# Magic House - Biomes o' Plenty
# Created by Ruins mod version 17.0 Ingame Parser
# authoring Player: Jordan_Greywolf
# Created for MC 1.12.2: 13 May 2018

# NOTE: This template requires the Biomes 'o Plenty mod.

biomesToSpawnIn=mystic_grove,ominous_woods,origin_island,rwg_plains,sacred_springs,woodland,woodlands

uniqueMinDistance=2000

weight=1
embed_into_distance=5
acceptable_target_blocks=

unacceptable_target_blocks=flowing_lava,lava,cloud,Natura:Cloud,red_mushroom_block,brown_mushroom_block,planks,cobblestone,torch,stone_slab,double_stone_slab,oak_stairs,spruce_stairs,birch_stairs,dark_oak_stairs,acacia_stairs,jungle_stairs,slime_congealed,slime_dirt,slime_grass,fence,stone_brick,cobblestone_wall,command_block

dimensions=26,13,14
allowable_overhang=0
max_leveling=5
leveling_buffer=-1
preserve_water=0
preserve_lava=0
preserve_plants=1

rule1=0,100,preserveBlock
rule2=0,100,minecraft:double_stone_slab-0
rule3=0,100,minecraft:stonebrick-1
rule4=0,100,minecraft:mossy_cobblestone-0
rule5=0,100,MobSpawner:Skeleton,MobSpawner:Zombie,MobSpawner:Spider
rule6=0,100,IInventory;minecraft:chest;biomesoplenty:log_1#3#5#0+biomesoplenty:log_0#4#4#2+biomesoplenty:log_0#3#4#3+biomesoplenty:log_1#3#5#4+minecraft:sapling#4#5#5+biomesoplenty:log_1#3#5#7+minecraft:log2#8#1#8+biomesoplenty:log_0#4#4#9+biomesoplenty:log_0#3#4#10+biomesoplenty:log_1#3#5#11+biomesoplenty:sapling_0#1#3#12+minecraft:log2#8#1#13+biomesoplenty:sapling_1#1#7#14+biomesoplenty:log_0#4#4#15+biomesoplenty:log_0#4#4#17+minecraft:log2#8#1#18+biomesoplenty:log_1#3#5#19+biomesoplenty:log_0#4#4#20+biomesoplenty:log_1#3#5#21+biomesoplenty:log_0#4#4#22+biomesoplenty:log_1#3#5#23+minecraft:log2#8#1#25+biomesoplenty:log_1#3#5#26-2
rule7=0,100,biomesoplenty:sacred_oak_stairs-2
rule8=0,100,biomesoplenty:sacred_oak_stairs-7
rule9=0,100,Skull:0:0-1
rule10=0,100,biomesoplenty:log_1-5
rule11=0,100,minecraft:stonebrick-0
rule12=0,100,biomesoplenty:sacred_oak_door_block-1
rule13=0,100,minecraft:planks-5
rule14=0,100,biomesoplenty:sacred_oak_door_block-9
rule15=0,100,Skull:0:0-2
rule16=0,100,minecraft:stonebrick-3
rule17=0,100,Skull:0:0-3
rule18=0,100,biomesoplenty:log_0-0
rule19=0,100,biomesoplenty:log_0-8
rule20=0,100,biomesoplenty:log_0-4
rule21=0,100,ChestGenHook:chests/simple_dungeon:5-3
rule22=0,100,minecraft:trapdoor-6
rule23=0,100,minecraft:bone_block-0
rule24=0,100,minecraft:trapdoor-4
rule25=0,100,minecraft:trapdoor-5
rule26=0,100,minecraft:trapdoor-7
rule27=0,100,biomesoplenty:magic_stairs-0
rule28=0,100,biomesoplenty:magic_stairs-5
rule29=0,100,biomesoplenty:planks_0-5
rule30=0,100,biomesoplenty:magic_stairs-4
rule31=0,100,biomesoplenty:magic_stairs-1
rule32=0,100,biomesoplenty:wood_slab_0-13
rule33=0,100,biomesoplenty:magic_stairs-6
rule34=0,100,biomesoplenty:magic_stairs-3
rule35=0,100,biomesoplenty:wood_slab_0-5
rule36=0,100,biomesoplenty:magic_stairs-2
rule37=0,100,biomesoplenty:magic_stairs-7

layer
1,1,1,1,1,1,1,1,1,1,1,1,1,1
1,1,1,1,1,1,1,1,1,1,1,1,1,1
1,1,2,2,2,2,2,2,2,2,2,2,1,1
1,1,2,3,3,3,3,3,3,3,3,2,2,1
1,1,2,3,4,4,4,4,4,4,3,2,2,2
1,1,2,3,4,4,4,4,4,4,3,2,2,2
1,1,2,3,4,4,4,4,4,4,3,2,2,2
1,1,2,3,4,4,4,4,4,4,3,2,2,2
1,1,2,3,4,4,4,4,4,4,3,2,2,2
1,1,2,3,3,3,3,3,3,3,3,2,2,1
1,1,2,2,2,2,2,2,2,2,2,2,1,1
1,1,1,1,1,1,1,1,1,1,1,1,1,1
1,1,1,1,1,1,1,1,1,1,1,1,1,1
endlayer

layer
1,1,1,1,1,1,1,1,1,1,1,1,1,1
1,1,1,1,1,1,1,1,1,1,1,1,1,1
1,1,1,1,1,1,1,1,1,1,1,1,1,1
1,1,1,3,3,3,3,3,3,3,3,2,1,1
1,1,1,3,0,0,0,0,0,0,3,2,2,1
1,1,1,3,5,0,0,0,0,0,3,2,2,2
1,1,1,3,6,0,0,0,0,0,3,2,2,2
1,1,1,3,5,0,0,0,0,0,3,2,2,2
1,1,1,3,0,0,0,8,7,0,3,2,2,1
1,1,1,3,3,3,3,3,3,3,3,2,1,1
1,1,1,1,1,1,1,1,1,1,1,1,1,1
1,1,1,1,1,1,1,1,1,1,1,1,1,1
1,1,1,1,1,1,1,1,1,1,1,1,1,1
endlayer

layer
1,1,1,1,1,1,1,1,1,1,1,1,1,1
1,1,1,1,1,1,1,1,1,1,1,1,1,1
1,1,1,1,1,1,1,1,1,1,1,1,1,1
1,1,1,3,3,3,3,3,3,3,3,1,1,1
1,1,1,3,0,0,0,0,0,0,3,2,1,1
1,1,1,3,9,0,0,0,0,0,3,2,2,1
1,1,1,3,0,0,0,0,0,0,3,2,2,2
1,1,1,3,9,0,0,0,0,0,3,2,2,1
1,1,1,3,0,0,8,7,0,0,3,2,1,1
1,1,1,3,3,3,3,3,3,3,3,1,1,1
1,1,1,1,1,1,1,1,1,1,1,1,1,1
1,1,1,1,1,1,1,1,1,1,1,1,1,1
1,1,1,1,1,1,1,1,1,1,1,1,1,1
endlayer

layer
1,1,1,1,1,1,1,1,1,1,1,1,1,1
1,1,1,1,1,1,1,1,1,1,1,1,1,1
1,1,1,1,1,1,1,1,1,1,1,1,1,1
1,1,1,3,3,3,3,3,3,3,3,1,1,1
1,1,1,3,0,0,0,0,0,0,3,1,1,1
1,1,1,3,0,0,0,0,0,0,3,2,1,1
1,1,1,3,0,0,0,0,0,0,3,2,2,1
1,1,1,3,0,0,0,0,0,0,3,2,1,1
1,1,1,3,0,8,7,0,0,0,3,1,1,1
1,1,1,3,3,3,3,3,3,3,3,1,1,1
1,1,1,1,1,1,1,1,1,1,1,1,1,1
1,1,1,1,1,1,1,1,1,1,1,1,1,1
1,1,1,1,1,1,1,1,1,1,1,1,1,1
endlayer

layer
1,1,1,1,1,1,1,1,1,1,1,1,1,1
1,1,1,1,1,1,1,1,1,1,1,1,1,1
1,1,1,1,1,1,1,1,1,1,1,1,1,1
1,1,1,3,3,3,3,3,3,3,3,1,1,1
1,1,1,3,10,10,10,10,10,10,3,1,1,1
1,1,1,3,10,10,10,10,10,10,3,1,1,1
1,1,1,3,10,10,10,10,10,10,3,2,1,1
1,1,1,3,10,10,10,10,10,10,3,1,1,1
1,1,1,3,10,7,0,0,0,10,3,1,1,1
1,1,1,3,3,3,3,3,3,3,3,1,1,1
1,1,1,1,1,1,1,1,1,1,1,1,1,1
1,1,1,1,1,1,1,1,1,1,1,1,1,1
1,1,1,1,1,1,1,1,1,1,1,1,1,1
endlayer

layer
1,1,1,1,1,1,1,1,1,1,1,1,1,1
1,1,1,1,1,1,1,1,1,1,1,1,1,1
1,1,1,1,1,1,1,1,1,1,1,1,1,1
1,1,1,2,11,11,11,11,11,11,2,1,1,1
1,1,1,11,0,0,0,8,7,0,11,1,1,1
1,1,1,11,0,0,0,0,0,0,11,0,1,1
1,1,1,11,5,0,0,0,0,0,12,0,0,1
1,1,1,11,0,0,0,0,0,0,11,0,1,1
1,1,1,11,0,0,0,0,0,0,11,1,1,1
1,1,1,2,11,11,11,11,11,11,2,1,1,1
1,1,1,1,1,1,1,1,1,1,1,1,1,1
1,1,1,1,1,1,1,1,1,1,1,1,1,1
1,1,1,1,1,1,1,1,1,1,1,1,1,1
endlayer

layer
1,1,1,1,1,0,0,0,1,1,1,1,1,1
1,1,1,0,0,0,0,0,0,0,0,1,1,1
1,1,0,0,0,0,0,0,0,0,0,0,1,1
1,0,0,2,11,13,11,11,13,11,2,0,0,1
0,0,0,13,0,0,8,7,0,0,13,0,0,1
0,0,0,11,0,0,0,0,0,0,11,0,0,0
0,0,0,11,9,0,0,0,0,0,14,0,0,0
0,0,0,11,0,0,0,0,0,0,11,0,0,0
0,0,0,13,0,0,0,0,0,0,13,0,0,1
1,0,0,2,11,13,11,11,13,11,2,0,0,1
1,1,0,0,0,0,0,0,0,0,0,0,0,1
1,1,0,0,0,0,0,0,0,0,0,1,1,1
1,1,1,1,0,0,0,0,0,1,1,1,1,1
endlayer

layer
1,1,1,0,0,0,0,0,0,0,0,1,1,1
1,0,0,0,0,0,0,0,0,0,0,0,1,1
0,0,0,0,0,0,0,0,0,0,0,0,0,1
0,0,0,2,11,13,11,11,13,11,2,0,0,0
0,0,0,13,0,8,7,0,0,0,13,0,0,0
0,0,0,11,0,0,0,0,0,0,11,0,0,0
0,0,0,11,0,0,0,0,0,17,16,15,0,0
0,0,0,11,0,0,0,0,0,0,11,0,0,0
0,0,0,13,0,0,0,0,0,0,13,0,0,0
0,0,0,2,11,13,11,11,13,11,2,0,0,0
1,0,0,0,0,0,0,0,0,0,0,0,0,1
1,0,0,0,0,0,0,0,0,0,0,0,0,1
1,1,0,0,0,0,0,0,0,0,0,1,1,1
endlayer

layer
1,0,0,0,0,0,0,0,0,0,0,0,0,1
0,0,0,0,0,0,0,0,0,0,0,0,0,0
0,0,0,18,0,18,0,0,18,0,18,0,0,0
0,0,19,2,11,11,11,11,11,11,2,19,0,0
0,0,0,11,10,7,0,0,0,10,11,0,0,0
0,0,19,11,10,10,10,10,10,10,11,19,0,0
0,0,0,11,10,10,10,10,10,10,11,0,0,0
0,0,19,11,10,10,10,10,10,10,11,19,0,0
0,0,0,11,10,10,10,10,10,10,11,0,0,0
0,0,19,2,11,11,11,11,11,11,2,19,0,0
0,0,0,18,0,18,0,0,18,0,18,0,0,0
0,0,0,0,0,0,0,0,0,0,0,0,0,0
0,0,0,0,0,0,0,0,0,0,0,0,0,1
endlayer

layer
0,0,0,0,0,0,0,0,0,0,0,0,0,0
0,0,0,0,0,0,0,0,0,0,0,0,0,0
0,0,20,19,19,20,19,19,20,19,19,20,0,0
0,0,18,0,0,0,0,0,0,0,0,18,0,0
0,0,18,0,0,0,0,0,0,0,0,18,0,0
0,0,20,0,0,0,0,0,0,0,0,20,0,0
0,0,18,5,0,0,0,0,0,0,21,18,0,0
0,0,20,0,0,0,0,0,0,0,0,20,0,0
0,0,18,0,0,0,0,0,0,0,0,18,0,0
0,0,18,0,0,0,0,0,0,0,0,18,0,0
0,0,20,19,19,20,19,19,20,19,19,20,0,0
0,0,0,0,0,0,0,0,0,0,0,0,0,0
0,0,0,0,0,0,0,0,0,0,0,0,0,0
endlayer

layer
0,0,0,0,0,0,0,0,0,0,0,0,0,0
0,0,0,0,0,22,0,0,22,0,0,0,0,0
0,0,20,23,23,20,13,13,20,23,23,20,0,0
0,0,23,0,0,0,0,0,0,0,0,23,0,0
0,0,23,0,0,0,0,0,0,0,0,23,0,0
0,25,20,0,0,0,0,0,0,0,0,20,24,0
0,0,13,9,0,0,0,0,0,0,0,13,0,0
0,25,20,0,0,0,0,0,0,0,0,20,24,0
0,0,23,0,0,0,0,0,0,0,0,23,0,0
0,0,23,0,0,0,0,0,0,0,0,23,0,0
0,0,20,23,23,20,13,13,20,23,23,20,0,0
0,0,0,0,0,26,0,0,26,0,0,0,0,0
0,0,0,0,0,0,0,0,0,0,0,0,0,0
endlayer

layer
0,0,0,0,0,0,0,0,0,0,0,0,0,0
0,0,0,0,0,22,0,0,22,0,0,0,0,0
0,0,20,23,23,20,13,13,20,23,23,20,0,0
0,0,23,0,0,0,0,0,0,0,0,23,0,0
0,0,23,0,0,0,0,0,0,0,0,23,0,0
0,25,20,0,0,0,0,0,0,0,0,20,24,0
0,0,13,0,0,0,0,0,0,0,0,13,0,0
0,25,20,0,0,0,0,0,0,0,0,20,24,0
0,0,23,0,0,0,0,0,0,0,0,23,0,0
0,0,23,0,0,0,0,0,0,0,0,23,0,0
0,0,20,23,23,20,13,13,20,23,23,20,0,0
0,0,0,0,0,26,0,0,26,0,0,0,0,0
0,0,0,0,0,0,0,0,0,0,0,0,0,0
endlayer

layer
0,0,0,0,0,0,0,0,0,0,0,0,0,0
0,0,0,0,0,0,0,0,0,0,0,0,0,0
0,0,20,19,19,20,19,19,20,19,19,20,0,0
0,0,18,0,0,0,0,0,0,0,0,18,0,0
0,0,18,0,0,0,0,0,0,0,0,18,0,0
0,0,20,0,0,0,0,0,0,0,0,20,0,0
0,0,18,0,0,0,0,0,0,0,0,18,0,0
0,0,20,0,0,0,0,0,0,0,0,20,0,0
0,0,18,0,0,0,0,0,0,0,0,18,0,0
0,0,18,0,0,0,0,0,0,0,0,18,0,0
0,0,20,19,19,20,19,19,20,19,19,20,0,0
0,0,0,0,0,0,0,0,0,0,0,0,0,0
0,0,0,0,0,0,0,0,0,0,0,0,0,0
endlayer

layer
0,0,0,0,0,0,0,0,0,0,0,0,0,0
0,27,27,27,27,27,27,27,27,27,27,27,27,0
0,28,20,29,29,29,29,29,29,29,29,20,28,0
0,0,23,0,0,0,0,0,0,0,0,23,0,0
0,0,23,0,0,0,0,0,0,0,0,23,0,0
0,25,20,0,0,0,0,0,0,0,0,20,24,0
0,0,13,0,0,0,0,0,0,0,0,13,0,0
0,25,20,0,0,0,0,0,0,0,0,20,24,0
0,0,23,0,0,0,0,0,0,0,0,23,0,0
0,0,23,0,0,0,0,0,0,0,0,23,0,0
0,30,20,29,29,29,29,29,29,29,29,20,30,0
0,31,31,31,31,31,31,31,31,31,31,31,31,0
0,0,0,0,0,0,0,0,0,0,0,0,0,0
endlayer

layer
0,0,0,0,0,0,0,0,0,0,0,0,0,0
0,0,0,0,0,0,0,0,0,0,0,0,0,0
0,29,29,29,29,29,29,29,29,29,29,29,29,0
0,0,23,0,0,0,0,0,0,0,0,23,0,0
0,0,23,0,0,0,0,0,0,0,0,23,0,0
0,25,20,0,0,0,0,0,0,0,0,20,24,0
0,0,13,0,0,0,0,0,0,0,0,13,0,0
0,25,20,0,0,0,0,0,0,0,0,20,24,0
0,0,23,0,0,0,0,0,0,0,0,23,0,0
0,0,23,0,0,0,0,0,0,0,0,23,0,0
0,29,29,29,29,29,29,29,29,29,29,29,29,0
0,0,0,0,0,0,0,0,0,0,0,0,0,0
0,0,0,0,0,0,0,0,0,0,0,0,0,0
endlayer

layer
0,0,0,0,0,0,0,0,0,0,0,0,0,0
0,0,0,0,0,0,0,0,0,0,0,0,0,0
0,27,27,27,27,27,27,27,27,27,27,27,27,0
0,28,18,28,28,28,28,28,28,28,28,18,28,0
0,0,18,0,0,0,0,0,0,0,0,18,0,0
0,0,20,0,0,0,0,0,0,0,0,20,0,0
0,0,18,0,0,0,0,0,0,0,0,18,0,0
0,0,20,0,0,0,0,0,0,0,0,20,0,0
0,0,18,0,0,0,0,0,0,0,0,18,0,0
0,30,18,30,30,30,30,30,30,30,30,18,30,0
0,31,31,31,31,31,31,31,31,31,31,31,31,0
0,0,0,0,0,0,0,0,0,0,0,0,0,0
0,0,0,0,0,0,0,0,0,0,0,0,0,0
endlayer

layer
0,0,0,0,0,0,0,0,0,0,0,0,0,0
0,0,0,0,0,0,0,0,0,0,0,0,0,0
0,0,0,0,0,0,0,0,0,0,0,0,0,0
0,29,29,29,29,29,29,29,29,29,29,29,29,0
0,0,23,0,0,0,0,0,0,0,0,23,0,0
0,25,20,0,0,0,0,0,0,0,0,20,24,0
0,0,13,0,0,0,0,0,0,0,0,13,0,0
0,25,20,0,0,0,0,0,0,0,0,20,24,0
0,0,23,0,0,0,0,0,0,0,0,23,0,0
0,29,29,29,29,29,29,29,29,29,29,29,29,0
0,0,0,0,0,0,0,0,0,0,0,0,0,0
0,0,0,0,0,0,0,0,0,0,0,0,0,0
0,0,0,0,0,0,0,0,0,0,0,0,0,0
endlayer

layer
0,0,0,0,0,0,0,0,0,0,0,0,0,0
0,0,0,0,0,0,0,0,0,0,0,0,0,0
0,0,0,0,0,0,0,0,0,0,0,0,0,0
0,27,27,27,27,27,27,27,27,27,27,27,27,0
0,28,23,28,28,28,28,28,28,28,28,23,28,0
0,25,20,0,0,0,0,0,0,0,0,20,24,0
0,0,13,0,0,0,0,0,0,0,0,13,0,0
0,25,20,0,0,0,0,0,0,0,0,20,24,0
0,30,23,30,30,30,30,30,30,30,30,23,30,0
0,31,31,31,31,31,31,31,31,31,31,31,31,0
0,0,0,0,0,0,0,0,0,0,0,0,0,0
0,0,0,0,0,0,0,0,0,0,0,0,0,0
0,0,0,0,0,0,0,0,0,0,0,0,0,0
endlayer

layer
0,0,0,0,0,0,0,0,0,0,0,0,0,0
0,0,0,0,0,0,0,0,0,0,0,0,0,0
0,0,0,0,0,0,0,0,0,0,0,0,0,0
0,0,0,0,0,0,0,0,0,0,0,0,0,0
0,29,29,29,29,29,29,29,29,29,29,29,29,0
0,0,20,0,0,0,0,0,0,0,0,20,0,0
0,0,18,0,0,0,0,0,0,0,0,18,0,0
0,0,20,0,0,0,0,0,0,0,0,20,0,0
0,29,29,29,29,29,29,29,29,29,29,29,29,0
0,0,0,0,0,0,0,0,0,0,0,0,0,0
0,0,0,0,0,0,0,0,0,0,0,0,0,0
0,0,0,0,0,0,0,0,0,0,0,0,0,0
0,0,0,0,0,0,0,0,0,0,0,0,0,0
endlayer

layer
0,0,0,0,0,0,0,0,0,0,0,0,0,0
0,0,0,0,0,0,0,0,0,0,0,0,0,0
0,0,0,0,0,0,0,0,0,0,0,0,0,0
0,0,0,0,0,0,0,0,0,0,0,0,0,0
0,27,27,27,27,27,27,27,27,27,27,27,27,0
0,28,20,28,28,28,28,28,28,28,28,20,28,0
0,0,23,0,0,0,0,0,0,0,0,23,0,0
0,30,20,30,30,30,30,30,30,30,30,20,30,0
0,31,31,31,31,31,31,31,31,31,31,31,31,0
0,0,0,0,0,0,0,0,0,0,0,0,0,0
0,0,0,0,0,0,0,0,0,0,0,0,0,0
0,0,0,0,0,0,0,0,0,0,0,0,0,0
0,0,0,0,0,0,0,0,0,0,0,0,0,0
endlayer

layer
0,0,0,0,0,0,0,0,0,0,0,0,0,0
0,0,0,0,0,0,0,0,0,0,0,0,0,0
0,0,0,0,0,0,0,0,0,0,0,0,0,0
0,0,0,0,0,0,0,0,0,0,0,0,0,0
0,0,0,0,0,0,0,0,0,0,0,0,0,0
0,29,29,29,29,29,29,29,29,29,29,29,29,0
0,0,23,0,0,0,0,0,0,0,0,23,0,0
0,29,29,29,29,29,29,29,29,29,29,29,29,0
0,0,0,0,0,0,0,0,0,0,0,0,0,0
0,0,0,0,0,0,0,0,0,0,0,0,0,0
0,0,0,0,0,0,0,0,0,0,0,0,0,0
0,0,0,0,0,0,0,0,0,0,0,0,0,0
0,0,0,0,0,0,0,0,0,0,0,0,0,0
endlayer

layer
0,0,0,0,0,0,0,0,0,0,0,0,0,0
0,0,0,0,0,0,0,0,0,0,0,0,0,0
0,0,0,0,0,0,0,0,0,0,0,0,0,0
0,0,0,0,0,0,0,0,0,0,0,0,0,0
0,0,0,0,0,0,0,0,0,0,0,0,0,0
0,27,27,27,27,27,27,27,27,27,27,27,27,0
0,32,29,32,32,32,32,32,32,32,32,29,32,0
0,31,31,31,31,31,31,31,31,31,31,31,31,0
0,0,0,0,0,0,0,0,0,0,0,0,0,0
0,0,0,0,0,0,0,0,0,0,0,0,0,0
0,0,0,0,0,0,0,0,0,0,0,0,0,0
0,0,0,0,0,0,0,0,0,0,0,0,0,0
0,0,0,0,0,0,0,0,0,0,0,0,0,0
endlayer

layer
0,0,0,0,0,0,0,0,0,0,0,0,0,0
0,0,0,0,0,0,0,0,0,0,0,0,0,0
0,0,0,0,0,0,0,0,0,0,0,0,0,0
0,0,0,0,0,0,0,0,0,0,0,0,0,0
0,0,0,0,0,0,0,0,0,0,0,0,0,0
0,0,0,0,0,0,0,0,0,0,0,0,0,0
37,29,36,35,35,35,35,35,35,35,35,34,29,33
0,0,0,0,0,0,0,0,0,0,0,0,0,0
0,0,0,0,0,0,0,0,0,0,0,0,0,0
0,0,0,0,0,0,0,0,0,0,0,0,0,0
0,0,0,0,0,0,0,0,0,0,0,0,0,0
0,0,0,0,0,0,0,0,0,0,0,0,0,0
0,0,0,0,0,0,0,0,0,0,0,0,0,0
endlayer

layer
0,0,0,0,0,0,0,0,0,0,0,0,0,0
0,0,0,0,0,0,0,0,0,0,0,0,0,0
0,0,0,0,0,0,0,0,0,0,0,0,0,0
0,0,0,0,0,0,0,0,0,0,0,0,0,0
0,0,0,0,0,0,0,0,0,0,0,0,0,0
0,0,0,0,0,0,0,0,0,0,0,0,0,0
29,36,0,0,0,0,0,0,0,0,0,0,34,29
0,0,0,0,0,0,0,0,0,0,0,0,0,0
0,0,0,0,0,0,0,0,0,0,0,0,0,0
0,0,0,0,0,0,0,0,0,0,0,0,0,0
0,0,0,0,0,0,0,0,0,0,0,0,0,0
0,0,0,0,0,0,0,0,0,0,0,0,0,0
0,0,0,0,0,0,0,0,0,0,0,0,0,0
endlayer

layer
0,0,0,0,0,0,0,0,0,0,0,0,0,0
0,0,0,0,0,0,0,0,0,0,0,0,0,0
0,0,0,0,0,0,0,0,0,0,0,0,0,0
0,0,0,0,0,0,0,0,0,0,0,0,0,0
0,0,0,0,0,0,0,0,0,0,0,0,0,0
0,0,0,0,0,0,0,0,0,0,0,0,0,0
29,0,0,0,0,0,0,0,0,0,0,0,0,29
0,0,0,0,0,0,0,0,0,0,0,0,0,0
0,0,0,0,0,0,0,0,0,0,0,0,0,0
0,0,0,0,0,0,0,0,0,0,0,0,0,0
0,0,0,0,0,0,0,0,0,0,0,0,0,0
0,0,0,0,0,0,0,0,0,0,0,0,0,0
0,0,0,0,0,0,0,0,0,0,0,0,0,0
endlayer

layer
0,0,0,0,0,0,0,0,0,0,0,0,0,0
0,0,0,0,0,0,0,0,0,0,0,0,0,0
0,0,0,0,0,0,0,0,0,0,0,0,0,0
0,0,0,0,0,0,0,0,0,0,0,0,0,0
0,0,0,0,0,0,0,0,0,0,0,0,0,0
0,0,0,0,0,0,0,0,0,0,0,0,0,0
36,0,0,0,0,0,0,0,0,0,0,0,0,34
0,0,0,0,0,0,0,0,0,0,0,0,0,0
0,0,0,0,0,0,0,0,0,0,0,0,0,0
0,0,0,0,0,0,0,0,0,0,0,0,0,0
0,0,0,0,0,0,0,0,0,0,0,0,0,0
0,0,0,0,0,0,0,0,0,0,0,0,0,0
0,0,0,0,0,0,0,0,0,0,0,0,0,0
endlayer

