# Biomes o' Plenty - Celestial Shard
# Created by Ruins mod version 17.1 Ingame Parser
# authoring Player: Jordan_Greywolf
# For MC 1.12 with Biomes o' Plenty
# Created for MC 1.12: 20 Jul 2018

biomesToSpawnIn=sky

weight=1
embed_into_distance=8
acceptable_target_blocks=end_stone

dimensions=15,6,6
allowable_overhang=99
max_leveling=24
leveling_buffer=-1
preserve_water=0
preserve_lava=0

rule1=0,100,preserveBlock
rule2=0,100,biomesoplenty:crystal-0

layer
1,1,1,1,1,1
1,1,1,1,1,1
1,1,2,2,1,1
1,1,2,2,1,1
1,1,1,1,1,1
1,1,1,1,1,1
endlayer

layer
1,1,1,1,1,1
1,1,1,1,1,1
1,1,2,2,1,1
1,1,2,2,1,1
1,1,1,1,1,1
1,1,1,1,1,1
endlayer

layer
1,1,1,1,1,1
1,1,2,2,1,1
1,2,2,2,2,1
1,2,2,2,2,1
1,1,2,2,1,1
1,1,1,1,1,1
endlayer

layer
1,1,1,1,1,1
1,1,2,2,1,1
1,2,2,2,2,1
1,2,2,2,2,1
1,1,2,2,1,1
1,1,1,1,1,1
endlayer

layer
1,1,1,1,1,1
1,1,2,2,1,1
1,2,2,2,2,1
1,2,2,2,2,1
1,1,2,2,1,1
1,1,1,1,1,1
endlayer

layer
1,1,2,2,1,1
1,2,2,2,2,1
2,2,2,2,2,2
2,2,2,2,2,2
1,2,2,2,2,1
1,1,2,2,1,1
endlayer

layer
1,1,2,2,1,1
1,2,2,2,2,1
2,2,2,2,2,2
2,2,2,2,2,2
1,2,2,2,2,1
1,1,2,2,1,1
endlayer

layer
1,1,2,2,1,1
1,2,2,2,2,1
2,2,2,2,2,2
2,2,2,2,2,2
1,2,2,2,2,1
1,1,2,2,1,1
endlayer

layer
1,1,1,1,1,1
1,1,2,2,1,1
1,2,2,2,2,1
1,2,2,2,2,1
1,1,2,2,1,1
1,1,1,1,1,1
endlayer

layer
1,1,1,1,1,1
1,1,2,2,1,1
1,2,2,2,2,1
1,2,2,2,2,1
1,1,2,2,1,1
1,1,1,1,1,1
endlayer

layer
1,1,1,1,1,1
1,1,2,2,1,1
1,2,2,2,2,1
1,2,2,2,2,1
1,1,2,2,1,1
1,1,1,1,1,1
endlayer

layer
1,1,1,1,1,1
1,1,1,1,1,1
1,1,2,2,1,1
1,1,2,2,1,1
1,1,1,1,1,1
1,1,1,1,1,1
endlayer

layer
1,1,1,1,1,1
1,1,1,1,1,1
1,1,2,2,1,1
1,1,2,2,1,1
1,1,1,1,1,1
1,1,1,1,1,1
endlayer

layer
1,1,1,1,1,1
1,1,1,1,1,1
1,1,2,2,1,1
1,1,2,2,1,1
1,1,1,1,1,1
1,1,1,1,1,1
endlayer

layer
1,1,1,1,1,1
1,1,1,1,1,1
1,1,2,2,1,1
1,1,2,2,1,1
1,1,1,1,1,1
1,1,1,1,1,1
endlayer

