# Baobab Tree Lookout -- 25 Mar 2016 -- MC 1.8
# Created by Ruins mod version 15.5 Ingame Parser
# authoring Player: Jordan_Greywolf

# Updated for MC 1.11: 13 Jan 2017
# Verified for MC 1.12: 23 Jun 2017
# Last Updated: 8 Dec 2018

biomesToSpawnIn=savanna,savanna m,savanna plateau,savanna plateau m,savanna_rock,mutated_savanna,mutated_savanna_rock

biomeTypesToSpawnIn=SAVANNA

weight=1
embed_into_distance=5
acceptable_target_blocks=

unacceptable_target_blocks=flowing_water,water,flowing_lava,lava,cloud,Natura:Cloud,slime_congealed,slime_dirt,slime_grass,command_block,planks,planks2,concrete,cobblestone,stonebrick,brick_block,glass,torch,oak_stairs,stone_stairs,brick_stairs,stone_brick_stairs,nether_brick_stairs,sandstone_stairs,spruce_stairs,birch_stairs,jungle_stairs,quartz_stairs,acacia_stairs,dark_oak_stairs,cobblestone_wall,stone_slab,double_stone_slab,stone_slab2,wooden_slab,double_wooden_slab,nether_brick,fence

uniqueMinDistance=1000

dimensions=29,19,19
allowable_overhang=0
max_leveling=5
leveling_buffer=-1
preserve_water=0
preserve_lava=0
preserve_plants=1

rule1=0,100,preserveBlock
rule2=0,100,minecraft:grass-0

# Acacia log (bark only)
rule3=0,100,minecraft:log2-12
rule4=0,100,minecraft:dirt-0
rule5=0,100,minecraft:ladder-2
rule6=0,100,minecraft:acacia_fence-0
rule7=0,100,minecraft:planks-4
rule8=0,100,minecraft:wooden_slab-4
rule9=0,100,minecraft:trapdoor-1
rule10=0,100,minecraft:trapdoor-9
rule11=0,100,minecraft:leaves2-4

layer
1,1,1,1,1,1,1,1,1,1,1,1,1,1,1,1,1,1,1
1,1,1,1,1,1,1,1,1,1,1,1,1,1,1,1,1,1,1
1,1,1,1,1,1,1,1,1,1,1,1,1,1,1,1,1,1,1
1,1,1,1,1,1,1,1,1,1,1,1,1,1,1,1,1,1,1
1,1,1,1,1,1,1,1,1,1,1,1,1,1,1,1,1,1,1
1,1,1,1,1,1,1,1,1,1,1,1,1,1,1,1,1,1,1
1,1,1,1,1,1,1,3,3,3,3,3,2,2,1,1,1,1,1
1,1,1,1,1,1,3,3,3,3,3,3,3,4,1,1,1,1,1
1,1,1,1,1,1,3,3,3,3,3,3,3,4,1,1,1,1,1
1,1,1,1,1,1,3,3,3,3,3,3,3,4,1,1,1,1,1
1,1,1,1,1,1,3,3,3,3,3,3,3,4,1,1,1,1,1
1,1,1,1,1,1,3,3,3,3,3,3,3,4,1,1,1,1,1
1,1,1,1,1,1,1,3,3,3,3,3,2,2,1,1,1,1,1
1,1,1,1,1,1,1,1,1,1,1,1,1,1,1,1,1,1,1
1,1,1,1,1,1,1,1,1,1,1,1,1,1,1,1,1,1,1
1,1,1,1,1,1,1,1,1,1,1,1,1,1,1,1,1,1,1
1,1,1,1,1,1,1,1,1,1,1,1,1,1,1,1,1,1,1
1,1,1,1,1,1,1,1,1,1,1,1,1,1,1,1,1,1,1
1,1,1,1,1,1,1,1,1,1,1,1,1,1,1,1,1,1,1
endlayer

layer
1,1,1,1,1,1,1,1,1,1,1,1,1,1,1,1,1,1,1
1,1,1,1,1,1,1,1,1,1,1,1,1,1,1,1,1,1,1
1,1,1,1,1,1,1,1,1,1,1,1,1,1,1,1,1,1,1
1,1,1,1,1,1,1,1,1,1,1,1,1,1,1,1,1,1,1
1,1,1,1,1,1,1,1,1,1,1,1,1,1,1,1,1,1,1
1,1,1,1,1,1,1,1,1,1,1,1,1,1,1,1,1,1,1
1,1,1,1,1,1,1,3,3,3,3,3,1,1,1,1,1,1,1
1,1,1,1,1,1,3,3,3,3,3,3,3,2,1,1,1,1,1
1,1,1,1,1,1,3,3,3,3,3,3,3,4,1,1,1,1,1
1,1,1,1,1,1,3,3,3,3,3,3,3,4,1,1,1,1,1
1,1,1,1,1,1,3,3,3,3,3,3,3,4,1,1,1,1,1
1,1,1,1,1,1,3,3,3,3,3,3,3,2,1,1,1,1,1
1,1,1,1,1,1,1,3,3,3,3,3,1,1,1,1,1,1,1
1,1,1,1,1,1,1,1,1,1,1,1,1,1,1,1,1,1,1
1,1,1,1,1,1,1,1,1,1,1,1,1,1,1,1,1,1,1
1,1,1,1,1,1,1,1,1,1,1,1,1,1,1,1,1,1,1
1,1,1,1,1,1,1,1,1,1,1,1,1,1,1,1,1,1,1
1,1,1,1,1,1,1,1,1,1,1,1,1,1,1,1,1,1,1
1,1,1,1,1,1,1,1,1,1,1,1,1,1,1,1,1,1,1
endlayer

layer
1,1,1,1,1,1,1,1,1,1,1,1,1,1,1,1,1,1,1
1,1,1,1,1,1,1,1,1,1,1,1,1,1,1,1,1,1,1
1,1,1,1,1,1,1,1,1,1,1,1,1,1,1,1,1,1,1
1,1,1,1,1,1,1,1,1,1,1,1,1,1,1,1,1,1,1
1,1,1,1,1,1,1,1,1,1,1,1,1,1,1,1,1,1,1
1,1,1,1,1,1,1,1,1,1,1,1,1,1,1,1,1,1,1
1,1,1,1,1,1,1,3,3,3,3,3,1,1,1,1,1,1,1
1,1,1,1,1,1,3,3,3,3,3,3,3,1,1,1,1,1,1
1,1,1,1,1,1,3,3,3,3,3,3,3,2,1,1,1,1,1
1,1,1,1,1,1,3,3,3,3,3,3,3,4,1,1,1,1,1
1,1,1,1,1,1,3,3,3,3,3,3,3,2,1,1,1,1,1
1,1,1,1,1,1,3,3,3,3,3,3,3,1,1,1,1,1,1
1,1,1,1,1,1,1,3,3,3,3,3,1,1,1,1,1,1,1
1,1,1,1,1,1,1,1,1,1,1,1,1,1,1,1,1,1,1
1,1,1,1,1,1,1,1,1,1,1,1,1,1,1,1,1,1,1
1,1,1,1,1,1,1,1,1,1,1,1,1,1,1,1,1,1,1
1,1,1,1,1,1,1,1,1,1,1,1,1,1,1,1,1,1,1
1,1,1,1,1,1,1,1,1,1,1,1,1,1,1,1,1,1,1
1,1,1,1,1,1,1,1,1,1,1,1,1,1,1,1,1,1,1
endlayer

layer
1,1,1,1,1,1,1,1,1,1,1,1,1,1,1,1,1,1,1
1,1,1,1,1,1,1,1,1,1,1,1,1,1,1,1,1,1,1
1,1,1,1,1,1,1,1,1,1,1,1,1,1,1,1,1,1,1
1,1,1,1,1,1,1,1,1,1,1,1,1,1,1,1,1,1,1
1,1,1,1,1,1,1,1,1,1,1,1,1,1,1,1,1,1,1
1,1,1,1,1,1,1,1,1,1,1,1,1,1,1,1,1,1,1
1,1,1,1,1,1,1,3,3,3,3,3,1,1,1,1,1,1,1
1,1,1,1,1,1,3,3,3,3,3,3,3,1,1,1,1,1,1
1,1,1,1,1,1,3,3,3,3,3,3,3,1,1,1,1,1,1
1,1,1,1,1,1,3,3,3,3,3,3,3,2,1,1,1,1,1
1,1,1,1,1,1,3,3,3,3,3,3,3,1,1,1,1,1,1
1,1,1,1,1,1,3,3,3,3,3,3,3,1,1,1,1,1,1
1,1,1,1,1,1,1,3,3,3,3,3,1,1,1,1,1,1,1
1,1,1,1,1,1,1,1,1,1,1,1,1,1,1,1,1,1,1
1,1,1,1,1,1,1,1,1,1,1,1,1,1,1,1,1,1,1
1,1,1,1,1,1,1,1,1,1,1,1,1,1,1,1,1,1,1
1,1,1,1,1,1,1,1,1,1,1,1,1,1,1,1,1,1,1
1,1,1,1,1,1,1,1,1,1,1,1,1,1,1,1,1,1,1
1,1,1,1,1,1,1,1,1,1,1,1,1,1,1,1,1,1,1
endlayer

layer
1,1,1,1,1,1,1,1,1,1,1,1,1,1,1,1,1,1,1
1,1,1,1,1,1,1,1,1,1,1,1,1,1,1,1,1,1,1
1,1,1,1,1,1,1,1,1,1,1,1,1,1,1,1,1,1,1
1,1,1,1,1,1,1,1,1,1,1,1,1,1,1,1,1,1,1
1,1,1,1,1,1,1,1,1,1,1,1,1,1,1,1,1,1,1
1,1,1,1,1,1,1,1,1,1,1,1,1,1,1,1,1,1,1
1,1,1,1,1,1,1,3,3,3,3,3,1,1,1,1,1,1,1
1,1,1,1,1,1,3,3,3,3,3,3,3,1,1,1,1,1,1
1,1,1,1,1,1,3,3,3,3,3,3,3,1,1,1,1,1,1
1,1,1,1,1,1,3,3,3,3,3,3,3,5,1,1,1,1,1
1,1,1,1,1,1,3,3,3,3,3,3,3,1,1,1,1,1,1
1,1,1,1,1,1,3,3,3,3,3,3,3,1,1,1,1,1,1
1,1,1,1,1,1,1,3,3,3,3,3,1,1,1,1,1,1,1
1,1,1,1,1,1,1,1,1,1,1,1,1,1,1,1,1,1,1
1,1,1,1,1,1,1,1,1,1,1,1,1,1,1,1,1,1,1
1,1,1,1,1,1,1,1,1,1,1,1,1,1,1,1,1,1,1
1,1,1,1,1,1,1,1,1,1,1,1,1,1,1,1,1,1,1
1,1,1,1,1,1,1,1,1,1,1,1,1,1,1,1,1,1,1
1,1,1,1,1,1,1,1,1,1,1,1,1,1,1,1,1,1,1
endlayer

layer
1,1,1,1,1,1,1,1,1,1,1,1,1,1,1,1,1,1,1
1,1,1,1,1,1,1,1,1,1,1,1,1,1,1,1,1,1,1
1,1,1,1,1,1,1,1,1,1,1,1,1,1,1,1,1,1,1
1,1,1,1,1,1,1,1,1,1,1,1,1,1,1,1,1,1,1
1,1,1,1,1,1,1,1,1,1,1,1,1,1,1,1,1,1,1
1,1,1,1,1,1,1,1,1,1,1,1,1,1,1,1,1,1,1
1,1,1,1,1,1,1,3,3,3,3,3,1,1,1,1,1,1,1
1,1,1,1,1,1,3,3,3,3,3,3,3,1,1,1,1,1,1
1,1,1,1,1,1,3,3,3,3,3,3,3,1,1,1,1,1,1
1,1,1,1,1,1,3,3,3,3,3,3,3,5,1,1,1,1,1
1,1,1,1,1,1,3,3,3,3,3,3,3,1,1,1,1,1,1
1,1,1,1,1,1,3,3,3,3,3,3,3,1,1,1,1,1,1
1,1,1,1,1,1,1,3,3,3,3,3,1,1,1,1,1,1,1
1,1,1,1,1,1,1,1,1,1,1,1,1,1,1,1,1,1,1
1,1,1,1,1,1,1,1,1,1,1,1,1,1,1,1,1,1,1
1,1,1,1,1,1,1,1,1,1,1,1,1,1,1,1,1,1,1
1,1,1,1,1,1,1,1,1,1,1,1,1,1,1,1,1,1,1
1,1,1,1,1,1,1,1,1,1,1,1,1,1,1,1,1,1,1
1,1,1,1,1,1,1,1,1,1,1,1,1,1,1,1,1,1,1
endlayer

layer
1,1,1,1,1,1,1,1,1,1,1,1,1,1,1,1,1,1,1
1,1,1,1,1,1,1,1,1,1,1,1,1,1,1,1,1,1,1
1,1,1,1,1,1,1,1,1,1,1,1,1,1,1,1,1,1,1
1,1,1,1,1,1,1,1,1,1,1,1,1,1,1,1,1,1,1
1,1,1,1,1,1,1,1,1,1,1,1,1,1,1,1,1,1,1
1,1,1,1,1,1,1,1,1,1,1,1,1,1,1,1,1,1,1
1,1,1,1,1,1,1,3,3,3,3,3,1,1,1,1,1,1,1
1,1,1,1,1,1,3,3,3,3,3,3,3,1,1,1,1,1,1
1,1,1,1,1,1,3,3,3,3,3,3,3,1,1,1,1,1,1
1,1,1,1,1,1,3,3,3,3,3,3,3,5,1,1,1,1,1
1,1,1,1,1,1,3,3,3,3,3,3,3,1,1,1,1,1,1
1,1,1,1,1,1,3,3,3,3,3,3,3,1,1,1,1,1,1
1,1,1,1,1,1,1,3,3,3,3,3,1,1,1,1,1,1,1
1,1,1,1,1,1,1,1,1,1,1,1,1,1,1,1,1,1,1
1,1,1,1,1,1,1,1,1,1,1,1,1,1,1,1,1,1,1
1,1,1,1,1,1,1,1,1,1,1,1,1,1,1,1,1,1,1
1,1,1,1,1,1,1,1,1,1,1,1,1,1,1,1,1,1,1
1,1,1,1,1,1,1,1,1,1,1,1,1,1,1,1,1,1,1
1,1,1,1,1,1,1,1,1,1,1,1,1,1,1,1,1,1,1
endlayer

layer
1,1,1,1,1,1,1,1,1,1,1,1,1,1,1,1,1,1,1
1,1,1,1,1,1,1,1,1,1,1,1,1,1,1,1,1,1,1
1,1,1,1,1,1,1,1,1,1,1,1,1,1,1,1,1,1,1
1,1,1,1,1,1,1,1,1,1,1,1,1,1,1,1,1,1,1
1,1,1,1,1,1,1,1,1,1,1,1,1,1,1,1,1,1,1
1,1,1,1,1,1,1,1,1,1,1,1,1,1,1,1,1,1,1
1,1,1,1,1,1,1,3,3,3,3,3,1,1,1,1,1,1,1
1,1,1,1,1,1,3,3,3,3,3,3,3,1,1,1,1,1,1
1,1,1,1,1,1,3,3,3,3,3,3,3,1,1,1,1,1,1
1,1,1,1,1,1,3,3,3,3,3,3,3,5,1,1,1,1,1
1,1,1,1,1,1,3,3,3,3,3,3,3,1,1,1,1,1,1
1,1,1,1,1,1,3,3,3,3,3,3,3,1,1,1,1,1,1
1,1,1,1,1,1,1,3,3,3,3,3,1,1,1,1,1,1,1
1,1,1,1,1,1,1,1,1,1,1,1,1,1,1,1,1,1,1
1,1,1,1,1,1,1,1,1,1,1,1,1,1,1,1,1,1,1
1,1,1,1,1,1,1,1,1,1,1,1,1,1,1,1,1,1,1
1,1,1,1,1,1,1,1,1,1,1,1,1,1,1,1,1,1,1
1,1,1,1,1,1,1,1,1,1,1,1,1,1,1,1,1,1,1
1,1,1,1,1,1,1,1,1,1,1,1,1,1,1,1,1,1,1
endlayer

layer
1,1,1,1,1,1,1,1,1,1,1,1,1,1,1,1,1,1,1
1,1,1,1,1,1,1,1,1,1,1,1,1,1,1,1,1,1,1
1,1,1,1,1,1,1,1,1,1,1,1,1,1,1,1,1,1,1
1,1,1,1,1,1,1,1,1,1,1,1,1,1,1,1,1,1,1
1,1,1,1,1,1,1,1,1,1,1,1,1,1,1,1,1,1,1
1,1,1,1,1,1,1,1,1,1,1,1,1,1,1,1,1,1,1
1,1,1,1,1,1,1,3,3,3,3,3,1,1,1,1,1,1,1
1,1,1,1,1,1,3,3,3,3,3,3,3,1,1,1,1,1,1
1,1,1,1,1,1,3,3,3,3,3,3,3,1,1,1,1,1,1
1,1,1,1,1,1,3,3,3,3,3,3,3,5,1,1,1,1,1
1,1,1,1,1,1,3,3,3,3,3,3,3,1,1,1,1,1,1
1,1,1,1,1,1,3,3,3,3,3,3,3,1,1,1,1,1,1
1,1,1,1,1,1,1,3,3,3,3,3,1,1,1,1,1,1,1
1,1,1,1,1,1,1,1,1,1,1,1,1,1,1,1,1,1,1
1,1,1,1,1,1,1,1,1,1,1,1,1,1,1,1,1,1,1
1,1,1,1,1,1,1,1,1,1,1,1,1,1,1,1,1,1,1
1,1,1,1,1,1,1,1,1,1,1,1,1,1,1,1,1,1,1
1,1,1,1,1,1,1,1,1,1,1,1,1,1,1,1,1,1,1
1,1,1,1,1,1,1,1,1,1,1,1,1,1,1,1,1,1,1
endlayer

layer
1,1,1,1,1,1,1,1,1,1,1,1,1,1,1,1,1,1,1
1,1,1,1,1,1,1,1,1,1,1,1,1,1,1,1,1,1,1
1,1,1,1,1,1,1,1,1,1,1,1,1,1,1,1,1,1,1
1,1,1,1,1,1,1,1,1,1,1,1,1,1,1,1,1,1,1
1,1,1,1,1,1,1,1,1,1,1,1,1,1,1,1,1,1,1
1,1,1,1,1,1,1,1,1,1,1,1,1,1,1,1,1,1,1
1,1,1,1,1,1,1,3,3,3,3,3,1,1,1,1,1,1,1
1,1,1,1,1,1,3,3,3,3,3,3,3,1,1,1,1,1,1
1,1,1,1,1,1,3,3,3,3,3,3,3,1,1,1,1,1,1
1,1,1,1,1,1,3,3,3,3,3,3,3,5,1,1,1,1,1
1,1,1,1,1,1,3,3,3,3,3,3,3,1,1,1,1,1,1
1,1,1,1,1,1,3,3,3,3,3,3,3,1,1,1,1,1,1
1,1,1,1,1,1,1,3,3,3,3,3,1,1,1,1,1,1,1
1,1,1,1,1,1,1,1,1,1,1,1,1,1,1,1,1,1,1
1,1,1,1,1,1,1,1,1,1,1,1,1,1,1,1,1,1,1
1,1,1,1,1,1,1,1,1,1,1,1,1,1,1,1,1,1,1
1,1,1,1,1,1,1,1,1,1,1,1,1,1,1,1,1,1,1
1,1,1,1,1,1,1,1,1,1,1,1,1,1,1,1,1,1,1
1,1,1,1,1,1,1,1,1,1,1,1,1,1,1,1,1,1,1
endlayer

layer
1,1,1,1,1,1,1,1,1,1,1,1,1,1,1,1,1,1,1
1,1,1,1,1,1,1,1,1,1,1,1,1,1,1,1,1,1,1
1,1,1,1,1,1,1,1,1,1,1,1,1,1,1,1,1,1,1
1,1,1,1,1,1,1,1,1,1,1,1,1,1,1,1,1,1,1
1,1,1,1,1,1,1,1,1,1,1,1,1,1,1,1,1,1,1
1,1,1,1,1,1,1,1,1,1,1,1,1,1,1,1,1,1,1
1,1,1,1,1,1,1,3,3,3,3,3,1,1,1,1,1,1,1
1,1,1,1,1,1,3,3,3,3,3,3,3,1,1,1,1,1,1
1,1,1,1,1,1,3,3,3,3,3,3,3,1,1,1,1,1,1
1,1,1,1,1,1,3,3,3,3,3,3,3,5,1,1,1,1,1
1,1,1,1,1,1,3,3,3,3,3,3,3,1,1,1,1,1,1
1,1,1,1,1,1,3,3,3,3,3,3,3,1,1,1,1,1,1
1,1,1,1,1,1,1,3,3,3,3,3,1,1,1,1,1,1,1
1,1,1,1,1,1,1,1,1,1,1,1,1,1,1,1,1,1,1
1,1,1,1,1,1,1,1,1,1,1,1,1,1,1,1,1,1,1
1,1,1,1,1,1,1,1,1,1,1,1,1,1,1,1,1,1,1
1,1,1,1,1,1,1,1,1,1,1,1,1,1,1,1,1,1,1
1,1,1,1,1,1,1,1,1,1,1,1,1,1,1,1,1,1,1
1,1,1,1,1,1,1,1,1,1,1,1,1,1,1,1,1,1,1
endlayer

layer
1,1,1,1,1,1,1,1,1,1,1,1,1,1,1,1,1,1,1
1,1,1,1,1,1,1,1,1,1,1,1,1,1,1,1,1,1,1
1,1,1,1,1,1,1,1,1,1,1,1,1,1,1,1,1,1,1
1,1,1,1,1,1,1,1,1,1,1,1,1,1,1,1,1,1,1
1,1,1,1,1,1,1,1,1,1,1,1,1,1,1,1,1,1,1
1,1,1,1,1,1,1,1,1,1,1,1,1,1,1,1,1,1,1
1,1,1,1,1,1,1,3,3,3,3,3,1,1,1,1,1,1,1
1,1,1,1,1,1,3,3,3,3,3,3,3,1,1,1,1,1,1
1,1,1,1,1,1,3,3,3,3,3,3,3,1,1,1,1,1,1
1,1,1,1,1,1,3,3,3,3,3,3,3,5,1,1,1,1,1
1,1,1,1,1,1,3,3,3,3,3,3,3,1,1,1,1,1,1
1,1,1,1,1,1,3,3,3,3,3,3,3,1,1,1,1,1,1
1,1,1,1,1,1,1,3,3,3,3,3,1,1,1,1,1,1,1
1,1,1,1,1,1,1,1,1,1,1,1,1,1,1,1,1,1,1
1,1,1,1,1,1,1,1,1,1,1,1,1,1,1,1,1,1,1
1,1,1,1,1,1,1,1,1,1,1,1,1,1,1,1,1,1,1
1,1,1,1,1,1,1,1,1,1,1,1,1,1,1,1,1,1,1
1,1,1,1,1,1,1,1,1,1,1,1,1,1,1,1,1,1,1
1,1,1,1,1,1,1,1,1,1,1,1,1,1,1,1,1,1,1
endlayer

layer
1,1,1,1,1,1,1,1,1,1,1,1,1,1,1,1,1,1,1
1,1,1,1,1,1,1,1,1,1,1,1,1,1,1,1,1,1,1
1,1,1,1,1,1,1,1,1,1,1,1,1,1,1,1,1,1,1
1,1,1,1,1,1,1,1,1,1,1,1,1,1,1,1,1,1,1
1,1,1,1,1,1,1,1,1,1,1,1,1,1,1,1,1,1,1
1,1,1,1,1,1,1,1,1,1,1,1,1,1,1,1,1,1,1
1,1,1,1,1,1,1,3,3,3,3,3,1,1,1,1,1,1,1
1,1,1,1,1,1,3,3,3,3,3,3,3,1,1,1,1,1,1
1,1,1,1,1,1,3,3,3,3,3,3,3,1,1,1,1,1,1
1,1,1,1,1,1,3,3,3,3,3,3,3,5,1,1,1,1,1
1,1,1,1,1,1,3,3,3,3,3,3,3,1,1,1,1,1,1
1,1,1,1,1,1,3,3,3,3,3,3,3,1,1,1,1,1,1
1,1,1,1,1,1,1,3,3,3,3,3,1,1,1,1,1,1,1
1,1,1,1,1,1,1,1,1,1,1,1,1,1,1,1,1,1,1
1,1,1,1,1,1,1,1,1,1,1,1,1,1,1,1,1,1,1
1,1,1,1,1,1,1,1,1,1,1,1,1,1,1,1,1,1,1
1,1,1,1,1,1,1,1,1,1,1,1,1,1,1,1,1,1,1
1,1,1,1,1,1,1,1,1,1,1,1,1,1,1,1,1,1,1
1,1,1,1,1,1,1,1,1,1,1,1,1,1,1,1,1,1,1
endlayer

layer
1,1,1,1,1,1,1,1,1,1,1,1,1,1,1,1,1,1,1
1,1,1,1,1,1,1,1,1,1,1,1,1,1,1,1,1,1,1
1,1,1,1,1,1,1,1,1,1,1,1,1,1,1,1,1,1,1
1,1,1,1,1,1,1,1,1,1,1,1,1,1,1,1,1,1,1
1,1,1,1,1,1,1,1,1,1,1,1,1,1,1,1,1,1,1
1,1,1,1,1,1,1,1,1,1,1,1,1,1,1,1,1,1,1
1,1,1,1,1,1,1,3,3,3,3,3,1,1,1,1,1,1,1
1,1,1,1,1,1,3,3,3,3,3,3,3,1,1,1,1,1,1
1,1,1,1,1,1,3,3,3,3,3,3,3,1,1,1,1,1,1
1,1,1,1,1,1,3,3,3,3,3,3,3,5,1,1,1,1,1
1,1,1,1,1,1,3,3,3,3,3,3,3,1,1,1,1,1,1
1,1,1,1,1,1,3,3,3,3,3,3,3,1,1,1,1,1,1
1,1,1,1,1,1,1,3,3,3,3,3,1,1,1,1,1,1,1
1,1,1,1,1,1,1,1,1,1,1,1,1,1,1,1,1,1,1
1,1,1,1,1,1,1,1,1,1,1,1,1,1,1,1,1,1,1
1,1,1,1,1,1,1,1,1,1,1,1,1,1,1,1,1,1,1
1,1,1,1,1,1,1,1,1,1,1,1,1,1,1,1,1,1,1
1,1,1,1,1,1,1,1,1,1,1,1,1,1,1,1,1,1,1
1,1,1,1,1,1,1,1,1,1,1,1,1,1,1,1,1,1,1
endlayer

layer
1,1,1,1,1,1,1,1,1,1,1,1,1,1,1,1,1,1,1
1,1,1,1,1,1,1,1,1,1,1,1,1,1,1,1,1,1,1
1,1,1,1,1,1,1,1,1,1,1,1,1,1,1,1,1,1,1
1,1,1,1,1,1,1,1,1,1,1,1,1,1,1,1,1,1,1
1,1,1,1,1,1,1,1,1,1,1,1,1,1,1,1,1,1,1
1,1,1,1,1,1,1,1,1,1,1,1,1,1,1,1,1,1,1
1,1,1,1,1,1,1,3,3,3,3,3,1,1,1,1,1,1,1
1,1,1,1,1,1,3,3,3,3,3,3,3,1,1,1,1,1,1
1,1,1,1,1,1,3,3,3,3,3,3,3,1,1,1,1,1,1
1,1,1,1,1,1,3,3,3,3,3,3,3,5,1,1,1,1,1
1,1,1,1,1,1,3,3,3,3,3,3,3,1,1,1,1,1,1
1,1,1,1,1,1,3,3,3,3,3,3,3,1,1,1,1,1,1
1,1,1,1,1,1,1,3,3,3,3,3,1,1,1,1,1,1,1
1,1,1,1,1,1,1,1,1,1,1,1,1,1,1,1,1,1,1
1,1,1,1,1,1,1,1,1,1,1,1,1,1,1,1,1,1,1
1,1,1,1,1,1,1,1,1,1,1,1,1,1,1,1,1,1,1
1,1,1,1,1,1,1,1,1,1,1,1,1,1,1,1,1,1,1
1,1,1,1,1,1,1,1,1,1,1,1,1,1,1,1,1,1,1
1,1,1,1,1,1,1,1,1,1,1,1,1,1,1,1,1,1,1
endlayer

layer
1,1,1,1,1,1,1,1,1,1,1,1,1,1,1,1,1,1,1
1,1,1,1,1,1,1,1,1,1,1,1,1,1,1,1,1,1,1
1,1,1,1,1,1,1,1,1,1,1,1,1,1,1,1,1,1,1
1,1,1,1,1,1,1,1,1,1,1,1,1,1,1,1,1,1,1
1,1,1,1,1,1,1,1,1,1,1,1,1,1,1,1,1,1,1
1,1,1,1,1,1,1,1,1,1,1,1,1,1,1,1,1,1,1
1,1,1,1,1,1,1,3,3,3,3,3,1,1,1,1,1,1,1
1,1,1,1,1,1,3,3,3,3,3,3,3,1,1,1,1,1,1
1,1,1,1,1,1,3,3,3,3,3,3,3,1,1,1,1,1,1
1,1,1,1,1,1,3,3,3,3,3,3,3,5,1,1,1,1,1
1,1,1,1,1,1,3,3,3,3,3,3,3,1,1,1,1,1,1
1,1,1,1,1,1,3,3,3,3,3,3,3,1,1,1,1,1,1
1,1,1,1,1,1,1,3,3,3,3,3,1,1,1,1,1,1,1
1,1,1,1,1,1,1,1,1,1,1,1,1,1,1,1,1,1,1
1,1,1,1,1,1,1,1,1,1,1,1,1,1,1,1,1,1,1
1,1,1,1,1,1,1,1,1,1,1,1,1,1,1,1,1,1,1
1,1,1,1,1,1,1,1,1,1,1,1,1,1,1,1,1,1,1
1,1,1,1,1,1,1,1,1,1,1,1,1,1,1,1,1,1,1
1,1,1,1,1,1,1,1,1,1,1,1,1,1,1,1,1,1,1
endlayer

layer
1,1,1,1,1,1,1,1,1,1,1,1,1,1,1,1,1,1,1
1,1,1,1,1,1,1,1,1,1,1,1,1,1,1,1,1,1,1
1,1,1,1,1,1,1,1,1,1,1,1,1,1,1,1,1,1,1
1,1,1,1,1,1,1,1,1,1,1,1,1,1,1,1,1,1,1
1,1,1,1,1,1,1,1,1,1,1,1,1,1,1,1,1,1,1
1,1,1,1,1,1,1,1,1,1,1,1,1,1,1,1,1,1,1
1,1,1,1,1,1,1,3,3,3,3,3,1,1,1,1,1,1,1
1,1,1,1,1,1,3,3,3,3,3,3,3,1,1,1,1,1,1
1,1,1,1,1,1,3,3,3,3,3,3,3,1,1,1,1,1,1
1,1,1,1,1,1,3,3,3,3,3,3,3,5,1,1,1,1,1
1,1,1,1,1,1,3,3,3,3,3,3,3,1,1,1,1,1,1
1,1,1,1,1,1,3,3,3,3,3,3,3,1,1,1,1,1,1
1,1,1,1,1,1,1,3,3,3,3,3,1,1,1,1,1,1,1
1,1,1,1,1,1,1,1,1,1,1,1,1,1,1,1,1,1,1
1,1,1,1,1,1,1,1,1,1,1,1,1,1,1,1,1,1,1
1,1,1,1,1,1,1,1,1,1,1,1,1,1,1,1,1,1,1
1,1,1,1,1,1,1,1,1,1,1,1,1,1,1,1,1,1,1
1,1,1,1,1,1,1,1,1,1,1,1,1,1,1,1,1,1,1
1,1,1,1,1,1,1,1,1,1,1,1,1,1,1,1,1,1,1
endlayer

layer
1,1,1,1,1,1,1,1,1,1,1,1,1,1,1,1,1,1,1
1,1,1,1,1,1,1,1,1,1,1,1,1,1,1,1,1,1,1
1,1,1,1,1,1,1,1,1,1,1,1,1,1,1,1,1,1,1
1,1,1,1,1,1,1,1,1,1,1,1,1,1,1,1,1,1,1
1,1,1,1,1,1,1,1,1,1,1,1,1,1,1,1,1,1,1
1,1,1,1,1,1,1,1,1,1,1,1,1,1,1,1,1,1,1
1,1,1,1,1,1,1,1,3,3,3,1,1,1,1,1,1,1,1
1,1,1,1,1,1,1,3,3,3,3,3,1,1,1,1,1,1,1
1,1,1,1,1,1,3,3,3,3,3,3,3,1,1,1,1,1,1
1,1,1,1,1,1,3,3,3,3,3,3,3,5,1,1,1,1,1
1,1,1,1,1,1,3,3,3,3,3,3,3,1,1,1,1,1,1
1,1,1,1,1,1,1,3,3,3,3,3,1,1,1,1,1,1,1
1,1,1,1,1,1,1,1,3,3,3,1,1,1,1,1,1,1,1
1,1,1,1,1,1,1,1,1,1,1,1,1,1,1,1,1,1,1
1,1,1,1,1,1,1,1,1,1,1,1,1,1,1,1,1,1,1
1,1,1,1,1,1,1,1,1,1,1,1,1,1,1,1,1,1,1
1,1,1,1,1,1,1,1,1,1,1,1,1,1,1,1,1,1,1
1,1,1,1,1,1,1,1,1,1,1,1,1,1,1,1,1,1,1
1,1,1,1,1,1,1,1,1,1,1,1,1,1,1,1,1,1,1
endlayer

layer
1,1,1,1,1,1,1,1,1,1,1,1,1,1,1,1,1,1,1
1,1,1,1,1,1,1,1,1,1,1,1,1,1,1,1,1,1,1
1,1,1,1,1,1,1,1,1,1,1,1,1,1,1,1,1,1,1
1,1,1,1,1,1,1,1,1,1,1,1,1,1,1,1,1,1,1
1,1,1,1,1,1,1,1,1,1,1,1,1,1,1,1,1,1,1
1,1,1,1,1,1,1,1,1,1,1,1,1,1,1,1,1,1,1
1,1,1,1,1,1,1,1,3,3,3,1,1,1,1,1,1,1,1
1,1,1,1,1,1,1,3,3,3,3,3,1,1,1,1,1,1,1
1,1,1,1,1,1,3,3,3,3,3,3,3,1,1,1,1,1,1
1,1,1,1,1,1,3,3,3,3,3,3,3,5,1,1,1,1,1
1,1,1,1,1,1,3,3,3,3,3,3,3,1,1,1,1,1,1
1,1,1,1,1,1,1,3,3,3,3,3,1,1,1,1,1,1,1
1,1,1,1,1,1,1,1,3,3,3,1,1,1,1,1,1,1,1
1,1,1,1,1,1,1,1,1,1,1,1,1,1,1,1,1,1,1
1,1,1,1,1,1,1,1,1,1,1,1,1,1,1,1,1,1,1
1,1,1,1,1,1,1,1,1,1,1,1,1,1,1,1,1,1,1
1,1,1,1,1,1,1,1,1,1,1,1,1,1,1,1,1,1,1
1,1,1,1,1,1,1,1,1,1,1,1,1,1,1,1,1,1,1
1,1,1,1,1,1,1,1,1,1,1,1,1,1,1,1,1,1,1
endlayer

layer
1,1,1,1,1,1,1,1,1,1,1,1,1,1,1,1,1,1,1
1,1,1,1,1,1,1,1,1,1,1,1,1,1,1,1,1,1,1
1,1,1,1,1,1,1,1,1,1,1,1,1,1,1,1,1,1,1
1,1,1,1,1,1,1,1,1,1,1,1,1,1,1,1,1,1,1
1,1,1,1,1,1,1,1,1,1,1,1,1,1,1,1,1,1,1
1,1,1,1,1,1,1,1,1,6,1,1,1,1,1,1,1,1,1
1,1,1,1,1,1,1,1,3,3,3,1,1,1,1,1,1,1,1
1,1,1,1,1,1,1,3,3,3,3,3,1,1,1,1,1,1,1
1,1,1,1,1,1,3,3,3,3,3,3,3,1,1,1,1,1,1
1,1,1,1,1,6,3,3,3,3,3,3,3,5,1,1,1,1,1
1,1,1,1,1,1,3,3,3,3,3,3,3,1,1,1,1,1,1
1,1,1,1,1,1,1,3,3,3,3,3,1,1,1,1,1,1,1
1,1,1,1,1,1,1,1,3,3,3,1,1,1,1,1,1,1,1
1,1,1,1,1,1,1,1,1,6,1,1,1,1,1,1,1,1,1
1,1,1,1,1,1,1,1,1,1,1,1,1,1,1,1,1,1,1
1,1,1,1,1,1,1,1,1,1,1,1,1,1,1,1,1,1,1
1,1,1,1,1,1,1,1,1,1,1,1,1,1,1,1,1,1,1
1,1,1,1,1,1,1,1,1,1,1,1,1,1,1,1,1,1,1
1,1,1,1,1,1,1,1,1,1,1,1,1,1,1,1,1,1,1
endlayer

layer
1,1,1,1,1,1,1,1,1,1,1,1,1,1,1,1,1,1,1
1,1,1,1,1,1,1,1,1,1,1,1,1,1,1,1,1,1,1
1,1,1,1,1,1,1,1,1,1,1,1,1,1,1,1,1,1,1
1,1,1,1,1,1,1,1,1,1,1,1,1,1,1,1,1,1,1
1,1,1,1,1,1,1,1,1,1,1,1,1,1,1,1,1,1,1
1,1,1,1,1,1,1,1,1,6,1,1,1,1,1,1,1,1,1
1,1,1,1,1,1,1,1,6,3,6,1,1,1,1,1,1,1,1
1,1,1,1,1,1,1,6,3,3,3,6,1,1,1,1,1,1,1
1,1,1,1,1,1,6,3,3,3,3,3,6,1,1,1,1,1,1
1,1,1,1,1,6,3,3,3,3,3,3,3,5,1,1,1,1,1
1,1,1,1,1,1,6,3,3,3,3,3,6,1,1,1,1,1,1
1,1,1,1,1,1,1,6,3,3,3,6,1,1,1,1,1,1,1
1,1,1,1,1,1,1,1,6,3,6,1,1,1,1,1,1,1,1
1,1,1,1,1,1,1,1,1,6,1,1,1,1,1,1,1,1,1
1,1,1,1,1,1,1,1,1,1,1,1,1,1,1,1,1,1,1
1,1,1,1,1,1,1,1,1,1,1,1,1,1,1,1,1,1,1
1,1,1,1,1,1,1,1,1,1,1,1,1,1,1,1,1,1,1
1,1,1,1,1,1,1,1,1,1,1,1,1,1,1,1,1,1,1
1,1,1,1,1,1,1,1,1,1,1,1,1,1,1,1,1,1,1
endlayer

layer
1,1,1,1,1,1,1,1,1,1,1,1,1,1,1,1,1,1,1
1,1,1,1,1,1,1,1,1,1,1,1,1,1,1,1,1,1,1
1,1,1,1,1,1,1,1,1,1,1,1,1,1,1,1,1,1,1
1,1,1,1,1,1,1,1,1,1,1,1,1,1,1,1,1,1,1
1,1,1,1,1,1,1,7,7,7,7,7,1,1,1,1,1,1,1
1,1,1,1,1,1,7,7,8,8,8,7,7,1,1,1,1,1,1
1,1,1,1,1,7,7,8,8,3,8,8,7,7,1,1,1,1,1
1,1,1,1,7,7,8,8,3,3,3,8,8,7,7,1,1,1,1
1,1,1,1,7,8,8,3,3,3,3,3,8,8,7,1,1,1,1
1,1,1,1,7,8,3,3,3,3,3,3,3,9,7,1,1,1,1
1,1,1,1,7,8,8,3,3,3,3,3,8,8,7,1,1,1,1
1,1,1,1,7,7,8,8,3,3,3,8,8,7,7,1,1,1,1
1,1,1,1,1,7,7,8,8,3,8,8,7,7,1,1,1,1,1
1,1,1,1,1,1,7,7,8,8,8,7,7,1,1,1,1,1,1
1,1,1,1,1,1,1,7,7,7,7,7,1,1,1,1,1,1,1
1,1,1,1,1,1,1,1,1,1,1,1,1,1,1,1,1,1,1
1,1,1,1,1,1,1,1,1,1,1,1,1,1,1,1,1,1,1
1,1,1,1,1,1,1,1,1,1,1,1,1,1,1,1,1,1,1
1,1,1,1,1,1,1,1,1,1,1,1,1,1,1,1,1,1,1
endlayer


layer
0,0,0,0,0,0,0,0,0,0,0,0,0,0,0,0,0,0,0
0,0,0,0,0,0,0,0,0,0,0,0,0,0,0,0,0,0,0
0,0,0,0,0,0,0,0,0,0,0,0,0,0,0,0,0,0,0
0,0,0,0,0,0,0,0,0,0,0,0,0,0,0,0,0,0,0
0,0,0,0,0,0,0,6,6,6,6,6,0,0,0,0,0,0,0
0,0,0,0,0,0,6,6,0,0,0,6,6,0,0,0,0,0,0
0,0,0,0,0,6,6,0,0,0,0,0,6,6,0,0,0,0,0
0,0,0,0,6,6,0,0,3,3,3,0,0,6,6,0,0,0,0
0,0,0,0,6,0,0,3,3,3,3,3,0,0,6,0,0,0,0
0,0,0,0,6,0,0,3,3,3,3,3,5,0,6,0,0,0,0
0,0,0,0,6,0,0,3,3,3,3,3,0,0,6,0,0,0,0
0,0,0,0,6,6,0,0,3,3,3,0,0,6,6,0,0,0,0
0,0,0,0,0,6,6,0,0,0,0,0,6,6,0,0,0,0,0
0,0,0,0,0,0,6,6,0,0,0,6,6,0,0,0,0,0,0
0,0,0,0,0,0,0,6,6,6,6,6,0,0,0,0,0,0,0
0,0,0,0,0,0,0,0,0,0,0,0,0,0,0,0,0,0,0
0,0,0,0,0,0,0,0,0,0,0,0,0,0,0,0,0,0,0
0,0,0,0,0,0,0,0,0,0,0,0,0,0,0,0,0,0,0
0,0,0,0,0,0,0,0,0,0,0,0,0,0,0,0,0,0,0
endlayer

layer
0,0,0,0,0,0,0,0,0,0,0,0,0,0,0,0,0,0,0
0,0,0,0,0,0,0,0,0,0,0,0,0,0,0,0,0,0,0
0,0,0,0,0,0,0,0,0,0,0,0,0,0,0,0,0,0,0
0,0,0,0,0,0,0,0,0,0,0,0,0,0,0,0,0,0,0
0,0,0,0,0,0,0,6,0,0,0,6,0,0,0,0,0,0,0
0,0,0,0,0,0,0,0,0,0,0,0,0,0,0,0,0,0,0
0,0,0,0,0,0,0,0,0,0,0,0,0,0,0,0,0,0,0
0,0,0,0,6,0,0,0,0,3,0,0,0,0,6,0,0,0,0
0,0,0,0,0,0,0,0,3,3,3,0,0,0,0,0,0,0,0
0,0,0,0,0,0,0,3,3,3,3,3,5,0,0,0,0,0,0
0,0,0,0,0,0,0,0,3,3,3,0,0,0,0,0,0,0,0
0,0,0,0,6,0,0,0,0,3,0,0,0,0,6,0,0,0,0
0,0,0,0,0,0,0,0,0,0,0,0,0,0,0,0,0,0,0
0,0,0,0,0,0,0,0,0,0,0,0,0,0,0,0,0,0,0
0,0,0,0,0,0,0,6,0,0,0,6,0,0,0,0,0,0,0
0,0,0,0,0,0,0,0,0,0,0,0,0,0,0,0,0,0,0
0,0,0,0,0,0,0,0,0,0,0,0,0,0,0,0,0,0,0
0,0,0,0,0,0,0,0,0,0,0,0,0,0,0,0,0,0,0
0,0,0,0,0,0,0,0,0,0,0,0,0,0,0,0,0,0,0
endlayer

layer
0,0,0,0,0,0,0,0,0,0,0,0,0,0,0,0,0,0,0
0,0,0,0,0,0,0,0,0,0,0,0,0,0,0,0,0,0,0
0,0,0,0,0,0,0,0,0,0,0,0,0,0,0,0,0,0,0
0,0,0,0,0,0,0,0,0,0,0,0,0,0,0,0,0,0,0
0,0,0,0,0,0,0,6,0,0,0,6,0,0,0,0,0,0,0
0,0,0,0,0,0,0,0,0,0,0,0,0,0,0,0,0,0,0
0,0,0,0,0,0,0,0,0,0,0,0,0,0,0,0,0,0,0
0,0,0,0,6,0,0,0,0,3,0,0,0,0,6,0,0,0,0
0,0,0,0,0,0,0,0,3,3,3,0,0,0,0,0,0,0,0
0,0,0,0,0,0,3,3,3,3,3,7,5,0,0,0,0,0,0
0,0,0,0,0,0,0,0,3,3,3,0,0,0,0,0,0,0,0
0,0,0,0,6,0,0,0,0,0,0,0,0,0,6,0,0,0,0
0,0,0,0,0,0,0,0,0,0,0,0,0,0,0,0,0,0,0
0,0,0,0,0,0,0,0,0,0,0,0,0,0,0,0,0,0,0
0,0,0,0,0,0,0,6,0,0,0,6,0,0,0,0,0,0,0
0,0,0,0,0,0,0,0,0,0,0,0,0,0,0,0,0,0,0
0,0,0,0,0,0,0,0,0,0,0,0,0,0,0,0,0,0,0
0,0,0,0,0,0,0,0,0,0,0,0,0,0,0,0,0,0,0
0,0,0,0,0,0,0,0,0,0,0,0,0,0,0,0,0,0,0
endlayer

layer
0,0,0,0,0,0,0,0,0,0,0,0,0,0,0,0,0,0,0
0,0,0,0,0,0,0,0,0,0,0,0,0,0,0,0,0,0,0
0,0,0,0,0,0,3,0,0,0,0,3,0,0,0,0,0,0,0
0,0,0,0,0,0,0,3,0,0,3,0,0,0,0,0,0,0,0
0,0,0,0,0,0,0,8,3,0,3,8,0,0,0,0,0,0,0
0,0,0,0,0,0,8,8,3,3,7,8,8,0,0,3,0,0,0
0,0,0,0,0,8,8,7,7,3,7,7,8,3,3,0,0,0,0
0,0,3,0,8,8,7,7,7,3,7,7,3,3,8,0,0,0,0
0,0,0,3,3,3,7,7,7,7,3,3,3,7,8,0,0,0,0
0,0,0,0,8,3,3,7,7,3,0,7,10,3,3,3,3,0,0
0,0,0,0,8,7,7,7,3,7,3,3,7,7,8,0,0,0,0
0,0,0,0,8,8,7,3,3,7,3,3,3,8,8,0,0,0,0
0,0,0,0,3,3,3,3,7,7,3,7,3,3,0,0,0,0,0
0,0,0,3,0,0,3,8,7,3,7,8,8,0,3,0,0,0,0
0,0,0,0,0,0,3,8,8,3,8,8,0,0,0,3,0,0,0
0,0,0,0,0,3,0,0,0,3,0,0,0,0,0,0,0,0,0
0,0,0,0,0,0,0,0,0,3,0,0,0,0,0,0,0,0,0
0,0,0,0,0,0,0,0,0,0,0,0,0,0,0,0,0,0,0
0,0,0,0,0,0,0,0,0,0,0,0,0,0,0,0,0,0,0
endlayer

layer
0,0,0,0,0,0,11,0,0,0,0,0,0,0,0,0,0,0,0
0,0,0,0,0,11,11,11,0,0,11,11,11,0,0,0,0,0,0
0,0,0,0,11,11,11,11,11,0,11,11,11,0,0,0,0,0,0
0,0,0,0,0,11,11,11,3,0,11,11,11,0,0,11,0,0,0
0,0,0,0,0,0,11,0,3,0,0,0,0,0,11,11,11,0,0
0,0,11,0,0,0,0,0,0,0,0,0,0,11,11,11,11,11,0
0,11,11,11,0,0,0,0,0,0,0,0,0,3,11,11,11,0,0
11,11,11,11,11,0,0,0,0,0,0,0,0,0,0,11,11,0,0
0,11,11,11,3,0,0,0,3,0,0,0,0,0,0,11,11,11,0
0,0,11,0,0,0,0,0,0,3,3,0,0,0,11,11,11,11,11
0,0,0,0,0,0,0,0,0,0,0,0,0,0,0,11,11,11,0
0,0,0,0,0,0,0,0,0,0,0,0,0,0,0,0,11,0,0
0,0,11,11,11,0,0,0,0,0,0,0,0,3,0,0,0,0,0
0,0,11,11,11,0,3,0,0,0,0,0,0,0,11,11,11,0,0
0,0,11,11,11,11,11,0,0,11,0,0,0,0,11,11,11,0,0
0,0,0,11,11,11,11,0,11,11,11,0,0,0,11,11,11,0,0
0,0,0,0,11,11,11,11,11,11,11,11,0,0,0,0,0,0,0
0,0,0,0,0,0,0,0,11,11,11,0,0,0,0,0,0,0,0
0,0,0,0,0,0,0,0,0,11,0,0,0,0,0,0,0,0,0
endlayer

layer
0,0,0,0,0,0,0,0,0,0,0,0,0,0,0,0,0,0,0
0,0,0,0,0,0,0,0,11,0,0,0,0,0,0,0,0,0,0
0,0,0,0,0,0,0,11,11,11,0,0,0,0,0,0,0,0,0
0,0,0,0,0,0,11,11,11,11,11,0,0,0,0,0,0,0,0
0,0,0,0,0,0,0,11,11,11,0,0,0,11,0,0,0,0,0
0,0,0,0,0,0,0,0,11,0,0,0,11,11,11,0,0,0,0
0,0,0,0,11,0,0,0,0,0,0,11,11,11,11,11,0,0,0
0,0,0,11,11,11,0,0,0,0,0,0,11,11,11,0,0,0,0
0,0,11,11,11,11,11,0,3,0,0,0,0,11,0,0,0,0,0
0,0,0,11,11,11,0,0,0,0,3,0,0,0,0,0,0,0,0
0,0,0,0,11,0,0,0,3,0,0,0,0,11,0,0,0,0,0
0,0,0,0,0,0,11,0,0,0,0,0,11,11,11,0,0,0,0
0,0,0,0,0,11,11,11,0,0,0,11,11,11,11,11,0,0,0
0,0,0,0,11,11,11,11,11,0,0,0,11,11,11,0,0,0,0
0,0,0,0,0,11,11,11,0,0,0,0,0,11,0,0,0,0,0
0,0,0,0,0,0,11,0,0,0,0,0,0,0,0,0,0,0,0
0,0,0,0,0,0,0,0,0,0,0,0,0,0,0,0,0,0,0
0,0,0,0,0,0,0,0,0,0,0,0,0,0,0,0,0,0,0
0,0,0,0,0,0,0,0,0,0,0,0,0,0,0,0,0,0,0
endlayer

layer
0,0,0,0,0,0,0,0,0,0,0,0,0,0,0,0,0,0,0
0,0,0,0,0,0,0,0,0,0,0,0,0,0,0,0,0,0,0
0,0,0,0,0,0,0,0,0,0,0,0,0,0,0,0,0,0,0
0,0,0,0,0,0,0,0,0,0,0,0,0,0,0,0,0,0,0
0,0,0,0,0,0,0,0,0,0,0,0,0,0,0,0,0,0,0
0,0,0,0,0,0,0,0,0,0,0,0,0,0,0,0,0,0,0
0,0,0,0,0,0,0,0,0,0,0,0,0,0,0,0,0,0,0
0,0,0,0,0,0,0,11,11,11,11,0,0,0,0,0,0,0,0
0,0,0,0,0,0,0,11,11,11,11,11,11,0,0,0,0,0,0
0,0,0,0,0,0,0,11,11,11,11,11,11,0,0,0,0,0,0
0,0,0,0,0,0,0,11,11,11,11,11,11,0,0,0,0,0,0
0,0,0,0,0,0,0,11,11,11,11,11,0,0,0,0,0,0,0
0,0,0,0,0,0,0,0,11,11,11,0,0,0,0,0,0,0,0
0,0,0,0,0,0,0,0,0,0,0,0,0,0,0,0,0,0,0
0,0,0,0,0,0,0,0,0,0,0,0,0,0,0,0,0,0,0
0,0,0,0,0,0,0,0,0,0,0,0,0,0,0,0,0,0,0
0,0,0,0,0,0,0,0,0,0,0,0,0,0,0,0,0,0,0
0,0,0,0,0,0,0,0,0,0,0,0,0,0,0,0,0,0,0
0,0,0,0,0,0,0,0,0,0,0,0,0,0,0,0,0,0,0
endlayer

