# Buried Pyramid; 12 Oct 2014
# Created by Ruins mod version 13.8 Ingame Parser
# authoring Player: Jordan_Greywolf
# Verified for MC 1.11: 10 Jan 2017
# Verified for MC 1.12: 23 Jun 2017
# Updated to MC 1.12.1: 9 Sep 2017
# Note: Scenery version (no treasure, no traps, no monsters)

biomesToSpawnIn=desert,deserthills,desert m,lush desert,lush_desert,oasis,dunes,desert oil field,rwg_hotdesert,desert_hills,mutated_desert

weight=1
embed_into_distance=6
acceptable_target_blocks=

unacceptable_target_blocks=flowing_water,water,flowing_lava,lava,cloud,Natura:Cloud,slime_congealed,slime_dirt,slime_grass,command_block,planks,planks2,concrete,cobblestone,stonebrick,brick_block,glass,torch,oak_stairs,stone_stairs,brick_stairs,stone_brick_stairs,nether_brick_stairs,sandstone_stairs,spruce_stairs,birch_stairs,jungle_stairs,quartz_stairs,acacia_stairs,dark_oak_stairs,cobblestone_wall,stone_slab,double_stone_slab,stone_slab2,wooden_slab,double_wooden_slab,nether_brick

dimensions=7,11,11
allowable_overhang=0
max_leveling=3
leveling_buffer=-1
preserve_water=0
preserve_lava=0
preserve_plants=1

rule1=0,100,minecraft:sandstone-0
rule2=0,100,minecraft:stained_hardened_clay-1
rule3=0,100,minecraft:stained_hardened_clay-11
rule4=0,100,minecraft:sandstone-1
rule5=0,100,minecraft:skull
rule6=0,100,preserveBlock
rule7=0,100,minecraft:sandstone_stairs-5
rule8=0,100,minecraft:sandstone_stairs-7
rule9=0,100,minecraft:sandstone_stairs-6
rule10=0,100,minecraft:sandstone_stairs-4

layer
1,1,1,1,1,1,1,1,1,1,1
1,1,1,1,1,1,1,1,1,1,1
1,1,1,1,1,1,1,1,1,1,1
1,1,1,2,3,2,3,2,1,1,1
1,1,1,3,1,1,1,3,1,1,1
1,1,1,2,1,3,1,2,1,1,1
1,1,1,3,1,1,1,3,1,1,1
1,1,1,2,3,2,3,2,1,1,1
1,1,1,1,1,1,1,1,1,1,1
1,1,1,1,1,1,1,1,1,1,1
1,1,1,1,1,1,1,1,1,1,1
endlayer

layer
1,1,1,1,1,1,1,1,1,1,1
1,1,1,1,1,1,1,1,1,1,1
1,1,4,0,0,0,0,0,4,1,1
1,1,0,0,5,0,0,0,0,1,1
1,1,0,0,0,0,0,0,0,1,1
1,1,0,0,0,0,0,0,0,1,1
1,1,0,0,0,0,5,0,0,1,1
1,1,0,0,0,0,0,0,0,1,1
1,1,4,0,0,0,0,0,4,1,1
1,1,1,1,1,1,1,1,1,1,1
1,1,1,1,1,1,1,1,1,1,1
endlayer

layer
6,6,6,6,6,6,6,6,6,6,6
6,1,1,1,1,1,1,1,1,1,6
6,1,1,7,7,7,7,7,1,1,6
6,1,9,0,0,0,0,0,8,1,6
6,1,9,0,0,0,0,0,8,1,6
6,1,9,0,0,0,0,0,8,1,6
6,1,9,0,0,0,0,0,8,1,6
6,1,9,0,0,0,0,0,8,1,6
6,1,1,10,10,10,10,10,1,1,6
6,1,1,1,1,1,1,1,1,1,6
6,6,6,6,6,6,6,6,6,6,6
endlayer

layer
6,6,6,6,6,6,6,6,6,6,6
6,6,6,6,6,6,6,6,6,6,6
6,6,1,1,1,1,1,1,1,6,6
6,6,1,9,7,7,7,7,1,6,6
6,6,1,9,0,0,0,8,1,6,6
6,6,1,9,0,0,0,8,1,6,6
6,6,1,9,0,0,0,8,1,6,6
6,6,1,10,10,10,10,8,1,6,6
6,6,1,1,1,1,1,1,1,6,6
6,6,6,6,6,6,6,6,6,6,6
6,6,6,6,6,6,6,6,6,6,6
endlayer

layer
6,6,6,6,6,6,6,6,6,6,6
6,6,6,6,6,6,6,6,6,6,6
6,6,6,6,6,6,6,6,6,6,6
6,6,6,1,1,1,1,1,6,6,6
6,6,6,1,7,7,8,1,6,6,6
6,6,6,1,9,0,8,1,6,6,6
6,6,6,1,9,10,10,1,6,6,6
6,6,6,1,1,1,1,1,6,6,6
6,6,6,6,6,6,6,6,6,6,6
6,6,6,6,6,6,6,6,6,6,6
6,6,6,6,6,6,6,6,6,6,6
endlayer

layer
6,6,6,6,6,6,6,6,6,6,6
6,6,6,6,6,6,6,6,6,6,6
6,6,6,6,6,6,6,6,6,6,6
6,6,6,6,6,6,6,6,6,6,6
6,6,6,6,1,1,1,6,6,6,6
6,6,6,6,1,1,1,6,6,6,6
6,6,6,6,1,1,1,6,6,6,6
6,6,6,6,6,6,6,6,6,6,6
6,6,6,6,6,6,6,6,6,6,6
6,6,6,6,6,6,6,6,6,6,6
6,6,6,6,6,6,6,6,6,6,6
endlayer

layer
6,6,6,6,6,6,6,6,6,6,6
6,6,6,6,6,6,6,6,6,6,6
6,6,6,6,6,6,6,6,6,6,6
6,6,6,6,6,6,6,6,6,6,6
6,6,6,6,6,6,6,6,6,6,6
6,6,6,6,6,1,6,6,6,6,6
6,6,6,6,6,6,6,6,6,6,6
6,6,6,6,6,6,6,6,6,6,6
6,6,6,6,6,6,6,6,6,6,6
6,6,6,6,6,6,6,6,6,6,6
6,6,6,6,6,6,6,6,6,6,6
endlayer

