# DesertFirePitHut_1v7v10 (ruined)
# 13 Oct 2014
# Created by Ruins mod version 13.8 Ingame Parser
# authoring Player: Jordan_Greywolf
# Verified for MC 1.11: 11 Jan 2017
# Verified for MC 1.12: 23 Jun 2017
# Updated to MC 1.12.1: 9 Sep 2017

biomesToSpawnIn=desert,deserthills,desert m,lush desert,lush_desert,oasis,dunes,desert oil field,rwg_hotdesert,rwg_oasis,desert_hills,mutated_desert

weight=1
embed_into_distance=1
acceptable_target_blocks=

unacceptable_target_blocks=flowing_water,water,flowing_lava,lava,cloud,Natura:Cloud,slime_congealed,slime_dirt,slime_grass,command_block,planks,planks2,concrete,cobblestone,stonebrick,brick_block,glass,torch,oak_stairs,stone_stairs,brick_stairs,stone_brick_stairs,nether_brick_stairs,sandstone_stairs,spruce_stairs,birch_stairs,jungle_stairs,quartz_stairs,acacia_stairs,dark_oak_stairs,cobblestone_wall,stone_slab,double_stone_slab,stone_slab2,wooden_slab,double_wooden_slab,nether_brick

dimensions=8,9,9
allowable_overhang=0
max_leveling=2
leveling_buffer=-1
preserve_water=0
preserve_lava=0

rule1=1,100,minecraft:sandstone-0
rule2=1,100,minecraft:netherrack-0
rule3=1,90,minecraft:sand-0
rule4=2,90,minecraft:sandstone_stairs-2
rule5=2,90,minecraft:sandstone_stairs-0
rule6=2,90,minecraft:sandstone_stairs-3
rule7=1,100,minecraft:stained_hardened_clay-0
rule8=1,100,minecraft:stained_hardened_clay-11
rule9=2,90,minecraft:sandstone_stairs-1
rule10=1,50,minecraft:fire-15
rule11=1,90,minecraft:sandstone-2
rule12=1,90,minecraft:sandstone-1
rule13=2,90,minecraft:stained_hardened_clay-1
rule14=2,90,minecraft:stained_hardened_clay-4
rule15=2,90,minecraft:stone_slab-9

layer
1,1,1,1,1,1,1,1,1
1,1,1,1,1,1,1,1,1
1,1,1,1,1,1,1,1,1
1,1,1,1,1,1,1,1,1
1,1,1,1,2,1,1,1,1
1,1,1,1,1,1,1,1,1
1,1,1,1,1,1,1,1,1
1,1,1,1,1,1,1,1,1
1,1,1,1,1,1,1,1,1
endlayer

layer
3,3,0,6,5,4,0,3,3
3,1,1,1,1,1,1,1,3
3,1,7,8,7,8,7,1,3
0,1,8,9,9,6,8,1,0
0,1,7,4,10,6,7,1,0
0,1,8,4,5,5,8,1,0
0,1,7,8,7,8,7,1,0
3,1,1,1,1,1,1,1,3
3,3,3,0,0,0,0,3,3
endlayer

layer
3,0,0,0,0,0,0,0,3
3,11,12,11,0,11,12,11,3
0,12,0,0,0,0,0,12,0
0,11,0,0,0,0,0,11,0
0,12,0,0,0,0,0,12,0
0,11,0,0,0,0,0,11,0
0,12,0,0,0,0,0,12,0
0,11,12,11,12,11,12,11,0
3,0,0,0,0,0,0,0,3
endlayer

layer
0,0,0,0,0,0,0,0,0
0,11,0,11,0,11,0,11,0
0,0,0,0,0,0,0,0,0
0,11,0,0,0,0,0,11,0
0,0,0,0,0,0,0,0,0
0,11,0,0,0,0,0,11,0
0,0,0,0,0,0,0,0,0
0,11,0,11,0,11,0,11,0
0,0,0,0,0,0,0,0,0
endlayer

layer
0,0,0,0,0,0,0,0,0
0,11,0,11,0,11,0,11,0
0,0,0,0,0,0,0,0,0
0,11,0,0,0,0,0,11,0
0,0,0,0,0,0,0,0,0
0,11,0,0,0,0,0,11,0
0,0,0,0,0,0,0,0,0
0,11,0,11,0,11,0,11,0
0,0,0,0,0,0,0,0,0
endlayer

layer
0,0,0,0,0,0,0,0,0
0,11,13,11,13,11,13,11,0
0,13,0,0,0,0,0,13,0
0,11,0,0,0,0,0,11,0
0,13,0,0,0,0,0,13,0
0,11,0,0,0,0,0,11,0
0,13,0,0,0,0,0,13,0
0,11,13,11,13,11,13,11,0
0,0,0,0,0,0,0,0,0
endlayer

layer
6,5,5,5,5,5,5,5,4
6,1,1,1,1,1,1,1,4
6,1,14,14,14,14,14,1,4
6,1,14,15,15,15,14,1,4
6,1,14,15,0,15,14,1,4
6,1,14,15,15,15,14,1,4
6,1,14,14,14,14,14,1,4
6,1,1,1,1,1,1,1,4
9,9,9,9,9,9,9,9,4
endlayer

layer
0,0,0,0,0,0,0,0,0
0,6,5,5,5,5,5,5,0
0,6,1,1,1,1,1,4,0
0,6,1,1,1,1,1,4,0
0,6,1,1,0,1,1,4,0
0,6,1,1,1,1,1,4,0
0,6,1,1,1,1,1,4,0
0,9,9,9,9,9,9,4,0
0,0,0,0,0,0,0,0,0
endlayer

