# DesertTent; 12 Oct 2014
# Created by Ruins mod version 13.8 Ingame Parser
# authoring Player: Jordan_Greywolf
# Last Updated: 14 Nov 2015
# Verified for MC 1.12: 23 Jun 2017
# Updated to MC 1.12.1: 9 Sep 2017

biomesToSpawnIn=desert,deserthills,desert m,lush desert,oasis,dunes,desert oil field,lush desert,lush_desert,rwg_hotdesert,rwg_oasis,desert_hills,mutated_desert

weight=1
embed_into_distance=4
acceptable_target_blocks=

unacceptable_target_blocks=flowing_water,water,flowing_lava,lava,cloud,Natura:Cloud,slime_congealed,slime_dirt,slime_grass,command_block,planks,planks2,concrete,cobblestone,stonebrick,brick_block,glass,torch,oak_stairs,stone_stairs,brick_stairs,stone_brick_stairs,nether_brick_stairs,sandstone_stairs,spruce_stairs,birch_stairs,jungle_stairs,quartz_stairs,acacia_stairs,dark_oak_stairs,cobblestone_wall,stone_slab,double_stone_slab,stone_slab2,wooden_slab,double_wooden_slab,nether_brick

dimensions=9,9,9
allowable_overhang=0
max_leveling=2
leveling_buffer=-1
preserve_water=0
preserve_lava=0
preserve_plants=1

rule1=0,100,preserveBlock
rule2=0,100,minecraft:sandstone-0
rule3=0,100,minecraft:wool-8
rule4=0,100,minecraft:wool-12
rule5=0,100,minecraft:fence-0

layer
2,2,2,2,2,2,2,2,2
2,2,2,2,2,2,2,2,2
2,2,2,2,2,2,2,2,2
2,2,2,2,2,2,2,2,2
2,2,2,2,2,2,2,2,2
2,2,2,2,2,2,2,2,2
2,2,2,2,2,2,2,2,2
2,2,2,2,2,2,2,2,2
2,2,2,2,2,2,2,2,2
endlayer

layer
2,2,2,2,2,2,2,2,2
2,2,2,2,2,2,2,2,2
2,2,2,2,2,2,2,2,2
2,2,2,2,2,2,2,2,2
2,2,2,2,2,2,2,2,2
2,2,2,2,2,2,2,2,2
2,2,2,2,2,2,2,2,2
2,2,2,2,2,2,2,2,2
2,2,2,2,2,2,2,2,2
endlayer

layer
2,2,2,2,2,2,2,2,2
2,2,2,2,2,2,2,2,2
2,2,2,2,2,2,2,2,2
2,2,2,2,2,2,2,2,2
2,2,2,2,2,2,2,2,2
2,2,2,2,2,2,2,2,2
2,2,2,2,2,2,2,2,2
2,2,2,2,2,2,2,2,2
2,2,2,2,2,2,2,2,2
endlayer



layer
1,1,1,1,1,1,1,1,1
1,2,2,2,2,2,2,2,1
1,2,2,2,2,2,2,2,1
1,2,2,2,2,2,2,2,1
1,2,2,2,2,2,2,2,1
1,2,2,2,2,2,2,2,1
1,2,2,2,2,2,2,2,1
1,2,2,2,2,2,2,2,1
1,1,1,1,1,1,1,1,1
endlayer

layer
1,1,3,4,0,4,3,1,1
1,4,0,5,0,5,0,4,1
0,4,0,0,0,0,0,4,0
0,4,0,5,0,5,0,4,0
0,4,0,0,0,0,0,4,0
0,4,0,5,0,5,0,4,0
0,4,0,0,0,0,0,4,1
0,4,0,5,0,5,0,4,1
1,0,0,0,0,0,0,1,1
endlayer

layer
0,0,3,4,0,4,3,0,0
0,3,0,5,0,5,0,3,0
0,3,0,0,0,0,0,3,0
0,3,0,5,0,5,0,3,0
0,3,0,0,0,0,0,3,0
0,3,0,5,0,5,0,3,0
0,3,0,0,0,0,0,3,0
0,3,0,5,0,5,0,3,0
0,0,0,0,0,0,0,0,0
endlayer

layer
0,0,0,4,0,4,0,0,0
0,4,3,5,0,5,3,4,0
0,4,0,0,0,0,0,4,0
0,4,0,5,0,5,0,4,0
0,4,0,0,0,0,0,4,0
0,4,0,5,0,5,0,4,0
0,4,0,0,0,0,0,4,0
0,4,0,5,0,5,0,4,0
0,0,3,4,0,4,3,0,0
endlayer

layer
0,0,0,0,0,0,0,0,0
0,0,3,4,3,4,3,0,0
0,3,3,4,3,4,3,3,0
0,3,3,5,3,5,3,3,0
0,0,3,4,3,4,3,0,0
0,3,3,5,3,5,3,3,0
0,3,3,4,3,4,3,3,0
0,0,3,4,3,4,3,0,0
0,0,0,0,3,0,0,0,0
endlayer

layer
0,0,0,0,0,0,0,0,0
0,0,0,0,0,0,0,0,0
0,0,0,4,0,4,0,0,0
0,0,0,4,0,4,0,0,0
0,0,0,0,0,0,0,0,0
0,0,0,4,0,4,0,0,0
0,0,0,4,0,4,0,0,0
0,0,0,0,0,0,0,0,0
0,0,0,0,0,0,0,0,0
endlayer

