# Sandstone Tomb Trap
# Created by Ruins mod version 17.1 Ingame Parser
# authoring Player: Jordan_Greywolf
# Created for MC 1.12: 7 Jun 2018
# Based on the Sticky Piston Trap designed by Turspikey

biomesToSpawnIn=desert,desert m,oasis,rwg_hotdesert,mutated_desert

uniqueMinDistance=1000

preventRotation=1

weight=1
embed_into_distance=4

unacceptable_target_blocks=flowing_water,water,flowing_lava,lava,command_block,cloud,slime_congealed,slime_dirt,slime_grass

dimensions=11,13,13
allowable_overhang=8
max_leveling=5
leveling_buffer=-1
preserve_water=0
preserve_lava=0

rule1=0,100,minecraft:sandstone-2
rule2=0,100,minecraft:sandstone-1
rule3=0,100,minecraft:magma-0
rule4=0,100,minecraft:wool-9
rule5=0,100,minecraft:redstone_wire-0
rule6=0,100,minecraft:unpowered_repeater-2
rule7=0,100,minecraft:web-0
rule8=0,100,minecraft:unpowered_repeater-0
rule9=0,100,minecraft:lapis_block-0
rule10=0,100,minecraft:concrete-11
rule11=1,100,minecraft:redstone_torch-5
rule12=0,100,minecraft:sticky_piston-11
rule13=2,100,minecraft:piston_head-11

rule14=0,100,IInventory;minecraft:trapped_chest;minecraft:gold_ingot#1#0#1+minecraft:skull#1#0#2+minecraft:redstone#1#0#4+minecraft:potato#4#0#5+minecraft:glass#8#0#8+minecraft:glass#8#0#9+minecraft:potato#4#0#10+minecraft:glass#8#0#11+minecraft:gold_ingot#1#0#12+minecraft:rotten_flesh#4#0#13+minecraft:gold_ingot#1#0#15+minecraft:potato#4#0#17+minecraft:rotten_flesh#4#0#19+minecraft:redstone#1#0#20+minecraft:glass#8#0#21+minecraft:gold_ingot#1#0#23+minecraft:skull#1#0#24+minecraft:potato#4#0#25-4

rule15=0,100,ChestGenHook:chests/simple_dungeon:5-4
rule16=0,100,MobSpawner:Skeleton

rule17=0,100,preserveBlock

rule18=0,100,minecraft:concrete-3
rule19=0,100,Skull:0:8-1
rule20=0,100,Skull:0:0-1
rule21=0,100,IInventory;minecraft:dispenser;minecraft:arrow#4#0#1+minecraft:arrow#4#0#2+minecraft:arrow#4#0#3+minecraft:arrow#4#0#7-4

layer
1,1,1,1,1,1,1,1,1,1,1,1,1
1,2,2,2,2,2,2,2,2,2,2,2,1
1,2,2,2,2,2,2,2,2,2,2,2,1
1,2,2,2,2,2,3,2,2,2,2,2,1
1,2,2,2,2,2,3,2,2,2,2,2,1
1,2,2,2,2,2,3,2,2,2,2,2,1
1,2,2,2,2,2,3,2,2,2,2,2,1
1,2,2,2,2,2,3,2,2,2,2,2,1
1,2,2,2,2,2,3,2,2,2,2,2,1
1,2,2,2,2,2,2,2,2,2,2,2,1
1,2,2,2,2,2,2,2,2,2,2,2,1
1,2,2,2,2,2,2,2,2,2,2,2,1
1,1,1,1,1,1,1,1,1,1,1,1,1
endlayer

layer
2,2,2,2,2,2,2,2,2,2,2,2,2
2,2,2,2,2,2,2,2,2,2,2,2,2
2,2,2,2,2,2,2,2,2,2,2,2,2
2,2,2,2,2,2,4,2,2,2,2,2,2
2,2,2,2,2,2,4,2,2,2,2,2,2
2,2,2,2,2,2,4,2,2,2,2,2,2
2,2,2,2,2,2,4,2,2,2,2,2,2
2,2,2,2,2,2,4,2,2,2,2,2,2
2,2,2,2,2,2,4,2,2,2,2,2,2
2,2,2,2,2,2,2,2,2,5,2,2,2
2,2,2,2,2,2,2,2,2,2,2,2,2
2,2,2,2,2,2,2,2,2,2,2,2,2
2,2,2,2,2,2,2,2,2,2,2,2,2
endlayer

layer
1,1,1,1,1,1,1,1,1,1,1,1,1
1,1,1,1,1,1,1,1,1,1,1,1,1
1,1,1,1,1,1,1,1,1,1,1,1,1
1,1,1,1,1,1,7,1,1,1,6,5,1
1,1,1,1,1,1,7,1,1,1,6,5,1
1,1,1,1,1,1,7,1,1,1,6,5,1
1,1,1,1,1,1,7,1,1,1,6,5,1
1,1,1,1,1,1,7,1,1,1,6,5,1
1,1,1,1,1,1,7,1,1,1,6,5,1
1,1,1,1,1,1,9,8,5,0,5,5,1
1,1,1,1,1,1,1,1,1,1,1,1,1
1,1,1,1,1,1,1,1,1,1,1,1,1
1,1,1,1,1,1,1,1,1,1,1,1,1
endlayer

layer
2,2,2,2,2,2,2,2,2,2,2,2,2
2,2,2,2,2,2,2,2,2,2,2,2,2
2,2,2,2,2,2,10,2,2,2,2,2,2
2,2,10,10,2,2,10,13,12,11,0,2,2
2,2,10,10,2,2,10,13,12,11,0,2,2
2,2,10,10,2,2,10,13,12,11,0,2,2
2,2,10,10,2,2,10,13,12,11,0,2,2
2,2,10,10,2,2,10,13,12,11,0,2,2
2,2,10,10,2,2,10,13,12,11,0,2,2
2,2,10,10,2,2,5,0,0,0,2,2,2
2,2,2,2,2,2,2,2,2,2,2,2,2
2,2,2,2,2,2,2,2,2,2,2,2,2
2,2,2,2,2,2,2,2,2,2,2,2,2
endlayer

layer
1,1,1,1,1,1,0,1,1,1,1,1,1
1,1,1,1,1,1,0,1,1,1,1,1,1
1,1,1,1,1,1,0,1,1,1,1,1,1
1,1,7,0,1,1,0,1,1,1,1,1,1
1,1,0,7,1,1,0,1,1,1,1,1,1
1,1,7,0,1,1,0,1,1,1,1,1,1
1,1,0,0,1,1,0,1,1,1,1,1,1
1,1,7,0,1,1,0,1,1,1,1,1,1
1,1,0,7,1,1,14,1,1,1,1,1,1
1,1,16,15,1,1,1,1,1,1,1,1,1
1,1,1,1,1,1,1,1,1,1,1,1,1
1,1,1,1,1,1,1,1,1,1,1,1,1
1,1,1,1,1,1,1,1,1,1,1,1,1
endlayer

layer
17,17,17,17,17,2,0,2,17,17,17,17,17
17,2,2,2,2,2,0,2,2,2,2,2,17
17,2,2,2,2,2,0,2,2,2,2,2,17
17,2,7,7,18,20,0,19,18,2,2,2,17
17,2,7,7,2,2,0,2,2,2,2,2,17
17,2,0,0,18,20,0,19,18,2,2,2,17
17,2,7,7,2,2,0,2,2,2,2,2,17
17,2,0,0,18,20,0,19,18,2,2,2,17
17,2,7,0,2,2,0,2,2,2,2,2,17
17,2,7,7,18,2,21,2,2,2,2,2,17
17,2,2,2,2,2,2,2,2,2,2,2,17
17,2,2,2,2,2,2,2,2,2,2,2,17
17,17,17,17,17,17,17,17,17,17,17,17,17
endlayer

layer
17,17,17,17,17,1,1,1,17,17,17,17,17
17,17,17,17,17,1,1,1,17,17,17,17,17
17,17,1,1,1,1,10,1,1,1,1,17,17
17,17,1,1,1,1,10,1,1,1,1,17,17
17,17,1,1,1,1,10,1,1,1,1,17,17
17,17,1,1,1,1,10,1,1,1,1,17,17
17,17,1,1,1,1,10,1,1,1,1,17,17
17,17,1,1,1,1,10,1,1,1,1,17,17
17,17,1,1,1,1,10,1,1,1,1,17,17
17,17,1,1,1,1,1,1,1,1,1,17,17
17,17,1,1,1,1,1,1,1,1,1,17,17
17,17,17,17,17,17,17,17,17,17,17,17,17
17,17,17,17,17,17,17,17,17,17,17,17,17
endlayer

layer
17,17,17,17,17,17,2,17,17,17,17,17,17
17,17,17,17,17,17,2,17,17,17,17,17,17
17,17,17,17,17,17,2,17,17,17,17,17,17
17,17,17,2,2,2,2,2,2,2,17,17,17
17,17,17,2,2,2,2,2,2,2,17,17,17
17,17,17,2,2,2,2,2,2,2,17,17,17
17,17,17,2,2,2,2,2,2,2,17,17,17
17,17,17,2,2,2,2,2,2,2,17,17,17
17,17,17,2,2,2,2,2,2,2,17,17,17
17,17,17,2,2,2,2,2,2,2,17,17,17
17,17,17,17,17,17,17,17,17,17,17,17,17
17,17,17,17,17,17,17,17,17,17,17,17,17
17,17,17,17,17,17,17,17,17,17,17,17,17
endlayer

layer
17,17,17,17,17,17,17,17,17,17,17,17,17
17,17,17,17,17,17,17,17,17,17,17,17,17
17,17,17,17,17,17,17,17,17,17,17,17,17
17,17,17,17,17,17,17,17,17,17,17,17,17
17,17,17,17,1,1,1,1,1,17,17,17,17
17,17,17,17,1,1,1,1,1,17,17,17,17
17,17,17,17,1,1,1,1,1,17,17,17,17
17,17,17,17,1,1,1,1,1,17,17,17,17
17,17,17,17,1,1,1,1,1,17,17,17,17
17,17,17,17,17,17,17,17,17,17,17,17,17
17,17,17,17,17,17,17,17,17,17,17,17,17
17,17,17,17,17,17,17,17,17,17,17,17,17
17,17,17,17,17,17,17,17,17,17,17,17,17
endlayer

layer
17,17,17,17,17,17,17,17,17,17,17,17,17
17,17,17,17,17,17,17,17,17,17,17,17,17
17,17,17,17,17,17,17,17,17,17,17,17,17
17,17,17,17,17,17,17,17,17,17,17,17,17
17,17,17,17,17,17,17,17,17,17,17,17,17
17,17,17,17,17,2,2,2,17,17,17,17,17
17,17,17,17,17,2,2,2,17,17,17,17,17
17,17,17,17,17,2,2,2,17,17,17,17,17
17,17,17,17,17,17,17,17,17,17,17,17,17
17,17,17,17,17,17,17,17,17,17,17,17,17
17,17,17,17,17,17,17,17,17,17,17,17,17
17,17,17,17,17,17,17,17,17,17,17,17,17
17,17,17,17,17,17,17,17,17,17,17,17,17
endlayer

layer
17,17,17,17,17,17,17,17,17,17,17,17,17
17,17,17,17,17,17,17,17,17,17,17,17,17
17,17,17,17,17,17,17,17,17,17,17,17,17
17,17,17,17,17,17,17,17,17,17,17,17,17
17,17,17,17,17,17,17,17,17,17,17,17,17
17,17,17,17,17,17,17,17,17,17,17,17,17
17,17,17,17,17,17,1,17,17,17,17,17,17
17,17,17,17,17,17,17,17,17,17,17,17,17
17,17,17,17,17,17,17,17,17,17,17,17,17
17,17,17,17,17,17,17,17,17,17,17,17,17
17,17,17,17,17,17,17,17,17,17,17,17,17
17,17,17,17,17,17,17,17,17,17,17,17,17
17,17,17,17,17,17,17,17,17,17,17,17,17
endlayer

