
# Shrine_Anubis_1v7v10 (alternate)
# (alternate "decorative" version minus the TNT & lava)
# 10 Mar 2014 -- updated to 1.7.10, 7 Oct 2014
# Created by Ruins mod version 12.3 Ingame Parser
# authoring Player: Jordan_Greywolf
# last updated 23 Mar 2016
# Updated to MC 1.9: 26 Apr 2016
# Verified for MC 1.12: 23 Jun 2017
# Updated to MC 1.12.1: 9 Sep 2017

biomesToSpawnIn=desert,desert m,deserthills,oasis,lush desert,lush_desert,desert oil field,rwg_oasis,rwg_hotdesert,desert_hills,mutated_desert


weight=1
embed_into_distance=5

acceptable_target_blocks=sand,sandstone

dimensions=18,7,12
allowable_overhang=0
max_cut_in=0
cut_in_buffer=0
max_leveling=4
leveling_buffer=-1
preserve_water=0
preserve_lava=0
preserve_plants=1

rule1=0,100,minecraft:sandstone-0
rule2=0,100,minecraft:obsidian-0
rule3=0,100,minecraft:sandstone-0
rule4=0,100,minecraft:sandstone_stairs-0
rule5=0,100,minecraft:sandstone_stairs-3
rule6=0,100,minecraft:sandstone_stairs-2
rule7=0,100,minecraft:sandstone-2
rule8=0,100,minecraft:sandstone_stairs-1
rule9=0,100,minecraft:obsidian-0

rule10=0,100,MobSpawner:Skeleton,MobSpawner:Husk

rule11=0,100,ChestGenHook:chests/simple_dungeon:2
rule12=0,100,ChestGenHook:chests/desert_pyramid:2
rule13=0,100,minecraft:sandstone-1
rule14=0,100,minecraft:sandstone_stairs-4
rule15=0,100,minecraft:sandstone_stairs-6
rule16=0,100,minecraft:sandstone_stairs-7
rule17=0,100,minecraft:sandstone_stairs-5
rule18=0,100,minecraft:stained_hardened_clay-11

layer
1,1,1,1,1,1,1,1,1,1,1,1
1,18,9,18,9,18,9,18,9,18,9,1
1,9,18,9,18,9,18,9,18,9,18,1
1,18,9,18,9,18,9,18,9,18,9,1
1,9,18,9,18,9,18,9,18,9,18,1
1,18,9,18,9,18,9,18,9,18,9,1
1,1,1,1,1,1,1,1,1,1,1,1
endlayer

layer
1,1,1,1,1,1,1,1,1,1,1,1
1,0,0,0,0,0,0,0,0,0,0,1
1,0,0,0,0,0,0,0,0,0,0,1
1,0,0,10,0,12,11,0,10,0,0,1
1,0,0,0,0,0,0,0,0,0,0,1
1,0,0,0,0,0,0,0,0,0,0,1
1,1,1,1,1,1,1,1,1,1,1,1
endlayer


layer
1,1,1,1,1,1,1,1,1,1,1,1
1,0,0,0,0,0,0,0,0,0,0,1
1,0,0,0,0,0,0,0,0,0,0,1
1,0,0,0,0,0,0,0,0,0,0,1
1,0,0,0,0,0,0,0,0,0,0,1
1,0,0,0,0,0,0,0,0,0,0,1
1,1,1,1,1,1,1,1,1,1,1,1
endlayer


layer
1,1,1,1,1,1,1,1,1,1,1,1
1,0,0,0,0,0,0,0,0,0,0,1
1,0,0,0,0,0,0,0,0,0,0,1
1,0,0,0,0,0,0,0,0,0,0,1
1,0,0,0,0,0,0,0,0,0,0,1
1,0,0,0,0,0,0,0,0,0,0,1
1,1,1,1,1,1,1,1,1,1,1,1
endlayer



layer
1,1,1,1,1,1,1,1,1,1,1,1
1,1,1,1,1,1,1,1,1,1,1,1
1,1,0,0,0,0,0,0,0,0,1,1
1,1,0,0,0,0,0,0,0,0,1,1
1,1,0,0,0,0,0,0,0,0,1,1
1,1,1,1,1,1,1,1,1,1,1,1
1,1,1,1,1,1,1,1,1,1,1,1
endlayer

layer
5,4,4,4,4,4,4,4,4,4,4,4
5,1,1,1,1,1,1,1,1,1,1,6
5,1,18,9,18,9,18,9,18,9,1,6
5,1,9,18,9,18,9,18,9,18,1,6
5,1,18,9,18,9,18,9,18,9,1,6
5,1,1,1,1,1,1,1,1,1,1,6
8,8,8,8,8,8,8,8,8,8,8,6
endlayer

layer
0,0,0,0,0,0,0,0,0,0,0,0
0,7,7,7,7,7,7,7,7,7,7,0
0,7,0,0,0,0,0,0,0,0,7,0
0,7,0,10,0,12,11,0,10,0,7,9
0,7,0,0,0,0,0,0,0,0,7,0
0,7,7,7,7,7,7,7,7,7,7,0
0,0,0,0,0,0,0,0,0,0,0,0
endlayer

layer
0,0,0,0,0,0,0,0,0,0,0,0
0,13,13,13,13,13,13,13,13,13,13,0
0,13,0,0,0,0,0,0,0,0,13,0
0,13,0,0,0,0,0,0,0,0,13,9
0,13,0,0,0,0,0,0,0,0,13,0
0,13,13,13,13,13,13,13,13,13,13,0
0,0,0,0,0,0,0,0,0,0,0,0
endlayer

layer
14,14,14,14,14,14,14,14,14,14,14,14
16,7,7,7,7,7,7,7,7,7,7,15
16,7,7,7,7,7,7,7,7,7,7,15
16,7,7,7,7,7,7,7,7,7,7,9
16,7,7,7,7,7,7,7,7,7,7,15
16,7,7,7,7,7,7,7,7,7,7,15
17,17,17,17,17,17,17,17,17,17,17,15
endlayer

layer
0,0,0,0,0,0,0,0,0,0,0,0
9,9,9,9,9,9,0,9,9,9,9,0
0,0,0,0,9,9,9,9,9,9,9,0
0,0,0,0,9,2,2,2,2,2,9,9
0,0,0,0,9,9,9,9,9,9,9,0
9,9,9,9,9,9,0,9,9,9,9,0
0,0,0,0,0,0,0,0,0,0,0,0
endlayer

layer
0,0,0,0,0,0,0,0,0,0,0,0
0,0,0,0,0,0,0,0,0,9,9,0
0,0,0,0,9,9,9,9,9,9,9,0
0,0,0,0,9,2,2,2,2,2,9,9
0,0,0,0,9,9,9,9,9,9,9,0
0,0,0,0,0,0,0,0,0,9,9,0
0,0,0,0,0,0,0,0,0,0,0,0
endlayer

layer
0,0,0,0,0,0,0,0,0,0,0,0
0,0,0,0,0,0,0,0,0,0,0,0
0,0,0,0,9,9,0,0,0,9,9,0
0,0,0,0,9,9,9,9,9,9,9,0
0,0,0,0,9,9,0,0,0,9,9,0
0,0,0,0,0,0,0,0,0,0,0,0
0,0,0,0,0,0,0,0,0,0,0,0
endlayer

layer
0,0,0,0,0,0,0,0,0,0,0,0
0,0,0,0,0,0,0,0,0,0,0,0
0,0,0,0,0,9,0,0,0,0,0,0
0,0,0,0,9,9,9,9,9,9,0,0
0,0,0,0,0,9,0,0,0,0,0,0
0,0,0,0,0,0,0,0,0,0,0,0
0,0,0,0,0,0,0,0,0,0,0,0
endlayer

layer
0,0,0,0,0,0,0,0,0,0,0,0
0,0,0,0,0,0,0,0,0,0,0,0
0,0,0,0,0,9,0,0,0,0,0,0
0,0,0,0,18,18,0,0,0,0,0,0
0,0,0,0,0,9,0,0,0,0,0,0
0,0,0,0,0,0,0,0,0,0,0,0
0,0,0,0,0,0,0,0,0,0,0,0
endlayer

layer
0,0,0,0,0,0,0,0,0,0,0,0
0,0,0,0,0,0,0,0,0,0,0,0
0,0,0,0,9,9,0,0,0,0,0,0
0,0,9,9,9,9,0,0,0,0,0,0
0,0,0,0,9,9,0,0,0,0,0,0
0,0,0,0,0,0,0,0,0,0,0,0
0,0,0,0,0,0,0,0,0,0,0,0
endlayer

layer
0,0,0,0,0,0,0,0,0,0,0,0
0,0,0,0,0,0,0,0,0,0,0,0
0,0,0,0,9,0,0,0,0,0,0,0
0,0,0,0,9,9,0,0,0,0,0,0
0,0,0,0,9,0,0,0,0,0,0,0
0,0,0,0,0,0,0,0,0,0,0,0
0,0,0,0,0,0,0,0,0,0,0,0
endlayer

layer
0,0,0,0,0,0,0,0,0,0,0,0
0,0,0,0,0,0,0,0,0,0,0,0
0,0,0,0,9,0,0,0,0,0,0,0
0,0,0,0,0,0,0,0,0,0,0,0
0,0,0,0,9,0,0,0,0,0,0,0
0,0,0,0,0,0,0,0,0,0,0,0
0,0,0,0,0,0,0,0,0,0,0,0
endlayer

layer
0,0,0,0,0,0,0,0,0,0,0,0
0,0,0,0,0,0,0,0,0,0,0,0
0,0,0,0,9,0,0,0,0,0,0,0
0,0,0,0,0,0,0,0,0,0,0,0
0,0,0,0,9,0,0,0,0,0,0,0
0,0,0,0,0,0,0,0,0,0,0,0
0,0,0,0,0,0,0,0,0,0,0,0
endlayer

