# Twilight Forest - Enchanted Pool
# Created by Ruins mod version 17.1 Ingame Parser
# authoring Player: Jordan_Greywolf

# Created for MC 1.12 with Benimatic's Twilight Forest Mod: 1 Jul 2018

# Last Updated: 3 Jul 2018

biomesToSpawnIn=birch_forest,birch_forest_hills,brushland,chaparral,dead_forest,forest,forest_hills,grassland,grove,land_of_lakes,lavender_fields,maple_woods,meadow,miningbiome,moor,mutated_birch_forest,mutated_birch_forest_hills,mutated_forest,mutated_plains,mystic_grove,oak_savannah,ominous_woods,orchard,outback,pasture,plains,prairie,quagmire,river,seasonal_forest,scrubland,shrubland,smaller_extreme_hills,twilight_clearing,twilight_forest,twilight_swamp,wasteland,wetland,woodland,xeric_shrubland

uniqueMinDistance=1000

weight=1
embed_into_distance=48
acceptable_target_blocks=

unacceptable_target_blocks=cloud,slime_congealed,slime_dirt,slime_grass,command_block

dimensions=9,13,13
allowable_overhang=0
max_leveling=16
leveling_buffer=-1
preserve_water=0
preserve_lava=0

rule1=0,100,twilightforest:maze_stone-2
rule2=0,100,twilightforest:maze_stone-7
rule3=0,100,twilightforest:magic_log_core-13
rule4=0,100,twilightforest:maze_stone-3
rule5=0,100,twilightforest:maze_stone-6
rule6=0,100,minecraft:water-0
rule7=0,100,minecraft:fence-0
rule8=0,100,minecraft:waterlily-0
rule9=0,100,twilightforest:huge_lilypad-0
rule10=0,100,twilightforest:huge_lilypad-12
rule11=0,100,twilightforest:huge_lilypad-4
rule12=0,100,twilightforest:huge_lilypad-8

# Randomized Mazestone Brick Wall
rule13=0,100,twilightforest:maze_stone-1,twilightforest:maze_stone-4,twilightforest:maze_stone-5

rule14=0,100,twilightforest:twilight_leaves-7
rule15=0,100,twilightforest:twilight_leaves-15
rule16=0,100,twilightforest:magic_leaves-5
rule17=0,100,twilightforest:magic_leaves-13

layer
1,1,1,1,1,1,1,1,1,1,1,1,1
1,1,1,1,1,1,1,1,1,1,1,1,1
1,1,1,1,1,1,1,1,1,1,1,1,1
1,1,1,1,1,1,1,1,1,1,1,1,1
1,1,1,1,1,1,1,1,1,1,1,1,1
1,1,1,1,1,2,2,2,1,1,1,1,1
1,1,1,1,1,2,3,2,1,1,1,1,1
1,1,1,1,1,2,2,2,1,1,1,1,1
1,1,1,1,1,1,1,1,1,1,1,1,1
1,1,1,1,1,1,1,1,1,1,1,1,1
1,1,1,1,1,1,1,1,1,1,1,1,1
1,1,1,1,1,1,1,1,1,1,1,1,1
1,1,1,1,1,1,1,1,1,1,1,1,1
endlayer

layer
1,4,4,4,1,4,4,4,1,4,4,4,1
4,1,1,1,1,1,1,1,1,1,1,1,4
4,1,1,1,1,1,1,1,1,1,1,1,4
4,1,1,1,1,1,1,1,1,1,1,1,4
1,1,1,1,1,1,1,1,1,1,1,1,1
4,1,1,1,1,2,2,2,1,1,1,1,4
4,1,1,1,1,2,2,2,1,1,1,1,4
4,1,1,1,1,2,2,2,1,1,1,1,4
1,1,1,1,1,1,1,1,1,1,1,1,1
4,1,1,1,1,1,1,1,1,1,1,1,4
4,1,1,1,1,1,1,1,1,1,1,1,4
4,1,1,1,1,1,1,1,1,1,1,1,4
1,4,4,4,1,4,4,4,1,4,4,4,1
endlayer

layer
1,1,1,1,1,1,1,1,1,1,1,1,1
1,5,5,5,5,5,5,5,5,5,5,5,1
1,5,5,5,5,5,5,5,5,5,5,5,1
1,5,5,5,5,5,5,5,5,5,5,5,1
1,5,5,5,4,4,4,4,4,5,5,5,1
1,5,5,5,4,6,6,6,4,5,5,5,1
1,5,5,5,4,6,6,6,4,5,5,5,1
1,5,5,5,4,6,6,6,4,5,5,5,1
1,5,5,5,4,4,4,4,4,5,5,5,1
1,5,5,5,5,5,5,5,5,5,5,5,1
1,5,5,5,5,5,5,5,5,5,5,5,1
1,5,5,5,5,5,5,5,5,5,5,5,1
1,1,1,1,1,1,1,1,1,1,1,1,1
endlayer

layer
1,4,4,4,1,7,0,7,1,4,4,4,1
4,4,4,4,4,0,0,0,4,4,4,4,4
4,4,0,0,0,0,0,0,0,0,0,4,4
4,4,0,0,0,0,0,0,0,0,0,4,4
1,4,0,0,7,0,0,0,7,0,0,4,1
7,0,0,0,0,8,8,8,0,0,0,0,7
0,0,0,0,0,8,10,9,0,0,0,0,0
7,0,0,0,0,8,12,11,0,0,0,0,7
1,4,0,0,7,0,0,0,7,0,0,4,1
4,4,0,0,0,0,0,0,0,0,0,4,4
4,4,0,0,0,0,0,0,0,0,0,4,4
4,4,4,4,4,0,0,0,4,4,4,4,4
1,4,4,4,1,7,0,7,1,4,4,4,1
endlayer

layer
1,13,13,13,1,7,0,7,1,13,13,13,1
13,14,14,14,14,0,0,0,14,15,14,14,13
13,14,0,0,0,0,0,0,0,0,0,14,13
13,14,0,0,0,0,0,0,0,0,0,14,13
1,14,0,0,16,0,0,0,16,0,0,14,1
7,0,0,0,0,0,0,0,0,0,0,0,7
0,0,0,0,0,0,0,0,0,0,0,0,0
7,0,0,0,0,0,0,0,0,0,0,0,7
1,14,0,0,16,0,0,0,16,0,0,14,1
13,14,0,0,0,0,0,0,0,0,0,14,13
13,14,0,0,0,0,0,0,0,0,0,14,13
13,14,14,14,14,0,0,0,14,14,14,14,13
1,13,13,13,1,7,0,7,1,13,13,13,1
endlayer

layer
1,13,13,13,1,7,7,7,1,13,13,13,1
13,14,14,14,14,0,0,0,14,15,14,14,13
13,14,0,0,0,0,0,0,0,0,0,14,13
13,14,0,0,16,0,0,0,16,0,0,14,13
1,14,0,16,16,16,0,16,16,16,0,14,1
7,0,0,0,16,0,0,0,16,0,0,0,7
7,0,0,0,0,0,0,0,0,0,0,0,7
7,0,0,0,16,0,0,0,16,0,0,0,7
1,14,0,16,16,16,0,16,16,16,0,14,1
13,14,0,0,17,0,0,0,16,0,0,14,13
13,14,0,0,0,0,0,0,0,0,0,14,13
13,14,14,14,14,0,0,0,14,14,14,14,13
1,13,13,13,1,7,7,7,1,13,13,13,1
endlayer

layer
1,4,4,4,1,1,1,1,1,4,4,4,1
4,14,14,14,14,0,0,0,14,14,14,14,4
4,14,0,0,0,0,0,0,0,0,0,14,4
4,14,0,0,16,0,0,0,16,0,0,14,4
1,14,0,16,16,16,0,16,16,16,0,14,1
1,0,0,0,16,0,0,0,16,0,0,0,1
1,0,0,0,0,0,0,0,0,0,0,0,1
1,0,0,0,16,0,0,0,16,0,0,0,1
1,14,0,16,16,16,0,16,16,16,0,14,1
4,14,0,0,16,0,0,0,16,0,0,14,4
4,14,0,0,0,0,0,0,0,0,0,14,4
4,14,14,14,14,0,0,0,14,14,14,14,4
1,4,4,4,1,1,1,1,1,4,4,4,1
endlayer

layer
1,1,1,1,1,1,1,1,1,1,1,1,1
1,14,14,14,14,0,0,0,14,15,14,14,1
1,14,0,0,0,0,0,0,0,0,0,14,1
1,14,0,0,0,0,0,0,0,0,0,14,1
1,14,0,0,16,0,0,0,16,0,0,14,1
1,0,0,0,0,0,0,0,0,0,0,0,1
1,0,0,0,0,0,0,0,0,0,0,0,1
1,0,0,0,0,0,0,0,0,0,0,0,1
1,14,0,0,16,0,0,0,16,0,0,14,1
1,14,0,0,0,0,0,0,0,0,0,14,1
1,14,0,0,0,0,0,0,0,0,0,14,1
1,14,14,14,14,0,0,0,14,14,14,14,1
1,1,1,1,1,1,1,1,1,1,1,1,1
endlayer

layer
1,1,1,1,1,1,1,1,1,1,1,1,1
1,4,4,4,4,4,4,4,4,4,4,4,1
1,4,4,4,4,4,4,4,4,4,4,4,1
1,4,4,0,0,0,0,0,0,0,4,4,1
1,4,4,0,0,0,0,0,0,0,4,4,1
1,4,4,0,0,0,0,0,0,0,4,4,1
1,4,4,0,0,0,0,0,0,0,4,4,1
1,4,4,0,0,0,0,0,0,0,4,4,1
1,4,4,0,0,0,0,0,0,0,4,4,1
1,4,4,0,0,0,0,0,0,0,4,4,1
1,4,4,4,4,4,4,4,4,4,4,4,1
1,4,4,4,4,4,4,4,4,4,4,4,1
1,1,1,1,1,1,1,1,1,1,1,1,1
endlayer

layer
13,13,13,13,13,13,13,13,13,13,13,13,13
13,13,13,13,13,13,13,13,13,13,13,13,13
13,13,13,13,13,13,13,13,13,13,13,13,13
13,13,13,0,0,0,0,0,0,0,13,13,13
13,13,13,0,0,0,0,0,0,0,13,13,13
13,13,13,0,0,0,0,0,0,0,13,13,13
13,13,13,0,0,0,0,0,0,0,13,13,13
13,13,13,0,0,0,0,0,0,0,13,13,13
13,13,13,0,0,0,0,0,0,0,13,13,13
13,13,13,0,0,0,0,0,0,0,13,13,13
13,13,13,13,13,13,13,13,13,13,13,13,13
13,13,13,13,13,13,13,13,13,13,13,13,13
13,13,13,13,13,13,13,13,13,13,13,13,13
endlayer

layer
5,5,5,5,5,5,5,5,5,5,5,5,5
5,5,5,5,5,5,5,5,5,5,5,5,5
5,5,5,5,5,5,5,5,5,5,5,5,5
5,5,5,5,5,5,5,5,5,5,5,5,5
5,5,5,5,5,5,5,5,5,5,5,5,5
5,5,5,5,5,5,5,5,5,5,5,5,5
5,5,5,5,5,5,5,5,5,5,5,5,5
5,5,5,5,5,5,5,5,5,5,5,5,5
5,5,5,5,5,5,5,5,5,5,5,5,5
5,5,5,5,5,5,5,5,5,5,5,5,5
5,5,5,5,5,5,5,5,5,5,5,5,5
5,5,5,5,5,5,5,5,5,5,5,5,5
5,5,5,5,5,5,5,5,5,5,5,5,5
endlayer


