# Twilight Forest Nagastone Tomb
# Created by Ruins mod version 17.1 Ingame Parser
# authoring Player: Jordan_Greywolf

# Made for MC 1.12 with Benematic's Twilight Forest: 28 Jun 2018

biomesToSpawnIn=oak_savannah,twilight_clearing,twilight_swamp

uniqueMinDistance=500


weight=1
embed_into_distance=6
acceptable_target_blocks=

unacceptable_target_blocks=flowing_water,water,flowing_lava,lava,cloud,Natura:Cloud,bedrock,cobblestone,endstone,red_mushroom_block,brown_mushroom_block,ice,slime_congealed,slime_dirt,slime_grass,command_block,planks,planks2,concrete,cobblestone,stonebrick,brick_block,glass,torch,oak_stairs,stone_stairs,brick_stairs,stone_brick_stairs,nether_brick_stairs,sandstone_stairs,spruce_stairs,birch_stairs,jungle_stairs,quartz_stairs,acacia_stairs,dark_oak_stairs,cobblestone_wall,stone_slab,double_stone_slab,stone_slab2,wooden_slab,double_wooden_slab,nether_brick

dimensions=14,17,7
allowable_overhang=0
max_leveling=6
leveling_buffer=-1
preserve_water=0
preserve_lava=0

rule1=0,100,twilightforest:etched_nagastone-1,twilightforest:etched_nagastone_mossy-1,twilightforest:etched_nagastone_weathered-1

rule2=0,100,twilightforest:nagastone_pillar_mossy-0,twilightforest:nagastone_pillar-0,twilightforest:nagastone_pillar_weathered-0

rule3=0,100,twilightforest:naga_stone-2
rule4=0,100,twilightforest:naga_stone-3
rule5=0,100,twilightforest:naga_stone-0

# Building Materials Chest
rule6=0,100,IInventory;minecraft:chest;twilightforest:nagastone_pillar_mossy#32#0#0+twilightforest:nagastone_pillar#32#0#2+twilightforest:nagastone_stairs_mossy#32#0#3+twilightforest:nagastone_stairs_weathered#32#0#4+twilightforest:naga_stone#6#0#6+twilightforest:etched_nagastone_weathered#32#0#8+twilightforest:naga_scale#4#0#10+twilightforest:nagastone_stairs#32#0#13+twilightforest:nagastone_stairs_mossy#32#8#14+twilightforest:nagastone_stairs#32#8#16+twilightforest:etched_nagastone#32#0#18+twilightforest:etched_nagastone_mossy#32#0#21+twilightforest:nagastone_stairs_weathered#32#8#23+twilightforest:nagastone_pillar_weathered#32#0#24+twilightforest:naga_stone#32#1#26-5

# Overgrowth
rule7=0,100,twilightforest:twilight_plant-4,twilightforest:twilight_plant-3,twilightforest:twilight_plant-2

rule8=0,100,IInventory;minecraft:chest;twilightforest:raven_feather#1#0#0+twilightforest:twilight_plant#4#3#5+twilightforest:firefly#3#0#12+twilightforest:maze_wafer#4#0#17+twilightforest:twilight_plant#4#1#24-5
rule9=0,100,twilightforest:naga_stone-1
rule10=0,100,twilightforest:naga_stone-10
rule11=0,100,twilightforest:naga_stone-12
rule12=0,100,twilightforest:naga_stone-11
rule13=0,100,twilightforest:nagastone_stairs_mossy-0
rule14=0,100,twilightforest:nagastone_stairs_mossy-8
rule15=0,100,twilightforest:nagastone_stairs_mossy-5
rule16=0,100,twilightforest:nagastone_stairs_mossy-13

rule17=0,100,MobSpawner:TwilightForest:Kobold

rule18=0,100,ChestGenHook:chests/simple_dungeon:5-5
rule19=0,100,twilightforest:naga_stone-13

rule20=0,100,MobSpawner:TwilightForest:Wraith

rule21=0,100,minecraft:vine-2
rule22=0,100,minecraft:vine-8
rule23=0,100,minecraft:vine-1
rule24=0,100,twilightforest:naga_stone-7
rule25=0,100,minecraft:vine-4
rule26=0,100,twilightforest:naga_stone-6
rule27=0,100,twilightforest:nagastone_stairs_mossy-7
rule28=0,100,twilightforest:nagastone_stairs_mossy-14
rule29=0,100,twilightforest:naga_stone-14
rule30=0,100,twilightforest:naga_stone-15

rule31=0,100,twilightforest:etched_nagastone_mossy-5,twilightforest:etched_nagastone-5,twilightforest:etched_nagastone_weathered-5

rule32=0,100,twilightforest:nagastone_stairs_mossy-2
rule33=0,100,twilightforest:nagastone_stairs_mossy-11

rule34=0,100,twilightforest:etched_nagastone_mossy-4,twilightforest:etched_nagastone-4,twilightforest:etched_nagastone_weathered-4

layer
1,1,1,1,1,1,1
1,1,1,1,1,1,1
1,1,1,1,1,1,1
1,1,1,1,1,1,1
1,1,1,1,1,1,1
1,1,1,1,1,1,1
1,1,1,1,1,1,1
1,1,1,1,1,1,1
1,1,1,1,1,1,1
1,1,1,1,1,1,1
1,1,1,1,1,1,1
1,1,1,1,1,1,1
1,1,1,1,1,1,1
1,1,1,1,1,1,1
1,1,1,1,1,1,1
1,1,1,1,1,1,1
1,1,1,1,1,1,1
endlayer

layer
2,3,2,4,2,3,2
9,8,8,7,6,6,5
2,0,0,0,0,0,2
10,0,0,0,0,0,10
11,0,0,0,0,0,11
12,7,0,0,0,7,12
2,0,0,0,0,0,2
10,0,0,0,0,0,10
11,0,0,0,0,0,11
12,0,0,0,0,0,12
2,7,0,0,0,7,2
10,0,0,0,0,0,10
11,14,0,0,0,13,11
12,16,7,0,7,15,12
2,18,2,0,2,17,2
9,0,0,7,0,0,5
2,4,2,3,2,4,2
endlayer

layer
2,19,2,19,2,19,2
19,0,0,20,0,0,19
2,0,0,21,0,0,2
19,0,22,0,0,0,19
2,0,0,0,0,0,2
19,0,0,0,0,21,19
2,0,0,0,0,0,2
19,22,0,0,22,0,19
2,0,0,0,0,0,2
19,0,0,0,0,0,19
2,0,0,0,0,0,2
19,0,0,0,0,0,19
2,0,0,0,0,0,2
19,14,0,0,23,13,19
2,16,2,0,2,15,2
19,0,0,0,0,0,19
2,19,2,19,2,19,2
endlayer

layer
2,19,2,24,2,19,2
24,0,25,12,23,0,24
11,0,25,21,0,0,11
26,0,22,0,0,0,26
2,0,0,0,0,0,2
24,0,0,0,0,21,24
11,0,0,0,23,0,11
26,22,22,0,22,0,26
2,0,0,0,0,0,2
24,21,0,0,0,21,24
11,0,25,0,23,0,11
26,0,0,0,23,0,26
2,0,25,0,0,0,2
24,0,25,0,23,0,24
11,14,2,0,2,13,11
26,28,0,10,0,27,26
2,19,2,26,2,19,2
endlayer

layer
1,1,1,1,1,1,1
1,0,25,24,23,0,1
1,0,25,11,23,0,1
1,22,22,11,22,22,1
1,29,29,30,29,29,1
1,21,21,11,21,21,1
1,0,25,11,23,0,1
1,22,22,11,22,22,1
1,29,29,30,29,29,1
1,21,21,11,21,21,1
1,0,25,11,23,0,1
1,0,25,11,23,0,1
1,0,25,11,23,0,1
1,0,25,11,23,0,1
1,0,1,11,1,0,1
1,14,28,26,27,13,1
1,1,1,1,1,1,1
endlayer

layer
1,1,1,1,1,1,1
1,31,31,31,31,31,1
1,31,31,31,31,31,1
1,31,31,31,31,31,1
1,31,31,31,31,31,1
1,31,31,31,31,31,1
1,31,31,31,31,31,1
1,31,31,31,31,31,1
1,31,31,31,31,31,1
1,31,31,31,31,31,1
1,31,31,31,31,31,1
1,31,31,31,31,31,1
1,31,31,31,31,31,1
1,21,31,31,31,21,1
1,0,1,31,1,0,1
1,0,33,31,32,0,1
1,1,1,1,1,1,1
endlayer

layer
2,19,2,0,2,19,2
10,7,0,21,0,7,10
11,0,2,0,2,0,11
12,0,0,0,0,0,12
2,0,2,0,2,0,2
10,0,0,0,0,0,10
11,0,2,0,2,0,11
12,7,0,0,0,7,12
2,0,2,0,2,0,2
10,0,0,0,0,0,10
11,0,2,0,2,0,11
12,0,0,0,0,0,12
2,7,2,0,2,7,2
10,0,0,0,0,0,10
11,0,2,0,2,0,11
12,0,0,0,0,0,12
2,19,2,19,2,19,2
endlayer

layer
2,19,2,0,2,19,2
19,0,0,21,0,0,19
2,0,2,0,2,0,2
19,0,0,0,0,0,19
2,0,2,0,2,0,2
19,0,0,0,0,0,19
2,0,2,0,2,0,2
19,0,0,0,0,0,19
2,0,2,0,2,0,2
19,0,0,0,0,0,19
2,0,2,0,2,0,2
19,0,0,0,0,0,19
2,0,2,0,2,0,2
19,0,0,0,0,0,19
2,0,2,0,2,0,2
19,0,0,0,0,0,19
2,19,2,19,2,19,2
endlayer

layer
2,3,2,3,2,3,2
9,0,0,21,0,22,5
2,0,2,0,2,0,2
24,0,0,0,0,22,24
11,0,2,0,2,0,11
26,0,0,0,0,0,26
2,0,2,0,2,0,2
24,0,0,0,0,0,24
11,0,2,0,2,0,11
26,0,0,0,0,0,26
2,0,2,0,2,0,2
24,0,0,0,0,0,24
11,0,2,0,2,0,11
26,0,0,0,0,0,26
2,0,2,0,2,0,2
9,0,21,0,0,0,5
2,4,2,3,2,4,2
endlayer

layer
1,1,1,1,1,1,1
31,0,0,21,0,22,1
1,0,1,0,1,0,1
1,22,0,0,0,22,1
1,0,1,0,1,0,1
1,22,0,0,0,0,1
1,0,1,0,1,0,1
1,0,0,21,0,0,1
1,0,1,0,1,0,1
1,0,0,0,0,22,1
1,0,1,0,1,0,1
1,0,0,0,0,0,1
1,0,1,0,1,0,1
1,0,0,21,0,0,34
1,0,1,0,1,0,1
1,21,21,0,21,0,1
1,1,1,1,1,1,1
endlayer

layer
30,29,30,29,30,29,30
11,22,30,21,30,22,11
30,30,30,29,30,30,30
11,22,11,21,11,22,11
30,30,30,29,30,30,30
11,22,11,21,11,22,11
30,30,30,29,30,30,30
11,22,11,21,11,22,11
30,30,30,29,30,30,30
11,22,11,21,11,22,11
30,30,30,29,30,30,30
11,22,11,21,11,22,11
30,30,30,29,30,30,30
11,22,11,21,11,22,11
30,30,30,29,30,30,30
11,21,30,21,30,21,11
30,29,30,29,30,29,30
endlayer

layer
0,22,0,0,0,22,0
0,30,30,30,30,30,0
25,30,30,0,30,30,0
0,11,0,0,0,11,23
0,30,0,0,0,30,0
25,11,0,0,0,11,0
0,30,0,0,0,30,0
0,11,0,0,0,11,23
0,30,0,0,0,30,0
0,11,0,0,0,11,0
25,30,0,0,0,30,0
0,11,0,0,0,11,0
0,30,0,0,0,30,23
0,11,0,0,0,11,0
25,30,30,0,30,30,23
0,30,30,30,30,30,0
0,21,0,0,0,21,0
endlayer

layer
0,0,0,0,0,0,0
0,0,25,30,22,0,0
0,25,30,30,30,0,0
0,0,30,30,30,0,0
0,0,11,0,11,0,0
0,0,11,0,11,23,0
0,0,11,0,11,0,0
0,0,11,0,11,0,0
0,0,11,0,11,0,0
0,25,11,0,11,23,0
0,0,11,0,11,0,0
0,0,11,0,11,0,0
0,0,11,0,11,0,0
0,0,30,30,30,23,0
0,0,30,30,30,0,0
0,0,0,30,23,0,0
0,0,25,21,23,0,0
endlayer

layer
0,0,0,3,23,0,0
0,0,0,26,0,0,0
0,0,0,21,0,0,0
0,0,0,24,23,0,0
0,0,25,11,0,0,0
0,0,25,11,0,0,0
0,0,0,11,23,0,0
0,0,0,11,0,0,0
0,0,0,11,0,0,0
0,0,0,11,0,0,0
0,0,0,11,23,0,0
0,0,25,11,0,0,0
0,0,0,11,0,0,0
0,0,0,26,23,0,0
0,0,0,0,0,0,0
0,0,0,24,23,0,0
0,0,25,4,23,0,0
endlayer

