# Twilight Forest Hidden Library
# Created by Ruins mod version 17.1 Ingame Parser
# authoring Player: Jordan_Greywolf
# Created for MC 1.12 with Benimatic's Twilight Forest Mod: 1 Jul 2018

biomesToSpawnIn=firefly_forest,twilight_clearing,twilight_forest,twilight_swamp

weight=1
embed_into_distance=32
acceptable_target_blocks=

unacceptable_target_blocks=command_block,slime_congealed,cloud,slime_dirt,slime_grass

dimensions=11,13,13
allowable_overhang=9
max_leveling=10
leveling_buffer=-1
preserve_water=0
preserve_lava=0

rule1=0,100,minecraft:stonebrick-0,minecraft:stonebrick-1,minecraft:stonebrick-2

rule2=0,100,MobSpawner:TwilightForest:Death_Tome

rule3=0,100,minecraft:black_glazed_terracotta-0
rule4=0,100,minecraft:wool-14
rule5=0,100,minecraft:black_glazed_terracotta-3
rule6=0,100,minecraft:wool-7
rule7=0,100,minecraft:black_glazed_terracotta-1
rule8=0,100,minecraft:black_glazed_terracotta-2
rule9=0,100,minecraft:stonebrick-3
rule10=0,100,ChestGenHook:chests/stronghold_library:5-5
rule11=0,100,minecraft:bookshelf-0
rule12=0,100,minecraft:cobblestone_wall-0,minecraft:cobblestone_wall-1
rule13=0,100,minecraft:cobblestone-0
rule14=0,100,minecraft:web-0,minecraft:air

rule15=0,100,IInventory;minecraft:chest;minecraft:black_glazed_terracotta#32#0#0+minecraft:paper#32#0#3+minecraft:wool#32#11#5+minecraft:wool#32#14#7+minecraft:black_glazed_terracotta#32#0#10+minecraft:wool#32#7#13+minecraft:wool#32#11#18+minecraft:wool#32#14#20+minecraft:wool#32#7#24+minecraft:paper#32#0#26-2

layer
1,1,1,1,1,1,1,1,1,1,1,1,1
1,1,1,1,1,1,1,1,1,1,1,1,1
1,1,1,1,1,1,1,1,1,1,1,1,1
1,1,1,1,1,1,1,1,1,1,1,1,1
1,1,1,1,1,1,1,1,1,1,1,1,1
1,1,1,1,1,1,1,1,1,1,1,1,1
1,1,1,1,1,1,1,1,1,1,1,1,1
1,1,1,1,1,1,1,1,1,1,1,1,1
1,1,1,1,1,1,1,1,1,1,1,1,1
1,1,1,1,1,1,1,1,1,1,1,1,1
1,1,1,1,1,1,1,1,1,1,1,1,1
1,1,1,1,1,1,1,1,1,1,1,1,1
1,1,1,1,1,1,1,1,1,1,1,1,1
endlayer

layer
1,1,1,1,1,1,1,1,1,1,1,1,1
1,1,1,1,1,5,4,3,1,1,1,1,1
1,1,5,3,1,4,6,4,1,5,3,1,1
1,1,8,7,1,8,4,7,1,8,7,1,1
1,1,1,1,2,1,1,1,2,1,1,1,1
1,5,4,3,1,5,4,3,1,5,4,3,1
1,4,6,4,1,4,6,4,1,4,6,4,1
1,8,4,7,1,8,4,7,1,8,4,7,1
1,1,1,1,2,1,1,1,2,1,1,1,1
1,1,5,3,1,5,4,3,1,5,3,1,1
1,1,8,7,1,4,6,4,1,8,7,1,1
1,1,1,1,1,8,4,7,1,1,1,1,1
1,1,1,1,1,1,1,1,1,1,1,1,1
endlayer

layer
1,1,1,1,1,1,1,1,1,1,1,1,1
1,1,1,1,1,5,4,3,1,1,1,1,1
1,1,5,3,1,4,6,4,1,5,3,1,1
1,1,8,7,1,8,4,7,1,8,7,1,1
1,1,1,1,2,1,1,1,2,1,1,1,1
1,5,4,3,1,5,4,3,1,5,4,3,1
1,4,6,4,1,4,6,4,1,4,6,4,1
1,8,4,7,1,8,4,7,1,8,4,7,1
1,1,1,1,2,1,1,1,2,1,1,1,1
1,1,5,3,1,5,4,3,1,5,3,1,1
1,1,8,7,1,4,6,4,1,8,7,1,1
1,1,1,1,1,8,4,7,1,1,1,1,1
1,1,1,1,1,1,1,1,1,1,1,1,1
endlayer

layer
1,1,1,1,1,1,9,1,1,1,1,1,1
1,1,11,11,1,0,0,0,1,11,11,10,1
1,11,0,0,0,0,0,0,0,0,0,11,1
1,11,0,0,0,0,0,0,0,0,0,11,1
1,1,0,0,12,0,0,0,12,0,0,1,1
1,0,0,0,0,0,0,0,0,0,0,0,1
9,0,0,0,0,0,15,0,0,0,0,0,0
1,0,0,0,0,0,0,0,0,0,0,0,1
1,1,0,0,12,0,0,0,12,0,0,1,1
1,11,0,0,0,0,0,0,0,0,0,11,1
1,11,0,0,0,0,0,0,0,0,0,11,1
1,11,11,11,1,0,0,0,1,11,11,1,1
1,1,1,1,1,1,9,1,1,1,1,1,1
endlayer

layer
1,1,1,1,1,1,13,1,1,1,1,1,1
1,1,11,11,1,0,0,0,1,11,11,1,1
1,11,0,0,0,0,0,0,0,0,0,11,1
1,11,0,0,0,0,0,0,0,0,0,11,1
1,1,0,0,12,0,0,0,12,0,0,1,1
1,0,0,0,0,0,0,0,0,0,0,0,1
13,0,0,0,0,0,0,0,0,0,0,0,0
1,0,0,0,0,0,0,0,0,0,0,0,1
1,1,0,0,12,0,0,0,12,0,0,1,1
1,11,0,0,0,0,0,0,0,0,0,11,1
1,11,0,0,0,0,0,0,0,0,0,11,1
1,1,11,11,1,0,0,0,1,11,11,1,1
1,1,1,1,1,1,13,1,1,1,1,1,1
endlayer

layer
1,1,1,1,1,1,13,1,1,1,1,1,1
1,1,11,11,1,0,0,0,1,11,11,1,1
1,11,0,0,0,0,0,0,0,0,0,11,1
1,11,0,0,0,0,0,0,0,0,0,11,1
1,1,0,0,12,0,0,0,12,0,0,1,1
1,0,0,0,0,0,0,0,0,0,0,0,1
13,0,0,0,0,0,0,0,0,0,0,0,9
1,0,0,0,0,0,0,0,0,0,0,0,1
1,1,0,0,12,0,0,0,12,0,0,1,1
1,11,0,0,0,0,0,0,0,0,0,11,1
1,11,0,0,0,0,0,0,0,0,0,11,1
1,1,11,11,1,0,0,0,1,11,11,1,1
1,1,1,1,1,1,13,1,1,1,1,1,1
endlayer

layer
1,1,1,1,1,1,13,1,1,1,1,1,1
1,1,11,11,1,0,0,0,1,11,11,1,1
1,11,0,0,0,0,0,0,0,0,0,11,1
1,11,0,0,0,0,0,0,0,0,0,11,1
1,1,0,0,12,0,0,0,12,0,0,1,1
1,0,0,0,0,0,0,0,0,0,0,0,1
13,0,0,0,0,0,0,0,0,0,0,0,13
1,0,0,0,0,0,0,0,0,0,0,0,1
1,1,0,0,12,0,0,0,12,0,0,1,1
1,11,0,0,0,0,0,0,0,0,0,11,1
1,11,0,0,0,0,0,0,0,0,0,11,1
1,1,11,11,1,0,0,0,1,11,11,1,1
1,1,1,1,1,1,13,1,1,1,1,1,1
endlayer

layer
1,1,1,1,1,1,13,1,1,1,1,1,1
1,1,11,11,1,0,0,0,1,11,11,1,1
1,11,0,0,0,0,0,0,0,0,0,11,1
1,11,0,0,0,0,0,0,0,0,0,11,1
1,1,0,0,12,0,0,0,12,0,0,1,1
1,0,0,0,0,0,0,0,0,0,0,0,1
13,0,0,0,0,0,0,0,0,0,0,0,13
1,0,0,0,0,0,0,0,0,0,0,0,1
1,1,0,0,12,0,0,0,12,0,0,1,1
1,11,0,0,0,0,0,0,0,0,0,11,1
1,11,0,0,0,0,0,0,0,0,0,11,1
1,1,11,11,1,0,0,0,1,11,11,1,1
1,1,1,1,1,1,13,1,1,1,1,1,1
endlayer

layer
1,1,1,1,1,1,9,1,1,1,1,1,1
1,1,11,11,1,14,0,14,1,11,11,1,1
1,11,14,0,0,0,0,0,0,0,14,11,1
1,11,0,0,0,0,0,0,0,0,0,11,1
1,1,0,0,12,0,0,0,12,0,0,1,1
1,14,0,0,0,0,0,0,0,0,0,14,1
9,0,0,0,0,0,0,0,0,0,0,0,9
1,14,0,0,0,0,0,0,0,0,0,14,1
1,1,0,0,12,0,0,0,12,0,0,1,1
1,11,0,0,0,0,0,0,0,0,0,11,1
1,11,14,0,0,0,0,0,0,0,14,11,1
1,1,11,11,1,14,0,14,1,11,11,1,1
1,1,1,1,1,1,9,1,1,1,1,1,1
endlayer

layer
1,1,1,1,1,1,1,1,1,1,1,1,1
1,1,11,11,1,14,14,14,1,11,11,1,1
1,11,14,14,14,0,0,0,14,14,14,11,1
1,11,14,0,0,0,0,0,0,0,14,11,1
1,1,14,0,12,0,0,0,12,0,14,1,1
1,14,0,0,0,0,0,0,0,0,0,14,1
1,14,0,0,0,0,0,0,0,0,0,14,1
1,14,0,0,0,0,0,0,0,0,0,14,1
1,1,14,0,12,0,0,0,12,0,14,1,1
1,11,14,0,0,0,0,0,0,0,14,11,1
1,11,14,14,14,0,0,0,14,14,14,11,1
1,1,11,11,1,14,14,14,1,11,11,1,1
1,1,1,1,1,1,1,1,1,1,1,1,1
endlayer

layer
1,1,1,1,1,1,1,1,1,1,1,1,1
1,1,1,1,1,1,1,1,1,1,1,1,1
1,1,1,1,1,1,1,1,1,1,1,1,1
1,1,1,1,1,1,1,1,1,1,1,1,1
1,1,1,1,9,1,1,1,9,1,1,1,1
1,1,1,1,1,1,1,1,1,1,1,1,1
1,1,1,1,1,1,1,1,1,1,1,1,1
1,1,1,1,1,1,1,1,1,1,1,1,1
1,1,1,1,9,1,1,1,9,1,1,1,1
1,1,1,1,1,1,1,1,1,1,1,1,1
1,1,1,1,1,1,1,1,1,1,1,1,1
1,1,1,1,1,1,1,1,1,1,1,1,1
1,1,1,1,1,1,1,1,1,1,1,1,1
endlayer

