# GatorIdol -- MC 1.7.10, 11 Oct 2014
# Updated to MC 1.8: 21 Jul 2015
# Created by Ruins mod version 13.8 Ingame Parser
# authoring Player: Jordan_Greywolf

# Updated to MC 1.12: 23 Jun 2017
# Updated to MC 1.12.1: 10 Sep 2017

biomesToSpawnIn=bayou,dead swamp,jungle,junglehills,jungle_hills,jungle m,jungleedge,jungleedge m,jungle_edge,bog,lush swamp,marsh,mangrove,mini jungle,mini_jungle,minijungle,mutated_jungle,mutated_jungle_edge,tropical_island

weight=1
embed_into_distance=6
acceptable_target_blocks=

unacceptable_target_blocks=flowing_lava,lava,cloud,Natura:Cloud,slime_congealed,slime_dirt,slime_grass,command_block,planks,planks2,concrete,cobblestone,stonebrick,brick_block,glass,torch,oak_stairs,stone_stairs,brick_stairs,stone_brick_stairs,nether_brick_stairs,sandstone_stairs,spruce_stairs,birch_stairs,jungle_stairs,quartz_stairs,acacia_stairs,dark_oak_stairs,cobblestone_wall,stone_slab,double_stone_slab,stone_slab2,wooden_slab,double_wooden_slab,nether_brick,fence

dimensions=14,7,7
allowable_overhang=25
max_leveling=4
leveling_buffer=-1
preserve_water=0
preserve_lava=0
preserve_plants=1

rule1=0,100,preserveBlock

rule2=0,100,minecraft:stonebrick,minecraft:stonebrick-2,minecraft:stonebrick-1,minecraft:stonebrick-1
rule3=0,100,minecraft:vine-8
rule4=0,100,minecraft:water-0
rule5=0,100,minecraft:vine-1
rule6=0,100,minecraft:vine-4
rule7=0,100,minecraft:vine-2
rule8=0,100,minecraft:stone_brick_stairs-3
rule9=0,100,minecraft:cobblestone_wall-1
rule10=0,100,minecraft:water-3
rule11=0,100,minecraft:water-2
rule12=0,100,minecraft:water-1
rule13=0,100,minecraft:stone_brick_stairs-7
rule14=0,100,minecraft:stonebrick-3

layer
1,1,1,1,1,1,1
1,2,2,2,2,2,1
1,2,2,2,2,1,1
1,1,2,2,2,2,1
1,2,2,2,2,1,1
1,2,2,2,2,2,1
1,1,1,1,1,1,1
endlayer

layer
1,1,1,1,1,1,1
1,2,2,2,2,2,1
1,2,2,2,2,1,1
1,1,2,2,2,2,1
1,2,2,2,2,1,1
1,2,2,2,2,2,1
1,1,1,1,1,1,1
endlayer

layer
1,1,1,1,1,1,1
1,2,2,2,2,2,1
1,2,2,2,2,1,1
1,1,2,2,2,2,1
1,2,2,2,2,1,1
1,2,2,2,2,2,1
1,1,1,1,1,1,1
endlayer

layer
1,1,1,1,1,1,1
1,2,2,2,2,2,1
1,2,2,2,2,1,1
1,1,2,2,2,2,1
1,2,2,2,2,1,1
1,2,2,2,2,2,1
1,1,1,1,1,1,1
endlayer

layer
1,1,1,1,1,1,1
1,2,2,2,2,2,1
1,2,2,2,2,1,1
1,1,2,2,2,2,1
1,2,2,2,2,1,1
1,2,2,2,2,2,1
1,1,1,1,1,1,1
endlayer

layer
1,1,1,1,1,1,1
1,2,2,2,2,2,1
1,2,2,2,2,1,1
1,1,2,2,2,2,1
1,2,2,2,2,1,1
1,2,2,2,2,2,1
1,1,1,1,1,1,1
endlayer


layer
1,1,1,1,1,1,1
1,2,2,2,2,2,1
1,2,2,2,2,1,1
1,1,2,2,2,2,1
1,2,2,2,2,1,1
1,2,2,2,2,2,1
1,1,1,1,1,1,1
endlayer

layer
1,1,1,3,1,1,1
1,2,2,2,3,1,1
1,2,4,2,2,2,1
6,2,4,4,4,2,5
1,2,4,2,2,2,1
1,2,2,2,7,1,1
1,1,1,7,1,1,1
endlayer

layer
1,1,0,0,0,1,1
1,3,3,3,3,0,1
6,2,2,2,2,5,0
6,2,4,4,2,5,0
6,2,2,2,2,5,0
1,7,7,7,7,0,1
1,1,0,0,0,1,1
endlayer

layer
1,0,3,3,3,3,1
0,6,2,2,2,2,5
0,6,2,2,3,0,0
6,2,4,2,2,5,0
0,6,2,2,7,0,0
0,6,2,2,2,2,5
1,0,7,7,7,7,1
endlayer

layer
0,0,0,0,0,0,0
0,0,3,0,0,0,0
0,6,2,5,0,0,0
6,2,4,2,8,8,8
0,6,2,5,0,0,0
0,0,7,0,0,0,0
0,0,0,0,0,0,0
endlayer

layer
0,0,0,0,0,0,0
0,0,3,3,0,0,0
0,6,2,2,9,9,9
6,2,4,4,12,11,10
0,6,2,2,9,9,9
0,0,7,7,0,0,0
0,0,0,0,0,0,0
endlayer

layer
0,0,0,0,0,0,0
0,0,0,3,0,0,0
0,0,6,2,5,0,0
0,6,2,2,13,13,13
0,0,6,2,5,0,0
0,0,0,7,0,0,0
0,0,0,0,0,0,0
endlayer

layer
0,0,0,0,0,0,0
0,0,0,3,0,0,0
0,0,6,14,5,0,0
0,0,0,7,0,0,0
0,0,6,14,5,0,0
0,0,0,7,0,0,0
0,0,0,0,0,0,0
endlayer

