# Jungle Crypt
# Created by Ruins mod version 16.8 Ingame Parser
# authoring Player: Jordan_Greywolf

# Created for MC 1.12: 23 Nov 2017

biomesToSpawnIn=bayou,dead swamp,dead_swamp,lush swamp,lush_swamp,jungle,jungle m,jungleedge,jungleedge m,junglehills,temperate rainforest,rainforest,extreme jungle,mutated_jungle,mutated_jungle_edge

weight=1

embed_into_distance=48
acceptable_target_blocks=

unacceptable_target_blocks=flowing_water,water,flowing_lava,lava,cloud,Natura:Cloud,slime_congealed,slime_dirt,slime_grass,command_block,planks,planks2,concrete,cobblestone,stonebrick,brick_block,glass,torch,oak_stairs,stone_stairs,brick_stairs,stone_brick_stairs,nether_brick_stairs,sandstone_stairs,spruce_stairs,birch_stairs,jungle_stairs,quartz_stairs,acacia_stairs,dark_oak_stairs,cobblestone_wall,stone_slab,double_stone_slab,stone_slab2,wooden_slab,double_wooden_slab,nether_brick,fence

dimensions=23,21,21
allowable_overhang=0
max_leveling=12
leveling_buffer=-1
preserve_water=0
preserve_lava=0
preserve_plants=1

rule1=0,100,minecraft:stonebrick-0,minecraft:stonebrick-0,minecraft:stonebrick-0,minecraft:stonebrick-1,minecraft:stonebrick-1,minecraft:stonebrick-2,minecraft:moss_stone

rule2=0,100,minecraft:stonebrick-3
rule3=0,100,minecraft:water-0
rule4=0,100,minecraft:water-8
rule5=0,100,minecraft:water-1
rule6=0,100,minecraft:water-2
rule7=0,100,minecraft:water-3
rule8=0,100,minecraft:water-4
rule9=0,100,minecraft:water-5
rule10=0,100,minecraft:stone_brick_stairs-3
rule11=0,100,minecraft:stone_brick_stairs-1
rule12=0,100,minecraft:water-6
rule13=0,100,minecraft:stone_brick_stairs-2
rule14=0,100,minecraft:water-7
rule15=0,100,minecraft:water-9
rule16=0,100,minecraft:stone_brick_stairs-0
rule17=0,100,minecraft:stone_slab-5

rule18=0,100,minecraft:cobblestone_wall-0,minecraft:cobblestone_wall-1

rule19=0,100,minecraft:stone_brick_stairs-5
rule20=0,100,minecraft:stone_slab-8
rule21=0,100,minecraft:stone_brick_stairs-7
rule22=0,100,minecraft:stone_brick_stairs-6
rule23=0,100,minecraft:stone_brick_stairs-4
rule24=0,100,minecraft:water-10

rule25=0,100,MobSpawner:Skeleton,MobSpawner:Zombie,MobSpawner:Spider

rule26=0,100,minecraft:emerald_block-0
rule27=0,100,ChestGenHook:chests/simple_dungeon:6-5
rule28=0,100,minecraft:vine-8
rule29=0,100,minecraft:vine-2
rule30=0,100,minecraft:vine-4
rule31=0,100,minecraft:vine-1
rule32=0,100,minecraft:vine-3
rule33=0,100,minecraft:vine-12
rule34=0,100,minecraft:vine-6
rule35=0,100,minecraft:vine-9
rule36=0,100,minecraft:stone_slab-13
rule37=1,100,minecraft:torch-5

layer
1,1,1,1,1,1,1,1,1,1,1,1,1,1,1,1,1,1,1,1,1
1,1,1,1,1,1,1,1,1,1,1,1,1,1,1,1,1,1,1,1,1
1,1,1,1,1,1,1,1,1,1,1,1,1,1,1,1,1,1,1,1,1
1,1,1,1,1,1,1,1,1,1,1,1,1,1,1,1,1,1,1,1,1
1,1,1,1,1,1,1,1,1,1,1,1,1,1,1,1,1,1,1,1,1
1,1,1,1,1,1,1,1,1,1,1,1,1,1,1,1,1,1,1,1,1
1,1,1,1,1,1,1,1,1,1,1,1,1,1,1,1,1,1,1,1,1
1,1,1,1,1,1,1,1,1,1,1,1,1,1,1,1,1,1,1,1,1
1,1,1,1,1,1,1,1,1,1,1,1,1,1,1,1,1,1,1,1,1
1,1,1,1,1,1,1,1,1,1,1,1,1,1,1,1,1,1,1,1,1
1,1,1,1,1,1,1,1,1,1,1,1,1,1,1,1,1,1,1,1,1
1,1,1,1,1,1,1,1,1,1,1,1,1,1,1,1,1,1,1,1,1
1,1,1,1,1,1,1,1,1,1,1,1,1,1,1,1,1,1,1,1,1
1,1,1,1,1,1,1,1,1,1,1,1,1,1,1,1,1,1,1,1,1
1,1,1,1,1,1,1,1,1,1,1,1,1,1,1,1,1,1,1,1,1
1,1,1,1,1,1,1,1,1,1,1,1,1,1,1,1,1,1,1,1,1
1,1,1,1,1,1,1,1,1,1,1,1,1,1,1,1,1,1,1,1,1
1,1,1,1,1,1,1,1,1,1,1,1,1,1,1,1,1,1,1,1,1
1,1,1,1,1,1,1,1,1,1,1,1,1,1,1,1,1,1,1,1,1
1,1,1,1,1,1,1,1,1,1,1,1,1,1,1,1,1,1,1,1,1
1,1,1,1,1,1,1,1,1,1,1,1,1,1,1,1,1,1,1,1,1
endlayer

layer
1,1,1,1,1,1,1,1,1,1,1,1,1,1,1,1,1,1,1,1,1
1,1,1,1,1,1,1,1,1,1,1,1,1,1,1,1,1,1,1,1,1
1,1,1,1,1,1,1,1,1,1,1,1,1,1,1,1,1,1,1,1,1
1,1,1,1,1,1,1,1,1,1,1,1,1,1,1,1,1,1,1,1,1
1,1,1,1,1,1,1,1,1,1,1,1,1,1,1,1,1,1,1,1,1
1,1,1,1,1,1,1,1,1,1,1,1,1,1,1,1,1,1,1,1,1
1,1,1,1,1,1,1,1,1,1,1,1,1,1,1,1,1,1,1,1,1
1,1,1,1,1,1,1,1,1,1,1,1,1,1,1,1,1,1,1,1,1
1,1,1,1,1,1,1,1,1,1,2,1,1,1,1,1,1,1,1,1,1
1,1,1,1,1,1,1,1,1,3,3,3,1,1,1,1,1,1,1,1,1
1,1,1,1,1,1,1,1,2,3,3,3,2,1,1,1,1,1,1,1,1
1,1,1,1,1,1,1,1,1,3,3,3,1,1,1,1,1,1,1,1,1
1,1,1,1,1,1,1,1,1,1,2,1,1,1,1,1,1,1,1,1,1
1,1,1,1,1,1,1,1,1,1,1,1,1,1,1,1,1,1,1,1,1
1,1,1,1,1,1,1,1,1,1,1,1,1,1,1,1,1,1,1,1,1
1,1,1,1,1,1,1,1,1,1,1,1,1,1,1,1,1,1,1,1,1
1,1,1,1,1,1,1,1,1,1,1,1,1,1,1,1,1,1,1,1,1
1,1,1,1,1,1,1,1,1,1,1,1,1,1,1,1,1,1,1,1,1
1,1,1,1,1,1,1,1,1,1,1,1,1,1,1,1,1,1,1,1,1
1,1,1,1,1,1,1,1,1,1,1,1,1,1,1,1,1,1,1,1,1
1,1,1,1,1,1,1,1,1,1,1,1,1,1,1,1,1,1,1,1,1
endlayer

layer
1,1,1,1,1,1,1,1,1,1,1,1,1,1,1,1,1,1,1,1,1
1,1,1,1,1,1,1,1,1,1,1,1,1,1,1,1,1,1,1,1,1
1,1,1,1,1,1,1,1,1,1,4,1,1,1,1,1,1,1,1,1,1
1,1,1,1,1,1,1,1,1,1,5,1,1,1,1,1,1,1,1,1,1
1,1,1,1,1,1,1,1,1,1,6,1,1,1,1,1,1,1,1,1,1
1,1,1,1,1,1,1,1,1,2,7,2,1,1,1,1,1,1,1,1,1
1,1,1,1,1,1,1,1,1,2,8,2,1,1,1,1,1,1,1,1,1
1,1,1,1,1,1,1,1,1,2,9,2,1,1,1,1,1,1,1,1,1
1,1,1,1,1,1,1,1,13,11,12,11,10,1,1,1,1,1,1,1,1
1,1,1,1,1,2,2,2,13,0,14,0,10,2,2,2,1,1,1,1,1
1,1,4,5,6,7,8,9,12,14,0,14,12,9,8,7,6,5,15,1,1
1,1,1,1,1,2,2,2,13,0,14,0,10,2,2,2,1,1,1,1,1
1,1,1,1,1,1,1,1,13,16,12,16,16,1,1,1,1,1,1,1,1
1,1,1,1,1,1,1,1,1,2,9,2,1,1,1,1,1,1,1,1,1
1,1,1,1,1,1,1,1,1,2,8,2,1,1,1,1,1,1,1,1,1
1,1,1,1,1,1,1,1,1,2,7,2,1,1,1,1,1,1,1,1,1
1,1,1,1,1,1,1,1,1,1,6,1,1,1,1,1,1,1,1,1,1
1,1,1,1,1,1,1,1,1,1,5,1,1,1,1,1,1,1,1,1,1
1,1,1,1,1,1,1,1,1,1,4,1,1,1,1,1,1,1,1,1,1
1,1,1,1,1,1,1,1,1,1,1,1,1,1,1,1,1,1,1,1,1
1,1,1,1,1,1,1,1,1,1,1,1,1,1,1,1,1,1,1,1,1
endlayer

layer
1,1,1,1,1,1,1,1,1,1,1,1,1,1,1,1,1,1,1,1,1
1,1,1,1,13,0,10,1,3,3,3,3,3,1,13,0,10,1,1,1,1
1,1,1,1,13,0,10,1,3,3,3,3,3,1,13,0,10,1,1,1,1
1,1,1,1,13,0,10,1,1,1,1,1,1,1,13,0,10,1,1,1,1
1,11,11,11,13,0,11,11,11,11,11,11,11,11,13,0,10,11,11,11,1
1,0,0,0,0,0,0,0,0,0,17,0,0,0,0,0,0,0,0,0,1
1,16,16,16,16,0,0,0,0,0,17,0,0,0,0,0,10,16,16,16,1
1,1,1,1,13,0,0,0,0,0,16,0,0,0,0,0,10,1,1,1,1
1,3,3,1,13,0,0,0,18,0,19,0,18,0,0,0,10,1,5,3,1
1,3,3,1,13,0,0,0,0,20,20,20,0,0,0,0,10,1,5,3,1
1,3,3,1,13,17,17,10,22,20,20,20,21,13,17,17,10,1,5,3,1
1,3,3,1,13,0,0,0,0,20,20,20,0,0,0,0,10,1,5,3,1
1,3,3,1,13,0,0,0,18,0,23,0,18,0,0,0,10,1,5,3,1
1,1,1,1,13,0,0,0,0,0,11,0,0,0,0,0,10,1,1,1,1
1,11,11,11,13,0,0,0,0,0,17,0,0,0,0,0,11,11,11,11,1
1,0,0,0,0,0,0,0,0,0,17,0,0,0,0,0,0,0,0,0,1
1,16,16,16,13,0,10,16,16,16,16,16,16,16,16,0,16,16,16,16,1
1,1,1,1,13,0,10,1,1,1,1,1,1,1,13,0,10,1,1,1,1
1,1,1,1,13,0,10,1,3,3,3,3,3,1,13,0,10,1,1,1,1
1,1,1,1,13,0,10,1,3,3,3,3,3,1,13,0,10,1,1,1,1
1,1,1,1,1,1,1,1,1,1,1,1,1,1,1,1,1,1,1,1,1
endlayer

layer
1,1,1,1,1,1,1,1,1,1,1,1,1,1,1,1,1,1,1,1,1
1,1,1,0,0,0,0,1,24,0,25,0,24,1,0,0,0,0,1,1,1
1,1,1,0,0,0,0,0,0,0,0,0,0,0,0,0,0,0,1,1,1
1,0,0,0,0,0,0,1,0,0,1,0,0,1,0,0,0,0,0,0,1
1,0,0,0,0,0,0,0,0,0,0,0,0,0,0,0,0,0,0,0,1
1,0,0,0,0,0,0,0,0,0,0,0,0,0,0,0,0,0,0,0,1
1,0,0,0,0,0,0,0,0,0,0,0,0,0,0,0,0,0,0,0,1
1,1,0,1,0,0,0,0,0,0,0,0,0,0,0,0,0,1,0,1,1
1,24,0,0,0,0,0,0,18,18,0,18,18,0,0,0,0,0,0,24,1
1,0,0,0,0,0,0,0,18,0,0,0,18,0,0,0,0,0,0,0,1
1,25,0,1,0,0,0,0,0,0,26,0,0,0,0,0,0,1,0,25,1
1,0,0,0,0,0,0,0,18,0,0,0,18,0,0,0,0,0,0,0,1
1,24,0,0,0,0,0,0,18,18,0,18,18,0,0,0,0,0,0,24,1
1,1,0,1,0,0,0,0,0,0,0,0,0,0,0,0,0,1,0,1,1
1,0,0,0,0,0,0,0,0,0,0,0,0,0,0,0,0,0,0,0,1
1,0,0,0,0,0,0,0,0,0,0,0,0,0,0,0,0,0,0,0,1
1,0,0,0,0,0,0,0,0,0,0,0,0,0,0,0,0,0,0,0,1
1,0,0,0,0,0,0,1,0,0,1,0,0,1,0,0,0,0,0,0,1
1,1,1,0,0,0,0,0,0,0,0,0,0,0,0,0,0,0,1,1,1
1,1,1,0,0,0,0,1,24,0,25,0,24,1,0,0,0,0,1,1,1
1,1,1,1,1,1,1,1,1,1,1,1,1,1,1,1,1,1,1,1,1
endlayer

layer
1,1,1,1,1,1,1,1,1,1,1,1,1,1,1,1,1,1,1,1,1
1,1,1,0,0,0,0,1,24,0,0,0,24,1,0,0,0,0,1,1,1
1,1,1,0,0,0,0,0,0,0,0,0,0,0,0,0,0,0,1,1,1
1,0,0,0,0,0,0,1,0,0,1,0,0,1,0,0,0,0,0,0,1
1,0,0,0,0,0,0,0,0,0,0,0,0,0,0,0,0,0,0,0,1
1,0,0,0,0,0,0,0,0,0,0,0,0,0,0,0,0,0,0,0,1
1,0,0,0,0,0,0,0,0,0,0,0,0,0,0,0,0,0,0,0,1
1,1,0,1,0,0,0,0,0,0,0,0,0,0,0,0,0,1,0,1,1
1,24,0,0,0,0,0,0,18,0,0,0,18,0,0,0,0,0,0,24,1
1,0,0,0,0,0,0,0,0,0,0,0,0,0,0,0,0,0,0,0,1
1,0,0,1,0,0,0,0,0,0,27,0,0,0,0,0,0,1,0,0,1
1,0,0,0,0,0,0,0,0,0,0,0,0,0,0,0,0,0,0,0,1
1,24,0,0,0,0,0,0,18,0,0,0,18,0,0,0,0,0,0,24,1
1,1,0,1,0,0,0,0,0,0,0,0,0,0,0,0,0,1,0,1,1
1,0,0,0,0,0,0,0,0,0,0,0,0,0,0,0,0,0,0,0,1
1,0,0,0,0,0,0,0,0,0,0,0,0,0,0,0,0,0,0,0,1
1,0,0,0,0,0,0,0,0,0,0,0,0,0,0,0,0,0,0,0,1
1,0,0,0,0,0,0,1,0,0,1,0,0,1,0,0,0,0,0,0,1
1,1,1,0,0,0,0,0,0,0,0,0,0,0,0,0,0,0,1,1,1
1,1,1,0,0,0,0,1,24,0,0,0,24,1,0,0,0,0,1,1,1
1,1,1,1,1,1,1,1,1,1,1,1,1,1,1,1,1,1,1,1,1
endlayer

layer
1,1,1,1,1,1,1,1,1,1,1,1,1,1,1,1,1,1,1,1,1
1,1,1,0,0,0,0,1,24,0,1,0,24,1,0,0,0,0,1,1,1
1,1,1,0,0,0,0,0,0,0,1,0,0,0,0,0,0,0,1,1,1
1,0,0,0,0,0,0,1,0,0,1,0,0,1,0,0,0,0,0,0,1
1,0,0,0,0,0,0,0,0,0,0,0,0,0,0,0,0,0,0,0,1
1,0,0,0,0,0,0,0,0,0,0,0,0,0,0,0,0,0,0,0,1
1,0,0,0,0,0,0,0,0,0,0,0,0,0,0,0,0,0,0,0,1
1,1,0,1,0,0,0,0,0,0,0,0,0,0,0,0,0,1,0,1,1
1,24,0,0,0,0,0,0,0,0,0,0,0,0,0,0,0,0,0,24,1
1,0,0,0,0,0,0,0,0,0,0,0,0,0,0,0,0,0,0,0,1
1,1,1,1,0,0,0,0,0,0,0,0,0,0,0,0,0,1,1,1,1
1,0,0,0,0,0,0,0,0,0,0,0,0,0,0,0,0,0,0,0,1
1,24,0,0,0,0,0,0,0,0,0,0,0,0,0,0,0,0,0,24,1
1,1,0,1,0,0,0,0,0,0,0,0,0,0,0,0,0,1,0,1,1
1,0,0,0,0,0,0,0,0,0,0,0,0,0,0,0,0,0,0,0,1
1,0,0,0,0,0,0,0,0,0,0,0,0,0,0,0,0,0,0,0,1
1,0,0,0,0,0,0,0,0,0,0,0,0,0,0,0,0,0,0,0,1
1,0,0,0,0,0,0,1,0,0,1,0,0,1,0,0,0,0,0,0,1
1,1,1,0,0,0,0,0,0,0,1,0,0,0,0,0,0,0,1,1,1
1,1,1,0,0,0,0,1,24,0,1,0,24,1,0,0,0,0,1,1,1
1,1,1,1,1,1,1,1,1,1,1,1,1,1,1,1,1,1,1,1,1
endlayer

layer
1,1,1,1,1,1,1,1,1,1,1,1,1,1,1,1,1,1,1,1,1
1,1,1,0,0,0,0,1,24,0,1,0,24,1,0,0,0,0,1,1,1
1,1,1,0,0,0,0,0,0,0,0,0,0,0,0,0,0,0,1,1,1
1,0,0,0,0,0,0,1,0,0,0,0,0,1,0,0,0,0,0,0,1
1,0,0,0,0,0,0,0,0,0,0,0,0,0,0,0,0,0,0,0,1
1,0,0,0,0,0,0,0,0,0,0,0,0,0,0,0,0,0,0,0,1
1,0,0,0,0,0,0,0,0,0,0,0,0,0,0,0,0,0,0,0,1
1,1,0,1,0,0,0,0,0,0,0,0,0,0,0,0,0,1,0,1,1
1,24,0,0,0,0,0,0,0,0,0,0,0,0,0,0,0,0,0,24,1
1,0,0,0,0,0,0,0,0,0,0,0,0,0,0,0,0,0,0,0,1
1,1,0,0,0,0,0,0,0,0,0,0,0,0,0,0,0,0,0,1,1
1,0,0,0,0,0,0,0,0,0,0,0,0,0,0,0,0,0,0,0,1
1,24,0,0,0,0,0,0,0,0,0,0,0,0,0,0,0,0,0,24,1
1,1,0,1,0,0,0,0,0,0,0,0,0,0,0,0,0,1,0,1,1
1,0,0,0,0,0,0,0,0,0,0,0,0,0,0,0,0,0,0,0,1
1,0,0,0,0,0,0,0,0,0,0,0,0,0,0,0,0,0,0,0,1
1,0,0,0,0,0,0,0,0,0,0,0,0,0,0,0,0,0,0,0,1
1,0,0,0,0,0,0,1,0,0,0,0,0,1,0,0,0,0,0,0,1
1,1,1,0,0,0,0,0,0,0,0,0,0,0,0,0,0,0,1,1,1
1,1,1,0,0,0,0,1,24,0,1,0,24,1,0,0,0,0,1,1,1
1,1,1,1,1,1,1,1,1,1,1,1,1,1,1,1,1,1,1,1,1
endlayer

layer
1,1,1,1,1,1,1,1,1,1,1,1,1,1,1,1,1,1,1,1,1
1,1,1,0,0,0,0,1,24,0,1,0,24,1,0,0,0,0,1,1,1
1,1,1,0,0,0,0,0,0,0,0,0,0,0,0,0,0,0,1,1,1
1,0,0,0,0,0,0,1,0,0,0,0,0,1,0,0,0,0,0,0,1
1,0,0,0,0,0,0,0,0,0,0,0,0,0,0,0,0,0,0,0,1
1,0,0,0,0,0,0,0,0,0,0,0,0,0,0,0,0,0,0,0,1
1,0,0,0,0,0,0,0,0,0,0,0,0,0,0,0,0,0,0,0,1
1,1,0,1,0,0,0,0,0,0,0,0,0,0,0,0,0,1,0,1,1
1,24,0,0,0,0,0,0,0,0,0,0,0,0,0,0,0,0,0,24,1
1,0,0,0,0,0,0,0,0,0,0,0,0,0,0,0,0,0,0,0,1
1,1,0,0,0,0,0,0,0,0,0,0,0,0,0,0,0,0,0,1,1
1,0,0,0,0,0,0,0,0,0,0,0,0,0,0,0,0,0,0,0,1
1,24,0,0,0,0,0,0,0,0,0,0,0,0,0,0,0,0,0,24,1
1,1,0,1,0,0,0,0,0,0,0,0,0,0,0,0,0,1,0,1,1
1,0,0,0,0,0,0,0,0,0,0,0,0,0,0,0,0,0,0,0,1
1,0,0,0,0,0,0,0,0,0,0,0,0,0,0,0,0,0,0,0,1
1,0,0,0,0,0,0,0,0,0,0,0,0,0,0,0,0,0,0,0,1
1,0,0,0,0,0,0,1,0,0,0,0,0,1,0,0,0,0,0,0,1
1,1,1,0,0,0,0,0,0,0,0,0,0,0,0,0,0,0,1,1,1
1,1,1,0,0,0,0,1,24,0,1,0,24,1,0,0,0,0,1,1,1
1,1,1,1,1,1,1,1,1,1,1,1,1,1,1,1,1,1,1,1,1
endlayer

layer
1,1,1,1,1,1,1,1,1,1,1,1,1,1,1,1,1,1,1,1,1
1,1,1,0,0,0,0,1,24,0,1,0,24,1,0,0,0,0,1,1,1
1,1,1,0,0,0,0,0,0,0,0,0,0,0,0,0,0,0,1,1,1
1,0,0,0,0,0,0,1,0,0,0,0,0,1,0,0,0,0,0,0,1
1,0,0,0,0,0,0,0,0,0,0,0,0,0,0,0,0,0,0,0,1
1,0,0,0,0,0,0,0,0,0,0,0,0,0,0,0,0,0,0,0,1
1,0,0,0,0,0,0,0,0,0,0,0,0,0,0,0,0,0,0,0,1
1,1,0,1,0,0,0,0,0,0,0,0,0,0,0,0,0,1,0,1,1
1,24,0,0,0,0,0,0,0,0,0,0,0,0,0,0,0,0,0,24,1
1,0,0,0,0,0,0,0,0,0,0,0,0,0,0,0,0,0,0,0,1
1,1,0,0,0,0,0,0,0,0,0,0,0,0,0,0,0,0,0,1,1
1,0,0,0,0,0,0,0,0,0,0,0,0,0,0,0,0,0,0,0,1
1,24,0,0,0,0,0,0,0,0,0,0,0,0,0,0,0,0,0,24,1
1,1,0,1,0,0,0,0,0,0,0,0,0,0,0,0,0,1,0,1,1
1,0,0,0,0,0,0,0,0,0,0,0,0,0,0,0,0,0,0,0,1
1,0,0,0,0,0,0,0,0,0,0,0,0,0,0,0,0,0,0,0,1
1,0,0,0,0,0,0,0,0,0,0,0,0,0,0,0,0,0,0,0,1
1,0,0,0,0,0,0,1,0,0,0,0,0,1,0,0,0,0,0,0,1
1,1,1,0,0,0,0,0,0,0,0,0,0,0,0,0,0,0,1,1,1
1,1,1,0,0,0,0,1,24,0,1,0,24,1,0,0,0,0,1,1,1
1,1,1,1,1,1,1,1,1,1,1,1,1,1,1,1,1,1,1,1,1
endlayer

layer
1,1,1,1,1,1,1,1,1,1,1,1,1,1,1,1,1,1,1,1,1
1,1,1,0,0,0,0,1,24,0,1,0,24,1,0,0,0,0,1,1,1
1,1,1,0,0,0,0,0,0,0,0,0,0,0,0,0,0,0,1,1,1
1,0,0,0,0,0,0,1,0,0,0,0,0,1,0,0,0,0,0,0,1
1,0,0,0,0,0,0,0,0,0,0,0,0,0,0,0,0,0,0,0,1
1,0,0,0,0,0,0,0,0,0,0,0,0,0,0,0,0,0,0,0,1
1,0,0,0,0,0,0,0,0,0,0,0,0,0,0,0,0,0,0,0,1
1,1,0,1,0,0,0,0,0,0,0,0,0,0,0,0,0,1,0,1,1
1,24,0,0,0,0,0,0,0,0,0,0,0,0,0,0,0,0,0,24,1
1,0,0,0,0,0,0,0,0,0,0,0,0,0,0,0,0,0,0,0,1
1,1,0,0,0,0,0,0,0,0,0,0,0,0,0,0,0,0,0,1,1
1,0,0,0,0,0,0,0,0,0,0,0,0,0,0,0,0,0,0,0,1
1,24,0,0,0,0,0,0,0,0,0,0,0,0,0,0,0,0,0,24,1
1,1,0,1,0,0,0,0,0,0,0,0,0,0,0,0,0,1,0,1,1
1,0,0,0,0,0,0,0,0,0,0,0,0,0,0,0,0,0,0,0,1
1,0,0,0,0,0,0,0,0,0,0,0,0,0,0,0,0,0,0,0,1
1,0,0,0,0,0,0,0,0,0,0,0,0,0,0,0,0,0,0,0,1
1,0,0,0,0,0,0,1,0,0,0,0,0,1,0,0,0,0,0,0,1
1,1,1,0,0,0,0,0,0,0,0,0,0,0,0,0,0,0,1,1,1
1,1,1,0,0,0,0,1,24,0,1,0,24,1,0,0,0,0,1,1,1
1,1,1,1,1,1,1,1,1,1,1,1,1,1,1,1,1,1,1,1,1
endlayer

layer
1,1,1,1,1,1,1,1,1,1,1,1,1,1,1,1,1,1,1,1,1
1,1,1,0,0,0,0,1,24,0,1,0,24,1,0,0,0,0,1,1,1
1,1,1,0,0,0,0,0,0,0,0,0,0,0,0,0,0,0,1,1,1
1,0,0,0,0,0,0,1,0,0,0,0,0,1,0,0,0,0,0,0,1
1,0,0,0,0,0,0,0,0,0,0,0,0,0,0,0,0,0,0,0,1
1,0,0,0,0,0,0,0,0,0,0,0,0,0,0,0,0,0,0,0,1
1,0,0,0,0,0,0,0,0,0,0,0,0,0,0,0,0,0,0,0,1
1,1,0,1,0,0,0,0,0,0,0,0,0,0,0,0,0,1,0,1,1
1,24,0,0,0,0,0,0,0,0,0,0,0,0,0,0,0,0,0,24,1
1,0,0,0,0,0,0,0,0,0,0,0,0,0,0,0,0,0,0,0,1
1,1,0,0,0,0,0,0,0,0,0,0,0,0,0,0,0,0,0,1,1
1,0,0,0,0,0,0,0,0,0,0,0,0,0,0,0,0,0,0,0,1
1,24,0,0,0,0,0,0,0,0,0,0,0,0,0,0,0,0,0,24,1
1,1,0,1,0,0,0,0,0,0,0,0,0,0,0,0,0,1,0,1,1
1,0,0,0,0,0,0,0,0,0,0,0,0,0,0,0,0,0,0,0,1
1,0,0,0,0,0,0,0,0,0,0,0,0,0,0,0,0,0,0,0,1
1,0,0,0,0,0,0,0,0,0,0,0,0,0,0,0,0,0,0,0,1
1,0,0,0,0,0,0,1,0,0,0,0,0,1,0,0,0,0,0,0,1
1,1,1,0,0,0,0,0,0,0,0,0,0,0,0,0,0,0,1,1,1
1,1,1,0,0,0,0,1,24,0,1,0,24,1,0,0,0,0,1,1,1
1,1,1,1,1,1,1,1,1,1,1,1,1,1,1,1,1,1,1,1,1
endlayer

layer
1,1,1,1,1,1,1,1,1,1,1,1,1,1,1,1,1,1,1,1,1
1,1,1,0,0,0,0,1,24,0,1,0,24,1,0,0,0,0,1,1,1
1,1,1,0,0,0,0,0,0,0,0,0,0,0,0,0,0,0,1,1,1
1,0,0,0,0,0,0,1,0,0,0,0,0,1,0,0,0,0,0,0,1
1,0,0,0,0,0,0,0,0,0,0,0,0,0,0,0,0,0,0,0,1
1,0,0,0,0,0,0,0,0,0,0,0,0,0,0,0,0,0,0,0,1
1,0,0,0,0,0,0,0,0,0,0,0,0,0,0,0,0,0,0,0,1
1,1,0,1,0,0,0,0,0,0,0,0,0,0,0,0,0,1,0,1,1
1,24,0,0,0,0,0,0,0,0,0,0,0,0,0,0,0,0,0,24,1
1,0,0,0,0,0,0,0,0,0,0,0,0,0,0,0,0,0,0,0,1
1,1,0,0,0,0,0,0,0,0,0,0,0,0,0,0,0,0,0,1,1
1,0,0,0,0,0,0,0,0,0,0,0,0,0,0,0,0,0,0,0,1
1,24,0,0,0,0,0,0,0,0,0,0,0,0,0,0,0,0,0,24,1
1,1,0,1,0,0,0,0,0,0,0,0,0,0,0,0,0,1,0,1,1
1,0,0,0,0,0,0,0,0,0,0,0,0,0,0,0,0,0,0,0,1
1,0,0,0,0,0,0,0,0,0,0,0,0,0,0,0,0,0,0,0,1
1,0,0,0,0,0,0,0,0,0,0,0,0,0,0,0,0,0,0,0,1
1,0,0,0,0,0,0,1,0,0,0,0,0,1,0,0,0,0,0,0,1
1,1,1,0,0,0,0,0,0,0,0,0,0,0,0,0,0,0,1,1,1
1,1,1,0,0,0,0,1,24,28,1,0,24,1,0,0,0,0,1,1,1
1,1,1,1,1,1,1,1,1,1,1,1,1,1,1,1,1,1,1,1,1
endlayer

layer
1,1,1,1,1,1,1,1,1,1,1,1,1,1,1,1,1,1,1,1,1
1,1,1,0,0,0,0,1,24,29,1,0,24,1,0,0,0,0,1,1,1
1,1,1,0,0,0,0,0,0,0,0,0,0,0,0,0,0,0,1,1,1
1,0,0,0,0,0,0,1,0,0,0,0,0,1,0,0,0,0,0,0,1
1,0,0,0,0,0,0,0,0,0,0,0,0,0,0,0,0,0,0,0,1
1,0,0,0,0,0,0,0,0,0,0,0,0,0,0,0,0,0,0,0,1
1,0,0,0,0,0,0,0,0,0,0,0,0,0,0,0,0,0,0,0,1
1,1,0,1,0,0,0,0,0,0,0,0,0,0,0,0,0,1,0,1,1
1,24,0,0,0,0,0,0,0,0,0,0,0,0,0,0,0,0,0,24,1
1,0,0,0,0,0,0,0,0,0,0,0,0,0,0,0,0,0,0,0,1
1,1,0,0,0,0,0,0,0,0,0,0,0,0,0,0,0,0,30,1,1
1,31,0,0,0,0,0,0,0,0,0,0,0,0,0,0,0,0,0,30,1
1,24,0,0,0,0,0,0,0,0,0,0,0,0,0,0,0,0,0,24,1
1,1,0,1,0,0,0,0,0,0,0,0,0,0,0,0,0,1,0,1,1
1,0,0,0,0,0,0,0,0,0,0,0,0,0,0,0,0,0,0,0,1
1,0,0,0,0,0,0,0,0,0,0,0,0,0,0,0,0,0,0,0,1
1,0,0,0,0,0,0,0,0,0,0,0,0,0,0,0,0,0,0,0,1
1,0,0,0,0,0,0,1,0,0,0,0,0,1,0,0,0,0,0,0,1
1,1,1,0,0,0,0,0,0,0,0,0,0,0,0,0,0,0,1,1,1
1,1,1,0,0,0,0,1,24,28,1,28,24,1,0,0,0,0,1,1,1
1,1,1,1,1,1,1,1,1,1,1,1,1,1,1,1,1,1,1,1,1
endlayer

layer
1,1,1,1,1,1,1,1,1,1,1,1,1,1,1,1,1,1,1,1,1
1,1,1,0,0,0,0,1,24,29,1,32,24,1,0,0,0,0,1,1,1
1,1,1,0,0,0,0,0,0,0,0,0,0,0,0,0,0,0,1,1,1
1,0,0,0,0,0,0,1,0,0,0,0,0,1,0,0,0,0,0,0,1
1,0,0,0,0,0,0,0,0,0,0,0,0,0,0,0,0,0,0,0,1
1,0,0,0,0,0,0,0,0,0,0,0,0,0,0,0,0,0,0,0,1
1,0,0,0,0,0,0,0,0,0,0,0,0,0,0,0,0,0,0,0,1
1,1,0,1,0,0,0,0,0,0,0,0,0,0,0,0,0,1,0,1,1
1,24,0,0,0,0,0,0,0,0,0,0,0,0,0,0,0,0,0,24,1
1,31,0,0,0,0,0,0,0,0,0,0,0,0,0,0,0,0,0,33,1
1,1,0,0,0,0,0,0,0,0,0,0,0,0,0,0,0,0,30,1,1
1,31,0,0,0,0,0,0,0,0,0,0,0,0,0,0,0,0,0,34,1
1,24,0,0,0,0,0,0,0,0,0,0,0,0,0,0,0,0,0,24,1
1,1,0,1,0,0,0,0,0,0,0,0,0,0,0,0,0,1,0,1,1
1,0,0,0,0,0,0,0,0,0,0,0,0,0,0,0,0,0,0,0,1
1,0,0,0,0,0,0,0,0,0,0,0,0,0,0,0,0,0,0,0,1
1,0,0,0,0,0,0,0,0,0,0,0,0,0,0,0,0,0,0,0,1
1,0,0,0,0,0,0,1,0,0,0,0,0,1,0,0,0,0,0,0,1
1,1,1,0,0,0,0,0,0,0,0,0,0,0,0,0,0,0,1,1,1
1,1,1,0,0,0,0,1,24,28,1,35,24,1,0,0,0,0,1,1,1
1,1,1,1,1,1,1,1,1,1,1,1,1,1,1,1,1,1,1,1,1
endlayer

layer
1,1,1,1,1,1,1,1,1,1,1,1,1,1,1,1,1,1,1,1,1
1,1,1,0,0,0,0,1,24,0,1,0,24,1,0,0,0,0,1,1,1
1,1,1,0,0,0,0,0,0,0,19,0,0,0,0,0,0,0,1,1,1
1,0,0,0,0,0,0,1,0,0,0,0,0,1,0,0,0,0,0,0,1
1,0,0,0,0,0,0,0,0,0,0,0,0,0,0,0,0,0,0,0,1
1,0,0,0,0,0,0,0,0,0,0,0,0,0,0,0,0,0,0,0,1
1,0,0,0,0,0,0,0,0,0,0,0,0,0,0,0,0,0,0,0,1
1,1,0,1,0,0,0,0,0,0,0,0,0,0,0,0,0,1,0,1,1
1,24,0,0,0,0,0,0,0,0,0,0,0,0,0,0,0,0,0,24,1
1,0,0,0,0,0,0,0,0,0,0,0,0,0,0,0,0,0,0,0,1
1,1,22,0,0,0,0,0,0,0,0,0,0,0,0,0,0,0,21,1,1
1,0,0,0,0,0,0,0,0,0,0,0,0,0,0,0,0,0,0,0,1
1,24,0,0,0,0,0,0,0,0,0,0,0,0,0,0,0,0,0,24,1
1,1,0,1,0,0,0,0,0,0,0,0,0,0,0,0,0,1,0,1,1
1,0,0,0,0,0,0,0,0,0,0,0,0,0,0,0,0,0,0,0,1
1,0,0,0,0,0,0,0,0,0,0,0,0,0,0,0,0,0,0,0,1
1,0,0,0,0,0,0,0,0,0,0,0,0,0,0,0,0,0,0,0,1
1,0,0,0,0,0,0,1,0,0,0,0,0,1,0,0,0,0,0,0,1
1,1,1,0,0,0,0,0,0,0,23,0,0,0,0,0,0,0,1,1,1
1,1,1,0,0,0,0,1,24,0,1,0,24,1,0,0,0,0,1,1,1
1,1,1,1,1,1,1,1,1,1,1,1,1,1,1,1,1,1,1,1,1
endlayer

layer
1,1,1,1,1,1,1,1,1,1,1,1,1,1,1,1,1,1,1,1,1
1,1,1,0,0,0,0,1,24,11,2,11,24,1,0,0,0,0,1,1,1
1,1,1,0,0,0,0,0,0,11,17,11,0,0,0,0,0,0,1,1,1
1,0,0,0,0,0,0,1,0,11,17,11,0,1,0,0,0,0,0,0,1
1,0,0,0,0,0,0,0,0,0,0,0,0,0,0,0,0,0,0,0,1
1,0,0,0,0,0,0,0,0,0,0,0,0,0,0,0,0,0,0,0,1
1,28,0,0,0,0,0,0,0,0,0,0,0,0,0,0,0,0,0,0,1
1,1,0,1,0,0,0,0,0,0,0,0,0,0,0,0,0,1,0,1,1
1,24,0,0,0,0,0,0,0,0,0,0,0,0,0,0,0,0,0,24,1
1,13,13,13,0,0,0,0,0,0,0,0,0,0,0,0,0,10,10,10,1
1,2,17,17,0,0,0,0,0,0,0,0,0,0,0,0,0,17,17,2,1
1,13,13,13,0,0,0,0,0,0,0,0,0,0,0,0,0,10,10,10,1
1,24,0,0,0,0,0,0,0,0,0,0,0,0,0,0,0,0,0,24,1
1,1,0,1,0,0,0,0,0,0,0,0,0,0,0,0,0,1,0,1,1
1,0,0,0,0,0,0,0,0,0,0,0,0,0,0,0,0,0,0,0,1
1,0,0,0,0,0,0,0,0,0,0,0,0,0,0,0,0,0,0,0,1
1,0,0,0,0,0,0,0,0,0,0,0,0,0,0,0,0,0,0,0,1
1,0,0,0,0,0,0,1,0,16,17,16,30,1,0,0,0,0,0,0,1
1,1,1,0,0,0,0,0,0,16,17,16,0,0,0,0,0,0,1,1,1
1,1,1,0,0,0,0,1,24,16,2,16,24,1,0,0,0,0,1,1,1
1,1,1,1,1,1,1,1,1,1,1,1,1,1,1,1,1,1,1,1,1
endlayer

layer
1,1,1,1,1,1,1,1,1,1,1,1,1,1,1,1,1,1,1,1,1
1,1,1,0,0,0,0,1,6,5,3,5,6,1,0,0,0,0,1,1,1
1,1,1,0,0,0,0,0,0,0,0,0,0,0,0,0,0,0,1,1,1
1,0,0,0,0,0,0,1,0,0,0,0,0,1,0,0,0,0,0,0,1
1,0,0,0,0,0,0,0,0,0,0,0,0,0,0,0,0,0,0,0,1
1,0,0,0,0,0,0,0,0,0,0,0,0,0,0,0,0,0,0,0,1
1,28,0,0,0,0,0,0,0,0,0,0,0,0,0,0,0,0,0,0,1
1,1,0,1,0,0,0,0,0,0,0,0,0,0,0,0,0,1,0,1,1
1,6,0,0,0,0,0,0,0,0,0,0,0,0,0,0,0,29,0,6,1
1,5,0,0,0,0,0,0,0,0,0,0,0,0,0,0,0,0,0,5,1
1,3,0,0,0,0,0,0,0,0,0,0,0,0,0,0,0,0,0,3,1
1,5,0,0,0,0,0,0,0,0,0,0,0,0,0,0,0,0,0,5,1
1,6,0,0,0,0,0,0,0,0,0,0,0,0,0,0,0,0,0,6,1
1,1,0,1,0,0,0,0,0,0,0,0,0,0,0,0,0,1,0,1,1
1,0,0,0,0,0,0,0,0,0,0,0,0,0,0,0,0,0,0,0,1
1,0,0,0,0,0,0,0,0,0,0,0,0,0,0,0,0,0,0,0,1
1,0,0,0,0,0,0,0,0,0,0,0,0,0,0,0,0,0,0,0,1
1,0,0,0,0,0,0,1,0,0,0,0,30,1,0,0,0,0,0,0,1
1,1,1,0,0,0,0,0,0,0,0,0,0,0,0,0,0,0,1,1,1
1,1,1,0,0,0,0,1,6,5,3,5,6,1,0,0,0,0,1,1,1
1,1,1,1,1,1,1,1,1,1,1,1,1,1,1,1,1,1,1,1,1
endlayer

layer
1,1,1,1,1,1,1,1,1,1,1,1,1,1,1,1,1,1,1,1,1
1,1,1,0,0,0,0,1,0,19,36,19,0,1,0,0,0,0,1,1,1
1,1,1,0,0,0,0,0,0,19,36,19,0,0,0,0,0,0,1,1,1
1,0,0,0,0,0,0,1,0,19,36,19,0,1,0,0,0,0,0,0,1
1,0,0,0,0,0,0,29,0,0,0,0,0,29,0,0,0,0,0,0,1
1,0,0,0,0,0,0,0,0,0,0,0,0,0,0,0,0,0,0,0,1
1,28,0,28,0,0,0,0,0,0,0,0,0,0,0,0,0,0,0,0,1
1,1,0,1,31,0,0,0,0,0,0,0,0,0,0,0,30,1,0,1,1
1,0,0,0,0,0,0,0,0,0,0,0,0,0,0,0,0,29,0,0,1
1,22,22,22,0,0,0,0,0,0,0,0,0,0,0,0,0,21,21,21,1
1,36,36,36,0,0,0,0,0,0,0,0,0,0,0,0,0,36,36,36,1
1,22,22,22,0,0,0,0,0,0,0,0,0,0,0,0,0,21,21,21,1
1,0,0,0,0,0,0,0,0,0,0,0,0,0,0,0,0,0,0,0,1
1,1,0,1,31,0,0,0,0,0,0,0,0,0,0,0,30,1,0,1,1
1,0,0,29,0,0,0,0,0,0,0,0,0,0,0,0,0,0,0,0,1
1,0,0,0,0,0,0,0,0,0,0,0,0,0,0,0,0,0,0,0,1
1,0,0,0,0,0,0,28,0,0,0,0,0,28,0,0,0,0,0,0,1
1,0,0,0,0,0,30,1,31,23,36,23,30,1,0,0,0,0,0,0,1
1,1,1,0,0,0,0,0,0,23,36,23,0,0,0,0,0,0,1,1,1
1,1,1,0,0,0,0,1,0,23,36,23,0,1,0,0,0,0,1,1,1
1,1,1,1,1,1,1,1,1,1,1,1,1,1,1,1,1,1,1,1,1
endlayer

layer
1,1,1,1,1,1,1,1,1,1,1,1,1,1,1,1,1,1,1,1,1
1,1,1,0,0,0,0,1,0,2,11,2,0,1,0,0,0,0,1,1,1
1,1,1,31,0,0,0,0,0,0,0,0,0,0,0,0,0,0,1,1,1
1,29,0,0,0,0,0,1,0,0,0,0,0,1,0,0,0,0,0,29,1
1,0,0,0,0,0,0,0,0,0,0,0,0,0,0,0,0,0,0,0,1
1,0,0,0,0,0,0,0,0,0,0,0,0,0,0,0,0,0,0,0,1
1,28,0,0,0,0,0,0,0,0,0,0,0,0,0,0,0,0,0,0,1
1,1,0,1,0,0,0,0,0,0,0,0,0,0,0,0,0,1,0,1,1
1,0,0,0,0,0,0,0,0,0,0,0,0,0,0,0,0,0,0,0,1
1,2,0,0,0,0,0,0,0,0,0,0,0,0,0,0,0,0,0,2,1
1,13,0,0,0,0,0,0,0,0,0,0,0,0,0,0,0,0,0,10,1
1,2,0,0,0,0,0,0,0,0,0,0,0,0,0,0,0,0,0,2,1
1,0,0,0,0,0,0,0,0,0,0,0,0,0,0,0,0,0,0,0,1
1,1,0,1,0,0,0,0,0,0,0,0,0,0,0,0,0,1,0,1,1
1,0,0,0,0,0,0,0,0,0,0,0,0,0,0,0,0,29,0,0,1
1,0,0,0,0,0,0,0,0,0,0,0,0,0,0,0,0,0,0,0,1
1,0,0,0,0,0,0,0,0,0,0,0,0,0,0,0,0,0,0,0,1
1,0,28,0,0,0,0,1,0,0,0,0,30,1,0,0,0,0,28,28,1
1,1,1,0,0,0,0,0,0,0,0,0,0,0,0,0,0,30,1,1,1
1,1,1,0,0,0,0,1,0,2,16,2,0,1,0,0,0,0,1,1,1
1,1,1,1,1,1,1,1,1,1,1,1,1,1,1,1,1,1,1,1,1
endlayer

layer
1,1,1,1,1,1,1,1,1,1,1,1,1,1,1,1,1,1,1,1,1
1,1,1,31,0,0,0,1,0,0,0,0,0,1,31,0,0,30,1,1,1
1,1,1,31,0,0,0,0,0,0,0,0,0,0,0,0,0,30,1,1,1
1,29,29,0,0,0,0,1,0,0,0,0,30,1,0,0,0,0,29,29,1
1,0,0,0,0,0,0,18,0,0,0,0,0,18,0,0,0,0,0,0,1
1,0,0,0,0,0,0,0,0,0,0,0,0,0,0,0,0,0,0,0,1
1,28,0,0,0,0,0,0,0,0,0,0,0,0,0,0,0,28,0,0,1
1,1,0,1,18,0,0,0,0,0,0,0,0,0,0,0,18,1,0,1,1
1,0,0,0,0,0,0,0,0,0,0,0,0,0,0,0,0,29,0,0,1
1,0,0,0,0,0,0,0,0,0,0,0,0,0,0,0,0,0,0,0,1
1,0,0,0,0,0,0,0,0,0,0,0,0,0,0,0,0,0,0,0,1
1,0,0,0,0,0,0,0,0,0,0,0,0,0,0,0,0,0,0,0,1
1,0,0,0,0,0,0,0,0,0,0,0,0,0,0,0,0,0,0,0,1
1,1,0,1,18,0,0,0,0,0,0,0,0,0,0,0,18,1,0,1,1
1,0,0,29,0,0,0,0,0,0,0,0,0,0,0,0,0,29,0,0,1
1,0,0,0,0,0,0,0,0,0,0,0,0,0,0,0,0,0,0,0,1
1,0,0,0,0,0,0,18,0,0,0,0,0,18,0,0,0,0,0,0,1
1,28,28,0,0,0,0,1,0,0,0,0,30,1,31,0,0,0,28,28,1
1,1,1,31,0,0,0,0,0,0,0,0,0,0,0,0,0,30,1,1,1
1,1,1,31,0,0,0,1,0,0,0,0,0,1,0,0,0,30,1,1,1
1,1,1,1,1,1,1,1,1,1,1,1,1,1,1,1,1,1,1,1,1
endlayer

layer
1,1,1,1,1,1,1,1,1,1,1,1,1,1,1,1,1,1,1,1,1
1,1,1,1,22,0,30,1,0,0,0,0,0,1,31,0,21,1,1,1,1
1,1,1,1,22,0,0,0,0,0,0,0,0,0,0,0,21,1,1,1,1
1,1,1,1,22,0,30,1,31,0,0,0,30,1,31,0,21,1,1,1,1
1,19,19,19,19,0,0,37,0,0,0,0,0,37,0,0,19,19,19,19,1
1,0,0,0,0,0,0,0,0,0,0,0,0,0,0,0,0,0,0,0,1
1,28,0,28,0,0,0,0,0,0,0,0,0,0,0,0,0,28,0,28,1
1,1,0,1,37,0,0,0,0,0,0,0,0,0,0,0,37,1,0,1,1
1,0,0,29,0,0,0,0,0,0,0,0,0,0,0,0,0,29,0,0,1
1,0,0,0,0,0,0,0,0,0,0,0,0,0,0,0,0,0,0,0,1
1,0,0,0,0,0,0,0,0,0,0,0,0,0,0,0,0,0,0,0,1
1,0,0,0,0,0,0,0,0,0,0,0,0,0,0,0,0,0,0,0,1
1,0,0,28,0,0,0,0,0,0,0,0,0,0,0,0,0,28,0,0,1
1,1,0,1,37,0,0,0,0,0,0,0,0,0,0,0,37,1,31,1,1
1,29,0,29,0,0,0,0,0,0,0,0,0,0,0,0,0,29,0,29,1
1,0,0,0,0,0,0,0,0,0,0,0,0,0,0,0,0,0,0,0,1
1,23,23,23,23,0,0,37,0,0,0,0,0,37,0,0,21,23,23,23,1
1,1,1,1,22,0,30,1,31,0,0,0,30,1,31,0,21,1,1,1,1
1,1,1,1,22,0,0,29,0,0,0,0,0,0,0,0,21,1,1,1,1
1,1,1,1,22,0,30,1,0,0,0,0,0,1,31,0,21,1,1,1,1
1,1,1,1,1,1,1,1,1,1,1,1,1,1,1,1,1,1,1,1,1
endlayer

layer
1,1,1,1,1,1,1,1,1,1,1,1,1,1,1,1,1,1,1,1,1
1,1,1,1,1,1,1,1,1,1,1,1,1,1,1,1,1,1,1,1,1
1,1,1,1,1,1,1,1,1,1,1,1,1,1,1,1,1,1,1,1,1
1,1,1,1,1,1,1,1,1,1,1,1,1,1,1,1,1,1,1,1,1
1,1,1,1,1,1,1,1,1,1,1,1,1,1,1,1,1,1,1,1,1
1,1,1,1,1,1,1,1,1,1,1,1,1,1,1,1,1,1,1,1,1
1,1,1,1,1,1,1,1,1,1,1,1,1,1,1,1,1,1,1,1,1
1,1,1,1,1,1,1,1,1,1,1,1,1,1,1,1,1,1,1,1,1
1,1,1,1,1,1,1,1,1,1,1,1,1,1,1,1,1,1,1,1,1
1,1,1,1,1,1,1,1,1,1,1,1,1,1,1,1,1,1,1,1,1
1,1,1,1,1,1,1,1,1,1,1,1,1,1,1,1,1,1,1,1,1
1,1,1,1,1,1,1,1,1,1,1,1,1,1,1,1,1,1,1,1,1
1,1,1,1,1,1,1,1,1,1,1,1,1,1,1,1,1,1,1,1,1
1,1,1,1,1,1,1,1,1,1,1,1,1,1,1,1,1,1,1,1,1
1,1,1,1,1,1,1,1,1,1,1,1,1,1,1,1,1,1,1,1,1
1,1,1,1,1,1,1,1,1,1,1,1,1,1,1,1,1,1,1,1,1
1,1,1,1,1,1,1,1,1,1,1,1,1,1,1,1,1,1,1,1,1
1,1,1,1,1,1,1,1,1,1,1,1,1,1,1,1,1,1,1,1,1
1,1,1,1,1,1,1,1,1,1,1,1,1,1,1,1,1,1,1,1,1
1,1,1,1,1,1,1,1,1,1,1,1,1,1,1,1,1,1,1,1,1
1,1,1,1,1,1,1,1,1,1,1,1,1,1,1,1,1,1,1,1,1
endlayer

