# Jungle Tree Stand
# MC 1.7.10; 4 Nov 2014
# Created by Ruins mod version 14.1 Ingame Parser
# authoring Player: Jordan_Greywolf

# Last Updated 25 Mar 2016
# Updated to MC 1.12: 23 Jun 2017
# Updated to MC 1.12.1: 10 Sep 2017

biomesToSpawnIn=jungle,jungle m,junglehills,jungle_edge,jungleedge,jungleedge m,mini_jungle,temperate rainforest,rainforest,mutated_jungle,mutated_jungle_edge

weight=1
embed_into_distance=10
acceptable_target_blocks=

unacceptable_target_blocks=flowing_water,water,flowing_lava,lava,Natura:Cloud,slime_congealed,slime_dirt,slime_grass,command_block,planks,planks2,concrete,cobblestone,stonebrick,brick_block,glass,torch,oak_stairs,stone_stairs,brick_stairs,stone_brick_stairs,nether_brick_stairs,sandstone_stairs,spruce_stairs,birch_stairs,jungle_stairs,quartz_stairs,acacia_stairs,dark_oak_stairs,cobblestone_wall,stone_slab,double_stone_slab,stone_slab2,wooden_slab,double_wooden_slab,nether_brick,fence

dimensions=39,16,14
allowable_overhang=999
max_leveling=10
leveling_buffer=-1
preserve_water=0
preserve_lava=0
preserve_plants=1

rule1=0,100,minecraft:grass-0
rule2=0,100,minecraft:grass-0
rule3=0,100,minecraft:double_plant-2
rule4=0,100,minecraft:leaves-7
rule5=0,100,minecraft:vine-1
rule6=0,100,minecraft:log-3
rule7=0,100,minecraft:vine-4
rule8=0,100,minecraft:vine-2
rule9=0,100,minecraft:double_plant-8
rule10=0,100,minecraft:vine-8
rule11=0,100,minecraft:double_plant-8
rule12=0,100,minecraft:double_plant-8
rule13=0,100,minecraft:double_plant-8
rule14=0,100,minecraft:leaves-7
rule15=0,100,minecraft:leaves-7
rule16=0,100,minecraft:leaves-7
rule17=0,100,minecraft:planks-3
rule18=0,100,minecraft:wooden_slab-3
rule19=0,100,minecraft:jungle_stairs-0
rule20=0,100,minecraft:jungle_stairs-1
rule21=0,100,minecraft:fence-0
rule22=0,100,minecraft:trapdoor-2
rule23=0,100,preserveBlock

# -10
layer
23,23,23,23,23,23,1,1,1,1,23,23,23,23
23,23,23,23,23,1,1,1,1,1,1,23,23,23
23,23,23,23,1,1,1,1,1,1,1,1,23,23
23,23,23,1,1,1,1,1,1,1,1,1,1,23
23,23,1,1,1,1,1,2,2,1,1,1,1,1
23,1,1,1,1,1,1,2,2,1,1,1,1,1
23,1,1,1,1,1,1,2,2,1,1,1,1,1
23,1,1,1,1,1,1,2,2,1,1,1,1,1
23,1,1,1,1,1,1,2,2,1,1,1,1,1
23,23,1,1,1,1,1,2,2,1,1,1,1,1
23,23,23,1,1,1,1,1,1,1,1,1,1,23
23,23,23,23,1,1,1,1,1,1,1,1,23,23
23,23,23,23,23,1,1,1,1,1,1,23,23,23
23,23,23,23,23,23,1,1,1,1,23,23,23,23
23,23,23,23,23,23,23,23,23,23,23,23,23,23
23,23,23,23,23,23,23,23,23,23,23,23,23,23
endlayer

# -9
layer
23,23,23,23,23,23,1,1,1,1,23,23,23,23
23,23,23,23,23,1,1,1,1,1,1,23,23,23
23,23,23,23,1,1,1,1,1,1,1,1,23,23
23,23,23,1,1,1,1,1,1,1,1,1,1,23
23,23,1,1,1,1,1,2,2,1,1,1,1,1
23,1,1,1,1,1,1,2,2,1,1,1,1,1
23,1,1,1,1,1,1,2,2,1,1,1,1,1
23,1,1,1,1,1,1,2,2,1,1,1,1,1
23,1,1,1,1,1,1,2,2,1,1,1,1,1
23,23,1,1,1,1,1,2,2,1,1,1,1,1
23,23,23,1,1,1,1,1,1,1,1,1,1,23
23,23,23,23,1,1,1,1,1,1,1,1,23,23
23,23,23,23,23,1,1,1,1,1,1,23,23,23
23,23,23,23,23,23,1,1,1,1,23,23,23,23
23,23,23,23,23,23,23,23,23,23,23,23,23,23
23,23,23,23,23,23,23,23,23,23,23,23,23,23
endlayer

# -8
layer
23,23,23,23,23,23,1,1,1,1,23,23,23,23
23,23,23,23,23,1,1,1,1,1,1,23,23,23
23,23,23,23,1,1,1,1,1,1,1,1,23,23
23,23,23,1,1,1,1,1,1,1,1,1,1,23
23,23,1,1,1,1,1,2,2,1,1,1,1,1
23,1,1,1,1,1,1,2,2,1,1,1,1,1
23,1,1,1,1,1,1,2,2,1,1,1,1,1
23,1,1,1,1,1,1,2,2,1,1,1,1,1
23,1,1,1,1,1,1,2,2,1,1,1,1,1
23,23,1,1,1,1,1,2,2,1,1,1,1,1
23,23,23,1,1,1,1,1,1,1,1,1,1,23
23,23,23,23,1,1,1,1,1,1,1,1,23,23
23,23,23,23,23,1,1,1,1,1,1,23,23,23
23,23,23,23,23,23,1,1,1,1,23,23,23,23
23,23,23,23,23,23,23,23,23,23,23,23,23,23
23,23,23,23,23,23,23,23,23,23,23,23,23,23
endlayer

# -7
layer
23,23,23,23,23,23,1,1,1,1,23,23,23,23
23,23,23,23,23,1,1,1,1,1,1,23,23,23
23,23,23,23,1,1,1,1,1,1,1,1,23,23
23,23,23,1,1,1,1,1,1,1,1,1,1,23
23,23,1,1,1,1,1,2,2,1,1,1,1,1
23,1,1,1,1,1,1,2,2,1,1,1,1,1
23,1,1,1,1,1,1,2,2,1,1,1,1,1
23,1,1,1,1,1,1,2,2,1,1,1,1,1
23,1,1,1,1,1,1,2,2,1,1,1,1,1
23,23,1,1,1,1,1,2,2,1,1,1,1,1
23,23,23,1,1,1,1,1,1,1,1,1,1,23
23,23,23,23,1,1,1,1,1,1,1,1,23,23
23,23,23,23,23,1,1,1,1,1,1,23,23,23
23,23,23,23,23,23,1,1,1,1,23,23,23,23
23,23,23,23,23,23,23,23,23,23,23,23,23,23
23,23,23,23,23,23,23,23,23,23,23,23,23,23
endlayer


# -6
layer
23,23,23,23,23,23,1,1,1,1,23,23,23,23
23,23,23,23,23,1,1,1,1,1,1,23,23,23
23,23,23,23,1,1,1,1,1,1,1,1,23,23
23,23,23,1,1,1,1,1,1,1,1,1,1,23
23,23,1,1,1,1,1,2,2,1,1,1,1,1
23,1,1,1,1,1,1,2,2,1,1,1,1,1
23,1,1,1,1,1,1,2,2,1,1,1,1,1
23,1,1,1,1,1,1,2,2,1,1,1,1,1
23,1,1,1,1,1,1,2,2,1,1,1,1,1
23,23,1,1,1,1,1,2,2,1,1,1,1,1
23,23,23,1,1,1,1,1,1,1,1,1,1,23
23,23,23,23,1,1,1,1,1,1,1,1,23,23
23,23,23,23,23,1,1,1,1,1,1,23,23,23
23,23,23,23,23,23,1,1,1,1,23,23,23,23
23,23,23,23,23,23,23,23,23,23,23,23,23,23
23,23,23,23,23,23,23,23,23,23,23,23,23,23
endlayer


# -5
layer
23,23,23,23,23,23,1,1,1,1,23,23,23,23
23,23,23,23,23,1,1,1,1,1,1,23,23,23
23,23,23,23,1,1,1,1,1,1,1,1,23,23
23,23,23,1,1,1,1,1,1,1,1,1,1,23
23,23,1,1,1,1,1,2,2,1,1,1,1,1
23,1,1,1,1,1,1,2,2,1,1,1,1,1
23,1,1,1,1,1,1,2,2,1,1,1,1,1
23,1,1,1,1,1,1,2,2,1,1,1,1,1
23,1,1,1,1,1,1,2,2,1,1,1,1,1
23,23,1,1,1,1,1,2,2,1,1,1,1,1
23,23,23,1,1,1,1,1,1,1,1,1,1,23
23,23,23,23,1,1,1,1,1,1,1,1,23,23
23,23,23,23,23,1,1,1,1,1,1,23,23,23
23,23,23,23,23,23,1,1,1,1,23,23,23,23
23,23,23,23,23,23,23,23,23,23,23,23,23,23
23,23,23,23,23,23,23,23,23,23,23,23,23,23
endlayer


# -4
layer
23,23,23,23,23,23,23,23,23,23,23,23,23,23
23,23,23,23,23,23,1,1,1,1,23,23,23,23
23,23,23,23,23,1,1,1,1,1,1,23,23,23
23,23,23,23,1,1,1,1,1,1,1,1,23,23
23,23,23,1,1,1,1,1,1,1,1,1,1,23
23,23,1,1,1,1,1,2,2,1,1,1,1,1
23,23,1,1,1,1,1,2,2,1,1,1,1,1
23,23,1,1,1,1,1,2,2,1,1,1,1,1
23,23,1,1,1,1,1,2,2,1,1,1,1,1
23,23,23,1,1,1,1,1,1,1,1,1,1,23
23,23,23,23,1,1,1,1,1,1,1,1,23,23
23,23,23,23,23,1,1,1,1,1,1,23,23,23
23,23,23,23,23,23,1,1,1,1,23,23,23,23
23,23,23,23,23,23,23,23,23,23,23,23,23,23
23,23,23,23,23,23,23,23,23,23,23,23,23,23
23,23,23,23,23,23,23,23,23,23,23,23,23,23
endlayer


# -3
layer
23,23,23,23,23,23,23,23,23,23,23,23,23,23
23,23,23,23,23,23,23,23,23,23,23,23,23,23
23,23,23,23,23,23,1,1,1,1,23,23,23,23
23,23,23,23,23,1,1,1,1,1,1,23,23,23
23,23,23,23,1,1,1,1,1,1,1,1,23,23
23,23,23,1,1,1,1,2,2,1,1,1,1,23
23,23,23,1,1,1,1,2,2,1,1,1,1,23
23,23,23,1,1,1,1,2,2,1,1,1,1,23
23,23,23,1,1,1,1,2,2,1,1,1,1,23
23,23,23,23,1,1,1,1,1,1,1,1,23,23
23,23,23,23,23,1,1,1,1,1,1,23,23,23
23,23,23,23,23,23,1,1,1,1,23,23,23,23
23,23,23,23,23,23,23,23,23,23,23,23,23,23
23,23,23,23,23,23,23,23,23,23,23,23,23,23
23,23,23,23,23,23,23,23,23,23,23,23,23,23
23,23,23,23,23,23,23,23,23,23,23,23,23,23
endlayer


# -2
layer
23,23,23,23,23,23,23,23,23,23,23,23,23,23
23,23,23,23,23,23,23,23,23,23,23,23,23,23
23,23,23,23,23,23,23,23,23,23,23,23,23,23
23,23,23,23,23,23,1,1,1,1,23,23,23,23
23,23,23,23,23,1,1,1,1,1,1,23,23,23
23,23,23,23,1,1,1,2,2,1,1,1,23,23
23,23,23,23,1,1,2,2,2,2,1,1,23,23
23,23,23,23,1,1,2,2,2,2,1,1,23,23
23,23,23,23,1,1,1,2,2,1,1,1,23,23
23,23,23,23,23,1,1,1,1,1,1,23,23,23
23,23,23,23,23,23,1,1,1,1,23,23,23,23
23,23,23,23,23,23,23,23,23,23,23,23,23,23
23,23,23,23,23,23,23,23,23,23,23,23,23,23
23,23,23,23,23,23,23,23,23,23,23,23,23,23
23,23,23,23,23,23,23,23,23,23,23,23,23,23
23,23,23,23,23,23,23,23,23,23,23,23,23,23
endlayer


layer
23,23,23,23,23,23,23,23,23,23,23,23,23,23
23,23,23,23,23,23,23,23,23,23,23,23,23,23
23,23,23,23,23,23,23,23,23,23,23,23,23,23
23,23,23,23,23,23,23,23,23,23,23,23,23,23
23,23,23,23,23,23,1,1,1,1,23,23,23,23
23,23,23,23,23,1,1,2,2,1,1,23,23,23
23,23,23,23,23,1,2,2,2,2,1,23,23,23
23,23,23,23,23,1,2,2,2,2,1,23,23,23
23,23,23,23,23,1,1,2,2,1,1,23,23,23
23,23,23,23,23,23,1,1,1,1,23,23,23,23
23,23,23,23,23,23,23,23,23,23,23,23,23,23
23,23,23,23,23,23,23,23,23,23,23,23,23,23
23,23,23,23,23,23,23,23,23,23,23,23,23,23
23,23,23,23,23,23,23,23,23,23,23,23,23,23
23,23,23,23,23,23,23,23,23,23,23,23,23,23
23,23,23,23,23,23,23,23,23,23,23,23,23,23
endlayer

layer
23,23,23,23,23,23,23,23,23,23,23,23,23,23
23,23,23,23,23,23,23,23,23,23,23,23,23,23
23,23,23,23,23,23,23,23,23,23,23,23,23,23
23,23,23,23,23,23,23,23,23,23,23,23,23,23
23,23,23,23,23,23,3,23,23,3,23,23,23,23
23,23,23,23,23,23,4,6,6,5,4,23,23,23
23,23,23,23,23,7,6,6,6,6,3,23,23,23
23,23,23,23,23,3,6,6,6,6,4,23,23,23
23,23,23,23,23,23,4,6,6,5,4,23,23,23
23,23,23,23,23,23,3,23,8,3,23,23,23,23
23,23,23,23,23,23,23,23,23,23,23,23,23,23
23,23,23,23,23,23,23,23,23,23,23,23,23,23
23,23,23,23,23,23,23,23,23,23,23,23,23,23
23,23,23,23,23,23,23,23,23,23,23,23,23,23
23,23,23,23,23,23,23,23,23,23,23,23,23,23
23,23,23,23,23,23,23,23,23,23,23,23,23,23
endlayer

layer
23,23,23,23,23,23,23,23,23,23,23,23,23,23
23,23,23,23,23,23,23,23,23,23,23,23,23,23
23,23,23,23,23,23,23,23,23,23,23,23,23,23
23,23,23,23,23,23,23,23,23,23,23,23,23,23
23,23,23,23,23,23,11,10,23,9,23,23,23,23
23,23,23,23,23,23,7,6,6,5,23,23,23,23
23,23,23,23,23,7,6,10,6,6,9,23,23,23
23,23,23,23,23,12,6,6,6,6,5,23,23,23
23,23,23,23,23,23,7,6,6,5,23,23,23,23
23,23,23,23,23,23,12,23,8,13,23,23,23,23
23,23,23,23,23,23,23,23,23,23,23,23,23,23
23,23,23,23,23,23,23,23,23,23,23,23,23,23
23,23,23,23,23,23,23,23,23,23,23,23,23,23
23,23,23,23,23,23,23,23,23,23,23,23,23,23
23,23,23,23,23,23,23,23,23,23,23,23,23,23
23,23,23,23,23,23,23,23,23,23,23,23,23,23
endlayer

layer
23,23,23,23,23,23,23,23,23,23,23,23,23,23
23,23,23,23,23,23,23,23,23,23,23,23,23,23
23,23,23,23,23,23,23,23,23,23,23,23,23,23
23,23,23,23,23,23,23,23,23,23,23,23,23,23
23,23,23,23,23,23,23,10,23,23,23,23,23,23
23,23,23,23,23,23,7,6,6,5,23,23,23,23
23,23,23,23,23,7,6,10,10,6,23,23,23,23
23,23,23,23,23,23,6,6,6,6,5,23,23,23
23,23,23,23,23,23,7,6,6,5,23,23,23,23
23,23,23,23,23,23,23,8,8,23,23,23,23,23
23,23,23,23,23,23,23,23,23,23,23,23,23,23
23,23,23,23,23,23,23,23,23,23,23,23,23,23
23,23,23,23,23,23,23,23,23,23,23,23,23,23
23,23,23,23,23,23,23,23,23,23,23,23,23,23
23,23,23,23,23,23,23,23,23,23,23,23,23,23
23,23,23,23,23,23,23,23,23,23,23,23,23,23
endlayer

layer
23,23,23,23,23,23,23,23,23,23,23,23,23,23
23,23,23,23,23,23,23,23,23,23,23,23,23,23
23,23,23,23,23,23,23,23,23,23,23,23,23,23
23,23,23,23,23,23,23,23,23,23,23,23,23,23
23,23,23,23,23,23,23,10,23,23,23,23,23,23
23,23,23,23,23,23,7,6,6,5,23,23,23,23
23,23,23,23,23,7,6,10,10,6,23,23,23,23
23,23,23,23,23,23,6,6,6,6,5,23,23,23
23,23,23,23,23,23,7,6,6,5,23,23,23,23
23,23,23,23,23,23,23,8,8,23,23,23,23,23
23,23,23,23,23,23,23,23,23,23,23,23,23,23
23,23,23,23,23,23,23,23,23,23,23,23,23,23
23,23,23,23,23,23,23,23,23,23,23,23,23,23
23,23,23,23,23,23,23,23,23,23,23,23,23,23
23,23,23,23,23,23,23,23,23,23,23,23,23,23
23,23,23,23,23,23,23,23,23,23,23,23,23,23
endlayer

layer
23,23,23,23,23,23,23,23,23,23,23,23,23,23
23,23,23,23,23,23,23,23,23,23,23,23,23,23
23,23,23,23,23,23,23,23,23,23,23,23,23,23
23,23,23,23,23,23,23,23,23,23,23,23,23,23
23,23,23,23,23,23,23,10,23,23,23,23,23,23
23,23,23,23,23,23,7,6,6,5,23,23,23,23
23,23,23,23,23,7,6,10,10,6,23,23,23,23
23,23,23,23,23,23,6,6,6,6,5,23,23,23
23,23,23,23,23,23,7,6,6,5,23,23,23,23
23,23,23,23,23,23,23,8,8,23,23,23,23,23
23,23,23,23,23,23,23,23,23,23,23,23,23,23
23,23,23,23,23,23,23,23,23,23,23,23,23,23
23,23,23,23,23,23,23,23,23,23,23,23,23,23
23,23,23,23,23,23,23,23,23,23,23,23,23,23
23,23,23,23,23,23,23,23,23,23,23,23,23,23
23,23,23,23,23,23,23,23,23,23,23,23,23,23
endlayer

layer
23,23,23,23,23,23,23,23,23,23,23,23,23,23
23,23,23,23,23,23,23,23,23,23,23,23,23,23
23,23,23,23,23,23,23,23,23,23,23,23,23,23
23,23,23,23,23,23,23,23,23,23,23,23,23,23
23,23,23,23,23,23,23,10,23,23,23,23,23,23
23,23,23,23,23,23,7,6,6,5,23,23,23,23
23,23,23,23,23,7,6,10,10,6,23,23,23,23
23,23,23,23,23,23,6,6,6,6,5,23,23,23
23,23,23,23,23,23,7,6,6,5,23,23,23,23
23,23,23,23,23,23,23,8,8,23,23,23,23,23
23,23,23,23,23,23,23,23,23,23,23,23,23,23
23,23,23,23,23,23,23,23,23,23,23,23,23,23
23,23,23,23,23,23,23,23,23,23,23,23,23,23
23,23,23,23,23,23,23,23,23,23,23,23,23,23
23,23,23,23,23,23,23,23,23,23,23,23,23,23
23,23,23,23,23,23,23,23,23,23,23,23,23,23
endlayer

layer
23,23,23,23,23,23,23,23,23,23,23,23,23,23
23,23,23,23,23,23,23,23,23,23,23,23,23,23
23,23,23,23,23,23,23,23,23,23,23,23,23,23
23,23,23,23,23,23,23,23,23,23,23,23,23,23
23,23,23,23,23,23,23,10,23,23,23,23,23,23
23,23,23,23,23,23,7,6,6,5,23,23,23,23
23,23,23,23,23,7,6,10,10,6,23,23,23,23
23,23,23,23,23,23,6,6,6,6,5,23,23,23
23,23,23,23,23,23,7,6,6,5,23,23,23,23
23,23,23,23,23,23,23,8,8,23,23,23,23,23
23,23,23,23,23,23,23,23,23,23,23,23,23,23
23,23,23,23,23,23,23,23,23,23,23,23,23,23
23,23,23,23,23,23,23,23,23,23,23,23,23,23
23,23,23,23,23,23,23,23,23,23,23,23,23,23
23,23,23,23,23,23,23,23,23,23,23,23,23,23
23,23,23,23,23,23,23,23,23,23,23,23,23,23
endlayer


layer
23,23,23,23,23,23,23,23,23,23,23,23,23,23
23,23,23,23,23,23,23,23,23,23,23,23,23,23
23,23,23,23,23,23,23,23,23,23,23,23,23,23
23,23,23,23,23,23,23,23,23,23,23,23,23,23
23,23,23,23,23,23,23,10,23,23,23,23,23,23
23,23,23,23,23,23,7,6,6,5,23,23,23,23
23,23,23,23,23,7,6,10,10,6,23,23,23,23
23,23,23,23,23,23,6,6,6,6,5,23,23,23
23,23,23,23,23,23,7,6,6,5,23,23,23,23
23,23,23,23,23,23,23,8,8,23,23,23,23,23
23,23,23,23,23,23,23,23,23,23,23,23,23,23
23,23,23,23,23,23,23,23,23,23,23,23,23,23
23,23,23,23,23,23,23,23,23,23,23,23,23,23
23,23,23,23,23,23,23,23,23,23,23,23,23,23
23,23,23,23,23,23,23,23,23,23,23,23,23,23
23,23,23,23,23,23,23,23,23,23,23,23,23,23
endlayer

layer
23,23,23,23,23,23,23,23,23,23,23,23,23,23
23,23,23,23,23,23,23,23,23,23,23,23,23,23
23,23,23,23,23,23,23,23,23,23,23,23,23,23
23,23,23,23,23,23,23,23,23,23,23,23,23,23
23,23,23,23,23,23,23,10,10,23,23,23,23,23
23,23,23,23,23,23,7,6,6,5,23,23,23,23
23,23,23,23,14,7,6,6,6,5,23,23,23,23
23,23,23,23,14,14,7,6,6,6,5,23,23,23
23,23,23,23,14,14,7,6,6,5,23,23,23,23
23,23,23,23,23,14,14,8,8,23,23,23,23,23
23,23,23,23,23,23,23,23,23,23,23,23,23,23
23,23,23,23,23,23,23,23,23,23,23,23,23,23
23,23,23,23,23,23,23,23,23,23,23,23,23,23
23,23,23,23,23,23,23,23,23,23,23,23,23,23
23,23,23,23,23,23,23,23,23,23,23,23,23,23
23,23,23,23,23,23,23,23,23,23,23,23,23,23
endlayer

layer
23,23,23,23,23,23,23,23,23,23,23,23,23,23
23,23,23,23,23,23,23,23,23,23,23,23,23,23
23,23,23,23,23,23,23,23,23,23,23,23,23,23
23,23,23,23,23,23,23,23,23,23,23,23,23,23
23,23,23,23,23,23,23,10,10,23,23,23,23,23
23,23,23,23,23,23,7,6,6,5,23,23,23,23
23,23,23,23,14,7,6,10,6,5,23,23,23,23
23,23,23,23,14,14,6,6,6,5,23,23,23,23
23,23,23,23,14,14,7,6,6,5,23,23,23,23
23,23,23,23,23,14,14,14,8,23,23,23,23,23
23,23,23,23,23,23,23,23,23,23,23,23,23,23
23,23,23,23,23,23,23,23,23,23,23,23,23,23
23,23,23,23,23,23,23,23,23,23,23,23,23,23
23,23,23,23,23,23,23,23,23,23,23,23,23,23
23,23,23,23,23,23,23,23,23,23,23,23,23,23
23,23,23,23,23,23,23,23,23,23,23,23,23,23
endlayer

layer
23,23,23,23,23,23,23,23,23,23,23,23,23,23
23,23,23,23,23,23,23,23,23,23,23,23,23,23
23,23,23,23,23,23,23,23,23,23,23,23,23,23
23,23,23,23,23,23,23,23,23,23,23,23,23,23
23,23,23,23,23,14,14,10,23,23,23,23,23,23
23,23,23,23,23,23,7,6,6,5,23,23,23,23
23,23,23,23,14,7,6,10,6,5,23,23,23,23
23,23,23,23,14,14,7,6,6,5,23,23,23,23
23,23,23,23,14,14,7,6,6,5,23,23,23,23
23,23,23,23,23,23,23,8,8,23,23,23,23,23
23,23,23,23,23,23,23,23,23,23,23,23,23,23
23,23,23,23,23,23,23,23,23,23,23,23,23,23
23,23,23,23,23,23,23,23,23,23,23,23,23,23
23,23,23,23,23,23,23,23,23,23,23,23,23,23
23,23,23,23,23,23,23,23,23,23,23,23,23,23
23,23,23,23,23,23,23,23,23,23,23,23,23,23
endlayer

layer
23,23,23,23,23,23,23,23,23,23,23,23,23,23
23,23,23,23,23,23,23,23,23,23,23,23,23,23
23,23,23,23,23,23,23,23,23,23,23,23,23,23
23,23,23,23,23,23,23,23,23,23,23,23,23,23
23,23,23,23,14,14,14,14,14,14,14,14,23,23
23,23,23,23,23,14,7,6,6,5,14,14,23,23
23,23,23,23,23,7,6,10,10,6,14,14,23,23
23,23,23,23,14,14,7,6,6,6,14,14,23,23
23,23,23,23,14,14,14,6,6,5,14,14,23,23
23,23,23,23,23,23,23,8,8,23,23,23,23,23
23,23,23,23,23,23,23,23,23,23,23,23,23,23
23,23,23,23,23,23,23,23,23,23,23,23,23,23
23,23,23,23,23,23,23,23,23,23,23,23,23,23
23,23,23,23,23,23,23,23,23,23,23,23,23,23
23,23,23,23,23,23,23,23,23,23,23,23,23,23
23,23,23,23,23,23,23,23,23,23,23,23,23,23
endlayer

layer
23,23,23,23,23,23,23,23,23,23,23,23,23,23
23,23,23,23,23,23,23,23,23,23,23,23,23,23
23,23,23,23,23,23,23,23,23,23,23,23,23,23
23,23,23,23,23,23,23,23,23,23,23,23,23,23
23,23,23,23,23,23,23,10,14,14,14,23,23,23
23,23,23,23,23,23,14,6,6,14,14,14,23,23
23,23,23,23,23,7,6,10,6,6,14,14,23,23
23,23,23,23,23,23,14,6,6,6,14,14,23,23
23,23,23,23,23,23,7,6,6,5,14,14,23,23
23,23,23,23,23,23,23,23,8,23,23,23,23,23
23,23,23,23,23,23,23,23,23,23,23,23,23,23
23,23,23,23,23,23,23,23,23,23,23,23,23,23
23,23,23,23,23,23,23,23,23,23,23,23,23,23
23,23,23,23,23,23,23,23,23,23,23,23,23,23
23,23,23,23,23,23,23,23,23,23,23,23,23,23
23,23,23,23,23,23,23,23,23,23,23,23,23,23
endlayer

layer
23,23,23,23,23,23,23,23,23,23,23,23,23,23
23,23,23,23,23,23,23,23,23,23,23,23,23,23
23,23,23,23,23,23,23,23,23,23,23,23,23,23
23,23,23,23,23,23,23,23,23,23,23,23,23,23
23,23,23,23,23,23,23,10,10,23,23,23,23,23
23,23,23,23,23,23,7,6,6,5,14,23,23,23
23,23,23,23,23,7,6,6,10,6,14,23,23,23
23,23,23,23,23,23,7,6,6,5,14,23,23,23
23,23,23,23,23,23,7,6,6,5,23,23,23,23
23,23,23,23,23,23,23,23,8,23,23,23,23,23
23,23,23,23,23,23,23,23,23,23,23,23,23,23
23,23,23,23,23,23,23,23,23,23,23,23,23,23
23,23,23,23,23,23,23,23,23,23,23,23,23,23
23,23,23,23,23,23,23,23,23,23,23,23,23,23
23,23,23,23,23,23,23,23,23,23,23,23,23,23
23,23,23,23,23,23,23,23,23,23,23,23,23,23
endlayer

layer
23,23,23,23,23,23,23,23,23,23,23,23,23,23
23,23,23,23,23,23,23,23,23,23,23,23,23,23
23,23,23,23,23,23,23,23,23,23,23,23,23,23
23,23,23,23,23,23,23,23,23,23,23,23,23,23
23,23,23,23,23,23,23,10,10,23,23,23,23,23
23,23,23,23,23,23,7,6,6,5,14,14,23,23
23,23,23,23,23,7,6,6,6,5,14,14,23,23
23,23,23,23,23,23,7,6,6,5,14,14,23,23
23,23,23,23,23,23,23,6,6,14,14,14,23,23
23,23,23,23,23,23,23,14,14,14,14,23,23,23
23,23,23,23,23,23,23,23,23,23,23,23,23,23
23,23,23,23,23,23,23,23,23,23,23,23,23,23
23,23,23,23,23,23,23,23,23,23,23,23,23,23
23,23,23,23,23,23,23,23,23,23,23,23,23,23
23,23,23,23,23,23,23,23,23,23,23,23,23,23
23,23,23,23,23,23,23,23,23,23,23,23,23,23
endlayer

layer
23,23,23,23,23,23,23,23,23,23,23,23,23,23
23,23,23,23,23,23,23,23,23,23,23,23,23,23
23,23,23,23,23,23,23,23,23,23,23,23,23,23
23,23,23,23,23,23,23,23,23,23,23,23,23,23
23,23,23,23,23,23,23,10,10,23,23,23,23,23
23,23,23,23,23,23,23,6,6,5,14,14,23,23
23,23,23,23,23,7,6,6,6,5,14,14,23,23
23,23,23,23,23,23,7,6,6,6,14,14,23,23
23,23,23,23,23,23,23,6,6,5,14,14,23,23
23,23,23,23,23,23,23,8,8,14,14,23,23,23
23,23,23,23,23,23,23,23,23,23,23,23,23,23
23,23,23,23,23,23,23,23,23,23,23,23,23,23
23,23,23,23,23,23,23,23,23,23,23,23,23,23
23,23,23,23,23,23,23,23,23,23,23,23,23,23
23,23,23,23,23,23,23,23,23,23,23,23,23,23
23,23,23,23,23,23,23,23,23,23,23,23,23,23
endlayer

layer
23,23,23,23,23,23,23,23,23,23,23,23,23,23
23,23,23,23,23,23,23,23,23,23,23,23,23,23
23,23,23,23,23,23,23,23,23,23,23,23,23,23
23,23,23,23,23,23,23,23,23,23,23,23,23,23
23,23,23,23,23,23,6,10,10,23,23,23,23,23
23,23,23,23,23,23,6,6,6,5,14,23,23,23
23,23,23,23,23,7,6,6,6,14,14,14,23,23
23,23,23,23,23,23,7,6,6,6,6,14,15,23
23,23,23,23,23,23,23,6,6,14,14,14,23,23
23,23,23,23,23,23,23,8,6,23,14,23,23,23
23,23,23,23,23,23,23,23,23,23,23,23,23,23
23,23,23,23,23,23,23,23,23,23,23,23,23,23
23,23,23,23,23,23,23,23,23,23,23,23,23,23
23,23,23,23,23,23,23,23,23,23,23,23,23,23
23,23,23,23,23,23,23,23,23,23,23,23,23,23
23,23,23,23,23,23,23,23,23,23,23,23,23,23
endlayer

layer
23,23,23,23,23,23,23,23,23,23,23,23,23,23
23,23,23,23,23,14,23,23,23,23,23,23,23,23
23,23,23,23,14,14,14,23,23,23,23,23,23,23
23,23,23,14,14,6,16,14,23,23,23,23,23,23
23,23,23,23,14,14,14,23,10,23,23,23,23,23
23,23,23,23,23,14,7,6,6,5,23,23,23,23
23,23,23,23,23,7,6,6,10,16,14,23,23,23
23,23,23,23,23,23,7,6,6,14,14,14,23,23
23,23,23,23,23,23,7,6,6,5,14,23,23,23
23,23,23,23,23,23,23,8,6,23,23,23,23,23
23,23,23,23,23,23,23,23,6,23,23,23,23,23
23,23,23,23,23,23,23,23,23,23,23,23,23,23
23,23,23,23,23,23,23,23,23,23,23,23,23,23
23,23,23,23,23,23,23,23,23,23,23,23,23,23
23,23,23,23,23,23,23,23,23,23,23,23,23,23
23,23,23,23,23,23,23,23,23,23,23,23,23,23
endlayer

layer
23,23,23,23,23,23,23,23,23,23,23,23,23,23
23,23,23,23,23,23,23,23,23,23,15,23,23,23
23,23,23,23,23,14,23,23,23,15,15,15,23,23
23,23,23,23,14,16,14,23,23,15,6,15,23,23
23,23,23,23,23,14,23,10,10,6,15,15,23,23
23,23,23,23,23,6,7,6,6,5,15,15,23,23
23,23,23,23,23,7,6,6,6,6,6,15,15,23
23,23,23,23,23,23,23,6,6,5,4,4,23,23
23,23,23,23,23,23,23,6,6,5,4,23,23,23
23,23,23,23,23,23,23,6,8,14,23,23,23,23
23,23,23,23,23,23,23,23,14,14,14,23,23,23
23,23,23,23,23,23,23,14,14,6,14,15,23,23
23,23,23,23,23,23,23,23,15,14,15,23,23,23
23,23,23,23,23,23,23,23,23,15,23,23,23,23
23,23,23,23,23,23,23,23,23,23,23,23,23,23
23,23,23,23,23,23,23,23,23,23,23,23,23,23
endlayer

layer
23,23,23,23,23,23,23,23,23,23,23,23,23,23
23,23,23,23,23,23,23,23,23,4,4,4,23,23
23,23,23,23,23,23,23,23,4,4,6,4,4,23
23,23,23,23,17,17,17,17,17,17,17,4,4,23
23,23,23,14,17,18,18,18,18,18,17,15,23,23
23,14,14,14,17,19,19,6,6,18,17,15,15,23
15,14,14,14,6,7,6,6,6,18,17,6,15,15
15,14,14,14,17,6,20,6,6,18,17,4,15,23
15,14,14,14,17,18,18,6,6,18,17,4,23,23
23,23,16,14,17,18,18,18,18,18,17,23,23,23
23,23,23,14,17,17,6,17,17,17,17,23,23,23
23,23,23,23,23,23,6,23,14,14,15,23,23,23
23,23,23,23,23,23,15,23,23,14,23,23,23,23
23,23,23,23,23,23,15,23,23,23,23,23,23,23
23,23,23,23,23,23,23,23,23,23,23,23,23,23
23,23,23,23,23,23,23,23,23,23,23,23,23,23
endlayer

layer
23,23,23,23,23,23,23,23,23,23,23,23,23,23
23,23,23,23,23,23,23,23,23,23,23,23,23,23
23,23,23,23,23,23,23,23,23,4,4,4,23,23
23,23,23,23,21,21,21,21,21,21,21,4,23,23
23,23,23,23,21,23,23,10,23,23,21,23,23,23
23,23,23,14,21,23,7,6,6,5,21,15,15,23
23,23,14,14,21,22,18,6,6,23,21,15,15,23
23,15,14,6,21,6,23,6,6,5,21,4,4,23
23,23,15,14,21,23,7,6,6,5,21,23,23,23
23,23,23,14,21,23,23,23,23,23,21,23,23,23
23,23,23,23,21,21,21,21,21,21,21,23,23,23
23,23,23,23,23,14,14,14,23,23,23,23,23,23
23,23,23,23,15,14,6,14,15,23,23,23,23,23
23,23,23,23,23,14,14,14,23,23,23,23,23,23
23,23,23,23,23,23,4,23,23,23,23,23,23,23
23,23,23,23,23,23,23,23,23,23,23,23,23,23
endlayer

layer
23,23,23,23,23,23,23,23,23,23,23,23,23,23
23,23,23,23,23,23,23,23,23,23,23,23,23,23
23,23,23,23,23,23,23,23,23,23,23,23,23,23
23,23,23,23,23,23,23,23,23,23,23,23,23,23
23,23,23,23,23,23,23,10,10,23,23,23,23,23
23,23,23,23,23,23,7,6,6,5,23,23,23,23
23,23,23,14,23,23,7,6,6,5,23,23,23,23
23,23,14,14,14,18,7,6,6,5,23,23,23,23
23,23,23,14,23,23,23,6,6,5,23,23,23,23
23,23,23,23,23,23,23,23,23,23,23,23,23,23
23,23,23,23,23,23,23,23,23,23,23,23,23,23
23,23,23,23,23,23,14,23,23,23,23,23,23,23
23,23,23,23,23,14,14,14,23,23,23,23,23,23
23,23,23,23,23,23,14,23,23,23,23,23,23,23
23,23,23,23,23,23,23,23,23,23,23,23,23,23
23,23,23,23,23,23,23,23,23,23,23,23,23,23
endlayer

layer
23,23,23,23,23,23,23,23,23,23,23,23,23,23
23,23,23,23,23,23,23,23,23,23,23,23,23,23
23,23,23,23,23,23,23,23,23,23,23,23,23,23
23,23,23,23,23,23,23,23,23,23,23,23,23,23
23,23,23,23,23,23,23,10,10,23,23,23,23,23
23,23,23,23,23,23,7,6,6,5,23,23,23,23
23,23,23,23,23,23,7,6,6,5,23,23,23,23
23,23,23,23,23,23,7,6,6,5,23,23,23,23
23,23,23,23,23,23,7,6,6,5,23,23,23,23
23,23,23,23,23,23,23,6,6,14,23,23,23,23
23,23,23,23,23,14,14,6,6,14,15,23,23,23
23,23,23,23,23,14,14,6,14,14,15,23,23,23
23,23,23,23,15,14,14,14,14,14,14,23,23,23
23,23,23,23,23,14,14,14,14,14,23,23,23,23
23,23,23,23,23,4,14,14,14,14,23,23,23,23
23,23,23,23,23,23,23,4,23,23,23,23,23,23
endlayer

layer
23,23,23,23,23,23,23,23,23,23,23,23,23,23
23,23,23,23,23,23,23,23,23,23,23,23,23,23
23,23,23,23,23,23,23,23,23,23,23,23,23,23
23,23,23,23,23,23,23,23,23,23,23,23,23,23
23,23,23,23,23,23,23,10,10,23,23,23,23,23
23,23,23,23,23,23,7,6,6,5,23,23,23,23
23,23,23,23,23,23,7,6,6,5,23,23,23,23
23,23,23,23,23,23,23,6,6,5,23,23,23,23
23,23,23,23,23,23,7,6,6,5,23,23,23,23
23,23,23,23,23,23,23,15,15,23,23,23,23,23
23,23,23,23,23,23,23,14,14,14,23,23,23,23
23,23,23,23,23,23,14,14,14,23,23,23,23,23
23,23,23,23,23,14,14,6,14,14,23,23,23,23
23,23,23,23,23,23,14,14,14,23,23,23,23,23
23,23,23,23,23,23,23,14,23,23,23,23,23,23
23,23,23,23,23,23,23,23,23,23,23,23,23,23
endlayer

layer
23,23,23,23,23,23,23,23,23,23,23,23,23,23
23,23,23,23,23,23,23,23,23,23,23,23,23,23
23,23,23,23,23,23,23,14,14,23,23,23,23,23
23,23,23,23,14,14,14,14,16,14,16,23,23,23
23,23,23,14,14,14,14,14,14,16,16,16,23,23
23,23,23,14,14,14,14,6,6,16,14,16,14,23
23,23,23,14,14,14,14,6,6,14,14,14,14,23
23,23,23,14,14,14,14,6,6,14,14,14,14,23
23,23,23,14,14,14,14,6,6,14,14,14,14,23
23,23,23,15,14,14,14,14,14,14,14,14,15,23
23,23,23,23,15,14,14,14,14,14,14,15,23,23
23,23,23,15,15,14,14,14,14,14,15,23,23,23
23,23,23,15,14,14,14,14,14,14,14,23,23,23
23,23,23,23,23,23,23,14,14,23,23,23,23,23
23,23,23,23,23,23,23,23,23,23,23,23,23,23
23,23,23,23,23,23,23,23,23,23,23,23,23,23
endlayer

layer
23,23,23,23,23,23,23,23,23,23,23,23,23,23
23,23,23,23,23,23,23,23,23,23,23,23,23,23
23,23,23,23,23,23,23,23,23,23,23,23,23,23
23,23,23,23,23,23,23,14,14,23,23,23,23,23
23,23,23,23,23,14,14,14,14,14,14,23,23,23
23,23,23,23,14,14,14,6,6,14,14,16,15,23
23,23,23,23,14,14,14,6,6,14,14,14,15,23
23,23,23,23,14,14,14,14,6,14,14,14,14,23
23,23,23,23,14,14,14,14,14,14,14,14,23,23
23,23,23,23,23,14,14,14,14,14,14,23,23,23
23,23,23,23,23,23,14,14,14,14,23,23,23,23
23,23,23,23,23,23,14,14,14,23,23,23,23,23
23,23,23,23,23,23,23,14,14,23,23,23,23,23
23,23,23,23,23,23,23,23,23,23,23,23,23,23
23,23,23,23,23,23,23,23,23,23,23,23,23,23
23,23,23,23,23,23,23,23,23,23,23,23,23,23
endlayer

layer
23,23,23,23,23,23,23,15,15,23,23,23,23,23
23,23,23,23,15,23,15,14,14,4,4,15,23,23
23,23,23,15,23,15,14,14,14,4,15,15,15,23
23,23,23,15,15,14,14,14,14,14,14,15,15,23
23,23,23,15,14,14,14,14,14,14,14,14,23,23
23,23,23,14,14,14,14,6,6,14,14,14,14,15
23,23,4,14,14,14,14,6,6,14,14,14,14,23
23,23,15,15,14,14,14,14,14,14,14,14,23,23
23,23,4,4,15,14,14,14,14,14,14,23,23,23
23,23,23,4,15,4,14,14,14,14,23,23,23,23
23,23,23,23,15,4,23,14,14,23,23,23,23,23
23,23,23,23,23,23,23,14,23,23,23,23,23,23
23,23,23,23,23,23,23,23,23,23,23,23,23,23
23,23,23,23,23,23,23,23,23,23,23,23,23,23
23,23,23,23,23,23,23,23,23,23,23,23,23,23
23,23,23,23,23,23,23,23,23,23,23,23,23,23
endlayer

layer
23,23,23,23,23,23,23,23,23,23,23,23,23,23
23,23,23,23,23,23,23,23,14,23,23,23,23,23
23,23,23,23,23,15,15,14,14,14,15,23,23,23
23,23,23,23,15,15,15,14,14,14,14,23,23,23
23,23,23,23,23,15,14,14,14,14,14,14,23,23
23,23,23,23,14,14,14,14,6,14,14,14,14,23
23,23,23,23,14,14,14,14,14,14,14,14,23,23
23,23,23,15,15,14,14,14,14,14,14,23,23,23
23,23,23,23,23,4,14,14,14,14,23,23,23,23
23,23,23,23,23,23,23,14,14,23,23,23,23,23
23,23,23,23,23,23,23,23,23,23,23,23,23,23
23,23,23,23,23,23,23,23,23,23,23,23,23,23
23,23,23,23,23,23,23,23,23,23,23,23,23,23
23,23,23,23,23,23,23,23,23,23,23,23,23,23
23,23,23,23,23,23,23,23,23,23,23,23,23,23
23,23,23,23,23,23,23,23,23,23,23,23,23,23
endlayer

layer
23,23,23,23,23,23,23,23,23,23,23,23,23,23
23,23,23,23,23,23,23,23,23,23,23,23,23,23
23,23,23,23,23,23,23,23,14,4,23,23,23,23
23,23,23,23,23,23,15,14,14,14,15,23,23,23
23,23,23,23,23,15,4,14,14,14,14,23,23,23
23,23,23,23,23,14,14,14,14,14,14,14,23,23
23,23,23,23,23,14,14,14,14,14,14,23,23,23
23,23,23,23,23,15,14,14,14,14,4,23,23,23
23,23,23,23,23,23,23,14,14,4,23,23,23,23
23,23,23,23,23,23,23,23,23,23,23,23,23,23
23,23,23,23,23,23,23,23,23,23,23,23,23,23
23,23,23,23,23,23,23,23,23,23,23,23,23,23
23,23,23,23,23,23,23,23,23,23,23,23,23,23
23,23,23,23,23,23,23,23,23,23,23,23,23,23
23,23,23,23,23,23,23,23,23,23,23,23,23,23
23,23,23,23,23,23,23,23,23,23,23,23,23,23
endlayer



