

# JungleIdol (20 Apr 2014)
# Created by Ruins mod version 12.3 Ingame Parser
# authoring Player: Jordan_Greywolf


# Converted to MC 1.12: 8 Apr 2018
# Last Updated: 29 May 2018



BiomesToSpawnIn=bog,extreme_jungle,green_swamp,mini_jungle,jungle,jungle_edge,junglehills,lush_swamp,marsh,mini_jungle,rainforest,swamp,swampland,tropical_rainforest



weight=1
embed_into_distance=1



unacceptable_target_blocks=flowing_water,water,flowing_lava,lava,cloud,Natura:Cloud,slime_congealed,slime_dirt,slime_grass,command_block



dimensions=7,10,10
allowable_overhang=0
max_cut_in=0
cut_in_buffer=0
max_leveling=4
leveling_buffer=-1
preserve_water=0
preserve_lava=0
preserve_plants=1



rule1=0,100,preserveBlock

# Mossy Cobblestone
rule2=0,100,mossy_cobblestone-0

# Water
rule3=0,100,flowing_water
rule4=0,100,flowing_water
rule5=0,100,flowing_water
rule6=0,100,flowing_water

# Spawner
rule7=0,100,MobSpawner:Slime,MobSpawner:Zombie

# Stone Brick Stairs
rule8=0,100,stone_brick_stairs-1

# Cobblestone Wall (Mossy)
rule9=0,100,cobblestone_wall-1

# Water
rule10=0,100,flowing_water

# Stone Brick Stairs
rule11=0,100,stone_brick_stairs-5

# Stone Bricks (Chiseled)
rule12=0,100,stonebrick-3

layer
1,1,2,2,2,2,2,2,1,1
1,2,2,2,2,2,2,2,2,1
2,2,2,2,2,2,2,2,2,2
2,2,2,2,2,2,2,2,2,2
2,2,2,2,2,2,2,2,2,2
2,2,2,2,2,2,2,2,2,2
2,2,2,2,3,3,2,2,2,2
2,2,2,4,5,5,4,2,2,2
1,2,2,6,4,4,6,2,2,1
1,1,2,2,2,2,2,2,1,1
endlayer



layer
1,1,0,0,0,0,0,0,1,1
1,0,0,0,2,2,0,0,0,1
0,0,0,2,7,7,2,0,0,0
0,0,0,2,2,2,2,0,0,0
0,0,0,0,0,0,0,0,0,0
0,0,0,0,0,0,0,0,0,0
0,0,0,0,0,0,0,0,0,0
0,0,0,0,0,0,0,0,0,0
1,0,0,0,0,0,0,0,0,1
1,1,0,0,0,0,0,0,1,1
endlayer



layer
1,0,0,0,0,0,0,0,0,1
0,0,0,0,2,2,0,0,0,0
0,0,0,0,2,2,0,0,0,0
0,0,0,0,2,2,0,0,0,0
0,0,0,0,8,8,0,0,0,0
0,0,0,0,8,8,0,0,0,0
0,0,0,0,0,0,0,0,0,0
0,0,0,0,0,0,0,0,0,0
0,0,0,0,0,0,0,0,0,0
1,0,0,0,0,0,0,0,0,1
endlayer



layer
0,0,0,0,0,0,0,0,0,0
0,0,0,0,0,0,0,0,0,0
0,0,0,9,2,2,9,0,0,0
0,0,0,9,2,2,9,0,0,0
0,0,0,9,10,10,9,0,0,0
0,0,0,9,0,0,9,0,0,0
0,0,0,0,0,0,0,0,0,0
0,0,0,0,0,0,0,0,0,0
0,0,0,0,0,0,0,0,0,0
0,0,0,0,0,0,0,0,0,0
endlayer



layer
0,0,0,0,0,0,0,0,0,0
0,0,0,0,0,0,0,0,0,0
0,0,0,0,2,2,0,0,0,0
0,0,0,0,2,2,0,0,0,0
0,0,0,0,11,11,0,0,0,0
0,0,0,0,11,11,0,0,0,0
0,0,0,0,0,0,0,0,0,0
0,0,0,0,0,0,0,0,0,0
0,0,0,0,0,0,0,0,0,0
0,0,0,0,0,0,0,0,0,0
endlayer



layer
0,0,0,0,0,0,0,0,0,0
0,0,0,0,0,0,0,0,0,0
0,0,0,0,2,2,0,0,0,0
0,0,0,9,12,12,9,0,0,0
0,0,0,0,0,0,0,0,0,0
0,0,0,0,0,0,0,0,0,0
0,0,0,0,0,0,0,0,0,0
0,0,0,0,0,0,0,0,0,0
0,0,0,0,0,0,0,0,0,0
0,0,0,0,0,0,0,0,0,0
endlayer



layer
0,0,0,0,0,0,0,0,0,0
0,0,0,0,0,0,0,0,0,0
0,0,0,0,0,0,0,0,0,0
0,0,0,0,9,9,0,0,0,0
0,0,0,0,0,0,0,0,0,0
0,0,0,0,0,0,0,0,0,0
0,0,0,0,0,0,0,0,0,0
0,0,0,0,0,0,0,0,0,0
0,0,0,0,0,0,0,0,0,0
0,0,0,0,0,0,0,0,0,0
endlayer



