
# Jungle_Ziggurat
# 15 Mar 2014; updated to MC 1.7.10, 10 Oct 2014
# Created by Ruins mod version 12.3 Ingame Parser
# authoring Player: Jordan_Greywolf

# Updated to MC 1.8: 24 Mar 2016
# Updated to MC 1.9: 29 Apr 2016
# Updated to MC 1.12: 23 Jun 2017
# Updated to MC 1.12.1: 10 Sep 2017

biomesToSpawnIn=bayou,bog,dead swamp,dead_swamp,fen,fire swamp,fire_swamp,green swampland,green_swamp,jungle,junglehills,jungle_hills,lush swamp,lush_swamp,mangrove,marsh,ominous woods,quagmire,sludgepit,swamp,swampland,swampland m,swamplands,wetlands,wetland,mutated_jungle,mutated_jungle_edge,tropical_island

uniqueMinDistance=2000
spawnMinDistance=1000

weight=1
embed_into_distance=8


unacceptable_target_blocks=cloud,Natura:Cloud,slime_congealed,slime_dirt,slime_grass,command_block,planks,planks2,concrete,cobblestone,stonebrick,brick_block,glass,torch,oak_stairs,stone_stairs,brick_stairs,stone_brick_stairs,nether_brick_stairs,sandstone_stairs,spruce_stairs,birch_stairs,jungle_stairs,quartz_stairs,acacia_stairs,dark_oak_stairs,cobblestone_wall,stone_slab,double_stone_slab,stone_slab2,wooden_slab,double_wooden_slab,nether_brick,fence

dimensions=20,22,22
allowable_overhang=0
max_cut_in=0
cut_in_buffer=-1
max_leveling=8
leveling_buffer=0
preserve_water=0
preserve_lava=0
preserve_plants=1

rule1=0,100,minecraft:stonebrick-1,minecraft:stonebrick-0,minecraft:stonebrick-2
rule2=0,100,minecraft:water-11
rule3=0,100,IInventory;minecraft:dispenser;minecraft:arrow#10#0-5
rule4=0,100,minecraft:stone_pressure_plate-0
rule5=0,100,minecraft:flowing_lava
rule6=0,100,minecraft:tripwire_hook-4
rule7=0,100,minecraft:tripwire-4
rule8=0,100,minecraft:tripwire_hook-6
rule9=0,100,ChestGenHook:chests/jungle_temple:2-4
rule10=0,100,minecraft:monster_egg-3
rule11=0,100,minecraft:water-13
rule12=0,100,minecraft:water-1
rule13=0,100,IInventory;minecraft:dispenser;minecraft:arrow#10#0-3
rule14=0,100,minecraft:tripwire_hook-2
rule15=0,100,minecraft:water-2
rule16=0,100,minecraft:tripwire_hook-7
rule17=0,100,IInventory;minecraft:dispenser;minecraft:arrow#10#0-2
rule18=0,100,minecraft:tripwire-0
rule19=0,100,ChestGenHook:chests/jungle_temple:2-2
rule20=0,100,minecraft:water-3
rule21=0,100,ChestGenHook:chests/jungle_temple:2-3
rule22=0,100,minecraft:tripwire_hook-1
rule23=0,100,minecraft:tripwire_hook-5
rule24=0,100,ChestGenHook:chests/jungle_temple:2-5
rule25=0,100,IInventory;minecraft:dispenser;minecraft:arrow#10#0-4
rule26=0,100,minecraft:stonebrick-3
rule27=0,100,minecraft:cobblestone_wall-1
rule28=0,100,minecraft:stone_brick_stairs-4
rule29=0,100,minecraft:stone_brick_stairs-6
rule30=0,100,minecraft:stone_brick_stairs-7
rule31=0,100,minecraft:stone_brick_stairs-5
rule32=1,100,minecraft:redstone_torch-5
rule33=2,100,WallSign:null:null:null:null-3
rule34=2,100,WallSign:null:null:null:null-2
rule35=2,100,WallSign:null:null:null:null-5
rule36=2,100,WallSign:null:null:null:null-4
rule37=0,100,minecraft:stone_brick_stairs-0
rule38=0,100,minecraft:stone_brick_stairs-1
rule39=0,100,minecraft:stone_brick_stairs-2
rule40=0,100,minecraft:stone_brick_stairs-3
rule41=0,100,minecraft:water-0
rule42=0,100,minecraft:water-4
rule43=0,100,minecraft:water-5
rule44=2,100,WallSign:null:null:null:null-3
rule45=2,100,WallSign:null:null:null:null-5
rule46=2,100,WallSign:null:null:null:null-4
rule47=2,100,WallSign:null:null:null:null-2
rule48=0,100,minecraft:stone_slab-13

rule49=0,100,preserveBlock

layer
1,1,1,1,1,1,1,1,1,1,1,1,1,1,1,1,1,1,1,1,1,1
1,1,1,1,1,1,1,1,1,1,1,1,1,1,1,1,1,1,1,1,1,1
1,1,1,1,1,1,1,1,1,1,1,1,1,1,1,1,1,1,1,1,1,1
1,1,1,1,1,1,1,1,1,1,1,1,1,1,1,1,1,1,1,1,1,1
1,1,1,1,1,1,1,1,1,1,1,1,1,1,1,1,1,1,1,1,1,1
1,1,1,1,1,1,1,1,1,1,1,1,1,1,1,1,1,1,1,1,1,1
1,1,1,1,1,1,1,1,1,1,1,1,1,1,1,1,1,1,1,1,1,1
1,1,1,1,1,1,1,1,1,1,1,1,1,1,1,1,1,1,1,1,1,1
1,1,1,1,1,1,1,1,1,1,1,1,1,1,1,1,1,1,1,1,1,1
1,1,1,1,1,1,1,1,1,1,1,1,1,1,1,1,1,1,1,1,1,1
1,1,1,1,1,1,1,1,1,1,2,2,1,1,1,1,1,1,1,1,1,1
1,1,1,1,1,1,1,1,1,1,2,2,1,1,1,1,1,1,1,1,1,1
1,1,1,1,1,1,1,1,1,1,1,1,1,1,1,1,1,1,1,1,1,1
1,1,1,1,1,1,1,1,1,1,1,1,1,1,1,1,1,1,1,1,1,1
1,1,1,1,1,1,1,1,1,1,1,1,1,1,1,1,1,1,1,1,1,1
1,1,1,1,1,1,1,1,1,1,1,1,1,1,1,1,1,1,1,1,1,1
1,1,1,1,1,1,1,1,1,1,1,1,1,1,1,1,1,1,1,1,1,1
1,1,1,1,1,1,1,1,1,1,1,1,1,1,1,1,1,1,1,1,1,1
1,1,1,1,1,1,1,1,1,1,1,1,1,1,1,1,1,1,1,1,1,1
1,1,1,1,1,1,1,1,1,1,1,1,1,1,1,1,1,1,1,1,1,1
1,1,1,1,1,1,1,1,1,1,1,1,1,1,1,1,1,1,1,1,1,1
1,1,1,1,1,1,1,1,1,1,1,1,1,1,1,1,1,1,1,1,1,1
endlayer

layer
1,1,1,1,1,1,1,1,1,3,1,1,3,1,1,1,1,1,1,1,1,1
1,0,0,0,0,0,0,0,0,4,0,0,4,0,0,0,0,0,0,0,0,1
1,0,0,0,0,0,0,0,0,0,0,0,0,0,0,0,0,0,0,0,0,1
1,0,0,1,1,1,1,1,1,1,0,0,1,1,1,1,1,1,1,0,0,1
1,0,0,1,5,5,5,5,1,8,7,7,6,1,5,5,5,5,1,0,0,1
1,0,0,1,5,5,5,5,1,1,9,9,1,1,5,5,5,5,1,0,0,1
1,0,0,1,5,5,5,5,5,1,10,10,1,5,5,5,5,5,1,0,0,1
1,0,0,1,5,5,5,5,5,1,11,11,1,5,5,5,5,5,1,0,0,1
1,0,0,1,1,1,5,5,5,1,12,12,1,5,5,5,1,1,1,0,0,1
17,4,0,1,16,1,1,1,1,1,15,15,1,1,1,1,1,14,1,0,4,13
1,0,0,0,7,21,1,11,12,15,20,20,15,12,11,1,19,18,0,0,0,1
1,0,0,0,7,21,1,11,12,15,20,20,15,12,11,1,19,18,0,0,0,1
17,4,0,1,23,1,1,1,1,1,15,15,1,1,1,1,1,22,1,0,4,13
1,0,0,1,1,1,5,5,5,1,12,12,1,5,5,5,1,1,1,0,0,1
1,0,0,1,5,5,5,5,5,1,11,11,1,5,5,5,5,5,1,0,0,1
1,0,0,1,5,5,5,5,5,1,1,1,1,5,5,5,5,5,1,0,0,1
1,0,0,1,5,5,5,5,1,1,24,24,1,1,5,5,5,5,1,0,0,1
1,0,0,1,5,5,5,5,1,8,7,7,6,1,5,5,5,5,1,0,0,1
1,0,0,1,1,1,1,1,1,1,0,0,1,1,1,1,1,1,1,0,0,1
1,0,0,0,0,0,0,0,0,0,0,0,0,0,0,0,0,0,0,0,0,1
1,0,0,0,0,0,0,0,0,4,0,0,4,0,0,0,0,0,0,0,0,1
1,1,1,1,1,1,1,1,1,25,1,1,25,1,1,1,1,1,1,1,1,1
endlayer

layer
1,1,26,1,26,26,26,26,26,1,1,1,1,26,26,26,26,26,1,26,1,1
1,0,0,0,0,0,0,0,0,0,0,0,0,0,0,0,0,0,0,0,0,1
26,0,0,0,0,0,0,0,0,0,0,0,0,0,0,0,0,0,0,0,0,26
1,0,0,27,27,27,27,27,1,1,0,0,1,1,27,27,27,27,27,0,0,1
26,0,0,27,0,0,0,0,1,17,0,0,13,1,0,0,0,0,27,0,0,26
26,0,0,27,0,0,0,0,1,1,0,0,1,1,0,0,0,0,27,0,0,26
26,0,0,27,0,0,0,0,0,0,10,10,0,0,0,0,0,0,27,0,0,26
26,0,0,27,0,0,0,0,0,0,11,11,0,0,0,0,0,0,27,0,0,26
26,0,0,1,1,1,0,0,0,27,0,0,27,0,0,0,1,1,1,0,0,26
1,0,0,1,3,1,0,0,27,10,28,28,1,27,0,0,1,3,1,0,0,1
1,0,0,0,0,0,1,11,0,30,10,10,29,0,11,1,0,0,0,0,0,1
1,0,0,0,0,0,1,11,0,30,10,10,29,0,11,1,0,0,0,0,0,1
1,0,0,1,25,1,0,0,27,1,31,31,1,27,0,0,1,25,1,0,0,1
26,0,0,1,1,1,0,0,0,27,0,0,27,0,0,0,1,1,1,0,0,26
26,0,0,27,0,0,0,0,0,0,11,11,0,0,0,0,0,0,27,0,0,26
26,0,0,27,0,0,0,0,0,0,1,1,0,0,0,0,0,0,27,0,0,26
26,0,0,27,0,0,0,0,1,1,0,0,1,1,0,0,0,0,27,0,0,26
26,0,0,27,0,0,0,0,1,17,0,0,13,1,0,0,0,0,27,0,0,26
1,0,0,27,27,27,27,27,1,1,0,0,1,1,27,27,27,27,27,0,0,1
26,0,0,0,0,0,0,0,0,0,0,0,0,0,0,0,0,0,0,0,0,26
1,0,0,0,0,0,0,0,0,0,0,0,0,0,0,0,0,0,0,0,0,1
1,1,26,1,26,26,26,26,26,1,1,1,1,26,26,26,26,26,1,26,1,1
endlayer

layer
1,1,26,1,26,1,1,1,26,1,1,1,1,26,1,1,1,26,1,26,1,1
1,0,0,0,0,0,0,0,0,0,0,0,0,0,0,0,0,0,0,0,0,1
26,0,0,0,0,0,0,0,0,0,0,0,0,0,0,0,0,0,0,0,0,26
1,0,0,32,0,0,0,27,27,1,1,1,1,27,27,0,0,0,32,0,0,1
26,0,0,0,0,0,0,0,0,1,34,33,1,0,0,0,0,0,0,0,0,26
1,0,0,0,0,0,0,0,0,1,34,33,1,0,0,0,0,0,0,0,0,1
1,0,0,0,0,0,0,0,0,0,1,1,0,0,0,0,0,0,0,0,0,1
1,0,0,27,0,0,0,0,0,0,11,11,0,0,0,0,0,0,27,0,0,1
26,0,0,27,0,0,0,0,0,32,0,0,32,0,0,0,0,0,27,0,0,26
1,0,0,1,1,1,0,0,32,1,10,10,1,32,0,0,1,1,1,0,0,1
1,0,0,1,35,35,1,11,0,10,5,5,10,0,11,1,35,35,1,0,0,1
1,0,0,1,36,36,1,11,0,10,5,5,10,0,11,1,36,36,1,0,0,1
1,0,0,1,1,1,0,0,32,1,10,10,1,32,0,0,1,1,1,0,0,1
26,0,0,27,0,0,0,0,0,32,0,0,32,0,0,0,0,0,27,0,0,26
1,0,0,27,0,0,0,0,0,0,11,11,0,0,0,0,0,0,27,0,0,1
1,0,0,0,0,0,0,0,0,0,1,1,0,0,0,0,0,0,0,0,0,1
1,0,0,0,0,0,0,0,0,1,34,33,1,0,0,0,0,0,0,0,0,1
26,0,0,0,0,0,0,0,0,1,34,33,1,0,0,0,0,0,0,0,0,26
1,0,0,32,0,0,0,27,27,1,1,1,1,27,27,0,0,0,32,0,0,1
26,0,0,0,0,0,0,0,0,0,0,0,0,0,0,0,0,0,0,0,0,26
1,0,0,0,0,0,0,0,0,0,0,0,0,0,0,0,0,0,0,0,0,1
1,1,26,1,26,1,1,1,26,1,1,1,1,26,1,1,1,26,1,26,1,1
endlayer

layer
1,1,26,1,26,26,26,1,26,1,1,1,1,26,1,26,26,26,1,26,1,1
1,0,0,0,0,0,0,0,0,0,0,0,0,0,0,0,0,0,0,0,0,1
26,0,0,0,0,0,0,0,0,0,0,0,0,0,0,0,0,0,0,0,0,26
1,0,0,0,0,0,0,0,0,1,1,1,1,0,0,0,0,0,0,0,0,1
26,0,0,0,0,0,0,0,0,1,5,5,1,0,0,0,0,0,0,0,0,26
26,0,0,0,0,0,0,0,0,1,5,5,1,0,0,0,0,0,0,0,0,26
26,0,0,0,0,0,0,0,0,0,1,1,0,0,0,0,0,0,0,0,0,26
1,0,0,0,0,0,0,0,0,0,11,11,0,0,0,0,0,0,0,0,0,1
26,0,0,0,0,0,0,0,0,0,0,0,0,0,0,0,0,0,0,0,0,26
1,0,0,1,1,1,0,0,0,1,10,10,1,0,0,0,1,1,1,0,0,1
1,0,0,1,5,5,1,11,0,10,0,0,10,0,11,1,5,5,1,0,0,1
1,0,0,1,5,5,1,11,0,10,0,0,10,0,11,1,5,5,1,0,0,1
1,0,0,1,1,1,0,0,0,1,10,10,1,0,0,0,1,1,1,0,0,1
26,0,0,0,0,0,0,0,0,0,0,0,0,0,0,0,0,0,0,0,0,26
1,0,0,0,0,0,0,0,0,0,11,11,0,0,0,0,0,0,0,0,0,1
26,0,0,0,0,0,0,0,0,0,1,1,0,0,0,0,0,0,0,0,0,26
26,0,0,0,0,0,0,0,0,1,5,5,1,0,0,0,0,0,0,0,0,26
26,0,0,0,0,0,0,0,0,1,5,5,1,0,0,0,0,0,0,0,0,26
1,0,0,0,0,0,0,0,0,1,1,1,1,0,0,0,0,0,0,0,0,1
26,0,0,0,0,0,0,0,0,0,0,0,0,0,0,0,0,0,0,0,0,26
1,0,0,0,0,0,0,0,0,0,0,0,0,0,0,0,0,0,0,0,0,1
1,1,26,1,26,26,26,1,26,1,1,1,1,26,1,26,26,26,1,26,1,1
endlayer

layer
1,1,26,1,1,1,26,1,26,1,1,1,1,26,1,26,1,1,1,26,1,1
1,0,0,0,0,0,0,0,0,0,0,0,0,0,0,0,0,0,0,0,0,1
26,0,0,0,0,0,0,0,0,0,0,0,0,0,0,0,0,0,0,0,0,26
1,0,0,0,0,0,0,0,0,1,1,1,1,0,0,0,0,0,0,0,0,1
1,0,0,0,0,0,0,0,0,1,0,0,1,0,0,0,0,0,0,0,0,1
1,0,0,0,0,0,0,0,0,1,0,0,1,0,0,0,0,0,0,0,0,1
26,0,0,0,0,0,0,0,0,0,1,1,0,0,0,0,0,0,0,0,0,26
1,0,0,0,0,0,0,0,0,0,11,11,0,0,0,0,0,0,0,0,0,1
26,0,0,0,0,0,0,0,0,0,0,0,0,0,0,0,0,0,0,0,0,26
1,0,0,1,1,1,0,0,0,1,0,0,1,0,0,0,1,1,1,0,0,1
1,0,0,1,0,0,1,11,0,0,0,0,0,0,11,1,0,0,1,0,0,1
1,0,0,1,0,0,1,11,0,0,0,0,0,0,11,1,0,0,1,0,0,1
1,0,0,1,1,1,0,0,0,1,0,0,1,0,0,0,1,1,1,0,0,1
26,0,0,0,0,0,0,0,0,0,0,0,0,0,0,0,0,0,0,0,0,26
1,0,0,0,0,0,0,0,0,0,11,11,0,0,0,0,0,0,0,0,0,1
26,0,0,0,0,0,0,0,0,0,1,1,0,0,0,0,0,0,0,0,0,26
1,0,0,0,0,0,0,0,0,1,0,0,1,0,0,0,0,0,0,0,0,1
1,0,0,0,0,0,0,0,0,1,0,0,1,0,0,0,0,0,0,0,0,1
1,0,0,0,0,0,0,0,0,1,1,1,1,0,0,0,0,0,0,0,0,1
26,0,0,0,0,0,0,0,0,0,0,0,0,0,0,0,0,0,0,0,0,26
1,0,0,0,0,0,0,0,0,0,0,0,0,0,0,0,0,0,0,0,0,1
1,1,26,1,1,1,26,1,26,1,1,1,1,26,1,26,1,1,1,26,1,1
endlayer

layer
1,1,26,26,26,26,26,1,26,1,1,1,1,26,1,26,26,26,26,26,1,1
1,0,0,0,0,0,0,0,0,0,0,0,0,0,0,0,0,0,0,0,0,1
26,0,0,0,0,0,0,0,0,0,0,0,0,0,0,0,0,0,0,0,0,26
26,0,0,0,0,0,0,0,0,1,1,1,1,0,0,0,0,0,0,0,0,26
26,0,0,0,0,0,0,0,0,0,1,1,0,0,0,0,0,0,0,0,0,26
26,0,0,0,0,0,0,0,0,0,1,1,0,0,0,0,0,0,0,0,0,26
26,0,0,0,0,0,0,0,0,0,1,1,0,0,0,0,0,0,0,0,0,26
1,0,0,0,0,0,0,0,0,0,11,11,0,0,0,0,0,0,0,0,0,1
26,0,0,0,0,0,0,0,0,0,0,0,0,0,0,0,0,0,0,0,0,26
1,0,0,1,0,0,0,0,0,1,0,0,1,0,0,0,0,0,1,0,0,1
1,0,0,1,1,1,1,11,0,0,0,0,0,0,11,1,1,1,1,0,0,1
1,0,0,1,1,1,1,11,0,0,0,0,0,0,11,1,1,1,1,0,0,1
1,0,0,1,0,0,0,0,0,1,0,0,1,0,0,0,0,0,1,0,0,1
26,0,0,0,0,0,0,0,0,0,0,0,0,0,0,0,0,0,0,0,0,26
1,0,0,0,0,0,0,0,0,0,11,11,0,0,0,0,0,0,0,0,0,1
26,0,0,0,0,0,0,0,0,0,1,1,0,0,0,0,0,0,0,0,0,26
26,0,0,0,0,0,0,0,0,0,1,1,0,0,0,0,0,0,0,0,0,26
26,0,0,0,0,0,0,0,0,0,1,1,0,0,0,0,0,0,0,0,0,26
26,0,0,0,0,0,0,0,0,1,1,1,1,0,0,0,0,0,0,0,0,26
26,0,0,0,0,0,0,0,0,0,0,0,0,0,0,0,0,0,0,0,0,26
1,0,0,0,0,0,0,0,0,0,0,0,0,0,0,0,0,0,0,0,0,1
1,1,26,26,26,26,26,1,26,1,1,1,1,26,1,26,26,26,26,26,1,1
endlayer

layer
1,1,1,1,1,1,1,1,1,1,1,1,1,1,1,1,1,1,1,1,1,1
1,0,0,0,0,0,0,0,0,0,0,0,0,0,0,0,0,0,0,0,0,1
1,0,0,0,0,0,0,0,0,0,0,0,0,0,0,0,0,0,0,0,0,1
1,0,0,0,0,0,0,0,0,1,1,1,1,0,0,0,0,0,0,0,0,1
1,0,0,0,0,0,0,0,0,0,0,0,0,0,0,0,0,0,0,0,0,1
1,0,0,0,0,0,0,0,0,0,0,0,0,0,0,0,0,0,0,0,0,1
1,0,0,0,0,0,0,0,0,0,0,0,0,0,0,0,0,0,0,0,0,1
1,0,0,0,0,0,0,0,0,0,11,11,0,0,0,0,0,0,0,0,0,1
1,0,0,0,0,0,0,0,0,0,0,0,0,0,0,0,0,0,0,0,0,1
1,0,0,1,0,0,0,0,0,1,0,0,1,0,0,0,0,0,1,0,0,1
1,0,0,1,0,0,0,11,0,0,0,0,0,0,11,0,0,0,1,0,0,1
1,0,0,1,0,0,0,11,0,0,0,0,0,0,11,0,0,0,1,0,0,1
1,0,0,1,0,0,0,0,0,1,0,0,1,0,0,0,0,0,1,0,0,1
1,0,0,0,0,0,0,0,0,0,0,0,0,0,0,0,0,0,0,0,0,1
1,0,0,0,0,0,0,0,0,0,11,11,0,0,0,0,0,0,0,0,0,1
1,0,0,0,0,0,0,0,0,0,0,0,0,0,0,0,0,0,0,0,0,1
1,0,0,0,0,0,0,0,0,0,0,0,0,0,0,0,0,0,0,0,0,1
1,0,0,0,0,0,0,0,0,0,0,0,0,0,0,0,0,0,0,0,0,1
1,0,0,0,0,0,0,0,0,1,1,1,1,0,0,0,0,0,0,0,0,1
1,0,0,0,0,0,0,0,0,0,0,0,0,0,0,0,0,0,0,0,0,1
1,0,0,0,0,0,0,0,0,0,0,0,0,0,0,0,0,0,0,0,0,1
1,1,1,1,1,1,1,1,1,1,1,1,1,1,1,1,1,1,1,1,1,1
endlayer

layer
49,49,49,49,49,49,49,49,49,26,37,37,26,49,49,49,49,49,49,49,49,49
49,1,1,1,1,1,1,1,1,1,1,1,1,1,1,1,1,1,1,1,1,49
49,1,1,1,1,1,1,1,1,1,1,1,1,1,1,1,1,1,1,1,1,49
49,1,1,1,1,1,1,1,1,1,1,1,1,1,1,1,1,1,1,1,1,49
49,1,1,1,1,0,0,0,0,0,38,38,0,0,0,0,0,1,1,1,1,49
49,1,1,1,0,0,0,0,0,0,38,38,0,0,0,0,0,0,1,1,1,49
49,1,1,1,0,0,0,0,0,0,38,38,0,0,0,0,0,0,1,1,1,49
49,1,1,1,0,0,0,0,0,0,11,11,0,0,0,0,0,0,1,1,1,49
49,1,1,1,0,0,0,0,0,0,0,0,0,0,0,0,0,0,1,1,1,49
26,1,1,1,0,0,0,0,0,1,0,0,1,0,0,0,0,0,1,1,1,26
40,1,1,1,39,39,39,11,0,0,0,0,0,0,11,40,40,40,1,1,1,39
40,1,1,1,39,39,39,11,0,0,0,0,0,0,11,40,40,40,1,1,1,39
26,1,1,1,0,0,0,0,0,1,0,0,1,0,0,0,0,0,1,1,1,26
49,1,1,1,0,0,0,0,0,0,0,0,0,0,0,0,0,0,1,1,1,49
49,1,1,1,0,0,0,0,0,0,11,11,0,0,0,0,0,0,1,1,1,49
49,1,1,1,0,0,0,0,0,0,37,37,0,0,0,0,0,0,1,1,1,49
49,1,1,1,0,0,0,0,0,0,37,37,0,0,0,0,0,0,1,1,1,49
49,1,1,1,1,0,0,0,0,0,37,37,0,0,0,0,0,1,1,1,1,49
49,1,1,1,1,1,1,1,1,1,1,1,1,1,1,1,1,1,1,1,1,49
49,1,1,1,1,1,1,1,1,1,1,1,1,1,1,1,1,1,1,1,1,49
49,1,1,1,1,1,1,1,1,1,1,1,1,1,1,1,1,1,1,1,1,49
49,49,49,49,49,49,49,49,49,26,38,38,26,49,49,49,49,49,49,49,49,49
endlayer

layer
49,49,49,49,49,49,49,49,49,49,49,49,49,49,49,49,49,49,49,49,49,49
49,49,49,49,49,49,49,49,49,26,37,37,26,49,49,49,49,49,49,49,49,49
49,49,1,1,1,1,1,1,1,1,41,41,1,1,1,1,1,1,1,1,49,49
49,49,1,1,1,1,1,1,1,26,12,12,26,1,1,1,1,1,1,1,49,49
49,49,1,1,1,0,0,0,0,27,15,15,27,0,0,0,0,1,1,1,49,49
49,49,1,1,0,0,0,0,0,27,20,20,27,0,0,0,0,0,1,1,49,49
49,49,1,1,0,0,0,0,0,27,42,42,27,0,0,0,0,0,1,1,49,49
49,49,1,1,0,0,0,0,0,0,43,43,0,0,0,0,0,0,1,1,49,49
49,49,1,1,0,0,0,0,0,0,0,0,0,0,0,0,0,0,1,1,49,49
49,26,1,26,27,27,27,0,0,1,0,0,1,0,0,27,27,27,26,1,26,49
49,40,41,12,15,20,42,43,0,0,0,0,0,0,43,42,20,15,12,41,39,49
49,40,41,12,15,20,42,43,0,0,0,0,0,0,43,42,20,15,12,41,39,49
49,26,1,26,27,27,27,0,0,1,0,0,1,0,0,27,27,27,26,1,26,49
49,49,1,1,0,0,0,0,0,0,0,0,0,0,0,0,0,0,1,1,49,49
49,49,1,1,0,0,0,0,0,0,43,43,0,0,0,0,0,0,1,1,49,49
49,49,1,1,0,0,0,0,0,27,42,42,27,0,0,0,0,0,1,1,49,49
49,49,1,1,0,0,0,0,0,27,20,20,27,0,0,0,0,0,1,1,49,49
49,49,1,1,1,0,0,0,0,27,15,15,27,0,0,0,0,1,1,1,49,49
49,49,1,1,1,1,1,1,1,26,12,12,26,1,1,1,1,1,1,1,49,49
49,49,1,1,1,1,1,1,1,1,41,41,1,1,1,1,1,1,1,1,49,49
49,49,49,49,49,49,49,49,49,26,38,38,26,49,49,49,49,49,49,49,49,49
49,49,49,49,49,49,49,49,49,49,49,49,49,49,49,49,49,49,49,49,49,49
endlayer

layer
49,49,49,49,49,49,49,49,49,49,49,49,49,49,49,49,49,49,49,49,49,49
49,49,49,49,49,49,49,49,49,49,49,49,49,49,49,49,49,49,49,49,49,49
49,49,49,49,49,49,49,49,49,26,37,37,26,49,49,49,49,49,49,49,49,49
49,49,49,1,1,1,1,1,1,1,1,1,1,1,1,1,1,1,1,49,49,49
49,49,49,1,1,0,0,0,0,0,31,31,0,0,0,0,0,1,1,49,49,49
49,49,49,1,0,0,0,0,0,0,31,31,0,0,0,0,0,0,1,49,49,49
49,49,49,1,0,0,0,0,0,32,31,31,32,0,0,0,0,0,1,49,49,49
49,49,49,1,0,0,0,0,0,0,0,0,0,0,0,0,0,0,1,49,49,49
49,49,49,1,0,0,0,0,0,0,0,0,0,0,0,0,0,0,1,49,49,49
49,49,26,1,0,0,32,0,0,1,0,0,1,0,0,32,0,0,1,26,49,49
49,49,40,1,29,29,29,0,0,0,0,0,0,0,0,30,30,30,1,39,49,49
49,49,40,1,29,29,29,0,0,0,0,0,0,0,0,30,30,30,1,39,49,49
49,49,26,1,0,0,32,0,0,1,0,0,1,0,0,32,0,0,1,26,49,49
49,49,49,1,0,0,0,0,0,0,0,0,0,0,0,0,0,0,1,49,49,49
49,49,49,1,0,0,0,0,0,0,0,0,0,0,0,0,0,0,1,49,49,49
49,49,49,1,0,0,0,0,0,32,28,28,32,0,0,0,0,0,1,49,49,49
49,49,49,1,0,0,0,0,0,0,28,28,0,0,0,0,0,0,1,49,49,49
49,49,49,1,1,0,0,0,0,0,28,28,0,0,0,0,0,1,1,49,49,49
49,49,49,1,1,1,1,1,1,1,1,1,1,1,1,1,1,1,1,49,49,49
49,49,49,49,49,49,49,49,49,26,38,38,26,49,49,49,49,49,49,49,49,49
49,49,49,49,49,49,49,49,49,49,49,49,49,49,49,49,49,49,49,49,49,49
49,49,49,49,49,49,49,49,49,49,49,49,49,49,49,49,49,49,49,49,49,49
endlayer

layer
49,49,49,49,49,49,49,49,49,49,49,49,49,49,49,49,49,49,49,49,49,49
49,49,49,49,49,49,49,49,49,49,49,49,49,49,49,49,49,49,49,49,49,49
49,49,49,49,49,49,49,49,49,49,49,49,49,49,49,49,49,49,49,49,49,49
49,49,49,49,49,49,49,49,49,26,37,37,26,49,49,49,49,49,49,49,49,49
49,49,49,49,1,1,1,1,1,1,26,26,1,1,1,1,1,1,49,49,49,49
49,49,49,49,1,1,0,0,0,0,0,0,0,0,0,0,1,1,49,49,49,49
49,49,49,49,1,0,0,0,0,0,0,0,0,0,0,0,0,1,49,49,49,49
49,49,49,49,1,0,0,0,0,0,0,0,0,0,0,0,0,1,49,49,49,49
49,49,49,49,1,0,0,0,0,0,0,0,0,0,0,0,0,1,49,49,49,49
49,49,49,26,1,0,0,0,0,1,10,10,1,0,0,0,0,1,26,49,49,49
49,49,49,40,26,0,0,0,0,10,34,35,10,0,0,0,0,26,39,49,49,49
49,49,49,40,26,0,0,0,0,10,36,33,10,0,0,0,0,26,39,49,49,49
49,49,49,26,1,0,0,0,0,1,10,10,1,0,0,0,0,1,26,49,49,49
49,49,49,49,1,0,0,0,0,0,0,0,0,0,0,0,0,1,49,49,49,49
49,49,49,49,1,0,0,0,0,0,0,0,0,0,0,0,0,1,49,49,49,49
49,49,49,49,1,0,0,0,0,0,0,0,0,0,0,0,0,1,49,49,49,49
49,49,49,49,1,1,0,0,0,0,0,0,0,0,0,0,1,1,49,49,49,49
49,49,49,49,1,1,1,1,1,1,26,26,1,1,1,1,1,1,49,49,49,49
49,49,49,49,49,49,49,49,49,26,38,38,26,49,49,49,49,49,49,49,49,49
49,49,49,49,49,49,49,49,49,49,49,49,49,49,49,49,49,49,49,49,49,49
49,49,49,49,49,49,49,49,49,49,49,49,49,49,49,49,49,49,49,49,49,49
49,49,49,49,49,49,49,49,49,49,49,49,49,49,49,49,49,49,49,49,49,49
endlayer

layer
49,49,49,49,49,49,49,49,49,49,49,49,49,49,49,49,49,49,49,49,49,49
49,49,49,49,49,49,49,49,49,49,49,49,49,49,49,49,49,49,49,49,49,49
49,49,49,49,49,49,49,49,49,49,49,49,49,49,49,49,49,49,49,49,49,49
49,49,49,49,49,49,49,49,49,49,49,49,49,49,49,49,49,49,49,49,49,49
49,49,49,49,49,49,49,49,49,26,37,37,26,49,49,49,49,49,49,49,49,49
49,49,49,49,49,1,1,1,1,1,1,1,1,1,1,1,1,49,49,49,49,49
49,49,49,49,49,1,1,0,0,0,0,0,0,0,0,1,1,49,49,49,49,49
49,49,49,49,49,1,0,0,0,0,0,0,0,0,0,0,1,49,49,49,49,49
49,49,49,49,49,1,0,0,0,0,0,0,0,0,0,0,1,49,49,49,49,49
49,49,49,49,26,1,0,0,0,1,10,10,1,0,0,0,1,26,49,49,49,49
49,49,49,49,40,1,0,0,0,10,41,41,10,0,0,0,1,39,49,49,49,49
49,49,49,49,40,1,0,0,0,10,41,41,10,0,0,0,1,39,49,49,49,49
49,49,49,49,26,1,0,0,0,1,10,10,1,0,0,0,1,26,49,49,49,49
49,49,49,49,49,1,0,0,0,0,0,0,0,0,0,0,1,49,49,49,49,49
49,49,49,49,49,1,0,0,0,0,0,0,0,0,0,0,1,49,49,49,49,49
49,49,49,49,49,1,1,0,0,0,0,0,0,0,0,1,1,49,49,49,49,49
49,49,49,49,49,1,1,1,1,1,1,1,1,1,1,1,1,49,49,49,49,49
49,49,49,49,49,49,49,49,49,26,38,38,26,49,49,49,49,49,49,49,49,49
49,49,49,49,49,49,49,49,49,49,49,49,49,49,49,49,49,49,49,49,49,49
49,49,49,49,49,49,49,49,49,49,49,49,49,49,49,49,49,49,49,49,49,49
49,49,49,49,49,49,49,49,49,49,49,49,49,49,49,49,49,49,49,49,49,49
49,49,49,49,49,49,49,49,49,49,49,49,49,49,49,49,49,49,49,49,49,49
endlayer

layer
49,49,49,49,49,49,49,49,49,49,49,49,49,49,49,49,49,49,49,49,49,49
49,49,49,49,49,49,49,49,49,49,49,49,49,49,49,49,49,49,49,49,49,49
49,49,49,49,49,49,49,49,49,49,49,49,49,49,49,49,49,49,49,49,49,49
49,49,49,49,49,49,49,49,49,49,49,49,49,49,49,49,49,49,49,49,49,49
49,49,49,49,49,49,49,49,49,49,49,49,49,49,49,49,49,49,49,49,49,49
49,49,49,49,49,49,49,49,49,26,37,37,26,49,49,49,49,49,49,49,49,49
49,49,49,49,49,49,1,1,1,1,1,1,1,1,1,1,49,49,49,49,49,49
49,49,49,49,49,49,1,1,0,0,0,0,0,0,1,1,49,49,49,49,49,49
49,49,49,49,49,49,1,0,0,0,0,0,0,0,0,1,49,49,49,49,49,49
49,49,49,49,49,26,1,0,0,1,0,0,1,0,0,1,26,49,49,49,49,49
49,49,49,49,49,40,1,0,0,0,0,0,0,0,0,1,39,49,49,49,49,49
49,49,49,49,49,40,1,0,0,0,0,0,0,0,0,1,39,49,49,49,49,49
49,49,49,49,49,26,1,0,0,1,0,0,1,0,0,1,26,49,49,49,49,49
49,49,49,49,49,49,1,0,0,0,0,0,0,0,0,1,49,49,49,49,49,49
49,49,49,49,49,49,1,1,0,0,0,0,0,0,1,1,49,49,49,49,49,49
49,49,49,49,49,49,1,1,1,1,1,1,1,1,1,1,49,49,49,49,49,49
49,49,49,49,49,49,49,49,49,26,38,38,26,49,49,49,49,49,49,49,49,49
49,49,49,49,49,49,49,49,49,49,49,49,49,49,49,49,49,49,49,49,49,49
49,49,49,49,49,49,49,49,49,49,49,49,49,49,49,49,49,49,49,49,49,49
49,49,49,49,49,49,49,49,49,49,49,49,49,49,49,49,49,49,49,49,49,49
49,49,49,49,49,49,49,49,49,49,49,49,49,49,49,49,49,49,49,49,49,49
49,49,49,49,49,49,49,49,49,49,49,49,49,49,49,49,49,49,49,49,49,49
endlayer

layer
49,49,49,49,49,49,49,49,49,49,49,49,49,49,49,49,49,49,49,49,49,49
49,49,49,49,49,49,49,49,49,49,49,49,49,49,49,49,49,49,49,49,49,49
49,49,49,49,49,49,49,49,49,49,49,49,49,49,49,49,49,49,49,49,49,49
49,49,49,49,49,49,49,49,49,49,49,49,49,49,49,49,49,49,49,49,49,49
49,49,49,49,49,49,49,49,49,49,49,49,49,49,49,49,49,49,49,49,49,49
49,49,49,49,49,49,49,49,49,49,49,49,49,49,49,49,49,49,49,49,49,49
49,49,49,49,49,49,49,49,49,26,37,37,26,49,49,49,49,49,49,49,49,49
49,49,49,49,49,49,49,1,1,1,1,1,1,1,1,49,49,49,49,49,49,49
49,49,49,49,49,49,49,1,1,0,0,0,0,1,1,49,49,49,49,49,49,49
49,49,49,49,49,49,26,1,0,1,10,10,1,0,1,26,49,49,49,49,49,49
49,49,49,49,49,49,40,1,0,10,45,44,10,0,1,39,49,49,49,49,49,49
49,49,49,49,49,49,40,1,0,10,47,46,10,0,1,39,49,49,49,49,49,49
49,49,49,49,49,49,26,1,0,1,10,10,1,0,1,26,49,49,49,49,49,49
49,49,49,49,49,49,49,1,1,0,0,0,0,1,1,49,49,49,49,49,49,49
49,49,49,49,49,49,49,1,1,1,1,1,1,1,1,49,49,49,49,49,49,49
49,49,49,49,49,49,49,49,49,26,38,38,26,49,49,49,49,49,49,49,49,49
49,49,49,49,49,49,49,49,49,49,49,49,49,49,49,49,49,49,49,49,49,49
49,49,49,49,49,49,49,49,49,49,49,49,49,49,49,49,49,49,49,49,49,49
49,49,49,49,49,49,49,49,49,49,49,49,49,49,49,49,49,49,49,49,49,49
49,49,49,49,49,49,49,49,49,49,49,49,49,49,49,49,49,49,49,49,49,49
49,49,49,49,49,49,49,49,49,49,49,49,49,49,49,49,49,49,49,49,49,49
49,49,49,49,49,49,49,49,49,49,49,49,49,49,49,49,49,49,49,49,49,49
endlayer

layer
49,49,49,49,49,49,49,49,49,49,49,49,49,49,49,49,49,49,49,49,49,49
49,49,49,49,49,49,49,49,49,49,49,49,49,49,49,49,49,49,49,49,49,49
49,49,49,49,49,49,49,49,49,49,49,49,49,49,49,49,49,49,49,49,49,49
49,49,49,49,49,49,49,49,49,49,49,49,49,49,49,49,49,49,49,49,49,49
49,49,49,49,49,49,49,49,49,49,49,49,49,49,49,49,49,49,49,49,49,49
49,49,49,49,49,49,49,49,49,49,49,49,49,49,49,49,49,49,49,49,49,49
49,49,49,49,49,49,49,49,49,49,49,49,49,49,49,49,49,49,49,49,49,49
49,49,49,49,49,49,49,49,49,26,37,37,26,49,49,49,49,49,49,49,49,49
49,49,49,49,49,49,49,49,1,1,1,1,1,1,49,49,49,49,49,49,49,49
49,49,49,49,49,49,49,26,1,1,1,1,1,1,26,49,49,49,49,49,49,49
49,49,49,49,49,49,49,40,1,1,41,41,1,1,39,49,49,49,49,49,49,49
49,49,49,49,49,49,49,40,1,1,41,41,1,1,39,49,49,49,49,49,49,49
49,49,49,49,49,49,49,26,1,1,1,1,1,1,26,49,49,49,49,49,49,49
49,49,49,49,49,49,49,49,1,1,1,1,1,1,49,49,49,49,49,49,49,49
49,49,49,49,49,49,49,49,49,26,38,38,26,49,49,49,49,49,49,49,49,49
49,49,49,49,49,49,49,49,49,49,49,49,49,49,49,49,49,49,49,49,49,49
49,49,49,49,49,49,49,49,49,49,49,49,49,49,49,49,49,49,49,49,49,49
49,49,49,49,49,49,49,49,49,49,49,49,49,49,49,49,49,49,49,49,49,49
49,49,49,49,49,49,49,49,49,49,49,49,49,49,49,49,49,49,49,49,49,49
49,49,49,49,49,49,49,49,49,49,49,49,49,49,49,49,49,49,49,49,49,49
49,49,49,49,49,49,49,49,49,49,49,49,49,49,49,49,49,49,49,49,49,49
49,49,49,49,49,49,49,49,49,49,49,49,49,49,49,49,49,49,49,49,49,49
endlayer

layer
49,49,49,49,49,49,49,49,49,49,49,49,49,49,49,49,49,49,49,49,49,49
49,49,49,49,49,49,49,49,49,49,49,49,49,49,49,49,49,49,49,49,49,49
49,49,49,49,49,49,49,49,49,49,49,49,49,49,49,49,49,49,49,49,49,49
49,49,49,49,49,49,49,49,49,49,49,49,49,49,49,49,49,49,49,49,49,49
49,49,49,49,49,49,49,49,49,49,49,49,49,49,49,49,49,49,49,49,49,49
49,49,49,49,49,49,49,49,49,49,49,49,49,49,49,49,49,49,49,49,49,49
49,49,49,49,49,49,49,49,49,49,49,49,49,49,49,49,49,49,49,49,49,49
49,49,49,49,49,49,49,49,49,49,49,49,49,49,49,49,49,49,49,49,49,49
49,49,49,49,49,49,49,49,49,49,49,49,49,49,49,49,49,49,49,49,49,49
49,49,49,49,49,49,49,49,49,1,0,0,1,49,49,49,49,49,49,49,49,49
49,49,49,49,49,49,49,49,49,0,0,0,0,49,49,49,49,49,49,49,49,49
49,49,49,49,49,49,49,49,49,0,0,0,0,49,49,49,49,49,49,49,49,49
49,49,49,49,49,49,49,49,49,1,0,0,1,49,49,49,49,49,49,49,49,49
49,49,49,49,49,49,49,49,49,49,49,49,49,49,49,49,49,49,49,49,49,49
49,49,49,49,49,49,49,49,49,49,49,49,49,49,49,49,49,49,49,49,49,49
49,49,49,49,49,49,49,49,49,49,49,49,49,49,49,49,49,49,49,49,49,49
49,49,49,49,49,49,49,49,49,49,49,49,49,49,49,49,49,49,49,49,49,49
49,49,49,49,49,49,49,49,49,49,49,49,49,49,49,49,49,49,49,49,49,49
49,49,49,49,49,49,49,49,49,49,49,49,49,49,49,49,49,49,49,49,49,49
49,49,49,49,49,49,49,49,49,49,49,49,49,49,49,49,49,49,49,49,49,49
49,49,49,49,49,49,49,49,49,49,49,49,49,49,49,49,49,49,49,49,49,49
49,49,49,49,49,49,49,49,49,49,49,49,49,49,49,49,49,49,49,49,49,49
endlayer

layer
49,49,49,49,49,49,49,49,49,49,49,49,49,49,49,49,49,49,49,49,49,49
49,49,49,49,49,49,49,49,49,49,49,49,49,49,49,49,49,49,49,49,49,49
49,49,49,49,49,49,49,49,49,49,49,49,49,49,49,49,49,49,49,49,49,49
49,49,49,49,49,49,49,49,49,49,49,49,49,49,49,49,49,49,49,49,49,49
49,49,49,49,49,49,49,49,49,49,49,49,49,49,49,49,49,49,49,49,49,49
49,49,49,49,49,49,49,49,49,49,49,49,49,49,49,49,49,49,49,49,49,49
49,49,49,49,49,49,49,49,49,49,49,49,49,49,49,49,49,49,49,49,49,49
49,49,49,49,49,49,49,49,49,49,49,49,49,49,49,49,49,49,49,49,49,49
49,49,49,49,49,49,49,49,49,49,49,49,49,49,49,49,49,49,49,49,49,49
49,49,49,49,49,49,49,49,49,26,0,0,26,49,49,49,49,49,49,49,49,49
49,49,49,49,49,49,49,49,49,0,0,0,0,49,49,49,49,49,49,49,49,49
49,49,49,49,49,49,49,49,49,0,0,0,0,49,49,49,49,49,49,49,49,49
49,49,49,49,49,49,49,49,49,26,0,0,26,49,49,49,49,49,49,49,49,49
49,49,49,49,49,49,49,49,49,49,49,49,49,49,49,49,49,49,49,49,49,49
49,49,49,49,49,49,49,49,49,49,49,49,49,49,49,49,49,49,49,49,49,49
49,49,49,49,49,49,49,49,49,49,49,49,49,49,49,49,49,49,49,49,49,49
49,49,49,49,49,49,49,49,49,49,49,49,49,49,49,49,49,49,49,49,49,49
49,49,49,49,49,49,49,49,49,49,49,49,49,49,49,49,49,49,49,49,49,49
49,49,49,49,49,49,49,49,49,49,49,49,49,49,49,49,49,49,49,49,49,49
49,49,49,49,49,49,49,49,49,49,49,49,49,49,49,49,49,49,49,49,49,49
49,49,49,49,49,49,49,49,49,49,49,49,49,49,49,49,49,49,49,49,49,49
49,49,49,49,49,49,49,49,49,49,49,49,49,49,49,49,49,49,49,49,49,49
endlayer

layer
49,49,49,49,49,49,49,49,49,49,49,49,49,49,49,49,49,49,49,49,49,49
49,49,49,49,49,49,49,49,49,49,49,49,49,49,49,49,49,49,49,49,49,49
49,49,49,49,49,49,49,49,49,49,49,49,49,49,49,49,49,49,49,49,49,49
49,49,49,49,49,49,49,49,49,49,49,49,49,49,49,49,49,49,49,49,49,49
49,49,49,49,49,49,49,49,49,49,49,49,49,49,49,49,49,49,49,49,49,49
49,49,49,49,49,49,49,49,49,49,49,49,49,49,49,49,49,49,49,49,49,49
49,49,49,49,49,49,49,49,49,49,49,49,49,49,49,49,49,49,49,49,49,49
49,49,49,49,49,49,49,49,49,49,49,49,49,49,49,49,49,49,49,49,49,49
49,49,49,49,49,49,49,49,49,49,49,49,49,49,49,49,49,49,49,49,49,49
49,49,49,49,49,49,49,49,49,37,37,37,39,49,49,49,49,49,49,49,49,49
49,49,49,49,49,49,49,49,49,40,48,48,39,49,49,49,49,49,49,49,49,49
49,49,49,49,49,49,49,49,49,40,48,48,39,49,49,49,49,49,49,49,49,49
49,49,49,49,49,49,49,49,49,40,38,38,38,49,49,49,49,49,49,49,49,49
49,49,49,49,49,49,49,49,49,49,49,49,49,49,49,49,49,49,49,49,49,49
49,49,49,49,49,49,49,49,49,49,49,49,49,49,49,49,49,49,49,49,49,49
49,49,49,49,49,49,49,49,49,49,49,49,49,49,49,49,49,49,49,49,49,49
49,49,49,49,49,49,49,49,49,49,49,49,49,49,49,49,49,49,49,49,49,49
49,49,49,49,49,49,49,49,49,49,49,49,49,49,49,49,49,49,49,49,49,49
49,49,49,49,49,49,49,49,49,49,49,49,49,49,49,49,49,49,49,49,49,49
49,49,49,49,49,49,49,49,49,49,49,49,49,49,49,49,49,49,49,49,49,49
49,49,49,49,49,49,49,49,49,49,49,49,49,49,49,49,49,49,49,49,49,49
49,49,49,49,49,49,49,49,49,49,49,49,49,49,49,49,49,49,49,49,49,49
endlayer

layer
49,49,49,49,49,49,49,49,49,49,49,49,49,49,49,49,49,49,49,49,49,49
49,49,49,49,49,49,49,49,49,49,49,49,49,49,49,49,49,49,49,49,49,49
49,49,49,49,49,49,49,49,49,49,49,49,49,49,49,49,49,49,49,49,49,49
49,49,49,49,49,49,49,49,49,49,49,49,49,49,49,49,49,49,49,49,49,49
49,49,49,49,49,49,49,49,49,49,49,49,49,49,49,49,49,49,49,49,49,49
49,49,49,49,49,49,49,49,49,49,49,49,49,49,49,49,49,49,49,49,49,49
49,49,49,49,49,49,49,49,49,49,49,49,49,49,49,49,49,49,49,49,49,49
49,49,49,49,49,49,49,49,49,49,49,49,49,49,49,49,49,49,49,49,49,49
49,49,49,49,49,49,49,49,49,49,49,49,49,49,49,49,49,49,49,49,49,49
49,49,49,49,49,49,49,49,49,30,28,28,28,49,49,49,49,49,49,49,49,49
49,49,49,49,49,49,49,49,49,30,26,26,29,49,49,49,49,49,49,49,49,49
49,49,49,49,49,49,49,49,49,30,26,26,29,49,49,49,49,49,49,49,49,49
49,49,49,49,49,49,49,49,49,31,31,31,31,49,49,49,49,49,49,49,49,49
49,49,49,49,49,49,49,49,49,49,49,49,49,49,49,49,49,49,49,49,49,49
49,49,49,49,49,49,49,49,49,49,49,49,49,49,49,49,49,49,49,49,49,49
49,49,49,49,49,49,49,49,49,49,49,49,49,49,49,49,49,49,49,49,49,49
49,49,49,49,49,49,49,49,49,49,49,49,49,49,49,49,49,49,49,49,49,49
49,49,49,49,49,49,49,49,49,49,49,49,49,49,49,49,49,49,49,49,49,49
49,49,49,49,49,49,49,49,49,49,49,49,49,49,49,49,49,49,49,49,49,49
49,49,49,49,49,49,49,49,49,49,49,49,49,49,49,49,49,49,49,49,49,49
49,49,49,49,49,49,49,49,49,49,49,49,49,49,49,49,49,49,49,49,49,49
49,49,49,49,49,49,49,49,49,49,49,49,49,49,49,49,49,49,49,49,49,49
endlayer


