# Aurora Column
# Created by Ruins mod version 17.1 Ingame Parser
# authoring Player: Jordan_Greywolf
# Created for MC 1.12 with Twilight Forest Mod: 3 Jul 2018

biomesToSpawnIn=snowy_forest,twilight_glacier

weight=1
embed_into_distance=4
acceptable_target_blocks=

unacceptable_target_blocks=flowing_water,water,flowing_lava,lava,cloud,slime_congealed,slime_dirt,slime_grass

dimensions=28,4,4
allowable_overhang=0
max_leveling=4
leveling_buffer=-1
preserve_water=0
preserve_lava=0

rule1=0,100,twilightforest:aurora_block-0

layer
1,1,1,1
1,1,1,1
1,1,1,1
1,1,1,1
endlayer

layer
1,1,1,1
1,1,1,1
1,1,1,1
1,1,1,1
endlayer

layer
1,1,1,1
1,1,1,1
1,1,1,1
1,1,1,1
endlayer

layer
1,1,1,1
1,1,1,1
1,1,1,1
1,1,1,1
endlayer

layer
1,1,1,1
1,1,1,1
1,1,1,1
1,1,1,1
endlayer


layer
1,1,1,1
1,1,1,1
1,1,1,1
1,1,1,1
endlayer

layer
1,1,1,1
1,1,1,1
1,1,1,1
1,1,1,1
endlayer

layer
1,1,1,1
1,1,1,1
1,1,1,1
1,1,1,1
endlayer

layer
1,1,1,1
1,1,1,1
1,1,1,1
1,1,1,1
endlayer

layer
1,1,1,1
1,1,1,1
1,1,1,1
1,1,1,1
endlayer

layer
1,1,1,1
1,1,1,1
1,1,1,1
1,1,1,1
endlayer

layer
1,1,1,1
1,1,1,1
1,1,1,1
1,1,1,1
endlayer

layer
1,1,1,1
1,1,1,1
1,1,1,1
1,1,1,1
endlayer

layer
1,1,1,1
1,1,1,1
1,1,1,1
1,1,1,1
endlayer

layer
1,1,1,1
1,1,1,1
1,1,1,1
1,1,1,1
endlayer

layer
1,1,1,1
1,1,1,1
1,1,1,1
1,1,1,1
endlayer

layer
1,1,1,1
1,1,1,1
1,1,1,1
1,1,1,1
endlayer

layer
1,1,1,1
1,1,1,1
1,1,1,1
1,1,1,1
endlayer

layer
1,1,1,1
1,1,1,1
1,1,1,1
1,1,1,1
endlayer

layer
1,1,1,1
1,1,1,1
1,1,1,1
1,1,1,1
endlayer

layer
1,1,1,1
1,1,1,1
1,1,1,1
1,1,1,1
endlayer


layer
1,1,1,1
1,1,1,1
1,1,1,1
1,1,1,1
endlayer

layer
1,1,1,1
1,1,1,1
1,1,1,1
1,1,1,0
endlayer

layer
1,1,1,1
1,1,1,1
1,1,1,0
1,1,0,0
endlayer

layer
1,1,1,1
1,1,1,0
1,1,0,0
1,0,0,0
endlayer

layer
1,1,1,0
1,1,0,0
1,0,0,0
0,0,0,0
endlayer

layer
1,1,0,0
1,0,0,0
0,0,0,0
0,0,0,0
endlayer

layer
1,0,0,0
0,0,0,0
0,0,0,0
0,0,0,0
endlayer

