# Mushroom Tower -- 6 Apr 2016 -- MC 1.8
# Created by Ruins mod version 15.5 Ingame Parser
# authoring Player: Jordan_Greywolf

# Last Updated 7 Apr 2016
# Updated to MC 1.12: 23 Jun 2017
# Updated to MC 1.12.1: 10 Sep 2017

biomesToSpawnIn=deep mushroom forest,dense twilight forest,enchanted forest,highlands,lighted forest,mushroom forest,mushroomisland,mushroomislandshore,roofed forest,roofed forest m,twilight clearing,mushrooms,lots of mushrooms,mushroom_island,mushroom_island_shore,roofed_forest,mutated_roofed_forest

preventRotation=1

uniqueMinDistance=1000

weight=1
embed_into_distance=16
acceptable_target_blocks=

unacceptable_target_blocks=cloud,Natura:Cloud,slime_congealed,slime_dirt,slime_grass,command_block

dimensions=96,21,21
allowable_overhang=999
max_leveling=16
leveling_buffer=-1
preserve_water=0
preserve_lava=0

rule1=0,100,CommandBlock:RUINSTRIGGER /testruin TP_MT_Roof ~0 ~1 ~0:@

rule2=0,100,preserveBlock
rule3=0,100,minecraft:red_mushroom_block-15
rule4=0,100,minecraft:brown_mushroom_block-14
rule5=0,100,minecraft:jungle_stairs-0

rule6=0,100,CommandBlock:RUINSTRIGGER /testruin TP_MT_Tower1 ~-5 ~-1 ~0:@,CommandBlock:RUINSTRIGGER /testruin TP_MT_Tower2 ~-7 ~-1 ~0:@,CommandBlock:RUINSTRIGGER /testruin TP_MT_Window1 ~-2 ~-1 ~0:@,CommandBlock:RUINSTRIGGER /testruin TP_MT_Window2 ~-1 ~-1 ~0:@

rule7=0,100,minecraft:red_mushroom,minecraft:brown_mushroom
rule8=0,100,minecraft:jungle_fence-0

rule9=0,100,CommandBlock:RUINSTRIGGER /testruin TP_MT_Decor_Chests ~0 ~-1 ~0:@,CommandBlock:RUINSTRIGGER /testruin TP_MT_Decor_Fountain ~0 ~-1 ~0:@,CommandBlock:RUINSTRIGGER /testruin TP_MT_Decor_RedCap ~0 ~-1 ~0:@

rule10=0,100,CommandBlock:RUINSTRIGGER /testruin TP_MT_Tower1 ~0 ~-1 ~5 3:@,CommandBlock:RUINSTRIGGER /testruin TP_MT_Tower2 ~0 ~-1 ~7 3:@,CommandBlock:RUINSTRIGGER /testruin TP_MT_Window1 ~0 ~-1 ~2 3:@,CommandBlock:RUINSTRIGGER /testruin TP_MT_Window2 ~0 ~-1 ~1 3:@

rule11=0,100,minecraft:planks-3
rule12=0,100,minecraft:jungle_stairs-1

rule13=0,100,CommandBlock:RUINSTRIGGER /testruin TP_MT_Tower1 ~5 ~-1 ~0 2:@,CommandBlock:RUINSTRIGGER /testruin TP_MT_Tower2 ~7 ~-1 ~0 2:@,CommandBlock:RUINSTRIGGER /testruin TP_MT_Window1 ~2 ~-1 ~0 2:@,CommandBlock:RUINSTRIGGER /testruin TP_MT_Window2 ~1 ~-1 ~0 2:@

rule14=0,100,CommandBlock:RUINSTRIGGER /setblock ~0 ~-1 ~0 mob_spawner 0 replace {SpawnData:{HandItems:[{Count:1,id:red_mushroom,tag:{ench:[{id:16,lvl:3}]}},{Count:1,id:brown_mushroom,tag:{ench:[{id:16,lvl:3}]}}],ArmorItems:[{Count:1,id:leather_boots,tag:{display:{color:16768967,Name:"Shroom Boots"}}},{Count:1,id:leather_leggings,tag:{display:{color:16771522,Name:"Shroom Leggings"}}},{Count:1,id:leather_chestplate,tag:{display:{color:16728642,Name:"Shroom Chest"}}},{Count:1,id:red_mushroom_block}],CustomName:"Shroom Zombie",HandDropChances:[0.5F,0.5F],ArmorDropChances:[0.2F,0.2F,0.2F,0.5F],Silent:1,id:zombie}}:@

rule15=0,100,CommandBlock:RUINSTRIGGER /testruin TP_MT_Tower1 ~0 ~-1 ~-5 1:@,CommandBlock:RUINSTRIGGER /testruin TP_MT_Tower2 ~0 ~-1 ~-7 1:@,CommandBlock:RUINSTRIGGER /testruin TP_MT_Window1 ~0 ~-1 ~-2 1:@,CommandBlock:RUINSTRIGGER /testruin TP_MT_Window2 ~0 ~-1 ~-1 1:@

rule16=0,100,CommandBlock:RUINSTRIGGER /testruin TP_MT_Decor_Chests ~0 ~-1 ~0:@,CommandBlock:RUINSTRIGGER /testruin TP_MT_Decor_Fountain ~0 ~-1 ~0:@,CommandBlock:RUINSTRIGGER /testruin TP_MT_Decor_RedCap ~0 ~-1 ~0:@

# Segment A - Underground
layer
2,2,2,2,2,2,2,2,3,3,3,3,3,2,2,2,2,2,2,2,2
2,2,2,2,2,3,3,3,4,4,4,4,4,3,3,3,2,2,2,2,2
2,2,2,3,3,4,4,4,4,4,4,4,4,4,4,4,3,3,2,2,2
2,2,3,4,4,4,4,4,4,4,4,4,4,4,4,4,4,4,3,2,2
2,2,3,4,4,4,4,4,4,4,4,4,4,4,4,4,4,4,3,2,2
2,3,4,4,4,4,4,4,4,4,4,4,4,4,4,4,4,4,4,3,2
2,3,4,4,4,4,4,4,4,4,4,4,4,4,4,4,4,4,4,3,2
2,3,4,4,4,4,4,4,4,4,4,4,4,4,4,4,4,4,4,3,2
3,4,4,4,4,4,4,4,4,4,4,4,4,4,4,4,4,4,4,4,3
3,4,4,4,4,4,4,4,4,4,4,4,4,4,4,4,4,4,4,4,3
3,4,4,4,4,4,4,4,4,4,4,4,4,4,4,4,4,4,0,4,3
3,4,4,4,4,4,4,4,4,4,4,4,4,4,4,4,4,4,0,4,3
3,4,4,4,4,4,4,4,4,4,4,4,4,4,4,4,4,4,0,4,3
2,3,4,4,4,4,4,4,4,4,4,4,4,4,4,4,4,4,5,3,2
2,3,4,4,4,4,4,4,4,4,4,4,4,4,4,4,4,4,4,3,2
2,3,4,4,4,4,4,4,4,4,4,4,4,4,4,4,4,4,4,3,2
2,2,3,4,4,4,4,4,4,4,4,4,4,4,4,4,4,4,3,2,2
2,2,3,4,4,4,4,4,4,4,4,4,4,4,4,4,4,4,3,2,2
2,2,2,3,3,4,4,4,4,4,4,4,4,4,4,4,3,3,2,2,2
2,2,2,2,2,3,3,3,4,4,4,4,4,3,3,3,2,2,2,2,2
2,2,2,2,2,2,2,2,3,3,3,3,3,2,2,2,2,2,2,2,2
endlayer

layer
2,2,2,2,2,2,2,2,3,3,3,3,3,2,2,2,2,2,2,2,2
2,2,2,2,2,3,3,3,0,0,0,0,0,3,3,3,2,2,2,2,2
2,2,2,3,3,0,0,0,0,7,0,0,7,0,0,0,3,3,2,2,2
2,2,3,0,0,0,0,0,0,0,7,0,0,7,0,0,0,0,3,2,2
2,2,3,0,0,0,7,0,0,0,0,7,0,0,0,0,0,7,3,2,2
2,3,0,0,0,0,0,0,0,0,0,0,0,0,0,7,0,0,0,3,2
2,3,0,0,0,0,0,0,7,0,0,0,0,0,0,0,0,0,0,3,2
2,3,0,0,7,0,0,0,0,0,0,0,7,0,0,0,0,7,0,3,2
3,7,0,0,0,0,0,0,0,0,4,0,0,0,0,7,0,0,0,0,3
3,0,0,7,0,0,7,0,0,4,4,4,0,0,0,0,0,8,8,8,3
3,0,0,0,0,0,0,0,4,4,9,4,4,0,7,0,0,8,0,0,3
3,0,0,0,0,0,0,0,0,4,4,4,0,0,0,0,0,8,0,0,3
3,0,0,7,0,0,0,0,0,0,4,0,0,0,0,0,0,8,0,0,3
2,3,11,11,0,0,0,0,0,7,0,0,0,0,0,0,7,0,0,3,2
2,3,12,11,0,0,7,0,0,0,0,0,0,7,0,0,0,0,0,3,2
2,3,0,0,0,0,0,0,0,0,7,0,0,0,0,0,0,0,0,3,2
2,2,3,0,0,0,7,0,0,7,0,0,0,0,0,7,0,0,3,2,2
2,2,3,0,0,0,0,0,0,0,0,0,0,0,0,0,0,0,3,2,2
2,2,2,3,3,0,0,0,0,0,0,0,0,0,0,0,3,3,2,2,2
2,2,2,2,2,3,3,3,0,0,0,0,0,3,3,3,2,2,2,2,2
2,2,2,2,2,2,2,2,3,3,3,3,3,2,2,2,2,2,2,2,2
endlayer

layer
2,2,2,2,2,2,2,2,3,3,3,3,3,2,2,2,2,2,2,2,2
2,2,2,2,2,3,3,3,0,0,0,0,0,3,3,3,2,2,2,2,2
2,2,2,3,3,0,0,0,0,0,0,0,0,0,0,0,3,3,2,2,2
2,2,3,0,0,0,0,0,0,0,0,0,0,0,0,0,0,0,3,2,2
2,2,3,0,0,0,0,0,0,0,0,0,0,0,0,0,0,0,3,2,2
2,3,0,0,0,0,0,0,0,0,0,0,0,0,0,0,0,0,0,3,2
2,3,0,0,0,0,0,0,0,0,0,0,0,0,0,0,0,0,0,3,2
2,3,0,0,0,0,0,0,0,0,0,0,0,0,0,0,0,0,0,3,2
3,0,0,0,0,0,0,0,0,0,0,0,0,0,0,0,0,0,0,0,3
3,0,0,0,0,0,0,0,0,0,4,7,0,0,0,0,0,0,0,0,3
3,0,0,0,0,0,0,0,0,4,4,4,0,0,0,0,0,0,0,0,3
3,0,0,0,0,0,0,0,0,0,4,0,0,0,0,0,0,0,0,0,3
3,11,11,11,0,0,0,0,0,0,7,0,0,0,0,0,0,0,0,0,3
2,3,12,11,0,0,0,0,0,0,0,0,0,0,0,0,0,0,0,3,2
2,3,0,8,0,0,0,0,0,0,0,0,0,0,0,0,0,0,0,3,2
2,3,0,0,0,0,0,0,0,0,0,0,0,0,0,0,0,0,0,3,2
2,2,3,0,0,0,0,0,0,0,0,0,0,0,0,0,0,0,3,2,2
2,2,3,0,0,0,0,0,0,0,0,0,0,0,0,0,0,0,3,2,2
2,2,2,3,3,0,0,0,0,0,0,0,0,0,0,0,3,3,2,2,2
2,2,2,2,2,3,3,3,0,0,0,0,0,3,3,3,2,2,2,2,2
2,2,2,2,2,2,2,2,3,3,3,3,3,2,2,2,2,2,2,2,2
endlayer

layer
2,2,2,2,2,2,2,2,3,3,3,3,3,2,2,2,2,2,2,2,2
2,2,2,2,2,3,3,3,0,0,0,0,0,3,3,3,2,2,2,2,2
2,2,2,3,3,0,0,0,0,0,0,0,0,0,0,0,3,3,2,2,2
2,2,3,0,0,0,0,0,0,0,0,0,0,0,0,0,0,0,3,2,2
2,2,3,0,0,0,0,0,0,0,0,0,0,0,0,0,0,0,3,2,2
2,3,0,0,0,0,0,0,0,0,0,0,0,0,0,0,0,0,0,3,2
2,3,0,0,0,0,0,0,0,0,0,0,0,0,0,0,0,0,0,3,2
2,3,0,0,0,0,0,0,0,0,0,0,0,0,0,0,0,0,0,3,2
3,0,0,0,0,0,0,0,0,0,0,0,0,0,0,0,0,0,0,0,3
3,0,0,0,0,0,0,0,0,0,0,0,0,0,0,0,0,0,0,0,3
3,0,0,0,0,0,0,0,0,0,4,7,0,0,0,0,0,0,0,0,3
3,11,11,11,0,0,0,0,0,0,0,0,0,0,0,0,0,0,0,0,3
3,11,12,11,0,0,0,0,0,0,0,0,0,0,0,0,0,0,0,0,3
2,3,0,8,0,0,0,0,0,0,0,0,0,0,0,0,0,0,0,3,2
2,3,0,8,0,0,0,0,0,0,0,0,0,0,0,0,0,0,0,3,2
2,3,0,0,0,0,0,0,0,0,0,0,0,0,0,0,0,0,0,3,2
2,2,3,0,0,0,0,0,0,0,0,0,0,0,0,0,0,0,3,2,2
2,2,3,0,0,0,0,0,0,0,0,0,0,0,0,0,0,0,3,2,2
2,2,2,3,3,0,0,0,0,0,0,0,0,0,0,0,3,3,2,2,2
2,2,2,2,2,3,3,3,0,0,0,0,0,3,3,3,2,2,2,2,2
2,2,2,2,2,2,2,2,3,3,3,3,3,2,2,2,2,2,2,2,2
endlayer

layer
2,2,2,2,2,2,2,2,3,3,3,3,3,2,2,2,2,2,2,2,2
2,2,2,2,2,3,3,3,0,0,0,0,0,3,3,3,2,2,2,2,2
2,2,2,3,3,0,0,0,0,0,0,0,0,0,0,0,3,3,2,2,2
2,2,3,0,0,0,0,0,0,0,0,0,0,0,0,0,0,0,3,2,2
2,2,3,0,0,0,0,0,0,0,0,0,0,0,0,0,0,0,3,2,2
2,3,0,0,0,0,0,0,0,0,0,0,0,0,0,0,0,0,0,3,2
2,3,0,0,0,0,0,0,0,0,0,0,0,0,0,0,0,0,0,3,2
2,3,0,0,0,0,0,0,0,0,0,0,0,0,0,0,0,0,0,3,2
3,0,0,0,0,0,0,0,0,0,0,0,0,0,0,0,0,0,0,0,3
3,0,0,0,0,0,0,0,0,0,0,0,0,0,0,0,0,0,0,0,3
3,11,11,11,0,0,0,0,0,0,14,0,0,0,0,0,0,0,0,0,3
3,11,12,11,0,0,0,0,0,0,0,0,0,0,0,0,0,0,0,0,3
3,8,0,8,0,0,0,0,0,0,0,0,0,0,0,0,0,0,0,0,3
2,3,0,8,0,0,0,0,0,0,0,0,0,0,0,0,0,0,0,3,2
2,3,0,0,0,0,0,0,0,0,0,0,0,0,0,0,0,0,0,3,2
2,3,0,0,0,0,0,0,0,0,0,0,0,0,0,0,0,0,0,3,2
2,2,3,0,0,0,0,0,0,0,0,0,0,0,0,0,0,0,3,2,2
2,2,3,0,0,0,0,0,0,0,0,0,0,0,0,0,0,0,3,2,2
2,2,2,3,3,0,0,0,0,0,0,0,0,0,0,0,3,3,2,2,2
2,2,2,2,2,3,3,3,0,0,0,0,0,3,3,3,2,2,2,2,2
2,2,2,2,2,2,2,2,3,3,3,3,3,2,2,2,2,2,2,2,2
endlayer

layer
2,2,2,2,2,2,2,2,3,3,3,3,3,2,2,2,2,2,2,2,2
2,2,2,2,2,3,3,3,0,0,0,0,0,3,3,3,2,2,2,2,2
2,2,2,3,3,0,0,0,0,0,0,0,0,0,0,0,3,3,2,2,2
2,2,3,0,0,0,0,0,0,0,0,0,0,0,0,0,0,0,3,2,2
2,2,3,0,0,0,0,0,0,0,0,0,0,0,0,0,0,0,3,2,2
2,3,0,0,0,0,0,0,0,0,0,0,0,0,0,0,0,0,0,3,2
2,3,0,0,0,0,0,0,0,0,0,0,0,0,0,0,0,0,0,3,2
2,3,0,0,0,0,0,0,0,0,0,0,0,0,0,0,0,0,0,3,2
3,0,0,0,0,0,0,0,0,0,0,0,0,0,0,0,0,0,0,0,3
3,11,11,11,0,0,0,0,0,0,4,0,0,0,0,0,0,0,0,0,3
3,11,12,11,0,0,0,0,0,4,4,4,0,0,0,0,0,0,0,0,3
3,8,0,8,0,0,0,0,0,0,4,0,0,0,0,0,0,0,0,0,3
3,8,0,8,0,0,0,0,0,0,0,0,0,0,0,0,0,0,0,0,3
2,3,0,0,0,0,0,0,0,0,0,0,0,0,0,0,0,0,0,3,2
2,3,0,0,0,0,0,0,0,0,0,0,0,0,0,0,0,0,0,3,2
2,3,0,0,0,0,0,0,0,0,0,0,0,0,0,0,0,0,0,3,2
2,2,3,0,0,0,0,0,0,0,0,0,0,0,0,0,0,0,3,2,2
2,2,3,0,0,0,0,0,0,0,0,0,0,0,0,0,0,0,3,2,2
2,2,2,3,3,0,0,0,0,0,0,0,0,0,0,0,3,3,2,2,2
2,2,2,2,2,3,3,3,0,0,0,0,0,3,3,3,2,2,2,2,2
2,2,2,2,2,2,2,2,3,3,3,3,3,2,2,2,2,2,2,2,2
endlayer

layer
2,2,2,2,2,2,2,2,3,3,3,3,3,2,2,2,2,2,2,2,2
2,2,2,2,2,3,3,3,0,0,0,0,0,3,3,3,2,2,2,2,2
2,2,2,3,3,0,0,0,0,0,0,0,0,0,0,0,3,3,2,2,2
2,2,3,0,0,0,0,0,0,0,0,0,0,0,0,0,0,0,3,2,2
2,2,3,0,0,0,0,0,0,0,0,0,0,0,0,0,0,0,3,2,2
2,3,0,0,0,0,0,0,0,0,0,0,0,0,0,0,0,0,0,3,2
2,3,0,0,0,0,0,0,0,0,0,0,0,0,0,0,0,0,0,3,2
2,3,0,0,0,0,0,0,0,0,0,0,0,0,0,0,0,0,0,3,2
3,11,11,11,0,0,0,0,0,0,0,0,0,0,0,0,0,0,0,0,3
3,11,12,11,0,0,0,0,0,4,4,4,0,0,0,0,0,0,0,0,3
3,8,0,8,0,0,0,0,0,4,4,4,0,0,0,0,0,0,0,0,3
3,8,0,8,0,0,0,0,0,4,4,4,0,0,0,0,0,0,0,0,3
3,0,0,0,0,0,0,0,0,0,0,0,0,0,0,0,0,0,0,0,3
2,3,0,0,0,0,0,0,0,0,0,0,0,0,0,0,0,0,0,3,2
2,3,0,0,0,0,0,0,0,0,0,0,0,0,0,0,0,0,0,3,2
2,3,0,0,0,0,0,0,0,0,0,0,0,0,0,0,0,0,0,3,2
2,2,3,0,0,0,0,0,0,0,0,0,0,0,0,0,0,0,3,2,2
2,2,3,0,0,0,0,0,0,0,0,0,0,0,0,0,0,0,3,2,2
2,2,2,3,3,0,0,0,0,0,0,0,0,0,0,0,3,3,2,2,2
2,2,2,2,2,3,3,3,0,0,0,0,0,3,3,3,2,2,2,2,2
2,2,2,2,2,2,2,2,3,3,3,3,3,2,2,2,2,2,2,2,2
endlayer

layer
2,2,2,2,2,2,2,2,3,3,3,3,3,2,2,2,2,2,2,2,2
2,2,2,2,2,3,3,3,0,0,0,0,0,3,3,3,2,2,2,2,2
2,2,2,3,3,0,0,0,0,0,0,0,0,0,0,0,3,3,2,2,2
2,2,3,0,0,0,0,0,0,0,0,0,0,0,0,0,0,0,3,2,2
2,2,3,0,0,0,0,0,0,0,0,0,0,0,0,0,0,0,3,2,2
2,3,0,0,0,0,0,0,0,0,0,0,0,0,0,0,0,0,0,3,2
2,3,0,0,0,0,0,0,0,0,0,0,0,0,0,0,0,0,0,3,2
2,3,11,11,0,0,0,0,0,0,0,0,0,0,0,0,0,0,0,3,2
3,11,12,11,0,0,0,0,0,4,4,4,0,0,0,0,0,0,0,0,3
3,8,0,8,0,0,0,0,4,4,4,4,4,0,0,0,0,0,0,0,3
3,8,0,8,0,0,0,0,4,4,4,4,4,0,0,0,0,0,0,0,3
3,0,0,0,0,0,0,0,4,4,4,4,4,0,0,0,0,0,0,0,3
3,0,0,0,0,0,0,0,0,4,4,4,0,0,0,0,0,0,0,0,3
2,3,0,0,0,0,0,0,0,0,0,0,0,0,0,0,0,0,0,3,2
2,3,0,0,0,0,0,0,0,0,0,0,0,0,0,0,0,0,0,3,2
2,3,0,0,0,0,0,0,0,0,0,0,0,0,0,0,0,0,0,3,2
2,2,3,0,0,0,0,0,0,0,0,0,0,0,0,0,0,0,3,2,2
2,2,3,0,0,0,0,0,0,0,0,0,0,0,0,0,0,0,3,2,2
2,2,2,3,3,0,0,0,0,0,0,0,0,0,0,0,3,3,2,2,2
2,2,2,2,2,3,3,3,0,0,0,0,0,3,3,3,2,2,2,2,2
2,2,2,2,2,2,2,2,3,3,3,3,3,2,2,2,2,2,2,2,2
endlayer

# Segment B - Underground
layer
2,2,2,2,2,2,2,2,3,3,3,3,3,2,2,2,2,2,2,2,2
2,2,2,2,2,3,3,3,4,4,4,4,4,3,3,3,2,2,2,2,2
2,2,2,3,3,4,4,4,4,4,4,4,4,4,4,4,3,3,2,2,2
2,2,3,4,4,4,4,4,4,4,4,4,4,4,4,4,4,4,3,2,2
2,2,3,4,4,4,4,4,4,4,4,4,4,4,4,4,4,4,3,2,2
2,3,4,4,4,4,4,4,4,4,4,4,4,4,4,4,4,4,4,3,2
2,3,4,4,4,4,4,4,4,4,4,4,4,4,4,4,4,4,4,3,2
2,3,12,4,4,4,4,4,4,4,4,4,4,4,4,4,4,4,4,3,2
3,4,0,4,4,4,4,4,4,4,4,4,4,4,4,4,4,4,4,4,3
3,4,0,4,4,4,4,4,4,4,4,4,4,4,4,4,4,4,4,4,3
3,4,0,4,4,4,4,4,4,4,4,4,4,4,4,4,4,4,4,4,3
3,4,4,4,4,4,4,4,4,4,4,4,4,4,4,4,4,4,4,4,3
3,4,4,4,4,4,4,4,4,4,4,4,4,4,4,4,4,4,4,4,3
2,3,4,4,4,4,4,4,4,4,4,4,4,4,4,4,4,4,4,3,2
2,3,4,4,4,4,4,4,4,4,4,4,4,4,4,4,4,4,4,3,2
2,3,4,4,4,4,4,4,4,4,4,4,4,4,4,4,4,4,4,3,2
2,2,3,4,4,4,4,4,4,4,4,4,4,4,4,4,4,4,3,2,2
2,2,3,4,4,4,4,4,4,4,4,4,4,4,4,4,4,4,3,2,2
2,2,2,3,3,4,4,4,4,4,4,4,4,4,4,4,3,3,2,2,2
2,2,2,2,2,3,3,3,4,4,4,4,4,3,3,3,2,2,2,2,2
2,2,2,2,2,2,2,2,3,3,3,3,3,2,2,2,2,2,2,2,2
endlayer

layer
2,2,2,2,2,2,2,2,3,3,3,3,3,2,2,2,2,2,2,2,2
2,2,2,2,2,3,3,3,0,0,0,0,0,3,3,3,2,2,2,2,2
2,2,2,3,3,0,0,0,7,0,0,0,0,7,0,0,3,3,2,2,2
2,2,3,0,0,0,0,0,0,0,0,7,0,0,0,0,0,0,3,2,2
2,2,3,0,0,0,0,0,0,0,0,0,0,0,7,0,7,0,3,2,2
2,3,0,0,7,0,0,0,0,0,7,0,0,0,0,0,0,0,0,3,2
2,3,0,0,0,0,0,0,0,0,0,0,0,7,0,0,0,11,5,3,2
2,3,0,8,0,0,0,7,0,0,0,0,0,0,0,0,0,11,11,3,2
3,0,0,8,0,7,0,0,0,0,4,0,0,0,0,0,7,0,0,0,3
3,0,0,8,0,0,0,0,0,4,4,4,0,0,0,0,0,7,0,7,3
3,0,0,8,7,0,7,0,4,4,16,4,4,0,7,0,0,0,0,0,3
3,8,8,8,0,0,0,0,0,4,4,4,0,0,0,7,0,0,7,0,3
3,0,0,0,0,0,0,0,0,0,4,0,0,0,0,0,0,0,0,0,3
2,3,0,0,0,0,0,0,0,0,0,0,0,0,0,0,0,7,0,3,2
2,3,7,0,0,7,0,0,0,0,0,7,0,0,0,0,0,0,0,3,2
2,3,0,7,0,0,0,0,0,7,0,0,0,0,0,7,0,0,0,3,2
2,2,3,7,0,0,0,0,7,0,0,0,0,0,0,0,0,0,3,2,2
2,2,3,0,7,0,7,0,0,0,0,0,0,0,0,0,0,0,3,2,2
2,2,2,3,3,0,0,0,0,0,0,0,7,0,0,0,3,3,2,2,2
2,2,2,2,2,3,3,3,0,7,0,0,0,3,3,3,2,2,2,2,2
2,2,2,2,2,2,2,2,3,3,3,3,3,2,2,2,2,2,2,2,2
endlayer

layer
2,2,2,2,2,2,2,2,3,3,3,3,3,2,2,2,2,2,2,2,2
2,2,2,2,2,3,3,3,0,0,0,0,0,3,3,3,2,2,2,2,2
2,2,2,3,3,0,0,0,0,0,0,0,0,0,0,0,3,3,2,2,2
2,2,3,0,0,0,0,0,0,0,0,0,0,0,0,0,0,0,3,2,2
2,2,3,0,0,0,0,0,0,0,0,0,0,0,0,0,0,0,3,2,2
2,3,0,0,0,0,0,0,0,0,0,0,0,0,0,0,0,0,0,3,2
2,3,0,0,0,0,0,0,0,0,0,0,0,0,0,0,0,8,0,3,2
2,3,0,0,0,0,0,0,0,0,0,0,0,0,0,0,0,11,5,3,2
3,0,0,0,0,0,0,0,0,0,0,0,0,0,0,0,0,11,11,11,3
3,0,0,0,0,0,0,0,0,0,4,7,0,0,0,0,0,0,0,0,3
3,0,0,0,0,0,0,0,7,4,4,4,0,0,0,0,0,0,0,0,3
3,0,0,0,0,0,0,0,0,0,4,0,0,0,0,0,0,0,0,0,3
3,0,0,0,0,0,0,0,0,0,0,0,0,0,0,0,0,0,0,0,3
2,3,0,0,0,0,0,0,0,0,0,0,0,0,0,0,0,0,0,3,2
2,3,0,0,0,0,0,0,0,0,0,0,0,0,0,0,0,0,0,3,2
2,3,0,0,0,0,0,0,0,0,0,0,0,0,0,0,0,0,0,3,2
2,2,3,0,0,0,0,0,0,0,0,0,0,0,0,0,0,0,3,2,2
2,2,3,0,0,0,0,0,0,0,0,0,0,0,0,0,0,0,3,2,2
2,2,2,3,3,0,0,0,0,0,0,0,0,0,0,0,3,3,2,2,2
2,2,2,2,2,3,3,3,0,0,0,0,0,3,3,3,2,2,2,2,2
2,2,2,2,2,2,2,2,3,3,3,3,3,2,2,2,2,2,2,2,2
endlayer

layer
2,2,2,2,2,2,2,2,3,3,3,3,3,2,2,2,2,2,2,2,2
2,2,2,2,2,3,3,3,0,0,0,0,0,3,3,3,2,2,2,2,2
2,2,2,3,3,0,0,0,0,0,0,0,0,0,0,0,3,3,2,2,2
2,2,3,0,0,0,0,0,0,0,0,0,0,0,0,0,0,0,3,2,2
2,2,3,0,0,0,0,0,0,0,0,0,0,0,0,0,0,0,3,2,2
2,3,0,0,0,0,0,0,0,0,0,0,0,0,0,0,0,0,0,3,2
2,3,0,0,0,0,0,0,0,0,0,0,0,0,0,0,0,8,0,3,2
2,3,0,0,0,0,0,0,0,0,0,0,0,0,0,0,0,8,0,3,2
3,0,0,0,0,0,0,0,0,0,0,0,0,0,0,0,0,11,5,11,3
3,0,0,0,0,0,0,0,0,0,0,0,0,0,0,0,0,11,11,11,3
3,0,0,0,0,0,0,0,0,0,4,0,0,0,0,0,0,0,0,0,3
3,0,0,0,0,0,0,0,0,0,7,0,0,0,0,0,0,0,0,0,3
3,0,0,0,0,0,0,0,0,0,0,0,0,0,0,0,0,0,0,0,3
2,3,0,0,0,0,0,0,0,0,0,0,0,0,0,0,0,0,0,3,2
2,3,0,0,0,0,0,0,0,0,0,0,0,0,0,0,0,0,0,3,2
2,3,0,0,0,0,0,0,0,0,0,0,0,0,0,0,0,0,0,3,2
2,2,3,0,0,0,0,0,0,0,0,0,0,0,0,0,0,0,3,2,2
2,2,3,0,0,0,0,0,0,0,0,0,0,0,0,0,0,0,3,2,2
2,2,2,3,3,0,0,0,0,0,0,0,0,0,0,0,3,3,2,2,2
2,2,2,2,2,3,3,3,0,0,0,0,0,3,3,3,2,2,2,2,2
2,2,2,2,2,2,2,2,3,3,3,3,3,2,2,2,2,2,2,2,2
endlayer

layer
2,2,2,2,2,2,2,2,3,3,3,3,3,2,2,2,2,2,2,2,2
2,2,2,2,2,3,3,3,0,0,0,0,0,3,3,3,2,2,2,2,2
2,2,2,3,3,0,0,0,0,0,0,0,0,0,0,0,3,3,2,2,2
2,2,3,0,0,0,0,0,0,0,0,0,0,0,0,0,0,0,3,2,2
2,2,3,0,0,0,0,0,0,0,0,0,0,0,0,0,0,0,3,2,2
2,3,0,0,0,0,0,0,0,0,0,0,0,0,0,0,0,0,0,3,2
2,3,0,0,0,0,0,0,0,0,0,0,0,0,0,0,0,0,0,3,2
2,3,0,0,0,0,0,0,0,0,0,0,0,0,0,0,0,8,0,3,2
3,0,0,0,0,0,0,0,0,0,0,0,0,0,0,0,0,8,0,8,3
3,0,0,0,0,0,0,0,0,0,0,0,0,0,0,0,0,11,5,11,3
3,0,0,0,0,0,0,0,0,0,14,0,0,0,0,0,0,11,11,11,3
3,0,0,0,0,0,0,0,0,0,0,0,0,0,0,0,0,0,0,0,3
3,0,0,0,0,0,0,0,0,0,0,0,0,0,0,0,0,0,0,0,3
2,3,0,0,0,0,0,0,0,0,0,0,0,0,0,0,0,0,0,3,2
2,3,0,0,0,0,0,0,0,0,0,0,0,0,0,0,0,0,0,3,2
2,3,0,0,0,0,0,0,0,0,0,0,0,0,0,0,0,0,0,3,2
2,2,3,0,0,0,0,0,0,0,0,0,0,0,0,0,0,0,3,2,2
2,2,3,0,0,0,0,0,0,0,0,0,0,0,0,0,0,0,3,2,2
2,2,2,3,3,0,0,0,0,0,0,0,0,0,0,0,3,3,2,2,2
2,2,2,2,2,3,3,3,0,0,0,0,0,3,3,3,2,2,2,2,2
2,2,2,2,2,2,2,2,3,3,3,3,3,2,2,2,2,2,2,2,2
endlayer

layer
2,2,2,2,2,2,2,2,3,3,3,3,3,2,2,2,2,2,2,2,2
2,2,2,2,2,3,3,3,0,0,0,0,0,3,3,3,2,2,2,2,2
2,2,2,3,3,0,0,0,0,0,0,0,0,0,0,0,3,3,2,2,2
2,2,3,0,0,0,0,0,0,0,0,0,0,0,0,0,0,0,3,2,2
2,2,3,0,0,0,0,0,0,0,0,0,0,0,0,0,0,0,3,2,2
2,3,0,0,0,0,0,0,0,0,0,0,0,0,0,0,0,0,0,3,2
2,3,0,0,0,0,0,0,0,0,0,0,0,0,0,0,0,0,0,3,2
2,3,0,0,0,0,0,0,0,0,0,0,0,0,0,0,0,0,0,3,2
3,0,0,0,0,0,0,0,0,0,0,0,0,0,0,0,0,8,0,8,3
3,0,0,0,0,0,0,0,0,0,4,0,0,0,0,0,0,8,0,8,3
3,0,0,0,0,0,0,0,0,4,4,4,0,0,0,0,0,11,5,11,3
3,0,0,0,0,0,0,0,0,0,4,0,0,0,0,0,0,11,11,11,3
3,0,0,0,0,0,0,0,0,0,0,0,0,0,0,0,0,0,0,0,3
2,3,0,0,0,0,0,0,0,0,0,0,0,0,0,0,0,0,0,3,2
2,3,0,0,0,0,0,0,0,0,0,0,0,0,0,0,0,0,0,3,2
2,3,0,0,0,0,0,0,0,0,0,0,0,0,0,0,0,0,0,3,2
2,2,3,0,0,0,0,0,0,0,0,0,0,0,0,0,0,0,3,2,2
2,2,3,0,0,0,0,0,0,0,0,0,0,0,0,0,0,0,3,2,2
2,2,2,3,3,0,0,0,0,0,0,0,0,0,0,0,3,3,2,2,2
2,2,2,2,2,3,3,3,0,0,0,0,0,3,3,3,2,2,2,2,2
2,2,2,2,2,2,2,2,3,3,3,3,3,2,2,2,2,2,2,2,2
endlayer

layer
2,2,2,2,2,2,2,2,3,3,3,3,3,2,2,2,2,2,2,2,2
2,2,2,2,2,3,3,3,0,0,0,0,0,3,3,3,2,2,2,2,2
2,2,2,3,3,0,0,0,0,0,0,0,0,0,0,0,3,3,2,2,2
2,2,3,0,0,0,0,0,0,0,0,0,0,0,0,0,0,0,3,2,2
2,2,3,0,0,0,0,0,0,0,0,0,0,0,0,0,0,0,3,2,2
2,3,0,0,0,0,0,0,0,0,0,0,0,0,0,0,0,0,0,3,2
2,3,0,0,0,0,0,0,0,0,0,0,0,0,0,0,0,0,0,3,2
2,3,0,0,0,0,0,0,0,0,0,0,0,0,0,0,0,0,0,3,2
3,0,0,0,0,0,0,0,0,0,0,0,0,0,0,0,0,0,0,0,3
3,0,0,0,0,0,0,0,0,4,4,4,0,0,0,0,0,8,0,8,3
3,0,0,0,0,0,0,0,0,4,4,4,0,0,0,0,0,8,0,8,3
3,0,0,0,0,0,0,0,0,4,4,4,0,0,0,0,0,11,5,11,3
3,0,0,0,0,0,0,0,0,0,0,0,0,0,0,0,0,11,11,11,3
2,3,0,0,0,0,0,0,0,0,0,0,0,0,0,0,0,0,0,3,2
2,3,0,0,0,0,0,0,0,0,0,0,0,0,0,0,0,0,0,3,2
2,3,0,0,0,0,0,0,0,0,0,0,0,0,0,0,0,0,0,3,2
2,2,3,0,0,0,0,0,0,0,0,0,0,0,0,0,0,0,3,2,2
2,2,3,0,0,0,0,0,0,0,0,0,0,0,0,0,0,0,3,2,2
2,2,2,3,3,0,0,0,0,0,0,0,0,0,0,0,3,3,2,2,2
2,2,2,2,2,3,3,3,0,0,0,0,0,3,3,3,2,2,2,2,2
2,2,2,2,2,2,2,2,3,3,3,3,3,2,2,2,2,2,2,2,2
endlayer

layer
2,2,2,2,2,2,2,2,3,3,3,3,3,2,2,2,2,2,2,2,2
2,2,2,2,2,3,3,3,0,0,0,0,0,3,3,3,2,2,2,2,2
2,2,2,3,3,0,0,0,0,0,0,0,0,0,0,0,3,3,2,2,2
2,2,3,0,0,0,0,0,0,0,0,0,0,0,0,0,0,0,3,2,2
2,2,3,0,0,0,0,0,0,0,0,0,0,0,0,0,0,0,3,2,2
2,3,0,0,0,0,0,0,0,0,0,0,0,0,0,0,0,0,0,3,2
2,3,0,0,0,0,0,0,0,0,0,0,0,0,0,0,0,0,0,3,2
2,3,0,0,0,0,0,0,0,0,0,0,0,0,0,0,0,0,0,3,2
3,0,0,0,0,0,0,0,0,4,4,4,0,0,0,0,0,0,0,0,3
3,0,0,0,0,0,0,0,4,4,4,4,4,0,0,0,0,0,0,0,3
3,0,0,0,0,0,0,0,4,4,4,4,4,0,0,0,0,8,0,8,3
3,0,0,0,0,0,0,0,4,4,4,4,4,0,0,0,0,8,0,8,3
3,0,0,0,0,0,0,0,0,4,4,4,0,0,0,0,0,11,5,11,3
2,3,0,0,0,0,0,0,0,0,0,0,0,0,0,0,0,11,11,3,2
2,3,0,0,0,0,0,0,0,0,0,0,0,0,0,0,0,0,0,3,2
2,3,0,0,0,0,0,0,0,0,0,0,0,0,0,0,0,0,0,3,2
2,2,3,0,0,0,0,0,0,0,0,0,0,0,0,0,0,0,3,2,2
2,2,3,0,0,0,0,0,0,0,0,0,0,0,0,0,0,0,3,2,2
2,2,2,3,3,0,0,0,0,0,0,0,0,0,0,0,3,3,2,2,2
2,2,2,2,2,3,3,3,0,0,0,0,0,3,3,3,2,2,2,2,2
2,2,2,2,2,2,2,2,3,3,3,3,3,2,2,2,2,2,2,2,2
endlayer

# Segment A - Ground Level
layer
2,2,2,2,2,2,2,2,3,3,3,3,3,2,2,2,2,2,2,2,2
2,2,2,2,2,3,3,3,4,4,4,4,4,3,3,3,2,2,2,2,2
2,2,2,3,3,4,4,4,4,4,4,4,4,4,4,4,3,3,2,2,2
2,2,3,4,4,4,4,4,4,4,4,4,4,4,4,4,4,4,3,2,2
2,2,3,4,4,4,4,4,4,4,4,4,4,4,4,4,4,4,3,2,2
2,3,4,4,4,4,4,4,4,4,4,4,4,4,4,4,4,4,4,3,2
2,3,4,4,4,4,4,4,4,4,4,4,4,4,4,4,4,4,4,3,2
2,3,4,4,4,4,4,4,4,4,4,4,4,4,4,4,4,4,4,3,2
3,4,4,4,4,4,4,4,4,4,4,4,4,4,4,4,4,4,4,4,3
3,4,4,4,4,4,4,4,4,4,4,4,4,4,4,4,4,4,4,4,3
3,4,4,4,4,4,4,4,4,4,4,4,4,4,4,4,4,4,0,4,3
3,4,4,4,4,4,4,4,4,4,4,4,4,4,4,4,4,4,0,4,3
3,4,4,4,4,4,4,4,4,4,4,4,4,4,4,4,4,4,0,4,3
2,3,4,4,4,4,4,4,4,4,4,4,4,4,4,4,4,4,5,3,2
2,3,4,4,4,4,4,4,4,4,4,4,4,4,4,4,4,4,4,3,2
2,3,4,4,4,4,4,4,4,4,4,4,4,4,4,4,4,4,4,3,2
2,2,3,4,4,4,4,4,4,4,4,4,4,4,4,4,4,4,3,2,2
2,2,3,4,4,4,4,4,4,4,4,4,4,4,4,4,4,4,3,2,2
2,2,2,3,3,4,4,4,4,4,4,4,4,4,4,4,3,3,2,2,2
2,2,2,2,2,3,3,3,4,4,4,4,4,3,3,3,2,2,2,2,2
2,2,2,2,2,2,2,2,3,3,3,3,3,2,2,2,2,2,2,2,2
endlayer

layer
2,2,2,2,2,2,2,2,3,3,3,3,3,2,2,2,2,2,2,2,2
2,2,2,2,2,3,3,3,0,0,6,0,0,3,3,3,2,2,2,2,2
2,2,2,3,3,0,0,0,0,7,0,0,7,0,0,0,3,3,2,2,2
2,2,3,0,0,0,0,0,0,0,7,0,0,7,0,0,0,0,3,2,2
2,2,3,0,0,0,7,0,0,0,0,7,0,0,0,0,0,7,3,2,2
2,3,0,0,0,0,0,0,0,0,0,0,0,0,0,7,0,0,0,3,2
2,3,0,0,0,0,0,0,7,0,0,0,0,0,0,0,0,0,0,3,2
2,3,0,0,7,0,0,0,0,0,0,0,7,0,0,0,0,7,0,3,2
3,7,0,0,0,0,0,0,0,0,4,0,0,0,0,7,0,0,0,0,3
3,0,0,7,0,0,7,0,0,4,4,4,0,0,0,0,0,8,8,8,3
3,10,0,0,0,0,0,0,4,4,9,4,4,0,7,0,0,8,0,0,3
3,0,0,0,0,0,0,0,0,4,4,4,0,0,0,0,0,8,0,0,3
3,0,0,7,0,0,0,0,0,0,4,0,0,0,0,0,0,8,0,0,3
2,3,11,11,0,0,0,0,0,7,0,0,0,0,0,0,7,0,0,3,2
2,3,12,11,0,0,7,0,0,0,0,0,0,7,0,0,0,0,0,3,2
2,3,0,0,0,0,0,0,0,0,7,0,0,0,0,0,0,0,0,3,2
2,2,3,0,0,0,7,0,0,7,0,0,0,0,0,7,0,0,3,2,2
2,2,3,0,0,0,0,0,0,0,0,0,0,0,0,0,0,0,3,2,2
2,2,2,3,3,0,0,0,0,0,0,0,0,0,0,0,3,3,2,2,2
2,2,2,2,2,3,3,3,0,0,13,0,0,3,3,3,2,2,2,2,2
2,2,2,2,2,2,2,2,3,3,3,3,3,2,2,2,2,2,2,2,2
endlayer

layer
2,2,2,2,2,2,2,2,3,3,3,3,3,2,2,2,2,2,2,2,2
2,2,2,2,2,3,3,3,0,0,0,0,0,3,3,3,2,2,2,2,2
2,2,2,3,3,0,0,0,0,0,0,0,0,0,0,0,3,3,2,2,2
2,2,3,0,0,0,0,0,0,0,0,0,0,0,0,0,0,0,3,2,2
2,2,3,0,0,0,0,0,0,0,0,0,0,0,0,0,0,0,3,2,2
2,3,0,0,0,0,0,0,0,0,0,0,0,0,0,0,0,0,0,3,2
2,3,0,0,0,0,0,0,0,0,0,0,0,0,0,0,0,0,0,3,2
2,3,0,0,0,0,0,0,0,0,0,0,0,0,0,0,0,0,0,3,2
3,0,0,0,0,0,0,0,0,0,0,0,0,0,0,0,0,0,0,0,3
3,0,0,0,0,0,0,0,0,0,4,7,0,0,0,0,0,0,0,0,3
3,0,0,0,0,0,0,0,0,4,4,4,0,0,0,0,0,0,0,0,3
3,0,0,0,0,0,0,0,0,0,4,0,0,0,0,0,0,0,0,0,3
3,11,11,11,0,0,0,0,0,0,7,0,0,0,0,0,0,0,0,0,3
2,3,12,11,0,0,0,0,0,0,0,0,0,0,0,0,0,0,0,3,2
2,3,0,8,0,0,0,0,0,0,0,0,0,0,0,0,0,0,0,3,2
2,3,0,0,0,0,0,0,0,0,0,0,0,0,0,0,0,0,0,3,2
2,2,3,0,0,0,0,0,0,0,0,0,0,0,0,0,0,0,3,2,2
2,2,3,0,0,0,0,0,0,0,0,0,0,0,0,0,0,0,3,2,2
2,2,2,3,3,0,0,0,0,0,0,0,0,0,0,0,3,3,2,2,2
2,2,2,2,2,3,3,3,0,0,0,0,0,3,3,3,2,2,2,2,2
2,2,2,2,2,2,2,2,3,3,3,3,3,2,2,2,2,2,2,2,2
endlayer

layer
2,2,2,2,2,2,2,2,3,3,3,3,3,2,2,2,2,2,2,2,2
2,2,2,2,2,3,3,3,0,0,0,0,0,3,3,3,2,2,2,2,2
2,2,2,3,3,0,0,0,0,0,0,0,0,0,0,0,3,3,2,2,2
2,2,3,0,0,0,0,0,0,0,0,0,0,0,0,0,0,0,3,2,2
2,2,3,0,0,0,0,0,0,0,0,0,0,0,0,0,0,0,3,2,2
2,3,0,0,0,0,0,0,0,0,0,0,0,0,0,0,0,0,0,3,2
2,3,0,0,0,0,0,0,0,0,0,0,0,0,0,0,0,0,0,3,2
2,3,0,0,0,0,0,0,0,0,0,0,0,0,0,0,0,0,0,3,2
3,0,0,0,0,0,0,0,0,0,0,0,0,0,0,0,0,0,0,0,3
3,0,0,0,0,0,0,0,0,0,0,0,0,0,0,0,0,0,0,0,3
3,0,0,0,0,0,0,0,0,0,4,7,0,0,0,0,0,0,0,0,3
3,11,11,11,0,0,0,0,0,0,0,0,0,0,0,0,0,0,0,0,3
3,11,12,11,0,0,0,0,0,0,0,0,0,0,0,0,0,0,0,0,3
2,3,0,8,0,0,0,0,0,0,0,0,0,0,0,0,0,0,0,3,2
2,3,0,8,0,0,0,0,0,0,0,0,0,0,0,0,0,0,0,3,2
2,3,0,0,0,0,0,0,0,0,0,0,0,0,0,0,0,0,0,3,2
2,2,3,0,0,0,0,0,0,0,0,0,0,0,0,0,0,0,3,2,2
2,2,3,0,0,0,0,0,0,0,0,0,0,0,0,0,0,0,3,2,2
2,2,2,3,3,0,0,0,0,0,0,0,0,0,0,0,3,3,2,2,2
2,2,2,2,2,3,3,3,0,0,0,0,0,3,3,3,2,2,2,2,2
2,2,2,2,2,2,2,2,3,3,3,3,3,2,2,2,2,2,2,2,2
endlayer

layer
2,2,2,2,2,2,2,2,3,3,3,3,3,2,2,2,2,2,2,2,2
2,2,2,2,2,3,3,3,0,0,0,0,0,3,3,3,2,2,2,2,2
2,2,2,3,3,0,0,0,0,0,0,0,0,0,0,0,3,3,2,2,2
2,2,3,0,0,0,0,0,0,0,0,0,0,0,0,0,0,0,3,2,2
2,2,3,0,0,0,0,0,0,0,0,0,0,0,0,0,0,0,3,2,2
2,3,0,0,0,0,0,0,0,0,0,0,0,0,0,0,0,0,0,3,2
2,3,0,0,0,0,0,0,0,0,0,0,0,0,0,0,0,0,0,3,2
2,3,0,0,0,0,0,0,0,0,0,0,0,0,0,0,0,0,0,3,2
3,0,0,0,0,0,0,0,0,0,0,0,0,0,0,0,0,0,0,0,3
3,0,0,0,0,0,0,0,0,0,0,0,0,0,0,0,0,0,0,0,3
3,11,11,11,0,0,0,0,0,0,14,0,0,0,0,0,0,0,0,0,3
3,11,12,11,0,0,0,0,0,0,0,0,0,0,0,0,0,0,0,0,3
3,8,0,8,0,0,0,0,0,0,0,0,0,0,0,0,0,0,0,0,3
2,3,0,8,0,0,0,0,0,0,0,0,0,0,0,0,0,0,0,3,2
2,3,0,0,0,0,0,0,0,0,0,0,0,0,0,0,0,0,0,3,2
2,3,0,0,0,0,0,0,0,0,0,0,0,0,0,0,0,0,0,3,2
2,2,3,0,0,0,0,0,0,0,0,0,0,0,0,0,0,0,3,2,2
2,2,3,0,0,0,0,0,0,0,0,0,0,0,0,0,0,0,3,2,2
2,2,2,3,3,0,0,0,0,0,0,0,0,0,0,0,3,3,2,2,2
2,2,2,2,2,3,3,3,0,0,0,0,0,3,3,3,2,2,2,2,2
2,2,2,2,2,2,2,2,3,3,3,3,3,2,2,2,2,2,2,2,2
endlayer

layer
2,2,2,2,2,2,2,2,3,3,3,3,3,2,2,2,2,2,2,2,2
2,2,2,2,2,3,3,3,0,0,0,0,0,3,3,3,2,2,2,2,2
2,2,2,3,3,0,0,0,0,0,0,0,0,0,0,0,3,3,2,2,2
2,2,3,0,0,0,0,0,0,0,0,0,0,0,0,0,0,0,3,2,2
2,2,3,0,0,0,0,0,0,0,0,0,0,0,0,0,0,0,3,2,2
2,3,0,0,0,0,0,0,0,0,0,0,0,0,0,0,0,0,0,3,2
2,3,0,0,0,0,0,0,0,0,0,0,0,0,0,0,0,0,0,3,2
2,3,0,0,0,0,0,0,0,0,0,0,0,0,0,0,0,0,0,3,2
3,0,0,0,0,0,0,0,0,0,0,0,0,0,0,0,0,0,0,0,3
3,11,11,11,0,0,0,0,0,0,4,0,0,0,0,0,0,0,0,0,3
3,11,12,11,0,0,0,0,0,4,4,4,0,0,0,0,0,0,0,0,3
3,8,0,8,0,0,0,0,0,0,4,0,0,0,0,0,0,0,0,0,3
3,8,0,8,0,0,0,0,0,0,0,0,0,0,0,0,0,0,0,0,3
2,3,0,0,0,0,0,0,0,0,0,0,0,0,0,0,0,0,0,3,2
2,3,0,0,0,0,0,0,0,0,0,0,0,0,0,0,0,0,0,3,2
2,3,0,0,0,0,0,0,0,0,0,0,0,0,0,0,0,0,0,3,2
2,2,3,0,0,0,0,0,0,0,0,0,0,0,0,0,0,0,3,2,2
2,2,3,0,0,0,0,0,0,0,0,0,0,0,0,0,0,0,3,2,2
2,2,2,3,3,0,0,0,0,0,0,0,0,0,0,0,3,3,2,2,2
2,2,2,2,2,3,3,3,0,0,0,0,0,3,3,3,2,2,2,2,2
2,2,2,2,2,2,2,2,3,3,3,3,3,2,2,2,2,2,2,2,2
endlayer

layer
2,2,2,2,2,2,2,2,3,3,3,3,3,2,2,2,2,2,2,2,2
2,2,2,2,2,3,3,3,0,0,0,0,0,3,3,3,2,2,2,2,2
2,2,2,3,3,0,0,0,0,0,0,0,0,0,0,0,3,3,2,2,2
2,2,3,0,0,0,0,0,0,0,0,0,0,0,0,0,0,0,3,2,2
2,2,3,0,0,0,0,0,0,0,0,0,0,0,0,0,0,0,3,2,2
2,3,0,0,0,0,0,0,0,0,0,0,0,0,0,0,0,0,0,3,2
2,3,0,0,0,0,0,0,0,0,0,0,0,0,0,0,0,0,0,3,2
2,3,0,0,0,0,0,0,0,0,0,0,0,0,0,0,0,0,0,3,2
3,11,11,11,0,0,0,0,0,0,0,0,0,0,0,0,0,0,0,0,3
3,11,12,11,0,0,0,0,0,4,4,4,0,0,0,0,0,0,0,0,3
3,8,0,8,0,0,0,0,0,4,4,4,0,0,0,0,0,0,0,0,3
3,8,0,8,0,0,0,0,0,4,4,4,0,0,0,0,0,0,0,0,3
3,0,0,0,0,0,0,0,0,0,0,0,0,0,0,0,0,0,0,0,3
2,3,0,0,0,0,0,0,0,0,0,0,0,0,0,0,0,0,0,3,2
2,3,0,0,0,0,0,0,0,0,0,0,0,0,0,0,0,0,0,3,2
2,3,0,0,0,0,0,0,0,0,0,0,0,0,0,0,0,0,0,3,2
2,2,3,0,0,0,0,0,0,0,0,0,0,0,0,0,0,0,3,2,2
2,2,3,0,0,0,0,0,0,0,0,0,0,0,0,0,0,0,3,2,2
2,2,2,3,3,0,0,0,0,0,0,0,0,0,0,0,3,3,2,2,2
2,2,2,2,2,3,3,3,0,0,0,0,0,3,3,3,2,2,2,2,2
2,2,2,2,2,2,2,2,3,3,3,3,3,2,2,2,2,2,2,2,2
endlayer

layer
2,2,2,2,2,2,2,2,3,3,3,3,3,2,2,2,2,2,2,2,2
2,2,2,2,2,3,3,3,0,0,0,0,0,3,3,3,2,2,2,2,2
2,2,2,3,3,0,0,0,0,0,0,0,0,0,0,0,3,3,2,2,2
2,2,3,0,0,0,0,0,0,0,0,0,0,0,0,0,0,0,3,2,2
2,2,3,0,0,0,0,0,0,0,0,0,0,0,0,0,0,0,3,2,2
2,3,0,0,0,0,0,0,0,0,0,0,0,0,0,0,0,0,0,3,2
2,3,0,0,0,0,0,0,0,0,0,0,0,0,0,0,0,0,0,3,2
2,3,11,11,0,0,0,0,0,0,0,0,0,0,0,0,0,0,0,3,2
3,11,12,11,0,0,0,0,0,4,4,4,0,0,0,0,0,0,0,0,3
3,8,0,8,0,0,0,0,4,4,4,4,4,0,0,0,0,0,0,0,3
3,8,0,8,0,0,0,0,4,4,4,4,4,0,0,0,0,0,0,0,3
3,0,0,0,0,0,0,0,4,4,4,4,4,0,0,0,0,0,0,0,3
3,0,0,0,0,0,0,0,0,4,4,4,0,0,0,0,0,0,0,0,3
2,3,0,0,0,0,0,0,0,0,0,0,0,0,0,0,0,0,0,3,2
2,3,0,0,0,0,0,0,0,0,0,0,0,0,0,0,0,0,0,3,2
2,3,0,0,0,0,0,0,0,0,0,0,0,0,0,0,0,0,0,3,2
2,2,3,0,0,0,0,0,0,0,0,0,0,0,0,0,0,0,3,2,2
2,2,3,0,0,0,0,0,0,0,0,0,0,0,0,0,0,0,3,2,2
2,2,2,3,3,0,0,0,0,0,0,0,0,0,0,0,3,3,2,2,2
2,2,2,2,2,3,3,3,0,0,0,0,0,3,3,3,2,2,2,2,2
2,2,2,2,2,2,2,2,3,3,3,3,3,2,2,2,2,2,2,2,2
endlayer

# Segment B
layer
2,2,2,2,2,2,2,2,3,3,3,3,3,2,2,2,2,2,2,2,2
2,2,2,2,2,3,3,3,4,4,4,4,4,3,3,3,2,2,2,2,2
2,2,2,3,3,4,4,4,4,4,4,4,4,4,4,4,3,3,2,2,2
2,2,3,4,4,4,4,4,4,4,4,4,4,4,4,4,4,4,3,2,2
2,2,3,4,4,4,4,4,4,4,4,4,4,4,4,4,4,4,3,2,2
2,3,4,4,4,4,4,4,4,4,4,4,4,4,4,4,4,4,4,3,2
2,3,4,4,4,4,4,4,4,4,4,4,4,4,4,4,4,4,4,3,2
2,3,12,4,4,4,4,4,4,4,4,4,4,4,4,4,4,4,4,3,2
3,4,0,4,4,4,4,4,4,4,4,4,4,4,4,4,4,4,4,4,3
3,4,0,4,4,4,4,4,4,4,4,4,4,4,4,4,4,4,4,4,3
3,4,0,4,4,4,4,4,4,4,4,4,4,4,4,4,4,4,4,4,3
3,4,4,4,4,4,4,4,4,4,4,4,4,4,4,4,4,4,4,4,3
3,4,4,4,4,4,4,4,4,4,4,4,4,4,4,4,4,4,4,4,3
2,3,4,4,4,4,4,4,4,4,4,4,4,4,4,4,4,4,4,3,2
2,3,4,4,4,4,4,4,4,4,4,4,4,4,4,4,4,4,4,3,2
2,3,4,4,4,4,4,4,4,4,4,4,4,4,4,4,4,4,4,3,2
2,2,3,4,4,4,4,4,4,4,4,4,4,4,4,4,4,4,3,2,2
2,2,3,4,4,4,4,4,4,4,4,4,4,4,4,4,4,4,3,2,2
2,2,2,3,3,4,4,4,4,4,4,4,4,4,4,4,3,3,2,2,2
2,2,2,2,2,3,3,3,4,4,4,4,4,3,3,3,2,2,2,2,2
2,2,2,2,2,2,2,2,3,3,3,3,3,2,2,2,2,2,2,2,2
endlayer

layer
2,2,2,2,2,2,2,2,3,3,3,3,3,2,2,2,2,2,2,2,2
2,2,2,2,2,3,3,3,0,0,6,0,0,3,3,3,2,2,2,2,2
2,2,2,3,3,0,0,0,7,0,0,0,0,7,0,0,3,3,2,2,2
2,2,3,0,0,0,0,0,0,0,0,7,0,0,0,0,0,0,3,2,2
2,2,3,0,0,0,0,0,0,0,0,0,0,0,7,0,7,0,3,2,2
2,3,0,0,7,0,0,0,0,0,7,0,0,0,0,0,0,0,0,3,2
2,3,0,0,0,0,0,0,0,0,0,0,0,7,0,0,0,11,5,3,2
2,3,0,8,0,0,0,7,0,0,0,0,0,0,0,0,0,11,11,3,2
3,0,0,8,0,7,0,0,0,0,4,0,0,0,0,0,7,0,0,0,3
3,0,0,8,0,0,0,0,0,4,4,4,0,0,0,0,0,7,0,7,3
3,0,0,8,7,0,7,0,4,4,16,4,4,0,7,0,0,0,0,15,3
3,8,8,8,0,0,0,0,0,4,4,4,0,0,0,7,0,0,7,0,3
3,0,0,0,0,0,0,0,0,0,4,0,0,0,0,0,0,0,0,0,3
2,3,0,0,0,0,0,0,0,0,0,0,0,0,0,0,0,7,0,3,2
2,3,7,0,0,7,0,0,0,0,0,7,0,0,0,0,0,0,0,3,2
2,3,0,7,0,0,0,0,0,7,0,0,0,0,0,7,0,0,0,3,2
2,2,3,7,0,0,0,0,7,0,0,0,0,0,0,0,0,0,3,2,2
2,2,3,0,7,0,7,0,0,0,0,0,0,0,0,0,0,0,3,2,2
2,2,2,3,3,0,0,0,0,0,0,0,7,0,0,0,3,3,2,2,2
2,2,2,2,2,3,3,3,0,7,13,0,0,3,3,3,2,2,2,2,2
2,2,2,2,2,2,2,2,3,3,3,3,3,2,2,2,2,2,2,2,2
endlayer

layer
2,2,2,2,2,2,2,2,3,3,3,3,3,2,2,2,2,2,2,2,2
2,2,2,2,2,3,3,3,0,0,0,0,0,3,3,3,2,2,2,2,2
2,2,2,3,3,0,0,0,0,0,0,0,0,0,0,0,3,3,2,2,2
2,2,3,0,0,0,0,0,0,0,0,0,0,0,0,0,0,0,3,2,2
2,2,3,0,0,0,0,0,0,0,0,0,0,0,0,0,0,0,3,2,2
2,3,0,0,0,0,0,0,0,0,0,0,0,0,0,0,0,0,0,3,2
2,3,0,0,0,0,0,0,0,0,0,0,0,0,0,0,0,8,0,3,2
2,3,0,0,0,0,0,0,0,0,0,0,0,0,0,0,0,11,5,3,2
3,0,0,0,0,0,0,0,0,0,0,0,0,0,0,0,0,11,11,11,3
3,0,0,0,0,0,0,0,0,0,4,7,0,0,0,0,0,0,0,0,3
3,0,0,0,0,0,0,0,7,4,4,4,0,0,0,0,0,0,0,0,3
3,0,0,0,0,0,0,0,0,0,4,0,0,0,0,0,0,0,0,0,3
3,0,0,0,0,0,0,0,0,0,0,0,0,0,0,0,0,0,0,0,3
2,3,0,0,0,0,0,0,0,0,0,0,0,0,0,0,0,0,0,3,2
2,3,0,0,0,0,0,0,0,0,0,0,0,0,0,0,0,0,0,3,2
2,3,0,0,0,0,0,0,0,0,0,0,0,0,0,0,0,0,0,3,2
2,2,3,0,0,0,0,0,0,0,0,0,0,0,0,0,0,0,3,2,2
2,2,3,0,0,0,0,0,0,0,0,0,0,0,0,0,0,0,3,2,2
2,2,2,3,3,0,0,0,0,0,0,0,0,0,0,0,3,3,2,2,2
2,2,2,2,2,3,3,3,0,0,0,0,0,3,3,3,2,2,2,2,2
2,2,2,2,2,2,2,2,3,3,3,3,3,2,2,2,2,2,2,2,2
endlayer

layer
2,2,2,2,2,2,2,2,3,3,3,3,3,2,2,2,2,2,2,2,2
2,2,2,2,2,3,3,3,0,0,0,0,0,3,3,3,2,2,2,2,2
2,2,2,3,3,0,0,0,0,0,0,0,0,0,0,0,3,3,2,2,2
2,2,3,0,0,0,0,0,0,0,0,0,0,0,0,0,0,0,3,2,2
2,2,3,0,0,0,0,0,0,0,0,0,0,0,0,0,0,0,3,2,2
2,3,0,0,0,0,0,0,0,0,0,0,0,0,0,0,0,0,0,3,2
2,3,0,0,0,0,0,0,0,0,0,0,0,0,0,0,0,8,0,3,2
2,3,0,0,0,0,0,0,0,0,0,0,0,0,0,0,0,8,0,3,2
3,0,0,0,0,0,0,0,0,0,0,0,0,0,0,0,0,11,5,11,3
3,0,0,0,0,0,0,0,0,0,0,0,0,0,0,0,0,11,11,11,3
3,0,0,0,0,0,0,0,0,0,4,0,0,0,0,0,0,0,0,0,3
3,0,0,0,0,0,0,0,0,0,7,0,0,0,0,0,0,0,0,0,3
3,0,0,0,0,0,0,0,0,0,0,0,0,0,0,0,0,0,0,0,3
2,3,0,0,0,0,0,0,0,0,0,0,0,0,0,0,0,0,0,3,2
2,3,0,0,0,0,0,0,0,0,0,0,0,0,0,0,0,0,0,3,2
2,3,0,0,0,0,0,0,0,0,0,0,0,0,0,0,0,0,0,3,2
2,2,3,0,0,0,0,0,0,0,0,0,0,0,0,0,0,0,3,2,2
2,2,3,0,0,0,0,0,0,0,0,0,0,0,0,0,0,0,3,2,2
2,2,2,3,3,0,0,0,0,0,0,0,0,0,0,0,3,3,2,2,2
2,2,2,2,2,3,3,3,0,0,0,0,0,3,3,3,2,2,2,2,2
2,2,2,2,2,2,2,2,3,3,3,3,3,2,2,2,2,2,2,2,2
endlayer

layer
2,2,2,2,2,2,2,2,3,3,3,3,3,2,2,2,2,2,2,2,2
2,2,2,2,2,3,3,3,0,0,0,0,0,3,3,3,2,2,2,2,2
2,2,2,3,3,0,0,0,0,0,0,0,0,0,0,0,3,3,2,2,2
2,2,3,0,0,0,0,0,0,0,0,0,0,0,0,0,0,0,3,2,2
2,2,3,0,0,0,0,0,0,0,0,0,0,0,0,0,0,0,3,2,2
2,3,0,0,0,0,0,0,0,0,0,0,0,0,0,0,0,0,0,3,2
2,3,0,0,0,0,0,0,0,0,0,0,0,0,0,0,0,0,0,3,2
2,3,0,0,0,0,0,0,0,0,0,0,0,0,0,0,0,8,0,3,2
3,0,0,0,0,0,0,0,0,0,0,0,0,0,0,0,0,8,0,8,3
3,0,0,0,0,0,0,0,0,0,0,0,0,0,0,0,0,11,5,11,3
3,0,0,0,0,0,0,0,0,0,14,0,0,0,0,0,0,11,11,11,3
3,0,0,0,0,0,0,0,0,0,0,0,0,0,0,0,0,0,0,0,3
3,0,0,0,0,0,0,0,0,0,0,0,0,0,0,0,0,0,0,0,3
2,3,0,0,0,0,0,0,0,0,0,0,0,0,0,0,0,0,0,3,2
2,3,0,0,0,0,0,0,0,0,0,0,0,0,0,0,0,0,0,3,2
2,3,0,0,0,0,0,0,0,0,0,0,0,0,0,0,0,0,0,3,2
2,2,3,0,0,0,0,0,0,0,0,0,0,0,0,0,0,0,3,2,2
2,2,3,0,0,0,0,0,0,0,0,0,0,0,0,0,0,0,3,2,2
2,2,2,3,3,0,0,0,0,0,0,0,0,0,0,0,3,3,2,2,2
2,2,2,2,2,3,3,3,0,0,0,0,0,3,3,3,2,2,2,2,2
2,2,2,2,2,2,2,2,3,3,3,3,3,2,2,2,2,2,2,2,2
endlayer

layer
2,2,2,2,2,2,2,2,3,3,3,3,3,2,2,2,2,2,2,2,2
2,2,2,2,2,3,3,3,0,0,0,0,0,3,3,3,2,2,2,2,2
2,2,2,3,3,0,0,0,0,0,0,0,0,0,0,0,3,3,2,2,2
2,2,3,0,0,0,0,0,0,0,0,0,0,0,0,0,0,0,3,2,2
2,2,3,0,0,0,0,0,0,0,0,0,0,0,0,0,0,0,3,2,2
2,3,0,0,0,0,0,0,0,0,0,0,0,0,0,0,0,0,0,3,2
2,3,0,0,0,0,0,0,0,0,0,0,0,0,0,0,0,0,0,3,2
2,3,0,0,0,0,0,0,0,0,0,0,0,0,0,0,0,0,0,3,2
3,0,0,0,0,0,0,0,0,0,0,0,0,0,0,0,0,8,0,8,3
3,0,0,0,0,0,0,0,0,0,4,0,0,0,0,0,0,8,0,8,3
3,0,0,0,0,0,0,0,0,4,4,4,0,0,0,0,0,11,5,11,3
3,0,0,0,0,0,0,0,0,0,4,0,0,0,0,0,0,11,11,11,3
3,0,0,0,0,0,0,0,0,0,0,0,0,0,0,0,0,0,0,0,3
2,3,0,0,0,0,0,0,0,0,0,0,0,0,0,0,0,0,0,3,2
2,3,0,0,0,0,0,0,0,0,0,0,0,0,0,0,0,0,0,3,2
2,3,0,0,0,0,0,0,0,0,0,0,0,0,0,0,0,0,0,3,2
2,2,3,0,0,0,0,0,0,0,0,0,0,0,0,0,0,0,3,2,2
2,2,3,0,0,0,0,0,0,0,0,0,0,0,0,0,0,0,3,2,2
2,2,2,3,3,0,0,0,0,0,0,0,0,0,0,0,3,3,2,2,2
2,2,2,2,2,3,3,3,0,0,0,0,0,3,3,3,2,2,2,2,2
2,2,2,2,2,2,2,2,3,3,3,3,3,2,2,2,2,2,2,2,2
endlayer

layer
2,2,2,2,2,2,2,2,3,3,3,3,3,2,2,2,2,2,2,2,2
2,2,2,2,2,3,3,3,0,0,0,0,0,3,3,3,2,2,2,2,2
2,2,2,3,3,0,0,0,0,0,0,0,0,0,0,0,3,3,2,2,2
2,2,3,0,0,0,0,0,0,0,0,0,0,0,0,0,0,0,3,2,2
2,2,3,0,0,0,0,0,0,0,0,0,0,0,0,0,0,0,3,2,2
2,3,0,0,0,0,0,0,0,0,0,0,0,0,0,0,0,0,0,3,2
2,3,0,0,0,0,0,0,0,0,0,0,0,0,0,0,0,0,0,3,2
2,3,0,0,0,0,0,0,0,0,0,0,0,0,0,0,0,0,0,3,2
3,0,0,0,0,0,0,0,0,0,0,0,0,0,0,0,0,0,0,0,3
3,0,0,0,0,0,0,0,0,4,4,4,0,0,0,0,0,8,0,8,3
3,0,0,0,0,0,0,0,0,4,4,4,0,0,0,0,0,8,0,8,3
3,0,0,0,0,0,0,0,0,4,4,4,0,0,0,0,0,11,5,11,3
3,0,0,0,0,0,0,0,0,0,0,0,0,0,0,0,0,11,11,11,3
2,3,0,0,0,0,0,0,0,0,0,0,0,0,0,0,0,0,0,3,2
2,3,0,0,0,0,0,0,0,0,0,0,0,0,0,0,0,0,0,3,2
2,3,0,0,0,0,0,0,0,0,0,0,0,0,0,0,0,0,0,3,2
2,2,3,0,0,0,0,0,0,0,0,0,0,0,0,0,0,0,3,2,2
2,2,3,0,0,0,0,0,0,0,0,0,0,0,0,0,0,0,3,2,2
2,2,2,3,3,0,0,0,0,0,0,0,0,0,0,0,3,3,2,2,2
2,2,2,2,2,3,3,3,0,0,0,0,0,3,3,3,2,2,2,2,2
2,2,2,2,2,2,2,2,3,3,3,3,3,2,2,2,2,2,2,2,2
endlayer

layer
2,2,2,2,2,2,2,2,3,3,3,3,3,2,2,2,2,2,2,2,2
2,2,2,2,2,3,3,3,0,0,0,0,0,3,3,3,2,2,2,2,2
2,2,2,3,3,0,0,0,0,0,0,0,0,0,0,0,3,3,2,2,2
2,2,3,0,0,0,0,0,0,0,0,0,0,0,0,0,0,0,3,2,2
2,2,3,0,0,0,0,0,0,0,0,0,0,0,0,0,0,0,3,2,2
2,3,0,0,0,0,0,0,0,0,0,0,0,0,0,0,0,0,0,3,2
2,3,0,0,0,0,0,0,0,0,0,0,0,0,0,0,0,0,0,3,2
2,3,0,0,0,0,0,0,0,0,0,0,0,0,0,0,0,0,0,3,2
3,0,0,0,0,0,0,0,0,4,4,4,0,0,0,0,0,0,0,0,3
3,0,0,0,0,0,0,0,4,4,4,4,4,0,0,0,0,0,0,0,3
3,0,0,0,0,0,0,0,4,4,4,4,4,0,0,0,0,8,0,8,3
3,0,0,0,0,0,0,0,4,4,4,4,4,0,0,0,0,8,0,8,3
3,0,0,0,0,0,0,0,0,4,4,4,0,0,0,0,0,11,5,11,3
2,3,0,0,0,0,0,0,0,0,0,0,0,0,0,0,0,11,11,3,2
2,3,0,0,0,0,0,0,0,0,0,0,0,0,0,0,0,0,0,3,2
2,3,0,0,0,0,0,0,0,0,0,0,0,0,0,0,0,0,0,3,2
2,2,3,0,0,0,0,0,0,0,0,0,0,0,0,0,0,0,3,2,2
2,2,3,0,0,0,0,0,0,0,0,0,0,0,0,0,0,0,3,2,2
2,2,2,3,3,0,0,0,0,0,0,0,0,0,0,0,3,3,2,2,2
2,2,2,2,2,3,3,3,0,0,0,0,0,3,3,3,2,2,2,2,2
2,2,2,2,2,2,2,2,3,3,3,3,3,2,2,2,2,2,2,2,2
endlayer


# Segment A
layer
2,2,2,2,2,2,2,2,3,3,3,3,3,2,2,2,2,2,2,2,2
2,2,2,2,2,3,3,3,4,4,4,4,4,3,3,3,2,2,2,2,2
2,2,2,3,3,4,4,4,4,4,4,4,4,4,4,4,3,3,2,2,2
2,2,3,4,4,4,4,4,4,4,4,4,4,4,4,4,4,4,3,2,2
2,2,3,4,4,4,4,4,4,4,4,4,4,4,4,4,4,4,3,2,2
2,3,4,4,4,4,4,4,4,4,4,4,4,4,4,4,4,4,4,3,2
2,3,4,4,4,4,4,4,4,4,4,4,4,4,4,4,4,4,4,3,2
2,3,4,4,4,4,4,4,4,4,4,4,4,4,4,4,4,4,4,3,2
3,4,4,4,4,4,4,4,4,4,4,4,4,4,4,4,4,4,4,4,3
3,4,4,4,4,4,4,4,4,4,4,4,4,4,4,4,4,4,4,4,3
3,4,4,4,4,4,4,4,4,4,4,4,4,4,4,4,4,4,0,4,3
3,4,4,4,4,4,4,4,4,4,4,4,4,4,4,4,4,4,0,4,3
3,4,4,4,4,4,4,4,4,4,4,4,4,4,4,4,4,4,0,4,3
2,3,4,4,4,4,4,4,4,4,4,4,4,4,4,4,4,4,5,3,2
2,3,4,4,4,4,4,4,4,4,4,4,4,4,4,4,4,4,4,3,2
2,3,4,4,4,4,4,4,4,4,4,4,4,4,4,4,4,4,4,3,2
2,2,3,4,4,4,4,4,4,4,4,4,4,4,4,4,4,4,3,2,2
2,2,3,4,4,4,4,4,4,4,4,4,4,4,4,4,4,4,3,2,2
2,2,2,3,3,4,4,4,4,4,4,4,4,4,4,4,3,3,2,2,2
2,2,2,2,2,3,3,3,4,4,4,4,4,3,3,3,2,2,2,2,2
2,2,2,2,2,2,2,2,3,3,3,3,3,2,2,2,2,2,2,2,2
endlayer

layer
2,2,2,2,2,2,2,2,3,3,3,3,3,2,2,2,2,2,2,2,2
2,2,2,2,2,3,3,3,0,0,6,0,0,3,3,3,2,2,2,2,2
2,2,2,3,3,0,0,0,0,7,0,0,7,0,0,0,3,3,2,2,2
2,2,3,0,0,0,0,0,0,0,7,0,0,7,0,0,0,0,3,2,2
2,2,3,0,0,0,7,0,0,0,0,7,0,0,0,0,0,7,3,2,2
2,3,0,0,0,0,0,0,0,0,0,0,0,0,0,7,0,0,0,3,2
2,3,0,0,0,0,0,0,7,0,0,0,0,0,0,0,0,0,0,3,2
2,3,0,0,7,0,0,0,0,0,0,0,7,0,0,0,0,7,0,3,2
3,7,0,0,0,0,0,0,0,0,4,0,0,0,0,7,0,0,0,0,3
3,0,0,7,0,0,7,0,0,4,4,4,0,0,0,0,0,8,8,8,3
3,10,0,0,0,0,0,0,4,4,9,4,4,0,7,0,0,8,0,0,3
3,0,0,0,0,0,0,0,0,4,4,4,0,0,0,0,0,8,0,0,3
3,0,0,7,0,0,0,0,0,0,4,0,0,0,0,0,0,8,0,0,3
2,3,11,11,0,0,0,0,0,7,0,0,0,0,0,0,7,0,0,3,2
2,3,12,11,0,0,7,0,0,0,0,0,0,7,0,0,0,0,0,3,2
2,3,0,0,0,0,0,0,0,0,7,0,0,0,0,0,0,0,0,3,2
2,2,3,0,0,0,7,0,0,7,0,0,0,0,0,7,0,0,3,2,2
2,2,3,0,0,0,0,0,0,0,0,0,0,0,0,0,0,0,3,2,2
2,2,2,3,3,0,0,0,0,0,0,0,0,0,0,0,3,3,2,2,2
2,2,2,2,2,3,3,3,0,0,13,0,0,3,3,3,2,2,2,2,2
2,2,2,2,2,2,2,2,3,3,3,3,3,2,2,2,2,2,2,2,2
endlayer

layer
2,2,2,2,2,2,2,2,3,3,3,3,3,2,2,2,2,2,2,2,2
2,2,2,2,2,3,3,3,0,0,0,0,0,3,3,3,2,2,2,2,2
2,2,2,3,3,0,0,0,0,0,0,0,0,0,0,0,3,3,2,2,2
2,2,3,0,0,0,0,0,0,0,0,0,0,0,0,0,0,0,3,2,2
2,2,3,0,0,0,0,0,0,0,0,0,0,0,0,0,0,0,3,2,2
2,3,0,0,0,0,0,0,0,0,0,0,0,0,0,0,0,0,0,3,2
2,3,0,0,0,0,0,0,0,0,0,0,0,0,0,0,0,0,0,3,2
2,3,0,0,0,0,0,0,0,0,0,0,0,0,0,0,0,0,0,3,2
3,0,0,0,0,0,0,0,0,0,0,0,0,0,0,0,0,0,0,0,3
3,0,0,0,0,0,0,0,0,0,4,7,0,0,0,0,0,0,0,0,3
3,0,0,0,0,0,0,0,0,4,4,4,0,0,0,0,0,0,0,0,3
3,0,0,0,0,0,0,0,0,0,4,0,0,0,0,0,0,0,0,0,3
3,11,11,11,0,0,0,0,0,0,7,0,0,0,0,0,0,0,0,0,3
2,3,12,11,0,0,0,0,0,0,0,0,0,0,0,0,0,0,0,3,2
2,3,0,8,0,0,0,0,0,0,0,0,0,0,0,0,0,0,0,3,2
2,3,0,0,0,0,0,0,0,0,0,0,0,0,0,0,0,0,0,3,2
2,2,3,0,0,0,0,0,0,0,0,0,0,0,0,0,0,0,3,2,2
2,2,3,0,0,0,0,0,0,0,0,0,0,0,0,0,0,0,3,2,2
2,2,2,3,3,0,0,0,0,0,0,0,0,0,0,0,3,3,2,2,2
2,2,2,2,2,3,3,3,0,0,0,0,0,3,3,3,2,2,2,2,2
2,2,2,2,2,2,2,2,3,3,3,3,3,2,2,2,2,2,2,2,2
endlayer

layer
2,2,2,2,2,2,2,2,3,3,3,3,3,2,2,2,2,2,2,2,2
2,2,2,2,2,3,3,3,0,0,0,0,0,3,3,3,2,2,2,2,2
2,2,2,3,3,0,0,0,0,0,0,0,0,0,0,0,3,3,2,2,2
2,2,3,0,0,0,0,0,0,0,0,0,0,0,0,0,0,0,3,2,2
2,2,3,0,0,0,0,0,0,0,0,0,0,0,0,0,0,0,3,2,2
2,3,0,0,0,0,0,0,0,0,0,0,0,0,0,0,0,0,0,3,2
2,3,0,0,0,0,0,0,0,0,0,0,0,0,0,0,0,0,0,3,2
2,3,0,0,0,0,0,0,0,0,0,0,0,0,0,0,0,0,0,3,2
3,0,0,0,0,0,0,0,0,0,0,0,0,0,0,0,0,0,0,0,3
3,0,0,0,0,0,0,0,0,0,0,0,0,0,0,0,0,0,0,0,3
3,0,0,0,0,0,0,0,0,0,4,7,0,0,0,0,0,0,0,0,3
3,11,11,11,0,0,0,0,0,0,0,0,0,0,0,0,0,0,0,0,3
3,11,12,11,0,0,0,0,0,0,0,0,0,0,0,0,0,0,0,0,3
2,3,0,8,0,0,0,0,0,0,0,0,0,0,0,0,0,0,0,3,2
2,3,0,8,0,0,0,0,0,0,0,0,0,0,0,0,0,0,0,3,2
2,3,0,0,0,0,0,0,0,0,0,0,0,0,0,0,0,0,0,3,2
2,2,3,0,0,0,0,0,0,0,0,0,0,0,0,0,0,0,3,2,2
2,2,3,0,0,0,0,0,0,0,0,0,0,0,0,0,0,0,3,2,2
2,2,2,3,3,0,0,0,0,0,0,0,0,0,0,0,3,3,2,2,2
2,2,2,2,2,3,3,3,0,0,0,0,0,3,3,3,2,2,2,2,2
2,2,2,2,2,2,2,2,3,3,3,3,3,2,2,2,2,2,2,2,2
endlayer

layer
2,2,2,2,2,2,2,2,3,3,3,3,3,2,2,2,2,2,2,2,2
2,2,2,2,2,3,3,3,0,0,0,0,0,3,3,3,2,2,2,2,2
2,2,2,3,3,0,0,0,0,0,0,0,0,0,0,0,3,3,2,2,2
2,2,3,0,0,0,0,0,0,0,0,0,0,0,0,0,0,0,3,2,2
2,2,3,0,0,0,0,0,0,0,0,0,0,0,0,0,0,0,3,2,2
2,3,0,0,0,0,0,0,0,0,0,0,0,0,0,0,0,0,0,3,2
2,3,0,0,0,0,0,0,0,0,0,0,0,0,0,0,0,0,0,3,2
2,3,0,0,0,0,0,0,0,0,0,0,0,0,0,0,0,0,0,3,2
3,0,0,0,0,0,0,0,0,0,0,0,0,0,0,0,0,0,0,0,3
3,0,0,0,0,0,0,0,0,0,0,0,0,0,0,0,0,0,0,0,3
3,11,11,11,0,0,0,0,0,0,14,0,0,0,0,0,0,0,0,0,3
3,11,12,11,0,0,0,0,0,0,0,0,0,0,0,0,0,0,0,0,3
3,8,0,8,0,0,0,0,0,0,0,0,0,0,0,0,0,0,0,0,3
2,3,0,8,0,0,0,0,0,0,0,0,0,0,0,0,0,0,0,3,2
2,3,0,0,0,0,0,0,0,0,0,0,0,0,0,0,0,0,0,3,2
2,3,0,0,0,0,0,0,0,0,0,0,0,0,0,0,0,0,0,3,2
2,2,3,0,0,0,0,0,0,0,0,0,0,0,0,0,0,0,3,2,2
2,2,3,0,0,0,0,0,0,0,0,0,0,0,0,0,0,0,3,2,2
2,2,2,3,3,0,0,0,0,0,0,0,0,0,0,0,3,3,2,2,2
2,2,2,2,2,3,3,3,0,0,0,0,0,3,3,3,2,2,2,2,2
2,2,2,2,2,2,2,2,3,3,3,3,3,2,2,2,2,2,2,2,2
endlayer

layer
2,2,2,2,2,2,2,2,3,3,3,3,3,2,2,2,2,2,2,2,2
2,2,2,2,2,3,3,3,0,0,0,0,0,3,3,3,2,2,2,2,2
2,2,2,3,3,0,0,0,0,0,0,0,0,0,0,0,3,3,2,2,2
2,2,3,0,0,0,0,0,0,0,0,0,0,0,0,0,0,0,3,2,2
2,2,3,0,0,0,0,0,0,0,0,0,0,0,0,0,0,0,3,2,2
2,3,0,0,0,0,0,0,0,0,0,0,0,0,0,0,0,0,0,3,2
2,3,0,0,0,0,0,0,0,0,0,0,0,0,0,0,0,0,0,3,2
2,3,0,0,0,0,0,0,0,0,0,0,0,0,0,0,0,0,0,3,2
3,0,0,0,0,0,0,0,0,0,0,0,0,0,0,0,0,0,0,0,3
3,11,11,11,0,0,0,0,0,0,4,0,0,0,0,0,0,0,0,0,3
3,11,12,11,0,0,0,0,0,4,4,4,0,0,0,0,0,0,0,0,3
3,8,0,8,0,0,0,0,0,0,4,0,0,0,0,0,0,0,0,0,3
3,8,0,8,0,0,0,0,0,0,0,0,0,0,0,0,0,0,0,0,3
2,3,0,0,0,0,0,0,0,0,0,0,0,0,0,0,0,0,0,3,2
2,3,0,0,0,0,0,0,0,0,0,0,0,0,0,0,0,0,0,3,2
2,3,0,0,0,0,0,0,0,0,0,0,0,0,0,0,0,0,0,3,2
2,2,3,0,0,0,0,0,0,0,0,0,0,0,0,0,0,0,3,2,2
2,2,3,0,0,0,0,0,0,0,0,0,0,0,0,0,0,0,3,2,2
2,2,2,3,3,0,0,0,0,0,0,0,0,0,0,0,3,3,2,2,2
2,2,2,2,2,3,3,3,0,0,0,0,0,3,3,3,2,2,2,2,2
2,2,2,2,2,2,2,2,3,3,3,3,3,2,2,2,2,2,2,2,2
endlayer

layer
2,2,2,2,2,2,2,2,3,3,3,3,3,2,2,2,2,2,2,2,2
2,2,2,2,2,3,3,3,0,0,0,0,0,3,3,3,2,2,2,2,2
2,2,2,3,3,0,0,0,0,0,0,0,0,0,0,0,3,3,2,2,2
2,2,3,0,0,0,0,0,0,0,0,0,0,0,0,0,0,0,3,2,2
2,2,3,0,0,0,0,0,0,0,0,0,0,0,0,0,0,0,3,2,2
2,3,0,0,0,0,0,0,0,0,0,0,0,0,0,0,0,0,0,3,2
2,3,0,0,0,0,0,0,0,0,0,0,0,0,0,0,0,0,0,3,2
2,3,0,0,0,0,0,0,0,0,0,0,0,0,0,0,0,0,0,3,2
3,11,11,11,0,0,0,0,0,0,0,0,0,0,0,0,0,0,0,0,3
3,11,12,11,0,0,0,0,0,4,4,4,0,0,0,0,0,0,0,0,3
3,8,0,8,0,0,0,0,0,4,4,4,0,0,0,0,0,0,0,0,3
3,8,0,8,0,0,0,0,0,4,4,4,0,0,0,0,0,0,0,0,3
3,0,0,0,0,0,0,0,0,0,0,0,0,0,0,0,0,0,0,0,3
2,3,0,0,0,0,0,0,0,0,0,0,0,0,0,0,0,0,0,3,2
2,3,0,0,0,0,0,0,0,0,0,0,0,0,0,0,0,0,0,3,2
2,3,0,0,0,0,0,0,0,0,0,0,0,0,0,0,0,0,0,3,2
2,2,3,0,0,0,0,0,0,0,0,0,0,0,0,0,0,0,3,2,2
2,2,3,0,0,0,0,0,0,0,0,0,0,0,0,0,0,0,3,2,2
2,2,2,3,3,0,0,0,0,0,0,0,0,0,0,0,3,3,2,2,2
2,2,2,2,2,3,3,3,0,0,0,0,0,3,3,3,2,2,2,2,2
2,2,2,2,2,2,2,2,3,3,3,3,3,2,2,2,2,2,2,2,2
endlayer

layer
2,2,2,2,2,2,2,2,3,3,3,3,3,2,2,2,2,2,2,2,2
2,2,2,2,2,3,3,3,0,0,0,0,0,3,3,3,2,2,2,2,2
2,2,2,3,3,0,0,0,0,0,0,0,0,0,0,0,3,3,2,2,2
2,2,3,0,0,0,0,0,0,0,0,0,0,0,0,0,0,0,3,2,2
2,2,3,0,0,0,0,0,0,0,0,0,0,0,0,0,0,0,3,2,2
2,3,0,0,0,0,0,0,0,0,0,0,0,0,0,0,0,0,0,3,2
2,3,0,0,0,0,0,0,0,0,0,0,0,0,0,0,0,0,0,3,2
2,3,11,11,0,0,0,0,0,0,0,0,0,0,0,0,0,0,0,3,2
3,11,12,11,0,0,0,0,0,4,4,4,0,0,0,0,0,0,0,0,3
3,8,0,8,0,0,0,0,4,4,4,4,4,0,0,0,0,0,0,0,3
3,8,0,8,0,0,0,0,4,4,4,4,4,0,0,0,0,0,0,0,3
3,0,0,0,0,0,0,0,4,4,4,4,4,0,0,0,0,0,0,0,3
3,0,0,0,0,0,0,0,0,4,4,4,0,0,0,0,0,0,0,0,3
2,3,0,0,0,0,0,0,0,0,0,0,0,0,0,0,0,0,0,3,2
2,3,0,0,0,0,0,0,0,0,0,0,0,0,0,0,0,0,0,3,2
2,3,0,0,0,0,0,0,0,0,0,0,0,0,0,0,0,0,0,3,2
2,2,3,0,0,0,0,0,0,0,0,0,0,0,0,0,0,0,3,2,2
2,2,3,0,0,0,0,0,0,0,0,0,0,0,0,0,0,0,3,2,2
2,2,2,3,3,0,0,0,0,0,0,0,0,0,0,0,3,3,2,2,2
2,2,2,2,2,3,3,3,0,0,0,0,0,3,3,3,2,2,2,2,2
2,2,2,2,2,2,2,2,3,3,3,3,3,2,2,2,2,2,2,2,2
endlayer

# Segment B
layer
2,2,2,2,2,2,2,2,3,3,3,3,3,2,2,2,2,2,2,2,2
2,2,2,2,2,3,3,3,4,4,4,4,4,3,3,3,2,2,2,2,2
2,2,2,3,3,4,4,4,4,4,4,4,4,4,4,4,3,3,2,2,2
2,2,3,4,4,4,4,4,4,4,4,4,4,4,4,4,4,4,3,2,2
2,2,3,4,4,4,4,4,4,4,4,4,4,4,4,4,4,4,3,2,2
2,3,4,4,4,4,4,4,4,4,4,4,4,4,4,4,4,4,4,3,2
2,3,4,4,4,4,4,4,4,4,4,4,4,4,4,4,4,4,4,3,2
2,3,12,4,4,4,4,4,4,4,4,4,4,4,4,4,4,4,4,3,2
3,4,0,4,4,4,4,4,4,4,4,4,4,4,4,4,4,4,4,4,3
3,4,0,4,4,4,4,4,4,4,4,4,4,4,4,4,4,4,4,4,3
3,4,0,4,4,4,4,4,4,4,4,4,4,4,4,4,4,4,4,4,3
3,4,4,4,4,4,4,4,4,4,4,4,4,4,4,4,4,4,4,4,3
3,4,4,4,4,4,4,4,4,4,4,4,4,4,4,4,4,4,4,4,3
2,3,4,4,4,4,4,4,4,4,4,4,4,4,4,4,4,4,4,3,2
2,3,4,4,4,4,4,4,4,4,4,4,4,4,4,4,4,4,4,3,2
2,3,4,4,4,4,4,4,4,4,4,4,4,4,4,4,4,4,4,3,2
2,2,3,4,4,4,4,4,4,4,4,4,4,4,4,4,4,4,3,2,2
2,2,3,4,4,4,4,4,4,4,4,4,4,4,4,4,4,4,3,2,2
2,2,2,3,3,4,4,4,4,4,4,4,4,4,4,4,3,3,2,2,2
2,2,2,2,2,3,3,3,4,4,4,4,4,3,3,3,2,2,2,2,2
2,2,2,2,2,2,2,2,3,3,3,3,3,2,2,2,2,2,2,2,2
endlayer

layer
2,2,2,2,2,2,2,2,3,3,3,3,3,2,2,2,2,2,2,2,2
2,2,2,2,2,3,3,3,0,0,6,0,0,3,3,3,2,2,2,2,2
2,2,2,3,3,0,0,0,7,0,0,0,0,7,0,0,3,3,2,2,2
2,2,3,0,0,0,0,0,0,0,0,7,0,0,0,0,0,0,3,2,2
2,2,3,0,0,0,0,0,0,0,0,0,0,0,7,0,7,0,3,2,2
2,3,0,0,7,0,0,0,0,0,7,0,0,0,0,0,0,0,0,3,2
2,3,0,0,0,0,0,0,0,0,0,0,0,7,0,0,0,11,5,3,2
2,3,0,8,0,0,0,7,0,0,0,0,0,0,0,0,0,11,11,3,2
3,0,0,8,0,7,0,0,0,0,4,0,0,0,0,0,7,0,0,0,3
3,0,0,8,0,0,0,0,0,4,4,4,0,0,0,0,0,7,0,7,3
3,0,0,8,7,0,7,0,4,4,16,4,4,0,7,0,0,0,0,15,3
3,8,8,8,0,0,0,0,0,4,4,4,0,0,0,7,0,0,7,0,3
3,0,0,0,0,0,0,0,0,0,4,0,0,0,0,0,0,0,0,0,3
2,3,0,0,0,0,0,0,0,0,0,0,0,0,0,0,0,7,0,3,2
2,3,7,0,0,7,0,0,0,0,0,7,0,0,0,0,0,0,0,3,2
2,3,0,7,0,0,0,0,0,7,0,0,0,0,0,7,0,0,0,3,2
2,2,3,7,0,0,0,0,7,0,0,0,0,0,0,0,0,0,3,2,2
2,2,3,0,7,0,7,0,0,0,0,0,0,0,0,0,0,0,3,2,2
2,2,2,3,3,0,0,0,0,0,0,0,7,0,0,0,3,3,2,2,2
2,2,2,2,2,3,3,3,0,7,13,0,0,3,3,3,2,2,2,2,2
2,2,2,2,2,2,2,2,3,3,3,3,3,2,2,2,2,2,2,2,2
endlayer

layer
2,2,2,2,2,2,2,2,3,3,3,3,3,2,2,2,2,2,2,2,2
2,2,2,2,2,3,3,3,0,0,0,0,0,3,3,3,2,2,2,2,2
2,2,2,3,3,0,0,0,0,0,0,0,0,0,0,0,3,3,2,2,2
2,2,3,0,0,0,0,0,0,0,0,0,0,0,0,0,0,0,3,2,2
2,2,3,0,0,0,0,0,0,0,0,0,0,0,0,0,0,0,3,2,2
2,3,0,0,0,0,0,0,0,0,0,0,0,0,0,0,0,0,0,3,2
2,3,0,0,0,0,0,0,0,0,0,0,0,0,0,0,0,8,0,3,2
2,3,0,0,0,0,0,0,0,0,0,0,0,0,0,0,0,11,5,3,2
3,0,0,0,0,0,0,0,0,0,0,0,0,0,0,0,0,11,11,11,3
3,0,0,0,0,0,0,0,0,0,4,7,0,0,0,0,0,0,0,0,3
3,0,0,0,0,0,0,0,7,4,4,4,0,0,0,0,0,0,0,0,3
3,0,0,0,0,0,0,0,0,0,4,0,0,0,0,0,0,0,0,0,3
3,0,0,0,0,0,0,0,0,0,0,0,0,0,0,0,0,0,0,0,3
2,3,0,0,0,0,0,0,0,0,0,0,0,0,0,0,0,0,0,3,2
2,3,0,0,0,0,0,0,0,0,0,0,0,0,0,0,0,0,0,3,2
2,3,0,0,0,0,0,0,0,0,0,0,0,0,0,0,0,0,0,3,2
2,2,3,0,0,0,0,0,0,0,0,0,0,0,0,0,0,0,3,2,2
2,2,3,0,0,0,0,0,0,0,0,0,0,0,0,0,0,0,3,2,2
2,2,2,3,3,0,0,0,0,0,0,0,0,0,0,0,3,3,2,2,2
2,2,2,2,2,3,3,3,0,0,0,0,0,3,3,3,2,2,2,2,2
2,2,2,2,2,2,2,2,3,3,3,3,3,2,2,2,2,2,2,2,2
endlayer

layer
2,2,2,2,2,2,2,2,3,3,3,3,3,2,2,2,2,2,2,2,2
2,2,2,2,2,3,3,3,0,0,0,0,0,3,3,3,2,2,2,2,2
2,2,2,3,3,0,0,0,0,0,0,0,0,0,0,0,3,3,2,2,2
2,2,3,0,0,0,0,0,0,0,0,0,0,0,0,0,0,0,3,2,2
2,2,3,0,0,0,0,0,0,0,0,0,0,0,0,0,0,0,3,2,2
2,3,0,0,0,0,0,0,0,0,0,0,0,0,0,0,0,0,0,3,2
2,3,0,0,0,0,0,0,0,0,0,0,0,0,0,0,0,8,0,3,2
2,3,0,0,0,0,0,0,0,0,0,0,0,0,0,0,0,8,0,3,2
3,0,0,0,0,0,0,0,0,0,0,0,0,0,0,0,0,11,5,11,3
3,0,0,0,0,0,0,0,0,0,0,0,0,0,0,0,0,11,11,11,3
3,0,0,0,0,0,0,0,0,0,4,0,0,0,0,0,0,0,0,0,3
3,0,0,0,0,0,0,0,0,0,7,0,0,0,0,0,0,0,0,0,3
3,0,0,0,0,0,0,0,0,0,0,0,0,0,0,0,0,0,0,0,3
2,3,0,0,0,0,0,0,0,0,0,0,0,0,0,0,0,0,0,3,2
2,3,0,0,0,0,0,0,0,0,0,0,0,0,0,0,0,0,0,3,2
2,3,0,0,0,0,0,0,0,0,0,0,0,0,0,0,0,0,0,3,2
2,2,3,0,0,0,0,0,0,0,0,0,0,0,0,0,0,0,3,2,2
2,2,3,0,0,0,0,0,0,0,0,0,0,0,0,0,0,0,3,2,2
2,2,2,3,3,0,0,0,0,0,0,0,0,0,0,0,3,3,2,2,2
2,2,2,2,2,3,3,3,0,0,0,0,0,3,3,3,2,2,2,2,2
2,2,2,2,2,2,2,2,3,3,3,3,3,2,2,2,2,2,2,2,2
endlayer

layer
2,2,2,2,2,2,2,2,3,3,3,3,3,2,2,2,2,2,2,2,2
2,2,2,2,2,3,3,3,0,0,0,0,0,3,3,3,2,2,2,2,2
2,2,2,3,3,0,0,0,0,0,0,0,0,0,0,0,3,3,2,2,2
2,2,3,0,0,0,0,0,0,0,0,0,0,0,0,0,0,0,3,2,2
2,2,3,0,0,0,0,0,0,0,0,0,0,0,0,0,0,0,3,2,2
2,3,0,0,0,0,0,0,0,0,0,0,0,0,0,0,0,0,0,3,2
2,3,0,0,0,0,0,0,0,0,0,0,0,0,0,0,0,0,0,3,2
2,3,0,0,0,0,0,0,0,0,0,0,0,0,0,0,0,8,0,3,2
3,0,0,0,0,0,0,0,0,0,0,0,0,0,0,0,0,8,0,8,3
3,0,0,0,0,0,0,0,0,0,0,0,0,0,0,0,0,11,5,11,3
3,0,0,0,0,0,0,0,0,0,14,0,0,0,0,0,0,11,11,11,3
3,0,0,0,0,0,0,0,0,0,0,0,0,0,0,0,0,0,0,0,3
3,0,0,0,0,0,0,0,0,0,0,0,0,0,0,0,0,0,0,0,3
2,3,0,0,0,0,0,0,0,0,0,0,0,0,0,0,0,0,0,3,2
2,3,0,0,0,0,0,0,0,0,0,0,0,0,0,0,0,0,0,3,2
2,3,0,0,0,0,0,0,0,0,0,0,0,0,0,0,0,0,0,3,2
2,2,3,0,0,0,0,0,0,0,0,0,0,0,0,0,0,0,3,2,2
2,2,3,0,0,0,0,0,0,0,0,0,0,0,0,0,0,0,3,2,2
2,2,2,3,3,0,0,0,0,0,0,0,0,0,0,0,3,3,2,2,2
2,2,2,2,2,3,3,3,0,0,0,0,0,3,3,3,2,2,2,2,2
2,2,2,2,2,2,2,2,3,3,3,3,3,2,2,2,2,2,2,2,2
endlayer

layer
2,2,2,2,2,2,2,2,3,3,3,3,3,2,2,2,2,2,2,2,2
2,2,2,2,2,3,3,3,0,0,0,0,0,3,3,3,2,2,2,2,2
2,2,2,3,3,0,0,0,0,0,0,0,0,0,0,0,3,3,2,2,2
2,2,3,0,0,0,0,0,0,0,0,0,0,0,0,0,0,0,3,2,2
2,2,3,0,0,0,0,0,0,0,0,0,0,0,0,0,0,0,3,2,2
2,3,0,0,0,0,0,0,0,0,0,0,0,0,0,0,0,0,0,3,2
2,3,0,0,0,0,0,0,0,0,0,0,0,0,0,0,0,0,0,3,2
2,3,0,0,0,0,0,0,0,0,0,0,0,0,0,0,0,0,0,3,2
3,0,0,0,0,0,0,0,0,0,0,0,0,0,0,0,0,8,0,8,3
3,0,0,0,0,0,0,0,0,0,4,0,0,0,0,0,0,8,0,8,3
3,0,0,0,0,0,0,0,0,4,4,4,0,0,0,0,0,11,5,11,3
3,0,0,0,0,0,0,0,0,0,4,0,0,0,0,0,0,11,11,11,3
3,0,0,0,0,0,0,0,0,0,0,0,0,0,0,0,0,0,0,0,3
2,3,0,0,0,0,0,0,0,0,0,0,0,0,0,0,0,0,0,3,2
2,3,0,0,0,0,0,0,0,0,0,0,0,0,0,0,0,0,0,3,2
2,3,0,0,0,0,0,0,0,0,0,0,0,0,0,0,0,0,0,3,2
2,2,3,0,0,0,0,0,0,0,0,0,0,0,0,0,0,0,3,2,2
2,2,3,0,0,0,0,0,0,0,0,0,0,0,0,0,0,0,3,2,2
2,2,2,3,3,0,0,0,0,0,0,0,0,0,0,0,3,3,2,2,2
2,2,2,2,2,3,3,3,0,0,0,0,0,3,3,3,2,2,2,2,2
2,2,2,2,2,2,2,2,3,3,3,3,3,2,2,2,2,2,2,2,2
endlayer

layer
2,2,2,2,2,2,2,2,3,3,3,3,3,2,2,2,2,2,2,2,2
2,2,2,2,2,3,3,3,0,0,0,0,0,3,3,3,2,2,2,2,2
2,2,2,3,3,0,0,0,0,0,0,0,0,0,0,0,3,3,2,2,2
2,2,3,0,0,0,0,0,0,0,0,0,0,0,0,0,0,0,3,2,2
2,2,3,0,0,0,0,0,0,0,0,0,0,0,0,0,0,0,3,2,2
2,3,0,0,0,0,0,0,0,0,0,0,0,0,0,0,0,0,0,3,2
2,3,0,0,0,0,0,0,0,0,0,0,0,0,0,0,0,0,0,3,2
2,3,0,0,0,0,0,0,0,0,0,0,0,0,0,0,0,0,0,3,2
3,0,0,0,0,0,0,0,0,0,0,0,0,0,0,0,0,0,0,0,3
3,0,0,0,0,0,0,0,0,4,4,4,0,0,0,0,0,8,0,8,3
3,0,0,0,0,0,0,0,0,4,4,4,0,0,0,0,0,8,0,8,3
3,0,0,0,0,0,0,0,0,4,4,4,0,0,0,0,0,11,5,11,3
3,0,0,0,0,0,0,0,0,0,0,0,0,0,0,0,0,11,11,11,3
2,3,0,0,0,0,0,0,0,0,0,0,0,0,0,0,0,0,0,3,2
2,3,0,0,0,0,0,0,0,0,0,0,0,0,0,0,0,0,0,3,2
2,3,0,0,0,0,0,0,0,0,0,0,0,0,0,0,0,0,0,3,2
2,2,3,0,0,0,0,0,0,0,0,0,0,0,0,0,0,0,3,2,2
2,2,3,0,0,0,0,0,0,0,0,0,0,0,0,0,0,0,3,2,2
2,2,2,3,3,0,0,0,0,0,0,0,0,0,0,0,3,3,2,2,2
2,2,2,2,2,3,3,3,0,0,0,0,0,3,3,3,2,2,2,2,2
2,2,2,2,2,2,2,2,3,3,3,3,3,2,2,2,2,2,2,2,2
endlayer

layer
2,2,2,2,2,2,2,2,3,3,3,3,3,2,2,2,2,2,2,2,2
2,2,2,2,2,3,3,3,0,0,0,0,0,3,3,3,2,2,2,2,2
2,2,2,3,3,0,0,0,0,0,0,0,0,0,0,0,3,3,2,2,2
2,2,3,0,0,0,0,0,0,0,0,0,0,0,0,0,0,0,3,2,2
2,2,3,0,0,0,0,0,0,0,0,0,0,0,0,0,0,0,3,2,2
2,3,0,0,0,0,0,0,0,0,0,0,0,0,0,0,0,0,0,3,2
2,3,0,0,0,0,0,0,0,0,0,0,0,0,0,0,0,0,0,3,2
2,3,0,0,0,0,0,0,0,0,0,0,0,0,0,0,0,0,0,3,2
3,0,0,0,0,0,0,0,0,4,4,4,0,0,0,0,0,0,0,0,3
3,0,0,0,0,0,0,0,4,4,4,4,4,0,0,0,0,0,0,0,3
3,0,0,0,0,0,0,0,4,4,4,4,4,0,0,0,0,8,0,8,3
3,0,0,0,0,0,0,0,4,4,4,4,4,0,0,0,0,8,0,8,3
3,0,0,0,0,0,0,0,0,4,4,4,0,0,0,0,0,11,5,11,3
2,3,0,0,0,0,0,0,0,0,0,0,0,0,0,0,0,11,11,3,2
2,3,0,0,0,0,0,0,0,0,0,0,0,0,0,0,0,0,0,3,2
2,3,0,0,0,0,0,0,0,0,0,0,0,0,0,0,0,0,0,3,2
2,2,3,0,0,0,0,0,0,0,0,0,0,0,0,0,0,0,3,2,2
2,2,3,0,0,0,0,0,0,0,0,0,0,0,0,0,0,0,3,2,2
2,2,2,3,3,0,0,0,0,0,0,0,0,0,0,0,3,3,2,2,2
2,2,2,2,2,3,3,3,0,0,0,0,0,3,3,3,2,2,2,2,2
2,2,2,2,2,2,2,2,3,3,3,3,3,2,2,2,2,2,2,2,2
endlayer


# Segment A
layer
2,2,2,2,2,2,2,2,3,3,3,3,3,2,2,2,2,2,2,2,2
2,2,2,2,2,3,3,3,4,4,4,4,4,3,3,3,2,2,2,2,2
2,2,2,3,3,4,4,4,4,4,4,4,4,4,4,4,3,3,2,2,2
2,2,3,4,4,4,4,4,4,4,4,4,4,4,4,4,4,4,3,2,2
2,2,3,4,4,4,4,4,4,4,4,4,4,4,4,4,4,4,3,2,2
2,3,4,4,4,4,4,4,4,4,4,4,4,4,4,4,4,4,4,3,2
2,3,4,4,4,4,4,4,4,4,4,4,4,4,4,4,4,4,4,3,2
2,3,4,4,4,4,4,4,4,4,4,4,4,4,4,4,4,4,4,3,2
3,4,4,4,4,4,4,4,4,4,4,4,4,4,4,4,4,4,4,4,3
3,4,4,4,4,4,4,4,4,4,4,4,4,4,4,4,4,4,4,4,3
3,4,4,4,4,4,4,4,4,4,4,4,4,4,4,4,4,4,0,4,3
3,4,4,4,4,4,4,4,4,4,4,4,4,4,4,4,4,4,0,4,3
3,4,4,4,4,4,4,4,4,4,4,4,4,4,4,4,4,4,0,4,3
2,3,4,4,4,4,4,4,4,4,4,4,4,4,4,4,4,4,5,3,2
2,3,4,4,4,4,4,4,4,4,4,4,4,4,4,4,4,4,4,3,2
2,3,4,4,4,4,4,4,4,4,4,4,4,4,4,4,4,4,4,3,2
2,2,3,4,4,4,4,4,4,4,4,4,4,4,4,4,4,4,3,2,2
2,2,3,4,4,4,4,4,4,4,4,4,4,4,4,4,4,4,3,2,2
2,2,2,3,3,4,4,4,4,4,4,4,4,4,4,4,3,3,2,2,2
2,2,2,2,2,3,3,3,4,4,4,4,4,3,3,3,2,2,2,2,2
2,2,2,2,2,2,2,2,3,3,3,3,3,2,2,2,2,2,2,2,2
endlayer

layer
2,2,2,2,2,2,2,2,3,3,3,3,3,2,2,2,2,2,2,2,2
2,2,2,2,2,3,3,3,0,0,6,0,0,3,3,3,2,2,2,2,2
2,2,2,3,3,0,0,0,0,7,0,0,7,0,0,0,3,3,2,2,2
2,2,3,0,0,0,0,0,0,0,7,0,0,7,0,0,0,0,3,2,2
2,2,3,0,0,0,7,0,0,0,0,7,0,0,0,0,0,7,3,2,2
2,3,0,0,0,0,0,0,0,0,0,0,0,0,0,7,0,0,0,3,2
2,3,0,0,0,0,0,0,7,0,0,0,0,0,0,0,0,0,0,3,2
2,3,0,0,7,0,0,0,0,0,0,0,7,0,0,0,0,7,0,3,2
3,7,0,0,0,0,0,0,0,0,4,0,0,0,0,7,0,0,0,0,3
3,0,0,7,0,0,7,0,0,4,4,4,0,0,0,0,0,8,8,8,3
3,10,0,0,0,0,0,0,4,4,9,4,4,0,7,0,0,8,0,0,3
3,0,0,0,0,0,0,0,0,4,4,4,0,0,0,0,0,8,0,0,3
3,0,0,7,0,0,0,0,0,0,4,0,0,0,0,0,0,8,0,0,3
2,3,11,11,0,0,0,0,0,7,0,0,0,0,0,0,7,0,0,3,2
2,3,12,11,0,0,7,0,0,0,0,0,0,7,0,0,0,0,0,3,2
2,3,0,0,0,0,0,0,0,0,7,0,0,0,0,0,0,0,0,3,2
2,2,3,0,0,0,7,0,0,7,0,0,0,0,0,7,0,0,3,2,2
2,2,3,0,0,0,0,0,0,0,0,0,0,0,0,0,0,0,3,2,2
2,2,2,3,3,0,0,0,0,0,0,0,0,0,0,0,3,3,2,2,2
2,2,2,2,2,3,3,3,0,0,13,0,0,3,3,3,2,2,2,2,2
2,2,2,2,2,2,2,2,3,3,3,3,3,2,2,2,2,2,2,2,2
endlayer

layer
2,2,2,2,2,2,2,2,3,3,3,3,3,2,2,2,2,2,2,2,2
2,2,2,2,2,3,3,3,0,0,0,0,0,3,3,3,2,2,2,2,2
2,2,2,3,3,0,0,0,0,0,0,0,0,0,0,0,3,3,2,2,2
2,2,3,0,0,0,0,0,0,0,0,0,0,0,0,0,0,0,3,2,2
2,2,3,0,0,0,0,0,0,0,0,0,0,0,0,0,0,0,3,2,2
2,3,0,0,0,0,0,0,0,0,0,0,0,0,0,0,0,0,0,3,2
2,3,0,0,0,0,0,0,0,0,0,0,0,0,0,0,0,0,0,3,2
2,3,0,0,0,0,0,0,0,0,0,0,0,0,0,0,0,0,0,3,2
3,0,0,0,0,0,0,0,0,0,0,0,0,0,0,0,0,0,0,0,3
3,0,0,0,0,0,0,0,0,0,4,7,0,0,0,0,0,0,0,0,3
3,0,0,0,0,0,0,0,0,4,4,4,0,0,0,0,0,0,0,0,3
3,0,0,0,0,0,0,0,0,0,4,0,0,0,0,0,0,0,0,0,3
3,11,11,11,0,0,0,0,0,0,7,0,0,0,0,0,0,0,0,0,3
2,3,12,11,0,0,0,0,0,0,0,0,0,0,0,0,0,0,0,3,2
2,3,0,8,0,0,0,0,0,0,0,0,0,0,0,0,0,0,0,3,2
2,3,0,0,0,0,0,0,0,0,0,0,0,0,0,0,0,0,0,3,2
2,2,3,0,0,0,0,0,0,0,0,0,0,0,0,0,0,0,3,2,2
2,2,3,0,0,0,0,0,0,0,0,0,0,0,0,0,0,0,3,2,2
2,2,2,3,3,0,0,0,0,0,0,0,0,0,0,0,3,3,2,2,2
2,2,2,2,2,3,3,3,0,0,0,0,0,3,3,3,2,2,2,2,2
2,2,2,2,2,2,2,2,3,3,3,3,3,2,2,2,2,2,2,2,2
endlayer

layer
2,2,2,2,2,2,2,2,3,3,3,3,3,2,2,2,2,2,2,2,2
2,2,2,2,2,3,3,3,0,0,0,0,0,3,3,3,2,2,2,2,2
2,2,2,3,3,0,0,0,0,0,0,0,0,0,0,0,3,3,2,2,2
2,2,3,0,0,0,0,0,0,0,0,0,0,0,0,0,0,0,3,2,2
2,2,3,0,0,0,0,0,0,0,0,0,0,0,0,0,0,0,3,2,2
2,3,0,0,0,0,0,0,0,0,0,0,0,0,0,0,0,0,0,3,2
2,3,0,0,0,0,0,0,0,0,0,0,0,0,0,0,0,0,0,3,2
2,3,0,0,0,0,0,0,0,0,0,0,0,0,0,0,0,0,0,3,2
3,0,0,0,0,0,0,0,0,0,0,0,0,0,0,0,0,0,0,0,3
3,0,0,0,0,0,0,0,0,0,0,0,0,0,0,0,0,0,0,0,3
3,0,0,0,0,0,0,0,0,0,4,7,0,0,0,0,0,0,0,0,3
3,11,11,11,0,0,0,0,0,0,0,0,0,0,0,0,0,0,0,0,3
3,11,12,11,0,0,0,0,0,0,0,0,0,0,0,0,0,0,0,0,3
2,3,0,8,0,0,0,0,0,0,0,0,0,0,0,0,0,0,0,3,2
2,3,0,8,0,0,0,0,0,0,0,0,0,0,0,0,0,0,0,3,2
2,3,0,0,0,0,0,0,0,0,0,0,0,0,0,0,0,0,0,3,2
2,2,3,0,0,0,0,0,0,0,0,0,0,0,0,0,0,0,3,2,2
2,2,3,0,0,0,0,0,0,0,0,0,0,0,0,0,0,0,3,2,2
2,2,2,3,3,0,0,0,0,0,0,0,0,0,0,0,3,3,2,2,2
2,2,2,2,2,3,3,3,0,0,0,0,0,3,3,3,2,2,2,2,2
2,2,2,2,2,2,2,2,3,3,3,3,3,2,2,2,2,2,2,2,2
endlayer

layer
2,2,2,2,2,2,2,2,3,3,3,3,3,2,2,2,2,2,2,2,2
2,2,2,2,2,3,3,3,0,0,0,0,0,3,3,3,2,2,2,2,2
2,2,2,3,3,0,0,0,0,0,0,0,0,0,0,0,3,3,2,2,2
2,2,3,0,0,0,0,0,0,0,0,0,0,0,0,0,0,0,3,2,2
2,2,3,0,0,0,0,0,0,0,0,0,0,0,0,0,0,0,3,2,2
2,3,0,0,0,0,0,0,0,0,0,0,0,0,0,0,0,0,0,3,2
2,3,0,0,0,0,0,0,0,0,0,0,0,0,0,0,0,0,0,3,2
2,3,0,0,0,0,0,0,0,0,0,0,0,0,0,0,0,0,0,3,2
3,0,0,0,0,0,0,0,0,0,0,0,0,0,0,0,0,0,0,0,3
3,0,0,0,0,0,0,0,0,0,0,0,0,0,0,0,0,0,0,0,3
3,11,11,11,0,0,0,0,0,0,14,0,0,0,0,0,0,0,0,0,3
3,11,12,11,0,0,0,0,0,0,0,0,0,0,0,0,0,0,0,0,3
3,8,0,8,0,0,0,0,0,0,0,0,0,0,0,0,0,0,0,0,3
2,3,0,8,0,0,0,0,0,0,0,0,0,0,0,0,0,0,0,3,2
2,3,0,0,0,0,0,0,0,0,0,0,0,0,0,0,0,0,0,3,2
2,3,0,0,0,0,0,0,0,0,0,0,0,0,0,0,0,0,0,3,2
2,2,3,0,0,0,0,0,0,0,0,0,0,0,0,0,0,0,3,2,2
2,2,3,0,0,0,0,0,0,0,0,0,0,0,0,0,0,0,3,2,2
2,2,2,3,3,0,0,0,0,0,0,0,0,0,0,0,3,3,2,2,2
2,2,2,2,2,3,3,3,0,0,0,0,0,3,3,3,2,2,2,2,2
2,2,2,2,2,2,2,2,3,3,3,3,3,2,2,2,2,2,2,2,2
endlayer

layer
2,2,2,2,2,2,2,2,3,3,3,3,3,2,2,2,2,2,2,2,2
2,2,2,2,2,3,3,3,0,0,0,0,0,3,3,3,2,2,2,2,2
2,2,2,3,3,0,0,0,0,0,0,0,0,0,0,0,3,3,2,2,2
2,2,3,0,0,0,0,0,0,0,0,0,0,0,0,0,0,0,3,2,2
2,2,3,0,0,0,0,0,0,0,0,0,0,0,0,0,0,0,3,2,2
2,3,0,0,0,0,0,0,0,0,0,0,0,0,0,0,0,0,0,3,2
2,3,0,0,0,0,0,0,0,0,0,0,0,0,0,0,0,0,0,3,2
2,3,0,0,0,0,0,0,0,0,0,0,0,0,0,0,0,0,0,3,2
3,0,0,0,0,0,0,0,0,0,0,0,0,0,0,0,0,0,0,0,3
3,11,11,11,0,0,0,0,0,0,4,0,0,0,0,0,0,0,0,0,3
3,11,12,11,0,0,0,0,0,4,4,4,0,0,0,0,0,0,0,0,3
3,8,0,8,0,0,0,0,0,0,4,0,0,0,0,0,0,0,0,0,3
3,8,0,8,0,0,0,0,0,0,0,0,0,0,0,0,0,0,0,0,3
2,3,0,0,0,0,0,0,0,0,0,0,0,0,0,0,0,0,0,3,2
2,3,0,0,0,0,0,0,0,0,0,0,0,0,0,0,0,0,0,3,2
2,3,0,0,0,0,0,0,0,0,0,0,0,0,0,0,0,0,0,3,2
2,2,3,0,0,0,0,0,0,0,0,0,0,0,0,0,0,0,3,2,2
2,2,3,0,0,0,0,0,0,0,0,0,0,0,0,0,0,0,3,2,2
2,2,2,3,3,0,0,0,0,0,0,0,0,0,0,0,3,3,2,2,2
2,2,2,2,2,3,3,3,0,0,0,0,0,3,3,3,2,2,2,2,2
2,2,2,2,2,2,2,2,3,3,3,3,3,2,2,2,2,2,2,2,2
endlayer

layer
2,2,2,2,2,2,2,2,3,3,3,3,3,2,2,2,2,2,2,2,2
2,2,2,2,2,3,3,3,0,0,0,0,0,3,3,3,2,2,2,2,2
2,2,2,3,3,0,0,0,0,0,0,0,0,0,0,0,3,3,2,2,2
2,2,3,0,0,0,0,0,0,0,0,0,0,0,0,0,0,0,3,2,2
2,2,3,0,0,0,0,0,0,0,0,0,0,0,0,0,0,0,3,2,2
2,3,0,0,0,0,0,0,0,0,0,0,0,0,0,0,0,0,0,3,2
2,3,0,0,0,0,0,0,0,0,0,0,0,0,0,0,0,0,0,3,2
2,3,0,0,0,0,0,0,0,0,0,0,0,0,0,0,0,0,0,3,2
3,11,11,11,0,0,0,0,0,0,0,0,0,0,0,0,0,0,0,0,3
3,11,12,11,0,0,0,0,0,4,4,4,0,0,0,0,0,0,0,0,3
3,8,0,8,0,0,0,0,0,4,4,4,0,0,0,0,0,0,0,0,3
3,8,0,8,0,0,0,0,0,4,4,4,0,0,0,0,0,0,0,0,3
3,0,0,0,0,0,0,0,0,0,0,0,0,0,0,0,0,0,0,0,3
2,3,0,0,0,0,0,0,0,0,0,0,0,0,0,0,0,0,0,3,2
2,3,0,0,0,0,0,0,0,0,0,0,0,0,0,0,0,0,0,3,2
2,3,0,0,0,0,0,0,0,0,0,0,0,0,0,0,0,0,0,3,2
2,2,3,0,0,0,0,0,0,0,0,0,0,0,0,0,0,0,3,2,2
2,2,3,0,0,0,0,0,0,0,0,0,0,0,0,0,0,0,3,2,2
2,2,2,3,3,0,0,0,0,0,0,0,0,0,0,0,3,3,2,2,2
2,2,2,2,2,3,3,3,0,0,0,0,0,3,3,3,2,2,2,2,2
2,2,2,2,2,2,2,2,3,3,3,3,3,2,2,2,2,2,2,2,2
endlayer

layer
2,2,2,2,2,2,2,2,3,3,3,3,3,2,2,2,2,2,2,2,2
2,2,2,2,2,3,3,3,0,0,0,0,0,3,3,3,2,2,2,2,2
2,2,2,3,3,0,0,0,0,0,0,0,0,0,0,0,3,3,2,2,2
2,2,3,0,0,0,0,0,0,0,0,0,0,0,0,0,0,0,3,2,2
2,2,3,0,0,0,0,0,0,0,0,0,0,0,0,0,0,0,3,2,2
2,3,0,0,0,0,0,0,0,0,0,0,0,0,0,0,0,0,0,3,2
2,3,0,0,0,0,0,0,0,0,0,0,0,0,0,0,0,0,0,3,2
2,3,11,11,0,0,0,0,0,0,0,0,0,0,0,0,0,0,0,3,2
3,11,12,11,0,0,0,0,0,4,4,4,0,0,0,0,0,0,0,0,3
3,8,0,8,0,0,0,0,4,4,4,4,4,0,0,0,0,0,0,0,3
3,8,0,8,0,0,0,0,4,4,4,4,4,0,0,0,0,0,0,0,3
3,0,0,0,0,0,0,0,4,4,4,4,4,0,0,0,0,0,0,0,3
3,0,0,0,0,0,0,0,0,4,4,4,0,0,0,0,0,0,0,0,3
2,3,0,0,0,0,0,0,0,0,0,0,0,0,0,0,0,0,0,3,2
2,3,0,0,0,0,0,0,0,0,0,0,0,0,0,0,0,0,0,3,2
2,3,0,0,0,0,0,0,0,0,0,0,0,0,0,0,0,0,0,3,2
2,2,3,0,0,0,0,0,0,0,0,0,0,0,0,0,0,0,3,2,2
2,2,3,0,0,0,0,0,0,0,0,0,0,0,0,0,0,0,3,2,2
2,2,2,3,3,0,0,0,0,0,0,0,0,0,0,0,3,3,2,2,2
2,2,2,2,2,3,3,3,0,0,0,0,0,3,3,3,2,2,2,2,2
2,2,2,2,2,2,2,2,3,3,3,3,3,2,2,2,2,2,2,2,2
endlayer

# Segment B
layer
2,2,2,2,2,2,2,2,3,3,3,3,3,2,2,2,2,2,2,2,2
2,2,2,2,2,3,3,3,4,4,4,4,4,3,3,3,2,2,2,2,2
2,2,2,3,3,4,4,4,4,4,4,4,4,4,4,4,3,3,2,2,2
2,2,3,4,4,4,4,4,4,4,4,4,4,4,4,4,4,4,3,2,2
2,2,3,4,4,4,4,4,4,4,4,4,4,4,4,4,4,4,3,2,2
2,3,4,4,4,4,4,4,4,4,4,4,4,4,4,4,4,4,4,3,2
2,3,4,4,4,4,4,4,4,4,4,4,4,4,4,4,4,4,4,3,2
2,3,12,4,4,4,4,4,4,4,4,4,4,4,4,4,4,4,4,3,2
3,4,0,4,4,4,4,4,4,4,4,4,4,4,4,4,4,4,4,4,3
3,4,0,4,4,4,4,4,4,4,4,4,4,4,4,4,4,4,4,4,3
3,4,0,4,4,4,4,4,4,4,4,4,4,4,4,4,4,4,4,4,3
3,4,4,4,4,4,4,4,4,4,4,4,4,4,4,4,4,4,4,4,3
3,4,4,4,4,4,4,4,4,4,4,4,4,4,4,4,4,4,4,4,3
2,3,4,4,4,4,4,4,4,4,4,4,4,4,4,4,4,4,4,3,2
2,3,4,4,4,4,4,4,4,4,4,4,4,4,4,4,4,4,4,3,2
2,3,4,4,4,4,4,4,4,4,4,4,4,4,4,4,4,4,4,3,2
2,2,3,4,4,4,4,4,4,4,4,4,4,4,4,4,4,4,3,2,2
2,2,3,4,4,4,4,4,4,4,4,4,4,4,4,4,4,4,3,2,2
2,2,2,3,3,4,4,4,4,4,4,4,4,4,4,4,3,3,2,2,2
2,2,2,2,2,3,3,3,4,4,4,4,4,3,3,3,2,2,2,2,2
2,2,2,2,2,2,2,2,3,3,3,3,3,2,2,2,2,2,2,2,2
endlayer

layer
2,2,2,2,2,2,2,2,3,3,3,3,3,2,2,2,2,2,2,2,2
2,2,2,2,2,3,3,3,0,0,6,0,0,3,3,3,2,2,2,2,2
2,2,2,3,3,0,0,0,7,0,0,0,0,7,0,0,3,3,2,2,2
2,2,3,0,0,0,0,0,0,0,0,7,0,0,0,0,0,0,3,2,2
2,2,3,0,0,0,0,0,0,0,0,0,0,0,7,0,7,0,3,2,2
2,3,0,0,7,0,0,0,0,0,7,0,0,0,0,0,0,0,0,3,2
2,3,0,0,0,0,0,0,0,0,0,0,0,7,0,0,0,11,5,3,2
2,3,0,8,0,0,0,7,0,0,0,0,0,0,0,0,0,11,11,3,2
3,0,0,8,0,7,0,0,0,0,4,0,0,0,0,0,7,0,0,0,3
3,0,0,8,0,0,0,0,0,4,4,4,0,0,0,0,0,7,0,7,3
3,0,0,8,7,0,7,0,4,4,16,4,4,0,7,0,0,0,0,15,3
3,8,8,8,0,0,0,0,0,4,4,4,0,0,0,7,0,0,7,0,3
3,0,0,0,0,0,0,0,0,0,4,0,0,0,0,0,0,0,0,0,3
2,3,0,0,0,0,0,0,0,0,0,0,0,0,0,0,0,7,0,3,2
2,3,7,0,0,7,0,0,0,0,0,7,0,0,0,0,0,0,0,3,2
2,3,0,7,0,0,0,0,0,7,0,0,0,0,0,7,0,0,0,3,2
2,2,3,7,0,0,0,0,7,0,0,0,0,0,0,0,0,0,3,2,2
2,2,3,0,7,0,7,0,0,0,0,0,0,0,0,0,0,0,3,2,2
2,2,2,3,3,0,0,0,0,0,0,0,7,0,0,0,3,3,2,2,2
2,2,2,2,2,3,3,3,0,7,13,0,0,3,3,3,2,2,2,2,2
2,2,2,2,2,2,2,2,3,3,3,3,3,2,2,2,2,2,2,2,2
endlayer

layer
2,2,2,2,2,2,2,2,3,3,3,3,3,2,2,2,2,2,2,2,2
2,2,2,2,2,3,3,3,0,0,0,0,0,3,3,3,2,2,2,2,2
2,2,2,3,3,0,0,0,0,0,0,0,0,0,0,0,3,3,2,2,2
2,2,3,0,0,0,0,0,0,0,0,0,0,0,0,0,0,0,3,2,2
2,2,3,0,0,0,0,0,0,0,0,0,0,0,0,0,0,0,3,2,2
2,3,0,0,0,0,0,0,0,0,0,0,0,0,0,0,0,0,0,3,2
2,3,0,0,0,0,0,0,0,0,0,0,0,0,0,0,0,8,0,3,2
2,3,0,0,0,0,0,0,0,0,0,0,0,0,0,0,0,11,5,3,2
3,0,0,0,0,0,0,0,0,0,0,0,0,0,0,0,0,11,11,11,3
3,0,0,0,0,0,0,0,0,0,4,7,0,0,0,0,0,0,0,0,3
3,0,0,0,0,0,0,0,7,4,4,4,0,0,0,0,0,0,0,0,3
3,0,0,0,0,0,0,0,0,0,4,0,0,0,0,0,0,0,0,0,3
3,0,0,0,0,0,0,0,0,0,0,0,0,0,0,0,0,0,0,0,3
2,3,0,0,0,0,0,0,0,0,0,0,0,0,0,0,0,0,0,3,2
2,3,0,0,0,0,0,0,0,0,0,0,0,0,0,0,0,0,0,3,2
2,3,0,0,0,0,0,0,0,0,0,0,0,0,0,0,0,0,0,3,2
2,2,3,0,0,0,0,0,0,0,0,0,0,0,0,0,0,0,3,2,2
2,2,3,0,0,0,0,0,0,0,0,0,0,0,0,0,0,0,3,2,2
2,2,2,3,3,0,0,0,0,0,0,0,0,0,0,0,3,3,2,2,2
2,2,2,2,2,3,3,3,0,0,0,0,0,3,3,3,2,2,2,2,2
2,2,2,2,2,2,2,2,3,3,3,3,3,2,2,2,2,2,2,2,2
endlayer

layer
2,2,2,2,2,2,2,2,3,3,3,3,3,2,2,2,2,2,2,2,2
2,2,2,2,2,3,3,3,0,0,0,0,0,3,3,3,2,2,2,2,2
2,2,2,3,3,0,0,0,0,0,0,0,0,0,0,0,3,3,2,2,2
2,2,3,0,0,0,0,0,0,0,0,0,0,0,0,0,0,0,3,2,2
2,2,3,0,0,0,0,0,0,0,0,0,0,0,0,0,0,0,3,2,2
2,3,0,0,0,0,0,0,0,0,0,0,0,0,0,0,0,0,0,3,2
2,3,0,0,0,0,0,0,0,0,0,0,0,0,0,0,0,8,0,3,2
2,3,0,0,0,0,0,0,0,0,0,0,0,0,0,0,0,8,0,3,2
3,0,0,0,0,0,0,0,0,0,0,0,0,0,0,0,0,11,5,11,3
3,0,0,0,0,0,0,0,0,0,0,0,0,0,0,0,0,11,11,11,3
3,0,0,0,0,0,0,0,0,0,4,0,0,0,0,0,0,0,0,0,3
3,0,0,0,0,0,0,0,0,0,7,0,0,0,0,0,0,0,0,0,3
3,0,0,0,0,0,0,0,0,0,0,0,0,0,0,0,0,0,0,0,3
2,3,0,0,0,0,0,0,0,0,0,0,0,0,0,0,0,0,0,3,2
2,3,0,0,0,0,0,0,0,0,0,0,0,0,0,0,0,0,0,3,2
2,3,0,0,0,0,0,0,0,0,0,0,0,0,0,0,0,0,0,3,2
2,2,3,0,0,0,0,0,0,0,0,0,0,0,0,0,0,0,3,2,2
2,2,3,0,0,0,0,0,0,0,0,0,0,0,0,0,0,0,3,2,2
2,2,2,3,3,0,0,0,0,0,0,0,0,0,0,0,3,3,2,2,2
2,2,2,2,2,3,3,3,0,0,0,0,0,3,3,3,2,2,2,2,2
2,2,2,2,2,2,2,2,3,3,3,3,3,2,2,2,2,2,2,2,2
endlayer

layer
2,2,2,2,2,2,2,2,3,3,3,3,3,2,2,2,2,2,2,2,2
2,2,2,2,2,3,3,3,0,0,0,0,0,3,3,3,2,2,2,2,2
2,2,2,3,3,0,0,0,0,0,0,0,0,0,0,0,3,3,2,2,2
2,2,3,0,0,0,0,0,0,0,0,0,0,0,0,0,0,0,3,2,2
2,2,3,0,0,0,0,0,0,0,0,0,0,0,0,0,0,0,3,2,2
2,3,0,0,0,0,0,0,0,0,0,0,0,0,0,0,0,0,0,3,2
2,3,0,0,0,0,0,0,0,0,0,0,0,0,0,0,0,0,0,3,2
2,3,0,0,0,0,0,0,0,0,0,0,0,0,0,0,0,8,0,3,2
3,0,0,0,0,0,0,0,0,0,0,0,0,0,0,0,0,8,0,8,3
3,0,0,0,0,0,0,0,0,0,0,0,0,0,0,0,0,11,5,11,3
3,0,0,0,0,0,0,0,0,0,14,0,0,0,0,0,0,11,11,11,3
3,0,0,0,0,0,0,0,0,0,0,0,0,0,0,0,0,0,0,0,3
3,0,0,0,0,0,0,0,0,0,0,0,0,0,0,0,0,0,0,0,3
2,3,0,0,0,0,0,0,0,0,0,0,0,0,0,0,0,0,0,3,2
2,3,0,0,0,0,0,0,0,0,0,0,0,0,0,0,0,0,0,3,2
2,3,0,0,0,0,0,0,0,0,0,0,0,0,0,0,0,0,0,3,2
2,2,3,0,0,0,0,0,0,0,0,0,0,0,0,0,0,0,3,2,2
2,2,3,0,0,0,0,0,0,0,0,0,0,0,0,0,0,0,3,2,2
2,2,2,3,3,0,0,0,0,0,0,0,0,0,0,0,3,3,2,2,2
2,2,2,2,2,3,3,3,0,0,0,0,0,3,3,3,2,2,2,2,2
2,2,2,2,2,2,2,2,3,3,3,3,3,2,2,2,2,2,2,2,2
endlayer

layer
2,2,2,2,2,2,2,2,3,3,3,3,3,2,2,2,2,2,2,2,2
2,2,2,2,2,3,3,3,0,0,0,0,0,3,3,3,2,2,2,2,2
2,2,2,3,3,0,0,0,0,0,0,0,0,0,0,0,3,3,2,2,2
2,2,3,0,0,0,0,0,0,0,0,0,0,0,0,0,0,0,3,2,2
2,2,3,0,0,0,0,0,0,0,0,0,0,0,0,0,0,0,3,2,2
2,3,0,0,0,0,0,0,0,0,0,0,0,0,0,0,0,0,0,3,2
2,3,0,0,0,0,0,0,0,0,0,0,0,0,0,0,0,0,0,3,2
2,3,0,0,0,0,0,0,0,0,0,0,0,0,0,0,0,0,0,3,2
3,0,0,0,0,0,0,0,0,0,0,0,0,0,0,0,0,8,0,8,3
3,0,0,0,0,0,0,0,0,0,4,0,0,0,0,0,0,8,0,8,3
3,0,0,0,0,0,0,0,0,4,4,4,0,0,0,0,0,11,5,11,3
3,0,0,0,0,0,0,0,0,0,4,0,0,0,0,0,0,11,11,11,3
3,0,0,0,0,0,0,0,0,0,0,0,0,0,0,0,0,0,0,0,3
2,3,0,0,0,0,0,0,0,0,0,0,0,0,0,0,0,0,0,3,2
2,3,0,0,0,0,0,0,0,0,0,0,0,0,0,0,0,0,0,3,2
2,3,0,0,0,0,0,0,0,0,0,0,0,0,0,0,0,0,0,3,2
2,2,3,0,0,0,0,0,0,0,0,0,0,0,0,0,0,0,3,2,2
2,2,3,0,0,0,0,0,0,0,0,0,0,0,0,0,0,0,3,2,2
2,2,2,3,3,0,0,0,0,0,0,0,0,0,0,0,3,3,2,2,2
2,2,2,2,2,3,3,3,0,0,0,0,0,3,3,3,2,2,2,2,2
2,2,2,2,2,2,2,2,3,3,3,3,3,2,2,2,2,2,2,2,2
endlayer

layer
2,2,2,2,2,2,2,2,3,3,3,3,3,2,2,2,2,2,2,2,2
2,2,2,2,2,3,3,3,0,0,0,0,0,3,3,3,2,2,2,2,2
2,2,2,3,3,0,0,0,0,0,0,0,0,0,0,0,3,3,2,2,2
2,2,3,0,0,0,0,0,0,0,0,0,0,0,0,0,0,0,3,2,2
2,2,3,0,0,0,0,0,0,0,0,0,0,0,0,0,0,0,3,2,2
2,3,0,0,0,0,0,0,0,0,0,0,0,0,0,0,0,0,0,3,2
2,3,0,0,0,0,0,0,0,0,0,0,0,0,0,0,0,0,0,3,2
2,3,0,0,0,0,0,0,0,0,0,0,0,0,0,0,0,0,0,3,2
3,0,0,0,0,0,0,0,0,0,0,0,0,0,0,0,0,0,0,0,3
3,0,0,0,0,0,0,0,0,4,4,4,0,0,0,0,0,8,0,8,3
3,0,0,0,0,0,0,0,0,4,4,4,0,0,0,0,0,8,0,8,3
3,0,0,0,0,0,0,0,0,4,4,4,0,0,0,0,0,11,5,11,3
3,0,0,0,0,0,0,0,0,0,0,0,0,0,0,0,0,11,11,11,3
2,3,0,0,0,0,0,0,0,0,0,0,0,0,0,0,0,0,0,3,2
2,3,0,0,0,0,0,0,0,0,0,0,0,0,0,0,0,0,0,3,2
2,3,0,0,0,0,0,0,0,0,0,0,0,0,0,0,0,0,0,3,2
2,2,3,0,0,0,0,0,0,0,0,0,0,0,0,0,0,0,3,2,2
2,2,3,0,0,0,0,0,0,0,0,0,0,0,0,0,0,0,3,2,2
2,2,2,3,3,0,0,0,0,0,0,0,0,0,0,0,3,3,2,2,2
2,2,2,2,2,3,3,3,0,0,0,0,0,3,3,3,2,2,2,2,2
2,2,2,2,2,2,2,2,3,3,3,3,3,2,2,2,2,2,2,2,2
endlayer

layer
2,2,2,2,2,2,2,2,3,3,3,3,3,2,2,2,2,2,2,2,2
2,2,2,2,2,3,3,3,0,0,0,0,0,3,3,3,2,2,2,2,2
2,2,2,3,3,0,0,0,0,0,0,0,0,0,0,0,3,3,2,2,2
2,2,3,0,0,0,0,0,0,0,0,0,0,0,0,0,0,0,3,2,2
2,2,3,0,0,0,0,0,0,0,0,0,0,0,0,0,0,0,3,2,2
2,3,0,0,0,0,0,0,0,0,0,0,0,0,0,0,0,0,0,3,2
2,3,0,0,0,0,0,0,0,0,0,0,0,0,0,0,0,0,0,3,2
2,3,0,0,0,0,0,0,0,0,0,0,0,0,0,0,0,0,0,3,2
3,0,0,0,0,0,0,0,0,4,4,4,0,0,0,0,0,0,0,0,3
3,0,0,0,0,0,0,0,4,4,4,4,4,0,0,0,0,0,0,0,3
3,0,0,0,0,0,0,0,4,4,4,4,4,0,0,0,0,8,0,8,3
3,0,0,0,0,0,0,0,4,4,4,4,4,0,0,0,0,8,0,8,3
3,0,0,0,0,0,0,0,0,4,4,4,0,0,0,0,0,11,5,11,3
2,3,0,0,0,0,0,0,0,0,0,0,0,0,0,0,0,11,11,3,2
2,3,0,0,0,0,0,0,0,0,0,0,0,0,0,0,0,0,0,3,2
2,3,0,0,0,0,0,0,0,0,0,0,0,0,0,0,0,0,0,3,2
2,2,3,0,0,0,0,0,0,0,0,0,0,0,0,0,0,0,3,2,2
2,2,3,0,0,0,0,0,0,0,0,0,0,0,0,0,0,0,3,2,2
2,2,2,3,3,0,0,0,0,0,0,0,0,0,0,0,3,3,2,2,2
2,2,2,2,2,3,3,3,0,0,0,0,0,3,3,3,2,2,2,2,2
2,2,2,2,2,2,2,2,3,3,3,3,3,2,2,2,2,2,2,2,2
endlayer


# Segment A
layer
2,2,2,2,2,2,2,2,3,3,3,3,3,2,2,2,2,2,2,2,2
2,2,2,2,2,3,3,3,4,4,4,4,4,3,3,3,2,2,2,2,2
2,2,2,3,3,4,4,4,4,4,4,4,4,4,4,4,3,3,2,2,2
2,2,3,4,4,4,4,4,4,4,4,4,4,4,4,4,4,4,3,2,2
2,2,3,4,4,4,4,4,4,4,4,4,4,4,4,4,4,4,3,2,2
2,3,4,4,4,4,4,4,4,4,4,4,4,4,4,4,4,4,4,3,2
2,3,4,4,4,4,4,4,4,4,4,4,4,4,4,4,4,4,4,3,2
2,3,4,4,4,4,4,4,4,4,4,4,4,4,4,4,4,4,4,3,2
3,4,4,4,4,4,4,4,4,4,4,4,4,4,4,4,4,4,4,4,3
3,4,4,4,4,4,4,4,4,4,4,4,4,4,4,4,4,4,4,4,3
3,4,4,4,4,4,4,4,4,4,4,4,4,4,4,4,4,4,0,4,3
3,4,4,4,4,4,4,4,4,4,4,4,4,4,4,4,4,4,0,4,3
3,4,4,4,4,4,4,4,4,4,4,4,4,4,4,4,4,4,0,4,3
2,3,4,4,4,4,4,4,4,4,4,4,4,4,4,4,4,4,5,3,2
2,3,4,4,4,4,4,4,4,4,4,4,4,4,4,4,4,4,4,3,2
2,3,4,4,4,4,4,4,4,4,4,4,4,4,4,4,4,4,4,3,2
2,2,3,4,4,4,4,4,4,4,4,4,4,4,4,4,4,4,3,2,2
2,2,3,4,4,4,4,4,4,4,4,4,4,4,4,4,4,4,3,2,2
2,2,2,3,3,4,4,4,4,4,4,4,4,4,4,4,3,3,2,2,2
2,2,2,2,2,3,3,3,4,4,4,4,4,3,3,3,2,2,2,2,2
2,2,2,2,2,2,2,2,3,3,3,3,3,2,2,2,2,2,2,2,2
endlayer

layer
2,2,2,2,2,2,2,2,3,3,3,3,3,2,2,2,2,2,2,2,2
2,2,2,2,2,3,3,3,0,0,6,0,0,3,3,3,2,2,2,2,2
2,2,2,3,3,0,0,0,0,7,0,0,7,0,0,0,3,3,2,2,2
2,2,3,0,0,0,0,0,0,0,7,0,0,7,0,0,0,0,3,2,2
2,2,3,0,0,0,7,0,0,0,0,7,0,0,0,0,0,7,3,2,2
2,3,0,0,0,0,0,0,0,0,0,0,0,0,0,7,0,0,0,3,2
2,3,0,0,0,0,0,0,7,0,0,0,0,0,0,0,0,0,0,3,2
2,3,0,0,7,0,0,0,0,0,0,0,7,0,0,0,0,7,0,3,2
3,7,0,0,0,0,0,0,0,0,4,0,0,0,0,7,0,0,0,0,3
3,0,0,7,0,0,7,0,0,4,4,4,0,0,0,0,0,8,8,8,3
3,10,0,0,0,0,0,0,4,4,9,4,4,0,7,0,0,8,0,0,3
3,0,0,0,0,0,0,0,0,4,4,4,0,0,0,0,0,8,0,0,3
3,0,0,7,0,0,0,0,0,0,4,0,0,0,0,0,0,8,0,0,3
2,3,11,11,0,0,0,0,0,7,0,0,0,0,0,0,7,0,0,3,2
2,3,12,11,0,0,7,0,0,0,0,0,0,7,0,0,0,0,0,3,2
2,3,0,0,0,0,0,0,0,0,7,0,0,0,0,0,0,0,0,3,2
2,2,3,0,0,0,7,0,0,7,0,0,0,0,0,7,0,0,3,2,2
2,2,3,0,0,0,0,0,0,0,0,0,0,0,0,0,0,0,3,2,2
2,2,2,3,3,0,0,0,0,0,0,0,0,0,0,0,3,3,2,2,2
2,2,2,2,2,3,3,3,0,0,13,0,0,3,3,3,2,2,2,2,2
2,2,2,2,2,2,2,2,3,3,3,3,3,2,2,2,2,2,2,2,2
endlayer

layer
2,2,2,2,2,2,2,2,3,3,3,3,3,2,2,2,2,2,2,2,2
2,2,2,2,2,3,3,3,0,0,0,0,0,3,3,3,2,2,2,2,2
2,2,2,3,3,0,0,0,0,0,0,0,0,0,0,0,3,3,2,2,2
2,2,3,0,0,0,0,0,0,0,0,0,0,0,0,0,0,0,3,2,2
2,2,3,0,0,0,0,0,0,0,0,0,0,0,0,0,0,0,3,2,2
2,3,0,0,0,0,0,0,0,0,0,0,0,0,0,0,0,0,0,3,2
2,3,0,0,0,0,0,0,0,0,0,0,0,0,0,0,0,0,0,3,2
2,3,0,0,0,0,0,0,0,0,0,0,0,0,0,0,0,0,0,3,2
3,0,0,0,0,0,0,0,0,0,0,0,0,0,0,0,0,0,0,0,3
3,0,0,0,0,0,0,0,0,0,4,7,0,0,0,0,0,0,0,0,3
3,0,0,0,0,0,0,0,0,4,4,4,0,0,0,0,0,0,0,0,3
3,0,0,0,0,0,0,0,0,0,4,0,0,0,0,0,0,0,0,0,3
3,11,11,11,0,0,0,0,0,0,7,0,0,0,0,0,0,0,0,0,3
2,3,12,11,0,0,0,0,0,0,0,0,0,0,0,0,0,0,0,3,2
2,3,0,8,0,0,0,0,0,0,0,0,0,0,0,0,0,0,0,3,2
2,3,0,0,0,0,0,0,0,0,0,0,0,0,0,0,0,0,0,3,2
2,2,3,0,0,0,0,0,0,0,0,0,0,0,0,0,0,0,3,2,2
2,2,3,0,0,0,0,0,0,0,0,0,0,0,0,0,0,0,3,2,2
2,2,2,3,3,0,0,0,0,0,0,0,0,0,0,0,3,3,2,2,2
2,2,2,2,2,3,3,3,0,0,0,0,0,3,3,3,2,2,2,2,2
2,2,2,2,2,2,2,2,3,3,3,3,3,2,2,2,2,2,2,2,2
endlayer

layer
2,2,2,2,2,2,2,2,3,3,3,3,3,2,2,2,2,2,2,2,2
2,2,2,2,2,3,3,3,0,0,0,0,0,3,3,3,2,2,2,2,2
2,2,2,3,3,0,0,0,0,0,0,0,0,0,0,0,3,3,2,2,2
2,2,3,0,0,0,0,0,0,0,0,0,0,0,0,0,0,0,3,2,2
2,2,3,0,0,0,0,0,0,0,0,0,0,0,0,0,0,0,3,2,2
2,3,0,0,0,0,0,0,0,0,0,0,0,0,0,0,0,0,0,3,2
2,3,0,0,0,0,0,0,0,0,0,0,0,0,0,0,0,0,0,3,2
2,3,0,0,0,0,0,0,0,0,0,0,0,0,0,0,0,0,0,3,2
3,0,0,0,0,0,0,0,0,0,0,0,0,0,0,0,0,0,0,0,3
3,0,0,0,0,0,0,0,0,0,0,0,0,0,0,0,0,0,0,0,3
3,0,0,0,0,0,0,0,0,0,4,7,0,0,0,0,0,0,0,0,3
3,11,11,11,0,0,0,0,0,0,0,0,0,0,0,0,0,0,0,0,3
3,11,12,11,0,0,0,0,0,0,0,0,0,0,0,0,0,0,0,0,3
2,3,0,8,0,0,0,0,0,0,0,0,0,0,0,0,0,0,0,3,2
2,3,0,8,0,0,0,0,0,0,0,0,0,0,0,0,0,0,0,3,2
2,3,0,0,0,0,0,0,0,0,0,0,0,0,0,0,0,0,0,3,2
2,2,3,0,0,0,0,0,0,0,0,0,0,0,0,0,0,0,3,2,2
2,2,3,0,0,0,0,0,0,0,0,0,0,0,0,0,0,0,3,2,2
2,2,2,3,3,0,0,0,0,0,0,0,0,0,0,0,3,3,2,2,2
2,2,2,2,2,3,3,3,0,0,0,0,0,3,3,3,2,2,2,2,2
2,2,2,2,2,2,2,2,3,3,3,3,3,2,2,2,2,2,2,2,2
endlayer

layer
2,2,2,2,2,2,2,2,3,3,3,3,3,2,2,2,2,2,2,2,2
2,2,2,2,2,3,3,3,0,0,0,0,0,3,3,3,2,2,2,2,2
2,2,2,3,3,0,0,0,0,0,0,0,0,0,0,0,3,3,2,2,2
2,2,3,0,0,0,0,0,0,0,0,0,0,0,0,0,0,0,3,2,2
2,2,3,0,0,0,0,0,0,0,0,0,0,0,0,0,0,0,3,2,2
2,3,0,0,0,0,0,0,0,0,0,0,0,0,0,0,0,0,0,3,2
2,3,0,0,0,0,0,0,0,0,0,0,0,0,0,0,0,0,0,3,2
2,3,0,0,0,0,0,0,0,0,0,0,0,0,0,0,0,0,0,3,2
3,0,0,0,0,0,0,0,0,0,0,0,0,0,0,0,0,0,0,0,3
3,0,0,0,0,0,0,0,0,0,0,0,0,0,0,0,0,0,0,0,3
3,11,11,11,0,0,0,0,0,0,14,0,0,0,0,0,0,0,0,0,3
3,11,12,11,0,0,0,0,0,0,0,0,0,0,0,0,0,0,0,0,3
3,8,0,8,0,0,0,0,0,0,0,0,0,0,0,0,0,0,0,0,3
2,3,0,8,0,0,0,0,0,0,0,0,0,0,0,0,0,0,0,3,2
2,3,0,0,0,0,0,0,0,0,0,0,0,0,0,0,0,0,0,3,2
2,3,0,0,0,0,0,0,0,0,0,0,0,0,0,0,0,0,0,3,2
2,2,3,0,0,0,0,0,0,0,0,0,0,0,0,0,0,0,3,2,2
2,2,3,0,0,0,0,0,0,0,0,0,0,0,0,0,0,0,3,2,2
2,2,2,3,3,0,0,0,0,0,0,0,0,0,0,0,3,3,2,2,2
2,2,2,2,2,3,3,3,0,0,0,0,0,3,3,3,2,2,2,2,2
2,2,2,2,2,2,2,2,3,3,3,3,3,2,2,2,2,2,2,2,2
endlayer

layer
2,2,2,2,2,2,2,2,3,3,3,3,3,2,2,2,2,2,2,2,2
2,2,2,2,2,3,3,3,0,0,0,0,0,3,3,3,2,2,2,2,2
2,2,2,3,3,0,0,0,0,0,0,0,0,0,0,0,3,3,2,2,2
2,2,3,0,0,0,0,0,0,0,0,0,0,0,0,0,0,0,3,2,2
2,2,3,0,0,0,0,0,0,0,0,0,0,0,0,0,0,0,3,2,2
2,3,0,0,0,0,0,0,0,0,0,0,0,0,0,0,0,0,0,3,2
2,3,0,0,0,0,0,0,0,0,0,0,0,0,0,0,0,0,0,3,2
2,3,0,0,0,0,0,0,0,0,0,0,0,0,0,0,0,0,0,3,2
3,0,0,0,0,0,0,0,0,0,0,0,0,0,0,0,0,0,0,0,3
3,11,11,11,0,0,0,0,0,0,4,0,0,0,0,0,0,0,0,0,3
3,11,12,11,0,0,0,0,0,4,4,4,0,0,0,0,0,0,0,0,3
3,8,0,8,0,0,0,0,0,0,4,0,0,0,0,0,0,0,0,0,3
3,8,0,8,0,0,0,0,0,0,0,0,0,0,0,0,0,0,0,0,3
2,3,0,0,0,0,0,0,0,0,0,0,0,0,0,0,0,0,0,3,2
2,3,0,0,0,0,0,0,0,0,0,0,0,0,0,0,0,0,0,3,2
2,3,0,0,0,0,0,0,0,0,0,0,0,0,0,0,0,0,0,3,2
2,2,3,0,0,0,0,0,0,0,0,0,0,0,0,0,0,0,3,2,2
2,2,3,0,0,0,0,0,0,0,0,0,0,0,0,0,0,0,3,2,2
2,2,2,3,3,0,0,0,0,0,0,0,0,0,0,0,3,3,2,2,2
2,2,2,2,2,3,3,3,0,0,0,0,0,3,3,3,2,2,2,2,2
2,2,2,2,2,2,2,2,3,3,3,3,3,2,2,2,2,2,2,2,2
endlayer

layer
2,2,2,2,2,2,2,2,3,3,3,3,3,2,2,2,2,2,2,2,2
2,2,2,2,2,3,3,3,0,0,0,0,0,3,3,3,2,2,2,2,2
2,2,2,3,3,0,0,0,0,0,0,0,0,0,0,0,3,3,2,2,2
2,2,3,0,0,0,0,0,0,0,0,0,0,0,0,0,0,0,3,2,2
2,2,3,0,0,0,0,0,0,0,0,0,0,0,0,0,0,0,3,2,2
2,3,0,0,0,0,0,0,0,0,0,0,0,0,0,0,0,0,0,3,2
2,3,0,0,0,0,0,0,0,0,0,0,0,0,0,0,0,0,0,3,2
2,3,0,0,0,0,0,0,0,0,0,0,0,0,0,0,0,0,0,3,2
3,11,11,11,0,0,0,0,0,0,0,0,0,0,0,0,0,0,0,0,3
3,11,12,11,0,0,0,0,0,4,4,4,0,0,0,0,0,0,0,0,3
3,8,0,8,0,0,0,0,0,4,4,4,0,0,0,0,0,0,0,0,3
3,8,0,8,0,0,0,0,0,4,4,4,0,0,0,0,0,0,0,0,3
3,0,0,0,0,0,0,0,0,0,0,0,0,0,0,0,0,0,0,0,3
2,3,0,0,0,0,0,0,0,0,0,0,0,0,0,0,0,0,0,3,2
2,3,0,0,0,0,0,0,0,0,0,0,0,0,0,0,0,0,0,3,2
2,3,0,0,0,0,0,0,0,0,0,0,0,0,0,0,0,0,0,3,2
2,2,3,0,0,0,0,0,0,0,0,0,0,0,0,0,0,0,3,2,2
2,2,3,0,0,0,0,0,0,0,0,0,0,0,0,0,0,0,3,2,2
2,2,2,3,3,0,0,0,0,0,0,0,0,0,0,0,3,3,2,2,2
2,2,2,2,2,3,3,3,0,0,0,0,0,3,3,3,2,2,2,2,2
2,2,2,2,2,2,2,2,3,3,3,3,3,2,2,2,2,2,2,2,2
endlayer

layer
2,2,2,2,2,2,2,2,3,3,3,3,3,2,2,2,2,2,2,2,2
2,2,2,2,2,3,3,3,0,0,0,0,0,3,3,3,2,2,2,2,2
2,2,2,3,3,0,0,0,0,0,0,0,0,0,0,0,3,3,2,2,2
2,2,3,0,0,0,0,0,0,0,0,0,0,0,0,0,0,0,3,2,2
2,2,3,0,0,0,0,0,0,0,0,0,0,0,0,0,0,0,3,2,2
2,3,0,0,0,0,0,0,0,0,0,0,0,0,0,0,0,0,0,3,2
2,3,0,0,0,0,0,0,0,0,0,0,0,0,0,0,0,0,0,3,2
2,3,11,11,0,0,0,0,0,0,0,0,0,0,0,0,0,0,0,3,2
3,11,12,11,0,0,0,0,0,4,4,4,0,0,0,0,0,0,0,0,3
3,8,0,8,0,0,0,0,4,4,4,4,4,0,0,0,0,0,0,0,3
3,8,0,8,0,0,0,0,4,4,4,4,4,0,0,0,0,0,0,0,3
3,0,0,0,0,0,0,0,4,4,4,4,4,0,0,0,0,0,0,0,3
3,0,0,0,0,0,0,0,0,4,4,4,0,0,0,0,0,0,0,0,3
2,3,0,0,0,0,0,0,0,0,0,0,0,0,0,0,0,0,0,3,2
2,3,0,0,0,0,0,0,0,0,0,0,0,0,0,0,0,0,0,3,2
2,3,0,0,0,0,0,0,0,0,0,0,0,0,0,0,0,0,0,3,2
2,2,3,0,0,0,0,0,0,0,0,0,0,0,0,0,0,0,3,2,2
2,2,3,0,0,0,0,0,0,0,0,0,0,0,0,0,0,0,3,2,2
2,2,2,3,3,0,0,0,0,0,0,0,0,0,0,0,3,3,2,2,2
2,2,2,2,2,3,3,3,0,0,0,0,0,3,3,3,2,2,2,2,2
2,2,2,2,2,2,2,2,3,3,3,3,3,2,2,2,2,2,2,2,2
endlayer

# Segment B
layer
2,2,2,2,2,2,2,2,3,3,3,3,3,2,2,2,2,2,2,2,2
2,2,2,2,2,3,3,3,4,4,4,4,4,3,3,3,2,2,2,2,2
2,2,2,3,3,4,4,4,4,4,4,4,4,4,4,4,3,3,2,2,2
2,2,3,4,4,4,4,4,4,4,4,4,4,4,4,4,4,4,3,2,2
2,2,3,4,4,4,4,4,4,4,4,4,4,4,4,4,4,4,3,2,2
2,3,4,4,4,4,4,4,4,4,4,4,4,4,4,4,4,4,4,3,2
2,3,4,4,4,4,4,4,4,4,4,4,4,4,4,4,4,4,4,3,2
2,3,12,4,4,4,4,4,4,4,4,4,4,4,4,4,4,4,4,3,2
3,4,0,4,4,4,4,4,4,4,4,4,4,4,4,4,4,4,4,4,3
3,4,0,4,4,4,4,4,4,4,4,4,4,4,4,4,4,4,4,4,3
3,4,0,4,4,4,4,4,4,4,4,4,4,4,4,4,4,4,4,4,3
3,4,4,4,4,4,4,4,4,4,4,4,4,4,4,4,4,4,4,4,3
3,4,4,4,4,4,4,4,4,4,4,4,4,4,4,4,4,4,4,4,3
2,3,4,4,4,4,4,4,4,4,4,4,4,4,4,4,4,4,4,3,2
2,3,4,4,4,4,4,4,4,4,4,4,4,4,4,4,4,4,4,3,2
2,3,4,4,4,4,4,4,4,4,4,4,4,4,4,4,4,4,4,3,2
2,2,3,4,4,4,4,4,4,4,4,4,4,4,4,4,4,4,3,2,2
2,2,3,4,4,4,4,4,4,4,4,4,4,4,4,4,4,4,3,2,2
2,2,2,3,3,4,4,4,4,4,4,4,4,4,4,4,3,3,2,2,2
2,2,2,2,2,3,3,3,4,4,4,4,4,3,3,3,2,2,2,2,2
2,2,2,2,2,2,2,2,3,3,3,3,3,2,2,2,2,2,2,2,2
endlayer

layer
2,2,2,2,2,2,2,2,3,3,3,3,3,2,2,2,2,2,2,2,2
2,2,2,2,2,3,3,3,0,0,6,0,0,3,3,3,2,2,2,2,2
2,2,2,3,3,0,0,0,7,0,0,0,0,7,0,0,3,3,2,2,2
2,2,3,0,0,0,0,0,0,0,0,7,0,0,0,0,0,0,3,2,2
2,2,3,0,0,0,0,0,0,0,0,0,0,0,7,0,7,0,3,2,2
2,3,0,0,7,0,0,0,0,0,7,0,0,0,0,0,0,0,0,3,2
2,3,0,0,0,0,0,0,0,0,0,0,0,7,0,0,0,11,5,3,2
2,3,0,8,0,0,0,7,0,0,0,0,0,0,0,0,0,11,11,3,2
3,0,0,8,0,7,0,0,0,0,4,0,0,0,0,0,7,0,0,0,3
3,0,0,8,0,0,0,0,0,4,4,4,0,0,0,0,0,7,0,7,3
3,0,0,8,7,0,7,0,4,4,16,4,4,0,7,0,0,0,0,15,3
3,8,8,8,0,0,0,0,0,4,4,4,0,0,0,7,0,0,7,0,3
3,0,0,0,0,0,0,0,0,0,4,0,0,0,0,0,0,0,0,0,3
2,3,0,0,0,0,0,0,0,0,0,0,0,0,0,0,0,7,0,3,2
2,3,7,0,0,7,0,0,0,0,0,7,0,0,0,0,0,0,0,3,2
2,3,0,7,0,0,0,0,0,7,0,0,0,0,0,7,0,0,0,3,2
2,2,3,7,0,0,0,0,7,0,0,0,0,0,0,0,0,0,3,2,2
2,2,3,0,7,0,7,0,0,0,0,0,0,0,0,0,0,0,3,2,2
2,2,2,3,3,0,0,0,0,0,0,0,7,0,0,0,3,3,2,2,2
2,2,2,2,2,3,3,3,0,7,13,0,0,3,3,3,2,2,2,2,2
2,2,2,2,2,2,2,2,3,3,3,3,3,2,2,2,2,2,2,2,2
endlayer

layer
2,2,2,2,2,2,2,2,3,3,3,3,3,2,2,2,2,2,2,2,2
2,2,2,2,2,3,3,3,0,0,0,0,0,3,3,3,2,2,2,2,2
2,2,2,3,3,0,0,0,0,0,0,0,0,0,0,0,3,3,2,2,2
2,2,3,0,0,0,0,0,0,0,0,0,0,0,0,0,0,0,3,2,2
2,2,3,0,0,0,0,0,0,0,0,0,0,0,0,0,0,0,3,2,2
2,3,0,0,0,0,0,0,0,0,0,0,0,0,0,0,0,0,0,3,2
2,3,0,0,0,0,0,0,0,0,0,0,0,0,0,0,0,8,0,3,2
2,3,0,0,0,0,0,0,0,0,0,0,0,0,0,0,0,11,5,3,2
3,0,0,0,0,0,0,0,0,0,0,0,0,0,0,0,0,11,11,11,3
3,0,0,0,0,0,0,0,0,0,4,7,0,0,0,0,0,0,0,0,3
3,0,0,0,0,0,0,0,7,4,4,4,0,0,0,0,0,0,0,0,3
3,0,0,0,0,0,0,0,0,0,4,0,0,0,0,0,0,0,0,0,3
3,0,0,0,0,0,0,0,0,0,0,0,0,0,0,0,0,0,0,0,3
2,3,0,0,0,0,0,0,0,0,0,0,0,0,0,0,0,0,0,3,2
2,3,0,0,0,0,0,0,0,0,0,0,0,0,0,0,0,0,0,3,2
2,3,0,0,0,0,0,0,0,0,0,0,0,0,0,0,0,0,0,3,2
2,2,3,0,0,0,0,0,0,0,0,0,0,0,0,0,0,0,3,2,2
2,2,3,0,0,0,0,0,0,0,0,0,0,0,0,0,0,0,3,2,2
2,2,2,3,3,0,0,0,0,0,0,0,0,0,0,0,3,3,2,2,2
2,2,2,2,2,3,3,3,0,0,0,0,0,3,3,3,2,2,2,2,2
2,2,2,2,2,2,2,2,3,3,3,3,3,2,2,2,2,2,2,2,2
endlayer

layer
2,2,2,2,2,2,2,2,3,3,3,3,3,2,2,2,2,2,2,2,2
2,2,2,2,2,3,3,3,0,0,0,0,0,3,3,3,2,2,2,2,2
2,2,2,3,3,0,0,0,0,0,0,0,0,0,0,0,3,3,2,2,2
2,2,3,0,0,0,0,0,0,0,0,0,0,0,0,0,0,0,3,2,2
2,2,3,0,0,0,0,0,0,0,0,0,0,0,0,0,0,0,3,2,2
2,3,0,0,0,0,0,0,0,0,0,0,0,0,0,0,0,0,0,3,2
2,3,0,0,0,0,0,0,0,0,0,0,0,0,0,0,0,8,0,3,2
2,3,0,0,0,0,0,0,0,0,0,0,0,0,0,0,0,8,0,3,2
3,0,0,0,0,0,0,0,0,0,0,0,0,0,0,0,0,11,5,11,3
3,0,0,0,0,0,0,0,0,0,0,0,0,0,0,0,0,11,11,11,3
3,0,0,0,0,0,0,0,0,0,4,0,0,0,0,0,0,0,0,0,3
3,0,0,0,0,0,0,0,0,0,7,0,0,0,0,0,0,0,0,0,3
3,0,0,0,0,0,0,0,0,0,0,0,0,0,0,0,0,0,0,0,3
2,3,0,0,0,0,0,0,0,0,0,0,0,0,0,0,0,0,0,3,2
2,3,0,0,0,0,0,0,0,0,0,0,0,0,0,0,0,0,0,3,2
2,3,0,0,0,0,0,0,0,0,0,0,0,0,0,0,0,0,0,3,2
2,2,3,0,0,0,0,0,0,0,0,0,0,0,0,0,0,0,3,2,2
2,2,3,0,0,0,0,0,0,0,0,0,0,0,0,0,0,0,3,2,2
2,2,2,3,3,0,0,0,0,0,0,0,0,0,0,0,3,3,2,2,2
2,2,2,2,2,3,3,3,0,0,0,0,0,3,3,3,2,2,2,2,2
2,2,2,2,2,2,2,2,3,3,3,3,3,2,2,2,2,2,2,2,2
endlayer

layer
2,2,2,2,2,2,2,2,3,3,3,3,3,2,2,2,2,2,2,2,2
2,2,2,2,2,3,3,3,0,0,0,0,0,3,3,3,2,2,2,2,2
2,2,2,3,3,0,0,0,0,0,0,0,0,0,0,0,3,3,2,2,2
2,2,3,0,0,0,0,0,0,0,0,0,0,0,0,0,0,0,3,2,2
2,2,3,0,0,0,0,0,0,0,0,0,0,0,0,0,0,0,3,2,2
2,3,0,0,0,0,0,0,0,0,0,0,0,0,0,0,0,0,0,3,2
2,3,0,0,0,0,0,0,0,0,0,0,0,0,0,0,0,0,0,3,2
2,3,0,0,0,0,0,0,0,0,0,0,0,0,0,0,0,8,0,3,2
3,0,0,0,0,0,0,0,0,0,0,0,0,0,0,0,0,8,0,8,3
3,0,0,0,0,0,0,0,0,0,0,0,0,0,0,0,0,11,5,11,3
3,0,0,0,0,0,0,0,0,0,14,0,0,0,0,0,0,11,11,11,3
3,0,0,0,0,0,0,0,0,0,0,0,0,0,0,0,0,0,0,0,3
3,0,0,0,0,0,0,0,0,0,0,0,0,0,0,0,0,0,0,0,3
2,3,0,0,0,0,0,0,0,0,0,0,0,0,0,0,0,0,0,3,2
2,3,0,0,0,0,0,0,0,0,0,0,0,0,0,0,0,0,0,3,2
2,3,0,0,0,0,0,0,0,0,0,0,0,0,0,0,0,0,0,3,2
2,2,3,0,0,0,0,0,0,0,0,0,0,0,0,0,0,0,3,2,2
2,2,3,0,0,0,0,0,0,0,0,0,0,0,0,0,0,0,3,2,2
2,2,2,3,3,0,0,0,0,0,0,0,0,0,0,0,3,3,2,2,2
2,2,2,2,2,3,3,3,0,0,0,0,0,3,3,3,2,2,2,2,2
2,2,2,2,2,2,2,2,3,3,3,3,3,2,2,2,2,2,2,2,2
endlayer

layer
2,2,2,2,2,2,2,2,3,3,3,3,3,2,2,2,2,2,2,2,2
2,2,2,2,2,3,3,3,0,0,0,0,0,3,3,3,2,2,2,2,2
2,2,2,3,3,0,0,0,0,0,0,0,0,0,0,0,3,3,2,2,2
2,2,3,0,0,0,0,0,0,0,0,0,0,0,0,0,0,0,3,2,2
2,2,3,0,0,0,0,0,0,0,0,0,0,0,0,0,0,0,3,2,2
2,3,0,0,0,0,0,0,0,0,0,0,0,0,0,0,0,0,0,3,2
2,3,0,0,0,0,0,0,0,0,0,0,0,0,0,0,0,0,0,3,2
2,3,0,0,0,0,0,0,0,0,0,0,0,0,0,0,0,0,0,3,2
3,0,0,0,0,0,0,0,0,0,0,0,0,0,0,0,0,8,0,8,3
3,0,0,0,0,0,0,0,0,0,4,0,0,0,0,0,0,8,0,8,3
3,0,0,0,0,0,0,0,0,4,4,4,0,0,0,0,0,11,5,11,3
3,0,0,0,0,0,0,0,0,0,4,0,0,0,0,0,0,11,11,11,3
3,0,0,0,0,0,0,0,0,0,0,0,0,0,0,0,0,0,0,0,3
2,3,0,0,0,0,0,0,0,0,0,0,0,0,0,0,0,0,0,3,2
2,3,0,0,0,0,0,0,0,0,0,0,0,0,0,0,0,0,0,3,2
2,3,0,0,0,0,0,0,0,0,0,0,0,0,0,0,0,0,0,3,2
2,2,3,0,0,0,0,0,0,0,0,0,0,0,0,0,0,0,3,2,2
2,2,3,0,0,0,0,0,0,0,0,0,0,0,0,0,0,0,3,2,2
2,2,2,3,3,0,0,0,0,0,0,0,0,0,0,0,3,3,2,2,2
2,2,2,2,2,3,3,3,0,0,0,0,0,3,3,3,2,2,2,2,2
2,2,2,2,2,2,2,2,3,3,3,3,3,2,2,2,2,2,2,2,2
endlayer

layer
2,2,2,2,2,2,2,2,3,3,3,3,3,2,2,2,2,2,2,2,2
2,2,2,2,2,3,3,3,0,0,0,0,0,3,3,3,2,2,2,2,2
2,2,2,3,3,0,0,0,0,0,0,0,0,0,0,0,3,3,2,2,2
2,2,3,0,0,0,0,0,0,0,0,0,0,0,0,0,0,0,3,2,2
2,2,3,0,0,0,0,0,0,0,0,0,0,0,0,0,0,0,3,2,2
2,3,0,0,0,0,0,0,0,0,0,0,0,0,0,0,0,0,0,3,2
2,3,0,0,0,0,0,0,0,0,0,0,0,0,0,0,0,0,0,3,2
2,3,0,0,0,0,0,0,0,0,0,0,0,0,0,0,0,0,0,3,2
3,0,0,0,0,0,0,0,0,0,0,0,0,0,0,0,0,0,0,0,3
3,0,0,0,0,0,0,0,0,4,4,4,0,0,0,0,0,8,0,8,3
3,0,0,0,0,0,0,0,0,4,4,4,0,0,0,0,0,8,0,8,3
3,0,0,0,0,0,0,0,0,4,4,4,0,0,0,0,0,11,5,11,3
3,0,0,0,0,0,0,0,0,0,0,0,0,0,0,0,0,11,11,11,3
2,3,0,0,0,0,0,0,0,0,0,0,0,0,0,0,0,0,0,3,2
2,3,0,0,0,0,0,0,0,0,0,0,0,0,0,0,0,0,0,3,2
2,3,0,0,0,0,0,0,0,0,0,0,0,0,0,0,0,0,0,3,2
2,2,3,0,0,0,0,0,0,0,0,0,0,0,0,0,0,0,3,2,2
2,2,3,0,0,0,0,0,0,0,0,0,0,0,0,0,0,0,3,2,2
2,2,2,3,3,0,0,0,0,0,0,0,0,0,0,0,3,3,2,2,2
2,2,2,2,2,3,3,3,0,0,0,0,0,3,3,3,2,2,2,2,2
2,2,2,2,2,2,2,2,3,3,3,3,3,2,2,2,2,2,2,2,2
endlayer

layer
2,2,2,2,2,2,2,2,3,3,3,3,3,2,2,2,2,2,2,2,2
2,2,2,2,2,3,3,3,0,0,0,0,0,3,3,3,2,2,2,2,2
2,2,2,3,3,0,0,0,0,0,0,0,0,0,0,0,3,3,2,2,2
2,2,3,0,0,0,0,0,0,0,0,0,0,0,0,0,0,0,3,2,2
2,2,3,0,0,0,0,0,0,0,0,0,0,0,0,0,0,0,3,2,2
2,3,0,0,0,0,0,0,0,0,0,0,0,0,0,0,0,0,0,3,2
2,3,0,0,0,0,0,0,0,0,0,0,0,0,0,0,0,0,0,3,2
2,3,0,0,0,0,0,0,0,0,0,0,0,0,0,0,0,0,0,3,2
3,0,0,0,0,0,0,0,0,4,4,4,0,0,0,0,0,0,0,0,3
3,0,0,0,0,0,0,0,4,4,4,4,4,0,0,0,0,0,0,0,3
3,0,0,0,0,0,0,0,4,4,4,4,4,0,0,0,0,8,0,8,3
3,0,0,0,0,0,0,0,4,4,4,4,4,0,0,0,0,8,0,8,3
3,0,0,0,0,0,0,0,0,4,4,4,0,0,0,0,0,11,5,11,3
2,3,0,0,0,0,0,0,0,0,0,0,0,0,0,0,0,11,11,3,2
2,3,0,0,0,0,0,0,0,0,0,0,0,0,0,0,0,0,0,3,2
2,3,0,0,0,0,0,0,0,0,0,0,0,0,0,0,0,0,0,3,2
2,2,3,0,0,0,0,0,0,0,0,0,0,0,0,0,0,0,3,2,2
2,2,3,0,0,0,0,0,0,0,0,0,0,0,0,0,0,0,3,2,2
2,2,2,3,3,0,0,0,0,0,0,0,0,0,0,0,3,3,2,2,2
2,2,2,2,2,3,3,3,0,0,0,0,0,3,3,3,2,2,2,2,2
2,2,2,2,2,2,2,2,3,3,3,3,3,2,2,2,2,2,2,2,2
endlayer


# Segment A - Top
layer
2,2,2,2,2,2,2,2,3,3,3,3,3,2,2,2,2,2,2,2,2
2,2,2,2,2,3,3,3,4,4,4,4,4,3,3,3,2,2,2,2,2
2,2,2,3,3,4,4,4,4,4,4,4,4,4,4,4,3,3,2,2,2
2,2,3,4,4,4,4,4,4,4,4,4,4,4,4,4,4,4,3,2,2
2,2,3,4,4,4,4,4,4,4,4,4,4,4,4,4,4,4,3,2,2
2,3,4,4,4,4,4,4,4,4,4,4,4,4,4,4,4,4,4,3,2
2,3,4,4,4,4,4,4,4,4,4,4,4,4,4,4,4,4,4,3,2
2,3,4,4,4,4,4,4,4,4,4,4,4,4,4,4,4,4,4,3,2
3,4,4,4,4,4,4,4,4,4,4,4,4,4,4,4,4,4,4,4,3
3,4,4,4,4,4,4,4,4,4,4,4,4,4,4,4,4,4,4,4,3
3,4,4,4,4,4,4,4,4,4,4,4,4,4,4,4,4,4,0,4,3
3,4,4,4,4,4,4,4,4,4,4,4,4,4,4,4,4,4,0,4,3
3,4,4,4,4,4,4,4,4,4,4,4,4,4,4,4,4,4,0,4,3
2,3,4,4,4,4,4,4,4,4,4,4,4,4,4,4,4,4,5,3,2
2,3,4,4,4,4,4,4,4,4,4,4,4,4,4,4,4,4,4,3,2
2,3,4,4,4,4,4,4,4,4,4,4,4,4,4,4,4,4,4,3,2
2,2,3,4,4,4,4,4,4,4,4,4,4,4,4,4,4,4,3,2,2
2,2,3,4,4,4,4,4,4,4,4,4,4,4,4,4,4,4,3,2,2
2,2,2,3,3,4,4,4,4,4,4,4,4,4,4,4,3,3,2,2,2
2,2,2,2,2,3,3,3,4,4,4,4,4,3,3,3,2,2,2,2,2
2,2,2,2,2,2,2,2,3,3,3,3,3,2,2,2,2,2,2,2,2
endlayer

layer
2,2,2,2,2,2,2,2,3,3,3,3,3,2,2,2,2,2,2,2,2
2,2,2,2,2,3,3,3,0,0,6,0,0,3,3,3,2,2,2,2,2
2,2,2,3,3,0,0,0,0,7,0,0,7,0,0,0,3,3,2,2,2
2,2,3,0,0,0,0,0,0,0,7,0,0,7,0,0,0,0,3,2,2
2,2,3,0,0,0,7,0,0,0,0,7,0,0,0,0,0,7,3,2,2
2,3,0,0,0,0,0,0,0,0,0,0,0,0,0,7,0,0,0,3,2
2,3,0,0,0,0,0,0,7,0,0,0,0,0,0,0,0,0,0,3,2
2,3,0,0,7,0,0,0,0,0,0,0,7,0,0,0,0,7,0,3,2
3,7,0,0,0,0,0,0,0,0,4,0,0,0,0,7,0,0,0,0,3
3,0,0,7,0,0,7,0,0,4,4,4,0,0,0,0,0,8,8,8,3
3,10,0,0,0,0,0,0,4,4,9,4,4,0,7,0,0,8,0,0,3
3,0,0,0,0,0,0,0,0,4,4,4,0,0,0,0,0,8,0,0,3
3,0,0,7,0,0,0,0,0,0,4,0,0,0,0,0,0,8,0,0,3
2,3,11,11,0,0,0,0,0,7,0,0,0,0,0,0,7,0,0,3,2
2,3,12,11,0,0,7,0,0,0,0,0,0,7,0,0,0,0,0,3,2
2,3,0,0,0,0,0,0,0,0,7,0,0,0,0,0,0,0,0,3,2
2,2,3,0,0,0,7,0,0,7,0,0,0,0,0,7,0,0,3,2,2
2,2,3,0,0,0,0,0,0,0,0,0,0,0,0,0,0,0,3,2,2
2,2,2,3,3,0,0,0,0,0,0,0,0,0,0,0,3,3,2,2,2
2,2,2,2,2,3,3,3,0,0,13,0,0,3,3,3,2,2,2,2,2
2,2,2,2,2,2,2,2,3,3,3,3,3,2,2,2,2,2,2,2,2
endlayer

layer
2,2,2,2,2,2,2,2,3,3,3,3,3,2,2,2,2,2,2,2,2
2,2,2,2,2,3,3,3,0,0,0,0,0,3,3,3,2,2,2,2,2
2,2,2,3,3,0,0,0,0,0,0,0,0,0,0,0,3,3,2,2,2
2,2,3,0,0,0,0,0,0,0,0,0,0,0,0,0,0,0,3,2,2
2,2,3,0,0,0,0,0,0,0,0,0,0,0,0,0,0,0,3,2,2
2,3,0,0,0,0,0,0,0,0,0,0,0,0,0,0,0,0,0,3,2
2,3,0,0,0,0,0,0,0,0,0,0,0,0,0,0,0,0,0,3,2
2,3,0,0,0,0,0,0,0,0,0,0,0,0,0,0,0,0,0,3,2
3,0,0,0,0,0,0,0,0,0,0,0,0,0,0,0,0,0,0,0,3
3,0,0,0,0,0,0,0,0,0,4,7,0,0,0,0,0,0,0,0,3
3,0,0,0,0,0,0,0,0,4,4,4,0,0,0,0,0,0,0,0,3
3,0,0,0,0,0,0,0,0,0,4,0,0,0,0,0,0,0,0,0,3
3,11,11,11,0,0,0,0,0,0,7,0,0,0,0,0,0,0,0,0,3
2,3,12,11,0,0,0,0,0,0,0,0,0,0,0,0,0,0,0,3,2
2,3,0,8,0,0,0,0,0,0,0,0,0,0,0,0,0,0,0,3,2
2,3,0,0,0,0,0,0,0,0,0,0,0,0,0,0,0,0,0,3,2
2,2,3,0,0,0,0,0,0,0,0,0,0,0,0,0,0,0,3,2,2
2,2,3,0,0,0,0,0,0,0,0,0,0,0,0,0,0,0,3,2,2
2,2,2,3,3,0,0,0,0,0,0,0,0,0,0,0,3,3,2,2,2
2,2,2,2,2,3,3,3,0,0,0,0,0,3,3,3,2,2,2,2,2
2,2,2,2,2,2,2,2,3,3,3,3,3,2,2,2,2,2,2,2,2
endlayer

layer
2,2,2,2,2,2,2,2,3,3,3,3,3,2,2,2,2,2,2,2,2
2,2,2,2,2,3,3,3,0,0,0,0,0,3,3,3,2,2,2,2,2
2,2,2,3,3,0,0,0,0,0,0,0,0,0,0,0,3,3,2,2,2
2,2,3,0,0,0,0,0,0,0,0,0,0,0,0,0,0,0,3,2,2
2,2,3,0,0,0,0,0,0,0,0,0,0,0,0,0,0,0,3,2,2
2,3,0,0,0,0,0,0,0,0,0,0,0,0,0,0,0,0,0,3,2
2,3,0,0,0,0,0,0,0,0,0,0,0,0,0,0,0,0,0,3,2
2,3,0,0,0,0,0,0,0,0,0,0,0,0,0,0,0,0,0,3,2
3,0,0,0,0,0,0,0,0,0,0,0,0,0,0,0,0,0,0,0,3
3,0,0,0,0,0,0,0,0,0,0,0,0,0,0,0,0,0,0,0,3
3,0,0,0,0,0,0,0,0,0,4,7,0,0,0,0,0,0,0,0,3
3,11,11,11,0,0,0,0,0,0,0,0,0,0,0,0,0,0,0,0,3
3,11,12,11,0,0,0,0,0,0,0,0,0,0,0,0,0,0,0,0,3
2,3,0,8,0,0,0,0,0,0,0,0,0,0,0,0,0,0,0,3,2
2,3,0,8,0,0,0,0,0,0,0,0,0,0,0,0,0,0,0,3,2
2,3,0,0,0,0,0,0,0,0,0,0,0,0,0,0,0,0,0,3,2
2,2,3,0,0,0,0,0,0,0,0,0,0,0,0,0,0,0,3,2,2
2,2,3,0,0,0,0,0,0,0,0,0,0,0,0,0,0,0,3,2,2
2,2,2,3,3,0,0,0,0,0,0,0,0,0,0,0,3,3,2,2,2
2,2,2,2,2,3,3,3,0,0,0,0,0,3,3,3,2,2,2,2,2
2,2,2,2,2,2,2,2,3,3,3,3,3,2,2,2,2,2,2,2,2
endlayer

layer
2,2,2,2,2,2,2,2,3,3,3,3,3,2,2,2,2,2,2,2,2
2,2,2,2,2,3,3,3,0,0,0,0,0,3,3,3,2,2,2,2,2
2,2,2,3,3,0,0,0,0,0,0,0,0,0,0,0,3,3,2,2,2
2,2,3,0,0,0,0,0,0,0,0,0,0,0,0,0,0,0,3,2,2
2,2,3,0,0,0,0,0,0,0,0,0,0,0,0,0,0,0,3,2,2
2,3,0,0,0,0,0,0,0,0,0,0,0,0,0,0,0,0,0,3,2
2,3,0,0,0,0,0,0,0,0,0,0,0,0,0,0,0,0,0,3,2
2,3,0,0,0,0,0,0,0,0,0,0,0,0,0,0,0,0,0,3,2
3,0,0,0,0,0,0,0,0,0,0,0,0,0,0,0,0,0,0,0,3
3,0,0,0,0,0,0,0,0,0,0,0,0,0,0,0,0,0,0,0,3
3,11,11,11,0,0,0,0,0,0,14,0,0,0,0,0,0,0,0,0,3
3,11,12,11,0,0,0,0,0,0,0,0,0,0,0,0,0,0,0,0,3
3,8,0,8,0,0,0,0,0,0,0,0,0,0,0,0,0,0,0,0,3
2,3,0,8,0,0,0,0,0,0,0,0,0,0,0,0,0,0,0,3,2
2,3,0,0,0,0,0,0,0,0,0,0,0,0,0,0,0,0,0,3,2
2,3,0,0,0,0,0,0,0,0,0,0,0,0,0,0,0,0,0,3,2
2,2,3,0,0,0,0,0,0,0,0,0,0,0,0,0,0,0,3,2,2
2,2,3,0,0,0,0,0,0,0,0,0,0,0,0,0,0,0,3,2,2
2,2,2,3,3,0,0,0,0,0,0,0,0,0,0,0,3,3,2,2,2
2,2,2,2,2,3,3,3,0,0,0,0,0,3,3,3,2,2,2,2,2
2,2,2,2,2,2,2,2,3,3,3,3,3,2,2,2,2,2,2,2,2
endlayer

layer
2,2,2,2,2,2,2,2,3,3,3,3,3,2,2,2,2,2,2,2,2
2,2,2,2,2,3,3,3,0,0,0,0,0,3,3,3,2,2,2,2,2
2,2,2,3,3,0,0,0,0,0,0,0,0,0,0,0,3,3,2,2,2
2,2,3,0,0,0,0,0,0,0,0,0,0,0,0,0,0,0,3,2,2
2,2,3,0,0,0,0,0,0,0,0,0,0,0,0,0,0,0,3,2,2
2,3,0,0,0,0,0,0,0,0,0,0,0,0,0,0,0,0,0,3,2
2,3,0,0,0,0,0,0,0,0,0,0,0,0,0,0,0,0,0,3,2
2,3,0,0,0,0,0,0,0,0,0,0,0,0,0,0,0,0,0,3,2
3,0,0,0,0,0,0,0,0,0,0,0,0,0,0,0,0,0,0,0,3
3,11,11,11,0,0,0,0,0,0,4,0,0,0,0,0,0,0,0,0,3
3,11,12,11,0,0,0,0,0,4,4,4,0,0,0,0,0,0,0,0,3
3,8,0,8,0,0,0,0,0,0,4,0,0,0,0,0,0,0,0,0,3
3,8,0,8,0,0,0,0,0,0,0,0,0,0,0,0,0,0,0,0,3
2,3,0,0,0,0,0,0,0,0,0,0,0,0,0,0,0,0,0,3,2
2,3,0,0,0,0,0,0,0,0,0,0,0,0,0,0,0,0,0,3,2
2,3,0,0,0,0,0,0,0,0,0,0,0,0,0,0,0,0,0,3,2
2,2,3,0,0,0,0,0,0,0,0,0,0,0,0,0,0,0,3,2,2
2,2,3,0,0,0,0,0,0,0,0,0,0,0,0,0,0,0,3,2,2
2,2,2,3,3,0,0,0,0,0,0,0,0,0,0,0,3,3,2,2,2
2,2,2,2,2,3,3,3,0,0,0,0,0,3,3,3,2,2,2,2,2
2,2,2,2,2,2,2,2,3,3,3,3,3,2,2,2,2,2,2,2,2
endlayer

layer
2,2,2,2,2,2,2,2,3,3,3,3,3,2,2,2,2,2,2,2,2
2,2,2,2,2,3,3,3,0,0,0,0,0,3,3,3,2,2,2,2,2
2,2,2,3,3,0,0,0,0,0,0,0,0,0,0,0,3,3,2,2,2
2,2,3,0,0,0,0,0,0,0,0,0,0,0,0,0,0,0,3,2,2
2,2,3,0,0,0,0,0,0,0,0,0,0,0,0,0,0,0,3,2,2
2,3,0,0,0,0,0,0,0,0,0,0,0,0,0,0,0,0,0,3,2
2,3,0,0,0,0,0,0,0,0,0,0,0,0,0,0,0,0,0,3,2
2,3,0,0,0,0,0,0,0,0,0,0,0,0,0,0,0,0,0,3,2
3,11,11,11,0,0,0,0,0,0,0,0,0,0,0,0,0,0,0,0,3
3,11,12,11,0,0,0,0,0,4,4,4,0,0,0,0,0,0,0,0,3
3,8,0,8,0,0,0,0,0,4,4,4,0,0,0,0,0,0,0,0,3
3,8,0,8,0,0,0,0,0,4,4,4,0,0,0,0,0,0,0,0,3
3,0,0,0,0,0,0,0,0,0,0,0,0,0,0,0,0,0,0,0,3
2,3,0,0,0,0,0,0,0,0,0,0,0,0,0,0,0,0,0,3,2
2,3,0,0,0,0,0,0,0,0,0,0,0,0,0,0,0,0,0,3,2
2,3,0,0,0,0,0,0,0,0,0,0,0,0,0,0,0,0,0,3,2
2,2,3,0,0,0,0,0,0,0,0,0,0,0,0,0,0,0,3,2,2
2,2,3,0,0,0,0,0,0,0,0,0,0,0,0,0,0,0,3,2,2
2,2,2,3,3,0,0,0,0,0,0,0,0,0,0,0,3,3,2,2,2
2,2,2,2,2,3,3,3,0,0,0,0,0,3,3,3,2,2,2,2,2
2,2,2,2,2,2,2,2,3,3,3,3,3,2,2,2,2,2,2,2,2
endlayer

layer
2,2,2,2,2,2,2,2,3,3,3,3,3,2,2,2,2,2,2,2,2
2,2,2,2,2,3,3,3,0,0,0,0,0,3,3,3,2,2,2,2,2
2,2,2,3,3,0,0,0,0,0,0,0,0,0,0,0,3,3,2,2,2
2,2,3,0,0,0,0,0,0,0,0,0,0,0,0,0,0,0,3,2,2
2,2,3,0,0,0,0,0,0,0,0,0,0,0,0,0,0,0,3,2,2
2,3,0,0,0,0,0,0,0,0,0,0,0,0,0,0,0,0,0,3,2
2,3,0,0,0,0,0,0,0,0,0,0,0,0,0,0,0,0,0,3,2
2,3,11,11,0,0,0,0,0,0,0,0,0,0,0,0,0,0,0,3,2
3,11,12,11,0,0,0,0,0,4,4,4,0,0,0,0,0,0,0,0,3
3,8,0,8,0,0,0,0,4,4,4,4,4,0,0,0,0,0,0,0,3
3,8,0,8,0,0,0,0,4,4,4,4,4,0,0,0,0,0,0,0,3
3,0,0,0,0,0,0,0,4,4,4,4,4,0,0,0,0,0,0,0,3
3,0,0,0,0,0,0,0,0,4,4,4,0,0,0,0,0,0,0,0,3
2,3,0,0,0,0,0,0,0,0,0,0,0,0,0,0,0,0,0,3,2
2,3,0,0,0,0,0,0,0,0,0,0,0,0,0,0,0,0,0,3,2
2,3,0,0,0,0,0,0,0,0,0,0,0,0,0,0,0,0,0,3,2
2,2,3,0,0,0,0,0,0,0,0,0,0,0,0,0,0,0,3,2,2
2,2,3,0,0,0,0,0,0,0,0,0,0,0,0,0,0,0,3,2,2
2,2,2,3,3,0,0,0,0,0,0,0,0,0,0,0,3,3,2,2,2
2,2,2,2,2,3,3,3,0,0,0,0,0,3,3,3,2,2,2,2,2
2,2,2,2,2,2,2,2,3,3,3,3,3,2,2,2,2,2,2,2,2
endlayer

# Segment B - Top
layer
2,2,2,2,2,2,2,2,3,3,3,3,3,2,2,2,2,2,2,2,2
2,2,2,2,2,3,3,3,4,4,4,4,4,3,3,3,2,2,2,2,2
2,2,2,3,3,4,4,4,4,4,4,4,4,4,4,4,3,3,2,2,2
2,2,3,4,4,4,4,4,4,4,4,4,4,4,4,4,4,4,3,2,2
2,2,3,4,4,4,4,4,4,4,4,4,4,4,4,4,4,4,3,2,2
2,3,4,4,4,4,4,4,4,4,4,4,4,4,4,4,4,4,4,3,2
2,3,4,4,4,4,4,4,4,4,4,4,4,4,4,4,4,4,4,3,2
2,3,12,4,4,4,4,4,4,4,4,4,4,4,4,4,4,4,4,3,2
3,4,0,4,4,4,4,4,4,4,4,4,4,4,4,4,4,4,4,4,3
3,4,0,4,4,4,4,4,4,4,4,4,4,4,4,4,4,4,4,4,3
3,4,0,4,4,4,4,4,4,4,4,4,4,4,4,4,4,4,4,4,3
3,4,4,4,4,4,4,4,4,4,4,4,4,4,4,4,4,4,4,4,3
3,4,4,4,4,4,4,4,4,4,4,4,4,4,4,4,4,4,4,4,3
2,3,4,4,4,4,4,4,4,4,4,4,4,4,4,4,4,4,4,3,2
2,3,4,4,4,4,4,4,4,4,4,4,4,4,4,4,4,4,4,3,2
2,3,4,4,4,4,4,4,4,4,4,4,4,4,4,4,4,4,4,3,2
2,2,3,4,4,4,4,4,4,4,4,4,4,4,4,4,4,4,3,2,2
2,2,3,4,4,4,4,4,4,4,4,4,4,4,4,4,4,4,3,2,2
2,2,2,3,3,4,4,4,4,4,4,4,4,4,4,4,3,3,2,2,2
2,2,2,2,2,3,3,3,4,4,4,4,4,3,3,3,2,2,2,2,2
2,2,2,2,2,2,2,2,3,3,3,3,3,2,2,2,2,2,2,2,2
endlayer

layer
2,2,2,2,2,2,2,2,3,3,3,3,3,2,2,2,2,2,2,2,2
2,2,2,2,2,3,3,3,0,0,0,0,0,3,3,3,2,2,2,2,2
2,2,2,3,3,0,0,0,7,0,0,0,0,7,0,0,3,3,2,2,2
2,2,3,0,0,0,0,0,0,0,0,7,0,0,0,0,0,0,3,2,2
2,2,3,0,0,0,0,0,0,0,0,0,0,0,7,0,7,0,3,2,2
2,3,0,0,7,0,0,0,0,0,7,0,0,0,0,0,0,0,0,3,2
2,3,0,0,0,0,0,0,0,0,0,0,0,7,0,0,0,0,0,3,2
2,3,0,8,0,0,0,7,0,0,0,0,0,0,0,0,0,0,0,3,2
3,0,0,8,0,7,0,0,0,0,4,0,0,0,0,0,7,0,0,0,3
3,0,0,8,0,0,0,0,0,4,4,4,0,0,0,0,0,7,0,7,3
3,0,0,8,7,0,7,0,4,4,1,4,4,0,7,0,0,0,0,0,3
3,8,8,8,0,0,0,0,0,4,4,4,0,0,0,7,0,0,7,0,3
3,0,0,0,0,0,0,0,0,0,4,0,0,0,0,0,0,0,0,0,3
2,3,0,0,0,0,0,0,0,0,0,0,0,0,0,0,0,7,0,3,2
2,3,7,0,0,7,0,0,0,0,0,7,0,0,0,0,0,0,0,3,2
2,3,0,7,0,0,0,0,0,7,0,0,0,0,0,7,0,0,0,3,2
2,2,3,7,0,0,0,0,7,0,0,0,0,0,0,0,0,0,3,2,2
2,2,3,0,7,0,7,0,0,0,0,0,0,0,0,0,0,0,3,2,2
2,2,2,3,3,0,0,0,0,0,0,0,7,0,0,0,3,3,2,2,2
2,2,2,2,2,3,3,3,0,7,0,0,0,3,3,3,2,2,2,2,2
2,2,2,2,2,2,2,2,3,3,3,3,3,2,2,2,2,2,2,2,2
endlayer

layer
2,2,2,2,2,2,2,2,3,3,3,3,3,2,2,2,2,2,2,2,2
2,2,2,2,2,3,3,3,0,0,0,0,0,3,3,3,2,2,2,2,2
2,2,2,3,3,0,0,0,0,0,0,0,0,0,0,0,3,3,2,2,2
2,2,3,0,0,0,0,0,0,0,0,0,0,0,0,0,0,0,3,2,2
2,2,3,0,0,0,0,0,0,0,0,0,0,0,0,0,0,0,3,2,2
2,3,0,0,0,0,0,0,0,0,0,0,0,0,0,0,0,0,0,3,2
2,3,0,0,0,0,0,0,0,0,0,0,0,0,0,0,0,0,0,3,2
2,3,0,0,0,0,0,0,0,0,0,0,0,0,0,0,0,0,0,3,2
3,0,0,0,0,0,0,0,0,0,0,0,0,0,0,0,0,0,0,0,3
3,0,0,0,0,0,0,0,0,0,4,7,0,0,0,0,0,0,0,0,3
3,0,0,0,0,0,0,0,7,4,4,4,0,0,0,0,0,0,0,0,3
3,0,0,0,0,0,0,0,0,0,4,0,0,0,0,0,0,0,0,0,3
3,0,0,0,0,0,0,0,0,0,0,0,0,0,0,0,0,0,0,0,3
2,3,0,0,0,0,0,0,0,0,0,0,0,0,0,0,0,0,0,3,2
2,3,0,0,0,0,0,0,0,0,0,0,0,0,0,0,0,0,0,3,2
2,3,0,0,0,0,0,0,0,0,0,0,0,0,0,0,0,0,0,3,2
2,2,3,0,0,0,0,0,0,0,0,0,0,0,0,0,0,0,3,2,2
2,2,3,0,0,0,0,0,0,0,0,0,0,0,0,0,0,0,3,2,2
2,2,2,3,3,0,0,0,0,0,0,0,0,0,0,0,3,3,2,2,2
2,2,2,2,2,3,3,3,0,0,0,0,0,3,3,3,2,2,2,2,2
2,2,2,2,2,2,2,2,3,3,3,3,3,2,2,2,2,2,2,2,2
endlayer

layer
2,2,2,2,2,2,2,2,3,3,3,3,3,2,2,2,2,2,2,2,2
2,2,2,2,2,3,3,3,0,0,0,0,0,3,3,3,2,2,2,2,2
2,2,2,3,3,0,0,0,0,0,0,0,0,0,0,0,3,3,2,2,2
2,2,3,0,0,0,0,0,0,0,0,0,0,0,0,0,0,0,3,2,2
2,2,3,0,0,0,0,0,0,0,0,0,0,0,0,0,0,0,3,2,2
2,3,0,0,0,0,0,0,0,0,0,0,0,0,0,0,0,0,0,3,2
2,3,0,0,0,0,0,0,0,0,0,0,0,0,0,0,0,0,0,3,2
2,3,0,0,0,0,0,0,0,0,0,0,0,0,0,0,0,0,0,3,2
3,0,0,0,0,0,0,0,0,0,0,0,0,0,0,0,0,0,0,0,3
3,0,0,0,0,0,0,0,0,0,0,0,0,0,0,0,0,0,0,0,3
3,0,0,0,0,0,0,0,0,0,4,0,0,0,0,0,0,0,0,0,3
3,0,0,0,0,0,0,0,0,0,7,0,0,0,0,0,0,0,0,0,3
3,0,0,0,0,0,0,0,0,0,0,0,0,0,0,0,0,0,0,0,3
2,3,0,0,0,0,0,0,0,0,0,0,0,0,0,0,0,0,0,3,2
2,3,0,0,0,0,0,0,0,0,0,0,0,0,0,0,0,0,0,3,2
2,3,0,0,0,0,0,0,0,0,0,0,0,0,0,0,0,0,0,3,2
2,2,3,0,0,0,0,0,0,0,0,0,0,0,0,0,0,0,3,2,2
2,2,3,0,0,0,0,0,0,0,0,0,0,0,0,0,0,0,3,2,2
2,2,2,3,3,0,0,0,0,0,0,0,0,0,0,0,3,3,2,2,2
2,2,2,2,2,3,3,3,0,0,0,0,0,3,3,3,2,2,2,2,2
2,2,2,2,2,2,2,2,3,3,3,3,3,2,2,2,2,2,2,2,2
endlayer

layer
2,2,2,2,2,2,2,2,3,3,3,3,3,2,2,2,2,2,2,2,2
2,2,2,2,2,3,3,3,0,0,0,0,0,3,3,3,2,2,2,2,2
2,2,2,3,3,0,0,0,0,0,0,0,0,0,0,0,3,3,2,2,2
2,2,3,0,0,0,0,0,0,0,0,0,0,0,0,0,0,0,3,2,2
2,2,3,0,0,0,0,0,0,0,0,0,0,0,0,0,0,0,3,2,2
2,3,0,0,0,0,0,0,0,0,0,0,0,0,0,0,0,0,0,3,2
2,3,0,0,0,0,0,0,0,0,0,0,0,0,0,0,0,0,0,3,2
2,3,0,0,0,0,0,0,0,0,0,0,0,0,0,0,0,0,0,3,2
3,0,0,0,0,0,0,0,0,0,0,0,0,0,0,0,0,0,0,0,3
3,0,0,0,0,0,0,0,0,0,0,0,0,0,0,0,0,0,0,0,3
3,0,0,0,0,0,0,0,0,0,14,0,0,0,0,0,0,0,0,0,3
3,0,0,0,0,0,0,0,0,0,0,0,0,0,0,0,0,0,0,0,3
3,0,0,0,0,0,0,0,0,0,0,0,0,0,0,0,0,0,0,0,3
2,3,0,0,0,0,0,0,0,0,0,0,0,0,0,0,0,0,0,3,2
2,3,0,0,0,0,0,0,0,0,0,0,0,0,0,0,0,0,0,3,2
2,3,0,0,0,0,0,0,0,0,0,0,0,0,0,0,0,0,0,3,2
2,2,3,0,0,0,0,0,0,0,0,0,0,0,0,0,0,0,3,2,2
2,2,3,0,0,0,0,0,0,0,0,0,0,0,0,0,0,0,3,2,2
2,2,2,3,3,0,0,0,0,0,0,0,0,0,0,0,3,3,2,2,2
2,2,2,2,2,3,3,3,0,0,0,0,0,3,3,3,2,2,2,2,2
2,2,2,2,2,2,2,2,3,3,3,3,3,2,2,2,2,2,2,2,2
endlayer

layer
2,2,2,2,2,2,2,2,3,3,3,3,3,2,2,2,2,2,2,2,2
2,2,2,2,2,3,3,3,0,0,0,0,0,3,3,3,2,2,2,2,2
2,2,2,3,3,0,0,0,0,0,0,0,0,0,0,0,3,3,2,2,2
2,2,3,0,0,0,0,0,0,0,0,0,0,0,0,0,0,0,3,2,2
2,2,3,0,0,0,0,0,0,0,0,0,0,0,0,0,0,0,3,2,2
2,3,0,0,0,0,0,0,0,0,0,0,0,0,0,0,0,0,0,3,2
2,3,0,0,0,0,0,0,0,0,0,0,0,0,0,0,0,0,0,3,2
2,3,0,0,0,0,0,0,0,0,0,0,0,0,0,0,0,0,0,3,2
3,0,0,0,0,0,0,0,0,0,0,0,0,0,0,0,0,0,0,0,3
3,0,0,0,0,0,0,0,0,0,4,0,0,0,0,0,0,0,0,0,3
3,0,0,0,0,0,0,0,0,4,4,4,0,0,0,0,0,0,0,0,3
3,0,0,0,0,0,0,0,0,0,4,0,0,0,0,0,0,0,0,0,3
3,0,0,0,0,0,0,0,0,0,0,0,0,0,0,0,0,0,0,0,3
2,3,0,0,0,0,0,0,0,0,0,0,0,0,0,0,0,0,0,3,2
2,3,0,0,0,0,0,0,0,0,0,0,0,0,0,0,0,0,0,3,2
2,3,0,0,0,0,0,0,0,0,0,0,0,0,0,0,0,0,0,3,2
2,2,3,0,0,0,0,0,0,0,0,0,0,0,0,0,0,0,3,2,2
2,2,3,0,0,0,0,0,0,0,0,0,0,0,0,0,0,0,3,2,2
2,2,2,3,3,0,0,0,0,0,0,0,0,0,0,0,3,3,2,2,2
2,2,2,2,2,3,3,3,0,0,0,0,0,3,3,3,2,2,2,2,2
2,2,2,2,2,2,2,2,3,3,3,3,3,2,2,2,2,2,2,2,2
endlayer

layer
2,2,2,2,2,2,2,2,3,3,3,3,3,2,2,2,2,2,2,2,2
2,2,2,2,2,3,3,3,0,0,0,0,0,3,3,3,2,2,2,2,2
2,2,2,3,3,0,0,0,0,0,0,0,0,0,0,0,3,3,2,2,2
2,2,3,0,0,0,0,0,0,0,0,0,0,0,0,0,0,0,3,2,2
2,2,3,0,0,0,0,0,0,0,0,0,0,0,0,0,0,0,3,2,2
2,3,0,0,0,0,0,0,0,0,0,0,0,0,0,0,0,0,0,3,2
2,3,0,0,0,0,0,0,0,0,0,0,0,0,0,0,0,0,0,3,2
2,3,0,0,0,0,0,0,0,0,0,0,0,0,0,0,0,0,0,3,2
3,0,0,0,0,0,0,0,0,0,0,0,0,0,0,0,0,0,0,0,3
3,0,0,0,0,0,0,0,0,4,4,4,0,0,0,0,0,0,0,0,3
3,0,0,0,0,0,0,0,0,4,4,4,0,0,0,0,0,0,0,0,3
3,0,0,0,0,0,0,0,0,4,4,4,0,0,0,0,0,0,0,0,3
3,0,0,0,0,0,0,0,0,0,0,0,0,0,0,0,0,0,0,0,3
2,3,0,0,0,0,0,0,0,0,0,0,0,0,0,0,0,0,0,3,2
2,3,0,0,0,0,0,0,0,0,0,0,0,0,0,0,0,0,0,3,2
2,3,0,0,0,0,0,0,0,0,0,0,0,0,0,0,0,0,0,3,2
2,2,3,0,0,0,0,0,0,0,0,0,0,0,0,0,0,0,3,2,2
2,2,3,0,0,0,0,0,0,0,0,0,0,0,0,0,0,0,3,2,2
2,2,2,3,3,0,0,0,0,0,0,0,0,0,0,0,3,3,2,2,2
2,2,2,2,2,3,3,3,0,0,0,0,0,3,3,3,2,2,2,2,2
2,2,2,2,2,2,2,2,3,3,3,3,3,2,2,2,2,2,2,2,2
endlayer

layer
2,2,2,2,2,2,2,2,3,3,3,3,3,2,2,2,2,2,2,2,2
2,2,2,2,2,3,3,3,0,0,0,0,0,3,3,3,2,2,2,2,2
2,2,2,3,3,0,0,0,0,0,0,0,0,0,0,0,3,3,2,2,2
2,2,3,0,0,0,0,0,0,0,0,0,0,0,0,0,0,0,3,2,2
2,2,3,0,0,0,0,0,0,0,0,0,0,0,0,0,0,0,3,2,2
2,3,0,0,0,0,0,0,0,0,0,0,0,0,0,0,0,0,0,3,2
2,3,0,0,0,0,0,0,0,0,0,0,0,0,0,0,0,0,0,3,2
2,3,0,0,0,0,0,0,0,0,0,0,0,0,0,0,0,0,0,3,2
3,0,0,0,0,0,0,0,0,4,4,4,0,0,0,0,0,0,0,0,3
3,0,0,0,0,0,0,0,4,4,4,4,4,0,0,0,0,0,0,0,3
3,0,0,0,0,0,0,0,4,4,4,4,4,0,0,0,0,0,0,0,3
3,0,0,0,0,0,0,0,4,4,4,4,4,0,0,0,0,0,0,0,3
3,0,0,0,0,0,0,0,0,4,4,4,0,0,0,0,0,0,0,0,3
2,3,0,0,0,0,0,0,0,0,0,0,0,0,0,0,0,0,0,3,2
2,3,0,0,0,0,0,0,0,0,0,0,0,0,0,0,0,0,0,3,2
2,3,0,0,0,0,0,0,0,0,0,0,0,0,0,0,0,0,0,3,2
2,2,3,0,0,0,0,0,0,0,0,0,0,0,0,0,0,0,3,2,2
2,2,3,0,0,0,0,0,0,0,0,0,0,0,0,0,0,0,3,2,2
2,2,2,3,3,0,0,0,0,0,0,0,0,0,0,0,3,3,2,2,2
2,2,2,2,2,3,3,3,0,0,0,0,0,3,3,3,2,2,2,2,2
2,2,2,2,2,2,2,2,3,3,3,3,3,2,2,2,2,2,2,2,2
endlayer


