# Chisel Mossy Ruin
# Created by Ruins mod version 17.1 Ingame Parser
# authoring Player: Jordan_Greywolf
# Created for MC 1.12 / Chisel: 13 Jun 2018

# Note: Only use this template if you have Chisel installed!

biomesToSpawnIn=bayou,dead swamp,dead_swamp,lush swamp,lush_swamp,jungle,jungle m,jungleedge,jungleedge m,junglehills,temperate rainforest,rainforest,extreme jungle,mutated_jungle,mutated_jungle_edge


spawnMinDistance=500
uniqueMinDistance=500

preventRotation=1

weight=1
embed_into_distance=8
acceptable_target_blocks=

unacceptable_target_blocks=flowing_lava,lava,cloud,Natura:Cloud,red_mushroom_block,brown_mushroom_block,planks,cobblestone,torch,stone_slab,double_stone_slab,oak_stairs,spruce_stairs,birch_stairs,dark_oak_stairs,acacia_stairs,jungle_stairs,slime_congealed,slime_dirt,slime_grass,fence,stone_brick,cobblestone_wall,command_block,concrete

dimensions=13,9,9
allowable_overhang=5
max_leveling=5
leveling_buffer=-1
preserve_water=0
preserve_lava=0


# Foundation (Mossy Cobblestone - Big Tile)

rule1=0,100,chisel:cobblestonemossy-7
rule2=0,100,chisel:cobblestonemossy1-7

# Floor (cobblestone/moss stone mix)
rule3=0,100,minecraft:mossy_cobblestone-0,minecraft:cobblestone-0

rule4=0,100,minecraft:tnt-0

rule5=0,100,chisel:cobblestonemossy1-2
rule6=0,100,chisel:cobblestonemossy-1

# "Magic Runes"
rule7=0,100,chisel:energizedvoidstone-4

# Treasure Block
rule8=0,100,minecraft:lapis_block-0

# Mob Spawner
rule9=0,100,MobSpawner:Spider,MobSpawner:Skeleton

rule10=0,100,minecraft:vine-6
rule11=0,100,minecraft:vine-2
rule12=0,100,minecraft:vine-8
rule13=0,100,minecraft:vine-4
rule14=0,100,minecraft:vine-1
rule15=0,100,chisel:lavastone-11
rule16=0,100,minecraft:vine-7

# Trapped Treasure Chest
rule17=0,100,IInventory;minecraft:trapped_chest;chisel:waterstone#8#11#0+chisel:chisel_diamond#{chiseldata:{}}#0#2+minecraft:vine#9#0#4+minecraft:diamond_hoe#1#0#6+chisel:voidstone#2#0#8+chisel:voidstone#2#0#10+minecraft:hay_block#1#0#12+chisel:voidstone#2#0#14+minecraft:golden_horse_armor#1#0#18+chisel:voidstone#2#0#20+chisel:lavastone#5#11#25-3

rule18=0,100,minecraft:vine-9

# Corner Supports
rule19=0,100,minecraft:cobblestone_wall-1,minecraft:cobblestone_wall-0

rule20=0,100,minecraft:vine-15

rule21=0,100,minecraft:flowing_lava

rule22=0,100,minecraft:vine-12
rule23=0,100,chisel:cobblestonemossy1-12
rule24=0,100,minecraft:stone_stairs-0
rule25=0,100,minecraft:stone_stairs-2
rule26=0,100,chisel:cobblestonemossy1-2
rule27=0,100,minecraft:stone_stairs-3
rule28=0,100,minecraft:stone_stairs-1

# Overgrowth
rule29=0,100,preserveBlock

# Ruined Columns
rule30=1,80,chisel:cobblestonemossy1-7

rule31=1,100,Skull:0:0-1

# Altar Sides
rule32=0,100,minecraft:stone_stairs-4
rule33=0,100,minecraft:stone_stairs-5

# Hidden Random Loot
rule34=0,100,ChestGenHook:chests/simple_dungeon:3-2


layer
1,1,1,1,1,1,1,1,1
1,1,1,1,1,1,1,1,1
1,1,1,1,1,1,1,1,1
1,1,1,1,1,1,1,1,1
1,1,1,1,2,1,1,1,1
1,1,1,1,1,1,1,1,1
1,1,1,1,1,1,1,1,1
1,1,1,1,1,1,1,1,1
1,1,1,1,1,1,1,1,1
endlayer

layer
1,1,1,1,1,1,1,1,1
1,3,3,3,3,3,3,3,1
1,3,3,3,4,3,3,3,1
1,3,3,3,4,3,3,3,1
1,3,4,4,4,4,4,3,1
1,3,3,3,4,3,3,3,1
1,3,3,3,4,3,3,3,1
1,3,3,3,3,3,3,3,1
1,1,1,1,1,1,1,1,1
endlayer

layer
5,6,6,5,6,5,6,6,5
6,3,3,3,3,3,3,3,6
6,3,3,3,7,3,3,3,6
5,3,3,3,3,3,3,3,5
6,3,7,3,8,3,7,3,6
5,3,3,3,3,3,3,3,5
6,3,3,3,7,3,3,3,6
6,3,3,3,3,3,3,3,6
5,6,6,5,6,5,6,6,5
endlayer

layer
2,6,6,2,6,2,6,6,2
6,9,0,11,11,11,11,10,6
6,11,0,12,12,12,0,13,6
2,14,13,5,15,5,14,13,2
6,14,13,15,17,0,14,16,6
2,14,13,5,15,5,14,13,2
6,14,0,11,11,11,0,13,6
6,9,18,12,12,12,12,13,6
2,6,6,2,6,2,6,6,2
endlayer

layer
2,6,6,2,6,2,6,6,2
6,14,11,11,11,11,11,13,6
6,14,0,12,12,12,0,13,6
2,14,13,19,15,19,14,13,2
6,14,13,15,21,15,14,20,6
2,14,13,19,15,19,14,13,2
6,14,0,11,11,11,0,13,6
6,12,12,12,12,12,12,22,6
2,6,6,2,6,2,6,6,2
endlayer

layer
2,6,6,2,6,2,6,6,2
6,11,11,11,11,11,11,11,6
6,14,0,12,12,12,0,13,6
2,14,13,19,15,19,14,13,2
6,14,13,15,21,15,14,20,6
2,14,13,19,15,19,14,13,2
6,14,0,11,11,11,0,13,6
6,14,12,12,12,12,12,22,6
2,6,6,2,6,2,6,6,2
endlayer

layer
2,6,6,2,6,2,6,6,2
6,14,11,11,11,11,11,13,6
6,14,0,12,12,12,0,13,6
2,14,13,5,15,5,14,13,2
6,14,13,15,21,15,14,20,6
2,14,13,5,15,5,14,13,2
6,14,0,11,11,11,0,13,6
6,14,12,12,12,12,12,12,6
2,6,6,2,6,2,6,6,2
endlayer

layer
5,6,6,5,6,5,6,6,5
6,3,3,3,3,3,3,3,6
6,3,3,3,3,3,3,3,6
5,3,3,23,23,23,3,3,5
6,3,3,23,23,23,3,20,6
5,3,3,23,23,23,3,3,5
6,3,3,3,3,3,3,3,6
6,3,3,3,3,3,3,3,6
5,6,6,5,6,5,6,6,5
endlayer

layer
24,24,24,24,24,24,24,24,24
27,26,23,26,23,26,23,26,25
27,23,23,23,23,23,23,23,25
27,26,23,26,23,26,23,26,25
27,23,23,23,34,23,23,20,25
27,26,23,26,23,26,23,26,25
27,23,23,23,23,23,23,23,25
27,26,23,26,23,26,23,26,25
27,28,28,28,28,28,28,28,25
endlayer

layer
29,29,29,29,29,29,29,29,29
29,30,29,30,0,30,29,30,29
29,29,29,0,0,0,29,29,29
29,30,0,0,32,0,0,30,29
29,0,0,29,7,29,0,0,29
29,30,0,0,33,0,0,30,29
29,29,29,0,0,0,29,29,29
29,30,29,30,0,30,29,30,29
29,29,29,29,29,29,29,29,29
endlayer

layer
29,29,29,29,0,29,29,29,29
29,30,29,30,0,30,29,30,29
29,29,0,0,0,0,0,29,29
29,30,0,0,0,0,0,30,29
0,0,0,0,31,0,0,0,0
29,30,0,0,0,0,0,30,29
29,29,0,0,0,0,0,29,29
29,30,29,30,0,30,29,30,29
29,29,29,29,0,29,29,29,29
endlayer

layer
29,29,0,0,0,0,0,29,29
29,30,0,30,0,30,0,30,29
0,0,0,0,0,0,0,0,0
0,30,0,0,0,0,0,30,0
0,0,0,0,0,0,0,0,0
0,30,0,0,0,0,0,30,0
0,0,0,0,0,0,0,0,0
29,30,0,30,0,30,0,30,29
29,29,0,0,0,0,0,29,29
endlayer

layer
29,0,0,0,0,0,0,0,29
0,31,0,31,0,31,0,31,0
0,0,0,0,0,0,0,0,0
0,31,0,0,0,0,0,31,0
0,0,0,0,0,0,0,0,0
0,31,0,0,0,0,0,31,0
0,0,0,0,0,0,0,0,0
0,31,0,31,0,31,0,31,0
29,0,0,0,0,0,0,0,29
endlayer


