# Chisel Ice Temple
# Created by Ruins mod version 17.1 Ingame Parser
# authoring Player: Jordan_Greywolf

# Created for MC 1.12 with Chisel Mod: 24 Jun 2018

biomesToSpawnIn=arctic,glacier,ice plains,ice plains spikes,iceika,polar chasm,polar_chasm,rwg_coldplains,ice_flats,mutated_ice_flats

weight=1
embed_into_distance=5
acceptable_target_blocks=

unacceptable_target_blocks=Natura:Cloud,cloud,slime_congealed,slime_dirt,slime_grass,command_block,planks,planks2,concrete,cobblestone,stonebrick,brick_block,glass,torch,oak_stairs,stone_stairs,brick_stairs,stone_brick_stairs,nether_brick_stairs,sandstone_stairs,spruce_stairs,birch_stairs,jungle_stairs,quartz_stairs,acacia_stairs,dark_oak_stairs,cobblestone_wall,stone_slab,double_stone_slab,stone_slab2,wooden_slab,double_wooden_slab,nether_brick,fence

uniqueMinDistance=500
spawnMinDistance=200

dimensions=14,13,13
allowable_overhang=8
max_leveling=5
leveling_buffer=0
preserve_water=0
preserve_lava=0

# Ice: "Big Tile"
rule1=0,100,chisel:ice-7

rule2=0,100,chisel:ice-4
rule3=0,100,chisel:ice-5
rule4=0,100,minecraft:packed_ice-0
rule5=0,100,minecraft:snow-0

# Factory Ice Block
rule6=0,100,chisel:factory1-1

# Plain Ice Pillar
rule7=0,100,chisel:icepillar-0

# Ice Brick Wall
rule8=0,100,chisel:ice-2,chisel:ice-1,chisel:ice1-8

# Snow "slab" (snow layer)
rule9=0,100,minecraft:snow_layer-4

rule10=0,100,ChestGenHook:chests/simple_dungeon:5-3

rule11=0,100,MobSpawner:Stray

# Scribed Ice Pillar Cap
rule12=0,100,chisel:icepillar-5

# "Greek" Ice Pillar
rule13=0,100,chisel:icepillar-1

# "Prism" Ice
rule14=0,100,chisel:ice1-14

layer
1,1,1,1,1,1,1,1,1,1,1,1,1
1,2,1,2,1,2,1,2,1,2,1,2,1
1,1,2,1,2,1,2,1,2,1,2,1,1
1,2,1,3,3,3,3,3,3,3,1,2,1
1,1,2,3,1,3,4,3,1,3,2,1,1
1,2,1,3,3,5,5,5,3,3,1,2,1
1,1,2,3,4,5,6,5,4,3,2,1,1
1,2,1,3,3,5,5,5,3,3,1,2,1
1,1,2,3,1,3,4,3,1,3,2,1,1
1,2,1,3,3,3,3,3,3,3,1,2,1
1,1,2,1,2,1,2,1,2,1,2,1,1
1,2,1,2,1,2,1,2,1,2,1,2,1
1,1,1,1,1,1,1,1,1,1,1,1,1
endlayer

layer
7,8,8,8,7,8,8,8,7,8,8,8,7
8,0,0,0,0,0,0,5,5,5,9,0,8
8,0,0,0,0,0,0,0,0,0,0,0,8
8,0,0,0,0,0,0,0,0,0,0,0,8
7,0,0,0,7,4,4,4,7,0,0,0,7
8,0,0,0,4,0,0,0,4,0,0,0,8
8,0,0,0,0,0,10,0,4,0,0,0,8
8,0,0,0,4,0,0,0,4,0,0,0,8
7,0,0,0,7,4,4,4,7,0,0,0,7
8,0,0,0,0,0,0,0,0,0,0,0,8
8,0,0,0,0,0,0,0,0,0,0,0,8
8,0,0,0,0,0,0,5,5,5,9,0,8
7,8,8,8,7,8,8,8,7,8,8,8,7
endlayer

layer
7,8,8,8,7,8,8,8,7,8,8,8,7
8,0,0,0,0,5,5,5,9,0,0,0,8
8,0,0,0,0,0,0,0,0,0,0,0,8
8,0,0,0,0,0,0,0,0,0,0,0,8
7,0,0,0,7,4,4,4,7,0,0,0,7
8,0,0,0,4,0,0,0,4,0,0,0,8
8,0,0,0,0,0,11,0,4,0,0,0,8
8,0,0,0,4,0,0,0,4,0,0,0,8
7,0,0,0,7,4,4,4,7,0,0,0,7
8,0,0,0,0,0,0,0,0,0,0,0,8
8,0,0,0,0,0,0,0,0,0,0,0,8
8,0,0,0,0,5,5,5,9,0,0,0,8
7,8,8,8,7,8,8,8,7,8,8,8,7
endlayer

layer
7,8,8,8,7,8,8,8,7,8,8,8,7
8,0,0,5,5,5,9,0,0,0,0,0,8
8,0,0,0,0,0,0,0,0,0,0,0,8
8,0,0,0,0,0,0,0,0,0,0,0,8
7,0,0,0,7,4,4,4,7,0,0,0,7
8,0,0,0,4,0,0,0,4,0,0,0,8
8,0,0,0,4,0,0,0,4,0,0,0,8
8,0,0,0,4,0,0,0,4,0,0,0,8
7,0,0,0,7,4,4,4,7,0,0,0,7
8,0,0,0,0,0,0,0,0,0,0,0,8
8,0,0,0,0,0,0,0,0,0,0,0,8
8,0,0,5,5,5,9,0,0,0,0,0,8
7,8,8,8,7,8,8,8,7,8,8,8,7
endlayer

layer
12,8,8,8,12,8,8,8,12,8,8,8,12
8,0,5,5,9,0,0,0,0,0,0,0,8
8,0,0,0,0,0,0,0,0,0,0,0,8
8,0,0,0,0,0,0,0,0,0,0,0,8
12,0,0,0,12,4,4,4,12,0,0,0,12
8,0,0,0,4,0,0,0,4,0,0,0,8
8,0,0,0,4,0,0,0,4,0,0,0,8
8,0,0,0,4,0,0,0,4,0,0,0,8
12,0,0,0,12,4,4,4,12,0,0,0,12
8,0,0,0,0,0,0,0,0,0,0,0,8
8,0,0,0,0,0,0,0,0,0,0,0,8
8,0,5,5,9,0,0,0,0,0,0,0,8
12,8,8,8,12,8,8,8,12,8,8,8,12
endlayer

layer
4,4,4,4,4,4,4,4,4,4,4,4,4
4,4,9,0,0,0,0,0,0,0,0,4,4
4,4,4,4,4,4,4,4,4,4,4,4,4
4,4,4,4,4,4,4,4,4,4,4,4,4
4,4,4,4,4,4,4,4,4,4,4,4,4
4,4,4,4,4,4,4,4,4,4,4,4,4
4,4,4,4,4,4,4,4,4,4,4,4,4
4,4,4,4,4,4,4,4,4,4,4,4,4
4,4,4,4,4,4,4,4,4,4,4,4,4
4,4,4,4,4,4,4,4,4,4,4,4,4
4,4,4,4,4,4,4,4,4,4,4,4,4
4,4,9,0,0,0,0,0,0,0,0,4,4
4,4,4,4,4,4,4,4,4,4,4,4,4
endlayer

layer
0,0,0,0,0,0,0,0,0,0,0,0,0
0,0,0,0,0,0,0,0,0,0,0,0,0
0,0,12,12,12,12,12,12,12,12,12,0,0
0,0,12,5,5,5,5,5,5,5,12,0,0
0,0,12,5,5,5,5,5,5,5,12,0,0
0,0,12,5,5,5,5,5,5,5,12,0,0
0,0,12,5,5,5,5,5,5,5,12,0,0
0,0,12,5,5,5,5,5,5,5,12,0,0
0,0,12,5,5,5,5,5,5,5,12,0,0
0,0,12,5,5,5,5,5,5,5,12,0,0
0,0,12,12,12,12,12,12,12,12,12,0,0
0,0,0,0,0,0,0,0,0,0,0,0,0
0,0,0,0,0,0,0,0,0,0,0,0,0
endlayer

layer
0,0,0,0,0,0,0,0,0,0,0,0,0
0,0,0,0,0,0,0,0,0,0,0,0,0
0,0,0,0,0,0,0,0,0,0,0,0,0
0,0,0,13,0,13,0,13,0,13,0,0,0
0,0,0,0,0,0,0,0,0,0,0,0,0
0,0,0,13,0,0,0,0,0,13,0,0,0
0,0,0,0,0,0,0,0,0,0,0,0,0
0,0,0,13,0,0,0,0,0,13,0,0,0
0,0,0,0,0,0,0,0,0,0,0,0,0
0,0,0,13,0,13,0,13,0,13,0,0,0
0,0,0,0,0,0,0,0,0,0,0,0,0
0,0,0,0,0,0,0,0,0,0,0,0,0
0,0,0,0,0,0,0,0,0,0,0,0,0
endlayer

layer
0,0,0,0,0,0,0,0,0,0,0,0,0
0,0,0,0,0,0,0,0,0,0,0,0,0
0,0,0,0,0,0,0,0,0,0,0,0,0
0,0,0,13,0,13,0,13,0,13,0,0,0
0,0,0,0,0,0,0,0,0,0,0,0,0
0,0,0,13,0,0,0,0,0,13,0,0,0
0,0,0,0,0,0,0,0,0,0,0,0,0
0,0,0,13,0,0,0,0,0,13,0,0,0
0,0,0,0,0,0,0,0,0,0,0,0,0
0,0,0,13,0,13,0,13,0,13,0,0,0
0,0,0,0,0,0,0,0,0,0,0,0,0
0,0,0,0,0,0,0,0,0,0,0,0,0
0,0,0,0,0,0,0,0,0,0,0,0,0
endlayer

layer
0,0,0,0,0,0,0,0,0,0,0,0,0
0,0,0,0,0,0,0,0,0,0,0,0,0
0,0,0,0,0,0,0,0,0,0,0,0,0
0,0,0,13,0,13,0,13,0,13,0,0,0
0,0,0,0,0,0,0,0,0,0,0,0,0
0,0,0,13,0,0,0,0,0,13,0,0,0
0,0,0,0,0,0,0,0,0,0,0,0,0
0,0,0,13,0,0,0,0,0,13,0,0,0
0,0,0,0,0,0,0,0,0,0,0,0,0
0,0,0,13,0,13,0,13,0,13,0,0,0
0,0,0,0,0,0,0,0,0,0,0,0,0
0,0,0,0,0,0,0,0,0,0,0,0,0
0,0,0,0,0,0,0,0,0,0,0,0,0
endlayer

layer
0,0,0,0,0,0,0,0,0,0,0,0,0
0,0,0,0,0,0,0,0,0,0,0,0,0
0,0,0,0,0,0,0,0,0,0,0,0,0
0,0,0,13,0,13,0,13,0,13,0,0,0
0,0,0,0,0,0,0,0,0,0,0,0,0
0,0,0,13,0,0,0,0,0,13,0,0,0
0,0,0,0,0,0,0,0,0,0,0,0,0
0,0,0,13,0,0,0,0,0,13,0,0,0
0,0,0,0,0,0,0,0,0,0,0,0,0
0,0,0,13,0,13,0,13,0,13,0,0,0
0,0,0,0,0,0,0,0,0,0,0,0,0
0,0,0,0,0,0,0,0,0,0,0,0,0
0,0,0,0,0,0,0,0,0,0,0,0,0
endlayer

layer
0,0,0,0,0,0,0,0,0,0,0,0,0
0,0,0,0,0,0,0,0,0,0,0,0,0
0,0,12,12,12,12,12,12,12,12,12,0,0
0,0,12,5,5,5,5,5,5,5,12,0,0
0,0,12,5,5,5,5,5,5,5,12,0,0
0,0,12,5,5,5,5,5,5,5,12,0,0
0,0,12,5,5,5,5,5,5,5,12,0,0
0,0,12,5,5,5,5,5,5,5,12,0,0
0,0,12,5,5,5,5,5,5,5,12,0,0
0,0,12,5,5,5,5,5,5,5,12,0,0
0,0,12,12,12,12,12,12,12,12,12,0,0
0,0,0,0,0,0,0,0,0,0,0,0,0
0,0,0,0,0,0,0,0,0,0,0,0,0
endlayer

layer
0,0,0,0,0,0,0,0,0,0,0,0,0
0,0,0,0,0,0,0,0,0,0,0,0,0
0,0,0,0,0,0,0,0,0,0,0,0,0
0,0,9,9,9,9,9,9,9,9,9,0,0
0,0,5,5,5,5,5,5,5,5,5,0,0
0,0,14,5,5,5,5,5,5,5,14,0,0
0,0,14,5,5,5,5,5,5,5,14,0,0
0,0,14,5,5,5,5,5,5,5,14,0,0
0,0,5,5,5,5,5,5,5,5,5,0,0
0,0,9,9,9,9,9,9,9,9,9,0,0
0,0,0,0,0,0,0,0,0,0,0,0,0
0,0,0,0,0,0,0,0,0,0,0,0,0
0,0,0,0,0,0,0,0,0,0,0,0,0
endlayer

layer
0,0,0,0,0,0,0,0,0,0,0,0,0
0,0,0,0,0,0,0,0,0,0,0,0,0
0,0,0,0,0,0,0,0,0,0,0,0,0
0,0,0,0,0,0,0,0,0,0,0,0,0
0,0,0,0,0,0,0,0,0,0,0,0,0
0,0,9,9,9,9,9,9,9,9,9,0,0
0,0,5,5,5,5,5,5,5,5,5,0,0
0,0,9,9,9,9,9,9,9,9,9,0,0
0,0,0,0,0,0,0,0,0,0,0,0,0
0,0,0,0,0,0,0,0,0,0,0,0,0
0,0,0,0,0,0,0,0,0,0,0,0,0
0,0,0,0,0,0,0,0,0,0,0,0,0
0,0,0,0,0,0,0,0,0,0,0,0,0
endlayer

