# Sand Castle (Small)
# Created by Ruins mod version 16.0 Ingame Parser
# authoring Player: Jordan_Greywolf
# Created for MC 1.9: 24 May 2016
# Updated for MC 1.11: 10 Jan 2017
# Verified for MC 1.12: 8 Jul 2017
# Updated to MC 1.12.1: 9 Sep 2017

biomesToSpawnIn=beach,highlands_desert island,beaches,desert_island

weight=1
embed_into_distance=4

acceptable_target_blocks=sand

unacceptable_target_blocks=
dimensions=11,7,7
allowable_overhang=0
max_leveling=3
leveling_buffer=-1
preserve_water=0
preserve_lava=0
preserve_plants=1

rule1=0,100,minecraft:sandstone-0
rule2=0,100,minecraft:sand-0
rule3=0,100,preserveBlock
rule4=0,100,minecraft:sandstone_stairs-3
rule5=0,100,minecraft:sandstone_stairs-2
rule6=0,100,minecraft:stone_slab-1
rule7=0,100,minecraft:sandstone_stairs-1
rule8=0,100,minecraft:sandstone_stairs-0
rule9=0,100,minecraft:stone_slab-9

layer
1,1,1,1,1,1,1
1,1,1,1,1,1,1
1,1,1,1,1,1,1
1,1,1,1,1,1,1
1,1,1,1,1,1,1
1,1,1,1,1,1,1
1,1,1,1,1,1,1
endlayer

layer
1,1,1,1,1,1,1
1,1,1,1,1,1,1
1,1,1,1,1,1,1
1,1,1,1,1,1,1
1,1,1,1,1,1,1
1,1,1,1,1,1,1
1,1,1,1,1,1,1
endlayer

layer
1,1,1,1,1,1,1
1,1,1,1,1,1,1
1,1,1,1,1,1,1
1,1,1,1,1,1,1
1,1,1,1,1,1,1
1,1,1,1,1,1,1
1,1,1,1,1,1,1
endlayer

layer
1,1,1,1,1,1,1
1,1,1,1,1,1,1
1,1,1,1,1,1,1
1,1,1,1,1,1,1
1,1,1,1,1,1,1
1,1,1,1,1,1,1
1,1,1,1,1,1,1
endlayer


layer
2,2,2,2,2,2,2
2,3,3,3,3,3,2
2,3,2,2,2,3,2
3,3,3,3,2,3,2
2,3,2,2,2,3,2
2,3,3,3,3,3,2
2,2,2,2,2,2,2
endlayer

layer
2,2,2,2,2,2,2
2,3,3,3,3,3,2
2,3,2,2,2,3,2
3,3,3,3,2,3,2
2,3,2,2,2,3,2
2,3,3,3,3,3,2
2,2,2,2,2,2,2
endlayer

layer
2,5,4,6,5,4,2
7,0,0,0,0,0,7
8,0,2,2,2,0,8
6,0,1,0,2,0,6
7,0,2,2,2,0,7
8,0,0,0,0,0,8
2,5,4,6,5,4,2
endlayer

layer
2,0,0,0,0,0,2
0,0,0,0,0,0,0
0,0,4,8,8,0,0
0,0,4,9,5,0,0
0,0,7,7,5,0,0
0,0,0,0,0,0,0
2,0,0,0,0,0,2
endlayer

layer
2,0,0,0,0,0,2
0,0,0,0,0,0,0
0,0,0,0,0,0,0
0,0,0,2,0,0,0
0,0,0,0,0,0,0
0,0,0,0,0,0,0
2,0,0,0,0,0,2
endlayer

layer
0,0,0,0,0,0,0
0,0,0,0,0,0,0
0,0,0,0,0,0,0
0,0,0,2,0,0,0
0,0,0,0,0,0,0
0,0,0,0,0,0,0
0,0,0,0,0,0,0
endlayer

layer
0,0,0,0,0,0,0
0,0,0,0,0,0,0
0,0,0,0,0,0,0
0,0,0,2,0,0,0
0,0,0,0,0,0,0
0,0,0,0,0,0,0
0,0,0,0,0,0,0
endlayer

