# Bedrock Rail - Adjoining Structures
# Created by Ruins mod version 16.8 Ingame Parser
# authoring Player: Jordan_Greywolf

# Created for MC 1.12: 16 May 2018

# NOTE: This uses the JG_BedrockRail_1v*.tml template in a
# sequence to create a "bedrock express" rail tunnel.



biomesToSpawnIn=badlands,beach,beaches,boneyard,cold_beach,coral_reef,corrupted_sands,deadlands,dreadlands,deep_ocean,desert,fen,field,frozen_ocean,garden,glacier,gravel_beach,grassland,fungi_forest,hell,ice_flats,ice plains,ice wasteland,kelp_forest,lavender fields,lavender_fields,meadow,mesa,mining biome,miningbiome,mining_biome,moor,mutated_ice_flats,mutated_plains,mutated_savanna,ocean,outback,pasture,phantasmagoric_inferno,plains,prairie,river,spectral_garden,swampland,stone_beach,undergarden,visceral_heap,wasteland

weight=8
embed_into_distance=256

unacceptable_target_blocks=command_block

preventRotation=1

dimensions=13,5,24
allowable_overhang=0
max_cut_in=0
cut_in_buffer=0
max_leveling=24
leveling_buffer=-1
preserve_water=0
preserve_lava=0
preserve_plants=1

adjoining_template=plains/JG_BedrockRail_1v12;0;128;-24
adjoining_template=plains/JG_BedrockRail_1v12;0;128;24
adjoining_template=plains/JG_BedrockRail_1v12;0;128;-48
adjoining_template=plains/JG_BedrockRail_1v12;0;128;48
adjoining_template=plains/JG_BedrockRail_1v12;0;128;-72
adjoining_template=plains/JG_BedrockRail_1v12;0;128;72
adjoining_template=plains/JG_BedrockRail_1v12;0;128;-96
adjoining_template=plains/JG_BedrockRail_1v12;0;128;96
adjoining_template=plains/JG_BedrockRail_1v12;0;128;-120
adjoining_template=plains/JG_BedrockRail_1v12;0;128;120


rule1=0,100,preserveBlock

# Regular rail
rule2=0,100,minecraft:rail

# Golden/powered rail booster
rule3=0,100,minecraft:golden_rail-8

# Structural supports
rule4=0,100,minecraft:stonebrick,minecraft:stonebrick,minecraft:stonebrick,minecraft:stonebrick-1,minecraft:stonebrick-2

# Rail power
rule5=7,100,minecraft:redstone_torch-5

# Buttress
rule6=0,100,minecraft:cobblestone_wall,cobblestone_wall-1

# Foundation
rule7=0,100,minecraft:obsidian


# Foundation (obsidian and preserveBlock)
layer
7,1,1,1,7,1,1,1,7,1,1,1,7,1,1,1,7,1,1,1,7,1,1,1
7,1,1,1,7,1,1,1,7,1,1,1,7,1,1,1,7,1,1,1,7,1,1,1
7,7,7,7,7,7,7,7,7,7,7,7,7,7,7,7,7,7,7,7,7,7,7,7
7,1,1,1,7,1,1,1,7,1,1,1,7,1,1,1,7,1,1,1,7,1,1,1
7,1,1,1,7,1,1,1,7,1,1,1,7,1,1,1,7,1,1,1,7,1,1,1
endlayer

# Raised Bed (obsidian)
layer
7,0,0,0,7,0,0,0,7,0,0,0,7,0,0,0,7,0,0,0,7,0,0,0
7,0,0,0,7,0,0,0,7,0,0,0,7,0,0,0,7,0,0,0,7,0,0,0
7,7,7,7,7,7,7,7,7,7,7,7,7,7,7,7,7,7,7,7,7,7,7,7
7,0,0,0,7,0,0,0,7,0,0,0,7,0,0,0,7,0,0,0,7,0,0,0
7,0,0,0,7,0,0,0,7,0,0,0,7,0,0,0,7,0,0,0,7,0,0,0
endlayer


layer
4,0,0,0,4,0,0,0,4,0,0,0,4,0,0,0,4,0,0,0,4,0,0,0
5,0,0,0,5,0,0,0,5,0,0,0,5,0,0,0,5,0,0,0,5,0,0,0
3,2,2,2,3,2,2,2,3,2,2,2,3,2,2,2,3,2,2,2,3,2,2,2
5,0,0,0,5,0,0,0,5,0,0,0,5,0,0,0,5,0,0,0,5,0,0,0
4,0,0,0,4,0,0,0,4,0,0,0,4,0,0,0,4,0,0,0,4,0,0,0
endlayer

layer
4,0,0,0,4,0,0,0,4,0,0,0,4,0,0,0,4,0,0,0,4,0,0,0
0,0,0,0,0,0,0,0,0,0,0,0,0,0,0,0,0,0,0,0,0,0,0,0
0,0,0,0,0,0,0,0,0,0,0,0,0,0,0,0,0,0,0,0,0,0,0,0
0,0,0,0,0,0,0,0,0,0,0,0,0,0,0,0,0,0,0,0,0,0,0,0
4,0,0,0,4,0,0,0,4,0,0,0,4,0,0,0,4,0,0,0,4,0,0,0
endlayer

layer
4,0,0,0,4,0,0,0,4,0,0,0,4,0,0,0,4,0,0,0,4,0,0,0
0,0,0,0,0,0,0,0,0,0,0,0,0,0,0,0,0,0,0,0,0,0,0,0
0,0,0,0,0,0,0,0,0,0,0,0,0,0,0,0,0,0,0,0,0,0,0,0
0,0,0,0,0,0,0,0,0,0,0,0,0,0,0,0,0,0,0,0,0,0,0,0
4,0,0,0,4,0,0,0,4,0,0,0,4,0,0,0,4,0,0,0,4,0,0,0
endlayer

layer
4,0,0,0,4,0,0,0,4,0,0,0,4,0,0,0,4,0,0,0,4,0,0,0
0,0,0,0,0,0,0,0,0,0,0,0,0,0,0,0,0,0,0,0,0,0,0,0
0,0,0,0,0,0,0,0,0,0,0,0,0,0,0,0,0,0,0,0,0,0,0,0
0,0,0,0,0,0,0,0,0,0,0,0,0,0,0,0,0,0,0,0,0,0,0,0
4,0,0,0,4,0,0,0,4,0,0,0,4,0,0,0,4,0,0,0,4,0,0,0
endlayer

layer
4,0,0,0,4,0,0,0,4,0,0,0,4,0,0,0,4,0,0,0,4,0,0,0
0,0,0,0,0,0,0,0,0,0,0,0,0,0,0,0,0,0,0,0,0,0,0,0
0,0,0,0,0,0,0,0,0,0,0,0,0,0,0,0,0,0,0,0,0,0,0,0
0,0,0,0,0,0,0,0,0,0,0,0,0,0,0,0,0,0,0,0,0,0,0,0
4,0,0,0,4,0,0,0,4,0,0,0,4,0,0,0,4,0,0,0,4,0,0,0
endlayer

layer
4,0,0,0,4,0,0,0,4,0,0,0,4,0,0,0,4,0,0,0,4,0,0,0
0,0,0,0,0,0,0,0,0,0,0,0,0,0,0,0,0,0,0,0,0,0,0,0
0,0,0,0,0,0,0,0,0,0,0,0,0,0,0,0,0,0,0,0,0,0,0,0
0,0,0,0,0,0,0,0,0,0,0,0,0,0,0,0,0,0,0,0,0,0,0,0
4,0,0,0,4,0,0,0,4,0,0,0,4,0,0,0,4,0,0,0,4,0,0,0
endlayer

layer
4,0,0,0,4,0,0,0,4,0,0,0,4,0,0,0,4,0,0,0,4,0,0,0
0,0,0,0,0,0,0,0,0,0,0,0,0,0,0,0,0,0,0,0,0,0,0,0
0,0,0,0,0,0,0,0,0,0,0,0,0,0,0,0,0,0,0,0,0,0,0,0
0,0,0,0,0,0,0,0,0,0,0,0,0,0,0,0,0,0,0,0,0,0,0,0
4,0,0,0,4,0,0,0,4,0,0,0,4,0,0,0,4,0,0,0,4,0,0,0
endlayer

layer
4,0,0,0,4,0,0,0,4,0,0,0,4,0,0,0,4,0,0,0,4,0,0,0
0,0,0,0,0,0,0,0,0,0,0,0,0,0,0,0,0,0,0,0,0,0,0,0
0,0,0,0,0,0,0,0,0,0,0,0,0,0,0,0,0,0,0,0,0,0,0,0
0,0,0,0,0,0,0,0,0,0,0,0,0,0,0,0,0,0,0,0,0,0,0,0
4,0,0,0,4,0,0,0,4,0,0,0,4,0,0,0,4,0,0,0,4,0,0,0
endlayer

layer
4,6,0,6,4,6,0,6,4,6,0,6,4,6,0,6,4,6,0,6,4,6,0,6
6,0,0,0,6,0,0,0,6,0,0,0,6,0,0,0,6,0,0,0,6,0,0,0
0,0,0,0,0,0,0,0,0,0,0,0,0,0,0,0,0,0,0,0,0,0,0,0
6,0,0,0,6,0,0,0,6,0,0,0,6,0,0,0,6,0,0,0,6,0,0,0
4,6,0,6,4,6,0,6,4,6,0,6,4,6,0,6,4,6,0,6,4,6,0,6
endlayer

layer
4,4,6,4,4,4,6,4,4,4,6,4,4,4,6,4,4,4,6,4,4,4,6,4
4,0,0,0,4,0,0,0,4,0,0,0,4,0,0,0,4,0,0,0,4,0,0,0
6,0,0,0,6,0,0,0,6,0,0,0,6,0,0,0,6,0,0,0,6,0,0,0
4,0,0,0,4,0,0,0,4,0,0,0,4,0,0,0,4,0,0,0,4,0,0,0
4,4,6,4,4,4,6,4,4,4,6,4,4,4,6,4,4,4,6,4,4,4,6,4
endlayer

layer
4,4,4,4,4,4,4,4,4,4,4,4,4,4,4,4,4,4,4,4,4,4,4,4
4,6,6,6,4,6,6,6,4,6,6,6,4,6,6,6,4,6,6,6,4,6,6,6
4,6,6,6,4,6,6,6,4,6,6,6,4,6,6,6,4,6,6,6,4,6,6,6
4,6,6,6,4,6,6,6,4,6,6,6,4,6,6,6,4,6,6,6,4,6,6,6
4,4,4,4,4,4,4,4,4,4,4,4,4,4,4,4,4,4,4,4,4,4,4,4
endlayer


