# HorseBarn-p -- Fantasy Barn (intact, run-down)
# 27 Sep 2014 - Minecraft 1.7.10
# Created by Ruins mod version 13.8 Ingame Parser
# authoring Player: Jordan_Greywolf

# Updated for MC 1.8: 5 Mar 2016
# Updated for MC 1.9: 17 Apr 2016
# Updated for MC 1.10: 13 Sep 2016
# Updated to MC 1.11: 13 Jan 2017
# Verified for MC 1.12: 23 Jun 2017
# Updated to MC 1.12.1: 10 Sep 2017

# Last Updated: 24 Jun 2018

biomesToSpawnIn=birch forest,birch_forest,brushland,chaparral,field,flower field,flower_field,forest,foresthills,forest_hills,field,flower forest,lavender fields,lavender_fields,majestic meadow,meadow,meadow forest,mutated_forest,mutated_birch_forest,mutated_plains,outback,pasture,pasture meadow,plains,prairie,rwg_plains,scrubland,shrubland,sublime shrubland,sunflower plains,thick shrubland,thinned pasture

preventRotation=1
spawnMinDistance=500

weight=1
embed_into_distance=5

unacceptable_target_blocks=flowing_water,water,flowing_lava,lava,cloud,Natura:Cloud,slime_congealed,slime_dirt,slime_grass,command_block,planks,planks2,concrete,cobblestone,stonebrick,brick_block,glass,torch,oak_stairs,stone_stairs,brick_stairs,stone_brick_stairs,nether_brick_stairs,sandstone_stairs,spruce_stairs,birch_stairs,jungle_stairs,quartz_stairs,acacia_stairs,dark_oak_stairs,cobblestone_wall,stone_slab,double_stone_slab,stone_slab2,wooden_slab,double_wooden_slab,nether_brick,fence

dimensions=16,20,20
allowable_overhang=0
max_leveling=2
leveling_buffer=-1
preserve_water=0
preserve_lava=0
preserve_plants=1

# Terrain Buffering
rule1=0,100,preserveBlock

rule2=0,100,minecraft:grass-0
rule3=0,100,minecraft:grass-0

# Stone Walls (random cobblestone / mossy_cobblestone)
rule4=0,100,minecraft:mossy_cobblestone-0,minecraft:cobblestone-0

# Basement Floor
rule5=0,100,minecraft:stone-0

# Paved Steps / Corral Corner
rule6=0,100,minecraft:double_stone_slab-0

# Well & Springs
rule7=0,100,minecraft:flowing_water

# Mob Spawners
rule8=0,100,MobSpawner:Spider

# Cobwebs Everywhere!
rule9=0,100,minecraft:web-0

# Hay Bales
rule10=0,100,minecraft:hay_block-0

# Trapped Treasure Chest
rule11=0,100,IInventory;minecraft:trapped_chest;minecraft:wheat#10#0#0+minecraft:saddle#1#0#1+minecraft:hay_block#7#0#2+minecraft:iron_ingot#3#0#3+minecraft:web#7#0#4+minecraft:grass#4#0#5+minecraft:fence#4#0#6+minecraft:log#2#0#7+minecraft:mossy_cobblestone#6#0#8-2

rule12=0,100,minecraft:tnt-0,minecraft:tnt-1
rule13=0,100,minecraft:trapped_chest-2

rule14=0,100,minecraft:spruce_stairs-4
rule15=0,100,minecraft:spruce_stairs-3
rule16=0,100,minecraft:fence-0
rule17=0,100,minecraft:spruce_stairs-1

# Farm Animal Mob Spawner (doesn't necessarily actually work)
rule18=0,100,MobSpawner:Horse

# Redstone Torch to activate dispenser
rule19=1,100,minecraft:redstone_torch-5

rule20=0,100,minecraft:planks-1

# Horse Spawner
rule21=0,100,CommandBlock:RUINSTRIGGER /summon horse ~0 ~0 ~0 {Attributes:[{Name:generic.movementSpeed,Base:0.4}],PersistenceRequired:1,Health:200.0f}:@

rule22=0,100,minecraft:planks-0
rule23=0,100,minecraft:oak_stairs-0

# Randomized Cobblestone Wall
rule24=0,100,minecraft:cobblestone_wall-1,minecraft:cobblestone_wall-0

rule25=0,100,minecraft:oak_stairs-2
rule26=0,100,minecraft:oak_stairs-3

# Randomized Plants
rule27=0,100,minecraft:tallgrass-1,minecraft:tallgrass-1,minecraft:tallgrass-1,minecraft:tallgrass-1,minecraft:tallgrass-1,minecraft:yellow_flower,minecraft:red_flower-3,minecraft:red_flower-8

rule28=0,100,minecraft:oak_stairs-1
rule29=1,100,minecraft:fence_gate-0

# Note: Setting doors to rule "1" seems to make them less likely to
# "pop" when building spawns.
rule30=1,100,minecraft:spruce_door-2

rule31=1,100,minecraft:wooden_pressure_plate-0
rule32=1,100,minecraft:spruce_door-0
rule33=1,100,minecraft:fence_gate-3
rule34=1,100,minecraft:fence_gate-1

rule35=0,100,minecraft:log-0
rule36=2,100,minecraft:ladder-4
rule37=1,100,minecraft:spruce_door-9
rule38=1,100,minecraft:spruce_door-8

rule39=0,100,minecraft:wooden_slab-0
rule40=0,100,minecraft:oak_stairs-4
rule41=0,100,minecraft:log-8
rule42=0,100,minecraft:log-4
rule43=0,100,minecraft:wooden_slab-9
rule44=0,100,minecraft:oak_stairs-5
rule45=0,100,minecraft:wooden_slab-8
rule46=0,100,minecraft:oak_stairs-6
rule47=0,100,minecraft:oak_stairs-7

layer
1,1,1,3,4,4,4,4,4,4,4,4,4,4,4,4,3,2,1,1
1,1,2,3,4,5,5,5,5,5,5,5,5,5,5,4,3,3,2,1
1,1,3,3,4,5,5,5,5,5,5,5,5,5,5,4,3,3,2,1
1,2,3,3,4,5,5,5,5,5,5,5,5,5,5,4,3,3,2,1
1,2,3,3,4,5,5,5,5,5,5,5,5,5,5,4,3,3,2,1
1,3,3,3,4,5,5,5,5,5,5,5,5,5,5,4,3,3,3,2
2,3,3,3,4,4,4,4,4,4,4,4,4,4,4,4,3,3,3,3
2,3,3,3,5,5,5,5,5,5,5,5,5,5,5,4,3,3,3,3
3,3,3,3,4,5,5,5,5,5,5,5,5,5,5,4,3,3,3,3
3,3,3,3,4,5,5,5,5,5,5,5,5,5,5,4,3,3,3,3
3,3,3,3,4,5,5,5,5,5,5,5,5,5,5,4,3,3,3,3
2,3,3,3,4,5,5,5,5,5,5,5,5,5,5,4,3,3,3,2
2,3,3,3,4,5,5,5,5,5,5,5,5,5,5,4,3,3,3,2
1,3,3,3,4,4,4,5,5,5,5,5,5,5,5,4,3,3,2,1
1,2,3,3,4,4,4,5,5,5,5,5,5,5,5,4,3,3,2,1
1,2,3,3,4,4,4,4,4,4,4,4,4,4,4,4,3,2,2,1
1,2,3,3,3,3,3,3,3,3,3,3,3,3,3,3,3,2,1,1
1,1,3,3,3,3,3,3,3,3,3,3,3,3,3,3,2,2,1,1
1,1,2,3,3,3,3,3,3,3,3,3,3,3,3,3,2,2,1,1
1,1,1,2,2,2,3,3,3,3,3,3,3,2,2,2,2,1,1,1
endlayer

layer
1,1,1,2,6,4,4,4,4,4,4,4,4,4,4,6,2,1,1,1
1,1,1,3,4,3,3,3,3,3,3,3,3,4,7,4,3,2,1,1
1,1,2,3,4,3,3,3,3,3,3,3,3,4,7,4,3,2,1,1
1,1,3,3,4,3,3,3,3,3,3,3,3,4,4,4,3,2,1,1
1,1,3,3,4,3,3,3,3,3,3,3,3,3,3,4,3,3,1,1
1,2,3,3,4,3,3,3,3,3,3,3,3,3,3,4,3,3,2,1
1,2,3,3,4,4,4,4,4,4,4,4,4,4,4,4,3,3,3,2
1,3,3,3,4,8,0,0,10,10,10,9,9,9,8,4,3,3,3,2
2,3,3,3,4,10,0,0,0,0,0,0,0,0,0,4,3,3,3,2
3,3,3,3,4,10,9,0,4,0,0,4,0,0,9,4,3,3,3,2
2,3,3,3,12,11,0,0,0,0,0,0,0,0,0,4,3,3,3,2
1,3,3,3,12,13,0,0,0,0,0,0,0,0,9,4,3,3,3,1
1,2,3,3,4,10,9,0,4,0,0,4,0,0,0,4,3,3,2,1
1,2,3,3,4,10,10,9,0,0,0,0,0,9,14,4,3,2,1,1
1,1,3,3,4,10,10,10,9,0,0,9,9,0,15,4,3,2,1,1
1,1,3,3,4,4,4,4,4,4,4,4,4,4,4,4,3,1,1,1
1,1,2,3,3,3,3,3,3,3,3,3,3,3,3,3,2,1,1,1
1,1,2,3,3,3,3,3,3,3,3,3,3,3,3,2,1,1,1,1
1,1,1,2,2,2,3,3,3,3,3,3,3,3,2,2,1,1,1,1
1,1,1,1,1,1,2,2,3,3,3,2,2,1,1,1,1,1,1,1
endlayer

layer
1,1,1,1,6,4,4,4,4,4,4,4,4,4,4,6,1,1,1,1
1,1,1,3,4,3,3,3,3,3,3,3,3,4,7,4,2,1,1,1
1,1,1,3,4,3,3,3,3,3,3,3,3,4,7,4,2,1,1,1
1,1,2,3,4,3,3,3,3,3,3,3,3,4,4,4,2,1,1,1
1,1,3,3,4,3,3,3,3,3,3,3,3,3,3,4,3,2,1,1
1,1,3,3,4,3,3,3,3,7,7,3,3,3,3,4,3,2,1,1
1,1,3,3,4,4,4,4,4,4,4,4,4,4,4,4,3,3,2,1
1,2,3,3,4,0,16,0,0,0,0,0,0,16,9,4,3,3,2,1
1,3,3,3,4,0,0,0,0,0,0,0,0,0,0,4,3,3,2,1
2,3,3,3,4,9,0,0,4,0,0,4,0,0,0,4,3,3,3,1
1,3,3,3,4,9,0,0,0,0,0,0,0,0,0,4,3,3,3,1
1,2,3,3,4,9,0,0,0,0,0,0,0,0,9,4,3,3,2,1
1,1,3,3,4,9,0,0,4,0,0,4,0,0,14,4,3,2,1,1
1,1,3,3,4,10,9,0,0,0,0,0,0,0,17,4,3,1,1,1
1,1,3,3,4,10,10,9,0,0,0,0,0,0,0,4,3,1,1,1
1,1,2,3,4,4,4,4,4,4,4,4,4,4,4,4,3,1,1,1
1,1,1,3,3,3,3,3,3,3,3,3,3,3,3,3,1,1,1,1
1,1,1,2,2,3,3,3,3,3,3,3,3,3,2,1,1,1,1,1
1,1,1,1,1,1,2,3,3,3,3,2,2,2,1,1,1,1,1,1
1,1,1,1,1,1,1,1,2,2,2,1,1,1,1,1,1,1,1,1
endlayer

layer
1,1,1,1,6,4,4,4,4,4,4,4,4,4,4,6,1,1,1,1
1,1,1,2,4,3,3,3,3,3,3,3,3,4,7,4,1,1,1,1
1,1,1,3,4,3,3,3,3,3,3,3,3,4,7,4,1,1,1,1
1,1,1,3,4,3,3,3,3,3,3,3,3,4,4,4,1,1,1,1
1,1,2,3,4,3,3,3,3,3,3,3,3,3,3,4,2,1,1,1
1,1,3,3,4,3,3,3,3,18,3,3,3,3,3,4,3,1,1,1
1,1,3,3,4,4,4,4,4,4,4,4,4,4,4,4,3,2,1,1
1,1,3,3,4,0,19,0,9,9,0,0,0,19,9,4,3,2,1,1
1,2,3,3,4,0,0,0,9,0,0,9,0,0,9,4,3,2,1,1
1,3,3,3,4,9,0,9,4,9,9,4,9,0,0,4,3,3,2,1
1,3,3,3,4,9,0,0,0,0,0,9,0,0,9,4,3,3,2,1
1,1,3,3,4,9,0,0,0,9,9,0,0,0,14,4,3,2,1,1
1,1,3,3,4,9,0,0,4,0,0,4,0,0,17,4,3,1,1,1
1,1,3,3,4,9,0,0,0,0,0,0,0,0,0,4,3,1,1,1
1,1,2,3,4,10,9,0,0,0,0,0,0,0,0,4,3,1,1,1
1,1,1,3,4,4,4,4,4,4,4,4,4,4,4,4,3,1,1,1
1,1,1,2,3,3,3,3,3,3,3,3,3,3,3,3,1,1,1,1
1,1,1,1,1,2,3,3,3,3,3,3,3,2,1,1,1,1,1,1
1,1,1,1,1,1,1,2,2,3,2,1,1,1,1,1,1,1,1,1
1,1,1,1,1,1,1,1,1,1,1,1,1,1,1,1,1,1,1,1
endlayer

layer
1,1,1,1,6,4,4,4,4,4,4,4,4,4,4,6,1,1,1,1
1,1,1,1,4,2,2,2,2,2,2,2,2,4,7,4,1,1,1,1
1,1,1,2,4,2,2,2,2,2,2,2,2,4,7,4,1,1,1,1
1,1,1,2,4,2,2,2,2,2,2,2,2,4,4,4,1,1,1,1
1,1,1,2,4,2,2,2,2,2,2,2,2,2,2,4,1,1,1,1
1,1,2,2,4,2,2,2,2,2,2,2,2,2,2,4,2,1,1,1
1,1,2,2,4,4,4,4,4,4,4,4,4,4,4,4,2,1,1,1
1,1,2,2,4,20,20,20,20,20,20,20,20,20,20,4,2,1,1,1
1,1,2,2,4,20,20,20,20,20,20,20,20,20,20,4,2,1,1,1
1,2,2,2,4,20,20,20,4,20,20,4,20,20,20,4,2,2,1,1
1,2,2,6,6,20,20,20,20,20,20,20,20,20,20,6,6,2,1,1
1,1,2,6,6,20,20,20,20,20,20,20,20,20,17,6,6,1,1,1
1,1,2,2,4,20,20,20,20,20,20,20,20,20,0,4,2,1,1,1
1,1,2,2,4,20,20,20,20,20,20,20,20,20,0,4,2,1,1,1
1,1,1,2,4,20,20,20,20,20,20,20,20,20,0,4,2,1,1,1
1,1,1,2,7,4,4,4,4,4,4,4,4,4,4,7,2,1,1,1
1,1,1,1,2,2,2,2,2,2,2,2,2,2,2,2,1,1,1,1
1,1,1,1,1,1,2,2,2,2,2,2,2,1,1,1,1,1,1,1
1,1,1,1,1,1,1,1,1,2,1,1,1,1,1,1,1,1,1,1
1,1,1,1,1,1,1,1,1,1,1,1,1,1,1,1,1,1,1,1
endlayer

layer
1,1,1,1,4,24,24,24,24,24,24,24,24,22,23,22,1,1,1,1
1,1,1,0,24,27,27,27,27,27,27,27,27,26,7,25,0,1,1,1
1,1,0,27,24,27,27,27,27,27,27,27,27,26,7,25,0,1,1,1
1,1,0,27,24,27,27,27,27,27,27,27,27,22,28,22,0,1,1,1
1,1,0,27,24,27,27,27,27,27,27,27,27,27,27,24,0,0,1,1
1,0,27,27,24,27,27,0,27,27,27,27,27,27,27,29,27,0,1,1
1,0,27,27,4,0,0,0,4,30,30,4,0,0,0,4,27,0,1,1
1,0,27,27,4,0,21,0,4,31,31,4,0,21,0,4,27,0,1,1
0,0,27,27,4,0,0,0,4,32,32,4,0,0,0,4,27,0,1,1
0,27,27,24,4,16,34,16,4,0,0,4,16,33,16,4,24,27,0,1
0,27,27,0,0,0,0,0,0,0,0,0,0,0,0,0,0,27,0,1
0,0,27,0,0,0,0,0,0,0,0,0,0,0,0,0,0,0,0,1
1,0,27,24,4,16,33,16,35,0,0,35,0,16,0,4,24,0,1,1
1,0,27,27,4,0,0,0,16,10,10,0,0,16,0,4,27,0,1,1
1,1,0,27,4,0,0,0,16,10,10,0,36,16,0,4,27,0,1,1
1,1,0,27,4,4,4,4,4,4,4,4,4,4,4,4,27,0,1,1
1,1,0,0,27,27,27,27,27,27,27,27,27,27,27,27,0,1,1,1
1,1,1,0,0,0,27,27,27,27,27,27,27,0,0,0,1,1,1,1
1,1,1,1,1,0,0,0,0,27,0,0,0,1,1,1,1,1,1,1
1,1,1,1,1,1,1,1,1,0,1,1,1,1,1,1,1,1,1,1
endlayer

layer
1,1,1,0,4,0,0,0,0,0,0,0,0,16,0,16,0,1,1,1
1,1,0,0,0,0,0,0,0,0,0,0,0,0,0,0,0,0,1,1
1,0,0,0,0,0,0,0,0,0,0,0,0,0,0,0,0,0,0,1
0,0,0,0,0,0,0,0,0,0,0,0,0,16,0,16,0,0,0,1
0,0,0,0,0,0,0,0,0,0,0,0,0,0,0,0,0,0,0,1
0,0,0,0,0,0,0,0,0,0,0,0,0,0,0,0,0,0,0,1
0,0,0,0,35,0,0,0,35,38,37,35,0,0,0,35,0,0,0,1
0,0,0,0,22,0,0,0,16,0,0,16,0,0,0,22,0,0,0,1
0,0,0,0,16,0,0,0,16,37,38,16,0,0,0,16,0,0,0,0
0,0,0,0,35,0,0,0,35,0,0,35,0,0,0,35,0,0,0,0
0,0,0,0,0,0,0,0,0,0,0,0,0,0,0,0,0,0,0,0
0,0,0,0,0,0,0,0,0,0,0,0,0,0,0,0,0,0,0,0
0,0,0,0,35,0,0,0,35,0,0,35,0,0,0,35,0,0,0,0
0,0,0,0,16,0,0,0,0,0,0,0,0,0,0,16,0,0,0,1
0,0,0,0,22,0,0,0,0,0,0,0,36,0,0,22,0,0,0,1
1,0,0,0,35,22,16,22,35,16,16,35,22,16,22,35,0,0,0,1
1,0,0,0,0,0,0,0,0,0,0,0,0,0,0,0,0,0,1,1
1,1,0,0,0,0,0,0,0,0,0,0,0,0,0,0,0,1,1,1
1,1,0,0,0,0,0,0,0,0,0,0,0,0,0,0,0,1,1,1
1,1,1,1,0,0,0,0,0,0,0,0,0,1,1,1,1,1,1,1
endlayer

layer
1,1,0,0,4,0,0,0,0,0,0,0,0,39,39,39,0,0,1,1
1,0,0,0,0,0,0,0,0,0,0,0,0,39,40,39,0,0,0,1
0,0,0,0,0,0,0,0,0,0,0,0,0,39,28,39,0,0,0,1
0,0,0,0,0,0,0,0,0,0,0,0,0,39,39,39,0,0,0,0
0,0,0,0,0,0,0,0,0,0,0,0,0,0,0,0,0,0,0,0
0,0,0,0,0,0,0,0,0,0,0,0,0,0,0,0,0,0,0,0
0,0,0,0,35,0,0,0,35,9,9,35,0,0,0,35,0,0,0,0
0,0,0,0,22,0,0,0,16,0,0,16,0,0,0,22,0,0,0,0
0,0,0,0,22,0,0,0,16,0,0,16,0,0,0,22,0,0,0,0
0,0,0,0,35,9,0,9,35,9,9,35,9,0,9,35,0,0,0,0
0,0,0,0,0,0,0,0,9,0,0,0,0,0,0,9,0,0,0,0
0,0,0,0,0,0,0,0,9,0,0,0,0,0,0,9,0,0,0,0
0,0,0,0,35,9,0,9,35,9,0,35,0,0,0,35,0,0,0,0
0,0,0,0,22,0,0,0,0,0,0,0,0,0,0,22,0,0,0,0
0,0,0,0,22,9,0,9,9,0,0,9,36,0,9,22,0,0,0,0
0,0,0,0,35,22,22,22,35,22,22,35,22,22,22,35,0,0,0,0
0,0,0,0,0,0,0,0,0,0,0,0,0,0,0,0,0,0,0,1
0,0,0,0,0,0,0,0,0,0,0,0,0,0,0,0,0,0,1,1
1,0,0,0,0,0,0,0,0,0,0,0,0,0,0,0,0,0,1,1
1,1,0,0,0,0,0,0,0,0,0,0,0,0,0,0,0,1,1,1
endlayer

layer
1,0,0,0,24,0,0,0,0,0,0,0,0,0,0,0,0,0,0,1
0,0,0,0,0,0,0,0,0,0,0,0,0,0,0,0,0,0,0,0
0,0,0,0,0,0,0,0,0,0,0,0,0,0,0,0,0,0,0,0
0,0,0,0,0,0,0,0,0,0,0,0,0,0,0,0,0,0,0,0
0,0,0,0,0,0,0,0,0,0,0,0,0,0,0,0,0,0,0,0
0,0,0,0,0,0,0,0,0,0,0,0,0,0,0,0,0,0,0,0
0,0,0,0,35,41,41,41,35,41,41,35,41,41,41,35,0,0,0,0
0,0,0,0,42,43,43,43,42,43,43,42,43,43,43,42,0,0,0,0
0,0,0,0,42,43,43,43,42,43,43,42,43,43,43,42,0,0,0,0
0,0,0,43,35,41,41,41,35,41,41,35,41,41,41,35,43,0,0,0
0,0,0,43,42,43,42,0,42,0,9,42,0,42,43,42,43,0,0,0
0,0,0,43,42,43,42,9,42,9,0,42,9,42,43,42,43,0,0,0
0,0,0,43,35,41,41,41,8,41,41,8,41,41,41,35,43,0,0,0
0,0,0,0,42,43,43,43,42,43,43,42,43,43,43,42,0,0,0,0
0,0,0,0,42,43,43,43,42,43,43,42,36,43,43,42,0,0,0,0
0,0,0,0,35,41,41,41,35,41,41,35,41,41,41,35,0,0,0,0
0,0,0,0,0,0,0,0,0,0,0,0,0,0,0,0,0,0,0,0
0,0,0,0,0,0,0,0,0,0,0,0,0,0,0,0,0,0,0,1
0,0,0,0,0,0,0,0,0,0,0,0,0,0,0,0,0,0,0,1
1,0,0,0,0,0,0,0,0,0,0,0,0,0,0,0,0,0,1,1
endlayer

layer
0,0,0,0,0,0,0,0,0,0,0,0,0,0,0,0,0,0,0,0
0,0,0,0,0,0,0,0,0,0,0,0,0,0,0,0,0,0,0,0
0,0,0,0,0,0,0,0,0,0,0,0,0,0,0,0,0,0,0,0
0,0,0,0,0,0,0,0,0,0,0,0,0,0,0,0,0,0,0,0
0,0,0,0,0,0,0,0,0,0,0,0,0,0,0,0,0,0,0,0
0,0,0,23,23,23,23,23,23,23,23,23,23,23,23,23,23,0,0,0
0,0,0,22,22,22,22,22,22,22,22,22,22,22,22,22,22,0,0,0
0,0,0,0,22,10,10,10,10,10,10,10,10,10,10,22,0,0,0,0
0,0,0,0,22,10,10,0,0,0,0,0,0,10,10,22,0,0,0,0
0,0,0,0,35,0,0,0,35,0,0,35,0,0,10,35,0,0,0,0
0,0,0,0,0,0,0,0,0,0,0,0,0,0,0,0,0,0,0,0
0,0,0,0,0,0,0,0,0,0,0,0,0,0,0,0,0,0,0,0
0,0,0,0,35,0,0,0,35,0,0,35,0,0,0,35,0,0,0,0
0,0,0,0,22,10,10,0,0,0,0,0,0,10,10,22,0,0,0,0
0,0,0,0,22,10,10,10,10,10,10,10,0,10,10,22,0,0,0,0
0,0,0,22,22,22,22,22,22,22,22,22,22,22,22,22,22,0,0,0
0,0,0,28,28,28,28,28,28,28,28,28,28,28,28,28,28,0,0,0
0,0,0,0,0,0,0,0,0,0,0,0,0,0,0,0,0,0,0,0
0,0,0,0,0,0,0,0,0,0,0,0,0,0,0,0,0,0,0,1
0,0,0,0,0,0,0,0,0,0,0,0,0,0,0,0,0,0,0,1
endlayer

layer
0,0,0,0,0,0,0,0,0,0,0,0,0,0,0,0,0,0,0,0
0,0,0,0,0,0,0,0,0,0,0,0,0,0,0,0,0,0,0,0
0,0,0,0,0,0,0,0,0,0,0,0,0,0,0,0,0,0,0,0
0,0,0,0,0,0,0,0,0,0,0,0,0,0,0,0,0,0,0,0
0,0,0,0,0,0,0,0,0,0,0,0,0,0,0,0,0,0,0,0
0,0,0,0,0,0,0,0,0,0,0,0,0,0,0,0,0,0,0,0
0,0,0,22,22,22,22,22,22,22,22,22,22,22,22,22,22,0,0,0
0,0,0,0,22,10,10,10,10,10,10,10,10,10,10,22,0,0,0,0
0,0,0,0,22,10,0,0,9,0,0,9,0,0,10,22,0,0,0,0
0,0,0,0,35,0,0,0,35,0,0,35,0,0,0,35,0,0,0,0
0,0,0,0,0,0,0,0,9,0,0,9,0,0,0,0,0,0,0,0
0,0,0,0,0,0,0,0,9,0,0,9,0,0,0,0,0,0,0,0
0,0,0,0,35,0,0,0,35,0,0,35,0,0,0,35,0,0,0,0
0,0,0,0,22,10,0,0,0,0,0,0,0,0,10,22,0,0,0,0
0,0,0,0,22,10,10,10,10,10,10,10,0,10,10,22,0,0,0,0
0,0,0,22,22,22,22,22,22,22,22,22,22,22,22,22,22,0,0,0
0,0,0,0,0,0,0,0,0,0,0,0,0,0,0,0,0,0,0,0
0,0,0,0,0,0,0,0,0,0,0,0,0,0,0,0,0,0,0,0
0,0,0,0,0,0,0,0,0,0,0,0,0,0,0,0,0,0,0,0
0,0,0,0,0,0,0,0,0,0,0,0,0,0,0,0,0,0,0,1
endlayer

layer
0,0,0,0,0,0,0,0,0,0,0,0,0,0,0,0,0,0,0,0
0,0,0,0,0,0,0,0,0,0,0,0,0,0,0,0,0,0,0,0
0,0,0,0,0,0,0,0,0,0,0,0,0,0,0,0,0,0,0,0
0,0,0,0,0,0,0,0,0,0,0,0,0,0,0,0,0,0,0,0
0,0,0,0,0,0,0,0,0,0,0,0,0,0,0,0,0,0,0,0
0,0,0,0,0,0,0,0,0,0,0,0,0,0,0,0,0,0,0,0
0,0,0,23,23,23,23,23,23,23,23,23,23,23,23,23,23,0,0,0
0,0,0,44,42,44,44,44,42,44,44,42,44,44,44,42,44,0,0,0
0,0,0,0,42,9,0,0,42,0,0,42,0,0,0,42,0,0,0,0
0,0,0,0,35,0,0,0,35,0,0,35,0,0,0,35,0,0,0,0
0,0,0,0,42,0,0,0,42,0,0,42,0,0,0,42,0,0,0,0
0,0,0,0,42,0,0,0,42,0,0,42,0,0,0,42,0,0,0,0
0,0,0,0,35,0,0,0,35,0,0,35,0,0,0,35,0,0,0,0
0,0,0,0,42,9,0,0,42,0,9,42,0,0,0,42,0,0,0,0
0,0,0,40,42,40,40,40,42,40,40,42,40,40,40,42,40,0,0,0
0,0,0,28,28,28,28,28,28,28,28,28,28,28,28,28,28,0,0,0
0,0,0,0,0,0,0,0,0,0,0,0,0,0,0,0,0,0,0,0
0,0,0,0,0,0,0,0,0,0,0,0,0,0,0,0,0,0,0,0
0,0,0,0,0,0,0,0,0,0,0,0,0,0,0,0,0,0,0,0
0,0,0,0,0,0,0,0,0,0,0,0,0,0,0,0,0,0,0,0
endlayer

layer
0,0,0,0,0,0,0,0,0,0,0,0,0,0,0,0,0,0,0,0
0,0,0,0,0,0,0,0,0,0,0,0,0,0,0,0,0,0,0,0
0,0,0,0,0,0,0,0,0,0,0,0,0,0,0,0,0,0,0,0
0,0,0,0,0,0,0,0,0,0,0,0,0,0,0,0,0,0,0,0
0,0,0,0,0,0,0,0,0,0,0,0,0,0,0,0,0,0,0,0
0,0,0,0,0,0,0,0,0,0,0,0,0,0,0,0,0,0,0,0
0,0,0,0,0,0,0,0,0,0,0,0,0,0,0,0,0,0,0,0
0,0,0,23,23,23,23,23,23,23,23,23,23,23,23,23,23,0,0,0
0,0,0,44,22,44,44,44,44,44,44,44,44,44,44,22,44,0,0,0
0,0,0,0,35,9,0,0,35,9,9,35,9,0,9,35,0,0,0,0
0,0,0,0,9,0,0,0,9,0,0,9,0,0,0,9,0,0,0,0
0,0,0,0,0,0,0,0,9,0,0,9,0,0,0,9,0,0,0,0
0,0,0,0,35,0,0,0,35,9,9,35,0,9,9,35,0,0,0,0
0,0,0,40,22,40,40,40,40,40,40,40,40,40,40,22,40,0,0,0
0,0,0,28,28,28,28,28,28,28,28,28,28,28,28,28,28,0,0,0
0,0,0,0,0,0,0,0,0,0,0,0,0,0,0,0,0,0,0,0
0,0,0,0,0,0,0,0,0,0,0,0,0,0,0,0,0,0,0,0
0,0,0,0,0,0,0,0,0,0,0,0,0,0,0,0,0,0,0,0
0,0,0,0,0,0,0,0,0,0,0,0,0,0,0,0,0,0,0,0
0,0,0,0,0,0,0,0,0,0,0,0,0,0,0,0,0,0,0,0
endlayer

layer
0,0,0,0,0,0,0,0,0,0,0,0,0,0,0,0,0,0,0,0
0,0,0,0,0,0,0,0,0,0,0,0,0,0,0,0,0,0,0,0
0,0,0,0,0,0,0,0,0,0,0,0,0,0,0,0,0,0,0,0
0,0,0,0,0,0,0,0,0,0,0,0,0,0,0,0,0,0,0,0
0,0,0,0,0,0,0,0,0,0,0,0,0,0,0,0,0,0,0,0
0,0,0,0,0,0,0,0,0,0,0,0,0,0,0,0,0,0,0,0
0,0,0,0,0,0,0,0,0,0,0,0,0,0,0,0,0,0,0,0
0,0,0,0,0,0,0,0,0,0,0,0,0,0,0,0,0,0,0,0
0,0,0,39,39,39,39,39,39,39,39,39,39,39,39,39,39,0,0,0
0,0,0,22,22,22,22,22,22,22,22,22,22,22,22,22,22,0,0,0
0,0,0,45,45,45,45,45,45,0,0,45,45,45,45,45,45,0,0,0
0,0,0,45,45,45,45,45,45,0,0,45,45,45,45,45,45,0,0,0
0,0,0,22,22,22,22,22,22,22,22,22,22,22,22,22,22,0,0,0
0,0,0,39,39,39,39,39,39,39,39,39,39,39,39,39,39,0,0,0
0,0,0,0,0,0,0,0,0,0,0,0,0,0,0,0,0,0,0,0
0,0,0,0,0,0,0,0,0,0,0,0,0,0,0,0,0,0,0,0
0,0,0,0,0,0,0,0,0,0,0,0,0,0,0,0,0,0,0,0
0,0,0,0,0,0,0,0,0,0,0,0,0,0,0,0,0,0,0,0
0,0,0,0,0,0,0,0,0,0,0,0,0,0,0,0,0,0,0,0
0,0,0,0,0,0,0,0,0,0,0,0,0,0,0,0,0,0,0,0
endlayer

layer
0,0,0,0,0,0,0,0,0,0,0,0,0,0,0,0,0,0,0,0
0,0,0,0,0,0,0,0,0,0,0,0,0,0,0,0,0,0,0,0
0,0,0,0,0,0,0,0,0,0,0,0,0,0,0,0,0,0,0,0
0,0,0,0,0,0,0,0,0,0,0,0,0,0,0,0,0,0,0,0
0,0,0,0,0,0,0,0,0,0,0,0,0,0,0,0,0,0,0,0
0,0,0,0,0,0,0,0,0,0,0,0,0,0,0,0,0,0,0,0
0,0,0,0,0,0,0,0,0,0,0,0,0,0,0,0,0,0,0,0
0,0,0,0,0,0,0,0,0,0,0,0,0,0,0,0,0,0,0,0
0,0,0,0,0,0,0,0,0,0,0,0,0,0,0,0,0,0,0,0
0,0,0,0,0,0,0,0,16,16,16,16,0,0,0,0,0,0,0,0
0,0,0,22,39,39,39,39,39,0,0,39,39,39,39,39,22,0,0,0
0,0,0,22,39,39,39,39,39,0,0,39,39,39,39,39,22,0,0,0
0,0,0,0,0,0,0,0,16,16,16,16,0,0,0,0,0,0,0,0
0,0,0,0,0,0,0,0,0,0,0,0,0,0,0,0,0,0,0,0
0,0,0,0,0,0,0,0,0,0,0,0,0,0,0,0,0,0,0,0
0,0,0,0,0,0,0,0,0,0,0,0,0,0,0,0,0,0,0,0
0,0,0,0,0,0,0,0,0,0,0,0,0,0,0,0,0,0,0,0
0,0,0,0,0,0,0,0,0,0,0,0,0,0,0,0,0,0,0,0
0,0,0,0,0,0,0,0,0,0,0,0,0,0,0,0,0,0,0,0
0,0,0,0,0,0,0,0,0,0,0,0,0,0,0,0,0,0,0,0
endlayer

layer
0,0,0,0,0,0,0,0,0,0,0,0,0,0,0,0,0,0,0,0
0,0,0,0,0,0,0,0,0,0,0,0,0,0,0,0,0,0,0,0
0,0,0,0,0,0,0,0,0,0,0,0,0,0,0,0,0,0,0,0
0,0,0,0,0,0,0,0,0,0,0,0,0,0,0,0,0,0,0,0
0,0,0,0,0,0,0,0,0,0,0,0,0,0,0,0,0,0,0,0
0,0,0,0,0,0,0,0,0,0,0,0,0,0,0,0,0,0,0,0
0,0,0,0,0,0,0,0,0,0,0,0,0,0,0,0,0,0,0,0
0,0,0,0,0,0,0,0,0,0,0,0,0,0,0,0,0,0,0,0
0,0,0,0,0,0,0,0,0,0,0,0,0,0,0,0,0,0,0,0
0,0,0,0,0,0,0,0,39,39,39,39,0,0,0,0,0,0,0,0
0,0,47,25,0,0,0,0,39,22,22,39,0,0,0,0,26,46,0,0
0,0,47,25,0,0,0,0,39,22,22,39,0,0,0,0,26,46,0,0
0,0,0,0,0,0,0,0,39,39,39,39,0,0,0,0,0,0,0,0
0,0,0,0,0,0,0,0,0,0,0,0,0,0,0,0,0,0,0,0
0,0,0,0,0,0,0,0,0,0,0,0,0,0,0,0,0,0,0,0
0,0,0,0,0,0,0,0,0,0,0,0,0,0,0,0,0,0,0,0
0,0,0,0,0,0,0,0,0,0,0,0,0,0,0,0,0,0,0,0
0,0,0,0,0,0,0,0,0,0,0,0,0,0,0,0,0,0,0,0
0,0,0,0,0,0,0,0,0,0,0,0,0,0,0,0,0,0,0,0
0,0,0,0,0,0,0,0,0,0,0,0,0,0,0,0,0,0,0,0
endlayer

