
# Menhir_Fountain
# 11 Mar 2014; updated to MC 1.7.10, 10 Oct 2014
# Created by Ruins mod version 12.3 Ingame Parser
# authoring Player: Jordan_Greywolf
# Updated for MC 1.8: 22 Jul 2015
# Updated for MC 1.10: 13 Sep 2016
# Updated to MC 1.11: 13 Jan 2017
# Verified for MC 1.12: 23 Jun 2017
# Updated to MC 1.12.1: 10 Sep 2017

biomesToSpawnIn=birch forest,birch forest hills,birch forest hills m,birch forest m,extreme hills edge,flower forest,forest,foresthills,highlands,highlands center,oak savanna,oak_savanna,plains,roofed forest,roofed forest m,savanna,savanna m,savanna plateau,savanna plateau m,swampland,swampland m,bayou,quagmire,dead forest,dead_forest,ominous woods,thick ominous woods,magical forest,mystic grove,sacred springs,moor,fen,mountain,mining biome,mining_biome,birch_forest,birch_forest_hills,mutated_birch_forest,mutated_birch_forest_hills,smaller_extreme_hills,mutated_forest,roofed_forest,mutated_roofed_forest,mutated_savanna,savanna_rock,mutated_savanna_rock,mutated_swampland

weight=1
embed_into_distance=2

unacceptable_target_blocks=water,flowing_water,lava,flowing_lava,cloud,Natura:Cloud,slime_congealed,slime_dirt,slime_grass,command_block,planks,planks2,concrete,cobblestone,stonebrick,brick_block,glass,torch,oak_stairs,stone_stairs,brick_stairs,stone_brick_stairs,nether_brick_stairs,sandstone_stairs,spruce_stairs,birch_stairs,jungle_stairs,quartz_stairs,acacia_stairs,dark_oak_stairs,cobblestone_wall,stone_slab,double_stone_slab,stone_slab2,wooden_slab,double_wooden_slab,nether_brick,fence

dimensions=7,13,13
allowable_overhang=0
max_cut_in=0
cut_in_buffer=0
max_leveling=8
leveling_buffer=-1
preserve_water=0
preserve_lava=0
preserve_plants=1

rule1=0,100,preserveBlock

# Pave Stones (and dirt/gravel)
rule2=0,100,minecraft:stone-0,minecraft:double_stone_slab-0,minecraft:grass-0,minecraft:gravel-0,minecraft:clay,minecraft:stone_slab-0

# Decorative Circle
rule3=0,100,minecraft:stonebrick-3

# Fountain
rule4=0,100,minecraft:flowing_water

# Column
rule5=1,100,minecraft:cobblestone-0,minecraft:mossy_cobblestone-0

# Keystone
rule6=0,100,minecraft:mossy_cobblestone-0,minecraft:cobblestone-0,minecraft:gravel-0

layer
1,1,1,1,1,2,2,2,1,1,1,1,1
1,1,1,2,2,2,2,2,2,2,1,1,1
1,1,2,2,2,3,3,3,2,2,2,1,1
1,2,2,2,3,4,4,4,3,2,2,2,1
1,2,2,3,4,4,4,4,4,3,2,2,1
2,2,3,4,4,4,4,4,4,4,3,2,2
2,2,3,4,4,4,2,4,4,4,3,2,2
2,2,3,4,4,4,4,4,4,4,3,2,2
1,2,2,3,4,4,4,4,4,3,2,2,1
1,2,2,2,3,4,4,4,3,2,2,2,1
1,1,2,2,2,3,3,3,2,2,2,1,1
1,1,1,2,2,2,2,2,2,2,1,1,1
1,1,1,1,1,2,2,2,1,1,1,1,1
endlayer


layer
1,1,1,1,1,2,2,2,1,1,1,1,1
1,1,1,2,2,2,2,2,2,2,1,1,1
1,1,2,2,2,3,3,3,2,2,2,1,1
1,2,2,2,3,4,4,4,3,2,2,2,1
1,2,2,3,4,4,4,4,4,3,2,2,1
2,2,3,4,4,4,4,4,4,4,3,2,2
2,2,3,4,4,4,2,4,4,4,3,2,2
2,2,3,4,4,4,4,4,4,4,3,2,2
1,2,2,3,4,4,4,4,4,3,2,2,1
1,2,2,2,3,4,4,4,3,2,2,2,1
1,1,2,2,2,3,3,3,2,2,2,1,1
1,1,1,2,2,2,2,2,2,2,1,1,1
1,1,1,1,1,2,2,2,1,1,1,1,1
endlayer

layer
1,1,1,1,1,5,1,5,1,1,1,1,1
1,1,1,5,1,0,1,0,1,5,1,1,1
1,1,1,1,0,0,0,0,0,1,1,1,1
1,5,1,0,0,0,0,0,0,0,1,5,1
1,1,0,0,0,0,0,0,0,0,0,1,1
5,0,0,0,0,0,0,0,0,0,0,0,5
1,1,0,0,0,0,2,0,0,0,0,1,1
5,0,0,0,0,0,0,0,0,0,0,0,5
1,1,0,0,0,0,0,0,0,0,0,1,1
1,5,1,0,0,0,0,0,0,0,1,5,1
1,1,1,1,0,0,0,0,0,1,1,1,1
1,1,1,5,1,0,1,0,1,5,1,1,1
1,1,1,1,1,5,1,5,1,1,1,1,1
endlayer

layer
1,1,1,1,1,5,1,5,1,1,1,1,1
1,1,1,5,0,0,0,0,0,5,1,1,1
1,1,1,0,0,0,0,0,0,0,1,1,1
1,5,0,0,0,0,0,0,0,0,0,5,1
1,0,0,0,0,0,0,0,0,0,0,0,1
5,0,0,0,0,0,0,0,0,0,0,0,5
1,0,0,0,0,0,2,0,0,0,0,0,1
5,0,0,0,0,0,0,0,0,0,0,0,5
1,0,0,0,0,0,0,0,0,0,0,0,1
1,5,0,0,0,0,0,0,0,0,0,5,1
1,1,1,0,0,0,0,0,0,0,1,1,1
1,1,1,5,0,0,0,0,0,5,1,1,1
1,1,1,1,1,5,1,5,1,1,1,1,1
endlayer

layer
1,1,1,1,1,5,6,5,1,1,1,1,1
1,1,1,5,0,0,0,0,0,5,1,1,1
1,1,6,0,0,0,0,0,0,0,6,1,1
1,5,0,0,0,0,0,0,0,0,0,5,1
1,0,0,0,0,0,0,0,0,0,0,0,1
5,0,0,0,0,0,0,0,0,0,0,0,5
6,0,0,0,0,0,2,0,0,0,0,0,6
5,0,0,0,0,0,0,0,0,0,0,0,5
1,0,0,0,0,0,0,0,0,0,0,0,1
1,5,0,0,0,0,0,0,0,0,0,5,1
1,1,6,0,0,0,0,0,0,0,6,1,1
1,1,1,5,0,0,0,0,0,5,1,1,1
1,1,1,1,1,5,6,5,1,1,1,1,1
endlayer

layer
1,1,1,1,0,0,0,0,0,1,1,1,1
1,1,1,0,0,0,0,0,0,0,1,1,1
1,1,0,0,0,0,0,0,0,0,0,1,1
1,0,0,0,0,0,0,0,0,0,0,0,1
0,0,0,0,0,0,4,0,0,0,0,0,0
0,0,0,0,0,0,0,0,0,0,0,0,0
0,0,0,0,4,0,4,0,4,0,0,0,0
0,0,0,0,0,0,0,0,0,0,0,0,0
0,0,0,0,0,0,4,0,0,0,0,0,0
1,0,0,0,0,0,0,0,0,0,0,0,1
1,1,0,0,0,0,0,0,0,0,0,1,1
1,1,1,0,0,0,0,0,0,0,1,1,1
1,1,1,1,0,0,0,0,0,1,1,1,1
endlayer

layer
1,1,1,0,0,0,0,0,0,0,1,1,1
1,1,0,0,0,0,0,0,0,0,0,1,1
1,0,0,0,0,0,0,0,0,0,0,0,1
0,0,0,0,0,0,0,0,0,0,0,0,0
0,0,0,0,0,0,0,0,0,0,0,0,0
0,0,0,0,0,0,4,0,0,0,0,0,0
0,0,0,0,0,4,0,4,0,0,0,0,0
0,0,0,0,0,0,4,0,0,0,0,0,0
0,0,0,0,0,0,0,0,0,0,0,0,0
0,0,0,0,0,0,0,0,0,0,0,0,0
1,0,0,0,0,0,0,0,0,0,0,0,1
1,1,0,0,0,0,0,0,0,0,0,1,1
1,1,1,0,0,0,0,0,0,0,1,1,1
endlayer

