# Mage Tower #1 -- 2 Apr 2015
# MC 1.7.10
# Created by Ruins mod version 13.8 Ingame Parser
# authoring Player: Jordan_Greywolf

# Updated to MC 1.8: 23 Mar 2016
# Updated to MC 1.9: 29 Apr 2016
# Updated to MC 1.10: 13 Sep 2016
# Updated to MC 1.11: 13 Jan 2017
# Verified for MC 1.12: 23 Jun 2017
# Updated to MC 1.12.1: 10 Sep 2017

# Last Updated: 9 Jun 2018

biomesToSpawnIn=badlands,dreadlands,plains,sunflower plains,forest,birch forest,taiga,ominous woods,thick ominous woods,eerie,eldritch,tainted land,magical forest,meadow forest,mystic grove,dead forest,dead_forest,dead swamp,dead_swamp,moor,moors,bramble,brambles,oasis,garden,enchanted forest,enchanted_forest,enchanted woodland,seasonal forest,seasonal_forest,silkglades,rwg_plains,xeric shrubland,xeric_shrubland,mutated_plains,birch_forest

uniqueMinDistance=2000
spawnMinDistance=500

preventRotation=1

weight=1
embed_into_distance=11
acceptable_target_blocks=

unacceptable_target_blocks=water,flowing_water,lava,flowing_lava,cloud,Natura:Cloud,slime_congealed,slime_dirt,slime_grass,command_block,planks,planks2,concrete,cobblestone,stonebrick,brick_block,glass,torch,oak_stairs,stone_stairs,brick_stairs,stone_brick_stairs,nether_brick_stairs,sandstone_stairs,spruce_stairs,birch_stairs,jungle_stairs,quartz_stairs,acacia_stairs,dark_oak_stairs,cobblestone_wall,stone_slab,double_stone_slab,stone_slab2,wooden_slab,double_wooden_slab,nether_brick,fence

dimensions=48,19,19
allowable_overhang=0
max_leveling=4
leveling_buffer=-1
preserve_water=0
preserve_lava=0
preserve_plants=1

rule1=0,100,minecraft:stonebrick-0,minecraft:stonebrick-1,minecraft:stonebrick-2
rule2=0,100,minecraft:stonebrick-3
rule3=0,100,minecraft:double_stone_slab-0
rule4=0,100,minecraft:stone_brick_stairs-3
rule5=0,100,minecraft:stone_brick_stairs-2
rule6=0,100,ChestGenHook:chests/simple_dungeon:3-5
rule7=0,100,minecraft:stone_brick_stairs-1
rule8=0,100,minecraft:stone_brick_stairs-0
rule9=0,100,minecraft:stone_slab-8
rule10=0,100,ChestGenHook:chests/simple_dungeon:3-3
rule11=0,100,ChestGenHook:chests/simple_dungeon:3-2
rule12=0,100,minecraft:stone_slab-0
rule13=0,100,ChestGenHook:chests/simple_dungeon:3-4

# Clay Golem
rule14=0,100,CommandBlock:RUINSTRIGGER /setblock ~0 ~-1 ~0 mob_spawner 0 replace {EntityId:skeleton,SpawnData:{id:Zombie,AbsorptionAmount:10,HandItems:[{Count:1,id:stone_shovel,tag:{display:{Name:"Enchanted Trowel"},ench:[{id:16,lvl:2},{id:33,lvl:1},{id:19,lvl:2}]}},{}],ArmorItems:[{Count:1,id:leather_boots},{id:Count:1,leather_leggings},{Count:1,id:leather_chestplate},{Count:1,id:clay}],CustomName:"Clay Golem",Attributes:[{Name:generic.knockbackResistance,Base:1.0}],HandDropChances:[0.2F,0.0F],ArmorDropChances:[0.0F,0.0F,0.0F,0.5F],Silent:1}}:@

rule15=0,100,minecraft:stone_brick_stairs-7
rule16=0,100,minecraft:stone_brick_stairs-6
rule17=0,100,minecraft:stone_brick_stairs-5
rule18=0,100,minecraft:stone_brick_stairs-4
rule19=2,100,minecraft:torch-5
rule20=0,100,minecraft:stained_glass-4
rule21=0,100,minecraft:water-0
rule22=0,100,minecraft:fence-0
rule23=0,100,minecraft:oak_stairs-4
rule24=0,100,minecraft:oak_stairs-6
rule25=0,100,minecraft:oak_stairs-7
rule26=0,100,minecraft:oak_stairs-5
rule27=0,100,minecraft:oak_stairs-1
rule28=0,100,minecraft:cobblestone_wall-0
rule29=0,100,minecraft:oak_stairs-3
rule30=0,100,minecraft:oak_stairs-2
rule31=0,100,minecraft:oak_stairs-0
rule32=0,100,minecraft:log-5
rule33=0,100,minecraft:log-9
rule34=0,100,minecraft:log-1
rule35=0,100,minecraft:planks-0
rule36=0,100,minecraft:wooden_slab-5
rule37=0,100,minecraft:dark_oak_stairs-2
rule38=0,100,minecraft:dark_oak_stairs-7
rule39=0,100,minecraft:dark_oak_stairs-6
rule40=0,100,minecraft:dark_oak_stairs-3
rule41=0,100,minecraft:dark_oak_stairs-0
rule42=0,100,minecraft:dark_oak_stairs-5
rule43=0,100,minecraft:dark_oak_stairs-4
rule44=0,100,minecraft:dark_oak_stairs-1
rule45=0,100,minecraft:wooden_slab-13
rule46=0,100,minecraft:planks-5
rule47=0,100,minecraft:nether_brick_fence-0

rule48=0,100,CommandBlock:RUINSTRIGGER /testruin TP_WaterHall ~-8 ~-1 ~0 1:@
rule49=0,100,CommandBlock:RUINSTRIGGER /testruin TP_WaterHall ~0 ~-1 ~-8:@
rule50=0,100,CommandBlock:RUINSTRIGGER /testruin TP_WaterHall ~8 ~-1 ~0 1:@
rule51=0,100,CommandBlock:RUINSTRIGGER /testruin TP_WaterHall ~0 ~-1 ~8:@

rule52=0,100,CommandBlock:RUINSTRIGGER /testruin TP_Decor_BookVault ~-17 ~-2 ~0:@,CommandBlock:RUINSTRIGGER /testruin TP_Decor_ChestVault ~-17 ~-2 ~0:@,CommandBlock:RUINSTRIGGER /testruin TP_Decor_Fountain ~-17 ~0 ~0:@,CommandBlock:RUINSTRIGGER /testruin TP_Decor_Garden ~-17 ~-2 ~0:@,CommandBlock:RUINSTRIGGER /testruin TP_Decor_LavaVault ~-17 ~-2 ~0:@,CommandBlock:RUINSTRIGGER /testruin TP_Decor_MonsterVault ~-17 ~-2 ~0:@,CommandBlock:RUINSTRIGGER /testruin TP_Decor_SkullVault ~-17 ~-2 ~0:@,CommandBlock:RUINSTRIGGER /testruin TP_Decor_WaterVault ~-17 ~-2 ~0:@,CommandBlock:RUINSTRIGGER /testruin TP_Decor_Prisoner ~-17 ~-2 ~0:@

rule53=0,100,CommandBlock:RUINSTRIGGER /testruin TP_Decor_BookVault ~0 ~-2 ~-17:@,CommandBlock:RUINSTRIGGER /testruin TP_Decor_ChestVault ~0 ~-2 ~-17:@,CommandBlock:RUINSTRIGGER /testruin TP_Decor_Fountain ~0 ~0 ~-17:@,CommandBlock:RUINSTRIGGER /testruin TP_Decor_Garden ~0 ~-2 ~-17:@,CommandBlock:RUINSTRIGGER /testruin TP_Decor_LavaVault ~0 ~-2 ~-17:@,CommandBlock:RUINSTRIGGER /testruin TP_Decor_MonsterVault ~0 ~-2 ~-17:@,CommandBlock:RUINSTRIGGER /testruin TP_Decor_SkullVault ~0 ~-2 ~-17:@,CommandBlock:RUINSTRIGGER /testruin TP_Decor_WaterVault ~0 ~-2 ~-17:@

rule54=0,100,CommandBlock:RUINSTRIGGER /testruin TP_Decor_BookVault ~17 ~-2 ~0:@,CommandBlock:RUINSTRIGGER /testruin TP_Decor_ChestVault ~17 ~-2 ~0:@,CommandBlock:RUINSTRIGGER /testruin TP_Decor_Fountain ~17 ~0 ~0:@,CommandBlock:RUINSTRIGGER /testruin TP_Decor_Garden ~17 ~-2 ~0:@,CommandBlock:RUINSTRIGGER /testruin TP_Decor_LavaVault ~17 ~-2 ~0:@,CommandBlock:RUINSTRIGGER /testruin TP_Decor_MonsterVault ~17 ~-2 ~0:@,CommandBlock:RUINSTRIGGER /testruin TP_Decor_SkullVault ~17 ~-2 ~0:@,CommandBlock:RUINSTRIGGER /testruin TP_Decor_WaterVault ~17 ~-2 ~0:@,CommandBlock:RUINSTRIGGER /testruin TP_Decor_Prisoner ~17 ~-2 ~0:@

rule55=0,100,CommandBlock:RUINSTRIGGER /testruin TP_Decor_BookVault ~0 ~-2 ~17:@,CommandBlock:RUINSTRIGGER /testruin TP_Decor_ChestVault ~0 ~-2 ~17:@,CommandBlock:RUINSTRIGGER /testruin TP_Decor_Fountain ~0 ~0 ~17:@,CommandBlock:RUINSTRIGGER /testruin TP_Decor_Garden ~0 ~-2 ~17:@,CommandBlock:RUINSTRIGGER /testruin TP_Decor_LavaVault ~0 ~-2 ~17:@,CommandBlock:RUINSTRIGGER /testruin TP_Decor_MonsterVault ~0 ~-2 ~17:@,CommandBlock:RUINSTRIGGER /testruin TP_Decor_SkullVault ~0 ~-2 ~17:@,CommandBlock:RUINSTRIGGER /testruin TP_Decor_WaterVault ~0 ~-2 ~17:@


layer
1,1,1,1,1,1,1,1,1,1,1,1,1,1,1,1,1,1,1
1,2,1,1,1,2,1,1,1,2,1,1,1,2,1,1,1,2,1
1,1,3,3,3,1,3,3,3,1,3,3,3,1,3,3,3,1,1
1,1,3,3,3,1,3,3,3,3,3,3,3,1,3,3,3,1,1
1,1,3,3,3,1,3,3,3,1,3,3,3,1,3,3,3,1,1
1,2,1,1,1,2,1,1,1,2,1,1,1,2,1,1,1,2,1
1,1,3,3,3,1,3,3,3,1,3,3,3,1,3,3,3,1,1
1,1,3,3,3,1,3,1,1,1,1,1,3,1,3,3,3,1,1
1,1,3,3,3,1,3,1,3,3,3,1,3,1,3,3,3,1,1
1,2,1,3,1,2,1,1,3,1,3,1,1,2,1,3,1,2,1
1,1,3,3,3,1,3,1,3,3,3,1,3,1,3,3,3,1,1
1,1,3,3,3,1,3,1,1,1,1,1,3,1,3,3,3,1,1
1,1,3,3,3,1,3,3,3,1,3,3,3,1,3,3,3,1,1
1,2,1,1,1,2,1,1,1,2,1,1,1,2,1,1,1,2,1
1,1,3,3,3,1,3,3,3,1,3,3,3,1,3,3,3,1,1
1,1,3,3,3,1,3,3,3,3,3,3,3,1,3,3,3,1,1
1,1,3,3,3,1,3,3,3,1,3,3,3,1,3,3,3,1,1
1,2,1,1,1,2,1,1,1,2,1,1,1,2,1,1,1,2,1
1,1,1,1,1,1,1,1,1,1,1,1,1,1,1,1,1,1,1
endlayer

layer
1,1,5,22,4,1,5,22,4,1,5,22,4,1,5,22,4,1,1
1,1,0,48,0,0,0,0,0,6,0,0,0,0,0,48,0,1,1
7,0,0,0,0,0,0,0,0,0,0,0,0,0,0,0,0,0,7
22,51,0,0,0,0,0,0,0,0,0,0,0,0,0,0,0,49,22
8,0,0,0,0,0,0,0,0,0,0,0,0,0,0,0,0,0,8
1,0,0,0,0,0,0,0,0,0,0,0,0,0,0,0,0,0,1
7,0,0,0,0,0,0,0,0,0,0,0,0,0,0,0,0,0,7
22,0,0,0,0,0,0,1,5,0,4,1,0,0,0,0,0,0,22
8,0,0,0,0,0,0,7,0,0,9,7,0,0,0,0,0,0,8
1,11,0,0,0,0,0,0,0,1,3,0,0,0,0,0,0,10,1
7,0,0,0,0,0,0,8,0,0,12,8,0,0,0,0,0,0,7
22,0,0,0,0,0,0,1,5,0,4,1,0,0,0,0,0,0,22
8,0,0,0,0,0,0,0,0,0,0,0,0,0,0,0,0,0,8
1,0,0,0,0,0,0,0,0,0,0,0,0,0,0,0,0,0,1
7,0,0,0,0,0,0,0,0,0,0,0,0,0,0,0,0,0,7
22,51,0,0,0,0,0,0,0,0,0,0,0,0,0,0,0,49,22
8,0,0,0,0,0,0,0,0,0,0,0,0,0,0,0,0,0,8
1,1,0,50,0,0,0,0,0,13,0,0,0,0,0,50,0,1,1
1,1,5,22,4,1,5,22,4,1,5,22,4,1,5,22,4,1,1
endlayer

layer
1,1,22,22,22,1,22,22,22,1,22,22,22,1,22,22,22,1,1
1,14,0,52,0,0,0,0,0,0,0,0,0,0,0,52,0,14,1
22,0,0,0,0,0,0,0,0,0,0,0,0,0,0,0,0,0,22
22,55,0,0,0,0,0,0,0,0,0,0,0,0,0,0,0,53,22
22,0,0,0,0,0,0,0,0,0,0,0,0,0,0,0,0,0,22
1,0,0,0,0,0,0,0,0,0,0,0,0,0,0,0,0,0,1
22,0,0,0,0,0,0,0,0,0,0,0,0,0,0,0,0,0,22
22,0,0,0,0,0,0,1,0,0,0,1,0,0,0,0,0,0,22
22,0,0,0,0,0,0,0,9,3,12,0,0,0,0,0,0,0,22
1,0,0,0,0,0,0,0,0,1,0,0,0,0,0,0,0,0,1
22,0,0,0,0,0,0,0,0,0,0,0,0,0,0,0,0,0,22
22,0,0,0,0,0,0,1,0,0,0,1,0,0,0,0,0,0,22
22,0,0,0,0,0,0,0,0,0,0,0,0,0,0,0,0,0,22
1,0,0,0,0,0,0,0,0,0,0,0,0,0,0,0,0,0,1
22,0,0,0,0,0,0,0,0,0,0,0,0,0,0,0,0,0,22
22,55,0,0,0,0,0,0,0,0,0,0,0,0,0,0,0,53,22
22,0,0,0,0,0,0,0,0,0,0,0,0,0,0,0,0,0,22
1,14,0,54,0,0,0,0,0,0,0,0,0,0,0,54,0,14,1
1,1,22,22,22,1,22,22,22,1,22,22,22,1,22,22,22,1,1
endlayer

layer
1,1,22,22,22,1,22,22,22,1,22,22,22,1,22,22,22,1,1
1,0,0,0,0,0,0,0,0,0,0,0,0,0,0,0,0,0,1
22,0,0,0,0,0,0,0,0,0,0,0,0,0,0,0,0,0,22
22,0,0,0,0,0,0,0,0,0,0,0,0,0,0,0,0,0,22
22,0,0,0,0,0,0,0,0,0,0,0,0,0,0,0,0,0,22
1,0,0,0,0,0,0,0,0,0,0,0,0,0,0,0,0,0,1
22,0,0,0,0,0,0,0,0,0,0,0,0,0,0,0,0,0,22
22,0,0,0,0,0,0,1,0,0,0,1,0,0,0,0,0,0,22
22,0,0,0,0,0,0,0,12,0,0,0,0,0,0,0,0,0,22
1,0,0,0,0,0,0,0,3,1,0,0,0,0,0,0,0,0,1
22,0,0,0,0,0,0,0,9,0,0,0,0,0,0,0,0,0,22
22,0,0,0,0,0,0,1,0,0,0,1,0,0,0,0,0,0,22
22,0,0,0,0,0,0,0,0,0,0,0,0,0,0,0,0,0,22
1,0,0,0,0,0,0,0,0,0,0,0,0,0,0,0,0,0,1
22,0,0,0,0,0,0,0,0,0,0,0,0,0,0,0,0,0,22
22,0,0,0,0,0,0,0,0,0,0,0,0,0,0,0,0,0,22
22,0,0,0,0,0,0,0,0,0,0,0,0,0,0,0,0,0,22
1,0,0,0,0,0,0,0,0,0,0,0,0,0,0,0,0,0,1
1,1,22,22,22,1,22,22,22,1,22,22,22,1,22,22,22,1,1
endlayer

layer
1,1,22,22,22,1,22,22,22,1,22,22,22,1,22,22,22,1,1
1,0,0,0,0,0,0,0,0,0,0,0,0,0,0,0,0,0,1
22,0,0,0,0,0,0,0,0,0,0,0,0,0,0,0,0,0,22
22,0,0,0,0,0,0,0,0,0,0,0,0,0,0,0,0,0,22
22,0,0,0,0,0,0,0,0,0,0,0,0,0,0,0,0,0,22
1,0,0,0,0,0,0,0,0,0,0,0,0,0,0,0,0,0,1
22,0,0,0,0,0,0,0,0,0,0,0,0,0,0,0,0,0,22
22,0,0,0,0,0,0,1,0,0,0,1,0,0,0,0,0,0,22
22,0,0,0,0,0,0,0,0,0,0,0,0,0,0,0,0,0,22
1,0,0,0,0,0,0,0,0,1,0,0,0,0,0,0,0,0,1
22,0,0,0,0,0,0,0,12,3,9,0,0,0,0,0,0,0,22
22,0,0,0,0,0,0,1,0,0,0,1,0,0,0,0,0,0,22
22,0,0,0,0,0,0,0,0,0,0,0,0,0,0,0,0,0,22
1,0,0,0,0,0,0,0,0,0,0,0,0,0,0,0,0,0,1
22,0,0,0,0,0,0,0,0,0,0,0,0,0,0,0,0,0,22
22,0,0,0,0,0,0,0,0,0,0,0,0,0,0,0,0,0,22
22,0,0,0,0,0,0,0,0,0,0,0,0,0,0,0,0,0,22
1,0,0,0,0,0,0,0,0,0,0,0,0,0,0,0,0,0,1
1,1,22,22,22,1,22,22,22,1,22,22,22,1,22,22,22,1,1
endlayer

layer
1,1,16,22,15,1,16,22,15,1,16,22,15,1,16,22,15,1,1
1,0,0,0,0,0,0,0,0,0,0,0,0,0,0,0,0,0,1
17,0,0,0,0,0,0,0,0,0,0,0,0,0,0,0,0,0,17
22,0,0,0,0,0,0,0,0,0,0,0,0,0,0,0,0,0,22
18,0,0,0,0,0,0,0,0,0,0,0,0,0,0,0,0,0,18
1,0,0,0,0,0,0,0,0,0,0,0,0,0,0,0,0,0,1
17,0,0,0,0,0,0,0,0,0,0,0,0,0,0,0,0,0,17
22,0,0,0,0,0,0,1,16,0,15,1,0,0,0,0,0,0,22
18,0,0,0,0,0,0,17,0,0,9,17,0,0,0,0,0,0,18
1,0,0,0,0,0,0,0,0,1,3,0,0,0,0,0,0,0,1
17,0,0,0,0,0,0,18,0,0,12,18,0,0,0,0,0,0,17
22,0,0,0,0,0,0,1,16,0,15,1,0,0,0,0,0,0,22
18,0,0,0,0,0,0,0,0,0,0,0,0,0,0,0,0,0,18
1,0,0,0,0,0,0,0,0,0,0,0,0,0,0,0,0,0,1
17,0,0,0,0,0,0,0,0,0,0,0,0,0,0,0,0,0,17
22,0,0,0,0,0,0,0,0,0,0,0,0,0,0,0,0,0,22
18,0,0,0,0,0,0,0,0,0,0,0,0,0,0,0,0,0,18
1,0,0,0,0,0,0,0,0,0,0,0,0,0,0,0,0,0,1
1,1,16,22,15,1,16,22,15,1,16,22,15,1,16,22,15,1,1
endlayer

Upper Basement
layer
1,1,1,1,1,1,1,1,1,1,1,1,1,1,1,1,1,1,1
1,0,0,0,0,0,0,0,0,0,0,0,0,0,0,0,0,0,1
1,0,0,0,0,0,0,0,0,0,0,0,0,0,0,0,0,0,1
1,0,0,0,0,0,0,0,0,0,0,0,0,0,0,0,0,0,1
1,0,0,0,0,0,0,0,0,0,0,0,0,0,0,0,0,0,1
1,0,0,0,0,0,0,0,0,0,0,0,0,0,0,0,0,0,1
1,0,0,0,0,0,0,0,0,0,0,0,0,0,0,0,0,0,1
1,0,0,0,0,0,0,1,1,1,1,1,0,0,0,0,0,0,1
1,0,0,0,0,0,0,1,9,3,12,1,0,0,0,0,0,0,1
1,0,0,0,0,0,0,1,0,1,0,1,0,0,0,0,0,0,1
1,0,0,0,0,0,0,1,0,0,0,1,0,0,0,0,0,0,1
1,0,0,0,0,0,0,1,1,1,1,1,0,0,0,0,0,0,1
1,0,0,0,0,0,0,0,0,0,0,0,0,0,0,0,0,0,1
1,0,0,0,0,0,0,0,0,0,0,0,0,0,0,0,0,0,1
1,0,0,0,0,0,0,0,0,0,0,0,0,0,0,0,0,0,1
1,0,0,0,0,0,0,0,0,0,0,0,0,0,0,0,0,0,1
1,0,0,0,0,0,0,0,0,0,0,0,0,0,0,0,0,0,1
1,0,0,0,0,0,0,0,0,0,0,0,0,0,0,0,0,0,1
1,1,1,1,1,1,1,1,1,1,1,1,1,1,1,1,1,1,1
endlayer

layer
1,1,22,22,22,1,22,22,22,1,22,22,22,1,22,22,22,1,1
1,0,0,0,0,0,0,0,0,0,0,0,0,0,0,0,0,0,1
22,0,0,0,0,0,0,0,0,0,0,0,0,0,0,0,0,0,22
22,0,0,0,0,0,0,0,0,0,0,0,0,0,0,0,0,0,22
22,0,0,0,0,0,0,0,0,0,0,0,0,0,0,0,0,0,22
1,0,0,0,0,0,0,0,0,0,0,0,0,0,0,0,0,0,1
22,0,0,0,0,0,0,0,0,0,0,0,0,0,0,0,0,0,22
22,0,0,0,0,0,0,1,22,22,22,1,0,0,0,0,0,0,22
22,0,0,0,0,0,0,22,12,0,0,22,0,0,0,0,0,0,22
1,0,0,0,0,0,0,22,3,1,0,22,0,0,0,0,0,0,1
22,0,0,0,0,0,0,22,9,0,0,22,0,0,0,0,0,0,22
22,0,0,0,0,0,0,1,22,22,22,1,0,0,0,0,0,0,22
22,0,0,0,0,0,0,0,0,0,0,0,0,0,0,0,0,0,22
1,0,0,0,0,0,0,0,0,0,0,0,0,0,0,0,0,0,1
22,0,0,0,0,0,0,0,0,0,0,0,0,0,0,0,0,0,22
22,0,0,0,0,0,0,0,0,0,0,0,0,0,0,0,0,0,22
22,0,0,0,0,0,0,0,0,0,0,0,0,0,0,0,0,0,22
1,0,0,0,0,0,0,0,0,0,0,0,0,0,0,0,0,0,1
1,1,22,22,22,1,22,22,22,1,22,22,22,1,22,22,22,1,1
endlayer

layer
1,1,22,22,22,1,22,22,22,1,22,22,22,1,22,22,22,1,1
1,0,0,0,0,0,0,0,0,0,0,0,0,0,0,0,0,0,1
22,0,0,0,0,0,0,0,0,0,0,0,0,0,0,0,0,0,22
22,0,0,0,0,0,0,0,0,0,0,0,0,0,0,0,0,0,22
22,0,0,0,0,0,0,0,0,0,0,0,0,0,0,0,0,0,22
1,0,0,0,0,0,0,0,0,0,0,0,0,0,0,0,0,0,1
22,0,0,0,0,0,0,0,0,0,0,0,0,0,0,0,0,0,22
22,0,0,0,0,0,0,1,22,22,22,1,0,0,0,0,0,0,22
22,0,0,0,0,0,0,22,0,0,0,22,0,0,0,0,0,0,22
1,0,0,0,0,0,0,22,0,1,0,22,0,0,0,0,0,0,1
22,0,0,0,0,0,0,22,12,3,9,22,0,0,0,0,0,0,22
22,0,0,0,0,0,0,1,22,22,22,1,0,0,0,0,0,0,22
22,0,0,0,0,0,0,0,0,0,0,0,0,0,0,0,0,0,22
1,0,0,0,0,0,0,0,0,0,0,0,0,0,0,0,0,0,1
22,0,0,0,0,0,0,0,0,0,0,0,0,0,0,0,0,0,22
22,0,0,0,0,0,0,0,0,0,0,0,0,0,0,0,0,0,22
22,0,0,0,0,0,0,0,0,0,0,0,0,0,0,0,0,0,22
1,0,0,0,0,0,0,0,0,0,0,0,0,0,0,0,0,0,1
1,1,22,22,22,1,22,22,22,1,22,22,22,1,22,22,22,1,1
endlayer

layer
1,1,16,22,15,1,16,22,15,1,16,22,15,1,16,22,15,1,1
1,0,0,0,0,0,0,0,0,0,0,0,0,0,0,0,0,0,1
17,0,0,0,0,0,0,0,0,0,0,0,0,0,0,0,0,0,17
22,0,0,0,0,0,0,0,0,0,0,0,0,0,0,0,0,0,22
18,0,0,0,0,0,0,0,0,0,0,0,0,0,0,0,0,0,18
1,0,0,0,0,0,0,0,0,0,0,0,0,0,0,0,0,0,1
17,0,0,0,0,0,0,0,0,0,0,0,0,0,0,0,0,0,17
22,0,0,0,0,0,0,1,16,22,15,1,0,0,0,0,0,0,22
18,0,0,0,0,0,0,17,0,0,9,17,0,0,0,0,0,0,18
1,0,0,0,0,0,0,22,0,1,3,22,0,0,0,0,0,0,1
17,0,0,0,0,0,0,18,0,0,12,18,0,0,0,0,0,0,17
22,0,0,0,0,0,0,1,16,22,15,1,0,0,0,0,0,0,22
18,0,0,0,0,0,0,0,0,0,0,0,0,0,0,0,0,0,18
1,0,0,0,0,0,0,0,0,0,0,0,0,0,0,0,0,0,1
17,0,0,0,0,0,0,0,0,0,0,0,0,0,0,0,0,0,17
22,0,0,0,0,0,0,0,0,0,0,0,0,0,0,0,0,0,22
18,0,0,0,0,0,0,0,0,0,0,0,0,0,0,0,0,0,18
1,0,0,0,0,0,0,0,0,0,0,0,0,0,0,0,0,0,1
1,1,16,22,15,1,16,22,15,1,16,22,15,1,16,22,15,1,1
endlayer


layer
1,1,1,1,1,1,1,1,1,1,1,1,1,1,1,1,1,1,1
1,1,16,0,15,17,16,0,15,17,16,0,15,17,16,0,15,1,1
1,17,0,0,0,0,0,0,0,0,0,0,0,0,0,0,0,17,1
1,0,0,0,0,0,0,0,0,0,0,0,0,0,0,0,0,0,1
1,18,0,0,0,0,0,0,0,0,0,0,0,0,0,0,0,18,1
1,16,0,0,0,0,0,0,0,0,0,0,0,0,0,0,0,15,1
1,17,0,0,0,0,0,18,0,0,0,18,0,0,0,0,0,17,1
1,0,0,0,0,0,15,1,1,1,1,1,16,0,0,0,0,0,1
1,18,0,0,0,0,0,1,9,3,12,1,0,0,0,0,0,18,1
1,16,0,0,0,0,0,1,0,1,0,1,0,0,0,0,0,15,1
1,17,0,0,0,0,0,1,0,0,0,1,0,0,0,0,0,17,1
1,0,0,0,0,0,15,1,1,1,1,1,16,0,0,0,0,0,1
1,18,0,0,0,0,0,17,0,0,0,17,0,0,0,0,0,18,1
1,16,0,0,0,0,0,0,0,0,0,0,0,0,0,0,0,15,1
1,17,0,0,0,0,0,0,0,0,0,0,0,0,0,0,0,17,1
1,0,0,0,0,0,0,0,0,0,0,0,0,0,0,0,0,0,1
1,18,0,0,0,0,0,0,0,0,0,0,0,0,0,0,0,18,1
1,1,16,0,15,18,16,0,15,18,16,0,15,18,16,0,15,1,1
1,1,1,1,1,1,1,1,1,1,1,1,1,1,1,1,1,1,1
endlayer

layer
1,1,8,8,8,1,8,8,8,1,8,8,8,1,8,8,8,1,1
1,1,1,1,1,1,1,1,1,1,1,1,1,1,1,1,1,1,1
4,1,9,1,9,1,9,1,9,1,9,1,9,1,9,1,9,1,5
4,1,1,2,1,2,1,2,1,2,1,2,1,2,1,2,1,1,5
4,1,9,1,9,1,9,1,9,1,9,1,9,1,9,1,9,1,5
1,1,1,2,1,2,1,2,1,2,1,2,1,2,1,2,1,1,1
4,1,9,1,9,1,9,1,9,1,9,1,9,1,9,1,9,1,5
4,1,1,2,1,2,1,1,1,1,1,1,1,2,1,2,1,1,5
4,1,9,1,9,1,9,1,12,0,0,1,9,1,9,1,9,1,5
1,1,1,2,1,2,1,1,3,1,0,1,1,2,1,2,1,1,1
4,1,9,1,9,1,9,1,9,0,0,1,9,1,9,1,9,1,5
4,1,1,2,1,2,1,1,1,1,1,1,1,2,1,2,1,1,5
4,1,9,1,9,1,9,1,9,1,9,1,9,1,9,1,9,1,5
1,1,1,2,1,2,1,2,1,2,1,2,1,2,1,2,1,1,1
4,1,9,1,9,1,9,1,9,1,9,1,9,1,9,1,9,1,5
4,1,1,2,1,2,1,2,1,2,1,2,1,2,1,2,1,1,5
4,1,9,1,9,1,9,1,9,1,9,1,9,1,9,1,9,1,5
1,1,1,1,1,1,1,1,1,1,1,1,1,1,1,1,1,1,1
1,1,7,7,7,1,7,7,7,1,7,7,7,1,7,7,7,1,1
endlayer

layer
0,0,0,0,0,0,0,0,0,0,0,0,0,0,0,0,0,0,0
0,1,8,8,8,1,8,8,8,1,8,8,8,1,8,8,8,1,0
0,4,19,1,19,1,19,1,19,1,19,1,19,1,19,1,19,5,0
0,4,1,1,1,1,1,1,1,1,1,1,1,1,1,1,1,5,0
0,4,19,1,19,1,19,1,19,1,19,1,19,1,19,1,19,5,0
0,1,1,1,1,1,1,1,1,1,1,1,1,1,1,1,1,1,0
0,4,19,1,19,1,19,1,19,1,19,1,19,1,19,1,19,5,0
0,4,1,1,1,1,1,1,1,1,1,1,1,1,1,1,1,5,0
0,4,19,1,19,1,19,1,0,0,0,1,19,1,19,1,19,5,0
0,1,1,1,1,1,1,1,0,1,0,1,1,1,1,1,1,1,0
0,4,19,1,19,1,19,1,12,3,9,1,19,1,19,1,19,5,0
0,4,1,1,1,1,1,1,1,1,1,1,1,1,1,1,1,5,0
0,4,19,1,19,1,19,1,19,1,19,1,19,1,19,1,19,5,0
0,1,1,1,1,1,1,1,1,1,1,1,1,1,1,1,1,1,0
0,4,19,1,19,1,19,1,19,1,19,1,19,1,19,1,19,5,0
0,4,1,1,1,1,1,1,1,1,1,1,1,1,1,1,1,5,0
0,4,19,1,19,1,19,1,19,1,19,1,19,1,19,1,19,5,0
0,1,7,7,7,1,7,7,7,1,7,7,7,1,7,7,7,1,0
0,0,0,0,0,0,0,0,0,0,0,0,0,0,0,0,0,0,0
endlayer

layer
0,0,0,0,0,0,0,0,0,0,0,0,0,0,0,0,0,0,0
0,0,0,0,0,0,0,0,0,0,0,0,0,0,0,0,0,0,0
0,0,4,8,8,1,8,8,8,1,8,8,8,1,8,8,8,0,0
0,0,4,1,1,1,1,1,1,1,1,1,1,1,1,1,5,0,0
0,0,4,1,20,1,20,1,20,1,20,1,20,1,20,1,5,0,0
0,0,1,1,1,1,1,1,1,1,1,1,1,1,1,1,1,0,0
0,0,4,1,20,1,20,1,20,1,20,1,20,1,20,1,5,0,0
0,0,4,1,1,1,1,1,1,1,1,1,1,1,1,1,5,0,0
0,0,4,1,20,1,20,1,0,0,9,1,20,1,20,1,5,0,0
0,0,1,1,1,1,1,1,0,1,3,1,1,1,1,1,1,0,0
0,0,4,1,20,1,20,1,0,0,12,1,20,1,20,1,5,0,0
0,0,4,1,1,1,1,1,1,1,1,1,1,1,1,1,5,0,0
0,0,4,1,20,1,20,1,20,1,20,1,20,1,20,1,5,0,0
0,0,1,1,1,1,1,1,1,1,1,1,1,1,1,1,1,0,0
0,0,4,1,20,1,20,1,20,1,20,1,20,1,20,1,5,0,0
0,0,4,1,1,1,1,1,1,1,1,1,1,1,1,1,5,0,0
0,0,7,7,7,1,7,7,7,1,7,7,7,1,7,7,5,0,0
0,0,0,0,0,0,0,0,0,0,0,0,0,0,0,0,0,0,0
0,0,0,0,0,0,0,0,0,0,0,0,0,0,0,0,0,0,0
endlayer

layer
0,0,0,0,0,0,0,0,0,0,0,0,0,0,0,0,0,0,0
0,0,0,0,0,0,0,0,0,0,0,0,0,0,0,0,0,0,0
0,0,0,0,0,0,0,0,0,0,0,0,0,0,0,0,0,0,0
0,0,0,4,8,1,8,8,8,1,8,8,8,1,8,8,0,0,0
0,0,0,4,21,21,21,21,21,21,21,21,21,21,21,5,0,0,0
0,0,0,1,21,21,21,21,21,21,21,21,21,21,21,1,0,0,0
0,0,0,4,21,21,21,21,21,21,21,21,21,21,21,5,0,0,0
0,0,0,4,21,21,21,1,1,1,1,1,21,21,21,5,0,0,0
0,0,0,4,21,21,21,1,9,3,12,1,21,21,21,5,0,0,0
0,0,0,1,21,21,21,1,0,1,0,1,21,21,21,1,0,0,0
0,0,0,4,21,21,21,1,0,0,0,1,21,21,21,5,0,0,0
0,0,0,4,21,21,21,1,1,1,1,1,21,21,21,5,0,0,0
0,0,0,4,21,21,21,21,21,21,21,21,21,21,21,5,0,0,0
0,0,0,1,21,21,21,21,21,21,21,21,21,21,21,1,0,0,0
0,0,0,4,21,21,21,21,21,21,21,21,21,21,21,5,0,0,0
0,0,0,7,7,1,7,7,7,1,7,7,7,1,7,5,0,0,0
0,0,0,0,0,0,0,0,0,0,0,0,0,0,0,0,0,0,0
0,0,0,0,0,0,0,0,0,0,0,0,0,0,0,0,0,0,0
0,0,0,0,0,0,0,0,0,0,0,0,0,0,0,0,0,0,0
endlayer

layer
0,0,0,0,0,0,0,0,0,0,0,0,0,0,0,0,0,0,0
0,0,0,0,0,0,0,0,0,0,0,0,0,0,0,0,0,0,0
0,0,0,0,0,0,0,0,0,0,0,0,0,0,0,0,0,0,0
0,0,0,0,0,0,0,0,0,0,0,0,0,0,0,0,0,0,0
0,0,0,0,0,0,0,0,0,0,0,0,0,0,0,0,0,0,0
0,0,0,0,0,0,0,0,0,0,0,0,0,0,0,0,0,0,0
0,0,0,0,0,0,0,0,0,0,0,0,0,0,0,0,0,0,0
0,0,0,0,0,0,0,2,1,0,1,2,0,0,0,0,0,0,0
0,0,0,0,0,0,0,1,12,0,0,1,0,0,0,0,0,0,0
0,0,0,0,0,0,0,1,3,1,0,1,0,0,0,0,0,0,0
0,0,0,0,0,0,0,1,9,0,0,1,0,0,0,0,0,0,0
0,0,0,0,0,0,0,2,1,1,1,2,0,0,0,0,0,0,0
0,0,0,0,0,0,0,0,0,0,0,0,0,0,0,0,0,0,0
0,0,0,0,0,0,0,0,0,0,0,0,0,0,0,0,0,0,0
0,0,0,0,0,0,0,0,0,0,0,0,0,0,0,0,0,0,0
0,0,0,0,0,0,0,0,0,0,0,0,0,0,0,0,0,0,0
0,0,0,0,0,0,0,0,0,0,0,0,0,0,0,0,0,0,0
0,0,0,0,0,0,0,0,0,0,0,0,0,0,0,0,0,0,0
0,0,0,0,0,0,0,0,0,0,0,0,0,0,0,0,0,0,0
endlayer

layer
0,0,0,0,0,0,0,0,0,0,0,0,0,0,0,0,0,0,0
0,0,0,0,0,0,0,0,0,0,0,0,0,0,0,0,0,0,0
0,0,0,0,0,0,0,0,0,0,0,0,0,0,0,0,0,0,0
0,0,0,0,0,0,0,0,0,0,0,0,0,0,0,0,0,0,0
0,0,0,0,0,0,0,0,0,0,0,0,0,0,0,0,0,0,0
0,0,0,0,0,0,0,0,0,0,0,0,0,0,0,0,0,0,0
0,0,0,0,0,0,0,0,0,0,0,0,0,0,0,0,0,0,0
0,0,0,0,0,0,0,2,1,0,1,2,0,0,0,0,0,0,0
0,0,0,0,0,0,0,1,0,0,0,1,0,0,0,0,0,0,0
0,0,0,0,0,0,0,22,0,1,0,22,0,0,0,0,0,0,0
0,0,0,0,0,0,0,1,12,3,9,1,0,0,0,0,0,0,0
0,0,0,0,0,0,0,2,1,22,1,2,0,0,0,0,0,0,0
0,0,0,0,0,0,0,0,0,0,0,0,0,0,0,0,0,0,0
0,0,0,0,0,0,0,0,0,0,0,0,0,0,0,0,0,0,0
0,0,0,0,0,0,0,0,0,0,0,0,0,0,0,0,0,0,0
0,0,0,0,0,0,0,0,0,0,0,0,0,0,0,0,0,0,0
0,0,0,0,0,0,0,0,0,0,0,0,0,0,0,0,0,0,0
0,0,0,0,0,0,0,0,0,0,0,0,0,0,0,0,0,0,0
0,0,0,0,0,0,0,0,0,0,0,0,0,0,0,0,0,0,0
endlayer

layer
0,0,0,0,0,0,0,0,0,0,0,0,0,0,0,0,0,0,0
0,0,0,0,0,0,0,0,0,0,0,0,0,0,0,0,0,0,0
0,0,0,0,0,0,0,0,0,0,0,0,0,0,0,0,0,0,0
0,0,0,0,0,0,0,0,0,0,0,0,0,0,0,0,0,0,0
0,0,0,0,0,0,0,0,0,0,0,0,0,0,0,0,0,0,0
0,0,0,0,0,0,0,0,0,0,0,0,0,0,0,0,0,0,0
0,0,0,0,0,0,0,0,0,0,0,0,0,0,0,0,0,0,0
0,0,0,0,0,0,0,2,1,1,1,2,0,0,0,0,0,0,0
0,0,0,0,0,0,0,1,0,0,9,1,0,0,0,0,0,0,0
0,0,0,0,0,0,0,22,0,1,3,22,0,0,0,0,0,0,0
0,0,0,0,0,0,0,1,0,0,12,1,0,0,0,0,0,0,0
0,0,0,0,0,0,0,2,1,22,1,2,0,0,0,0,0,0,0
0,0,0,0,0,0,0,0,0,0,0,0,0,0,0,0,0,0,0
0,0,0,0,0,0,0,0,0,0,0,0,0,0,0,0,0,0,0
0,0,0,0,0,0,0,0,0,0,0,0,0,0,0,0,0,0,0
0,0,0,0,0,0,0,0,0,0,0,0,0,0,0,0,0,0,0
0,0,0,0,0,0,0,0,0,0,0,0,0,0,0,0,0,0,0
0,0,0,0,0,0,0,0,0,0,0,0,0,0,0,0,0,0,0
0,0,0,0,0,0,0,0,0,0,0,0,0,0,0,0,0,0,0
endlayer

layer
0,0,0,0,0,0,0,0,0,0,0,0,0,0,0,0,0,0,0
0,0,0,0,0,0,0,0,0,0,0,0,0,0,0,0,0,0,0
0,0,0,0,0,0,0,0,0,0,0,0,0,0,0,0,0,0,0
0,0,0,0,0,0,0,0,0,0,0,0,0,0,0,0,0,0,0
0,0,0,0,0,0,0,0,0,0,0,0,0,0,0,0,0,0,0
0,0,0,0,0,0,0,0,0,0,0,0,0,0,0,0,0,0,0
0,0,0,0,0,0,0,18,0,0,0,18,0,0,0,0,0,0,0
0,0,0,0,0,0,15,1,1,1,1,1,16,0,0,0,0,0,0
0,0,0,0,0,0,0,1,9,3,12,1,0,0,0,0,0,0,0
0,0,0,0,0,0,0,1,0,1,0,1,0,0,0,0,0,0,0
0,0,0,0,0,0,0,1,0,0,0,1,0,0,0,0,0,0,0
0,0,0,0,0,0,15,1,1,1,1,1,16,0,0,0,0,0,0
0,0,0,0,0,0,0,17,0,0,0,17,0,0,0,0,0,0,0
0,0,0,0,0,0,0,0,0,0,0,0,0,0,0,0,0,0,0
0,0,0,0,0,0,0,0,0,0,0,0,0,0,0,0,0,0,0
0,0,0,0,0,0,0,0,0,0,0,0,0,0,0,0,0,0,0
0,0,0,0,0,0,0,0,0,0,0,0,0,0,0,0,0,0,0
0,0,0,0,0,0,0,0,0,0,0,0,0,0,0,0,0,0,0
0,0,0,0,0,0,0,0,0,0,0,0,0,0,0,0,0,0,0
endlayer

layer
0,0,0,0,0,0,0,0,0,0,0,0,0,0,0,0,0,0,0
0,0,0,0,0,0,0,0,0,0,0,0,0,0,0,0,0,0,0
0,0,0,0,0,0,0,0,0,0,0,0,0,0,0,0,0,0,0
0,0,0,0,0,0,0,0,0,0,0,0,0,0,0,0,0,0,0
0,0,0,0,0,0,0,0,0,0,0,0,0,0,0,0,0,0,0
0,0,0,0,0,0,0,0,0,0,0,0,0,0,0,0,0,0,0
0,0,0,0,0,0,1,1,1,1,1,1,1,0,0,0,0,0,0
0,0,0,0,0,0,1,5,7,7,7,7,1,0,0,0,0,0,0
0,0,0,0,0,0,1,5,12,0,0,4,1,0,0,0,0,0,0
0,0,0,0,0,0,1,5,3,1,0,4,1,0,0,0,0,0,0
0,0,0,0,0,0,1,5,9,0,0,4,1,0,0,0,0,0,0
0,0,0,0,0,0,1,8,8,8,8,4,1,0,0,0,0,0,0
0,0,0,0,0,0,1,1,1,1,1,1,1,0,0,0,0,0,0
0,0,0,0,0,0,0,0,0,0,0,0,0,0,0,0,0,0,0
0,0,0,0,0,0,0,0,0,0,0,0,0,0,0,0,0,0,0
0,0,0,0,0,0,0,0,0,0,0,0,0,0,0,0,0,0,0
0,0,0,0,0,0,0,0,0,0,0,0,0,0,0,0,0,0,0
0,0,0,0,0,0,0,0,0,0,0,0,0,0,0,0,0,0,0
0,0,0,0,0,0,0,0,0,0,0,0,0,0,0,0,0,0,0
endlayer

layer
0,0,0,0,0,0,0,0,0,0,0,0,0,0,0,0,0,0,0
0,0,0,0,0,0,0,0,0,0,0,0,0,0,0,0,0,0,0
0,0,0,0,0,0,0,0,0,0,0,0,0,0,0,0,0,0,0
0,0,0,0,0,0,0,0,0,0,0,0,0,0,0,0,0,0,0
0,0,0,0,0,0,0,0,0,0,0,0,0,0,0,0,0,0,0
0,0,0,0,0,0,0,23,0,0,0,23,0,0,0,0,0,0,0
0,0,0,0,0,0,2,1,1,1,1,1,2,0,0,0,0,0,0
0,0,0,0,0,25,1,0,0,0,0,0,1,24,0,0,0,0,0
0,0,0,0,0,0,1,0,0,0,0,0,1,0,0,0,0,0,0
0,0,0,0,0,0,1,0,0,1,0,0,1,0,0,0,0,0,0
0,0,0,0,0,0,1,0,12,3,9,0,1,0,0,0,0,0,0
0,0,0,0,0,25,1,0,0,0,0,0,1,24,0,0,0,0,0
0,0,0,0,0,0,2,1,1,1,1,1,2,0,0,0,0,0,0
0,0,0,0,0,0,0,26,0,0,0,26,0,0,0,0,0,0,0
0,0,0,0,0,0,0,0,0,0,0,0,0,0,0,0,0,0,0
0,0,0,0,0,0,0,0,0,0,0,0,0,0,0,0,0,0,0
0,0,0,0,0,0,0,0,0,0,0,0,0,0,0,0,0,0,0
0,0,0,0,0,0,0,0,0,0,0,0,0,0,0,0,0,0,0
0,0,0,0,0,0,0,0,0,0,0,0,0,0,0,0,0,0,0
endlayer

layer
0,0,0,0,0,0,0,0,0,0,0,0,0,0,0,0,0,0,0
0,0,0,0,0,0,0,0,0,0,0,0,0,0,0,0,0,0,0
0,0,0,0,0,0,0,0,0,0,0,0,0,0,0,0,0,0,0
0,0,0,0,0,0,0,0,0,0,0,0,0,0,0,0,0,0,0
0,0,0,0,0,0,0,23,0,0,0,23,0,0,0,0,0,0,0
0,0,0,0,0,0,0,27,0,0,0,27,0,0,0,0,0,0,0
0,0,0,0,0,0,2,1,0,28,0,1,2,0,0,0,0,0,0
0,0,0,0,25,30,1,0,0,0,0,0,1,29,24,0,0,0,0
0,0,0,0,0,0,0,0,0,0,9,0,0,0,0,0,0,0,0
0,0,0,0,0,0,28,0,0,1,3,0,28,0,0,0,0,0,0
0,0,0,0,0,0,0,0,0,0,12,0,0,0,0,0,0,0,0
0,0,0,0,25,30,1,0,0,0,0,0,1,29,24,0,0,0,0
0,0,0,0,0,0,2,1,0,28,0,1,2,0,0,0,0,0,0
0,0,0,0,0,0,0,31,0,0,0,31,0,0,0,0,0,0,0
0,0,0,0,0,0,0,26,0,0,0,26,0,0,0,0,0,0,0
0,0,0,0,0,0,0,0,0,0,0,0,0,0,0,0,0,0,0
0,0,0,0,0,0,0,0,0,0,0,0,0,0,0,0,0,0,0
0,0,0,0,0,0,0,0,0,0,0,0,0,0,0,0,0,0,0
0,0,0,0,0,0,0,0,0,0,0,0,0,0,0,0,0,0,0
endlayer

layer
0,0,0,0,0,0,0,0,0,0,0,0,0,0,0,0,0,0,0
0,0,0,0,0,0,0,0,0,0,0,0,0,0,0,0,0,0,0
0,0,0,0,0,0,0,0,0,0,0,0,0,0,0,0,0,0,0
0,0,0,0,0,0,0,23,0,0,0,23,0,0,0,0,0,0,0
0,0,0,0,0,0,0,27,0,0,0,27,0,0,0,0,0,0,0
0,0,0,0,0,0,0,0,0,0,0,0,0,0,0,0,0,0,0
0,0,0,0,0,0,2,1,16,28,15,1,2,0,0,0,0,0,0
0,0,0,25,30,0,1,0,0,0,0,0,1,0,29,24,0,0,0
0,0,0,0,0,0,17,0,9,3,12,0,17,0,0,0,0,0,0
0,0,0,0,0,0,28,0,0,1,0,0,28,0,0,0,0,0,0
0,0,0,0,0,0,18,0,0,0,0,0,18,0,0,0,0,0,0
0,0,0,25,30,0,1,0,0,0,0,0,1,0,29,24,0,0,0
0,0,0,0,0,0,2,1,16,28,15,1,2,0,0,0,0,0,0
0,0,0,0,0,0,0,0,0,0,0,0,0,0,0,0,0,0,0
0,0,0,0,0,0,0,31,0,0,0,31,0,0,0,0,0,0,0
0,0,0,0,0,0,0,26,0,0,0,26,0,0,0,0,0,0,0
0,0,0,0,0,0,0,0,0,0,0,0,0,0,0,0,0,0,0
0,0,0,0,0,0,0,0,0,0,0,0,0,0,0,0,0,0,0
0,0,0,0,0,0,0,0,0,0,0,0,0,0,0,0,0,0,0
endlayer

layer
0,0,0,0,0,0,0,0,0,0,0,0,0,0,0,0,0,0,0
0,0,0,0,0,0,0,0,0,0,0,0,0,0,0,0,0,0,0
0,0,0,0,0,0,0,23,0,0,0,23,0,0,0,0,0,0,0
0,0,0,0,0,0,0,27,0,0,0,27,0,0,0,0,0,0,0
0,0,0,0,0,0,0,0,0,0,0,0,0,0,0,0,0,0,0
0,0,0,0,0,0,0,0,0,0,0,0,0,0,0,0,0,0,0
0,0,0,0,0,0,1,1,1,1,1,1,1,0,0,0,0,0,0
0,0,25,30,0,0,1,17,17,17,17,15,1,0,0,29,24,0,0
0,0,0,0,0,0,1,16,12,0,0,15,1,0,0,0,0,0,0
0,0,0,0,0,0,1,16,3,1,0,15,1,0,0,0,0,0,0
0,0,0,0,0,0,1,16,9,0,0,15,1,0,0,0,0,0,0
0,0,25,30,0,0,1,16,18,18,18,18,1,0,0,29,24,0,0
0,0,0,0,0,0,1,1,1,1,1,1,1,0,0,0,0,0,0
0,0,0,0,0,0,0,0,0,0,0,0,0,0,0,0,0,0,0
0,0,0,0,0,0,0,0,0,0,0,0,0,0,0,0,0,0,0
0,0,0,0,0,0,0,31,0,0,0,31,0,0,0,0,0,0,0
0,0,0,0,0,0,0,26,0,0,0,26,0,0,0,0,0,0,0
0,0,0,0,0,0,0,0,0,0,0,0,0,0,0,0,0,0,0
0,0,0,0,0,0,0,0,0,0,0,0,0,0,0,0,0,0,0
endlayer

layer
0,0,0,0,0,0,0,0,0,0,0,0,0,0,0,0,0,0,0
0,0,0,0,0,0,0,32,33,33,33,32,0,0,0,0,0,0,0
0,0,0,0,0,0,0,34,33,33,33,34,0,0,0,0,0,0,0
0,0,0,0,0,0,0,32,35,35,35,32,0,0,0,0,0,0,0
0,0,0,0,0,0,0,32,35,35,35,32,0,0,0,0,0,0,0
0,0,0,0,0,0,0,32,35,35,35,32,0,0,0,0,0,0,0
0,0,0,0,0,0,34,34,33,33,33,34,34,0,0,0,0,0,0
0,33,34,33,33,33,34,12,12,12,12,12,34,33,33,33,34,33,0
0,32,32,35,35,35,32,12,0,0,0,12,32,35,35,35,32,32,0
0,32,32,35,35,35,32,12,0,1,0,12,32,35,35,35,32,32,0
0,32,32,35,35,35,32,12,12,3,9,12,32,35,35,35,32,32,0
0,33,34,33,33,33,34,12,12,12,12,12,34,33,33,33,34,33,0
0,0,0,0,0,0,34,34,33,33,33,34,34,0,0,0,0,0,0
0,0,0,0,0,0,0,32,35,35,35,32,0,0,0,0,0,0,0
0,0,0,0,0,0,0,32,35,35,35,32,0,0,0,0,0,0,0
0,0,0,0,0,0,0,32,35,35,35,32,0,0,0,0,0,0,0
0,0,0,0,0,0,0,34,33,33,33,34,0,0,0,0,0,0,0
0,0,0,0,0,0,0,32,33,33,33,32,0,0,0,0,0,0,0
0,0,0,0,0,0,0,0,0,0,0,0,0,0,0,0,0,0,0
endlayer

layer
0,0,0,0,0,0,0,0,0,0,0,0,0,0,0,0,0,0,0
0,0,0,0,0,0,0,22,22,22,22,22,0,0,0,0,0,0,0
0,0,0,0,0,0,0,34,31,6,31,34,0,0,0,0,0,0,0
0,0,0,0,0,0,0,29,0,0,0,30,0,0,0,0,0,0,0
0,0,0,0,0,0,0,22,0,0,0,22,0,0,0,0,0,0,0
0,0,0,0,0,0,0,29,0,0,0,30,0,0,0,0,0,0,0
0,0,0,0,0,0,34,34,0,0,0,34,34,0,0,0,0,0,0
0,22,34,31,22,31,34,14,0,0,0,14,34,31,22,31,34,22,0
0,22,29,0,0,0,0,0,0,0,9,0,0,0,0,0,30,22,0
0,22,11,0,0,0,0,0,0,1,3,0,0,0,0,0,10,22,0
0,22,29,0,0,0,0,0,0,0,12,0,0,0,0,0,30,22,0
0,22,34,27,22,27,34,14,0,0,0,14,34,27,22,27,34,22,0
0,0,0,0,0,0,34,34,0,0,0,34,34,0,0,0,0,0,0
0,0,0,0,0,0,0,29,0,0,0,30,0,0,0,0,0,0,0
0,0,0,0,0,0,0,22,0,0,0,22,0,0,0,0,0,0,0
0,0,0,0,0,0,0,29,0,0,0,30,0,0,0,0,0,0,0
0,0,0,0,0,0,0,34,27,13,27,34,0,0,0,0,0,0,0
0,0,0,0,0,0,0,22,22,22,22,22,0,0,0,0,0,0,0
0,0,0,0,0,0,0,0,0,0,0,0,0,0,0,0,0,0,0
endlayer

layer
0,0,0,0,0,0,0,0,0,0,0,0,0,0,0,0,0,0,0
0,0,0,0,0,0,0,22,0,0,0,22,0,0,0,0,0,0,0
0,0,0,0,0,0,0,34,23,0,23,34,0,0,0,0,0,0,0
0,0,0,0,0,0,0,25,0,0,0,24,0,0,0,0,0,0,0
0,0,0,0,0,0,0,22,0,0,0,22,0,0,0,0,0,0,0
0,0,0,0,0,0,0,25,0,0,0,24,0,0,0,0,0,0,0
0,0,0,0,0,0,34,34,0,0,0,34,34,0,0,0,0,0,0
0,22,34,23,22,23,34,0,0,0,0,0,34,23,22,23,34,22,0
0,0,25,0,0,0,0,0,9,3,12,0,0,0,0,0,24,0,0
0,0,0,0,0,0,0,0,0,1,0,0,0,0,0,0,0,0,0
0,0,25,0,0,0,0,0,0,0,0,0,0,0,0,0,24,0,0
0,22,34,26,22,26,34,0,0,0,0,0,34,26,22,26,34,22,0
0,0,0,0,0,0,34,34,0,0,0,34,34,0,0,0,0,0,0
0,0,0,0,0,0,0,25,0,0,0,24,0,0,0,0,0,0,0
0,0,0,0,0,0,0,22,0,0,0,22,0,0,0,0,0,0,0
0,0,0,0,0,0,0,25,0,0,0,24,0,0,0,0,0,0,0
0,0,0,0,0,0,0,34,26,0,26,34,0,0,0,0,0,0,0
0,0,0,0,0,0,0,22,0,0,0,22,0,0,0,0,0,0,0
0,0,0,0,0,0,0,0,0,0,0,0,0,0,0,0,0,0,0
endlayer

layer
0,0,0,0,0,0,0,0,0,0,0,0,0,0,0,0,0,0,0
0,0,0,0,0,0,0,22,0,0,0,22,0,0,0,0,0,0,0
0,0,0,0,0,0,0,34,33,33,33,34,0,0,0,0,0,0,0
0,0,0,0,0,0,0,32,0,0,0,32,0,0,0,0,0,0,0
0,0,0,0,0,0,0,32,0,0,0,32,0,0,0,0,0,0,0
0,0,0,0,0,0,0,32,0,0,0,32,0,0,0,0,0,0,0
0,0,0,0,0,0,34,34,33,33,33,34,34,0,0,0,0,0,0
0,22,34,33,33,33,34,0,0,0,0,0,34,33,33,33,34,22,0
0,0,32,0,0,0,32,0,12,0,0,0,32,0,0,0,32,0,0
0,0,32,0,0,0,32,0,3,1,0,0,32,0,0,0,32,0,0
0,0,32,0,0,0,32,0,9,0,0,0,32,0,0,0,32,0,0
0,22,34,33,33,33,34,0,0,0,0,0,34,33,33,33,34,22,0
0,0,0,0,0,0,34,34,33,33,33,34,34,0,0,0,0,0,0
0,0,0,0,0,0,0,32,0,0,0,32,0,0,0,0,0,0,0
0,0,0,0,0,0,0,32,0,0,0,32,0,0,0,0,0,0,0
0,0,0,0,0,0,0,32,0,0,0,32,0,0,0,0,0,0,0
0,0,0,0,0,0,0,34,33,33,33,34,0,0,0,0,0,0,0
0,0,0,0,0,0,0,22,0,0,0,22,0,0,0,0,0,0,0
0,0,0,0,0,0,0,0,0,0,0,0,0,0,0,0,0,0,0
endlayer

layer
0,0,0,0,0,0,0,0,0,0,0,0,0,0,0,0,0,0,0
0,0,0,0,0,0,36,40,39,0,38,37,36,0,0,0,0,0,0
0,0,0,0,0,0,36,40,35,31,35,37,36,0,0,0,0,0,0
0,0,0,0,0,0,36,40,39,0,38,37,36,0,0,0,0,0,0
0,0,0,0,0,0,36,40,39,0,38,37,36,0,0,0,0,0,0
0,0,0,0,0,0,36,40,39,0,38,37,36,0,0,0,0,0,0
0,36,36,36,36,36,40,41,35,35,35,37,41,36,36,36,36,36,0
0,41,41,41,41,41,41,26,26,0,26,25,37,41,41,41,41,41,0
0,42,35,42,42,42,35,24,0,0,0,25,35,42,42,42,35,42,0
0,0,29,0,0,0,35,0,0,1,0,0,35,0,0,0,30,0,0
0,43,35,43,43,43,35,24,12,3,9,25,35,43,43,43,35,43,0
0,44,44,44,44,44,40,24,23,0,23,23,44,44,44,44,44,44,0
0,36,36,36,36,36,44,40,35,35,35,44,37,36,36,36,36,36,0
0,0,0,0,0,0,36,40,39,0,38,37,36,0,0,0,0,0,0
0,0,0,0,0,0,36,40,39,0,38,37,36,0,0,0,0,0,0
0,0,0,0,0,0,36,40,39,0,38,37,36,0,0,0,0,0,0
0,0,0,0,0,0,36,40,35,27,35,37,36,0,0,0,0,0,0
0,0,0,0,0,0,36,40,39,0,38,37,36,0,0,0,0,0,0
0,0,0,0,0,0,0,0,0,0,0,0,0,0,0,0,0,0,0
endlayer

layer
0,0,0,0,0,0,0,0,0,0,0,0,0,0,0,0,0,0,0
0,0,0,0,0,0,0,0,40,0,37,0,0,0,0,0,0,0,0
0,0,0,0,0,0,0,0,40,23,37,0,0,0,0,0,0,0,0
0,0,0,0,0,0,0,0,40,45,37,0,0,0,0,0,0,0,0
0,0,0,0,0,0,0,0,40,45,37,0,0,0,0,0,0,0,0
0,0,0,0,0,0,0,0,40,45,37,0,0,0,0,0,0,0,0
0,0,0,0,0,0,0,0,41,46,41,0,0,0,0,0,0,0,0
0,0,0,0,0,0,0,34,46,0,46,34,0,0,0,0,0,0,0
0,41,41,41,41,41,40,46,0,0,9,46,37,41,41,41,41,41,0
0,0,25,45,45,45,46,0,0,1,3,0,46,45,45,45,24,0,0
0,44,44,44,44,44,40,46,0,0,12,46,37,44,44,44,44,44,0
0,0,0,0,0,0,0,34,46,0,46,34,0,0,0,0,0,0,0
0,0,0,0,0,0,0,0,44,46,44,0,0,0,0,0,0,0,0
0,0,0,0,0,0,0,0,40,45,37,0,0,0,0,0,0,0,0
0,0,0,0,0,0,0,0,40,45,37,0,0,0,0,0,0,0,0
0,0,0,0,0,0,0,0,40,45,37,0,0,0,0,0,0,0,0
0,0,0,0,0,0,0,0,40,26,37,0,0,0,0,0,0,0,0
0,0,0,0,0,0,0,0,40,0,37,0,0,0,0,0,0,0,0
0,0,0,0,0,0,0,0,0,0,0,0,0,0,0,0,0,0,0
endlayer

layer
0,0,0,0,0,0,0,0,0,0,0,0,0,0,0,0,0,0,0
0,0,0,0,0,0,0,0,0,41,0,0,0,0,0,0,0,0,0
0,0,0,0,0,0,0,0,0,46,0,0,0,0,0,0,0,0,0
0,0,0,0,0,0,0,0,0,44,0,0,0,0,0,0,0,0,0
0,0,0,0,0,0,0,0,0,0,0,0,0,0,0,0,0,0,0
0,0,0,0,0,0,0,0,0,0,0,0,0,0,0,0,0,0,0
0,0,0,0,0,0,0,0,0,0,0,0,0,0,0,0,0,0,0
0,0,0,0,0,0,0,34,35,35,35,34,0,0,0,0,0,0,0
0,0,0,0,0,0,0,35,9,3,12,35,0,0,0,0,0,0,0
0,40,46,37,0,0,0,35,0,1,0,35,0,0,0,40,46,37,0
0,0,0,0,0,0,0,35,0,0,0,35,0,0,0,0,0,0,0
0,0,0,0,0,0,0,34,35,35,35,34,0,0,0,0,0,0,0
0,0,0,0,0,0,0,0,0,0,0,0,0,0,0,0,0,0,0
0,0,0,0,0,0,0,0,0,0,0,0,0,0,0,0,0,0,0
0,0,0,0,0,0,0,0,0,0,0,0,0,0,0,0,0,0,0
0,0,0,0,0,0,0,0,0,41,0,0,0,0,0,0,0,0,0
0,0,0,0,0,0,0,0,0,46,0,0,0,0,0,0,0,0,0
0,0,0,0,0,0,0,0,0,44,0,0,0,0,0,0,0,0,0
0,0,0,0,0,0,0,0,0,0,0,0,0,0,0,0,0,0,0
endlayer

layer
0,0,0,0,0,0,0,0,0,0,0,0,0,0,0,0,0,0,0
0,0,0,0,0,0,0,0,0,43,0,0,0,0,0,0,0,0,0
0,0,0,0,0,0,0,0,0,44,0,0,0,0,0,0,0,0,0
0,0,0,0,0,0,0,0,0,0,0,0,0,0,0,0,0,0,0
0,0,0,0,0,0,0,0,0,0,0,0,0,0,0,0,0,0,0
0,0,0,0,0,0,0,0,0,0,0,0,0,0,0,0,0,0,0
0,0,0,0,0,0,0,0,0,0,0,0,0,0,0,0,0,0,0
0,0,0,0,0,0,0,34,35,22,35,34,0,0,0,0,0,0,0
0,0,0,0,0,0,0,35,12,0,0,35,0,0,0,0,0,0,0
0,38,37,0,0,0,0,22,3,1,0,22,0,0,0,0,40,39,0
0,0,0,0,0,0,0,35,9,0,0,35,0,0,0,0,0,0,0
0,0,0,0,0,0,0,34,35,22,35,34,0,0,0,0,0,0,0
0,0,0,0,0,0,0,0,0,0,0,0,0,0,0,0,0,0,0
0,0,0,0,0,0,0,0,0,0,0,0,0,0,0,0,0,0,0
0,0,0,0,0,0,0,0,0,0,0,0,0,0,0,0,0,0,0
0,0,0,0,0,0,0,0,0,0,0,0,0,0,0,0,0,0,0
0,0,0,0,0,0,0,0,0,41,0,0,0,0,0,0,0,0,0
0,0,0,0,0,0,0,0,0,42,0,0,0,0,0,0,0,0,0
0,0,0,0,0,0,0,0,0,0,0,0,0,0,0,0,0,0,0
endlayer

layer
0,0,0,0,0,0,0,0,0,41,0,0,0,0,0,0,0,0,0
0,0,0,0,0,0,0,0,0,44,0,0,0,0,0,0,0,0,0
0,0,0,0,0,0,0,0,0,0,0,0,0,0,0,0,0,0,0
0,0,0,0,0,0,0,0,0,0,0,0,0,0,0,0,0,0,0
0,0,0,0,0,0,0,0,0,0,0,0,0,0,0,0,0,0,0
0,0,0,0,0,0,0,0,0,0,0,0,0,0,0,0,0,0,0
0,0,0,0,0,0,0,0,0,0,0,0,0,0,0,0,0,0,0
0,0,0,0,0,0,0,34,35,22,35,34,0,0,0,0,0,0,0
0,0,0,0,0,0,0,35,0,0,0,35,0,0,0,0,0,0,0
40,37,0,0,0,0,0,22,0,1,0,22,0,0,0,0,0,40,37
0,0,0,0,0,0,0,35,12,3,9,35,0,0,0,0,0,0,0
0,0,0,0,0,0,0,34,35,22,35,34,0,0,0,0,0,0,0
0,0,0,0,0,0,0,0,0,0,0,0,0,0,0,0,0,0,0
0,0,0,0,0,0,0,0,0,0,0,0,0,0,0,0,0,0,0
0,0,0,0,0,0,0,0,0,0,0,0,0,0,0,0,0,0,0
0,0,0,0,0,0,0,0,0,0,0,0,0,0,0,0,0,0,0
0,0,0,0,0,0,0,0,0,0,0,0,0,0,0,0,0,0,0
0,0,0,0,0,0,0,0,0,41,0,0,0,0,0,0,0,0,0
0,0,0,0,0,0,0,0,0,44,0,0,0,0,0,0,0,0,0
endlayer

layer
0,0,0,0,0,0,0,0,0,0,0,0,0,0,0,0,0,0,0
0,0,0,0,0,0,0,0,0,0,0,0,0,0,0,0,0,0,0
0,0,0,0,0,0,0,0,0,0,0,0,0,0,0,0,0,0,0
0,0,0,0,0,0,0,0,0,0,0,0,0,0,0,0,0,0,0
0,0,0,0,0,0,0,0,0,0,0,0,0,0,0,0,0,0,0
0,0,0,0,0,0,0,0,0,0,0,0,0,0,0,0,0,0,0
0,0,0,0,0,0,0,0,0,0,0,0,0,0,0,0,0,0,0
0,0,0,0,0,0,0,34,35,35,35,34,0,0,0,0,0,0,0
0,0,0,0,0,0,0,35,0,0,9,35,0,0,0,0,0,0,0
0,0,0,0,0,0,0,35,0,1,3,35,0,0,0,0,0,0,0
0,0,0,0,0,0,0,35,0,0,12,35,0,0,0,0,0,0,0
0,0,0,0,0,0,0,34,35,35,35,34,0,0,0,0,0,0,0
0,0,0,0,0,0,0,0,0,0,0,0,0,0,0,0,0,0,0
0,0,0,0,0,0,0,0,0,0,0,0,0,0,0,0,0,0,0
0,0,0,0,0,0,0,0,0,0,0,0,0,0,0,0,0,0,0
0,0,0,0,0,0,0,0,0,0,0,0,0,0,0,0,0,0,0
0,0,0,0,0,0,0,0,0,0,0,0,0,0,0,0,0,0,0
0,0,0,0,0,0,0,0,0,0,0,0,0,0,0,0,0,0,0
0,0,0,0,0,0,0,0,0,0,0,0,0,0,0,0,0,0,0
endlayer

layer
0,0,0,0,0,0,0,0,0,0,0,0,0,0,0,0,0,0,0
0,0,0,0,0,0,0,0,0,0,0,0,0,0,0,0,0,0,0
0,0,0,0,0,0,0,0,0,0,0,0,0,0,0,0,0,0,0
0,0,0,0,0,0,0,0,0,0,0,0,0,0,0,0,0,0,0
0,0,0,0,0,0,0,0,0,0,0,0,0,0,0,0,0,0,0
0,0,0,0,0,0,0,0,0,0,0,0,0,0,0,0,0,0,0
0,0,0,0,0,0,36,39,0,0,0,38,36,0,0,0,0,0,0
0,0,0,0,0,0,42,34,33,33,33,34,42,0,0,0,0,0,0
0,0,0,0,0,0,0,32,0,3,12,32,0,0,0,0,0,0,0
0,0,0,0,0,0,0,32,0,1,0,32,0,0,0,0,0,0,0
0,0,0,0,0,0,0,32,0,0,0,32,0,0,0,0,0,0,0
0,0,0,0,0,0,43,34,33,33,33,34,43,0,0,0,0,0,0
0,0,0,0,0,0,36,39,0,0,0,38,36,0,0,0,0,0,0
0,0,0,0,0,0,0,0,0,0,0,0,0,0,0,0,0,0,0
0,0,0,0,0,0,0,0,0,0,0,0,0,0,0,0,0,0,0
0,0,0,0,0,0,0,0,0,0,0,0,0,0,0,0,0,0,0
0,0,0,0,0,0,0,0,0,0,0,0,0,0,0,0,0,0,0
0,0,0,0,0,0,0,0,0,0,0,0,0,0,0,0,0,0,0
0,0,0,0,0,0,0,0,0,0,0,0,0,0,0,0,0,0,0
endlayer

layer
0,0,0,0,0,0,0,0,0,0,0,0,0,0,0,0,0,0,0
0,0,0,0,0,0,0,0,0,0,0,0,0,0,0,0,0,0,0
0,0,0,0,0,0,0,0,0,0,0,0,0,0,0,0,0,0,0
0,0,0,0,0,0,0,0,0,0,0,0,0,0,0,0,0,0,0
0,0,0,0,0,0,0,0,0,0,0,0,0,0,0,0,0,0,0
0,0,0,0,0,0,0,0,0,0,0,0,0,0,0,0,0,0,0
0,0,0,0,0,0,0,46,0,0,0,46,0,0,0,0,0,0,0
0,0,0,0,0,0,46,46,35,22,35,46,46,0,0,0,0,0,0
0,0,0,0,0,0,0,35,0,0,0,35,0,0,0,0,0,0,0
0,0,0,0,0,0,0,22,0,13,0,22,0,0,0,0,0,0,0
0,0,0,0,0,0,0,35,0,0,0,35,0,0,0,0,0,0,0
0,0,0,0,0,0,46,46,35,22,35,46,46,0,0,0,0,0,0
0,0,0,0,0,0,0,46,0,0,0,46,0,0,0,0,0,0,0
0,0,0,0,0,0,0,0,0,0,0,0,0,0,0,0,0,0,0
0,0,0,0,0,0,0,0,0,0,0,0,0,0,0,0,0,0,0
0,0,0,0,0,0,0,0,0,0,0,0,0,0,0,0,0,0,0
0,0,0,0,0,0,0,0,0,0,0,0,0,0,0,0,0,0,0
0,0,0,0,0,0,0,0,0,0,0,0,0,0,0,0,0,0,0
0,0,0,0,0,0,0,0,0,0,0,0,0,0,0,0,0,0,0
endlayer

layer
0,0,0,0,0,0,0,0,0,0,0,0,0,0,0,0,0,0,0
0,0,0,0,0,0,0,0,0,0,0,0,0,0,0,0,0,0,0
0,0,0,0,0,0,0,0,0,0,0,0,0,0,0,0,0,0,0
0,0,0,0,0,0,0,0,0,0,0,0,0,0,0,0,0,0,0
0,0,0,0,0,0,0,0,0,0,0,0,0,0,0,0,0,0,0
0,0,0,0,0,0,0,0,0,0,0,0,0,0,0,0,0,0,0
0,0,0,0,0,0,0,40,39,0,38,37,0,0,0,0,0,0,0
0,0,0,0,0,0,41,46,35,22,35,46,41,0,0,0,0,0,0
0,0,0,0,0,0,42,35,0,0,0,35,42,0,0,0,0,0,0
0,0,0,0,0,0,0,22,0,0,0,22,0,0,0,0,0,0,0
0,0,0,0,0,0,43,35,0,0,0,35,43,0,0,0,0,0,0
0,0,0,0,0,0,44,46,35,22,35,46,44,0,0,0,0,0,0
0,0,0,0,0,0,0,40,39,0,38,37,0,0,0,0,0,0,0
0,0,0,0,0,0,0,0,0,0,0,0,0,0,0,0,0,0,0
0,0,0,0,0,0,0,0,0,0,0,0,0,0,0,0,0,0,0
0,0,0,0,0,0,0,0,0,0,0,0,0,0,0,0,0,0,0
0,0,0,0,0,0,0,0,0,0,0,0,0,0,0,0,0,0,0
0,0,0,0,0,0,0,0,0,0,0,0,0,0,0,0,0,0,0
0,0,0,0,0,0,0,0,0,0,0,0,0,0,0,0,0,0,0
endlayer

layer
0,0,0,0,0,0,0,0,0,0,0,0,0,0,0,0,0,0,0
0,0,0,0,0,0,0,0,0,0,0,0,0,0,0,0,0,0,0
0,0,0,0,0,0,0,0,0,0,0,0,0,0,0,0,0,0,0
0,0,0,0,0,0,0,0,0,0,0,0,0,0,0,0,0,0,0
0,0,0,0,0,0,0,0,0,0,0,0,0,0,0,0,0,0,0
0,0,0,0,0,0,0,0,0,0,0,0,0,0,0,0,0,0,0
0,0,0,0,0,0,0,0,40,45,37,0,0,0,0,0,0,0,0
0,0,0,0,0,0,0,0,40,35,37,0,0,0,0,0,0,0,0
0,0,0,0,0,0,41,41,34,33,34,41,41,0,0,0,0,0,0
0,0,0,0,0,0,45,35,32,14,32,35,45,0,0,0,0,0,0
0,0,0,0,0,0,44,44,34,33,34,44,44,0,0,0,0,0,0
0,0,0,0,0,0,0,0,40,35,37,0,0,0,0,0,0,0,0
0,0,0,0,0,0,0,0,40,45,37,0,0,0,0,0,0,0,0
0,0,0,0,0,0,0,0,0,0,0,0,0,0,0,0,0,0,0
0,0,0,0,0,0,0,0,0,0,0,0,0,0,0,0,0,0,0
0,0,0,0,0,0,0,0,0,0,0,0,0,0,0,0,0,0,0
0,0,0,0,0,0,0,0,0,0,0,0,0,0,0,0,0,0,0
0,0,0,0,0,0,0,0,0,0,0,0,0,0,0,0,0,0,0
0,0,0,0,0,0,0,0,0,0,0,0,0,0,0,0,0,0,0
endlayer

layer
0,0,0,0,0,0,0,0,0,0,0,0,0,0,0,0,0,0,0
0,0,0,0,0,0,0,0,0,0,0,0,0,0,0,0,0,0,0
0,0,0,0,0,0,0,0,0,0,0,0,0,0,0,0,0,0,0
0,0,0,0,0,0,0,0,0,0,0,0,0,0,0,0,0,0,0
0,0,0,0,0,0,0,0,0,0,0,0,0,0,0,0,0,0,0
0,0,0,0,0,0,0,0,0,41,0,0,0,0,0,0,0,0,0
0,0,0,0,0,0,0,0,0,44,0,0,0,0,0,0,0,0,0
0,0,0,0,0,0,0,0,0,36,0,0,0,0,0,0,0,0,0
0,0,0,0,0,0,0,0,34,22,34,0,0,0,0,0,0,0,0
0,0,0,0,0,40,37,36,22,0,22,36,40,37,0,0,0,0,0
0,0,0,0,0,0,0,0,34,22,34,0,0,0,0,0,0,0,0
0,0,0,0,0,0,0,0,0,36,0,0,0,0,0,0,0,0,0
0,0,0,0,0,0,0,0,0,41,0,0,0,0,0,0,0,0,0
0,0,0,0,0,0,0,0,0,44,0,0,0,0,0,0,0,0,0
0,0,0,0,0,0,0,0,0,0,0,0,0,0,0,0,0,0,0
0,0,0,0,0,0,0,0,0,0,0,0,0,0,0,0,0,0,0
0,0,0,0,0,0,0,0,0,0,0,0,0,0,0,0,0,0,0
0,0,0,0,0,0,0,0,0,0,0,0,0,0,0,0,0,0,0
0,0,0,0,0,0,0,0,0,0,0,0,0,0,0,0,0,0,0
endlayer

layer
0,0,0,0,0,0,0,0,0,0,0,0,0,0,0,0,0,0,0
0,0,0,0,0,0,0,0,0,0,0,0,0,0,0,0,0,0,0
0,0,0,0,0,0,0,0,0,0,0,0,0,0,0,0,0,0,0
0,0,0,0,0,0,0,0,0,0,0,0,0,0,0,0,0,0,0
0,0,0,0,0,0,0,0,0,0,0,0,0,0,0,0,0,0,0
0,0,0,0,0,0,0,0,0,0,0,0,0,0,0,0,0,0,0
0,0,0,0,0,0,0,0,0,0,0,0,0,0,0,0,0,0,0
0,0,0,0,0,0,0,0,0,0,0,0,0,0,0,0,0,0,0
0,0,0,0,0,0,0,0,34,22,34,0,0,0,0,0,0,0,0
0,0,0,0,0,0,0,0,22,0,22,0,0,0,0,0,0,0,0
0,0,0,0,0,0,0,0,34,22,34,0,0,0,0,0,0,0,0
0,0,0,0,0,0,0,0,0,0,0,0,0,0,0,0,0,0,0
0,0,0,0,0,0,0,0,0,0,0,0,0,0,0,0,0,0,0
0,0,0,0,0,0,0,0,0,0,0,0,0,0,0,0,0,0,0
0,0,0,0,0,0,0,0,0,0,0,0,0,0,0,0,0,0,0
0,0,0,0,0,0,0,0,0,0,0,0,0,0,0,0,0,0,0
0,0,0,0,0,0,0,0,0,0,0,0,0,0,0,0,0,0,0
0,0,0,0,0,0,0,0,0,0,0,0,0,0,0,0,0,0,0
0,0,0,0,0,0,0,0,0,0,0,0,0,0,0,0,0,0,0
endlayer

layer
0,0,0,0,0,0,0,0,0,0,0,0,0,0,0,0,0,0,0
0,0,0,0,0,0,0,0,0,0,0,0,0,0,0,0,0,0,0
0,0,0,0,0,0,0,0,0,0,0,0,0,0,0,0,0,0,0
0,0,0,0,0,0,0,0,0,0,0,0,0,0,0,0,0,0,0
0,0,0,0,0,0,0,0,0,0,0,0,0,0,0,0,0,0,0
0,0,0,0,0,0,0,0,0,0,0,0,0,0,0,0,0,0,0
0,0,0,0,0,0,0,0,0,0,0,0,0,0,0,0,0,0,0
0,0,0,0,0,0,0,0,0,0,0,0,0,0,0,0,0,0,0
0,0,0,0,0,0,0,0,34,22,34,0,0,0,0,0,0,0,0
0,0,0,0,0,0,0,0,22,0,22,0,0,0,0,0,0,0,0
0,0,0,0,0,0,0,0,34,22,34,0,0,0,0,0,0,0,0
0,0,0,0,0,0,0,0,0,0,0,0,0,0,0,0,0,0,0
0,0,0,0,0,0,0,0,0,0,0,0,0,0,0,0,0,0,0
0,0,0,0,0,0,0,0,0,0,0,0,0,0,0,0,0,0,0
0,0,0,0,0,0,0,0,0,0,0,0,0,0,0,0,0,0,0
0,0,0,0,0,0,0,0,0,0,0,0,0,0,0,0,0,0,0
0,0,0,0,0,0,0,0,0,0,0,0,0,0,0,0,0,0,0
0,0,0,0,0,0,0,0,0,0,0,0,0,0,0,0,0,0,0
0,0,0,0,0,0,0,0,0,0,0,0,0,0,0,0,0,0,0
endlayer

layer
0,0,0,0,0,0,0,0,0,0,0,0,0,0,0,0,0,0,0
0,0,0,0,0,0,0,0,0,0,0,0,0,0,0,0,0,0,0
0,0,0,0,0,0,0,0,0,0,0,0,0,0,0,0,0,0,0
0,0,0,0,0,0,0,0,0,0,0,0,0,0,0,0,0,0,0
0,0,0,0,0,0,0,0,0,0,0,0,0,0,0,0,0,0,0
0,0,0,0,0,0,0,0,0,0,0,0,0,0,0,0,0,0,0
0,0,0,0,0,0,0,0,0,0,0,0,0,0,0,0,0,0,0
0,0,0,0,0,0,0,0,40,45,37,0,0,0,0,0,0,0,0
0,0,0,0,0,0,0,41,46,35,46,41,0,0,0,0,0,0,0
0,0,0,0,0,0,0,45,35,0,35,45,0,0,0,0,0,0,0
0,0,0,0,0,0,0,44,46,35,46,44,0,0,0,0,0,0,0
0,0,0,0,0,0,0,0,40,45,37,0,0,0,0,0,0,0,0
0,0,0,0,0,0,0,0,0,0,0,0,0,0,0,0,0,0,0
0,0,0,0,0,0,0,0,0,0,0,0,0,0,0,0,0,0,0
0,0,0,0,0,0,0,0,0,0,0,0,0,0,0,0,0,0,0
0,0,0,0,0,0,0,0,0,0,0,0,0,0,0,0,0,0,0
0,0,0,0,0,0,0,0,0,0,0,0,0,0,0,0,0,0,0
0,0,0,0,0,0,0,0,0,0,0,0,0,0,0,0,0,0,0
0,0,0,0,0,0,0,0,0,0,0,0,0,0,0,0,0,0,0
endlayer

layer
0,0,0,0,0,0,0,0,0,0,0,0,0,0,0,0,0,0,0
0,0,0,0,0,0,0,0,0,0,0,0,0,0,0,0,0,0,0
0,0,0,0,0,0,0,0,0,0,0,0,0,0,0,0,0,0,0
0,0,0,0,0,0,0,0,0,0,0,0,0,0,0,0,0,0,0
0,0,0,0,0,0,0,0,0,0,0,0,0,0,0,0,0,0,0
0,0,0,0,0,0,0,0,0,0,0,0,0,0,0,0,0,0,0
0,0,0,0,0,0,0,0,0,41,0,0,0,0,0,0,0,0,0
0,0,0,0,0,0,0,0,0,44,0,0,0,0,0,0,0,0,0
0,0,0,0,0,0,0,0,41,41,37,0,0,0,0,0,0,0,0
0,0,0,0,0,0,40,37,40,46,37,40,37,0,0,0,0,0,0
0,0,0,0,0,0,0,0,40,44,44,0,0,0,0,0,0,0,0
0,0,0,0,0,0,0,0,0,41,0,0,0,0,0,0,0,0,0
0,0,0,0,0,0,0,0,0,44,0,0,0,0,0,0,0,0,0
0,0,0,0,0,0,0,0,0,0,0,0,0,0,0,0,0,0,0
0,0,0,0,0,0,0,0,0,0,0,0,0,0,0,0,0,0,0
0,0,0,0,0,0,0,0,0,0,0,0,0,0,0,0,0,0,0
0,0,0,0,0,0,0,0,0,0,0,0,0,0,0,0,0,0,0
0,0,0,0,0,0,0,0,0,0,0,0,0,0,0,0,0,0,0
0,0,0,0,0,0,0,0,0,0,0,0,0,0,0,0,0,0,0
endlayer

layer
0,0,0,0,0,0,0,0,0,0,0,0,0,0,0,0,0,0,0
0,0,0,0,0,0,0,0,0,0,0,0,0,0,0,0,0,0,0
0,0,0,0,0,0,0,0,0,0,0,0,0,0,0,0,0,0,0
0,0,0,0,0,0,0,0,0,0,0,0,0,0,0,0,0,0,0
0,0,0,0,0,0,0,0,0,0,0,0,0,0,0,0,0,0,0
0,0,0,0,0,0,0,0,0,0,0,0,0,0,0,0,0,0,0
0,0,0,0,0,0,0,0,0,0,0,0,0,0,0,0,0,0,0
0,0,0,0,0,0,0,0,0,0,0,0,0,0,0,0,0,0,0
0,0,0,0,0,0,0,0,0,0,0,0,0,0,0,0,0,0,0
0,0,0,0,0,0,0,0,0,46,0,0,0,0,0,0,0,0,0
0,0,0,0,0,0,0,0,0,0,0,0,0,0,0,0,0,0,0
0,0,0,0,0,0,0,0,0,0,0,0,0,0,0,0,0,0,0
0,0,0,0,0,0,0,0,0,0,0,0,0,0,0,0,0,0,0
0,0,0,0,0,0,0,0,0,0,0,0,0,0,0,0,0,0,0
0,0,0,0,0,0,0,0,0,0,0,0,0,0,0,0,0,0,0
0,0,0,0,0,0,0,0,0,0,0,0,0,0,0,0,0,0,0
0,0,0,0,0,0,0,0,0,0,0,0,0,0,0,0,0,0,0
0,0,0,0,0,0,0,0,0,0,0,0,0,0,0,0,0,0,0
0,0,0,0,0,0,0,0,0,0,0,0,0,0,0,0,0,0,0
endlayer

layer
0,0,0,0,0,0,0,0,0,0,0,0,0,0,0,0,0,0,0
0,0,0,0,0,0,0,0,0,0,0,0,0,0,0,0,0,0,0
0,0,0,0,0,0,0,0,0,0,0,0,0,0,0,0,0,0,0
0,0,0,0,0,0,0,0,0,0,0,0,0,0,0,0,0,0,0
0,0,0,0,0,0,0,0,0,0,0,0,0,0,0,0,0,0,0
0,0,0,0,0,0,0,0,0,0,0,0,0,0,0,0,0,0,0
0,0,0,0,0,0,0,0,0,0,0,0,0,0,0,0,0,0,0
0,0,0,0,0,0,0,0,0,0,0,0,0,0,0,0,0,0,0
0,0,0,0,0,0,0,0,0,0,0,0,0,0,0,0,0,0,0
0,0,0,0,0,0,0,0,0,46,0,0,0,0,0,0,0,0,0
0,0,0,0,0,0,0,0,0,0,0,0,0,0,0,0,0,0,0
0,0,0,0,0,0,0,0,0,0,0,0,0,0,0,0,0,0,0
0,0,0,0,0,0,0,0,0,0,0,0,0,0,0,0,0,0,0
0,0,0,0,0,0,0,0,0,0,0,0,0,0,0,0,0,0,0
0,0,0,0,0,0,0,0,0,0,0,0,0,0,0,0,0,0,0
0,0,0,0,0,0,0,0,0,0,0,0,0,0,0,0,0,0,0
0,0,0,0,0,0,0,0,0,0,0,0,0,0,0,0,0,0,0
0,0,0,0,0,0,0,0,0,0,0,0,0,0,0,0,0,0,0
0,0,0,0,0,0,0,0,0,0,0,0,0,0,0,0,0,0,0
endlayer

layer
0,0,0,0,0,0,0,0,0,0,0,0,0,0,0,0,0,0,0
0,0,0,0,0,0,0,0,0,0,0,0,0,0,0,0,0,0,0
0,0,0,0,0,0,0,0,0,0,0,0,0,0,0,0,0,0,0
0,0,0,0,0,0,0,0,0,0,0,0,0,0,0,0,0,0,0
0,0,0,0,0,0,0,0,0,0,0,0,0,0,0,0,0,0,0
0,0,0,0,0,0,0,0,0,0,0,0,0,0,0,0,0,0,0
0,0,0,0,0,0,0,0,0,0,0,0,0,0,0,0,0,0,0
0,0,0,0,0,0,0,0,0,0,0,0,0,0,0,0,0,0,0
0,0,0,0,0,0,0,0,0,0,0,0,0,0,0,0,0,0,0
0,0,0,0,0,0,0,0,0,47,0,0,0,0,0,0,0,0,0
0,0,0,0,0,0,0,0,0,0,0,0,0,0,0,0,0,0,0
0,0,0,0,0,0,0,0,0,0,0,0,0,0,0,0,0,0,0
0,0,0,0,0,0,0,0,0,0,0,0,0,0,0,0,0,0,0
0,0,0,0,0,0,0,0,0,0,0,0,0,0,0,0,0,0,0
0,0,0,0,0,0,0,0,0,0,0,0,0,0,0,0,0,0,0
0,0,0,0,0,0,0,0,0,0,0,0,0,0,0,0,0,0,0
0,0,0,0,0,0,0,0,0,0,0,0,0,0,0,0,0,0,0
0,0,0,0,0,0,0,0,0,0,0,0,0,0,0,0,0,0,0
0,0,0,0,0,0,0,0,0,0,0,0,0,0,0,0,0,0,0
endlayer

layer
0,0,0,0,0,0,0,0,0,0,0,0,0,0,0,0,0,0,0
0,0,0,0,0,0,0,0,0,0,0,0,0,0,0,0,0,0,0
0,0,0,0,0,0,0,0,0,0,0,0,0,0,0,0,0,0,0
0,0,0,0,0,0,0,0,0,0,0,0,0,0,0,0,0,0,0
0,0,0,0,0,0,0,0,0,0,0,0,0,0,0,0,0,0,0
0,0,0,0,0,0,0,0,0,0,0,0,0,0,0,0,0,0,0
0,0,0,0,0,0,0,0,0,0,0,0,0,0,0,0,0,0,0
0,0,0,0,0,0,0,0,0,0,0,0,0,0,0,0,0,0,0
0,0,0,0,0,0,0,0,0,0,0,0,0,0,0,0,0,0,0
0,0,0,0,0,0,0,0,0,47,0,0,0,0,0,0,0,0,0
0,0,0,0,0,0,0,0,0,0,0,0,0,0,0,0,0,0,0
0,0,0,0,0,0,0,0,0,0,0,0,0,0,0,0,0,0,0
0,0,0,0,0,0,0,0,0,0,0,0,0,0,0,0,0,0,0
0,0,0,0,0,0,0,0,0,0,0,0,0,0,0,0,0,0,0
0,0,0,0,0,0,0,0,0,0,0,0,0,0,0,0,0,0,0
0,0,0,0,0,0,0,0,0,0,0,0,0,0,0,0,0,0,0
0,0,0,0,0,0,0,0,0,0,0,0,0,0,0,0,0,0,0
0,0,0,0,0,0,0,0,0,0,0,0,0,0,0,0,0,0,0
0,0,0,0,0,0,0,0,0,0,0,0,0,0,0,0,0,0,0
endlayer

layer
0,0,0,0,0,0,0,0,0,0,0,0,0,0,0,0,0,0,0
0,0,0,0,0,0,0,0,0,0,0,0,0,0,0,0,0,0,0
0,0,0,0,0,0,0,0,0,0,0,0,0,0,0,0,0,0,0
0,0,0,0,0,0,0,0,0,0,0,0,0,0,0,0,0,0,0
0,0,0,0,0,0,0,0,0,0,0,0,0,0,0,0,0,0,0
0,0,0,0,0,0,0,0,0,0,0,0,0,0,0,0,0,0,0
0,0,0,0,0,0,0,0,0,0,0,0,0,0,0,0,0,0,0
0,0,0,0,0,0,0,0,0,0,0,0,0,0,0,0,0,0,0
0,0,0,0,0,0,0,0,0,0,0,0,0,0,0,0,0,0,0
0,0,0,0,0,0,0,0,0,19,0,0,0,0,0,0,0,0,0
0,0,0,0,0,0,0,0,0,0,0,0,0,0,0,0,0,0,0
0,0,0,0,0,0,0,0,0,0,0,0,0,0,0,0,0,0,0
0,0,0,0,0,0,0,0,0,0,0,0,0,0,0,0,0,0,0
0,0,0,0,0,0,0,0,0,0,0,0,0,0,0,0,0,0,0
0,0,0,0,0,0,0,0,0,0,0,0,0,0,0,0,0,0,0
0,0,0,0,0,0,0,0,0,0,0,0,0,0,0,0,0,0,0
0,0,0,0,0,0,0,0,0,0,0,0,0,0,0,0,0,0,0
0,0,0,0,0,0,0,0,0,0,0,0,0,0,0,0,0,0,0
0,0,0,0,0,0,0,0,0,0,0,0,0,0,0,0,0,0,0
endlayer

