
# Pumpkin Patch
# 9 Mar 2014; updated to MC 1.7.10, 9 Oct 2014
# Created by Ruins mod version 12.3 Ingame Parser
# authoring Player: Jordan_Greywolf
# Updated for MC 1.8: 22 Jul 2015
# Last Updated: 22 Mar 2016
# Updated for MC 1.10: 13 Sep 2016
# Updated to MC 1.11: 13 Jan 2017
# Verified for MC 1.12: 23 Jun 2017
# Updated to MC 1.12.1: 10 Sep 2017

biomesToSpawnIn=field,forest,flower forest,plains,sunflower pasture,plains,prairie,swampland,origin valley,brushland,coniferous forest,deciduous forest,eerie,eldritch,enchanted forest,flower field,fungi forest,fungi_forest,garden,grassland,grove,heathland,meadow,meadow forest,ominous woods,rwg_plains,thick ominous woods,thinned timber,orchard,seasonal forest,autumn hills,autumn woods,rwg_plains,mining biome,mutated_forest,mutated_plains,temperate_rainforest

weight=1
embed_into_distance=1

unacceptable_target_blocks=water,flowing_water,lava,flowing_lava,cloud,Natura:Cloud,slime_congealed,slime_dirt,slime_grass,command_block,planks,planks2,concrete,cobblestone,stonebrick,brick_block,glass,torch,oak_stairs,stone_stairs,brick_stairs,stone_brick_stairs,nether_brick_stairs,sandstone_stairs,spruce_stairs,birch_stairs,jungle_stairs,quartz_stairs,acacia_stairs,dark_oak_stairs,cobblestone_wall,stone_slab,double_stone_slab,stone_slab2,wooden_slab,double_wooden_slab,nether_brick,fence

dimensions=6,12,11
allowable_overhang=0
max_cut_in=0
cut_in_buffer=0
max_leveling=8
leveling_buffer=0
preserve_water=0
preserve_lava=0
preserve_plants=1

rule1=0,100,minecraft:grass-0
rule2=0,100,minecraft:dirt-0
rule3=0,100,minecraft:farmland-7
rule4=0,100,minecraft:water-0
rule5=0,100,minecraft:fence-0
rule6=0,75,minecraft:pumpkin-4
rule7=0,100,minecraft:pumpkin_stem-7,pumpkin_stem-1,pumpkin_stem-4
rule8=0,100,minecraft:wooden_slab-0
rule9=0,100,minecraft:fence_gate-3
rule10=0,100,minecraft:hay_block-0
rule11=0,100,minecraft:lit_pumpkin-3

layer
2,2,2,2,2,2,2,2,2,2,2
2,2,2,2,2,2,2,2,2,2,2
2,2,2,2,2,2,2,2,2,2,2
2,2,2,2,2,2,2,2,2,2,2
2,2,2,2,2,2,2,2,2,2,2
2,2,2,2,2,2,2,2,2,2,2
2,2,2,2,2,2,2,2,2,2,2
2,2,2,2,2,2,2,2,2,2,2
2,2,2,2,2,2,2,2,2,2,2
2,2,2,2,2,2,2,2,2,2,2
2,2,2,2,2,2,2,2,2,2,2
2,2,2,2,2,2,2,2,2,2,2
endlayer


layer
2,2,2,2,2,2,2,2,2,2,2
2,2,2,2,2,2,2,2,2,2,2
2,2,2,2,2,2,2,2,2,2,2
2,2,2,2,2,2,2,2,2,2,2
2,2,2,2,2,2,2,2,2,2,2
2,2,2,2,2,2,2,2,2,2,2
2,2,2,2,2,2,2,2,2,2,2
2,2,2,2,2,2,2,2,2,2,2
2,2,2,2,2,2,2,2,2,2,2
2,2,2,2,2,2,2,2,2,2,2
2,2,2,2,2,2,2,2,2,2,2
2,2,2,2,2,2,2,2,2,2,2
endlayer


layer
1,1,1,1,1,1,1,1,1,1,1
1,2,3,2,3,1,3,2,3,2,1
1,2,3,2,3,2,3,2,3,2,1
1,2,3,2,3,4,3,2,3,2,1
1,2,3,2,3,4,3,2,3,2,1
1,2,3,2,3,4,3,2,3,2,1
1,2,3,2,3,4,3,2,3,2,1
1,2,3,2,3,4,3,2,3,2,1
1,2,3,2,3,4,3,2,3,2,1
1,2,3,2,3,1,3,2,3,2,1
1,2,3,2,3,1,3,2,3,2,1
1,1,1,1,1,1,1,1,1,1,1
endlayer

layer
5,5,5,5,5,5,5,5,5,5,5
5,6,7,6,7,5,7,6,7,6,5
5,6,7,6,7,8,7,6,7,6,5
5,6,7,6,7,8,7,6,7,6,5
5,6,7,6,7,8,7,6,7,6,5
5,6,7,6,7,8,7,6,7,6,5
5,6,7,6,7,8,7,6,7,6,5
5,6,7,6,7,8,7,6,7,6,5
5,6,7,6,7,8,7,6,7,6,5
5,6,7,6,7,8,7,6,7,6,5
5,6,7,6,7,8,7,6,7,6,5
5,5,5,5,5,9,5,5,5,5,5
endlayer

layer
0,0,0,0,0,0,0,0,0,0,0
0,0,0,0,5,10,5,0,0,0,0
0,0,0,0,0,0,0,0,0,0,0
0,0,0,0,0,0,0,0,0,0,0
0,0,0,0,0,0,0,0,0,0,0
0,0,0,0,0,0,0,0,0,0,0
0,0,0,0,0,0,0,0,0,0,0
0,0,0,0,0,0,0,0,0,0,0
0,0,0,0,0,0,0,0,0,0,0
0,0,0,0,0,0,0,0,0,0,0
0,0,0,0,0,0,0,0,0,0,0
0,0,0,0,11,0,11,0,0,0,0
endlayer

layer
0,0,0,0,0,0,0,0,0,0,0
0,0,0,0,0,11,0,0,0,0,0
0,0,0,0,0,0,0,0,0,0,0
0,0,0,0,0,0,0,0,0,0,0
0,0,0,0,0,0,0,0,0,0,0
0,0,0,0,0,0,0,0,0,0,0
0,0,0,0,0,0,0,0,0,0,0
0,0,0,0,0,0,0,0,0,0,0
0,0,0,0,0,0,0,0,0,0,0
0,0,0,0,0,0,0,0,0,0,0
0,0,0,0,0,0,0,0,0,0,0
0,0,0,0,0,0,0,0,0,0,0
endlayer

