# Raised Railroad Ruin
# Created by Ruins mod version 13.8 Ingame Parser
# authoring Player: Jordan_Greywolf
# Updated for MC 1.8: 22 Jul 2015
# Last Updated MC 22 Mar 2016
# Updated for MC 1.10: 13 Sep 2016
# Updated to MC 1.11: 13 Jan 2017
# Verified for MC 1.12: 23 Jun 2017
# Updated to MC 1.12.1: 10 Sep 2017

biomesToSpawnIn=extreme hills,extreme hills edge,extreme hills+,extreme hills m,extreme hills+ m,forest,mesa,plains,alps,canyon,canyon ravine,crag,dead forest,dead_forest,dead swamp,dead_swamp,dry river,dry_river,mesa plateau,mesa plateau f,rwg_plains,sludgepit,thicket,thornlands,volcano,volcanic_island,wasteland,wetland,white_beachxeric shrubland,xeric_shrubland,mining biome,mining_biome,extreme_hills,smaller_extreme_hills,extreme_hills_with_trees,mutated_extreme_hills,mutated_extreme_hills_with_trees,mesa_rock,mesa_clear_rock

weight=1
embed_into_distance=8
acceptable_target_blocks=

unacceptable_target_blocks=water,flowing_water,lava,flowing_lava,cloud,Natura:Cloud,slime_congealed,slime_dirt,slime_grass,command_block,planks,planks2,concrete,cobblestone,stonebrick,brick_block,glass,torch,oak_stairs,stone_stairs,brick_stairs,stone_brick_stairs,nether_brick_stairs,sandstone_stairs,spruce_stairs,birch_stairs,jungle_stairs,quartz_stairs,acacia_stairs,dark_oak_stairs,cobblestone_wall,stone_slab,double_stone_slab,stone_slab2,wooden_slab,double_wooden_slab,nether_brick,fence

dimensions=14,41,5
allowable_overhang=0
max_leveling=5
leveling_buffer=-1
preserve_water=1
preserve_lava=1
preserve_plants=1

rule1=0,100,preserveBlock
rule2=0,100,minecraft:stonebrick-0,minecraft:stonebrick-0,minecraft:stonebrick-1,minecraft:stonebrick-2
rule3=0,100,minecraft:stonebrick-3
rule4=0,100,minecraft:stone_brick_stairs-4
rule5=0,100,minecraft:stone_brick_stairs-6
rule6=0,100,minecraft:stone_brick_stairs-7
rule7=0,100,minecraft:stone_brick_stairs-5
rule8=0,100,minecraft:stonebrick-3
rule9=0,100,minecraft:rail-1

rule10=0,90,minecraft:cobblestone_wall-0,minecraft:cobblestone_wall-0,minecraft:cobblestone_wall-1

rule11=0,100,minecraft:golden_rail-9

rule12=3,100,minecraft:cobblestone_wall-0,minecraft:cobblestone_wall-0,minecraft:cobblestone_wall-1

layer
1,1,1,1,1
1,1,1,1,1
1,1,1,1,1
1,2,1,2,1
1,1,1,1,1
1,1,1,1,1
1,1,1,1,1
1,1,1,1,1
1,1,1,1,1
1,1,1,1,1
1,2,1,2,1
1,1,1,1,1
1,1,1,1,1
1,1,1,1,1
1,1,1,1,1
1,1,1,1,1
1,1,1,1,1
1,2,1,2,1
1,1,1,1,1
1,1,1,1,1
1,1,1,1,1
1,1,1,1,1
1,1,1,1,1
1,1,1,1,1
1,2,1,2,1
1,1,1,1,1
1,1,1,1,1
1,1,1,1,1
1,1,1,1,1
1,1,1,1,1
1,1,1,1,1
1,2,1,2,1
1,1,1,1,1
1,1,1,1,1
1,1,1,1,1
1,1,1,1,1
1,1,1,1,1
1,1,1,1,1
1,2,1,2,1
1,1,1,1,1
1,1,1,1,1
endlayer

layer
1,1,1,1,1
1,1,1,1,1
1,1,1,1,1
1,2,1,2,1
1,1,1,1,1
1,1,1,1,1
1,1,1,1,1
1,1,1,1,1
1,1,1,1,1
1,1,1,1,1
1,2,1,2,1
1,1,1,1,1
1,1,1,1,1
1,1,1,1,1
1,1,1,1,1
1,1,1,1,1
1,1,1,1,1
1,2,1,2,1
1,1,1,1,1
1,1,1,1,1
1,1,1,1,1
1,1,1,1,1
1,1,1,1,1
1,1,1,1,1
1,2,1,2,1
1,1,1,1,1
1,1,1,1,1
1,1,1,1,1
1,1,1,1,1
1,1,1,1,1
1,1,1,1,1
1,2,1,2,1
1,1,1,1,1
1,1,1,1,1
1,1,1,1,1
1,1,1,1,1
1,1,1,1,1
1,1,1,1,1
1,2,1,2,1
1,1,1,1,1
1,1,1,1,1
endlayer

layer
1,1,1,1,1
1,1,1,1,1
1,1,1,1,1
1,2,1,2,1
1,1,1,1,1
1,1,1,1,1
1,1,1,1,1
1,1,1,1,1
1,1,1,1,1
1,1,1,1,1
1,2,1,2,1
1,1,1,1,1
1,1,1,1,1
1,1,1,1,1
1,1,1,1,1
1,1,1,1,1
1,1,1,1,1
1,2,1,2,1
1,1,1,1,1
1,1,1,1,1
1,1,1,1,1
1,1,1,1,1
1,1,1,1,1
1,1,1,1,1
1,2,1,2,1
1,1,1,1,1
1,1,1,1,1
1,1,1,1,1
1,1,1,1,1
1,1,1,1,1
1,1,1,1,1
1,2,1,2,1
1,1,1,1,1
1,1,1,1,1
1,1,1,1,1
1,1,1,1,1
1,1,1,1,1
1,1,1,1,1
1,2,1,2,1
1,1,1,1,1
1,1,1,1,1
endlayer

layer
1,1,1,1,1
1,1,1,1,1
1,1,1,1,1
1,2,1,2,1
1,1,1,1,1
1,1,1,1,1
1,1,1,1,1
1,1,1,1,1
1,1,1,1,1
1,1,1,1,1
1,2,1,2,1
1,1,1,1,1
1,1,1,1,1
1,1,1,1,1
1,1,1,1,1
1,1,1,1,1
1,1,1,1,1
1,2,1,2,1
1,1,1,1,1
1,1,1,1,1
1,1,1,1,1
1,1,1,1,1
1,1,1,1,1
1,1,1,1,1
1,2,1,2,1
1,1,1,1,1
1,1,1,1,1
1,1,1,1,1
1,1,1,1,1
1,1,1,1,1
1,1,1,1,1
1,2,1,2,1
1,1,1,1,1
1,1,1,1,1
1,1,1,1,1
1,1,1,1,1
1,1,1,1,1
1,1,1,1,1
1,2,1,2,1
1,1,1,1,1
1,1,1,1,1
endlayer

layer
1,1,1,1,1
1,1,1,1,1
1,1,1,1,1
1,2,1,2,1
1,1,1,1,1
1,1,1,1,1
1,1,1,1,1
1,1,1,1,1
1,1,1,1,1
1,1,1,1,1
1,2,1,2,1
1,1,1,1,1
1,1,1,1,1
1,1,1,1,1
1,1,1,1,1
1,1,1,1,1
1,1,1,1,1
1,2,1,2,1
1,1,1,1,1
1,1,1,1,1
1,1,1,1,1
1,1,1,1,1
1,1,1,1,1
1,1,1,1,1
1,2,1,2,1
1,1,1,1,1
1,1,1,1,1
1,1,1,1,1
1,1,1,1,1
1,1,1,1,1
1,1,1,1,1
1,2,1,2,1
1,1,1,1,1
1,1,1,1,1
1,1,1,1,1
1,1,1,1,1
1,1,1,1,1
1,1,1,1,1
1,2,1,2,1
1,1,1,1,1
1,1,1,1,1
endlayer

layer
1,1,1,1,1
1,1,1,1,1
1,1,1,1,1
1,2,1,2,1
1,1,1,1,1
1,1,1,1,1
1,1,1,1,1
1,1,1,1,1
1,1,1,1,1
1,1,1,1,1
1,2,1,2,1
1,1,1,1,1
1,1,1,1,1
1,1,1,1,1
1,1,1,1,1
1,1,1,1,1
1,1,1,1,1
1,2,1,2,1
1,1,1,1,1
1,1,1,1,1
1,1,1,1,1
1,1,1,1,1
1,1,1,1,1
1,1,1,1,1
1,2,1,2,1
1,1,1,1,1
1,1,1,1,1
1,1,1,1,1
1,1,1,1,1
1,1,1,1,1
1,1,1,1,1
1,2,1,2,1
1,1,1,1,1
1,1,1,1,1
1,1,1,1,1
1,1,1,1,1
1,1,1,1,1
1,1,1,1,1
1,2,1,2,1
1,1,1,1,1
1,1,1,1,1
endlayer


layer
1,1,1,1,1
1,1,1,1,1
1,1,1,1,1
1,2,1,2,1
1,1,1,1,1
1,1,1,1,1
1,1,1,1,1
1,1,1,1,1
1,1,1,1,1
1,1,1,1,1
1,2,1,2,1
1,1,1,1,1
1,1,1,1,1
1,1,1,1,1
1,1,1,1,1
1,1,1,1,1
1,1,1,1,1
1,2,1,2,1
1,1,1,1,1
1,1,1,1,1
1,1,1,1,1
1,1,1,1,1
1,1,1,1,1
1,1,1,1,1
1,2,1,2,1
1,1,1,1,1
1,1,1,1,1
1,1,1,1,1
1,1,1,1,1
1,1,1,1,1
1,1,1,1,1
1,2,1,2,1
1,1,1,1,1
1,1,1,1,1
1,1,1,1,1
1,1,1,1,1
1,1,1,1,1
1,1,1,1,1
1,2,1,2,1
1,1,1,1,1
1,1,1,1,1
endlayer


layer
1,1,1,1,1
1,1,1,1,1
1,1,1,1,1
1,2,1,2,1
1,1,1,1,1
1,1,1,1,1
1,1,1,1,1
1,1,1,1,1
1,1,1,1,1
1,1,1,1,1
1,2,1,2,1
1,1,1,1,1
1,1,1,1,1
1,1,1,1,1
1,1,1,1,1
1,1,1,1,1
1,1,1,1,1
1,2,1,2,1
1,1,1,1,1
1,1,1,1,1
1,1,1,1,1
1,1,1,1,1
1,1,1,1,1
1,1,1,1,1
1,2,1,2,1
1,1,1,1,1
1,1,1,1,1
1,1,1,1,1
1,1,1,1,1
1,1,1,1,1
1,1,1,1,1
1,2,1,2,1
1,1,1,1,1
1,1,1,1,1
1,1,1,1,1
1,1,1,1,1
1,1,1,1,1
1,1,1,1,1
1,2,1,2,1
1,1,1,1,1
1,1,1,1,1
endlayer

layer
1,1,1,1,1
1,1,1,1,1
1,1,1,1,1
1,2,1,2,1
1,1,1,1,1
1,1,1,1,1
1,1,1,1,1
1,1,1,1,1
1,1,1,1,1
1,1,1,1,1
1,2,1,2,1
1,1,1,1,1
1,1,1,1,1
1,1,1,1,1
1,1,1,1,1
1,1,1,1,1
1,1,1,1,1
1,2,1,2,1
1,1,1,1,1
1,1,1,1,1
1,1,1,1,1
1,1,1,1,1
1,1,1,1,1
1,1,1,1,1
1,2,1,2,1
1,1,1,1,1
1,1,1,1,1
1,1,1,1,1
1,1,1,1,1
1,1,1,1,1
1,1,1,1,1
1,2,1,2,1
1,1,1,1,1
1,1,1,1,1
1,1,1,1,1
1,1,1,1,1
1,1,1,1,1
1,1,1,1,1
1,2,1,2,1
1,1,1,1,1
1,1,1,1,1
endlayer

layer
0,0,0,0,0
0,0,0,0,0
0,0,0,0,0
0,3,0,3,0
0,0,0,0,0
0,0,0,0,0
0,0,0,0,0
0,0,0,0,0
0,0,0,0,0
0,0,0,0,0
0,2,0,2,0
0,0,0,0,0
0,0,0,0,0
0,0,0,0,0
0,0,0,0,0
0,0,0,0,0
0,0,0,0,0
0,2,0,2,0
0,0,0,0,0
0,0,0,0,0
0,0,0,0,0
0,0,0,0,0
0,0,0,0,0
0,0,0,0,0
0,2,0,2,0
0,0,0,0,0
0,0,0,0,0
0,0,0,0,0
0,0,0,0,0
0,0,0,0,0
0,0,0,0,0
0,2,0,2,0
0,0,0,0,0
0,0,0,0,0
0,0,0,0,0
0,0,0,0,0
0,0,0,0,0
0,0,0,0,0
0,2,0,2,0
0,0,0,0,0
0,0,0,0,0
endlayer

layer
0,0,0,0,0
0,0,0,0,0
0,4,0,4,0
6,2,2,2,5
0,7,0,7,0
0,0,0,0,0
0,0,0,0,0
0,0,0,0,0
0,0,0,0,0
0,4,0,4,0
6,3,2,3,5
0,7,0,7,0
0,0,0,0,0
0,0,0,0,0
0,0,0,0,0
0,0,0,0,0
0,4,0,4,0
6,3,2,3,5
0,7,0,7,0
0,0,0,0,0
0,0,0,0,0
0,0,0,0,0
0,0,0,0,0
0,4,0,4,0
6,3,2,3,5
0,7,0,7,0
0,0,0,0,0
0,0,0,0,0
0,0,0,0,0
0,0,0,0,0
0,4,0,4,0
6,3,2,3,5
0,7,0,7,0
0,0,0,0,0
0,0,0,0,0
0,0,0,0,0
0,0,0,0,0
0,4,0,4,0
6,3,2,3,5
0,7,0,7,0
0,0,0,0,0
endlayer

layer
0,0,2,0,0
6,2,2,2,0
2,2,2,2,2
3,8,2,8,3
2,2,2,2,2
6,2,2,2,5
6,2,2,2,5
6,2,2,2,5
6,2,2,2,5
2,2,2,2,2
3,8,2,8,3
2,2,2,2,2
6,2,2,2,5
6,2,2,2,5
6,2,2,2,5
6,2,2,2,5
2,2,2,2,2
3,8,2,8,3
2,2,2,2,2
6,2,2,2,5
6,2,2,2,5
6,2,2,2,5
6,2,2,2,5
2,2,2,2,2
3,8,2,8,3
2,2,2,2,2
6,2,2,2,5
6,2,2,2,5
6,2,2,2,5
6,2,2,2,5
2,2,2,2,2
3,8,2,8,3
2,2,2,2,2
6,2,2,2,5
6,2,2,2,5
6,2,2,2,5
6,2,2,2,5
2,2,2,2,2
3,8,2,8,3
2,2,2,2,0
6,0,2,0,0
endlayer

layer
0,0,0,0,0
10,9,0,9,0
10,9,0,9,10
10,11,0,11,10
10,9,0,9,10
10,9,0,9,10
10,9,0,9,10
10,9,0,9,10
10,9,0,9,10
10,9,0,9,10
10,11,0,11,10
10,9,0,9,10
10,9,0,9,10
10,9,0,9,10
10,9,0,9,10
10,9,0,9,10
10,9,0,9,10
10,11,0,11,10
10,9,0,9,10
10,9,0,9,10
10,9,0,9,10
10,9,0,9,10
10,9,0,9,10
10,9,0,9,10
10,11,0,11,10
10,9,0,9,10
10,9,0,9,10
10,9,0,9,10
10,9,0,9,10
10,9,0,9,10
10,9,0,9,10
10,11,0,11,10
10,9,0,9,10
10,9,0,9,10
10,9,0,9,10
10,9,0,9,10
10,9,0,9,10
10,9,0,9,10
10,11,0,11,10
10,9,0,9,0
10,0,0,0,0
endlayer

layer
0,0,0,0,0
12,0,0,0,0
12,0,0,0,12
12,0,0,0,12
12,0,0,0,12
12,0,0,0,12
12,0,0,0,12
12,0,0,0,12
12,0,0,0,12
12,0,0,0,12
12,0,0,0,12
12,0,0,0,12
12,0,0,0,12
12,0,0,0,12
12,0,0,0,12
12,0,0,0,12
12,0,0,0,12
12,0,0,0,12
12,0,0,0,12
12,0,0,0,12
12,0,0,0,12
12,0,0,0,12
12,0,0,0,12
12,0,0,0,12
12,0,0,0,12
12,0,0,0,12
12,0,0,0,12
12,0,0,0,12
12,0,0,0,12
12,0,0,0,12
12,0,0,0,12
12,0,0,0,12
12,0,0,0,12
12,0,0,0,12
12,0,0,0,12
12,0,0,0,12
12,0,0,0,12
12,0,0,0,12
12,0,0,0,12
12,0,0,0,0
12,0,0,0,0
endlayer



