# Shrine of Stained Glass (ruined)
# 26 Apr 2014; updated to MC 1.7.10, 10 Oct 2014
# Created by Ruins mod version 12.3 Ingame Parser
# authoring Player: Jordan_Greywolf
# Updated for MC 1.8: 22 Jul 2015
# Updated for MC 1.9: 17 Apr 2016
# Updated for MC 1.10: 13 Sep 2016
# Updated to MC 1.11: 13 Jan 2017
# Verified for MC 1.12: 23 Jun 2017
# Updated to MC 1.12.1: 10 Sep 2017

# Last Updated: 9 Jun 2018


biomesToSpawnIn=dead forest,dead_forest,dead swamp,dead_swamp,dreadlands,extreme hills,extreme hills edge,oak savanna,oak_savanna,plains,roofed forest,roofed forest m,rwg_plains,green_swamp,lush_swamp,swampland,swampland m,forest,wasteland,badlands,ominous woods,thick ominous woods,eerie,eldritch,tainted land,eerie,magical forest,witherlands,xeric shrubland,xeric_shrubland,extreme_hills,smaller_extreme_hills,roofed_forest,mutated_roofed_forest

weight=1
embed_into_distance=4

preventRotation=1
uniqueMinDistance=1000
spawnMinDistance=500

unacceptable_target_blocks=brown_mushroom_block,red_mushroom_block,lava,flowing_lava,water,flowing_water,cloud,Natura:Cloud,slime_congealed,slime_dirt,slime_grass,command_block,planks,planks2,concrete,cobblestone,stonebrick,brick_block,glass,torch,oak_stairs,stone_stairs,brick_stairs,stone_brick_stairs,nether_brick_stairs,sandstone_stairs,spruce_stairs,birch_stairs,jungle_stairs,quartz_stairs,acacia_stairs,dark_oak_stairs,cobblestone_wall,stone_slab,double_stone_slab,stone_slab2,wooden_slab,double_wooden_slab,nether_brick,fence

dimensions=21,12,12
allowable_overhang=12
max_cut_in=0
cut_in_buffer=0
max_leveling=6
leveling_buffer=-1
preserve_water=1
preserve_lava=0
preserve_plants=1

rule1=0,100,preserveBlock

rule2=0,100,minecraft:stonebrick,minecraft:stonebrick-1,minecraft:stonebrick-2

rule3=0,100,minecraft:nether_brick-0
rule4=0,100,minecraft:wool-0
rule5=0,100,minecraft:stonebrick-2
rule6=0,100,minecraft:stone_slab-6
rule7=0,100,minecraft:spruce_stairs-7
rule8=0,100,minecraft:spruce_stairs-6
rule9=0,100,minecraft:spruce_stairs-0
rule10=0,100,preserveBlock
rule11=0,100,minecraft:stonebrick-1
rule12=0,100,minecraft:nether_brick_fence-0

# Dark Stained Glass
rule13=0,100,minecraft:stained_glass_pane-11,minecraft:stained_glass_pane-9,minecraft:stained_glass_pane-13

rule14=0,100,preserveBlock
rule15=0,100,preserveBlock
rule16=0,100,minecraft:planks-1

# Light Stained Glass
rule17=0,100,minecraft:stained_glass_pane-4,minecraft:stained_glass_pane-3,minecraft:stained_glass_pane-0,minecraft:stained_glass_pane-2

rule18=0,100,minecraft:spruce_stairs-2
rule19=0,100,minecraft:spruce_stairs-3
rule20=0,100,minecraft:cobblestone_wall-1

rule21=0,100,minecraft:web-0
rule22=0,100,MobSpawner:Spider
rule23=0,100,ChestGenHook:chests/simple_dungeon:3-5
rule24=0,100,minecraft:ladder-5

rule25=0,100,ChestGenHook:chests/jungle_temple:3-5

# -4
layer
1,2,2,1,1,1,1,1,1,2,2,1
2,2,2,2,2,2,2,2,2,2,2,2
2,2,2,3,3,3,3,3,3,2,2,2
2,2,3,3,3,3,3,3,3,3,2,2
2,2,3,3,3,3,3,3,3,3,2,2
2,2,3,3,3,3,3,3,3,3,2,2
2,2,3,3,3,3,3,3,3,3,2,2
2,2,3,3,3,3,3,3,3,3,2,2
2,2,3,3,3,3,3,3,3,3,2,2
2,2,2,3,3,3,3,3,3,2,2,2
2,2,2,2,2,2,2,2,2,2,2,2
1,2,2,1,1,2,2,1,1,2,2,1
endlayer

# -3
layer
1,2,2,1,1,1,1,1,1,2,2,1
2,2,2,2,2,2,2,2,2,2,2,2
2,2,2,21,21,23,25,21,21,2,2,2
2,2,21,21,0,2,2,0,21,21,2,2
2,2,0,0,0,24,24,0,0,0,2,2
2,2,0,0,0,0,0,0,0,0,2,2
2,2,0,0,0,0,0,0,0,0,2,2
2,2,21,0,0,0,0,0,0,21,2,2
2,2,21,0,0,0,0,0,0,21,2,2
2,2,2,21,21,0,0,21,21,2,2,2
2,2,2,2,2,2,2,2,2,2,2,2
1,2,2,1,1,2,2,1,1,2,2,1
endlayer

# -2
layer
1,2,2,1,1,1,1,1,1,2,2,1
2,2,2,2,2,2,2,2,2,2,2,2
2,2,2,21,0,22,22,0,21,2,2,2
2,2,21,0,0,2,2,0,0,21,2,2
2,2,0,0,0,24,24,0,0,0,2,2
2,2,0,0,0,0,0,0,0,0,2,2
2,2,0,0,0,0,0,0,0,0,2,2
2,2,0,0,0,0,0,0,0,0,2,2
2,2,21,0,0,0,0,0,0,21,2,2
2,2,2,21,0,0,0,0,21,2,2,2
2,2,2,2,2,2,2,2,2,2,2,2
1,2,2,1,1,2,2,1,1,2,2,1
endlayer

# -1
layer
1,2,2,1,1,1,1,1,1,2,2,1
2,2,2,2,2,2,2,2,2,2,2,2
2,2,2,21,21,0,0,21,21,2,2,2
2,2,21,0,0,2,2,0,21,21,2,2
2,2,0,0,0,24,24,0,0,21,2,2
2,2,0,0,0,0,0,0,0,0,2,2
2,2,0,0,0,0,0,0,0,0,2,2
2,2,21,0,0,0,0,0,0,21,2,2
2,2,21,21,0,0,0,0,21,21,2,2
2,2,2,21,21,0,0,21,21,2,2,2
2,2,2,2,2,2,2,2,2,2,2,2
1,2,2,1,1,2,2,1,1,2,2,1
endlayer


layer
1,2,2,1,1,1,1,1,1,2,2,1
2,2,2,2,2,2,2,2,2,2,2,2
2,2,2,3,3,3,3,3,3,2,2,2
1,2,3,3,3,3,3,3,3,3,2,1
1,2,3,3,3,4,4,3,3,3,2,1
1,2,3,3,3,3,3,3,3,3,2,1
1,5,3,3,3,3,3,3,3,3,2,1
1,2,3,3,3,3,3,3,3,3,2,1
1,2,3,3,3,3,3,3,3,3,2,1
2,2,2,3,3,3,3,3,3,2,2,2
2,2,2,2,2,3,3,2,2,2,2,2
1,2,2,1,1,6,6,1,1,2,2,1
endlayer

layer
1,2,2,1,1,1,1,1,1,2,2,1
2,2,2,2,2,2,2,2,2,2,2,2
2,2,2,3,3,3,3,3,3,2,2,5
1,2,1,3,1,8,7,1,3,1,2,1
1,2,1,1,1,1,1,1,1,1,2,1
1,2,1,1,1,1,1,1,1,1,2,1
1,5,1,9,9,1,1,9,9,1,5,1
1,2,1,1,1,1,1,1,1,1,2,1
1,2,1,9,9,1,1,9,9,1,2,1
2,2,2,1,1,1,1,1,1,2,2,5
2,2,2,2,2,10,10,2,2,2,2,2
1,2,2,1,1,1,1,1,1,2,2,1
endlayer

layer
1,11,11,1,1,1,1,1,1,11,11,1
11,1,1,11,11,11,11,11,11,1,1,11
11,1,11,1,12,1,1,12,1,11,1,5
1,11,1,12,1,1,1,1,12,1,11,1
1,13,1,1,1,1,1,1,1,1,13,1
1,13,1,1,1,1,1,1,1,1,13,1
1,1,1,1,1,1,1,1,1,1,1,1
1,13,1,1,1,1,1,1,1,1,13,1
1,11,1,1,1,1,1,1,1,1,11,1
5,1,11,1,1,1,1,1,1,11,1,5
11,1,1,11,5,15,14,11,11,1,1,11
1,11,5,1,1,1,1,1,1,11,5,1
endlayer

layer
1,11,11,1,1,1,1,1,1,11,5,1
5,1,1,11,13,13,13,13,11,1,1,11
11,1,11,1,1,1,1,1,1,11,1,11
1,11,12,1,1,1,1,1,1,12,11,1
1,13,1,1,1,1,1,1,1,1,13,1
1,13,1,1,1,1,1,1,1,1,13,1
1,1,1,1,1,1,1,1,1,1,1,1
1,13,1,1,1,1,1,1,1,1,13,1
1,11,1,1,1,1,1,1,1,1,11,1
11,1,11,12,1,1,1,1,12,11,1,11
11,1,1,11,11,11,11,5,11,1,1,11
1,11,5,1,1,1,1,1,1,5,11,1
endlayer

layer
1,11,5,1,1,1,1,1,1,11,5,1
11,1,1,11,13,13,13,13,11,1,1,11
11,1,11,1,1,1,1,1,1,11,1,11
16,11,1,1,1,1,1,1,1,1,11,16
16,11,1,1,1,1,1,1,1,1,11,16
1,11,1,1,1,1,1,1,1,1,11,1
1,1,1,1,1,1,1,1,1,1,1,1
16,11,1,1,1,1,1,1,1,1,11,16
16,11,1,1,1,1,1,1,1,1,11,16
11,1,11,1,1,1,1,1,1,11,1,11
11,1,1,11,11,11,11,11,11,1,1,5
1,11,11,1,1,1,1,1,1,5,11,1
endlayer

layer
1,11,11,1,1,1,1,1,1,11,11,1
11,1,1,11,13,17,17,13,11,1,1,5
11,1,11,1,1,1,1,1,1,11,1,11
19,11,1,1,1,1,1,1,1,1,11,18
19,16,1,1,1,1,1,1,1,1,16,18
1,1,1,1,1,1,1,1,1,1,1,1
1,1,1,1,1,1,1,1,1,1,1,1
19,16,1,1,1,1,1,1,1,1,16,18
19,11,1,1,1,1,1,1,1,1,11,18
11,1,11,1,1,1,1,1,1,11,1,11
11,1,1,11,11,13,13,11,11,1,1,11
1,11,11,1,1,1,1,1,1,11,11,1
endlayer

layer
1,11,11,1,1,1,1,1,1,5,11,1
11,1,1,11,13,17,17,13,11,1,1,5
11,1,11,1,1,1,1,1,1,11,1,11
1,11,16,1,1,1,1,1,1,16,11,1
1,19,16,1,1,1,1,1,1,16,18,1
1,1,1,1,1,1,1,1,1,1,1,1
1,1,1,1,1,1,1,1,1,1,1,1
1,19,16,1,1,1,1,1,1,16,18,1
1,11,16,1,1,1,1,1,1,16,11,1
11,1,11,1,1,1,1,1,1,11,1,11
11,1,1,11,13,17,17,13,11,1,1,11
1,11,11,1,1,1,1,1,1,11,11,1
endlayer

layer
1,11,11,1,1,1,1,1,1,5,11,1
11,1,1,11,11,13,13,11,11,1,1,5
11,1,11,1,1,1,1,1,1,11,1,11
1,11,16,1,1,1,1,1,1,16,11,1
1,1,16,1,1,1,1,1,1,16,1,1
1,1,1,1,1,1,1,1,1,1,1,1
1,1,1,1,1,1,1,1,1,1,1,1
1,1,16,1,1,1,1,1,1,16,1,1
1,11,16,1,1,1,1,1,1,16,11,1
11,1,11,1,1,1,1,1,1,11,1,11
11,1,1,11,13,17,17,13,11,1,1,11
1,11,11,1,1,1,1,1,1,11,11,1
endlayer

layer
1,11,11,5,1,1,1,1,5,11,11,1
11,1,1,11,11,13,13,11,11,1,1,5
11,1,11,16,1,1,1,1,16,11,1,11
1,5,19,16,1,1,1,1,16,18,11,1
1,1,19,16,1,1,1,1,16,18,1,1
1,1,1,1,1,1,1,1,1,1,1,1
1,1,1,1,1,1,1,1,1,1,1,1
1,1,1,1,1,1,1,1,16,18,1,1
1,11,19,16,1,1,1,1,16,18,11,1
11,1,11,16,1,1,1,1,16,11,1,11
11,1,1,16,11,13,13,11,16,1,1,11
1,11,11,16,1,1,1,1,16,11,11,1
endlayer

layer
1,11,11,11,1,1,1,1,11,11,11,1
11,1,1,11,11,11,11,11,11,1,1,11
11,1,11,16,1,1,1,1,16,11,1,11
1,5,1,16,1,1,1,1,16,1,11,1
1,1,1,16,1,1,1,1,1,1,1,1
1,1,1,1,1,1,1,1,1,1,1,1
1,1,1,1,1,1,1,1,1,1,1,1
1,1,1,1,1,1,1,1,16,1,1,1
1,11,1,1,1,1,1,1,16,1,11,1
11,1,11,16,1,1,1,1,16,11,1,11
11,1,1,16,11,11,11,11,16,1,1,11
1,11,11,16,1,1,1,1,16,11,11,1
endlayer

layer
1,5,20,19,16,1,1,16,18,20,5,1
5,11,5,19,16,5,11,16,18,5,11,5
20,5,11,19,16,1,1,16,18,11,5,20
1,20,1,19,16,1,1,16,18,1,20,1
1,1,1,19,1,1,1,1,1,1,1,1
1,1,1,1,1,1,1,1,1,1,1,1
1,1,1,1,1,1,1,1,1,1,1,1
1,1,1,1,1,1,1,1,18,1,1,1
1,20,1,1,1,1,1,16,18,1,20,1
20,5,11,1,16,1,1,16,18,11,5,20
5,11,5,19,16,11,11,16,18,5,11,5
1,5,20,19,16,1,1,16,18,20,5,1
endlayer

layer
1,5,1,1,16,1,1,16,1,1,5,1
5,5,5,1,16,5,5,16,1,5,5,5
1,5,20,1,16,1,1,16,1,20,5,1
1,1,1,1,1,1,1,1,1,1,1,1
1,1,1,1,1,1,1,1,1,1,1,1
1,1,1,1,1,1,1,1,1,1,1,1
1,1,1,1,1,1,1,1,1,1,1,1
1,1,1,1,1,1,1,1,1,1,1,1
1,1,1,1,1,1,1,16,1,1,1,1
1,5,20,1,16,1,1,16,1,20,5,1
5,5,5,1,16,11,11,16,1,5,5,5
1,5,1,1,16,1,1,16,1,1,5,1
endlayer

layer
1,20,1,1,19,16,16,18,1,1,20,1
20,5,20,1,19,16,16,18,1,20,5,20
1,20,1,1,19,16,16,18,1,1,20,1
1,1,1,1,1,1,1,1,1,1,1,1
1,1,1,1,1,1,1,1,1,1,1,1
1,1,1,1,1,1,1,1,1,1,1,1
1,1,1,1,1,1,1,1,1,1,1,1
1,1,1,1,1,1,1,1,1,1,1,1
1,1,1,1,1,1,1,1,1,1,1,1
1,20,1,1,19,16,16,18,1,1,20,1
20,5,20,1,19,16,16,18,1,20,5,20
1,20,1,1,19,16,16,18,1,1,20,1
endlayer

layer
1,1,1,1,1,19,18,1,1,1,1,1
1,5,1,1,1,19,18,1,1,1,5,1
1,1,1,1,1,1,18,1,1,1,1,1
1,1,1,1,1,1,1,1,1,1,1,1
1,1,1,1,1,1,1,1,1,1,1,1
1,1,1,1,1,1,1,1,1,1,1,1
1,1,1,1,1,1,1,1,1,1,1,1
1,1,1,1,1,1,1,1,1,1,1,1
1,1,1,1,1,1,1,1,1,1,1,1
1,1,1,1,1,19,18,1,1,1,1,1
1,5,1,1,1,19,18,1,1,1,5,1
1,1,1,1,1,19,18,1,1,1,1,1
endlayer

layer
1,1,1,1,1,1,1,1,1,1,1,1
1,5,1,1,1,1,1,1,1,1,5,1
1,1,1,1,1,1,1,1,1,1,1,1
1,1,1,1,1,1,1,1,1,1,1,1
1,1,1,1,1,1,1,1,1,1,1,1
1,1,1,1,1,1,1,1,1,1,1,1
1,1,1,1,1,1,1,1,1,1,1,1
1,1,1,1,1,1,1,1,1,1,1,1
1,1,1,1,1,1,1,1,1,1,1,1
1,1,1,1,1,1,1,1,1,1,1,1
1,5,1,1,1,1,1,1,1,1,5,1
1,1,1,1,1,1,1,1,1,1,1,1
endlayer

layer
1,1,1,1,1,1,1,1,1,1,1,1
1,20,1,1,1,1,1,1,1,1,20,1
1,1,1,1,1,1,1,1,1,1,1,1
1,1,1,1,1,1,1,1,1,1,1,1
1,1,1,1,1,1,1,1,1,1,1,1
1,1,1,1,1,1,1,1,1,1,1,1
1,1,1,1,1,1,1,1,1,1,1,1
1,1,1,1,1,1,1,1,1,1,1,1
1,1,1,1,1,1,1,1,1,1,1,1
1,1,1,1,1,1,1,1,1,1,1,1
1,20,1,1,1,1,1,1,1,1,20,1
1,1,1,1,1,1,1,1,1,1,1,1
endlayer

layer
1,1,1,1,1,1,1,1,1,1,1,1
1,20,1,1,1,1,1,1,1,1,20,1
1,1,1,1,1,1,1,1,1,1,1,1
1,1,1,1,1,1,1,1,1,1,1,1
1,1,1,1,1,1,1,1,1,1,1,1
1,1,1,1,1,1,1,1,1,1,1,1
1,1,1,1,1,1,1,1,1,1,1,1
1,1,1,1,1,1,1,1,1,1,1,1
1,1,1,1,1,1,1,1,1,1,1,1
1,1,1,1,1,1,1,1,1,1,1,1
1,20,1,1,1,1,1,1,1,1,20,1
1,1,1,1,1,1,1,1,1,1,1,1
endlayer



