# SheepBarn -- Fantasy Barn (Intact, Run-Down)
# 24 Sep 2014 - Minecraft 1.7.10
# Created by Ruins mod version 13.8 Ingame Parser
# authoring Player: Jordan_Greywolf
# Updated to MC 1.8: 5 Mar 2016
# Updated to MC 1.9: 17 Apr 2016
# Updated to MC 1.10: 13 Sep 2016
# Updated to MC 1.11: 13 Jan 2017
# Verified for MC 1.12: 23 Jun 2017
# Updated to MC 1.12.1: 10 Sep 2017

# Last Updated: 9 Jun 2018

biomesToSpawnIn=plains,forest,extreme hills edge,lavender fields,lavender_fields,flower field,flower_field,flower forest,rwg_plains,sunflower plains,shrubland,heathland,scrubland,highland,smaller_extreme_hills,mutated_forest,mutated_plains,steppe,wetland

spawnMinDistance=500

weight=1
embed_into_distance=4
acceptable_target_blocks=

unacceptable_target_blocks=flowing_water,water,flowing_lava,lava,cloud,Natura:Cloud,slime_congealed,slime_dirt,slime_grass,command_block,planks,planks2,concrete,cobblestone,stonebrick,brick_block,glass,torch,oak_stairs,stone_stairs,brick_stairs,stone_brick_stairs,nether_brick_stairs,sandstone_stairs,spruce_stairs,birch_stairs,jungle_stairs,quartz_stairs,acacia_stairs,dark_oak_stairs,cobblestone_wall,stone_slab,double_stone_slab,stone_slab2,wooden_slab,double_wooden_slab,nether_brick,fence

dimensions=16,20,20
allowable_overhang=0
max_leveling=2
leveling_buffer=-1
preserve_water=0
preserve_lava=0
preserve_plants=1

# Terrain Buffering (preserve some of surrounding slope)
rule1=0,100,preserveBlock

rule2=0,100,minecraft:grass-0
rule3=0,100,minecraft:dirt-0

# Stone Walls (random cobblestone / mossy_cobblestone)
rule4=0,100,minecraft:mossy_cobblestone-0,minecraft:cobblestone-0

# Basement Floor
rule5=0,100,minecraft:stone-0

# Paved Steps / Corral Corner
rule6=0,100,minecraft:double_stone_slab-0

# Well & Springs
rule7=0,100,minecraft:flowing_water

# Spider Mob Spawners
rule8=0,100,MobSpawner:Cave_Spider,MobSpawner:Spider

rule9=0,100,minecraft:spruce_stairs-3

# Cobwebs Everywhere!
rule10=0,100,minecraft:web-0

# Hay Bales
rule11=0,100,minecraft:hay_block-0

rule12=0,100,minecraft:spruce_stairs-5

# Trapped Treasure Chest
rule13=0,100,IInventory;minecraft:trapped_chest;minecraft:wheat#4#0#0+minecraft:dye#4#1#1+minecraft:dye#4#9#2+minecraft:dye#4#5#3+minecraft:dye#4#6#4+minecraft:grass#4#0#5+minecraft:acacia_fence#8#0#6+minecraft:log#4#0#7+minecraft:dye#4#11#8-2

rule14=0,100,minecraft:tnt

rule15=0,100,IInventory;minecraft:trapped_chest;minecraft:dye#4#14#0+minecraft:dye#4#13#1+minecraft:dye#4#12#2+minecraft:dye#4#11#3+minecraft:dye#4#10#4+minecraft:shears#1#0#5+minecraft:dye#4#7#6+minecraft:dye#4#8#7-2

rule16=0,100,minecraft:spruce_stairs-0

# Farm Animal Mob Spawner (doesn't necessarily actually work)
rule17=0,100,MobSpawner:Sheep

# Spruce Planks (flooring)
rule18=0,100,minecraft:planks-1

# Oak Planks (walls, roof)
rule19=0,100,minecraft:planks-0

rule20=0,100,minecraft:oak_stairs-0

# Randomized Cobblestone Wall
rule21=0,100,minecraft:cobblestone_wall-1,minecraft:cobblestone_wall-0

rule22=0,100,minecraft:oak_stairs-2
rule23=0,100,minecraft:oak_stairs-3

# Randomized Plants
rule24=0,100,minecraft:tallgrass-1,minecraft:tallgrass-1,minecraft:tallgrass-1,minecraft:tallgrass-1,minecraft:tallgrass-1,minecraft:yellow_flower,minecraft:red_flower-3,minecraft:red_flower-8

rule25=0,100,minecraft:oak_stairs-1
rule26=1,100,minecraft:acacia_fence_gate-0

# Note: Setting doors to rule "1" seems to make them less likely to
# "pop" when building spawns.
rule27=1,100,minecraft:acacia_door-2

rule28=0,100,minecraft:acacia_fence-0

# Note: Set to rule "2" to make it less likely to "pop" when spawning.
rule29=2,100,minecraft:ladder-5

rule30=1,100,minecraft:wooden_pressure_plate-0
rule31=1,100,minecraft:acacia_door-0
rule32=1,100,minecraft:acacia_fence_gate-1
rule33=1,100,minecraft:acacia_door-1
rule34=1,100,minecraft:acacia_door-3
rule35=1,100,minecraft:acacia_fence_gate-3
rule36=0,100,minecraft:log-0
rule37=1,100,minecraft:acacia_door-9
rule38=1,100,minecraft:acacia_door-8
rule39=0,100,minecraft:wooden_slab-0
rule40=0,100,minecraft:oak_stairs-4
rule41=0,100,minecraft:log-8
rule42=0,100,minecraft:log-4
rule43=0,100,minecraft:wooden_slab-9

# Dispenser (Sheep Spawn Egg)
#rule44=0,100,IInventory;minecraft:dispenser;minecraft:spawn_egg#{EntityTag:{id:sheep}}#91#0-0
rule44=0,100,CommandBlock:RUINSTRIGGER /summon sheep ~0 ~-1 ~0:@

# Note: Old redstone torch trigger doesn't work in current version.
rule45=1,100,minecraft:hay_block

rule46=0,100,minecraft:oak_stairs-5
rule47=0,100,minecraft:wooden_slab-8
rule48=0,100,minecraft:oak_stairs-6
rule49=0,100,minecraft:oak_stairs-7



layer
1,1,1,3,4,4,4,4,4,4,4,4,4,4,4,4,3,2,1,1
1,1,2,3,4,5,5,5,5,5,5,5,5,5,5,4,3,3,2,1
1,1,3,3,4,5,5,5,5,5,5,5,5,5,5,4,3,3,2,1
1,2,3,3,4,5,5,5,5,5,5,5,5,5,5,4,3,3,2,1
1,2,3,3,4,5,5,5,5,5,5,5,5,5,5,4,3,3,2,1
1,3,3,3,4,5,5,5,5,5,5,5,5,5,5,4,3,3,3,2
2,3,3,3,4,4,4,4,4,4,4,4,4,4,4,4,3,3,3,3
2,3,3,3,5,5,5,5,5,5,5,5,5,5,5,4,3,3,3,3
3,3,3,3,4,5,5,5,5,5,5,5,5,5,5,4,3,3,3,3
3,3,3,3,4,5,5,5,5,5,5,5,5,5,5,4,3,3,3,3
3,3,3,3,4,5,5,5,5,5,5,5,5,5,5,4,3,3,3,3
2,3,3,3,4,5,5,5,5,5,5,5,5,5,5,4,3,3,3,2
2,3,3,3,4,5,5,5,5,5,5,5,5,5,5,4,3,3,3,2
1,3,3,3,4,4,4,5,5,5,5,5,5,5,5,4,3,3,2,1
1,2,3,3,4,4,4,5,5,5,5,5,5,5,5,4,3,3,2,1
1,2,3,3,4,4,4,4,4,4,4,4,4,4,4,4,3,2,2,1
1,2,3,3,3,3,3,3,3,3,3,3,3,3,3,3,3,2,1,1
1,1,3,3,3,3,3,3,3,3,3,3,3,3,3,3,2,2,1,1
1,1,2,3,3,3,3,3,3,3,3,3,3,3,3,3,2,2,1,1
1,1,1,2,2,2,3,3,3,3,3,3,3,2,2,2,2,1,1,1
endlayer

layer
1,1,1,2,6,4,4,4,4,4,4,4,4,4,4,6,2,1,1,1
1,1,1,3,4,3,3,3,3,3,3,3,3,4,7,4,3,2,1,1
1,1,2,3,4,3,3,3,3,3,3,3,3,4,7,4,3,2,1,1
1,1,3,3,4,3,3,3,3,3,3,3,3,4,4,4,3,2,1,1
1,1,3,3,4,3,3,3,3,3,3,3,3,3,3,4,3,3,1,1
1,2,3,3,4,3,3,3,3,3,3,3,3,3,3,4,3,3,2,1
1,2,3,3,4,4,4,4,4,4,4,4,4,4,4,4,3,3,3,2
1,3,3,3,4,8,11,11,0,0,0,0,0,10,9,4,3,3,3,2
2,3,3,3,4,11,11,10,0,0,0,0,0,10,12,4,3,3,3,2
3,3,3,3,4,11,10,0,4,0,0,4,0,0,8,4,3,3,3,2
2,3,3,3,14,13,10,0,0,0,0,0,0,0,0,4,3,3,3,2
1,3,3,3,14,15,10,0,0,0,0,0,0,0,0,4,3,3,3,1
1,2,3,3,4,11,10,0,4,0,0,4,0,0,10,4,3,3,2,1
1,2,3,3,4,11,11,10,0,0,0,0,0,10,10,4,3,2,1,1
1,1,3,3,4,11,11,11,10,0,0,10,10,10,10,4,3,2,1,1
1,1,3,3,4,4,4,4,4,4,4,4,4,4,4,4,3,1,1,1
1,1,2,3,3,3,3,3,3,3,3,3,3,3,3,3,2,1,1,1
1,1,2,3,3,3,3,3,3,3,3,3,3,3,3,2,1,1,1,1
1,1,1,2,2,2,3,3,3,3,3,3,3,3,2,2,1,1,1,1
1,1,1,1,1,1,2,2,3,3,3,2,2,1,1,1,1,1,1,1
endlayer

layer
1,1,1,1,6,4,4,4,4,4,4,4,4,4,4,6,1,1,1,1
1,1,1,3,4,3,3,3,3,3,3,3,3,4,7,4,2,1,1,1
1,1,1,3,4,3,3,3,3,3,3,3,3,4,7,4,2,1,1,1
1,1,2,3,4,3,3,3,3,3,3,3,3,4,4,4,2,1,1,1
1,1,3,3,4,3,3,3,3,3,3,3,3,3,3,4,3,2,1,1
1,1,3,3,4,3,3,3,3,7,7,3,3,3,3,4,3,2,1,1
1,1,3,3,4,4,4,4,4,4,4,4,4,4,4,4,3,3,2,1
1,2,3,3,4,11,11,10,0,0,0,0,0,10,0,4,3,3,2,1
1,3,3,3,4,11,10,0,0,0,0,0,0,10,16,4,3,3,2,1
2,3,3,3,4,10,0,0,4,0,0,4,0,0,12,4,3,3,3,1
1,3,3,3,4,10,0,0,0,0,0,0,0,0,10,4,3,3,3,1
1,2,3,3,4,10,0,0,0,0,0,0,0,0,0,4,3,3,2,1
1,1,3,3,4,10,0,0,4,0,0,4,0,0,0,4,3,2,1,1
1,1,3,3,4,11,10,0,0,0,0,0,0,0,0,4,3,1,1,1
1,1,3,3,4,11,11,10,0,0,0,0,0,0,10,4,3,1,1,1
1,1,2,3,4,4,4,4,4,4,4,4,4,4,4,4,3,1,1,1
1,1,1,3,3,3,3,3,3,3,3,3,3,3,3,3,1,1,1,1
1,1,1,2,2,3,3,3,3,3,3,3,3,3,2,1,1,1,1,1
1,1,1,1,1,1,2,3,3,3,3,2,2,2,1,1,1,1,1,1
1,1,1,1,1,1,1,1,2,2,2,1,1,1,1,1,1,1,1,1
endlayer

layer
1,1,1,1,6,4,4,4,4,4,4,4,4,4,4,6,1,1,1,1
1,1,1,2,4,3,3,3,3,3,3,3,3,4,7,4,1,1,1,1
1,1,1,3,4,3,3,3,3,3,3,3,3,4,7,4,1,1,1,1
1,1,1,3,4,3,3,3,3,3,3,3,3,4,4,4,1,1,1,1
1,1,2,3,4,3,3,3,3,3,3,3,3,3,3,4,2,1,1,1
1,1,3,3,4,3,3,3,3,17,3,3,3,3,3,4,3,1,1,1
1,1,3,3,4,4,4,4,4,4,4,4,4,4,4,4,3,2,1,1
1,1,3,3,4,11,10,0,10,10,10,0,0,0,0,4,3,2,1,1
1,2,3,3,4,10,0,0,10,0,0,10,0,0,0,4,3,2,1,1
1,3,3,3,4,10,0,10,4,10,10,4,10,0,16,4,3,3,2,1
1,3,3,3,4,10,0,0,0,0,0,10,0,0,12,4,3,3,2,1
1,1,3,3,4,10,0,0,0,10,10,0,0,0,10,4,3,2,1,1
1,1,3,3,4,10,0,0,4,0,0,4,0,10,10,4,3,1,1,1
1,1,3,3,4,10,0,0,0,0,0,0,0,0,10,4,3,1,1,1
1,1,2,3,4,11,10,0,0,0,0,0,0,10,10,4,3,1,1,1
1,1,1,3,4,4,4,4,4,4,4,4,4,4,4,4,3,1,1,1
1,1,1,2,3,3,3,3,3,3,3,3,3,3,3,3,1,1,1,1
1,1,1,1,1,2,3,3,3,3,3,3,3,2,1,1,1,1,1,1
1,1,1,1,1,1,1,2,2,3,2,1,1,1,1,1,1,1,1,1
1,1,1,1,1,1,1,1,1,1,1,1,1,1,1,1,1,1,1,1
endlayer

layer
1,1,1,1,6,4,4,4,4,4,4,4,4,4,4,6,1,1,1,1
1,1,1,1,4,2,2,2,2,2,2,2,2,4,7,4,1,1,1,1
1,1,1,2,4,2,2,2,2,2,2,2,2,4,7,4,1,1,1,1
1,1,1,2,4,2,2,2,2,2,2,2,2,4,4,4,1,1,1,1
1,1,1,2,4,2,2,2,2,2,2,2,2,2,2,4,1,1,1,1
1,1,2,2,4,2,2,2,2,2,2,2,2,2,2,4,2,1,1,1
1,1,2,2,4,4,4,4,4,4,4,4,4,4,4,4,2,1,1,1
1,1,2,2,4,2,2,2,18,18,18,18,18,18,0,4,2,1,1,1
1,1,2,2,4,2,2,2,18,18,18,18,18,18,0,4,2,1,1,1
1,2,2,2,4,18,18,18,4,18,18,4,18,18,0,4,2,2,1,1
1,2,2,6,6,18,18,18,18,18,18,18,18,18,16,6,6,2,1,1
1,1,2,6,6,18,18,18,18,18,18,18,18,18,18,6,6,1,1,1
1,1,2,2,4,18,18,18,18,18,18,18,18,18,18,4,2,1,1,1
1,1,2,2,4,2,2,2,18,18,18,18,2,2,2,4,2,1,1,1
1,1,1,2,4,2,2,2,18,18,18,18,2,2,2,4,2,1,1,1
1,1,1,2,7,4,4,4,4,4,4,4,4,4,4,7,2,1,1,1
1,1,1,1,2,2,2,2,2,2,2,2,2,2,2,2,1,1,1,1
1,1,1,1,1,1,2,2,2,2,2,2,2,1,1,1,1,1,1,1
1,1,1,1,1,1,1,1,1,2,1,1,1,1,1,1,1,1,1,1
1,1,1,1,1,1,1,1,1,1,1,1,1,1,1,1,1,1,1,1
endlayer

layer
1,1,1,1,4,21,21,21,21,21,21,21,21,19,20,19,1,1,1,1
1,1,1,0,21,24,24,24,24,24,24,24,24,23,7,22,0,1,1,1
1,1,0,24,21,24,24,24,24,24,24,24,24,23,7,22,0,1,1,1
1,1,0,24,21,24,24,24,24,24,24,24,24,19,25,19,0,1,1,1
1,1,0,24,21,24,24,24,24,24,24,24,24,24,24,21,0,0,1,1
1,0,24,24,21,24,24,24,24,24,24,24,24,24,24,26,24,0,1,1
1,0,24,24,4,4,4,4,4,27,27,4,4,4,4,4,24,0,1,1
1,0,24,24,4,0,0,0,4,30,30,4,29,28,10,4,24,0,1,1
0,0,24,24,4,0,0,0,4,31,31,4,0,28,10,4,24,0,1,1
0,24,24,21,4,28,32,28,4,0,0,4,0,28,0,4,21,24,0,1
0,24,24,0,34,0,0,0,0,0,0,0,0,0,0,33,0,24,0,1
0,0,24,0,34,0,0,0,0,0,0,0,0,0,0,33,0,0,0,1
1,0,24,21,4,28,35,28,36,0,0,36,28,35,28,4,21,0,1,1
1,0,24,24,4,0,0,0,28,11,11,28,0,0,0,4,24,0,1,1
1,1,0,24,4,0,0,0,28,11,11,28,0,0,0,4,24,0,1,1
1,1,0,24,4,4,4,4,4,4,4,4,4,4,4,4,24,0,1,1
1,1,0,0,24,24,24,24,24,24,24,24,24,24,24,24,0,1,1,1
1,1,1,0,0,0,24,24,24,24,24,24,24,0,0,0,1,1,1,1
1,1,1,1,1,0,0,0,0,24,0,0,0,1,1,1,1,1,1,1
1,1,1,1,1,1,1,1,1,0,1,1,1,1,1,1,1,1,1,1
endlayer

layer
1,1,1,0,4,0,0,0,0,0,0,0,0,28,0,28,0,1,1,1
1,1,0,0,0,0,0,0,0,0,0,0,0,0,0,0,0,0,1,1
1,0,0,0,0,0,0,0,0,0,0,0,0,0,0,0,0,0,0,1
0,0,0,0,0,0,0,0,0,0,0,0,0,28,0,28,0,0,0,1
0,0,0,0,0,0,0,0,0,0,0,0,0,0,0,0,0,0,0,1
0,0,0,0,0,0,0,0,0,0,0,0,0,0,0,0,0,0,0,1
0,0,0,0,36,19,28,19,36,38,37,36,19,28,19,36,0,0,0,1
0,0,0,0,19,0,0,0,28,0,0,28,29,0,10,19,0,0,0,1
0,0,0,0,28,0,0,0,28,37,38,28,0,0,0,28,0,0,0,0
0,0,0,0,36,0,0,0,36,0,0,36,0,0,0,36,0,0,0,0
0,0,0,0,38,0,0,0,0,0,0,0,0,0,0,37,0,0,0,0
0,0,0,0,37,0,0,0,0,0,0,0,0,0,0,38,0,0,0,0
0,0,0,0,36,0,0,0,36,0,0,36,0,0,0,36,0,0,0,0
0,0,0,0,28,0,0,0,0,0,0,0,0,0,0,28,0,0,0,1
0,0,0,0,19,0,0,0,0,0,0,0,0,0,0,19,0,0,0,1
1,0,0,0,36,19,28,19,36,28,28,36,19,28,19,36,0,0,0,1
1,0,0,0,0,0,0,0,0,0,0,0,0,0,0,0,0,0,1,1
1,1,0,0,0,0,0,0,0,0,0,0,0,0,0,0,0,1,1,1
1,1,0,0,0,0,0,0,0,0,0,0,0,0,0,0,0,1,1,1
1,1,1,1,0,0,0,0,0,0,0,0,0,1,1,1,1,1,1,1
endlayer

layer
1,1,0,0,4,0,0,0,0,0,0,0,0,39,39,39,0,0,1,1
1,0,0,0,0,0,0,0,0,0,0,0,0,39,40,39,0,0,0,1
0,0,0,0,0,0,0,0,0,0,0,0,0,39,25,39,0,0,0,1
0,0,0,0,0,0,0,0,0,0,0,0,0,39,39,39,0,0,0,0
0,0,0,0,0,0,0,0,0,0,0,0,0,0,0,0,0,0,0,0
0,0,0,0,0,0,0,0,0,0,0,0,0,0,0,0,0,0,0,0
0,0,0,0,36,19,19,19,36,10,10,36,19,19,19,36,0,0,0,0
0,0,0,0,19,10,0,10,28,0,0,28,29,0,10,19,0,0,0,0
0,0,0,0,19,0,0,0,28,0,0,28,0,0,0,19,0,0,0,0
0,0,0,0,36,10,0,10,36,10,10,36,10,0,10,36,0,0,0,0
0,0,0,0,10,0,0,0,10,0,0,0,0,0,0,10,0,0,0,0
0,0,0,0,10,0,0,0,10,0,0,0,0,0,0,10,0,0,0,0
0,0,0,0,36,10,0,10,36,10,0,36,0,0,0,36,0,0,0,0
0,0,0,0,19,0,0,0,0,0,0,0,0,0,0,19,0,0,0,0
0,0,0,0,19,10,0,10,10,0,0,10,10,0,10,19,0,0,0,0
0,0,0,0,36,19,19,19,36,19,19,36,19,19,19,36,0,0,0,0
0,0,0,0,0,0,0,0,0,0,0,0,0,0,0,0,0,0,0,1
0,0,0,0,0,0,0,0,0,0,0,0,0,0,0,0,0,0,1,1
1,0,0,0,0,0,0,0,0,0,0,0,0,0,0,0,0,0,1,1
1,1,0,0,0,0,0,0,0,0,0,0,0,0,0,0,0,1,1,1
endlayer

layer
1,0,0,0,21,0,0,0,0,0,0,0,0,0,0,0,0,0,0,1
0,0,0,0,0,0,0,0,0,0,0,0,0,0,0,0,0,0,0,0
0,0,0,0,0,0,0,0,0,0,0,0,0,0,0,0,0,0,0,0
0,0,0,0,0,0,0,0,0,0,0,0,0,0,0,0,0,0,0,0
0,0,0,0,0,0,0,0,0,0,0,0,0,0,0,0,0,0,0,0
0,0,0,0,0,0,0,0,0,0,0,0,0,0,0,0,0,0,0,0
0,0,0,0,36,41,41,41,36,41,41,36,41,41,41,36,0,0,0,0
0,0,0,0,42,43,44,43,42,43,43,42,29,43,43,42,0,0,0,0
0,0,0,0,42,43,43,43,42,43,43,42,43,43,43,42,0,0,0,0
0,0,0,43,36,41,41,41,36,41,41,36,41,41,41,36,43,0,0,0
0,0,0,43,42,43,42,0,42,0,10,42,0,42,43,42,43,0,0,0
0,0,0,43,42,43,42,10,42,10,0,42,10,42,43,42,43,0,0,0
0,0,0,43,36,41,41,41,8,41,41,8,41,41,41,36,43,0,0,0
0,0,0,0,42,43,43,43,42,43,43,42,43,43,43,42,0,0,0,0
0,0,0,0,42,43,44,43,42,43,43,42,43,44,43,42,0,0,0,0
0,0,0,0,36,41,41,41,36,41,41,36,41,41,41,36,0,0,0,0
0,0,0,0,0,0,0,0,0,0,0,0,0,0,0,0,0,0,0,0
0,0,0,0,0,0,0,0,0,0,0,0,0,0,0,0,0,0,0,1
0,0,0,0,0,0,0,0,0,0,0,0,0,0,0,0,0,0,0,1
1,0,0,0,0,0,0,0,0,0,0,0,0,0,0,0,0,0,1,1
endlayer

layer
0,0,0,0,0,0,0,0,0,0,0,0,0,0,0,0,0,0,0,0
0,0,0,0,0,0,0,0,0,0,0,0,0,0,0,0,0,0,0,0
0,0,0,0,0,0,0,0,0,0,0,0,0,0,0,0,0,0,0,0
0,0,0,0,0,0,0,0,0,0,0,0,0,0,0,0,0,0,0,0
0,0,0,0,0,0,0,0,0,0,0,0,0,0,0,0,0,0,0,0
0,0,0,20,20,20,20,20,20,20,20,20,20,20,20,20,20,0,0,0
0,0,0,19,19,19,19,19,19,19,19,19,19,19,19,19,19,0,0,0
0,0,0,0,19,11,45,11,11,11,11,11,0,11,11,19,0,0,0,0
0,0,0,0,19,11,11,0,0,0,0,0,0,0,11,19,0,0,0,0
0,0,0,0,36,0,0,0,36,0,0,36,0,0,0,36,0,0,0,0
0,0,0,0,0,0,0,0,0,0,0,0,0,0,0,0,0,0,0,0
0,0,0,0,0,0,0,0,0,0,0,0,0,0,0,0,0,0,0,0
0,0,0,0,36,0,0,0,36,0,0,36,0,0,0,36,0,0,0,0
0,0,0,0,19,11,11,0,0,0,0,0,0,11,11,19,0,0,0,0
0,0,0,0,19,11,45,11,11,11,11,11,11,45,11,19,0,0,0,0
0,0,0,19,19,19,19,19,19,19,19,19,19,19,19,19,19,0,0,0
0,0,0,25,25,25,25,25,25,25,25,25,25,25,25,25,25,0,0,0
0,0,0,0,0,0,0,0,0,0,0,0,0,0,0,0,0,0,0,0
0,0,0,0,0,0,0,0,0,0,0,0,0,0,0,0,0,0,0,1
0,0,0,0,0,0,0,0,0,0,0,0,0,0,0,0,0,0,0,1
endlayer

layer
0,0,0,0,0,0,0,0,0,0,0,0,0,0,0,0,0,0,0,0
0,0,0,0,0,0,0,0,0,0,0,0,0,0,0,0,0,0,0,0
0,0,0,0,0,0,0,0,0,0,0,0,0,0,0,0,0,0,0,0
0,0,0,0,0,0,0,0,0,0,0,0,0,0,0,0,0,0,0,0
0,0,0,0,0,0,0,0,0,0,0,0,0,0,0,0,0,0,0,0
0,0,0,0,0,0,0,0,0,0,0,0,0,0,0,0,0,0,0,0
0,0,0,19,19,19,19,19,19,19,19,19,19,19,19,19,19,0,0,0
0,0,0,0,19,11,11,11,11,11,11,11,0,11,11,19,0,0,0,0
0,0,0,0,19,11,0,0,10,0,0,10,0,0,11,19,0,0,0,0
0,0,0,0,36,0,0,0,36,0,0,36,0,0,0,36,0,0,0,0
0,0,0,0,0,0,0,0,10,0,0,10,0,0,0,0,0,0,0,0
0,0,0,0,0,0,0,0,10,0,0,10,0,0,0,0,0,0,0,0
0,0,0,0,36,0,0,0,36,0,0,36,0,0,0,36,0,0,0,0
0,0,0,0,19,11,0,0,0,0,0,0,0,0,11,19,0,0,0,0
0,0,0,0,19,11,11,11,11,11,11,11,11,11,11,19,0,0,0,0
0,0,0,19,19,19,19,19,19,19,19,19,19,19,19,19,19,0,0,0
0,0,0,0,0,0,0,0,0,0,0,0,0,0,0,0,0,0,0,0
0,0,0,0,0,0,0,0,0,0,0,0,0,0,0,0,0,0,0,0
0,0,0,0,0,0,0,0,0,0,0,0,0,0,0,0,0,0,0,0
0,0,0,0,0,0,0,0,0,0,0,0,0,0,0,0,0,0,0,1
endlayer

layer
0,0,0,0,0,0,0,0,0,0,0,0,0,0,0,0,0,0,0,0
0,0,0,0,0,0,0,0,0,0,0,0,0,0,0,0,0,0,0,0
0,0,0,0,0,0,0,0,0,0,0,0,0,0,0,0,0,0,0,0
0,0,0,0,0,0,0,0,0,0,0,0,0,0,0,0,0,0,0,0
0,0,0,0,0,0,0,0,0,0,0,0,0,0,0,0,0,0,0,0
0,0,0,0,0,0,0,0,0,0,0,0,0,0,0,0,0,0,0,0
0,0,0,20,20,20,20,20,20,20,20,20,20,20,20,20,20,0,0,0
0,0,0,46,42,46,46,46,42,46,46,42,46,46,46,42,46,0,0,0
0,0,0,0,42,10,0,0,42,0,0,42,0,0,0,42,0,0,0,0
0,0,0,0,36,0,0,0,36,0,0,36,0,0,0,36,0,0,0,0
0,0,0,0,42,0,0,0,42,0,0,42,0,0,0,42,0,0,0,0
0,0,0,0,42,0,0,0,42,0,0,42,0,0,0,42,0,0,0,0
0,0,0,0,36,0,0,0,36,0,0,36,0,0,0,36,0,0,0,0
0,0,0,0,42,10,0,0,42,0,10,42,0,0,0,42,0,0,0,0
0,0,0,40,42,40,40,40,42,40,40,42,40,40,40,42,40,0,0,0
0,0,0,25,25,25,25,25,25,25,25,25,25,25,25,25,25,0,0,0
0,0,0,0,0,0,0,0,0,0,0,0,0,0,0,0,0,0,0,0
0,0,0,0,0,0,0,0,0,0,0,0,0,0,0,0,0,0,0,0
0,0,0,0,0,0,0,0,0,0,0,0,0,0,0,0,0,0,0,0
0,0,0,0,0,0,0,0,0,0,0,0,0,0,0,0,0,0,0,0
endlayer

layer
0,0,0,0,0,0,0,0,0,0,0,0,0,0,0,0,0,0,0,0
0,0,0,0,0,0,0,0,0,0,0,0,0,0,0,0,0,0,0,0
0,0,0,0,0,0,0,0,0,0,0,0,0,0,0,0,0,0,0,0
0,0,0,0,0,0,0,0,0,0,0,0,0,0,0,0,0,0,0,0
0,0,0,0,0,0,0,0,0,0,0,0,0,0,0,0,0,0,0,0
0,0,0,0,0,0,0,0,0,0,0,0,0,0,0,0,0,0,0,0
0,0,0,0,0,0,0,0,0,0,0,0,0,0,0,0,0,0,0,0
0,0,0,20,20,20,20,20,20,20,20,20,20,20,20,20,20,0,0,0
0,0,0,46,19,46,46,46,46,46,46,46,46,46,46,19,46,0,0,0
0,0,0,0,36,10,0,0,36,10,10,36,10,0,10,36,0,0,0,0
0,0,0,0,10,0,0,0,10,0,0,10,0,0,0,10,0,0,0,0
0,0,0,0,0,0,0,0,10,0,0,10,0,0,0,10,0,0,0,0
0,0,0,0,36,0,0,0,36,10,10,36,0,10,10,36,0,0,0,0
0,0,0,40,19,40,40,40,40,40,40,40,40,40,40,19,40,0,0,0
0,0,0,25,25,25,25,25,25,25,25,25,25,25,25,25,25,0,0,0
0,0,0,0,0,0,0,0,0,0,0,0,0,0,0,0,0,0,0,0
0,0,0,0,0,0,0,0,0,0,0,0,0,0,0,0,0,0,0,0
0,0,0,0,0,0,0,0,0,0,0,0,0,0,0,0,0,0,0,0
0,0,0,0,0,0,0,0,0,0,0,0,0,0,0,0,0,0,0,0
0,0,0,0,0,0,0,0,0,0,0,0,0,0,0,0,0,0,0,0
endlayer

layer
0,0,0,0,0,0,0,0,0,0,0,0,0,0,0,0,0,0,0,0
0,0,0,0,0,0,0,0,0,0,0,0,0,0,0,0,0,0,0,0
0,0,0,0,0,0,0,0,0,0,0,0,0,0,0,0,0,0,0,0
0,0,0,0,0,0,0,0,0,0,0,0,0,0,0,0,0,0,0,0
0,0,0,0,0,0,0,0,0,0,0,0,0,0,0,0,0,0,0,0
0,0,0,0,0,0,0,0,0,0,0,0,0,0,0,0,0,0,0,0
0,0,0,0,0,0,0,0,0,0,0,0,0,0,0,0,0,0,0,0
0,0,0,0,0,0,0,0,0,0,0,0,0,0,0,0,0,0,0,0
0,0,0,39,39,39,39,39,39,39,39,39,39,39,39,39,39,0,0,0
0,0,0,19,19,19,19,19,19,19,19,19,19,19,19,19,19,0,0,0
0,0,0,47,47,47,47,47,47,0,0,47,47,47,47,47,47,0,0,0
0,0,0,47,47,47,47,47,47,0,0,47,47,47,47,47,47,0,0,0
0,0,0,19,19,19,19,19,19,19,19,19,19,19,19,19,19,0,0,0
0,0,0,39,39,39,39,39,39,39,39,39,39,39,39,39,39,0,0,0
0,0,0,0,0,0,0,0,0,0,0,0,0,0,0,0,0,0,0,0
0,0,0,0,0,0,0,0,0,0,0,0,0,0,0,0,0,0,0,0
0,0,0,0,0,0,0,0,0,0,0,0,0,0,0,0,0,0,0,0
0,0,0,0,0,0,0,0,0,0,0,0,0,0,0,0,0,0,0,0
0,0,0,0,0,0,0,0,0,0,0,0,0,0,0,0,0,0,0,0
0,0,0,0,0,0,0,0,0,0,0,0,0,0,0,0,0,0,0,0
endlayer

layer
0,0,0,0,0,0,0,0,0,0,0,0,0,0,0,0,0,0,0,0
0,0,0,0,0,0,0,0,0,0,0,0,0,0,0,0,0,0,0,0
0,0,0,0,0,0,0,0,0,0,0,0,0,0,0,0,0,0,0,0
0,0,0,0,0,0,0,0,0,0,0,0,0,0,0,0,0,0,0,0
0,0,0,0,0,0,0,0,0,0,0,0,0,0,0,0,0,0,0,0
0,0,0,0,0,0,0,0,0,0,0,0,0,0,0,0,0,0,0,0
0,0,0,0,0,0,0,0,0,0,0,0,0,0,0,0,0,0,0,0
0,0,0,0,0,0,0,0,0,0,0,0,0,0,0,0,0,0,0,0
0,0,0,0,0,0,0,0,0,0,0,0,0,0,0,0,0,0,0,0
0,0,0,0,0,0,0,0,28,28,28,28,0,0,0,0,0,0,0,0
0,0,0,19,39,39,39,39,39,0,0,39,39,39,39,39,19,0,0,0
0,0,0,19,39,39,39,39,39,0,0,39,39,39,39,39,19,0,0,0
0,0,0,0,0,0,0,0,28,28,28,28,0,0,0,0,0,0,0,0
0,0,0,0,0,0,0,0,0,0,0,0,0,0,0,0,0,0,0,0
0,0,0,0,0,0,0,0,0,0,0,0,0,0,0,0,0,0,0,0
0,0,0,0,0,0,0,0,0,0,0,0,0,0,0,0,0,0,0,0
0,0,0,0,0,0,0,0,0,0,0,0,0,0,0,0,0,0,0,0
0,0,0,0,0,0,0,0,0,0,0,0,0,0,0,0,0,0,0,0
0,0,0,0,0,0,0,0,0,0,0,0,0,0,0,0,0,0,0,0
0,0,0,0,0,0,0,0,0,0,0,0,0,0,0,0,0,0,0,0
endlayer

layer
0,0,0,0,0,0,0,0,0,0,0,0,0,0,0,0,0,0,0,0
0,0,0,0,0,0,0,0,0,0,0,0,0,0,0,0,0,0,0,0
0,0,0,0,0,0,0,0,0,0,0,0,0,0,0,0,0,0,0,0
0,0,0,0,0,0,0,0,0,0,0,0,0,0,0,0,0,0,0,0
0,0,0,0,0,0,0,0,0,0,0,0,0,0,0,0,0,0,0,0
0,0,0,0,0,0,0,0,0,0,0,0,0,0,0,0,0,0,0,0
0,0,0,0,0,0,0,0,0,0,0,0,0,0,0,0,0,0,0,0
0,0,0,0,0,0,0,0,0,0,0,0,0,0,0,0,0,0,0,0
0,0,0,0,0,0,0,0,0,0,0,0,0,0,0,0,0,0,0,0
0,0,0,0,0,0,0,0,39,39,39,39,0,0,0,0,0,0,0,0
0,0,49,22,0,0,0,0,39,19,19,39,0,0,0,0,23,48,0,0
0,0,49,22,0,0,0,0,39,19,19,39,0,0,0,0,23,48,0,0
0,0,0,0,0,0,0,0,39,39,39,39,0,0,0,0,0,0,0,0
0,0,0,0,0,0,0,0,0,0,0,0,0,0,0,0,0,0,0,0
0,0,0,0,0,0,0,0,0,0,0,0,0,0,0,0,0,0,0,0
0,0,0,0,0,0,0,0,0,0,0,0,0,0,0,0,0,0,0,0
0,0,0,0,0,0,0,0,0,0,0,0,0,0,0,0,0,0,0,0
0,0,0,0,0,0,0,0,0,0,0,0,0,0,0,0,0,0,0,0
0,0,0,0,0,0,0,0,0,0,0,0,0,0,0,0,0,0,0,0
0,0,0,0,0,0,0,0,0,0,0,0,0,0,0,0,0,0,0,0
endlayer

