# Townhouse
# 9 Mar 2014 -- updated to 1.7.10, 8 Oct 2014
# Created by Ruins mod version 12.3 Ingame Parser
# authoring Player: Jordan_Greywolf

# Updated for MC 1.9: 17 Apr 2016
# Last Updated: 27 Apr 2016
# Updated for MC 1.10: 13 Sep 2016
# Updated to MC 1.11: 13 Jan 2017
# Verified for MC 1.12: 23 Jun 2017
# Updated to MC 1.12.1: 10 Sep 2017

# Last Updated: 9 Jun 2018


biomesToSpawnIn=dead forest,dead_forest,dead swamp,dead_swamp,lavender fields,lavender_fields,heathland,flower fields,flower_field,forest,foresthill,meadow,plains,sunflower plains,shrubland,scrubland,pasture,forest_hills,mutated_forest,mutated_plains,temperate_rainforest

weight=1
embed_into_distance=4

spawnMinDistance=500

unacceptable_target_blocks=lava,flowing_lava,water,flowing_water,cloud,Natura:Cloud,red_mushroom_block,brown_mushroom_block,slime_congealed,slime_dirt,slime_grass,command_block,planks,planks2,concrete,cobblestone,stonebrick,brick_block,glass,torch,oak_stairs,stone_stairs,brick_stairs,stone_brick_stairs,nether_brick_stairs,sandstone_stairs,spruce_stairs,birch_stairs,jungle_stairs,quartz_stairs,acacia_stairs,dark_oak_stairs,cobblestone_wall,stone_slab,double_stone_slab,stone_slab2,wooden_slab,double_wooden_slab,nether_brick,fence

dimensions=18,11,10
allowable_overhang=0
max_cut_in=0
cut_in_buffer=0
max_leveling=4
leveling_buffer=-1
preserve_water=0
preserve_lava=0
preserve_plants=1

rule1=0,100,preserveBlock
rule2=0,100,minecraft:stone-0,preserveBlock,minecraft:monster_egg-0
rule3=0,100,minecraft:tnt-1,minecraft:tnt-0,MobSpawner:Creeper
rule4=0,100,minecraft:cobblestone-0,minecraft:mossy_cobblestone-0,minecraft:monster_egg-1,minecraft:cobblestone-0
rule5=0,100,minecraft:stone_stairs-1

rule6=0,100,IInventory;minecraft:dispenser;minecraft:spawn_egg#{EntityTag:{id:"Creeper"}}#50#0+minecraft:spawn_egg#{EntityTag:{id:creeper}}#50#1+minecraft:spawn_egg#{EntityTag:{id:creeper}}#50#2+minecraft:spawn_egg#{EntityTag:{id:zombie_villager}}#54#7+minecraft:spawn_egg#{EntityTag:{id:silverfish}}#60#8-5

rule7=0,100,IInventory;minecraft:trapped_chest;minecraft:monster_egg#2#1+minecraft:monster_egg#1#0+minecraft:stone#16#0+minecraft:web#7#0+minecraft:tnt#1#0+minecraft:glowstone#1#0-5

rule8=0,100,minecraft:stone_pressure_plate-0,minecraft:wooden_pressure_plate-0

rule9=0,100,IInventory;minecraft:trapped_chest;minecraft:porkchop#2#0+minecraft:pumpkin#2#0+minecraft:wheat_seeds#13#0+minecraft:chicken#2#0+minecraft:egg#8#0+minecraft:melon_block#5#0+minecraft:stone_pickaxe#1#0+minecraft:carrot#18#0+minecraft:grass#3#0-3

rule10=0,100,minecraft:monster_egg-1,minecraft:cobblestone-0

rule11=0,100,minecraft:web-0
rule12=0,100,minecraft:stone_stairs-2
rule13=0,100,minecraft:fence-0
rule14=0,100,minecraft:planks-0
rule15=0,100,minecraft:oak_stairs-0
rule16=0,100,minecraft:wooden_slab-8
rule17=0,100,minecraft:stone_stairs-3
rule18=0,100,minecraft:planks-2
rule19=0,100,minecraft:oak_stairs-1
rule20=0,100,minecraft:spruce_stairs-3
rule21=1,100,minecraft:wooden_door-3
rule22=0,100,minecraft:crafting_table-0

rule23=0,100,IInventory;minecraft:lit_furnace;minecraft:coal#9#1#1-4

rule24=0,100,minecraft:oak_stairs-2
rule25=0,100,minecraft:log-0
rule26=1,100,minecraft:redstone_torch-5
rule27=0,100,minecraft:wooden_pressure_plate-0
rule28=1,100,minecraft:wooden_door-8
rule29=0,100,minecraft:log-1
rule30=0,100,minecraft:log-9
rule31=0,100,minecraft:log-5

# Randomized Flower Pot
rule32=0,100,teBlock;minecraft:flower_pot;{Item:"minecraft:red_flower",x:0,y:0,z:0,Data:4,id:"flower_pot"}-0,teBlock;minecraft:flower_pot;{Item:"minecraft:red_flower",x:0,y:0,z:0,Data:2,id:"flower_pot"}-0,teBlock;minecraft:flower_pot;{Item:"minecraft:red_flower",x:0,y:0,z:0,Data:0,id:"flower_pot"}-0,teBlock;minecraft:flower_pot;{Item:"minecraft:tallgrass",x:0,y:0,z:0,Data:2,id:"flower_pot"}-0

rule33=0,100,minecraft:bed-3
rule34=0,100,minecraft:bed-11
rule35=0,100,minecraft:oak_stairs-3
rule36=0,100,minecraft:oak_stairs-7
rule37=0,100,minecraft:oak_stairs-6

layer
1,1,1,1,1,1,1,1,1,1
1,1,1,1,1,1,1,1,1,1
1,1,1,2,2,2,2,2,1,1
1,1,1,2,2,2,2,2,1,1
1,1,1,2,2,2,2,2,1,1
1,1,1,2,2,2,2,2,1,1
1,1,1,2,2,2,3,2,1,1
1,1,1,2,2,2,2,2,1,1
1,1,1,2,2,2,2,2,1,1
1,1,1,1,1,1,1,1,1,1
1,1,1,1,1,1,1,1,1,1
endlayer

layer
1,1,1,1,1,1,1,1,1,1
1,1,1,1,1,1,1,1,1,1
1,1,1,4,4,4,4,4,1,1
1,1,1,4,7,6,5,4,1,1
1,1,1,4,0,8,0,4,1,1
1,1,1,4,0,0,4,4,1,1
1,1,1,4,0,0,9,4,1,1
1,1,1,4,0,0,0,4,1,1
1,1,1,4,4,10,4,4,1,1
1,1,1,1,1,1,1,1,1,1
1,1,1,1,1,1,1,1,1,1
endlayer

layer
1,1,1,1,1,1,1,1,1,1
1,1,1,1,1,1,1,1,1,1
1,1,1,4,4,4,4,4,1,1
1,1,1,4,0,12,11,4,1,1
1,1,1,4,0,11,11,4,1,1
1,1,1,10,11,11,13,4,1,1
1,1,1,4,0,0,11,4,1,1
1,1,1,4,0,13,0,4,1,1
1,1,1,4,4,4,4,4,1,1
1,1,1,1,1,1,1,1,1,1
1,1,1,1,1,1,1,1,1,1
endlayer

layer
1,1,1,1,1,1,1,1,1,1
1,1,1,1,1,1,1,1,1,1
1,1,1,4,10,4,4,4,1,1
1,1,1,4,12,0,11,4,1,1
1,1,1,4,0,11,11,4,1,1
1,1,1,4,0,0,0,4,1,1
1,1,1,4,0,0,0,4,1,1
1,1,1,4,0,0,0,4,1,1
1,1,1,4,4,4,4,4,1,1
1,1,1,1,1,1,1,1,1,1
1,1,1,1,1,1,1,1,1,1
endlayer

layer
1,1,1,0,0,0,0,1,1,1
1,1,0,0,0,0,0,0,1,1
1,0,0,4,4,4,4,4,0,1
0,0,0,4,11,0,11,4,0,0
0,0,0,4,15,14,14,4,0,0
0,0,4,10,16,16,16,4,0,0
0,0,17,4,14,14,14,4,0,0
0,0,4,4,16,16,16,4,0,0
1,0,0,4,4,4,4,4,0,1
1,1,0,0,4,4,4,0,1,1
1,1,1,0,0,0,0,1,1,1
endlayer

layer
1,1,0,0,0,0,0,0,1,1
1,0,0,0,0,0,0,0,0,1
0,0,0,4,18,18,18,4,0,0
0,0,0,18,0,0,19,18,0,0
0,0,0,18,0,0,11,18,0,0
0,0,13,18,11,0,0,18,0,0
0,0,0,21,0,13,20,18,0,0
0,0,13,18,11,0,22,18,0,0
0,0,0,4,18,23,18,4,0,0
1,0,0,0,4,4,4,0,0,1
1,1,0,0,0,0,0,0,1,1
endlayer

layer
1,0,0,0,0,0,0,0,0,1
0,0,0,0,0,0,0,0,0,0
0,0,0,4,18,18,18,4,0,0
0,0,0,25,11,24,11,18,0,0
0,0,0,13,0,0,0,25,0,0
0,0,26,25,0,0,0,13,0,0
0,0,0,28,0,27,0,25,0,0
0,0,26,18,0,0,26,18,0,0
0,0,0,4,18,4,18,4,0,0
0,0,0,0,4,4,4,0,0,0
1,0,0,0,0,0,0,0,0,1
endlayer

layer
0,0,0,0,0,0,0,0,0,0
0,0,0,0,0,0,0,0,0,0
0,0,0,4,18,18,18,4,0,0
0,0,0,18,24,0,0,18,0,0
0,0,0,18,11,0,11,18,0,0
0,0,0,18,0,0,0,18,0,0
0,0,0,18,0,0,0,18,0,0
0,0,0,18,11,0,11,18,0,0
0,0,0,4,18,4,18,4,0,0
0,0,0,0,4,4,4,0,0,0
0,0,0,0,0,0,0,0,0,0
endlayer

layer
0,0,0,0,0,0,0,0,0,0
0,29,30,30,30,30,30,30,29,0
0,31,14,14,14,14,14,14,31,0
0,31,16,24,0,11,11,14,31,0
0,31,14,14,14,14,14,14,31,0
0,31,16,14,16,16,16,14,31,0
0,31,14,14,14,14,14,14,31,0
0,31,16,14,16,16,16,14,31,0
0,31,14,14,14,4,14,14,31,0
0,29,30,30,4,4,4,30,29,0
0,0,0,0,0,0,0,0,0,0
endlayer

layer
0,0,0,0,0,0,0,0,0,0
0,29,18,18,18,18,18,18,29,0
0,18,13,0,0,11,0,32,18,0
0,18,0,0,0,0,0,0,18,0
0,18,0,0,0,0,0,0,18,0
0,29,0,0,33,0,33,11,29,0
0,18,11,11,34,11,34,0,18,0
0,18,0,11,11,0,0,0,18,0
0,18,13,0,4,23,4,0,18,0
0,29,18,18,4,4,4,18,29,0
0,0,0,0,0,0,0,0,0,0
endlayer

layer
0,0,0,0,0,0,0,0,0,0
0,29,18,18,18,18,18,18,29,0
0,25,27,13,0,11,13,0,25,0
0,13,0,0,0,0,0,0,13,0
0,25,11,11,0,0,0,11,25,0
0,29,0,0,0,0,11,11,29,0
0,25,0,0,0,0,11,11,25,0
0,13,0,0,0,0,0,0,13,0
0,25,27,13,17,4,12,0,25,0
0,29,18,18,4,4,4,18,29,0
0,0,0,0,0,0,0,0,0,0
endlayer

layer
35,0,0,0,0,0,0,0,0,24
35,29,30,30,30,30,30,30,29,24
35,31,0,26,0,0,26,11,31,24
35,31,0,0,0,0,0,0,31,24
35,31,11,0,0,0,0,0,31,24
35,31,0,0,0,0,0,11,31,24
35,31,0,0,0,0,0,0,31,24
35,31,0,0,0,11,0,0,31,24
35,31,11,26,0,4,0,0,31,24
35,29,30,30,4,4,4,30,29,24
35,0,0,0,0,0,0,0,0,24
endlayer

layer
0,35,0,0,0,0,0,0,24,0
0,35,18,18,18,18,18,18,24,0
0,35,37,11,0,11,0,36,24,0
0,35,37,0,0,0,0,36,24,0
0,35,37,0,0,0,11,36,24,0
0,35,37,11,0,0,0,36,24,0
0,35,37,0,0,0,0,36,24,0
0,35,37,0,0,0,0,36,24,0
0,35,37,0,11,4,0,36,24,0
0,35,18,18,4,4,4,18,24,0
0,35,0,0,0,0,0,0,24,0
endlayer

layer
0,0,35,0,0,0,0,24,0,0
0,0,35,18,18,18,18,24,0,0
0,0,35,37,11,0,36,24,0,0
0,0,35,37,0,11,36,24,0,0
0,0,35,37,0,0,36,24,0,0
0,0,35,37,0,0,36,24,0,0
0,0,35,37,0,11,36,24,0,0
0,0,35,37,0,11,36,24,0,0
0,0,35,37,11,4,36,24,0,0
0,0,35,18,4,4,4,24,0,0
0,0,35,0,0,0,0,24,0,0
endlayer

layer
0,0,0,35,0,0,24,0,0,0
0,0,0,35,18,18,24,0,0,0
0,0,0,35,37,36,24,0,0,0
0,0,0,35,37,36,24,0,0,0
0,0,0,35,37,36,24,0,0,0
0,0,0,35,37,36,24,0,0,0
0,0,0,35,37,36,24,0,0,0
0,0,0,35,37,36,24,0,0,0
0,0,0,35,37,4,24,0,0,0
0,0,0,35,4,4,24,0,0,0
0,0,0,35,0,0,24,0,0,0
endlayer

layer
0,0,0,0,35,24,0,0,0,0
0,0,0,0,35,24,0,0,0,0
0,0,0,0,35,24,0,0,0,0
0,0,0,0,35,24,0,0,0,0
0,0,0,0,35,24,0,0,0,0
0,0,0,0,35,24,0,0,0,0
0,0,0,0,35,24,0,0,0,0
0,0,0,0,35,24,0,0,0,0
0,0,0,0,35,24,0,0,0,0
0,0,0,0,35,4,0,0,0,0
0,0,0,0,35,24,0,0,0,0
endlayer

layer
0,0,0,0,0,0,0,0,0,0
0,0,0,0,0,0,0,0,0,0
0,0,0,0,0,0,0,0,0,0
0,0,0,0,0,0,0,0,0,0
0,0,0,0,0,0,0,0,0,0
0,0,0,0,0,0,0,0,0,0
0,0,0,0,0,0,0,0,0,0
0,0,0,0,0,0,0,0,0,0
0,0,0,0,0,0,0,0,0,0
0,0,0,0,0,4,0,0,0,0
0,0,0,0,0,0,0,0,0,0
endlayer

layer
0,0,0,0,0,0,0,0,0,0
0,0,0,0,0,0,0,0,0,0
0,0,0,0,0,0,0,0,0,0
0,0,0,0,0,0,0,0,0,0
0,0,0,0,0,0,0,0,0,0
0,0,0,0,0,0,0,0,0,0
0,0,0,0,0,0,0,0,0,0
0,0,0,0,0,0,0,0,0,0
0,0,0,0,0,0,0,0,0,0
0,0,0,0,0,4,0,0,0,0
0,0,0,0,0,0,0,0,0,0
endlayer

