# Travelers' Inn (ruined)
# 25 Apr 2014; updated to MC 1.7.10, 8 Oct 2014
# Created by Ruins mod version 12.3 Ingame Parser
# authoring Player: Jordan_Greywolf
# Last Updated: 29 Oct 2015
# Updated to MC 1.8: 5 Mar 2016
# Updated to MC 1.9: 17 Apr 2016
# Updated to MC 1.10: 13 Sep 2016
# Updated to MC 1.11: 13 Jan 2017
# Verified for MC 1.12: 23 Jun 2017
# Updated to MC 1.12.1: 10 Sep 2017

# Last Updated: 6 Apr 2018


biomesToSpawnIn=birch forest,eerie,eldritch,flower_field,flower forest,forest,plains,sunflower plains,savanna,taiga,dead forest,dead swamp,ominous woods,rwg_coldplains,rwg_plains,tainted land,thick ominous woods,birch_forest,mutated_forest,mutated_plains,temperate_rainforest

weight=1
embed_into_distance=4

preventRotation=1

spawnMinDistance=800

unacceptable_target_blocks=lava,flowing_lava,water,flowing_lava,cloud,Natura:Cloud,slime_congealed,slime_dirt,slime_grass,command_block,planks,planks2,concrete,cobblestone,stonebrick,brick_block,glass,torch,oak_stairs,stone_stairs,brick_stairs,stone_brick_stairs,nether_brick_stairs,sandstone_stairs,spruce_stairs,birch_stairs,jungle_stairs,quartz_stairs,acacia_stairs,dark_oak_stairs,cobblestone_wall,stone_slab,double_stone_slab,stone_slab2,wooden_slab,double_wooden_slab,nether_brick,fence

dimensions=19,13,14
allowable_overhang=12
max_cut_in=0
cut_in_buffer=0
max_leveling=4
leveling_buffer=-1
preserve_water=0
preserve_lava=0
preserve_plants=1

rule1=0,100,preserveBlock
rule2=0,100,minecraft:cobblestone-0
rule3=0,100,minecraft:netherrack-0,minecraft:gravel
rule4=0,100,minecraft:mossy_cobblestone-0
rule5=0,100,minecraft:grass-0
rule6=0,100,minecraft:fire-15,minecraft:fire-7,minecraft:fire-0
rule7=1,100,minecraft:iron_bars-0
rule8=0,100,minecraft:cobblestone_wall-0
rule9=2,100,minecraft:ladder-3
rule10=0,100,minecraft:web-0

rule11=0,100,preserveBlock

rule12=0,50,minecraft:farmland-7,minecraft:farmland-5,minecraft:farmland-3
rule13=0,100,minecraft:farmland-0,minecraft:dirt
rule14=0,100,minecraft:water-0
rule15=0,75,minecraft:jungle_fence-0
rule16=1,50,minecraft:jungle_fence_gate-1
rule17=0,25,minecraft:wheat-7,minecraft:wheat-3,minecraft:wheat-1
rule18=0,25,minecraft:melon_block-0
rule19=0,25,minecraft:melon_stem-7,minecraft:melon_stem-3,minecraft:melon_stem-1
rule20=1,75,minecraft:leaves-4
rule21=0,80,minecraft:wool-14,minecraft:wool-6
rule22=1,75,minecraft:leaves-12
rule23=0,100,minecraft:stone_stairs-1
rule24=0,100,minecraft:log-0
rule25=1,90,minecraft:planks-0
rule26=1,75,minecraft:flower_pot-0
rule27=1,80,minecraft:crafting_table-0
rule28=1,75,minecraft:furnace
rule29=2,50,minecraft:trapdoor-3
rule30=2,80,minecraft:ladder-2
rule31=2,80,minecraft:spruce_stairs-3
rule32=2,80,minecraft:spruce_stairs-2
rule33=1,75,minecraft:jungle_door-2
rule34=1,75,minecraft:glass_pane-0

rule35=1,100,MobSpawner:Spider,MobSpawner:Cave_Spider,MobSpawner:Skeleton,MobSpawner:Zombie

rule36=1,50,minecraft:stone_pressure_plate-0
rule37=1,100,minecraft:jungle_door-9
rule38=1,100,minecraft:jungle_door-8
rule39=1,50,minecraft:redstone_torch-5
rule40=0,100,minecraft:log-4
rule41=2,80,minecraft:spruce_stairs-0
rule42=0,100,minecraft:log-8
rule43=2,80,minecraft:planks-2
rule44=0,25,minecraft:redstone_lamp-0
rule45=2,80,minecraft:spruce_stairs-1
rule46=0,100,minecraft:planks-1
rule47=0,100,minecraft:stone_stairs-2
rule48=0,100,minecraft:stone_stairs-3
rule49=1,100,minecraft:wooden_slab
rule50=1,100,minecraft:wooden_slab
rule51=0,100,minecraft:wooden_slab-1

rule52=0,100,ChestGenHook:chests/village_blacksmith:2,IInventory;minecraft:chest;minecraft:web#6#0#4,IInventory;minecraft:chest;minecraft:grass#6#0#8,IInventory;minecraft:chest;minecraft:torch#12#0#5


layer
1,1,1,1,1,2,2,2,2,1,1,1,1,1
1,1,1,1,2,2,35,35,2,2,1,1,1,1
1,1,1,1,2,2,2,2,2,2,1,1,1,1
1,1,1,1,2,4,4,4,4,2,1,1,1,1
1,1,1,1,2,4,4,4,4,2,1,1,1,1
1,1,1,1,2,4,4,4,4,2,1,1,1,1
1,2,2,2,2,4,4,4,4,2,2,2,2,1
1,2,4,4,4,4,4,4,4,4,4,4,2,1
1,2,4,4,4,4,4,4,4,4,4,4,2,1
1,2,4,4,4,4,4,4,4,4,4,4,2,1
1,2,4,4,4,4,4,4,4,4,4,4,2,1
1,2,2,2,2,4,4,4,4,2,2,2,2,1
1,1,1,1,1,2,2,2,2,1,1,1,1,1
endlayer

layer
1,1,1,1,1,2,2,2,2,1,1,1,1,5
1,1,1,1,2,2,0,0,2,2,1,1,1,1
1,1,1,1,2,2,7,7,2,2,1,1,1,1
1,1,1,1,2,8,0,0,8,2,1,1,1,1
1,1,1,1,2,0,0,0,0,2,1,1,1,1
1,1,1,1,2,0,0,0,0,2,1,1,1,1
1,2,2,2,2,0,0,0,9,2,2,2,2,1
1,2,8,0,0,0,0,0,0,0,0,8,2,1
1,2,52,0,0,0,0,0,0,0,0,52,2,1
1,2,52,0,0,0,0,0,0,0,0,52,2,1
1,2,8,0,0,0,0,0,0,0,0,8,2,1
1,2,2,2,2,10,0,0,10,2,2,2,2,1
5,1,1,1,1,2,2,2,2,1,1,1,1,5
endlayer

layer
5,5,5,5,5,2,2,2,2,5,5,5,5,11
5,1,1,1,2,2,0,0,2,2,1,1,1,5
5,1,1,1,2,2,7,7,2,2,1,1,1,5
5,1,1,1,2,8,0,0,8,2,1,1,1,5
5,1,1,1,2,0,0,0,0,2,1,1,1,5
5,1,1,1,2,0,0,0,0,2,1,1,1,5
5,2,2,2,2,0,0,0,9,2,2,2,2,5
1,2,8,0,0,0,0,0,0,0,0,8,2,1
1,2,10,0,0,0,0,0,0,0,0,10,2,1
1,2,10,0,0,0,0,0,0,0,0,10,2,1
1,2,8,0,0,0,0,0,0,0,0,8,2,1
5,2,2,2,2,10,0,0,10,2,2,2,2,5
11,5,1,1,1,2,2,2,2,1,1,1,5,11
endlayer

layer
11,11,11,11,11,2,2,2,2,11,11,11,11,11
11,5,5,5,2,2,0,0,2,2,5,5,5,11
11,5,13,1,2,2,2,2,2,2,12,12,5,11
11,5,12,5,2,2,0,0,2,2,12,12,5,11
11,5,13,1,2,10,0,0,10,2,12,12,5,11
11,5,12,5,2,10,0,0,10,2,12,12,5,11
11,2,14,2,2,0,0,0,9,2,2,14,2,11
5,2,2,10,0,0,0,0,0,10,10,2,2,5
5,2,10,0,0,0,0,0,0,0,0,10,2,5
5,2,10,0,0,0,0,0,0,0,0,10,2,5
5,2,2,10,10,0,0,0,0,10,10,2,2,5
11,2,2,2,2,10,10,10,10,2,2,2,2,11
11,11,5,5,5,2,2,2,2,5,5,5,11,11
endlayer

layer
11,11,11,0,0,2,2,2,2,0,0,11,11,11
11,15,16,15,2,2,35,35,2,2,15,16,15,11
11,15,19,18,2,2,2,2,2,2,17,17,15,11
11,15,19,18,2,2,2,2,2,2,17,17,15,11
11,15,19,18,2,2,2,2,2,2,17,17,15,0
0,15,19,18,2,2,2,2,2,2,17,17,15,0
0,2,2,2,2,2,2,2,9,2,2,2,2,0
20,2,2,2,2,2,21,21,2,2,2,2,2,20
20,2,2,2,2,2,21,21,2,2,2,2,2,20
20,2,2,2,2,2,21,21,2,2,2,2,2,20
20,2,2,2,2,2,21,21,2,2,2,2,2,20
11,2,2,2,2,2,2,2,2,2,2,2,2,11
11,11,22,22,0,2,23,23,2,0,22,22,11,11
endlayer

layer
11,11,0,0,0,2,2,2,2,0,0,0,11,11
11,0,0,0,24,2,0,0,2,24,0,0,0,11
11,0,0,0,25,2,7,7,2,25,0,0,0,0
0,0,0,0,25,26,0,0,26,25,0,0,0,0
0,0,0,0,25,0,0,0,0,25,0,0,0,0
0,0,0,0,25,28,0,0,27,25,0,0,0,0
0,24,25,25,24,0,0,0,29,24,25,25,24,0
20,25,30,0,0,0,0,0,0,0,0,9,25,20
20,25,32,15,31,0,0,0,0,32,15,31,25,20
20,25,32,15,31,0,0,0,0,32,15,31,25,20
20,25,0,0,0,0,0,0,0,0,0,0,25,20
0,24,25,25,24,25,33,33,25,24,25,25,24,0
11,0,22,22,0,15,0,0,15,0,22,22,0,11
endlayer

layer
11,0,0,0,0,2,2,2,2,0,0,0,0,11
11,0,0,0,24,2,0,0,2,24,0,0,0,0
0,0,0,0,25,2,0,0,2,25,0,0,0,0
0,0,0,0,34,0,0,0,0,34,0,0,0,0
0,0,0,0,34,0,0,0,0,34,0,0,0,0
0,0,0,0,25,0,0,0,18,25,0,0,0,0
0,24,34,34,24,0,0,0,0,24,34,34,24,0
0,25,30,0,0,0,0,0,0,0,0,9,25,0
0,34,0,36,0,0,0,0,0,0,36,0,34,0
0,34,0,36,0,0,0,0,0,0,36,0,34,0
0,25,0,0,0,0,0,0,0,0,0,0,25,0
0,24,34,34,24,25,38,37,25,24,34,34,24,0
0,0,0,0,0,39,0,0,39,0,0,0,0,0
endlayer

layer
11,0,0,0,0,2,2,2,2,0,0,0,0,0
0,0,0,0,24,2,0,0,2,24,0,0,0,0
0,0,0,0,25,2,2,2,2,25,0,0,0,0
0,0,0,0,25,8,0,0,8,25,0,0,0,0
0,0,0,0,25,0,0,0,0,25,0,0,0,0
0,0,0,0,25,0,0,0,0,25,0,0,0,0
0,24,25,25,24,0,0,0,0,24,25,25,24,0
0,25,30,0,0,0,0,0,0,0,0,9,25,0
0,25,0,0,0,0,0,0,0,0,0,0,25,0
0,25,0,0,0,0,0,0,0,0,0,0,25,0
0,25,0,0,0,0,0,0,0,0,0,0,25,0
0,24,25,25,24,25,25,25,25,24,25,25,24,0
0,0,0,0,0,0,0,0,0,0,0,0,0,0
endlayer

layer
0,0,0,31,0,2,2,2,2,0,32,0,0,0
0,0,0,31,24,2,2,2,2,24,32,0,0,0
0,0,0,31,40,2,2,2,2,40,32,0,0,0
0,0,0,31,40,8,8,8,8,40,32,0,0,0
0,0,0,31,40,0,0,0,0,40,32,0,0,0
41,41,41,41,40,0,0,0,0,40,41,41,41,41
0,24,42,42,24,42,42,42,42,24,42,42,24,0
0,40,30,43,40,0,0,0,0,40,43,9,40,0
0,40,43,43,40,0,44,44,0,40,43,43,40,0
0,40,43,43,40,0,44,44,0,40,43,43,40,0
0,40,43,43,40,0,0,0,0,40,43,43,40,0
0,24,42,42,24,42,42,42,42,24,42,42,24,0
45,45,45,45,45,45,45,45,45,45,45,45,45,45
endlayer

layer
0,0,0,0,46,48,2,2,47,46,0,0,0,0
0,0,0,0,46,2,2,2,2,46,0,0,0,0
0,0,0,0,46,2,2,2,2,46,0,0,0,0
0,0,0,0,46,0,0,0,0,46,0,0,0,0
0,0,0,0,46,0,0,0,0,46,0,0,0,0
0,0,0,0,46,0,0,0,0,46,0,0,0,0
46,46,46,46,46,15,15,15,15,46,46,46,46,46
0,25,29,0,15,0,0,0,0,15,0,29,25,0
0,34,0,0,15,0,7,7,0,15,0,0,34,0
0,34,0,0,15,0,7,7,0,15,0,0,34,0
0,25,50,49,15,0,0,0,0,15,50,49,25,0
46,46,46,46,46,46,34,34,46,46,46,46,46,46
0,0,0,0,0,0,0,0,0,0,0,0,0,0
endlayer

layer
0,0,0,0,46,0,2,2,0,46,0,0,0,0
0,0,0,0,46,2,2,2,2,46,0,0,0,0
0,0,0,0,46,2,2,2,2,46,0,0,0,0
0,0,0,0,46,0,0,0,0,46,0,0,0,0
0,0,0,0,46,0,0,0,0,46,0,0,0,0
0,0,0,0,46,0,0,0,0,46,0,0,0,0
46,46,46,46,46,0,0,0,0,46,46,46,46,46
0,25,0,0,0,0,0,0,0,0,0,0,25,0
0,34,0,0,0,0,7,7,0,0,0,0,34,0
0,34,0,0,0,0,7,7,0,0,0,0,34,0
0,25,0,0,0,0,0,0,0,0,0,0,25,0
46,46,46,46,46,46,34,34,46,46,46,46,46,46
0,0,0,0,0,0,0,0,0,0,0,0,0,0
endlayer

layer
0,0,0,0,31,46,0,0,46,32,0,0,0,0
0,0,0,0,31,46,2,2,46,32,0,0,0,0
0,0,0,0,31,46,2,2,46,32,0,0,0,0
0,0,0,0,31,46,0,0,46,32,0,0,0,0
0,0,0,0,31,46,0,0,46,32,0,0,0,0
0,0,0,0,31,46,0,0,46,32,0,0,0,0
41,41,41,41,41,46,0,0,46,32,41,41,41,41
46,46,46,46,46,46,0,0,46,46,46,46,46,46
0,34,0,0,0,0,7,7,0,0,0,0,34,0
0,34,0,0,0,0,7,7,0,0,0,0,34,0
46,46,46,46,46,46,46,46,46,46,46,46,46,46
45,45,45,45,45,45,45,45,45,45,45,45,45,45
0,0,0,0,0,0,0,0,0,0,0,0,0,0
endlayer

layer
0,0,0,0,0,31,46,46,32,0,0,0,0,0
0,0,0,0,0,31,2,2,0,0,0,0,0,0
0,0,0,0,0,31,46,46,32,0,0,0,0,0
0,0,0,0,0,31,46,46,32,0,0,0,0,0
0,0,0,0,0,31,46,46,32,0,0,0,0,0
0,0,0,0,0,31,46,46,32,0,0,0,0,0
0,0,0,0,0,31,46,46,32,0,0,0,0,0
41,41,41,41,41,41,46,46,32,41,41,41,41,41
46,46,46,46,46,46,46,46,46,46,46,46,46,46
46,46,46,46,46,46,46,46,46,46,46,46,46,46
45,45,45,45,45,45,45,45,45,45,45,45,45,45
0,0,0,0,0,0,0,0,0,0,0,0,0,0
0,0,0,0,0,0,0,0,0,0,0,0,0,0
endlayer

layer
0,0,0,0,0,0,46,46,0,0,0,0,0,0
0,0,0,0,0,0,2,2,0,0,0,0,0,0
0,0,0,0,0,0,45,45,0,0,0,0,0,0
0,0,0,0,0,0,51,51,0,0,0,0,0,0
0,0,0,0,0,0,51,51,0,0,0,0,0,0
0,0,0,0,0,0,51,51,0,0,0,0,0,0
0,0,0,0,0,0,51,51,0,0,0,0,0,0
0,0,0,0,0,0,51,51,0,0,0,0,0,0
46,32,51,51,51,51,51,51,51,51,51,51,31,46
46,32,51,51,51,51,51,51,51,51,51,51,31,46
0,0,0,0,0,0,0,0,0,0,0,0,0,0
0,0,0,0,0,0,0,0,0,0,0,0,0,0
0,0,0,0,0,0,0,0,0,0,0,0,0,0
endlayer

layer
0,0,0,0,0,0,46,46,0,0,0,0,0,0
0,0,0,0,0,0,2,2,0,0,0,0,0,0
0,0,0,0,0,0,0,0,0,0,0,0,0,0
0,0,0,0,0,0,0,0,0,0,0,0,0,0
0,0,0,0,0,0,0,0,0,0,0,0,0,0
0,0,0,0,0,0,0,0,0,0,0,0,0,0
0,0,0,0,0,0,0,0,0,0,0,0,0,0
0,0,0,0,0,0,0,0,0,0,0,0,0,0
46,0,0,0,0,0,0,0,0,0,0,0,0,46
46,0,0,0,0,0,0,0,0,0,0,0,0,46
0,0,0,0,0,0,0,0,0,0,0,0,0,0
0,0,0,0,0,0,0,0,0,0,0,0,0,0
0,0,0,0,0,0,0,0,0,0,0,0,0,0
endlayer

layer
0,0,0,0,0,0,45,45,0,0,0,0,0,0
0,0,0,0,0,0,2,2,0,0,0,0,0,0
0,0,0,0,0,0,0,0,0,0,0,0,0,0
0,0,0,0,0,0,0,0,0,0,0,0,0,0
0,0,0,0,0,0,0,0,0,0,0,0,0,0
0,0,0,0,0,0,0,0,0,0,0,0,0,0
0,0,0,0,0,0,0,0,0,0,0,0,0,0
0,0,0,0,0,0,0,0,0,0,0,0,0,0
32,0,0,0,0,0,0,0,0,0,0,0,0,31
32,0,0,0,0,0,0,0,0,0,0,0,0,31
0,0,0,0,0,0,0,0,0,0,0,0,0,0
0,0,0,0,0,0,0,0,0,0,0,0,0,0
0,0,0,0,0,0,0,0,0,0,0,0,0,0
endlayer

layer
0,0,0,0,0,0,0,0,0,0,0,0,0,0
0,0,0,0,0,0,2,2,0,0,0,0,0,0
0,0,0,0,0,0,0,0,0,0,0,0,0,0
0,0,0,0,0,0,0,0,0,0,0,0,0,0
0,0,0,0,0,0,0,0,0,0,0,0,0,0
0,0,0,0,0,0,0,0,0,0,0,0,0,0
0,0,0,0,0,0,0,0,0,0,0,0,0,0
0,0,0,0,0,0,0,0,0,0,0,0,0,0
0,0,0,0,0,0,0,0,0,0,0,0,0,0
0,0,0,0,0,0,0,0,0,0,0,0,0,0
0,0,0,0,0,0,0,0,0,0,0,0,0,0
0,0,0,0,0,0,0,0,0,0,0,0,0,0
0,0,0,0,0,0,0,0,0,0,0,0,0,0
endlayer

layer
0,0,0,0,0,0,2,2,0,0,0,0,0,0
0,0,0,0,0,2,3,3,2,0,0,0,0,0
0,0,0,0,0,0,2,2,0,0,0,0,0,0
0,0,0,0,0,0,0,0,0,0,0,0,0,0
0,0,0,0,0,0,0,0,0,0,0,0,0,0
0,0,0,0,0,0,0,0,0,0,0,0,0,0
0,0,0,0,0,0,0,0,0,0,0,0,0,0
0,0,0,0,0,0,0,0,0,0,0,0,0,0
0,0,0,0,0,0,0,0,0,0,0,0,0,0
0,0,0,0,0,0,0,0,0,0,0,0,0,0
0,0,0,0,0,0,0,0,0,0,0,0,0,0
0,0,0,0,0,0,0,0,0,0,0,0,0,0
0,0,0,0,0,0,0,0,0,0,0,0,0,0
endlayer

layer
0,0,0,0,0,0,2,2,0,0,0,0,0,0
0,0,0,0,0,2,6,6,2,0,0,0,0,0
0,0,0,0,0,0,2,2,0,0,0,0,0,0
0,0,0,0,0,0,0,0,0,0,0,0,0,0
0,0,0,0,0,0,0,0,0,0,0,0,0,0
0,0,0,0,0,0,0,0,0,0,0,0,0,0
0,0,0,0,0,0,0,0,0,0,0,0,0,0
0,0,0,0,0,0,0,0,0,0,0,0,0,0
0,0,0,0,0,0,0,0,0,0,0,0,0,0
0,0,0,0,0,0,0,0,0,0,0,0,0,0
0,0,0,0,0,0,0,0,0,0,0,0,0,0
0,0,0,0,0,0,0,0,0,0,0,0,0,0
0,0,0,0,0,0,0,0,0,0,0,0,0,0
endlayer

