# Tower Dungeon Base
# Created by Ruins mod version 15.6 Ingame Parser
# authoring Player: Jordan_Greywolf
# Created for MC 1.8: 30 May 2016
# Updated for MC 1.9: 30 May 2016
# Updated for MC 1.10: 13 Sep 2016
# Updated to MC 1.11: 13 Jan 2017
# Verified for MC 1.12: 23 Jun 2017
# Updated to MC 1.12.1: 10 Sep 2017

# Last Updated: 9 Jun 2018


biomesToSpawnIn=bayou,birch forest,birch_forest,bog,brushland,chaparral,dead forest,dead_forest,dead swamp,dead_swamp,eerie,eldritch,fen,flower field,flower_field,forest,grassland,grove,heathland,land of lakes,land_of_lakes,lavender fields,lavender_fields,lush swamp,lush_swamp,magical forest,mangrove,maple woods,maple_woods,marsh,meadow,moor,mountain foothills,mystic grove,ominous woods,orchard,origin island,origin_island,outback,plains,prairie,quagmire,seasonal forest,seasonal_forest,shield,shrubland,sunflower plains,swampland,tainted land,wasteland,wetland,woodland,xeric shrubland,xeric_shrubland,mutated_plains

uniqueMinDistance=2000
spawnMinDistance=800

weight=1
embed_into_distance=44
acceptable_target_blocks=

unacceptable_target_blocks=cloud,Natura:Cloud,slime_congealed,slime_dirt,slime_grass,command_block,planks,planks2,concrete,cobblestone,stonebrick,brick_block,glass,torch,oak_stairs,stone_stairs,brick_stairs,stone_brick_stairs,nether_brick_stairs,sandstone_stairs,spruce_stairs,birch_stairs,jungle_stairs,quartz_stairs,acacia_stairs,dark_oak_stairs,cobblestone_wall,stone_slab,double_stone_slab,stone_slab2,wooden_slab,double_wooden_slab,nether_brick,fence

dimensions=51,11,11
allowable_overhang=0
max_leveling=20
leveling_buffer=-1
preserve_water=0
preserve_lava=0
preserve_plants=1

rule1=0,100,preserveBlock

rule2=0,100,minecraft:stonebrick-0,minecraft:stonebrick-0,minecraft:stonebrick-1,minecraft:stonebrick-1,minecraft:stonebrick-2

rule3=0,100,minecraft:stone-2
rule4=0,100,minecraft:stone-6
rule5=0,100,minecraft:stone-4
rule6=0,100,minecraft:stone_brick_stairs-3
rule7=0,100,minecraft:stone_brick_stairs-1
rule8=0,100,minecraft:stone_brick_stairs-2

rule9=0,100,CommandBlock:RUINSTRIGGER /testruin TP_Decor_BookVault ~-4 ~0 ~0:@,CommandBlock:RUINSTRIGGER /testruin TP_Decor_MonsterVault ~-4 ~0 ~0:@,CommandBlock:RUINSTRIGGER /testruin TP_Decor_SkullVault ~-4 ~0 ~0:@,CommandBlock:RUINSTRIGGER /testruin TP_Decor_LavaVault ~-4 ~0 ~0:@,CommandBlock:RUINSTRIGGER /testruin TP_Decor_Fountain ~-4 ~1 ~0:@,CommandBlock:RUINSTRIGGER /testruin TP_Decor_Garden ~-4 ~0 ~0:@,CommandBlock:RUINSTRIGGER /testruin TP_Mine_Tunnel ~-12 ~0 ~0 1:@

rule10=0,100,CommandBlock:RUINSTRIGGER /testruin TP_Decor_BookVault ~0 ~0 ~-4:@,CommandBlock:RUINSTRIGGER /testruin TP_Decor_MonsterVault ~0 ~0 ~-4:@,CommandBlock:RUINSTRIGGER /testruin TP_Decor_SkullVault ~0 ~0 ~-4:@,CommandBlock:RUINSTRIGGER /testruin TP_Decor_LavaVault ~0 ~0 ~-4:@,CommandBlock:RUINSTRIGGER /testruin TP_Decor_Fountain ~0 ~1 ~-4:@,CommandBlock:RUINSTRIGGER /testruin TP_Decor_Garden ~0 ~0 ~-4:@,CommandBlock:RUINSTRIGGER /testruin TP_Mine_Tunnel ~-0 ~0 ~-12:@

rule11=0,100,minecraft:stone_brick_stairs-4

rule12=0,100,CommandBlock:RUINSTRIGGER /testruin TP_Decor_BookVault ~0 ~0 ~4:@,CommandBlock:RUINSTRIGGER /testruin TP_Decor_MonsterVault ~0 ~0 ~4:@,CommandBlock:RUINSTRIGGER /testruin TP_Decor_SkullVault ~0 ~0 ~4:@,CommandBlock:RUINSTRIGGER /testruin TP_Decor_LavaVault ~0 ~0 ~4:@,CommandBlock:RUINSTRIGGER /testruin TP_Decor_Fountain ~0 ~1 ~4:@,CommandBlock:RUINSTRIGGER /testruin TP_Decor_Garden ~0 ~0 ~4:@,CommandBlock:RUINSTRIGGER /testruin TP_Mine_Tunnel ~-0 ~0 ~12:@

rule13=0,100,minecraft:stone_brick_stairs-0

rule14=0,100,CommandBlock:RUINSTRIGGER /testruin TP_Decor_BookVault ~4 ~0 ~0:@,CommandBlock:RUINSTRIGGER /testruin TP_Decor_MonsterVault ~4 ~0 ~0:@,CommandBlock:RUINSTRIGGER /testruin TP_Decor_SkullVault ~4 ~0 ~0:@,CommandBlock:RUINSTRIGGER /testruin TP_Decor_LavaVault ~4 ~0 ~0:@,CommandBlock:RUINSTRIGGER /testruin TP_Decor_Fountain ~4 ~1 ~0:@,CommandBlock:RUINSTRIGGER /testruin TP_Decor_Garden ~4 ~0 ~0:@,CommandBlock:RUINSTRIGGER /testruin TP_Mine_Tunnel ~12 ~0 ~0 1:@

rule15=0,100,minecraft:cobblestone_wall-0,minecraft:cobblestone_wall-1

rule16=0,100,minecraft:iron_bars-0
rule17=0,100,minecraft:stone_brick_stairs-7
rule18=0,100,minecraft:stone_brick_stairs-5
rule19=0,100,minecraft:stone_brick_stairs-6

rule20=1,100,minecraft:stonebrick-2,minecraft:stonebrick-2,minecraft:stonebrick-2,minecraft:stonebrick-2,minecraft:stonebrick-2,minecraft:stonebrick-2,minecraft:stonebrick-2,minecraft:stonebrick-2,minecraft:stonebrick-2,preserveBlock

rule21=0,100,minecraft:stone_slab-13
rule22=0,100,minecraft:stonebrick-3

# Bedrock Buffer
layer
1,1,1,1,1,1,1,1,1,1,1
1,1,1,1,1,1,1,1,1,1,1
1,1,1,1,1,1,1,1,1,1,1
1,1,1,1,1,1,1,1,1,1,1
1,1,1,1,1,1,1,1,1,1,1
1,1,1,1,1,1,1,1,1,1,1
1,1,1,1,1,1,1,1,1,1,1
1,1,1,1,1,1,1,1,1,1,1
1,1,1,1,1,1,1,1,1,1,1
1,1,1,1,1,1,1,1,1,1,1
1,1,1,1,1,1,1,1,1,1,1
endlayer


# Bottom Floor
layer
1,2,2,2,2,2,2,2,2,2,1
2,2,2,2,3,3,3,2,2,2,2
2,2,2,4,5,3,5,4,2,2,2
2,2,4,4,5,5,5,4,4,2,2
2,3,5,5,3,4,3,5,5,3,2
2,3,3,5,4,5,4,5,3,3,2
2,3,5,5,3,4,3,5,5,3,2
2,2,4,4,5,5,5,4,4,2,2
2,2,2,4,5,3,5,4,2,2,2
2,2,2,2,3,3,3,2,2,2,2
1,2,2,2,2,2,2,2,2,2,1
endlayer

# Underground 1
layer
1,2,2,8,2,7,2,6,2,2,1
2,2,7,8,0,9,0,7,6,2,2
2,7,8,0,0,0,0,0,7,6,2
7,8,0,0,0,0,0,0,0,7,7
2,0,0,0,0,0,0,0,0,0,2
8,12,0,0,0,4,11,0,0,10,6
2,0,0,0,0,0,7,0,0,0,2
13,13,0,0,0,0,0,0,0,6,13
2,8,13,0,0,0,0,0,6,13,2
2,2,8,13,0,14,0,6,13,2,2
1,2,2,8,2,13,2,6,2,2,1
endlayer

# Underground 2
layer
1,2,2,15,2,16,2,15,2,2,1
2,2,0,0,0,0,0,0,0,2,2
2,0,0,0,0,0,0,0,0,0,2
15,0,0,0,0,0,0,0,0,0,15
2,0,0,0,0,0,11,0,0,0,2
16,0,0,0,0,3,7,0,0,0,16
2,0,0,0,0,0,0,0,0,0,2
15,0,0,0,0,0,0,0,0,0,15
2,0,0,0,0,0,0,0,0,0,2
2,2,0,0,0,0,0,0,0,2,2
1,2,2,15,2,16,2,15,2,2,1
endlayer

# Underground 3
layer
1,2,15,15,2,16,2,15,15,2,1
2,15,0,0,0,0,0,0,0,15,2
15,0,0,0,0,0,0,0,0,0,15
15,0,0,0,0,0,0,0,0,0,15
2,0,0,0,0,17,7,0,0,0,2
16,0,0,0,0,5,0,0,0,0,16
2,0,0,0,0,0,0,0,0,0,2
15,0,0,0,0,0,0,0,0,0,15
15,0,0,0,0,0,0,0,0,0,15
2,15,0,0,0,0,0,0,0,15,2
1,2,15,15,2,16,2,15,15,2,1
endlayer

# Underground 4
layer
1,2,2,15,2,16,2,15,2,2,1
2,2,0,0,0,0,0,0,0,2,2
2,0,0,0,0,0,0,0,0,0,2
15,0,0,0,0,0,0,0,0,0,15
2,0,0,0,17,8,0,0,0,0,2
16,0,0,0,0,4,0,0,0,0,16
2,0,0,0,0,0,0,0,0,0,2
15,0,0,0,0,0,0,0,0,0,15
2,0,0,0,0,0,0,0,0,0,2
2,2,0,0,0,0,0,0,0,2,2
1,2,2,15,2,16,2,15,2,2,1
endlayer

# Underground 5
layer
1,2,2,19,2,18,2,17,2,2,1
2,2,19,18,0,0,0,17,18,2,2
2,19,18,0,0,0,0,0,17,18,2
18,18,0,0,0,0,0,0,0,17,18
2,0,0,0,8,0,0,0,0,0,2
19,0,0,0,18,3,0,0,0,0,17
2,0,0,0,0,0,0,0,0,0,2
11,11,0,0,0,0,0,0,0,17,11
2,19,11,0,0,0,0,0,17,11,2
2,2,19,11,0,0,0,17,11,2,2
1,2,2,19,2,11,2,17,2,2,1
endlayer

# Underground 6
layer
1,2,2,2,2,2,2,2,2,2,1
2,2,2,2,3,3,3,2,2,2,2
2,2,2,4,5,3,5,4,2,2,2
2,2,4,4,5,5,5,4,4,2,2
2,3,5,5,0,0,0,5,5,3,2
2,3,3,5,13,5,4,5,3,3,2
2,3,5,5,3,4,3,5,5,3,2
2,2,4,4,5,5,5,4,4,2,2
2,2,2,4,5,3,5,4,2,2,2
2,2,2,2,3,3,3,2,2,2,2
1,2,2,2,2,2,2,2,2,2,1
endlayer

# Underground 1
layer
1,2,2,8,2,7,2,6,2,2,1
2,2,7,8,0,9,0,7,6,2,2
2,7,8,0,0,0,0,0,7,6,2
7,8,0,0,0,0,0,0,0,7,7
2,0,0,0,0,0,0,0,0,0,2
8,12,0,0,0,4,11,0,0,10,6
2,0,0,0,0,0,7,0,0,0,2
13,13,0,0,0,0,0,0,0,6,13
2,8,13,0,0,0,0,0,6,13,2
2,2,8,13,0,14,0,6,13,2,2
1,2,2,8,2,13,2,6,2,2,1
endlayer

# Underground 2
layer
1,2,2,15,2,16,2,15,2,2,1
2,2,0,0,0,0,0,0,0,2,2
2,0,0,0,0,0,0,0,0,0,2
15,0,0,0,0,0,0,0,0,0,15
2,0,0,0,0,0,11,0,0,0,2
16,0,0,0,0,3,7,0,0,0,16
2,0,0,0,0,0,0,0,0,0,2
15,0,0,0,0,0,0,0,0,0,15
2,0,0,0,0,0,0,0,0,0,2
2,2,0,0,0,0,0,0,0,2,2
1,2,2,15,2,16,2,15,2,2,1
endlayer

# Underground 3
layer
1,2,15,15,2,16,2,15,15,2,1
2,15,0,0,0,0,0,0,0,15,2
15,0,0,0,0,0,0,0,0,0,15
15,0,0,0,0,0,0,0,0,0,15
2,0,0,0,0,17,7,0,0,0,2
16,0,0,0,0,5,0,0,0,0,16
2,0,0,0,0,0,0,0,0,0,2
15,0,0,0,0,0,0,0,0,0,15
15,0,0,0,0,0,0,0,0,0,15
2,15,0,0,0,0,0,0,0,15,2
1,2,15,15,2,16,2,15,15,2,1
endlayer

# Underground 4
layer
1,2,2,15,2,16,2,15,2,2,1
2,2,0,0,0,0,0,0,0,2,2
2,0,0,0,0,0,0,0,0,0,2
15,0,0,0,0,0,0,0,0,0,15
2,0,0,0,17,8,0,0,0,0,2
16,0,0,0,0,4,0,0,0,0,16
2,0,0,0,0,0,0,0,0,0,2
15,0,0,0,0,0,0,0,0,0,15
2,0,0,0,0,0,0,0,0,0,2
2,2,0,0,0,0,0,0,0,2,2
1,2,2,15,2,16,2,15,2,2,1
endlayer

# Underground 5
layer
1,2,2,19,2,18,2,17,2,2,1
2,2,19,18,0,0,0,17,18,2,2
2,19,18,0,0,0,0,0,17,18,2
18,18,0,0,0,0,0,0,0,17,18
2,0,0,0,8,0,0,0,0,0,2
19,0,0,0,18,3,0,0,0,0,17
2,0,0,0,0,0,0,0,0,0,2
11,11,0,0,0,0,0,0,0,17,11
2,19,11,0,0,0,0,0,17,11,2
2,2,19,11,0,0,0,17,11,2,2
1,2,2,19,2,11,2,17,2,2,1
endlayer

# Underground 6
layer
1,2,2,2,2,2,2,2,2,2,1
2,2,2,2,3,3,3,2,2,2,2
2,2,2,4,5,3,5,4,2,2,2
2,2,4,4,5,5,5,4,4,2,2
2,3,5,5,0,0,0,5,5,3,2
2,3,3,5,13,5,4,5,3,3,2
2,3,5,5,3,4,3,5,5,3,2
2,2,4,4,5,5,5,4,4,2,2
2,2,2,4,5,3,5,4,2,2,2
2,2,2,2,3,3,3,2,2,2,2
1,2,2,2,2,2,2,2,2,2,1
endlayer

# Underground 1
layer
1,2,2,8,2,7,2,6,2,2,1
2,2,7,8,0,9,0,7,6,2,2
2,7,8,0,0,0,0,0,7,6,2
7,8,0,0,0,0,0,0,0,7,7
2,0,0,0,0,0,0,0,0,0,2
8,12,0,0,0,4,11,0,0,10,6
2,0,0,0,0,0,7,0,0,0,2
13,13,0,0,0,0,0,0,0,6,13
2,8,13,0,0,0,0,0,6,13,2
2,2,8,13,0,14,0,6,13,2,2
1,2,2,8,2,13,2,6,2,2,1
endlayer

# Underground 2
layer
1,2,2,15,2,16,2,15,2,2,1
2,2,0,0,0,0,0,0,0,2,2
2,0,0,0,0,0,0,0,0,0,2
15,0,0,0,0,0,0,0,0,0,15
2,0,0,0,0,0,11,0,0,0,2
16,0,0,0,0,3,7,0,0,0,16
2,0,0,0,0,0,0,0,0,0,2
15,0,0,0,0,0,0,0,0,0,15
2,0,0,0,0,0,0,0,0,0,2
2,2,0,0,0,0,0,0,0,2,2
1,2,2,15,2,16,2,15,2,2,1
endlayer

# Underground 3
layer
1,2,15,15,2,16,2,15,15,2,1
2,15,0,0,0,0,0,0,0,15,2
15,0,0,0,0,0,0,0,0,0,15
15,0,0,0,0,0,0,0,0,0,15
2,0,0,0,0,17,7,0,0,0,2
16,0,0,0,0,5,0,0,0,0,16
2,0,0,0,0,0,0,0,0,0,2
15,0,0,0,0,0,0,0,0,0,15
15,0,0,0,0,0,0,0,0,0,15
2,15,0,0,0,0,0,0,0,15,2
1,2,15,15,2,16,2,15,15,2,1
endlayer

# Underground 4
layer
1,2,2,15,2,16,2,15,2,2,1
2,2,0,0,0,0,0,0,0,2,2
2,0,0,0,0,0,0,0,0,0,2
15,0,0,0,0,0,0,0,0,0,15
2,0,0,0,17,8,0,0,0,0,2
16,0,0,0,0,4,0,0,0,0,16
2,0,0,0,0,0,0,0,0,0,2
15,0,0,0,0,0,0,0,0,0,15
2,0,0,0,0,0,0,0,0,0,2
2,2,0,0,0,0,0,0,0,2,2
1,2,2,15,2,16,2,15,2,2,1
endlayer

# Underground 5
layer
1,2,2,19,2,18,2,17,2,2,1
2,2,19,18,0,0,0,17,18,2,2
2,19,18,0,0,0,0,0,17,18,2
18,18,0,0,0,0,0,0,0,17,18
2,0,0,0,8,0,0,0,0,0,2
19,0,0,0,18,3,0,0,0,0,17
2,0,0,0,0,0,0,0,0,0,2
11,11,0,0,0,0,0,0,0,17,11
2,19,11,0,0,0,0,0,17,11,2
2,2,19,11,0,0,0,17,11,2,2
1,2,2,19,2,11,2,17,2,2,1
endlayer

# Underground 6
layer
1,2,2,2,2,2,2,2,2,2,1
2,2,2,2,3,3,3,2,2,2,2
2,2,2,4,5,3,5,4,2,2,2
2,2,4,4,5,5,5,4,4,2,2
2,3,5,5,0,0,0,5,5,3,2
2,3,3,5,13,5,4,5,3,3,2
2,3,5,5,3,4,3,5,5,3,2
2,2,4,4,5,5,5,4,4,2,2
2,2,2,4,5,3,5,4,2,2,2
2,2,2,2,3,3,3,2,2,2,2
1,2,2,2,2,2,2,2,2,2,1
endlayer

# Underground 1
layer
1,2,2,8,2,7,2,6,2,2,1
2,2,7,8,0,9,0,7,6,2,2
2,7,8,0,0,0,0,0,7,6,2
7,8,0,0,0,0,0,0,0,7,7
2,0,0,0,0,0,0,0,0,0,2
8,12,0,0,0,4,11,0,0,10,6
2,0,0,0,0,0,7,0,0,0,2
13,13,0,0,0,0,0,0,0,6,13
2,8,13,0,0,0,0,0,6,13,2
2,2,8,13,0,14,0,6,13,2,2
1,2,2,8,2,13,2,6,2,2,1
endlayer

# Underground 2
layer
1,2,2,15,2,16,2,15,2,2,1
2,2,0,0,0,0,0,0,0,2,2
2,0,0,0,0,0,0,0,0,0,2
15,0,0,0,0,0,0,0,0,0,15
2,0,0,0,0,0,11,0,0,0,2
16,0,0,0,0,3,7,0,0,0,16
2,0,0,0,0,0,0,0,0,0,2
15,0,0,0,0,0,0,0,0,0,15
2,0,0,0,0,0,0,0,0,0,2
2,2,0,0,0,0,0,0,0,2,2
1,2,2,15,2,16,2,15,2,2,1
endlayer

# Underground 3
layer
1,2,15,15,2,16,2,15,15,2,1
2,15,0,0,0,0,0,0,0,15,2
15,0,0,0,0,0,0,0,0,0,15
15,0,0,0,0,0,0,0,0,0,15
2,0,0,0,0,17,7,0,0,0,2
16,0,0,0,0,5,0,0,0,0,16
2,0,0,0,0,0,0,0,0,0,2
15,0,0,0,0,0,0,0,0,0,15
15,0,0,0,0,0,0,0,0,0,15
2,15,0,0,0,0,0,0,0,15,2
1,2,15,15,2,16,2,15,15,2,1
endlayer

# Underground 4
layer
1,2,2,15,2,16,2,15,2,2,1
2,2,0,0,0,0,0,0,0,2,2
2,0,0,0,0,0,0,0,0,0,2
15,0,0,0,0,0,0,0,0,0,15
2,0,0,0,17,8,0,0,0,0,2
16,0,0,0,0,4,0,0,0,0,16
2,0,0,0,0,0,0,0,0,0,2
15,0,0,0,0,0,0,0,0,0,15
2,0,0,0,0,0,0,0,0,0,2
2,2,0,0,0,0,0,0,0,2,2
1,2,2,15,2,16,2,15,2,2,1
endlayer

# Underground 5
layer
1,2,2,19,2,18,2,17,2,2,1
2,2,19,18,0,0,0,17,18,2,2
2,19,18,0,0,0,0,0,17,18,2
18,18,0,0,0,0,0,0,0,17,18
2,0,0,0,8,0,0,0,0,0,2
19,0,0,0,18,3,0,0,0,0,17
2,0,0,0,0,0,0,0,0,0,2
11,11,0,0,0,0,0,0,0,17,11
2,19,11,0,0,0,0,0,17,11,2
2,2,19,11,0,0,0,17,11,2,2
1,2,2,19,2,11,2,17,2,2,1
endlayer

# Underground 6
layer
1,2,2,2,2,2,2,2,2,2,1
2,2,2,2,3,3,3,2,2,2,2
2,2,2,4,5,3,5,4,2,2,2
2,2,4,4,5,5,5,4,4,2,2
2,3,5,5,0,0,0,5,5,3,2
2,3,3,5,13,5,4,5,3,3,2
2,3,5,5,3,4,3,5,5,3,2
2,2,4,4,5,5,5,4,4,2,2
2,2,2,4,5,3,5,4,2,2,2
2,2,2,2,3,3,3,2,2,2,2
1,2,2,2,2,2,2,2,2,2,1
endlayer

# Underground 1
layer
1,2,2,8,2,7,2,6,2,2,1
2,2,7,8,0,9,0,7,6,2,2
2,7,8,0,0,0,0,0,7,6,2
7,8,0,0,0,0,0,0,0,7,7
2,0,0,0,0,0,0,0,0,0,2
8,12,0,0,0,4,11,0,0,10,6
2,0,0,0,0,0,7,0,0,0,2
13,13,0,0,0,0,0,0,0,6,13
2,8,13,0,0,0,0,0,6,13,2
2,2,8,13,0,14,0,6,13,2,2
1,2,2,8,2,13,2,6,2,2,1
endlayer

# Underground 2
layer
1,2,2,15,2,16,2,15,2,2,1
2,2,0,0,0,0,0,0,0,2,2
2,0,0,0,0,0,0,0,0,0,2
15,0,0,0,0,0,0,0,0,0,15
2,0,0,0,0,0,11,0,0,0,2
16,0,0,0,0,3,7,0,0,0,16
2,0,0,0,0,0,0,0,0,0,2
15,0,0,0,0,0,0,0,0,0,15
2,0,0,0,0,0,0,0,0,0,2
2,2,0,0,0,0,0,0,0,2,2
1,2,2,15,2,16,2,15,2,2,1
endlayer

# Underground 3
layer
1,2,15,15,2,16,2,15,15,2,1
2,15,0,0,0,0,0,0,0,15,2
15,0,0,0,0,0,0,0,0,0,15
15,0,0,0,0,0,0,0,0,0,15
2,0,0,0,0,17,7,0,0,0,2
16,0,0,0,0,5,0,0,0,0,16
2,0,0,0,0,0,0,0,0,0,2
15,0,0,0,0,0,0,0,0,0,15
15,0,0,0,0,0,0,0,0,0,15
2,15,0,0,0,0,0,0,0,15,2
1,2,15,15,2,16,2,15,15,2,1
endlayer

# Underground 4
layer
1,2,2,15,2,16,2,15,2,2,1
2,2,0,0,0,0,0,0,0,2,2
2,0,0,0,0,0,0,0,0,0,2
15,0,0,0,0,0,0,0,0,0,15
2,0,0,0,17,8,0,0,0,0,2
16,0,0,0,0,4,0,0,0,0,16
2,0,0,0,0,0,0,0,0,0,2
15,0,0,0,0,0,0,0,0,0,15
2,0,0,0,0,0,0,0,0,0,2
2,2,0,0,0,0,0,0,0,2,2
1,2,2,15,2,16,2,15,2,2,1
endlayer

# Underground 5
layer
1,2,2,19,2,18,2,17,2,2,1
2,2,19,18,0,0,0,17,18,2,2
2,19,18,0,0,0,0,0,17,18,2
18,18,0,0,0,0,0,0,0,17,18
2,0,0,0,8,0,0,0,0,0,2
19,0,0,0,18,3,0,0,0,0,17
2,0,0,0,0,0,0,0,0,0,2
11,11,0,0,0,0,0,0,0,17,11
2,19,11,0,0,0,0,0,17,11,2
2,2,19,11,0,0,0,17,11,2,2
1,2,2,19,2,11,2,17,2,2,1
endlayer

# Underground 6
layer
1,2,2,2,2,2,2,2,2,2,1
2,2,2,2,3,3,3,2,2,2,2
2,2,2,4,5,3,5,4,2,2,2
2,2,4,4,5,5,5,4,4,2,2
2,3,5,5,0,0,0,5,5,3,2
2,3,3,5,13,5,4,5,3,3,2
2,3,5,5,3,4,3,5,5,3,2
2,2,4,4,5,5,5,4,4,2,2
2,2,2,4,5,3,5,4,2,2,2
2,2,2,2,3,3,3,2,2,2,2
1,2,2,2,2,2,2,2,2,2,1
endlayer

# Underground 1
layer
1,2,2,8,2,7,2,6,2,2,1
2,2,7,8,0,9,0,7,6,2,2
2,7,8,0,0,0,0,0,7,6,2
7,8,0,0,0,0,0,0,0,7,7
2,0,0,0,0,0,0,0,0,0,2
8,12,0,0,0,4,11,0,0,10,6
2,0,0,0,0,0,7,0,0,0,2
13,13,0,0,0,0,0,0,0,6,13
2,8,13,0,0,0,0,0,6,13,2
2,2,8,13,0,14,0,6,13,2,2
1,2,2,8,2,13,2,6,2,2,1
endlayer

# Underground 2
layer
1,2,2,15,2,16,2,15,2,2,1
2,2,0,0,0,0,0,0,0,2,2
2,0,0,0,0,0,0,0,0,0,2
15,0,0,0,0,0,0,0,0,0,15
2,0,0,0,0,0,11,0,0,0,2
16,0,0,0,0,3,7,0,0,0,16
2,0,0,0,0,0,0,0,0,0,2
15,0,0,0,0,0,0,0,0,0,15
2,0,0,0,0,0,0,0,0,0,2
2,2,0,0,0,0,0,0,0,2,2
1,2,2,15,2,16,2,15,2,2,1
endlayer

# Underground 3
layer
1,2,15,15,2,16,2,15,15,2,1
2,15,0,0,0,0,0,0,0,15,2
15,0,0,0,0,0,0,0,0,0,15
15,0,0,0,0,0,0,0,0,0,15
2,0,0,0,0,17,7,0,0,0,2
16,0,0,0,0,5,0,0,0,0,16
2,0,0,0,0,0,0,0,0,0,2
15,0,0,0,0,0,0,0,0,0,15
15,0,0,0,0,0,0,0,0,0,15
2,15,0,0,0,0,0,0,0,15,2
1,2,15,15,2,16,2,15,15,2,1
endlayer

# Underground 4
layer
1,2,2,15,2,16,2,15,2,2,1
2,2,0,0,0,0,0,0,0,2,2
2,0,0,0,0,0,0,0,0,0,2
15,0,0,0,0,0,0,0,0,0,15
2,0,0,0,17,8,0,0,0,0,2
16,0,0,0,0,4,0,0,0,0,16
2,0,0,0,0,0,0,0,0,0,2
15,0,0,0,0,0,0,0,0,0,15
2,0,0,0,0,0,0,0,0,0,2
2,2,0,0,0,0,0,0,0,2,2
1,2,2,15,2,16,2,15,2,2,1
endlayer

# Underground 5
layer
1,2,2,19,2,18,2,17,2,2,1
2,2,19,18,0,0,0,17,18,2,2
2,19,18,0,0,0,0,0,17,18,2
18,18,0,0,0,0,0,0,0,17,18
2,0,0,0,8,0,0,0,0,0,2
19,0,0,0,18,3,0,0,0,0,17
2,0,0,0,0,0,0,0,0,0,2
11,11,0,0,0,0,0,0,0,17,11
2,19,11,0,0,0,0,0,17,11,2
2,2,19,11,0,0,0,17,11,2,2
1,2,2,19,2,11,2,17,2,2,1
endlayer

# Underground 6
layer
1,2,2,2,2,2,2,2,2,2,1
2,2,2,2,3,3,3,2,2,2,2
2,2,2,4,5,3,5,4,2,2,2
2,2,4,4,5,5,5,4,4,2,2
2,3,5,5,0,0,0,5,5,3,2
2,3,3,5,13,5,4,5,3,3,2
2,3,5,5,3,4,3,5,5,3,2
2,2,4,4,5,5,5,4,4,2,2
2,2,2,4,5,3,5,4,2,2,2
2,2,2,2,3,3,3,2,2,2,2
1,2,2,2,2,2,2,2,2,2,1
endlayer

# Underground 1 (top)
layer
1,2,2,8,2,7,2,6,2,2,1
2,2,7,8,0,0,0,7,6,2,2
2,7,8,0,0,0,0,0,7,6,2
7,8,0,0,0,0,0,0,0,7,7
2,0,0,0,0,0,0,0,0,0,2
8,0,0,0,0,4,11,0,0,0,6
2,0,0,0,0,0,7,0,0,0,2
13,13,0,0,0,0,0,0,0,6,13
2,8,13,0,0,0,0,0,6,13,2
2,2,8,13,0,0,0,6,13,2,2
1,2,2,8,2,13,2,6,2,2,1
endlayer

# Underground 2 (top)
layer
1,2,2,15,2,16,2,15,2,2,1
2,2,0,0,0,0,0,0,0,2,2
2,0,0,0,0,0,0,0,0,0,2
15,0,0,0,0,0,0,0,0,0,15
2,0,0,0,0,0,11,0,0,0,2
16,0,0,0,0,3,7,0,0,0,16
2,0,0,0,0,0,0,0,0,0,2
15,0,0,0,0,0,0,0,0,0,15
2,0,0,0,0,0,0,0,0,0,2
2,2,0,0,0,0,0,0,0,2,2
1,2,2,15,2,16,2,15,2,2,1
endlayer

# Underground 3 (top)
layer
1,2,15,15,2,16,2,15,15,2,1
2,15,0,0,0,0,0,0,0,15,2
15,0,0,0,0,0,0,0,0,0,15
15,0,0,0,0,0,0,0,0,0,15
2,0,0,0,0,17,7,0,0,0,2
16,0,0,0,0,5,0,0,0,0,16
2,0,0,0,0,0,0,0,0,0,2
15,0,0,0,0,0,0,0,0,0,15
15,0,0,0,0,0,0,0,0,0,15
2,15,0,0,0,0,0,0,0,15,2
1,2,15,15,2,16,2,15,15,2,1
endlayer

# Underground 4 (top)
layer
1,2,2,15,2,16,2,15,2,2,1
2,2,0,0,0,0,0,0,0,2,2
2,0,0,0,0,0,0,0,0,0,2
15,0,0,0,0,0,0,0,0,0,15
2,0,0,0,17,8,0,0,0,0,2
16,0,0,0,0,4,0,0,0,0,16
2,0,0,0,0,0,0,0,0,0,2
15,0,0,0,0,0,0,0,0,0,15
2,0,0,0,0,0,0,0,0,0,2
2,2,0,0,0,0,0,0,0,2,2
1,2,2,15,2,16,2,15,2,2,1
endlayer

# Underground 5 (top)
layer
1,2,2,19,2,18,2,17,2,2,1
2,2,19,18,0,0,0,17,18,2,2
2,19,18,0,0,0,0,0,17,18,2
18,18,0,0,0,0,0,0,0,17,18
2,0,0,0,8,0,0,0,0,0,2
19,0,0,0,18,3,0,0,0,0,17
2,0,0,0,0,0,0,0,0,0,2
11,11,0,0,0,0,0,0,0,17,11
2,19,11,0,0,0,0,0,17,11,2
2,2,19,11,0,0,0,17,11,2,2
1,2,2,19,2,11,2,17,2,2,1
endlayer

# Underground 6 (top)
layer
1,2,2,2,2,2,2,2,2,2,1
2,2,2,2,3,3,3,2,2,2,2
2,2,2,4,5,3,5,4,2,2,2
2,2,4,4,5,5,5,4,4,2,2
2,3,5,5,0,0,0,5,5,3,2
2,3,3,5,13,5,4,5,3,3,2
2,3,5,5,3,4,3,5,5,3,2
2,2,4,4,5,5,5,4,4,2,2
2,2,2,4,5,3,5,4,2,2,2
2,2,2,2,3,3,3,2,2,2,2
1,2,2,2,2,2,2,2,2,2,1
endlayer

# Aboveground 1
layer
1,1,1,20,20,2,2,2,1,1,1
1,1,2,2,1,1,1,2,2,1,1
1,2,2,1,1,1,1,1,2,2,1
2,2,1,1,1,0,1,1,1,2,2
20,1,1,1,0,0,0,1,1,1,2
2,1,1,0,0,0,11,1,1,1,2
2,1,1,1,0,0,7,1,1,1,2
2,2,1,1,1,0,0,1,1,2,20
1,20,20,1,1,1,1,1,2,20,1
1,1,20,2,1,1,1,2,2,1,1
1,1,1,2,2,1,2,2,1,1,1
endlayer

# Aboveground 2
layer
1,1,1,20,20,1,2,20,1,1,1
1,1,20,2,1,1,1,2,20,1,1
1,20,2,1,1,1,1,1,2,2,1
20,2,1,1,0,0,0,1,1,2,2
20,1,1,0,0,0,0,0,1,1,2
1,1,0,0,0,0,7,0,1,1,1
2,1,1,0,0,0,0,1,1,1,2
2,2,1,1,0,0,0,1,1,2,20
1,20,20,1,1,0,1,1,2,20,1
1,1,20,2,1,1,1,2,20,1,1
1,1,1,2,2,1,2,20,1,1,1
endlayer

# Aboveground 3
layer
1,1,1,20,20,1,2,20,1,1,1
1,1,20,2,1,1,1,20,20,1,1
1,20,20,1,1,0,1,1,20,20,1
20,2,1,0,0,0,0,0,1,20,20
20,1,0,0,0,0,0,0,1,1,2
1,0,0,0,0,0,0,0,0,1,1
2,1,0,0,0,0,0,0,1,1,2
20,2,1,0,0,0,0,0,1,2,20
1,20,20,1,1,0,0,1,2,20,1
1,1,20,20,1,1,1,20,20,1,1
1,1,1,2,2,21,2,20,1,1,1
endlayer

# Aboveground 4
layer
1,1,1,20,20,22,2,20,1,1,1
1,1,20,20,1,1,1,20,20,1,1
1,20,20,1,0,0,0,1,20,20,1
20,20,1,0,0,0,0,0,1,20,20
20,1,0,0,0,0,0,0,0,1,20
22,0,0,0,0,0,0,0,0,1,22
2,0,0,0,0,0,0,0,0,1,2
20,20,1,0,0,0,0,0,1,20,20
1,20,20,1,0,0,0,0,2,20,1
1,1,20,20,1,0,1,20,20,1,1
1,1,1,20,20,22,2,20,1,1,1
endlayer

# Aboveground 5
layer
1,1,1,20,20,20,20,20,1,1,1
1,1,20,20,1,0,1,20,20,1,1
1,20,20,0,0,0,0,0,20,20,1
20,20,0,0,0,0,0,0,0,20,20
20,0,0,0,0,0,0,0,0,1,20
2,0,0,0,0,0,0,0,0,0,2
20,0,0,0,0,0,0,0,0,1,20
20,20,0,0,0,0,0,0,0,20,20
1,20,20,0,0,0,0,0,20,20,1
1,1,20,20,0,0,0,20,20,1,1
1,1,1,20,20,2,20,20,1,1,1
endlayer

# Aboveground 6
layer
1,1,1,20,20,20,20,20,1,1,1
1,1,20,20,0,0,0,20,20,1,1
1,20,20,0,0,0,0,0,20,20,1
20,20,0,0,0,0,0,0,0,20,20
20,0,0,0,0,0,0,0,0,0,20
20,0,0,0,0,0,0,0,0,0,2
20,0,0,0,0,0,0,0,0,0,20
20,20,0,0,0,0,0,0,0,20,20
1,20,20,0,0,0,0,0,20,20,1
1,1,20,20,0,0,0,20,20,1,1
1,1,1,20,20,2,20,20,1,1,1
endlayer

# Aboveground 7
layer
1,1,1,1,20,1,1,1,1,1,1
1,1,1,1,0,0,0,20,20,1,1
1,1,20,0,0,0,0,0,20,1,1
1,20,0,0,0,0,0,0,0,20,1
20,0,0,0,0,0,0,0,0,0,20
1,0,0,0,0,0,0,0,0,0,2
20,0,0,0,0,0,0,0,0,0,1
1,1,0,0,0,0,0,0,0,20,20
1,1,20,0,0,0,0,0,1,20,1
1,1,20,20,0,0,0,1,1,1,1
1,1,1,1,20,1,20,1,1,1,1
endlayer


