# Trojan Horse (created 8/27/2017 for MC 1.12)
# Created by Ruins mod version 16.6 Ingame Parser
# authoring Player: Jordan_Greywolf

# Updated for MC 1.12.1: 10 Sep 2017

# Last Updated: 6 Apr 2018


biomesToSpawnIn=brushland,chaparral,field,flower field,flower_field,field,lavender fields,lavender_fields,majestic meadow,meadow,outback,pasture,pasture meadow,plains,prairie,rwg_plains,sublime shrubland,sunflower plains,thick shrubland,thinned pasture,mining biome,mutated_plains

uniqueMinDistance=4000
spawnMinDistance=1000

preventRotation=1
weight=1
embed_into_distance=4

acceptable_target_blocks=
unacceptable_target_blocks=flowing_water,water,flowing_lava,lava,cloud,Natura:Cloud,slime_congealed,slime_dirt,slime_grass,command_block,planks,planks2,concrete,cobblestone,stonebrick,brick_block,glass,torch,oak_stairs,stone_stairs,brick_stairs,stone_brick_stairs,nether_brick_stairs,sandstone_stairs,spruce_stairs,birch_stairs,jungle_stairs,quartz_stairs,acacia_stairs,dark_oak_stairs,cobblestone_wall,stone_slab,double_stone_slab,stone_slab2,wooden_slab,double_wooden_slab,nether_brick,fence

dimensions=42,12,32
allowable_overhang=0
max_leveling=3
leveling_buffer=-1
preserve_water=0
preserve_lava=0
preserve_plants

rule1=0,100,preserveBlock
rule2=0,100,minecraft:planks-0
rule3=0,100,minecraft:wooden_door-1
rule4=0,100,minecraft:ladder-2
rule5=0,100,minecraft:wooden_door-9
rule6=0,100,minecraft:wooden_door-8
rule7=0,100,minecraft:oak_stairs-2
rule8=0,100,minecraft:oak_stairs-0
rule9=0,100,minecraft:oak_stairs-3
rule10=0,100,minecraft:oak_stairs-1
rule11=0,100,minecraft:oak_stairs-4
rule12=0,100,minecraft:oak_stairs-7
rule13=0,100,minecraft:oak_stairs-6
rule14=0,100,minecraft:oak_stairs-5
rule15=0,100,minecraft:wooden_slab-0
rule16=0,100,minecraft:bookshelf-0

rule17=0,100,MobSpawner:Skeleton,MobSpawner:Zombie,MobSpawner:Spider

rule18=0,100,minecraft:ladder-3
rule19=0,100,minecraft:wooden_door-3
rule20=0,100,minecraft:wooden_slab-8
rule21=2,100,minecraft:redstone_torch-3
rule22=2,100,minecraft:redstone_torch-4
rule23=2,100,minecraft:redstone_torch-1
rule24=0,100,ChestGenHook:chests/simple_dungeon:5-3
rule25=0,100,ChestGenHook:chests/simple_dungeon:5-2
rule26=2,100,minecraft:redstone_torch-2
rule27=0,100,minecraft:wooden_door-2
rule28=0,100,minecraft:wooden_door-0
rule29=2,100,minecraft:torch-1
rule30=2,100,minecraft:torch-2
rule31=0,100,minecraft:ladder-5
rule32=0,100,minecraft:ladder-4
rule33=0,100,minecraft:fence-0
rule34=1,100,minecraft:redstone_torch-5

layer
1,1,1,1,1,2,2,2,2,1,1,1,1,1,1,1,1,1,1,1,1,1,2,2,2,2,1,1,1,1,1,1
1,1,1,1,1,2,2,2,2,1,1,1,1,1,1,1,1,1,1,1,1,1,2,1,1,2,1,1,1,1,1,1
1,1,1,1,1,2,2,2,2,1,1,1,1,1,1,1,1,1,1,1,1,1,2,1,1,2,1,1,1,1,1,1
1,1,1,1,1,2,2,2,2,1,1,1,1,1,1,1,1,1,1,1,1,1,2,2,2,2,1,1,1,1,1,1
1,1,1,1,1,1,1,1,1,1,1,1,1,1,1,1,1,1,1,1,1,1,1,1,1,1,1,1,1,1,1,1
1,1,1,1,1,1,1,1,1,1,1,1,1,1,1,1,1,1,1,1,1,1,1,1,1,1,1,1,1,1,1,1
1,1,1,1,1,1,1,1,1,1,1,1,1,1,1,1,1,1,1,1,1,1,1,1,1,1,1,1,1,1,1,1
1,1,1,1,1,1,1,1,1,1,1,1,1,1,1,1,1,1,1,1,1,1,1,1,1,1,1,1,1,1,1,1
1,1,1,1,1,2,2,2,2,1,1,1,1,1,1,1,1,1,1,1,1,1,2,2,2,2,1,1,1,1,1,1
1,1,1,1,1,2,2,2,2,1,1,1,1,1,1,1,1,1,1,1,1,1,2,1,1,2,1,1,1,1,1,1
1,1,1,1,1,2,2,2,2,1,1,1,1,1,1,1,1,1,1,1,1,1,2,1,1,2,1,1,1,1,1,1
1,1,1,1,1,2,2,2,2,1,1,1,1,1,1,1,1,1,1,1,1,1,2,2,2,2,1,1,1,1,1,1
endlayer

layer
1,1,1,1,1,2,2,2,2,1,1,1,1,1,1,1,1,1,1,1,1,1,2,2,2,2,1,1,1,1,1,1
1,1,1,1,1,2,2,2,2,1,1,1,1,1,1,1,1,1,1,1,1,1,2,1,1,2,1,1,1,1,1,1
1,1,1,1,1,2,2,2,2,1,1,1,1,1,1,1,1,1,1,1,1,1,2,1,1,2,1,1,1,1,1,1
1,1,1,1,1,2,2,2,2,1,1,1,1,1,1,1,1,1,1,1,1,1,2,2,2,2,1,1,1,1,1,1
1,1,1,1,1,1,1,1,1,1,1,1,1,1,1,1,1,1,1,1,1,1,1,1,1,1,1,1,1,1,1,1
1,1,1,1,1,1,1,1,1,1,1,1,1,1,1,1,1,1,1,1,1,1,1,1,1,1,1,1,1,1,1,1
1,1,1,1,1,1,1,1,1,1,1,1,1,1,1,1,1,1,1,1,1,1,1,1,1,1,1,1,1,1,1,1
1,1,1,1,1,1,1,1,1,1,1,1,1,1,1,1,1,1,1,1,1,1,1,1,1,1,1,1,1,1,1,1
1,1,1,1,1,2,2,2,2,1,1,1,1,1,1,1,1,1,1,1,1,1,2,2,2,2,1,1,1,1,1,1
1,1,1,1,1,2,2,2,2,1,1,1,1,1,1,1,1,1,1,1,1,1,2,1,1,2,1,1,1,1,1,1
1,1,1,1,1,2,2,2,2,1,1,1,1,1,1,1,1,1,1,1,1,1,2,1,1,2,1,1,1,1,1,1
1,1,1,1,1,2,2,2,2,1,1,1,1,1,1,1,1,1,1,1,1,1,2,2,2,2,1,1,1,1,1,1
endlayer

layer
1,1,1,1,1,2,2,2,2,1,1,1,1,1,1,1,1,1,1,1,1,1,2,2,2,2,1,1,1,1,1,1
1,1,1,1,1,2,2,2,2,1,1,1,1,1,1,1,1,1,1,1,1,1,2,1,1,2,1,1,1,1,1,1
1,1,1,1,1,2,2,2,2,1,1,1,1,1,1,1,1,1,1,1,1,1,2,1,1,2,1,1,1,1,1,1
1,1,1,1,1,2,2,2,2,1,1,1,1,1,1,1,1,1,1,1,1,1,2,2,2,2,1,1,1,1,1,1
1,1,1,1,1,1,1,1,1,1,1,1,1,1,1,1,1,1,1,1,1,1,1,1,1,1,1,1,1,1,1,1
1,1,1,1,1,1,1,1,1,1,1,1,1,1,1,1,1,1,1,1,1,1,1,1,1,1,1,1,1,1,1,1
1,1,1,1,1,1,1,1,1,1,1,1,1,1,1,1,1,1,1,1,1,1,1,1,1,1,1,1,1,1,1,1
1,1,1,1,1,1,1,1,1,1,1,1,1,1,1,1,1,1,1,1,1,1,1,1,1,1,1,1,1,1,1,1
1,1,1,1,1,2,2,2,2,1,1,1,1,1,1,1,1,1,1,1,1,1,2,2,2,2,1,1,1,1,1,1
1,1,1,1,1,2,2,2,2,1,1,1,1,1,1,1,1,1,1,1,1,1,2,1,1,2,1,1,1,1,1,1
1,1,1,1,1,2,2,2,2,1,1,1,1,1,1,1,1,1,1,1,1,1,2,1,1,2,1,1,1,1,1,1
1,1,1,1,1,2,2,2,2,1,1,1,1,1,1,1,1,1,1,1,1,1,2,2,2,2,1,1,1,1,1,1
endlayer

layer
1,1,1,1,1,2,2,2,2,1,1,1,1,1,1,1,1,1,1,1,1,1,2,2,2,2,1,1,1,1,1,1
1,1,1,1,1,2,2,2,2,1,1,1,1,1,1,1,1,1,1,1,1,1,2,1,1,2,1,1,1,1,1,1
1,1,1,1,1,2,2,2,2,1,1,1,1,1,1,1,1,1,1,1,1,1,2,1,1,2,1,1,1,1,1,1
1,1,1,1,1,2,2,2,2,1,1,1,1,1,1,1,1,1,1,1,1,1,2,2,2,2,1,1,1,1,1,1
1,1,1,1,1,1,1,1,1,1,1,1,1,1,1,1,1,1,1,1,1,1,1,1,1,1,1,1,1,1,1,1
1,1,1,1,1,1,1,1,1,1,1,1,1,1,1,1,1,1,1,1,1,1,1,1,1,1,1,1,1,1,1,1
1,1,1,1,1,1,1,1,1,1,1,1,1,1,1,1,1,1,1,1,1,1,1,1,1,1,1,1,1,1,1,1
1,1,1,1,1,1,1,1,1,1,1,1,1,1,1,1,1,1,1,1,1,1,1,1,1,1,1,1,1,1,1,1
1,1,1,1,1,2,2,2,2,1,1,1,1,1,1,1,1,1,1,1,1,1,2,2,2,2,1,1,1,1,1,1
1,1,1,1,1,2,2,2,2,1,1,1,1,1,1,1,1,1,1,1,1,1,2,1,1,2,1,1,1,1,1,1
1,1,1,1,1,2,2,2,2,1,1,1,1,1,1,1,1,1,1,1,1,1,2,1,1,2,1,1,1,1,1,1
1,1,1,1,1,2,2,2,2,1,1,1,1,1,1,1,1,1,1,1,1,1,2,2,2,2,1,1,1,1,1,1
endlayer


layer
1,1,1,1,1,2,2,2,2,0,1,1,1,1,1,1,1,1,1,1,1,1,2,2,2,2,1,1,1,1,1,1
1,1,1,1,1,2,4,0,3,0,1,1,1,1,1,1,1,1,1,1,1,1,2,1,1,2,1,1,1,1,1,1
1,1,1,1,1,2,4,0,3,0,1,1,1,1,1,1,1,1,1,1,1,1,2,1,1,2,1,1,1,1,1,1
1,1,1,1,1,2,2,2,2,1,1,1,1,1,1,1,1,1,1,1,1,1,2,2,2,2,1,1,1,1,1,1
1,1,1,1,1,1,1,1,1,1,1,1,1,1,1,1,1,1,1,1,1,1,1,1,1,1,1,1,1,1,1,1
1,1,1,1,1,1,1,1,1,1,1,1,1,1,1,1,1,1,1,1,1,1,1,1,1,1,1,1,1,1,1,1
1,1,1,1,1,1,1,1,1,1,1,1,1,1,1,1,1,1,1,1,1,1,1,1,1,1,1,1,1,1,1,1
1,1,1,1,1,1,1,1,1,1,1,1,1,1,1,1,1,1,1,1,1,1,1,1,1,1,1,1,1,1,1,1
1,1,1,1,1,2,2,2,2,1,1,1,1,1,1,1,1,1,1,1,1,1,2,2,2,2,1,1,1,1,1,1
1,1,1,1,1,2,4,0,3,0,1,1,1,1,1,1,1,1,1,1,1,1,2,1,1,2,1,1,1,1,1,1
1,1,1,1,1,2,4,0,3,0,1,1,1,1,1,1,1,1,1,1,1,1,2,1,1,2,1,1,1,1,1,1
1,1,1,1,1,2,2,2,2,0,1,1,1,1,1,1,1,1,1,1,1,1,2,2,2,2,1,1,1,1,1,1
endlayer

layer
1,1,1,1,1,2,2,2,2,0,1,1,1,1,1,1,1,1,1,1,1,1,2,2,2,2,1,1,1,1,1,1
1,1,1,1,1,2,4,0,5,0,1,1,1,1,1,1,1,1,1,1,1,1,2,1,1,2,1,1,1,1,1,1
1,1,1,1,1,2,4,0,6,0,1,1,1,1,1,1,1,1,1,1,1,1,2,1,1,2,1,1,1,1,1,1
1,1,1,1,1,2,2,2,2,1,1,1,1,1,1,1,1,1,1,1,1,1,2,2,2,2,1,1,1,1,1,1
1,1,1,1,1,1,1,1,1,1,1,1,1,1,1,1,1,1,1,1,1,1,1,1,1,1,1,1,1,1,1,1
1,1,1,1,1,1,1,1,1,1,1,1,1,1,1,1,1,1,1,1,1,1,1,1,1,1,1,1,1,1,1,1
1,1,1,1,1,1,1,1,1,1,1,1,1,1,1,1,1,1,1,1,1,1,1,1,1,1,1,1,1,1,1,1
1,1,1,1,1,1,1,1,1,1,1,1,1,1,1,1,1,1,1,1,1,1,1,1,1,1,1,1,1,1,1,1
1,1,1,1,1,2,2,2,2,1,1,1,1,1,1,1,1,1,1,1,1,1,2,2,2,2,1,1,1,1,1,1
1,1,1,1,1,2,4,0,5,0,1,1,1,1,1,1,1,1,1,1,1,1,2,1,1,2,1,1,1,1,1,1
1,1,1,1,1,2,4,0,6,0,1,1,1,1,1,1,1,1,1,1,1,1,2,1,1,2,1,1,1,1,1,1
1,1,1,1,1,2,2,2,2,0,1,1,1,1,1,1,1,1,1,1,1,1,2,2,2,2,1,1,1,1,1,1
endlayer

layer
1,1,1,1,1,9,8,8,8,1,1,1,1,1,1,1,1,1,1,1,1,1,8,8,8,7,1,1,1,1,1,1
1,1,1,1,1,9,4,0,7,1,1,1,1,1,1,1,1,1,1,1,1,1,9,2,2,7,1,1,1,1,1,1
1,1,1,1,1,9,4,0,7,1,1,1,1,1,1,1,1,1,1,1,1,1,9,2,2,7,1,1,1,1,1,1
1,1,1,1,1,10,10,10,7,1,1,1,1,1,1,1,1,1,1,1,1,1,9,10,10,10,1,1,1,1,1,1
1,1,1,1,1,1,1,1,1,1,1,1,1,1,1,1,1,1,1,1,1,1,1,1,1,1,1,1,1,1,1,1
1,1,1,1,1,1,1,1,1,1,1,1,1,1,1,1,1,1,1,1,1,1,1,1,1,1,1,1,1,1,1,1
1,1,1,1,1,1,1,1,1,1,1,1,1,1,1,1,1,1,1,1,1,1,1,1,1,1,1,1,1,1,1,1
1,1,1,1,1,1,1,1,1,1,1,1,1,1,1,1,1,1,1,1,1,1,1,1,1,1,1,1,1,1,1,1
1,1,1,1,1,9,8,8,8,1,1,1,1,1,1,1,1,1,1,1,1,1,8,8,8,7,1,1,1,1,1,1
1,1,1,1,1,9,4,0,7,1,1,1,1,1,1,1,1,1,1,1,1,1,9,2,2,7,1,1,1,1,1,1
1,1,1,1,1,9,4,0,7,1,1,1,1,1,1,1,1,1,1,1,1,1,9,2,2,7,1,1,1,1,1,1
1,1,1,1,1,10,10,10,10,1,1,1,1,1,1,1,1,1,1,1,1,1,9,10,10,10,1,1,1,1,1,1
endlayer

layer
1,1,1,1,1,12,11,11,11,1,1,1,1,1,1,1,1,1,1,1,1,1,12,11,11,11,1,1,1,1,1,1
1,1,1,1,1,12,4,0,13,1,1,1,1,1,1,1,1,1,1,1,1,1,12,2,2,13,1,1,1,1,1,1
1,1,1,1,1,12,4,0,13,1,1,1,1,1,1,1,1,1,1,1,1,1,12,2,2,13,1,1,1,1,1,1
1,1,1,1,1,14,14,14,13,1,1,1,1,1,1,1,1,1,1,1,1,1,14,14,14,13,1,1,1,1,1,1
1,1,1,1,1,1,1,1,1,1,1,1,1,1,1,1,1,1,1,1,1,1,1,1,1,1,1,1,1,1,1,1
1,1,1,1,1,1,1,1,1,1,1,1,1,1,1,1,1,1,1,1,1,1,1,1,1,1,1,1,1,1,1,1
1,1,1,1,1,1,1,1,1,1,1,1,1,1,1,1,1,1,1,1,1,1,1,1,1,1,1,1,1,1,1,1
1,1,1,1,1,1,1,1,1,1,1,1,1,1,1,1,1,1,1,1,1,1,1,1,1,1,1,1,1,1,1,1
1,1,1,1,1,12,11,11,11,1,1,1,1,1,1,1,1,1,1,1,1,1,12,11,11,11,1,1,1,1,1,1
1,1,1,1,1,12,4,0,13,1,1,1,1,1,1,1,1,1,1,1,1,1,12,2,2,13,1,1,1,1,1,1
1,1,1,1,1,12,4,0,13,1,1,1,1,1,1,1,1,1,1,1,1,1,12,2,2,13,1,1,1,1,1,1
1,1,1,1,1,14,14,14,13,1,1,1,1,1,1,1,1,1,1,1,1,1,14,14,14,13,1,1,1,1,1,1
endlayer

Main Leg Support
layer
1,1,1,1,1,2,2,2,2,1,1,1,1,1,1,1,1,1,1,1,1,1,2,2,2,2,1,1,1,1,1,1
1,1,1,1,1,2,4,0,2,1,1,1,1,1,1,1,1,1,1,1,1,1,2,2,2,2,1,1,1,1,1,1
1,1,1,1,1,2,4,0,2,1,1,1,1,1,1,1,1,1,1,1,1,1,2,2,2,2,1,1,1,1,1,1
1,1,1,1,1,2,2,2,2,1,1,1,1,1,1,1,1,1,1,1,1,1,2,2,2,2,1,1,1,1,1,1
1,1,1,1,1,1,1,1,1,1,1,1,1,1,1,1,1,1,1,1,1,1,1,1,1,1,1,1,1,1,1,1
1,1,1,1,1,1,1,1,1,1,1,1,1,1,1,1,1,1,1,1,1,1,1,1,1,1,1,1,1,1,1,1
1,1,1,1,1,1,1,1,1,1,1,1,1,1,1,1,1,1,1,1,1,1,1,1,1,1,1,1,1,1,1,1
1,1,1,1,1,1,1,1,1,1,1,1,1,1,1,1,1,1,1,1,1,1,1,1,1,1,1,1,1,1,1,1
1,1,1,1,1,2,2,2,2,1,1,1,1,1,1,1,1,1,1,1,1,1,2,2,2,2,1,1,1,1,1,1
1,1,1,1,1,2,4,0,2,1,1,1,1,1,1,1,1,1,1,1,1,1,2,2,2,2,1,1,1,1,1,1
1,1,1,1,1,2,4,0,2,1,1,1,1,1,1,1,1,1,1,1,1,1,2,2,2,2,1,1,1,1,1,1
1,1,1,1,1,2,2,2,2,1,1,1,1,1,1,1,1,1,1,1,1,1,2,2,2,2,1,1,1,1,1,1
endlayer

Main Leg Support
layer
1,1,1,1,1,2,2,2,2,1,1,1,1,1,1,1,1,1,1,1,1,1,2,2,2,2,1,1,1,1,1,1
1,1,1,1,1,2,4,0,2,1,1,1,1,1,1,1,1,1,1,1,1,1,2,2,2,2,1,1,1,1,1,1
1,1,1,1,1,2,4,0,2,1,1,1,1,1,1,1,1,1,1,1,1,1,2,2,2,2,1,1,1,1,1,1
1,1,1,1,1,2,2,2,2,1,1,1,1,1,1,1,1,1,1,1,1,1,2,2,2,2,1,1,1,1,1,1
1,1,1,1,1,1,1,1,1,1,1,1,1,1,1,1,1,1,1,1,1,1,1,1,1,1,1,1,1,1,1,1
1,1,1,1,1,1,1,1,1,1,1,1,1,1,1,1,1,1,1,1,1,1,1,1,1,1,1,1,1,1,1,1
1,1,1,1,1,1,1,1,1,1,1,1,1,1,1,1,1,1,1,1,1,1,1,1,1,1,1,1,1,1,1,1
1,1,1,1,1,1,1,1,1,1,1,1,1,1,1,1,1,1,1,1,1,1,1,1,1,1,1,1,1,1,1,1
1,1,1,1,1,2,2,2,2,1,1,1,1,1,1,1,1,1,1,1,1,1,2,2,2,2,1,1,1,1,1,1
1,1,1,1,1,2,4,0,2,1,1,1,1,1,1,1,1,1,1,1,1,1,2,2,2,2,1,1,1,1,1,1
1,1,1,1,1,2,4,0,2,1,1,1,1,1,1,1,1,1,1,1,1,1,2,2,2,2,1,1,1,1,1,1
1,1,1,1,1,2,2,2,2,1,1,1,1,1,1,1,1,1,1,1,1,1,2,2,2,2,1,1,1,1,1,1
endlayer

Main Leg Support
layer
1,1,1,1,1,2,2,2,2,1,1,1,1,1,1,1,1,1,1,1,1,1,2,2,2,2,1,1,1,1,1,1
1,1,1,1,1,2,4,0,2,1,1,1,1,1,1,1,1,1,1,1,1,1,2,2,2,2,1,1,1,1,1,1
1,1,1,1,1,2,4,0,2,1,1,1,1,1,1,1,1,1,1,1,1,1,2,2,2,2,1,1,1,1,1,1
1,1,1,1,1,2,2,2,2,1,1,1,1,1,1,1,1,1,1,1,1,1,2,2,2,2,1,1,1,1,1,1
1,1,1,1,1,1,1,1,1,1,1,1,1,1,1,1,1,1,1,1,1,1,1,1,1,1,1,1,1,1,1,1
1,1,1,1,1,1,1,1,1,1,1,1,1,1,1,1,1,1,1,1,1,1,1,1,1,1,1,1,1,1,1,1
1,1,1,1,1,1,1,1,1,1,1,1,1,1,1,1,1,1,1,1,1,1,1,1,1,1,1,1,1,1,1,1
1,1,1,1,1,1,1,1,1,1,1,1,1,1,1,1,1,1,1,1,1,1,1,1,1,1,1,1,1,1,1,1
1,1,1,1,1,2,2,2,2,1,1,1,1,1,1,1,1,1,1,1,1,1,2,2,2,2,1,1,1,1,1,1
1,1,1,1,1,2,4,0,2,1,1,1,1,1,1,1,1,1,1,1,1,1,2,2,2,2,1,1,1,1,1,1
1,1,1,1,1,2,4,0,2,1,1,1,1,1,1,1,1,1,1,1,1,1,2,2,2,2,1,1,1,1,1,1
1,1,1,1,1,2,2,2,2,1,1,1,1,1,1,1,1,1,1,1,1,1,2,2,2,2,1,1,1,1,1,1
endlayer

Main Leg Support
layer
1,1,1,1,1,2,2,2,2,1,1,1,1,1,1,1,1,1,1,1,1,1,2,2,2,2,1,1,1,1,1,1
1,1,1,1,1,2,4,0,2,1,1,1,1,1,1,1,1,1,1,1,1,1,2,2,2,2,1,1,1,1,1,1
1,1,1,1,1,2,4,0,2,1,1,1,1,1,1,1,1,1,1,1,1,1,2,2,2,2,1,1,1,1,1,1
1,1,1,1,1,2,2,2,2,1,1,1,1,1,1,1,1,1,1,1,1,1,2,2,2,2,1,1,1,1,1,1
1,1,1,1,1,1,1,1,1,1,1,1,1,1,1,1,1,1,1,1,1,1,1,1,1,1,1,1,1,1,1,1
1,1,1,1,1,1,1,1,1,1,1,1,1,1,1,1,1,1,1,1,1,1,1,1,1,1,1,1,1,1,1,1
1,1,1,1,1,1,1,1,1,1,1,1,1,1,1,1,1,1,1,1,1,1,1,1,1,1,1,1,1,1,1,1
1,1,1,1,1,1,1,1,1,1,1,1,1,1,1,1,1,1,1,1,1,1,1,1,1,1,1,1,1,1,1,1
1,1,1,1,1,2,2,2,2,1,1,1,1,1,1,1,1,1,1,1,1,1,2,2,2,2,1,1,1,1,1,1
1,1,1,1,1,2,4,0,2,1,1,1,1,1,1,1,1,1,1,1,1,1,2,2,2,2,1,1,1,1,1,1
1,1,1,1,1,2,4,0,2,1,1,1,1,1,1,1,1,1,1,1,1,1,2,2,2,2,1,1,1,1,1,1
1,1,1,1,1,2,2,2,2,1,1,1,1,1,1,1,1,1,1,1,1,1,2,2,2,2,1,1,1,1,1,1
endlayer


layer
1,1,1,1,1,2,2,2,2,1,1,1,1,1,1,1,1,1,1,1,1,1,2,2,2,2,1,1,1,1,1,1
1,1,1,1,1,2,4,0,2,1,1,1,1,1,1,1,1,1,1,1,1,1,2,2,2,2,1,1,1,1,1,1
1,1,1,1,1,2,4,0,2,1,1,1,1,1,1,1,1,1,1,1,1,1,2,2,2,2,1,1,1,1,1,1
1,1,1,1,1,2,2,2,2,1,1,1,1,1,1,1,1,1,1,1,1,1,2,2,2,2,1,1,1,1,1,1
1,1,1,1,1,1,1,1,1,1,1,1,1,1,1,1,1,1,1,1,1,1,1,1,1,1,1,1,1,1,1,1
9,13,1,1,1,1,1,1,1,1,1,1,1,1,1,1,1,1,1,1,1,1,1,1,1,1,1,1,1,1,1,1
9,13,1,1,1,1,1,1,1,1,1,1,1,1,1,1,1,1,1,1,1,1,1,1,1,1,1,1,1,1,1,1
1,1,1,1,1,1,1,1,1,1,1,1,1,1,1,1,1,1,1,1,1,1,1,1,1,1,1,1,1,1,1,1
1,1,1,1,1,2,2,2,2,1,1,1,1,1,1,1,1,1,1,1,1,1,2,2,2,2,1,1,1,1,1,1
1,1,1,1,1,2,4,0,2,1,1,1,1,1,1,1,1,1,1,1,1,1,2,2,2,2,1,1,1,1,1,1
1,1,1,1,1,2,4,0,2,1,1,1,1,1,1,1,1,1,1,1,1,1,2,2,2,2,1,1,1,1,1,1
1,1,1,1,1,2,2,2,2,1,1,1,1,1,1,1,1,1,1,1,1,1,2,2,2,2,1,1,1,1,1,1
endlayer

layer
1,1,1,1,1,2,2,2,2,13,1,1,1,1,1,1,1,1,1,1,12,2,2,2,2,2,1,1,1,1,1,1
1,1,1,1,1,2,4,0,2,2,2,2,2,11,11,11,11,11,11,11,2,2,2,2,2,2,1,1,1,1,1,1
1,1,1,1,1,2,4,0,2,2,2,2,2,2,2,2,2,2,2,2,2,2,2,2,2,2,1,1,1,1,1,1
1,1,1,1,1,2,2,2,2,2,2,2,2,2,2,2,2,2,2,2,2,2,2,2,2,2,1,1,1,1,1,1
1,1,1,1,1,2,2,2,2,2,2,2,2,2,2,2,2,2,2,2,2,2,2,2,2,2,1,1,1,1,1,1
9,2,13,1,1,2,2,2,2,2,2,2,2,2,2,2,2,2,2,2,2,2,2,2,2,2,1,1,1,1,1,1
9,2,13,1,1,2,2,2,2,2,2,2,2,2,2,2,2,2,2,2,2,2,2,2,2,2,1,1,1,1,1,1
1,1,1,1,1,2,2,2,2,2,2,2,2,2,2,2,2,2,2,2,2,2,2,2,2,2,1,1,1,1,1,1
1,1,1,1,1,2,2,2,2,2,2,2,2,2,2,2,2,2,2,2,2,2,2,2,2,2,1,1,1,1,1,1
1,1,1,1,1,2,4,0,2,2,2,2,2,2,2,2,2,2,2,2,2,2,2,2,2,2,1,1,1,1,1,1
1,1,1,1,1,2,4,0,2,2,2,2,2,14,14,14,14,14,14,14,2,2,2,2,2,2,1,1,1,1,1,1
1,1,1,1,1,2,2,2,2,13,1,1,1,1,1,1,1,1,1,1,12,2,2,2,2,2,1,1,1,1,1,1
endlayer

layer
1,1,1,1,1,2,2,2,2,2,2,2,13,1,1,1,1,1,1,1,2,2,2,2,2,2,1,1,1,1,1,1
1,1,1,1,1,2,4,15,2,15,15,15,2,2,2,2,2,2,2,2,2,15,15,15,2,2,1,1,1,1,1,1
1,1,1,1,1,2,4,15,2,15,15,15,2,15,15,15,15,15,15,2,15,15,15,15,15,2,1,1,1,1,1,1
1,1,1,1,1,2,15,15,2,15,15,15,2,15,15,15,15,15,15,2,15,15,15,15,15,2,1,1,1,1,1,1
1,1,1,1,1,2,15,15,2,15,15,15,2,15,15,15,15,15,15,2,15,15,15,15,15,2,1,1,1,1,1,1
9,2,2,1,1,2,15,15,2,7,15,9,2,15,15,15,15,15,9,2,7,15,15,15,9,2,1,1,1,1,1,1
9,2,2,1,1,2,15,15,2,7,15,9,2,15,15,15,15,15,9,2,7,15,15,15,9,2,1,1,1,1,1,1
1,1,1,1,1,2,15,15,2,15,15,15,2,15,15,15,15,15,15,2,15,15,15,15,15,2,1,1,1,1,1,1
1,1,1,1,1,2,15,15,2,15,15,15,2,15,15,15,15,15,15,2,15,15,15,15,15,2,1,1,1,1,1,1
1,1,1,1,1,2,4,15,2,15,15,15,2,15,15,15,15,15,15,2,15,15,15,15,15,2,1,1,1,1,1,1
1,1,1,1,1,2,4,15,2,15,15,15,2,2,2,2,2,2,2,2,2,15,15,15,2,2,1,1,1,1,1,1
1,1,1,1,1,2,2,2,2,2,2,2,2,1,1,1,1,1,1,1,2,2,2,2,2,2,1,1,1,1,1,1
endlayer

layer
0,0,0,0,0,2,2,2,2,2,2,2,2,0,0,0,0,0,0,0,2,2,2,2,2,2,0,0,0,0,0,0
0,0,0,0,0,2,0,0,2,15,15,15,2,2,2,2,2,2,2,2,17,15,15,15,16,2,0,0,0,0,0,0
0,0,0,0,0,2,0,0,2,0,0,0,2,0,0,15,15,0,0,2,0,0,0,0,15,2,0,0,0,0,0,0
0,0,0,0,0,2,0,0,2,0,0,0,2,0,0,0,0,0,0,2,0,0,0,0,15,2,0,0,0,0,0,0
0,0,0,0,0,2,0,0,2,0,0,0,2,0,0,0,0,0,0,2,0,0,0,0,0,2,0,0,0,0,0,0
9,2,2,0,0,2,0,0,3,0,0,0,19,0,0,0,0,0,0,19,0,0,0,0,18,2,0,0,0,0,0,0
9,2,2,0,0,2,0,0,3,0,0,0,19,0,0,0,0,0,0,19,0,0,0,0,18,2,0,0,0,0,0,0
0,0,0,0,0,2,0,0,2,0,0,0,2,0,0,0,0,0,0,2,0,0,0,0,0,2,0,0,0,0,0,0
0,0,0,0,0,2,0,0,2,0,0,0,2,0,0,0,0,0,0,2,0,0,0,0,15,2,0,0,0,0,0,0
0,0,0,0,0,2,0,0,2,0,0,0,2,0,0,15,15,0,0,2,0,0,0,0,15,2,0,0,0,0,0,0
0,0,0,0,0,2,0,0,2,15,15,15,2,2,2,2,2,2,2,2,17,15,15,15,16,2,0,0,0,0,0,0
0,0,0,0,0,2,2,2,2,2,2,2,2,0,0,0,0,0,0,0,2,2,2,2,2,2,0,0,0,0,0,0
endlayer

layer
0,0,0,0,0,2,2,2,2,2,2,2,2,0,0,0,0,0,0,0,2,2,2,2,2,2,0,0,0,0,0,0
0,0,0,0,0,2,20,0,2,0,0,0,2,2,2,2,2,2,2,2,0,0,0,0,16,2,0,0,0,0,0,0
0,0,0,0,0,2,0,0,2,0,0,0,2,0,0,0,0,0,0,2,0,0,0,0,0,2,0,0,0,0,0,0
0,0,0,0,0,2,0,0,2,0,0,0,2,0,0,0,0,0,0,2,0,0,0,0,0,2,0,0,0,0,0,0
0,0,0,0,0,2,0,0,2,0,0,21,2,22,0,0,0,0,0,2,0,0,0,0,21,2,0,0,0,0,0,0
9,2,2,0,0,2,0,0,5,0,0,0,6,0,0,0,0,0,0,6,0,0,0,0,18,2,0,0,0,0,0,0
9,2,2,0,0,2,0,0,6,0,0,0,5,0,0,0,0,0,0,5,0,0,0,0,18,2,0,0,0,0,0,0
0,0,0,0,0,2,0,0,2,0,0,21,2,22,0,0,0,0,0,2,0,0,0,0,21,2,0,0,0,0,0,0
0,0,0,0,0,2,0,0,2,0,0,0,2,0,0,0,0,0,0,2,0,0,0,0,0,2,0,0,0,0,0,0
0,0,0,0,0,2,0,0,2,0,0,0,2,0,0,0,0,0,0,2,0,0,0,0,0,2,0,0,0,0,0,0
0,0,0,0,0,2,0,0,2,0,0,0,2,2,2,2,2,2,2,2,0,0,0,0,16,2,0,0,0,0,0,0
0,0,0,0,0,2,2,2,2,2,2,2,2,0,0,0,0,0,0,0,2,2,2,2,2,2,0,0,0,0,0,0
endlayer

layer
0,0,0,0,0,2,2,2,2,2,2,2,2,0,0,0,0,0,0,0,2,2,2,2,2,2,0,0,0,0,0,0
0,0,0,0,0,2,2,2,15,15,15,2,2,2,2,2,2,2,2,2,15,15,15,15,15,2,0,0,0,0,0,0
0,0,0,0,0,2,2,15,15,15,15,9,2,7,15,15,15,15,9,2,7,15,15,15,15,2,0,0,0,0,0,0
0,0,0,0,0,2,10,15,15,15,15,15,2,15,15,15,15,15,15,2,15,15,15,15,15,2,0,0,0,0,0,0
0,0,0,0,0,2,15,15,15,15,15,15,2,15,15,15,15,15,15,2,15,15,15,15,15,2,0,0,0,0,0,0
9,2,2,0,0,2,2,7,15,15,15,15,2,2,7,15,15,9,2,2,15,15,15,15,18,2,0,0,0,0,0,0
9,2,2,0,0,2,2,7,15,15,15,15,2,2,7,15,15,9,2,2,15,15,15,15,18,2,0,0,0,0,0,0
0,0,0,0,0,2,15,15,15,15,15,15,2,15,15,15,15,15,15,2,15,15,15,15,15,2,0,0,0,0,0,0
0,0,0,0,0,2,8,15,15,15,15,15,2,15,15,15,15,15,15,2,15,15,15,15,15,2,0,0,0,0,0,0
0,0,0,0,0,2,2,15,15,15,15,9,2,7,15,15,15,15,9,2,7,15,15,15,15,2,0,0,0,0,0,0
0,0,0,0,0,2,2,2,15,15,15,2,2,2,2,2,2,2,2,2,15,15,15,15,15,2,0,0,0,0,0,0
0,0,0,0,0,2,2,2,2,2,2,2,2,0,0,0,0,0,0,0,2,2,2,2,2,2,0,0,0,0,0,0
endlayer

layer
0,0,0,0,0,2,2,2,2,2,2,2,2,0,0,0,0,0,0,0,2,2,2,2,2,2,0,0,0,0,0,0
0,0,0,0,0,2,2,2,22,0,0,17,2,2,2,2,2,2,2,2,0,0,23,15,15,2,0,0,0,0,0,0
0,0,0,0,0,2,10,0,0,0,0,0,19,0,0,0,0,0,0,3,0,0,0,0,15,2,0,0,0,0,0,0
0,0,0,0,0,2,0,0,0,0,0,0,2,15,0,0,0,0,15,2,0,0,0,0,0,2,0,0,0,0,0,0
0,0,0,0,0,2,0,0,0,0,0,0,2,15,0,0,0,0,15,2,15,0,0,0,0,2,0,0,0,0,0,0
9,2,2,0,0,2,25,0,0,0,0,0,2,25,15,15,15,15,24,2,15,0,0,0,18,2,0,0,0,0,0,0
9,2,2,0,0,2,25,0,0,0,0,0,2,25,15,15,15,15,24,2,15,0,0,0,18,2,0,0,0,0,0,0
0,0,0,0,0,2,0,0,0,0,0,0,2,15,0,0,0,0,15,2,15,0,0,0,0,2,0,0,0,0,0,0
0,0,0,0,0,2,0,0,0,0,0,0,2,15,0,0,0,0,15,2,0,0,0,0,0,2,0,0,0,0,0,0
0,0,0,0,0,2,8,0,0,0,0,0,19,0,0,0,0,0,0,3,0,0,0,0,15,2,0,0,0,0,0,0
0,0,0,0,0,2,2,2,22,0,0,17,2,2,2,2,2,2,2,2,0,0,26,15,15,2,0,0,0,0,0,0
0,0,0,0,0,2,2,2,2,2,2,2,2,0,0,0,0,0,0,0,2,2,2,2,2,2,0,0,0,0,0,0
endlayer

layer
0,0,0,0,0,2,2,2,2,2,2,2,2,0,0,0,0,0,0,0,2,2,2,2,2,2,0,0,0,0,0,0
0,0,0,0,0,2,10,2,0,0,0,0,2,2,2,2,2,2,2,2,0,0,0,0,0,2,0,0,0,0,0,0
0,0,0,0,0,2,0,0,0,0,0,0,6,0,0,0,0,0,0,5,0,0,0,0,0,2,0,0,0,0,0,0
0,0,0,0,0,2,0,0,0,0,0,0,2,15,0,0,0,0,15,2,0,0,0,0,0,2,0,0,0,0,0,0
0,0,0,0,0,2,0,0,0,0,0,0,2,15,0,0,0,0,15,2,0,0,0,0,0,2,13,0,0,0,0,0
9,2,2,0,0,2,0,0,0,0,0,0,2,17,0,0,0,0,17,2,0,0,0,0,0,2,13,0,0,0,0,0
9,2,2,0,0,2,0,0,0,0,0,0,2,17,0,0,0,0,17,2,0,0,0,0,0,2,13,0,0,0,0,0
0,0,0,0,0,2,0,0,0,0,0,0,2,15,0,0,0,0,15,2,0,0,0,0,0,2,13,0,0,0,0,0
0,0,0,0,0,2,0,0,0,0,0,0,2,15,0,0,0,0,15,2,0,0,0,0,0,2,0,0,0,0,0,0
0,0,0,0,0,2,0,0,0,0,0,0,6,0,0,0,0,0,0,6,0,0,0,0,0,2,0,0,0,0,0,0
0,0,0,0,0,2,8,2,0,0,0,0,2,2,2,2,2,2,2,2,0,0,0,0,0,2,0,0,0,0,0,0
0,0,0,0,0,2,2,2,2,2,2,2,2,0,0,0,0,0,0,0,2,2,2,2,2,2,0,0,0,0,0,0
endlayer

layer
0,0,0,0,0,2,2,2,2,2,2,2,2,0,0,0,0,0,0,0,2,2,2,2,2,2,0,0,0,0,0,0
0,0,0,0,0,2,0,9,2,2,2,2,2,2,2,2,2,2,2,2,2,2,2,2,2,2,0,0,0,0,0,0
0,0,0,0,0,2,0,2,2,2,2,2,2,2,2,2,2,2,2,2,2,2,2,2,2,2,0,0,0,0,0,0
0,0,0,0,0,2,0,2,2,2,2,2,2,2,2,2,2,2,2,2,2,2,2,2,2,2,0,0,0,0,0,0
0,0,0,0,0,2,11,2,2,2,2,2,2,2,2,2,2,2,2,2,2,2,2,2,2,2,2,0,0,0,0,0
9,2,2,0,0,2,2,2,2,2,2,2,2,2,2,2,2,2,2,2,2,2,2,2,2,2,2,0,0,0,0,0
9,2,2,0,0,2,2,2,2,2,2,2,2,2,2,2,2,2,2,2,2,2,2,2,2,2,2,0,0,0,0,0
0,0,0,0,0,2,14,2,2,2,2,2,2,2,2,2,2,2,2,2,2,2,2,2,2,2,2,0,0,0,0,0
0,0,0,0,0,2,0,2,2,2,2,2,2,2,2,2,2,2,2,2,2,2,2,2,2,2,0,0,0,0,0,0
0,0,0,0,0,2,0,2,2,2,2,2,2,2,2,2,2,2,2,2,2,2,2,2,2,2,0,0,0,0,0,0
0,0,0,0,0,2,0,9,2,2,2,2,2,2,2,2,2,2,2,2,2,2,2,2,2,2,0,0,0,0,0,0
0,0,0,0,0,2,2,2,2,2,2,2,2,0,0,0,0,0,0,0,2,2,2,2,2,2,0,0,0,0,0,0
endlayer

layer
0,0,0,0,0,2,2,2,2,2,2,2,2,0,0,0,0,0,0,0,2,2,2,2,2,2,0,0,0,0,0,0
0,0,0,0,0,2,0,0,15,15,15,15,2,2,2,2,2,2,2,2,15,7,15,9,15,2,0,0,0,0,0,0
0,0,0,0,0,2,0,15,15,15,15,15,2,2,15,15,15,15,2,2,15,15,15,15,15,2,0,0,0,0,0,0
0,0,0,0,0,2,15,15,15,15,15,15,2,15,15,15,15,15,15,2,2,15,15,15,2,2,0,0,0,0,0,0
0,0,0,0,0,2,15,15,15,15,15,15,2,15,15,8,8,15,15,2,2,2,2,2,2,2,2,13,0,0,0,0
9,2,2,0,0,2,15,15,15,15,15,9,2,7,15,15,15,15,9,2,7,15,15,15,15,15,9,13,0,0,0,0
9,2,2,0,0,2,15,15,15,15,15,9,2,7,15,15,15,15,9,2,7,15,15,15,15,15,9,13,0,0,0,0
0,0,0,0,0,2,15,15,15,15,15,15,2,15,15,10,10,15,15,2,2,2,2,2,2,2,2,13,0,0,0,0
0,0,0,0,0,2,15,15,15,15,15,15,2,15,15,15,15,15,15,2,2,15,15,15,2,2,0,0,0,0,0,0
0,0,0,0,0,2,0,15,15,15,15,15,2,2,15,15,15,15,2,2,15,15,15,15,15,2,0,0,0,0,0,0
0,0,0,0,0,2,0,0,15,15,15,15,2,2,2,2,2,2,2,2,15,7,15,9,15,2,0,0,0,0,0,0
0,0,0,0,0,2,2,2,2,2,2,2,2,0,0,0,0,0,0,0,2,2,2,2,2,2,0,0,0,0,0,0
endlayer

layer
0,0,0,0,0,2,2,2,2,2,2,2,2,0,0,0,0,0,0,0,2,2,2,2,2,2,0,0,0,0,0,0
0,0,0,0,0,2,0,0,0,0,0,0,2,2,2,2,2,2,2,2,0,15,15,15,0,2,0,0,0,0,0,0
0,0,0,0,0,2,0,0,0,0,0,0,2,17,0,0,0,0,17,2,0,0,0,0,0,2,0,0,0,0,0,0
0,0,0,0,0,2,0,0,0,0,0,0,2,0,0,0,0,0,0,2,16,0,0,0,16,2,0,0,0,0,0,0
0,0,0,0,0,2,0,0,0,0,0,0,2,0,0,15,15,0,0,2,2,2,27,2,2,2,2,2,0,0,0,0
9,2,2,0,0,2,0,0,0,0,0,0,19,0,0,15,15,0,0,3,0,0,0,0,0,0,18,2,0,0,0,0
9,2,2,0,0,2,0,0,0,0,0,0,19,0,0,15,15,0,0,3,0,0,0,0,0,0,18,2,0,0,0,0
0,0,0,0,0,2,0,0,0,0,0,0,2,0,0,15,15,0,0,2,2,2,28,2,2,2,2,2,0,0,0,0
0,0,0,0,0,2,0,0,0,0,0,0,2,0,0,0,0,0,0,2,16,0,0,0,16,2,0,0,0,0,0,0
0,0,0,0,0,2,0,0,0,0,0,0,2,17,0,0,0,0,17,2,0,0,0,0,0,2,0,0,0,0,0,0
0,0,0,0,0,2,0,0,0,0,0,0,2,2,2,2,2,2,2,2,0,15,15,15,0,2,0,0,0,0,0,0
0,0,0,0,0,2,2,2,2,2,2,2,2,0,0,0,0,0,0,0,2,2,2,2,2,2,0,0,0,0,0,0
endlayer

layer
0,0,0,0,0,2,2,2,2,2,2,2,2,0,0,0,0,0,0,0,2,2,2,2,2,2,0,0,0,0,0,0
0,0,0,0,0,2,0,0,0,29,0,0,2,2,2,2,2,2,2,2,23,0,0,0,23,2,0,0,0,0,0,0
0,0,0,0,0,2,0,0,0,0,0,0,2,23,0,0,0,0,23,2,0,0,0,0,0,2,0,0,0,0,0,0
0,0,0,0,0,2,0,0,0,0,0,0,2,0,0,0,0,0,0,2,16,0,0,0,16,2,0,0,0,0,0,0
0,0,0,0,0,2,0,0,0,0,0,0,2,0,0,0,0,0,0,2,2,2,6,2,2,2,2,2,0,0,0,0
9,2,2,13,0,2,0,0,0,0,0,0,6,0,0,0,0,0,0,5,0,0,0,0,0,0,18,2,0,0,0,0
9,2,2,13,0,2,0,0,0,0,0,0,5,0,0,0,0,0,0,6,0,0,0,0,0,0,18,2,0,0,0,0
0,0,0,0,0,2,0,0,0,0,0,0,2,0,0,0,0,0,0,2,2,2,6,2,2,2,2,2,0,0,0,0
0,0,0,0,0,2,0,0,0,0,0,0,2,0,0,0,0,0,0,2,16,0,0,0,16,2,0,0,0,0,0,0
0,0,0,0,0,2,0,0,0,0,0,0,2,26,0,0,0,0,26,2,0,0,0,0,0,2,0,0,0,0,0,0
0,0,0,0,0,2,0,0,0,30,0,0,2,2,2,2,2,2,2,2,26,0,0,0,26,2,0,0,0,0,0,0
0,0,0,0,0,2,2,2,2,2,2,2,2,0,0,0,0,0,0,0,2,2,2,2,2,2,0,0,0,0,0,0
endlayer

layer
0,0,0,0,0,9,8,8,8,8,8,8,7,0,0,0,0,0,0,0,9,8,8,8,8,8,0,0,0,0,0,0
0,0,0,0,0,9,2,2,2,2,2,2,2,8,8,8,8,8,8,8,2,2,2,2,2,7,0,0,0,0,0,0
0,0,0,0,0,9,2,2,2,2,2,2,2,2,2,2,2,2,2,2,2,2,2,2,2,7,0,0,0,0,0,0
0,0,0,0,0,9,2,2,2,2,2,2,2,2,2,2,2,2,2,2,2,2,2,2,2,7,0,0,0,0,0,0
0,0,0,0,0,9,2,2,2,2,2,2,2,2,2,2,2,2,2,2,2,2,2,2,2,2,2,7,0,0,0,0
0,9,2,2,2,2,2,2,2,2,2,2,2,2,2,2,2,2,2,2,2,2,2,2,2,7,18,2,0,0,0,0
0,9,2,2,2,2,2,2,2,2,2,2,2,2,2,2,2,2,2,2,2,2,2,2,2,7,18,2,0,0,0,0
0,0,0,0,0,9,2,2,2,2,2,2,2,2,2,2,2,2,2,2,2,2,2,2,2,2,2,7,0,0,0,0
0,0,0,0,0,9,2,2,2,2,2,2,2,2,2,2,2,2,2,2,2,2,2,2,2,7,0,0,0,0,0,0
0,0,0,0,0,9,2,2,2,2,2,2,2,2,2,2,2,2,2,2,2,2,2,2,2,7,0,0,0,0,0,0
0,0,0,0,0,9,2,2,2,2,2,2,2,10,10,10,10,10,10,10,2,2,2,2,2,7,0,0,0,0,0,0
0,0,0,0,0,10,10,10,10,10,10,10,7,0,0,0,0,0,0,0,9,10,10,10,10,7,0,0,0,0,0,0
endlayer

layer
0,0,0,0,0,0,0,0,0,0,0,0,0,0,0,0,0,0,0,0,0,0,0,0,0,0,0,0,0,0,0,0
0,0,0,0,0,0,0,0,0,0,0,0,0,0,0,0,0,0,0,0,0,0,0,0,0,0,0,0,0,0,0,0
0,0,0,0,0,0,0,0,0,0,0,0,0,0,0,0,0,0,0,0,0,0,0,0,0,0,0,0,0,0,0,0
0,0,0,0,0,0,0,0,0,0,0,0,0,0,0,0,0,0,0,0,0,0,0,0,0,0,0,0,0,0,0,0
0,0,0,0,0,0,0,0,0,0,0,0,0,0,0,0,0,0,0,0,0,0,2,2,2,2,2,0,0,0,0,0
0,0,9,2,2,7,0,0,0,0,0,0,0,0,0,0,0,0,0,0,2,2,2,2,15,31,18,2,0,0,0,0
0,0,9,2,2,7,0,0,0,0,0,0,0,0,0,0,0,0,0,0,2,2,2,2,15,32,18,2,0,0,0,0
0,0,0,0,0,0,0,0,0,0,0,0,0,0,0,0,0,0,0,0,0,0,2,2,2,2,2,0,0,0,0,0
0,0,0,0,0,0,0,0,0,0,0,0,0,0,0,0,0,0,0,0,0,0,0,0,0,0,0,0,0,0,0,0
0,0,0,0,0,0,0,0,0,0,0,0,0,0,0,0,0,0,0,0,0,0,0,0,0,0,0,0,0,0,0,0
0,0,0,0,0,0,0,0,0,0,0,0,0,0,0,0,0,0,0,0,0,0,0,0,0,0,0,0,0,0,0,0
0,0,0,0,0,0,0,0,0,0,0,0,0,0,0,0,0,0,0,0,0,0,0,0,0,0,0,0,0,0,0,0
endlayer

layer
0,0,0,0,0,0,0,0,0,0,0,0,0,0,0,0,0,0,0,0,0,0,0,0,0,0,0,0,0,0,0,0
0,0,0,0,0,0,0,0,0,0,0,0,0,0,0,0,0,0,0,0,0,0,0,0,0,0,0,0,0,0,0,0
0,0,0,0,0,0,0,0,0,0,0,0,0,0,0,0,0,0,0,0,0,0,0,0,0,0,0,0,0,0,0,0
0,0,0,0,0,0,0,0,0,0,0,0,0,0,0,0,0,0,0,0,0,0,0,0,0,0,0,0,0,0,0,0
0,0,0,0,0,0,0,0,0,0,0,0,0,0,0,0,0,0,0,0,0,0,2,2,2,2,2,0,0,0,0,0
0,0,0,0,0,0,0,0,0,0,0,0,0,0,0,0,0,0,0,12,2,2,2,17,0,31,0,7,0,0,0,0
0,0,0,0,0,0,0,0,0,0,0,0,0,0,0,0,0,0,0,12,2,2,2,17,0,32,0,7,0,0,0,0
0,0,0,0,0,0,0,0,0,0,0,0,0,0,0,0,0,0,0,0,0,0,2,2,2,2,2,0,0,0,0,0
0,0,0,0,0,0,0,0,0,0,0,0,0,0,0,0,0,0,0,0,0,0,0,0,0,0,0,0,0,0,0,0
0,0,0,0,0,0,0,0,0,0,0,0,0,0,0,0,0,0,0,0,0,0,0,0,0,0,0,0,0,0,0,0
0,0,0,0,0,0,0,0,0,0,0,0,0,0,0,0,0,0,0,0,0,0,0,0,0,0,0,0,0,0,0,0
0,0,0,0,0,0,0,0,0,0,0,0,0,0,0,0,0,0,0,0,0,0,0,0,0,0,0,0,0,0,0,0
endlayer

layer
0,0,0,0,0,0,0,0,0,0,0,0,0,0,0,0,0,0,0,0,0,0,0,0,0,0,0,0,0,0,0,0
0,0,0,0,0,0,0,0,0,0,0,0,0,0,0,0,0,0,0,0,0,0,0,0,0,0,0,0,0,0,0,0
0,0,0,0,0,0,0,0,0,0,0,0,0,0,0,0,0,0,0,0,0,0,0,0,0,0,0,0,0,0,0,0
0,0,0,0,0,0,0,0,0,0,0,0,0,0,0,0,0,0,0,0,0,0,0,0,0,0,0,0,0,0,0,0
0,0,0,0,0,0,0,0,0,0,0,0,0,0,0,0,0,0,0,0,0,0,2,2,2,2,7,0,0,0,0,0
0,0,0,0,0,0,0,0,0,0,0,0,0,0,0,0,0,0,0,12,2,2,2,0,0,31,2,0,0,0,0,0
0,0,0,0,0,0,0,0,0,0,0,0,0,0,0,0,0,0,0,12,2,2,2,0,0,32,2,0,0,0,0,0
0,0,0,0,0,0,0,0,0,0,0,0,0,0,0,0,0,0,0,0,0,0,2,2,2,2,7,0,0,0,0,0
0,0,0,0,0,0,0,0,0,0,0,0,0,0,0,0,0,0,0,0,0,0,0,0,0,0,0,0,0,0,0,0
0,0,0,0,0,0,0,0,0,0,0,0,0,0,0,0,0,0,0,0,0,0,0,0,0,0,0,0,0,0,0,0
0,0,0,0,0,0,0,0,0,0,0,0,0,0,0,0,0,0,0,0,0,0,0,0,0,0,0,0,0,0,0,0
0,0,0,0,0,0,0,0,0,0,0,0,0,0,0,0,0,0,0,0,0,0,0,0,0,0,0,0,0,0,0,0
endlayer

layer
0,0,0,0,0,0,0,0,0,0,0,0,0,0,0,0,0,0,0,0,0,0,0,0,0,0,0,0,0,0,0,0
0,0,0,0,0,0,0,0,0,0,0,0,0,0,0,0,0,0,0,0,0,0,0,0,0,0,0,0,0,0,0,0
0,0,0,0,0,0,0,0,0,0,0,0,0,0,0,0,0,0,0,0,0,0,0,0,0,0,0,0,0,0,0,0
0,0,0,0,0,0,0,0,0,0,0,0,0,0,0,0,0,0,0,0,0,0,0,0,0,0,0,0,0,0,0,0
0,0,0,0,0,0,0,0,0,0,0,0,0,0,0,0,0,0,0,0,0,0,2,2,2,2,0,0,0,0,0,0
0,0,0,0,0,0,0,0,0,0,0,0,0,0,0,0,0,0,0,12,2,2,2,0,0,31,2,0,0,0,0,0
0,0,0,0,0,0,0,0,0,0,0,0,0,0,0,0,0,0,0,12,2,2,2,0,0,32,2,0,0,0,0,0
0,0,0,0,0,0,0,0,0,0,0,0,0,0,0,0,0,0,0,0,0,0,2,2,2,2,0,0,0,0,0,0
0,0,0,0,0,0,0,0,0,0,0,0,0,0,0,0,0,0,0,0,0,0,0,0,0,0,0,0,0,0,0,0
0,0,0,0,0,0,0,0,0,0,0,0,0,0,0,0,0,0,0,0,0,0,0,0,0,0,0,0,0,0,0,0
0,0,0,0,0,0,0,0,0,0,0,0,0,0,0,0,0,0,0,0,0,0,0,0,0,0,0,0,0,0,0,0
0,0,0,0,0,0,0,0,0,0,0,0,0,0,0,0,0,0,0,0,0,0,0,0,0,0,0,0,0,0,0,0
endlayer

layer
0,0,0,0,0,0,0,0,0,0,0,0,0,0,0,0,0,0,0,0,0,0,0,0,0,0,0,0,0,0,0,0
0,0,0,0,0,0,0,0,0,0,0,0,0,0,0,0,0,0,0,0,0,0,0,0,0,0,0,0,0,0,0,0
0,0,0,0,0,0,0,0,0,0,0,0,0,0,0,0,0,0,0,0,0,0,0,0,0,0,0,0,0,0,0,0
0,0,0,0,0,0,0,0,0,0,0,0,0,0,0,0,0,0,0,0,0,0,0,0,0,0,0,0,0,0,0,0
0,0,0,0,0,0,0,0,0,0,0,0,0,0,0,0,0,0,0,0,0,0,2,2,2,2,0,0,0,0,0,0
0,0,0,0,0,0,0,0,0,0,0,0,0,0,0,0,0,0,0,12,2,2,2,0,0,31,2,0,0,0,0,0
0,0,0,0,0,0,0,0,0,0,0,0,0,0,0,0,0,0,0,12,2,2,2,0,0,32,2,0,0,0,0,0
0,0,0,0,0,0,0,0,0,0,0,0,0,0,0,0,0,0,0,0,0,0,2,2,2,2,0,0,0,0,0,0
0,0,0,0,0,0,0,0,0,0,0,0,0,0,0,0,0,0,0,0,0,0,0,0,0,0,0,0,0,0,0,0
0,0,0,0,0,0,0,0,0,0,0,0,0,0,0,0,0,0,0,0,0,0,0,0,0,0,0,0,0,0,0,0
0,0,0,0,0,0,0,0,0,0,0,0,0,0,0,0,0,0,0,0,0,0,0,0,0,0,0,0,0,0,0,0
0,0,0,0,0,0,0,0,0,0,0,0,0,0,0,0,0,0,0,0,0,0,0,0,0,0,0,0,0,0,0,0
endlayer

layer
0,0,0,0,0,0,0,0,0,0,0,0,0,0,0,0,0,0,0,0,0,0,0,0,0,0,0,0,0,0,0,0
0,0,0,0,0,0,0,0,0,0,0,0,0,0,0,0,0,0,0,0,0,0,0,0,0,0,0,0,0,0,0,0
0,0,0,0,0,0,0,0,0,0,0,0,0,0,0,0,0,0,0,0,0,0,0,0,0,0,0,0,0,0,0,0
0,0,0,0,0,0,0,0,0,0,0,0,0,0,0,0,0,0,0,0,0,0,0,0,0,0,0,0,0,0,0,0
0,0,0,0,0,0,0,0,0,0,0,0,0,0,0,0,0,0,0,0,0,0,2,2,2,2,13,0,0,0,0,0
0,0,0,0,0,0,0,0,0,0,0,0,0,0,0,0,0,0,0,12,2,2,2,2,2,31,2,13,0,0,0,0
0,0,0,0,0,0,0,0,0,0,0,0,0,0,0,0,0,0,0,12,2,2,2,2,2,32,2,13,0,0,0,0
0,0,0,0,0,0,0,0,0,0,0,0,0,0,0,0,0,0,0,0,0,0,2,2,2,2,13,0,0,0,0,0
0,0,0,0,0,0,0,0,0,0,0,0,0,0,0,0,0,0,0,0,0,0,0,0,0,0,0,0,0,0,0,0
0,0,0,0,0,0,0,0,0,0,0,0,0,0,0,0,0,0,0,0,0,0,0,0,0,0,0,0,0,0,0,0
0,0,0,0,0,0,0,0,0,0,0,0,0,0,0,0,0,0,0,0,0,0,0,0,0,0,0,0,0,0,0,0
0,0,0,0,0,0,0,0,0,0,0,0,0,0,0,0,0,0,0,0,0,0,0,0,0,0,0,0,0,0,0,0
endlayer

layer
0,0,0,0,0,0,0,0,0,0,0,0,0,0,0,0,0,0,0,0,0,0,0,0,0,0,0,0,0,0,0,0
0,0,0,0,0,0,0,0,0,0,0,0,0,0,0,0,0,0,0,0,0,0,0,0,0,0,0,0,0,0,0,0
0,0,0,0,0,0,0,0,0,0,0,0,0,0,0,0,0,0,0,0,0,0,0,0,0,0,0,0,0,0,0,0
0,0,0,0,0,0,0,0,0,0,0,0,0,0,0,0,0,0,0,0,0,0,12,2,2,13,0,0,0,12,2,2
0,0,0,0,0,0,0,0,0,0,0,0,0,0,0,0,0,0,0,0,0,0,2,2,2,2,2,2,2,2,2,2
0,0,0,0,0,0,0,0,0,0,0,0,0,0,0,0,0,0,0,12,2,2,2,2,2,31,2,2,2,2,2,2
0,0,0,0,0,0,0,0,0,0,0,0,0,0,0,0,0,0,0,12,2,2,2,2,2,32,2,2,2,2,2,2
0,0,0,0,0,0,0,0,0,0,0,0,0,0,0,0,0,0,0,0,0,0,2,2,2,2,2,2,2,2,2,2
0,0,0,0,0,0,0,0,0,0,0,0,0,0,0,0,0,0,0,0,0,0,12,2,2,13,0,0,0,12,2,2
0,0,0,0,0,0,0,0,0,0,0,0,0,0,0,0,0,0,0,0,0,0,0,0,0,0,0,0,0,0,0,0
0,0,0,0,0,0,0,0,0,0,0,0,0,0,0,0,0,0,0,0,0,0,0,0,0,0,0,0,0,0,0,0
0,0,0,0,0,0,0,0,0,0,0,0,0,0,0,0,0,0,0,0,0,0,0,0,0,0,0,0,0,0,0,0
endlayer

layer
0,0,0,0,0,0,0,0,0,0,0,0,0,0,0,0,0,0,0,0,0,0,0,0,0,0,0,0,0,0,0,0
0,0,0,0,0,0,0,0,0,0,0,0,0,0,0,0,0,0,0,0,0,0,0,0,0,0,0,0,0,0,0,0
0,0,0,0,0,0,0,0,0,0,0,0,0,0,0,0,0,0,0,0,0,0,0,0,0,0,0,0,0,0,0,0
0,0,0,0,0,0,0,0,0,0,0,0,0,0,0,0,0,0,0,0,0,0,2,2,2,2,2,2,2,2,2,2
0,0,0,0,0,0,0,0,0,0,0,0,0,0,0,0,0,0,0,0,0,0,2,10,15,2,15,15,15,15,2,2
0,0,0,0,0,0,0,0,0,0,0,0,0,0,0,0,0,0,0,12,2,2,2,2,15,31,15,33,33,15,15,2
0,0,0,0,0,0,0,0,0,0,0,0,0,0,0,0,0,0,0,12,2,2,2,2,15,32,15,33,33,15,15,2
0,0,0,0,0,0,0,0,0,0,0,0,0,0,0,0,0,0,0,0,0,0,2,8,15,2,15,15,15,15,2,2
0,0,0,0,0,0,0,0,0,0,0,0,0,0,0,0,0,0,0,0,0,0,2,2,2,2,2,2,2,2,2,2
0,0,0,0,0,0,0,0,0,0,0,0,0,0,0,0,0,0,0,0,0,0,0,0,0,0,0,0,0,0,0,0
0,0,0,0,0,0,0,0,0,0,0,0,0,0,0,0,0,0,0,0,0,0,0,0,0,0,0,0,0,0,0,0
0,0,0,0,0,0,0,0,0,0,0,0,0,0,0,0,0,0,0,0,0,0,0,0,0,0,0,0,0,0,0,0
endlayer

layer
0,0,0,0,0,0,0,0,0,0,0,0,0,0,0,0,0,0,0,0,0,0,0,0,0,0,0,0,0,0,0,0
0,0,0,0,0,0,0,0,0,0,0,0,0,0,0,0,0,0,0,0,0,0,0,0,0,0,0,0,0,0,0,0
0,0,0,0,0,0,0,0,0,0,0,0,0,0,0,0,0,0,0,0,0,0,0,0,0,0,0,0,0,0,0,0
0,0,0,0,0,0,0,0,0,0,0,0,0,0,0,0,0,0,0,0,0,0,2,2,2,2,2,2,2,2,2,2
0,0,0,0,0,0,0,0,0,0,0,0,0,0,0,0,0,0,0,0,0,0,2,17,0,10,0,0,0,0,16,2
0,0,0,0,0,0,0,0,0,0,0,0,0,0,0,0,0,0,0,12,2,2,2,25,0,0,0,15,15,0,33,2
0,0,0,0,0,0,0,0,0,0,0,0,0,0,0,0,0,0,0,12,2,2,2,25,0,0,0,15,15,0,33,2
0,0,0,0,0,0,0,0,0,0,0,0,0,0,0,0,0,0,0,0,0,0,2,17,0,8,0,0,0,0,16,2
0,0,0,0,0,0,0,0,0,0,0,0,0,0,0,0,0,0,0,0,0,0,2,2,2,2,2,2,2,2,2,2
0,0,0,0,0,0,0,0,0,0,0,0,0,0,0,0,0,0,0,0,0,0,0,0,0,0,0,0,0,0,0,0
0,0,0,0,0,0,0,0,0,0,0,0,0,0,0,0,0,0,0,0,0,0,0,0,0,0,0,0,0,0,0,0
0,0,0,0,0,0,0,0,0,0,0,0,0,0,0,0,0,0,0,0,0,0,0,0,0,0,0,0,0,0,0,0
endlayer

layer
0,0,0,0,0,0,0,0,0,0,0,0,0,0,0,0,0,0,0,0,0,0,0,0,0,0,0,0,0,0,0,0
0,0,0,0,0,0,0,0,0,0,0,0,0,0,0,0,0,0,0,0,0,0,0,0,0,0,0,0,0,0,0,0
0,0,0,0,0,0,0,0,0,0,0,0,0,0,0,0,0,0,0,0,0,0,0,0,0,0,0,0,0,0,0,0
0,0,0,0,0,0,0,0,0,0,0,0,0,0,0,0,0,0,0,0,0,0,2,2,2,2,2,2,2,2,2,0
0,0,0,0,0,0,0,0,0,0,0,0,0,0,0,0,0,0,0,0,0,0,2,0,0,0,0,0,0,0,16,2
0,0,0,0,0,0,0,0,0,0,0,0,0,0,0,0,0,0,0,12,2,2,2,0,0,0,0,0,0,0,34,2
0,0,0,0,0,0,0,0,0,0,0,0,0,0,0,0,0,0,0,12,2,2,2,0,0,0,0,0,0,0,34,2
0,0,0,0,0,0,0,0,0,0,0,0,0,0,0,0,0,0,0,0,0,0,2,0,0,0,0,0,0,0,16,2
0,0,0,0,0,0,0,0,0,0,0,0,0,0,0,0,0,0,0,0,0,0,2,2,2,2,2,2,2,2,2,0
0,0,0,0,0,0,0,0,0,0,0,0,0,0,0,0,0,0,0,0,0,0,0,0,0,0,0,0,0,0,0,0
0,0,0,0,0,0,0,0,0,0,0,0,0,0,0,0,0,0,0,0,0,0,0,0,0,0,0,0,0,0,0,0
0,0,0,0,0,0,0,0,0,0,0,0,0,0,0,0,0,0,0,0,0,0,0,0,0,0,0,0,0,0,0,0
endlayer

layer
0,0,0,0,0,0,0,0,0,0,0,0,0,0,0,0,0,0,0,0,0,0,0,0,0,0,0,0,0,0,0,0
0,0,0,0,0,0,0,0,0,0,0,0,0,0,0,0,0,0,0,0,0,0,0,0,0,0,0,0,0,0,0,0
0,0,0,0,0,0,0,0,0,0,0,0,0,0,0,0,0,0,0,0,0,0,0,0,0,0,0,0,0,0,0,0
0,0,0,0,0,0,0,0,0,0,0,0,0,0,0,0,0,0,0,0,0,0,2,2,2,11,11,2,2,2,2,2
0,0,0,0,0,0,0,0,0,0,0,0,0,0,0,0,0,0,0,0,0,0,2,0,0,0,0,0,0,0,16,2
0,0,0,0,0,0,0,0,0,0,0,0,0,0,0,0,0,0,0,12,2,2,2,0,0,0,0,0,0,0,17,2
0,0,0,0,0,0,0,0,0,0,0,0,0,0,0,0,0,0,0,12,2,2,2,0,0,0,0,0,0,0,17,2
0,0,0,0,0,0,0,0,0,0,0,0,0,0,0,0,0,0,0,0,0,0,2,0,0,0,0,0,0,0,16,2
0,0,0,0,0,0,0,0,0,0,0,0,0,0,0,0,0,0,0,0,0,0,2,2,2,14,14,2,2,2,2,2
0,0,0,0,0,0,0,0,0,0,0,0,0,0,0,0,0,0,0,0,0,0,0,0,0,0,0,0,0,0,0,0
0,0,0,0,0,0,0,0,0,0,0,0,0,0,0,0,0,0,0,0,0,0,0,0,0,0,0,0,0,0,0,0
0,0,0,0,0,0,0,0,0,0,0,0,0,0,0,0,0,0,0,0,0,0,0,0,0,0,0,0,0,0,0,0
endlayer

layer
0,0,0,0,0,0,0,0,0,0,0,0,0,0,0,0,0,0,0,0,0,0,0,0,0,0,0,0,0,0,0,0
0,0,0,0,0,0,0,0,0,0,0,0,0,0,0,0,0,0,0,0,0,0,0,0,0,0,0,0,0,0,0,0
0,0,0,0,0,0,0,0,0,0,0,0,0,0,0,0,0,0,0,0,0,0,0,0,0,0,0,0,0,0,0,0
0,0,0,0,0,0,0,0,0,0,0,0,0,0,0,0,0,0,0,0,0,0,2,2,2,2,7,0,0,0,0,0
0,0,0,0,0,0,0,0,0,0,0,0,0,0,0,0,0,0,0,0,0,0,2,2,2,2,2,2,2,2,2,7
0,0,0,0,0,0,0,0,0,0,0,0,0,0,0,0,0,0,0,12,2,2,2,2,2,2,2,2,2,2,2,7
0,0,0,0,0,0,0,0,0,0,0,0,0,0,0,0,0,0,0,12,2,2,2,2,2,2,2,2,2,2,2,7
0,0,0,0,0,0,0,0,0,0,0,0,0,0,0,0,0,0,0,0,0,0,2,2,2,2,2,2,2,2,2,7
0,0,0,0,0,0,0,0,0,0,0,0,0,0,0,0,0,0,0,0,0,0,2,2,2,2,7,0,0,0,0,0
0,0,0,0,0,0,0,0,0,0,0,0,0,0,0,0,0,0,0,0,0,0,0,0,0,0,0,0,0,0,0,0
0,0,0,0,0,0,0,0,0,0,0,0,0,0,0,0,0,0,0,0,0,0,0,0,0,0,0,0,0,0,0,0
0,0,0,0,0,0,0,0,0,0,0,0,0,0,0,0,0,0,0,0,0,0,0,0,0,0,0,0,0,0,0,0
endlayer

layer
0,0,0,0,0,0,0,0,0,0,0,0,0,0,0,0,0,0,0,0,0,0,0,0,0,0,0,0,0,0,0,0
0,0,0,0,0,0,0,0,0,0,0,0,0,0,0,0,0,0,0,0,0,0,0,0,0,0,0,0,0,0,0,0
0,0,0,0,0,0,0,0,0,0,0,0,0,0,0,0,0,0,0,0,0,0,0,0,0,0,0,0,0,0,0,0
0,0,0,0,0,0,0,0,0,0,0,0,0,0,0,0,0,0,0,0,0,0,2,0,0,0,0,0,0,0,0,0
0,0,0,0,0,0,0,0,0,0,0,0,0,0,0,0,0,0,0,0,0,0,2,0,0,0,0,0,0,0,0,0
0,0,0,0,0,0,0,0,0,0,0,0,0,0,0,0,0,0,0,12,2,2,2,2,2,2,0,0,0,0,0,0
0,0,0,0,0,0,0,0,0,0,0,0,0,0,0,0,0,0,0,12,2,2,2,2,2,2,0,0,0,0,0,0
0,0,0,0,0,0,0,0,0,0,0,0,0,0,0,0,0,0,0,0,0,0,2,0,0,0,0,0,0,0,0,0
0,0,0,0,0,0,0,0,0,0,0,0,0,0,0,0,0,0,0,0,0,0,2,0,0,0,0,0,0,0,0,0
0,0,0,0,0,0,0,0,0,0,0,0,0,0,0,0,0,0,0,0,0,0,0,0,0,0,0,0,0,0,0,0
0,0,0,0,0,0,0,0,0,0,0,0,0,0,0,0,0,0,0,0,0,0,0,0,0,0,0,0,0,0,0,0
0,0,0,0,0,0,0,0,0,0,0,0,0,0,0,0,0,0,0,0,0,0,0,0,0,0,0,0,0,0,0,0
endlayer

layer
0,0,0,0,0,0,0,0,0,0,0,0,0,0,0,0,0,0,0,0,0,0,0,0,0,0,0,0,0,0,0,0
0,0,0,0,0,0,0,0,0,0,0,0,0,0,0,0,0,0,0,0,0,0,0,0,0,0,0,0,0,0,0,0
0,0,0,0,0,0,0,0,0,0,0,0,0,0,0,0,0,0,0,0,0,0,0,0,0,0,0,0,0,0,0,0
0,0,0,0,0,0,0,0,0,0,0,0,0,0,0,0,0,0,0,0,0,0,2,0,0,0,0,0,0,0,0,0
0,0,0,0,0,0,0,0,0,0,0,0,0,0,0,0,0,0,0,0,0,0,2,0,0,0,0,0,0,0,0,0
0,0,0,0,0,0,0,0,0,0,0,0,0,0,0,0,0,0,0,12,2,2,2,2,2,2,13,0,0,0,0,0
0,0,0,0,0,0,0,0,0,0,0,0,0,0,0,0,0,0,0,12,2,2,2,2,2,2,13,0,0,0,0,0
0,0,0,0,0,0,0,0,0,0,0,0,0,0,0,0,0,0,0,0,0,0,2,0,0,0,0,0,0,0,0,0
0,0,0,0,0,0,0,0,0,0,0,0,0,0,0,0,0,0,0,0,0,0,2,0,0,0,0,0,0,0,0,0
0,0,0,0,0,0,0,0,0,0,0,0,0,0,0,0,0,0,0,0,0,0,0,0,0,0,0,0,0,0,0,0
0,0,0,0,0,0,0,0,0,0,0,0,0,0,0,0,0,0,0,0,0,0,0,0,0,0,0,0,0,0,0,0
0,0,0,0,0,0,0,0,0,0,0,0,0,0,0,0,0,0,0,0,0,0,0,0,0,0,0,0,0,0,0,0
endlayer

layer
0,0,0,0,0,0,0,0,0,0,0,0,0,0,0,0,0,0,0,0,0,0,0,0,0,0,0,0,0,0,0,0
0,0,0,0,0,0,0,0,0,0,0,0,0,0,0,0,0,0,0,0,0,0,0,0,0,0,0,0,0,0,0,0
0,0,0,0,0,0,0,0,0,0,0,0,0,0,0,0,0,0,0,0,0,0,0,0,0,0,0,0,0,0,0,0
0,0,0,0,0,0,0,0,0,0,0,0,0,0,0,0,0,0,0,0,0,0,8,0,0,0,0,0,0,0,0,0
0,0,0,0,0,0,0,0,0,0,0,0,0,0,0,0,0,0,0,0,0,0,10,0,0,0,0,0,0,0,0,0
0,0,0,0,0,0,0,0,0,0,0,0,0,0,0,0,0,0,0,12,2,2,2,2,2,2,2,13,0,0,0,0
0,0,0,0,0,0,0,0,0,0,0,0,0,0,0,0,0,0,0,12,2,2,2,2,2,2,2,13,0,0,0,0
0,0,0,0,0,0,0,0,0,0,0,0,0,0,0,0,0,0,0,0,0,0,8,0,0,0,0,0,0,0,0,0
0,0,0,0,0,0,0,0,0,0,0,0,0,0,0,0,0,0,0,0,0,0,10,0,0,0,0,0,0,0,0,0
0,0,0,0,0,0,0,0,0,0,0,0,0,0,0,0,0,0,0,0,0,0,0,0,0,0,0,0,0,0,0,0
0,0,0,0,0,0,0,0,0,0,0,0,0,0,0,0,0,0,0,0,0,0,0,0,0,0,0,0,0,0,0,0
0,0,0,0,0,0,0,0,0,0,0,0,0,0,0,0,0,0,0,0,0,0,0,0,0,0,0,0,0,0,0,0
endlayer

layer
0,0,0,0,0,0,0,0,0,0,0,0,0,0,0,0,0,0,0,0,0,0,0,0,0,0,0,0,0,0,0,0
0,0,0,0,0,0,0,0,0,0,0,0,0,0,0,0,0,0,0,0,0,0,0,0,0,0,0,0,0,0,0,0
0,0,0,0,0,0,0,0,0,0,0,0,0,0,0,0,0,0,0,0,0,0,0,0,0,0,0,0,0,0,0,0
0,0,0,0,0,0,0,0,0,0,0,0,0,0,0,0,0,0,0,0,0,0,0,0,0,0,0,0,0,0,0,0
0,0,0,0,0,0,0,0,0,0,0,0,0,0,0,0,0,0,0,0,0,0,0,0,0,0,0,0,0,0,0,0
0,0,0,0,0,0,0,0,0,0,0,0,0,0,0,0,0,0,0,0,7,2,2,2,2,2,2,2,13,0,0,0
0,0,0,0,0,0,0,0,0,0,0,0,0,0,0,0,0,0,0,0,7,2,2,2,2,2,2,2,13,0,0,0
0,0,0,0,0,0,0,0,0,0,0,0,0,0,0,0,0,0,0,0,0,0,0,0,0,0,0,0,0,0,0,0
0,0,0,0,0,0,0,0,0,0,0,0,0,0,0,0,0,0,0,0,0,0,0,0,0,0,0,0,0,0,0,0
0,0,0,0,0,0,0,0,0,0,0,0,0,0,0,0,0,0,0,0,0,0,0,0,0,0,0,0,0,0,0,0
0,0,0,0,0,0,0,0,0,0,0,0,0,0,0,0,0,0,0,0,0,0,0,0,0,0,0,0,0,0,0,0
0,0,0,0,0,0,0,0,0,0,0,0,0,0,0,0,0,0,0,0,0,0,0,0,0,0,0,0,0,0,0,0
endlayer

layer
0,0,0,0,0,0,0,0,0,0,0,0,0,0,0,0,0,0,0,0,0,0,0,0,0,0,0,0,0,0,0,0
0,0,0,0,0,0,0,0,0,0,0,0,0,0,0,0,0,0,0,0,0,0,0,0,0,0,0,0,0,0,0,0
0,0,0,0,0,0,0,0,0,0,0,0,0,0,0,0,0,0,0,0,0,0,0,0,0,0,0,0,0,0,0,0
0,0,0,0,0,0,0,0,0,0,0,0,0,0,0,0,0,0,0,0,0,0,0,0,0,0,0,0,0,0,0,0
0,0,0,0,0,0,0,0,0,0,0,0,0,0,0,0,0,0,0,0,0,0,0,0,0,0,0,0,0,0,0,0
0,0,0,0,0,0,0,0,0,0,0,0,0,0,0,0,0,0,0,0,0,9,9,9,9,9,9,9,9,0,0,0
0,0,0,0,0,0,0,0,0,0,0,0,0,0,0,0,0,0,0,0,0,9,9,9,9,9,9,9,9,0,0,0
0,0,0,0,0,0,0,0,0,0,0,0,0,0,0,0,0,0,0,0,0,0,0,0,0,0,0,0,0,0,0,0
0,0,0,0,0,0,0,0,0,0,0,0,0,0,0,0,0,0,0,0,0,0,0,0,0,0,0,0,0,0,0,0
0,0,0,0,0,0,0,0,0,0,0,0,0,0,0,0,0,0,0,0,0,0,0,0,0,0,0,0,0,0,0,0
0,0,0,0,0,0,0,0,0,0,0,0,0,0,0,0,0,0,0,0,0,0,0,0,0,0,0,0,0,0,0,0
0,0,0,0,0,0,0,0,0,0,0,0,0,0,0,0,0,0,0,0,0,0,0,0,0,0,0,0,0,0,0,0
endlayer

