# Underground Fountain Shrine -- created for MC 1.9 -- 5 May 2016
# Created by Ruins mod version 16.0 Ingame Parser
# authoring Player: Jordan_Greywolf

# Updated to MC 1.10: 13 Sep 2016
# Updated to MC 1.11: 13 Jan 2017
# Verified for MC 1.12: 23 Jun 2017
# Updated to MC 1.12.1: 10 Sep 2017

# Last Updated: 9 Jun 2018


biomesToSpawnIn=bog,biome_degraded,biome_meneglin,desert,deep ocean,extreme hills edge,field,lavender fields,lavender_fields,meadow,ocean,origin valley,origin_valley,pasture,plains,prairie,savanna,savanna m,shrubland,scrubland,sunflower plains,swampland,xeric shrubland,xeric_shrubland,wasteland,deep_ocean,smaller_extreme_hills,mutated_plains,temperate_rainforest,highland,fen,wetlands,land_of_lakes

weight=1
embed_into_distance=64
acceptable_target_blocks=

unacceptable_target_blocks=cloud,Natura:Cloud,slime_congealed,slime_dirt,slime_grass,command_block,planks,planks2,concrete,cobblestone,stonebrick,brick_block,glass,torch,oak_stairs,stone_stairs,brick_stairs,stone_brick_stairs,nether_brick_stairs,sandstone_stairs,spruce_stairs,birch_stairs,jungle_stairs,quartz_stairs,acacia_stairs,dark_oak_stairs,cobblestone_wall,stone_slab,double_stone_slab,stone_slab2,wooden_slab,double_wooden_slab,nether_brick,fence

dimensions=19,21,21
allowable_overhang=9999
max_leveling=20
leveling_buffer=-1
preserve_water=0
preserve_lava=0
preserve_plants=1

rule1=0,100,minecraft:stone-6
rule2=0,100,preserveBlock
rule3=0,100,minecraft:dirt-0
rule4=0,100,minecraft:wooden_slab-5
rule5=0,100,minecraft:stone_slab-6
rule6=0,100,minecraft:nether_brick_stairs-0
rule7=0,100,minecraft:nether_brick_stairs-2
rule8=0,100,minecraft:grass-0
rule9=0,100,minecraft:nether_brick_stairs-3
rule10=0,100,minecraft:dark_oak_stairs-3
rule11=0,100,minecraft:dark_oak_stairs-2
rule12=0,100,minecraft:nether_brick_stairs-1
rule13=0,100,minecraft:stone_brick_stairs-0
rule14=0,100,IInventory;minecraft:chest;minecraft:stained_glass#8#2#4+minecraft:stained_glass#8#3#10+minecraft:stained_glass#8#10#16+minecraft:stained_glass#8#11#23-4
rule15=0,100,MobSpawner:Skeleton,MobSpawner:Zombie,MobSpawner:Spider,MobSpawner:Slime
rule16=0,100,ChestGenHook:chests/simple_dungeon:5-4
rule17=0,100,minecraft:stone_brick_stairs-3
rule18=0,100,minecraft:stone_brick_stairs-2
rule19=0,100,minecraft:water-0
rule20=0,100,minecraft:dark_oak_stairs-1
rule21=0,100,IInventory;minecraft:chest;minecraft:nether_brick#16#0#3+minecraft:stone#16#4#6+minecraft:stone#16#6#11+minecraft:log2#16#1#23-2
rule22=0,100,ChestGenHook:chests/simple_dungeon:5-3
rule23=0,100,minecraft:stonebrick-3
rule24=0,100,minecraft:dark_oak_stairs-0
rule25=0,100,ChestGenHook:chests/simple_dungeon:5-2
rule26=0,100,IInventory;minecraft:chest;minecraft:sapling#16#5#6+minecraft:dirt#16#0#10+minecraft:water_bucket#1#0#22+minecraft:stonebrick#16#0#25-3
rule27=0,100,minecraft:stone_brick_stairs-1
rule28=0,100,IInventory;minecraft:chest;minecraft:iron_bars#16#0#4+minecraft:grass#16#0#11+minecraft:torch#16#0#16+minecraft:stone#16#0#24-5
rule29=0,100,ChestGenHook:chests/simple_dungeon:5-5

# Random "Cool Color" Stained Glass Pane
rule30=0,100,minecraft:stained_glass_pane-2,minecraft:stained_glass_pane-3,minecraft:stained_glass_pane-10,minecraft:stained_glass_pane-11
rule31=0,100,minecraft:iron_bars-0
rule32=0,100,minecraft:double_plant-4
rule33=0,100,minecraft:stone_slab-0
rule34=0,100,minecraft:water-9
rule35=0,100,minecraft:double_plant-10
rule36=0,100,minecraft:water-1
rule37=0,100,minecraft:nether_brick_stairs-4
rule38=0,100,minecraft:nether_brick_stairs-6
rule39=0,100,minecraft:nether_brick_stairs-7
rule40=0,100,minecraft:nether_brick_stairs-5
rule41=0,100,minecraft:lit_redstone_lamp-0
rule42=0,100,minecraft:stone-4
rule43=0,100,minecraft:stone_slab-8
rule44=2,100,minecraft:redstone_torch-2
rule45=2,100,minecraft:redstone_torch-4
rule46=2,100,minecraft:redstone_torch-3
rule47=2,100,minecraft:redstone_torch-1
rule48=1,100,minecraft:redstone_torch-5

layer
1,1,1,1,1,1,1,1,1,1,1,1,1,1,1,1,1,1,1,1,1
1,2,2,2,2,2,2,2,2,2,2,2,2,2,2,2,2,2,2,2,1
1,2,2,2,2,2,2,2,2,2,2,2,2,2,2,2,2,2,2,2,1
1,2,2,3,2,2,2,2,2,2,2,2,2,2,2,2,2,3,2,2,1
1,2,2,2,2,2,2,2,2,2,2,2,2,2,2,2,2,2,2,2,1
1,2,2,2,2,2,2,2,2,2,2,2,2,2,2,2,2,2,2,2,1
1,2,2,2,2,2,2,2,2,1,1,1,2,2,2,2,2,2,2,2,1
1,2,2,2,2,2,2,2,2,1,1,1,2,2,2,2,2,2,2,2,1
1,2,2,2,2,2,2,2,1,1,1,1,1,2,2,2,2,2,2,2,1
1,2,2,2,2,2,1,1,1,1,1,1,1,1,1,2,2,2,2,2,1
1,2,2,2,2,2,1,1,1,1,1,1,1,1,1,2,2,2,2,2,1
1,2,2,2,2,2,1,1,1,1,1,1,1,1,1,2,2,2,2,2,1
1,2,2,2,2,2,2,2,1,1,1,1,1,2,2,2,2,2,2,2,1
1,2,2,2,2,2,2,2,2,1,1,1,2,2,2,2,2,2,2,2,1
1,2,2,2,2,2,2,2,2,1,1,1,2,2,2,2,2,2,2,2,1
1,2,2,2,2,2,2,2,2,2,2,2,2,2,2,2,2,2,2,2,1
1,2,2,2,2,2,2,2,2,2,2,2,2,2,2,2,2,2,2,2,1
1,2,2,3,2,2,2,2,2,2,2,2,2,2,2,2,2,3,2,2,1
1,2,2,2,2,2,2,2,2,2,2,2,2,2,2,2,2,2,2,2,1
1,2,2,2,2,2,2,2,2,2,2,2,2,2,2,2,2,2,2,2,1
1,1,1,1,1,1,1,1,1,1,1,1,1,1,1,1,1,1,1,1,1
endlayer

layer
1,1,1,1,1,1,1,1,1,1,1,1,1,1,1,1,1,1,1,1,1
1,4,5,4,5,4,5,4,5,4,5,4,5,4,5,4,5,4,5,4,1
1,5,4,6,4,5,4,5,4,5,4,5,4,5,4,5,4,6,4,5,1
1,4,9,8,7,4,5,4,5,11,5,10,5,4,5,4,9,8,7,4,1
1,5,4,12,4,5,4,5,4,5,4,5,4,5,4,5,4,12,4,5,1
1,4,5,4,5,4,5,4,5,4,5,4,5,4,5,4,5,4,5,4,1
1,5,4,5,4,5,4,5,17,16,15,14,13,5,4,5,4,5,4,5,1
1,4,5,4,5,4,5,17,13,1,1,1,18,13,5,4,5,4,5,4,1
1,5,4,5,4,5,17,13,1,19,19,19,1,18,13,5,4,5,4,5,1
1,4,5,20,5,4,22,1,19,19,19,19,19,1,21,4,5,20,5,4,1
1,5,4,5,4,5,15,1,19,19,23,19,19,1,15,5,4,5,4,5,1
1,4,5,24,5,4,26,1,19,19,19,19,19,1,25,4,5,24,5,4,1
1,5,4,5,4,5,27,17,1,19,19,19,1,27,18,5,4,5,4,5,1
1,4,5,4,5,4,5,27,17,1,1,1,27,18,5,4,5,4,5,4,1
1,5,4,5,4,5,4,5,27,29,15,28,18,5,4,5,4,5,4,5,1
1,4,5,4,5,4,5,4,5,4,5,4,5,4,5,4,5,4,5,4,1
1,5,4,6,4,5,4,5,4,5,4,5,4,5,4,5,4,6,4,5,1
1,4,9,8,7,4,5,4,5,11,5,10,5,4,5,4,9,8,7,4,1
1,5,4,12,4,5,4,5,4,5,4,5,4,5,4,5,4,12,4,5,1
1,4,5,4,5,4,5,4,5,4,5,4,5,4,5,4,5,4,5,4,1
1,1,1,1,1,1,1,1,1,1,1,1,1,1,1,1,1,1,1,1,1
endlayer

layer
1,1,30,1,30,30,1,30,1,31,31,31,1,30,1,30,30,1,30,1,1
1,0,0,0,0,0,0,0,0,0,0,0,0,0,0,0,0,0,0,0,1
30,0,31,31,31,0,0,0,0,0,0,0,0,0,0,0,31,31,31,0,30
1,0,31,32,31,0,0,0,0,33,33,33,0,0,0,0,31,32,31,0,1
30,0,31,31,31,0,0,0,0,0,0,0,0,0,0,0,31,31,31,0,30
30,0,0,0,0,0,0,0,0,0,0,0,0,0,0,0,0,0,0,0,30
1,0,0,0,0,0,0,0,0,0,0,0,0,0,0,0,0,0,0,0,1
30,0,0,0,0,0,0,0,0,33,33,33,0,0,0,0,0,0,0,0,30
1,0,0,0,0,0,0,0,33,0,0,0,33,0,0,0,0,0,0,0,1
31,0,0,33,0,0,0,33,0,0,34,0,0,33,0,0,0,33,0,0,31
31,0,0,33,0,0,0,33,0,34,23,34,0,33,0,0,0,33,0,0,31
31,0,0,33,0,0,0,33,0,0,34,0,0,33,0,0,0,33,0,0,31
1,0,0,0,0,0,0,0,33,0,0,0,33,0,0,0,0,0,0,0,1
30,0,0,0,0,0,0,0,0,33,33,33,0,0,0,0,0,0,0,0,30
1,0,0,0,0,0,0,0,0,0,0,0,0,0,0,0,0,0,0,0,1
30,0,0,0,0,0,0,0,0,0,0,0,0,0,0,0,0,0,0,0,30
30,0,31,31,31,0,0,0,0,0,0,0,0,0,0,0,31,31,31,0,30
1,0,31,32,31,0,0,0,0,33,33,33,0,0,0,0,31,32,31,0,1
30,0,31,31,31,0,0,0,0,0,0,0,0,0,0,0,31,31,31,0,30
1,0,0,0,0,0,0,0,0,0,0,0,0,0,0,0,0,0,0,0,1
1,1,30,1,30,30,1,30,1,31,31,31,1,30,1,30,30,1,30,1,1
endlayer

layer
1,1,30,1,30,30,1,30,1,31,31,31,1,30,1,30,30,1,30,1,1
1,0,0,0,0,0,0,0,0,0,0,0,0,0,0,0,0,0,0,0,1
30,0,31,31,31,0,0,0,0,0,0,0,0,0,0,0,31,31,31,0,30
1,0,31,35,31,0,0,0,0,0,0,0,0,0,0,0,31,35,31,0,1
30,0,31,31,31,0,0,0,0,0,0,0,0,0,0,0,31,31,31,0,30
30,0,0,0,0,0,0,0,0,0,0,0,0,0,0,0,0,0,0,0,30
1,0,0,0,0,0,0,0,0,0,0,0,0,0,0,0,0,0,0,0,1
30,0,0,0,0,0,0,0,0,0,0,0,0,0,0,0,0,0,0,0,30
1,0,0,0,0,0,0,0,0,0,0,0,0,0,0,0,0,0,0,0,1
31,0,0,0,0,0,0,0,0,0,36,0,0,0,0,0,0,0,0,0,31
31,0,0,0,0,0,0,0,0,36,19,36,0,0,0,0,0,0,0,0,31
31,0,0,0,0,0,0,0,0,0,36,0,0,0,0,0,0,0,0,0,31
1,0,0,0,0,0,0,0,0,0,0,0,0,0,0,0,0,0,0,0,1
30,0,0,0,0,0,0,0,0,0,0,0,0,0,0,0,0,0,0,0,30
1,0,0,0,0,0,0,0,0,0,0,0,0,0,0,0,0,0,0,0,1
30,0,0,0,0,0,0,0,0,0,0,0,0,0,0,0,0,0,0,0,30
30,0,31,31,31,0,0,0,0,0,0,0,0,0,0,0,31,31,31,0,30
1,0,31,35,31,0,0,0,0,0,0,0,0,0,0,0,31,35,31,0,1
30,0,31,31,31,0,0,0,0,0,0,0,0,0,0,0,31,31,31,0,30
1,0,0,0,0,0,0,0,0,0,0,0,0,0,0,0,0,0,0,0,1
1,1,30,1,30,30,1,30,1,31,31,31,1,30,1,30,30,1,30,1,1
endlayer

layer
1,1,30,1,30,30,1,30,1,31,31,31,1,30,1,30,30,1,30,1,1
1,0,0,0,0,0,0,0,0,0,0,0,0,0,0,0,0,0,0,0,1
30,0,0,37,0,0,0,0,0,0,0,0,0,0,0,0,0,37,0,0,30
1,0,39,0,38,0,0,0,0,0,0,0,0,0,0,0,39,0,38,0,1
30,0,0,40,0,0,0,0,0,0,0,0,0,0,0,0,0,40,0,0,30
30,0,0,0,0,0,0,0,0,0,0,0,0,0,0,0,0,0,0,0,30
1,0,0,0,0,0,0,0,0,0,0,0,0,0,0,0,0,0,0,0,1
30,0,0,0,0,0,0,0,0,0,0,0,0,0,0,0,0,0,0,0,30
1,0,0,0,0,0,0,0,0,0,0,0,0,0,0,0,0,0,0,0,1
31,0,0,0,0,0,0,0,0,0,0,0,0,0,0,0,0,0,0,0,31
31,0,0,0,0,0,0,0,0,0,0,0,0,0,0,0,0,0,0,0,31
31,0,0,0,0,0,0,0,0,0,0,0,0,0,0,0,0,0,0,0,31
1,0,0,0,0,0,0,0,0,0,0,0,0,0,0,0,0,0,0,0,1
30,0,0,0,0,0,0,0,0,0,0,0,0,0,0,0,0,0,0,0,30
1,0,0,0,0,0,0,0,0,0,0,0,0,0,0,0,0,0,0,0,1
30,0,0,0,0,0,0,0,0,0,0,0,0,0,0,0,0,0,0,0,30
30,0,0,37,0,0,0,0,0,0,0,0,0,0,0,0,0,37,0,0,30
1,0,39,0,38,0,0,0,0,0,0,0,0,0,0,0,39,0,38,0,1
30,0,0,40,0,0,0,0,0,0,0,0,0,0,0,0,0,40,0,0,30
1,0,0,0,0,0,0,0,0,0,0,0,0,0,0,0,0,0,0,0,1
1,1,30,1,30,30,1,30,1,31,31,31,1,30,1,30,30,1,30,1,1
endlayer

layer
1,1,30,1,30,30,1,30,1,31,31,31,1,30,1,30,30,1,30,1,1
1,0,0,0,0,0,0,0,0,0,0,0,0,0,0,0,0,0,0,0,1
30,0,0,1,0,0,0,0,0,0,0,0,0,0,0,0,0,1,0,0,30
1,0,1,0,1,0,0,0,0,0,0,0,0,0,0,0,1,0,1,0,1
30,0,0,1,0,0,0,0,0,0,0,0,0,0,0,0,0,1,0,0,30
30,0,0,0,0,0,0,0,0,0,0,0,0,0,0,0,0,0,0,0,30
1,0,0,0,0,0,0,0,0,0,0,0,0,0,0,0,0,0,0,0,1
30,0,0,0,0,0,0,0,0,0,0,0,0,0,0,0,0,0,0,0,30
1,0,0,0,0,0,0,0,0,0,0,0,0,0,0,0,0,0,0,0,1
31,0,0,0,0,0,0,0,0,0,0,0,0,0,0,0,0,0,0,0,31
31,0,0,0,0,0,0,0,0,0,0,0,0,0,0,0,0,0,0,0,31
31,0,0,0,0,0,0,0,0,0,0,0,0,0,0,0,0,0,0,0,31
1,0,0,0,0,0,0,0,0,0,0,0,0,0,0,0,0,0,0,0,1
30,0,0,0,0,0,0,0,0,0,0,0,0,0,0,0,0,0,0,0,30
1,0,0,0,0,0,0,0,0,0,0,0,0,0,0,0,0,0,0,0,1
30,0,0,0,0,0,0,0,0,0,0,0,0,0,0,0,0,0,0,0,30
30,0,0,1,0,0,0,0,0,0,0,0,0,0,0,0,0,1,0,0,30
1,0,1,0,1,0,0,0,0,0,0,0,0,0,0,0,1,0,1,0,1
30,0,0,1,0,0,0,0,0,0,0,0,0,0,0,0,0,1,0,0,30
1,0,0,0,0,0,0,0,0,0,0,0,0,0,0,0,0,0,0,0,1
1,1,30,1,30,30,1,30,1,31,31,31,1,30,1,30,30,1,30,1,1
endlayer

layer
1,1,1,1,30,30,1,1,1,1,31,1,1,1,1,30,30,1,1,1,1
1,0,0,0,0,0,0,0,0,0,0,0,0,0,0,0,0,0,0,0,1
1,0,0,1,0,0,0,0,0,0,0,0,0,0,0,0,0,1,0,0,1
1,0,1,0,1,0,0,0,0,0,0,0,0,0,0,0,1,0,1,0,1
30,0,0,1,0,0,0,0,0,0,0,0,0,0,0,0,0,1,0,0,30
30,0,0,0,0,0,0,0,0,0,0,0,0,0,0,0,0,0,0,0,30
1,0,0,0,0,0,0,0,0,0,0,0,0,0,0,0,0,0,0,0,1
1,0,0,0,0,0,0,0,0,0,0,0,0,0,0,0,0,0,0,0,1
1,0,0,0,0,0,0,0,0,0,0,0,0,0,0,0,0,0,0,0,1
1,0,0,0,0,0,0,0,0,0,0,0,0,0,0,0,0,0,0,0,1
31,0,0,0,0,0,0,0,0,0,0,0,0,0,0,0,0,0,0,0,31
1,0,0,0,0,0,0,0,0,0,0,0,0,0,0,0,0,0,0,0,1
1,0,0,0,0,0,0,0,0,0,0,0,0,0,0,0,0,0,0,0,1
1,0,0,0,0,0,0,0,0,0,0,0,0,0,0,0,0,0,0,0,1
1,0,0,0,0,0,0,0,0,0,0,0,0,0,0,0,0,0,0,0,1
30,0,0,0,0,0,0,0,0,0,0,0,0,0,0,0,0,0,0,0,30
30,0,0,1,0,0,0,0,0,0,0,0,0,0,0,0,0,1,0,0,30
1,0,1,0,1,0,0,0,0,0,0,0,0,0,0,0,1,0,1,0,1
1,0,0,1,0,0,0,0,0,0,0,0,0,0,0,0,0,1,0,0,1
1,0,0,0,0,0,0,0,0,0,0,0,0,0,0,0,0,0,0,0,1
1,1,1,1,30,30,1,1,1,1,31,1,1,1,1,30,30,1,1,1,1
endlayer

layer
1,1,1,1,30,30,1,1,1,1,1,1,1,1,1,30,30,1,1,1,1
1,0,0,0,0,0,0,0,0,0,0,0,0,0,0,0,0,0,0,0,1
1,0,1,1,1,0,0,0,0,0,0,0,0,0,0,0,1,1,1,0,1
1,0,1,0,1,0,0,0,0,0,0,0,0,0,0,0,1,0,1,0,1
30,0,1,1,1,0,0,0,0,0,0,0,0,0,0,0,1,1,1,0,30
30,0,0,0,0,0,0,0,0,0,0,0,0,0,0,0,0,0,0,0,30
1,0,0,0,0,0,0,0,0,0,0,0,0,0,0,0,0,0,0,0,1
1,0,0,0,0,0,0,0,0,0,0,0,0,0,0,0,0,0,0,0,1
1,0,0,0,0,0,0,0,0,0,0,0,0,0,0,0,0,0,0,0,1
1,0,0,0,0,0,0,0,0,0,0,0,0,0,0,0,0,0,0,0,1
1,0,0,0,0,0,0,0,0,0,0,0,0,0,0,0,0,0,0,0,1
1,0,0,0,0,0,0,0,0,0,0,0,0,0,0,0,0,0,0,0,1
1,0,0,0,0,0,0,0,0,0,0,0,0,0,0,0,0,0,0,0,1
1,0,0,0,0,0,0,0,0,0,0,0,0,0,0,0,0,0,0,0,1
1,0,0,0,0,0,0,0,0,0,0,0,0,0,0,0,0,0,0,0,1
30,0,0,0,0,0,0,0,0,0,0,0,0,0,0,0,0,0,0,0,30
30,0,1,1,1,0,0,0,0,0,0,0,0,0,0,0,1,1,1,0,30
1,0,1,0,1,0,0,0,0,0,0,0,0,0,0,0,1,0,1,0,1
1,0,1,1,1,0,0,0,0,0,0,0,0,0,0,0,1,1,1,0,1
1,0,0,0,0,0,0,0,0,0,0,0,0,0,0,0,0,0,0,0,1
1,1,1,1,30,30,1,1,1,1,1,1,1,1,1,30,30,1,1,1,1
endlayer

layer
1,1,1,1,1,1,1,1,1,1,1,1,1,1,1,1,1,1,1,1,1
1,0,0,0,0,0,0,0,0,0,0,0,0,0,0,0,0,0,0,0,1
1,0,1,1,1,0,0,0,0,0,0,0,0,0,0,0,1,1,1,0,1
1,0,1,41,1,0,0,0,0,0,0,0,0,0,0,0,1,41,1,0,1
1,0,1,1,1,0,0,0,0,0,0,0,0,0,0,0,1,1,1,0,1
1,0,0,0,0,0,0,0,0,0,0,0,0,0,0,0,0,0,0,0,1
1,0,0,0,0,0,0,0,0,0,0,0,0,0,0,0,0,0,0,0,1
1,0,0,0,0,0,0,0,0,0,0,0,0,0,0,0,0,0,0,0,1
1,0,0,0,0,0,0,0,0,0,0,0,0,0,0,0,0,0,0,0,1
1,0,0,0,0,0,0,0,0,0,0,0,0,0,0,0,0,0,0,0,1
1,0,0,0,0,0,0,0,0,0,0,0,0,0,0,0,0,0,0,0,1
1,0,0,0,0,0,0,0,0,0,0,0,0,0,0,0,0,0,0,0,1
1,0,0,0,0,0,0,0,0,0,0,0,0,0,0,0,0,0,0,0,1
1,0,0,0,0,0,0,0,0,0,0,0,0,0,0,0,0,0,0,0,1
1,0,0,0,0,0,0,0,0,0,0,0,0,0,0,0,0,0,0,0,1
1,0,0,0,0,0,0,0,0,0,0,0,0,0,0,0,0,0,0,0,1
1,0,1,1,1,0,0,0,0,0,0,0,0,0,0,0,1,1,1,0,1
1,0,1,41,1,0,0,0,0,0,0,0,0,0,0,0,1,41,1,0,1
1,0,1,1,1,0,0,0,0,0,0,0,0,0,0,0,1,1,1,0,1
1,0,0,0,0,0,0,0,0,0,0,0,0,0,0,0,0,0,0,0,1
1,1,1,1,1,1,1,1,1,1,1,1,1,1,1,1,1,1,1,1,1
endlayer

layer
2,2,2,2,2,2,2,2,2,2,2,2,2,2,2,2,2,2,2,2,2
2,42,42,42,42,42,42,42,42,42,42,42,42,42,42,42,42,42,42,42,2
2,42,42,42,42,42,42,42,43,43,43,43,43,42,42,42,42,42,42,42,2
2,42,42,44,42,42,42,43,0,0,0,0,0,43,42,42,42,44,42,42,2
2,42,42,42,42,42,0,0,0,0,0,0,0,0,0,42,42,42,42,42,2
2,42,42,42,42,42,0,0,0,0,0,0,0,0,0,42,42,42,42,42,2
2,42,42,42,0,0,0,0,0,0,0,0,0,0,0,0,0,42,42,42,2
2,42,42,43,0,0,0,0,0,0,0,0,0,0,0,0,0,43,42,42,2
2,42,43,0,0,0,0,0,0,0,0,0,0,0,0,0,0,0,43,42,2
2,42,43,0,0,0,0,0,0,0,0,0,0,0,0,0,0,0,43,42,2
2,42,43,0,0,0,0,0,0,0,0,0,0,0,0,0,0,0,43,42,2
2,42,43,0,0,0,0,0,0,0,0,0,0,0,0,0,0,0,43,42,2
2,42,43,0,0,0,0,0,0,0,0,0,0,0,0,0,0,0,43,42,2
2,42,42,43,0,0,0,0,0,0,0,0,0,0,0,0,0,43,42,42,2
2,42,42,42,0,0,0,0,0,0,0,0,0,0,0,0,0,42,42,42,2
2,42,42,42,42,42,0,0,0,0,0,0,0,0,0,42,42,42,42,42,2
2,42,42,42,42,42,0,0,0,0,0,0,0,0,0,42,42,42,42,42,2
2,42,42,44,42,42,42,43,0,0,0,0,0,43,42,42,42,44,42,42,2
2,42,42,42,42,42,42,42,43,43,43,43,43,42,42,42,42,42,42,42,2
2,42,42,42,42,42,42,42,42,42,42,42,42,42,42,42,42,42,42,42,2
2,2,2,2,2,2,2,2,2,2,2,2,2,2,2,2,2,2,2,2,2
endlayer

layer
2,2,2,2,2,2,2,2,2,2,2,2,2,2,2,2,2,2,2,2,2
0,0,0,0,0,0,0,0,0,0,0,0,0,0,0,0,0,0,0,2,2
0,0,42,42,42,42,42,42,42,42,42,42,42,42,42,42,42,42,42,2,2
0,0,42,42,42,42,42,42,43,43,43,43,43,42,42,42,42,42,42,2,2
0,0,42,42,42,42,43,43,0,0,0,0,0,43,43,42,42,42,42,2,2
0,0,42,42,42,42,0,0,0,0,0,0,0,0,0,42,42,42,42,2,2
0,0,42,42,43,0,0,0,0,0,0,0,0,0,0,0,43,42,42,2,2
0,0,42,42,43,0,0,0,0,0,0,0,0,0,0,0,43,42,42,2,2
0,0,42,43,0,0,0,0,0,0,0,0,0,0,0,0,0,43,42,2,2
0,0,42,43,0,0,0,0,0,0,44,0,0,0,0,0,0,43,42,2,2
0,0,42,43,0,0,0,0,0,46,42,45,0,0,0,0,0,43,42,2,2
0,0,42,43,0,0,0,0,0,0,47,0,0,0,0,0,0,43,42,2,2
0,0,42,43,0,0,0,0,0,0,0,0,0,0,0,0,0,43,42,2,2
0,0,42,42,43,0,0,0,0,0,0,0,0,0,0,0,43,42,42,2,2
0,0,42,42,43,0,0,0,0,0,0,0,0,0,0,0,43,42,42,2,2
0,0,42,42,42,42,0,0,0,0,0,0,0,0,0,42,42,42,42,2,2
0,0,42,42,42,42,43,43,0,0,0,0,0,43,43,42,42,42,42,2,2
0,0,42,42,42,42,42,42,43,43,43,43,43,42,42,42,42,42,42,2,2
2,2,42,42,42,42,42,42,42,42,42,42,42,42,42,42,42,42,42,2,2
2,2,2,2,2,2,2,2,2,2,2,2,2,2,2,2,2,2,2,2,2
2,2,2,2,2,2,2,2,2,2,2,2,2,2,2,2,2,2,2,2,2
endlayer

layer
2,2,2,2,2,2,2,2,2,2,2,2,2,2,2,2,2,2,2,2,2
2,2,2,2,2,2,2,2,2,2,2,2,2,2,2,2,2,2,2,2,2
2,2,2,2,2,2,2,2,2,2,2,2,2,2,2,2,2,2,2,2,2
2,2,2,42,42,42,42,42,42,42,42,42,42,42,42,42,42,42,2,2,2
2,2,2,42,42,42,42,42,43,43,43,43,43,42,42,42,42,42,2,2,2
2,2,2,42,42,42,43,43,0,0,0,0,0,43,43,42,42,42,2,2,2
2,2,2,42,42,43,0,0,0,0,0,0,0,0,0,43,42,42,2,2,2
2,2,2,42,42,43,0,0,0,0,0,0,0,0,0,43,42,42,2,2,2
2,2,2,42,43,0,0,0,0,0,0,0,0,0,0,0,43,42,2,2,2
2,2,2,42,43,0,0,0,0,0,0,0,0,0,0,0,43,42,2,2,2
2,2,2,42,43,0,0,0,0,0,31,0,0,0,0,0,43,42,2,2,2
2,2,2,42,43,0,0,0,0,0,0,0,0,0,0,0,43,42,2,2,2
2,2,2,42,43,0,0,0,0,0,0,0,0,0,0,0,43,42,2,2,2
2,2,2,42,42,43,0,0,0,0,0,0,0,0,0,43,42,42,2,2,2
2,2,2,42,42,43,0,0,0,0,0,0,0,0,0,43,42,42,2,2,2
2,2,2,42,42,42,43,43,0,0,0,0,0,43,43,42,42,42,2,2,2
2,2,2,42,42,42,42,42,43,43,43,43,43,42,42,42,42,42,2,2,2
2,2,2,42,42,42,42,42,42,42,42,42,42,42,42,42,42,42,2,2,2
2,2,2,2,2,2,2,2,2,2,2,2,2,2,2,2,2,2,2,2,2
2,2,2,2,2,2,2,2,2,2,2,2,2,2,2,2,2,2,2,2,2
2,2,2,2,2,2,2,2,2,2,2,2,2,2,2,2,2,2,2,2,2
endlayer

layer
2,2,2,2,2,2,2,2,2,2,2,2,2,2,2,2,2,2,2,2,2
2,2,2,2,2,2,2,2,2,2,2,2,2,2,2,2,2,2,2,2,2
2,2,2,2,2,2,2,2,2,2,2,2,2,2,2,2,2,2,2,2,2
2,2,2,2,2,2,2,2,2,2,2,2,2,2,2,2,2,2,2,2,2
2,2,2,2,2,2,2,2,42,42,42,42,42,2,2,2,2,2,2,2,2
2,2,2,2,2,2,42,42,0,0,0,0,0,42,42,2,2,2,2,2,2
2,2,2,2,2,42,0,0,0,0,0,0,0,0,0,42,2,2,2,2,2
2,2,2,2,2,42,0,0,0,0,0,0,0,0,0,42,2,2,2,2,2
2,2,2,2,42,0,0,0,0,0,0,0,0,0,0,0,42,2,2,2,2
2,2,2,2,42,0,0,0,0,0,44,0,0,0,0,0,42,2,2,2,2
2,2,2,2,42,0,0,0,0,46,42,45,0,0,0,0,42,2,2,2,2
2,2,2,2,42,0,0,0,0,0,47,0,0,0,0,0,42,2,2,2,2
2,2,2,2,42,0,0,0,0,0,0,0,0,0,0,0,42,2,2,2,2
2,2,2,2,2,42,0,0,0,0,0,0,0,0,0,42,2,2,2,2,2
2,2,2,2,2,42,0,0,0,0,0,0,0,0,0,42,2,2,2,2,2
2,2,2,2,2,2,42,42,0,0,0,0,0,42,42,2,2,2,2,2,2
2,2,2,2,2,2,2,2,42,42,42,42,42,2,2,2,2,2,2,2,2
2,2,2,2,2,2,2,2,2,2,2,2,2,2,2,2,2,2,2,2,2
2,2,2,2,2,2,2,2,2,2,2,2,2,2,2,2,2,2,2,2,2
2,2,2,2,2,2,2,2,2,2,2,2,2,2,2,2,2,2,2,2,2
2,2,2,2,2,2,2,2,2,2,2,2,2,2,2,2,2,2,2,2,2
endlayer

layer
2,2,2,2,2,2,2,2,2,2,2,2,2,2,2,2,2,2,2,2,2
2,2,2,2,2,2,2,2,2,2,2,2,2,2,2,2,2,2,2,2,2
2,2,2,2,2,2,2,2,2,2,2,2,2,2,2,2,2,2,2,2,2
2,2,2,2,2,2,2,2,2,2,2,2,2,2,2,2,2,2,2,2,2
2,2,2,2,2,2,2,2,2,42,42,42,2,2,2,2,2,2,2,2,2
2,2,2,2,2,2,42,42,42,0,0,0,42,42,42,2,2,2,2,2,2
2,2,2,2,2,42,0,0,0,0,0,0,0,0,0,42,2,2,2,2,2
2,2,2,2,2,42,0,0,0,0,44,0,0,0,0,42,2,2,2,2,2
2,2,2,2,2,42,0,0,0,46,42,45,0,0,0,42,2,2,2,2,2
2,2,2,2,42,0,0,0,44,0,31,0,44,0,0,0,42,2,2,2,2
2,2,2,2,42,0,0,46,42,31,31,31,42,45,0,0,42,2,2,2,2
2,2,2,2,42,0,0,0,47,0,31,0,47,0,0,0,42,2,2,2,2
2,2,2,2,2,42,0,0,0,46,42,45,0,0,0,42,2,2,2,2,2
2,2,2,2,2,42,0,0,0,0,47,0,0,0,0,42,2,2,2,2,2
2,2,2,2,2,42,0,0,0,0,0,0,0,0,0,42,2,2,2,2,2
2,2,2,2,2,2,42,42,42,0,0,0,42,42,42,2,2,2,2,2,2
2,2,2,2,2,2,2,2,2,42,42,42,2,2,2,2,2,2,2,2,2
2,2,2,2,2,2,2,2,2,2,2,2,2,2,2,2,2,2,2,2,2
2,2,2,2,2,2,2,2,2,2,2,2,2,2,2,2,2,2,2,2,2
2,2,2,2,2,2,2,2,2,2,2,2,2,2,2,2,2,2,2,2,2
2,2,2,2,2,2,2,2,2,2,2,2,2,2,2,2,2,2,2,2,2
endlayer

layer
2,2,2,2,2,2,2,2,2,2,2,2,2,2,2,2,2,2,2,2,2
2,2,2,2,2,2,2,2,2,2,2,2,2,2,2,2,2,2,2,2,2
2,2,2,2,2,2,2,2,2,2,2,2,2,2,2,2,2,2,2,2,2
2,2,2,2,2,2,2,2,2,2,2,2,2,2,2,2,2,2,2,2,2
2,2,2,2,2,2,2,2,2,2,42,2,2,2,2,2,2,2,2,2,2
2,2,2,2,2,2,2,2,42,42,0,42,42,2,2,2,2,2,2,2,2
2,2,2,2,2,2,42,42,0,0,0,0,0,42,42,2,2,2,2,2,2
2,2,2,2,2,2,42,0,0,0,0,0,0,0,42,2,2,2,2,2,2
2,2,2,2,2,42,0,0,0,0,48,0,0,0,0,42,2,2,2,2,2
2,2,2,2,2,42,0,0,0,0,0,0,0,0,0,42,2,2,2,2,2
2,2,2,2,42,0,0,0,48,0,31,0,48,0,0,0,42,2,2,2,2
2,2,2,2,2,42,0,0,0,0,0,0,0,0,0,42,2,2,2,2,2
2,2,2,2,2,42,0,0,0,0,48,0,0,0,0,42,2,2,2,2,2
2,2,2,2,2,2,42,0,0,0,0,0,0,0,42,2,2,2,2,2,2
2,2,2,2,2,2,42,42,0,0,0,0,0,42,42,2,2,2,2,2,2
2,2,2,2,2,2,2,2,42,42,0,42,42,2,2,2,2,2,2,2,2
2,2,2,2,2,2,2,2,2,2,42,2,2,2,2,2,2,2,2,2,2
2,2,2,2,2,2,2,2,2,2,2,2,2,2,2,2,2,2,2,2,2
2,2,2,2,2,2,2,2,2,2,2,2,2,2,2,2,2,2,2,2,2
2,2,2,2,2,2,2,2,2,2,2,2,2,2,2,2,2,2,2,2,2
2,2,2,2,2,2,2,2,2,2,2,2,2,2,2,2,2,2,2,2,2
endlayer

layer
2,2,2,2,2,2,2,2,2,2,2,2,2,2,2,2,2,2,2,2,2
2,2,2,2,2,2,2,2,2,2,2,2,2,2,2,2,2,2,2,2,2
2,2,2,2,2,2,2,2,2,2,2,2,2,2,2,2,2,2,2,2,2
2,2,2,2,2,2,2,2,2,2,2,2,2,2,2,2,2,2,2,2,2
2,2,2,2,2,2,2,2,2,2,2,2,2,2,2,2,2,2,2,2,2
2,2,2,2,2,2,2,2,42,42,42,42,42,2,2,2,2,2,2,2,2
2,2,2,2,2,2,2,42,0,0,0,0,0,42,2,2,2,2,2,2,2
2,2,2,2,2,2,42,0,0,0,0,0,0,0,42,2,2,2,2,2,2
2,2,2,2,2,42,0,0,0,0,31,0,0,0,0,42,2,2,2,2,2
2,2,2,2,2,42,0,0,0,0,31,0,0,0,0,42,2,2,2,2,2
2,2,2,2,2,42,0,0,31,31,31,31,31,0,0,42,2,2,2,2,2
2,2,2,2,2,42,0,0,0,0,31,0,0,0,0,42,2,2,2,2,2
2,2,2,2,2,42,0,0,0,0,31,0,0,0,0,42,2,2,2,2,2
2,2,2,2,2,2,42,0,0,0,0,0,0,0,42,2,2,2,2,2,2
2,2,2,2,2,2,2,42,0,0,0,0,0,42,2,2,2,2,2,2,2
2,2,2,2,2,2,2,2,42,42,42,42,42,2,2,2,2,2,2,2,2
2,2,2,2,2,2,2,2,2,2,2,2,2,2,2,2,2,2,2,2,2
2,2,2,2,2,2,2,2,2,2,2,2,2,2,2,2,2,2,2,2,2
2,2,2,2,2,2,2,2,2,2,2,2,2,2,2,2,2,2,2,2,2
2,2,2,2,2,2,2,2,2,2,2,2,2,2,2,2,2,2,2,2,2
2,2,2,2,2,2,2,2,2,2,2,2,2,2,2,2,2,2,2,2,2
endlayer

layer
2,2,2,2,2,2,2,2,2,2,2,2,2,2,2,2,2,2,2,2,2
2,2,2,2,2,2,2,2,2,2,2,2,2,2,2,2,2,2,2,2,2
2,2,2,2,2,2,2,2,2,2,2,2,2,2,2,2,2,2,2,2,2
2,2,2,2,2,2,2,2,2,2,2,2,2,2,2,2,2,2,2,2,2
2,2,2,2,2,2,2,2,2,2,2,2,2,2,2,2,2,2,2,2,2
2,2,2,2,2,2,2,2,2,42,42,42,2,2,2,2,2,2,2,2,2
2,2,2,2,2,2,2,2,42,0,0,0,42,2,2,2,2,2,2,2,2
2,2,2,2,2,2,2,42,0,0,0,0,0,42,2,2,2,2,2,2,2
2,2,2,2,2,2,42,0,0,0,0,0,0,0,42,2,2,2,2,2,2
2,2,2,2,2,42,0,0,0,0,0,0,0,0,0,42,2,2,2,2,2
2,2,2,2,2,42,0,0,0,0,31,0,0,0,0,42,2,2,2,2,2
2,2,2,2,2,42,0,0,0,0,0,0,0,0,0,42,2,2,2,2,2
2,2,2,2,2,2,42,0,0,0,0,0,0,0,42,2,2,2,2,2,2
2,2,2,2,2,2,2,42,0,0,0,0,0,42,2,2,2,2,2,2,2
2,2,2,2,2,2,2,2,42,0,0,0,42,2,2,2,2,2,2,2,2
2,2,2,2,2,2,2,2,2,42,42,42,2,2,2,2,2,2,2,2,2
2,2,2,2,2,2,2,2,2,2,2,2,2,2,2,2,2,2,2,2,2
2,2,2,2,2,2,2,2,2,2,2,2,2,2,2,2,2,2,2,2,2
2,2,2,2,2,2,2,2,2,2,2,2,2,2,2,2,2,2,2,2,2
2,2,2,2,2,2,2,2,2,2,2,2,2,2,2,2,2,2,2,2,2
2,2,2,2,2,2,2,2,2,2,2,2,2,2,2,2,2,2,2,2,2
endlayer

layer
2,2,2,2,2,2,2,2,2,2,2,2,2,2,2,2,2,2,2,2,2
2,2,2,2,2,2,2,2,2,2,2,2,2,2,2,2,2,2,2,2,2
2,2,2,2,2,2,2,2,2,2,2,2,2,2,2,2,2,2,2,2,2
2,2,2,2,2,2,2,2,2,2,2,2,2,2,2,2,2,2,2,2,2
2,2,2,2,2,2,2,2,2,2,2,2,2,2,2,2,2,2,2,2,2
2,2,2,2,2,2,2,2,2,2,2,2,2,2,2,2,2,2,2,2,2
2,2,2,2,2,2,2,2,2,42,42,42,2,2,2,2,2,2,2,2,2
2,2,2,2,2,2,2,2,42,42,42,42,42,2,2,2,2,2,2,2,2
2,2,2,2,2,2,2,42,42,0,0,0,42,42,2,2,2,2,2,2,2
2,2,2,2,2,2,42,42,0,0,0,0,0,42,42,2,2,2,2,2,2
2,2,2,2,2,2,42,42,0,0,31,0,0,42,42,2,2,2,2,2,2
2,2,2,2,2,2,42,42,0,0,0,0,0,42,42,2,2,2,2,2,2
2,2,2,2,2,2,2,42,42,0,0,0,42,42,2,2,2,2,2,2,2
2,2,2,2,2,2,2,2,42,42,42,42,42,2,2,2,2,2,2,2,2
2,2,2,2,2,2,2,2,2,42,42,42,2,2,2,2,2,2,2,2,2
2,2,2,2,2,2,2,2,2,2,2,2,2,2,2,2,2,2,2,2,2
2,2,2,2,2,2,2,2,2,2,2,2,2,2,2,2,2,2,2,2,2
2,2,2,2,2,2,2,2,2,2,2,2,2,2,2,2,2,2,2,2,2
2,2,2,2,2,2,2,2,2,2,2,2,2,2,2,2,2,2,2,2,2
2,2,2,2,2,2,2,2,2,2,2,2,2,2,2,2,2,2,2,2,2
2,2,2,2,2,2,2,2,2,2,2,2,2,2,2,2,2,2,2,2,2
endlayer

layer
2,2,2,2,2,2,2,2,2,2,2,2,2,2,2,2,2,2,2,2,2
2,2,2,2,2,2,2,2,2,2,2,2,2,2,2,2,2,2,2,2,2
2,2,2,2,2,2,2,2,2,2,2,2,2,2,2,2,2,2,2,2,2
2,2,2,2,2,2,2,2,2,2,2,2,2,2,2,2,2,2,2,2,2
2,2,2,2,2,2,2,2,2,2,2,2,2,2,2,2,2,2,2,2,2
2,2,2,2,2,2,2,2,2,2,2,2,2,2,2,2,2,2,2,2,2
2,2,2,2,2,2,2,2,2,2,2,2,2,2,2,2,2,2,2,2,2
2,2,2,2,2,2,2,2,2,2,2,2,2,2,2,2,2,2,2,2,2
2,2,2,2,2,2,2,2,2,42,42,42,2,2,2,2,2,2,2,2,2
2,2,2,2,2,2,2,2,42,42,42,42,42,2,2,2,2,2,2,2,2
2,2,2,2,2,2,2,2,42,42,42,42,42,2,2,2,2,2,2,2,2
2,2,2,2,2,2,2,2,42,42,42,42,42,2,2,2,2,2,2,2,2
2,2,2,2,2,2,2,2,2,42,42,42,2,2,2,2,2,2,2,2,2
2,2,2,2,2,2,2,2,2,2,2,2,2,2,2,2,2,2,2,2,2
2,2,2,2,2,2,2,2,2,2,2,2,2,2,2,2,2,2,2,2,2
2,2,2,2,2,2,2,2,2,2,2,2,2,2,2,2,2,2,2,2,2
2,2,2,2,2,2,2,2,2,2,2,2,2,2,2,2,2,2,2,2,2
2,2,2,2,2,2,2,2,2,2,2,2,2,2,2,2,2,2,2,2,2
2,2,2,2,2,2,2,2,2,2,2,2,2,2,2,2,2,2,2,2,2
2,2,2,2,2,2,2,2,2,2,2,2,2,2,2,2,2,2,2,2,2
2,2,2,2,2,2,2,2,2,2,2,2,2,2,2,2,2,2,2,2,2
endlayer


