# VillageMiniPlains (18 Mar 2014 for MC v. 1.7.2)

# Created by Ruins mod version 12.3 Ingame Parser
# authoring Player: Jordan_Greywolf

# Updated for MC 1.7.10, 16 Oct 2014
# Updated to MC 1.8: 5 Mar 2016
# Updated to MC 1.9: 16 Apr 2016
# Updated to MC 1.10: 13 Sep 2016
# Updated to MC 1.11: 13 Jan 2017
# Verified for MC 1.12: 23 Jun 2017
# Updated to MC 1.12.1: 10 Sep 2017

# Last Updated: 9 Jun 2018


biomesToSpawnIn=brushland,extreme hills,extreme_hills,extreme hills edge,extreme hills m,extreme hills+,extreme hills+ m,field,flower field,flower_field,garden,grassland,grove,heathland,lavender fields,lavender_fields,meadow,mutated_extreme_hills,mutated_plains,mystic grove,mystic_grove,oak savannah,oak_savannah,origin valley,origin_valley,pasture,plains,prairie,rwg_plains,sacred springs,sacred_springs,scrubland,shield,shrubland,silkglades,smaller_extreme_hills,steppe,sunflower plains,silkglades,twilight clearing,twilight_clearing

uniqueMinDistance=2000


weight=1
embed_into_distance=6
acceptable_target_blocks=

unacceptable_target_blocks=flowing_lava,lava,cloud,Natura:Cloud,slime_congealed,slime_dirt,slime_grass,command_block,planks,planks2,concrete,cobblestone,stonebrick,brick_block,glass,torch,oak_stairs,stone_stairs,brick_stairs,stone_brick_stairs,nether_brick_stairs,sandstone_stairs,spruce_stairs,birch_stairs,jungle_stairs,quartz_stairs,acacia_stairs,dark_oak_stairs,cobblestone_wall,stone_slab,double_stone_slab,stone_slab2,wooden_slab,double_wooden_slab,nether_brick,fence

dimensions=16,18,19
allowable_overhang=9999
max_leveling=6
leveling_buffer=-1
preserve_water=0
preserve_lava=0
preserve_plants=1

# Stonebrick Walls
rule1=0,100,minecraft:stonebrick-0,minecraft:stonebrick-0,minecraft:stonebrick-1,minecraft:stonebrick-2

rule2=0,100,minecraft:oak_stairs-1

# Mossy Cobblestone Pavement
rule3=0,100,minecraft:mossy_cobblestone-0

# Stone Slab (used as flooring in "dungeon" so monsters won't normally
# spawn except from Monster Spawners).
rule4=0,100,minecraft:stone_slab-0

rule5=0,100,minecraft:stone_brick_stairs-1
rule6=0,100,minecraft:oak_stairs-3
rule7=0,100,minecraft:oak_stairs-2
rule8=0,100,minecraft:stone_brick_stairs-0
rule9=0,100,minecraft:crafting_table-0
rule10=0,100,minecraft:planks-0
rule11=0,100,minecraft:stonebrick-3
rule12=2,100,minecraft:ladder-5
rule13=2,100,minecraft:ladder-4
rule14=0,100,minecraft:spruce_fence-0
rule15=0,100,ChestGenHook:chests/simple_dungeon:5-3
rule16=0,100,minecraft:iron_bars-0
rule17=0,100,minecraft:web-0
rule18=1,100,minecraft:bed-10
rule19=1,100,minecraft:bed-2
rule20=1,100,minecraft:bed-0
rule21=1,100,minecraft:bed-8
rule22=0,100,minecraft:cobblestone-0
rule23=0,100,minecraft:water-0
rule24=0,100,minecraft:bookshelf-0
rule25=0,100,MobSpawner:Cave_Spider,MobSpawner:Spider
rule26=1,100,minecraft:bed-3
rule27=0,100,minecraft:spruce_stairs-3
rule28=1,100,minecraft:bed-11
rule29=1,100,minecraft:torch-5
rule30=0,100,minecraft:carpet-15

# Random Decorative Item
rule32=0,100,minecraft:flower_pot-0,minecraft:cake-0,minecraft:lit_pumpkin,minecraft:melon_block,teBlock;minecraft:flower_pot;{Item:"minecraft:red_flower",x:0,y:0,z:0,Data:0,id:"flower_pot"}-0

rule32=0,100,minecraft:stone_slab-8
rule33=0,100,minecraft:planks-1
rule34=0,100,minecraft:brick_block-0
rule35=0,100,minecraft:nether_brick-0
rule36=0,100,minecraft:grass-0

# Randomized farmland/dirt (as these villagers clearly are too busy
# fortifying vs. monsters to farm properly)
rule37=0,100,minecraft:farmland-7,minecraft:farmland-4,minecraft:farmland-1,minecraft:dirt-0

rule38=0,100,minecraft:log-1
rule39=0,100,minecraft:log-2
rule40=0,100,minecraft:planks-2
rule41=0,100,minecraft:nether_brick_fence-0
rule42=0,100,minecraft:spruce_stairs-2
rule43=0,100,IInventory;minecraft:lit_furnace;minecraft:coal#6#1#1-2
rule44=2,100,minecraft:trapdoor-1
rule45=1,100,minecraft:spruce_door-2
rule46=0,100,minecraft:spruce_stairs-0
rule47=0,100,CommandBlock:RUINSTRIGGER /summon villager ~0 ~0 ~0:@
rule48=1,100,minecraft:double_plant-4
rule49=1,100,minecraft:spruce_door-1

# Crops with randomized growth
rule50=0,100,minecraft:potatoes-7,minecraft:potatoes-4,minecraft:potatoes-1
rule51=0,100,minecraft:wheat-7,minecraft:wheat-4,minecraft:wheat-1

rule52=1,100,minecraft:spruce_door-0
rule53=0,100,minecraft:spruce_fence_gate-2
rule54=1,100,minecraft:spruce_door-3

# Crops with randomized growth
rule55=0,100,minecraft:carrots-7,minecraft:carrots-4,minecraft:carrots-1

# Randomized plants in mini-yards
rule57=0,100,minecraft:red_flower-0,minecraft:red_flower-1,minecraft:red_flower-2,minecraft:tallgrass-2

rule57=1,100,minecraft:spruce_door-5
rule58=0,100,minecraft:cobblestone_wall-0
rule59=0,100,minecraft:carpet-14
rule60=1,100,minecraft:spruce_door-8
rule61=0,100,minecraft:glass_pane-0
rule62=1,100,minecraft:spruce_door-9
rule63=0,100,minecraft:double_plant-11
rule64=0,100,minecraft:double_plant-10
rule65=0,100,minecraft:stone_brick_stairs-4
rule66=0,100,minecraft:stone_brick_stairs-5
rule67=0,100,minecraft:double_plant-8
rule68=0,100,minecraft:double_plant-9
rule69=0,100,minecraft:spruce_stairs-4
rule70=0,100,minecraft:oak_stairs-0
rule71=0,100,minecraft:log-4
rule72=0,100,minecraft:log-8
rule73=0,100,minecraft:oak_stairs-5
rule74=0,100,minecraft:oak_stairs-4
rule75=0,100,minecraft:log-9
rule76=0,100,minecraft:log-5
rule77=0,100,minecraft:spruce_stairs-1
rule78=0,100,minecraft:nether_brick_stairs-2
rule79=0,100,minecraft:nether_brick_stairs-3
rule80=0,100,minecraft:log-0
rule81=0,100,minecraft:birch_stairs-2
rule82=0,100,minecraft:oak_stairs-7
rule83=0,100,minecraft:oak_stairs-6
rule84=0,100,minecraft:birch_stairs-3
rule85=0,100,minecraft:jungle_stairs-0
rule86=0,100,minecraft:jungle_stairs-1
rule87=0,100,minecraft:wooden_slab-0
rule88=0,100,minecraft:planks-3
rule89=0,100,minecraft:jungle_stairs-3
rule90=0,100,minecraft:wooden_slab-2
rule91=0,100,minecraft:birch_stairs-0
rule92=0,100,minecraft:wooden_slab-1
rule93=0,100,minecraft:nether_brick_stairs-1
rule94=0,100,minecraft:nether_brick_stairs-0

rule95=0,100,CommandBlock:RUINSTRIGGER /gamerule commandBlockOutput false:@

rule96=0,100,IInventory;minecraft:chest;minecraft:torch#8#0#1+minecraft:bread#6#0#4+minecraft:apple#8#0#6+minecraft:egg#9#0#8-3

layer
1,1,1,1,1,1,1,1,1,1,1,1,1,1,1,1,1,1,1
1,3,3,3,3,3,3,3,3,3,3,3,3,3,3,3,3,3,1
1,3,3,3,3,3,3,3,3,3,3,3,3,3,3,3,3,3,1
1,3,3,3,3,3,3,3,3,3,3,3,3,3,3,3,3,3,1
1,3,3,3,3,3,3,3,3,3,3,3,3,3,3,3,3,3,1
1,3,3,3,3,3,3,3,3,3,3,3,3,3,3,3,3,3,1
1,3,3,3,3,3,3,3,3,3,3,3,3,3,3,3,3,3,1
1,3,3,3,3,3,3,3,3,3,3,3,3,3,3,3,3,3,1
1,3,3,3,3,3,3,3,3,3,3,3,3,3,3,3,3,3,1
1,3,3,3,3,3,3,3,3,3,3,3,3,3,3,3,3,3,1
1,3,3,3,3,3,3,3,3,3,3,3,3,3,3,3,3,3,1
1,3,3,3,3,3,3,3,3,3,3,3,3,3,3,3,3,3,1
1,3,3,3,3,3,3,3,3,3,3,3,3,3,3,3,3,3,1
1,3,3,3,3,3,3,3,3,3,3,3,3,3,3,3,3,3,1
1,3,3,3,3,3,3,3,3,3,3,3,3,3,3,3,3,3,1
1,3,3,3,3,3,3,3,3,3,3,3,3,3,3,3,3,3,1
1,3,3,3,3,3,3,3,3,3,3,3,3,3,3,3,3,3,1
1,1,1,1,1,1,1,1,1,1,1,1,1,1,1,1,1,1,1
endlayer

layer
1,1,1,1,1,1,1,1,1,1,1,1,1,1,1,1,1,1,1
1,3,3,3,3,3,3,3,3,3,3,3,3,3,3,3,3,3,1
1,3,3,3,3,3,3,3,3,3,3,3,3,3,3,3,3,3,1
1,3,3,3,3,3,3,3,3,3,3,3,3,3,3,3,3,3,1
1,3,3,3,3,3,3,3,3,3,3,3,3,3,3,3,3,3,1
1,3,3,3,3,3,3,3,3,3,3,3,3,3,3,3,3,3,1
1,3,3,3,3,3,3,3,3,3,3,3,3,3,3,3,3,3,1
1,3,3,3,3,3,3,3,3,3,3,3,3,3,3,3,3,3,1
1,3,3,3,3,3,3,3,3,3,3,3,3,3,3,3,3,3,1
1,3,3,3,3,3,3,3,3,3,3,3,3,3,3,3,3,3,1
1,3,3,3,3,3,3,3,3,3,3,3,3,3,3,3,3,3,1
1,3,3,3,3,3,3,3,3,3,3,3,3,3,3,3,3,3,1
1,3,3,3,3,3,3,3,3,3,3,3,3,3,3,3,3,3,1
1,3,3,3,3,3,3,3,3,3,3,3,3,3,3,3,3,3,1
1,3,3,3,3,3,3,3,3,3,3,3,3,3,3,3,3,3,1
1,3,3,3,3,3,3,3,3,3,3,3,3,3,3,3,3,3,1
1,3,3,3,3,3,3,3,3,3,3,3,3,3,3,3,3,3,1
1,1,1,1,1,1,1,1,1,1,1,1,1,1,1,1,1,1,1
endlayer



layer
1,1,1,1,1,1,1,1,1,1,1,1,1,1,1,1,1,1,1
1,4,5,4,4,1,3,3,3,1,2,2,2,2,2,2,2,2,1
1,4,4,4,4,1,3,3,3,1,7,4,4,4,4,4,4,6,1
1,4,4,4,4,1,3,3,3,1,7,4,4,1,4,8,4,6,1
1,4,4,4,4,4,1,1,1,1,1,1,1,1,1,1,1,1,1
1,1,1,1,1,4,4,4,4,4,4,4,4,4,4,4,1,4,1
1,3,3,3,1,1,4,1,1,1,1,1,9,4,4,4,1,4,1
1,3,3,3,1,4,4,4,1,3,3,1,1,1,4,4,1,1,1
1,3,3,3,1,4,4,4,1,3,3,3,1,1,4,4,1,4,1
1,1,1,1,1,4,4,4,1,3,3,1,4,1,4,4,1,4,1
1,4,4,2,1,4,4,4,1,3,3,1,4,1,4,4,1,1,1
1,4,4,4,1,1,4,1,1,1,1,1,1,1,4,4,1,4,1
1,4,4,4,1,4,4,4,4,4,4,4,4,4,4,4,1,4,1
1,4,10,10,1,4,4,4,1,1,1,1,1,1,1,1,1,1,1
1,4,1,1,1,1,1,1,1,2,2,2,1,3,3,3,3,3,1
1,4,1,3,3,3,3,3,1,7,4,4,1,3,3,3,3,3,1
1,11,1,3,3,3,3,3,1,7,4,8,1,3,3,3,3,3,1
1,1,1,1,1,1,1,1,1,1,1,1,1,1,1,1,1,1,1
endlayer

layer
1,1,1,1,1,1,1,1,1,1,1,1,1,1,1,1,1,1,1
1,0,12,0,0,1,7,2,2,1,2,2,2,2,2,2,2,2,1
1,0,0,0,0,1,7,0,13,1,7,0,0,0,0,0,95,6,1
1,0,0,0,0,1,1,14,1,1,7,0,0,9,0,13,0,6,1
1,0,0,0,0,0,1,1,1,1,1,1,1,1,1,1,1,1,1
1,1,1,1,1,0,0,0,0,0,0,0,0,0,0,17,16,15,1
1,14,19,18,1,16,0,16,1,1,1,1,16,0,0,0,16,96,1
1,0,0,0,1,0,0,0,1,22,22,1,21,20,0,0,1,1,1
1,24,13,0,1,0,0,0,1,22,23,1,1,1,0,0,16,0,1
1,1,1,1,1,0,0,0,1,22,23,1,25,16,0,0,16,0,1
1,14,0,12,1,0,0,0,1,22,22,1,0,16,0,0,1,1,1
1,0,0,0,1,16,17,16,1,1,1,1,1,1,0,0,16,0,1
1,0,0,0,1,0,0,0,0,0,0,0,0,0,17,0,16,0,1
1,0,19,18,1,0,0,0,1,1,1,1,1,1,1,1,1,1,1
1,0,24,1,1,1,1,1,1,2,2,2,1,14,0,9,0,14,1
1,0,24,24,27,0,19,18,1,7,0,0,1,26,0,0,0,26,1
1,24,1,24,0,0,0,13,1,7,0,13,1,28,0,13,0,28,1
1,1,1,1,1,1,1,1,1,1,1,1,1,1,1,1,1,1,1
endlayer

layer
1,1,1,16,1,1,1,1,1,1,1,1,1,1,1,1,1,1,1
1,17,12,0,17,1,7,2,2,1,2,2,2,2,2,2,2,2,1
1,0,0,0,0,1,7,0,13,1,7,17,0,0,0,0,0,6,1
1,0,0,0,0,1,1,29,1,1,7,17,0,29,17,13,0,6,1
1,17,0,0,17,17,1,1,1,1,1,1,1,1,1,1,1,1,1
1,1,1,1,1,17,17,17,17,17,17,17,0,17,17,17,16,17,1
1,30,0,0,1,16,17,16,1,1,1,1,16,0,0,0,16,17,1
16,0,0,0,1,17,0,17,1,22,22,1,17,17,0,17,1,1,1
1,29,13,0,1,17,0,17,1,22,23,1,1,1,17,0,16,17,1
1,1,1,1,1,17,0,17,1,22,23,1,17,16,0,0,16,17,1
1,29,0,12,1,17,0,17,1,22,22,1,17,16,0,17,1,1,1
16,0,0,0,1,16,17,16,1,1,1,1,1,1,0,0,16,17,1
1,0,0,0,1,0,17,17,0,0,0,0,17,17,0,17,16,17,1
1,17,0,0,1,0,17,17,1,1,1,1,1,1,1,1,1,1,1
1,0,24,1,1,1,1,1,1,2,2,2,1,30,0,29,0,30,1
1,0,24,31,0,0,0,0,1,7,17,0,1,0,0,0,0,0,1
1,24,1,29,0,0,0,13,1,7,17,13,1,0,0,13,0,0,1
1,1,1,1,1,16,1,1,1,1,16,1,1,16,1,1,1,16,1
endlayer

layer
1,1,1,1,1,1,1,1,1,1,1,1,1,1,1,1,1,1,1
1,32,12,32,32,1,7,2,2,1,32,32,32,32,32,32,32,32,1
1,32,32,32,32,1,7,17,13,1,32,32,32,32,32,32,32,32,1
1,32,32,32,32,1,1,17,1,1,32,32,32,32,32,13,32,32,1
1,32,32,32,32,32,1,1,1,1,1,1,1,1,1,1,1,1,1
1,1,1,1,1,32,32,32,32,32,32,32,32,32,32,32,1,32,1
1,17,0,17,1,1,32,1,1,1,1,1,1,32,32,32,1,32,1
1,0,0,0,1,32,32,32,1,22,22,1,32,32,32,32,1,1,1
1,17,13,0,1,32,32,32,1,22,23,22,1,1,32,32,1,32,1
1,1,1,1,1,32,32,32,1,22,23,1,32,1,32,32,1,32,1
1,0,0,12,1,32,32,32,1,22,22,1,32,1,32,32,1,1,1
1,32,32,32,1,1,32,1,1,1,1,1,1,1,32,32,1,32,1
1,17,0,17,1,32,32,32,32,32,32,32,32,32,32,32,1,32,1
1,32,32,32,1,32,32,32,1,1,1,1,1,1,1,1,1,1,1
1,0,24,1,1,1,1,1,1,32,32,32,1,32,32,32,32,32,1
1,0,24,24,17,0,0,17,1,32,32,32,1,17,17,17,32,32,1
1,24,1,24,0,0,0,13,1,32,32,13,1,17,17,13,32,32,1
1,1,1,1,1,1,1,1,1,1,1,1,1,1,1,1,1,1,1
endlayer

layer
1,1,1,1,1,1,1,1,1,1,1,1,1,1,1,1,1,1,1
1,11,12,11,22,33,33,33,33,34,33,33,33,33,33,33,1,11,1
1,11,11,11,22,33,33,33,13,34,33,33,33,33,33,33,1,11,1
1,11,11,11,22,3,34,33,34,34,33,33,33,33,33,13,1,3,1
1,11,11,11,22,3,36,3,36,36,35,35,35,35,35,35,1,3,1
1,22,22,22,22,3,3,3,3,3,3,3,3,3,3,3,3,3,1
1,38,38,38,36,3,3,37,37,37,3,37,37,37,3,3,1,3,1
1,38,38,38,3,3,3,37,37,37,3,37,37,37,3,3,1,3,11
1,38,13,38,36,3,3,37,37,37,23,37,37,37,3,3,3,3,3
1,22,22,22,22,3,3,37,37,37,23,37,37,37,3,3,3,3,3
1,33,33,12,22,3,3,37,37,37,3,37,37,37,3,3,1,3,11
1,33,33,33,22,3,3,37,37,37,3,37,37,37,3,3,1,3,1
1,33,33,33,22,3,3,3,3,3,3,3,3,3,3,3,3,3,1
1,22,22,22,22,36,3,36,36,36,36,3,36,36,3,36,1,3,1
1,11,11,3,3,3,3,36,39,39,39,35,39,36,3,36,1,3,1
1,11,1,33,33,33,33,33,22,35,35,35,22,40,40,40,1,11,1
1,11,1,33,33,33,33,13,1,35,35,13,22,40,40,13,1,11,1
1,1,1,1,1,1,1,1,1,1,1,1,1,1,1,1,1,1,1
endlayer

layer
1,1,1,1,1,1,1,1,1,1,1,1,1,1,1,1,1,1,1
1,0,44,24,43,0,0,0,0,24,42,41,27,42,41,27,1,0,1
1,0,0,46,22,14,0,0,44,24,0,0,0,0,0,0,1,45,1
1,26,0,0,22,34,34,45,34,34,43,47,0,0,0,44,1,0,1
1,28,47,0,49,0,48,0,48,48,35,35,45,45,35,35,1,0,1
1,22,22,22,22,0,0,0,0,0,0,0,0,0,0,0,47,0,1
1,38,0,38,48,0,14,51,51,51,14,50,50,50,14,0,1,0,1
1,43,0,49,0,0,14,51,51,51,14,50,50,50,14,0,11,52,11
1,38,44,38,48,0,14,51,51,51,11,50,50,50,14,0,54,0,53
1,22,22,22,22,0,14,51,51,51,11,55,55,55,14,0,54,0,53
1,9,0,44,22,0,14,51,51,51,14,55,55,55,14,0,11,45,11
1,43,0,0,49,0,14,51,51,51,14,55,55,55,14,0,1,0,1
1,14,14,0,49,0,0,0,0,0,0,0,0,0,0,0,47,0,1
1,22,22,22,22,48,0,56,48,56,48,0,56,56,0,48,1,0,1
1,0,57,0,0,0,0,56,39,39,39,52,39,56,0,48,1,0,1
1,0,24,40,40,40,52,40,22,26,0,0,22,46,45,46,1,52,1
1,0,1,24,47,0,0,44,22,28,14,44,22,43,0,44,1,0,1
1,1,1,1,1,1,1,1,1,1,1,1,1,1,1,1,1,1,1
endlayer

layer
58,1,16,1,1,1,1,16,1,1,1,16,1,1,16,1,1,1,58
1,12,0,29,9,0,0,0,12,24,0,59,0,0,59,0,1,12,1
1,0,0,0,22,29,0,0,0,24,0,0,0,0,0,0,1,60,1
1,0,0,0,22,61,34,60,34,34,29,0,0,0,0,0,1,0,1
16,0,0,0,60,0,63,0,63,63,35,35,60,62,35,35,1,0,1
1,22,22,22,22,0,0,0,0,0,0,0,0,0,0,0,47,0,1
1,38,0,38,64,0,29,0,0,0,29,0,0,0,29,0,1,0,1
1,29,0,60,0,0,0,0,0,0,0,0,0,0,0,0,11,60,11
1,38,0,38,64,0,0,0,0,0,65,0,0,0,0,0,60,0,0
1,22,22,22,22,0,0,0,0,0,66,0,0,0,0,0,62,0,0
16,31,0,0,22,0,0,0,0,0,0,0,0,0,0,0,11,60,11
1,58,0,0,62,0,29,0,0,0,29,0,0,0,29,0,1,0,1
16,59,59,0,60,0,0,0,0,0,0,0,0,0,0,0,47,0,1
1,22,22,22,22,64,0,0,68,0,68,0,0,0,0,67,1,0,1
16,0,62,0,0,0,0,0,39,61,39,60,39,0,0,67,1,0,1
1,0,29,40,61,40,60,40,22,0,0,0,22,69,60,69,1,60,1
1,13,1,24,0,0,0,0,22,0,59,0,22,29,0,0,1,13,1
58,1,1,1,16,1,16,1,1,1,1,1,1,1,16,1,1,1,58
endlayer

layer
58,1,1,11,11,72,71,72,72,71,70,70,70,70,70,70,1,1,58
1,12,0,0,11,33,71,33,12,71,73,73,0,0,73,73,1,12,1
1,0,0,0,11,33,71,33,33,71,0,0,0,0,0,0,1,1,1
11,0,0,0,11,72,71,33,33,71,74,74,0,0,74,74,10,0,58
11,0,0,0,11,0,71,72,72,71,2,2,2,2,2,2,2,0,58
11,11,11,11,11,0,0,0,0,0,0,0,0,0,0,0,0,0,58
75,75,75,75,75,0,0,0,0,0,0,0,0,0,0,0,58,0,58
58,0,0,76,14,0,0,0,0,0,0,0,0,0,0,0,11,11,11
75,75,75,75,75,0,0,0,0,0,8,0,0,0,0,0,66,0,66
46,46,46,46,46,0,0,0,0,0,5,0,0,0,0,0,65,0,65
22,0,0,0,22,0,0,0,0,0,0,0,0,0,0,0,11,11,11
22,58,0,14,22,14,0,0,0,0,0,0,0,0,0,0,58,0,58
22,0,0,0,22,0,0,0,0,0,0,0,0,0,0,0,0,0,58
77,77,77,77,77,0,0,0,0,0,14,0,0,0,0,0,58,0,58
8,8,8,0,0,0,0,0,79,39,39,39,78,0,0,0,58,0,58
1,1,1,70,70,70,70,70,79,0,14,0,78,6,10,7,1,1,1
1,13,1,6,14,14,14,7,79,0,0,0,78,6,10,7,1,13,1
58,1,1,2,2,2,2,2,79,39,61,39,78,6,10,7,1,1,58
endlayer

layer
1,1,1,40,81,33,80,61,61,80,0,0,0,0,0,0,1,1,1
1,12,14,0,81,42,0,0,44,10,70,70,83,82,70,70,1,12,1
1,14,14,14,81,42,0,0,0,24,10,10,83,82,10,10,1,1,1
84,14,14,14,81,33,14,19,18,10,2,2,83,82,2,2,2,0,29
84,0,14,0,81,0,80,61,61,80,0,0,0,0,0,0,0,0,0
84,40,40,40,81,0,0,0,0,0,0,0,0,0,0,0,0,0,0
85,85,85,85,85,0,0,0,0,0,0,0,0,0,0,0,29,0,29
58,0,0,38,29,0,0,0,0,0,0,0,0,0,0,0,8,8,8
86,86,86,86,86,0,0,0,0,0,0,0,0,0,0,0,16,14,16
0,0,0,0,0,0,0,0,0,0,0,0,0,0,0,0,16,14,16
33,33,33,33,33,0,0,0,0,0,0,0,0,0,0,0,5,5,5
22,58,0,29,22,29,0,0,0,0,0,0,0,0,0,0,29,0,29
33,33,33,33,33,0,0,0,0,0,0,0,0,0,0,0,0,0,0
0,0,0,0,0,0,0,0,0,0,29,0,0,0,0,0,0,0,0
0,0,0,0,0,0,0,0,0,35,39,35,0,0,0,0,29,0,29
1,1,1,0,0,0,0,0,0,35,29,35,0,0,2,0,1,1,1
1,13,1,0,6,29,7,0,0,35,0,35,0,0,58,0,1,13,1
1,1,1,0,0,0,0,0,0,35,61,35,0,0,70,0,1,1,1
endlayer

layer
1,1,1,40,0,33,80,61,61,80,0,0,0,0,0,0,1,1,1
16,12,1,40,0,61,0,0,0,82,0,0,6,7,0,0,16,12,16
1,1,1,40,0,61,0,0,0,31,7,87,6,7,87,6,1,16,1
0,40,0,40,0,33,29,0,0,82,0,0,6,7,0,0,0,0,0
0,40,0,40,0,0,80,61,61,80,0,0,0,0,0,0,0,0,0
0,40,40,40,0,0,0,0,0,0,0,0,0,0,0,0,0,0,0
0,0,0,0,0,0,0,0,0,0,0,0,0,0,0,0,0,0,0
88,88,88,88,88,0,0,0,0,0,0,0,0,0,0,0,0,0,0
0,0,0,0,0,0,0,0,0,0,0,0,0,0,0,0,8,8,8
0,0,0,0,0,0,0,0,0,0,0,0,0,0,0,0,5,5,5
46,46,46,46,46,0,0,0,0,0,0,0,0,0,0,0,0,0,0
22,33,33,33,33,0,0,0,0,0,0,0,0,0,0,0,0,0,0
77,77,77,77,77,0,0,0,0,0,0,0,0,0,0,0,0,0,0
0,0,0,0,0,0,0,0,0,0,0,0,0,0,0,0,0,0,0
0,0,0,0,0,0,0,0,0,79,35,78,0,0,0,0,0,0,0
1,16,1,0,0,0,0,0,0,79,35,78,0,0,0,0,1,16,1
16,13,16,0,0,87,0,0,0,79,35,78,0,0,29,0,16,13,16
1,1,1,0,0,0,0,0,0,79,35,78,0,0,0,0,1,1,1
endlayer

layer
1,1,1,81,0,46,71,72,72,71,0,0,0,0,0,0,1,1,1
16,12,1,81,0,33,71,0,0,71,0,0,0,0,0,0,16,12,16
1,1,1,81,0,33,71,0,0,71,0,0,0,0,0,0,1,16,1
0,84,40,81,0,77,71,0,0,71,0,0,0,0,0,0,0,0,0
0,84,40,81,0,0,71,72,72,71,0,0,0,0,0,0,0,0,0
0,84,40,81,0,0,0,0,0,0,0,0,0,0,0,0,0,0,0
0,0,0,0,0,0,0,0,0,0,0,0,0,0,0,0,0,0,0
58,14,14,14,89,0,0,0,0,0,0,0,0,0,0,0,0,0,0
0,0,0,0,0,0,0,0,0,0,0,0,0,0,0,0,0,0,0
0,0,0,0,0,0,0,0,0,0,0,0,0,0,0,0,0,0,0
0,0,0,0,0,0,0,0,0,0,0,0,0,0,0,0,0,0,0
22,33,33,33,33,0,0,0,0,0,0,0,0,0,0,0,0,0,0
0,0,0,0,0,0,0,0,0,0,0,0,0,0,0,0,0,0,0
0,0,0,0,0,0,0,0,0,0,0,0,0,0,0,0,0,0,0
0,0,0,0,0,0,0,0,0,0,35,0,0,0,0,0,0,0,0
1,16,1,0,0,0,0,0,0,0,35,0,0,0,0,0,1,16,1
16,13,16,0,0,0,0,0,0,0,35,0,0,0,0,0,16,13,16
1,1,1,0,0,0,0,0,0,0,35,0,0,0,0,0,1,1,1
endlayer

layer
11,11,11,0,0,0,27,74,74,42,0,0,0,0,0,0,11,11,11
11,12,11,0,0,46,46,14,14,42,0,0,0,0,0,0,11,12,11
11,11,11,0,0,77,77,14,14,42,0,0,0,0,0,0,11,11,11
0,0,90,0,0,0,27,14,14,42,0,0,0,0,0,0,0,0,0
0,0,90,0,0,0,27,73,73,42,0,0,0,0,0,0,0,0,0
0,0,91,0,0,0,0,0,0,0,0,0,0,0,0,0,0,0,0
0,0,0,0,0,0,0,0,0,0,0,0,0,0,0,0,0,0,0
0,0,0,0,0,0,0,0,0,0,0,0,0,0,0,0,0,0,0
0,0,0,0,0,0,0,0,0,0,0,0,0,0,0,0,0,0,0
0,0,0,0,0,0,0,0,0,0,0,0,0,0,0,0,0,0,0
0,0,0,0,0,0,0,0,0,0,0,0,0,0,0,0,0,0,0
22,92,92,92,27,0,0,0,0,0,0,0,0,0,0,0,0,0,0
0,0,0,0,0,0,0,0,0,0,0,0,0,0,0,0,0,0,0
0,0,0,0,0,0,0,0,0,0,0,0,0,0,0,0,0,0,0
0,0,0,0,0,0,0,0,0,0,93,0,0,0,0,0,0,0,0
11,11,11,0,0,0,0,0,0,0,94,0,0,0,0,0,11,11,11
11,13,11,0,0,0,0,0,0,0,93,0,0,0,0,0,11,13,11
11,11,11,0,0,0,0,0,0,0,94,0,0,0,0,0,11,11,11
endlayer

layer
14,14,14,0,0,0,0,33,33,0,0,0,0,0,0,0,14,14,14
14,0,14,0,0,0,0,33,33,0,0,0,0,0,0,0,14,0,14
14,14,14,0,0,0,0,33,33,0,0,0,0,0,0,0,14,14,14
0,0,0,0,0,0,0,33,33,0,0,0,0,0,0,0,0,0,0
0,0,0,0,0,0,0,33,33,0,0,0,0,0,0,0,0,0,0
0,0,0,0,0,0,0,0,0,0,0,0,0,0,0,0,0,0,0
0,0,0,0,0,0,0,0,0,0,0,0,0,0,0,0,0,0,0
0,0,0,0,0,0,0,0,0,0,0,0,0,0,0,0,0,0,0
0,0,0,0,0,0,0,0,0,0,0,0,0,0,0,0,0,0,0
0,0,0,0,0,0,0,0,0,0,0,0,0,0,0,0,0,0,0
0,0,0,0,0,0,0,0,0,0,0,0,0,0,0,0,0,0,0
58,0,0,0,0,0,0,0,0,0,0,0,0,0,0,0,0,0,0
0,0,0,0,0,0,0,0,0,0,0,0,0,0,0,0,0,0,0
0,0,0,0,0,0,0,0,0,0,0,0,0,0,0,0,0,0,0
0,0,0,0,0,0,0,0,0,0,0,0,0,0,0,0,0,0,0
14,14,14,0,0,0,0,0,0,0,0,0,0,0,0,0,14,14,14
14,0,14,0,0,0,0,0,0,0,0,0,0,0,0,0,14,0,14
14,14,14,0,0,0,0,0,0,0,0,0,0,0,0,0,14,14,14
endlayer

layer
29,0,29,0,0,0,0,27,42,0,0,0,0,0,0,0,29,0,29
0,0,0,0,0,0,0,27,42,0,0,0,0,0,0,0,0,0,0
29,0,29,0,0,0,0,27,42,0,0,0,0,0,0,0,29,0,29
0,0,0,0,0,0,0,27,42,0,0,0,0,0,0,0,0,0,0
0,0,0,0,0,0,0,27,42,0,0,0,0,0,0,0,0,0,0
0,0,0,0,0,0,0,0,0,0,0,0,0,0,0,0,0,0,0
0,0,0,0,0,0,0,0,0,0,0,0,0,0,0,0,0,0,0
0,0,0,0,0,0,0,0,0,0,0,0,0,0,0,0,0,0,0
0,0,0,0,0,0,0,0,0,0,0,0,0,0,0,0,0,0,0
0,0,0,0,0,0,0,0,0,0,0,0,0,0,0,0,0,0,0
0,0,0,0,0,0,0,0,0,0,0,0,0,0,0,0,0,0,0
0,0,0,0,0,0,0,0,0,0,0,0,0,0,0,0,0,0,0
0,0,0,0,0,0,0,0,0,0,0,0,0,0,0,0,0,0,0
0,0,0,0,0,0,0,0,0,0,0,0,0,0,0,0,0,0,0
0,0,0,0,0,0,0,0,0,0,0,0,0,0,0,0,0,0,0
29,0,29,0,0,0,0,0,0,0,0,0,0,0,0,0,29,0,29
0,0,0,0,0,0,0,0,0,0,0,0,0,0,0,0,0,0,0
29,0,29,0,0,0,0,0,0,0,0,0,0,0,0,0,29,0,29
endlayer

