# Vault Dungeon 3x3
# Created by Ruins mod version 16.0 Ingame Parser
# authoring Player: Jordan_Greywolf
# Created for MC 1.9: 22 May 2016
# Updated to MC 1.10: 13 Sep 2016
# Updated to MC 1.11: 13 Jan 2017
# Verified for MC 1.12: 23 Jun 2017
# Updated to MC 1.12.1: 10 Sep 2017

# Last Updated: 9 Jun 2018


biomesToSpawnIn=arctic,badlands,bamboo forest,bamboo_forest,bayou,blessed bog,bog,boreal forest,boreal_forest,chaparral,cold beach,cold_beach,cold desert,cold_desert,cold taiga,cold taiga hills,cold taiga m,coniferous forest,coniferous_forest,dead forest,dead_forest,deadlands,dense forest,desert,desert m,desert oil field,deserthills,dreadland,extreme hills edge,fen,flower forest,forest,foresthills,frost forest,glacier,green swampland,green_swamp,grove,heathland,hot springs,ice plains,lavender fields,lavender_fields,mystic grove,oasis,ominous woods,outback,overgrown greens,pasture,plains,prairie,quagmire,redwood forest,savanna,savanna m,scrubland,seasonal forest,seasonal_forest,shield,shrubland,silkglades,steppe,sunflower plains,swampland,swampland m,tainted land,tainted lands,temperate rainforest,tundra,wasteland,wetland,wondrous woods,xeric shrubland,xeric_shrubland,taiga_cold,taiga_cold_hills,mutated_taiga,mutated_taiga_cold,mutated_desert,desert_hills,smaller_extreme_hills,redwood_taiga,savanna_rock,stone_beach

preventRotation=1

uniqueMinDistance=2500

weight=1
embed_into_distance=40
acceptable_target_blocks=

unacceptable_target_blocks=cloud,Natura:Cloud,slime_congealed,slime_dirt,slime_grass,command_block,planks,planks2,concrete,cobblestone,stonebrick,brick_block,glass,torch,oak_stairs,stone_stairs,brick_stairs,stone_brick_stairs,nether_brick_stairs,sandstone_stairs,spruce_stairs,birch_stairs,jungle_stairs,quartz_stairs,acacia_stairs,dark_oak_stairs,cobblestone_wall,stone_slab,double_stone_slab,stone_slab2,wooden_slab,double_wooden_slab,nether_brick,fence

dimensions=13,48,48
allowable_overhang=999
max_leveling=0
leveling_buffer=0
preserve_water=0
preserve_lava=0

rule1=0,100,preserveBlock
rule2=0,100,minecraft:water-0
rule3=0,100,minecraft:stonebrick-0,minecraft:stonebrick-0,minecraft:stonebrick-1,minecraft:stonebrick-2
rule4=0,100,minecraft:mossy_cobblestone-0
rule5=0,100,minecraft:stonebrick-3
rule6=0,100,minecraft:stone_brick_stairs-3
rule7=0,100,minecraft:stone_brick_stairs-1
rule8=0,100,minecraft:stone_brick_stairs-2
rule9=0,100,minecraft:stone_brick_stairs-0
rule10=0,100,minecraft:red_sandstone_stairs-0
rule11=0,100,minecraft:red_sandstone_stairs-3
rule12=0,100,minecraft:red_sandstone_stairs-2
rule13=0,100,minecraft:red_sandstone_stairs-1
rule14=0,100,minecraft:cobblestone_wall-0
rule15=0,100,minecraft:stone_slab2-0
rule16=0,100,minecraft:double_stone_slab-0
rule17=0,100,minecraft:cobblestone-0
rule18=0,100,minecraft:stone_stairs-3
rule19=0,100,minecraft:stone_stairs-2
rule20=0,100,minecraft:stone_stairs-1
rule21=0,100,minecraft:stone_stairs-0
rule22=0,100,ChestGenHook:chests/simple_dungeon:3-5
rule23=0,100,minecraft:water-10
rule24=0,100,minecraft:waterlily-0,minecraft:air
rule25=0,100,minecraft:stone_slab-0
rule26=0,100,ChestGenHook:chests/simple_dungeon:3-3
rule27=0,100,ChestGenHook:chests/simple_dungeon:3-2
rule28=0,100,minecraft:netherrack-0

rule29=0,100,IInventory;minecraft:chest;minecraft:sapling#16#5#2+minecraft:stonebrick#16#2#3+minecraft:stonebrick#16#1#6+minecraft:stonebrick#16#0#8+minecraft:stonebrick#16#2#9+minecraft:planks#16#5#10+minecraft:planks#16#5#12+minecraft:stone#16#0#14+minecraft:sapling#16#5#16+minecraft:stone#16#0#18+minecraft:stonebrick#16#1#22+minecraft:stonebrick#16#0#24-3

rule30=0,100,IInventory;minecraft:chest;minecraft:red_sandstone#8#2#0+minecraft:sandstone#16#0#3+minecraft:sand#16#0#5+minecraft:sand#8#1#6+minecraft:red_sandstone#8#0#10+minecraft:sandstone#16#0#11+minecraft:sand#8#1#13+minecraft:red_sandstone#8#2#17+minecraft:red_sandstone#8#2#18+minecraft:red_sandstone#8#0#21+minecraft:sand#16#0#24+minecraft:red_sandstone#8#2#25-4

rule31=0,100,IInventory;minecraft:chest;minecraft:dirt#16#0#0+minecraft:bone#2#0#4+minecraft:apple#3#0#7+minecraft:stick#6#0#10+minecraft:dirt#16#0#12+minecraft:water_bucket#1#0#15+minecraft:coal#4#0#17+minecraft:pumpkin_seeds#2#0#19+minecraft:bread#4#0#20+minecraft:iron_bars#16#0#23-4

rule32=0,100,minecraft:iron_bars-0
rule33=1,100,minecraft:redstone_torch-5
rule34=0,100,minecraft:dark_oak_fence_gate-2
rule35=0,100,minecraft:dark_oak_fence_gate-0
rule36=0,100,minecraft:stone_brick_stairs-5
rule37=0,100,minecraft:stone_brick_stairs-7
rule38=0,100,minecraft:stone_brick_stairs-6
rule39=0,100,minecraft:dark_oak_fence_gate-3
rule40=0,100,minecraft:dark_oak_fence_gate-1
rule41=0,100,minecraft:stone_brick_stairs-4
rule42=0,100,minecraft:fire-15
rule43=0,100,minecraft:water-2
rule44=0,100,minecraft:water-1

rule45=0,100,MobSpawner:Skeleton,MobSpawner:Zombie,MobSpawner:Spider

rule46=0,100,minecraft:stone_stairs-7
rule47=0,100,minecraft:stone_stairs-6
rule48=0,100,minecraft:stone_stairs-5
rule49=0,100,minecraft:stone_slab-11
rule50=0,100,minecraft:stone_stairs-4
rule51=0,100,minecraft:stone_slab-8
rule52=0,100,minecraft:stone_slab-13
rule53=0,100,minecraft:glowstone-0

rule54=0,100,CommandBlock:RUINSTRIGGER /testruin TP_VRoom_Garden ~1 ~-8 ~1:@-0,CommandBlock:RUINSTRIGGER /testruin TP_VRoom_MushGarden ~1 ~-8 ~1:@-0,CommandBlock:RUINSTRIGGER /testruin TP_VRoom_Library ~1 ~-8 ~1:@-0,CommandBlock:RUINSTRIGGER /testruin TP_VRoom_Bedroom ~1 ~-8 ~1:@-0,CommandBlock:RUINSTRIGGER /testruin TP_VRoom_Furnace ~1 ~-9 ~1:@-0,CommandBlock:RUINSTRIGGER /testruin TP_VRoom_Cage ~1 ~-9 ~1:@-0,CommandBlock:RUINSTRIGGER /testruin TP_VRoom_Fountains ~1 ~-9 ~1:@-0

layer
1,1,1,1,1,1,1,1,1,1,1,1,1,1,1,1,1,1,1,1,1,1,1,1,1,1,1,1,1,1,1,1,1,1,1,1,1,1,1,1,1,1,1,1,1,1,1,1
1,1,1,1,1,1,1,1,1,1,1,1,1,1,1,1,1,1,1,1,1,1,1,1,1,1,1,1,1,1,1,1,1,1,1,1,1,1,1,1,1,1,1,1,1,1,1,1
1,1,1,1,1,1,1,1,1,1,1,1,1,1,1,1,1,1,1,1,1,1,1,1,1,1,1,1,1,1,1,1,1,1,1,1,1,1,1,1,1,1,1,1,1,1,1,1
1,1,1,1,1,1,1,1,1,1,1,1,1,1,1,1,1,1,1,1,1,1,1,1,1,1,1,1,1,1,1,1,1,1,1,1,1,1,1,1,1,1,1,1,1,1,1,1
1,1,1,1,1,1,1,1,1,1,1,1,1,1,1,1,1,1,1,1,1,1,1,1,1,1,1,1,1,1,1,1,1,1,1,1,1,1,1,1,1,1,1,1,1,1,1,1
1,1,1,1,1,1,1,1,1,1,1,1,1,1,1,1,1,1,1,1,1,1,1,1,1,1,1,1,1,1,1,1,1,1,1,1,1,1,1,1,1,1,1,1,1,1,1,1
1,1,1,1,1,1,1,1,1,1,1,1,1,1,1,1,1,1,1,1,1,1,1,1,1,1,1,1,1,1,1,1,1,1,1,1,1,1,1,1,1,1,1,1,1,1,1,1
1,1,1,1,1,1,1,1,1,1,1,1,1,1,1,1,1,1,1,1,1,1,1,1,1,1,1,1,1,1,1,1,1,1,1,1,1,1,1,1,1,1,1,1,1,1,1,1
1,1,1,1,1,1,1,1,1,1,1,1,1,1,1,1,1,1,1,1,1,1,1,1,1,1,1,1,1,1,1,1,1,1,1,1,1,1,1,1,1,1,1,1,1,1,1,1
1,1,1,1,1,1,1,1,1,1,1,1,1,1,1,1,1,1,1,1,1,1,1,1,1,1,1,1,1,1,1,1,1,1,1,1,1,1,1,1,1,1,1,1,1,1,1,1
1,1,1,1,1,1,1,1,1,1,1,1,1,1,1,1,1,1,1,1,1,1,1,1,1,1,1,1,1,1,1,1,1,1,1,1,1,1,1,1,1,1,1,1,1,1,1,1
1,1,1,1,1,1,1,1,1,1,1,1,1,1,1,1,1,1,1,1,1,1,1,1,1,1,1,1,1,1,1,1,1,1,1,1,1,1,1,1,1,1,1,1,1,1,1,1
1,1,1,1,1,1,1,1,1,1,1,1,1,1,1,1,1,1,1,1,1,1,1,1,1,1,1,1,1,1,1,1,1,1,1,1,1,1,1,1,1,1,1,1,1,1,1,1
1,1,1,1,1,1,1,1,1,1,1,1,1,1,1,1,1,1,1,1,1,1,1,1,1,1,1,1,1,1,1,1,1,1,1,1,1,1,1,1,1,1,1,1,1,1,1,1
1,1,1,1,1,1,1,1,1,1,1,1,1,1,1,1,1,1,1,1,1,1,1,1,1,1,1,1,1,1,1,1,1,1,1,1,1,1,1,1,1,1,1,1,1,1,1,1
1,1,1,1,1,1,1,1,1,1,1,1,1,1,1,1,1,1,1,1,1,1,1,1,1,1,1,1,1,1,1,1,1,1,1,1,1,1,1,1,1,1,1,1,1,1,1,1
1,1,1,1,1,1,1,1,1,1,1,1,1,1,1,1,1,1,1,1,1,1,1,1,1,1,1,1,1,1,1,1,1,1,1,1,1,1,1,1,1,1,1,1,1,1,1,1
1,1,1,1,1,1,1,1,1,1,1,1,1,1,1,1,1,1,1,1,1,1,1,1,1,1,1,1,1,1,1,1,1,1,1,1,1,1,1,1,1,1,1,1,1,1,1,1
1,1,1,1,1,1,1,1,1,1,1,1,1,1,1,1,1,1,1,1,1,1,1,1,1,1,1,1,1,1,1,1,1,1,1,1,1,1,1,1,1,1,1,1,1,1,1,1
1,1,1,1,1,1,1,1,1,1,1,1,1,1,1,1,1,1,1,1,1,1,1,1,1,1,1,1,1,1,1,1,1,1,1,1,1,1,1,1,1,1,1,1,1,1,1,1
1,1,1,1,1,1,1,1,1,1,1,1,1,1,1,1,1,1,1,1,1,1,1,1,1,1,1,1,1,1,1,1,1,1,1,1,1,1,1,1,1,1,1,1,1,1,1,1
1,1,1,1,1,1,1,1,1,1,1,1,1,1,1,1,1,1,1,1,1,1,1,1,1,1,1,1,1,1,1,1,1,1,1,1,1,1,1,1,1,1,1,1,1,1,1,1
1,1,1,1,1,1,1,1,1,1,1,1,1,1,1,1,1,1,1,1,1,1,1,1,1,1,1,1,1,1,1,1,1,1,1,1,1,1,1,1,1,1,1,1,1,1,1,1
1,1,1,1,1,1,1,1,1,1,1,1,1,1,1,1,1,1,1,1,1,1,1,1,1,1,1,1,1,1,1,1,1,1,1,1,1,1,1,1,1,1,1,1,1,1,1,1
1,1,1,1,1,1,1,1,1,1,1,1,1,1,1,1,1,1,1,1,1,1,1,1,1,1,1,1,1,1,1,1,1,1,1,1,1,1,1,1,1,1,1,1,1,1,1,1
1,1,1,1,1,1,1,1,1,1,1,1,1,1,1,1,1,1,1,1,1,1,1,1,1,1,1,1,1,1,1,1,1,1,1,1,1,1,1,1,1,1,1,1,1,1,1,1
1,1,1,1,1,1,1,1,1,1,1,1,1,1,1,1,1,1,1,1,1,1,1,1,1,1,1,1,1,1,1,1,1,1,1,1,1,1,1,1,1,1,1,1,1,1,1,1
1,1,1,1,1,1,1,1,1,1,1,1,1,1,1,1,1,1,1,1,1,1,1,1,1,1,1,1,1,1,1,1,1,1,1,1,1,1,1,1,1,1,1,1,1,1,1,1
1,1,1,1,1,1,1,1,1,1,1,1,1,1,1,1,1,1,1,1,1,1,1,1,1,1,1,1,1,1,1,1,1,1,1,1,1,1,1,1,1,1,1,1,1,1,1,1
1,1,1,1,1,1,1,1,1,1,1,1,1,1,1,1,1,1,1,1,1,1,1,1,1,1,1,1,1,1,1,1,1,1,1,1,1,1,1,1,1,1,1,1,1,1,1,1
1,1,1,1,1,1,1,1,1,1,1,1,1,1,1,1,1,1,1,1,1,1,1,1,1,1,1,1,1,1,1,1,1,1,1,1,1,1,1,1,1,1,1,1,1,1,1,1
1,1,1,1,1,1,1,1,1,1,1,1,1,1,1,1,1,1,1,1,1,1,1,1,1,1,1,1,1,1,1,1,1,1,1,1,1,1,1,1,1,1,1,1,1,1,1,1
1,1,1,1,1,1,1,1,1,1,1,1,1,1,1,1,1,1,1,1,1,1,1,1,1,1,1,1,1,1,1,1,1,1,1,1,1,1,1,1,1,1,1,1,1,1,1,1
1,1,1,1,1,1,1,1,1,1,1,1,1,1,1,1,1,1,1,1,1,1,1,1,1,1,1,1,1,1,1,1,1,1,1,1,1,1,1,1,1,1,1,1,1,1,1,1
1,1,1,1,1,1,1,1,1,1,1,1,1,1,1,1,1,1,1,1,1,1,1,1,1,1,1,1,1,1,1,1,1,1,1,1,1,1,1,1,1,1,1,1,1,1,1,1
1,1,1,1,1,1,1,1,1,1,1,1,1,1,1,1,1,1,1,1,1,1,1,1,1,1,1,1,1,1,1,1,1,1,1,1,1,1,1,1,1,1,1,1,1,1,1,1
1,1,1,1,1,1,1,1,1,1,1,1,1,1,1,1,1,1,1,1,1,1,1,1,1,1,1,1,1,1,1,1,1,1,1,1,1,1,1,1,1,1,1,1,1,1,1,1
1,1,1,1,1,1,1,1,1,1,1,1,1,1,1,1,1,1,1,1,1,1,1,1,1,1,1,1,1,1,1,1,1,1,1,1,1,1,1,1,1,1,1,1,1,1,1,1
1,1,1,1,1,1,1,1,1,1,1,1,1,1,1,1,1,1,1,1,1,1,1,1,1,1,1,1,1,1,1,1,1,1,1,1,1,1,1,1,1,1,1,1,1,1,1,1
1,1,1,1,1,1,1,1,1,1,1,1,1,1,1,1,1,1,1,1,1,1,1,1,1,1,1,1,1,1,1,1,1,1,1,1,1,1,1,1,1,1,1,1,1,1,1,1
1,1,1,1,1,1,1,1,1,1,1,1,1,1,1,1,1,1,1,1,1,1,1,1,1,1,1,1,1,1,1,1,1,1,1,1,1,1,1,1,1,1,1,1,1,1,1,1
1,1,1,1,1,1,1,1,1,1,1,1,1,1,1,1,1,1,1,1,1,1,1,1,1,1,1,1,1,1,1,1,1,1,1,1,1,1,1,1,1,1,1,1,1,1,1,1
1,1,1,1,1,1,1,1,1,1,1,1,1,1,1,1,1,1,1,1,1,1,1,1,1,1,1,1,1,1,1,1,1,1,1,1,1,1,1,1,1,1,1,1,1,1,1,1
1,1,1,1,1,1,1,1,1,1,1,1,1,1,1,1,1,1,1,1,1,1,1,1,1,1,1,1,1,1,1,1,1,1,1,1,1,1,1,1,1,1,1,1,1,1,1,1
1,1,1,1,1,1,1,1,1,1,1,1,1,1,1,1,1,1,1,1,1,1,1,1,1,1,1,1,1,1,1,1,1,1,1,1,1,1,1,1,1,1,1,1,1,1,1,1
1,1,1,1,1,1,1,1,1,1,1,1,1,1,1,1,1,1,1,1,1,1,1,1,1,1,1,1,1,1,1,1,1,1,1,1,1,1,1,1,1,1,1,1,1,1,1,1
1,1,1,1,1,1,1,1,1,1,1,1,1,1,1,1,1,1,1,1,1,1,1,1,1,1,1,1,1,1,1,1,1,1,1,1,1,1,1,1,1,1,1,1,1,1,1,1
1,1,1,1,1,1,1,1,1,1,1,1,1,1,1,1,1,1,1,1,1,1,1,1,1,1,1,1,1,1,1,1,1,1,1,1,1,1,1,1,1,1,1,1,1,1,1,1
endlayer

layer
1,1,1,1,1,1,1,1,1,1,1,1,1,1,1,1,1,1,1,1,1,1,1,1,1,1,1,1,1,1,1,1,1,1,1,1,1,1,1,1,1,1,1,1,1,1,1,1
1,1,1,1,1,1,1,1,1,1,1,1,1,1,1,1,1,1,1,1,1,1,1,1,1,1,1,1,1,1,1,1,1,1,1,1,1,1,1,1,1,1,1,1,1,1,1,1
1,1,1,1,1,1,1,1,1,1,1,1,1,1,1,1,1,1,1,1,1,1,1,1,1,1,1,1,1,1,1,1,1,1,1,1,1,1,1,1,1,1,1,1,1,1,1,1
1,1,1,1,1,1,1,1,1,1,1,1,1,1,1,1,1,1,1,1,1,1,1,1,1,1,1,1,1,1,1,1,1,1,1,1,1,1,1,1,1,1,1,1,1,1,1,1
1,1,1,1,1,1,1,1,1,1,1,1,1,1,1,1,1,1,1,1,1,1,1,1,1,1,1,1,1,1,1,1,1,1,1,1,1,1,1,1,1,1,1,1,1,1,1,1
1,1,1,1,1,1,1,1,1,1,1,1,1,1,1,1,1,1,1,1,1,1,1,1,1,1,1,1,1,1,1,1,1,1,1,1,1,1,1,1,1,1,1,1,1,1,1,1
1,1,1,1,1,1,1,1,1,1,1,1,1,1,1,1,1,1,1,1,1,1,1,1,1,1,1,1,1,1,1,1,1,1,1,1,1,1,1,1,1,1,1,1,1,1,1,1
1,1,1,1,1,1,1,1,1,1,1,1,1,1,1,1,1,1,1,1,1,1,1,1,1,1,1,1,1,1,1,1,1,1,1,1,1,1,1,1,1,1,1,1,1,1,1,1
1,1,1,1,1,1,1,1,1,1,1,1,1,1,1,1,1,1,1,1,1,1,1,1,1,1,1,1,1,1,1,1,1,1,1,1,1,1,1,1,1,1,1,1,1,1,1,1
1,1,1,1,1,1,1,1,1,1,1,1,1,1,1,1,1,1,1,1,1,1,1,1,1,1,1,1,1,1,1,1,1,1,1,1,1,1,1,1,1,1,1,1,1,1,1,1
1,1,1,1,1,1,1,1,1,1,1,1,1,1,1,1,1,1,1,1,1,1,1,1,1,1,1,1,1,1,1,1,1,1,1,1,1,1,1,1,1,1,1,1,1,1,1,1
1,1,1,1,1,1,1,1,1,1,1,1,1,1,1,1,1,1,1,1,1,1,1,1,1,1,1,1,1,1,1,1,1,1,1,1,1,1,1,1,1,1,1,1,1,1,1,1
1,1,1,1,1,1,1,1,1,1,1,1,1,1,1,1,1,1,1,1,1,1,1,1,1,1,1,1,1,1,1,1,1,1,1,1,1,1,1,1,1,1,1,1,1,1,1,1
1,1,1,1,1,1,1,1,1,1,1,1,1,1,1,1,1,1,1,1,1,1,1,1,1,1,1,1,1,1,1,1,1,1,1,1,1,1,1,1,1,1,1,1,1,1,1,1
1,1,1,1,1,1,1,1,1,1,1,1,1,1,1,1,1,1,1,1,1,1,1,1,1,1,1,1,1,1,1,1,1,1,1,1,1,1,1,1,1,1,1,1,1,1,1,1
1,1,1,1,1,1,1,1,1,1,1,1,1,1,1,1,1,1,1,1,1,1,1,1,1,1,1,1,1,1,1,1,1,1,1,1,1,1,1,1,1,1,1,1,1,1,1,1
1,1,1,1,1,1,1,1,1,1,1,1,1,1,1,1,1,1,1,1,1,1,1,1,1,1,1,1,1,1,1,1,1,1,1,1,1,1,1,1,1,1,1,1,1,1,1,1
1,1,1,1,1,1,1,1,1,1,1,1,1,1,1,1,1,1,1,1,1,1,1,1,1,1,1,1,1,1,1,1,1,1,1,1,1,1,1,1,1,1,1,1,1,1,1,1
1,1,1,1,1,1,1,1,1,1,1,1,1,1,1,1,1,1,1,1,1,1,1,1,1,1,1,1,1,1,1,1,1,1,1,1,1,1,1,1,1,1,1,1,1,1,1,1
1,1,1,1,1,1,1,1,1,1,1,1,1,1,1,1,1,1,1,1,1,1,1,1,1,1,1,1,1,1,1,1,1,1,1,1,1,1,1,1,1,1,1,1,1,1,1,1
1,1,1,1,1,1,1,1,1,1,1,1,1,1,1,1,1,1,1,1,1,1,1,1,1,1,1,1,1,1,1,1,1,1,1,1,1,1,1,1,1,1,1,1,1,1,1,1
1,1,1,1,1,1,1,1,1,1,1,1,1,1,1,1,1,1,1,1,1,1,1,1,1,1,1,1,1,1,1,1,1,1,1,1,1,1,1,1,1,1,1,1,1,1,1,1
1,1,1,1,1,1,1,1,1,1,1,1,1,1,1,1,1,1,1,1,1,1,1,1,1,1,1,1,1,1,1,1,1,1,1,1,1,1,1,1,1,1,1,1,1,1,1,1
1,1,1,1,1,1,1,1,1,1,1,1,1,1,1,1,1,1,1,1,1,1,1,2,2,1,1,1,1,1,1,1,1,1,1,1,1,1,1,1,1,1,1,1,1,1,1,1
1,1,1,1,1,1,1,1,1,1,1,1,1,1,1,1,1,1,1,1,1,1,1,2,2,1,1,1,1,1,1,1,1,1,1,1,1,1,1,1,1,1,1,1,1,1,1,1
1,1,1,1,1,1,1,1,1,1,1,1,1,1,1,1,1,1,1,1,1,1,1,1,1,1,1,1,1,1,1,1,1,1,1,1,1,1,1,1,1,1,1,1,1,1,1,1
1,1,1,1,1,1,1,1,1,1,1,1,1,1,1,1,1,1,1,1,1,1,1,1,1,1,1,1,1,1,1,1,1,1,1,1,1,1,1,1,1,1,1,1,1,1,1,1
1,1,1,1,1,1,1,1,1,1,1,1,1,1,1,1,1,1,1,1,1,1,1,1,1,1,1,1,1,1,1,1,1,1,1,1,1,1,1,1,1,1,1,1,1,1,1,1
1,1,1,1,1,1,1,1,1,1,1,1,1,1,1,1,1,1,1,1,1,1,1,1,1,1,1,1,1,1,1,1,1,1,1,1,1,1,1,1,1,1,1,1,1,1,1,1
1,1,1,1,1,1,1,1,1,1,1,1,1,1,1,1,1,1,1,1,1,1,1,1,1,1,1,1,1,1,1,1,1,1,1,1,1,1,1,1,1,1,1,1,1,1,1,1
1,1,1,1,1,1,1,1,1,1,1,1,1,1,1,1,1,1,1,1,1,1,1,1,1,1,1,1,1,1,1,1,1,1,1,1,1,1,1,1,1,1,1,1,1,1,1,1
1,1,1,1,1,1,1,1,1,1,1,1,1,1,1,1,1,1,1,1,1,1,1,1,1,1,1,1,1,1,1,1,1,1,1,1,1,1,1,1,1,1,1,1,1,1,1,1
1,1,1,1,1,1,1,1,1,1,1,1,1,1,1,1,1,1,1,1,1,1,1,1,1,1,1,1,1,1,1,1,1,1,1,1,1,1,1,1,1,1,1,1,1,1,1,1
1,1,1,1,1,1,1,1,1,1,1,1,1,1,1,1,1,1,1,1,1,1,1,1,1,1,1,1,1,1,1,1,1,1,1,1,1,1,1,1,1,1,1,1,1,1,1,1
1,1,1,1,1,1,1,1,1,1,1,1,1,1,1,1,1,1,1,1,1,1,1,1,1,1,1,1,1,1,1,1,1,1,1,1,1,1,1,1,1,1,1,1,1,1,1,1
1,1,1,1,1,1,1,1,1,1,1,1,1,1,1,1,1,1,1,1,1,1,1,1,1,1,1,1,1,1,1,1,1,1,1,1,1,1,1,1,1,1,1,1,1,1,1,1
1,1,1,1,1,1,1,1,1,1,1,1,1,1,1,1,1,1,1,1,1,1,1,1,1,1,1,1,1,1,1,1,1,1,1,1,1,1,1,1,1,1,1,1,1,1,1,1
1,1,1,1,1,1,1,1,1,1,1,1,1,1,1,1,1,1,1,1,1,1,1,1,1,1,1,1,1,1,1,1,1,1,1,1,1,1,1,1,1,1,1,1,1,1,1,1
1,1,1,1,1,1,1,1,1,1,1,1,1,1,1,1,1,1,1,1,1,1,1,1,1,1,1,1,1,1,1,1,1,1,1,1,1,1,1,1,1,1,1,1,1,1,1,1
1,1,1,1,1,1,1,1,1,1,1,1,1,1,1,1,1,1,1,1,1,1,1,1,1,1,1,1,1,1,1,1,1,1,1,1,1,1,1,1,1,1,1,1,1,1,1,1
1,1,1,1,1,1,1,1,1,1,1,1,1,1,1,1,1,1,1,1,1,1,1,1,1,1,1,1,1,1,1,1,1,1,1,1,1,1,1,1,1,1,1,1,1,1,1,1
1,1,1,1,1,1,1,1,1,1,1,1,1,1,1,1,1,1,1,1,1,1,1,1,1,1,1,1,1,1,1,1,1,1,1,1,1,1,1,1,1,1,1,1,1,1,1,1
1,1,1,1,1,1,1,1,1,1,1,1,1,1,1,1,1,1,1,1,1,1,1,1,1,1,1,1,1,1,1,1,1,1,1,1,1,1,1,1,1,1,1,1,1,1,1,1
1,1,1,1,1,1,1,1,1,1,1,1,1,1,1,1,1,1,1,1,1,1,1,1,1,1,1,1,1,1,1,1,1,1,1,1,1,1,1,1,1,1,1,1,1,1,1,1
1,1,1,1,1,1,1,1,1,1,1,1,1,1,1,1,1,1,1,1,1,1,1,1,1,1,1,1,1,1,1,1,1,1,1,1,1,1,1,1,1,1,1,1,1,1,1,1
1,1,1,1,1,1,1,1,1,1,1,1,1,1,1,1,1,1,1,1,1,1,1,1,1,1,1,1,1,1,1,1,1,1,1,1,1,1,1,1,1,1,1,1,1,1,1,1
1,1,1,1,1,1,1,1,1,1,1,1,1,1,1,1,1,1,1,1,1,1,1,1,1,1,1,1,1,1,1,1,1,1,1,1,1,1,1,1,1,1,1,1,1,1,1,1
1,1,1,1,1,1,1,1,1,1,1,1,1,1,1,1,1,1,1,1,1,1,1,1,1,1,1,1,1,1,1,1,1,1,1,1,1,1,1,1,1,1,1,1,1,1,1,1
endlayer

layer
1,1,1,1,1,3,3,4,4,3,3,1,1,1,1,1,1,1,1,1,1,3,3,4,4,3,3,1,1,1,1,1,1,1,1,1,1,3,3,4,4,3,3,1,1,1,1,1
1,1,1,1,1,3,4,4,4,4,3,1,1,1,1,1,1,1,1,1,1,3,4,4,4,4,3,1,1,1,1,1,1,1,1,1,1,3,4,4,4,4,3,1,1,1,1,1
1,1,1,1,1,3,4,4,4,4,3,1,1,1,1,1,1,1,1,1,1,3,4,4,4,4,3,1,1,1,1,1,1,1,1,1,1,3,4,4,4,4,3,1,1,1,1,1
1,1,1,5,3,3,3,4,4,3,3,3,5,1,1,1,1,1,1,5,3,3,3,4,4,3,3,3,5,1,1,1,1,1,1,5,3,3,3,4,4,3,3,3,5,1,1,1
1,1,1,3,4,4,4,4,4,4,4,4,3,1,1,1,1,1,1,3,4,4,4,4,4,4,4,4,3,1,1,1,1,1,1,3,4,4,4,4,4,4,4,4,3,1,1,1
3,3,3,3,4,4,4,4,4,4,4,4,3,3,3,3,3,3,3,3,4,4,4,4,4,4,4,4,3,3,3,3,3,3,3,3,4,4,4,4,4,4,4,4,3,3,3,3
3,4,4,3,4,4,7,7,7,6,4,4,3,4,4,3,3,4,4,3,4,4,7,7,7,6,4,4,3,4,4,3,3,4,4,3,4,4,7,7,7,6,4,4,3,4,4,3
4,4,4,4,4,4,8,0,0,6,4,4,4,4,4,4,4,4,4,4,4,4,8,0,0,6,4,4,4,4,4,4,4,4,4,4,4,4,8,0,0,6,4,4,4,4,4,4
4,4,4,4,4,4,8,0,0,6,4,4,4,4,4,4,4,4,4,4,4,4,8,0,0,6,4,4,4,4,4,4,4,4,4,4,4,4,8,0,0,6,4,4,4,4,4,4
3,4,4,3,4,4,8,9,9,9,4,4,3,4,4,3,3,4,4,3,4,4,8,9,9,9,4,4,3,4,4,3,3,4,4,3,4,4,8,9,9,9,4,4,3,4,4,3
3,3,3,3,4,4,4,4,4,4,4,4,3,3,3,3,3,3,3,3,4,4,4,4,4,4,4,4,3,3,3,3,3,3,3,3,4,4,4,4,4,4,4,4,3,3,3,3
1,1,1,3,4,4,4,4,4,4,4,4,3,2,2,2,2,2,2,3,4,4,4,4,4,4,4,4,3,2,2,2,2,2,2,3,4,4,4,4,4,4,4,4,3,1,1,1
1,1,1,5,3,3,3,4,4,3,3,3,5,2,2,2,2,2,2,5,3,3,3,4,4,3,3,3,5,2,2,2,2,2,2,5,3,3,3,4,4,3,3,3,5,1,1,1
1,1,1,1,1,3,4,4,4,4,3,2,2,2,2,2,2,2,2,2,2,8,4,4,4,4,6,2,2,2,2,2,2,2,2,2,2,3,4,4,4,4,3,1,1,1,1,1
1,1,1,1,1,3,4,4,4,4,3,2,2,2,2,2,2,2,2,2,2,8,4,4,4,4,6,2,2,2,2,2,2,2,2,2,2,3,4,4,4,4,3,1,1,1,1,1
1,1,1,1,1,3,3,4,4,3,3,2,2,2,2,5,5,2,2,2,2,3,3,4,4,3,3,2,2,2,2,5,5,2,2,2,2,3,3,4,4,3,3,1,1,1,1,1
1,1,1,1,1,3,3,4,4,3,3,2,2,2,2,5,5,2,2,2,2,3,3,4,4,3,3,2,2,2,2,5,5,2,2,2,2,3,3,4,4,3,3,1,1,1,1,1
1,1,1,1,1,3,4,4,4,4,3,2,2,2,2,2,2,2,2,2,2,8,4,4,4,4,6,2,2,2,2,2,2,2,2,2,2,3,4,4,4,4,3,1,1,1,1,1
1,1,1,1,1,3,4,4,4,4,3,2,2,2,2,2,2,2,2,2,2,8,4,4,4,4,6,2,2,2,2,2,2,2,2,2,2,3,4,4,4,4,3,1,1,1,1,1
1,1,1,5,3,3,3,4,4,3,3,3,5,2,2,2,2,2,2,5,3,3,3,4,4,3,3,3,5,2,2,2,2,2,2,5,3,3,3,4,4,3,3,3,5,1,1,1
1,1,1,3,4,4,4,4,4,4,4,4,3,2,2,2,2,2,2,3,4,4,4,4,4,4,4,4,3,2,2,2,2,2,2,3,4,4,4,4,4,4,4,4,3,1,1,1
3,3,3,3,4,4,4,4,4,4,4,4,3,7,7,3,3,7,7,3,4,4,4,4,4,4,4,4,3,7,7,3,3,7,7,3,4,4,4,4,4,4,4,4,3,3,3,3
3,4,4,3,4,4,7,7,7,6,4,4,3,4,4,3,3,4,4,3,4,4,11,10,10,10,4,4,3,4,4,3,3,4,4,3,4,4,7,7,7,6,4,4,3,4,4,3
4,4,4,4,4,4,8,0,0,6,4,4,4,4,4,4,4,4,4,4,4,4,11,2,2,12,4,4,4,4,4,4,4,4,4,4,4,4,8,0,0,6,4,4,4,4,4,4
4,4,4,4,4,4,8,0,0,6,4,4,4,4,4,4,4,4,4,4,4,4,11,2,2,12,4,4,4,4,4,4,4,4,4,4,4,4,8,0,0,6,4,4,4,4,4,4
3,4,4,3,4,4,8,9,9,9,4,4,3,4,4,3,3,4,4,3,4,4,13,13,13,12,4,4,3,4,4,3,3,4,4,3,4,4,8,9,9,9,4,4,3,4,4,3
3,3,3,3,4,4,4,4,4,4,4,4,3,9,9,3,3,9,9,3,4,4,4,4,4,4,4,4,3,9,9,3,3,9,9,3,4,4,4,4,4,4,4,4,3,3,3,3
1,1,1,3,4,4,4,4,4,4,4,4,3,2,2,2,2,2,2,3,4,4,4,4,4,4,4,4,3,2,2,2,2,2,2,3,4,4,4,4,4,4,4,4,3,1,1,1
1,1,1,5,3,3,3,4,4,3,3,3,5,2,2,2,2,2,2,5,3,3,3,4,4,3,3,3,5,2,2,2,2,2,2,5,3,3,3,4,4,3,3,3,5,1,1,1
1,1,1,1,1,3,4,4,4,4,3,2,2,2,2,2,2,2,2,2,2,8,4,4,4,4,6,2,2,2,2,2,2,2,2,2,2,3,4,4,4,4,3,1,1,1,1,1
1,1,1,1,1,3,4,4,4,4,3,2,2,2,2,2,2,2,2,2,2,8,4,4,4,4,6,2,2,2,2,2,2,2,2,2,2,3,4,4,4,4,3,1,1,1,1,1
1,1,1,1,1,3,3,4,4,3,3,2,2,2,2,5,5,2,2,2,2,3,3,4,4,3,3,2,2,2,2,5,5,2,2,2,2,3,3,4,4,3,3,1,1,1,1,1
1,1,1,1,1,3,3,4,4,3,3,2,2,2,2,5,5,2,2,2,2,3,3,4,4,3,3,2,2,2,2,5,5,2,2,2,2,3,3,4,4,3,3,1,1,1,1,1
1,1,1,1,1,3,4,4,4,4,3,2,2,2,2,2,2,2,2,2,2,8,4,4,4,4,6,2,2,2,2,2,2,2,2,2,2,3,4,4,4,4,3,1,1,1,1,1
1,1,1,1,1,3,4,4,4,4,3,2,2,2,2,2,2,2,2,2,2,8,4,4,4,4,6,2,2,2,2,2,2,2,2,2,2,3,4,4,4,4,3,1,1,1,1,1
1,1,1,5,3,3,3,4,4,3,3,3,5,2,2,2,2,2,2,5,3,3,3,4,4,3,3,3,5,2,2,2,2,2,2,5,3,3,3,4,4,3,3,3,5,1,1,1
1,1,1,3,4,4,4,4,4,4,4,4,3,2,2,2,2,2,2,3,4,4,4,4,4,4,4,4,3,2,2,2,2,2,2,3,4,4,4,4,4,4,4,4,3,1,1,1
3,3,3,3,4,4,4,4,4,4,4,4,3,3,3,3,3,3,3,3,4,4,4,4,4,4,4,4,3,3,3,3,3,3,3,3,4,4,4,4,4,4,4,4,3,3,3,3
3,4,4,3,4,4,7,7,7,6,4,4,3,4,4,3,3,4,4,3,4,4,7,7,7,6,4,4,3,4,4,3,3,4,4,3,4,4,7,7,7,6,4,4,3,4,4,3
4,4,4,4,4,4,8,0,0,6,4,4,4,4,4,4,4,4,4,4,4,4,8,0,0,6,4,4,4,4,4,4,4,4,4,4,4,4,8,0,0,6,4,4,4,4,4,4
4,4,4,4,4,4,8,0,0,6,4,4,4,4,4,4,4,4,4,4,4,4,8,0,0,6,4,4,4,4,4,4,4,4,4,4,4,4,8,0,0,6,4,4,4,4,4,4
3,4,4,3,4,4,8,9,9,9,4,4,3,4,4,3,3,4,4,3,4,4,8,9,9,9,4,4,3,4,4,3,3,4,4,3,4,4,8,9,9,9,4,4,3,4,4,3
3,3,3,3,4,4,4,4,4,4,4,4,3,3,3,3,3,3,3,3,4,4,4,4,4,4,4,4,3,3,3,3,3,3,3,3,4,4,4,4,4,4,4,4,3,3,3,3
1,1,1,3,4,4,4,4,4,4,4,4,3,1,1,1,1,1,1,3,4,4,4,4,4,4,4,4,3,1,1,1,1,1,1,3,4,4,4,4,4,4,4,4,3,1,1,1
1,1,1,5,3,3,3,4,4,3,3,3,5,1,1,1,1,1,1,5,3,3,3,4,4,3,3,3,5,1,1,1,1,1,1,5,3,3,3,4,4,3,3,3,5,1,1,1
1,1,1,1,1,3,4,4,4,4,3,1,1,1,1,1,1,1,1,1,1,3,4,4,4,4,3,1,1,1,1,1,1,1,1,1,1,3,4,4,4,4,3,1,1,1,1,1
1,1,1,1,1,3,4,4,4,4,3,1,1,1,1,1,1,1,1,1,1,3,4,4,4,4,3,1,1,1,1,1,1,1,1,1,1,3,4,4,4,4,3,1,1,1,1,1
1,1,1,1,1,3,3,4,4,3,3,1,1,1,1,1,1,1,1,1,1,3,3,4,4,3,3,1,1,1,1,1,1,1,1,1,1,3,3,4,4,3,3,1,1,1,1,1
endlayer

layer
1,1,1,1,1,3,3,7,7,3,3,1,1,1,1,1,1,1,1,1,1,3,3,7,7,3,3,1,1,1,1,1,1,1,1,1,1,3,3,7,7,3,3,1,1,1,1,1
1,1,1,1,1,3,14,15,15,14,3,1,1,1,1,1,1,1,1,1,1,3,14,15,15,14,3,1,1,1,1,1,1,1,1,1,1,3,14,15,15,14,3,1,1,1,1,1
1,1,1,1,1,3,15,15,15,15,3,1,1,1,1,1,1,1,1,1,1,3,15,15,15,15,3,1,1,1,1,1,1,1,1,1,1,3,15,15,15,15,3,1,1,1,1,1
1,1,1,16,3,3,3,15,15,3,3,3,16,1,1,1,1,1,1,16,3,3,3,15,15,3,3,3,16,1,1,1,1,1,1,16,3,3,3,15,15,3,3,3,16,1,1,1
1,1,1,3,17,19,15,15,15,15,18,17,3,1,1,1,1,1,1,3,17,19,15,15,15,15,18,17,3,1,1,1,1,1,1,3,17,19,15,15,15,15,18,17,3,1,1,1
3,3,3,3,20,15,15,15,15,15,15,20,3,3,3,3,3,3,3,3,20,15,15,15,15,15,15,20,3,3,3,3,3,3,3,3,20,15,15,15,15,15,15,20,3,3,3,3
3,14,15,3,15,15,0,0,0,0,15,15,3,15,14,3,3,14,15,3,15,15,0,0,0,0,15,15,3,15,14,3,3,14,15,3,15,15,0,0,0,0,15,15,3,15,14,3
8,15,15,15,15,15,0,0,0,0,15,15,15,15,15,11,12,15,15,15,15,15,0,0,0,0,15,15,15,15,15,11,12,15,15,15,15,15,0,0,0,0,15,15,15,15,15,6
8,15,15,15,15,15,0,0,0,0,15,15,15,15,15,11,12,15,15,15,15,15,0,0,0,0,15,15,15,15,15,11,12,15,15,15,15,15,0,0,0,0,15,15,15,15,15,6
3,14,15,3,15,15,0,0,0,0,15,15,3,15,14,3,3,14,15,3,15,15,0,0,0,0,15,15,3,15,14,3,3,14,15,3,15,15,0,0,0,0,15,15,3,15,14,3
3,3,3,3,21,15,15,15,15,15,15,21,3,3,3,22,22,3,3,3,21,15,15,15,15,15,15,21,3,3,3,22,22,3,3,3,21,15,15,15,15,15,15,21,3,3,3,3
1,1,1,3,17,19,15,15,15,15,18,17,3,23,24,0,24,24,23,3,17,19,15,15,15,15,18,17,3,23,24,0,24,24,23,3,17,19,15,15,15,15,18,17,3,1,1,1
1,1,1,16,3,3,3,15,15,3,3,3,16,0,23,24,24,23,0,16,3,3,3,10,10,3,3,3,16,0,23,24,24,23,0,16,3,3,3,15,15,3,3,3,16,1,1,1
1,1,1,1,1,3,15,15,15,15,3,23,0,23,24,24,24,24,23,0,23,0,15,25,25,15,0,23,0,23,24,24,0,24,23,0,23,3,15,15,15,15,3,1,1,1,1,1
1,1,1,1,1,3,14,15,15,14,3,24,23,0,24,24,24,24,24,23,24,0,15,25,25,15,0,24,23,24,24,24,24,24,24,23,24,3,14,15,15,14,3,1,1,1,1,1
1,1,1,1,1,3,3,10,10,3,27,24,24,24,24,6,9,24,24,24,24,3,3,15,15,3,3,24,24,24,24,6,9,24,24,24,24,26,3,10,10,3,3,1,1,1,1,1
1,1,1,1,1,3,3,13,13,3,27,24,0,24,24,7,8,24,24,24,24,3,3,15,15,3,3,24,24,24,24,7,8,24,24,24,24,26,3,13,13,3,3,1,1,1,1,1
1,1,1,1,1,3,14,15,15,14,3,24,23,24,24,24,24,24,24,23,24,0,15,25,25,15,0,24,23,24,24,24,0,24,24,23,24,3,14,15,15,14,3,1,1,1,1,1
1,1,1,1,1,3,15,15,15,15,3,23,0,23,24,24,24,24,23,0,23,0,15,25,25,15,0,23,0,23,24,24,24,24,23,0,23,3,15,15,15,15,3,1,1,1,1,1
1,1,1,16,3,3,3,15,15,3,3,3,16,0,23,24,24,23,0,16,3,3,3,15,15,3,3,3,16,0,23,24,24,23,0,16,3,3,3,15,15,3,3,3,16,1,1,1
1,1,1,3,17,19,15,15,15,15,18,17,3,23,24,24,24,24,23,3,17,19,15,25,25,15,18,17,3,23,24,24,24,24,23,3,17,19,15,15,15,15,18,17,3,1,1,1
3,3,3,3,20,15,15,15,15,15,15,20,3,0,0,3,3,0,0,3,20,25,10,25,25,10,25,20,3,0,0,3,3,0,0,3,20,15,15,15,15,15,15,20,3,3,3,3
3,14,15,3,15,15,0,0,0,0,15,15,3,15,15,3,3,15,15,3,15,11,28,12,11,28,12,15,3,15,15,3,3,15,15,3,15,15,0,0,0,0,15,15,3,15,14,3
8,15,15,15,15,15,0,0,0,0,15,15,11,25,25,15,15,25,25,15,25,25,13,24,24,13,25,25,15,25,25,15,15,25,25,12,15,15,0,0,0,0,15,15,15,15,15,6
8,15,15,15,15,15,0,0,0,0,15,15,11,25,25,15,15,25,25,15,25,25,10,24,24,10,25,25,15,25,25,15,15,25,25,12,15,15,0,0,0,0,15,15,15,15,15,6
3,14,15,3,15,15,0,0,0,0,15,15,3,15,15,3,3,15,15,3,15,11,28,12,11,28,12,15,3,15,15,3,3,15,15,3,15,15,0,0,0,0,15,15,3,15,14,3
3,3,3,3,21,15,15,15,15,15,15,21,3,0,0,3,3,0,0,3,21,25,13,25,25,13,25,21,3,0,0,3,3,0,0,3,21,15,15,15,15,15,15,21,3,3,3,3
1,1,1,3,17,19,15,15,15,15,18,17,3,23,24,24,24,24,23,3,17,19,15,25,25,15,18,17,3,23,24,24,24,24,23,3,17,19,15,15,15,15,18,17,3,1,1,1
1,1,1,16,3,3,3,15,15,3,3,3,16,0,23,24,24,23,0,16,3,3,3,15,15,3,3,3,16,0,23,24,24,23,0,16,3,3,3,15,15,3,3,3,16,1,1,1
1,1,1,1,1,3,15,15,15,15,3,23,0,23,24,24,24,24,23,0,23,0,15,25,25,15,0,23,0,23,24,24,24,24,23,0,23,3,15,15,15,15,3,1,1,1,1,1
1,1,1,1,1,3,14,15,15,14,3,24,23,24,24,24,24,24,24,23,24,0,15,25,25,15,0,24,23,24,24,24,24,24,24,23,24,3,14,15,15,14,3,1,1,1,1,1
1,1,1,1,1,3,3,10,10,3,27,24,24,24,24,6,9,24,24,24,24,3,3,15,15,3,3,24,24,24,24,6,9,24,24,24,24,29,3,10,10,3,3,1,1,1,1,1
1,1,1,1,1,3,3,13,13,3,27,24,24,24,24,7,8,24,24,24,24,3,3,15,15,3,3,24,24,24,24,7,8,24,24,24,24,29,3,13,13,3,3,1,1,1,1,1
1,1,1,1,1,3,14,15,15,14,3,24,23,24,24,24,24,24,24,23,24,0,15,25,25,15,0,24,23,24,24,24,24,24,24,23,24,3,14,15,15,14,3,1,1,1,1,1
1,1,1,1,1,3,15,15,15,15,3,23,0,23,24,24,24,0,23,0,23,0,15,25,25,15,0,23,0,23,24,24,24,24,23,0,23,3,15,15,15,15,3,1,1,1,1,1
1,1,1,16,3,3,3,15,15,3,3,3,16,0,23,24,24,23,0,16,3,3,3,13,13,3,3,3,16,0,23,24,24,23,0,16,3,3,3,15,15,3,3,3,16,1,1,1
1,1,1,3,17,19,15,15,15,15,18,17,3,23,24,24,24,24,23,3,17,19,15,15,15,15,18,17,3,23,24,24,24,24,23,3,17,19,15,15,15,15,18,17,3,1,1,1
3,3,3,3,20,15,15,15,15,15,15,20,3,3,3,31,31,3,3,3,20,15,15,15,15,15,15,20,3,3,3,30,30,3,3,3,20,15,15,15,15,15,15,20,3,3,3,3
3,14,15,3,15,15,0,0,0,0,15,15,3,15,14,3,3,14,15,3,15,15,0,0,0,0,15,15,3,15,14,3,3,14,15,3,15,15,0,0,0,0,15,15,3,15,14,3
8,15,15,15,15,15,0,0,0,0,15,15,15,15,15,11,12,15,15,15,15,15,0,0,0,0,15,15,15,15,15,11,12,15,15,15,15,15,0,0,0,0,15,15,15,15,15,6
8,15,15,15,15,15,0,0,0,0,15,15,15,15,15,11,12,15,15,15,15,15,0,0,0,0,15,15,15,15,15,11,12,15,15,15,15,15,0,0,0,0,15,15,15,15,15,6
3,14,15,3,15,15,0,0,0,0,15,15,3,15,14,3,3,14,15,3,15,15,0,0,0,0,15,15,3,15,14,3,3,14,15,3,15,15,0,0,0,0,15,15,3,15,14,3
3,3,3,3,21,15,15,15,15,15,15,21,3,3,3,3,3,3,3,3,21,15,15,15,15,15,15,21,3,3,3,3,3,3,3,3,21,15,15,15,15,15,15,21,3,3,3,3
1,1,1,3,17,19,15,15,15,15,18,17,3,1,1,1,1,1,1,3,17,19,15,15,15,15,18,17,3,1,1,1,1,1,1,3,17,19,15,15,15,15,18,17,3,1,1,1
1,1,1,16,3,3,3,15,15,3,3,3,16,1,1,1,1,1,1,16,3,3,3,15,15,3,3,3,16,1,1,1,1,1,1,16,3,3,3,15,15,3,3,3,16,1,1,1
1,1,1,1,1,3,15,15,15,15,3,1,1,1,1,1,1,1,1,1,1,3,15,15,15,15,3,1,1,1,1,1,1,1,1,1,1,3,15,15,15,15,3,1,1,1,1,1
1,1,1,1,1,3,14,15,15,14,3,1,1,1,1,1,1,1,1,1,1,3,14,15,15,14,3,1,1,1,1,1,1,1,1,1,1,3,14,15,15,14,3,1,1,1,1,1
1,1,1,1,1,3,3,9,9,3,3,1,1,1,1,1,1,1,1,1,1,3,3,9,9,3,3,1,1,1,1,1,1,1,1,1,1,3,3,9,9,3,3,1,1,1,1,1
endlayer

layer
1,1,1,1,1,3,14,32,32,14,3,1,1,1,1,1,1,1,1,1,1,3,14,32,32,14,3,1,1,1,1,1,1,1,1,1,1,3,14,32,32,14,3,1,1,1,1,1
1,1,1,1,1,8,33,0,0,33,6,1,1,1,1,1,1,1,1,1,1,8,33,0,0,33,6,1,1,1,1,1,1,1,1,1,1,8,33,0,0,33,6,1,1,1,1,1
1,1,1,1,1,8,0,0,0,0,6,1,1,1,1,1,1,1,1,1,1,8,0,0,0,0,6,1,1,1,1,1,1,1,1,1,1,8,0,0,0,0,6,1,1,1,1,1
1,1,1,16,3,3,14,0,0,14,3,3,16,1,1,1,1,1,1,16,3,3,14,0,0,14,3,3,16,1,1,1,1,1,1,16,3,3,14,0,0,14,3,3,16,1,1,1
1,1,1,3,17,0,0,0,0,0,0,17,3,1,1,1,1,1,1,3,17,0,0,0,0,0,0,17,3,1,1,1,1,1,1,3,17,0,0,0,0,0,0,17,3,1,1,1
3,7,7,3,0,0,0,0,0,0,0,0,3,7,7,3,3,7,7,3,0,0,0,0,0,0,0,0,3,7,7,3,3,7,7,3,0,0,0,0,0,0,0,0,3,7,7,3
14,33,0,14,0,0,0,0,0,0,0,0,14,0,33,14,14,33,0,14,0,0,0,0,0,0,0,0,14,0,33,14,14,33,0,14,0,0,0,0,0,0,0,0,14,0,33,14
32,0,0,0,0,0,0,0,0,0,0,0,0,0,0,34,0,0,0,0,0,0,0,0,0,0,0,0,0,0,0,0,34,0,0,0,0,0,0,0,0,0,0,0,0,0,0,32
32,0,0,0,0,0,0,0,0,0,0,0,0,0,0,35,0,0,0,0,0,0,0,0,0,0,0,0,0,0,0,0,34,0,0,0,0,0,0,0,0,0,0,0,0,0,0,32
14,33,0,14,0,0,0,0,0,0,0,0,14,0,33,14,14,33,0,14,0,0,0,0,0,0,0,0,14,0,33,14,14,33,0,14,0,0,0,0,0,0,0,0,14,0,33,14
3,9,9,3,0,0,0,0,0,0,0,0,3,9,9,36,36,9,9,3,0,0,0,0,0,0,0,0,3,9,9,36,36,9,9,3,0,0,0,0,0,0,0,0,3,9,9,3
1,1,1,3,17,0,0,0,0,0,0,17,3,23,0,0,0,0,23,3,17,0,0,0,0,0,0,17,3,23,0,0,0,0,23,3,17,0,0,0,0,0,0,17,3,1,1,1
1,1,1,16,3,3,14,0,0,14,3,3,16,38,23,0,0,23,37,16,3,3,14,39,39,14,3,3,16,38,23,0,0,23,37,16,3,3,14,0,0,14,3,3,16,1,1,1
1,1,1,1,1,8,0,0,0,0,6,23,36,23,0,0,0,0,23,36,23,0,0,0,0,0,0,23,36,23,0,0,0,0,23,36,23,8,0,0,0,0,6,1,1,1,1,1
1,1,1,1,1,8,33,0,0,33,6,0,23,0,0,0,0,0,0,23,0,0,0,0,0,0,0,0,23,0,0,0,0,0,0,23,0,8,33,0,0,33,6,1,1,1,1,1
1,1,1,1,1,3,14,40,40,14,38,0,0,0,0,37,41,0,0,0,0,3,14,0,0,14,3,0,0,0,0,37,41,0,0,0,0,37,14,39,40,14,3,1,1,1,1,1
1,1,1,1,1,3,14,0,0,14,38,0,0,0,0,36,38,0,0,0,0,3,14,0,0,14,3,0,0,0,0,36,38,0,0,0,0,37,14,0,0,14,3,1,1,1,1,1
1,1,1,1,1,8,33,0,0,33,6,0,23,0,0,0,0,0,0,23,0,0,0,0,0,0,0,0,23,0,0,0,0,0,0,23,0,8,33,0,0,33,6,1,1,1,1,1
1,1,1,1,1,8,0,0,0,0,6,23,41,23,0,0,0,0,23,41,23,0,0,0,0,0,0,23,41,23,0,0,0,0,23,41,23,8,0,0,0,0,6,1,1,1,1,1
1,1,1,16,3,3,14,0,0,14,3,3,16,38,23,0,0,23,37,16,3,3,14,0,0,14,3,3,16,38,23,0,0,23,37,16,3,3,14,0,0,14,3,3,16,1,1,1
1,1,1,3,17,0,0,0,0,0,0,17,3,23,0,0,0,0,23,3,17,0,0,0,0,0,0,17,3,23,0,0,0,0,23,3,17,0,0,0,0,0,0,17,3,1,1,1
3,7,7,3,0,0,0,0,0,0,0,0,3,0,0,3,3,0,0,3,0,0,0,0,0,0,0,0,3,0,0,3,3,0,0,3,0,0,0,0,0,0,0,0,3,7,7,3
14,33,0,14,0,0,0,0,0,0,0,0,14,0,0,14,14,0,0,14,0,0,42,0,0,42,0,0,14,0,0,14,14,0,0,14,0,0,0,0,0,0,0,0,14,0,33,14
32,0,0,0,0,0,0,0,0,0,0,0,34,0,0,0,0,0,0,0,0,0,0,0,0,0,0,0,0,0,0,0,0,0,0,35,0,0,0,0,0,0,0,0,0,0,0,32
32,0,0,0,0,0,0,0,0,0,0,0,34,0,0,0,0,0,0,0,0,0,0,0,0,0,0,0,0,0,0,0,0,0,0,34,0,0,0,0,0,0,0,0,0,0,0,32
14,33,0,14,0,0,0,0,0,0,0,0,14,0,0,14,14,0,0,14,0,0,42,0,0,42,0,0,14,0,0,14,14,0,0,14,0,0,0,0,0,0,0,0,14,0,33,14
3,9,9,3,0,0,0,0,0,0,0,0,3,0,0,3,3,0,0,3,0,0,0,0,0,0,0,0,3,0,0,3,3,0,0,3,0,0,0,0,0,0,0,0,3,9,9,3
1,1,1,3,17,0,0,0,0,0,0,17,3,23,0,0,0,0,23,3,17,0,0,0,0,0,0,17,3,23,0,0,0,0,23,3,17,0,0,0,0,0,0,17,3,1,1,1
1,1,1,16,3,3,14,0,0,14,3,3,16,38,23,0,0,23,37,16,3,3,14,0,0,14,3,3,16,38,23,0,0,23,37,16,3,3,14,0,0,14,3,3,16,1,1,1
1,1,1,1,1,8,0,0,0,0,6,23,36,23,0,0,0,0,23,36,23,0,0,0,0,0,0,23,36,23,0,0,0,0,23,36,23,8,0,0,0,0,6,1,1,1,1,1
1,1,1,1,1,8,33,0,0,33,6,0,23,0,0,0,0,0,0,23,0,0,0,0,0,0,0,0,23,0,0,0,0,0,0,23,0,8,33,0,0,33,6,1,1,1,1,1
1,1,1,1,1,3,14,0,0,14,38,0,0,0,0,37,41,0,0,0,0,3,14,0,0,14,3,0,0,0,0,37,41,0,0,0,0,37,14,0,0,14,3,1,1,1,1,1
1,1,1,1,1,3,14,39,40,14,38,0,0,0,0,36,38,0,0,0,0,3,14,0,0,14,3,0,0,0,0,36,38,0,0,0,0,37,14,39,39,14,3,1,1,1,1,1
1,1,1,1,1,8,33,0,0,33,6,0,23,0,0,0,0,0,0,23,0,0,0,0,0,0,0,0,23,0,0,0,0,0,0,23,0,8,33,0,0,33,6,1,1,1,1,1
1,1,1,1,1,8,0,0,0,0,6,23,41,23,0,0,0,0,23,41,23,0,0,0,0,0,0,23,41,23,0,0,0,0,23,41,23,8,0,0,0,0,6,1,1,1,1,1
1,1,1,16,3,3,14,0,0,14,3,3,16,38,23,0,0,23,37,16,3,3,14,40,40,14,3,3,16,38,23,0,0,23,37,16,3,3,14,0,0,14,3,3,16,1,1,1
1,1,1,3,17,0,0,0,0,0,0,17,3,23,0,0,0,0,23,3,17,0,0,0,0,0,0,17,3,23,0,0,0,0,23,3,17,0,0,0,0,0,0,17,3,1,1,1
3,7,7,3,0,0,0,0,0,0,0,0,3,7,7,41,41,7,7,3,0,0,0,0,0,0,0,0,3,7,7,41,41,7,7,3,0,0,0,0,0,0,0,0,3,7,7,3
14,33,0,14,0,0,0,0,0,0,0,0,14,0,33,14,14,33,0,14,0,0,0,0,0,0,0,0,14,0,33,14,14,33,0,14,0,0,0,0,0,0,0,0,14,0,33,14
32,0,0,0,0,0,0,0,0,0,0,0,0,0,0,35,0,0,0,0,0,0,0,0,0,0,0,0,0,0,0,0,35,0,0,0,0,0,0,0,0,0,0,0,0,0,0,32
32,0,0,0,0,0,0,0,0,0,0,0,0,0,0,35,0,0,0,0,0,0,0,0,0,0,0,0,0,0,0,0,34,0,0,0,0,0,0,0,0,0,0,0,0,0,0,32
14,33,0,14,0,0,0,0,0,0,0,0,14,0,33,14,14,33,0,14,0,0,0,0,0,0,0,0,14,0,33,14,14,33,0,14,0,0,0,0,0,0,0,0,14,0,33,14
3,9,9,3,0,0,0,0,0,0,0,0,3,9,9,3,3,9,9,3,0,0,0,0,0,0,0,0,3,9,9,3,3,9,9,3,0,0,0,0,0,0,0,0,3,9,9,3
1,1,1,3,17,0,0,0,0,0,0,17,3,1,1,1,1,1,1,3,17,0,0,0,0,0,0,17,3,1,1,1,1,1,1,3,17,0,0,0,0,0,0,17,3,1,1,1
1,1,1,16,3,3,14,0,0,14,3,3,16,1,1,1,1,1,1,16,3,3,14,0,0,14,3,3,16,1,1,1,1,1,1,16,3,3,14,0,0,14,3,3,16,1,1,1
1,1,1,1,1,8,0,0,0,0,6,1,1,1,1,1,1,1,1,1,1,8,0,0,0,0,6,1,1,1,1,1,1,1,1,1,1,8,0,0,0,0,6,1,1,1,1,1
1,1,1,1,1,8,33,0,0,33,6,1,1,1,1,1,1,1,1,1,1,8,33,0,0,33,6,1,1,1,1,1,1,1,1,1,1,8,33,0,0,33,6,1,1,1,1,1
1,1,1,1,1,3,14,32,32,14,3,1,1,1,1,1,1,1,1,1,1,3,14,32,32,14,3,1,1,1,1,1,1,1,1,1,1,3,14,32,32,14,3,1,1,1,1,1
endlayer

layer
1,1,1,1,1,3,38,32,32,37,3,1,1,1,1,1,1,1,1,1,1,3,38,32,32,37,3,1,1,1,1,1,1,1,1,1,1,3,38,32,32,37,3,1,1,1,1,1
1,1,1,1,1,38,0,0,0,0,37,1,1,1,1,1,1,1,1,1,1,38,0,0,0,0,37,1,1,1,1,1,1,1,1,1,1,38,0,0,0,0,37,1,1,1,1,1
1,1,1,1,1,38,0,0,0,0,37,1,1,1,1,1,1,1,1,1,1,38,0,0,0,0,37,1,1,1,1,1,1,1,1,1,1,38,0,0,0,0,37,1,1,1,1,1
1,1,1,16,3,3,14,0,0,14,3,3,16,1,1,1,1,1,1,16,3,3,14,0,0,14,3,3,16,1,1,1,1,1,1,16,3,3,14,0,0,14,3,3,16,1,1,1
1,1,1,3,17,0,0,0,0,0,0,17,3,1,1,1,1,1,1,3,17,0,0,0,0,0,0,17,3,1,1,1,1,1,1,3,17,0,0,0,0,0,0,17,3,1,1,1
3,36,36,3,0,0,0,0,0,0,0,0,3,36,36,3,3,36,36,3,0,0,0,0,0,0,0,0,3,36,36,3,3,36,36,3,0,0,0,0,0,0,0,0,3,36,36,3
36,0,0,14,0,0,0,0,0,0,0,0,14,0,0,36,36,0,0,14,0,0,0,0,0,0,0,0,14,0,0,36,36,0,0,14,0,0,0,0,0,0,0,0,14,0,0,36
32,0,0,0,0,0,0,0,0,0,0,0,0,0,0,0,0,0,0,0,0,0,0,0,0,0,0,0,0,0,0,0,0,0,0,0,0,0,0,0,0,0,0,0,0,0,0,32
32,0,0,0,0,0,0,0,0,0,0,0,0,0,0,0,0,0,0,0,0,0,0,0,0,0,0,0,0,0,0,0,0,0,0,0,0,0,0,0,0,0,0,0,0,0,0,32
41,0,0,14,0,0,0,0,0,0,0,0,14,0,0,41,41,0,0,14,0,0,0,0,0,0,0,0,14,0,0,41,41,0,0,14,0,0,0,0,0,0,0,0,14,0,0,41
3,41,41,3,0,0,0,0,0,0,0,0,3,41,41,3,3,41,41,3,0,0,0,0,0,0,0,0,3,41,41,3,3,41,41,3,0,0,0,0,0,0,0,0,3,41,41,3
1,1,1,3,17,0,0,0,0,0,0,17,3,43,0,36,36,0,43,3,17,0,0,0,0,0,0,17,3,43,0,36,36,0,43,3,17,0,0,0,0,0,0,17,3,1,1,1
1,1,1,16,3,3,14,0,0,14,3,3,2,44,43,0,0,43,44,2,3,3,14,0,0,14,3,3,2,44,43,0,0,43,44,2,3,3,14,0,0,14,3,3,16,1,1,1
1,1,1,1,1,38,0,0,0,0,37,43,44,43,0,0,0,0,43,44,43,0,0,0,0,0,0,43,44,43,0,0,0,0,43,44,43,38,0,0,0,0,37,1,1,1,1,1
1,1,1,1,1,38,0,0,0,0,37,0,43,0,0,0,0,0,0,43,0,0,0,0,0,0,0,0,43,0,0,0,0,0,0,43,0,38,0,0,0,0,37,1,1,1,1,1
1,1,1,1,1,3,38,0,0,37,3,38,0,0,0,45,32,0,0,0,37,3,38,0,0,37,3,38,0,0,0,32,45,0,0,0,37,3,38,0,0,37,3,1,1,1,1,1
1,1,1,1,1,3,38,0,0,37,3,38,0,0,0,32,32,0,0,0,37,3,38,0,0,37,3,38,0,0,0,32,32,0,0,0,37,3,38,0,0,37,3,1,1,1,1,1
1,1,1,1,1,38,0,0,0,0,37,0,43,0,0,0,0,0,0,43,0,0,0,0,0,0,0,0,43,0,0,0,0,0,0,43,0,38,0,0,0,0,37,1,1,1,1,1
1,1,1,1,1,38,0,0,0,0,37,43,44,43,0,0,0,0,43,44,43,0,0,0,0,0,0,43,44,43,0,0,0,0,43,44,43,38,0,0,0,0,37,1,1,1,1,1
1,1,1,16,3,3,14,0,0,14,3,3,2,44,43,0,0,43,44,2,3,3,14,0,0,14,3,3,2,44,43,0,0,43,44,2,3,3,14,0,0,14,3,3,16,1,1,1
1,1,1,3,17,0,0,0,0,0,0,17,3,43,0,41,41,0,43,3,17,0,0,0,0,0,0,17,3,43,0,41,41,0,43,3,17,0,0,0,0,0,0,17,3,1,1,1
3,36,36,3,0,0,0,0,0,0,0,0,3,0,0,3,3,0,0,3,0,0,0,0,0,0,0,0,3,0,0,3,3,0,0,3,0,0,0,0,0,0,0,0,3,36,36,3
36,0,0,14,0,0,0,0,0,0,0,0,14,0,0,36,36,0,0,14,0,0,0,0,0,0,0,0,14,0,0,36,36,0,0,14,0,0,0,0,0,0,0,0,14,0,0,36
32,0,0,0,0,0,0,0,0,0,0,0,0,0,0,0,0,0,0,0,0,0,0,0,0,0,0,0,0,0,0,0,0,0,0,0,0,0,0,0,0,0,0,0,0,0,0,32
32,0,0,0,0,0,0,0,0,0,0,0,0,0,0,0,0,0,0,0,0,0,0,0,0,0,0,0,0,0,0,0,0,0,0,0,0,0,0,0,0,0,0,0,0,0,0,32
41,0,0,14,0,0,0,0,0,0,0,0,14,0,0,41,41,0,0,14,0,0,0,0,0,0,0,0,14,0,0,41,41,0,0,14,0,0,0,0,0,0,0,0,14,0,0,41
3,41,41,3,0,0,0,0,0,0,0,0,3,0,0,3,3,0,0,3,0,0,0,0,0,0,0,0,3,0,0,3,3,0,0,3,0,0,0,0,0,0,0,0,3,41,41,3
1,1,1,3,17,0,0,0,0,0,0,17,3,43,0,36,36,0,43,3,17,0,0,0,0,0,0,17,3,43,0,36,36,0,43,3,17,0,0,0,0,0,0,17,3,1,1,1
1,1,1,16,3,3,14,0,0,14,3,3,2,44,43,0,0,43,44,2,3,3,14,0,0,14,3,3,2,44,43,0,0,43,44,2,3,3,14,0,0,14,3,3,16,1,1,1
1,1,1,1,1,38,0,0,0,0,37,43,44,43,0,0,0,0,43,44,43,0,0,0,0,0,0,43,44,43,0,0,0,0,43,44,43,38,0,0,0,0,37,1,1,1,1,1
1,1,1,1,1,38,0,0,0,0,37,0,43,0,0,0,0,0,0,43,0,0,0,0,0,0,0,0,43,0,0,0,0,0,0,43,0,38,0,0,0,0,37,1,1,1,1,1
1,1,1,1,1,3,38,0,0,37,3,38,0,0,0,32,32,0,0,0,37,3,38,0,0,37,3,38,0,0,0,32,32,0,0,0,37,3,38,0,0,37,3,1,1,1,1,1
1,1,1,1,1,3,38,0,0,37,3,38,0,0,0,45,32,0,0,0,37,3,38,0,0,37,3,38,0,0,0,32,45,0,0,0,37,3,38,0,0,37,3,1,1,1,1,1
1,1,1,1,1,38,0,0,0,0,37,0,43,0,0,0,0,0,0,43,0,0,0,0,0,0,0,0,43,0,0,0,0,0,0,43,0,38,0,0,0,0,37,1,1,1,1,1
1,1,1,1,1,38,0,0,0,0,37,43,44,43,0,0,0,0,43,44,43,0,0,0,0,0,0,43,44,43,0,0,0,0,43,44,43,38,0,0,0,0,37,1,1,1,1,1
1,1,1,16,3,3,14,0,0,14,3,3,2,44,43,0,0,43,44,2,3,3,14,0,0,14,3,3,2,44,43,0,0,43,44,2,3,3,14,0,0,14,3,3,16,1,1,1
1,1,1,3,17,0,0,0,0,0,0,17,3,43,0,41,41,0,43,3,17,0,0,0,0,0,0,17,3,43,0,41,41,0,43,3,17,0,0,0,0,0,0,17,3,1,1,1
3,36,36,3,0,0,0,0,0,0,0,0,3,36,36,3,3,36,36,3,0,0,0,0,0,0,0,0,3,36,36,3,3,36,36,3,0,0,0,0,0,0,0,0,3,36,36,3
36,0,0,14,0,0,0,0,0,0,0,0,14,0,0,36,36,0,0,14,0,0,0,0,0,0,0,0,14,0,0,36,36,0,0,14,0,0,0,0,0,0,0,0,14,0,0,36
32,0,0,0,0,0,0,0,0,0,0,0,0,0,0,0,0,0,0,0,0,0,0,0,0,0,0,0,0,0,0,0,0,0,0,0,0,0,0,0,0,0,0,0,0,0,0,32
32,0,0,0,0,0,0,0,0,0,0,0,0,0,0,0,0,0,0,0,0,0,0,0,0,0,0,0,0,0,0,0,0,0,0,0,0,0,0,0,0,0,0,0,0,0,0,32
41,0,0,14,0,0,0,0,0,0,0,0,14,0,0,41,41,0,0,14,0,0,0,0,0,0,0,0,14,0,0,41,41,0,0,14,0,0,0,0,0,0,0,0,14,0,0,41
3,41,41,3,0,0,0,0,0,0,0,0,3,41,41,3,3,41,41,3,0,0,0,0,0,0,0,0,3,41,41,3,3,41,41,3,0,0,0,0,0,0,0,0,3,41,41,3
1,1,1,3,17,0,0,0,0,0,0,17,3,1,1,1,1,1,1,3,17,0,0,0,0,0,0,17,3,1,1,1,1,1,1,3,17,0,0,0,0,0,0,17,3,1,1,1
1,1,1,16,3,3,14,0,0,14,3,3,16,1,1,1,1,1,1,16,3,3,14,0,0,14,3,3,16,1,1,1,1,1,1,16,3,3,14,0,0,14,3,3,16,1,1,1
1,1,1,1,1,38,0,0,0,0,37,1,1,1,1,1,1,1,1,1,1,38,0,0,0,0,37,1,1,1,1,1,1,1,1,1,1,38,0,0,0,0,37,1,1,1,1,1
1,1,1,1,1,38,0,0,0,0,37,1,1,1,1,1,1,1,1,1,1,38,0,0,0,0,37,1,1,1,1,1,1,1,1,1,1,38,0,0,0,0,37,1,1,1,1,1
1,1,1,1,1,3,38,32,32,37,3,1,1,1,1,1,1,1,1,1,1,3,38,32,32,37,3,1,1,1,1,1,1,1,1,1,1,3,38,32,32,37,3,1,1,1,1,1
endlayer

layer
1,1,1,1,1,3,3,38,37,3,3,1,1,1,1,1,1,1,1,1,1,3,3,38,37,3,3,1,1,1,1,1,1,1,1,1,1,3,3,38,37,3,3,1,1,1,1,1
1,1,1,1,1,3,0,0,0,0,3,1,1,1,1,1,1,1,1,1,1,3,0,0,0,0,3,1,1,1,1,1,1,1,1,1,1,3,0,0,0,0,3,1,1,1,1,1
1,1,1,1,1,3,0,0,0,0,3,1,1,1,1,1,1,1,1,1,1,3,0,0,0,0,3,1,1,1,1,1,1,1,1,1,1,3,0,0,0,0,3,1,1,1,1,1
1,1,1,16,3,3,14,0,0,14,3,3,16,1,1,1,1,1,1,16,3,3,14,0,0,14,3,3,16,1,1,1,1,1,1,16,3,3,14,0,0,14,3,3,16,1,1,1
1,1,1,3,17,47,0,0,0,0,46,17,3,1,1,1,1,1,1,3,17,47,0,0,0,0,46,17,3,1,1,1,1,1,1,3,17,47,0,0,0,0,46,17,3,1,1,1
3,3,3,3,48,49,0,0,0,0,49,48,3,3,3,3,3,3,3,3,48,49,0,0,0,0,49,48,3,3,3,3,3,3,3,3,48,49,0,0,0,0,49,48,3,3,3,3
3,0,0,14,0,0,0,0,0,0,0,0,14,0,0,3,3,0,0,14,0,0,0,0,0,0,0,0,14,0,0,3,3,0,0,14,0,0,0,0,0,0,0,0,14,0,0,3
36,0,0,0,0,0,0,0,0,0,0,0,0,0,0,36,36,0,0,0,0,0,0,0,0,0,0,0,0,0,0,36,36,0,0,0,0,0,0,0,0,0,0,0,0,0,0,36
41,0,0,0,0,0,0,0,0,0,0,0,0,0,0,41,41,0,0,0,0,0,0,0,0,0,0,0,0,0,0,41,41,0,0,0,0,0,0,0,0,0,0,0,0,0,0,41
3,0,0,14,0,0,0,0,0,0,0,0,14,0,0,3,3,0,0,14,0,0,0,0,0,0,0,0,14,0,0,3,3,0,0,14,0,0,0,0,0,0,0,0,14,0,0,3
3,3,3,3,50,49,0,0,0,0,49,50,3,3,3,3,3,3,3,3,50,49,0,0,0,0,49,50,3,3,3,3,3,3,3,3,50,49,0,0,0,0,49,50,3,3,3,3
1,1,1,3,17,47,0,0,0,0,46,17,3,3,3,3,3,3,3,3,17,47,0,0,0,0,46,17,3,3,3,3,3,3,3,3,17,47,0,0,0,0,46,17,3,1,1,1
1,1,1,16,3,3,14,0,0,14,3,3,16,3,3,3,3,3,3,16,3,3,14,0,0,14,3,3,16,3,3,3,3,3,3,16,3,3,14,0,0,14,3,3,16,1,1,1
1,1,1,1,1,3,0,0,0,0,3,3,3,3,36,36,36,37,3,3,3,38,0,0,0,0,37,3,3,3,36,36,36,37,3,3,3,3,0,0,0,0,3,1,1,1,1,1
1,1,1,1,1,3,0,0,0,0,3,3,3,36,38,0,0,36,37,3,3,38,0,0,0,0,37,3,3,36,38,0,0,36,37,3,3,3,0,0,0,0,3,1,1,1,1,1
1,1,1,1,1,3,3,38,37,3,3,3,3,38,0,0,0,0,37,3,3,3,3,38,37,3,3,3,3,38,0,0,0,0,37,3,3,3,3,38,37,3,3,1,1,1,1,1
1,1,1,1,1,3,3,38,37,3,3,3,3,38,0,0,0,0,37,3,3,3,3,38,37,3,3,3,3,38,0,0,0,0,37,3,3,3,3,38,37,3,3,1,1,1,1,1
1,1,1,1,1,3,0,0,0,0,3,3,3,38,41,0,0,37,41,3,3,38,0,0,0,0,37,3,3,38,41,0,0,37,41,3,3,3,0,0,0,0,3,1,1,1,1,1
1,1,1,1,1,3,0,0,0,0,3,3,3,3,38,41,41,41,3,3,3,38,0,0,0,0,37,3,3,3,38,41,41,41,3,3,3,3,0,0,0,0,3,1,1,1,1,1
1,1,1,16,3,3,14,0,0,14,3,3,16,3,3,3,3,3,3,16,3,3,14,0,0,14,3,3,16,3,3,3,3,3,3,16,3,3,14,0,0,14,3,3,16,1,1,1
1,1,1,3,17,47,0,0,0,0,46,17,3,3,3,3,3,3,3,3,17,47,0,0,0,0,46,17,3,3,3,3,3,3,3,3,17,47,0,0,0,0,46,17,3,1,1,1
3,3,3,3,48,49,0,0,0,0,49,48,3,36,36,3,3,36,36,3,48,49,0,0,0,0,49,48,3,36,36,3,3,36,36,3,48,49,0,0,0,0,49,48,3,3,3,3
3,0,0,14,0,0,0,0,0,0,0,0,14,0,0,3,3,0,0,14,0,0,0,0,0,0,0,0,14,0,0,3,3,0,0,14,0,0,0,0,0,0,0,0,14,0,0,3
36,0,0,0,0,0,0,0,0,0,0,0,0,0,0,36,36,0,0,0,0,0,0,0,0,0,0,0,0,0,0,36,36,0,0,0,0,0,0,0,0,0,0,0,0,0,0,36
41,0,0,0,0,0,0,0,0,0,0,0,0,0,0,41,41,0,0,0,0,0,0,0,0,0,0,0,0,0,0,41,41,0,0,0,0,0,0,0,0,0,0,0,0,0,0,41
3,0,0,14,0,0,0,0,0,0,0,0,14,0,0,3,3,0,0,14,0,0,0,0,0,0,0,0,14,0,0,3,3,0,0,14,0,0,0,0,0,0,0,0,14,0,0,3
3,3,3,3,50,49,0,0,0,0,49,50,3,41,41,3,3,41,41,3,50,49,0,0,0,0,49,50,3,41,41,3,3,41,41,3,50,49,0,0,0,0,49,50,3,3,3,3
1,1,1,3,17,47,0,0,0,0,46,17,3,3,3,3,3,3,3,3,17,47,0,0,0,0,46,17,3,3,3,3,3,3,3,3,17,47,0,0,0,0,46,17,3,1,1,1
1,1,1,16,3,3,14,0,0,14,3,3,16,3,3,3,3,3,3,16,3,3,14,0,0,14,3,3,16,3,3,3,3,3,3,16,3,3,14,0,0,14,3,3,16,1,1,1
1,1,1,1,1,3,0,0,0,0,3,3,3,3,36,36,36,37,3,3,3,38,0,0,0,0,37,3,3,3,36,36,36,37,3,3,3,3,0,0,0,0,3,1,1,1,1,1
1,1,1,1,1,3,0,0,0,0,3,3,3,36,38,0,0,36,37,3,3,38,0,0,0,0,37,3,3,36,38,0,0,36,37,3,3,3,0,0,0,0,3,1,1,1,1,1
1,1,1,1,1,3,3,38,37,3,3,3,3,38,0,0,0,0,37,3,3,3,3,38,37,3,3,3,3,38,0,0,0,0,37,3,3,3,3,38,37,3,3,1,1,1,1,1
1,1,1,1,1,3,3,38,37,3,3,3,3,38,0,0,0,0,37,3,3,3,3,38,37,3,3,3,3,38,0,0,0,0,37,3,3,3,3,38,37,3,3,1,1,1,1,1
1,1,1,1,1,3,0,0,0,0,3,3,3,38,41,0,0,37,41,3,3,38,0,0,0,0,37,3,3,38,41,0,0,37,41,3,3,3,0,0,0,0,3,1,1,1,1,1
1,1,1,1,1,3,0,0,0,0,3,3,3,3,38,41,41,41,3,3,3,38,0,0,0,0,37,3,3,3,38,41,41,41,3,3,3,3,0,0,0,0,3,1,1,1,1,1
1,1,1,16,3,3,14,0,0,14,3,3,16,3,3,3,3,3,3,16,3,3,14,0,0,14,3,3,16,3,3,3,3,3,3,16,3,3,14,0,0,14,3,3,16,1,1,1
1,1,1,3,17,47,0,0,0,0,46,17,3,3,3,3,3,3,3,3,17,47,0,0,0,0,46,17,3,3,3,3,3,3,3,3,17,47,0,0,0,0,46,17,3,1,1,1
3,3,3,3,48,49,0,0,0,0,49,48,3,3,3,3,3,3,3,3,48,49,0,0,0,0,49,48,3,3,3,3,3,3,3,3,48,49,0,0,0,0,49,48,3,3,3,3
3,0,0,14,0,0,0,0,0,0,0,0,14,0,0,3,3,0,0,14,0,0,0,0,0,0,0,0,14,0,0,3,3,0,0,14,0,0,0,0,0,0,0,0,14,0,0,3
36,0,0,0,0,0,0,0,0,0,0,0,0,0,0,36,36,0,0,0,0,0,0,0,0,0,0,0,0,0,0,36,36,0,0,0,0,0,0,0,0,0,0,0,0,0,0,36
41,0,0,0,0,0,0,0,0,0,0,0,0,0,0,41,41,0,0,0,0,0,0,0,0,0,0,0,0,0,0,41,41,0,0,0,0,0,0,0,0,0,0,0,0,0,0,41
3,0,0,14,0,0,0,0,0,0,0,0,14,0,0,3,3,0,0,14,0,0,0,0,0,0,0,0,14,0,0,3,3,0,0,14,0,0,0,0,0,0,0,0,14,0,0,3
3,3,3,3,50,49,0,0,0,0,49,50,3,3,3,3,3,3,3,3,50,49,0,0,0,0,49,50,3,3,3,3,3,3,3,3,50,49,0,0,0,0,49,50,3,3,3,3
1,1,1,3,17,47,0,0,0,0,46,17,3,1,1,1,1,1,1,3,17,47,0,0,0,0,46,17,3,1,1,1,1,1,1,3,17,47,0,0,0,0,46,17,3,1,1,1
1,1,1,16,3,3,14,0,0,14,3,3,16,1,1,1,1,1,1,16,3,3,14,0,0,14,3,3,16,1,1,1,1,1,1,16,3,3,14,0,0,14,3,3,16,1,1,1
1,1,1,1,1,3,0,0,0,0,3,1,1,1,1,1,1,1,1,1,1,3,0,0,0,0,3,1,1,1,1,1,1,1,1,1,1,3,0,0,0,0,3,1,1,1,1,1
1,1,1,1,1,3,0,0,0,0,3,1,1,1,1,1,1,1,1,1,1,3,0,0,0,0,3,1,1,1,1,1,1,1,1,1,1,3,0,0,0,0,3,1,1,1,1,1
1,1,1,1,1,3,3,38,37,3,3,1,1,1,1,1,1,1,1,1,1,3,3,38,37,3,3,1,1,1,1,1,1,1,1,1,1,3,3,38,37,3,3,1,1,1,1,1
endlayer

layer
1,1,1,1,1,1,3,3,3,3,1,1,1,1,1,1,1,1,1,1,1,1,3,3,3,3,1,1,1,1,1,1,1,1,1,1,1,1,3,3,3,3,1,1,1,1,1,1
1,1,1,1,1,1,38,36,36,37,1,1,1,1,1,1,1,1,1,1,1,1,38,36,36,37,1,1,1,1,1,1,1,1,1,1,1,1,38,36,36,37,1,1,1,1,1,1
1,1,1,1,1,1,38,0,0,37,1,1,1,1,1,1,1,1,1,1,1,1,38,0,0,37,1,1,1,1,1,1,1,1,1,1,1,1,38,0,0,37,1,1,1,1,1,1
1,1,1,16,3,3,38,0,0,37,3,3,16,1,1,1,1,1,1,16,3,3,38,0,0,37,3,3,16,1,1,1,1,1,1,16,3,3,38,0,0,37,3,3,16,1,1,1
1,1,1,3,17,19,0,0,0,0,18,17,3,1,1,1,1,1,1,3,17,19,0,0,0,0,18,17,3,1,1,1,1,1,1,3,17,19,0,0,0,0,18,17,3,1,1,1
1,1,1,3,20,33,0,0,0,0,33,20,3,1,1,1,1,1,1,3,20,33,0,0,0,0,33,20,3,1,1,1,1,1,1,3,20,33,0,0,0,0,33,20,3,1,1,1
3,36,36,36,0,0,0,0,0,0,0,0,36,36,36,3,3,36,36,36,0,0,0,0,0,0,0,0,36,36,36,3,3,36,36,36,0,0,0,0,0,0,0,0,36,36,36,3
3,38,0,0,0,0,0,0,0,0,0,0,0,0,37,3,3,38,0,0,0,0,0,0,0,0,0,0,0,0,37,3,3,38,0,0,0,0,0,0,0,0,0,0,0,0,37,3
3,38,0,0,0,0,0,0,0,0,0,0,0,0,37,3,3,38,0,0,0,0,0,0,0,0,0,0,0,0,37,3,3,38,0,0,0,0,0,0,0,0,0,0,0,0,37,3
3,41,41,41,0,0,0,0,0,0,0,0,41,41,41,3,3,41,41,41,0,0,0,0,0,0,0,0,41,41,41,3,3,41,41,41,0,0,0,0,0,0,0,0,41,41,41,3
1,1,1,3,21,33,0,0,0,0,33,21,3,1,1,1,1,1,1,3,21,33,0,0,0,0,33,21,3,1,1,1,1,1,1,3,21,33,0,0,0,0,33,21,3,1,1,1
1,1,1,3,17,19,0,0,0,0,18,17,3,1,1,1,1,1,1,3,17,19,0,0,0,0,18,17,3,1,1,1,1,1,1,3,17,19,0,0,0,0,18,17,3,1,1,1
1,1,1,16,3,3,38,0,0,37,3,3,16,1,1,1,1,1,1,16,3,3,38,0,0,37,3,3,16,1,1,1,1,1,1,16,3,3,38,0,0,37,3,3,16,1,1,1
1,1,1,1,1,1,38,0,0,37,1,1,1,1,3,3,3,3,1,1,1,1,38,0,0,37,1,1,1,1,3,3,3,3,1,1,1,1,38,0,0,37,1,1,1,1,1,1
1,1,1,1,1,1,38,41,41,37,1,1,1,3,3,36,36,3,3,1,1,1,38,41,41,37,1,1,1,3,3,36,36,3,3,1,1,1,38,41,41,37,1,1,1,1,1,1
1,1,1,1,1,1,3,3,3,3,1,1,1,3,38,0,0,37,3,1,1,1,3,3,3,3,1,1,1,3,38,0,0,37,3,1,1,1,3,3,3,3,1,1,1,1,1,1
1,1,1,1,1,1,3,3,3,3,1,1,1,3,38,0,0,37,3,1,1,1,3,3,3,3,1,1,1,3,38,0,0,37,3,1,1,1,3,3,3,3,1,1,1,1,1,1
1,1,1,1,1,1,38,36,36,37,1,1,1,3,3,41,41,3,3,1,1,1,38,36,36,37,1,1,1,3,3,41,41,3,3,1,1,1,38,36,36,37,1,1,1,1,1,1
1,1,1,1,1,1,38,0,0,37,1,1,1,1,3,3,3,3,1,1,1,1,38,0,0,37,1,1,1,1,3,3,3,3,1,1,1,1,38,0,0,37,1,1,1,1,1,1
1,1,1,16,3,3,38,0,0,37,3,3,16,1,1,1,1,1,1,16,3,3,38,0,0,37,3,3,16,1,1,1,1,1,1,16,3,3,38,0,0,37,3,3,16,1,1,1
1,1,1,3,17,19,0,0,0,0,18,17,3,1,1,1,1,1,1,3,17,19,0,0,0,0,18,17,3,1,1,1,1,1,1,3,17,19,0,0,0,0,18,17,3,1,1,1
1,1,1,3,20,33,0,0,0,0,33,20,3,1,1,1,1,1,1,3,20,45,0,0,0,0,45,20,3,1,1,1,1,1,1,3,20,33,0,0,0,0,33,20,3,1,1,1
3,36,36,36,0,0,0,0,0,0,0,0,36,36,36,3,3,36,36,36,0,0,0,0,0,0,0,0,36,36,36,3,3,36,36,36,0,0,0,0,0,0,0,0,36,36,36,3
3,38,0,0,0,0,0,0,0,0,0,0,0,0,37,3,3,38,0,0,0,0,0,0,0,0,0,0,0,0,37,3,3,38,0,0,0,0,0,0,0,0,0,0,0,0,37,3
3,38,0,0,0,0,0,0,0,0,0,0,0,0,37,3,3,38,0,0,0,0,0,0,0,0,0,0,0,0,37,3,3,38,0,0,0,0,0,0,0,0,0,0,0,0,37,3
3,41,41,41,0,0,0,0,0,0,0,0,41,41,41,3,3,41,41,41,0,0,0,0,0,0,0,0,41,41,41,3,3,41,41,41,0,0,0,0,0,0,0,0,41,41,41,3
1,1,1,3,21,33,0,0,0,0,33,21,3,1,1,1,1,1,1,3,21,45,0,0,0,0,45,21,3,1,1,1,1,1,1,3,21,33,0,0,0,0,33,21,3,1,1,1
1,1,1,3,17,19,0,0,0,0,18,17,3,1,1,1,1,1,1,3,17,19,0,0,0,0,18,17,3,1,1,1,1,1,1,3,17,19,0,0,0,0,18,17,3,1,1,1
1,1,1,16,3,3,38,0,0,37,3,3,16,1,1,1,1,1,1,16,3,3,38,0,0,37,3,3,16,1,1,1,1,1,1,16,3,3,38,0,0,37,3,3,16,1,1,1
1,1,1,1,1,1,38,0,0,37,1,1,1,1,3,3,3,3,1,1,1,1,38,0,0,37,1,1,1,1,3,3,3,3,1,1,1,1,38,0,0,37,1,1,1,1,1,1
1,1,1,1,1,1,38,41,41,37,1,1,1,3,3,36,36,3,3,1,1,1,38,41,41,37,1,1,1,3,3,36,36,3,3,1,1,1,38,41,41,37,1,1,1,1,1,1
1,1,1,1,1,1,3,3,3,3,1,1,1,3,38,0,0,37,3,1,1,1,3,3,3,3,1,1,1,3,38,0,0,37,3,1,1,1,3,3,3,3,1,1,1,1,1,1
1,1,1,1,1,1,3,3,3,3,1,1,1,3,38,0,0,37,3,1,1,1,3,3,3,3,1,1,1,3,38,0,0,37,3,1,1,1,3,3,3,3,1,1,1,1,1,1
1,1,1,1,1,1,38,36,36,37,1,1,1,3,3,41,41,3,3,1,1,1,38,36,36,37,1,1,1,3,3,41,41,3,3,1,1,1,38,36,36,37,1,1,1,1,1,1
1,1,1,1,1,1,38,0,0,37,1,1,1,1,3,3,3,3,1,1,1,1,38,0,0,37,1,1,1,1,3,3,3,3,1,1,1,1,38,0,0,37,1,1,1,1,1,1
1,1,1,16,3,3,38,0,0,37,3,3,16,1,1,1,1,1,1,16,3,3,38,0,0,37,3,3,16,1,1,1,1,1,1,16,3,3,38,0,0,37,3,3,16,1,1,1
1,1,1,3,17,19,0,0,0,0,18,17,3,1,1,1,1,1,1,3,17,19,0,0,0,0,18,17,3,1,1,1,1,1,1,3,17,19,0,0,0,0,18,17,3,1,1,1
1,1,1,3,20,33,0,0,0,0,33,20,3,1,1,1,1,1,1,3,20,33,0,0,0,0,33,20,3,1,1,1,1,1,1,3,20,33,0,0,0,0,33,20,3,1,1,1
3,36,36,36,0,0,0,0,0,0,0,0,36,36,36,3,3,36,36,36,0,0,0,0,0,0,0,0,36,36,36,3,3,36,36,36,0,0,0,0,0,0,0,0,36,36,36,3
3,38,0,0,0,0,0,0,0,0,0,0,0,0,37,3,3,38,0,0,0,0,0,0,0,0,0,0,0,0,37,3,3,38,0,0,0,0,0,0,0,0,0,0,0,0,37,3
3,38,0,0,0,0,0,0,0,0,0,0,0,0,37,3,3,38,0,0,0,0,0,0,0,0,0,0,0,0,37,3,3,38,0,0,0,0,0,0,0,0,0,0,0,0,37,3
3,41,41,41,0,0,0,0,0,0,0,0,41,41,41,3,3,41,41,41,0,0,0,0,0,0,0,0,41,41,41,3,3,41,41,41,0,0,0,0,0,0,0,0,41,41,41,3
1,1,1,3,21,33,0,0,0,0,33,21,3,1,1,1,1,1,1,3,21,33,0,0,0,0,33,21,3,1,1,1,1,1,1,3,21,33,0,0,0,0,33,21,3,1,1,1
1,1,1,3,17,19,0,0,0,0,18,17,3,1,1,1,1,1,1,3,17,19,0,0,0,0,18,17,3,1,1,1,1,1,1,3,17,19,0,0,0,0,18,17,3,1,1,1
1,1,1,16,3,3,38,0,0,37,3,3,16,1,1,1,1,1,1,16,3,3,38,0,0,37,3,3,16,1,1,1,1,1,1,16,3,3,38,0,0,37,3,3,16,1,1,1
1,1,1,1,1,1,38,0,0,37,1,1,1,1,1,1,1,1,1,1,1,1,38,0,0,37,1,1,1,1,1,1,1,1,1,1,1,1,38,0,0,37,1,1,1,1,1,1
1,1,1,1,1,1,38,41,41,37,1,1,1,1,1,1,1,1,1,1,1,1,38,41,41,37,1,1,1,1,1,1,1,1,1,1,1,1,38,41,41,37,1,1,1,1,1,1
1,1,1,1,1,1,3,3,3,3,1,1,1,1,1,1,1,1,1,1,1,1,3,3,3,3,1,1,1,1,1,1,1,1,1,1,1,1,3,3,3,3,1,1,1,1,1,1
endlayer

layer
1,1,1,1,1,1,1,1,1,1,1,1,1,1,1,1,1,1,1,1,1,1,1,1,1,1,1,1,1,1,1,1,1,1,1,1,1,1,1,1,1,1,1,1,1,1,1,1
1,1,1,1,1,1,1,3,3,1,1,1,1,1,1,1,1,1,1,1,1,1,1,3,3,1,1,1,1,1,1,1,1,1,1,1,1,1,1,3,3,1,1,1,1,1,1,1
1,1,1,1,1,1,1,3,3,1,1,1,1,1,1,1,1,1,1,1,1,1,1,3,3,1,1,1,1,1,1,1,1,1,1,1,1,1,1,3,3,1,1,1,1,1,1,1
1,1,1,16,3,3,3,3,3,3,3,3,16,1,1,1,1,1,1,16,3,3,3,3,3,3,3,3,16,1,1,1,1,1,1,16,3,3,3,3,3,3,3,3,16,1,1,1
1,1,1,3,5,0,0,0,0,0,0,5,3,1,1,1,1,1,1,3,5,0,0,0,0,0,0,5,3,1,1,1,1,1,1,3,5,0,0,0,0,0,0,5,3,1,1,1
1,1,1,3,0,0,0,0,0,0,0,0,3,1,1,1,1,1,1,3,0,0,0,0,0,0,0,0,3,1,1,1,1,1,1,3,0,0,0,0,0,0,0,0,3,1,1,1
1,1,1,3,0,0,0,0,0,0,0,0,3,1,1,1,1,1,1,3,0,0,0,0,0,0,0,0,3,1,1,1,1,1,1,3,0,0,0,0,0,0,0,0,3,1,1,1
1,3,3,3,0,0,0,0,0,0,0,0,3,3,3,1,1,3,3,3,0,0,0,0,0,0,0,0,3,3,3,1,1,3,3,3,0,0,0,0,0,0,0,0,3,3,3,1
1,3,3,3,0,0,0,0,0,0,0,0,3,3,3,1,1,3,3,3,0,0,0,0,0,0,0,0,3,3,3,1,1,3,3,3,0,0,0,0,0,0,0,0,3,3,3,1
1,1,1,3,0,0,0,0,0,0,0,0,3,1,1,1,1,1,1,3,0,0,0,0,0,0,0,0,3,1,1,1,1,1,1,3,0,0,0,0,0,0,0,0,3,1,1,1
1,1,1,3,0,0,0,0,0,0,0,0,3,1,1,1,1,1,1,3,0,0,0,0,0,0,0,0,3,1,1,1,1,1,1,3,0,0,0,0,0,0,0,0,3,1,1,1
1,1,1,3,5,0,0,0,0,0,0,5,3,1,1,1,1,1,1,3,5,0,0,0,0,0,0,5,3,1,1,1,1,1,1,3,5,0,0,0,0,0,0,5,3,1,1,1
1,1,1,16,3,3,3,3,3,3,3,3,16,1,1,1,1,1,1,16,3,3,3,3,3,3,3,3,16,1,1,1,1,1,1,16,3,3,3,3,3,3,3,3,16,1,1,1
1,1,1,1,1,1,1,3,3,1,1,1,1,1,1,1,1,1,1,1,1,1,1,3,3,1,1,1,1,1,1,1,1,1,1,1,1,1,1,3,3,1,1,1,1,1,1,1
1,1,1,1,1,1,1,3,3,1,1,1,1,1,3,3,3,3,1,1,1,1,1,3,3,1,1,1,1,1,3,3,3,3,1,1,1,1,1,3,3,1,1,1,1,1,1,1
1,1,1,1,1,1,1,1,1,1,1,1,1,1,3,3,3,3,1,1,1,1,1,1,1,1,1,1,1,1,3,3,3,3,1,1,1,1,1,1,1,1,1,1,1,1,1,1
1,1,1,1,1,1,1,1,1,1,1,1,1,1,3,3,3,3,1,1,1,1,1,1,1,1,1,1,1,1,3,3,3,3,1,1,1,1,1,1,1,1,1,1,1,1,1,1
1,1,1,1,1,1,1,3,3,1,1,1,1,1,3,3,3,3,1,1,1,1,1,3,3,1,1,1,1,1,3,3,3,3,1,1,1,1,1,3,3,1,1,1,1,1,1,1
1,1,1,1,1,1,1,3,3,1,1,1,1,1,1,1,1,1,1,1,1,1,1,3,3,1,1,1,1,1,1,1,1,1,1,1,1,1,1,3,3,1,1,1,1,1,1,1
1,1,1,16,3,3,3,3,3,3,3,3,16,1,1,1,1,1,1,16,3,3,3,3,3,3,3,3,16,1,1,1,1,1,1,16,3,3,3,3,3,3,3,3,16,1,1,1
1,1,1,3,5,0,0,0,0,0,0,5,3,1,1,1,1,1,1,3,5,0,0,0,0,0,0,5,3,1,1,1,1,1,1,3,5,0,0,0,0,0,0,5,3,1,1,1
1,1,1,3,0,0,0,0,0,0,0,0,3,1,1,1,1,1,1,3,0,0,0,0,0,0,0,0,3,1,1,1,1,1,1,3,0,0,0,0,0,0,0,0,3,1,1,1
1,1,1,3,0,0,0,0,0,0,0,0,3,1,1,1,1,1,1,3,0,0,0,0,0,0,0,0,3,1,1,1,1,1,1,3,0,0,0,0,0,0,0,0,3,1,1,1
1,3,3,3,0,0,0,0,0,0,0,0,3,3,3,1,1,3,3,3,0,0,0,51,51,0,0,0,3,3,3,1,1,3,3,3,0,0,0,0,0,0,0,0,3,3,3,1
1,3,3,3,0,0,0,0,0,0,0,0,3,3,3,1,1,3,3,3,0,0,0,51,51,0,0,0,3,3,3,1,1,3,3,3,0,0,0,0,0,0,0,0,3,3,3,1
1,1,1,3,0,0,0,0,0,0,0,0,3,1,1,1,1,1,1,3,0,0,0,0,0,0,0,0,3,1,1,1,1,1,1,3,0,0,0,0,0,0,0,0,3,1,1,1
1,1,1,3,0,0,0,0,0,0,0,0,3,1,1,1,1,1,1,3,0,0,0,0,0,0,0,0,3,1,1,1,1,1,1,3,0,0,0,0,0,0,0,0,3,1,1,1
1,1,1,3,5,0,0,0,0,0,0,5,3,1,1,1,1,1,1,3,5,0,0,0,0,0,0,5,3,1,1,1,1,1,1,3,5,0,0,0,0,0,0,5,3,1,1,1
1,1,1,16,3,3,3,3,3,3,3,3,16,1,1,1,1,1,1,16,3,3,3,3,3,3,3,3,16,1,1,1,1,1,1,16,3,3,3,3,3,3,3,3,16,1,1,1
1,1,1,1,1,1,1,3,3,1,1,1,1,1,1,1,1,1,1,1,1,1,1,3,3,1,1,1,1,1,1,1,1,1,1,1,1,1,1,3,3,1,1,1,1,1,1,1
1,1,1,1,1,1,1,3,3,1,1,1,1,1,3,3,3,3,1,1,1,1,1,3,3,1,1,1,1,1,3,3,3,3,1,1,1,1,1,3,3,1,1,1,1,1,1,1
1,1,1,1,1,1,1,1,1,1,1,1,1,1,3,3,3,3,1,1,1,1,1,1,1,1,1,1,1,1,3,3,3,3,1,1,1,1,1,1,1,1,1,1,1,1,1,1
1,1,1,1,1,1,1,1,1,1,1,1,1,1,3,3,3,3,1,1,1,1,1,1,1,1,1,1,1,1,3,3,3,3,1,1,1,1,1,1,1,1,1,1,1,1,1,1
1,1,1,1,1,1,1,3,3,1,1,1,1,1,3,3,3,3,1,1,1,1,1,3,3,1,1,1,1,1,3,3,3,3,1,1,1,1,1,3,3,1,1,1,1,1,1,1
1,1,1,1,1,1,1,3,3,1,1,1,1,1,1,1,1,1,1,1,1,1,1,3,3,1,1,1,1,1,1,1,1,1,1,1,1,1,1,3,3,1,1,1,1,1,1,1
1,1,1,16,3,3,3,3,3,3,3,3,16,1,1,1,1,1,1,16,3,3,3,3,3,3,3,3,16,1,1,1,1,1,1,16,3,3,3,3,3,3,3,3,16,1,1,1
1,1,1,3,5,0,0,0,0,0,0,5,3,1,1,1,1,1,1,3,5,0,0,0,0,0,0,5,3,1,1,1,1,1,1,3,5,0,0,0,0,0,0,5,3,1,1,1
1,1,1,3,0,0,0,0,0,0,0,0,3,1,1,1,1,1,1,3,0,0,0,0,0,0,0,0,3,1,1,1,1,1,1,3,0,0,0,0,0,0,0,0,3,1,1,1
1,1,1,3,0,0,0,0,0,0,0,0,3,1,1,1,1,1,1,3,0,0,0,0,0,0,0,0,3,1,1,1,1,1,1,3,0,0,0,0,0,0,0,0,3,1,1,1
1,3,3,3,0,0,0,0,0,0,0,0,3,3,3,1,1,3,3,3,0,0,0,0,0,0,0,0,3,3,3,1,1,3,3,3,0,0,0,0,0,0,0,0,3,3,3,1
1,3,3,3,0,0,0,0,0,0,0,0,3,3,3,1,1,3,3,3,0,0,0,0,0,0,0,0,3,3,3,1,1,3,3,3,0,0,0,0,0,0,0,0,3,3,3,1
1,1,1,3,0,0,0,0,0,0,0,0,3,1,1,1,1,1,1,3,0,0,0,0,0,0,0,0,3,1,1,1,1,1,1,3,0,0,0,0,0,0,0,0,3,1,1,1
1,1,1,3,0,0,0,0,0,0,0,0,3,1,1,1,1,1,1,3,0,0,0,0,0,0,0,0,3,1,1,1,1,1,1,3,0,0,0,0,0,0,0,0,3,1,1,1
1,1,1,3,5,0,0,0,0,0,0,5,3,1,1,1,1,1,1,3,5,0,0,0,0,0,0,5,3,1,1,1,1,1,1,3,5,0,0,0,0,0,0,5,3,1,1,1
1,1,1,16,3,3,3,3,3,3,3,3,16,1,1,1,1,1,1,16,3,3,3,3,3,3,3,3,16,1,1,1,1,1,1,16,3,3,3,3,3,3,3,3,16,1,1,1
1,1,1,1,1,1,1,3,3,1,1,1,1,1,1,1,1,1,1,1,1,1,1,3,3,1,1,1,1,1,1,1,1,1,1,1,1,1,1,3,3,1,1,1,1,1,1,1
1,1,1,1,1,1,1,3,3,1,1,1,1,1,1,1,1,1,1,1,1,1,1,3,3,1,1,1,1,1,1,1,1,1,1,1,1,1,1,3,3,1,1,1,1,1,1,1
1,1,1,1,1,1,1,1,1,1,1,1,1,1,1,1,1,1,1,1,1,1,1,1,1,1,1,1,1,1,1,1,1,1,1,1,1,1,1,1,1,1,1,1,1,1,1,1
endlayer

layer
1,1,1,1,1,1,1,1,1,1,1,1,1,1,1,1,1,1,1,1,1,1,1,1,1,1,1,1,1,1,1,1,1,1,1,1,1,1,1,1,1,1,1,1,1,1,1,1
1,1,1,1,1,1,1,1,1,1,1,1,1,1,1,1,1,1,1,1,1,1,1,1,1,1,1,1,1,1,1,1,1,1,1,1,1,1,1,1,1,1,1,1,1,1,1,1
1,1,1,1,1,1,1,1,1,1,1,1,1,1,1,1,1,1,1,1,1,1,1,1,1,1,1,1,1,1,1,1,1,1,1,1,1,1,1,1,1,1,1,1,1,1,1,1
1,1,1,5,3,3,3,3,3,3,3,3,5,1,1,1,1,1,1,5,3,3,3,3,3,3,3,3,5,1,1,1,1,1,1,5,3,3,3,3,3,3,3,3,5,1,1,1
1,1,1,3,3,3,36,0,0,36,3,3,3,1,1,1,1,1,1,3,3,3,36,0,0,36,3,3,3,1,1,1,1,1,1,3,3,3,36,0,0,36,3,3,3,1,1,1
1,1,1,3,3,52,0,0,0,0,52,3,3,1,1,1,1,1,1,3,3,52,0,0,0,0,52,3,3,1,1,1,1,1,1,3,3,52,0,0,0,0,52,3,3,1,1,1
1,1,1,3,38,0,0,0,0,0,0,37,3,1,1,1,1,1,1,3,38,0,0,0,0,0,0,37,3,1,1,1,1,1,1,3,38,0,0,0,0,0,0,37,3,1,1,1
1,1,1,3,0,0,0,0,0,0,0,0,3,1,1,1,1,1,1,3,0,0,0,0,0,0,0,0,3,1,1,1,1,1,1,3,0,0,0,0,0,0,0,0,3,1,1,1
1,1,1,3,0,0,0,0,0,0,0,0,3,1,1,1,1,1,1,3,0,0,0,0,0,0,0,0,3,1,1,1,1,1,1,3,0,0,0,0,0,0,0,0,3,1,1,1
1,1,1,3,38,0,0,0,0,0,0,37,3,1,1,1,1,1,1,3,38,0,0,0,0,0,0,37,3,1,1,1,1,1,1,3,38,0,0,0,0,0,0,37,3,1,1,1
1,1,1,3,3,52,0,0,0,0,52,3,3,1,1,1,1,1,1,3,3,52,0,0,0,0,52,3,3,1,1,1,1,1,1,3,3,52,0,0,0,0,52,3,3,1,1,1
1,1,1,3,3,3,41,0,0,41,3,3,3,1,1,1,1,1,1,3,3,3,41,0,0,41,3,3,3,1,1,1,1,1,1,3,3,3,41,0,0,41,3,3,3,1,1,1
1,1,1,5,3,3,3,3,3,3,3,3,5,1,1,1,1,1,1,5,3,3,3,3,3,3,3,3,5,1,1,1,1,1,1,5,3,3,3,3,3,3,3,3,5,1,1,1
1,1,1,1,1,1,1,1,1,1,1,1,1,1,1,1,1,1,1,1,1,1,1,1,1,1,1,1,1,1,1,1,1,1,1,1,1,1,1,1,1,1,1,1,1,1,1,1
1,1,1,1,1,1,1,1,1,1,1,1,1,1,1,1,1,1,1,1,1,1,1,1,1,1,1,1,1,1,1,1,1,1,1,1,1,1,1,1,1,1,1,1,1,1,1,1
1,1,1,1,1,1,1,1,1,1,1,1,1,1,1,1,1,1,1,1,1,1,1,1,1,1,1,1,1,1,1,1,1,1,1,1,1,1,1,1,1,1,1,1,1,1,1,1
1,1,1,1,1,1,1,1,1,1,1,1,1,1,1,1,1,1,1,1,1,1,1,1,1,1,1,1,1,1,1,1,1,1,1,1,1,1,1,1,1,1,1,1,1,1,1,1
1,1,1,1,1,1,1,1,1,1,1,1,1,1,1,1,1,1,1,1,1,1,1,1,1,1,1,1,1,1,1,1,1,1,1,1,1,1,1,1,1,1,1,1,1,1,1,1
1,1,1,1,1,1,1,1,1,1,1,1,1,1,1,1,1,1,1,1,1,1,1,1,1,1,1,1,1,1,1,1,1,1,1,1,1,1,1,1,1,1,1,1,1,1,1,1
1,1,1,5,3,3,3,3,3,3,3,3,5,1,1,1,1,1,1,5,3,3,3,3,3,3,3,3,5,1,1,1,1,1,1,5,3,3,3,3,3,3,3,3,5,1,1,1
1,1,1,3,3,3,36,0,0,36,3,3,3,1,1,1,1,1,1,3,3,3,36,0,0,36,3,3,3,1,1,1,1,1,1,3,3,3,36,0,0,36,3,3,3,1,1,1
1,1,1,3,3,52,0,0,0,0,52,3,3,1,1,1,1,1,1,3,3,52,0,0,0,0,52,3,3,1,1,1,1,1,1,3,3,52,0,0,0,0,52,3,3,1,1,1
1,1,1,3,38,0,0,0,0,0,0,37,3,1,1,1,1,1,1,3,38,0,0,41,41,0,0,37,3,1,1,1,1,1,1,3,38,0,0,0,0,0,0,37,3,1,1,1
1,1,1,3,0,0,0,0,0,0,0,0,3,1,1,1,1,1,1,3,0,0,37,53,53,38,0,0,3,1,1,1,1,1,1,3,0,0,0,0,0,0,0,0,3,1,1,1
1,1,1,3,0,0,0,0,0,0,0,0,3,1,1,1,1,1,1,3,0,0,37,53,53,38,0,0,3,1,1,1,1,1,1,3,0,0,0,0,0,0,0,0,3,1,1,1
1,1,1,3,38,0,0,0,0,0,0,37,3,1,1,1,1,1,1,3,38,0,0,36,36,0,0,37,3,1,1,1,1,1,1,3,38,0,0,0,0,0,0,37,3,1,1,1
1,1,1,3,3,52,0,0,0,0,52,3,3,1,1,1,1,1,1,3,3,52,0,0,0,0,52,3,3,1,1,1,1,1,1,3,3,52,0,0,0,0,52,3,3,1,1,1
1,1,1,3,3,3,41,0,0,41,3,3,3,1,1,1,1,1,1,3,3,3,41,0,0,41,3,3,3,1,1,1,1,1,1,3,3,3,41,0,0,41,3,3,3,1,1,1
1,1,1,5,3,3,3,3,3,3,3,3,5,1,1,1,1,1,1,5,3,3,3,3,3,3,3,3,5,1,1,1,1,1,1,5,3,3,3,3,3,3,3,3,5,1,1,1
1,1,1,1,1,1,1,1,1,1,1,1,1,1,1,1,1,1,1,1,1,1,1,1,1,1,1,1,1,1,1,1,1,1,1,1,1,1,1,1,1,1,1,1,1,1,1,1
1,1,1,1,1,1,1,1,1,1,1,1,1,1,1,1,1,1,1,1,1,1,1,1,1,1,1,1,1,1,1,1,1,1,1,1,1,1,1,1,1,1,1,1,1,1,1,1
1,1,1,1,1,1,1,1,1,1,1,1,1,1,1,1,1,1,1,1,1,1,1,1,1,1,1,1,1,1,1,1,1,1,1,1,1,1,1,1,1,1,1,1,1,1,1,1
1,1,1,1,1,1,1,1,1,1,1,1,1,1,1,1,1,1,1,1,1,1,1,1,1,1,1,1,1,1,1,1,1,1,1,1,1,1,1,1,1,1,1,1,1,1,1,1
1,1,1,1,1,1,1,1,1,1,1,1,1,1,1,1,1,1,1,1,1,1,1,1,1,1,1,1,1,1,1,1,1,1,1,1,1,1,1,1,1,1,1,1,1,1,1,1
1,1,1,1,1,1,1,1,1,1,1,1,1,1,1,1,1,1,1,1,1,1,1,1,1,1,1,1,1,1,1,1,1,1,1,1,1,1,1,1,1,1,1,1,1,1,1,1
1,1,1,5,3,3,3,3,3,3,3,3,5,1,1,1,1,1,1,5,3,3,3,3,3,3,3,3,5,1,1,1,1,1,1,5,3,3,3,3,3,3,3,3,5,1,1,1
1,1,1,3,3,3,36,0,0,36,3,3,3,1,1,1,1,1,1,3,3,3,36,0,0,36,3,3,3,1,1,1,1,1,1,3,3,3,36,0,0,36,3,3,3,1,1,1
1,1,1,3,3,52,0,0,0,0,52,3,3,1,1,1,1,1,1,3,3,52,0,0,0,0,52,3,3,1,1,1,1,1,1,3,3,52,0,0,0,0,52,3,3,1,1,1
1,1,1,3,38,0,0,0,0,0,0,37,3,1,1,1,1,1,1,3,38,0,0,0,0,0,0,37,3,1,1,1,1,1,1,3,38,0,0,0,0,0,0,37,3,1,1,1
1,1,1,3,0,0,0,0,0,0,0,0,3,1,1,1,1,1,1,3,0,0,0,0,0,0,0,0,3,1,1,1,1,1,1,3,0,0,0,0,0,0,0,0,3,1,1,1
1,1,1,3,0,0,0,0,0,0,0,0,3,1,1,1,1,1,1,3,0,0,0,0,0,0,0,0,3,1,1,1,1,1,1,3,0,0,0,0,0,0,0,0,3,1,1,1
1,1,1,3,38,0,0,0,0,0,0,37,3,1,1,1,1,1,1,3,38,0,0,0,0,0,0,37,3,1,1,1,1,1,1,3,38,0,0,0,0,0,0,37,3,1,1,1
1,1,1,3,3,52,0,0,0,0,52,3,3,1,1,1,1,1,1,3,3,52,0,0,0,0,52,3,3,1,1,1,1,1,1,3,3,52,0,0,0,0,52,3,3,1,1,1
1,1,1,3,3,3,41,0,0,41,3,3,3,1,1,1,1,1,1,3,3,3,41,0,0,41,3,3,3,1,1,1,1,1,1,3,3,3,41,0,0,41,3,3,3,1,1,1
1,1,1,5,3,3,3,3,3,3,3,3,5,1,1,1,1,1,1,5,3,3,3,3,3,3,3,3,5,1,1,1,1,1,1,5,3,3,3,3,3,3,3,3,5,1,1,1
1,1,1,1,1,1,1,1,1,1,1,1,1,1,1,1,1,1,1,1,1,1,1,1,1,1,1,1,1,1,1,1,1,1,1,1,1,1,1,1,1,1,1,1,1,1,1,1
1,1,1,1,1,1,1,1,1,1,1,1,1,1,1,1,1,1,1,1,1,1,1,1,1,1,1,1,1,1,1,1,1,1,1,1,1,1,1,1,1,1,1,1,1,1,1,1
1,1,1,1,1,1,1,1,1,1,1,1,1,1,1,1,1,1,1,1,1,1,1,1,1,1,1,1,1,1,1,1,1,1,1,1,1,1,1,1,1,1,1,1,1,1,1,1
endlayer

layer
1,1,1,1,1,1,1,1,1,1,1,1,1,1,1,1,1,1,1,1,1,1,1,1,1,1,1,1,1,1,1,1,1,1,1,1,1,1,1,1,1,1,1,1,1,1,1,1
1,1,1,1,1,1,1,1,1,1,1,1,1,1,1,1,1,1,1,1,1,1,1,1,1,1,1,1,1,1,1,1,1,1,1,1,1,1,1,1,1,1,1,1,1,1,1,1
1,1,1,1,1,1,1,1,1,1,1,1,1,1,1,1,1,1,1,1,1,1,1,1,1,1,1,1,1,1,1,1,1,1,1,1,1,1,1,1,1,1,1,1,1,1,1,1
1,1,1,1,1,1,1,1,1,1,1,1,1,1,1,1,1,1,1,1,1,1,1,1,1,1,1,1,1,1,1,1,1,1,1,1,1,1,1,1,1,1,1,1,1,1,1,1
1,1,1,1,1,1,3,36,36,3,1,1,1,1,1,1,1,1,1,1,1,1,3,36,36,3,1,1,1,1,1,1,1,1,1,1,1,1,3,36,36,3,1,1,1,1,1,1
1,1,1,1,1,3,36,0,0,36,3,1,1,1,1,1,1,1,1,1,1,3,36,0,0,36,3,1,1,1,1,1,1,1,1,1,1,3,36,0,0,36,3,1,1,1,1,1
1,1,1,1,3,38,0,0,0,0,37,3,1,1,1,1,1,1,1,1,3,38,0,0,0,0,37,3,1,1,1,1,1,1,1,1,3,38,0,0,0,0,37,3,1,1,1,1
1,1,1,1,38,0,0,0,0,0,0,37,1,1,1,1,1,1,1,1,38,0,0,0,0,0,0,37,1,1,1,1,1,1,1,1,38,0,0,0,0,0,0,37,1,1,1,1
1,1,1,1,38,0,0,0,0,0,0,37,1,1,1,1,1,1,1,1,38,0,0,0,0,0,0,37,1,1,1,1,1,1,1,1,38,0,0,0,0,0,0,37,1,1,1,1
1,1,1,1,3,38,0,0,0,0,37,3,1,1,1,1,1,1,1,1,3,38,0,0,0,0,37,3,1,1,1,1,1,1,1,1,3,38,0,0,0,0,37,3,1,1,1,1
1,1,1,1,1,3,41,0,0,41,3,1,1,1,1,1,1,1,1,1,1,3,41,0,0,41,3,1,1,1,1,1,1,1,1,1,1,3,41,0,0,41,3,1,1,1,1,1
1,1,1,1,1,1,3,41,41,3,1,1,1,1,1,1,1,1,1,1,1,1,3,41,41,3,1,1,1,1,1,1,1,1,1,1,1,1,3,41,41,3,1,1,1,1,1,1
1,1,1,1,1,1,1,1,1,1,1,1,1,1,1,1,1,1,1,1,1,1,1,1,1,1,1,1,1,1,1,1,1,1,1,1,1,1,1,1,1,1,1,1,1,1,1,1
1,1,1,1,1,1,1,1,1,1,1,1,1,1,1,1,1,1,1,1,1,1,1,1,1,1,1,1,1,1,1,1,1,1,1,1,1,1,1,1,1,1,1,1,1,1,1,1
1,1,1,1,1,1,1,1,1,1,1,1,1,1,1,1,1,1,1,1,1,1,1,1,1,1,1,1,1,1,1,1,1,1,1,1,1,1,1,1,1,1,1,1,1,1,1,1
1,1,1,1,1,1,1,1,1,1,1,1,1,1,1,1,1,1,1,1,1,1,1,1,1,1,1,1,1,1,1,1,1,1,1,1,1,1,1,1,1,1,1,1,1,1,1,1
1,1,1,1,1,1,1,1,1,1,1,1,1,1,1,1,1,1,1,1,1,1,1,1,1,1,1,1,1,1,1,1,1,1,1,1,1,1,1,1,1,1,1,1,1,1,1,1
1,1,1,1,1,1,1,1,1,1,1,1,1,1,1,1,1,1,1,1,1,1,1,1,1,1,1,1,1,1,1,1,1,1,1,1,1,1,1,1,1,1,1,1,1,1,1,1
1,1,1,1,1,1,1,1,1,1,1,1,1,1,1,1,1,1,1,1,1,1,1,1,1,1,1,1,1,1,1,1,1,1,1,1,1,1,1,1,1,1,1,1,1,1,1,1
1,1,1,1,1,1,1,1,1,1,1,1,1,1,1,1,1,1,1,1,1,1,1,1,1,1,1,1,1,1,1,1,1,1,1,1,1,1,1,1,1,1,1,1,1,1,1,1
1,1,1,1,1,1,3,36,36,3,1,1,1,1,1,1,1,1,1,1,1,1,3,36,36,3,1,1,1,1,1,1,1,1,1,1,1,1,3,36,36,3,1,1,1,1,1,1
1,1,1,1,1,3,36,0,0,36,3,1,1,1,1,1,1,1,1,1,1,3,36,0,0,36,3,1,1,1,1,1,1,1,1,1,1,3,36,0,0,36,3,1,1,1,1,1
1,1,1,1,3,38,0,0,0,0,37,3,1,1,1,1,1,1,1,1,3,38,0,0,0,0,37,3,1,1,1,1,1,1,1,1,3,38,0,0,0,0,37,3,1,1,1,1
1,1,1,1,38,0,0,0,0,0,0,37,1,1,1,1,1,1,1,1,38,0,0,32,32,0,0,37,1,1,1,1,1,1,1,1,38,0,0,0,0,0,0,37,1,1,1,1
1,1,1,1,38,0,0,0,0,0,0,37,1,1,1,1,1,1,1,1,38,0,0,32,32,0,0,37,1,1,1,1,1,1,1,1,38,0,0,0,0,0,0,37,1,1,1,1
1,1,1,1,3,38,0,0,0,0,37,3,1,1,1,1,1,1,1,1,3,38,0,0,0,0,37,3,1,1,1,1,1,1,1,1,3,38,0,0,0,0,37,3,1,1,1,1
1,1,1,1,1,3,41,0,0,41,3,1,1,1,1,1,1,1,1,1,1,3,41,0,0,41,3,1,1,1,1,1,1,1,1,1,1,3,41,0,0,41,3,1,1,1,1,1
1,1,1,1,1,1,3,41,41,3,1,1,1,1,1,1,1,1,1,1,1,1,3,41,41,3,1,1,1,1,1,1,1,1,1,1,1,1,3,41,41,3,1,1,1,1,1,1
1,1,1,1,1,1,1,1,1,1,1,1,1,1,1,1,1,1,1,1,1,1,1,1,1,1,1,1,1,1,1,1,1,1,1,1,1,1,1,1,1,1,1,1,1,1,1,1
1,1,1,1,1,1,1,1,1,1,1,1,1,1,1,1,1,1,1,1,1,1,1,1,1,1,1,1,1,1,1,1,1,1,1,1,1,1,1,1,1,1,1,1,1,1,1,1
1,1,1,1,1,1,1,1,1,1,1,1,1,1,1,1,1,1,1,1,1,1,1,1,1,1,1,1,1,1,1,1,1,1,1,1,1,1,1,1,1,1,1,1,1,1,1,1
1,1,1,1,1,1,1,1,1,1,1,1,1,1,1,1,1,1,1,1,1,1,1,1,1,1,1,1,1,1,1,1,1,1,1,1,1,1,1,1,1,1,1,1,1,1,1,1
1,1,1,1,1,1,1,1,1,1,1,1,1,1,1,1,1,1,1,1,1,1,1,1,1,1,1,1,1,1,1,1,1,1,1,1,1,1,1,1,1,1,1,1,1,1,1,1
1,1,1,1,1,1,1,1,1,1,1,1,1,1,1,1,1,1,1,1,1,1,1,1,1,1,1,1,1,1,1,1,1,1,1,1,1,1,1,1,1,1,1,1,1,1,1,1
1,1,1,1,1,1,1,1,1,1,1,1,1,1,1,1,1,1,1,1,1,1,1,1,1,1,1,1,1,1,1,1,1,1,1,1,1,1,1,1,1,1,1,1,1,1,1,1
1,1,1,1,1,1,1,1,1,1,1,1,1,1,1,1,1,1,1,1,1,1,1,1,1,1,1,1,1,1,1,1,1,1,1,1,1,1,1,1,1,1,1,1,1,1,1,1
1,1,1,1,1,1,3,36,36,3,1,1,1,1,1,1,1,1,1,1,1,1,3,36,36,3,1,1,1,1,1,1,1,1,1,1,1,1,3,36,36,3,1,1,1,1,1,1
1,1,1,1,1,3,36,0,0,36,3,1,1,1,1,1,1,1,1,1,1,3,36,0,0,36,3,1,1,1,1,1,1,1,1,1,1,3,36,0,0,36,3,1,1,1,1,1
1,1,1,1,3,38,0,0,0,0,37,3,1,1,1,1,1,1,1,1,3,38,0,0,0,0,37,3,1,1,1,1,1,1,1,1,3,38,0,0,0,0,37,3,1,1,1,1
1,1,1,1,38,0,0,0,0,0,0,37,1,1,1,1,1,1,1,1,38,0,0,0,0,0,0,37,1,1,1,1,1,1,1,1,38,0,0,0,0,0,0,37,1,1,1,1
1,1,1,1,38,0,0,0,0,0,0,37,1,1,1,1,1,1,1,1,38,0,0,0,0,0,0,37,1,1,1,1,1,1,1,1,38,0,0,0,0,0,0,37,1,1,1,1
1,1,1,1,3,38,0,0,0,0,37,3,1,1,1,1,1,1,1,1,3,38,0,0,0,0,37,3,1,1,1,1,1,1,1,1,3,38,0,0,0,0,37,3,1,1,1,1
1,1,1,1,1,3,41,0,0,41,3,1,1,1,1,1,1,1,1,1,1,3,41,0,0,41,3,1,1,1,1,1,1,1,1,1,1,3,41,0,0,41,3,1,1,1,1,1
1,1,1,1,1,1,3,41,41,3,1,1,1,1,1,1,1,1,1,1,1,1,3,41,41,3,1,1,1,1,1,1,1,1,1,1,1,1,3,41,41,3,1,1,1,1,1,1
1,1,1,1,1,1,1,1,1,1,1,1,1,1,1,1,1,1,1,1,1,1,1,1,1,1,1,1,1,1,1,1,1,1,1,1,1,1,1,1,1,1,1,1,1,1,1,1
1,1,1,1,1,1,1,1,1,1,1,1,1,1,1,1,1,1,1,1,1,1,1,1,1,1,1,1,1,1,1,1,1,1,1,1,1,1,1,1,1,1,1,1,1,1,1,1
1,1,1,1,1,1,1,1,1,1,1,1,1,1,1,1,1,1,1,1,1,1,1,1,1,1,1,1,1,1,1,1,1,1,1,1,1,1,1,1,1,1,1,1,1,1,1,1
1,1,1,1,1,1,1,1,1,1,1,1,1,1,1,1,1,1,1,1,1,1,1,1,1,1,1,1,1,1,1,1,1,1,1,1,1,1,1,1,1,1,1,1,1,1,1,1
endlayer

layer
1,1,1,1,1,1,1,1,1,1,1,1,1,1,1,1,1,1,1,1,1,1,1,1,1,1,1,1,1,1,1,1,1,1,1,1,1,1,1,1,1,1,1,1,1,1,1,1
1,1,1,1,1,1,1,1,1,1,1,1,1,1,1,1,1,1,1,1,1,1,1,1,1,1,1,1,1,1,1,1,1,1,1,1,1,1,1,1,1,1,1,1,1,1,1,1
1,1,1,1,1,1,1,1,1,1,1,1,1,1,1,1,1,1,1,1,1,1,1,1,1,1,1,1,1,1,1,1,1,1,1,1,1,1,1,1,1,1,1,1,1,1,1,1
1,1,1,1,1,1,1,1,1,1,1,1,1,1,1,1,1,1,1,1,1,1,1,1,1,1,1,1,1,1,1,1,1,1,1,1,1,1,1,1,1,1,1,1,1,1,1,1
1,1,1,1,1,1,1,1,1,1,1,1,1,1,1,1,1,1,1,1,1,1,1,1,1,1,1,1,1,1,1,1,1,1,1,1,1,1,1,1,1,1,1,1,1,1,1,1
1,1,1,1,1,1,3,36,36,3,1,1,1,1,1,1,1,1,1,1,1,1,3,36,36,3,1,1,1,1,1,1,1,1,1,1,1,1,3,36,36,3,1,1,1,1,1,1
1,1,1,1,1,3,3,0,0,3,3,1,1,1,1,1,1,1,1,1,1,3,3,0,0,3,3,1,1,1,1,1,1,1,1,1,1,3,3,0,0,3,3,1,1,1,1,1
1,1,1,1,1,38,0,0,54,0,37,1,1,1,1,1,1,1,1,1,1,38,0,0,54,0,37,1,1,1,1,1,1,1,1,1,1,38,0,0,54,0,37,1,1,1,1,1
1,1,1,1,1,38,0,0,0,0,37,1,1,1,1,1,1,1,1,1,1,38,0,0,0,0,37,1,1,1,1,1,1,1,1,1,1,38,0,0,0,0,37,1,1,1,1,1
1,1,1,1,1,3,3,0,0,3,3,1,1,1,1,1,1,1,1,1,1,3,3,0,0,3,3,1,1,1,1,1,1,1,1,1,1,3,3,0,0,3,3,1,1,1,1,1
1,1,1,1,1,1,3,41,41,3,1,1,1,1,1,1,1,1,1,1,1,1,3,41,41,3,1,1,1,1,1,1,1,1,1,1,1,1,3,41,41,3,1,1,1,1,1,1
1,1,1,1,1,1,1,1,1,1,1,1,1,1,1,1,1,1,1,1,1,1,1,1,1,1,1,1,1,1,1,1,1,1,1,1,1,1,1,1,1,1,1,1,1,1,1,1
1,1,1,1,1,1,1,1,1,1,1,1,1,1,1,1,1,1,1,1,1,1,1,1,1,1,1,1,1,1,1,1,1,1,1,1,1,1,1,1,1,1,1,1,1,1,1,1
1,1,1,1,1,1,1,1,1,1,1,1,1,1,1,1,1,1,1,1,1,1,1,1,1,1,1,1,1,1,1,1,1,1,1,1,1,1,1,1,1,1,1,1,1,1,1,1
1,1,1,1,1,1,1,1,1,1,1,1,1,1,1,1,1,1,1,1,1,1,1,1,1,1,1,1,1,1,1,1,1,1,1,1,1,1,1,1,1,1,1,1,1,1,1,1
1,1,1,1,1,1,1,1,1,1,1,1,1,1,1,1,1,1,1,1,1,1,1,1,1,1,1,1,1,1,1,1,1,1,1,1,1,1,1,1,1,1,1,1,1,1,1,1
1,1,1,1,1,1,1,1,1,1,1,1,1,1,1,1,1,1,1,1,1,1,1,1,1,1,1,1,1,1,1,1,1,1,1,1,1,1,1,1,1,1,1,1,1,1,1,1
1,1,1,1,1,1,1,1,1,1,1,1,1,1,1,1,1,1,1,1,1,1,1,1,1,1,1,1,1,1,1,1,1,1,1,1,1,1,1,1,1,1,1,1,1,1,1,1
1,1,1,1,1,1,1,1,1,1,1,1,1,1,1,1,1,1,1,1,1,1,1,1,1,1,1,1,1,1,1,1,1,1,1,1,1,1,1,1,1,1,1,1,1,1,1,1
1,1,1,1,1,1,1,1,1,1,1,1,1,1,1,1,1,1,1,1,1,1,1,1,1,1,1,1,1,1,1,1,1,1,1,1,1,1,1,1,1,1,1,1,1,1,1,1
1,1,1,1,1,1,1,1,1,1,1,1,1,1,1,1,1,1,1,1,1,1,1,1,1,1,1,1,1,1,1,1,1,1,1,1,1,1,1,1,1,1,1,1,1,1,1,1
1,1,1,1,1,1,3,36,36,3,1,1,1,1,1,1,1,1,1,1,1,1,3,36,36,3,1,1,1,1,1,1,1,1,1,1,1,1,3,36,36,3,1,1,1,1,1,1
1,1,1,1,1,3,3,0,0,3,3,1,1,1,1,1,1,1,1,1,1,3,3,0,0,3,3,1,1,1,1,1,1,1,1,1,1,3,3,0,0,3,3,1,1,1,1,1
1,1,1,1,1,38,0,0,54,0,37,1,1,1,1,1,1,1,1,1,1,38,0,32,32,0,37,1,1,1,1,1,1,1,1,1,1,38,0,0,54,0,37,1,1,1,1,1
1,1,1,1,1,38,0,0,0,0,37,1,1,1,1,1,1,1,1,1,1,38,0,32,32,0,37,1,1,1,1,1,1,1,1,1,1,38,0,0,0,0,37,1,1,1,1,1
1,1,1,1,1,3,3,0,0,3,3,1,1,1,1,1,1,1,1,1,1,3,3,0,0,3,3,1,1,1,1,1,1,1,1,1,1,3,3,0,0,3,3,1,1,1,1,1
1,1,1,1,1,1,3,41,41,3,1,1,1,1,1,1,1,1,1,1,1,1,3,41,41,3,1,1,1,1,1,1,1,1,1,1,1,1,3,41,41,3,1,1,1,1,1,1
1,1,1,1,1,1,1,1,1,1,1,1,1,1,1,1,1,1,1,1,1,1,1,1,1,1,1,1,1,1,1,1,1,1,1,1,1,1,1,1,1,1,1,1,1,1,1,1
1,1,1,1,1,1,1,1,1,1,1,1,1,1,1,1,1,1,1,1,1,1,1,1,1,1,1,1,1,1,1,1,1,1,1,1,1,1,1,1,1,1,1,1,1,1,1,1
1,1,1,1,1,1,1,1,1,1,1,1,1,1,1,1,1,1,1,1,1,1,1,1,1,1,1,1,1,1,1,1,1,1,1,1,1,1,1,1,1,1,1,1,1,1,1,1
1,1,1,1,1,1,1,1,1,1,1,1,1,1,1,1,1,1,1,1,1,1,1,1,1,1,1,1,1,1,1,1,1,1,1,1,1,1,1,1,1,1,1,1,1,1,1,1
1,1,1,1,1,1,1,1,1,1,1,1,1,1,1,1,1,1,1,1,1,1,1,1,1,1,1,1,1,1,1,1,1,1,1,1,1,1,1,1,1,1,1,1,1,1,1,1
1,1,1,1,1,1,1,1,1,1,1,1,1,1,1,1,1,1,1,1,1,1,1,1,1,1,1,1,1,1,1,1,1,1,1,1,1,1,1,1,1,1,1,1,1,1,1,1
1,1,1,1,1,1,1,1,1,1,1,1,1,1,1,1,1,1,1,1,1,1,1,1,1,1,1,1,1,1,1,1,1,1,1,1,1,1,1,1,1,1,1,1,1,1,1,1
1,1,1,1,1,1,1,1,1,1,1,1,1,1,1,1,1,1,1,1,1,1,1,1,1,1,1,1,1,1,1,1,1,1,1,1,1,1,1,1,1,1,1,1,1,1,1,1
1,1,1,1,1,1,1,1,1,1,1,1,1,1,1,1,1,1,1,1,1,1,1,1,1,1,1,1,1,1,1,1,1,1,1,1,1,1,1,1,1,1,1,1,1,1,1,1
1,1,1,1,1,1,1,1,1,1,1,1,1,1,1,1,1,1,1,1,1,1,1,1,1,1,1,1,1,1,1,1,1,1,1,1,1,1,1,1,1,1,1,1,1,1,1,1
1,1,1,1,1,1,3,36,36,3,1,1,1,1,1,1,1,1,1,1,1,1,3,36,36,3,1,1,1,1,1,1,1,1,1,1,1,1,3,36,36,3,1,1,1,1,1,1
1,1,1,1,1,3,3,0,0,3,3,1,1,1,1,1,1,1,1,1,1,3,3,0,0,3,3,1,1,1,1,1,1,1,1,1,1,3,3,0,0,3,3,1,1,1,1,1
1,1,1,1,1,38,0,0,54,0,37,1,1,1,1,1,1,1,1,1,1,38,0,0,54,0,37,1,1,1,1,1,1,1,1,1,1,38,0,0,54,0,37,1,1,1,1,1
1,1,1,1,1,38,0,0,0,0,37,1,1,1,1,1,1,1,1,1,1,38,0,0,0,0,37,1,1,1,1,1,1,1,1,1,1,38,0,0,0,0,37,1,1,1,1,1
1,1,1,1,1,3,3,0,0,3,3,1,1,1,1,1,1,1,1,1,1,3,3,0,0,3,3,1,1,1,1,1,1,1,1,1,1,3,3,0,0,3,3,1,1,1,1,1
1,1,1,1,1,1,3,41,41,3,1,1,1,1,1,1,1,1,1,1,1,1,3,41,41,3,1,1,1,1,1,1,1,1,1,1,1,1,3,41,41,3,1,1,1,1,1,1
1,1,1,1,1,1,1,1,1,1,1,1,1,1,1,1,1,1,1,1,1,1,1,1,1,1,1,1,1,1,1,1,1,1,1,1,1,1,1,1,1,1,1,1,1,1,1,1
1,1,1,1,1,1,1,1,1,1,1,1,1,1,1,1,1,1,1,1,1,1,1,1,1,1,1,1,1,1,1,1,1,1,1,1,1,1,1,1,1,1,1,1,1,1,1,1
1,1,1,1,1,1,1,1,1,1,1,1,1,1,1,1,1,1,1,1,1,1,1,1,1,1,1,1,1,1,1,1,1,1,1,1,1,1,1,1,1,1,1,1,1,1,1,1
1,1,1,1,1,1,1,1,1,1,1,1,1,1,1,1,1,1,1,1,1,1,1,1,1,1,1,1,1,1,1,1,1,1,1,1,1,1,1,1,1,1,1,1,1,1,1,1
1,1,1,1,1,1,1,1,1,1,1,1,1,1,1,1,1,1,1,1,1,1,1,1,1,1,1,1,1,1,1,1,1,1,1,1,1,1,1,1,1,1,1,1,1,1,1,1
endlayer

layer
1,1,1,1,1,1,1,1,1,1,1,1,1,1,1,1,1,1,1,1,1,1,1,1,1,1,1,1,1,1,1,1,1,1,1,1,1,1,1,1,1,1,1,1,1,1,1,1
1,1,1,1,1,1,1,1,1,1,1,1,1,1,1,1,1,1,1,1,1,1,1,1,1,1,1,1,1,1,1,1,1,1,1,1,1,1,1,1,1,1,1,1,1,1,1,1
1,1,1,1,1,1,1,1,1,1,1,1,1,1,1,1,1,1,1,1,1,1,1,1,1,1,1,1,1,1,1,1,1,1,1,1,1,1,1,1,1,1,1,1,1,1,1,1
1,1,1,1,1,1,1,1,1,1,1,1,1,1,1,1,1,1,1,1,1,1,1,1,1,1,1,1,1,1,1,1,1,1,1,1,1,1,1,1,1,1,1,1,1,1,1,1
1,1,1,1,1,1,1,1,1,1,1,1,1,1,1,1,1,1,1,1,1,1,1,1,1,1,1,1,1,1,1,1,1,1,1,1,1,1,1,1,1,1,1,1,1,1,1,1
1,1,1,1,1,1,1,1,1,1,1,1,1,1,1,1,1,1,1,1,1,1,1,1,1,1,1,1,1,1,1,1,1,1,1,1,1,1,1,1,1,1,1,1,1,1,1,1
1,1,1,1,1,1,3,3,3,3,1,1,1,1,1,1,1,1,1,1,1,1,3,3,3,3,1,1,1,1,1,1,1,1,1,1,1,1,3,3,3,3,1,1,1,1,1,1
1,1,1,1,1,1,3,5,5,3,1,1,1,1,1,1,1,1,1,1,1,1,3,5,5,3,1,1,1,1,1,1,1,1,1,1,1,1,3,5,5,3,1,1,1,1,1,1
1,1,1,1,1,1,3,5,5,3,1,1,1,1,1,1,1,1,1,1,1,1,3,5,5,3,1,1,1,1,1,1,1,1,1,1,1,1,3,5,5,3,1,1,1,1,1,1
1,1,1,1,1,1,3,3,3,3,1,1,1,1,1,1,1,1,1,1,1,1,3,3,3,3,1,1,1,1,1,1,1,1,1,1,1,1,3,3,3,3,1,1,1,1,1,1
1,1,1,1,1,1,1,1,1,1,1,1,1,1,1,1,1,1,1,1,1,1,1,1,1,1,1,1,1,1,1,1,1,1,1,1,1,1,1,1,1,1,1,1,1,1,1,1
1,1,1,1,1,1,1,1,1,1,1,1,1,1,1,1,1,1,1,1,1,1,1,1,1,1,1,1,1,1,1,1,1,1,1,1,1,1,1,1,1,1,1,1,1,1,1,1
1,1,1,1,1,1,1,1,1,1,1,1,1,1,1,1,1,1,1,1,1,1,1,1,1,1,1,1,1,1,1,1,1,1,1,1,1,1,1,1,1,1,1,1,1,1,1,1
1,1,1,1,1,1,1,1,1,1,1,1,1,1,1,1,1,1,1,1,1,1,1,1,1,1,1,1,1,1,1,1,1,1,1,1,1,1,1,1,1,1,1,1,1,1,1,1
1,1,1,1,1,1,1,1,1,1,1,1,1,1,1,1,1,1,1,1,1,1,1,1,1,1,1,1,1,1,1,1,1,1,1,1,1,1,1,1,1,1,1,1,1,1,1,1
1,1,1,1,1,1,1,1,1,1,1,1,1,1,1,1,1,1,1,1,1,1,1,1,1,1,1,1,1,1,1,1,1,1,1,1,1,1,1,1,1,1,1,1,1,1,1,1
1,1,1,1,1,1,1,1,1,1,1,1,1,1,1,1,1,1,1,1,1,1,1,1,1,1,1,1,1,1,1,1,1,1,1,1,1,1,1,1,1,1,1,1,1,1,1,1
1,1,1,1,1,1,1,1,1,1,1,1,1,1,1,1,1,1,1,1,1,1,1,1,1,1,1,1,1,1,1,1,1,1,1,1,1,1,1,1,1,1,1,1,1,1,1,1
1,1,1,1,1,1,1,1,1,1,1,1,1,1,1,1,1,1,1,1,1,1,1,1,1,1,1,1,1,1,1,1,1,1,1,1,1,1,1,1,1,1,1,1,1,1,1,1
1,1,1,1,1,1,1,1,1,1,1,1,1,1,1,1,1,1,1,1,1,1,1,1,1,1,1,1,1,1,1,1,1,1,1,1,1,1,1,1,1,1,1,1,1,1,1,1
1,1,1,1,1,1,1,1,1,1,1,1,1,1,1,1,1,1,1,1,1,1,1,1,1,1,1,1,1,1,1,1,1,1,1,1,1,1,1,1,1,1,1,1,1,1,1,1
1,1,1,1,1,1,1,1,1,1,1,1,1,1,1,1,1,1,1,1,1,1,1,1,1,1,1,1,1,1,1,1,1,1,1,1,1,1,1,1,1,1,1,1,1,1,1,1
1,1,1,1,1,1,3,3,3,3,1,1,1,1,1,1,1,1,1,1,1,1,3,3,3,3,1,1,1,1,1,1,1,1,1,1,1,1,3,3,3,3,1,1,1,1,1,1
1,1,1,1,1,1,3,5,5,3,1,1,1,1,1,1,1,1,1,1,1,1,3,5,5,3,1,1,1,1,1,1,1,1,1,1,1,1,3,5,5,3,1,1,1,1,1,1
1,1,1,1,1,1,3,5,5,3,1,1,1,1,1,1,1,1,1,1,1,1,3,5,5,3,1,1,1,1,1,1,1,1,1,1,1,1,3,5,5,3,1,1,1,1,1,1
1,1,1,1,1,1,3,3,3,3,1,1,1,1,1,1,1,1,1,1,1,1,3,3,3,3,1,1,1,1,1,1,1,1,1,1,1,1,3,3,3,3,1,1,1,1,1,1
1,1,1,1,1,1,1,1,1,1,1,1,1,1,1,1,1,1,1,1,1,1,1,1,1,1,1,1,1,1,1,1,1,1,1,1,1,1,1,1,1,1,1,1,1,1,1,1
1,1,1,1,1,1,1,1,1,1,1,1,1,1,1,1,1,1,1,1,1,1,1,1,1,1,1,1,1,1,1,1,1,1,1,1,1,1,1,1,1,1,1,1,1,1,1,1
1,1,1,1,1,1,1,1,1,1,1,1,1,1,1,1,1,1,1,1,1,1,1,1,1,1,1,1,1,1,1,1,1,1,1,1,1,1,1,1,1,1,1,1,1,1,1,1
1,1,1,1,1,1,1,1,1,1,1,1,1,1,1,1,1,1,1,1,1,1,1,1,1,1,1,1,1,1,1,1,1,1,1,1,1,1,1,1,1,1,1,1,1,1,1,1
1,1,1,1,1,1,1,1,1,1,1,1,1,1,1,1,1,1,1,1,1,1,1,1,1,1,1,1,1,1,1,1,1,1,1,1,1,1,1,1,1,1,1,1,1,1,1,1
1,1,1,1,1,1,1,1,1,1,1,1,1,1,1,1,1,1,1,1,1,1,1,1,1,1,1,1,1,1,1,1,1,1,1,1,1,1,1,1,1,1,1,1,1,1,1,1
1,1,1,1,1,1,1,1,1,1,1,1,1,1,1,1,1,1,1,1,1,1,1,1,1,1,1,1,1,1,1,1,1,1,1,1,1,1,1,1,1,1,1,1,1,1,1,1
1,1,1,1,1,1,1,1,1,1,1,1,1,1,1,1,1,1,1,1,1,1,1,1,1,1,1,1,1,1,1,1,1,1,1,1,1,1,1,1,1,1,1,1,1,1,1,1
1,1,1,1,1,1,1,1,1,1,1,1,1,1,1,1,1,1,1,1,1,1,1,1,1,1,1,1,1,1,1,1,1,1,1,1,1,1,1,1,1,1,1,1,1,1,1,1
1,1,1,1,1,1,1,1,1,1,1,1,1,1,1,1,1,1,1,1,1,1,1,1,1,1,1,1,1,1,1,1,1,1,1,1,1,1,1,1,1,1,1,1,1,1,1,1
1,1,1,1,1,1,1,1,1,1,1,1,1,1,1,1,1,1,1,1,1,1,1,1,1,1,1,1,1,1,1,1,1,1,1,1,1,1,1,1,1,1,1,1,1,1,1,1
1,1,1,1,1,1,1,1,1,1,1,1,1,1,1,1,1,1,1,1,1,1,1,1,1,1,1,1,1,1,1,1,1,1,1,1,1,1,1,1,1,1,1,1,1,1,1,1
1,1,1,1,1,1,3,3,3,3,1,1,1,1,1,1,1,1,1,1,1,1,3,3,3,3,1,1,1,1,1,1,1,1,1,1,1,1,3,3,3,3,1,1,1,1,1,1
1,1,1,1,1,1,3,5,5,3,1,1,1,1,1,1,1,1,1,1,1,1,3,5,5,3,1,1,1,1,1,1,1,1,1,1,1,1,3,5,5,3,1,1,1,1,1,1
1,1,1,1,1,1,3,5,5,3,1,1,1,1,1,1,1,1,1,1,1,1,3,5,5,3,1,1,1,1,1,1,1,1,1,1,1,1,3,5,5,3,1,1,1,1,1,1
1,1,1,1,1,1,3,3,3,3,1,1,1,1,1,1,1,1,1,1,1,1,3,3,3,3,1,1,1,1,1,1,1,1,1,1,1,1,3,3,3,3,1,1,1,1,1,1
1,1,1,1,1,1,1,1,1,1,1,1,1,1,1,1,1,1,1,1,1,1,1,1,1,1,1,1,1,1,1,1,1,1,1,1,1,1,1,1,1,1,1,1,1,1,1,1
1,1,1,1,1,1,1,1,1,1,1,1,1,1,1,1,1,1,1,1,1,1,1,1,1,1,1,1,1,1,1,1,1,1,1,1,1,1,1,1,1,1,1,1,1,1,1,1
1,1,1,1,1,1,1,1,1,1,1,1,1,1,1,1,1,1,1,1,1,1,1,1,1,1,1,1,1,1,1,1,1,1,1,1,1,1,1,1,1,1,1,1,1,1,1,1
1,1,1,1,1,1,1,1,1,1,1,1,1,1,1,1,1,1,1,1,1,1,1,1,1,1,1,1,1,1,1,1,1,1,1,1,1,1,1,1,1,1,1,1,1,1,1,1
1,1,1,1,1,1,1,1,1,1,1,1,1,1,1,1,1,1,1,1,1,1,1,1,1,1,1,1,1,1,1,1,1,1,1,1,1,1,1,1,1,1,1,1,1,1,1,1
1,1,1,1,1,1,1,1,1,1,1,1,1,1,1,1,1,1,1,1,1,1,1,1,1,1,1,1,1,1,1,1,1,1,1,1,1,1,1,1,1,1,1,1,1,1,1,1
endlayer

