
# Covered Wagon & Campfire
# 7 Mar 2014; updated to 1.7.10, 9 Oct 2014
# Created by Ruins mod version 12.3 Ingame Parser
# authoring Player: Jordan_Greywolf
# Last Updated: 24 Mar 2016
# Updated for MC 1.10: 13 Sep 2016
# Updated for MC 1.11: 13 Jan 2017
# Verified for MC 1.12: 23 Jun 2017
# Updated to MC 1.12.1: 10 Sep 2017

# Last Updated: 9 Jun 2018

biomesToSpawnIn=ice plains,plains,savanna,sunflower plains,twilight clearing,twilight_clearing,flower field,flower_field,lavender fields,lavender_fields,scrubland,shrubland,heathland,grasslands,grassland,chaparral,brushland,lush desert,rwg_plains,sunflower plains,mining biome,mining_biome,miningbiome,ice_flats,mutated_plains

weight=1
embed_into_distance=2

unacceptable_target_blocks=water,flowing_water,lava,flowing_lava,cloud,Natura:Cloud,brown_mushroom_block,red_mushroom_block,ice,slime_congealed,slime_dirt,slime_grass,command_block,planks,planks2,concrete,cobblestone,stonebrick,brick_block,glass,torch,oak_stairs,stone_stairs,brick_stairs,stone_brick_stairs,nether_brick_stairs,sandstone_stairs,spruce_stairs,birch_stairs,jungle_stairs,quartz_stairs,acacia_stairs,dark_oak_stairs,cobblestone_wall,stone_slab,double_stone_slab,stone_slab2,wooden_slab,double_wooden_slab,nether_brick,fence

dimensions=8,9,17
allowable_overhang=0
max_cut_in=0
cut_in_buffer=0
max_leveling=2
leveling_buffer=-1
preserve_water=0
preserve_lava=0
preserve_plants=1

rule1=0,100,preserveBlock
rule2=0,100,minecraft:grass-0
rule3=0,100,minecraft:grass-0
rule4=0,100,minecraft:cobblestone-0
rule5=0,100,minecraft:netherrack-0
rule6=0,75,minecraft:tallgrass-1,minecraft:tallgrass-1,minecraft:tallgrass-1,minecraft:tallgrass-0,minecraft:tallgrass-2,minecraft:red_flower,minecraft:yellow_flower
rule7=0,100,minecraft:log-8
rule8=0,100,minecraft:oak_stairs-6
rule9=0,100,minecraft:oak_stairs-7
rule10=0,100,minecraft:cobblestone_wall-0
rule11=0,100,minecraft:fire-15
rule12=0,100,minecraft:spruce_stairs-2
rule13=0,100,minecraft:oak_stairs-2
rule14=0,100,minecraft:oak_stairs-3
rule15=0,100,minecraft:spruce_stairs-1
rule16=0,50,minecraft:cauldron-3
rule17=0,100,minecraft:planks-1
rule18=0,100,minecraft:spruce_stairs-3
rule19=0,100,minecraft:spruce_stairs-0
rule20=0,100,minecraft:fence-0
rule21=1,100,minecraft:fence_gate-0
# rule22=0,100,minecraft:melon-0,minecraft:pumpkin-4,minecraft:tnt-0,minecraft:tnt-1,minecraft:lit_pumpkin-4,minecraft:cake,minecraft:hay_block

rule22=0,100,minecraft:melon,minecraft:pumpkin-4,minecraft:tnt-0,minecraft:tnt-1,minecraft:cake,minecraft:hay_block

rule23=0,100,IInventory;minecraft:trapped_chest;minecraft:carrot#18#0+minecraft:melon_block#1#0+minecraft:stone_pickaxe#1#0+minecraft:stick#3#0+minecraft:pumpkin#1#0+minecraft:wool#6#0+minecraft:torch#19#0-3
rule24=0,100,minecraft:wool-0
rule25=1,100,minecraft:redstone_torch-5

layer
1,1,1,2,2,3,3,3,3,3,3,3,2,2,1,1,1
1,1,2,2,3,3,3,3,3,3,3,3,3,2,2,1,1
1,2,2,3,3,3,3,3,3,3,3,3,3,3,2,2,1
2,2,3,3,3,3,3,3,3,3,3,3,3,3,3,2,2
2,3,3,3,3,3,3,3,3,3,3,3,3,3,3,3,2
2,2,3,3,3,3,3,3,3,3,3,3,3,3,3,2,2
1,2,2,3,3,3,3,3,3,3,3,3,3,3,2,2,1
1,1,2,2,3,3,3,3,3,3,3,3,3,2,2,1,1
1,1,1,2,2,3,3,3,3,3,3,3,2,2,1,1,1
endlayer

layer
1,1,1,1,1,2,2,2,2,2,2,2,1,1,1,1,1
1,1,1,1,2,2,2,2,2,2,2,3,3,1,1,1,1
1,1,1,2,2,3,2,2,2,2,2,2,2,2,1,1,1
1,1,2,2,2,2,2,2,2,2,2,4,4,4,2,1,1
1,2,2,2,2,2,2,2,2,2,2,4,5,4,2,2,1
1,1,2,2,2,2,2,2,2,2,2,4,4,4,2,1,1
1,1,1,2,2,3,2,2,2,2,2,2,2,2,1,1,1
1,1,1,1,2,2,2,2,2,2,2,2,2,1,1,1,1
1,1,1,1,1,2,2,2,2,2,2,2,1,1,1,1,1
endlayer

layer
1,1,1,1,1,6,6,0,0,6,6,6,0,1,1,1,1
1,1,1,1,6,6,6,0,6,0,6,7,7,7,0,1,1
1,1,1,6,9,8,0,9,8,6,6,0,0,0,0,0,1
1,1,6,0,0,0,6,0,6,0,0,0,10,0,0,0,0
1,6,6,0,6,0,6,0,0,12,0,0,11,0,0,6,0
1,1,6,6,0,0,0,0,0,6,0,0,10,0,0,0,0
1,1,1,6,9,8,6,9,8,6,6,0,6,0,0,0,1
1,1,1,1,6,6,6,0,6,6,6,6,0,0,0,1,1
1,1,1,1,1,6,6,6,6,6,6,6,0,1,1,1,1
endlayer

layer
1,1,1,0,0,0,0,0,0,0,0,0,0,0,0,1,1
1,1,0,0,0,0,0,0,0,0,0,0,0,0,0,0,1
1,0,0,0,14,13,0,14,13,0,0,0,0,0,0,0,0
0,0,0,15,15,15,15,15,15,15,0,0,10,0,0,0,0
0,0,0,12,18,17,17,17,12,0,0,0,16,0,0,0,0
0,0,0,19,19,19,19,19,19,19,0,0,10,0,0,0,0
1,0,0,0,14,13,0,14,13,0,0,0,0,0,0,0,0
1,1,0,0,0,0,0,0,0,0,0,0,0,0,0,0,1
1,1,1,0,0,0,0,0,0,0,0,0,0,0,0,1,1
endlayer

layer
1,1,0,0,0,0,0,0,0,0,0,0,0,0,0,0,1
1,0,0,0,0,0,0,0,0,0,0,0,0,0,0,0,0
0,0,0,0,0,0,0,0,0,0,0,0,0,0,0,0,0
0,0,0,20,20,20,20,20,20,20,0,0,0,0,0,0,0
0,0,0,0,0,23,22,22,0,21,0,0,0,0,0,0,0
0,0,0,20,20,20,20,20,20,20,0,0,0,0,0,0,0
0,0,0,0,0,0,0,0,0,0,0,0,0,0,0,0,0
1,0,0,0,0,0,0,0,0,0,0,0,0,0,0,0,0
1,1,0,0,0,0,0,0,0,0,0,0,0,0,0,0,1
endlayer

layer
1,0,0,0,0,0,0,0,0,0,0,0,0,0,0,0,0
0,0,0,0,0,0,0,0,0,0,0,0,0,0,0,0,0
0,0,0,0,0,0,0,0,0,0,0,0,0,0,0,0,0
0,0,0,0,25,24,24,24,24,24,0,0,0,0,0,0,0
0,0,0,0,0,0,0,0,0,0,0,0,0,0,0,0,0
0,0,0,0,25,24,24,24,24,24,0,0,0,0,0,0,0
0,0,0,0,0,0,0,0,0,0,0,0,0,0,0,0,0
0,0,0,0,0,0,0,0,0,0,0,0,0,0,0,0,0
1,0,0,0,0,0,0,0,0,0,0,0,0,0,0,0,0
endlayer

layer
0,0,0,0,0,0,0,0,0,0,0,0,0,0,0,0,0
0,0,0,0,0,0,0,0,0,0,0,0,0,0,0,0,0
0,0,0,0,0,0,0,0,0,0,0,0,0,0,0,0,0
0,0,0,0,0,24,24,24,24,24,0,0,0,0,0,0,0
0,0,0,0,0,0,0,0,0,0,0,0,0,0,0,0,0
0,0,0,0,0,24,24,24,24,24,0,0,0,0,0,0,0
0,0,0,0,0,0,0,0,0,0,0,0,0,0,0,0,0
0,0,0,0,0,0,0,0,0,0,0,0,0,0,0,0,0
0,0,0,0,0,0,0,0,0,0,0,0,0,0,0,0,0
endlayer

layer
0,0,0,0,0,0,0,0,0,0,0,0,0,0,0,0,0
0,0,0,0,0,0,0,0,0,0,0,0,0,0,0,0,0
0,0,0,0,0,0,0,0,0,0,0,0,0,0,0,0,0
0,0,0,0,0,24,0,24,0,24,0,0,0,0,0,0,0
0,0,0,0,0,24,24,24,24,24,0,0,0,0,0,0,0
0,0,0,0,0,24,0,24,0,24,0,0,0,0,0,0,0
0,0,0,0,0,0,0,0,0,0,0,0,0,0,0,0,0
0,0,0,0,0,0,0,0,0,0,0,0,0,0,0,0,0
0,0,0,0,0,0,0,0,0,0,0,0,0,0,0,0,0
endlayer

