# WalledGarden - MC 1.7.10, 11 Oct 2014
# Created by Ruins mod version 13.8 Ingame Parser
# authoring Player: Jordan_Greywolf
# Updated for MC 1.8: 22 Jul 2015
# Updated for MC 1.9: 27 Apr 2016
# Updated for MC 1.10: 13 Sep 2016
# Updated for MC 1.11: 13 Jan 2017
# Verified for MC 1.12: 23 Jun 2017

# Last Updated: 9 Jun 2018

biomesToSpawnIn=bamboo forest,bamboo_forest,birch forest,birch forest m,boreal forest,boreal_forest,cherry blossom grove,cherry_blossom_forest,clearing,enchanted forest,enchanted_forest,flower field,flower_field,flower forest,highland,highlands,highlands center,lavender fields,lavender_fields,lighted forest,lighted_forest,magical forest,meadow,mushroom forest,mystic grove,origin valley,origin_valley,plains,roofed forest,roofed forest m,rwg_plains,sacred springs,seasonal forest,seasonal_forest,silkglades,sunflower plains,twilight clearing,twilight_clearing,woodland,woodlands,mining biome,mining_biome,miningbiome,birch_forest,mutated_birch_forest,mutated_plains,roofed_forest,mutated_roofed_forest

uniqueMinDistance=2000
spawnMinDistance=1000

weight=1
embed_into_distance=6

unacceptable_target_blocks=flowing_lava,lava,cloud,Natura:Cloud,red_mushroom_block,brown_mushroom_block,slime_congealed,slime_dirt,slime_grass,command_block,planks,planks2,concrete,cobblestone,stonebrick,brick_block,glass,torch,oak_stairs,stone_stairs,brick_stairs,stone_brick_stairs,nether_brick_stairs,sandstone_stairs,spruce_stairs,birch_stairs,jungle_stairs,quartz_stairs,acacia_stairs,dark_oak_stairs,cobblestone_wall,stone_slab,double_stone_slab,stone_slab2,wooden_slab,double_wooden_slab,nether_brick,fence

dimensions=15,21,21
allowable_overhang=0
max_leveling=6
leveling_buffer=-1
preserve_water=0
preserve_lava=0
preserve_plants=1

# Chiseled Stone column cap
rule1=0,100,minecraft:stonebrick-3

# Randomized cobblestone/mossy cobblestone
rule2=0,100,minecraft:cobblestone-0,minecraft:mossy_cobblestone

rule3=0,100,minecraft:double_stone_slab-0
rule4=0,100,minecraft:grass-0
rule5=0,100,minecraft:stone_slab-15
rule6=0,100,minecraft:stone_slab-14
rule7=0,100,minecraft:water-0
rule8=0,100,minecraft:dirt-0
rule9=0,100,minecraft:stone_slab-0
rule10=0,100,minecraft:quartz_block-1

# Randomized cobblestone/mossy cobblestone wall
rule11=0,100,minecraft:cobblestone_wall-0,minecraft:cobblestone_wall-1

# Randomized flowers
rule12=0,100,minecraft:yellow_flower,minecraft:red_flower-0,minecraft:red_flower-1,minecraft:red_flower-2,minecraft:red_flower-3,minecraft:red_flower-4,minecraft:red_flower-5,minecraft:red_flower-6,minecraft:red_flower-7,minecraft:tallgrass-2

# Birch trunk
rule13=0,100,minecraft:log-2

rule14=0,100,minecraft:water-9
rule15=0,100,minecraft:quartz_block-2
rule16=0,100,minecraft:iron_bars-0
rule17=0,100,minecraft:stone_stairs-7
rule18=0,100,minecraft:stone_stairs-6
rule19=0,100,minecraft:stone_stairs-5
rule20=0,100,minecraft:stone_stairs-4
rule21=0,100,minecraft:stonebrick-0
rule22=0,100,minecraft:water-1
rule23=0,100,minecraft:stone_slab-8
rule24=0,100,minecraft:leaves-2
rule25=0,100,minecraft:leaves-10

# -----------------------------------------

layer
1,2,2,2,2,1,2,2,1,2,3,2,1,2,2,1,2,2,2,2,1
2,4,4,4,4,2,5,6,5,6,5,6,5,6,5,2,4,4,4,4,2
2,4,7,7,4,3,6,5,6,5,6,5,6,5,6,3,4,7,7,4,2
2,4,7,7,4,3,5,6,5,6,5,6,5,6,5,3,4,7,7,4,2
2,4,4,4,4,2,6,5,6,5,6,5,6,5,6,2,4,4,4,4,2
1,2,3,3,2,2,2,2,2,2,3,2,2,2,2,2,2,3,3,2,1
2,5,6,5,6,2,4,4,4,4,3,4,4,4,4,2,6,5,6,5,2
2,6,5,6,5,2,4,8,3,3,3,3,3,8,4,2,5,6,5,6,2
1,5,6,5,6,2,4,3,3,7,7,7,3,3,4,2,6,5,6,5,1
2,6,5,6,5,2,4,3,7,7,7,7,7,3,4,2,5,6,5,6,2
3,5,6,5,6,3,3,3,7,7,10,7,7,3,3,3,6,5,6,5,3
2,6,5,6,5,2,4,3,7,7,7,7,7,3,4,2,5,6,5,6,2
1,5,6,5,6,2,4,3,3,7,7,7,3,3,4,2,6,5,6,5,1
2,6,5,6,5,2,4,8,3,3,3,3,3,8,4,2,5,6,5,6,2
2,5,6,5,6,2,4,4,4,4,3,4,4,4,4,2,6,5,6,5,2
1,2,3,3,2,2,2,2,2,2,3,2,2,2,2,2,2,3,3,2,1
2,4,4,4,4,2,6,5,6,5,6,5,6,5,6,2,4,4,4,4,2
2,4,7,7,4,3,5,6,5,6,5,6,5,6,5,3,4,7,7,4,2
2,4,7,7,4,3,6,5,6,5,6,5,6,5,6,3,4,7,7,4,2
2,4,4,4,4,2,5,6,5,6,5,6,5,6,5,2,4,4,4,4,2
1,2,2,2,2,1,2,2,1,2,3,2,1,2,2,1,2,2,2,2,1
endlayer

layer
1,2,2,2,2,1,2,2,1,2,3,2,1,2,2,1,2,2,2,2,1
2,0,0,0,0,2,0,0,0,0,0,0,0,0,0,2,0,0,0,0,2
2,0,7,7,0,0,0,0,0,0,0,0,0,0,0,0,0,7,7,0,2
2,0,7,7,0,0,0,0,0,0,0,0,0,0,0,0,0,7,7,0,2
2,0,0,0,0,2,0,0,0,0,0,0,0,0,0,2,0,0,0,0,2
1,2,0,0,2,2,2,2,2,2,0,2,2,2,2,2,2,0,0,2,1
2,0,0,0,0,2,0,0,0,0,0,0,0,0,0,2,0,0,0,0,2
2,0,0,0,0,2,0,0,0,0,0,0,0,0,0,2,0,0,0,0,2
1,0,0,0,0,2,0,0,0,7,7,7,0,0,0,2,0,0,0,0,1
2,0,0,0,0,2,0,0,7,7,7,7,7,0,0,2,0,0,0,0,2
3,0,0,0,0,0,0,0,7,7,10,7,7,0,0,0,0,0,0,0,3
2,0,0,0,0,2,0,0,7,7,7,7,7,0,0,2,0,0,0,0,2
1,0,0,0,0,2,0,0,0,7,7,7,0,0,0,2,0,0,0,0,1
2,0,0,0,0,2,0,0,0,0,0,0,0,0,0,2,0,0,0,0,2
2,0,0,0,0,2,0,0,0,0,0,0,0,0,0,2,0,0,0,0,2
1,2,0,0,2,2,2,2,2,2,0,2,2,2,2,2,2,0,0,2,1
2,0,0,0,0,2,0,0,0,0,0,0,0,0,0,2,0,0,0,0,2
2,0,7,7,0,0,0,0,0,0,0,0,0,0,0,0,0,7,7,0,2
2,0,7,7,0,0,0,0,0,0,0,0,0,0,0,0,0,7,7,0,2
2,0,0,0,0,2,0,0,0,0,0,0,0,0,0,2,0,0,0,0,2
1,2,2,2,2,1,2,2,1,2,3,2,1,2,2,1,2,2,2,2,1
endlayer

layer
1,2,2,2,2,1,2,2,1,2,3,2,1,2,2,1,2,2,2,2,1
2,0,0,0,0,2,0,0,0,0,0,0,0,0,0,2,0,0,0,0,2
2,0,7,7,0,0,0,0,0,0,0,0,0,0,0,0,0,7,7,0,2
2,0,7,7,0,0,0,0,0,0,0,0,0,0,0,0,0,7,7,0,2
2,0,0,0,0,2,0,0,0,0,0,0,0,0,0,2,0,0,0,0,2
1,2,0,0,2,2,2,2,2,2,0,2,2,2,2,2,2,0,0,2,1
2,0,0,0,0,2,0,0,0,0,0,0,0,0,0,2,0,0,0,0,2
2,0,0,0,0,2,0,0,0,0,0,0,0,0,0,2,0,0,0,0,2
1,0,0,0,0,2,0,0,0,7,7,7,0,0,0,2,0,0,0,0,1
2,0,0,0,0,2,0,0,7,7,7,7,7,0,0,2,0,0,0,0,2
3,0,0,0,0,0,0,0,7,7,10,7,7,0,0,0,0,0,0,0,3
2,0,0,0,0,2,0,0,7,7,7,7,7,0,0,2,0,0,0,0,2
1,0,0,0,0,2,0,0,0,7,7,7,0,0,0,2,0,0,0,0,1
2,0,0,0,0,2,0,0,0,0,0,0,0,0,0,2,0,0,0,0,2
2,0,0,0,0,2,0,0,0,0,0,0,0,0,0,2,0,0,0,0,2
1,2,0,0,2,2,2,2,2,2,0,2,2,2,2,2,2,0,0,2,1
2,0,0,0,0,2,0,0,0,0,0,0,0,0,0,2,0,0,0,0,2
2,0,7,7,0,0,0,0,0,0,0,0,0,0,0,0,0,7,7,0,2
2,0,7,7,0,0,0,0,0,0,0,0,0,0,0,0,0,7,7,0,2
2,0,0,0,0,2,0,0,0,0,0,0,0,0,0,2,0,0,0,0,2
1,2,2,2,2,1,2,2,1,2,3,2,1,2,2,1,2,2,2,2,1
endlayer

layer
1,2,2,2,2,1,2,2,1,2,3,2,1,2,2,1,2,2,2,2,1
2,2,2,2,2,2,0,0,0,0,0,0,0,0,0,2,2,2,2,2,2
2,2,7,7,2,2,0,0,0,0,0,0,0,0,0,2,2,7,7,2,2
2,2,7,7,2,2,0,0,0,0,0,0,0,0,0,2,2,7,7,2,2
2,2,2,2,2,2,0,0,0,0,0,0,0,0,0,2,2,2,2,2,2
1,2,2,2,2,2,2,2,2,2,2,2,2,2,2,2,2,2,2,2,1
2,0,0,0,0,2,0,0,0,0,0,0,0,0,0,2,0,0,0,0,2
2,0,0,0,0,2,0,0,2,2,2,2,2,0,0,2,0,0,0,0,2
1,0,0,0,0,2,0,2,2,7,7,7,2,2,0,2,0,0,0,0,1
2,0,0,0,0,2,0,2,7,7,7,7,7,2,0,2,0,0,0,0,2
3,0,0,0,0,2,0,2,7,7,10,7,7,2,0,2,0,0,0,0,3
2,0,0,0,0,2,0,2,7,7,7,7,7,2,0,2,0,0,0,0,2
1,0,0,0,0,2,0,2,2,7,7,7,2,2,0,2,0,0,0,0,1
2,0,0,0,0,2,0,0,2,2,2,2,2,0,0,2,0,0,0,0,2
2,0,0,0,0,2,0,0,0,0,0,0,0,0,0,2,0,0,0,0,2
1,2,2,2,2,2,2,2,2,2,2,2,2,2,2,2,2,2,2,2,1
2,2,2,2,2,2,0,0,0,0,0,0,0,0,0,2,2,2,2,2,2
2,2,7,7,2,2,0,0,0,0,0,0,0,0,0,2,2,7,7,2,2
2,2,7,7,2,2,0,0,0,0,0,0,0,0,0,2,2,7,7,2,2
2,2,2,2,2,2,0,0,0,0,0,0,0,0,0,2,2,2,2,2,2
1,2,2,2,2,1,2,2,1,2,3,2,1,2,2,1,2,2,2,2,1
endlayer

layer
1,2,2,2,2,1,2,2,1,2,3,2,1,2,2,1,2,2,2,2,1
2,2,2,2,2,2,0,0,0,0,0,0,0,0,0,2,2,2,2,2,2
2,2,7,7,2,2,0,0,0,0,0,0,0,0,0,2,2,7,7,2,2
2,2,7,7,2,2,0,0,0,0,0,0,0,0,0,2,2,7,7,2,2
2,2,2,2,2,2,0,0,0,0,0,0,0,0,0,2,2,2,2,2,2
1,2,2,2,2,2,2,2,2,2,2,2,2,2,2,2,2,2,2,2,1
2,0,0,0,0,2,0,0,2,2,2,2,2,0,0,2,0,0,0,0,2
2,0,0,0,0,2,0,2,2,2,2,2,2,2,0,2,0,0,0,0,2
1,0,0,0,0,2,2,2,2,7,7,7,2,2,2,2,0,0,0,0,1
2,0,0,0,0,2,2,2,7,7,7,7,7,2,2,2,0,0,0,0,2
3,0,0,0,0,2,2,2,7,7,10,7,7,2,2,2,0,0,0,0,3
2,0,0,0,0,2,2,2,7,7,7,7,7,2,2,2,0,0,0,0,2
1,0,0,0,0,2,2,2,2,7,7,7,2,2,2,2,0,0,0,0,1
2,0,0,0,0,2,0,2,2,2,2,2,2,2,0,2,0,0,0,0,2
2,0,0,0,0,2,0,0,2,2,2,2,2,0,0,2,0,0,0,0,2
1,2,2,2,2,2,2,2,2,2,2,2,2,2,2,2,2,2,2,2,1
2,2,2,2,2,2,0,0,0,0,0,0,0,0,0,2,2,2,2,2,2
2,2,7,7,2,2,0,0,0,0,0,0,0,0,0,2,2,7,7,2,2
2,2,7,7,2,2,0,0,0,0,0,0,0,0,0,2,2,7,7,2,2
2,2,2,2,2,2,0,0,0,0,0,0,0,0,0,2,2,2,2,2,2
1,2,2,2,2,1,2,2,1,2,3,2,1,2,2,1,2,2,2,2,1
endlayer

layer
1,2,2,2,2,1,2,2,1,2,3,2,1,2,2,1,2,2,2,2,1
2,2,2,2,2,2,0,0,0,0,0,0,0,0,0,2,2,2,2,2,2
2,2,7,7,2,2,0,0,0,0,0,0,0,0,0,2,2,7,7,2,2
2,2,7,7,2,2,0,0,0,0,0,0,0,0,0,2,2,7,7,2,2
2,2,2,2,2,2,0,0,0,0,0,0,0,0,0,2,2,2,2,2,2
1,2,2,2,2,2,2,2,2,2,2,2,2,2,2,2,2,2,2,2,1
2,0,0,0,0,2,2,2,2,2,2,2,2,2,2,2,0,0,0,0,2
2,0,0,0,0,2,2,2,2,2,2,2,2,2,2,2,0,0,0,0,2
1,0,0,0,0,2,2,2,2,7,7,7,2,2,2,2,0,0,0,0,1
2,0,0,0,0,2,2,2,7,7,7,7,7,2,2,2,0,0,0,0,2
3,0,0,0,0,2,2,2,7,7,10,7,7,2,2,2,0,0,0,0,3
2,0,0,0,0,2,2,2,7,7,7,7,7,2,2,2,0,0,0,0,2
1,0,0,0,0,2,2,2,2,7,7,7,2,2,2,2,0,0,0,0,1
2,0,0,0,0,2,2,2,2,2,2,2,2,2,2,2,0,0,0,0,2
2,0,0,0,0,2,2,2,2,2,2,2,2,2,2,2,0,0,0,0,2
1,2,2,2,2,2,2,2,2,2,2,2,2,2,2,2,2,2,2,2,1
2,2,2,2,2,2,0,0,0,0,0,0,0,0,0,2,2,2,2,2,2
2,2,7,7,2,2,0,0,0,0,0,0,0,0,0,2,2,7,7,2,2
2,2,7,7,2,2,0,0,0,0,0,0,0,0,0,2,2,7,7,2,2
2,2,2,2,2,2,0,0,0,0,0,0,0,0,0,2,2,2,2,2,2
1,2,2,2,2,1,2,2,1,2,3,2,1,2,2,1,2,2,2,2,1
endlayer


layer
1,2,2,2,2,1,2,2,1,2,9,2,1,2,2,1,2,2,2,2,1
2,4,4,4,4,2,5,6,5,6,5,6,5,6,5,2,4,4,4,4,2
2,4,7,7,4,3,6,5,6,5,6,5,6,5,6,3,4,7,7,4,2
2,4,7,7,4,3,5,6,5,6,5,6,5,6,5,3,4,7,7,4,2
2,4,4,4,4,2,6,5,6,5,6,5,6,5,6,2,4,4,4,4,2
1,2,3,3,2,2,2,2,2,2,3,2,2,2,2,2,2,3,3,2,1
2,5,6,5,6,2,4,4,4,4,3,4,4,4,4,2,6,5,6,5,2
2,6,5,6,5,2,4,8,3,3,3,3,3,8,4,2,5,6,5,6,2
1,5,6,5,6,2,4,3,3,7,7,7,3,3,4,2,6,5,6,5,1
2,6,5,6,5,2,4,3,7,7,7,7,7,3,4,2,5,6,5,6,2
9,5,6,5,6,3,3,3,7,7,10,7,7,3,3,3,6,5,6,5,9
2,6,5,6,5,2,4,3,7,7,7,7,7,3,4,2,5,6,5,6,2
1,5,6,5,6,2,4,3,3,7,7,7,3,3,4,2,6,5,6,5,1
2,6,5,6,5,2,4,8,3,3,3,3,3,8,4,2,5,6,5,6,2
2,5,6,5,6,2,4,4,4,4,3,4,4,4,4,2,6,5,6,5,2
1,2,3,3,2,2,2,2,2,2,3,2,2,2,2,2,2,3,3,2,1
2,4,4,4,4,2,6,5,6,5,6,5,6,5,6,2,4,4,4,4,2
2,4,7,7,4,3,5,6,5,6,5,6,5,6,5,3,4,7,7,4,2
2,4,7,7,4,3,6,5,6,5,6,5,6,5,6,3,4,7,7,4,2
2,4,4,4,4,2,5,6,5,6,5,6,5,6,5,2,4,4,4,4,2
1,2,2,2,2,1,2,2,1,2,9,2,1,2,2,1,2,2,2,2,1
endlayer

layer
3,11,11,11,11,3,11,11,3,11,0,11,3,11,11,3,11,11,11,11,3
11,12,12,12,12,11,0,0,0,0,0,0,0,0,0,11,12,12,12,12,11
11,12,0,0,12,0,0,0,0,0,0,0,0,0,0,0,12,0,0,12,11
11,12,0,0,12,0,0,0,0,0,0,0,0,0,0,0,12,0,0,12,11
11,12,12,12,12,11,0,0,0,0,0,0,0,0,0,11,12,12,12,12,11
3,11,0,0,11,3,11,11,3,11,0,11,3,11,11,3,11,0,0,11,3
11,0,0,0,0,11,12,12,12,12,0,12,12,12,12,11,0,0,0,0,11
11,0,0,0,0,11,12,13,0,0,0,0,0,13,12,11,0,0,0,0,11
3,0,0,0,0,3,12,0,0,0,0,0,0,0,12,3,0,0,0,0,3
11,0,0,0,0,11,12,0,0,0,14,0,0,0,12,11,0,0,0,0,11
0,0,0,0,0,0,0,0,0,14,15,14,0,0,0,0,0,0,0,0,0
11,0,0,0,0,11,12,0,0,0,14,0,0,0,12,11,0,0,0,0,11
3,0,0,0,0,3,12,0,0,0,0,0,0,0,12,3,0,0,0,0,3
11,0,0,0,0,11,12,13,0,0,0,0,0,13,12,11,0,0,0,0,11
11,0,0,0,0,11,12,12,12,12,0,12,12,12,12,11,0,0,0,0,11
3,11,0,0,11,3,11,11,3,11,0,11,3,11,11,3,11,0,0,11,3
11,12,12,12,12,11,0,0,0,0,0,0,0,0,0,11,12,12,12,12,11
11,12,0,0,12,0,0,0,0,0,0,0,0,0,0,0,12,0,0,12,11
11,12,0,0,12,0,0,0,0,0,0,0,0,0,0,0,12,0,0,12,11
11,12,12,12,12,11,0,0,0,0,0,0,0,0,0,11,12,12,12,12,11
3,11,11,11,11,3,11,11,3,11,0,11,3,11,11,3,11,11,11,11,3
endlayer

layer
3,0,0,0,0,3,16,16,3,11,0,11,3,16,16,3,0,0,0,0,3
0,0,0,0,0,11,0,0,0,0,0,0,0,0,0,11,0,0,0,0,0
0,0,0,0,0,0,0,0,0,0,0,0,0,0,0,0,0,0,0,0,0
0,0,0,0,0,0,0,0,0,0,0,0,0,0,0,0,0,0,0,0,0
0,0,0,0,0,11,0,0,0,0,0,0,0,0,0,11,0,0,0,0,0
3,11,0,0,11,3,16,16,3,11,0,11,3,16,16,3,11,0,0,11,3
16,0,0,0,0,16,0,0,0,0,0,0,0,0,0,16,0,0,0,0,16
16,0,0,0,0,16,0,13,0,0,0,0,0,13,0,16,0,0,0,0,16
3,0,0,0,0,3,0,0,0,0,0,0,0,0,0,3,0,0,0,0,3
11,0,0,0,0,11,0,0,0,0,14,0,0,0,0,11,0,0,0,0,11
0,0,0,0,0,0,0,0,0,14,15,14,0,0,0,0,0,0,0,0,0
11,0,0,0,0,11,0,0,0,0,14,0,0,0,0,11,0,0,0,0,11
3,0,0,0,0,3,0,0,0,0,0,0,0,0,0,3,0,0,0,0,3
16,0,0,0,0,16,0,13,0,0,0,0,0,13,0,16,0,0,0,0,16
16,0,0,0,0,16,0,0,0,0,0,0,0,0,0,16,0,0,0,0,16
3,11,0,0,11,3,16,16,3,11,0,11,3,16,16,3,11,0,0,11,3
0,0,0,0,0,11,0,0,0,0,0,0,0,0,0,11,0,0,0,0,0
0,0,0,0,0,0,0,0,0,0,0,0,0,0,0,0,0,0,0,0,0
0,0,0,0,0,0,0,0,0,0,0,0,0,0,0,0,0,0,0,0,0
0,0,0,0,0,11,0,0,0,0,0,0,0,0,0,11,0,0,0,0,0
3,0,0,0,0,3,16,16,3,11,0,11,3,16,16,3,0,0,0,0,3
endlayer

layer
3,0,0,0,0,3,11,11,3,18,0,17,3,11,11,3,0,0,0,0,3
0,0,0,0,0,19,0,0,0,0,0,0,0,0,0,19,0,0,0,0,0
0,0,0,0,0,0,0,0,0,0,0,0,0,0,0,0,0,0,0,0,0
0,0,0,0,0,0,0,0,0,0,0,0,0,0,0,0,0,0,0,0,0
0,0,0,0,0,20,0,0,0,0,0,0,0,0,0,20,0,0,0,0,0
3,18,0,0,17,3,11,11,3,18,0,17,3,11,11,3,18,0,0,17,3
11,0,0,0,0,11,0,0,0,0,0,0,0,0,0,11,0,0,0,0,11
11,0,0,0,0,11,0,13,0,0,0,0,0,13,0,11,0,0,0,0,11
3,0,0,0,0,3,0,0,0,0,0,0,0,0,0,3,0,0,0,0,3
19,0,0,0,0,19,0,0,0,0,14,0,0,0,0,19,0,0,0,0,19
0,0,0,0,0,0,0,0,0,14,10,14,0,0,0,0,0,0,0,0,0
20,0,0,0,0,20,0,0,0,0,14,0,0,0,0,20,0,0,0,0,20
3,0,0,0,0,3,0,0,0,0,0,0,0,0,0,3,0,0,0,0,3
11,0,0,0,0,11,0,13,0,0,0,0,0,13,0,11,0,0,0,0,11
11,0,0,0,0,11,0,0,0,0,0,0,0,0,0,11,0,0,0,0,11
3,18,0,0,17,3,11,11,3,18,0,17,3,11,11,3,18,0,0,17,3
0,0,0,0,0,19,0,0,0,0,0,0,0,0,0,19,0,0,0,0,0
0,0,0,0,0,0,0,0,0,0,0,0,0,0,0,0,0,0,0,0,0
0,0,0,0,0,0,0,0,0,0,0,0,0,0,0,0,0,0,0,0,0
0,0,0,0,0,20,0,0,0,0,0,0,0,0,0,20,0,0,0,0,0
3,0,0,0,0,3,11,11,3,18,0,17,3,11,11,3,0,0,0,0,3
endlayer

layer
1,21,21,21,21,1,21,21,1,21,21,21,1,21,21,1,21,21,21,21,1
21,0,0,0,0,21,0,0,0,0,0,0,0,0,0,21,0,0,0,0,21
21,0,0,0,0,21,0,0,0,0,0,0,0,0,0,21,0,0,0,0,21
21,0,0,0,0,21,0,0,0,0,0,0,0,0,0,21,0,0,0,0,21
21,0,0,0,0,21,0,0,0,0,0,0,0,0,0,21,0,0,0,0,21
1,21,21,21,21,1,21,21,1,21,21,21,1,21,21,1,21,21,21,21,1
21,0,0,0,0,21,0,0,0,0,0,0,0,0,0,21,0,0,0,0,21
21,0,0,0,0,21,0,13,0,0,0,0,0,13,0,21,0,0,0,0,21
1,0,0,0,0,1,0,0,0,0,0,0,0,0,0,1,0,0,0,0,1
21,0,0,0,0,21,0,0,0,0,22,0,0,0,0,21,0,0,0,0,21
21,0,0,0,0,21,0,0,0,22,7,22,0,0,0,21,0,0,0,0,21
21,0,0,0,0,21,0,0,0,0,22,0,0,0,0,21,0,0,0,0,21
1,0,0,0,0,1,0,0,0,0,0,0,0,0,0,1,0,0,0,0,1
21,0,0,0,0,21,0,13,0,0,0,0,0,13,0,21,0,0,0,0,21
21,0,0,0,0,21,0,0,0,0,0,0,0,0,0,21,0,0,0,0,21
1,21,21,21,21,1,21,21,1,21,21,21,1,21,21,1,21,21,21,21,1
21,0,0,0,0,21,0,0,0,0,0,0,0,0,0,21,0,0,0,0,21
21,0,0,0,0,21,0,0,0,0,0,0,0,0,0,21,0,0,0,0,21
21,0,0,0,0,21,0,0,0,0,0,0,0,0,0,21,0,0,0,0,21
21,0,0,0,0,21,0,0,0,0,0,0,0,0,0,21,0,0,0,0,21
1,21,21,21,21,1,21,21,1,21,21,21,1,21,21,1,21,21,21,21,1
endlayer

layer
9,9,9,9,9,9,9,9,3,3,9,3,3,9,9,9,9,9,9,9,9
9,0,0,0,3,3,3,3,3,3,0,3,3,3,3,3,3,0,0,0,9
9,0,0,0,23,23,23,23,23,23,0,23,23,23,23,23,23,0,0,0,9
9,0,0,0,23,23,23,23,23,23,0,23,23,23,23,23,23,0,0,0,9
9,3,23,23,3,3,3,3,3,3,0,3,3,3,3,3,3,23,23,3,9
9,3,23,23,3,9,9,9,3,3,9,3,3,9,9,9,3,23,23,3,9
9,3,23,23,3,9,24,24,24,24,0,24,24,24,24,9,3,23,23,3,9
9,3,23,23,3,9,24,13,24,24,0,24,24,13,24,9,3,23,23,3,9
3,3,23,23,3,3,24,24,24,24,0,24,24,24,24,3,3,23,23,3,3
3,23,23,23,3,3,24,24,24,24,0,24,24,24,24,3,3,23,23,3,3
9,0,0,0,0,9,0,0,0,0,0,0,0,0,0,9,0,0,0,0,9
3,3,23,23,3,3,24,24,24,0,0,0,24,24,24,3,3,23,23,3,3
3,3,23,23,3,3,24,24,24,24,0,24,24,24,24,3,3,23,23,3,3
9,3,23,23,3,9,24,13,24,24,0,24,24,13,24,9,3,23,23,3,9
9,3,23,23,3,9,24,24,24,24,0,24,24,24,24,9,3,23,23,3,9
9,3,23,23,3,9,9,9,3,3,9,3,3,9,9,9,3,23,23,3,9
9,3,23,23,3,3,3,3,3,3,0,3,3,3,3,3,3,23,23,3,9
9,0,0,0,23,23,23,23,23,23,0,23,23,23,23,23,23,0,0,0,9
9,0,0,0,23,23,23,23,23,23,0,23,23,23,23,23,23,0,0,0,9
9,0,0,0,3,3,3,3,3,3,0,3,3,3,3,3,3,0,0,0,9
9,9,9,9,9,9,9,9,3,3,9,3,3,9,9,9,9,9,9,9,9
endlayer

layer
0,0,0,0,0,0,0,0,0,9,3,9,0,0,0,0,0,0,0,0,0
0,0,0,0,0,0,0,0,0,9,3,9,0,0,0,0,0,0,0,0,0
0,0,0,0,9,9,9,9,9,9,3,9,9,9,9,9,9,0,0,0,0
0,0,0,0,9,9,9,9,9,9,3,9,9,9,9,9,9,0,0,0,0
0,0,9,9,0,0,0,0,0,9,3,9,0,0,0,0,0,9,9,0,0
0,0,9,9,0,24,24,24,24,9,3,9,24,24,24,0,0,9,9,0,0
0,0,9,9,0,24,24,24,24,24,0,24,24,24,24,24,0,9,9,0,0
0,0,9,9,0,24,24,13,24,24,0,24,24,13,24,24,0,9,9,0,0
0,0,9,9,0,24,24,24,24,24,0,24,24,24,24,24,0,9,9,0,0
9,9,9,9,9,9,24,24,24,24,0,0,24,24,24,9,9,9,9,9,9
3,3,3,3,3,3,0,0,0,0,0,0,0,0,0,3,3,3,3,3,3
9,9,9,9,9,9,24,24,24,0,0,0,24,24,24,9,9,9,9,9,9
0,0,9,9,0,24,24,24,24,24,0,24,24,24,24,24,0,9,9,0,0
0,0,9,9,0,24,24,13,24,24,0,24,25,13,24,24,0,9,9,0,0
0,0,9,9,0,24,24,24,24,24,0,24,24,24,24,24,0,9,9,0,0
0,0,9,9,0,0,24,24,24,9,3,9,24,24,24,24,0,9,9,0,0
0,0,9,9,0,0,0,0,0,9,3,9,0,0,0,0,0,9,9,0,0
0,0,0,0,9,9,9,9,9,9,3,9,9,9,9,9,9,0,0,0,0
0,0,0,0,9,9,9,9,9,9,3,9,9,9,9,9,9,0,0,0,0
0,0,0,0,0,0,0,0,0,9,3,9,0,0,0,0,0,0,0,0,0
0,0,0,0,0,0,0,0,0,9,3,9,0,0,0,0,0,0,0,0,0
endlayer

layer
0,0,0,0,0,0,0,0,0,0,0,0,0,0,0,0,0,0,0,0,0
0,0,0,0,0,0,0,0,0,0,0,0,0,0,0,0,0,0,0,0,0
0,0,0,0,0,0,0,0,0,0,0,0,0,0,0,0,0,0,0,0,0
0,0,0,0,0,0,0,0,0,0,0,0,0,0,0,0,0,0,0,0,0
0,0,0,0,0,0,0,0,0,0,0,0,0,0,0,0,0,0,0,0,0
0,0,0,0,0,0,0,0,0,0,0,0,0,0,0,0,0,0,0,0,0
0,0,0,0,0,0,0,24,0,0,0,0,0,24,0,0,0,0,0,0,0
0,0,0,0,0,0,24,13,24,0,0,0,25,13,24,0,0,0,0,0,0
0,0,0,0,0,0,24,24,0,0,0,0,0,24,24,0,0,0,0,0,0
0,0,0,0,0,0,0,0,0,0,0,0,0,0,0,0,0,0,0,0,0
0,0,0,0,0,0,0,0,0,0,0,0,0,0,0,0,0,0,0,0,0
0,0,0,0,0,0,0,0,0,0,0,0,0,0,0,0,0,0,0,0,0
0,0,0,0,0,0,24,24,0,0,0,0,24,24,0,0,0,0,0,0,0
0,0,0,0,0,0,24,13,24,0,0,0,24,13,24,0,0,0,0,0,0
0,0,0,0,0,0,24,24,0,0,0,0,0,24,24,0,0,0,0,0,0
0,0,0,0,0,0,0,0,0,0,0,0,0,0,0,0,0,0,0,0,0
0,0,0,0,0,0,0,0,0,0,0,0,0,0,0,0,0,0,0,0,0
0,0,0,0,0,0,0,0,0,0,0,0,0,0,0,0,0,0,0,0,0
0,0,0,0,0,0,0,0,0,0,0,0,0,0,0,0,0,0,0,0,0
0,0,0,0,0,0,0,0,0,0,0,0,0,0,0,0,0,0,0,0,0
0,0,0,0,0,0,0,0,0,0,0,0,0,0,0,0,0,0,0,0,0
endlayer

layer
0,0,0,0,0,0,0,0,0,0,0,0,0,0,0,0,0,0,0,0,0
0,0,0,0,0,0,0,0,0,0,0,0,0,0,0,0,0,0,0,0,0
0,0,0,0,0,0,0,0,0,0,0,0,0,0,0,0,0,0,0,0,0
0,0,0,0,0,0,0,0,0,0,0,0,0,0,0,0,0,0,0,0,0
0,0,0,0,0,0,0,0,0,0,0,0,0,0,0,0,0,0,0,0,0
0,0,0,0,0,0,0,0,0,0,0,0,0,0,0,0,0,0,0,0,0
0,0,0,0,0,0,0,24,0,0,0,0,0,24,0,0,0,0,0,0,0
0,0,0,0,0,0,24,24,24,0,0,0,24,24,24,0,0,0,0,0,0
0,0,0,0,0,0,0,24,0,0,0,0,0,24,0,0,0,0,0,0,0
0,0,0,0,0,0,0,0,0,0,0,0,0,0,0,0,0,0,0,0,0
0,0,0,0,0,0,0,0,0,0,0,0,0,0,0,0,0,0,0,0,0
0,0,0,0,0,0,0,0,0,0,0,0,0,0,0,0,0,0,0,0,0
0,0,0,0,0,0,0,24,0,0,0,0,0,24,0,0,0,0,0,0,0
0,0,0,0,0,0,24,24,24,0,0,0,24,24,24,0,0,0,0,0,0
0,0,0,0,0,0,0,24,0,0,0,0,0,24,0,0,0,0,0,0,0
0,0,0,0,0,0,0,0,0,0,0,0,0,0,0,0,0,0,0,0,0
0,0,0,0,0,0,0,0,0,0,0,0,0,0,0,0,0,0,0,0,0
0,0,0,0,0,0,0,0,0,0,0,0,0,0,0,0,0,0,0,0,0
0,0,0,0,0,0,0,0,0,0,0,0,0,0,0,0,0,0,0,0,0
0,0,0,0,0,0,0,0,0,0,0,0,0,0,0,0,0,0,0,0,0
0,0,0,0,0,0,0,0,0,0,0,0,0,0,0,0,0,0,0,0,0
endlayer

