# Kujaku's Castle
# Created by Ruins mod version 15.6 Ingame Parser
# authoring Player: Kujaku10
# Created for MC 1.8: 27 Jun 2018
# Updated to MC 1.12: 5 Jul 2018

biomesToSpawnIn=flower_field,grassland,land_of_lakes,lavender_fields,meadow,miningbiome,mutated_plains,oak_savannah,pasture,plains,prairie,rwg_plains,twilight_clearing

uniqueMinDistance=1000

weight=1
embed_into_distance=6
acceptable_target_blocks=

unacceptable_target_blocks=log,planks,flowing_lava,lava,cloud,Natura:Cloud,red_mushroom_block,brown_mushroom_block,slime_congealed,slime_dirt,slime_grass,command_block,planks2,concrete,cobblestone,stonebrick,brick_block,glass,torch,oak_stairs,stone_stairs,brick_stairs,stone_brick_stairs,nether_brick_stairs,sandstone_stairs,spruce_stairs,birch_stairs,jungle_stairs,quartz_stairs,acacia_stairs,dark_oak_stairs,cobblestone_wall,stone_slab,double_stone_slab,stone_slab2,wooden_slab,double_wooden_slab,nether_brick

dimensions=26,56,34
allowable_overhang=0
max_leveling=6
leveling_buffer=-1
preserve_water=0
preserve_lava=0

rule1=0,100,preserveBlock

rule2=0,100,minecraft:stonebrick-0,minecraft:stonebrick-0,minecraft:stonebrick-1,minecraft:stonebrick-2

rule3=0,100,minecraft:cyan_glazed_terracotta-0
rule4=0,100,minecraft:cyan_glazed_terracotta-3
rule5=0,100,minecraft:gray_glazed_terracotta-0
rule6=0,100,minecraft:gray_glazed_terracotta-3
rule7=0,100,minecraft:cyan_glazed_terracotta-1
rule8=0,100,minecraft:cyan_glazed_terracotta-2
rule9=0,100,minecraft:gray_glazed_terracotta-1
rule10=0,100,minecraft:gray_glazed_terracotta-2
rule11=0,100,minecraft:green_glazed_terracotta-0
rule12=0,100,minecraft:green_glazed_terracotta-3
rule13=0,100,minecraft:white_glazed_terracotta-0
rule14=0,100,minecraft:white_glazed_terracotta-3
rule15=0,100,minecraft:green_glazed_terracotta-1
rule16=0,100,minecraft:green_glazed_terracotta-2
rule17=0,100,minecraft:white_glazed_terracotta-1
rule18=0,100,minecraft:white_glazed_terracotta-2
rule19=0,100,MobSpawner:Creeper
rule20=0,100,minecraft:web-0
rule21=0,100,MobSpawner:Spider
rule22=0,100,IInventory;minecraft:chest;minecraft:cyan_glazed_terracotta#16#0#0+minecraft:cyan_glazed_terracotta#16#0#5+minecraft:cyan_glazed_terracotta#16#0#12+minecraft:cyan_glazed_terracotta#16#0#16+minecraft:cyan_glazed_terracotta#16#0#19+minecraft:cyan_glazed_terracotta#16#0#22+minecraft:cyan_glazed_terracotta#16#0#24+minecraft:cyan_glazed_terracotta#16#0#26-3
rule23=0,100,minecraft:spruce_door-3
rule24=0,100,minecraft:spruce_door-1
rule25=0,100,IInventory;minecraft:chest;minecraft:gray_glazed_terracotta#16#0#0+minecraft:gray_glazed_terracotta#16#0#2+minecraft:gray_glazed_terracotta#16#0#7+minecraft:gray_glazed_terracotta#16#0#13+minecraft:gray_glazed_terracotta#16#0#17+minecraft:gray_glazed_terracotta#16#0#19+minecraft:gray_glazed_terracotta#16#0#21+minecraft:gray_glazed_terracotta#16#0#25-2
rule26=0,100,ChestGenHook:chests/simple_dungeon:5-3
rule27=0,100,ChestGenHook:chests/simple_dungeon:5-2
rule28=0,100,Skull:4:6-1
rule29=0,100,minecraft:stone_brick_stairs-3
rule30=0,100,minecraft:skull-1
rule31=0,100,minecraft:flower_pot-0
rule32=0,100,minecraft:iron_door-2
rule33=0,100,minecraft:iron_door-0
rule34=0,100,minecraft:stone_brick_stairs-2
rule35=0,100,IInventory;minecraft:chest;minecraft:green_glazed_terracotta#16#0#1+minecraft:green_glazed_terracotta#16#0#7+minecraft:green_glazed_terracotta#16#0#9+minecraft:green_glazed_terracotta#16#0#11+minecraft:green_glazed_terracotta#16#0#14+minecraft:green_glazed_terracotta#16#0#19+minecraft:green_glazed_terracotta#16#0#24+minecraft:green_glazed_terracotta#16#0#26-3
rule36=0,100,IInventory;minecraft:chest;minecraft:white_glazed_terracotta#16#0#2+minecraft:white_glazed_terracotta#16#0#5+minecraft:white_glazed_terracotta#16#0#8+minecraft:white_glazed_terracotta#16#0#10+minecraft:white_glazed_terracotta#16#0#15+minecraft:white_glazed_terracotta#16#0#18+minecraft:white_glazed_terracotta#16#0#21+minecraft:white_glazed_terracotta#16#0#26-2
rule37=0,100,Skull:2:9-1
rule38=0,100,MobSpawner:Zombie
rule39=0,100,MobSpawner:Skeleton
rule40=2,100,minecraft:redstone_torch-3
rule41=2,100,minecraft:redstone_torch-4
rule42=0,100,minecraft:spruce_door-8
rule43=0,100,minecraft:spruce_door-9
rule44=2,100,minecraft:redstone_torch-1
rule45=2,100,minecraft:redstone_torch-2
rule46=0,100,minecraft:tripwire_hook-3
rule47=0,100,minecraft:iron_door-9
rule48=0,100,minecraft:iron_door-8
rule49=0,100,minecraft:lever-1
rule50=0,100,minecraft:lever-2
rule51=0,100,minecraft:tripwire_hook-1
rule52=0,100,minecraft:stone_brick_stairs-0
rule53=0,100,minecraft:iron_bars-0
rule54=0,100,minecraft:stone_brick_stairs-1
rule55=0,100,minecraft:stone_slab-13
rule56=0,100,minecraft:planks-4
rule57=0,100,minecraft:sandstone-0
rule58=0,100,minecraft:planks-0
rule59=0,100,minecraft:stone_brick_stairs-6
rule60=0,100,minecraft:stone_brick_stairs-7
rule61=0,100,minecraft:fence-0
rule62=0,100,minecraft:stone_slab-5
rule63=0,100,minecraft:hay_block-4
rule64=0,100,minecraft:noteblock-0
rule65=0,100,minecraft:hay_block-8
rule66=0,100,minecraft:cobblestone_wall-0
rule67=0,100,ChestGenHook:chests/village_blacksmith:1-5
rule68=0,100,ChestGenHook:chests/spawn_bonus_chest:3-3
rule69=0,100,minecraft:lit_furnace-2
rule70=0,100,IInventory;minecraft:chest;minecraft:torch#16#0#8-2
rule71=0,100,minecraft:crafting_table-0
rule72=0,100,minecraft:hay_block-0
rule73=0,100,minecraft:anvil-3
rule74=0,100,minecraft:anvil-1
rule75=0,100,minecraft:lit_furnace-3
rule76=0,100,ChestGenHook:chests/village_blacksmith:1-4
rule77=0,100,minecraft:planks-1
rule78=1,100,minecraft:redstone_torch-5
rule79=0,100,minecraft:stone_brick_stairs-5
rule80=0,100,minecraft:planks-5
rule81=0,100,minecraft:stone_brick_stairs-4
rule82=0,100,minecraft:pumpkin-1
rule83=0,100,minecraft:pumpkin-0
rule84=0,100,minecraft:pumpkin-2
rule85=0,100,minecraft:pumpkin-3
rule86=0,100,minecraft:acacia_stairs-0
rule87=0,100,minecraft:stone_slab-0
rule88=0,100,minecraft:acacia_stairs-1
rule89=0,100,minecraft:double_stone_slab-5

layer
1,1,1,1,1,1,2,2,2,2,2,2,2,2,2,2,2,2,2,2,2,2,2,2,2,2,2,2,1,1,1,1,1,1
1,1,1,1,1,1,2,2,2,2,2,2,2,2,2,2,2,2,2,2,2,2,2,2,2,2,2,2,1,1,1,1,1,1
1,1,1,1,1,1,2,6,5,6,5,6,5,6,5,2,2,2,2,4,3,4,3,4,3,4,3,2,1,1,1,1,1,1
1,1,1,1,1,1,2,10,9,10,9,10,9,10,9,2,2,2,2,8,7,8,7,8,7,8,7,2,1,1,1,1,1,1
1,1,1,1,1,1,2,6,5,6,5,6,5,6,5,2,2,2,2,4,3,4,3,4,3,4,3,2,1,1,1,1,1,1
1,1,1,1,1,1,2,10,9,10,9,10,9,10,9,2,2,2,2,8,7,8,7,8,7,8,7,2,1,1,1,1,1,1
1,1,1,1,1,1,2,6,5,6,5,6,5,6,5,2,2,2,2,4,3,4,3,4,3,4,3,2,1,1,1,1,1,1
1,1,1,1,1,1,2,10,9,10,9,10,9,10,9,2,2,2,2,8,7,8,7,8,7,8,7,2,1,1,1,1,1,1
1,1,1,1,1,1,2,6,5,6,5,6,5,6,5,2,2,2,2,4,3,4,3,4,3,4,3,2,1,1,1,1,1,1
1,1,1,1,1,1,2,10,9,10,9,10,9,10,9,2,2,2,2,8,7,8,7,8,7,8,7,2,1,1,1,1,1,1
1,1,1,1,2,2,2,2,2,2,2,2,2,2,2,2,2,2,2,2,2,2,2,2,2,2,2,2,2,2,1,1,1,1
1,1,1,2,2,2,2,2,2,2,2,2,2,2,2,2,2,2,2,2,2,2,2,2,2,2,2,2,2,2,2,1,1,1
1,1,2,2,2,2,2,2,2,2,2,2,2,2,2,2,2,2,2,2,2,2,2,2,2,2,2,2,2,2,2,2,1,1
1,2,2,2,2,2,2,2,2,2,2,2,2,2,2,2,2,2,2,2,2,2,2,2,2,2,2,2,2,2,2,2,2,1
1,2,2,2,2,2,2,2,2,2,2,2,2,2,2,2,2,2,2,2,2,2,2,2,2,2,2,2,2,2,2,2,2,1
1,2,2,2,2,2,2,2,2,2,2,2,2,2,2,2,2,2,2,2,2,2,2,2,2,2,2,2,2,2,2,2,2,1
1,1,2,2,2,2,2,2,2,2,2,2,2,2,2,2,2,2,2,2,2,2,2,2,2,2,2,2,2,2,2,2,1,1
1,1,1,2,2,2,2,2,2,2,2,2,2,2,2,2,2,2,2,2,2,2,2,2,2,2,2,2,2,2,2,1,1,1
1,1,1,1,2,2,2,2,2,2,2,2,2,2,2,2,2,2,2,2,2,2,2,2,2,2,2,2,2,2,1,1,1,1
1,1,1,1,2,2,2,2,2,2,2,2,2,2,2,2,2,2,2,2,2,2,2,2,2,2,2,2,2,2,1,1,1,1
1,1,1,1,2,2,2,2,2,2,2,2,2,2,2,2,2,2,2,2,2,2,2,2,2,2,2,2,2,2,1,1,1,1
1,1,1,1,2,2,2,2,2,2,2,2,2,2,2,2,2,2,2,2,2,2,2,2,2,2,2,2,2,2,1,1,1,1
1,1,1,1,2,2,2,2,2,2,2,2,2,2,2,2,2,2,2,2,2,2,2,2,2,2,2,2,2,2,1,1,1,1
1,1,1,1,2,2,2,2,2,2,2,2,2,2,2,2,2,2,2,2,2,2,2,2,2,2,2,2,2,2,1,1,1,1
1,1,1,1,2,2,2,2,2,2,2,2,2,2,2,2,2,2,2,2,2,2,2,2,2,2,2,2,2,2,1,1,1,1
1,1,1,1,2,2,2,2,2,2,2,2,2,2,2,2,2,2,2,2,2,2,2,2,2,2,2,2,2,2,1,1,1,1
1,1,1,1,2,2,2,2,2,2,2,2,2,2,2,2,2,2,2,2,2,2,2,2,2,2,2,2,2,2,1,1,1,1
1,1,1,1,2,2,2,2,2,2,2,2,2,2,2,2,2,2,2,2,2,2,2,2,2,2,2,2,2,2,1,1,1,1
1,1,1,1,2,2,2,2,2,2,2,2,2,2,2,2,2,2,2,2,2,2,2,2,2,2,2,2,2,2,1,1,1,1
1,1,1,1,2,2,2,2,2,2,2,2,2,2,2,2,2,2,2,2,2,2,2,2,2,2,2,2,2,2,1,1,1,1
1,1,1,1,2,2,2,2,2,2,2,2,2,2,2,2,2,2,2,2,2,2,2,2,2,2,2,2,2,2,1,1,1,1
1,1,1,1,2,2,2,2,2,2,2,2,2,2,2,2,2,2,2,2,2,2,2,2,2,2,2,2,2,2,1,1,1,1
1,1,1,1,2,2,2,2,2,2,2,2,2,2,2,2,2,2,2,2,2,2,2,2,2,2,2,2,2,2,1,1,1,1
1,1,1,1,2,2,2,2,2,2,2,2,2,2,2,2,2,2,2,2,2,2,2,2,2,2,2,2,2,2,1,1,1,1
1,1,1,1,2,2,2,2,2,2,2,2,2,2,2,2,2,2,2,2,2,2,2,2,2,2,2,2,2,2,1,1,1,1
1,1,1,1,2,2,2,2,2,2,2,2,2,2,2,2,2,2,2,2,2,2,2,2,2,2,2,2,2,2,1,1,1,1
1,1,1,1,2,2,2,2,2,2,2,2,2,2,2,2,2,2,2,2,2,2,2,2,2,2,2,2,2,2,1,1,1,1
1,1,1,1,2,2,2,2,2,2,2,2,2,2,2,2,2,2,2,2,2,2,2,2,2,2,2,2,2,2,1,1,1,1
1,1,1,2,2,2,2,2,2,2,2,2,2,2,2,2,2,2,2,2,2,2,2,2,2,2,2,2,2,2,2,1,1,1
1,1,2,2,2,2,2,2,2,2,2,2,2,2,2,2,2,2,2,2,2,2,2,2,2,2,2,2,2,2,2,2,1,1
1,2,2,2,2,2,2,2,2,2,2,2,2,2,2,2,2,2,2,2,2,2,2,2,2,2,2,2,2,2,2,2,2,1
1,2,2,2,2,2,2,2,2,2,2,2,2,2,2,2,2,2,2,2,2,2,2,2,2,2,2,2,2,2,2,2,2,1
1,2,2,2,2,2,2,2,2,2,2,2,2,2,2,2,2,2,2,2,2,2,2,2,2,2,2,2,2,2,2,2,2,1
1,1,2,2,2,2,2,2,2,2,2,2,2,2,2,2,2,2,2,2,2,2,2,2,2,2,2,2,2,2,2,2,1,1
1,1,1,2,2,2,2,2,2,2,2,2,2,2,2,2,2,2,2,2,2,2,2,2,2,2,2,2,2,2,2,1,1,1
1,1,1,1,2,2,2,2,2,2,2,2,2,2,2,2,2,2,2,2,2,2,2,2,2,2,2,2,2,2,1,1,1,1
1,1,1,1,1,1,2,14,13,14,13,14,13,14,13,2,2,2,2,12,11,12,11,12,11,12,11,2,1,1,1,1,1,1
1,1,1,1,1,1,2,18,17,18,17,18,17,18,17,2,2,2,2,16,15,16,15,16,15,16,15,2,1,1,1,1,1,1
1,1,1,1,1,1,2,14,13,14,13,14,13,14,13,2,2,2,2,12,11,12,11,12,11,12,11,2,1,1,1,1,1,1
1,1,1,1,1,1,2,18,17,18,17,18,17,18,17,2,2,2,2,16,15,16,15,16,15,16,15,2,1,1,1,1,1,1
1,1,1,1,1,1,2,14,13,14,13,14,13,14,13,2,2,2,2,12,11,12,11,12,11,12,11,2,1,1,1,1,1,1
1,1,1,1,1,1,2,18,17,18,17,18,17,18,17,2,2,2,2,16,15,16,15,16,15,16,15,2,1,1,1,1,1,1
1,1,1,1,1,1,2,14,13,14,13,14,13,14,13,2,2,2,2,12,11,12,11,12,11,12,11,2,1,1,1,1,1,1
1,1,1,1,1,1,2,18,17,18,17,18,17,18,17,2,2,2,2,16,15,16,15,16,15,16,15,2,1,1,1,1,1,1
1,1,1,1,1,1,2,2,2,2,2,2,2,2,2,2,2,2,2,2,2,2,2,2,2,2,2,2,1,1,1,1,1,1
1,1,1,1,1,1,2,2,2,2,2,2,2,2,2,2,2,2,2,2,2,2,2,2,2,2,2,2,1,1,1,1,1,1
endlayer

layer
1,1,1,1,1,1,2,2,2,2,2,2,2,2,2,2,2,2,2,2,2,2,2,2,2,2,2,2,1,1,1,1,1,1
1,1,1,1,1,1,2,2,2,2,2,2,2,2,2,2,0,0,2,2,2,2,2,2,2,2,2,2,1,1,1,1,1,1
1,1,1,1,1,1,2,21,20,0,20,0,0,20,20,2,0,0,2,0,0,0,0,0,0,0,19,2,1,1,1,1,1,1
1,1,1,1,1,1,2,20,0,0,0,0,0,0,20,2,0,0,2,0,0,0,0,0,0,0,0,2,1,1,1,1,1,1
1,1,1,1,1,1,2,20,0,0,0,0,0,0,0,2,20,0,2,0,0,0,0,0,0,0,0,2,1,1,1,1,1,1
1,1,1,1,1,1,2,25,20,0,0,0,0,0,0,24,0,0,23,0,0,0,0,0,0,0,22,2,1,1,1,1,1,1
1,1,1,1,1,1,2,27,20,0,0,0,0,0,0,24,0,0,23,0,0,0,0,0,0,0,26,2,1,1,1,1,1,1
1,1,1,1,1,1,2,20,0,0,0,0,0,0,0,2,0,28,2,0,0,0,0,0,0,0,0,2,1,1,1,1,1,1
1,1,1,1,1,1,2,20,0,0,0,0,0,0,20,2,0,0,2,0,0,0,0,0,0,0,0,2,1,1,1,1,1,1
1,1,1,1,1,1,2,20,20,0,0,0,0,20,20,2,0,0,2,0,0,0,0,0,0,0,0,2,1,1,1,1,1,1
1,1,1,1,2,2,2,2,2,2,2,2,2,2,2,2,0,0,2,2,2,2,2,2,2,2,2,2,2,2,1,1,1,1
1,1,1,2,2,2,2,2,2,2,2,2,2,2,2,2,0,0,2,2,2,2,2,2,2,2,2,2,2,2,2,1,1,1
1,1,2,0,0,29,2,2,2,2,2,2,2,2,2,2,0,0,2,2,2,2,2,2,2,2,0,0,29,2,2,2,1,1
1,2,2,0,0,29,2,2,2,2,2,2,2,2,2,0,0,0,0,2,2,2,2,2,2,2,0,0,29,2,2,2,2,1
1,2,2,0,0,2,2,2,2,2,2,2,2,2,2,0,0,0,0,2,2,2,2,2,2,2,0,0,2,2,2,2,2,1
1,2,2,0,0,2,2,2,2,2,2,2,2,2,2,0,0,0,0,2,2,2,2,2,2,2,0,0,2,2,2,2,2,1
1,1,2,0,0,0,0,2,2,2,2,2,2,2,2,2,0,0,2,2,2,2,2,2,2,2,0,0,2,2,2,2,1,1
1,1,1,2,0,0,0,0,2,2,2,2,2,2,2,2,0,0,2,2,2,2,2,2,2,2,0,0,2,2,2,1,1,1
1,1,1,1,2,0,0,0,2,2,2,2,2,2,2,2,0,0,2,2,2,2,2,2,2,2,0,0,2,2,1,1,1,1
1,1,1,1,2,2,0,0,2,2,2,2,2,2,2,2,0,0,2,2,2,2,2,2,2,2,0,0,2,2,1,1,1,1
1,1,1,1,2,2,0,0,2,0,0,0,0,0,0,0,0,0,0,0,0,0,0,0,0,2,0,0,2,2,1,1,1,1
1,1,1,1,2,2,0,0,2,0,0,0,0,0,0,0,0,0,0,0,0,0,0,0,0,2,0,0,2,2,1,1,1,1
1,1,1,1,2,2,0,0,2,0,0,2,2,2,2,2,0,0,2,2,2,2,2,0,0,2,0,0,2,2,1,1,1,1
1,1,1,1,2,2,0,0,2,0,0,2,30,0,0,2,0,0,2,0,0,0,2,0,0,2,0,0,2,2,1,1,1,1
1,1,1,1,2,2,0,0,2,0,0,2,0,0,0,2,0,0,2,31,0,0,2,0,0,2,0,0,2,2,1,1,1,1
1,1,1,1,2,2,0,0,2,0,0,2,0,0,31,2,0,0,2,0,0,0,2,0,0,2,0,0,2,2,1,1,1,1
1,1,1,1,2,2,0,0,2,0,0,2,2,32,2,2,0,0,2,2,32,2,2,0,0,2,0,0,2,2,1,1,1,1
1,1,1,1,2,2,0,0,0,0,0,0,0,0,0,0,0,0,0,0,0,0,0,0,0,0,0,0,0,2,1,1,1,1
1,1,1,1,2,2,0,0,0,0,0,0,0,0,0,0,0,0,0,0,0,0,0,0,0,0,0,0,0,2,1,1,1,1
1,1,1,1,2,2,0,0,2,0,0,2,2,33,2,2,0,0,2,2,33,2,2,0,0,2,0,0,2,2,1,1,1,1
1,1,1,1,2,2,0,0,2,0,0,2,0,0,0,2,0,0,2,0,0,0,2,0,0,2,0,0,2,2,1,1,1,1
1,1,1,1,2,2,0,0,2,0,0,2,0,0,0,2,0,0,2,31,0,0,2,0,0,2,0,0,2,2,1,1,1,1
1,1,1,1,2,2,0,0,2,0,0,2,30,0,31,2,0,0,2,0,0,0,2,0,0,2,0,0,2,2,1,1,1,1
1,1,1,1,2,2,0,0,2,0,0,2,2,2,2,2,0,0,2,2,2,2,2,0,0,2,0,0,2,2,1,1,1,1
1,1,1,1,2,2,0,0,2,0,0,0,0,0,0,0,0,0,0,0,0,0,0,0,0,2,0,0,2,2,1,1,1,1
1,1,1,1,2,2,0,0,2,0,0,0,0,0,0,0,0,0,0,0,0,0,0,0,0,2,0,0,2,2,1,1,1,1
1,1,1,1,2,2,0,0,2,2,2,2,2,2,2,2,0,0,2,2,2,2,2,2,2,2,0,0,2,2,1,1,1,1
1,1,1,1,2,2,0,0,2,2,2,2,2,2,2,2,0,0,2,2,2,2,2,2,2,2,0,0,0,2,1,1,1,1
1,1,1,2,2,2,0,0,2,2,2,2,2,2,2,2,0,0,2,2,2,2,2,2,2,2,2,0,0,0,2,1,1,1
1,1,2,2,2,2,0,0,2,2,2,2,2,2,2,2,0,0,2,2,2,2,2,2,2,2,2,2,0,0,0,2,1,1
1,2,2,2,2,2,0,0,2,2,2,2,2,2,2,0,0,0,0,2,2,2,2,2,2,2,2,2,2,0,0,2,2,1
1,2,2,2,2,2,0,0,2,2,2,2,2,2,2,0,0,0,0,2,2,2,2,2,2,2,2,2,2,0,0,2,2,1
1,2,2,2,2,34,0,0,2,2,2,2,2,2,2,0,0,0,0,2,2,2,2,2,2,2,2,2,34,0,0,2,2,1
1,1,2,2,2,34,0,0,2,2,2,2,2,2,2,2,0,0,2,2,2,2,2,2,2,2,2,2,34,0,0,2,1,1
1,1,1,2,2,2,2,2,2,2,2,2,2,2,2,2,0,0,2,2,2,2,2,2,2,2,2,2,2,2,2,1,1,1
1,1,1,1,2,2,2,2,2,2,2,2,2,2,2,2,0,0,2,2,2,2,2,2,2,2,2,2,2,2,1,1,1,1
1,1,1,1,1,1,2,0,0,0,0,30,0,0,30,2,0,0,2,0,0,0,0,0,0,0,0,2,1,1,1,1,1,1
1,1,1,1,1,1,2,0,0,0,0,0,0,0,0,2,0,0,2,0,0,0,0,0,0,0,0,2,1,1,1,1,1,1
1,1,1,1,1,1,2,30,0,0,0,0,30,0,0,2,30,0,2,0,0,0,0,0,0,0,0,2,1,1,1,1,1,1
1,1,1,1,1,1,2,36,0,0,0,0,0,0,0,24,0,0,23,0,0,0,0,0,0,0,35,2,1,1,1,1,1,1
1,1,1,1,1,1,2,27,0,0,0,0,0,0,0,24,0,0,23,0,0,0,0,0,0,0,26,2,1,1,1,1,1,1
1,1,1,1,1,1,2,0,0,0,0,0,0,0,0,2,0,37,2,0,0,0,0,0,0,0,0,2,1,1,1,1,1,1
1,1,1,1,1,1,2,0,0,0,30,0,0,0,0,2,0,0,2,0,0,0,0,0,0,0,0,2,1,1,1,1,1,1
1,1,1,1,1,1,2,39,0,0,0,0,0,0,0,2,0,0,2,0,0,0,0,0,0,0,38,2,1,1,1,1,1,1
1,1,1,1,1,1,2,2,2,2,2,2,2,2,2,2,0,0,2,2,2,2,2,2,2,2,2,2,1,1,1,1,1,1
1,1,1,1,1,1,2,2,2,2,2,2,2,2,2,2,2,2,2,2,2,2,2,2,2,2,2,2,1,1,1,1,1,1
endlayer

layer
1,1,1,1,1,1,2,2,2,2,2,2,2,2,2,2,2,2,2,2,2,2,2,2,2,2,2,2,1,1,1,1,1,1
1,1,1,1,1,1,2,2,2,2,2,2,2,2,2,2,0,0,2,2,2,2,2,2,2,2,2,2,1,1,1,1,1,1
1,1,1,1,1,1,2,20,0,0,0,0,0,0,20,2,0,0,2,0,0,0,0,0,0,0,0,2,1,1,1,1,1,1
1,1,1,1,1,1,2,0,0,0,0,0,0,0,0,2,0,0,2,0,0,0,0,0,0,0,0,2,1,1,1,1,1,1
1,1,1,1,1,1,2,0,0,0,0,0,0,0,0,2,41,40,2,0,0,0,0,0,0,0,0,2,1,1,1,1,1,1
1,1,1,1,1,1,2,20,0,0,0,0,0,0,0,43,0,0,42,0,0,0,0,0,0,0,0,2,1,1,1,1,1,1
1,1,1,1,1,1,2,20,0,0,0,0,0,0,0,42,0,0,43,0,0,0,0,0,0,0,0,2,1,1,1,1,1,1
1,1,1,1,1,1,2,0,0,0,0,0,0,0,0,2,41,40,2,0,0,0,0,0,0,0,0,2,1,1,1,1,1,1
1,1,1,1,1,1,2,0,0,0,0,0,0,0,0,2,0,0,2,0,0,0,0,0,0,0,0,2,1,1,1,1,1,1
1,1,1,1,1,1,2,20,0,0,0,0,0,0,20,2,0,0,2,0,0,0,0,0,0,0,0,2,1,1,1,1,1,1
1,1,1,1,2,2,2,2,2,2,2,2,2,2,2,2,0,0,2,2,2,2,2,2,2,2,2,2,2,2,1,1,1,1
1,1,1,2,2,2,2,2,2,2,2,2,2,2,2,2,0,0,2,2,2,2,2,2,2,2,2,2,2,2,2,1,1,1
1,1,2,0,0,0,29,2,2,2,2,2,2,2,2,2,0,0,2,2,2,2,2,2,2,2,0,0,0,29,2,2,1,1
1,2,2,0,0,0,29,2,2,2,2,2,2,2,2,44,0,0,44,2,2,2,2,2,2,2,0,0,0,29,2,2,2,1
1,2,2,0,40,2,2,2,2,2,2,2,2,2,2,0,0,0,0,2,2,2,2,2,2,2,0,0,2,2,2,2,2,1
1,2,2,0,0,2,2,2,2,2,2,2,2,2,2,45,0,0,45,2,2,2,2,2,2,2,0,0,2,2,2,2,2,1
1,1,2,0,0,0,0,2,2,2,2,2,2,2,2,2,0,0,2,2,2,2,2,2,2,2,0,0,2,2,2,2,1,1
1,1,1,2,0,0,0,0,2,2,2,2,2,2,2,2,0,0,2,2,2,2,2,2,2,2,0,40,2,2,2,1,1,1
1,1,1,1,2,0,0,0,2,2,2,2,2,2,2,2,0,0,2,2,2,2,2,2,2,2,0,0,2,2,1,1,1,1
1,1,1,1,2,2,0,0,2,2,2,2,2,2,2,2,0,0,2,2,2,2,2,2,2,2,0,0,2,2,1,1,1,1
1,1,1,1,2,2,41,0,2,0,0,0,0,0,0,0,0,0,0,0,0,0,0,0,0,2,0,0,2,2,1,1,1,1
1,1,1,1,2,2,0,0,2,0,0,0,0,0,0,0,0,0,0,0,0,0,0,0,0,2,0,0,2,2,1,1,1,1
1,1,1,1,2,2,0,0,2,0,40,2,2,2,2,2,41,40,2,2,2,2,2,41,0,2,0,0,2,2,1,1,1,1
1,1,1,1,2,2,0,0,2,0,0,2,46,46,20,2,0,0,2,0,46,46,2,0,0,2,0,40,2,2,1,1,1,1
1,1,1,1,2,2,0,0,2,0,0,2,0,0,0,2,0,0,2,0,0,0,2,0,0,2,0,0,2,2,1,1,1,1
1,1,1,1,2,2,0,0,2,0,0,2,0,0,0,2,0,0,2,0,0,0,2,0,0,2,0,0,2,2,1,1,1,1
1,1,1,1,2,2,41,0,2,41,40,2,2,48,2,2,41,40,2,2,47,2,2,41,40,2,0,0,2,2,1,1,1,1
1,1,1,1,2,2,0,0,0,0,0,0,0,0,49,0,0,0,0,0,0,49,0,0,0,0,0,0,0,2,1,1,1,1
1,1,1,1,2,2,0,0,0,0,0,0,50,0,0,0,0,0,0,50,0,0,0,0,0,0,0,0,0,2,1,1,1,1
1,1,1,1,2,2,0,0,2,41,40,2,2,48,2,2,41,40,2,2,47,2,2,41,40,2,0,40,2,2,1,1,1,1
1,1,1,1,2,2,0,0,2,0,0,2,20,0,0,2,0,0,2,0,0,20,2,0,0,2,0,0,2,2,1,1,1,1
1,1,1,1,2,2,0,0,2,0,0,2,0,0,0,2,0,0,2,0,0,0,2,0,0,2,0,0,2,2,1,1,1,1
1,1,1,1,2,2,41,0,2,0,0,2,51,51,20,2,0,0,2,0,51,51,2,0,0,2,0,0,2,2,1,1,1,1
1,1,1,1,2,2,0,0,2,0,40,2,2,2,2,2,41,40,2,2,2,2,2,41,0,2,0,0,2,2,1,1,1,1
1,1,1,1,2,2,0,0,2,0,0,0,0,0,0,0,0,0,0,0,0,0,0,0,0,2,0,40,2,2,1,1,1,1
1,1,1,1,2,2,0,0,2,0,0,0,0,0,0,0,0,0,0,0,0,0,0,0,0,2,0,0,2,2,1,1,1,1
1,1,1,1,2,2,0,0,2,2,2,2,2,2,2,2,0,0,2,2,2,2,2,2,2,2,0,0,2,2,1,1,1,1
1,1,1,1,2,2,0,0,2,2,2,2,2,2,2,2,0,0,2,2,2,2,2,2,2,2,0,0,0,2,1,1,1,1
1,1,1,2,2,2,41,0,2,2,2,2,2,2,2,2,0,0,2,2,2,2,2,2,2,2,2,0,0,44,2,1,1,1
1,1,2,2,2,2,0,0,2,2,2,2,2,2,2,2,0,0,2,2,2,2,2,2,2,2,2,2,0,0,0,2,1,1
1,2,2,2,2,2,0,0,2,2,2,2,2,2,2,44,0,0,44,2,2,2,2,2,2,2,2,2,2,0,0,2,2,1
1,2,2,2,2,2,0,0,2,2,2,2,2,2,2,0,0,0,0,2,2,2,2,2,2,2,2,2,2,0,0,2,2,1
1,2,2,2,34,0,0,0,2,2,2,2,2,2,2,45,0,0,45,2,2,2,2,2,2,2,2,34,0,0,0,2,2,1
1,1,2,2,34,0,0,0,2,2,2,2,2,2,2,2,0,0,2,2,2,2,2,2,2,2,2,34,0,0,0,2,1,1
1,1,1,2,2,2,2,2,2,2,2,2,2,2,2,2,0,0,2,2,2,2,2,2,2,2,2,2,2,2,2,1,1,1
1,1,1,1,2,2,2,2,2,2,2,2,2,2,2,2,0,0,2,2,2,2,2,2,2,2,2,2,2,2,1,1,1,1
1,1,1,1,1,1,2,0,0,0,0,0,0,0,0,2,0,0,2,0,0,0,0,0,0,0,0,2,1,1,1,1,1,1
1,1,1,1,1,1,2,0,0,0,0,0,0,0,0,2,0,0,2,0,0,0,0,0,0,0,0,2,1,1,1,1,1,1
1,1,1,1,1,1,2,0,0,0,0,0,0,0,0,2,41,40,2,0,0,0,0,0,0,0,0,2,1,1,1,1,1,1
1,1,1,1,1,1,2,0,0,0,0,0,0,0,0,43,0,0,42,0,0,0,0,0,0,0,0,2,1,1,1,1,1,1
1,1,1,1,1,1,2,0,0,0,0,0,0,0,0,42,0,0,43,0,0,0,0,0,0,0,0,2,1,1,1,1,1,1
1,1,1,1,1,1,2,0,0,0,0,0,0,0,0,2,41,40,2,0,0,0,0,0,0,0,0,2,1,1,1,1,1,1
1,1,1,1,1,1,2,0,0,0,0,0,0,0,0,2,0,0,2,0,0,0,0,0,0,0,0,2,1,1,1,1,1,1
1,1,1,1,1,1,2,0,0,0,0,0,0,0,0,2,0,0,2,0,0,0,0,0,0,0,0,2,1,1,1,1,1,1
1,1,1,1,1,1,2,2,2,2,2,2,2,2,2,2,0,0,2,2,2,2,2,2,2,2,2,2,1,1,1,1,1,1
1,1,1,1,1,1,2,2,2,2,2,2,2,2,2,2,2,2,2,2,2,2,2,2,2,2,2,2,1,1,1,1,1,1
endlayer

layer
1,1,1,1,1,1,2,2,2,2,2,2,2,2,2,2,2,2,2,2,2,2,2,2,2,2,2,2,1,1,1,1,1,1
1,1,1,1,1,1,2,2,2,2,2,2,2,2,2,2,0,0,2,2,2,2,2,2,2,2,2,2,1,1,1,1,1,1
1,1,1,1,1,1,2,20,20,0,20,0,0,20,20,2,0,0,2,0,0,0,0,0,0,0,0,2,1,1,1,1,1,1
1,1,1,1,1,1,2,20,0,0,0,0,0,0,20,2,0,0,2,0,0,0,0,0,0,0,0,2,1,1,1,1,1,1
1,1,1,1,1,1,2,0,0,0,0,0,0,0,0,2,0,0,2,0,0,0,0,0,0,0,0,2,1,1,1,1,1,1
1,1,1,1,1,1,2,0,0,0,0,0,0,0,0,2,20,0,2,0,0,0,0,0,0,0,0,2,1,1,1,1,1,1
1,1,1,1,1,1,2,0,0,0,0,0,0,0,0,2,0,0,2,0,0,0,0,0,0,0,0,2,1,1,1,1,1,1
1,1,1,1,1,1,2,20,0,0,0,0,0,0,20,2,0,0,2,0,0,0,0,0,0,0,0,2,1,1,1,1,1,1
1,1,1,1,1,1,2,20,0,0,0,0,0,20,20,2,0,0,2,0,0,0,0,0,0,0,0,2,1,1,1,1,1,1
1,1,1,1,1,1,2,20,20,0,0,0,20,20,20,2,0,0,2,0,0,0,0,0,0,0,0,2,1,1,1,1,1,1
1,1,1,1,2,2,2,2,2,2,2,2,2,2,2,2,0,0,2,2,2,2,2,2,2,2,2,2,2,2,1,1,1,1
1,1,1,2,2,2,2,2,2,2,2,2,2,2,2,2,0,0,2,2,2,2,2,2,2,2,2,2,2,2,2,1,1,1
1,1,2,0,0,0,0,2,2,2,2,2,2,2,2,2,0,0,2,2,2,2,2,2,2,2,0,0,0,0,2,2,1,1
1,2,2,0,0,0,0,0,2,2,2,2,2,2,2,0,0,0,0,2,2,2,2,2,2,2,0,0,45,0,0,2,2,1
1,2,2,0,0,2,52,52,2,2,2,2,2,2,2,0,0,0,0,2,2,2,2,2,2,2,0,0,2,52,52,2,2,1
1,2,2,0,0,2,2,2,2,2,2,2,2,2,2,0,0,0,0,2,2,2,2,2,2,2,0,0,2,2,2,2,2,1
1,1,2,0,0,0,0,2,2,2,2,2,2,2,2,2,0,0,2,2,2,2,2,2,2,2,0,0,2,2,2,2,1,1
1,1,1,2,0,0,0,0,2,2,2,2,2,2,2,2,0,0,2,2,2,2,2,2,2,2,0,0,2,2,2,1,1,1
1,1,1,1,2,0,0,0,2,2,2,2,2,2,2,2,0,0,2,2,2,2,2,2,2,2,0,0,2,2,1,1,1,1
1,1,1,1,2,2,0,0,2,2,2,2,2,2,2,2,0,0,2,2,2,2,2,2,2,2,0,0,2,2,1,1,1,1
1,1,1,1,2,2,0,0,2,0,0,0,0,0,0,0,0,0,0,0,0,0,0,0,0,2,0,0,2,2,1,1,1,1
1,1,1,1,2,2,0,0,2,0,0,0,0,0,0,0,0,0,0,0,0,0,0,0,0,2,0,0,2,2,1,1,1,1
1,1,1,1,2,2,0,0,2,0,0,2,2,2,2,2,0,0,2,2,2,2,2,0,0,2,0,0,2,2,1,1,1,1
1,1,1,1,2,2,0,0,2,0,0,2,20,20,20,2,0,0,2,20,0,0,2,0,0,2,0,0,2,2,1,1,1,1
1,1,1,1,2,2,0,0,2,0,0,2,0,0,0,2,0,0,2,0,0,0,2,0,0,2,0,0,2,2,1,1,1,1
1,1,1,1,2,2,0,0,2,0,0,2,20,0,20,2,0,0,2,20,0,0,2,0,0,2,0,0,2,2,1,1,1,1
1,1,1,1,2,2,0,0,2,0,0,2,2,2,2,2,0,0,2,2,2,2,2,0,0,2,0,0,2,2,1,1,1,1
1,1,1,1,2,2,0,0,53,0,0,0,0,0,0,0,0,0,0,0,0,0,0,0,0,53,0,0,0,2,1,1,1,1
1,1,1,1,2,2,0,0,53,0,0,0,0,0,0,0,0,0,0,0,0,0,0,0,0,53,0,0,0,2,1,1,1,1
1,1,1,1,2,2,0,0,2,0,0,2,2,2,2,2,0,0,2,2,2,2,2,0,0,2,0,0,2,2,1,1,1,1
1,1,1,1,2,2,0,0,2,0,0,2,20,0,20,2,0,0,2,20,0,20,2,0,0,2,0,0,2,2,1,1,1,1
1,1,1,1,2,2,0,0,2,0,0,2,20,0,0,2,0,0,2,0,0,0,2,0,0,2,0,0,2,2,1,1,1,1
1,1,1,1,2,2,0,0,2,0,0,2,20,20,20,2,0,0,2,20,20,20,2,0,0,2,0,0,2,2,1,1,1,1
1,1,1,1,2,2,0,0,2,0,0,2,2,2,2,2,0,0,2,2,2,2,2,0,0,2,0,0,2,2,1,1,1,1
1,1,1,1,2,2,0,0,2,0,0,0,0,0,0,0,0,0,0,0,0,0,0,0,0,2,0,0,2,2,1,1,1,1
1,1,1,1,2,2,0,0,2,0,0,0,0,0,0,0,0,0,0,0,0,0,0,0,0,2,0,0,2,2,1,1,1,1
1,1,1,1,2,2,0,0,2,2,2,2,2,2,2,2,0,0,2,2,2,2,2,2,2,2,0,0,2,2,1,1,1,1
1,1,1,1,2,2,0,0,2,2,2,2,2,2,2,2,0,0,2,2,2,2,2,2,2,2,0,0,0,2,1,1,1,1
1,1,1,2,2,2,0,0,2,2,2,2,2,2,2,2,0,0,2,2,2,2,2,2,2,2,2,0,0,0,2,1,1,1
1,1,2,2,2,2,0,0,2,2,2,2,2,2,2,2,0,0,2,2,2,2,2,2,2,2,2,2,0,0,0,2,1,1
1,2,2,2,2,2,0,0,2,2,2,2,2,2,2,0,0,0,0,2,2,2,2,2,2,2,2,2,2,0,0,2,2,1
1,2,2,54,54,2,0,0,2,2,2,2,2,2,2,0,0,0,0,2,2,2,2,2,2,2,54,54,2,0,0,2,2,1
1,2,2,0,0,44,0,0,2,2,2,2,2,2,2,0,0,0,0,2,2,2,2,2,2,2,0,0,44,0,0,2,2,1
1,1,2,2,0,0,0,0,2,2,2,2,2,2,2,2,0,0,2,2,2,2,2,2,2,2,2,0,0,0,0,2,1,1
1,1,1,2,2,2,2,2,2,2,2,2,2,2,2,2,0,0,2,2,2,2,2,2,2,2,2,2,2,2,2,1,1,1
1,1,1,1,2,2,2,2,2,2,2,2,2,2,2,2,0,0,2,2,2,2,2,2,2,2,2,2,2,2,1,1,1,1
1,1,1,1,1,1,2,0,0,0,0,0,0,0,0,2,0,0,2,0,0,0,0,0,0,0,0,2,1,1,1,1,1,1
1,1,1,1,1,1,2,0,0,0,0,0,0,0,0,2,0,0,2,0,0,0,0,0,0,0,0,2,1,1,1,1,1,1
1,1,1,1,1,1,2,0,0,0,0,0,0,0,0,2,0,0,2,0,0,0,0,0,0,0,0,2,1,1,1,1,1,1
1,1,1,1,1,1,2,0,0,0,0,0,0,0,0,2,0,0,2,0,0,0,0,0,0,0,0,2,1,1,1,1,1,1
1,1,1,1,1,1,2,0,0,0,0,0,0,0,0,2,0,0,2,0,0,0,0,0,0,0,0,2,1,1,1,1,1,1
1,1,1,1,1,1,2,0,0,0,0,0,0,0,0,2,0,0,2,0,0,0,0,0,0,0,0,2,1,1,1,1,1,1
1,1,1,1,1,1,2,0,0,0,0,0,0,0,0,2,0,0,2,0,0,0,0,0,0,0,0,2,1,1,1,1,1,1
1,1,1,1,1,1,2,0,0,0,0,0,0,0,0,2,0,0,2,0,0,0,0,0,0,0,0,2,1,1,1,1,1,1
1,1,1,1,1,1,2,2,2,2,2,2,2,2,2,2,0,0,2,2,2,2,2,2,2,2,2,2,1,1,1,1,1,1
1,1,1,1,1,1,2,2,2,2,2,2,2,2,2,2,2,2,2,2,2,2,2,2,2,2,2,2,1,1,1,1,1,1
endlayer

layer
1,1,1,1,1,1,2,2,2,2,2,2,2,2,2,2,2,2,2,2,2,2,2,2,2,2,2,2,1,1,1,1,1,1
1,1,1,1,1,1,2,2,2,2,2,2,2,2,2,2,55,55,2,2,2,2,2,2,2,2,2,2,1,1,1,1,1,1
1,1,1,1,1,1,2,2,2,2,2,2,2,2,2,2,55,55,2,2,2,2,2,2,2,2,2,2,1,1,1,1,1,1
1,1,1,1,1,1,2,2,2,2,2,2,2,2,2,2,55,55,2,2,2,2,2,2,2,2,2,2,1,1,1,1,1,1
1,1,1,1,1,1,2,2,2,2,2,2,2,2,2,2,55,55,2,2,2,2,2,2,2,2,2,2,1,1,1,1,1,1
1,1,1,1,1,1,2,2,2,2,2,2,2,2,2,2,55,55,2,2,2,2,2,2,2,2,2,2,1,1,1,1,1,1
1,1,1,1,1,1,2,2,2,2,2,2,2,2,2,2,55,55,2,2,2,2,2,2,2,2,2,2,1,1,1,1,1,1
1,1,1,1,1,1,2,2,2,2,2,2,2,2,2,2,55,55,2,2,2,2,2,2,2,2,2,2,1,1,1,1,1,1
1,1,1,1,1,1,2,2,2,2,2,2,2,2,2,2,55,55,2,2,2,2,2,2,2,2,2,2,1,1,1,1,1,1
1,1,1,1,1,1,2,2,2,2,2,2,2,2,2,2,55,55,2,2,2,2,2,2,2,2,2,2,1,1,1,1,1,1
1,1,1,1,2,2,2,2,2,2,2,2,2,2,2,2,55,55,2,2,2,2,2,2,2,2,2,2,2,2,1,1,1,1
1,1,1,2,2,2,2,2,2,2,2,2,2,2,2,2,55,55,2,2,2,2,2,2,2,2,2,2,2,2,2,1,1,1
1,1,2,0,0,0,0,2,2,2,2,2,2,2,2,2,55,55,2,2,2,2,2,2,2,2,0,0,0,0,2,2,1,1
1,2,2,0,0,0,0,0,2,2,2,2,2,2,2,55,55,55,55,2,2,2,2,2,2,2,0,0,0,0,0,2,2,1
1,2,2,0,0,2,0,0,2,2,2,2,2,2,2,55,55,55,55,2,2,2,2,2,2,2,0,0,2,0,0,2,2,1
1,2,2,0,0,2,52,52,2,2,2,2,2,2,2,55,55,55,55,2,2,2,2,2,2,2,0,0,2,52,52,2,2,1
1,1,2,0,0,2,2,2,2,2,2,2,2,2,2,2,55,55,2,2,2,2,2,2,2,2,0,0,2,2,2,2,1,1
1,1,1,2,2,0,0,0,2,2,2,2,2,2,2,2,55,55,2,2,2,2,2,2,2,2,0,0,2,2,2,1,1,1
1,1,1,1,2,0,0,0,2,2,2,2,2,2,2,2,55,55,2,2,2,2,2,2,2,2,0,0,2,2,1,1,1,1
1,1,1,1,2,2,0,0,2,2,2,2,2,2,2,2,55,55,2,2,2,2,2,2,2,2,0,0,2,2,1,1,1,1
1,1,1,1,2,2,0,0,2,55,55,55,55,55,55,55,55,55,55,55,55,55,55,55,55,2,0,0,2,2,1,1,1,1
1,1,1,1,2,2,0,0,2,55,55,55,55,55,55,55,55,55,55,55,55,55,55,55,55,2,0,0,2,2,1,1,1,1
1,1,1,1,2,2,0,0,2,55,55,2,2,2,2,2,55,55,2,2,2,2,2,55,55,2,0,0,2,2,1,1,1,1
1,1,1,1,2,2,0,0,2,55,55,2,2,2,2,2,55,55,2,20,20,20,2,55,55,2,0,0,2,2,1,1,1,1
1,1,1,1,2,2,0,0,2,55,55,2,2,2,2,2,55,55,2,0,0,0,2,55,55,2,0,0,2,2,1,1,1,1
1,1,1,1,2,2,0,0,2,55,55,2,2,2,2,2,55,55,2,20,20,20,2,55,55,2,0,0,2,2,1,1,1,1
1,1,1,1,2,2,0,0,2,55,55,2,2,2,2,2,55,55,2,2,2,2,2,55,55,2,0,0,2,2,1,1,1,1
1,1,1,1,2,2,0,0,2,55,55,55,55,55,55,55,55,55,55,55,55,55,55,55,55,2,0,0,0,2,1,1,1,1
1,1,1,1,2,2,0,0,2,55,55,55,55,55,55,55,55,55,55,55,55,55,55,55,55,2,0,0,0,2,1,1,1,1
1,1,1,1,2,2,0,0,2,55,55,2,2,2,2,2,55,55,2,2,2,2,2,55,55,2,0,0,2,2,1,1,1,1
1,1,1,1,2,2,0,0,2,55,55,2,2,2,2,2,55,55,2,2,2,2,2,55,55,2,0,0,2,2,1,1,1,1
1,1,1,1,2,2,0,0,2,55,55,2,2,2,2,2,55,55,2,2,2,2,2,55,55,2,0,0,2,2,1,1,1,1
1,1,1,1,2,2,0,0,2,55,55,2,2,2,2,2,55,55,2,2,2,2,2,55,55,2,0,0,2,2,1,1,1,1
1,1,1,1,2,2,0,0,2,55,55,2,2,2,2,2,55,55,2,2,2,2,2,55,55,2,0,0,2,2,1,1,1,1
1,1,1,1,2,2,0,0,2,55,55,55,55,55,55,55,55,55,55,55,55,55,55,55,55,2,0,0,2,2,1,1,1,1
1,1,1,1,2,2,0,0,2,55,55,55,55,55,55,55,55,55,55,55,55,55,55,55,55,2,0,0,2,2,1,1,1,1
1,1,1,1,2,2,0,0,2,2,2,2,2,2,2,2,55,55,2,2,2,2,2,2,2,2,0,0,2,2,1,1,1,1
1,1,1,1,2,2,0,0,2,2,2,2,2,2,2,2,55,55,2,2,2,2,2,2,2,2,0,0,0,2,1,1,1,1
1,1,1,2,2,2,0,0,2,2,2,2,2,2,2,2,55,55,2,2,2,2,2,2,2,2,2,0,0,0,2,1,1,1
1,1,2,2,2,2,0,0,2,2,2,2,2,2,2,2,55,55,2,2,2,2,2,2,2,2,2,2,0,0,0,2,1,1
1,2,2,54,54,2,0,0,2,2,2,2,2,2,2,55,55,55,55,2,2,2,2,2,2,2,54,54,2,0,0,2,2,1
1,2,2,0,0,2,0,0,2,2,2,2,2,2,2,55,55,55,55,2,2,2,2,2,2,2,0,0,2,0,0,2,2,1
1,2,2,0,0,0,0,0,2,2,2,2,2,2,2,55,55,55,55,2,2,2,2,2,2,2,0,0,0,0,0,2,2,1
1,1,2,2,0,0,0,0,2,2,2,2,2,2,2,2,55,55,2,2,2,2,2,2,2,2,2,0,0,0,0,2,1,1
1,1,1,2,2,2,2,2,2,2,2,2,2,2,2,2,55,55,2,2,2,2,2,2,2,2,2,2,2,2,2,1,1,1
1,1,1,1,2,2,2,2,2,2,2,2,2,2,2,2,55,55,2,2,2,2,2,2,2,2,2,2,2,2,1,1,1,1
1,1,1,1,1,1,2,2,2,2,2,2,2,2,2,2,55,55,2,2,2,2,2,2,2,2,2,2,1,1,1,1,1,1
1,1,1,1,1,1,2,2,2,2,2,2,2,2,2,2,55,55,2,2,2,2,2,2,2,2,2,2,1,1,1,1,1,1
1,1,1,1,1,1,2,2,2,2,2,2,2,2,2,2,55,55,2,2,2,2,2,2,2,2,2,2,1,1,1,1,1,1
1,1,1,1,1,1,2,2,2,2,2,2,2,2,2,2,55,55,2,2,2,2,2,2,2,2,2,2,1,1,1,1,1,1
1,1,1,1,1,1,2,2,2,2,2,2,2,2,2,2,55,55,2,2,2,2,2,2,2,2,2,2,1,1,1,1,1,1
1,1,1,1,1,1,2,2,2,2,2,2,2,2,2,2,55,55,2,2,2,2,2,2,2,2,2,2,1,1,1,1,1,1
1,1,1,1,1,1,2,2,2,2,2,2,2,2,2,2,55,55,2,2,2,2,2,2,2,2,2,2,1,1,1,1,1,1
1,1,1,1,1,1,2,2,2,2,2,2,2,2,2,2,55,55,2,2,2,2,2,2,2,2,2,2,1,1,1,1,1,1
1,1,1,1,1,1,2,2,2,2,2,2,2,2,2,2,55,55,2,2,2,2,2,2,2,2,2,2,1,1,1,1,1,1
1,1,1,1,1,1,2,2,2,2,2,2,2,2,2,2,2,2,2,2,2,2,2,2,2,2,2,2,1,1,1,1,1,1
endlayer

layer
1,1,1,1,1,1,2,2,2,2,2,2,2,2,2,2,2,2,2,2,2,2,2,2,2,2,2,2,1,1,1,1,1,1
1,1,1,1,1,1,2,57,56,57,2,2,56,57,56,2,56,56,2,57,56,57,2,2,56,57,56,2,1,1,1,1,1,1
1,1,1,1,1,1,2,56,57,2,57,56,2,56,57,2,56,56,2,56,57,2,57,56,2,56,57,2,1,1,1,1,1,1
1,1,1,1,1,1,2,57,2,57,57,56,56,2,56,2,56,56,2,57,2,57,57,56,56,2,56,2,1,1,1,1,1,1
1,1,1,1,1,1,2,56,2,56,56,57,57,2,57,2,56,56,2,56,2,56,56,57,57,2,57,2,1,1,1,1,1,1
1,1,1,1,1,1,2,57,2,56,56,57,57,2,56,2,56,56,2,57,2,56,56,57,57,2,56,2,1,1,1,1,1,1
1,1,1,1,1,1,2,56,2,2,2,2,2,2,57,2,56,56,2,56,2,2,2,2,2,2,57,2,1,1,1,1,1,1
1,1,1,1,1,1,2,57,2,57,56,57,56,2,56,2,56,56,2,57,2,57,56,57,56,2,56,2,1,1,1,1,1,1
1,1,1,1,1,1,2,56,57,56,57,58,57,56,57,2,56,56,2,56,57,56,58,56,57,56,57,2,1,1,1,1,1,1
1,1,1,1,1,1,2,57,56,57,56,57,2,2,2,2,56,56,2,2,2,2,56,57,56,57,56,2,1,1,1,1,1,1
1,1,1,1,2,2,2,2,57,56,57,56,2,2,2,2,56,56,2,2,2,2,57,56,57,56,2,2,2,2,1,1,1,1
1,1,1,2,2,2,2,2,2,57,56,57,2,2,2,2,56,56,2,2,2,2,56,57,56,2,2,2,2,2,2,1,1,1
1,1,2,2,0,0,0,2,2,2,2,2,2,2,2,2,56,56,2,2,2,2,2,2,2,2,2,59,0,0,2,2,1,1
1,2,2,2,0,0,0,0,2,2,2,2,2,2,2,56,56,56,56,2,2,2,2,2,2,2,2,59,0,0,0,2,2,1
1,2,2,2,2,2,0,0,2,2,2,2,2,2,2,56,56,56,56,2,2,2,2,2,2,2,2,2,2,0,0,2,2,1
1,2,2,2,2,34,0,0,2,2,2,2,2,2,2,56,56,56,56,2,2,2,2,2,2,2,2,2,34,0,0,2,2,1
1,1,2,2,2,34,0,2,2,56,56,56,56,2,2,2,56,56,2,2,2,56,56,56,56,2,2,2,34,0,2,2,1,1
1,1,1,2,2,2,2,2,2,56,56,56,56,2,2,2,56,56,2,2,2,56,56,56,56,2,2,2,2,2,2,1,1,1
1,1,1,1,2,2,2,2,2,56,56,56,56,2,2,2,56,56,2,2,2,56,56,56,56,2,2,2,2,2,1,1,1,1
1,1,1,1,2,2,2,2,2,2,2,2,2,2,2,2,2,2,2,2,2,2,2,2,2,2,2,2,2,2,1,1,1,1
1,1,1,1,2,2,2,2,2,57,57,57,57,57,57,57,57,57,57,57,57,57,57,57,57,2,2,2,2,2,1,1,1,1
1,1,1,1,2,2,2,2,2,57,57,57,57,57,57,57,57,57,57,57,57,57,57,57,57,2,2,2,2,2,1,1,1,1
1,1,1,1,2,2,2,2,2,57,57,2,2,2,2,2,57,57,2,2,2,2,2,57,57,2,2,2,2,2,1,1,1,1
1,1,1,1,2,2,2,2,2,57,57,2,56,56,56,2,57,57,2,56,56,56,2,57,57,2,2,2,2,2,1,1,1,1
1,1,1,1,2,2,2,2,2,57,57,2,56,58,56,2,57,57,2,56,58,56,2,57,57,2,2,2,2,2,1,1,1,1
1,1,1,1,2,2,2,2,2,57,57,2,56,56,56,2,57,57,2,56,56,56,2,57,57,2,2,2,2,2,1,1,1,1
1,1,1,1,2,2,2,2,2,57,57,2,2,2,2,2,57,57,2,2,2,2,2,57,57,2,2,2,2,2,1,1,1,1
1,1,1,1,2,2,2,2,2,57,57,57,57,57,57,57,57,57,57,57,57,57,57,57,57,2,2,2,2,2,1,1,1,1
1,1,1,1,2,2,2,2,2,57,57,57,57,57,57,57,57,57,57,57,57,57,57,57,57,2,2,2,2,2,1,1,1,1
1,1,1,1,2,2,2,2,2,57,57,2,2,2,2,2,57,57,2,2,2,2,2,57,57,2,2,2,2,2,1,1,1,1
1,1,1,1,2,2,2,2,2,57,57,2,56,56,56,2,57,57,2,56,56,56,2,57,57,2,2,2,2,2,1,1,1,1
1,1,1,1,2,2,2,2,2,57,57,2,56,58,56,2,57,57,2,56,58,56,2,57,57,2,2,2,2,2,1,1,1,1
1,1,1,1,2,2,2,2,2,57,57,2,56,56,56,2,57,57,2,56,56,56,2,57,57,2,2,2,2,2,1,1,1,1
1,1,1,1,2,2,2,2,2,57,57,2,2,2,2,2,57,57,2,2,2,2,2,57,57,2,2,2,2,2,1,1,1,1
1,1,1,1,2,2,2,2,2,57,57,57,57,57,57,57,57,57,57,57,57,57,57,57,57,2,2,2,2,2,1,1,1,1
1,1,1,1,2,2,2,2,2,57,57,57,57,57,57,57,57,57,57,57,57,57,57,57,57,2,2,2,2,2,1,1,1,1
1,1,1,1,2,2,2,2,2,2,2,2,2,2,2,2,2,2,2,2,2,2,2,2,2,2,2,2,2,2,1,1,1,1
1,1,1,1,2,2,2,2,2,56,56,56,56,2,2,2,56,56,2,2,2,56,56,56,56,2,2,2,2,2,1,1,1,1
1,1,1,2,2,2,2,2,2,56,56,56,56,2,2,2,56,56,2,2,2,56,56,56,56,2,2,2,2,2,2,1,1,1
1,1,2,2,0,29,2,2,2,56,56,56,56,2,2,2,56,56,2,2,2,56,56,56,56,2,2,0,29,2,2,2,1,1
1,2,2,0,0,29,2,2,2,2,2,2,2,2,2,56,56,56,56,2,2,2,2,2,2,2,0,0,29,2,2,2,2,1
1,2,2,0,0,2,2,2,2,2,2,2,2,2,2,56,56,56,56,2,2,2,2,2,2,2,0,0,2,2,2,2,2,1
1,2,2,0,0,0,60,2,2,2,2,2,2,2,2,56,56,56,56,2,2,2,2,2,2,2,0,0,0,60,2,2,2,1
1,1,2,2,0,0,60,2,2,2,2,2,2,2,2,2,56,56,2,2,2,2,2,2,2,2,2,0,0,60,2,2,1,1
1,1,1,2,2,2,2,2,2,56,57,56,2,2,2,2,56,56,2,2,2,2,56,57,56,2,2,2,2,2,2,1,1,1
1,1,1,1,2,2,2,2,56,57,56,57,2,2,2,2,56,56,2,2,2,2,57,56,57,56,2,2,2,2,1,1,1,1
1,1,1,1,1,1,2,56,57,56,57,56,2,2,2,2,56,56,2,2,2,2,56,57,56,57,56,2,1,1,1,1,1,1
1,1,1,1,1,1,2,57,56,57,56,58,56,57,56,2,56,56,2,56,57,56,58,56,57,56,57,2,1,1,1,1,1,1
1,1,1,1,1,1,2,56,2,56,57,56,57,2,57,2,56,56,2,57,2,57,56,57,56,2,56,2,1,1,1,1,1,1
1,1,1,1,1,1,2,57,2,2,2,2,2,2,56,2,56,56,2,56,2,2,2,2,2,2,57,2,1,1,1,1,1,1
1,1,1,1,1,1,2,56,2,57,57,56,56,2,57,2,56,56,2,57,2,57,57,56,56,2,56,2,1,1,1,1,1,1
1,1,1,1,1,1,2,57,2,57,57,56,56,2,56,2,56,56,2,56,2,57,57,56,56,2,57,2,1,1,1,1,1,1
1,1,1,1,1,1,2,56,2,56,56,57,57,2,57,2,56,56,2,57,2,56,56,57,57,2,56,2,1,1,1,1,1,1
1,1,1,1,1,1,2,57,56,2,56,57,2,57,56,2,56,56,2,56,57,2,56,57,2,56,57,2,1,1,1,1,1,1
1,1,1,1,1,1,2,56,57,56,2,2,57,56,57,2,56,56,2,57,56,57,2,2,56,57,56,2,1,1,1,1,1,1
1,1,1,1,1,1,2,2,2,2,2,2,2,2,2,2,2,2,2,2,2,2,2,2,2,2,2,2,1,1,1,1,1,1
endlayer

layer
1,1,1,1,1,1,0,0,0,0,0,0,0,0,0,0,0,0,0,0,0,0,0,0,0,0,0,0,1,1,1,1,1,1
1,1,1,1,1,1,0,0,0,0,0,0,0,0,0,0,0,0,0,0,0,0,0,0,0,0,0,0,1,1,1,1,1,1
1,1,1,1,1,1,0,0,0,0,0,0,0,0,0,0,0,0,0,0,0,0,0,0,0,0,0,0,1,1,1,1,1,1
1,1,1,1,1,1,0,0,0,0,0,0,0,0,0,0,0,0,0,0,0,0,0,0,0,0,0,0,1,1,1,1,1,1
1,1,1,1,1,1,0,0,0,0,0,0,0,0,0,0,0,0,0,0,0,0,0,0,0,0,0,0,1,1,1,1,1,1
1,1,1,1,1,1,0,0,0,0,0,0,0,0,0,0,0,0,0,0,0,0,0,0,0,0,0,0,1,1,1,1,1,1
1,1,1,1,1,1,0,0,0,0,0,0,0,0,0,0,0,0,0,0,0,0,0,0,0,0,0,0,1,1,1,1,1,1
1,1,1,1,1,1,0,0,0,0,0,0,0,0,0,0,0,0,0,0,0,0,0,0,0,0,0,0,1,1,1,1,1,1
1,1,1,1,1,1,0,0,0,0,0,61,0,0,0,0,0,0,0,0,0,0,61,0,0,0,0,0,1,1,1,1,1,1
1,1,1,1,1,1,0,0,0,0,0,0,0,0,0,0,0,0,0,0,0,0,0,0,0,0,0,0,1,1,1,1,1,1
1,1,1,1,2,2,2,0,0,0,0,0,0,2,2,0,0,0,0,2,2,0,0,0,0,0,0,2,2,2,1,1,1,1
1,1,1,62,2,2,2,62,0,0,0,0,64,2,2,2,0,0,2,2,2,63,0,0,0,0,62,2,2,2,62,1,1,1
1,1,62,2,2,59,0,2,62,0,0,63,64,2,66,0,0,0,0,66,2,65,0,0,0,62,2,2,59,0,2,62,1,1
1,2,2,2,2,59,0,0,2,2,2,2,2,2,0,0,0,0,0,0,2,2,2,2,2,2,2,2,59,0,0,2,2,1
1,2,2,54,54,2,0,0,2,2,2,34,0,0,0,0,0,0,0,0,0,0,29,2,2,2,54,54,2,0,0,2,2,1
1,2,2,0,0,0,0,0,2,2,2,2,2,2,0,0,0,0,0,0,2,2,2,2,2,2,0,0,0,0,0,2,2,1
1,1,62,2,0,0,0,2,2,0,67,67,0,2,66,0,0,0,0,66,2,0,67,67,0,2,2,0,0,0,2,62,1,1
1,1,1,62,2,0,2,54,2,70,0,0,68,2,2,0,0,0,0,2,2,69,0,0,68,2,54,2,0,2,62,1,1,1
1,1,1,1,2,0,0,0,2,70,0,0,71,2,2,2,0,0,2,2,2,69,0,0,68,2,0,0,0,2,1,1,1,1
1,1,1,1,2,0,0,0,2,0,0,0,0,2,2,0,0,0,0,2,2,0,0,0,0,2,0,0,0,2,1,1,1,1
1,1,1,1,2,52,0,0,2,0,0,0,0,0,0,0,0,0,0,0,0,0,0,0,0,2,0,0,52,2,1,1,1,1
1,1,1,1,2,2,0,0,2,73,0,0,0,0,0,0,0,0,0,0,0,0,0,0,72,2,0,0,2,2,1,1,1,1
1,1,1,1,2,54,0,0,2,65,0,0,0,0,66,0,0,0,0,66,0,0,0,0,64,2,0,0,54,2,1,1,1,1
1,1,1,1,2,0,0,0,2,0,0,0,0,0,0,0,0,0,0,0,0,0,0,0,0,2,0,0,0,2,1,1,1,1
1,1,1,1,2,52,0,0,2,0,0,0,0,61,0,0,0,0,0,0,61,0,0,0,0,2,0,0,52,2,1,1,1,1
1,1,1,1,2,2,0,0,2,0,0,0,0,0,0,0,0,0,0,0,0,0,0,0,0,2,0,0,2,2,1,1,1,1
1,1,1,1,2,54,0,0,2,0,0,0,0,0,66,0,0,0,0,66,0,0,0,0,74,2,0,0,54,2,1,1,1,1
1,1,1,1,2,0,0,0,0,0,0,0,0,0,0,0,0,0,0,0,0,0,0,0,0,0,0,0,0,2,1,1,1,1
1,1,1,1,2,0,0,0,0,0,0,0,0,0,0,0,0,0,0,0,0,0,0,0,0,0,0,0,0,2,1,1,1,1
1,1,1,1,2,52,0,0,2,0,0,0,0,0,66,0,0,0,0,66,0,0,0,0,0,2,0,0,52,2,1,1,1,1
1,1,1,1,2,2,0,0,2,64,0,0,0,0,0,0,0,0,0,0,0,0,0,0,0,2,0,0,2,2,1,1,1,1
1,1,1,1,2,54,0,0,2,0,0,0,0,61,0,0,0,0,0,0,61,0,0,0,0,2,0,0,54,2,1,1,1,1
1,1,1,1,2,0,0,0,2,73,0,0,0,0,0,0,0,0,0,0,0,0,0,0,0,2,0,0,0,2,1,1,1,1
1,1,1,1,2,52,0,0,2,0,0,0,0,0,66,0,0,0,0,66,0,0,0,0,74,2,0,0,52,2,1,1,1,1
1,1,1,1,2,2,0,0,2,0,0,0,0,0,0,0,0,0,0,0,0,0,0,0,65,2,0,0,2,2,1,1,1,1
1,1,1,1,2,54,0,0,2,0,0,0,0,0,0,0,0,0,0,0,0,0,0,0,0,2,0,0,54,2,1,1,1,1
1,1,1,1,2,0,0,0,2,0,0,0,0,2,2,0,0,0,0,2,2,0,0,0,0,2,0,0,0,2,1,1,1,1
1,1,1,1,2,0,0,0,2,69,0,0,68,2,2,2,0,0,2,2,2,70,0,0,68,2,0,0,0,2,1,1,1,1
1,1,1,62,2,0,2,52,2,70,0,0,75,2,2,0,0,0,0,2,2,70,0,0,68,2,52,2,0,2,62,1,1,1
1,1,62,2,0,0,0,2,2,0,76,76,0,2,66,0,0,0,0,66,2,0,76,76,0,2,2,0,0,0,2,62,1,1
1,2,2,0,0,0,0,0,2,2,2,2,2,2,0,0,0,0,0,0,2,2,2,2,2,2,0,0,0,0,0,2,2,1
1,2,2,0,0,2,52,52,2,2,2,34,0,0,0,0,0,0,0,0,0,0,29,2,2,2,0,0,2,52,52,2,2,1
1,2,2,0,0,60,2,2,2,2,2,2,2,2,0,0,0,0,0,0,2,2,2,2,2,2,0,0,60,2,2,2,2,1
1,1,62,2,0,60,2,2,62,0,0,63,72,2,66,0,0,0,0,66,2,0,64,64,72,62,2,0,60,2,2,62,1,1
1,1,1,62,2,2,2,62,0,0,0,63,0,2,2,2,0,0,2,2,2,0,0,0,0,0,62,2,2,2,62,1,1,1
1,1,1,1,2,2,2,0,0,0,0,0,0,2,2,0,0,0,0,2,2,0,0,0,0,0,0,2,2,2,1,1,1,1
1,1,1,1,1,1,0,0,0,0,0,0,0,0,0,0,0,0,0,0,0,0,0,0,0,0,0,0,1,1,1,1,1,1
1,1,1,1,1,1,0,0,0,0,0,61,0,0,0,0,0,0,0,0,0,0,61,0,0,0,0,0,1,1,1,1,1,1
1,1,1,1,1,1,0,0,0,0,0,0,0,0,0,0,0,0,0,0,0,0,0,0,0,0,0,0,1,1,1,1,1,1
1,1,1,1,1,1,0,0,0,0,0,0,0,0,0,0,0,0,0,0,0,0,0,0,0,0,0,0,1,1,1,1,1,1
1,1,1,1,1,1,0,0,0,0,0,0,0,0,0,0,0,0,0,0,0,0,0,0,0,0,0,0,1,1,1,1,1,1
1,1,1,1,1,1,0,0,0,0,0,0,0,0,0,0,0,0,0,0,0,0,0,0,0,0,0,0,1,1,1,1,1,1
1,1,1,1,1,1,0,0,0,0,0,0,0,0,0,0,0,0,0,0,0,0,0,0,0,0,0,0,1,1,1,1,1,1
1,1,1,1,1,1,0,0,0,0,0,0,0,0,0,0,0,0,0,0,0,0,0,0,0,0,0,0,1,1,1,1,1,1
1,1,1,1,1,1,0,0,0,0,0,0,0,0,0,0,0,0,0,0,0,0,0,0,0,0,0,0,1,1,1,1,1,1
1,1,1,1,1,1,0,0,0,0,0,0,0,0,0,0,0,0,0,0,0,0,0,0,0,0,0,0,1,1,1,1,1,1
endlayer

layer
1,1,1,1,1,1,0,0,0,0,0,0,0,0,0,0,0,0,0,0,0,0,0,0,0,0,0,0,1,1,1,1,1,1
1,1,1,1,1,1,0,0,0,0,0,0,0,0,0,0,0,0,0,0,0,0,0,0,0,0,0,0,1,1,1,1,1,1
1,1,1,1,1,1,0,0,0,0,0,0,0,0,0,0,0,0,0,0,0,0,0,0,0,0,0,0,1,1,1,1,1,1
1,1,1,1,1,1,0,0,0,0,0,0,0,0,0,0,0,0,0,0,0,0,0,0,0,0,0,0,1,1,1,1,1,1
1,1,1,1,1,1,0,0,0,0,0,0,0,0,0,0,0,0,0,0,0,0,0,0,0,0,0,0,1,1,1,1,1,1
1,1,1,1,1,1,0,0,0,0,0,0,0,0,0,0,0,0,0,0,0,0,0,0,0,0,0,0,1,1,1,1,1,1
1,1,1,1,1,1,0,0,0,0,0,0,0,0,0,0,0,0,0,0,0,0,0,0,0,0,0,0,1,1,1,1,1,1
1,1,1,1,1,1,0,0,0,0,0,0,0,0,0,0,0,0,0,0,0,0,0,0,0,0,0,0,1,1,1,1,1,1
1,1,1,1,1,1,0,0,0,0,61,77,61,0,0,0,0,0,0,0,0,61,77,61,0,0,0,0,1,1,1,1,1,1
1,1,1,1,1,1,0,0,0,0,0,0,0,0,0,0,0,0,0,0,0,0,0,0,0,0,0,0,1,1,1,1,1,1
1,1,1,1,29,2,34,0,0,0,0,0,0,2,2,0,0,0,0,2,2,0,0,0,0,0,0,29,2,34,1,1,1,1
1,1,1,1,2,2,2,0,0,0,0,0,0,2,2,2,0,0,2,2,2,0,0,0,0,0,0,2,2,2,1,1,1,1
1,1,1,2,0,29,2,2,0,0,0,0,0,2,78,0,0,0,0,78,2,65,0,0,0,0,2,0,29,2,2,0,1,1
1,52,2,0,0,29,79,79,2,2,2,2,2,2,0,0,0,0,0,0,2,2,2,2,2,2,0,0,29,79,79,2,52,1
1,2,2,0,0,2,0,0,2,2,34,0,0,0,0,0,0,0,0,0,0,0,0,29,2,2,0,0,2,0,0,2,2,1
1,54,2,0,0,0,0,40,2,2,2,2,2,2,0,0,0,0,0,0,2,2,2,2,2,2,0,0,0,0,40,2,54,1
1,1,1,2,0,0,0,2,2,0,67,67,0,2,78,0,0,0,0,78,2,0,67,67,0,2,2,0,0,0,2,1,1,1
1,1,1,1,2,0,2,44,2,70,0,0,0,2,2,0,0,0,0,2,2,69,0,0,68,2,44,2,0,2,1,1,1,1
1,1,1,1,2,0,0,0,2,70,0,0,0,2,2,2,0,0,2,2,2,69,0,0,68,2,0,0,0,2,1,1,1,1
1,1,1,1,2,0,0,0,2,0,0,0,0,2,2,0,0,0,0,2,2,0,0,0,0,2,0,0,0,2,1,1,1,1
1,1,1,1,2,0,0,0,2,0,0,0,0,0,0,0,0,0,0,0,0,0,0,0,0,2,0,0,0,2,1,1,1,1
1,1,1,1,2,2,41,0,2,0,0,0,0,0,0,0,0,0,0,0,0,0,0,0,0,2,0,40,2,2,1,1,1,1
1,1,1,1,2,0,0,0,2,0,0,0,0,0,78,0,0,0,0,78,0,0,0,0,0,2,0,0,0,2,1,1,1,1
1,1,1,1,2,0,0,0,0,0,0,0,0,61,0,0,0,0,0,0,61,0,0,0,0,0,0,0,0,2,1,1,1,1
1,1,1,1,2,0,0,0,2,0,0,0,0,77,0,0,0,0,0,0,80,0,0,0,0,2,0,0,0,2,1,1,1,1
1,1,1,1,2,2,41,0,2,0,0,0,0,61,0,0,0,0,0,0,61,0,0,0,0,2,0,40,2,2,1,1,1,1
1,1,1,1,2,0,0,0,2,0,0,0,0,0,78,0,0,0,0,78,0,0,0,0,0,2,0,0,0,2,1,1,1,1
1,1,1,1,2,0,0,0,0,0,0,0,0,0,0,0,0,0,0,0,0,0,0,0,0,0,0,0,0,2,1,1,1,1
1,1,1,1,2,0,0,0,0,0,0,0,0,0,0,0,0,0,0,0,0,0,0,0,0,0,0,0,0,2,1,1,1,1
1,1,1,1,2,0,0,0,2,0,0,0,0,0,78,0,0,0,0,78,0,0,0,0,0,2,0,0,0,2,1,1,1,1
1,1,1,1,2,2,41,0,2,0,0,0,0,61,0,0,0,0,0,0,61,0,0,0,0,2,0,40,2,2,1,1,1,1
1,1,1,1,2,0,0,0,2,0,0,0,0,77,0,0,0,0,0,0,77,0,0,0,0,2,0,0,0,2,1,1,1,1
1,1,1,1,2,0,0,0,0,0,0,0,0,61,0,0,0,0,0,0,61,0,0,0,0,0,0,0,0,2,1,1,1,1
1,1,1,1,2,0,0,0,2,0,0,0,0,0,78,0,0,0,0,78,0,0,0,0,0,2,0,0,0,2,1,1,1,1
1,1,1,1,2,2,41,0,2,0,0,0,0,0,0,0,0,0,0,0,0,0,0,0,0,2,0,40,2,2,1,1,1,1
1,1,1,1,2,0,0,0,2,0,0,0,0,0,0,0,0,0,0,0,0,0,0,0,0,2,0,0,0,2,1,1,1,1
1,1,1,1,2,0,0,0,2,0,0,0,0,2,2,0,0,0,0,2,2,0,0,0,0,2,0,0,0,2,1,1,1,1
1,1,1,1,2,0,0,0,2,0,0,0,0,2,2,2,0,0,2,2,2,70,0,0,68,2,0,0,0,2,1,1,1,1
1,1,1,1,2,0,2,45,2,0,0,0,0,2,2,0,0,0,0,2,2,70,0,0,68,2,45,2,0,2,1,1,1,1
1,1,1,2,0,0,0,2,2,0,76,76,0,2,78,0,0,0,0,78,2,0,76,76,0,2,2,0,0,0,2,0,1,1
1,52,2,41,0,0,0,0,2,2,2,2,2,2,0,0,0,0,0,0,2,2,2,2,2,2,41,0,0,0,0,2,52,1
1,2,2,0,0,2,0,0,2,2,34,0,0,0,0,0,0,0,0,0,0,0,0,29,2,2,0,0,2,0,0,2,2,1
1,54,2,81,81,34,0,0,2,2,2,2,2,2,0,0,0,0,0,0,2,2,2,2,2,2,81,81,34,0,0,2,54,1
1,1,1,2,2,34,0,2,0,0,0,0,0,2,78,0,0,0,0,78,2,0,0,64,0,0,2,2,34,0,2,1,1,1
1,1,1,1,2,2,2,0,0,0,0,0,0,2,2,2,0,0,2,2,2,0,0,0,0,0,0,2,2,2,1,1,1,1
1,1,1,1,29,2,34,0,0,0,0,0,0,2,2,0,0,0,0,2,2,0,0,0,0,0,0,29,2,34,1,1,1,1
1,1,1,1,1,1,0,0,0,0,0,0,0,0,0,0,0,0,0,0,0,0,0,0,0,0,0,0,1,1,1,1,1,1
1,1,1,1,1,1,0,0,0,0,61,77,61,0,0,0,0,0,0,0,0,61,77,61,0,0,0,0,1,1,1,1,1,1
1,1,1,1,1,1,0,0,0,0,0,0,0,0,0,0,0,0,0,0,0,0,0,0,0,0,0,0,1,1,1,1,1,1
1,1,1,1,1,1,0,0,0,0,0,0,0,0,0,0,0,0,0,0,0,0,0,0,0,0,0,0,1,1,1,1,1,1
1,1,1,1,1,1,0,0,0,0,0,0,0,0,0,0,0,0,0,0,0,0,0,0,0,0,0,0,1,1,1,1,1,1
1,1,1,1,1,1,0,0,0,0,0,0,0,0,0,0,0,0,0,0,0,0,0,0,0,0,0,0,1,1,1,1,1,1
1,1,1,1,1,1,0,0,0,0,0,0,0,0,0,0,0,0,0,0,0,0,0,0,0,0,0,0,1,1,1,1,1,1
1,1,1,1,1,1,0,0,0,0,0,0,0,0,0,0,0,0,0,0,0,0,0,0,0,0,0,0,1,1,1,1,1,1
1,1,1,1,1,1,0,0,0,0,0,0,0,0,0,0,0,0,0,0,0,0,0,0,0,0,0,0,1,1,1,1,1,1
1,1,1,1,1,1,0,0,0,0,0,0,0,0,0,0,0,0,0,0,0,0,0,0,0,0,0,0,1,1,1,1,1,1
endlayer

layer
1,1,1,1,1,1,0,0,0,0,0,0,0,0,0,0,0,0,0,0,0,0,0,0,0,0,0,0,1,1,1,1,1,1
1,1,1,1,1,1,0,0,0,0,0,0,0,0,0,0,0,0,0,0,0,0,0,0,0,0,0,0,1,1,1,1,1,1
1,1,1,1,1,1,0,0,0,0,0,0,0,0,0,0,0,0,0,0,0,0,0,0,0,0,0,0,1,1,1,1,1,1
1,1,1,1,1,1,0,0,0,0,0,0,0,0,0,0,0,0,0,0,0,0,0,0,0,0,0,0,1,1,1,1,1,1
1,1,1,1,1,1,0,0,0,0,0,0,0,0,0,0,0,0,0,0,0,0,0,0,0,0,0,0,1,1,1,1,1,1
1,1,1,1,1,1,0,0,0,0,0,0,0,0,0,0,0,0,0,0,0,0,0,0,0,0,0,0,1,1,1,1,1,1
1,1,1,1,1,1,0,0,0,0,0,0,0,0,0,0,0,0,0,0,0,0,0,0,0,0,0,0,1,1,1,1,1,1
1,1,1,1,1,1,0,0,0,0,0,0,0,0,0,0,0,0,0,0,0,0,0,0,0,0,0,0,1,1,1,1,1,1
1,1,1,1,1,1,0,0,0,0,0,82,0,0,0,0,0,0,0,0,0,0,82,0,0,0,0,0,1,1,1,1,1,1
1,1,1,1,1,1,0,0,0,0,0,0,0,0,66,0,0,0,0,66,0,0,0,0,0,0,0,0,1,1,1,1,1,1
1,1,1,1,0,52,0,0,0,0,0,0,0,2,2,0,0,0,0,2,2,0,0,0,0,0,0,0,52,0,1,1,1,1
1,1,1,1,2,2,2,0,0,0,0,0,0,2,2,2,0,0,2,2,2,0,0,0,0,0,0,2,2,2,1,1,1,1
1,1,1,2,0,0,0,2,0,0,0,0,0,2,59,0,0,0,0,60,2,0,0,0,0,0,2,0,0,0,2,0,1,1
1,1,2,41,0,0,0,0,2,2,2,2,2,2,59,0,0,0,0,60,2,2,2,2,2,2,41,0,0,0,0,2,1,1
1,29,2,0,0,2,52,52,2,34,0,45,0,2,59,0,0,0,0,60,2,0,45,0,29,2,0,0,2,52,52,2,34,1
1,1,2,41,0,0,2,2,2,2,2,2,2,2,59,0,0,0,0,60,2,2,2,2,2,2,41,0,0,2,2,2,1,1
1,1,1,2,0,0,2,2,2,66,0,0,66,2,59,0,0,0,0,60,2,66,0,0,66,2,2,0,0,2,2,1,1,1
1,1,1,1,2,2,2,79,2,0,0,0,0,2,2,0,0,0,0,2,2,0,0,0,0,2,79,2,2,2,1,1,1,1
1,1,1,1,2,0,0,0,2,0,0,0,0,2,2,2,0,0,2,2,2,0,0,0,0,2,0,0,0,2,1,1,1,1
1,1,1,1,2,0,0,0,2,0,0,0,0,2,2,0,0,0,0,2,2,0,0,0,0,2,0,0,0,2,1,1,1,1
1,1,1,1,2,81,0,0,2,66,0,0,0,0,66,0,0,0,0,66,0,0,0,0,66,2,0,0,81,2,1,1,1,1
1,1,1,1,2,2,0,0,2,0,0,0,0,0,0,0,0,0,0,0,0,0,0,0,0,2,0,0,2,2,1,1,1,1
1,1,1,1,2,79,0,0,2,0,0,0,0,0,0,0,0,0,0,0,0,0,0,0,0,2,0,0,79,2,1,1,1,1
1,1,1,1,2,0,0,0,0,0,0,0,0,0,0,0,0,0,0,0,0,0,0,0,0,0,0,0,0,2,1,1,1,1
1,1,1,1,2,81,0,0,2,0,0,0,0,84,0,0,0,0,0,0,83,0,0,0,0,2,0,0,81,2,1,1,1,1
1,1,1,1,2,2,0,0,2,66,0,0,0,0,0,0,0,0,0,0,0,0,0,0,66,2,0,0,2,2,1,1,1,1
1,1,1,1,2,79,0,0,2,0,0,0,0,0,0,0,0,0,0,0,0,0,0,0,0,2,0,0,79,2,1,1,1,1
1,1,1,1,2,0,0,0,2,0,0,0,0,0,0,0,0,0,0,0,0,0,0,0,0,2,0,0,0,2,1,1,1,1
1,1,1,1,2,0,0,0,2,0,0,0,0,0,0,0,0,0,0,0,0,0,0,0,0,2,0,0,0,2,1,1,1,1
1,1,1,1,2,81,0,0,2,0,0,0,0,0,0,0,0,0,0,0,0,0,0,0,0,2,0,0,0,2,1,1,1,1
1,1,1,1,2,2,0,0,2,66,0,0,0,0,0,0,0,0,0,0,0,0,0,0,66,2,0,0,2,2,1,1,1,1
1,1,1,1,2,79,0,0,2,0,0,0,0,84,0,0,0,0,0,0,83,0,0,0,0,2,0,0,79,2,1,1,1,1
1,1,1,1,2,0,0,0,0,0,0,0,0,0,0,0,0,0,0,0,0,0,0,0,0,0,0,0,0,2,1,1,1,1
1,1,1,1,2,81,0,0,2,0,0,0,0,0,0,0,0,0,0,0,0,0,0,0,0,2,0,0,81,2,1,1,1,1
1,1,1,1,2,2,0,0,2,0,0,0,0,0,0,0,0,0,0,0,0,0,0,0,0,2,0,0,2,2,1,1,1,1
1,1,1,1,2,79,0,0,2,66,0,0,0,0,66,0,0,0,0,66,0,0,0,0,66,2,0,0,79,2,1,1,1,1
1,1,1,1,2,0,0,0,2,0,0,0,0,2,2,0,0,0,0,2,2,0,0,0,0,2,0,0,0,2,1,1,1,1
1,1,1,1,2,0,0,0,2,0,0,0,0,2,2,2,0,0,2,2,2,0,0,0,0,2,0,0,0,2,1,1,1,1
1,1,1,1,2,2,2,81,2,0,0,0,0,2,2,0,0,0,0,2,2,0,0,0,0,2,81,2,2,2,1,1,1,1
1,1,1,2,2,0,0,2,2,66,0,0,66,2,59,0,0,0,0,60,2,66,0,0,66,2,2,2,0,0,2,0,1,1
1,1,2,2,2,0,0,40,2,2,2,2,2,2,59,0,0,0,0,60,2,2,2,2,2,2,2,2,0,0,40,2,1,1
1,29,2,54,54,2,0,0,2,34,0,44,0,2,59,0,0,0,0,60,2,0,44,0,29,2,54,54,2,0,0,2,34,1
1,1,2,0,0,0,0,40,2,2,2,2,2,2,59,0,0,0,0,60,2,2,2,2,2,2,0,0,0,0,40,2,1,1
1,1,1,2,0,0,0,2,0,0,0,0,0,2,59,0,0,0,0,60,2,0,0,0,0,0,2,0,0,0,2,1,1,1
1,1,1,1,2,2,2,0,0,0,0,0,0,2,2,2,59,60,2,2,2,0,0,0,0,0,0,2,2,2,1,1,1,1
1,1,1,1,0,54,0,0,0,0,0,0,0,2,2,0,0,0,0,2,2,0,0,0,0,0,0,0,54,0,1,1,1,1
1,1,1,1,1,1,0,0,0,0,0,0,0,0,66,0,0,0,0,66,0,0,0,0,0,0,0,0,1,1,1,1,1,1
1,1,1,1,1,1,0,0,0,0,0,85,0,0,0,0,0,0,0,0,0,0,85,0,0,0,0,0,1,1,1,1,1,1
1,1,1,1,1,1,0,0,0,0,0,0,0,0,0,0,0,0,0,0,0,0,0,0,0,0,0,0,1,1,1,1,1,1
1,1,1,1,1,1,0,0,0,0,0,0,0,0,0,0,0,0,0,0,0,0,0,0,0,0,0,0,1,1,1,1,1,1
1,1,1,1,1,1,0,0,0,0,0,0,0,0,0,0,0,0,0,0,0,0,0,0,0,0,0,0,1,1,1,1,1,1
1,1,1,1,1,1,0,0,0,0,0,0,0,0,0,0,0,0,0,0,0,0,0,0,0,0,0,0,1,1,1,1,1,1
1,1,1,1,1,1,0,0,0,0,0,0,0,0,0,0,0,0,0,0,0,0,0,0,0,0,0,0,1,1,1,1,1,1
1,1,1,1,1,1,0,0,0,0,0,0,0,0,0,0,0,0,0,0,0,0,0,0,0,0,0,0,1,1,1,1,1,1
1,1,1,1,1,1,0,0,0,0,0,0,0,0,0,0,0,0,0,0,0,0,0,0,0,0,0,0,1,1,1,1,1,1
1,1,1,1,1,1,0,0,0,0,0,0,0,0,0,0,0,0,0,0,0,0,0,0,0,0,0,0,1,1,1,1,1,1
endlayer

layer
1,1,1,1,1,1,0,0,0,0,0,0,0,0,0,0,0,0,0,0,0,0,0,0,0,0,0,0,1,1,1,1,1,1
1,1,1,1,1,1,0,0,0,0,0,0,0,0,0,0,0,0,0,0,0,0,0,0,0,0,0,0,1,1,1,1,1,1
1,1,1,1,1,1,0,0,0,0,0,0,0,0,0,0,0,0,0,0,0,0,0,0,0,0,0,0,1,1,1,1,1,1
1,1,1,1,1,1,0,0,0,0,0,0,0,0,0,0,0,0,0,0,0,0,0,0,0,0,0,0,1,1,1,1,1,1
1,1,1,1,1,1,0,0,0,0,0,0,0,0,0,0,0,0,0,0,0,0,0,0,0,0,0,0,1,1,1,1,1,1
1,1,1,1,1,1,0,0,0,0,0,0,0,0,0,0,0,0,0,0,0,0,0,0,0,0,0,0,1,1,1,1,1,1
1,1,1,1,1,1,0,0,0,0,0,0,0,0,0,0,0,0,0,0,0,0,0,0,0,0,0,0,1,1,1,1,1,1
1,1,1,1,1,1,0,0,0,0,0,0,0,0,0,0,0,0,0,0,0,0,0,0,0,0,0,0,1,1,1,1,1,1
1,1,1,1,1,1,0,0,0,0,0,0,0,0,0,0,0,0,0,0,0,0,0,0,0,0,0,0,1,1,1,1,1,1
1,1,1,1,1,1,0,0,0,0,0,0,0,0,78,0,0,0,0,78,0,0,0,0,0,0,0,0,1,1,1,1,1,1
1,1,1,1,0,0,0,0,0,0,0,0,0,2,2,59,0,0,60,2,2,0,0,0,0,0,0,0,0,0,1,1,1,1
1,1,1,1,2,2,2,0,0,0,0,0,0,2,2,2,59,60,2,2,2,0,0,0,0,0,0,2,2,2,1,1,1,1
1,1,1,2,0,0,0,2,0,0,0,0,0,2,2,59,0,0,60,2,2,0,0,0,0,0,2,0,0,0,2,0,1,1
1,1,2,0,0,0,0,0,2,2,2,2,2,2,2,59,0,0,60,2,2,2,2,2,2,2,0,0,0,0,0,2,1,1
1,1,2,0,0,2,0,0,0,0,0,0,0,2,2,59,0,0,60,2,2,0,0,0,0,29,0,0,2,0,0,2,1,1
1,1,2,2,2,34,0,0,2,2,2,2,2,2,2,59,0,0,60,2,2,2,2,2,2,2,2,2,34,0,0,2,1,1
1,1,1,2,2,34,0,2,2,78,0,0,78,2,2,59,0,0,60,2,2,78,0,0,78,2,2,2,34,0,2,1,1,1
1,1,1,1,2,2,2,2,2,0,0,0,0,2,2,59,0,0,60,2,2,0,0,0,0,2,2,2,2,2,1,1,1,1
1,1,1,1,2,2,2,2,2,0,0,0,0,2,2,2,59,60,2,2,2,0,0,0,0,2,2,2,2,2,1,1,1,1
1,1,1,1,2,2,2,2,2,0,0,0,0,2,2,59,0,0,60,2,2,0,0,0,0,2,2,2,2,2,1,1,1,1
1,1,1,1,2,2,2,2,2,78,0,0,0,0,78,0,0,0,0,78,0,0,0,0,78,2,2,2,2,2,1,1,1,1
1,1,1,1,2,2,2,2,2,0,0,0,0,0,0,0,0,0,0,0,0,0,0,0,0,2,2,2,2,2,1,1,1,1
1,1,1,1,2,2,2,2,2,0,0,0,0,0,0,0,0,0,0,0,0,0,0,0,0,2,2,2,2,2,1,1,1,1
1,1,1,1,2,2,2,2,2,0,0,0,0,0,0,0,0,0,0,0,0,0,0,0,0,2,2,2,2,2,1,1,1,1
1,1,1,1,2,2,2,2,2,0,0,0,0,0,0,0,0,0,0,0,0,0,0,0,0,2,2,2,2,2,1,1,1,1
1,1,1,1,2,2,2,2,2,78,0,0,0,0,0,0,0,0,0,0,0,0,0,0,78,2,2,2,2,2,1,1,1,1
1,1,1,1,2,2,2,2,2,0,0,0,0,0,0,0,0,0,0,0,0,0,0,0,0,2,2,2,2,2,1,1,1,1
1,1,1,1,2,2,2,2,2,0,0,0,0,0,0,0,0,0,0,0,0,0,0,0,0,2,2,2,2,2,1,1,1,1
1,1,1,1,2,2,2,2,2,0,0,0,0,0,0,0,0,0,0,0,0,0,0,0,0,2,2,2,2,2,1,1,1,1
1,1,1,1,2,2,2,2,2,0,0,0,0,0,0,0,0,0,0,0,0,0,0,0,0,2,2,2,2,2,1,1,1,1
1,1,1,1,2,2,2,2,2,78,0,0,0,0,0,0,0,0,0,0,0,0,0,0,78,2,2,2,2,2,1,1,1,1
1,1,1,1,2,2,2,2,2,0,0,0,0,0,0,0,0,0,0,0,0,0,0,0,0,2,2,2,2,2,1,1,1,1
1,1,1,1,2,2,2,2,2,0,0,0,0,0,0,0,0,0,0,0,0,0,0,0,0,2,2,2,2,2,1,1,1,1
1,1,1,1,2,2,2,2,2,0,0,0,0,0,0,0,0,0,0,0,0,0,0,0,0,2,2,2,2,2,1,1,1,1
1,1,1,1,2,2,2,2,2,0,0,0,0,0,0,0,0,0,0,0,0,0,0,0,0,2,2,2,2,2,1,1,1,1
1,1,1,1,2,2,2,2,2,78,0,0,0,0,78,0,0,0,0,78,0,0,0,0,78,2,2,2,2,2,1,1,1,1
1,1,1,1,2,2,2,2,2,0,0,0,0,2,2,59,0,0,60,2,2,0,0,0,0,2,2,2,2,2,1,1,1,1
1,1,1,1,2,2,2,2,2,0,0,0,0,2,2,2,59,60,2,2,2,0,0,0,0,2,2,2,2,2,1,1,1,1
1,1,1,1,2,2,2,2,2,0,0,0,0,2,2,59,0,0,60,2,2,0,0,0,0,2,2,2,2,2,1,1,1,1
1,1,1,2,0,29,2,2,2,78,0,0,78,2,2,59,0,0,60,2,2,78,0,0,78,2,2,0,29,2,2,0,1,1
1,1,2,0,0,29,2,2,2,2,2,2,2,2,2,59,0,0,60,2,2,2,2,2,2,2,0,0,29,2,2,2,1,1
1,1,2,0,0,2,0,0,34,0,0,0,0,2,2,59,0,0,60,2,2,0,0,0,0,0,0,0,2,0,0,2,1,1
1,1,2,0,0,0,0,0,2,2,2,2,2,2,2,59,0,0,60,2,2,2,2,2,2,2,0,0,0,0,0,2,1,1
1,1,1,2,0,0,0,2,0,0,0,0,0,2,2,59,0,0,60,2,2,0,0,0,0,0,2,0,0,0,2,1,1,1
1,1,1,1,2,2,2,0,0,0,0,0,0,2,2,2,2,2,2,2,2,0,0,0,0,0,0,2,2,2,1,1,1,1
1,1,1,1,0,0,0,0,0,0,0,0,0,2,2,59,0,0,60,2,2,0,0,0,0,0,0,0,0,0,1,1,1,1
1,1,1,1,1,1,0,0,0,0,0,0,0,0,78,0,0,0,0,78,0,0,0,0,0,0,0,0,1,1,1,1,1,1
1,1,1,1,1,1,0,0,0,0,0,0,0,0,0,0,0,0,0,0,0,0,0,0,0,0,0,0,1,1,1,1,1,1
1,1,1,1,1,1,0,0,0,0,0,0,0,0,0,0,0,0,0,0,0,0,0,0,0,0,0,0,1,1,1,1,1,1
1,1,1,1,1,1,0,0,0,0,0,0,0,0,0,0,0,0,0,0,0,0,0,0,0,0,0,0,1,1,1,1,1,1
1,1,1,1,1,1,0,0,0,0,0,0,0,0,0,0,0,0,0,0,0,0,0,0,0,0,0,0,1,1,1,1,1,1
1,1,1,1,1,1,0,0,0,0,0,0,0,0,0,0,0,0,0,0,0,0,0,0,0,0,0,0,1,1,1,1,1,1
1,1,1,1,1,1,0,0,0,0,0,0,0,0,0,0,0,0,0,0,0,0,0,0,0,0,0,0,1,1,1,1,1,1
1,1,1,1,1,1,0,0,0,0,0,0,0,0,0,0,0,0,0,0,0,0,0,0,0,0,0,0,1,1,1,1,1,1
1,1,1,1,1,1,0,0,0,0,0,0,0,0,0,0,0,0,0,0,0,0,0,0,0,0,0,0,1,1,1,1,1,1
1,1,1,1,1,1,0,0,0,0,0,0,0,0,0,0,0,0,0,0,0,0,0,0,0,0,0,0,1,1,1,1,1,1
endlayer

layer
1,1,1,1,1,1,0,0,0,0,0,0,0,0,0,0,0,0,0,0,0,0,0,0,0,0,0,0,1,1,1,1,1,1
1,1,1,1,1,1,0,0,0,0,0,0,0,0,0,0,0,0,0,0,0,0,0,0,0,0,0,0,1,1,1,1,1,1
1,1,1,1,1,1,0,0,0,0,0,0,0,0,0,0,0,0,0,0,0,0,0,0,0,0,0,0,1,1,1,1,1,1
1,1,1,1,1,1,0,0,0,0,0,0,0,0,0,0,0,0,0,0,0,0,0,0,0,0,0,0,1,1,1,1,1,1
1,1,1,1,1,1,0,0,0,0,0,0,0,0,0,0,0,0,0,0,0,0,0,0,0,0,0,0,1,1,1,1,1,1
1,1,1,1,1,1,0,0,0,0,0,0,0,0,0,0,0,0,0,0,0,0,0,0,0,0,0,0,1,1,1,1,1,1
1,1,1,1,1,1,0,0,0,0,0,0,0,0,0,0,0,0,0,0,0,0,0,0,0,0,0,0,1,1,1,1,1,1
1,1,1,1,1,1,0,0,0,0,0,0,0,0,0,0,0,0,0,0,0,0,0,0,0,0,0,0,1,1,1,1,1,1
1,1,1,1,1,1,0,0,0,0,0,0,0,0,0,0,0,0,0,0,0,0,0,0,0,0,0,0,1,1,1,1,1,1
1,1,1,1,1,1,0,0,0,0,0,0,0,0,0,0,0,0,0,0,0,0,0,0,0,0,0,0,1,1,1,1,1,1
1,1,1,1,0,0,0,0,0,0,0,0,0,2,2,2,59,60,2,2,2,0,0,0,0,0,0,0,0,0,1,1,1,1
1,1,1,1,2,0,2,0,0,0,0,0,0,2,2,2,2,2,2,2,2,0,0,0,0,0,0,2,0,2,1,1,1,1
1,1,1,2,2,0,0,2,0,0,0,0,0,2,2,2,2,2,2,2,2,0,0,0,0,0,2,2,0,0,2,0,1,1
1,1,2,2,2,0,0,40,2,2,2,2,2,2,2,2,2,2,2,2,2,2,2,2,2,2,2,2,0,0,40,2,1,1
1,1,0,54,54,2,0,0,0,0,0,0,2,2,2,2,2,2,2,2,2,2,0,0,0,0,29,54,2,0,0,0,1,1
1,1,2,0,0,0,0,40,2,2,2,2,2,2,2,2,2,2,2,2,2,2,2,2,2,2,0,0,0,0,40,2,1,1
1,1,1,2,0,0,0,2,2,2,2,2,2,2,2,2,2,2,2,2,2,2,2,2,2,2,2,0,0,0,2,1,1,1
1,1,1,1,2,0,2,54,2,2,2,2,2,2,2,2,2,2,2,2,2,2,2,2,2,2,0,2,0,2,1,1,1,1
1,1,1,1,2,0,0,0,2,2,2,2,2,2,2,2,2,2,2,2,2,2,2,2,2,2,0,0,0,2,1,1,1,1
1,1,1,1,2,0,0,52,2,2,2,2,2,2,2,2,2,2,2,2,2,2,2,2,2,2,52,0,0,2,1,1,1,1
1,1,1,1,2,0,0,2,2,2,2,2,2,2,0,0,0,0,0,0,2,2,2,2,2,2,2,0,0,2,1,1,1,1
1,1,1,1,2,0,0,54,2,2,2,2,0,0,0,0,0,0,0,0,0,0,2,2,2,2,54,0,0,2,1,1,1,1
1,1,1,1,2,0,0,0,2,2,2,2,0,0,0,0,0,0,0,0,0,0,2,2,2,2,0,0,0,2,1,1,1,1
1,1,1,1,2,0,0,0,2,2,2,2,0,0,0,0,0,0,0,0,0,0,2,2,2,2,0,0,0,2,1,1,1,1
1,1,1,1,2,0,0,52,2,2,2,2,0,0,0,0,0,0,0,0,0,0,2,2,2,2,52,0,0,2,1,1,1,1
1,1,1,1,2,0,0,2,2,2,2,2,0,0,0,0,0,0,0,0,0,0,2,2,2,2,2,0,0,2,1,1,1,1
1,1,1,1,2,0,0,54,2,2,2,2,0,0,0,0,0,0,0,0,0,0,2,2,2,2,54,0,0,2,1,1,1,1
1,1,1,1,2,0,0,0,2,2,2,2,0,0,0,0,0,0,0,0,0,0,2,2,2,2,0,0,0,2,1,1,1,1
1,1,1,1,2,0,0,0,2,2,2,2,0,0,0,0,0,0,0,0,0,0,2,2,2,2,0,0,0,2,1,1,1,1
1,1,1,1,2,0,0,52,2,2,2,2,0,0,0,0,0,0,0,0,0,0,2,2,2,2,52,0,0,2,1,1,1,1
1,1,1,1,2,0,0,2,2,2,2,2,0,0,0,0,0,0,0,0,0,0,2,2,2,2,2,0,0,2,1,1,1,1
1,1,1,1,2,0,0,54,2,2,2,2,0,0,0,0,0,0,0,0,0,0,2,2,2,2,54,0,0,2,1,1,1,1
1,1,1,1,2,0,0,0,2,2,2,2,0,0,0,0,0,0,0,0,0,0,2,2,2,2,0,0,0,2,1,1,1,1
1,1,1,1,2,0,0,0,2,2,2,2,0,0,0,0,0,0,0,0,0,0,2,2,2,2,0,0,0,2,1,1,1,1
1,1,1,1,2,0,0,52,2,2,2,2,0,0,0,0,0,0,0,0,0,0,2,2,2,2,52,0,0,2,1,1,1,1
1,1,1,1,2,0,0,2,2,2,2,2,2,2,0,0,0,0,0,0,2,2,2,2,2,2,2,0,0,2,1,1,1,1
1,1,1,1,2,0,0,54,2,2,2,2,2,2,2,2,2,2,2,2,2,2,2,2,2,2,54,0,0,2,1,1,1,1
1,1,1,1,2,0,0,0,2,2,2,2,2,2,2,2,2,2,2,2,2,2,2,2,2,2,0,0,0,2,1,1,1,1
1,1,1,1,2,0,2,52,2,2,2,2,2,2,2,2,2,2,2,2,2,2,2,2,2,2,0,2,0,2,1,1,1,1
1,1,1,2,0,0,0,2,2,2,2,2,2,2,2,2,2,2,2,2,2,2,2,2,2,2,2,0,0,0,2,0,1,1
1,1,2,41,0,0,0,0,2,2,2,2,2,2,2,2,2,2,2,2,2,2,2,2,2,2,41,0,0,0,0,2,1,1
1,1,0,0,0,2,52,34,0,0,0,0,2,2,2,2,2,2,2,2,2,2,0,0,0,0,0,0,2,52,52,0,1,1
1,1,2,41,0,0,2,2,2,2,2,2,2,2,2,2,2,2,2,2,2,2,2,2,2,2,41,0,0,2,2,2,1,1
1,1,1,2,0,0,2,2,0,0,0,0,0,2,2,2,2,2,2,2,2,0,0,0,0,0,2,0,0,2,2,1,1,1
1,1,1,1,2,0,2,0,0,0,0,0,0,2,2,2,2,2,2,2,2,0,0,0,0,0,0,2,0,2,1,1,1,1
1,1,1,1,0,0,0,0,0,0,0,0,0,2,2,2,59,60,2,2,2,0,0,0,0,0,0,0,0,0,1,1,1,1
1,1,1,1,1,1,0,0,0,0,0,0,0,0,0,0,0,0,0,0,0,0,0,0,0,0,0,0,1,1,1,1,1,1
1,1,1,1,1,1,0,0,0,0,0,0,0,0,0,0,0,0,0,0,0,0,0,0,0,0,0,0,1,1,1,1,1,1
1,1,1,1,1,1,0,0,0,0,0,0,0,0,0,0,0,0,0,0,0,0,0,0,0,0,0,0,1,1,1,1,1,1
1,1,1,1,1,1,0,0,0,0,0,0,0,0,0,0,0,0,0,0,0,0,0,0,0,0,0,0,1,1,1,1,1,1
1,1,1,1,1,1,0,0,0,0,0,0,0,0,0,0,0,0,0,0,0,0,0,0,0,0,0,0,1,1,1,1,1,1
1,1,1,1,1,1,0,0,0,0,0,0,0,0,0,0,0,0,0,0,0,0,0,0,0,0,0,0,1,1,1,1,1,1
1,1,1,1,1,1,0,0,0,0,0,0,0,0,0,0,0,0,0,0,0,0,0,0,0,0,0,0,1,1,1,1,1,1
1,1,1,1,1,1,0,0,0,0,0,0,0,0,0,0,0,0,0,0,0,0,0,0,0,0,0,0,1,1,1,1,1,1
1,1,1,1,1,1,0,0,0,0,0,0,0,0,0,0,0,0,0,0,0,0,0,0,0,0,0,0,1,1,1,1,1,1
1,1,1,1,1,1,0,0,0,0,0,0,0,0,0,0,0,0,0,0,0,0,0,0,0,0,0,0,1,1,1,1,1,1
endlayer

layer
1,1,1,1,1,1,0,0,0,0,0,0,0,0,0,0,0,0,0,0,0,0,0,0,0,0,0,0,1,1,1,1,1,1
1,1,1,1,1,1,0,0,0,0,0,0,0,0,0,0,0,0,0,0,0,0,0,0,0,0,0,0,1,1,1,1,1,1
1,1,1,1,1,1,0,0,0,0,0,0,0,0,0,0,0,0,0,0,0,0,0,0,0,0,0,0,1,1,1,1,1,1
1,1,1,1,1,1,0,0,0,0,0,0,0,0,0,0,0,0,0,0,0,0,0,0,0,0,0,0,1,1,1,1,1,1
1,1,1,1,1,1,0,0,0,0,0,0,0,0,0,0,0,0,0,0,0,0,0,0,0,0,0,0,1,1,1,1,1,1
1,1,1,1,1,1,0,0,0,0,0,0,0,0,0,0,0,0,0,0,0,0,0,0,0,0,0,0,1,1,1,1,1,1
1,1,1,1,1,1,0,0,0,0,0,0,0,0,0,0,0,0,0,0,0,0,0,0,0,0,0,0,1,1,1,1,1,1
1,1,1,1,1,1,0,0,0,0,0,0,0,0,0,0,0,0,0,0,0,0,0,0,0,0,0,0,1,1,1,1,1,1
1,1,1,1,1,1,0,0,0,0,0,0,0,0,0,0,0,0,0,0,0,0,0,0,0,0,0,0,1,1,1,1,1,1
1,1,1,1,1,1,0,0,0,0,0,0,60,81,59,0,0,0,0,60,81,81,0,0,0,0,0,0,1,1,1,1,1,1
1,1,1,1,0,0,0,0,0,0,0,0,60,2,2,2,2,2,2,2,2,59,0,0,0,0,0,0,0,0,1,1,1,1
1,1,1,1,2,0,2,0,0,0,0,0,79,2,34,0,0,0,0,29,2,79,0,0,0,0,0,2,0,2,1,1,1,1
1,1,1,2,0,29,2,2,0,0,0,0,0,2,0,0,0,0,0,0,2,0,0,0,0,0,2,0,29,2,2,0,1,1
1,1,2,41,0,29,2,2,2,2,2,2,2,2,0,0,0,0,0,0,2,2,2,2,2,2,41,0,29,2,2,2,1,1
1,1,0,0,0,2,0,0,2,0,0,2,34,0,0,0,0,0,0,0,0,29,2,0,0,0,0,0,2,0,0,0,1,1
1,1,2,41,0,0,0,0,2,2,2,2,2,2,0,0,0,0,0,0,2,2,2,2,2,2,41,0,0,0,0,2,1,1
1,1,1,2,0,0,0,2,2,0,0,0,0,2,0,0,0,0,0,0,2,0,0,0,0,2,2,0,0,0,2,1,1,1
1,1,1,1,2,0,2,0,2,0,0,0,0,0,0,0,0,0,0,0,0,0,0,0,0,2,0,2,0,2,1,1,1,1
1,1,1,1,2,0,0,0,2,0,0,0,0,2,0,0,0,0,0,0,2,0,0,0,0,2,0,0,0,2,1,1,1,1
1,1,1,1,2,0,0,0,2,0,0,0,0,2,2,2,2,2,2,2,2,0,0,0,0,2,0,0,0,2,1,1,1,1
1,1,1,1,2,0,0,2,2,0,0,2,2,2,0,0,0,0,0,0,2,2,2,0,0,2,2,0,0,2,1,1,1,1
1,1,1,1,2,0,0,0,2,0,0,2,0,0,0,0,0,0,0,0,0,0,2,0,0,2,0,0,0,2,1,1,1,1
1,1,1,1,2,0,0,0,2,0,0,2,0,0,0,0,0,0,0,0,0,0,2,0,0,2,0,0,0,2,1,1,1,1
1,1,1,1,2,0,0,0,2,0,0,2,0,0,0,0,0,0,0,0,0,0,2,0,0,2,0,0,0,2,1,1,1,1
1,1,1,1,2,0,0,0,2,0,0,2,0,0,0,0,0,0,0,0,0,0,2,0,0,2,0,0,0,2,1,1,1,1
1,1,1,1,2,0,0,2,2,0,0,2,0,0,0,0,0,0,0,0,0,0,2,0,0,2,2,0,0,2,1,1,1,1
1,1,1,1,2,0,0,0,2,0,0,2,0,0,0,0,0,0,0,0,0,0,2,0,0,2,0,0,0,2,1,1,1,1
1,1,1,1,2,0,0,0,2,0,0,2,0,0,0,0,0,0,0,0,0,0,2,0,0,2,0,0,0,2,1,1,1,1
1,1,1,1,2,0,0,0,2,0,0,2,0,0,0,0,0,0,0,0,0,0,2,0,0,2,0,0,0,2,1,1,1,1
1,1,1,1,2,0,0,0,2,0,0,2,0,0,0,0,0,0,0,0,0,0,2,0,0,2,0,0,0,2,1,1,1,1
1,1,1,1,2,0,0,2,2,0,0,2,0,0,0,0,0,0,0,0,0,0,2,0,0,2,2,0,0,2,1,1,1,1
1,1,1,1,2,0,0,0,2,0,0,2,0,0,0,0,0,0,0,0,0,0,2,0,0,2,0,0,0,2,1,1,1,1
1,1,1,1,2,0,0,0,2,0,0,2,0,0,0,0,0,0,0,0,0,0,2,0,0,2,0,0,0,2,1,1,1,1
1,1,1,1,2,0,0,0,2,0,0,2,0,0,0,0,0,0,0,0,0,0,2,0,0,2,0,0,0,2,1,1,1,1
1,1,1,1,2,0,0,0,2,0,0,2,0,0,0,0,0,0,0,0,0,0,2,0,0,2,0,0,0,2,1,1,1,1
1,1,1,1,2,0,0,2,2,0,0,2,2,2,0,0,0,0,0,0,2,2,2,0,0,2,2,0,0,2,1,1,1,1
1,1,1,1,2,0,0,0,2,0,0,0,0,2,2,2,2,2,2,2,2,0,0,0,0,2,0,0,0,2,1,1,1,1
1,1,1,1,2,0,0,0,2,0,0,0,0,2,0,0,0,0,0,0,2,0,0,0,0,2,0,0,0,2,1,1,1,1
1,1,1,1,2,0,2,0,2,0,0,0,0,0,0,0,0,0,0,0,0,0,0,0,0,2,0,2,0,2,1,1,1,1
1,1,1,2,0,0,0,2,2,0,0,0,0,2,0,0,0,0,0,0,2,0,0,0,0,2,2,0,0,0,2,0,1,1
1,1,2,0,0,0,0,40,2,2,2,2,2,2,0,0,0,0,0,0,2,2,2,2,2,2,0,0,0,0,40,2,1,1
1,1,0,0,0,2,0,0,0,0,0,2,34,0,0,0,0,0,0,0,0,29,2,0,0,2,0,0,2,0,0,0,1,1
1,1,2,2,2,34,0,40,2,2,2,2,2,2,0,0,0,0,0,0,2,2,2,2,2,2,2,2,34,0,40,2,1,1
1,1,1,2,2,34,0,2,0,0,0,0,0,2,0,0,0,0,0,0,2,0,0,0,0,0,2,2,34,0,2,1,1,1
1,1,1,1,2,0,2,0,0,0,0,0,81,2,34,0,0,0,0,29,2,81,0,0,0,0,0,2,0,2,1,1,1,1
1,1,1,1,0,0,0,0,0,0,0,0,60,2,2,2,2,2,2,2,2,59,0,0,0,0,0,0,0,0,1,1,1,1
1,1,1,1,1,1,0,0,0,0,0,0,79,79,59,0,0,0,0,60,79,59,0,0,0,0,0,0,1,1,1,1,1,1
1,1,1,1,1,1,0,0,0,0,0,0,0,0,0,0,0,0,0,0,0,0,0,0,0,0,0,0,1,1,1,1,1,1
1,1,1,1,1,1,0,0,0,0,0,0,0,0,0,0,0,0,0,0,0,0,0,0,0,0,0,0,1,1,1,1,1,1
1,1,1,1,1,1,0,0,0,0,0,0,0,0,0,0,0,0,0,0,0,0,0,0,0,0,0,0,1,1,1,1,1,1
1,1,1,1,1,1,0,0,0,0,0,0,0,0,0,0,0,0,0,0,0,0,0,0,0,0,0,0,1,1,1,1,1,1
1,1,1,1,1,1,0,0,0,0,0,0,0,0,0,0,0,0,0,0,0,0,0,0,0,0,0,0,1,1,1,1,1,1
1,1,1,1,1,1,0,0,0,0,0,0,0,0,0,0,0,0,0,0,0,0,0,0,0,0,0,0,1,1,1,1,1,1
1,1,1,1,1,1,0,0,0,0,0,0,0,0,0,0,0,0,0,0,0,0,0,0,0,0,0,0,1,1,1,1,1,1
1,1,1,1,1,1,0,0,0,0,0,0,0,0,0,0,0,0,0,0,0,0,0,0,0,0,0,0,1,1,1,1,1,1
1,1,1,1,1,1,0,0,0,0,0,0,0,0,0,0,0,0,0,0,0,0,0,0,0,0,0,0,1,1,1,1,1,1
endlayer

layer
1,1,1,1,1,1,0,0,0,0,0,0,0,0,0,0,0,0,0,0,0,0,0,0,0,0,0,0,1,1,1,1,1,1
1,1,1,1,1,1,0,0,0,0,0,0,0,0,0,0,0,0,0,0,0,0,0,0,0,0,0,0,1,1,1,1,1,1
1,1,1,1,1,1,0,0,0,0,0,0,0,0,0,0,0,0,0,0,0,0,0,0,0,0,0,0,1,1,1,1,1,1
1,1,1,1,1,1,0,0,0,0,0,0,0,0,0,0,0,0,0,0,0,0,0,0,0,0,0,0,1,1,1,1,1,1
1,1,1,1,1,1,0,0,0,0,0,0,0,0,0,0,0,0,0,0,0,0,0,0,0,0,0,0,1,1,1,1,1,1
1,1,1,1,1,1,0,0,0,0,0,0,0,0,0,0,0,0,0,0,0,0,0,0,0,0,0,0,1,1,1,1,1,1
1,1,1,1,1,1,0,0,0,0,0,0,0,0,0,0,0,0,0,0,0,0,0,0,0,0,0,0,1,1,1,1,1,1
1,1,1,1,1,1,0,0,0,0,0,0,0,0,0,0,0,0,0,0,0,0,0,0,0,0,0,0,1,1,1,1,1,1
1,1,1,1,1,1,0,0,0,0,0,0,0,0,0,0,0,0,0,0,0,0,0,0,0,0,0,0,1,1,1,1,1,1
1,1,1,1,1,1,0,0,0,0,0,0,2,2,2,0,0,0,0,2,2,2,0,0,0,0,0,0,1,1,1,1,1,1
1,1,1,1,0,0,0,0,0,0,0,0,2,0,2,2,2,2,2,2,0,2,0,0,0,0,0,0,0,0,1,1,1,1
1,1,1,1,2,2,2,0,0,0,0,0,2,0,0,0,0,0,0,0,0,2,0,0,0,0,0,2,2,2,1,1,1,1
1,1,1,2,0,0,0,2,0,0,66,0,0,2,0,0,0,0,0,0,2,0,0,66,0,0,2,0,0,0,2,0,1,1
1,1,2,0,0,0,0,0,2,2,2,2,2,2,0,0,0,0,0,0,2,2,2,2,2,2,0,0,0,0,0,2,1,1
1,1,2,0,0,2,52,52,2,0,2,34,0,0,0,0,0,0,0,0,0,0,29,2,0,0,0,0,2,52,52,2,1,1
1,1,2,0,0,0,2,2,2,2,2,2,2,2,0,0,0,0,0,0,2,2,2,2,2,2,0,0,0,2,2,2,1,1
1,1,1,2,0,0,2,2,2,0,0,0,0,2,0,0,0,0,0,0,2,0,0,0,0,2,2,0,0,2,2,1,1,1
1,1,1,60,2,0,2,44,2,0,0,0,0,0,0,0,0,0,0,0,0,0,0,0,0,2,44,2,2,2,59,1,1,1
1,1,1,60,2,0,0,0,2,0,0,0,0,2,0,0,0,0,0,0,2,0,0,0,0,2,0,0,0,2,59,1,1,1
1,1,1,60,2,0,0,0,2,0,0,0,0,2,2,0,0,0,0,2,2,0,0,0,0,2,0,0,0,2,59,1,1,1
1,1,1,60,2,0,40,2,2,0,0,62,0,62,0,0,0,0,0,0,62,0,62,0,0,2,2,41,0,2,59,1,1,1
1,1,1,60,2,0,0,0,2,0,0,0,0,0,0,0,0,0,0,0,0,0,0,0,0,2,0,0,0,2,59,1,1,1
1,1,1,60,2,0,0,0,2,0,0,62,0,0,0,0,0,0,0,0,0,0,62,0,0,2,0,0,0,2,59,1,1,1
1,1,1,60,2,0,0,0,2,0,0,0,0,0,0,0,0,0,0,0,0,0,0,0,0,2,0,0,0,2,59,1,1,1
1,1,1,60,2,0,0,0,2,0,0,62,0,0,0,0,0,0,0,0,0,0,62,0,0,2,0,0,0,2,59,1,1,1
1,1,1,60,2,0,40,2,2,0,0,0,0,0,0,0,0,0,0,0,0,0,0,0,0,2,2,41,0,2,59,1,1,1
1,1,1,60,2,0,0,0,2,0,0,62,0,0,0,0,0,0,0,0,0,0,62,0,0,2,0,0,0,2,59,1,1,1
1,1,1,60,2,0,0,0,2,0,0,0,0,0,0,0,0,0,0,0,0,0,0,0,0,2,0,0,0,2,59,1,1,1
1,1,1,60,2,0,0,0,2,0,0,0,0,0,0,0,0,0,0,0,0,0,0,0,0,2,0,0,0,2,59,1,1,1
1,1,1,60,2,0,0,0,2,0,0,62,0,0,0,0,0,0,0,0,0,0,62,0,0,2,0,0,0,2,59,1,1,1
1,1,1,60,2,0,40,2,2,0,0,0,0,0,0,0,0,0,0,0,0,0,0,0,0,2,2,41,0,2,59,1,1,1
1,1,1,60,2,0,0,0,2,0,0,62,0,0,0,0,0,0,0,0,0,0,62,0,0,2,0,0,0,2,59,1,1,1
1,1,1,60,2,0,0,0,2,0,0,0,0,0,0,0,0,0,0,0,0,0,0,0,0,2,0,0,0,2,59,1,1,1
1,1,1,60,2,0,0,0,2,0,0,62,0,0,0,0,0,0,0,0,0,0,62,0,0,2,0,0,0,2,59,1,1,1
1,1,1,60,2,0,0,0,2,0,0,0,0,0,0,0,0,0,0,0,0,0,0,0,0,2,0,0,0,2,59,1,1,1
1,1,1,60,2,0,40,2,2,0,0,62,0,62,0,0,0,0,0,0,62,0,62,0,0,2,2,41,0,2,59,1,1,1
1,1,1,60,2,0,0,0,2,0,0,0,0,2,2,0,0,0,0,2,2,0,0,0,0,2,0,0,0,2,59,1,1,1
1,1,1,60,2,0,0,0,2,0,0,0,0,2,0,0,0,0,0,0,2,0,0,0,0,2,0,0,0,2,59,1,1,1
1,1,1,60,2,0,2,45,2,0,0,0,0,0,0,0,0,0,0,0,0,0,0,0,0,2,45,2,2,2,59,1,1,1
1,1,1,2,2,0,0,2,2,0,0,0,0,2,0,0,0,0,0,0,2,0,0,0,0,2,2,2,0,0,2,0,1,1
1,1,2,2,2,0,0,0,2,2,2,2,2,2,0,0,0,0,0,0,2,2,2,2,2,2,2,2,0,0,0,2,1,1
1,1,2,54,54,2,0,0,0,0,2,34,0,0,0,0,0,0,0,0,0,0,29,2,0,2,54,54,2,0,0,2,1,1
1,1,2,0,0,0,0,0,2,2,2,2,2,2,0,0,0,0,0,0,2,2,2,2,2,2,0,0,0,0,0,2,1,1
1,1,1,2,0,0,0,2,0,0,66,0,0,2,0,0,0,0,0,0,2,0,0,66,0,0,2,0,0,0,2,1,1,1
1,1,1,1,2,2,2,0,0,0,0,0,2,0,0,0,0,0,0,0,0,2,0,0,0,0,0,2,2,2,1,1,1,1
1,1,1,1,0,0,0,0,0,0,0,0,2,0,2,2,2,2,2,2,0,2,0,0,0,0,0,0,0,0,1,1,1,1
1,1,1,1,1,1,0,0,0,0,0,0,2,2,2,0,0,0,0,2,2,2,0,0,0,0,0,0,1,1,1,1,1,1
1,1,1,1,1,1,0,0,0,0,0,0,0,0,0,0,0,0,0,0,0,0,0,0,0,0,0,0,1,1,1,1,1,1
1,1,1,1,1,1,0,0,0,0,0,0,0,0,0,0,0,0,0,0,0,0,0,0,0,0,0,0,1,1,1,1,1,1
1,1,1,1,1,1,0,0,0,0,0,0,0,0,0,0,0,0,0,0,0,0,0,0,0,0,0,0,1,1,1,1,1,1
1,1,1,1,1,1,0,0,0,0,0,0,0,0,0,0,0,0,0,0,0,0,0,0,0,0,0,0,1,1,1,1,1,1
1,1,1,1,1,1,0,0,0,0,0,0,0,0,0,0,0,0,0,0,0,0,0,0,0,0,0,0,1,1,1,1,1,1
1,1,1,1,1,1,0,0,0,0,0,0,0,0,0,0,0,0,0,0,0,0,0,0,0,0,0,0,1,1,1,1,1,1
1,1,1,1,1,1,0,0,0,0,0,0,0,0,0,0,0,0,0,0,0,0,0,0,0,0,0,0,1,1,1,1,1,1
1,1,1,1,1,1,0,0,0,0,0,0,0,0,0,0,0,0,0,0,0,0,0,0,0,0,0,0,1,1,1,1,1,1
1,1,1,1,1,1,0,0,0,0,0,0,0,0,0,0,0,0,0,0,0,0,0,0,0,0,0,0,1,1,1,1,1,1
endlayer

layer
1,1,1,1,1,1,0,0,0,0,0,0,0,0,0,0,0,0,0,0,0,0,0,0,0,0,0,0,1,1,1,1,1,1
1,1,1,1,1,1,0,0,0,0,0,0,0,0,0,0,0,0,0,0,0,0,0,0,0,0,0,0,1,1,1,1,1,1
1,1,1,1,1,1,0,0,0,0,0,0,0,0,0,0,0,0,0,0,0,0,0,0,0,0,0,0,1,1,1,1,1,1
1,1,1,1,1,1,0,0,0,0,0,0,0,0,0,0,0,0,0,0,0,0,0,0,0,0,0,0,1,1,1,1,1,1
1,1,1,1,1,1,0,0,0,0,0,0,0,0,0,0,0,0,0,0,0,0,0,0,0,0,0,0,1,1,1,1,1,1
1,1,1,1,1,1,0,0,0,0,0,0,0,0,0,0,0,0,0,0,0,0,0,0,0,0,0,0,1,1,1,1,1,1
1,1,1,1,1,1,0,0,0,0,0,0,0,0,0,0,0,0,0,0,0,0,0,0,0,0,0,0,1,1,1,1,1,1
1,1,1,1,1,1,0,0,0,0,0,0,0,0,0,0,0,0,0,0,0,0,0,0,0,0,0,0,1,1,1,1,1,1
1,1,1,1,1,1,0,0,0,0,0,0,0,0,0,0,0,0,0,0,0,0,0,0,0,0,0,0,1,1,1,1,1,1
1,1,1,1,1,1,0,0,0,0,0,0,2,0,2,86,86,86,86,2,0,2,0,0,0,0,0,0,1,1,1,1,1,1
1,1,1,1,81,81,81,0,0,0,0,0,0,0,2,2,2,2,2,2,0,0,0,0,0,0,0,81,81,81,1,1,1,1
1,1,1,60,2,2,2,59,0,0,0,0,2,0,0,0,0,0,0,0,0,2,0,0,0,0,60,2,2,2,59,1,1,1
1,1,81,2,0,0,0,2,81,0,78,0,0,2,0,0,0,0,0,0,2,0,0,78,0,81,2,0,0,0,2,81,1,1
1,60,2,0,0,0,0,0,2,2,2,2,2,2,66,0,0,0,0,66,2,2,2,2,2,2,0,0,0,0,0,2,59,1
1,60,2,0,0,2,0,0,2,2,34,0,0,0,0,0,0,0,0,0,0,0,0,29,2,0,0,0,2,0,0,2,59,1
1,60,2,2,2,34,0,0,2,2,2,2,2,2,66,0,0,0,0,66,2,2,2,2,2,2,2,2,34,0,0,2,59,1
1,1,79,2,2,34,0,2,2,66,0,0,66,2,0,0,0,0,0,0,2,66,0,0,66,2,2,2,34,0,2,79,1,1
1,1,1,60,2,2,2,59,2,0,0,0,0,2,0,0,0,0,0,0,2,0,0,0,0,2,60,2,2,2,59,1,1,1
1,1,1,87,2,79,79,0,2,0,0,0,0,2,66,0,0,0,0,66,2,0,0,0,0,2,0,79,79,2,87,1,1,1
1,1,1,87,2,0,0,0,2,0,0,0,0,2,2,59,0,0,60,2,2,0,0,0,0,2,0,0,0,2,87,1,1,1
1,1,1,87,2,0,0,2,2,66,0,0,0,0,0,0,0,0,0,0,0,0,0,0,66,2,2,0,0,2,87,1,1,1
1,1,1,87,2,0,0,0,2,0,0,0,0,0,0,0,0,0,0,0,0,0,0,0,0,2,0,0,0,2,87,1,1,1
1,1,1,87,2,0,0,0,2,0,0,0,0,0,0,0,0,0,0,0,0,0,0,0,0,2,0,0,0,2,87,1,1,1
1,1,1,87,2,0,0,0,2,0,0,0,0,0,0,0,0,0,0,0,0,0,0,0,0,2,0,0,0,2,87,1,1,1
1,1,1,87,2,0,0,0,2,0,0,0,0,0,0,0,0,0,0,0,0,0,0,0,0,2,0,0,0,2,87,1,1,1
1,1,1,87,2,0,0,2,2,66,0,0,0,0,0,0,0,0,0,0,0,0,0,0,66,2,2,0,0,2,87,1,1,1
1,1,1,87,2,0,0,0,2,0,0,0,0,0,0,0,0,0,0,0,0,0,0,0,0,2,0,0,0,2,87,1,1,1
1,1,1,87,2,0,0,0,2,0,0,0,0,0,0,0,0,0,0,0,0,0,0,0,0,2,0,0,0,2,87,1,1,1
1,1,1,87,2,0,0,0,2,0,0,0,0,0,0,0,0,0,0,0,0,0,0,0,0,2,0,0,0,2,87,1,1,1
1,1,1,87,2,0,0,0,2,0,0,0,0,0,0,0,0,0,0,0,0,0,0,0,0,2,0,0,0,2,87,1,1,1
1,1,1,87,2,0,0,2,2,66,0,0,0,0,0,0,0,0,0,0,0,0,0,0,66,2,2,0,0,2,87,1,1,1
1,1,1,87,2,0,0,0,2,0,0,0,0,0,0,0,0,0,0,0,0,0,0,0,0,2,0,0,0,2,87,1,1,1
1,1,1,87,2,0,0,0,2,0,0,0,0,0,0,0,0,0,0,0,0,0,0,0,0,2,0,0,0,2,87,1,1,1
1,1,1,87,2,0,0,0,2,0,0,0,0,0,0,0,0,0,0,0,0,0,0,0,0,2,0,0,0,2,87,1,1,1
1,1,1,87,2,0,0,0,2,0,0,0,0,0,0,0,0,0,0,0,0,0,0,0,0,2,0,0,0,2,87,1,1,1
1,1,1,87,2,0,0,2,2,66,0,0,0,0,0,0,0,0,0,0,0,0,0,0,66,2,2,0,0,2,87,1,1,1
1,1,1,87,2,0,0,0,2,0,0,0,0,2,2,59,0,0,60,2,2,0,0,0,0,2,0,0,0,2,87,1,1,1
1,1,1,87,2,81,81,0,2,0,0,0,0,2,66,0,0,0,0,66,2,0,0,0,0,2,0,81,81,2,87,1,1,1
1,1,1,60,2,2,2,59,2,0,0,0,0,2,0,0,0,0,0,0,2,0,0,0,0,2,60,2,2,2,59,1,1,1
1,1,81,2,0,29,2,2,2,66,0,0,66,2,0,0,0,0,0,0,2,66,0,0,66,2,2,0,29,2,2,81,1,1
1,60,2,0,0,29,2,2,2,2,2,2,2,2,66,0,0,0,0,66,2,2,2,2,2,2,0,0,29,2,2,2,59,1
1,60,2,0,0,2,0,0,0,2,34,0,0,0,0,0,0,0,0,0,0,0,0,29,2,2,0,0,2,0,0,2,59,1
1,60,2,0,0,0,0,0,2,2,2,2,2,2,66,0,0,0,0,66,2,2,2,2,2,2,0,0,0,0,0,2,59,1
1,1,79,2,0,0,0,2,79,0,78,0,0,2,0,0,0,0,0,0,2,0,0,78,0,79,2,0,0,0,2,79,1,1
1,1,1,60,2,2,2,59,0,0,0,0,2,0,0,0,0,0,0,0,0,2,0,0,0,0,60,2,2,2,59,1,1,1
1,1,1,1,79,79,79,0,0,0,0,0,0,0,2,2,2,2,2,2,0,0,0,0,0,0,0,79,79,79,1,1,1,1
1,1,1,1,1,1,0,0,0,0,0,0,2,0,2,88,88,88,88,2,0,2,0,0,0,0,0,0,1,1,1,1,1,1
1,1,1,1,1,1,0,0,0,0,0,0,0,0,0,0,0,0,0,0,0,0,0,0,0,0,0,0,1,1,1,1,1,1
1,1,1,1,1,1,0,0,0,0,0,0,0,0,0,0,0,0,0,0,0,0,0,0,0,0,0,0,1,1,1,1,1,1
1,1,1,1,1,1,0,0,0,0,0,0,0,0,0,0,0,0,0,0,0,0,0,0,0,0,0,0,1,1,1,1,1,1
1,1,1,1,1,1,0,0,0,0,0,0,0,0,0,0,0,0,0,0,0,0,0,0,0,0,0,0,1,1,1,1,1,1
1,1,1,1,1,1,0,0,0,0,0,0,0,0,0,0,0,0,0,0,0,0,0,0,0,0,0,0,1,1,1,1,1,1
1,1,1,1,1,1,0,0,0,0,0,0,0,0,0,0,0,0,0,0,0,0,0,0,0,0,0,0,1,1,1,1,1,1
1,1,1,1,1,1,0,0,0,0,0,0,0,0,0,0,0,0,0,0,0,0,0,0,0,0,0,0,1,1,1,1,1,1
1,1,1,1,1,1,0,0,0,0,0,0,0,0,0,0,0,0,0,0,0,0,0,0,0,0,0,0,1,1,1,1,1,1
1,1,1,1,1,1,0,0,0,0,0,0,0,0,0,0,0,0,0,0,0,0,0,0,0,0,0,0,1,1,1,1,1,1
endlayer

layer
1,1,1,1,1,1,0,0,0,0,0,0,0,0,0,0,0,0,0,0,0,0,0,0,0,0,0,0,1,1,1,1,1,1
1,1,1,1,1,1,0,0,0,0,0,0,0,0,0,0,0,0,0,0,0,0,0,0,0,0,0,0,1,1,1,1,1,1
1,1,1,1,1,1,0,0,0,0,0,0,0,0,0,0,0,0,0,0,0,0,0,0,0,0,0,0,1,1,1,1,1,1
1,1,1,1,1,1,0,0,0,0,0,0,0,0,0,0,0,0,0,0,0,0,0,0,0,0,0,0,1,1,1,1,1,1
1,1,1,1,1,1,0,0,0,0,0,0,0,0,0,0,0,0,0,0,0,0,0,0,0,0,0,0,1,1,1,1,1,1
1,1,1,1,1,1,0,0,0,0,0,0,0,0,0,0,0,0,0,0,0,0,0,0,0,0,0,0,1,1,1,1,1,1
1,1,1,1,1,1,0,0,0,0,0,0,0,0,0,0,0,0,0,0,0,0,0,0,0,0,0,0,1,1,1,1,1,1
1,1,1,1,1,1,0,0,0,0,0,0,0,0,0,0,0,0,0,0,0,0,0,0,0,0,0,0,1,1,1,1,1,1
1,1,1,1,1,1,0,0,0,0,0,0,0,0,0,0,0,0,0,0,0,0,0,0,0,0,0,0,1,1,1,1,1,1
1,1,1,1,1,1,0,0,0,0,0,0,2,0,2,0,0,0,0,2,0,2,0,0,0,0,0,0,1,1,1,1,1,1
1,1,1,1,87,87,87,0,0,0,0,0,0,0,2,86,86,86,86,2,0,0,0,0,0,0,0,87,87,87,1,1,1,1
1,1,1,87,2,2,2,87,0,0,0,0,2,0,2,2,2,2,2,2,0,2,0,0,0,0,87,2,2,2,87,1,1,1
1,1,87,2,2,2,0,2,87,0,0,0,0,2,0,0,0,0,0,0,2,0,0,0,0,87,2,2,2,0,2,87,1,1
1,87,2,2,2,2,0,40,2,2,2,2,2,2,78,0,0,0,0,78,2,2,2,2,2,2,2,2,2,0,40,2,87,1
1,87,2,54,54,2,0,0,2,34,0,0,0,0,0,0,0,0,0,0,0,0,0,0,29,2,54,54,2,0,0,2,87,1
1,87,2,0,0,0,0,40,2,2,2,2,2,2,78,0,0,0,0,78,2,2,2,2,2,2,0,0,0,0,40,2,87,1
1,1,87,2,0,0,0,2,2,78,0,0,78,2,0,0,0,0,0,0,2,78,0,0,78,2,2,0,0,0,2,87,1,1
1,1,1,87,2,2,2,87,2,0,0,0,0,2,0,0,0,0,0,0,2,0,0,0,0,2,87,2,2,2,87,1,1,1
1,1,1,1,2,87,87,0,2,0,0,0,0,2,78,0,0,0,0,78,2,0,0,0,0,2,0,87,87,2,1,1,1,1
1,1,1,1,2,0,0,81,2,0,0,0,0,2,2,2,2,2,2,2,2,0,0,0,0,2,81,0,0,2,1,1,1,1
1,1,1,1,2,0,0,2,2,78,0,0,0,0,0,0,0,0,0,0,0,0,0,0,78,2,2,0,0,2,1,1,1,1
1,1,1,1,2,0,0,79,2,0,0,0,0,0,0,0,0,0,0,0,0,0,0,0,0,2,79,0,0,2,1,1,1,1
1,1,1,1,2,0,0,0,2,0,0,0,0,0,0,0,0,0,0,0,0,0,0,0,0,2,0,0,0,2,1,1,1,1
1,1,1,1,2,0,0,0,2,0,0,0,0,0,0,0,0,0,0,0,0,0,0,0,0,2,0,0,0,2,1,1,1,1
1,1,1,1,2,0,0,81,2,0,0,0,0,0,0,0,0,0,0,0,0,0,0,0,0,2,81,0,0,2,1,1,1,1
1,1,1,1,2,0,0,2,2,78,0,0,0,0,0,0,0,0,0,0,0,0,0,0,78,2,2,0,0,2,1,1,1,1
1,1,1,1,2,0,0,79,2,0,0,0,0,0,0,0,0,0,0,0,0,0,0,0,0,2,79,0,0,2,1,1,1,1
1,1,1,1,2,0,0,0,2,0,0,0,0,0,0,0,0,0,0,0,0,0,0,0,0,2,0,0,0,2,1,1,1,1
1,1,1,1,2,0,0,0,2,0,0,0,0,0,0,0,0,0,0,0,0,0,0,0,0,2,0,0,0,2,1,1,1,1
1,1,1,1,2,0,0,81,2,0,0,0,0,0,0,0,0,0,0,0,0,0,0,0,0,2,81,0,0,2,1,1,1,1
1,1,1,1,2,0,0,2,2,78,0,0,0,0,0,0,0,0,0,0,0,0,0,0,78,2,2,0,0,2,1,1,1,1
1,1,1,1,2,0,0,79,2,0,0,0,0,0,0,0,0,0,0,0,0,0,0,0,0,2,79,0,0,2,1,1,1,1
1,1,1,1,2,0,0,0,2,0,0,0,0,0,0,0,0,0,0,0,0,0,0,0,0,2,0,0,0,2,1,1,1,1
1,1,1,1,2,0,0,0,2,0,0,0,0,0,0,0,0,0,0,0,0,0,0,0,0,2,0,0,0,2,1,1,1,1
1,1,1,1,2,0,0,81,2,0,0,0,0,0,0,0,0,0,0,0,0,0,0,0,0,2,81,0,0,2,1,1,1,1
1,1,1,1,2,0,0,2,2,78,0,0,0,0,0,0,0,0,0,0,0,0,0,0,78,2,2,0,0,2,1,1,1,1
1,1,1,1,2,0,0,79,2,0,0,0,0,2,2,2,2,2,2,2,2,0,0,0,0,2,79,0,0,2,1,1,1,1
1,1,1,1,2,87,87,0,2,0,0,0,0,2,78,0,0,0,0,78,2,0,0,0,0,2,0,87,87,2,1,1,1,1
1,1,1,87,2,2,2,87,2,0,0,0,0,2,0,0,0,0,0,0,2,0,0,0,0,2,87,2,2,2,87,1,1,1
1,1,87,2,0,0,0,2,2,78,0,0,78,2,0,0,0,0,0,0,2,78,0,0,78,2,2,0,0,0,2,87,1,1
1,87,2,41,0,0,0,0,2,2,2,2,2,2,78,0,0,0,0,78,2,2,2,2,2,2,41,0,0,0,0,2,87,1
1,87,2,0,0,2,52,52,2,34,0,0,0,0,0,0,0,0,0,0,0,0,0,0,29,2,0,0,2,52,52,2,87,1
1,87,2,41,0,2,2,2,2,2,2,2,2,2,78,0,0,0,0,78,2,2,2,2,2,2,41,0,2,2,2,2,87,1
1,1,87,2,0,2,2,2,87,0,0,0,0,2,0,0,0,0,0,0,2,0,0,0,0,87,2,0,2,2,2,87,1,1
1,1,1,87,2,2,2,87,0,0,0,0,2,0,0,2,2,2,2,0,0,2,0,0,0,0,87,2,2,2,87,1,1,1
1,1,1,1,87,87,87,0,0,0,0,0,0,0,2,88,88,88,88,2,0,0,0,0,0,0,0,87,87,87,1,1,1,1
1,1,1,1,1,1,0,0,0,0,0,0,2,0,2,0,0,0,0,2,0,2,0,0,0,0,0,0,1,1,1,1,1,1
1,1,1,1,1,1,0,0,0,0,0,0,0,0,0,0,0,0,0,0,0,0,0,0,0,0,0,0,1,1,1,1,1,1
1,1,1,1,1,1,0,0,0,0,0,0,0,0,0,0,0,0,0,0,0,0,0,0,0,0,0,0,1,1,1,1,1,1
1,1,1,1,1,1,0,0,0,0,0,0,0,0,0,0,0,0,0,0,0,0,0,0,0,0,0,0,1,1,1,1,1,1
1,1,1,1,1,1,0,0,0,0,0,0,0,0,0,0,0,0,0,0,0,0,0,0,0,0,0,0,1,1,1,1,1,1
1,1,1,1,1,1,0,0,0,0,0,0,0,0,0,0,0,0,0,0,0,0,0,0,0,0,0,0,1,1,1,1,1,1
1,1,1,1,1,1,0,0,0,0,0,0,0,0,0,0,0,0,0,0,0,0,0,0,0,0,0,0,1,1,1,1,1,1
1,1,1,1,1,1,0,0,0,0,0,0,0,0,0,0,0,0,0,0,0,0,0,0,0,0,0,0,1,1,1,1,1,1
1,1,1,1,1,1,0,0,0,0,0,0,0,0,0,0,0,0,0,0,0,0,0,0,0,0,0,0,1,1,1,1,1,1
1,1,1,1,1,1,0,0,0,0,0,0,0,0,0,0,0,0,0,0,0,0,0,0,0,0,0,0,1,1,1,1,1,1
endlayer

layer
1,1,1,1,1,1,0,0,0,0,0,0,0,0,0,0,0,0,0,0,0,0,0,0,0,0,0,0,1,1,1,1,1,1
1,1,1,1,1,1,0,0,0,0,0,0,0,0,0,0,0,0,0,0,0,0,0,0,0,0,0,0,1,1,1,1,1,1
1,1,1,1,1,1,0,0,0,0,0,0,0,0,0,0,0,0,0,0,0,0,0,0,0,0,0,0,1,1,1,1,1,1
1,1,1,1,1,1,0,0,0,0,0,0,0,0,0,0,0,0,0,0,0,0,0,0,0,0,0,0,1,1,1,1,1,1
1,1,1,1,1,1,0,0,0,0,0,0,0,0,0,0,0,0,0,0,0,0,0,0,0,0,0,0,1,1,1,1,1,1
1,1,1,1,1,1,0,0,0,0,0,0,0,0,0,0,0,0,0,0,0,0,0,0,0,0,0,0,1,1,1,1,1,1
1,1,1,1,1,1,0,0,0,0,0,0,0,0,0,0,0,0,0,0,0,0,0,0,0,0,0,0,1,1,1,1,1,1
1,1,1,1,1,1,0,0,0,0,0,0,0,0,0,0,0,0,0,0,0,0,0,0,0,0,0,0,1,1,1,1,1,1
1,1,1,1,1,1,0,0,0,0,0,60,81,81,81,81,0,0,81,81,81,81,59,0,0,0,0,0,1,1,1,1,1,1
1,1,1,1,1,1,0,0,0,0,0,60,2,2,2,59,0,0,60,2,2,2,59,0,0,0,0,0,1,1,1,1,1,1
1,1,1,1,0,0,0,0,0,0,0,60,2,2,2,59,0,0,60,2,2,2,59,0,0,0,0,0,0,0,1,1,1,1
1,1,1,1,2,2,2,0,0,0,0,0,2,2,2,86,86,86,86,2,2,2,0,0,0,0,0,2,2,2,1,1,1,1
1,1,1,2,0,29,2,2,0,81,0,81,0,2,2,2,2,2,2,2,2,0,81,0,81,0,2,0,29,2,2,0,1,1
1,1,2,0,0,29,2,2,2,2,2,2,2,2,0,0,0,0,0,0,2,2,2,2,2,2,0,0,29,2,2,2,1,1
1,1,2,0,0,2,0,0,34,0,0,0,0,0,0,0,0,0,0,0,0,0,0,0,0,0,0,0,2,0,0,2,1,1
1,1,2,0,0,0,0,0,2,2,2,2,2,2,2,2,2,2,2,2,2,2,2,2,2,2,0,0,0,0,0,2,1,1
1,1,1,2,0,0,0,2,2,0,0,0,60,2,2,2,2,2,2,2,2,59,0,0,0,2,2,0,0,0,2,1,1,1
1,1,1,1,2,2,2,2,2,0,0,0,60,2,2,2,2,2,2,2,2,59,0,0,0,2,2,2,2,2,1,1,1,1
1,1,1,1,2,2,2,2,2,0,0,0,60,2,2,2,2,2,2,2,2,59,0,0,0,2,2,2,2,2,1,1,1,1
1,1,1,1,2,2,2,2,2,0,0,0,60,2,2,2,2,2,2,2,2,59,0,0,0,2,2,2,2,2,1,1,1,1
1,1,1,1,2,2,2,2,2,59,0,0,0,79,79,79,79,79,79,79,79,0,0,0,60,2,2,2,2,2,1,1,1,1
1,1,1,1,2,2,2,2,2,59,0,0,0,0,0,0,0,0,0,0,0,0,0,0,60,2,2,2,2,2,1,1,1,1
1,1,1,1,2,2,2,2,2,59,0,0,0,0,0,0,0,0,0,0,0,0,0,0,60,2,2,2,2,2,1,1,1,1
1,1,1,1,2,2,2,2,2,59,0,0,0,0,0,0,0,0,0,0,0,0,0,0,60,2,2,2,2,2,1,1,1,1
1,1,1,1,2,2,2,2,2,59,0,0,0,0,0,0,0,0,0,0,0,0,0,0,60,2,2,2,2,2,1,1,1,1
1,1,1,1,2,2,2,2,2,59,0,0,0,0,0,0,0,0,0,0,0,0,0,0,60,2,2,2,2,2,1,1,1,1
1,1,1,1,2,2,2,2,2,59,0,0,0,0,0,0,0,0,0,0,0,0,0,0,60,2,2,2,2,2,1,1,1,1
1,1,1,1,2,2,2,2,2,59,0,0,0,0,0,0,0,0,0,0,0,0,0,0,60,2,2,2,2,2,1,1,1,1
1,1,1,1,2,2,2,2,2,59,0,0,0,0,0,0,0,0,0,0,0,0,0,0,60,2,2,2,2,2,1,1,1,1
1,1,1,1,2,2,2,2,2,59,0,0,0,0,0,0,0,0,0,0,0,0,0,0,60,2,2,2,2,2,1,1,1,1
1,1,1,1,2,2,2,2,2,59,0,0,0,0,0,0,0,0,0,0,0,0,0,0,60,2,2,2,2,2,1,1,1,1
1,1,1,1,2,2,2,2,2,59,0,0,0,0,0,0,0,0,0,0,0,0,0,0,60,2,2,2,2,2,1,1,1,1
1,1,1,1,2,2,2,2,2,59,0,0,0,0,0,0,0,0,0,0,0,0,0,0,60,2,2,2,2,2,1,1,1,1
1,1,1,1,2,2,2,2,2,59,0,0,0,0,0,0,0,0,0,0,0,0,0,0,60,2,2,2,2,2,1,1,1,1
1,1,1,1,2,2,2,2,2,59,0,0,0,0,0,0,0,0,0,0,0,0,0,0,60,2,2,2,2,2,1,1,1,1
1,1,1,1,2,2,2,2,2,59,0,0,0,81,81,81,81,81,81,81,81,0,0,0,60,2,2,2,2,2,1,1,1,1
1,1,1,1,2,2,2,2,2,0,0,0,60,2,2,2,2,2,2,2,2,59,0,0,0,2,2,2,2,2,1,1,1,1
1,1,1,1,2,2,2,2,2,0,0,0,60,2,2,2,2,2,2,2,2,59,0,0,0,2,2,2,2,2,1,1,1,1
1,1,1,1,2,2,2,2,2,0,0,0,60,2,2,2,2,2,2,2,2,59,0,0,0,2,2,2,2,2,1,1,1,1
1,1,1,2,0,0,0,2,2,0,0,0,60,2,2,2,2,2,2,2,2,59,0,0,0,2,2,0,0,0,2,0,1,1
1,1,2,0,0,0,0,0,2,2,2,2,2,2,2,2,2,2,2,2,2,2,2,2,2,2,0,0,0,0,0,2,1,1
1,1,2,0,0,2,0,0,0,0,0,0,0,0,0,0,0,0,0,0,0,0,0,0,0,29,0,0,2,0,0,2,1,1
1,1,2,2,2,34,0,0,2,2,2,2,2,2,0,0,0,0,0,0,2,2,2,2,2,2,2,2,34,0,0,2,1,1
1,1,1,2,2,34,0,2,0,79,0,79,2,2,2,2,2,2,2,2,2,2,79,0,79,0,2,2,34,0,2,1,1,1
1,1,1,1,2,2,2,0,0,0,0,0,2,2,2,88,88,88,88,2,2,2,0,0,0,0,0,2,2,2,1,1,1,1
1,1,1,1,0,0,0,0,0,0,0,60,2,2,2,59,0,0,60,2,2,2,59,0,0,0,0,0,0,0,1,1,1,1
1,1,1,1,1,1,0,0,0,0,0,60,2,2,2,59,0,0,60,2,2,2,59,0,0,0,0,0,1,1,1,1,1,1
1,1,1,1,1,1,0,0,0,0,0,79,79,79,79,59,0,0,60,79,79,79,59,0,0,0,0,0,1,1,1,1,1,1
1,1,1,1,1,1,0,0,0,0,0,0,0,0,0,0,0,0,0,0,0,0,0,0,0,0,0,0,1,1,1,1,1,1
1,1,1,1,1,1,0,0,0,0,0,0,0,0,0,0,0,0,0,0,0,0,0,0,0,0,0,0,1,1,1,1,1,1
1,1,1,1,1,1,0,0,0,0,0,0,0,0,0,0,0,0,0,0,0,0,0,0,0,0,0,0,1,1,1,1,1,1
1,1,1,1,1,1,0,0,0,0,0,0,0,0,0,0,0,0,0,0,0,0,0,0,0,0,0,0,1,1,1,1,1,1
1,1,1,1,1,1,0,0,0,0,0,0,0,0,0,0,0,0,0,0,0,0,0,0,0,0,0,0,1,1,1,1,1,1
1,1,1,1,1,1,0,0,0,0,0,0,0,0,0,0,0,0,0,0,0,0,0,0,0,0,0,0,1,1,1,1,1,1
1,1,1,1,1,1,0,0,0,0,0,0,0,0,0,0,0,0,0,0,0,0,0,0,0,0,0,0,1,1,1,1,1,1
1,1,1,1,1,1,0,0,0,0,0,0,0,0,0,0,0,0,0,0,0,0,0,0,0,0,0,0,1,1,1,1,1,1
endlayer

layer
1,1,1,1,1,1,0,0,0,0,0,0,0,0,0,0,0,0,0,0,0,0,0,0,0,0,0,0,1,1,1,1,1,1
1,1,1,1,1,1,0,0,0,0,0,0,0,0,0,0,0,0,0,0,0,0,0,0,0,0,0,0,1,1,1,1,1,1
1,1,1,1,1,1,0,0,0,0,0,0,0,0,0,0,0,0,0,0,0,0,0,0,0,0,0,0,1,1,1,1,1,1
1,1,1,1,1,1,0,0,0,0,0,0,0,0,0,0,0,0,0,0,0,0,0,0,0,0,0,0,1,1,1,1,1,1
1,1,1,1,1,1,0,0,0,0,0,0,0,0,0,0,0,0,0,0,0,0,0,0,0,0,0,0,1,1,1,1,1,1
1,1,1,1,1,1,0,0,0,0,0,0,0,0,0,0,0,0,0,0,0,0,0,0,0,0,0,0,1,1,1,1,1,1
1,1,1,1,1,1,0,0,0,0,0,0,0,0,0,0,0,0,0,0,0,0,0,0,0,0,0,0,1,1,1,1,1,1
1,1,1,1,1,1,0,0,0,0,0,0,0,0,0,0,0,0,0,0,0,0,0,0,0,0,0,0,1,1,1,1,1,1
1,1,1,1,1,1,0,0,0,0,0,62,62,62,62,62,0,0,62,62,62,62,62,0,0,0,0,0,1,1,1,1,1,1
1,1,1,1,1,1,0,0,0,0,0,62,2,62,2,62,0,0,62,2,62,2,62,0,0,0,0,0,1,1,1,1,1,1
1,1,1,1,0,0,0,0,0,0,0,62,62,87,62,62,0,0,62,62,87,62,62,0,0,0,0,0,0,0,1,1,1,1
1,1,1,1,2,0,2,0,0,0,0,0,2,62,2,0,0,0,0,2,62,2,0,0,0,0,0,2,0,2,1,1,1,1
1,1,1,2,0,0,0,2,0,2,0,2,0,86,86,86,86,86,86,86,86,0,2,0,2,0,2,0,0,0,2,0,1,1
1,1,2,41,0,0,0,0,2,2,2,2,2,2,2,2,2,2,2,2,2,2,2,2,2,2,41,0,0,0,0,2,1,1
1,1,0,0,0,2,52,34,0,0,0,0,0,60,2,2,2,2,2,2,59,0,0,0,0,0,0,0,2,52,52,0,1,1
1,1,2,41,0,0,2,2,2,2,2,2,2,2,2,2,54,54,2,2,2,2,2,2,2,2,41,0,0,2,2,2,1,1
1,1,1,2,0,0,2,2,2,0,0,0,87,2,0,0,0,0,0,0,2,87,0,0,0,2,2,0,0,2,2,1,1,1
1,1,1,1,2,2,2,2,2,0,0,0,87,2,0,0,0,0,0,0,2,87,0,0,0,2,2,2,2,2,1,1,1,1
1,1,1,1,2,54,54,54,2,0,0,0,87,2,0,0,0,0,0,0,2,87,0,0,0,2,54,54,54,2,1,1,1,1
1,1,1,1,2,0,0,0,2,81,0,0,87,2,2,2,2,2,2,2,2,87,0,0,81,2,0,0,0,2,1,1,1,1
1,1,1,1,2,0,0,0,0,2,0,0,0,87,87,87,87,87,87,87,87,0,0,0,2,0,0,0,0,2,1,1,1,1
1,1,1,1,2,0,0,0,0,2,0,0,0,0,0,0,0,0,0,0,0,0,0,0,2,0,0,0,0,2,1,1,1,1
1,1,1,1,2,52,0,0,0,2,0,0,0,0,0,0,0,0,0,0,0,0,0,0,2,0,0,0,52,2,1,1,1,1
1,1,1,1,2,2,0,0,0,2,0,0,0,0,0,0,0,0,0,0,0,0,0,0,2,0,0,0,2,2,1,1,1,1
1,1,1,1,2,54,0,0,0,2,0,0,0,0,0,0,0,0,0,0,0,0,0,0,2,0,0,0,54,2,1,1,1,1
1,1,1,1,2,0,0,0,0,2,0,0,0,0,0,0,0,0,0,0,0,0,0,0,2,0,0,0,0,2,1,1,1,1
1,1,1,1,2,52,0,0,0,2,0,0,0,0,0,0,0,0,0,0,0,0,0,0,2,0,0,0,52,2,1,1,1,1
1,1,1,1,2,2,0,0,0,2,0,0,0,0,0,0,0,0,0,0,0,0,0,0,2,0,0,0,2,2,1,1,1,1
1,1,1,1,2,2,0,0,0,2,0,0,0,0,0,0,0,0,0,0,0,0,0,0,2,0,0,0,2,2,1,1,1,1
1,1,1,1,2,54,0,0,0,2,0,0,0,0,0,0,0,0,0,0,0,0,0,0,2,0,0,0,54,2,1,1,1,1
1,1,1,1,2,0,0,0,0,2,0,0,0,0,0,0,0,0,0,0,0,0,0,0,2,0,0,0,0,2,1,1,1,1
1,1,1,1,2,52,0,0,0,2,0,0,0,0,0,0,0,0,0,0,0,0,0,0,2,0,0,0,52,2,1,1,1,1
1,1,1,1,2,2,0,0,0,2,0,0,0,0,0,0,0,0,0,0,0,0,0,0,2,0,0,0,2,2,1,1,1,1
1,1,1,1,2,54,0,0,0,2,0,0,0,0,0,0,0,0,0,0,0,0,0,0,2,0,0,0,54,2,1,1,1,1
1,1,1,1,2,0,0,0,0,2,0,0,0,0,0,0,0,0,0,0,0,0,0,0,2,0,0,0,0,2,1,1,1,1
1,1,1,1,2,0,0,0,0,2,0,0,0,87,87,87,87,87,87,87,87,0,0,0,2,0,0,0,0,2,1,1,1,1
1,1,1,1,2,0,0,0,2,79,0,0,87,2,2,2,2,2,2,2,2,87,0,0,79,2,0,0,0,2,1,1,1,1
1,1,1,1,2,52,52,52,2,0,0,0,87,2,0,0,0,0,0,0,2,87,0,0,0,2,52,52,52,2,1,1,1,1
1,1,1,1,2,2,2,2,2,0,0,0,87,2,0,0,0,0,0,0,2,87,0,0,0,2,2,2,2,2,1,1,1,1
1,1,1,2,2,0,0,2,2,0,0,0,87,2,0,0,0,0,0,0,2,87,0,0,0,2,2,2,0,0,2,0,1,1
1,1,2,2,2,0,0,40,2,2,2,2,2,2,2,2,52,52,2,2,2,2,2,2,2,2,2,2,0,0,40,2,1,1
1,1,0,54,54,2,0,0,0,0,0,0,0,60,2,2,2,2,2,2,59,0,0,0,0,0,29,54,2,0,0,0,1,1
1,1,2,0,0,0,0,40,2,2,2,2,2,2,2,2,2,2,2,2,2,2,2,2,2,2,0,0,0,0,40,2,1,1
1,1,1,2,0,0,0,2,0,2,0,2,0,88,88,88,88,88,88,88,88,0,2,0,2,0,2,0,0,0,2,1,1,1
1,1,1,1,2,0,2,0,0,0,0,0,2,62,2,0,0,0,0,2,62,2,0,0,0,0,0,2,0,2,1,1,1,1
1,1,1,1,0,0,0,0,0,0,0,62,62,87,62,62,0,0,62,62,87,62,62,0,0,0,0,0,0,0,1,1,1,1
1,1,1,1,1,1,0,0,0,0,0,62,2,62,2,62,0,0,62,2,62,2,62,0,0,0,0,0,1,1,1,1,1,1
1,1,1,1,1,1,0,0,0,0,0,62,62,62,62,62,0,0,62,62,62,62,62,0,0,0,0,0,1,1,1,1,1,1
1,1,1,1,1,1,0,0,0,0,0,0,0,0,0,0,0,0,0,0,0,0,0,0,0,0,0,0,1,1,1,1,1,1
1,1,1,1,1,1,0,0,0,0,0,0,0,0,0,0,0,0,0,0,0,0,0,0,0,0,0,0,1,1,1,1,1,1
1,1,1,1,1,1,0,0,0,0,0,0,0,0,0,0,0,0,0,0,0,0,0,0,0,0,0,0,1,1,1,1,1,1
1,1,1,1,1,1,0,0,0,0,0,0,0,0,0,0,0,0,0,0,0,0,0,0,0,0,0,0,1,1,1,1,1,1
1,1,1,1,1,1,0,0,0,0,0,0,0,0,0,0,0,0,0,0,0,0,0,0,0,0,0,0,1,1,1,1,1,1
1,1,1,1,1,1,0,0,0,0,0,0,0,0,0,0,0,0,0,0,0,0,0,0,0,0,0,0,1,1,1,1,1,1
1,1,1,1,1,1,0,0,0,0,0,0,0,0,0,0,0,0,0,0,0,0,0,0,0,0,0,0,1,1,1,1,1,1
1,1,1,1,1,1,0,0,0,0,0,0,0,0,0,0,0,0,0,0,0,0,0,0,0,0,0,0,1,1,1,1,1,1
endlayer

layer
1,1,1,1,1,1,0,0,0,0,0,0,0,0,0,0,0,0,0,0,0,0,0,0,0,0,0,0,1,1,1,1,1,1
1,1,1,1,1,1,0,0,0,0,0,0,0,0,0,0,0,0,0,0,0,0,0,0,0,0,0,0,1,1,1,1,1,1
1,1,1,1,1,1,0,0,0,0,0,0,0,0,0,0,0,0,0,0,0,0,0,0,0,0,0,0,1,1,1,1,1,1
1,1,1,1,1,1,0,0,0,0,0,0,0,0,0,0,0,0,0,0,0,0,0,0,0,0,0,0,1,1,1,1,1,1
1,1,1,1,1,1,0,0,0,0,0,0,0,0,0,0,0,0,0,0,0,0,0,0,0,0,0,0,1,1,1,1,1,1
1,1,1,1,1,1,0,0,0,0,0,0,0,0,0,0,0,0,0,0,0,0,0,0,0,0,0,0,1,1,1,1,1,1
1,1,1,1,1,1,0,0,0,0,0,0,0,0,0,0,0,0,0,0,0,0,0,0,0,0,0,0,1,1,1,1,1,1
1,1,1,1,1,1,0,0,0,0,0,0,0,0,0,0,0,0,0,0,0,0,0,0,0,0,0,0,1,1,1,1,1,1
1,1,1,1,1,1,0,0,0,0,0,0,0,0,0,0,0,0,0,0,0,0,0,0,0,0,0,0,1,1,1,1,1,1
1,1,1,1,1,1,0,0,0,0,0,0,62,0,62,0,0,0,0,62,0,62,0,0,0,0,0,0,1,1,1,1,1,1
1,1,1,1,0,0,0,0,0,0,0,0,0,0,0,0,0,0,0,0,0,0,0,0,0,0,0,0,0,0,1,1,1,1
1,1,1,1,2,0,2,0,0,0,0,0,62,0,62,0,0,0,0,62,0,62,0,0,0,0,0,2,0,2,1,1,1,1
1,1,1,2,0,0,0,2,0,2,0,2,0,0,0,0,0,0,0,0,0,0,2,0,2,0,2,0,0,0,2,0,1,1
1,1,2,0,0,0,0,40,2,2,2,2,2,2,2,2,2,2,2,2,2,2,2,2,2,2,0,0,0,0,40,2,1,1
1,1,0,0,0,2,0,0,0,0,2,2,2,2,2,2,54,54,2,2,2,2,2,2,2,0,0,0,2,0,0,0,1,1
1,1,2,2,2,34,0,40,2,2,2,2,2,2,2,2,0,0,2,2,2,2,2,2,2,2,2,2,34,0,40,2,1,1
1,1,1,2,2,34,0,2,2,0,0,0,0,0,66,0,0,0,0,66,0,0,0,0,0,2,2,2,34,0,2,1,1,1
1,1,1,1,2,2,0,2,2,0,0,0,0,2,0,0,0,0,0,0,2,0,0,0,0,2,2,54,2,2,1,1,1,1
1,1,1,1,2,44,0,44,2,0,0,0,0,0,0,0,0,0,0,0,0,0,0,0,0,2,44,0,44,2,1,1,1,1
1,1,1,1,2,0,0,0,2,2,0,0,0,2,0,2,0,0,2,0,2,0,0,0,2,2,0,0,0,2,1,1,1,1
1,1,1,1,0,0,0,0,0,2,0,0,0,0,0,0,0,0,0,0,0,0,0,0,2,0,0,0,0,0,1,1,1,1
1,1,1,1,2,0,0,0,0,0,0,0,0,0,0,0,0,0,0,0,0,0,0,0,0,0,0,0,0,2,1,1,1,1
1,1,1,1,2,0,0,0,0,0,0,0,0,0,0,0,0,0,0,0,0,0,0,0,0,0,0,0,0,2,1,1,1,1
1,1,1,1,2,2,41,0,0,2,0,0,0,0,0,0,0,0,0,0,0,0,0,0,2,0,0,40,2,2,1,1,1,1
1,1,1,1,2,0,0,0,0,2,0,0,0,0,0,0,0,0,0,0,0,0,0,0,2,0,0,0,0,2,1,1,1,1
1,1,1,1,0,0,0,0,0,0,0,0,0,0,0,0,0,0,0,0,0,0,0,0,0,0,0,0,0,0,1,1,1,1
1,1,1,1,2,0,0,0,0,0,0,0,0,0,0,0,0,0,0,0,0,0,0,0,0,0,0,0,0,2,1,1,1,1
1,1,1,1,2,2,41,0,0,2,0,0,0,0,0,0,0,0,0,0,0,0,0,0,2,0,0,40,2,2,1,1,1,1
1,1,1,1,2,2,41,0,0,2,0,0,0,0,0,0,0,0,0,0,0,0,0,0,2,0,0,40,2,2,1,1,1,1
1,1,1,1,2,0,0,0,0,0,0,0,0,0,0,0,0,0,0,0,0,0,0,0,0,0,0,0,0,2,1,1,1,1
1,1,1,1,0,0,0,0,0,0,0,0,0,0,0,0,0,0,0,0,0,0,0,0,0,0,0,0,0,0,1,1,1,1
1,1,1,1,2,0,0,0,0,2,0,0,0,0,0,0,0,0,0,0,0,0,0,0,2,0,0,0,0,2,1,1,1,1
1,1,1,1,2,2,41,0,0,2,0,0,0,0,0,0,0,0,0,0,0,0,0,0,2,0,0,40,2,2,1,1,1,1
1,1,1,1,2,0,0,0,0,0,0,0,0,0,0,0,0,0,0,0,0,0,0,0,0,0,0,0,0,2,1,1,1,1
1,1,1,1,2,0,0,0,0,0,0,0,0,0,0,0,0,0,0,0,0,0,0,0,0,0,0,0,0,2,1,1,1,1
1,1,1,1,0,0,0,0,0,2,0,0,0,0,0,0,0,0,0,0,0,0,0,0,2,0,0,0,0,0,1,1,1,1
1,1,1,1,2,0,0,0,2,2,0,0,0,2,0,2,0,0,2,0,2,0,0,0,2,2,0,0,0,2,1,1,1,1
1,1,1,1,2,45,0,45,2,0,0,0,0,0,0,0,0,0,0,0,0,0,0,0,0,2,45,0,45,2,1,1,1,1
1,1,1,1,2,2,52,2,2,0,0,0,0,2,0,0,0,0,0,0,2,0,0,0,0,2,2,0,2,2,1,1,1,1
1,1,1,2,0,29,2,2,2,0,0,0,0,0,66,0,0,0,0,66,0,0,0,0,0,2,2,0,29,2,2,0,1,1
1,1,2,41,0,29,2,2,2,2,2,2,2,2,2,2,0,0,2,2,2,2,2,2,2,2,41,0,29,2,2,2,1,1
1,1,0,0,0,2,0,0,0,2,2,2,2,2,2,2,52,52,2,2,2,2,2,2,0,0,0,0,2,0,0,0,1,1
1,1,2,41,0,0,0,0,2,2,2,2,2,2,2,2,2,2,2,2,2,2,2,2,2,2,41,0,0,0,0,2,1,1
1,1,1,2,0,0,0,2,0,2,0,2,0,0,0,0,0,0,0,0,0,0,2,0,2,0,2,0,0,0,2,1,1,1
1,1,1,1,2,0,2,0,0,0,0,0,62,0,62,0,0,0,0,62,0,62,0,0,0,0,0,2,0,2,1,1,1,1
1,1,1,1,0,0,0,0,0,0,0,0,0,0,0,0,0,0,0,0,0,0,0,0,0,0,0,0,0,0,1,1,1,1
1,1,1,1,1,1,0,0,0,0,0,0,62,0,62,0,0,0,0,62,0,62,0,0,0,0,0,0,1,1,1,1,1,1
1,1,1,1,1,1,0,0,0,0,0,0,0,0,0,0,0,0,0,0,0,0,0,0,0,0,0,0,1,1,1,1,1,1
1,1,1,1,1,1,0,0,0,0,0,0,0,0,0,0,0,0,0,0,0,0,0,0,0,0,0,0,1,1,1,1,1,1
1,1,1,1,1,1,0,0,0,0,0,0,0,0,0,0,0,0,0,0,0,0,0,0,0,0,0,0,1,1,1,1,1,1
1,1,1,1,1,1,0,0,0,0,0,0,0,0,0,0,0,0,0,0,0,0,0,0,0,0,0,0,1,1,1,1,1,1
1,1,1,1,1,1,0,0,0,0,0,0,0,0,0,0,0,0,0,0,0,0,0,0,0,0,0,0,1,1,1,1,1,1
1,1,1,1,1,1,0,0,0,0,0,0,0,0,0,0,0,0,0,0,0,0,0,0,0,0,0,0,1,1,1,1,1,1
1,1,1,1,1,1,0,0,0,0,0,0,0,0,0,0,0,0,0,0,0,0,0,0,0,0,0,0,1,1,1,1,1,1
1,1,1,1,1,1,0,0,0,0,0,0,0,0,0,0,0,0,0,0,0,0,0,0,0,0,0,0,1,1,1,1,1,1
1,1,1,1,1,1,0,0,0,0,0,0,0,0,0,0,0,0,0,0,0,0,0,0,0,0,0,0,1,1,1,1,1,1
endlayer

layer
1,1,1,1,1,1,0,0,0,0,0,0,0,0,0,0,0,0,0,0,0,0,0,0,0,0,0,0,1,1,1,1,1,1
1,1,1,1,1,1,0,0,0,0,0,0,0,0,0,0,0,0,0,0,0,0,0,0,0,0,0,0,1,1,1,1,1,1
1,1,1,1,1,1,0,0,0,0,0,0,0,0,0,0,0,0,0,0,0,0,0,0,0,0,0,0,1,1,1,1,1,1
1,1,1,1,1,1,0,0,0,0,0,0,0,0,0,0,0,0,0,0,0,0,0,0,0,0,0,0,1,1,1,1,1,1
1,1,1,1,1,1,0,0,0,0,0,0,0,0,0,0,0,0,0,0,0,0,0,0,0,0,0,0,1,1,1,1,1,1
1,1,1,1,1,1,0,0,0,0,0,0,0,0,0,0,0,0,0,0,0,0,0,0,0,0,0,0,1,1,1,1,1,1
1,1,1,1,1,1,0,0,0,0,0,0,0,0,0,0,0,0,0,0,0,0,0,0,0,0,0,0,1,1,1,1,1,1
1,1,1,1,1,1,0,0,0,0,0,0,0,0,0,0,0,0,0,0,0,0,0,0,0,0,0,0,1,1,1,1,1,1
1,1,1,1,1,1,0,0,0,0,0,0,0,0,0,0,0,0,0,0,0,0,0,0,0,0,0,0,1,1,1,1,1,1
1,1,1,1,1,1,0,0,0,0,0,0,0,0,0,0,0,0,0,0,0,0,0,0,0,0,0,0,1,1,1,1,1,1
1,1,1,1,0,0,0,0,0,0,0,0,0,0,0,0,0,0,0,0,0,0,0,0,0,0,0,0,0,0,1,1,1,1
1,1,1,1,2,2,2,0,0,0,0,0,0,0,0,0,0,0,0,0,0,0,0,0,0,0,0,2,2,2,1,1,1,1
1,1,1,2,2,0,0,2,81,2,81,2,81,81,81,81,81,81,81,81,81,81,2,81,2,81,2,2,0,0,2,0,1,1
1,1,2,2,2,0,0,0,2,2,2,2,2,2,2,2,2,2,2,2,2,2,2,2,2,2,2,2,0,0,0,2,1,1
1,1,2,54,54,2,0,0,0,2,2,2,2,2,2,34,0,0,29,2,2,2,2,2,2,59,54,54,2,0,0,2,1,1
1,1,2,0,0,0,0,0,2,2,2,2,2,2,2,2,0,0,2,2,2,2,2,2,2,2,0,0,0,0,0,2,1,1
1,1,1,2,0,0,0,2,2,79,79,0,0,0,78,0,0,0,0,78,0,0,0,79,60,2,2,0,0,0,2,1,1,1
1,1,1,1,2,2,0,2,2,59,0,0,0,0,0,0,0,0,0,0,0,0,0,0,60,2,2,0,2,2,1,1,1,1
1,1,1,60,2,79,0,79,2,0,0,0,0,0,0,0,0,0,0,0,0,0,0,0,0,2,79,0,79,2,59,1,1,1
1,1,1,1,2,0,0,0,2,2,0,0,0,0,0,0,0,0,0,0,0,0,0,0,2,2,0,0,0,2,1,1,1,1
1,1,1,1,0,0,0,0,0,2,0,0,0,0,0,0,0,0,0,0,0,0,0,0,2,0,0,0,0,0,1,1,1,1
1,1,1,1,2,0,0,0,0,0,0,0,0,0,0,0,0,0,0,0,0,0,0,0,0,0,0,0,0,2,1,1,1,1
1,1,1,60,2,81,0,0,0,0,0,0,0,0,0,0,0,0,0,0,0,0,0,0,0,0,0,0,81,2,59,1,1,1
1,1,1,60,2,2,0,0,0,2,0,0,0,0,0,0,0,0,0,0,0,0,0,0,2,0,0,0,2,2,59,1,1,1
1,1,1,1,2,79,0,0,0,2,0,0,0,0,0,0,0,0,0,0,0,0,0,0,2,0,0,0,79,2,1,1,1,1
1,1,1,1,0,0,0,0,0,0,0,0,0,0,0,0,0,0,0,0,0,0,0,0,0,0,0,0,0,0,1,1,1,1
1,1,1,1,2,81,0,0,0,0,0,0,0,0,0,0,0,0,0,0,0,0,0,0,0,0,0,0,81,2,1,1,1,1
1,1,1,60,2,2,0,0,0,2,0,0,0,0,0,0,0,0,0,0,0,0,0,0,2,0,0,0,2,2,59,1,1,1
1,1,1,60,2,2,0,0,0,2,0,0,0,0,0,0,0,0,0,0,0,0,0,0,2,0,0,0,2,2,59,1,1,1
1,1,1,1,2,79,0,0,0,0,0,0,0,0,0,0,0,0,0,0,0,0,0,0,0,0,0,0,79,2,1,1,1,1
1,1,1,1,0,0,0,0,0,0,0,0,0,0,0,0,0,0,0,0,0,0,0,0,0,0,0,0,0,0,1,1,1,1
1,1,1,1,2,81,0,0,0,2,0,0,0,0,0,0,0,0,0,0,0,0,0,0,2,0,0,0,81,2,1,1,1,1
1,1,1,60,2,2,0,0,0,2,0,0,0,0,0,0,0,0,0,0,0,0,0,0,2,0,0,0,2,2,59,1,1,1
1,1,1,60,2,79,0,0,0,0,0,0,0,0,0,0,0,0,0,0,0,0,0,0,0,0,0,0,79,2,59,1,1,1
1,1,1,1,2,0,0,0,0,0,0,0,0,0,0,0,0,0,0,0,0,0,0,0,0,0,0,0,0,2,1,1,1,1
1,1,1,1,0,0,0,0,0,2,0,0,0,0,0,0,0,0,0,0,0,0,0,0,2,0,0,0,0,0,1,1,1,1
1,1,1,1,2,0,0,0,2,2,0,0,0,0,0,0,0,0,0,0,0,0,0,0,2,2,0,0,0,2,1,1,1,1
1,1,1,60,2,81,0,81,2,0,0,0,0,0,0,0,0,0,0,0,0,0,0,0,0,2,81,0,81,2,59,1,1,1
1,1,1,1,2,2,0,2,2,59,0,0,0,0,0,0,0,0,0,0,0,0,0,0,60,2,2,0,2,2,1,1,1,1
1,1,1,2,0,0,0,2,2,81,81,0,0,0,78,0,0,0,0,78,0,0,0,81,81,2,2,0,0,0,2,0,1,1
1,1,2,0,0,0,0,0,2,2,2,2,2,2,2,2,0,0,2,2,2,2,2,2,2,2,0,0,0,0,0,2,1,1
1,1,2,0,0,2,52,52,60,2,2,2,2,2,2,34,0,0,29,2,2,2,2,2,2,0,0,0,2,52,52,2,1,1
1,1,2,0,0,0,2,2,2,2,2,2,2,2,2,2,2,2,2,2,2,2,2,2,2,2,0,0,0,2,2,2,1,1
1,1,1,2,0,0,2,2,79,2,79,2,79,79,79,79,79,79,79,79,79,79,2,79,2,79,2,0,0,2,2,1,1,1
1,1,1,1,2,2,2,0,0,0,0,0,0,0,0,0,0,0,0,0,0,0,0,0,0,0,0,2,2,2,1,1,1,1
1,1,1,1,0,0,0,0,0,0,0,0,0,0,0,0,0,0,0,0,0,0,0,0,0,0,0,0,0,0,1,1,1,1
1,1,1,1,1,1,0,0,0,0,0,0,0,0,0,0,0,0,0,0,0,0,0,0,0,0,0,0,1,1,1,1,1,1
1,1,1,1,1,1,0,0,0,0,0,0,0,0,0,0,0,0,0,0,0,0,0,0,0,0,0,0,1,1,1,1,1,1
1,1,1,1,1,1,0,0,0,0,0,0,0,0,0,0,0,0,0,0,0,0,0,0,0,0,0,0,1,1,1,1,1,1
1,1,1,1,1,1,0,0,0,0,0,0,0,0,0,0,0,0,0,0,0,0,0,0,0,0,0,0,1,1,1,1,1,1
1,1,1,1,1,1,0,0,0,0,0,0,0,0,0,0,0,0,0,0,0,0,0,0,0,0,0,0,1,1,1,1,1,1
1,1,1,1,1,1,0,0,0,0,0,0,0,0,0,0,0,0,0,0,0,0,0,0,0,0,0,0,1,1,1,1,1,1
1,1,1,1,1,1,0,0,0,0,0,0,0,0,0,0,0,0,0,0,0,0,0,0,0,0,0,0,1,1,1,1,1,1
1,1,1,1,1,1,0,0,0,0,0,0,0,0,0,0,0,0,0,0,0,0,0,0,0,0,0,0,1,1,1,1,1,1
1,1,1,1,1,1,0,0,0,0,0,0,0,0,0,0,0,0,0,0,0,0,0,0,0,0,0,0,1,1,1,1,1,1
1,1,1,1,1,1,0,0,0,0,0,0,0,0,0,0,0,0,0,0,0,0,0,0,0,0,0,0,1,1,1,1,1,1
endlayer

layer
1,1,1,1,1,1,0,0,0,0,0,0,0,0,0,0,0,0,0,0,0,0,0,0,0,0,0,0,1,1,1,1,1,1
1,1,1,1,1,1,0,0,0,0,0,0,0,0,0,0,0,0,0,0,0,0,0,0,0,0,0,0,1,1,1,1,1,1
1,1,1,1,1,1,0,0,0,0,0,0,0,0,0,0,0,0,0,0,0,0,0,0,0,0,0,0,1,1,1,1,1,1
1,1,1,1,1,1,0,0,0,0,0,0,0,0,0,0,0,0,0,0,0,0,0,0,0,0,0,0,1,1,1,1,1,1
1,1,1,1,1,1,0,0,0,0,0,0,0,0,0,0,0,0,0,0,0,0,0,0,0,0,0,0,1,1,1,1,1,1
1,1,1,1,1,1,0,0,0,0,0,0,0,0,0,0,0,0,0,0,0,0,0,0,0,0,0,0,1,1,1,1,1,1
1,1,1,1,1,1,0,0,0,0,0,0,0,0,0,0,0,0,0,0,0,0,0,0,0,0,0,0,1,1,1,1,1,1
1,1,1,1,1,1,0,0,0,0,0,0,0,0,0,0,0,0,0,0,0,0,0,0,0,0,0,0,1,1,1,1,1,1
1,1,1,1,1,1,0,0,0,0,0,0,0,0,0,0,0,0,0,0,0,0,0,0,0,0,0,0,1,1,1,1,1,1
1,1,1,1,1,1,0,0,0,0,0,0,0,0,0,0,0,0,0,0,0,0,0,0,0,0,0,0,1,1,1,1,1,1
1,1,1,1,0,0,0,0,0,0,0,0,0,0,0,0,0,0,0,0,0,0,0,0,0,0,0,0,0,0,1,1,1,1
1,1,1,1,2,2,2,0,0,81,0,81,0,0,0,0,0,0,0,0,0,0,81,0,81,0,0,2,2,2,1,1,1,1
1,1,1,2,0,29,2,2,2,2,2,2,2,2,2,2,2,2,2,2,2,2,2,2,2,2,2,0,29,2,2,0,1,1
1,1,2,41,0,29,2,2,2,2,0,0,0,0,0,0,0,0,0,0,0,0,0,0,29,2,41,0,29,2,2,2,1,1
1,1,2,0,0,2,0,0,2,2,0,0,0,0,0,0,0,0,0,0,0,0,0,0,0,0,0,0,2,0,0,2,1,1
1,1,2,41,0,0,0,0,2,2,0,0,0,0,0,0,0,0,0,0,0,0,0,0,29,2,41,0,0,0,0,2,1,1
1,1,1,2,0,0,0,2,2,2,2,2,2,2,2,2,2,2,2,2,2,2,2,2,2,2,2,0,0,0,2,1,1,1
1,1,1,60,2,2,2,2,2,2,0,0,0,0,0,0,0,0,0,0,0,0,0,0,2,2,2,0,2,2,59,1,1,1
1,1,1,2,2,2,2,2,2,2,0,0,0,0,0,0,0,0,0,0,0,0,0,0,2,2,2,0,2,2,2,1,1,1
1,1,1,2,2,2,2,2,2,2,0,0,0,0,0,0,0,0,0,0,0,0,0,0,2,2,2,2,2,2,2,1,1,1
1,1,1,2,2,2,2,2,2,2,0,0,0,0,0,0,0,0,0,0,0,0,0,0,2,2,2,2,2,2,2,1,1,1
1,1,1,2,2,2,2,2,2,2,0,0,0,0,0,0,0,0,0,0,0,0,0,0,2,2,2,2,2,2,2,1,1,1
1,1,1,2,2,2,2,2,2,2,0,0,0,0,0,0,0,0,0,0,0,0,0,0,2,2,2,2,2,2,2,1,1,1
1,1,1,2,2,2,2,2,2,2,0,0,0,0,0,0,0,0,0,0,0,0,0,0,2,2,2,2,2,2,2,1,1,1
1,1,1,2,2,2,2,2,2,2,0,0,0,0,0,0,0,0,0,0,0,0,0,0,2,2,2,2,2,2,2,1,1,1
1,1,1,2,2,2,2,2,2,2,0,0,0,0,0,0,0,0,0,0,0,0,0,0,2,2,2,2,2,2,2,1,1,1
1,1,1,2,2,2,2,2,2,2,0,0,0,0,0,0,0,0,0,0,0,0,0,0,2,2,2,2,2,2,2,1,1,1
1,1,1,2,2,2,2,2,2,2,0,0,0,0,0,0,0,0,0,0,0,0,0,0,2,2,2,2,2,2,2,1,1,1
1,1,1,2,2,2,2,2,2,2,0,0,0,0,0,0,0,0,0,0,0,0,0,0,2,2,2,2,2,2,2,1,1,1
1,1,1,2,2,2,2,2,2,2,0,0,0,0,0,0,0,0,0,0,0,0,0,0,2,2,2,2,2,2,2,1,1,1
1,1,1,2,2,2,2,2,2,2,0,0,0,0,0,0,0,0,0,0,0,0,0,0,2,2,2,2,2,2,2,1,1,1
1,1,1,2,2,2,2,2,2,2,0,0,0,0,0,0,0,0,0,0,0,0,0,0,2,2,2,2,2,2,2,1,1,1
1,1,1,2,2,2,2,2,2,2,0,0,0,0,0,0,0,0,0,0,0,0,0,0,2,2,2,2,2,2,2,1,1,1
1,1,1,2,2,2,2,2,2,2,0,0,0,0,0,0,0,0,0,0,0,0,0,0,2,2,2,2,2,2,2,1,1,1
1,1,1,2,2,2,2,2,2,2,0,0,0,0,0,0,0,0,0,0,0,0,0,0,2,2,2,2,2,2,2,1,1,1
1,1,1,2,2,2,2,2,2,2,0,0,0,0,0,0,0,0,0,0,0,0,0,0,2,2,2,2,2,2,2,1,1,1
1,1,1,2,2,2,2,2,2,2,0,0,0,0,0,0,0,0,0,0,0,0,0,0,2,2,2,2,2,2,2,1,1,1
1,1,1,2,2,2,0,2,2,2,0,0,0,0,0,0,0,0,0,0,0,0,0,0,2,2,2,2,2,2,2,1,1,1
1,1,1,60,2,2,0,2,2,2,0,0,0,0,0,0,0,0,0,0,0,0,0,0,2,2,2,2,2,2,59,1,1,1
1,1,1,2,0,0,0,2,2,2,2,2,2,2,2,2,2,2,2,2,2,2,2,2,2,2,2,0,0,0,2,0,1,1
1,1,2,0,0,0,0,40,2,34,0,0,0,0,0,0,0,0,0,0,0,0,0,0,2,2,0,0,0,0,40,2,1,1
1,1,2,0,0,2,0,0,0,0,0,0,0,0,0,0,0,0,0,0,0,0,0,0,2,0,0,0,2,0,0,2,1,1
1,1,2,2,2,34,0,40,2,34,0,0,0,0,0,0,0,0,0,0,0,0,0,0,2,2,2,2,34,0,40,2,1,1
1,1,1,2,2,34,0,2,2,2,2,2,2,2,2,2,2,2,2,2,2,2,2,2,2,2,2,2,34,0,2,1,1,1
1,1,1,1,2,2,2,0,0,79,0,79,0,0,0,0,0,0,0,0,0,0,79,0,79,0,0,2,2,2,1,1,1,1
1,1,1,1,0,0,0,0,0,0,0,0,0,0,0,0,0,0,0,0,0,0,0,0,0,0,0,0,0,0,1,1,1,1
1,1,1,1,1,1,0,0,0,0,0,0,0,0,0,0,0,0,0,0,0,0,0,0,0,0,0,0,1,1,1,1,1,1
1,1,1,1,1,1,0,0,0,0,0,0,0,0,0,0,0,0,0,0,0,0,0,0,0,0,0,0,1,1,1,1,1,1
1,1,1,1,1,1,0,0,0,0,0,0,0,0,0,0,0,0,0,0,0,0,0,0,0,0,0,0,1,1,1,1,1,1
1,1,1,1,1,1,0,0,0,0,0,0,0,0,0,0,0,0,0,0,0,0,0,0,0,0,0,0,1,1,1,1,1,1
1,1,1,1,1,1,0,0,0,0,0,0,0,0,0,0,0,0,0,0,0,0,0,0,0,0,0,0,1,1,1,1,1,1
1,1,1,1,1,1,0,0,0,0,0,0,0,0,0,0,0,0,0,0,0,0,0,0,0,0,0,0,1,1,1,1,1,1
1,1,1,1,1,1,0,0,0,0,0,0,0,0,0,0,0,0,0,0,0,0,0,0,0,0,0,0,1,1,1,1,1,1
1,1,1,1,1,1,0,0,0,0,0,0,0,0,0,0,0,0,0,0,0,0,0,0,0,0,0,0,1,1,1,1,1,1
1,1,1,1,1,1,0,0,0,0,0,0,0,0,0,0,0,0,0,0,0,0,0,0,0,0,0,0,1,1,1,1,1,1
1,1,1,1,1,1,0,0,0,0,0,0,0,0,0,0,0,0,0,0,0,0,0,0,0,0,0,0,1,1,1,1,1,1
endlayer

layer
1,1,1,1,1,1,0,0,0,0,0,0,0,0,0,0,0,0,0,0,0,0,0,0,0,0,0,0,1,1,1,1,1,1
1,1,1,1,1,1,0,0,0,0,0,0,0,0,0,0,0,0,0,0,0,0,0,0,0,0,0,0,1,1,1,1,1,1
1,1,1,1,1,1,0,0,0,0,0,0,0,0,0,0,0,0,0,0,0,0,0,0,0,0,0,0,1,1,1,1,1,1
1,1,1,1,1,1,0,0,0,0,0,0,0,0,0,0,0,0,0,0,0,0,0,0,0,0,0,0,1,1,1,1,1,1
1,1,1,1,1,1,0,0,0,0,0,0,0,0,0,0,0,0,0,0,0,0,0,0,0,0,0,0,1,1,1,1,1,1
1,1,1,1,1,1,0,0,0,0,0,0,0,0,0,0,0,0,0,0,0,0,0,0,0,0,0,0,1,1,1,1,1,1
1,1,1,1,1,1,0,0,0,0,0,0,0,0,0,0,0,0,0,0,0,0,0,0,0,0,0,0,1,1,1,1,1,1
1,1,1,1,1,1,0,0,0,0,0,0,0,0,0,0,0,0,0,0,0,0,0,0,0,0,0,0,1,1,1,1,1,1
1,1,1,1,1,1,0,0,0,0,0,0,0,0,0,0,0,0,0,0,0,0,0,0,0,0,0,0,1,1,1,1,1,1
1,1,1,1,1,1,0,0,0,0,0,0,0,0,0,0,0,0,0,0,0,0,0,0,0,0,0,0,1,1,1,1,1,1
1,1,1,1,81,81,81,81,81,81,81,81,81,81,81,81,81,81,81,81,81,81,81,81,81,81,81,81,81,81,1,1,1,1
1,1,1,60,2,2,2,2,2,2,2,2,2,2,2,2,2,2,2,2,2,2,2,2,2,2,2,2,2,2,59,1,1,1
1,1,81,2,0,0,0,2,2,2,2,2,2,2,2,2,2,2,2,2,2,2,2,2,2,2,2,0,0,0,2,81,1,1
1,60,2,0,0,0,0,0,2,59,0,44,0,0,0,44,0,0,44,0,0,0,44,0,60,2,0,0,0,0,0,2,59,1
1,60,2,0,0,2,52,52,2,59,0,0,0,0,0,0,0,0,0,0,0,0,0,0,0,0,0,0,2,52,52,2,59,1
1,60,2,0,0,0,2,2,2,59,0,45,0,0,0,45,0,0,45,0,0,0,45,0,60,2,0,0,0,2,2,2,59,1
1,1,79,2,0,0,2,2,2,2,2,2,2,2,2,2,2,2,2,2,2,2,2,2,2,2,2,0,0,2,2,79,1,1
1,1,1,2,2,2,2,2,2,2,2,2,2,2,2,2,2,2,2,2,2,2,2,2,2,2,2,2,2,2,2,1,1,1
1,1,1,2,2,2,2,2,2,2,79,79,79,79,79,79,79,79,79,79,79,79,79,79,2,2,2,2,2,2,2,1,1,1
1,1,1,2,87,2,2,2,87,2,0,0,0,0,0,0,0,0,0,0,0,0,0,0,2,87,2,2,2,87,2,1,1,1
1,1,1,2,87,2,54,2,87,2,0,0,0,0,0,0,0,0,0,0,0,0,0,0,2,87,2,54,2,87,2,1,1,1
1,1,1,2,87,87,87,87,87,2,0,0,0,0,0,0,0,0,0,0,0,0,0,0,2,87,87,87,87,87,2,1,1,1
1,1,1,2,87,87,87,87,87,2,0,0,0,0,0,0,0,0,0,0,0,0,0,0,2,87,87,87,87,87,2,1,1,1
1,1,1,2,87,87,87,87,87,2,0,0,0,0,0,0,0,0,0,0,0,0,0,0,2,87,87,87,87,87,2,1,1,1
1,1,1,2,87,87,87,87,87,2,0,0,0,0,0,0,0,0,0,0,0,0,0,0,2,87,87,87,87,87,2,1,1,1
1,1,1,2,87,87,87,87,87,2,0,0,0,0,0,0,0,0,0,0,0,0,0,0,2,87,87,87,87,87,2,1,1,1
1,1,1,2,87,87,87,87,87,2,0,0,0,0,0,0,0,0,0,0,0,0,0,0,2,87,87,87,87,87,2,1,1,1
1,1,1,2,87,87,87,87,87,2,0,0,0,0,0,0,0,0,0,0,0,0,0,0,2,87,87,87,87,87,2,1,1,1
1,1,1,2,87,87,87,87,87,2,0,0,0,0,0,0,0,0,0,0,0,0,0,0,2,87,87,87,87,87,2,1,1,1
1,1,1,2,87,87,87,87,87,2,0,0,0,0,0,0,0,0,0,0,0,0,0,0,2,87,87,87,87,87,2,1,1,1
1,1,1,2,87,87,87,87,87,2,0,0,0,0,0,0,0,0,0,0,0,0,0,0,2,87,87,87,87,87,2,1,1,1
1,1,1,2,87,87,87,87,87,2,0,0,0,0,0,0,0,0,0,0,0,0,0,0,2,87,87,87,87,87,2,1,1,1
1,1,1,2,87,87,87,87,87,2,0,0,0,0,0,0,0,0,0,0,0,0,0,0,2,87,87,87,87,87,2,1,1,1
1,1,1,2,87,87,87,87,87,2,0,0,0,0,0,0,0,0,0,0,0,0,0,0,2,87,87,87,87,87,2,1,1,1
1,1,1,2,87,87,87,87,87,2,0,0,0,0,0,0,0,0,0,0,0,0,0,0,2,87,87,87,87,87,2,1,1,1
1,1,1,2,87,2,52,2,87,2,0,0,0,0,0,0,0,0,0,0,0,0,0,0,2,87,2,52,2,87,2,1,1,1
1,1,1,2,87,2,2,2,87,2,0,0,0,0,0,0,0,0,0,0,0,0,0,0,2,87,2,2,2,87,2,1,1,1
1,1,1,2,2,2,2,2,2,2,81,81,81,81,81,81,81,81,81,81,81,81,81,81,2,2,2,2,2,2,2,1,1,1
1,1,1,2,2,2,2,2,2,2,2,2,2,2,2,2,2,2,2,2,2,2,2,2,2,2,2,2,2,2,2,1,1,1
1,1,81,2,2,0,0,2,2,2,2,2,2,2,2,2,2,2,2,2,2,2,2,2,2,2,2,2,0,0,2,81,1,1
1,60,2,2,2,0,0,0,2,59,0,44,0,0,0,44,0,0,44,0,0,0,44,0,60,2,2,2,0,0,0,2,59,1
1,60,2,54,54,2,0,0,0,0,0,0,0,0,0,0,0,0,0,0,0,0,0,0,60,2,54,54,2,0,0,2,59,1
1,60,2,0,0,0,0,0,2,59,0,45,0,0,0,45,0,0,45,0,0,0,45,0,60,2,0,0,0,0,0,2,59,1
1,1,79,2,0,0,0,2,2,2,2,2,2,2,2,2,2,2,2,2,2,2,2,2,2,2,2,0,0,0,2,79,1,1
1,1,1,60,2,2,2,2,2,2,2,2,2,2,2,2,2,2,2,2,2,2,2,2,2,2,2,2,2,2,59,1,1,1
1,1,1,1,79,79,79,79,79,79,79,79,79,79,79,79,79,79,79,79,79,79,79,79,79,79,79,79,79,79,1,1,1,1
1,1,1,1,1,1,0,0,0,0,0,0,0,0,0,0,0,0,0,0,0,0,0,0,0,0,0,0,1,1,1,1,1,1
1,1,1,1,1,1,0,0,0,0,0,0,0,0,0,0,0,0,0,0,0,0,0,0,0,0,0,0,1,1,1,1,1,1
1,1,1,1,1,1,0,0,0,0,0,0,0,0,0,0,0,0,0,0,0,0,0,0,0,0,0,0,1,1,1,1,1,1
1,1,1,1,1,1,0,0,0,0,0,0,0,0,0,0,0,0,0,0,0,0,0,0,0,0,0,0,1,1,1,1,1,1
1,1,1,1,1,1,0,0,0,0,0,0,0,0,0,0,0,0,0,0,0,0,0,0,0,0,0,0,1,1,1,1,1,1
1,1,1,1,1,1,0,0,0,0,0,0,0,0,0,0,0,0,0,0,0,0,0,0,0,0,0,0,1,1,1,1,1,1
1,1,1,1,1,1,0,0,0,0,0,0,0,0,0,0,0,0,0,0,0,0,0,0,0,0,0,0,1,1,1,1,1,1
1,1,1,1,1,1,0,0,0,0,0,0,0,0,0,0,0,0,0,0,0,0,0,0,0,0,0,0,1,1,1,1,1,1
1,1,1,1,1,1,0,0,0,0,0,0,0,0,0,0,0,0,0,0,0,0,0,0,0,0,0,0,1,1,1,1,1,1
1,1,1,1,1,1,0,0,0,0,0,0,0,0,0,0,0,0,0,0,0,0,0,0,0,0,0,0,1,1,1,1,1,1
endlayer

layer
1,1,1,1,1,1,0,0,0,0,0,0,0,0,0,0,0,0,0,0,0,0,0,0,0,0,0,0,1,1,1,1,1,1
1,1,1,1,1,1,0,0,0,0,0,0,0,0,0,0,0,0,0,0,0,0,0,0,0,0,0,0,1,1,1,1,1,1
1,1,1,1,1,1,0,0,0,0,0,0,0,0,0,0,0,0,0,0,0,0,0,0,0,0,0,0,1,1,1,1,1,1
1,1,1,1,1,1,0,0,0,0,0,0,0,0,0,0,0,0,0,0,0,0,0,0,0,0,0,0,1,1,1,1,1,1
1,1,1,1,1,1,0,0,0,0,0,0,0,0,0,0,0,0,0,0,0,0,0,0,0,0,0,0,1,1,1,1,1,1
1,1,1,1,1,1,0,0,0,0,0,0,0,0,0,0,0,0,0,0,0,0,0,0,0,0,0,0,1,1,1,1,1,1
1,1,1,1,1,1,0,0,0,0,0,0,0,0,0,0,0,0,0,0,0,0,0,0,0,0,0,0,1,1,1,1,1,1
1,1,1,1,1,1,0,0,0,0,0,0,0,0,0,0,0,0,0,0,0,0,0,0,0,0,0,0,1,1,1,1,1,1
1,1,1,1,1,1,0,0,0,0,0,0,0,0,0,0,0,0,0,0,0,0,0,0,0,0,0,0,1,1,1,1,1,1
1,1,1,1,1,1,0,0,0,0,0,0,0,0,0,0,0,0,0,0,0,0,0,0,0,0,0,0,1,1,1,1,1,1
1,1,1,1,87,87,87,87,87,87,87,87,87,87,87,87,87,87,87,87,87,87,87,87,87,87,87,87,87,87,1,1,1,1
1,1,1,87,2,2,2,2,2,2,2,2,2,2,2,2,2,2,2,2,2,2,2,2,2,2,2,2,2,2,87,1,1,1
1,1,87,2,0,0,0,2,2,2,59,79,79,79,79,60,2,2,59,79,79,79,79,60,2,2,2,0,0,0,2,87,1,1
1,87,2,2,0,0,0,40,2,87,0,0,0,0,0,0,79,79,0,0,0,0,0,0,87,2,2,0,0,0,40,2,87,1
1,87,2,2,2,2,0,0,2,87,0,0,0,0,0,0,0,0,0,0,0,0,0,0,87,2,2,2,2,0,0,2,87,1
1,87,2,2,2,34,0,40,2,87,0,0,0,0,0,0,81,81,0,0,0,0,0,0,87,2,2,2,34,0,40,2,87,1
1,1,87,2,2,34,0,2,2,2,59,81,81,81,81,60,2,2,59,81,81,81,81,60,2,2,2,2,34,0,2,87,1,1
1,1,1,87,2,2,2,2,2,2,2,2,2,2,2,2,2,2,2,2,2,2,2,2,2,2,2,2,2,2,87,1,1,1
1,1,1,2,2,2,2,2,87,2,87,87,87,87,87,87,87,87,87,87,87,87,87,87,2,87,2,2,2,2,2,1,1,1
1,1,1,62,0,2,54,2,0,62,0,0,0,0,0,0,0,0,0,0,0,0,0,0,62,0,2,54,2,0,62,1,1,1
1,1,1,2,0,62,0,62,0,2,0,0,0,0,0,0,0,0,0,0,0,0,0,0,2,0,62,0,62,0,2,1,1,1
1,1,1,62,0,0,0,0,0,62,0,0,0,0,0,0,0,0,0,0,0,0,0,0,62,0,0,0,0,0,62,1,1,1
1,1,1,2,0,0,0,0,0,2,0,0,0,0,0,0,0,0,0,0,0,0,0,0,2,0,0,0,0,0,2,1,1,1
1,1,1,62,0,0,0,0,0,62,0,0,0,0,0,0,0,0,0,0,0,0,0,0,62,0,0,0,0,0,62,1,1,1
1,1,1,2,0,0,0,0,0,2,0,0,0,0,0,0,0,0,0,0,0,0,0,0,2,0,0,0,0,0,2,1,1,1
1,1,1,62,0,0,0,0,0,62,0,0,0,0,0,0,0,0,0,0,0,0,0,0,62,0,0,0,0,0,62,1,1,1
1,1,1,2,0,0,0,0,0,2,0,0,0,0,0,0,0,0,0,0,0,0,0,0,2,0,0,0,0,0,2,1,1,1
1,1,1,62,0,0,0,0,0,62,0,0,0,0,0,0,0,0,0,0,0,0,0,0,62,0,0,0,0,0,62,1,1,1
1,1,1,62,0,0,0,0,0,62,0,0,0,0,0,0,0,0,0,0,0,0,0,0,62,0,0,0,0,0,62,1,1,1
1,1,1,2,0,0,0,0,0,2,0,0,0,0,0,0,0,0,0,0,0,0,0,0,2,0,0,0,0,0,2,1,1,1
1,1,1,62,0,0,0,0,0,62,0,0,0,0,0,0,0,0,0,0,0,0,0,0,62,0,0,0,0,0,62,1,1,1
1,1,1,2,0,0,0,0,0,2,0,0,0,0,0,0,0,0,0,0,0,0,0,0,2,0,0,0,0,0,2,1,1,1
1,1,1,62,0,0,0,0,0,62,0,0,0,0,0,0,0,0,0,0,0,0,0,0,62,0,0,0,0,0,62,1,1,1
1,1,1,2,0,0,0,0,0,2,0,0,0,0,0,0,0,0,0,0,0,0,0,0,2,0,0,0,0,0,2,1,1,1
1,1,1,62,0,0,0,0,0,62,0,0,0,0,0,0,0,0,0,0,0,0,0,0,62,0,0,0,0,0,62,1,1,1
1,1,1,2,0,62,0,62,0,2,0,0,0,0,0,0,0,0,0,0,0,0,0,0,2,0,62,0,62,0,2,1,1,1
1,1,1,62,0,2,52,2,0,62,0,0,0,0,0,0,0,0,0,0,0,0,0,0,62,0,2,52,2,0,62,1,1,1
1,1,1,2,2,2,2,2,87,2,87,87,87,87,87,87,87,87,87,87,87,87,87,87,2,87,2,2,2,2,2,1,1,1
1,1,1,87,2,2,2,2,2,2,2,2,2,2,2,2,2,2,2,2,2,2,2,2,2,2,2,2,2,2,87,1,1,1
1,1,87,2,0,29,2,2,2,2,59,79,79,79,79,60,2,2,59,79,79,79,79,60,2,2,2,0,29,2,2,87,1,1
1,87,2,41,0,29,2,2,2,87,0,0,0,0,0,0,79,79,0,0,0,0,0,0,87,2,41,0,29,2,2,2,87,1
1,87,2,0,0,2,2,2,2,87,0,0,0,0,0,0,0,0,0,0,0,0,0,0,87,2,0,0,2,2,2,2,87,1
1,87,2,41,0,0,0,2,2,87,0,0,0,0,0,0,81,81,0,0,0,0,0,0,87,2,41,0,0,0,2,2,87,1
1,1,87,2,0,0,0,2,2,2,59,81,81,81,81,60,2,2,59,81,81,81,81,60,2,2,2,0,0,0,2,87,1,1
1,1,1,87,2,2,2,2,2,2,2,2,2,2,2,2,2,2,2,2,2,2,2,2,2,2,2,2,2,2,87,1,1,1
1,1,1,1,87,87,87,87,87,87,87,87,87,87,87,87,87,87,87,87,87,87,87,87,87,87,87,87,87,87,1,1,1,1
1,1,1,1,1,1,0,0,0,0,0,0,0,0,0,0,0,0,0,0,0,0,0,0,0,0,0,0,1,1,1,1,1,1
1,1,1,1,1,1,0,0,0,0,0,0,0,0,0,0,0,0,0,0,0,0,0,0,0,0,0,0,1,1,1,1,1,1
1,1,1,1,1,1,0,0,0,0,0,0,0,0,0,0,0,0,0,0,0,0,0,0,0,0,0,0,1,1,1,1,1,1
1,1,1,1,1,1,0,0,0,0,0,0,0,0,0,0,0,0,0,0,0,0,0,0,0,0,0,0,1,1,1,1,1,1
1,1,1,1,1,1,0,0,0,0,0,0,0,0,0,0,0,0,0,0,0,0,0,0,0,0,0,0,1,1,1,1,1,1
1,1,1,1,1,1,0,0,0,0,0,0,0,0,0,0,0,0,0,0,0,0,0,0,0,0,0,0,1,1,1,1,1,1
1,1,1,1,1,1,0,0,0,0,0,0,0,0,0,0,0,0,0,0,0,0,0,0,0,0,0,0,1,1,1,1,1,1
1,1,1,1,1,1,0,0,0,0,0,0,0,0,0,0,0,0,0,0,0,0,0,0,0,0,0,0,1,1,1,1,1,1
1,1,1,1,1,1,0,0,0,0,0,0,0,0,0,0,0,0,0,0,0,0,0,0,0,0,0,0,1,1,1,1,1,1
1,1,1,1,1,1,0,0,0,0,0,0,0,0,0,0,0,0,0,0,0,0,0,0,0,0,0,0,1,1,1,1,1,1
endlayer

layer
1,1,1,1,1,1,0,0,0,0,0,0,0,0,0,0,0,0,0,0,0,0,0,0,0,0,0,0,1,1,1,1,1,1
1,1,1,1,1,1,0,0,0,0,0,0,0,0,0,0,0,0,0,0,0,0,0,0,0,0,0,0,1,1,1,1,1,1
1,1,1,1,1,1,0,0,0,0,0,0,0,0,0,0,0,0,0,0,0,0,0,0,0,0,0,0,1,1,1,1,1,1
1,1,1,1,1,1,0,0,0,0,0,0,0,0,0,0,0,0,0,0,0,0,0,0,0,0,0,0,1,1,1,1,1,1
1,1,1,1,1,1,0,0,0,0,0,0,0,0,0,0,0,0,0,0,0,0,0,0,0,0,0,0,1,1,1,1,1,1
1,1,1,1,1,1,0,0,0,0,0,0,0,0,0,0,0,0,0,0,0,0,0,0,0,0,0,0,1,1,1,1,1,1
1,1,1,1,1,1,0,0,0,0,0,0,0,0,0,0,0,0,0,0,0,0,0,0,0,0,0,0,1,1,1,1,1,1
1,1,1,1,1,1,0,0,0,0,0,0,0,0,0,0,0,0,0,0,0,0,0,0,0,0,0,0,1,1,1,1,1,1
1,1,1,1,1,1,0,0,0,0,0,0,0,0,0,0,0,0,0,0,0,0,0,0,0,0,0,0,1,1,1,1,1,1
1,1,1,1,1,1,0,0,0,0,0,0,0,0,0,0,0,0,0,0,0,0,0,0,0,0,0,0,1,1,1,1,1,1
1,1,1,2,2,2,2,2,0,0,0,0,0,0,0,0,0,0,0,0,0,0,0,0,0,0,2,2,2,2,2,1,1,1
1,1,2,2,2,2,2,2,2,2,2,2,2,2,2,2,2,2,2,2,2,2,2,2,2,2,2,2,2,2,2,2,1,1
1,2,2,2,2,2,60,2,2,2,2,2,2,2,2,2,2,2,2,2,2,2,2,2,2,2,2,2,0,0,2,2,2,1
1,2,2,2,2,2,0,60,2,2,2,2,2,2,2,2,2,2,2,2,2,2,2,2,2,2,2,2,0,0,0,2,2,1
1,2,2,54,54,2,0,60,2,2,2,2,2,2,2,2,2,2,2,2,2,2,2,2,2,2,54,54,2,0,0,2,2,1
1,2,2,0,0,0,0,60,2,2,2,2,2,2,2,2,2,2,2,2,2,2,2,2,2,2,0,0,0,0,0,2,2,1
1,2,2,2,0,0,0,2,2,2,2,2,2,2,2,2,2,2,2,2,2,2,2,2,2,2,2,0,0,0,2,2,2,1
1,1,2,2,2,2,2,2,2,2,2,2,2,2,2,2,2,2,2,2,2,2,2,2,2,2,2,2,2,2,2,2,1,1
1,1,1,2,2,2,54,2,0,62,0,0,0,0,0,0,0,0,0,0,0,0,0,0,62,0,2,54,2,2,2,1,1,1
1,1,1,1,0,62,0,62,0,0,0,0,0,0,0,0,0,0,0,0,0,0,0,0,0,0,62,0,62,0,1,1,1,1
1,1,1,62,0,0,0,0,0,62,0,0,0,0,0,0,0,0,0,0,0,0,0,0,62,0,0,0,0,0,62,1,1,1
1,1,1,1,0,0,0,0,0,0,0,0,0,0,0,0,0,0,0,0,0,0,0,0,0,0,0,0,0,0,1,1,1,1
1,1,1,62,0,0,0,0,0,62,0,0,0,0,0,0,0,0,0,0,0,0,0,0,62,0,0,0,0,0,62,1,1,1
1,1,1,1,0,0,0,0,0,0,0,0,0,0,0,0,0,0,0,0,0,0,0,0,0,0,0,0,0,0,1,1,1,1
1,1,1,62,0,0,0,0,0,62,0,0,0,0,0,0,0,0,0,0,0,0,0,0,62,0,0,0,0,0,62,1,1,1
1,1,1,1,0,0,0,0,0,0,0,0,0,0,0,0,0,0,0,0,0,0,0,0,0,0,0,0,0,0,1,1,1,1
1,1,1,62,0,0,0,0,0,62,0,0,0,0,0,0,0,0,0,0,0,0,0,0,62,0,0,0,0,0,62,1,1,1
1,1,1,1,0,0,0,0,0,0,0,0,0,0,0,0,0,0,0,0,0,0,0,0,0,0,0,0,0,0,1,1,1,1
1,1,1,1,0,0,0,0,0,0,0,0,0,0,0,0,0,0,0,0,0,0,0,0,0,0,0,0,0,0,1,1,1,1
1,1,1,62,0,0,0,0,0,62,0,0,0,0,0,0,0,0,0,0,0,0,0,0,62,0,0,0,0,0,62,1,1,1
1,1,1,1,0,0,0,0,0,0,0,0,0,0,0,0,0,0,0,0,0,0,0,0,0,0,0,0,0,0,1,1,1,1
1,1,1,62,0,0,0,0,0,62,0,0,0,0,0,0,0,0,0,0,0,0,0,0,62,0,0,0,0,0,62,1,1,1
1,1,1,1,0,0,0,0,0,0,0,0,0,0,0,0,0,0,0,0,0,0,0,0,0,0,0,0,0,0,1,1,1,1
1,1,1,62,0,0,0,0,0,62,0,0,0,0,0,0,0,0,0,0,0,0,0,0,62,0,0,0,0,0,62,1,1,1
1,1,1,1,0,0,0,0,0,0,0,0,0,0,0,0,0,0,0,0,0,0,0,0,0,0,0,0,0,0,1,1,1,1
1,1,1,62,0,0,0,0,0,62,0,0,0,0,0,0,0,0,0,0,0,0,0,0,62,0,0,0,0,0,62,1,1,1
1,1,1,1,0,62,0,62,0,0,0,0,0,0,0,0,0,0,0,0,0,0,0,0,0,0,62,0,62,0,1,1,1,1
1,1,1,2,2,2,52,2,0,62,0,0,0,0,0,0,0,0,0,0,0,0,0,0,62,0,2,52,2,2,2,1,1,1
1,1,2,2,2,2,2,2,2,2,2,2,2,2,2,2,2,2,2,2,2,2,2,2,2,2,2,2,2,2,2,2,1,1
1,2,2,2,0,0,0,2,2,2,2,2,2,2,2,2,2,2,2,2,2,2,2,2,2,2,2,0,0,0,2,2,2,1
1,2,2,0,0,0,0,0,2,2,2,2,2,2,2,2,2,2,2,2,2,2,2,2,2,2,59,0,0,0,0,2,2,1
1,2,2,0,0,2,52,52,2,2,2,2,2,2,2,2,2,2,2,2,2,2,2,2,2,2,59,0,2,52,52,2,2,1
1,2,2,0,0,0,2,2,2,2,2,2,2,2,2,2,2,2,2,2,2,2,2,2,2,2,59,0,2,2,2,2,2,1
1,2,2,2,0,0,2,2,2,2,2,2,2,2,2,2,2,2,2,2,2,2,2,2,2,2,2,59,2,2,2,2,2,1
1,1,2,2,2,2,2,2,2,2,2,2,2,2,2,2,2,2,2,2,2,2,2,2,2,2,2,2,2,2,2,2,1,1
1,1,1,2,2,2,2,2,0,0,0,0,0,0,0,0,0,0,0,0,0,0,0,0,0,0,2,2,2,2,2,1,1,1
1,1,1,1,1,1,0,0,0,0,0,0,0,0,0,0,0,0,0,0,0,0,0,0,0,0,0,0,1,1,1,1,1,1
1,1,1,1,1,1,0,0,0,0,0,0,0,0,0,0,0,0,0,0,0,0,0,0,0,0,0,0,1,1,1,1,1,1
1,1,1,1,1,1,0,0,0,0,0,0,0,0,0,0,0,0,0,0,0,0,0,0,0,0,0,0,1,1,1,1,1,1
1,1,1,1,1,1,0,0,0,0,0,0,0,0,0,0,0,0,0,0,0,0,0,0,0,0,0,0,1,1,1,1,1,1
1,1,1,1,1,1,0,0,0,0,0,0,0,0,0,0,0,0,0,0,0,0,0,0,0,0,0,0,1,1,1,1,1,1
1,1,1,1,1,1,0,0,0,0,0,0,0,0,0,0,0,0,0,0,0,0,0,0,0,0,0,0,1,1,1,1,1,1
1,1,1,1,1,1,0,0,0,0,0,0,0,0,0,0,0,0,0,0,0,0,0,0,0,0,0,0,1,1,1,1,1,1
1,1,1,1,1,1,0,0,0,0,0,0,0,0,0,0,0,0,0,0,0,0,0,0,0,0,0,0,1,1,1,1,1,1
1,1,1,1,1,1,0,0,0,0,0,0,0,0,0,0,0,0,0,0,0,0,0,0,0,0,0,0,1,1,1,1,1,1
1,1,1,1,1,1,0,0,0,0,0,0,0,0,0,0,0,0,0,0,0,0,0,0,0,0,0,0,1,1,1,1,1,1
endlayer

layer
1,1,1,1,1,1,0,0,0,0,0,0,0,0,0,0,0,0,0,0,0,0,0,0,0,0,0,0,1,1,1,1,1,1
1,1,1,1,1,1,0,0,0,0,0,0,0,0,0,0,0,0,0,0,0,0,0,0,0,0,0,0,1,1,1,1,1,1
1,1,1,1,1,1,0,0,0,0,0,0,0,0,0,0,0,0,0,0,0,0,0,0,0,0,0,0,1,1,1,1,1,1
1,1,1,1,1,1,0,0,0,0,0,0,0,0,0,0,0,0,0,0,0,0,0,0,0,0,0,0,1,1,1,1,1,1
1,1,1,1,1,1,0,0,0,0,0,0,0,0,0,0,0,0,0,0,0,0,0,0,0,0,0,0,1,1,1,1,1,1
1,1,1,1,1,1,0,0,0,0,0,0,0,0,0,0,0,0,0,0,0,0,0,0,0,0,0,0,1,1,1,1,1,1
1,1,1,1,1,1,0,0,0,0,0,0,0,0,0,0,0,0,0,0,0,0,0,0,0,0,0,0,1,1,1,1,1,1
1,1,1,1,1,1,0,0,0,0,0,0,0,0,0,0,0,0,0,0,0,0,0,0,0,0,0,0,1,1,1,1,1,1
1,1,1,1,1,1,0,0,0,0,0,0,0,0,0,0,0,0,0,0,0,0,0,0,0,0,0,0,1,1,1,1,1,1
1,1,1,1,1,1,0,0,0,0,0,0,0,0,0,0,0,0,0,0,0,0,0,0,0,0,0,0,1,1,1,1,1,1
1,1,1,2,2,2,2,2,0,0,0,0,0,0,0,0,0,0,0,0,0,0,0,0,0,0,2,2,2,2,2,1,1,1
1,1,2,87,87,87,87,87,2,2,2,2,2,2,2,2,2,2,2,2,2,2,2,2,2,2,87,87,87,87,87,2,1,1
1,2,87,87,87,87,87,87,87,87,87,87,87,87,87,87,87,87,87,87,87,87,87,87,87,87,87,87,0,0,87,87,2,1
1,2,87,87,87,87,0,87,87,87,87,87,87,87,87,87,87,87,87,87,87,87,87,87,87,87,87,87,0,0,0,87,2,1
1,2,87,0,0,87,0,87,87,87,87,87,87,87,87,87,87,87,87,87,87,87,87,87,87,87,0,0,87,0,0,87,2,1
1,2,87,0,0,0,0,87,87,87,87,87,87,87,87,87,87,87,87,87,87,87,87,87,87,87,0,0,0,0,0,87,2,1
1,2,87,87,0,0,0,87,87,87,87,87,87,87,87,87,87,87,87,87,87,87,87,87,87,87,87,0,0,0,87,87,2,1
1,1,2,87,87,87,87,87,2,2,2,2,2,2,2,2,2,2,2,2,2,2,2,2,2,2,87,87,87,87,87,2,1,1
1,1,1,2,2,2,0,2,0,0,0,0,0,0,0,0,0,0,0,0,0,0,0,0,0,0,2,0,2,2,2,1,1,1
1,1,1,1,0,0,0,0,0,0,0,0,0,0,0,0,0,0,0,0,0,0,0,0,0,0,0,0,0,0,1,1,1,1
1,1,1,1,0,0,0,0,0,0,0,0,0,0,0,0,0,0,0,0,0,0,0,0,0,0,0,0,0,0,1,1,1,1
1,1,1,1,0,0,0,0,0,0,0,0,0,0,0,0,0,0,0,0,0,0,0,0,0,0,0,0,0,0,1,1,1,1
1,1,1,1,0,0,0,0,0,0,0,0,0,0,0,0,0,0,0,0,0,0,0,0,0,0,0,0,0,0,1,1,1,1
1,1,1,1,0,0,0,0,0,0,0,0,0,0,0,0,0,0,0,0,0,0,0,0,0,0,0,0,0,0,1,1,1,1
1,1,1,1,0,0,0,0,0,0,0,0,0,0,0,0,0,0,0,0,0,0,0,0,0,0,0,0,0,0,1,1,1,1
1,1,1,1,0,0,0,0,0,0,0,0,0,0,0,0,0,0,0,0,0,0,0,0,0,0,0,0,0,0,1,1,1,1
1,1,1,1,0,0,0,0,0,0,0,0,0,0,0,0,0,0,0,0,0,0,0,0,0,0,0,0,0,0,1,1,1,1
1,1,1,1,0,0,0,0,0,0,0,0,0,0,0,0,0,0,0,0,0,0,0,0,0,0,0,0,0,0,1,1,1,1
1,1,1,1,0,0,0,0,0,0,0,0,0,0,0,0,0,0,0,0,0,0,0,0,0,0,0,0,0,0,1,1,1,1
1,1,1,1,0,0,0,0,0,0,0,0,0,0,0,0,0,0,0,0,0,0,0,0,0,0,0,0,0,0,1,1,1,1
1,1,1,1,0,0,0,0,0,0,0,0,0,0,0,0,0,0,0,0,0,0,0,0,0,0,0,0,0,0,1,1,1,1
1,1,1,1,0,0,0,0,0,0,0,0,0,0,0,0,0,0,0,0,0,0,0,0,0,0,0,0,0,0,1,1,1,1
1,1,1,1,0,0,0,0,0,0,0,0,0,0,0,0,0,0,0,0,0,0,0,0,0,0,0,0,0,0,1,1,1,1
1,1,1,1,0,0,0,0,0,0,0,0,0,0,0,0,0,0,0,0,0,0,0,0,0,0,0,0,0,0,1,1,1,1
1,1,1,1,0,0,0,0,0,0,0,0,0,0,0,0,0,0,0,0,0,0,0,0,0,0,0,0,0,0,1,1,1,1
1,1,1,1,0,0,0,0,0,0,0,0,0,0,0,0,0,0,0,0,0,0,0,0,0,0,0,0,0,0,1,1,1,1
1,1,1,1,0,0,0,0,0,0,0,0,0,0,0,0,0,0,0,0,0,0,0,0,0,0,0,0,0,0,1,1,1,1
1,1,1,2,2,2,0,2,0,0,0,0,0,0,0,0,0,0,0,0,0,0,0,0,0,0,2,0,2,2,2,1,1,1
1,1,2,87,87,87,87,87,2,2,2,2,2,2,2,2,2,2,2,2,2,2,2,2,2,2,87,87,87,87,87,2,1,1
1,2,87,87,0,0,0,87,87,87,87,87,87,87,87,87,87,87,87,87,87,87,87,87,87,87,87,0,0,0,87,87,2,1
