# Kujaku's Fountain #3
# Created by Ruins mod version 14.3 Ingame Parser
# authoring Player: Kujaku10
# 12 Dec 2014
# Last Updated 23 Mar 2016
# Updated to MC 1.11: 13 Jan 2017
# Verified for MC 1.12: 23 Jun 2017
# Updated to MC 1.12.1: 10 Sep 2017

# Last Updated: 6 Apr 2018

biomestospawnin=autumn hills,autumn woods,autumnal_woods,cherry blossom grove,cherry_blossom_grove,desert,enchanted forest,enchanted_forest,green hills,forest,foresthills,forest_hills,jungle,jungle_edge,junglehills,jungle_hills,magical forest,mini_jungle,mining_biome,mutated_plains,mystic grove,ominous woods,pasture,plains,prairie,sacred springs,sunflower plains,woodland,xeric shrubland,xeric_shrubland

weight=1
embed_into_distance=2
acceptable_target_blocks=

uniqueMinDistance=1000
spawnMinDistance=500

unacceptable_target_blocks=flowing_water,water,flowing_lava,lava,cloud,Natura:Cloud,slime_congealed,slime_dirt,slime_grass,command_block,planks,planks2,concrete,cobblestone,stonebrick,brick_block,glass,torch,oak_stairs,stone_stairs,brick_stairs,stone_brick_stairs,nether_brick_stairs,sandstone_stairs,spruce_stairs,birch_stairs,jungle_stairs,quartz_stairs,acacia_stairs,dark_oak_stairs,cobblestone_wall,stone_slab,double_stone_slab,stone_slab2,wooden_slab,double_wooden_slab,nether_brick,fence

dimensions=7,11,11
allowable_overhang=0
max_leveling=2
leveling_buffer=-1
preserve_water=0
preserve_lava=0
preserve_plant=1

rule1=0,100,preserveBlock
rule2=0,100,minecraft:grass-0
rule3=0,100,minecraft:stonebrick-0
rule4=0,100,minecraft:glowstone-0
rule5=0,100,minecraft:dirt-0
rule6=0,100,minecraft:red_flower-1
rule7=0,100,minecraft:red_flower-2
rule8=0,100,minecraft:red_flower-0
rule9=0,100,minecraft:red_flower-6
rule10=0,100,minecraft:stone_slab-5
rule11=0,100,minecraft:stonebrick-3
rule12=0,100,minecraft:red_flower-7
rule13=0,100,minecraft:water-1
rule14=0,100,minecraft:water-9
rule15=0,100,minecraft:water-2
rule16=0,100,minecraft:stone_brick_stairs-4
rule17=0,100,minecraft:stone_brick_stairs-6
rule18=0,100,minecraft:stone_brick_stairs-7
rule19=0,100,minecraft:stone_brick_stairs-5
rule20=0,100,minecraft:water-0

layer
1,1,2,2,2,2,2,2,2,1,1
1,2,2,2,2,2,2,2,2,2,1
2,2,2,2,3,3,3,2,2,2,2
2,2,2,3,3,3,3,3,2,2,2
2,2,3,3,3,4,3,3,3,2,2
2,2,3,3,4,3,4,3,3,2,2
2,2,3,3,3,4,3,3,3,2,2
2,2,2,3,3,3,3,3,2,2,2
2,2,2,2,3,3,3,2,2,5,2
1,2,2,2,2,2,2,2,2,2,1
1,1,2,2,2,2,2,2,2,1,1
endlayer


layer
1,1,1,2,2,2,2,2,1,1,1
1,1,2,2,2,2,2,2,2,1,1
1,2,2,2,3,3,3,2,2,2,1
2,2,2,3,3,3,3,3,2,2,2
2,2,3,3,3,4,3,3,3,2,2
2,2,3,3,4,3,4,3,3,2,2
2,2,3,3,3,4,3,3,3,2,2
2,2,2,3,3,3,3,3,2,2,2
1,2,2,2,3,3,3,2,2,5,1
1,1,2,2,2,2,2,2,2,1,1
1,1,1,2,2,2,2,2,1,1,1
endlayer

layer
1,1,1,0,0,0,0,0,1,1,1
1,1,0,0,8,7,6,0,0,1,1
1,0,0,9,10,11,10,9,0,0,1
0,0,12,10,13,14,13,10,12,0,0
0,7,10,13,15,13,15,13,10,7,0
0,6,11,14,13,3,13,14,11,6,0
0,8,10,13,15,13,15,13,10,8,0
0,0,12,10,13,14,13,10,9,0,0
1,0,0,9,10,11,10,12,0,0,1
1,1,0,0,7,8,6,0,0,1,1
1,1,1,0,0,0,0,0,1,1,1
endlayer

layer
1,1,0,0,0,0,0,0,0,1,1
1,0,0,0,0,0,0,0,0,0,1
0,0,0,0,0,0,0,0,0,0,0
0,0,0,0,0,14,0,0,0,0,0
0,0,0,0,0,0,0,0,0,0,0
0,0,0,14,0,3,0,14,0,0,0
0,0,0,0,0,0,0,0,0,0,0
0,0,0,0,0,14,0,0,0,0,0
0,0,0,0,0,0,0,0,0,0,0
1,0,0,0,0,0,0,0,0,0,1
1,1,0,0,0,0,0,0,0,1,1
endlayer

layer
1,0,0,0,0,0,0,0,0,0,1
0,0,0,0,0,0,0,0,0,0,0
0,0,0,0,0,0,0,0,0,0,0
0,0,0,0,0,14,0,0,0,0,0
0,0,0,0,0,16,0,0,0,0,0
0,0,0,14,18,3,17,14,0,0,0
0,0,0,0,0,19,0,0,0,0,0
0,0,0,0,0,14,0,0,0,0,0
0,0,0,0,0,0,0,0,0,0,0
0,0,0,0,0,0,0,0,0,0,0
1,0,0,0,0,0,0,0,0,0,1
endlayer

layer
1,0,0,0,0,0,0,0,0,0,1
0,0,0,0,0,0,0,0,0,0,0
0,0,0,0,0,0,0,0,0,0,0
0,0,0,0,0,13,0,0,0,0,0
0,0,0,0,10,20,10,0,0,0,0
0,0,0,13,20,3,20,13,0,0,0
0,0,0,0,10,20,10,0,0,0,0
0,0,0,0,0,13,0,0,0,0,0
0,0,0,0,0,0,0,0,0,0,0
0,0,0,0,0,0,0,0,0,0,0
1,0,0,0,0,0,0,0,0,0,1
endlayer

layer
0,0,0,0,0,0,0,0,0,0,0
0,0,0,0,0,0,0,0,0,0,0
0,0,0,0,0,0,0,0,0,0,0
0,0,0,0,0,0,0,0,0,0,0
0,0,0,0,0,0,0,0,0,0,0
0,0,0,0,0,11,0,0,0,0,0
0,0,0,0,0,0,0,0,0,0,0
0,0,0,0,0,0,0,0,0,0,0
0,0,0,0,0,0,0,0,0,0,0
0,0,0,0,0,0,0,0,0,0,0
0,0,0,0,0,0,0,0,0,0,0
endlayer

