# Chisel Glyph Tomb
# Created by Ruins mod version 17.1 Ingame Parser
# authoring Player: Jordan_Greywolf
# Made for MC 1.12 with Chisel: 28 Jun 2018

biomesToSpawnIn=desert,deserthills,desert m,oasis,dunes,desert oil field,desert_oil_field,rwg_hotdesert,rwg_oasis,desert_hills,mutated_desert

weight=1
embed_into_distance=25
acceptable_target_blocks=

unacceptable_target_blocks=command_block,cloud,slime_dirt,slime_grass,slime_congealed

dimensions=15,16,16

allowable_overhang=0
max_leveling=16
leveling_buffer=-1
preserve_water=0
preserve_lava=0

# Smooth Sandstone
rule1=0,100,minecraft:sandstone-2

# Sandstone - Encased Bricks
rule2=0,100,chisel:sandstoneyellow-4

# Randomized Glyphs
rule3=0,100,chisel:sandstone-scribbles-0,chisel:sandstone-scribbles-1,chisel:sandstone-scribbles-2,chisel:sandstone-scribbles-3,chisel:sandstone-scribbles-4,chisel:sandstone-scribbles-5,chisel:sandstone-scribbles-6,chisel:sandstone-scribbles-7,chisel:sandstone-scribbles-8,chisel:sandstone-scribbles-9,chisel:sandstone-scribbles-10,chisel:sandstone-scribbles-11,chisel:sandstone-scribbles-12,chisel:sandstone-scribbles-13,chisel:sandstone-scribbles-14,chisel:sandstone-scribbles-15

# Trap!
rule4=0,100,minecraft:tnt

rule5=0,100,minecraft:sandstone_stairs-2
rule6=0,100,minecraft:sandstone_stairs-0
rule7=0,100,minecraft:sandstone_stairs-3
rule8=0,100,minecraft:sandstone_stairs-1
rule9=0,100,minecraft:sandstone_stairs-6
rule10=0,100,minecraft:sandstone_stairs-4

rule11=0,100,ChestGenHook:chests/desert_pyramid:5-4
rule12=0,100,minecraft:sandstone_stairs-7

# Trapped Chest with Chisel Blocks
rule13=0,100,IInventory;minecraft:trapped_chest;chisel:sandstone-scribbles#64#2#0+chisel:sandstone-scribbles#64#0#1+chisel:sandstone-scribbles#64#1#2+chisel:sandstone-scribbles#64#3#3+chisel:sandstone-scribbles#64#4#4+chisel:sandstone-scribbles#64#5#5+chisel:sandstone-scribbles#64#6#6+chisel:sandstone-scribbles#64#7#7+chisel:sandstone-scribbles#64#8#8+chisel:sandstone-scribbles#64#9#9+chisel:sandstone-scribbles#64#10#10+chisel:sandstone-scribbles#64#11#11+chisel:sandstone-scribbles#64#12#12+chisel:sandstone-scribbles#64#13#13+chisel:sandstone-scribbles#64#14#14+chisel:sandstone-scribbles#64#15#15+minecraft:sandstone#64#2#16+chisel:hardenedclay2#64#4#17-5

rule14=0,100,IInventory;minecraft:trapped_chest;chisel:sandstoneyellow#64#4#0-5

rule15=0,100,minecraft:sandstone_stairs-5

# Vault Top
rule16=0,100,minecraft:stone_slab-1

# Column Tops
rule17=0,100,chisel:hardenedclay2-4

rule18=0,100,preserveBlock

# Blue Ceiling Blocks
rule19=0,100,minecraft:stained_hardened_clay-11

layer
1,1,1,1,1,1,1,1,1,1,1,1,1,1,1,1
1,1,1,1,1,1,1,1,1,1,1,1,1,1,1,1
1,1,1,1,1,1,1,1,1,1,1,1,1,1,1,1
1,1,1,1,1,1,1,1,1,1,1,1,1,1,1,1
1,1,1,1,1,1,1,1,1,1,1,1,1,1,1,1
1,1,1,1,1,1,1,1,1,1,1,1,1,1,1,1
1,1,1,1,1,1,1,1,1,1,1,1,1,1,1,1
1,1,1,1,1,1,1,1,1,1,1,1,1,1,1,1
1,1,1,1,1,1,1,1,1,1,1,1,1,1,1,1
1,1,1,1,1,1,1,1,1,1,1,1,1,1,1,1
1,1,1,1,1,1,1,1,1,1,1,1,1,1,1,1
1,1,1,1,1,1,1,1,1,1,1,1,1,1,1,1
1,1,1,1,1,1,1,1,1,1,1,1,1,1,1,1
1,1,1,1,1,1,1,1,1,1,1,1,1,1,1,1
1,1,1,1,1,1,1,1,1,1,1,1,1,1,1,1
1,1,1,1,1,1,1,1,1,1,1,1,1,1,1,1
endlayer

layer
1,1,1,1,1,1,1,1,1,1,1,1,1,1,1,1
1,1,1,1,1,1,1,1,1,1,1,1,1,1,1,1
1,1,1,1,1,1,1,1,1,1,1,1,1,1,1,1
1,1,1,1,1,1,1,1,1,1,1,1,1,1,1,1
1,1,1,1,2,2,2,2,2,2,2,2,1,1,1,1
1,1,1,1,2,3,3,3,3,3,3,2,1,1,1,1
1,1,1,1,2,3,3,3,3,3,3,2,1,1,1,1
1,1,1,1,2,3,3,4,4,3,3,2,1,1,1,1
1,1,1,1,2,3,3,4,4,3,3,2,1,1,1,1
1,1,1,1,2,3,3,3,3,3,3,2,1,1,1,1
1,1,1,1,2,3,3,3,3,3,3,2,1,1,1,1
1,1,1,1,2,2,2,2,2,2,2,2,1,1,1,1
1,1,1,1,1,1,1,1,1,1,1,1,1,1,1,1
1,1,1,1,1,1,1,1,1,1,1,1,1,1,1,1
1,1,1,1,1,1,1,1,1,1,1,1,1,1,1,1
1,1,1,1,1,1,1,1,1,1,1,1,1,1,1,1
endlayer

layer
1,1,1,1,1,1,1,0,0,1,1,1,1,1,1,1
1,0,0,0,0,0,0,0,0,0,0,0,0,0,0,1
1,0,1,0,1,0,1,0,0,1,0,1,0,1,0,1
1,0,0,0,0,0,0,0,0,0,0,0,0,0,0,1
1,0,1,0,0,0,0,0,0,0,0,0,0,1,0,1
1,0,0,0,0,0,0,0,0,0,0,0,0,0,0,1
1,0,1,0,0,0,6,6,6,5,0,0,0,1,0,1
0,0,0,0,0,0,7,3,3,5,0,0,0,0,0,0
0,0,0,0,0,0,7,3,3,5,0,0,0,0,0,0
1,0,1,0,0,0,8,8,8,8,0,0,0,1,0,1
1,0,0,0,0,0,0,0,0,0,0,0,0,0,0,1
1,0,1,0,0,0,0,0,0,0,0,0,0,1,0,1
1,0,0,0,0,0,0,0,0,0,0,0,0,0,0,1
1,0,1,0,1,0,1,0,0,1,0,1,0,1,0,1
1,0,0,0,0,0,0,0,0,0,0,0,0,0,0,1
1,1,1,1,1,1,1,0,0,1,1,1,1,1,1,1
endlayer

layer
1,1,3,3,3,3,1,0,0,1,3,3,3,3,1,1
1,0,0,0,0,0,0,0,0,0,0,0,0,0,0,1
3,0,3,0,3,0,3,0,0,3,0,3,0,3,0,3
3,0,0,0,0,0,0,0,0,0,0,0,0,0,0,3
3,0,3,0,0,0,0,0,0,0,0,0,0,3,0,3
3,0,0,0,0,0,0,0,0,0,0,0,0,0,0,3
1,0,3,0,0,0,10,10,10,9,0,0,0,3,0,1
0,0,0,0,0,0,12,11,11,9,0,0,0,0,0,0
0,0,0,0,0,0,12,14,13,9,0,0,0,0,0,0
1,0,3,0,0,0,12,15,15,15,0,0,0,3,0,1
3,0,0,0,0,0,0,0,0,0,0,0,0,0,0,3
3,0,3,0,0,0,0,0,0,0,0,0,0,3,0,3
3,0,0,0,0,0,0,0,0,0,0,0,0,0,0,3
3,0,3,0,3,0,3,0,0,3,0,3,0,3,0,3
1,0,0,0,0,0,0,0,0,0,0,0,0,0,0,1
1,1,3,3,3,3,1,0,0,1,3,3,3,3,1,1
endlayer

layer
1,1,3,3,3,3,1,0,0,1,3,3,3,3,1,1
1,0,0,0,0,0,0,0,0,0,0,0,0,0,0,1
3,0,3,0,3,0,3,0,0,3,0,3,0,3,0,3
3,0,0,0,0,0,0,0,0,0,0,0,0,0,0,3
3,0,3,0,0,0,0,0,0,0,0,0,0,3,0,3
3,0,0,0,0,0,0,0,0,0,0,0,0,0,0,3
1,0,3,0,0,0,3,3,3,3,0,0,0,3,0,1
0,0,0,0,0,0,3,3,3,3,0,0,0,0,0,0
0,0,0,0,0,0,3,3,3,3,0,0,0,0,0,0
1,0,3,0,0,0,3,3,3,3,0,0,0,3,0,1
3,0,0,0,0,0,0,0,0,0,0,0,0,0,0,3
3,0,3,0,0,0,0,0,0,0,0,0,0,3,0,3
3,0,0,0,0,0,0,0,0,0,0,0,0,0,0,3
3,0,3,0,3,0,3,0,0,3,0,3,0,3,0,3
1,0,0,0,0,0,0,0,0,0,0,0,0,0,0,1
1,1,3,3,3,3,1,0,0,1,3,3,3,3,1,1
endlayer

layer
1,1,3,3,3,3,1,0,0,1,3,3,3,3,1,1
1,0,0,0,0,0,0,0,0,0,0,0,0,0,0,1
3,0,3,0,3,0,3,0,0,3,0,3,0,3,0,3
3,0,0,0,0,0,0,0,0,0,0,0,0,0,0,3
3,0,3,0,0,0,0,0,0,0,0,0,0,3,0,3
3,0,0,0,0,0,0,0,0,0,0,0,0,0,0,3
1,0,3,0,0,0,16,16,16,16,0,0,0,3,0,1
0,0,0,0,0,0,16,16,16,16,0,0,0,0,0,0
0,0,0,0,0,0,16,16,16,16,0,0,0,0,0,0
1,0,3,0,0,0,16,16,16,16,0,0,0,3,0,1
3,0,0,0,0,0,0,0,0,0,0,0,0,0,0,3
3,0,3,0,0,0,0,0,0,0,0,0,0,3,0,3
3,0,0,0,0,0,0,0,0,0,0,0,0,0,0,3
3,0,3,0,3,0,3,0,0,3,0,3,0,3,0,3
1,0,0,0,0,0,0,0,0,0,0,0,0,0,0,1
1,1,3,3,3,3,1,0,0,1,3,3,3,3,1,1
endlayer

layer
1,1,1,1,1,1,1,1,1,1,1,1,1,1,1,1
1,0,0,0,0,0,0,0,0,0,0,0,0,0,0,1
1,0,17,0,17,0,17,0,0,17,0,17,0,17,0,1
1,0,0,0,0,0,0,0,0,0,0,0,0,0,0,1
1,0,17,0,0,0,0,0,0,0,0,0,0,17,0,1
1,0,0,0,0,0,0,0,0,0,0,0,0,0,0,1
1,0,17,0,0,0,0,0,0,0,0,0,0,17,0,1
1,0,0,0,0,0,0,0,0,0,0,0,0,0,0,1
1,0,0,0,0,0,0,0,0,0,0,0,0,0,0,1
1,0,17,0,0,0,0,0,0,0,0,0,0,17,0,1
1,0,0,0,0,0,0,0,0,0,0,0,0,0,0,1
1,0,17,0,0,0,0,0,0,0,0,0,0,17,0,1
1,0,0,0,0,0,0,0,0,0,0,0,0,0,0,1
1,0,17,0,17,0,17,0,0,17,0,17,0,17,0,1
1,0,0,0,0,0,0,0,0,0,0,0,0,0,0,1
1,1,1,1,1,1,1,1,1,1,1,1,1,1,1,1
endlayer

layer
1,1,1,1,1,1,1,1,1,1,1,1,1,1,1,1
1,1,1,1,1,1,1,1,1,1,1,1,1,1,1,1
1,1,1,1,1,1,1,1,1,1,1,1,1,1,1,1
1,1,1,1,1,1,1,1,1,1,1,1,1,1,1,1
1,1,1,1,15,15,15,15,15,15,15,12,1,1,1,1
1,1,1,1,9,0,0,0,0,0,0,12,1,1,1,1
1,1,1,1,9,0,0,0,0,0,0,12,1,1,1,1
1,1,1,1,9,0,0,0,0,0,0,12,1,1,1,1
1,1,1,1,9,0,0,0,0,0,0,12,1,1,1,1
1,1,1,1,9,0,0,0,0,0,0,12,1,1,1,1
1,1,1,1,9,0,0,0,0,0,0,12,1,1,1,1
1,1,1,1,9,10,10,10,10,10,10,10,1,1,1,1
1,1,1,1,1,1,1,1,1,1,1,1,1,1,1,1
1,1,1,1,1,1,1,1,1,1,1,1,1,1,1,1
1,1,1,1,1,1,1,1,1,1,1,1,1,1,1,1
1,1,1,1,1,1,1,1,1,1,1,1,1,1,1,1
endlayer

layer
18,18,18,18,18,18,18,18,18,18,18,18,18,18,18,18
18,1,1,1,1,1,1,1,1,1,1,1,1,1,1,18
18,1,1,1,1,1,1,1,1,1,1,1,1,1,1,18
18,1,1,19,19,19,19,19,19,19,19,19,19,1,1,18
18,1,1,19,19,19,19,19,19,19,19,19,19,1,1,18
18,1,1,19,19,0,0,0,0,0,0,19,19,1,1,18
18,1,1,19,19,0,0,0,0,0,0,19,19,1,1,18
18,1,1,19,19,0,0,0,0,0,0,19,19,1,1,18
18,1,1,19,19,0,0,0,0,0,0,19,19,1,1,18
18,1,1,19,19,0,0,0,0,0,0,19,19,1,1,18
18,1,1,19,19,0,0,0,0,0,0,19,19,1,1,18
18,1,1,19,19,19,19,19,19,19,19,19,19,1,1,18
18,1,1,19,19,19,19,19,19,19,19,19,19,1,1,18
18,1,1,1,1,1,1,1,1,1,1,1,1,1,1,18
18,1,1,1,1,1,1,1,1,1,1,1,1,1,1,18
18,18,18,18,18,18,18,18,18,18,18,18,18,18,18,18
endlayer

layer
18,18,18,18,18,18,18,18,18,18,18,18,18,18,18,18
18,18,18,18,18,18,18,18,18,18,18,18,18,18,18,18
18,18,1,1,1,1,1,1,1,1,1,1,1,1,18,18
18,18,1,1,1,1,1,1,1,1,1,1,1,1,18,18
18,18,1,1,19,19,19,19,19,19,19,19,1,1,18,18
18,18,1,1,19,19,19,19,19,19,19,19,1,1,18,18
18,18,1,1,19,19,0,0,0,0,19,19,1,1,18,18
18,18,1,1,19,19,0,0,0,0,19,19,1,1,18,18
18,18,1,1,19,19,0,0,0,0,19,19,1,1,18,18
18,18,1,1,19,19,0,0,0,0,19,19,1,1,18,18
18,18,1,1,19,19,19,19,19,19,19,19,1,1,18,18
18,18,1,1,19,19,19,19,19,19,19,19,1,1,18,18
18,18,1,1,1,1,1,1,1,1,1,1,1,1,18,18
18,18,1,1,1,1,1,1,1,1,1,1,1,1,18,18
18,18,18,18,18,18,18,18,18,18,18,18,18,18,18,18
18,18,18,18,18,18,18,18,18,18,18,18,18,18,18,18
endlayer

layer
18,18,18,18,18,18,18,18,18,18,18,18,18,18,18,18
18,18,18,18,18,18,18,18,18,18,18,18,18,18,18,18
18,18,18,18,18,18,18,18,18,18,18,18,18,18,18,18
18,18,18,1,1,1,1,1,1,1,1,1,1,18,18,18
18,18,18,1,1,1,1,1,1,1,1,1,1,18,18,18
18,18,18,1,1,19,19,19,19,19,19,1,1,18,18,18
18,18,18,1,1,19,19,19,19,19,19,1,1,18,18,18
18,18,18,1,1,19,19,0,0,19,19,1,1,18,18,18
18,18,18,1,1,19,19,0,0,19,19,1,1,18,18,18
18,18,18,1,1,19,19,19,19,19,19,1,1,18,18,18
18,18,18,1,1,19,19,19,19,19,19,1,1,18,18,18
18,18,18,1,1,1,1,1,1,1,1,1,1,18,18,18
18,18,18,1,1,1,1,1,1,1,1,1,1,18,18,18
18,18,18,18,18,18,18,18,18,18,18,18,18,18,18,18
18,18,18,18,18,18,18,18,18,18,18,18,18,18,18,18
18,18,18,18,18,18,18,18,18,18,18,18,18,18,18,18
endlayer

layer
18,18,18,18,18,18,18,18,18,18,18,18,18,18,18,18
18,18,18,18,18,18,18,18,18,18,18,18,18,18,18,18
18,18,18,18,18,18,18,18,18,18,18,18,18,18,18,18
18,18,18,18,18,18,18,18,18,18,18,18,18,18,18,18
18,18,18,18,1,1,1,1,1,1,1,1,18,18,18,18
18,18,18,18,1,1,1,1,1,1,1,1,18,18,18,18
18,18,18,18,1,1,19,19,19,19,1,1,18,18,18,18
18,18,18,18,1,1,19,19,19,19,1,1,18,18,18,18
18,18,18,18,1,1,19,19,19,19,1,1,18,18,18,18
18,18,18,18,1,1,19,19,19,19,1,1,18,18,18,18
18,18,18,18,1,1,1,1,1,1,1,1,18,18,18,18
18,18,18,18,1,1,1,1,1,1,1,1,18,18,18,18
18,18,18,18,18,18,18,18,18,18,18,18,18,18,18,18
18,18,18,18,18,18,18,18,18,18,18,18,18,18,18,18
18,18,18,18,18,18,18,18,18,18,18,18,18,18,18,18
18,18,18,18,18,18,18,18,18,18,18,18,18,18,18,18
endlayer

layer
18,18,18,18,18,18,18,18,18,18,18,18,18,18,18,18
18,18,18,18,18,18,18,18,18,18,18,18,18,18,18,18
18,18,18,18,18,18,18,18,18,18,18,18,18,18,18,18
18,18,18,18,18,18,18,18,18,18,18,18,18,18,18,18
18,18,18,18,18,18,18,18,18,18,18,18,18,18,18,18
18,18,18,18,18,1,1,1,1,1,1,18,18,18,18,18
18,18,18,18,18,1,1,1,1,1,1,18,18,18,18,18
18,18,18,18,18,1,1,19,19,1,1,18,18,18,18,18
18,18,18,18,18,1,1,19,19,1,1,18,18,18,18,18
18,18,18,18,18,1,1,1,1,1,1,18,18,18,18,18
18,18,18,18,18,1,1,1,1,1,1,18,18,18,18,18
18,18,18,18,18,18,18,18,18,18,18,18,18,18,18,18
18,18,18,18,18,18,18,18,18,18,18,18,18,18,18,18
18,18,18,18,18,18,18,18,18,18,18,18,18,18,18,18
18,18,18,18,18,18,18,18,18,18,18,18,18,18,18,18
18,18,18,18,18,18,18,18,18,18,18,18,18,18,18,18
endlayer

layer
18,18,18,18,18,18,18,18,18,18,18,18,18,18,18,18
18,18,18,18,18,18,18,18,18,18,18,18,18,18,18,18
18,18,18,18,18,18,18,18,18,18,18,18,18,18,18,18
18,18,18,18,18,18,18,18,18,18,18,18,18,18,18,18
18,18,18,18,18,18,18,18,18,18,18,18,18,18,18,18
18,18,18,18,18,18,18,18,18,18,18,18,18,18,18,18
18,18,18,18,18,18,1,1,1,1,18,18,18,18,18,18
18,18,18,18,18,18,1,1,1,1,18,18,18,18,18,18
18,18,18,18,18,18,1,1,1,1,18,18,18,18,18,18
18,18,18,18,18,18,1,1,1,1,18,18,18,18,18,18
18,18,18,18,18,18,18,18,18,18,18,18,18,18,18,18
18,18,18,18,18,18,18,18,18,18,18,18,18,18,18,18
18,18,18,18,18,18,18,18,18,18,18,18,18,18,18,18
18,18,18,18,18,18,18,18,18,18,18,18,18,18,18,18
18,18,18,18,18,18,18,18,18,18,18,18,18,18,18,18
18,18,18,18,18,18,18,18,18,18,18,18,18,18,18,18
endlayer

layer
18,18,18,18,18,18,18,18,18,18,18,18,18,18,18,18
18,18,18,18,18,18,18,18,18,18,18,18,18,18,18,18
18,18,18,18,18,18,18,18,18,18,18,18,18,18,18,18
18,18,18,18,18,18,18,18,18,18,18,18,18,18,18,18
18,18,18,18,18,18,18,18,18,18,18,18,18,18,18,18
18,18,18,18,18,18,18,18,18,18,18,18,18,18,18,18
18,18,18,18,18,18,18,18,18,18,18,18,18,18,18,18
18,18,18,18,18,18,18,1,1,18,18,18,18,18,18,18
18,18,18,18,18,18,18,1,1,18,18,18,18,18,18,18
18,18,18,18,18,18,18,18,18,18,18,18,18,18,18,18
18,18,18,18,18,18,18,18,18,18,18,18,18,18,18,18
18,18,18,18,18,18,18,18,18,18,18,18,18,18,18,18
18,18,18,18,18,18,18,18,18,18,18,18,18,18,18,18
18,18,18,18,18,18,18,18,18,18,18,18,18,18,18,18
18,18,18,18,18,18,18,18,18,18,18,18,18,18,18,18
18,18,18,18,18,18,18,18,18,18,18,18,18,18,18,18
endlayer

