# AirshipBlue
# 13 Mar 2014; updated to MC 1.7.10, 11 Oct 2014
# Created by Ruins mod version 12.3 Ingame Parser
# authoring Player: Jordan_Greywolf
# Last Updated: 25 Mar 2016
# Updated to MC 1.9: 26 Apr 2016
# Updated for MC 1.11: 13 Jan 2017
# Verified for MC 1.12: 21 Jun 2017
# Updated to MC 1.12.1: 10 Sep 2017

biomesToSpawnIn=dungeon,kelp forest,kelp_forest,ocean,ocean oil field,ocean_oil_field,oceanic abyss,oceanic_abyss,coral reef,coral_reef,deep ocean,deep_ocean,frozen ocean,frozen_ocean,sky,the end,rwg_oceantemperate,the_end

weight=1
embed_into_distance=-50

uniqueMinDistance=1000
spawnMinDistance=1000



unacceptable_target_blocks=command_block

dimensions=17,13,26
allowable_overhang=9999
max_cut_in=0
cut_in_buffer=0
max_leveling=10
leveling_buffer=-1
preserve_water=0
preserve_lava=0
preserve_plants=1

rule1=0,100,minecraft:planks-1
rule2=0,100,minecraft:fence-0
rule3=0,100,minecraft:oak_stairs-4
rule4=0,100,minecraft:spruce_stairs-4
rule5=0,100,minecraft:oak_stairs-6
rule6=0,100,minecraft:wooden_slab-0
rule7=0,100,minecraft:oak_stairs-7
rule8=0,100,minecraft:spruce_stairs-7
rule9=0,100,minecraft:glowstone-0
rule10=0,100,minecraft:oak_stairs-5
rule11=0,100,minecraft:spruce_stairs-5
rule12=0,100,minecraft:planks-0
rule13=0,100,minecraft:oak_stairs-1
rule14=0,100,minecraft:bookshelf-0
rule15=0,100,ChestGenHook:chests/simple_dungeon:3-5
rule16=0,100,minecraft:bed-0
rule17=0,100,minecraft:bed-8
rule18=0,100,minecraft:wooden_slab-9
rule19=0,100,minecraft:spruce_stairs-3
rule20=0,100,minecraft:crafting_table-0
rule21=0,100,ChestGenHook:chests/simple_dungeon:3-4
rule22=0,100,minecraft:oak_stairs-0
rule23=0,100,minecraft:wooden_slab-1
rule24=0,100,minecraft:dispenser-3
rule25=0,100,minecraft:trapdoor-9
rule26=0,100,minecraft:trapdoor-8
rule27=0,100,minecraft:iron_bars-0

# Random Cargo
rule28=0,100,minecraft:hay_block-0,minecraft:melon_block,minecraft:pumpkin,minecraft:noteblock

rule29=0,100,minecraft:spruce_stairs-2
rule30=0,100,IInventory;minecraft:furnace;minecraft:coal#10#1#1-3
rule31=0,100,minecraft:torch-5
rule32=0,100,minecraft:wool-11
rule33=0,100,minecraft:wool-3
rule34=0,100,MobSpawner:Creeper


# 1
layer
0,0,0,0,0,0,0,0,0,0,0,0,0,0,0,0,0,0,0,0,0,0,0,0,0,0
0,0,0,0,0,0,0,0,0,0,0,0,0,0,0,0,0,0,0,0,0,0,0,0,0,0
0,0,0,0,0,0,0,0,0,0,0,0,0,0,0,0,0,0,0,0,0,0,0,0,0,0
0,0,0,0,0,0,0,0,0,0,0,0,0,0,0,0,0,0,0,0,0,0,0,0,0,0
0,0,0,0,0,0,0,0,0,0,0,0,0,0,0,0,0,0,0,0,0,0,0,0,0,0
0,0,0,0,0,0,0,0,0,0,0,0,0,0,0,0,0,0,0,0,0,0,0,0,0,0
0,0,0,0,0,0,0,0,0,0,0,1,1,1,1,1,2,1,1,0,0,0,0,0,0,0
0,0,0,0,0,0,0,0,0,0,0,0,0,0,0,0,0,0,0,0,0,0,0,0,0,0
0,0,0,0,0,0,0,0,0,0,0,0,0,0,0,0,0,0,0,0,0,0,0,0,0,0
0,0,0,0,0,0,0,0,0,0,0,0,0,0,0,0,0,0,0,0,0,0,0,0,0,0
0,0,0,0,0,0,0,0,0,0,0,0,0,0,0,0,0,0,0,0,0,0,0,0,0,0
0,0,0,0,0,0,0,0,0,0,0,0,0,0,0,0,0,0,0,0,0,0,0,0,0,0
0,0,0,0,0,0,0,0,0,0,0,0,0,0,0,0,0,0,0,0,0,0,0,0,0,0
endlayer

# 2
layer
0,0,0,0,0,0,0,0,0,0,0,0,0,0,0,0,0,0,0,0,0,0,0,0,0,0
0,0,0,0,0,0,0,0,0,0,0,0,0,0,0,0,0,0,0,0,0,0,0,0,0,0
0,0,0,0,0,0,0,0,0,0,0,0,0,0,0,0,0,0,0,0,0,0,0,0,0,0
0,0,0,0,0,0,0,0,0,0,0,0,0,0,0,0,0,0,0,0,0,0,0,0,0,0
0,0,0,0,0,0,0,0,0,0,0,4,3,3,4,3,0,0,0,0,0,0,0,0,0,0
0,0,0,0,0,0,0,0,0,0,7,1,6,6,1,6,5,0,0,0,0,0,0,0,0,0
0,0,0,9,0,0,0,0,0,8,1,1,1,1,1,1,2,1,1,0,0,0,0,0,0,0
0,0,0,0,0,0,0,0,0,0,7,1,6,6,1,6,5,0,0,0,0,0,0,0,0,0
0,0,0,0,0,0,0,0,0,0,0,11,10,10,11,10,0,0,0,0,0,0,0,0,0,0
0,0,0,0,0,0,0,0,0,0,0,0,0,0,0,0,0,0,0,0,0,0,0,0,0,0
0,0,0,0,0,0,0,0,0,0,0,0,0,0,0,0,0,0,0,0,0,0,0,0,0,0
0,0,0,0,0,0,0,0,0,0,0,0,0,0,0,0,0,0,0,0,0,0,0,0,0,0
0,0,0,0,0,0,0,0,0,0,0,0,0,0,0,0,0,0,0,0,0,0,0,0,0,0
endlayer

# 3
layer
0,0,0,0,0,0,0,0,0,0,0,0,0,0,0,0,0,0,0,0,0,0,0,0,0,0
0,0,0,0,0,0,0,0,0,0,0,0,0,0,0,0,2,0,0,0,0,0,0,0,0,0
0,0,0,0,0,0,0,0,0,0,0,0,0,0,0,0,0,0,0,0,0,0,0,0,0,0
0,0,0,0,0,0,0,0,0,0,0,0,0,0,0,0,0,0,0,0,0,0,0,0,0,0
0,0,0,0,0,0,0,0,0,0,3,1,13,13,1,12,3,0,0,0,0,0,0,0,0,0
0,0,0,0,0,0,0,0,0,7,17,16,0,0,15,0,14,5,0,0,0,0,0,0,0,0
0,0,0,2,0,0,0,18,1,20,0,0,0,0,0,0,19,18,18,0,0,0,0,0,0,0
0,0,0,0,0,0,0,0,0,7,17,16,0,0,21,0,14,5,0,0,0,0,0,0,0,0
0,0,0,0,0,0,0,0,0,0,10,1,22,22,1,12,10,0,0,0,0,0,0,0,0,0
0,0,0,0,0,0,0,0,0,0,0,0,0,0,0,0,0,0,0,0,0,0,0,0,0,0
0,0,0,0,0,0,0,0,0,0,0,0,0,0,0,0,0,0,0,0,0,0,0,0,0,0
0,0,0,0,0,0,0,0,0,0,0,0,0,0,0,0,2,0,0,0,0,0,0,0,0,0
0,0,0,0,0,0,0,0,0,0,0,0,0,0,0,0,0,0,0,0,0,0,0,0,0,0
endlayer

# 4
layer
0,0,0,0,0,0,0,0,0,0,0,0,0,0,0,23,2,0,0,0,0,0,0,0,0,0
0,0,0,0,0,0,0,0,0,0,0,0,0,0,0,24,2,0,0,0,0,0,0,0,0,0
0,0,0,0,0,0,0,0,0,0,0,0,0,0,0,23,2,0,0,0,0,0,0,0,0,0
0,0,0,0,0,0,0,0,0,0,0,4,0,0,4,23,0,0,0,0,0,0,0,0,0,0
0,0,0,0,0,0,0,0,0,7,12,1,2,2,1,13,12,5,0,0,0,0,0,0,0,0
0,0,0,0,0,0,0,0,7,12,0,0,0,0,0,0,14,12,5,0,0,0,0,0,0,0
0,0,0,2,0,0,18,1,1,0,0,0,0,0,0,0,0,19,1,1,0,0,0,0,0,0
0,0,0,0,0,0,0,0,7,12,0,0,0,0,0,0,14,12,5,0,0,0,0,0,0,0
0,0,0,0,0,0,0,0,0,7,12,1,2,2,1,22,12,5,0,0,0,0,0,0,0,0
0,0,0,0,0,0,0,0,0,0,0,11,0,0,11,23,0,0,0,0,0,0,0,0,0,0
0,0,0,0,0,0,0,0,0,0,0,0,0,0,0,23,2,0,0,0,0,0,0,0,0,0
0,0,0,0,0,0,0,0,0,0,0,0,0,0,0,24,2,0,0,0,0,0,0,0,0,0
0,0,0,0,0,0,0,0,0,0,0,0,0,0,0,23,2,0,0,0,0,0,0,0,0,0
endlayer

# 5
layer
0,0,0,0,0,0,0,0,0,0,0,0,0,0,0,0,0,0,0,0,0,0,0,0,0,0
0,0,0,0,0,0,0,0,0,0,0,0,0,0,0,0,2,0,0,0,0,0,0,0,0,0
0,0,0,0,0,0,0,0,0,0,0,0,0,0,0,0,0,0,0,0,0,0,0,0,0,0
0,0,0,0,0,0,0,0,0,2,18,1,1,1,1,1,1,2,0,0,0,0,0,0,0,0
0,0,0,0,0,0,0,0,0,1,1,1,1,1,1,18,1,1,18,0,0,0,0,0,0,0
0,0,0,0,0,0,0,18,1,1,18,1,26,25,1,18,18,1,1,1,0,0,0,0,0,0
0,18,18,1,1,1,1,1,1,18,18,1,26,25,1,0,0,0,19,1,2,0,0,0,0,0
0,0,0,0,0,0,0,18,1,1,18,1,26,25,1,18,18,1,1,1,0,0,0,0,0,0
0,0,0,0,0,0,0,0,0,1,1,1,1,1,1,18,1,1,18,0,0,0,0,0,0,0
0,0,0,0,0,0,0,0,0,2,18,1,1,1,1,1,1,2,0,0,0,0,0,0,0,0
0,0,0,0,0,0,0,0,0,0,0,0,0,0,0,0,0,0,0,0,0,0,0,0,0,0
0,0,0,0,0,0,0,0,0,0,0,0,0,0,0,0,2,0,0,0,0,0,0,0,0,0
0,0,0,0,0,0,0,0,0,0,0,0,0,0,0,0,0,0,0,0,0,0,0,0,0,0
endlayer

# 6
layer
0,0,0,0,0,0,0,0,0,0,0,0,0,0,0,0,0,0,0,0,0,0,0,0,0,0
0,0,0,0,0,0,0,0,0,0,0,0,0,0,0,0,0,0,0,0,0,0,0,0,0,0
0,0,0,0,0,0,0,0,0,0,0,0,0,0,0,0,0,0,0,0,0,0,0,0,0,0
0,0,0,0,0,0,0,0,0,2,27,27,27,27,27,27,27,2,0,0,0,0,0,0,0,0
0,0,0,0,0,0,0,0,0,27,27,0,0,0,0,0,27,27,27,0,0,0,0,0,0,0
0,0,0,0,0,0,0,27,27,27,0,28,0,0,28,23,0,0,27,27,0,0,0,0,0,0
23,23,23,23,0,2,0,27,0,0,28,0,0,0,30,29,0,0,0,27,2,0,0,0,0,0
0,0,0,0,0,0,0,27,27,27,0,28,0,0,28,23,0,0,27,27,0,0,0,0,0,0
0,0,0,0,0,0,0,0,0,27,27,0,0,0,0,0,27,27,27,0,0,0,0,0,0,0
0,0,0,0,0,0,0,0,0,2,27,27,27,27,27,27,27,2,0,0,0,0,0,0,0,0
0,0,0,0,0,0,0,0,0,0,0,0,0,0,0,0,0,0,0,0,0,0,0,0,0,0
0,0,0,0,0,0,0,0,0,0,0,0,0,0,0,0,0,0,0,0,0,0,0,0,0,0
0,0,0,0,0,0,0,0,0,0,0,0,0,0,0,0,0,0,0,0,0,0,0,0,0,0
endlayer

# 7
layer
0,0,0,0,0,0,0,0,0,0,0,0,0,0,0,0,0,0,0,0,0,0,0,0,0,0
0,0,0,0,0,0,0,0,0,0,0,0,0,0,0,0,0,0,0,0,0,0,0,0,0,0
0,0,0,0,0,0,0,0,0,0,0,0,0,0,0,0,0,0,0,0,0,0,0,0,0,0
0,0,0,0,0,0,0,0,0,2,0,0,0,0,0,0,0,2,0,0,0,0,0,0,0,0
0,0,0,0,0,0,0,0,0,0,0,0,0,0,0,0,0,0,0,0,0,0,0,0,0,0
0,0,0,0,0,0,0,0,0,0,0,0,0,0,0,0,0,0,0,0,0,0,0,0,0,0
0,0,0,0,0,2,0,0,0,0,0,0,0,0,31,0,0,0,0,0,2,2,0,0,0,0
0,0,0,0,0,0,0,0,0,0,0,0,0,0,0,0,0,0,0,0,0,0,0,0,0,0
0,0,0,0,0,0,0,0,0,0,0,0,0,0,0,0,0,0,0,0,0,0,0,0,0,0
0,0,0,0,0,0,0,0,0,2,0,0,0,0,0,0,0,2,0,0,0,0,0,0,0,0
0,0,0,0,0,0,0,0,0,0,0,0,0,0,0,0,0,0,0,0,0,0,0,0,0,0
0,0,0,0,0,0,0,0,0,0,0,0,0,0,0,0,0,0,0,0,0,0,0,0,0,0
0,0,0,0,0,0,0,0,0,0,0,0,0,0,0,0,0,0,0,0,0,0,0,0,0,0
endlayer

# 8
layer
0,0,0,0,0,0,0,0,0,0,0,0,0,0,0,0,0,0,0,0,0,0,0,0,0,0
0,0,0,0,0,0,0,0,0,0,0,0,0,0,0,0,0,0,0,0,0,0,0,0,0,0
0,0,0,0,0,0,0,0,0,0,0,0,0,0,0,0,0,0,0,0,0,0,0,0,0,0
0,0,0,0,0,0,0,0,0,2,0,0,0,0,0,0,0,2,0,0,0,0,0,0,0,0
0,0,0,0,0,0,0,0,0,0,0,0,0,0,0,0,0,0,0,0,0,0,0,0,0,0
0,0,0,0,0,0,0,0,0,0,0,0,0,0,0,0,0,0,0,0,0,0,0,0,0,0
0,0,0,0,0,2,0,0,0,0,0,0,0,0,0,0,0,0,0,0,0,2,0,0,0,0
0,0,0,0,0,0,0,0,0,0,0,0,0,0,0,0,0,0,0,0,0,0,0,0,0,0
0,0,0,0,0,0,0,0,0,0,0,0,0,0,0,0,0,0,0,0,0,0,0,0,0,0
0,0,0,0,0,0,0,0,0,2,0,0,0,0,0,0,0,2,0,0,0,0,0,0,0,0
0,0,0,0,0,0,0,0,0,0,0,0,0,0,0,0,0,0,0,0,0,0,0,0,0,0
0,0,0,0,0,0,0,0,0,0,0,0,0,0,0,0,0,0,0,0,0,0,0,0,0,0
0,0,0,0,0,0,0,0,0,0,0,0,0,0,0,0,0,0,0,0,0,0,0,0,0,0
endlayer

# 9
layer
0,0,0,0,0,0,0,0,0,0,0,0,0,0,0,0,0,0,0,0,0,0,0,0,0,0
0,0,0,0,0,0,0,0,0,0,0,0,0,0,0,0,0,0,0,0,0,0,0,0,0,0
0,0,0,0,0,0,0,0,0,0,0,0,0,0,0,0,0,0,0,0,0,0,0,0,0,0
0,0,0,0,0,0,0,0,0,2,0,0,0,0,0,0,0,2,0,0,0,0,0,0,0,0
0,0,0,0,0,0,0,0,0,0,0,0,0,0,0,0,0,0,0,0,0,0,0,0,0,0
0,0,0,0,0,0,0,0,0,0,0,0,32,32,33,32,32,0,0,0,0,0,0,0,0,0
0,0,0,0,0,2,0,0,0,0,0,32,32,32,0,33,32,32,0,0,0,2,0,0,0,0
0,0,0,0,0,0,0,0,0,0,0,0,32,32,33,32,32,0,0,0,0,0,0,0,0,0
0,0,0,0,0,0,0,0,0,0,0,0,0,0,0,0,0,0,0,0,0,0,0,0,0,0
0,0,0,0,0,0,0,0,0,2,0,0,0,0,0,0,0,2,0,0,0,0,0,0,0,0
0,0,0,0,0,0,0,0,0,0,0,0,0,0,0,0,0,0,0,0,0,0,0,0,0,0
0,0,0,0,0,0,0,0,0,0,0,0,0,0,0,0,0,0,0,0,0,0,0,0,0,0
0,0,0,0,0,0,0,0,0,0,0,0,0,0,0,0,0,0,0,0,0,0,0,0,0,0
endlayer

# 10
layer
0,0,0,0,0,0,0,0,0,0,0,0,0,0,0,0,0,0,0,0,0,0,0,0,0,0
0,0,0,0,0,0,0,0,0,0,0,0,0,0,0,0,0,0,0,0,0,0,0,0,0,0
0,0,0,0,0,0,0,0,0,0,0,0,0,0,0,0,0,0,0,0,0,0,0,0,0,0
0,0,0,0,0,0,0,0,0,2,0,0,0,0,0,0,0,2,0,0,0,0,0,0,0,0
0,0,0,0,0,0,0,0,0,0,0,0,32,33,32,32,32,0,0,0,0,0,0,0,0,0
0,0,0,0,0,0,0,0,0,0,32,32,32,0,0,0,32,32,32,0,0,0,0,0,0,0
0,0,0,0,0,2,0,0,32,32,32,0,0,0,0,0,0,0,32,32,32,2,0,0,0,0
0,0,0,0,0,0,0,0,0,0,32,32,32,0,0,0,32,32,32,0,0,0,0,0,0,0
0,0,0,0,0,0,0,0,0,0,0,32,32,33,32,32,32,0,0,0,0,0,0,0,0,0
0,0,0,0,0,0,0,0,0,2,0,0,0,0,0,0,0,2,0,0,0,0,0,0,0,0
0,0,0,0,0,0,0,0,0,0,0,0,0,0,0,0,0,0,0,0,0,0,0,0,0,0
0,0,0,0,0,0,0,0,0,0,0,0,0,0,0,0,0,0,0,0,0,0,0,0,0,0
0,0,0,0,0,0,0,0,0,0,0,0,0,0,0,0,0,0,0,0,0,0,0,0,0,0
endlayer

# 11
layer
0,0,0,0,0,0,0,0,0,0,0,0,0,0,0,0,0,0,0,0,0,0,0,0,0,0
0,0,0,0,0,0,0,0,0,0,0,0,0,0,0,0,0,0,0,0,0,0,0,0,0,0
0,0,0,0,0,0,0,0,0,0,0,0,0,0,0,0,0,0,0,0,0,0,0,0,0,0
0,0,0,0,0,0,0,0,0,2,0,0,32,32,33,32,32,2,0,0,0,0,0,0,0,0
0,0,0,0,0,0,0,0,0,32,32,32,32,0,0,0,32,32,32,32,0,0,0,0,0,0
0,0,0,0,0,0,0,32,32,32,32,0,0,0,0,0,0,0,32,32,32,32,0,0,0,0
0,0,0,0,0,32,32,32,32,0,0,0,0,0,0,0,0,0,0,0,32,32,32,32,0,0
0,0,0,0,0,0,0,32,32,32,32,0,0,0,0,0,0,0,32,32,32,32,0,0,0,0
0,0,0,0,0,0,0,0,0,32,32,32,32,0,0,0,32,32,32,32,0,0,0,0,0,0
0,0,0,0,0,0,0,0,0,2,0,0,32,32,33,32,32,2,0,0,0,0,0,0,0,0
0,0,0,0,0,0,0,0,0,0,0,0,0,0,0,0,0,0,0,0,0,0,0,0,0,0
0,0,0,0,0,0,0,0,0,0,0,0,0,0,0,0,0,0,0,0,0,0,0,0,0,0
0,0,0,0,0,0,0,0,0,0,0,0,0,0,0,0,0,0,0,0,0,0,0,0,0,0
endlayer

# 12
layer
0,0,0,0,0,0,0,0,0,0,0,0,0,0,0,0,0,0,0,0,0,0,0,0,0,0
0,0,0,0,0,0,0,0,0,0,0,0,0,0,0,0,0,0,0,0,0,0,0,0,0,0
0,0,0,0,0,0,0,0,0,0,0,32,32,32,32,33,32,32,0,0,0,0,0,0,0,0
0,0,0,0,0,0,0,0,0,32,32,32,0,0,0,0,0,32,32,32,0,0,0,0,0,0
0,0,0,0,0,0,0,32,32,32,32,0,0,0,0,0,0,0,32,32,32,32,0,0,0,0
0,0,0,0,0,32,32,32,0,0,0,0,0,0,0,0,0,0,0,0,0,32,32,32,0,0
0,0,0,0,33,32,0,0,0,0,0,0,0,0,0,0,0,0,0,0,0,0,0,32,33,0
0,0,0,0,0,32,32,32,0,0,0,0,0,0,0,0,0,0,0,0,0,32,32,32,0,0
0,0,0,0,0,0,0,32,32,32,32,0,0,0,0,0,0,0,32,32,32,32,0,0,0,0
0,0,0,0,0,0,0,0,0,32,32,32,0,0,0,0,0,32,32,32,0,0,0,0,0,0
0,0,0,0,0,0,0,0,0,0,0,32,32,32,32,33,32,32,0,0,0,0,0,0,0,0
0,0,0,0,0,0,0,0,0,0,0,0,0,0,0,0,0,0,0,0,0,0,0,0,0,0
0,0,0,0,0,0,0,0,0,0,0,0,0,0,0,0,0,0,0,0,0,0,0,0,0,0
endlayer

# 13
layer
0,0,0,0,0,0,0,0,0,0,0,0,0,0,0,0,0,0,0,0,0,0,0,0,0,0
0,0,0,0,0,0,0,0,0,0,0,0,0,0,0,0,0,0,0,0,0,0,0,0,0,0
0,0,0,0,0,0,0,0,0,0,32,32,32,32,33,32,32,32,32,0,0,0,0,0,0,0
0,0,0,0,0,0,0,32,32,32,32,0,0,0,34,0,0,0,32,32,32,32,0,0,0,0
0,0,0,0,0,32,32,32,32,0,0,0,0,0,0,0,0,0,0,0,32,32,32,32,0,0
0,0,0,0,33,32,0,0,0,0,0,0,0,0,0,0,0,0,0,0,0,0,0,32,33,0
0,0,0,32,32,34,0,0,0,0,0,0,0,0,0,0,0,0,0,0,0,0,0,34,32,32
0,0,0,0,33,32,0,0,0,0,0,0,0,0,0,0,0,0,0,0,0,0,0,32,33,0
0,0,0,0,0,32,32,32,32,0,0,0,0,0,0,0,0,0,0,0,32,32,32,32,0,0
0,0,0,0,0,0,0,32,32,32,32,0,0,0,34,0,0,0,32,32,32,32,0,0,0,0
0,0,0,0,0,0,0,0,0,0,32,32,32,32,33,32,32,32,32,0,0,0,0,0,0,0
0,0,0,0,0,0,0,0,0,0,0,0,0,0,0,0,0,0,0,0,0,0,0,0,0,0
0,0,0,0,0,0,0,0,0,0,0,0,0,0,0,0,0,0,0,0,0,0,0,0,0,0
endlayer

# 14
layer
0,0,0,0,0,0,0,0,0,0,0,0,0,0,0,0,0,0,0,0,0,0,0,0,0,0
0,0,0,0,0,0,0,0,0,0,0,0,0,0,0,0,0,0,0,0,0,0,0,0,0,0
0,0,0,0,0,0,0,0,0,0,0,32,32,33,32,32,32,32,0,0,0,0,0,0,0,0
0,0,0,0,0,0,0,0,0,32,32,32,0,0,0,0,0,32,32,32,0,0,0,0,0,0
0,0,0,0,0,0,0,32,32,32,32,0,0,0,0,0,0,0,32,32,32,32,0,0,0,0
0,0,0,0,0,32,32,32,0,0,0,0,0,0,0,0,0,0,0,0,0,32,32,32,0,0
0,0,0,0,33,32,0,0,0,0,0,0,0,0,0,0,0,0,0,0,0,0,0,32,33,0
0,0,0,0,0,32,32,32,0,0,0,0,0,0,0,0,0,0,0,0,0,32,32,32,0,0
0,0,0,0,0,0,0,32,32,32,32,0,0,0,0,0,0,0,32,32,32,32,0,0,0,0
0,0,0,0,0,0,0,0,0,32,32,32,0,0,0,0,0,32,32,32,0,0,0,0,0,0
0,0,0,0,0,0,0,0,0,0,0,32,32,33,32,32,32,32,0,0,0,0,0,0,0,0
0,0,0,0,0,0,0,0,0,0,0,0,0,0,0,0,0,0,0,0,0,0,0,0,0,0
0,0,0,0,0,0,0,0,0,0,0,0,0,0,0,0,0,0,0,0,0,0,0,0,0,0
endlayer

# 15
layer
0,0,0,0,0,0,0,0,0,0,0,0,0,0,0,0,0,0,0,0,0,0,0,0,0,0
0,0,0,0,0,0,0,0,0,0,0,0,0,0,0,0,0,0,0,0,0,0,0,0,0,0
0,0,0,0,0,0,0,0,0,0,0,0,0,0,0,0,0,0,0,0,0,0,0,0,0,0
0,0,0,0,0,0,0,0,0,0,0,32,32,32,33,32,32,32,0,0,0,0,0,0,0,0
0,0,0,0,0,0,0,0,0,32,32,0,0,0,0,0,0,0,32,32,0,0,0,0,0,0
0,0,0,0,0,0,0,32,32,32,32,0,0,0,0,0,0,0,32,32,32,32,0,0,0,0
0,0,0,0,0,32,32,32,32,0,0,0,0,0,0,0,0,0,0,0,32,32,32,32,0,0
0,0,0,0,0,0,0,32,32,32,32,0,0,0,0,0,0,0,32,32,32,32,0,0,0,0
0,0,0,0,0,0,0,0,0,32,32,0,0,0,0,0,0,0,32,32,0,0,0,0,0,0
0,0,0,0,0,0,0,0,0,0,0,32,32,32,33,32,32,32,0,0,0,0,0,0,0,0
0,0,0,0,0,0,0,0,0,0,0,0,0,0,0,0,0,0,0,0,0,0,0,0,0,0
0,0,0,0,0,0,0,0,0,0,0,0,0,0,0,0,0,0,0,0,0,0,0,0,0,0
0,0,0,0,0,0,0,0,0,0,0,0,0,0,0,0,0,0,0,0,0,0,0,0,0,0
endlayer

# 16
layer
0,0,0,0,0,0,0,0,0,0,0,0,0,0,0,0,0,0,0,0,0,0,0,0,0,0
0,0,0,0,0,0,0,0,0,0,0,0,0,0,0,0,0,0,0,0,0,0,0,0,0,0
0,0,0,0,0,0,0,0,0,0,0,0,0,0,0,0,0,0,0,0,0,0,0,0,0,0
0,0,0,0,0,0,0,0,0,0,0,0,0,0,0,0,0,0,0,0,0,0,0,0,0,0
0,0,0,0,0,0,0,0,0,0,0,32,32,32,32,33,32,32,0,0,0,0,0,0,0,0
0,0,0,0,0,0,0,0,0,32,32,32,0,0,0,0,0,32,32,32,0,0,0,0,0,0
0,0,0,0,0,0,0,32,32,32,32,0,0,0,0,0,0,0,32,32,32,32,0,0,0,0
0,0,0,0,0,0,0,0,0,32,32,32,0,0,0,0,0,32,32,32,0,0,0,0,0,0
0,0,0,0,0,0,0,0,0,0,0,32,32,32,32,33,32,32,0,0,0,0,0,0,0,0
0,0,0,0,0,0,0,0,0,0,0,0,0,0,0,0,0,0,0,0,0,0,0,0,0,0
0,0,0,0,0,0,0,0,0,0,0,0,0,0,0,0,0,0,0,0,0,0,0,0,0,0
0,0,0,0,0,0,0,0,0,0,0,0,0,0,0,0,0,0,0,0,0,0,0,0,0,0
0,0,0,0,0,0,0,0,0,0,0,0,0,0,0,0,0,0,0,0,0,0,0,0,0,0
endlayer

# 17
layer
0,0,0,0,0,0,0,0,0,0,0,0,0,0,0,0,0,0,0,0,0,0,0,0,0,0
0,0,0,0,0,0,0,0,0,0,0,0,0,0,0,0,0,0,0,0,0,0,0,0,0,0
0,0,0,0,0,0,0,0,0,0,0,0,0,0,0,0,0,0,0,0,0,0,0,0,0,0
0,0,0,0,0,0,0,0,0,0,0,0,0,0,0,0,0,0,0,0,0,0,0,0,0,0
0,0,0,0,0,0,0,0,0,0,0,0,0,0,0,0,0,0,0,0,0,0,0,0,0,0
0,0,0,0,0,0,0,0,0,0,0,32,32,32,33,32,32,32,0,0,0,0,0,0,0,0
0,0,0,0,0,0,0,0,0,0,32,32,32,33,32,32,32,32,32,0,0,0,0,0,0,0
0,0,0,0,0,0,0,0,0,0,0,32,32,32,33,32,32,32,0,0,0,0,0,0,0,0
0,0,0,0,0,0,0,0,0,0,0,0,0,0,0,0,0,0,0,0,0,0,0,0,0,0
0,0,0,0,0,0,0,0,0,0,0,0,0,0,0,0,0,0,0,0,0,0,0,0,0,0
0,0,0,0,0,0,0,0,0,0,0,0,0,0,0,0,0,0,0,0,0,0,0,0,0,0
0,0,0,0,0,0,0,0,0,0,0,0,0,0,0,0,0,0,0,0,0,0,0,0,0,0
0,0,0,0,0,0,0,0,0,0,0,0,0,0,0,0,0,0,0,0,0,0,0,0,0,0
endlayer

