# DesertIsland
# 13 Mar 2014; updated to 1.7.10, 9 Oct 2014
# Created by Ruins mod version 12.3 Ingame Parser
# authoring Player: Jordan_Greywolf
# Updated for MC 1.8: 22 Jul 2015
# Last Updated 22 Nov 2015
# Updated for MC 1.11: 13 Jan 2017
# Verified for MC 1.12: 21 Jun 2017
# Updated to MC 1.12.1: 10 Sep 2017

biomesToSpawnIn=beach,coral reef,coral_reef,kelp forest,kelp_forest,ocean,desert,rwg_oceanhot,rwg_oceantemperate,rwg_oceanwet,rwg_hotdesert,beaches,stone_beach

weight=1
embed_into_distance=34

acceptable_target_blocks=water,flowing_water,sand,dirt,gravel,stone,sandstone,grass

dimensions=46,12,12

allowable_overhang=0
max_cut_in=0
cut_in_buffer=0
max_leveling=30
leveling_buffer=-1
preserve_water=0
preserve_lava=0
preserve_plants=0

rule1=0,100,preserveBlock
rule2=0,100,minecraft:sand-0
rule3=0,100,minecraft:dirt-0
rule4=0,100,minecraft:sandstone-0
rule5=0,100,minecraft:grass-0
rule6=0,100,minecraft:log-3
rule7=0,100,minecraft:tallgrass-1,minecraft:tallgrass-0
rule8=0,100,minecraft:log-15
rule9=0,100,minecraft:leaves-7

layer
1,1,1,4,4,4,4,4,4,4,4,1
1,1,4,4,4,4,4,4,4,4,4,4
1,4,4,4,4,4,4,4,4,4,4,4
1,4,4,4,4,4,4,4,4,4,4,4
4,4,4,4,4,4,4,4,4,4,4,4
4,4,4,4,4,4,4,4,4,4,4,4
4,4,4,4,4,4,4,4,4,4,4,4
4,4,4,4,4,4,4,4,4,4,4,4
4,4,4,4,4,4,4,4,4,4,4,4
1,4,4,4,4,4,4,4,4,4,4,1
1,1,4,4,4,4,4,4,4,4,1,1
1,1,1,1,4,4,4,4,1,1,1,1
endlayer

layer
1,1,1,2,2,2,2,2,2,2,2,1
1,1,2,2,2,2,2,2,2,2,2,2
1,2,2,2,2,2,2,2,2,2,2,2
1,2,2,2,2,2,2,2,2,2,2,2
2,2,2,2,2,2,2,2,2,2,2,2
2,2,2,2,2,2,2,2,2,2,2,2
2,2,2,2,2,2,2,2,2,2,2,2
2,2,2,2,2,2,2,2,2,2,2,2
2,2,2,2,2,2,2,2,2,2,2,2
1,2,2,2,2,2,2,2,2,2,2,1
1,1,2,2,2,2,2,2,2,2,1,1
1,1,1,1,2,2,2,2,1,1,1,1
endlayer

layer
1,1,1,2,2,2,2,2,2,2,2,1
1,1,2,2,2,2,2,2,2,2,2,2
1,2,2,2,2,2,2,2,2,2,2,2
1,2,2,2,2,2,2,2,2,2,2,2
2,2,2,2,2,2,2,2,2,2,2,2
2,2,2,2,2,2,2,2,2,2,2,2
2,2,2,2,2,2,2,2,2,2,2,2
2,2,2,2,2,2,2,2,2,2,2,2
2,2,2,2,2,2,2,2,2,2,2,2
1,2,2,2,2,2,2,2,2,2,2,1
1,1,2,2,2,2,2,2,2,2,1,1
1,1,1,1,2,2,2,2,1,1,1,1
endlayer

layer
1,1,1,2,2,2,2,2,2,2,2,1
1,1,2,2,2,2,2,2,2,2,2,2
1,2,2,2,2,2,2,2,2,2,2,2
1,2,2,2,2,2,2,2,2,2,2,2
2,2,2,2,2,2,2,2,2,2,2,2
2,2,2,2,2,2,2,2,2,2,2,2
2,2,2,2,2,2,2,2,2,2,2,2
2,2,2,2,2,2,2,2,2,2,2,2
2,2,2,2,2,2,2,2,2,2,2,2
1,2,2,2,2,2,2,2,2,2,2,1
1,1,2,2,2,2,2,2,2,2,1,1
1,1,1,1,2,2,2,2,1,1,1,1
endlayer

layer
1,1,1,2,2,2,2,2,2,2,2,1
1,1,2,2,2,2,2,2,2,2,2,2
1,2,2,2,2,2,2,2,2,2,2,2
1,2,2,2,2,2,2,2,2,2,2,2
2,2,2,2,2,2,2,2,2,2,2,2
2,2,2,2,2,2,2,2,2,2,2,2
2,2,2,2,2,2,2,2,2,2,2,2
2,2,2,2,2,2,2,2,2,2,2,2
2,2,2,2,2,2,2,2,2,2,2,2
1,2,2,2,2,2,2,2,2,2,2,1
1,1,2,2,2,2,2,2,2,2,1,1
1,1,1,1,2,2,2,2,1,1,1,1
endlayer

layer
1,1,1,2,2,2,2,2,2,2,2,1
1,1,2,2,2,2,2,2,2,2,2,2
1,2,2,2,2,2,2,2,2,2,2,2
1,2,2,2,2,2,2,2,2,2,2,2
2,2,2,2,2,2,2,2,2,2,2,2
2,2,2,2,2,2,2,2,2,2,2,2
2,2,2,2,2,2,2,2,2,2,2,2
2,2,2,2,2,2,2,2,2,2,2,2
2,2,2,2,2,2,2,2,2,2,2,2
1,2,2,2,2,2,2,2,2,2,2,1
1,1,2,2,2,2,2,2,2,2,1,1
1,1,1,1,2,2,2,2,1,1,1,1
endlayer

layer
1,1,1,2,2,2,2,2,2,2,2,1
1,1,2,2,2,2,2,2,2,2,2,2
1,2,2,2,2,2,2,2,2,2,2,2
1,2,2,2,2,2,2,2,2,2,2,2
2,2,2,2,2,2,2,2,2,2,2,2
2,2,2,2,2,2,2,2,2,2,2,2
2,2,2,2,2,2,2,2,2,2,2,2
2,2,2,2,2,2,2,2,2,2,2,2
2,2,2,2,2,2,2,2,2,2,2,2
1,2,2,2,2,2,2,2,2,2,2,1
1,1,2,2,2,2,2,2,2,2,1,1
1,1,1,1,2,2,2,2,1,1,1,1
endlayer

layer
1,1,1,2,2,2,2,2,2,2,2,1
1,1,2,2,2,2,2,2,2,2,2,2
1,2,2,2,2,2,2,2,2,2,2,2
1,2,2,2,2,2,2,2,2,2,2,2
2,2,2,2,2,2,2,2,2,2,2,2
2,2,2,2,2,2,2,2,2,2,2,2
2,2,2,2,2,2,2,2,2,2,2,2
2,2,2,2,2,2,2,2,2,2,2,2
2,2,2,2,2,2,2,2,2,2,2,2
1,2,2,2,2,2,2,2,2,2,2,1
1,1,2,2,2,2,2,2,2,2,1,1
1,1,1,1,2,2,2,2,1,1,1,1
endlayer

layer
1,1,1,2,2,2,2,2,2,2,2,1
1,1,2,2,2,2,2,2,2,2,2,2
1,2,2,2,2,2,2,2,2,2,2,2
1,2,2,2,2,2,2,2,2,2,2,2
2,2,2,2,2,2,2,2,2,2,2,2
2,2,2,2,2,2,2,2,2,2,2,2
2,2,2,2,2,2,2,2,2,2,2,2
2,2,2,2,2,2,2,2,2,2,2,2
2,2,2,2,2,2,2,2,2,2,2,2
1,2,2,2,2,2,2,2,2,2,2,1
1,1,2,2,2,2,2,2,2,2,1,1
1,1,1,1,2,2,2,2,1,1,1,1
endlayer

layer
1,1,1,2,2,2,2,2,2,2,2,1
1,1,2,2,2,2,2,2,2,2,2,2
1,2,2,2,2,2,2,2,2,2,2,2
1,2,2,2,2,2,2,2,2,2,2,2
2,2,2,2,2,2,2,2,2,2,2,2
2,2,2,2,2,2,2,2,2,2,2,2
2,2,2,2,2,2,2,2,2,2,2,2
2,2,2,2,2,2,2,2,2,2,2,2
2,2,2,2,2,2,2,2,2,2,2,2
1,2,2,2,2,2,2,2,2,2,2,1
1,1,2,2,2,2,2,2,2,2,1,1
1,1,1,1,2,2,2,2,1,1,1,1
endlayer

layer
1,1,1,2,2,2,2,2,2,2,2,1
1,1,2,2,2,2,2,2,2,2,2,2
1,2,2,2,2,2,2,2,2,2,2,2
1,2,2,2,2,2,2,2,2,2,2,2
2,2,2,2,2,2,2,2,2,2,2,2
2,2,2,2,2,2,2,2,2,2,2,2
2,2,2,2,2,2,2,2,2,2,2,2
2,2,2,2,2,2,2,2,2,2,2,2
2,2,2,2,2,2,2,2,2,2,2,2
1,2,2,2,2,2,2,2,2,2,2,1
1,1,2,2,2,2,2,2,2,2,1,1
1,1,1,1,2,2,2,2,1,1,1,1
endlayer

layer
1,1,1,2,2,2,2,2,2,2,2,1
1,1,2,2,2,2,2,2,2,2,2,2
1,2,2,2,2,2,2,2,2,2,2,2
1,2,2,2,2,2,2,2,2,2,2,2
2,2,2,2,2,2,2,2,2,2,2,2
2,2,2,2,2,2,2,2,2,2,2,2
2,2,2,2,2,2,2,2,2,2,2,2
2,2,2,2,2,2,2,2,2,2,2,2
2,2,2,2,2,2,2,2,2,2,2,2
1,2,2,2,2,2,2,2,2,2,2,1
1,1,2,2,2,2,2,2,2,2,1,1
1,1,1,1,2,2,2,2,1,1,1,1
endlayer

layer
1,1,1,2,2,2,2,2,2,2,2,1
1,1,2,2,2,2,2,2,2,2,2,2
1,2,2,2,2,2,2,2,2,2,2,2
1,2,2,2,2,2,2,2,2,2,2,2
2,2,2,2,2,2,2,2,2,2,2,2
2,2,2,2,2,2,2,2,2,2,2,2
2,2,2,2,2,2,2,2,2,2,2,2
2,2,2,2,2,2,2,2,2,2,2,2
2,2,2,2,2,2,2,2,2,2,2,2
1,2,2,2,2,2,2,2,2,2,2,1
1,1,2,2,2,2,2,2,2,2,1,1
1,1,1,1,2,2,2,2,1,1,1,1
endlayer

layer
1,1,1,2,2,2,2,2,2,2,2,1
1,1,2,2,2,2,2,2,2,2,2,2
1,2,2,2,2,2,2,2,2,2,2,2
1,2,2,2,2,2,2,2,2,2,2,2
2,2,2,2,2,2,2,2,2,2,2,2
2,2,2,2,2,2,2,2,2,2,2,2
2,2,2,2,2,2,2,2,2,2,2,2
2,2,2,2,2,2,2,2,2,2,2,2
2,2,2,2,2,2,2,2,2,2,2,2
1,2,2,2,2,2,2,2,2,2,2,1
1,1,2,2,2,2,2,2,2,2,1,1
1,1,1,1,2,2,2,2,1,1,1,1
endlayer

layer
1,1,1,2,2,2,2,2,2,2,2,1
1,1,2,2,2,2,2,2,2,2,2,2
1,2,2,2,2,2,2,2,2,2,2,2
1,2,2,2,2,2,2,2,2,2,2,2
2,2,2,2,2,2,2,2,2,2,2,2
2,2,2,2,2,2,2,2,2,2,2,2
2,2,2,2,2,2,2,2,2,2,2,2
2,2,2,2,2,2,2,2,2,2,2,2
2,2,2,2,2,2,2,2,2,2,2,2
1,2,2,2,2,2,2,2,2,2,2,1
1,1,2,2,2,2,2,2,2,2,1,1
1,1,1,1,2,2,2,2,1,1,1,1
endlayer

layer
1,1,1,2,2,2,2,2,2,2,2,1
1,1,2,2,2,2,2,2,2,2,2,2
1,2,2,2,2,2,2,2,2,2,2,2
1,2,2,2,2,2,2,2,2,2,2,2
2,2,2,2,2,2,2,2,2,2,2,2
2,2,2,2,2,2,2,2,2,2,2,2
2,2,2,2,2,2,2,2,2,2,2,2
2,2,2,2,2,2,2,2,2,2,2,2
2,2,2,2,2,2,2,2,2,2,2,2
1,2,2,2,2,2,2,2,2,2,2,1
1,1,2,2,2,2,2,2,2,2,1,1
1,1,1,1,2,2,2,2,1,1,1,1
endlayer

layer
1,1,1,2,2,2,2,2,2,2,2,1
1,1,2,2,2,2,2,2,2,2,2,2
1,2,2,2,2,2,2,2,2,2,2,2
1,2,2,2,2,2,2,2,2,2,2,2
2,2,2,2,2,2,2,2,2,2,2,2
2,2,2,2,2,2,2,2,2,2,2,2
2,2,2,2,2,2,2,2,2,2,2,2
2,2,2,2,2,2,2,2,2,2,2,2
2,2,2,2,2,2,2,2,2,2,2,2
1,2,2,2,2,2,2,2,2,2,2,1
1,1,2,2,2,2,2,2,2,2,1,1
1,1,1,1,2,2,2,2,1,1,1,1
endlayer

layer
1,1,1,2,2,2,2,2,2,2,2,1
1,1,2,2,2,2,2,2,2,2,2,2
1,2,2,2,2,2,2,2,2,2,2,2
1,2,2,2,2,2,2,2,2,2,2,2
2,2,2,2,2,2,2,2,2,2,2,2
2,2,2,2,2,2,2,2,2,2,2,2
2,2,2,2,2,2,2,2,2,2,2,2
2,2,2,2,2,2,2,2,2,2,2,2
2,2,2,2,2,2,2,2,2,2,2,2
1,2,2,2,2,2,2,2,2,2,2,1
1,1,2,2,2,2,2,2,2,2,1,1
1,1,1,1,2,2,2,2,1,1,1,1
endlayer

layer
1,1,1,2,2,2,2,2,2,2,2,1
1,1,2,2,2,2,2,2,2,2,2,2
1,2,2,2,2,2,2,2,2,2,2,2
1,2,2,2,2,2,2,2,2,2,2,2
2,2,2,2,2,2,2,2,2,2,2,2
2,2,2,2,2,2,2,2,2,2,2,2
2,2,2,2,2,2,2,2,2,2,2,2
2,2,2,2,2,2,2,2,2,2,2,2
2,2,2,2,2,2,2,2,2,2,2,2
1,2,2,2,2,2,2,2,2,2,2,1
1,1,2,2,2,2,2,2,2,2,1,1
1,1,1,1,2,2,2,2,1,1,1,1
endlayer

layer
1,1,1,2,2,2,2,2,2,2,2,1
1,1,2,2,2,2,2,2,2,2,2,2
1,2,2,2,2,2,2,2,2,2,2,2
1,2,2,2,2,2,2,2,2,2,2,2
2,2,2,2,2,2,2,2,2,2,2,2
2,2,2,2,2,2,2,2,2,2,2,2
2,2,2,2,2,2,2,2,2,2,2,2
2,2,2,2,2,2,2,2,2,2,2,2
2,2,2,2,2,2,2,2,2,2,2,2
1,2,2,2,2,2,2,2,2,2,2,1
1,1,2,2,2,2,2,2,2,2,1,1
1,1,1,1,2,2,2,2,1,1,1,1
endlayer

layer
1,1,1,2,2,2,2,2,2,2,2,1
1,1,2,2,2,2,2,2,2,2,2,2
1,2,2,2,2,2,2,2,2,2,2,2
1,2,2,2,2,2,2,2,2,2,2,2
2,2,2,2,2,2,2,2,2,2,2,2
2,2,2,2,2,2,2,2,2,2,2,2
2,2,2,2,2,2,2,2,2,2,2,2
2,2,2,2,2,2,2,2,2,2,2,2
2,2,2,2,2,2,2,2,2,2,2,2
1,2,2,2,2,2,2,2,2,2,2,1
1,1,2,2,2,2,2,2,2,2,1,1
1,1,1,1,2,2,2,2,1,1,1,1
endlayer

layer
1,1,1,2,2,2,2,2,2,2,2,1
1,1,2,2,2,2,2,2,2,2,2,2
1,2,2,2,2,2,2,2,2,2,2,2
1,2,2,2,2,2,2,2,2,2,2,2
2,2,2,2,2,2,2,2,2,2,2,2
2,2,2,2,2,2,2,2,2,2,2,2
2,2,2,2,2,2,2,2,2,2,2,2
2,2,2,2,2,2,2,2,2,2,2,2
2,2,2,2,2,2,2,2,2,2,2,2
1,2,2,2,2,2,2,2,2,2,2,1
1,1,2,2,2,2,2,2,2,2,1,1
1,1,1,1,2,2,2,2,1,1,1,1
endlayer

layer
1,1,1,2,2,2,2,2,2,2,2,1
1,1,2,2,2,2,2,2,2,2,2,2
1,2,2,2,2,2,2,2,2,2,2,2
1,2,2,2,2,2,2,2,2,2,2,2
2,2,2,2,2,2,2,2,2,2,2,2
2,2,2,2,2,2,2,2,2,2,2,2
2,2,2,2,2,2,2,2,2,2,2,2
2,2,2,2,2,2,2,2,2,2,2,2
2,2,2,2,2,2,2,2,2,2,2,2
1,2,2,2,2,2,2,2,2,2,2,1
1,1,2,2,2,2,2,2,2,2,1,1
1,1,1,1,2,2,2,2,1,1,1,1
endlayer

layer
1,1,1,2,2,2,2,2,2,2,2,1
1,1,2,2,2,2,2,2,2,2,2,2
1,2,2,2,2,2,2,2,2,2,2,2
1,2,2,2,2,2,2,2,2,2,2,2
2,2,2,2,2,2,2,2,2,2,2,2
2,2,2,2,2,2,2,2,2,2,2,2
2,2,2,2,2,2,2,2,2,2,2,2
2,2,2,2,2,2,2,2,2,2,2,2
2,2,2,2,2,2,2,2,2,2,2,2
1,2,2,2,2,2,2,2,2,2,2,1
1,1,2,2,2,2,2,2,2,2,1,1
1,1,1,1,2,2,2,2,1,1,1,1
endlayer

layer
1,1,1,2,2,2,2,2,2,2,2,1
1,1,2,2,2,2,2,2,2,2,2,2
1,2,2,2,2,2,2,2,2,2,2,2
1,2,2,2,2,2,2,2,2,2,2,2
2,2,2,2,2,2,2,2,2,2,2,2
2,2,2,2,2,2,2,2,2,2,2,2
2,2,2,2,2,2,2,2,2,2,2,2
2,2,2,2,2,2,2,2,2,2,2,2
2,2,2,2,2,2,2,2,2,2,2,2
1,2,2,2,2,2,2,2,2,2,2,1
1,1,2,2,2,2,2,2,2,2,1,1
1,1,1,1,2,2,2,2,1,1,1,1
endlayer

layer
1,1,1,2,2,2,2,2,2,2,2,1
1,1,2,2,2,2,2,2,2,2,2,2
1,2,2,2,2,2,2,2,2,2,2,2
1,2,2,2,2,2,2,2,2,2,2,2
2,2,2,2,2,2,2,2,2,2,2,2
2,2,2,2,2,2,2,2,2,2,2,2
2,2,2,2,2,2,2,2,2,2,2,2
2,2,2,2,2,2,2,2,2,2,2,2
2,2,2,2,2,2,2,2,2,2,2,2
1,2,2,2,2,2,2,2,2,2,2,1
1,1,2,2,2,2,2,2,2,2,1,1
1,1,1,1,2,2,2,2,1,1,1,1
endlayer

layer
1,1,1,2,2,2,2,2,2,2,2,1
1,1,2,2,2,2,2,2,2,2,2,2
1,2,2,2,2,2,2,2,2,2,2,2
1,2,2,2,2,2,2,2,2,2,2,2
2,2,2,2,2,2,2,2,2,2,2,2
2,2,2,2,2,2,2,2,2,2,2,2
2,2,2,2,2,2,2,2,2,2,2,2
2,2,2,2,2,2,2,2,2,2,2,2
2,2,2,2,2,2,2,2,2,2,2,2
1,2,2,2,2,2,2,2,2,2,2,1
1,1,2,2,2,2,2,2,2,2,1,1
1,1,1,1,2,2,2,2,1,1,1,1
endlayer

layer
1,1,1,2,2,2,2,2,2,2,2,1
1,1,2,2,2,2,2,2,2,2,2,2
1,2,2,2,2,2,2,2,2,2,2,2
1,2,2,2,2,2,2,2,2,2,2,2
2,2,2,2,2,2,2,2,2,2,2,2
2,2,2,2,2,2,2,2,2,2,2,2
2,2,2,2,2,2,2,2,2,2,2,2
2,2,2,2,2,2,2,2,2,2,2,2
2,2,2,2,2,2,2,2,2,2,2,2
1,2,2,2,2,2,2,2,2,2,2,1
1,1,2,2,2,2,2,2,2,2,1,1
1,1,1,1,2,2,2,2,1,1,1,1
endlayer

layer
1,1,1,2,2,2,2,2,2,2,2,1
1,1,2,2,2,2,2,2,2,2,2,2
1,2,2,2,2,2,2,2,2,2,2,2
1,2,2,2,2,2,2,2,2,2,2,2
2,2,2,2,2,2,2,2,2,2,2,2
2,2,2,2,2,2,2,2,2,2,2,2
2,2,2,2,2,2,2,2,2,2,2,2
2,2,2,2,2,2,2,2,2,2,2,2
2,2,2,2,2,2,2,2,2,2,2,2
1,2,2,2,2,2,2,2,2,2,2,1
1,1,2,2,2,2,2,2,2,2,1,1
1,1,1,1,2,2,2,2,1,1,1,1
endlayer

layer
1,1,1,2,2,2,2,2,2,2,2,1
1,1,2,2,2,2,2,2,2,2,2,2
1,2,2,2,2,2,2,2,2,2,2,2
1,2,2,2,2,2,2,2,2,2,2,2
2,2,2,2,2,2,2,2,2,2,2,2
2,2,2,2,2,2,2,2,2,2,2,2
2,2,2,2,2,2,2,2,2,2,2,2
2,2,2,2,2,2,2,2,2,2,2,2
2,2,2,2,2,2,2,2,2,2,2,2
1,2,2,2,2,2,2,2,2,2,2,1
1,1,2,2,2,2,2,2,2,2,1,1
1,1,1,1,2,2,2,2,1,1,1,1
endlayer


layer
1,1,1,2,2,2,2,2,2,2,2,1
1,1,2,2,2,2,2,2,2,2,2,2
1,2,2,2,2,2,2,2,2,2,2,2
1,2,2,2,2,2,2,2,2,2,2,2
2,2,2,2,2,2,2,2,2,2,2,2
2,2,2,2,2,2,2,2,2,2,2,2
2,2,2,2,2,2,2,2,2,2,2,2
2,2,2,2,2,2,2,2,2,2,2,2
2,2,2,2,2,2,2,2,2,2,2,2
1,2,2,2,2,2,2,2,2,2,2,1
1,1,2,2,2,2,2,2,2,2,1,1
1,1,1,1,2,2,2,2,1,1,1,1
endlayer

layer
1,1,1,1,1,2,2,2,2,1,1,1
1,1,1,1,2,2,2,2,2,2,1,1
1,1,1,2,2,2,2,2,2,2,2,1
1,1,2,2,2,2,2,2,2,2,2,2
1,2,2,2,2,2,2,2,2,2,2,2
2,2,2,2,2,2,2,2,2,2,2,2
2,2,2,2,2,2,2,2,2,2,2,2
2,2,2,2,2,2,2,2,2,2,2,1
1,1,2,2,2,2,2,2,2,2,1,1
1,1,2,2,2,2,2,2,2,2,1,1
1,1,1,1,2,2,2,2,1,1,1,1
1,1,1,1,1,2,2,1,1,1,1,1
endlayer

layer
1,1,1,1,1,1,1,2,1,1,1,1
1,1,1,1,2,2,2,2,2,1,1,1
1,1,1,2,2,3,3,3,3,2,1,1
1,1,2,2,3,3,4,4,3,3,2,1
1,2,2,3,3,4,4,4,4,3,2,2
2,2,2,3,4,4,4,4,4,3,2,2
2,2,2,3,4,4,4,4,3,3,2,2
2,2,2,3,3,3,4,3,3,2,1,1
1,1,2,2,2,3,3,3,2,2,1,1
1,1,1,2,2,2,2,2,2,1,1,1
1,1,1,1,2,2,2,1,1,1,1,1
1,1,1,1,1,2,1,1,1,1,1,1
endlayer

layer
1,1,1,1,1,1,1,2,1,1,1,1
1,1,1,1,1,2,2,2,2,1,1,1
1,1,1,1,2,3,3,3,3,2,1,1
1,1,1,2,3,3,2,2,3,3,2,1
1,2,2,3,3,2,2,2,2,3,2,1
1,2,2,3,2,2,2,2,2,3,2,2
2,2,2,3,3,2,2,2,3,3,2,1
1,2,2,3,3,3,2,3,3,2,1,1
1,1,2,2,2,3,3,3,2,1,1,1
1,1,1,2,2,2,2,2,2,1,1,1
1,1,1,1,2,2,2,1,1,1,1,1
1,1,1,1,1,1,1,1,1,1,1,1
endlayer

layer
1,1,1,1,1,1,1,2,1,1,1,1
1,1,1,1,1,2,2,5,2,1,1,1
1,1,1,1,2,5,5,5,5,2,1,1
1,1,1,2,5,6,5,5,5,5,2,1
1,1,2,5,5,5,5,5,5,5,2,1
1,2,2,5,5,5,5,5,5,5,5,2
1,2,5,5,5,5,5,5,5,5,2,1
1,1,2,5,5,5,5,6,5,2,1,1
1,1,1,2,2,5,5,5,2,1,1,1
1,1,1,2,2,2,5,2,1,1,1,1
1,1,1,1,1,2,2,1,1,1,1,1
1,1,1,1,1,1,1,1,1,1,1,1
endlayer

layer
1,1,1,1,1,1,1,1,1,1,1,1
1,1,1,1,1,1,1,7,1,1,1,1
1,1,1,1,1,7,7,7,7,1,1,1
1,1,1,1,7,6,7,7,7,7,1,1
1,1,1,7,7,7,7,7,7,7,1,1
1,1,1,7,7,7,7,7,7,7,7,1
1,1,7,7,7,7,7,7,7,7,1,1
1,1,1,7,7,7,7,6,7,1,1,1
1,1,1,1,1,7,7,7,1,1,1,1
1,1,1,1,1,1,7,1,1,1,1,1
1,1,1,1,1,1,1,1,1,1,1,1
1,1,1,1,1,1,1,1,1,1,1,1
endlayer

layer
1,1,1,1,1,1,1,1,1,1,1,1
1,1,1,1,1,1,1,1,1,1,1,1
1,1,1,1,1,1,1,1,1,1,1,1
1,1,1,1,1,6,1,1,1,1,1,1
1,1,1,1,1,1,1,1,1,1,1,1
1,1,1,1,1,1,1,1,1,1,1,1
1,1,1,1,1,1,1,1,1,1,1,1
1,1,1,1,1,1,1,6,1,1,1,1
1,1,1,1,1,1,1,1,1,1,1,1
1,1,1,1,1,1,1,1,1,1,1,1
1,1,1,1,1,1,1,1,1,1,1,1
1,1,1,1,1,1,1,1,1,1,1,1
endlayer

layer
1,1,1,1,1,1,1,1,1,1,1,1
1,1,1,1,1,1,1,1,1,1,1,1
1,1,1,1,1,1,1,1,1,1,1,1
1,1,1,1,1,6,1,1,1,1,1,1
1,1,1,1,1,1,1,1,1,1,1,1
1,1,1,1,1,1,1,1,1,1,1,1
1,1,1,1,1,1,1,1,1,1,1,1
1,1,1,1,1,1,1,6,1,1,1,1
1,1,1,1,1,1,1,1,1,1,1,1
1,1,1,1,1,1,1,1,1,1,1,1
1,1,1,1,1,1,1,1,1,1,1,1
1,1,1,1,1,1,1,1,1,1,1,1
endlayer

layer
1,1,1,1,1,1,1,1,1,1,1,1
1,1,1,1,1,1,1,1,1,1,1,1
1,1,1,1,1,1,1,1,1,1,1,1
1,1,1,1,8,8,1,1,1,1,1,1
1,1,1,1,1,1,1,1,1,1,1,1
1,1,1,1,1,1,1,1,1,1,1,1
1,1,1,1,1,1,1,1,1,1,1,1
1,1,1,1,1,1,1,6,1,1,1,1
1,1,1,1,1,1,1,1,1,1,1,1
1,1,1,1,1,1,1,1,1,1,1,1
1,1,1,1,1,1,1,1,1,1,1,1
1,1,1,1,1,1,1,1,1,1,1,1
endlayer

layer
1,1,1,1,1,1,1,1,1,1,1,1
1,1,1,1,1,1,1,1,1,1,1,1
1,1,1,1,1,1,1,1,1,1,1,1
1,1,1,1,6,1,1,1,1,1,1,1
1,1,1,1,1,1,1,1,1,1,1,1
1,1,1,1,1,1,1,1,1,1,1,1
1,1,1,1,1,1,1,1,1,1,1,1
1,1,1,1,1,1,1,8,1,1,1,1
1,1,1,1,1,1,1,8,1,1,1,1
1,1,1,1,1,1,1,1,1,1,1,1
1,1,1,1,1,1,1,1,1,1,1,1
1,1,1,1,1,1,1,1,1,1,1,1
endlayer

layer
1,1,9,1,1,1,9,1,1,1,1,1
1,1,1,1,1,1,1,1,1,1,1,1
1,1,1,1,1,1,1,1,1,1,1,1
9,9,1,1,6,1,1,9,9,1,1,1
1,1,1,1,1,1,1,1,1,1,1,1
1,1,1,1,1,1,1,1,1,1,1,1
1,1,9,1,1,1,9,1,1,1,1,1
1,1,1,1,1,1,1,1,1,1,1,1
1,1,1,1,1,1,1,6,1,1,1,1
1,1,1,1,1,1,1,1,1,1,1,1
1,1,1,1,1,1,1,1,1,1,1,1
1,1,1,1,1,1,1,1,1,1,1,1
endlayer

layer
1,1,9,1,1,1,9,1,1,1,1,1
1,1,1,9,1,9,1,1,1,1,1,1
1,1,1,9,9,9,1,1,1,1,1,1
1,1,9,9,6,9,9,1,1,1,1,1
1,1,1,9,9,9,1,1,1,1,1,1
1,1,1,9,1,9,1,1,1,1,1,1
1,1,9,1,1,1,9,1,1,1,1,1
1,1,1,1,1,1,1,1,1,1,1,1
1,1,1,1,1,1,1,6,1,1,1,1
1,1,1,1,1,1,1,1,1,1,1,1
1,1,1,1,1,1,1,1,1,1,1,1
1,1,1,1,1,1,1,1,1,1,1,1
endlayer

layer
1,1,1,1,1,1,1,1,1,1,1,1
1,1,1,1,1,1,1,1,1,1,1,1
1,1,1,1,9,1,1,1,1,1,1,1
1,1,1,9,9,9,1,1,1,1,1,1
1,1,1,1,9,1,1,1,1,1,1,1
1,1,1,1,1,1,1,1,1,1,1,1
1,1,1,1,1,1,1,1,1,1,1,1
1,1,1,1,1,1,1,1,1,1,1,1
1,1,1,1,1,1,1,6,1,1,1,1
1,1,1,1,1,1,1,1,1,1,1,1
1,1,1,1,1,1,1,1,1,1,1,1
1,1,1,1,1,1,1,1,1,1,1,1
endlayer

layer
1,1,1,1,1,1,1,1,1,1,1,1
1,1,1,1,1,1,1,1,1,1,1,1
1,1,1,1,1,1,1,1,1,1,1,1
1,1,1,1,1,1,1,1,1,1,1,1
1,1,1,1,1,1,1,1,1,1,1,1
1,1,1,1,1,9,1,1,1,9,1,1
1,1,1,1,1,1,1,1,1,1,1,1
1,1,1,1,1,1,1,1,1,1,1,1
1,1,1,9,9,1,1,6,1,1,9,9
1,1,1,1,1,1,1,1,1,1,1,1
1,1,1,1,1,1,1,1,1,1,1,1
1,1,1,1,1,9,1,1,1,9,1,1
endlayer

layer
1,1,1,1,1,1,1,1,1,1,1,1
1,1,1,1,1,1,1,1,1,1,1,1
1,1,1,1,1,1,1,1,1,1,1,1
1,1,1,1,1,1,1,1,1,1,1,1
1,1,1,1,1,1,1,1,1,1,1,1
1,1,1,1,1,9,1,1,1,9,1,1
1,1,1,1,1,1,9,1,9,1,1,1
1,1,1,1,1,1,9,9,9,1,1,1
1,1,1,1,1,9,9,9,9,9,1,1
1,1,1,1,1,1,9,9,9,1,1,1
1,1,1,1,1,1,9,1,9,1,1,1
1,1,1,1,1,9,1,1,1,9,1,1
endlayer

layer
1,1,1,1,1,1,1,1,1,1,1,1
1,1,1,1,1,1,1,1,1,1,1,1
1,1,1,1,1,1,1,1,1,1,1,1
1,1,1,1,1,1,1,1,1,1,1,1
1,1,1,1,1,1,1,1,1,1,1,1
1,1,1,1,1,1,1,1,1,1,1,1
1,1,1,1,1,1,1,1,1,1,1,1
1,1,1,1,1,1,1,9,1,1,1,1
1,1,1,1,1,1,9,9,9,1,1,1
1,1,1,1,1,1,1,9,1,1,1,1
1,1,1,1,1,1,1,1,1,1,1,1
1,1,1,1,1,1,1,1,1,1,1,1
endlayer



