# GiantClam -- 13 Oct 2014
# Created by Ruins mod version 13.8 Ingame Parser
# authoring Player: Jordan_Greywolf
# Updated for MC 1.8: 22 Jul 2015
# Updated for MC 1.11: 13 Jan 2017
# Verified for MC 1.12: 21 Jun 2017
# Updated to MC 1.12.1: 10 Sep 2017
# Last Updated: 8 Dec 2018

biomesToSpawnIn=deep ocean,ocean,oceanic abyss,kelp forest,coral reef,kelp_forest,coral_reef,ocean oil field,rwg_oceanhot,rwg_oceantemperate,rwg_oceanwet,deep_ocean
biomeTypesToSpawnIn=OCEAN

weight=1
embed_into_distance=1
acceptable_target_blocks=sand,clay,gravel,stone,dirt,grass,sandstone


dimensions=7,7,9
allowable_overhang=60
max_leveling=2
leveling_buffer=-1
preserve_water=1
preserve_lava=0

rule1=0,100,preserveBlock
rule2=0,100,minecraft:hardened_clay-0
rule3=0,100,minecraft:stained_hardened_clay-0

# The "Pearl"
rule4=0,100,minecraft:quartz_block-0,minecraft:sea_lantern,minecraft:glowstone

layer
1,1,1,1,1,1,1,1,1
1,1,1,1,1,1,1,1,1
1,1,2,2,2,2,2,1,1
1,2,2,2,2,2,2,2,1
1,1,2,2,2,2,2,1,1
1,1,1,1,1,1,1,1,1
1,1,1,1,1,1,1,1,1
endlayer

layer
1,1,1,2,2,2,1,1,1
1,1,2,2,2,2,2,1,1
1,2,0,3,3,3,0,2,1
2,0,3,3,3,3,3,0,2
2,2,0,3,3,3,0,2,2
1,2,2,2,2,2,2,2,1
1,1,1,2,1,2,1,1,1
endlayer

layer
1,1,2,2,2,2,2,1,1
1,0,0,3,3,3,0,0,1
0,0,0,3,0,3,0,0,0
2,0,0,0,4,0,0,0,2
2,0,0,0,0,0,0,0,2
0,0,0,0,0,0,0,0,0
1,0,2,0,2,0,2,0,1
endlayer

layer
1,0,0,0,2,0,0,0,1
0,0,2,2,2,2,2,0,0
0,0,0,0,3,0,0,0,0
0,0,0,0,0,0,0,0,0
0,0,0,0,0,0,0,0,0
0,0,0,0,0,0,0,0,0
0,0,0,0,0,0,0,0,0
endlayer

layer
0,0,0,0,0,0,0,0,0
0,0,0,2,2,2,0,0,0
0,2,2,0,3,0,2,2,0
0,0,0,0,0,0,0,0,0
0,0,0,0,0,0,0,0,0
0,0,0,0,0,0,0,0,0
0,0,0,0,0,0,0,0,0
endlayer

layer
0,0,0,0,0,0,0,0,0
0,0,0,2,2,2,0,0,0
0,2,2,2,2,2,2,2,0
2,2,2,2,2,2,2,2,2
0,0,0,0,0,0,0,0,0
0,0,0,0,0,0,0,0,0
0,0,0,0,0,0,0,0,0
endlayer

layer
0,0,0,0,0,0,0,0,0
0,0,0,0,0,0,0,0,0
0,0,2,0,2,0,2,0,0
0,2,2,2,2,2,2,2,0
0,2,0,2,0,2,0,2,0
0,0,0,0,0,0,0,0,0
0,0,0,0,0,0,0,0,0
endlayer

