# Overturned Sailing Ship
# Created by Ruins mod version 12.3 Ingame Parser
# authoring Player: Jordan_Greywolf
# Originally Converted to 1.5.2 - 2 Apr 2014
# Overturned Sunken Version for MC 1.12: 6 Jul 2018
# Last Updated: 8 Dec 2018

biomesToSpawnIn=coral reef,coral_reef,deep ocean,deep_ocean,kelp forest,kelp_forest,ocean,ocean oil field,ocean_oil_field,oceanic abyss,oceanic_abyss,rwg_oceanhot,rwg_oceantemperate,rwg_oceanwet
biomeTypesToSpawnIn=OCEAN

uniqueMinDistance=1000

weight=1
embed_into_distance=3
acceptable_target_blocks=

unacceptable_target_blocks=lava,flowing_lava,cloud,Natura:Cloud,slime_congealed,slime_dirt,slime_grass,command_block,ice,packed_ice,blue_ice,snow

dimensions=14,34,15
allowable_overhang=99
max_leveling=16
leveling_buffer=-1
preserve_water=1
preserve_lava=0

rule1=0,100,preserveBlock

rule2=0,100,minecraft:double_wooden_slab-1
rule3=0,100,minecraft:log-5

# Rotten Sails
rule4=0,100,minecraft:wool-13,minecraft:wool-7,minecraft:wool-15,minecraft:wool-12

rule5=0,100,minecraft:log-1
rule6=0,100,minecraft:ladder-4
rule7=0,100,minecraft:redstone_lamp-0
rule8=0,100,minecraft:wooden_slab-9
rule9=0,100,minecraft:spruce_fence-0
rule10=0,100,minecraft:planks-1
rule11=0,100,minecraft:spruce_stairs-0
rule12=0,100,minecraft:log-9
rule13=0,100,minecraft:spruce_stairs-4
rule14=0,100,minecraft:spruce_stairs-5

# Cabin Window Panes
rule15=0,100,minecraft:stained_glass_pane-4,minecraft:stained_glass_pane-1

# Air Pockets
rule16=0,100,minecraft:air-0

# Pirate Summon
rule17=0,100,CommandBlock:RUINSTRIGGER /summon zombie_villager ~0 ~0 ~0 {HandItems:[{Count:1,id:iron_sword,tag:{display:{Name:"Rusty Cutlass"}}},{}],ArmorItems:[{Count:1,id:leather_boots,tag:{display:{color:0}}},{},{Count:1,id:leather_chestplate,tag:{display:{color:14540253}}},{Count:1,id:skull,Damage:2}],Health:30.0f,HandDropChances:[0.5F,0.0F],ArmorDropChances:[0.2F,0.2F,0.2F,0.2F],CanPickUpLoot:1,Silent:1,PersistenceRequired:1}:@

rule18=0,100,ChestGenHook:chests/simple_dungeon:5-2
rule19=0,100,Skull:0:2-1

# "Globe"
rule20=0,100,minecraft:lapis_block-0

rule21=0,100,minecraft:spruce_stairs-1
rule22=0,100,minecraft:spruce_door-2
rule23=0,100,minecraft:spruce_door-9
rule24=0,100,minecraft:spruce_stairs-6
rule25=0,100,minecraft:spruce_stairs-7
rule26=0,100,minecraft:trapdoor-11
rule27=0,100,minecraft:trapdoor-10

# Overturned Cargo/Debris
rule28=0,100,minecraft:noteblock-0,ChestGenHook:chests/spawn_bonus_chest:5-2,minecraft:hay_block-0,minecraft:flower_pot,minecraft:wool-11


rule29=0,100,MobSpawner:Zombie
rule30=0,100,minecraft:wooden_slab-1
rule31=0,100,minecraft:spruce_door-8

layer
1,1,1,1,1,1,1,1,1,1,1,1,1,1,1
1,1,1,1,1,1,1,1,1,1,1,1,1,1,1
1,1,1,1,1,1,1,1,1,1,1,1,1,1,1
1,1,1,1,1,1,1,1,1,1,1,1,1,1,1
1,1,1,1,1,1,1,1,1,1,1,1,1,1,1
1,1,1,1,1,1,1,4,1,1,1,1,1,1,1
1,1,1,1,1,1,1,1,1,1,1,1,1,1,1
1,1,1,1,1,1,1,1,1,1,1,1,1,1,1
1,1,1,1,1,1,1,5,1,1,1,1,1,1,1
1,1,1,1,1,1,1,1,1,1,1,1,1,1,1
1,1,1,1,1,1,1,1,1,1,1,1,1,1,1
1,1,1,1,1,1,1,1,1,1,1,1,1,1,1
1,1,1,1,1,1,1,1,1,1,1,1,1,1,1
1,1,1,1,1,1,1,1,1,1,1,1,1,1,1
1,1,1,1,1,1,1,5,1,1,1,1,1,1,1
1,1,1,1,1,4,1,1,1,1,1,1,1,1,1
1,1,1,1,1,1,1,4,1,1,1,1,1,1,1
1,1,1,1,1,1,1,1,1,1,1,1,1,1,1
1,1,1,1,1,1,1,1,1,1,1,1,1,1,1
1,1,1,1,1,1,1,5,1,1,1,1,1,1,1
1,1,1,1,1,1,1,1,1,4,1,1,1,1,1
1,1,1,1,1,1,4,1,1,1,1,1,1,1,1
1,1,1,1,1,1,1,1,1,1,1,1,1,1,1
1,1,1,1,1,1,1,1,1,1,1,1,1,1,1
1,1,1,1,1,1,1,5,1,1,1,1,1,1,1
1,1,1,1,1,1,1,1,1,1,1,1,1,1,1
1,1,1,1,1,1,1,1,1,1,1,1,1,1,1
1,1,1,1,1,1,1,1,1,1,1,1,1,1,1
1,1,1,1,1,1,4,1,1,1,1,1,1,1,1
1,1,1,1,1,1,1,1,1,1,1,1,1,1,1
1,1,1,1,1,1,1,1,1,1,1,1,1,1,1
1,1,1,1,1,1,1,1,1,1,1,1,1,1,1
1,1,1,1,1,1,1,1,1,1,1,1,1,1,1
1,1,1,1,1,1,1,1,1,1,1,1,1,1,1
endlayer


layer
1,1,1,1,1,1,1,1,1,1,1,1,1,1,1
1,1,1,1,1,1,1,1,1,1,1,1,1,1,1
1,1,1,1,1,1,1,1,1,1,1,1,1,1,1
1,1,1,1,1,1,1,4,1,1,1,1,1,1,1
1,1,1,1,1,1,1,1,1,1,1,1,1,1,1
1,1,1,1,1,1,1,4,1,1,1,1,1,1,1
1,1,1,1,1,1,1,1,1,1,1,1,1,1,1
1,1,1,1,1,1,1,1,1,1,1,1,1,1,1
1,1,1,1,1,1,1,5,1,1,1,1,1,1,1
1,1,1,1,1,1,1,1,1,1,1,1,1,1,1
1,1,1,1,1,1,1,1,1,1,1,1,1,1,1
1,1,1,1,1,1,1,1,1,1,1,1,1,1,1
1,1,1,1,1,1,1,1,1,1,1,1,1,1,1
1,1,1,1,1,1,1,1,1,1,1,1,1,1,1
1,1,1,1,1,1,1,5,1,1,1,1,1,1,1
1,1,1,1,1,4,1,1,1,4,1,1,1,1,1
1,1,1,1,1,1,1,4,4,1,1,1,1,1,1
1,1,1,1,1,1,1,1,1,1,1,1,1,1,1
1,1,1,1,1,1,1,1,1,1,1,1,1,1,1
1,1,1,1,1,1,1,5,1,1,1,1,1,1,1
1,1,1,1,1,4,1,1,1,4,1,1,1,1,1
1,1,1,1,1,1,4,4,1,1,1,1,1,1,1
1,1,1,1,1,1,1,1,1,1,1,1,1,1,1
1,1,1,1,1,1,1,1,1,1,1,1,1,1,1
1,1,1,1,1,1,1,5,1,1,1,1,1,1,1
1,1,1,1,1,1,1,1,1,1,1,1,1,1,1
1,1,1,1,1,1,1,1,1,1,1,1,1,1,1
1,1,1,1,1,1,1,1,1,1,1,1,1,1,1
1,1,1,1,1,1,4,1,1,1,1,1,1,1,1
1,1,1,1,1,1,1,1,1,1,1,1,1,1,1
1,1,1,1,1,1,1,1,1,1,1,1,1,1,1
1,1,1,1,1,1,1,1,1,1,1,1,1,1,1
1,1,1,1,1,1,1,1,1,1,1,1,1,1,1
1,1,1,1,1,1,1,1,1,1,1,1,1,1,1
endlayer


layer
1,1,1,1,1,1,1,1,1,1,1,1,1,1,1
1,1,1,1,1,1,4,1,1,1,1,1,1,1,1
1,1,1,1,1,1,1,4,1,1,1,1,1,1,1
1,1,1,1,1,1,1,4,1,1,1,1,1,1,1
1,1,1,1,1,1,1,1,1,1,1,1,1,1,1
1,1,1,1,1,1,1,4,1,1,1,1,1,1,1
1,1,1,1,1,1,1,4,1,1,1,1,1,1,1
1,1,1,1,1,1,4,1,1,1,1,1,1,1,1
1,1,1,1,1,1,1,5,1,1,1,1,1,1,1
1,1,1,1,1,1,1,1,1,1,1,1,1,1,1
1,1,1,1,1,1,1,1,1,1,1,1,1,1,1
1,1,1,1,1,1,1,1,1,1,1,1,1,1,1
1,1,1,1,1,1,1,1,1,1,1,1,1,1,1
1,1,1,1,1,1,1,1,1,1,1,1,1,1,1
1,1,1,1,1,1,1,5,1,1,1,1,1,1,1
1,1,1,4,1,4,1,1,1,4,1,4,1,1,1
1,1,1,1,1,1,4,4,4,1,1,1,1,1,1
1,1,1,1,1,1,1,1,1,1,1,1,1,1,1
1,1,1,1,1,1,1,1,1,1,1,1,1,1,1
1,1,1,1,1,1,1,5,1,1,1,1,1,1,1
1,1,1,1,4,4,1,1,1,4,4,1,1,1,1
1,1,1,1,1,1,4,4,4,1,1,1,1,1,1
1,1,1,1,1,1,1,1,1,1,1,1,1,1,1
1,1,1,1,1,1,1,1,1,1,1,1,1,1,1
1,1,1,1,1,1,1,5,1,1,1,1,1,1,1
1,1,1,1,1,1,1,1,1,1,1,1,1,1,1
1,1,1,1,1,1,1,1,1,1,1,1,1,1,1
1,1,1,1,1,1,4,1,1,1,1,1,1,1,1
1,1,1,1,1,1,4,1,1,1,1,1,1,1,1
1,1,1,1,1,1,1,1,1,1,1,1,1,1,1
1,1,1,1,1,1,4,1,1,1,1,1,1,1,1
1,1,1,1,1,1,1,1,1,1,1,1,1,1,1
1,1,1,1,1,1,1,1,1,1,1,1,1,1,1
1,1,1,1,1,1,1,1,1,1,1,1,1,1,1
endlayer


layer
1,1,1,1,1,1,1,2,1,1,1,1,1,1,1
1,1,1,1,1,1,4,3,1,1,1,1,1,1,1
1,1,1,1,1,1,1,3,1,1,1,1,1,1,1
1,1,1,1,1,1,1,3,1,1,1,1,1,1,1
1,1,1,1,1,1,1,3,1,1,1,1,1,1,1
1,1,1,1,1,1,1,3,1,1,1,1,1,1,1
1,1,1,1,1,1,1,3,1,1,1,1,1,1,1
1,1,1,1,1,1,4,3,1,1,1,1,1,1,1
1,1,1,1,1,1,1,5,1,1,1,1,1,1,1
1,1,1,1,1,1,1,1,1,1,1,1,1,1,1
1,1,1,1,1,1,1,1,1,1,1,1,1,1,1
1,1,1,1,1,1,1,1,1,1,1,1,1,1,1
1,1,1,1,1,1,1,1,1,1,1,1,1,1,1
1,1,1,1,1,1,1,1,1,1,1,1,1,1,1
1,1,1,1,1,1,1,5,1,1,1,1,1,1,1
1,1,1,4,4,4,1,1,1,4,4,4,1,1,1
1,1,1,4,4,4,4,4,4,4,4,4,1,1,1
1,1,1,1,1,1,1,1,1,1,1,1,1,1,1
1,1,1,1,1,1,1,1,1,1,1,1,1,1,1
1,1,1,1,1,1,1,5,1,1,1,1,1,1,1
1,1,1,4,4,4,1,1,1,4,4,4,1,1,1
1,1,1,4,4,4,4,4,4,4,4,4,1,1,1
1,1,1,1,1,1,1,1,1,1,1,1,1,1,1
1,1,1,1,1,1,1,1,1,1,1,1,1,1,1
1,1,1,1,1,1,1,5,1,1,1,1,1,1,1
1,1,1,1,1,1,1,1,1,1,1,1,1,1,1
1,1,1,1,1,1,4,1,1,1,1,1,1,1,1
1,1,1,1,1,1,4,1,1,1,1,1,1,1,1
1,1,1,1,1,1,4,1,1,1,1,1,1,1,1
1,1,1,1,1,1,4,1,1,1,1,1,1,1,1
1,1,1,1,1,1,4,1,1,1,1,1,1,1,1
1,1,1,1,1,1,1,1,1,1,1,1,1,1,1
1,1,1,1,1,1,1,1,1,1,1,1,1,1,1
1,1,1,1,1,1,1,1,1,1,1,1,1,1,1
endlayer

layer
1,1,1,1,1,1,1,1,1,1,1,1,1,1,1
1,1,1,1,1,1,1,1,1,1,1,1,1,1,1
1,1,1,1,1,1,1,1,1,1,1,1,1,1,1
1,1,1,1,1,1,1,1,1,1,1,1,1,1,1
1,1,1,1,1,1,1,1,1,1,1,1,1,1,1
1,1,1,1,1,1,1,1,1,1,1,1,1,1,1
1,1,1,1,1,1,1,1,1,1,1,1,1,1,1
1,1,1,1,1,1,1,1,1,1,1,1,1,1,1
1,1,1,1,1,1,1,5,1,1,1,1,1,1,1
1,1,1,1,1,1,1,1,1,1,1,1,1,1,1
1,1,1,1,1,1,1,1,1,1,1,1,1,1,1
1,1,1,1,1,1,1,1,1,1,1,1,1,1,1
1,1,1,1,1,1,1,1,1,1,1,1,1,1,1
1,1,1,1,1,1,1,1,1,1,1,1,1,1,1
1,1,1,1,1,1,1,5,1,1,1,1,1,1,1
1,1,4,4,4,4,4,4,4,4,4,4,4,1,1
1,1,1,1,1,1,1,1,1,1,1,1,1,1,1
1,1,1,1,1,1,1,1,1,1,1,1,1,1,1
1,1,1,1,1,1,1,1,1,1,1,1,1,1,1
1,1,1,1,1,1,1,5,1,1,1,1,1,1,1
1,1,4,4,4,4,4,4,4,4,4,4,4,1,1
1,1,1,1,1,1,4,4,4,1,1,1,1,1,1
1,1,1,1,1,1,1,1,1,1,1,1,1,1,1
1,1,1,1,1,1,1,1,1,1,1,1,1,1,1
1,1,1,1,1,1,1,5,1,1,1,1,1,1,1
1,1,1,1,1,1,1,1,1,1,1,1,1,1,1
1,1,1,1,1,1,4,1,1,1,1,1,1,1,1
1,1,1,1,1,1,4,1,1,1,1,1,1,1,1
1,1,1,1,1,1,4,1,1,1,1,1,1,1,1
1,1,1,1,1,1,4,1,1,1,1,1,1,1,1
1,1,1,1,1,1,4,1,1,1,1,1,1,1,1
1,1,1,1,1,1,1,1,1,1,1,1,1,1,1
1,1,1,1,1,1,1,1,1,1,1,1,1,1,1
1,1,1,1,1,1,1,1,1,1,1,1,1,1,1
endlayer

layer
1,1,1,1,1,1,1,1,1,1,1,1,1,1,1
1,1,1,1,1,1,1,1,1,1,1,1,1,1,1
1,1,1,1,1,1,1,1,1,1,1,1,1,1,1
1,1,7,1,1,2,8,8,8,2,1,1,7,1,1
1,1,1,1,1,1,1,1,1,1,1,1,1,1,1
1,1,1,1,1,1,1,1,1,1,1,1,1,1,1
1,1,1,1,1,1,1,1,1,1,1,1,1,1,1
1,1,1,1,1,1,1,1,1,1,1,1,1,1,1
1,1,1,1,1,1,1,5,1,1,1,1,1,1,1
1,1,1,1,1,1,1,1,1,1,1,1,1,1,1
1,1,1,1,1,1,1,1,1,1,1,1,1,1,1
1,1,1,1,1,1,1,1,1,1,1,1,1,1,1
1,1,1,1,1,1,1,1,1,1,1,1,1,1,1
1,1,1,1,1,1,1,6,1,1,1,1,1,1,1
1,1,1,1,1,1,1,5,1,1,1,1,1,1,1
1,1,4,1,1,1,1,1,1,1,1,1,4,1,1
1,1,1,1,1,1,1,1,1,1,1,1,1,1,1
1,1,1,1,1,1,1,1,1,1,1,1,1,1,1
1,1,1,1,1,1,1,6,1,1,1,1,1,1,1
1,1,1,1,1,1,1,5,1,1,1,1,1,1,1
1,1,4,1,1,1,1,1,1,1,1,1,4,1,1
1,1,1,1,1,1,1,1,1,1,1,1,1,1,1
1,1,1,1,1,1,1,1,1,1,1,1,1,1,1
1,1,1,1,1,1,1,6,1,1,1,1,1,1,1
1,1,1,1,1,1,1,5,1,1,1,1,1,1,1
1,1,1,1,1,1,4,1,1,1,1,1,1,1,1
1,1,1,1,1,1,4,1,1,1,1,1,1,1,1
1,1,1,1,1,1,1,1,1,1,1,1,1,1,1
1,1,1,1,1,1,1,1,1,1,1,1,1,1,1
1,1,1,1,1,1,4,1,1,1,1,1,1,1,1
1,1,1,1,1,1,4,1,1,1,1,1,1,1,1
1,1,1,1,1,1,1,1,1,1,1,1,1,1,1
1,1,1,1,1,1,1,1,1,1,1,1,1,1,1
1,1,1,1,1,1,1,1,1,1,1,1,1,1,1
endlayer

layer
1,1,1,1,1,1,1,1,1,1,1,1,1,1,1
1,1,1,1,1,1,1,1,1,1,1,1,1,1,1
1,1,1,1,1,1,1,1,1,1,1,1,1,1,1
1,1,9,9,9,10,11,11,11,10,9,9,9,1,1
1,1,9,1,1,1,1,10,1,1,1,1,9,1,1
1,1,9,1,1,1,1,1,1,1,1,1,9,1,1
1,1,9,1,1,1,1,1,1,1,1,1,9,1,1
1,1,9,1,1,1,1,1,1,1,1,1,9,1,1
1,1,9,9,1,9,9,5,9,9,1,9,9,1,1
1,1,1,1,1,1,1,1,1,1,1,1,1,1,1
1,1,1,1,1,1,1,1,1,1,1,1,1,1,1
1,1,1,1,1,1,1,1,1,1,1,1,1,1,1
1,1,1,1,1,1,1,1,1,1,1,1,1,1,1
1,1,1,1,1,1,1,6,1,1,1,1,1,1,1
12,12,12,12,12,12,12,5,12,12,12,12,12,12,12
1,4,1,1,1,1,1,9,1,1,1,1,1,4,1
1,1,1,1,1,1,1,1,1,1,1,1,1,1,1
1,1,1,1,1,1,1,1,1,1,1,1,1,1,1
1,1,1,1,1,1,1,6,1,1,1,1,1,1,1
12,12,12,12,12,12,12,5,12,12,12,12,12,12,12
1,4,1,1,1,1,1,9,1,1,1,1,1,4,1
1,1,1,1,1,1,1,1,1,1,1,1,1,1,1
1,1,1,1,1,1,1,1,1,1,1,1,1,1,1
1,1,1,1,1,1,1,6,1,1,1,1,1,1,1
1,1,1,1,1,1,1,5,1,1,1,1,1,1,1
1,1,1,1,1,1,4,1,1,1,1,1,1,1,1
1,1,1,1,1,1,1,1,1,1,1,1,1,1,1
1,1,1,1,1,1,1,1,1,1,1,1,1,1,1
1,1,1,1,1,1,1,1,1,1,1,1,1,1,1
1,1,1,1,1,1,1,1,1,1,1,1,1,1,1
1,1,1,1,1,1,4,1,1,1,1,1,1,1,1
1,1,1,1,1,1,1,1,1,1,1,1,1,1,1
1,1,1,1,1,1,1,1,1,1,1,1,1,1,1
1,1,1,1,1,1,1,1,1,1,1,1,1,1,1
endlayer

layer
1,1,1,1,1,1,1,1,1,1,1,1,1,1,1
1,1,1,1,1,1,1,1,1,1,1,1,1,1,1
1,1,1,1,1,1,1,1,1,1,1,1,1,1,1
1,1,10,10,10,10,10,10,10,10,10,10,10,1,1
1,1,10,8,8,8,8,10,8,8,8,8,10,1,1
1,1,10,8,8,8,8,8,8,8,8,8,10,1,1
1,1,10,8,8,8,8,8,8,8,8,8,10,1,1
1,1,10,8,8,8,8,13,8,8,8,8,10,1,1
1,1,10,10,1,10,10,14,10,10,1,10,10,1,1
1,1,1,1,1,1,1,1,1,1,1,1,1,1,1
1,1,1,1,1,1,1,1,1,1,1,1,1,1,1
1,1,1,1,1,1,1,1,1,1,1,1,1,1,1
1,1,1,1,1,1,1,1,1,1,1,1,1,1,1
1,1,1,1,1,1,1,6,1,1,1,1,1,1,1
1,1,1,1,1,1,1,5,1,1,1,1,1,1,1
1,1,1,1,1,1,1,7,1,1,1,1,1,1,1
1,1,1,1,1,1,1,1,1,1,1,1,1,1,1
1,1,1,1,1,1,1,1,1,1,1,1,1,1,1
1,1,1,1,1,1,1,6,1,1,1,1,1,1,1
1,1,1,1,1,1,1,5,1,1,1,1,1,1,1
1,1,1,1,1,1,1,7,1,1,1,1,1,1,1
1,1,1,1,1,1,1,1,1,1,1,1,1,1,1
1,1,1,1,1,1,1,1,1,1,1,1,1,1,1
1,1,1,1,1,1,1,6,1,1,1,1,1,1,1
1,1,1,1,1,1,1,5,1,1,1,1,1,1,1
1,1,1,1,1,1,4,3,1,1,1,1,1,1,1
1,1,1,1,1,1,1,3,1,1,1,1,1,1,1
1,1,1,1,1,1,1,3,1,1,1,1,1,1,1
1,1,1,1,1,1,7,3,7,1,1,1,1,1,1
1,1,1,1,1,1,1,3,1,1,1,1,1,1,1
1,1,1,1,1,1,1,3,1,1,1,1,1,1,1
1,1,1,1,1,1,4,3,1,1,1,1,1,1,1
1,1,1,1,1,1,1,3,1,1,1,1,1,1,1
1,1,1,1,1,1,1,3,1,1,1,1,1,1,1
endlayer

layer
1,1,1,1,1,1,1,1,1,1,1,1,1,1,1
1,1,1,1,1,1,1,1,1,1,1,1,1,1,1
1,1,1,1,1,1,1,7,1,1,1,1,1,1,1
1,1,10,15,15,15,10,10,10,15,15,15,10,1,1
1,1,15,19,17,18,16,7,16,16,17,16,15,1,1
1,1,15,17,16,16,16,16,16,20,16,16,15,1,1
1,1,15,18,16,16,16,16,16,16,16,16,15,1,1
1,1,15,16,16,7,16,16,16,7,16,16,15,1,1
1,1,10,10,21,10,10,22,10,10,21,10,10,1,1
1,1,1,9,1,1,1,1,1,1,1,9,1,1,1
1,1,1,9,1,1,1,1,1,1,1,9,1,1,1
1,1,1,9,1,1,1,1,1,1,1,9,1,1,1
1,1,1,9,1,1,1,1,1,1,1,9,1,1,1
1,1,1,9,1,1,1,6,1,1,1,9,1,1,1
1,1,1,9,1,1,1,5,1,1,1,9,1,1,1
1,1,1,9,1,1,1,1,1,1,1,9,1,1,1
1,1,1,9,1,1,1,1,16,1,1,9,1,1,1
1,1,1,9,1,1,1,1,1,1,1,9,1,1,1
1,1,1,9,1,1,1,6,1,1,1,9,1,1,1
1,1,1,9,1,1,1,5,1,1,1,9,1,1,1
1,1,1,9,1,1,1,1,1,1,1,9,1,1,1
1,1,1,9,1,1,1,1,1,1,1,9,1,1,1
1,1,1,9,1,1,1,1,1,1,1,9,1,1,1
1,1,1,9,1,16,1,6,1,16,1,9,1,1,1
1,1,1,9,9,1,1,5,1,1,9,9,1,1,1
1,1,1,1,9,1,1,1,1,1,9,1,1,1,1
1,1,1,1,9,9,1,1,1,9,9,1,1,1,1
1,1,1,1,1,9,9,1,9,9,1,1,1,1,1
1,1,1,1,1,1,9,1,9,1,1,1,1,1,1
1,1,1,1,1,1,1,1,1,1,1,1,1,1,1
1,1,1,1,1,1,1,1,1,1,1,1,1,1,1
1,1,1,1,1,1,1,1,1,1,1,1,1,1,1
1,1,1,1,1,1,1,1,1,1,1,1,1,1,1
1,1,1,1,1,1,1,1,1,1,1,1,1,1,1
endlayer

layer
1,1,1,1,1,1,1,1,1,1,1,1,1,1,1
1,1,1,1,1,1,1,1,1,1,1,1,1,1,1
1,1,1,1,1,1,1,1,1,1,1,1,1,1,1
1,1,10,15,15,15,10,22,10,15,15,15,10,1,1
1,1,15,16,16,16,16,16,16,16,16,16,15,1,1
1,1,15,16,16,16,16,16,16,16,16,16,15,1,1
1,1,15,16,16,16,16,16,16,16,16,16,15,1,1
1,1,15,16,16,16,16,16,16,16,16,16,15,1,1
1,1,10,10,10,10,10,23,10,10,10,10,10,1,1
1,1,1,25,14,8,8,16,8,8,14,24,1,1,1
1,1,1,25,8,8,8,8,8,8,8,24,1,1,1
1,1,1,25,8,8,26,26,26,8,8,24,1,1,1
1,1,1,25,8,8,27,27,27,8,8,24,1,1,1
1,1,1,25,8,8,8,11,8,8,8,24,1,1,1
1,1,1,25,8,8,8,5,8,8,8,24,1,1,1
1,1,1,25,8,8,8,8,8,8,8,24,1,1,1
1,1,1,25,8,8,26,26,26,8,8,24,1,1,1
1,1,1,25,8,8,27,27,27,8,8,24,1,1,1
1,1,1,25,8,8,8,11,8,8,8,24,1,1,1
1,1,1,25,8,8,8,5,8,8,8,24,1,1,1
1,1,1,25,8,8,8,8,8,8,8,24,1,1,1
1,1,1,25,8,8,26,26,26,8,8,24,1,1,1
1,1,1,25,8,8,27,27,27,8,8,24,1,1,1
1,1,1,25,8,8,8,11,8,8,8,24,1,1,1
1,1,1,25,10,8,8,5,8,8,10,24,1,1,1
1,1,1,1,10,8,8,8,8,8,10,1,1,1,1
1,1,1,1,10,10,8,8,8,10,10,1,1,1,1
1,1,1,1,1,10,10,8,10,10,1,1,1,1,1
1,1,1,1,1,1,10,11,10,1,1,1,1,1,1
1,1,1,1,1,1,1,10,1,1,1,1,1,1,1
1,1,1,1,1,1,1,10,1,1,1,1,1,1,1
1,1,1,1,1,1,1,14,1,1,1,1,1,1,1
1,1,1,1,1,1,1,1,1,1,1,1,1,1,1
1,1,1,1,1,1,1,1,1,1,1,1,1,1,1
endlayer

layer
1,1,1,1,1,1,1,1,1,1,1,1,1,1,1
1,1,1,1,1,9,9,9,9,9,1,1,1,1,1
1,1,1,1,1,9,1,1,1,9,1,1,1,1,1
1,1,10,15,15,15,10,23,10,15,15,15,10,1,1
1,1,15,16,16,16,16,16,16,16,16,16,15,1,1
1,1,15,16,16,16,16,16,16,16,16,16,15,1,1
1,1,15,16,16,16,16,16,16,16,16,16,15,1,1
1,1,15,16,16,16,16,13,16,16,16,16,15,1,1
1,1,10,10,10,22,10,10,10,22,10,10,10,1,1
1,1,1,10,16,16,16,21,16,16,16,10,1,1,1
1,1,1,10,28,16,16,17,16,16,28,10,1,1,1
1,1,1,10,16,16,16,16,16,28,16,10,1,1,1
1,1,1,10,16,28,16,16,16,16,16,10,1,1,1
1,1,1,10,28,16,16,7,16,28,16,10,1,1,1
1,1,1,10,16,28,16,5,16,16,16,10,1,1,1
1,1,1,10,16,16,18,19,16,16,28,10,1,1,1
1,1,1,10,16,16,16,16,16,16,16,10,1,1,1
1,1,1,10,16,16,16,16,16,16,17,10,1,1,1
1,1,1,10,28,16,16,7,16,16,16,10,1,1,1
1,1,1,10,16,16,16,5,16,28,16,10,1,1,1
1,1,1,10,16,16,28,16,16,16,16,10,1,1,1
1,1,1,10,18,16,16,16,16,28,16,10,1,1,1
1,1,1,10,17,16,16,16,16,16,28,10,1,1,1
1,1,1,10,16,28,16,7,16,16,16,10,1,1,1
1,1,1,10,16,16,28,5,16,16,16,10,1,1,1
1,1,1,1,10,18,16,29,28,16,10,1,1,1,1
1,1,1,1,10,16,17,16,16,17,10,1,1,1,1
1,1,1,1,1,10,16,7,16,10,1,1,1,1,1
1,1,1,1,1,1,10,10,10,1,1,1,1,1,1
1,1,1,1,1,1,1,14,1,1,1,1,1,1,1
1,1,1,1,1,1,1,1,1,1,1,1,1,1,1
1,1,1,1,1,1,1,1,1,1,1,1,1,1,1
1,1,1,1,1,1,1,1,1,1,1,1,1,1,1
1,1,1,1,1,1,1,1,1,1,1,1,1,1,1
endlayer

layer
1,1,1,1,1,1,1,1,1,1,1,1,1,1,1
1,1,1,1,1,13,13,13,13,13,1,1,1,1,1
1,1,1,1,1,25,2,2,2,24,1,1,1,1,1
1,1,30,30,30,10,10,10,10,10,30,30,30,1,1
1,1,30,8,8,8,8,8,8,8,8,8,30,1,1
1,1,30,8,10,8,8,8,8,8,10,8,30,1,1
1,1,30,8,10,8,10,10,10,8,10,8,30,1,1
1,1,30,8,8,16,10,10,10,16,8,8,30,1,1
1,1,25,10,10,23,10,10,10,31,10,10,24,1,1
1,1,1,2,16,16,16,7,16,16,16,2,1,1,1
1,1,1,2,16,16,16,16,16,16,16,2,1,1,1
1,1,1,2,16,16,16,16,16,16,16,2,1,1,1
1,1,1,10,24,16,16,16,16,16,25,10,1,1,1
1,1,1,2,16,16,16,16,16,16,16,2,1,1,1
1,1,1,2,16,16,16,5,16,16,16,2,1,1,1
1,1,1,2,16,16,16,16,16,16,16,2,1,1,1
1,1,1,10,24,16,16,16,16,16,25,10,1,1,1
1,1,1,2,16,16,16,16,16,16,16,2,1,1,1
1,1,1,2,16,16,16,16,16,16,16,2,1,1,1
1,1,1,2,16,16,16,5,16,16,16,2,1,1,1
1,1,1,10,24,16,16,16,16,16,25,10,1,1,1
1,1,1,2,16,16,16,16,16,16,16,2,1,1,1
1,1,1,2,16,16,16,16,16,16,16,2,1,1,1
1,1,1,2,16,16,16,16,16,16,16,2,1,1,1
1,1,1,10,24,16,16,5,16,16,25,10,1,1,1
1,1,1,1,10,16,16,16,16,16,10,1,1,1,1
1,1,1,1,10,16,16,16,16,16,10,1,1,1,1
1,1,1,1,1,10,13,10,13,10,1,1,1,1,1
1,1,1,1,1,1,1,14,1,1,1,1,1,1,1
1,1,1,1,1,1,1,1,1,1,1,1,1,1,1
1,1,1,1,1,1,1,1,1,1,1,1,1,1,1
1,1,1,1,1,1,1,1,1,1,1,1,1,1,1
1,1,1,1,1,1,1,1,1,1,1,1,1,1,1
1,1,1,1,1,1,1,1,1,1,1,1,1,1,1
endlayer

layer
1,1,1,1,1,1,1,1,1,1,1,1,1,1,1
1,1,1,1,1,1,1,1,1,1,1,1,1,1,1
1,1,1,1,1,1,1,1,1,1,1,1,1,1,1
1,1,1,1,1,1,1,1,1,1,1,1,1,1,1
1,1,1,1,1,1,1,10,1,1,1,1,1,1,1
1,1,1,1,1,1,10,10,10,1,1,1,1,1,1
1,1,1,1,1,10,16,10,16,10,1,1,1,1,1
1,1,1,1,10,10,10,10,10,10,10,1,1,1,1
1,1,1,1,10,14,10,10,10,14,10,1,1,1,1
1,1,1,1,2,16,16,16,16,16,2,1,1,1,1
1,1,1,1,2,16,16,16,16,16,2,1,1,1,1
1,1,1,1,2,16,16,16,16,16,2,1,1,1,1
1,1,1,1,10,24,16,16,16,25,10,1,1,1,1
1,1,1,1,2,16,16,16,16,16,2,1,1,1,1
1,1,1,1,2,16,16,5,16,16,2,1,1,1,1
1,1,1,1,2,16,16,16,16,16,2,1,1,1,1
1,1,1,1,10,24,16,16,16,25,10,1,1,1,1
1,1,1,1,2,16,16,16,16,16,2,1,1,1,1
1,1,1,1,2,16,16,16,16,16,2,1,1,1,1
1,1,1,1,2,16,16,5,16,16,2,1,1,1,1
1,1,1,1,10,24,16,16,16,25,10,1,1,1,1
1,1,1,1,2,16,16,16,16,16,2,1,1,1,1
1,1,1,1,2,16,16,16,16,16,2,1,1,1,1
1,1,1,1,2,16,16,16,16,16,2,1,1,1,1
1,1,1,1,10,24,16,5,16,25,10,1,1,1,1
1,1,1,1,10,16,16,16,16,16,10,1,1,1,1
1,1,1,1,1,10,16,13,16,10,1,1,1,1,1
1,1,1,1,1,1,10,10,10,1,1,1,1,1,1
1,1,1,1,1,1,1,1,1,1,1,1,1,1,1
1,1,1,1,1,1,1,1,1,1,1,1,1,1,1
1,1,1,1,1,1,1,1,1,1,1,1,1,1,1
1,1,1,1,1,1,1,1,1,1,1,1,1,1,1
1,1,1,1,1,1,1,1,1,1,1,1,1,1,1
1,1,1,1,1,1,1,1,1,1,1,1,1,1,1
endlayer

layer
1,1,1,1,1,1,1,1,1,1,1,1,1,1,1
1,1,1,1,1,1,1,1,1,1,1,1,1,1,1
1,1,1,1,1,1,1,1,1,1,1,1,1,1,1
1,1,1,1,1,1,1,1,1,1,1,1,1,1,1
1,1,1,1,1,1,1,10,1,1,1,1,1,1,1
1,1,1,1,1,1,1,1,1,1,1,1,1,1,1
1,1,1,1,1,1,10,10,10,1,1,1,1,1,1
1,1,1,1,1,10,2,10,2,10,1,1,1,1,1
1,1,1,1,1,10,10,10,10,10,1,1,1,1,1
1,1,1,1,1,2,2,10,2,2,1,1,1,1,1
1,1,1,1,1,2,2,10,2,2,1,1,1,1,1
1,1,1,1,1,2,2,10,2,2,1,1,1,1,1
1,1,1,1,1,10,10,10,10,10,1,1,1,1,1
1,1,1,1,1,2,2,10,2,2,1,1,1,1,1
1,1,1,1,1,2,2,10,2,2,1,1,1,1,1
1,1,1,1,1,2,2,10,2,2,1,1,1,1,1
1,1,1,1,1,10,10,10,10,10,1,1,1,1,1
1,1,1,1,1,2,2,10,2,2,1,1,1,1,1
1,1,1,1,1,2,2,10,2,2,1,1,1,1,1
1,1,1,1,1,2,2,10,2,2,1,1,1,1,1
1,1,1,1,1,10,10,10,10,10,1,1,1,1,1
1,1,1,1,1,2,2,10,2,2,1,1,1,1,1
1,1,1,1,1,2,2,10,2,2,1,1,1,1,1
1,1,1,1,1,2,2,10,2,2,1,1,1,1,1
1,1,1,1,1,10,10,10,10,10,1,1,1,1,1
1,1,1,1,1,10,2,10,2,10,1,1,1,1,1
1,1,1,1,1,1,10,10,10,1,1,1,1,1,1
1,1,1,1,1,1,1,1,1,1,1,1,1,1,1
1,1,1,1,1,1,1,1,1,1,1,1,1,1,1
1,1,1,1,1,1,1,1,1,1,1,1,1,1,1
1,1,1,1,1,1,1,1,1,1,1,1,1,1,1
1,1,1,1,1,1,1,1,1,1,1,1,1,1,1
1,1,1,1,1,1,1,1,1,1,1,1,1,1,1
1,1,1,1,1,1,1,1,1,1,1,1,1,1,1
endlayer

