# SunkenShip_Haunted (3 May 2014)
# Updated to MC 1.7.10, 13 Oct 2014
# Created by Ruins mod version 12.3 Ingame Parser
# authoring Player: Jordan_Greywolf

# Note: Tripwire, signs, and vines used to form "air pockets" where monsters might be
# able to spawn (and player to breathe); tripwire will be washed away upon spawning,
# but may create gap in water.

# Modified to replace tripwire with air pocket exploit.

# Last Updated: 22 Nov 2015
# Updated for MC 1.8: 5 Mar 2016
# Updated for MC 1.9: 26 Apr 2016
# Updated for MC 1.11: 13 Jan 2017
# Updated for MC 1.12: 21 Jun 2017
# Updated to MC 1.12.1: 10 Sep 2017
# Last Updated: 8 Dec 2018

biomesToSpawnIn=beaches,coral_reef,deep_ocean,flower_island,forested_island,gravel_beach,kelp_forest,ocean,ocean_oilfield,oceanic_abyss,rwg_oceanhot,rwg_oceantemperate,rwg_oceanwet,stone_beach,tropical_island,white_beach

weight=1
embed_into_distance=2
acceptable_target_blocks=

biomeTypesToSpawnIn=OCEAN
unacceptable_target_blocks=lava,flowing_lava,cloud,Natura:Cloud,slime_congealed,slime_dirt,slime_grass,command_block,planks,planks2,concrete,cobblestone,stonebrick,brick_block,glass,torch,oak_stairs,stone_stairs,brick_stairs,stone_brick_stairs,nether_brick_stairs,sandstone_stairs,spruce_stairs,birch_stairs,jungle_stairs,quartz_stairs,acacia_stairs,dark_oak_stairs,cobblestone_wall,stone_slab,double_stone_slab,stone_slab2,wooden_slab,double_wooden_slab,nether_brick,fence,ice,snow,blue_ice


dimensions=21,11,36
allowable_overhang=400
max_cut_in=0
cut_in_buffer=0
max_leveling=4
leveling_buffer=-1
preserve_water=1
preserve_lava=0
preserve_plants=1

# Preserve Terrain (for sinking into ocean bottom, or if it spawns on beach)
rule1=0,100,preserveBlock

# Oak Planks
rule2=0,100,minecraft:planks-0

# Birch Planks (structural frame)
rule3=0,100,minecraft:planks-2

# Cargo Remains (melons, pumpkins, "crates," fish)
rule4=0,100,minecraft:melon_block-0,minecraft:pumpkin-0,minecraft:noteblock,IInventory;minecraft:chest;minecraft:fish#8#0,IInventory;minecraft:trapped_chest;minecraft:sponge#2#0,minecraft:tnt-0

# Monster Spawners
rule5=0,100,MobSpawner:Zombie,MobSpawner:Skeleton

# Wall Signs -- blank
rule6=2,100,WallSign:null:null:null:null-4
rule7=2,100,WallSign:null:null:null:null-2

# Log (Oak -- mast)
rule8=0,100,minecraft:log-0

# Wall Signs - blank
rule9=2,100,WallSign:null:null:null:null-3
rule10=2,100,WallSign:null:null:null:null-5

# Fence (deck railing)
rule11=0,100,minecraft:fence-0

# Vine
rule12=0,100,minecraft:vine-2
rule13=0,100,minecraft:vine-1
rule14=0,100,minecraft:vine-8
rule15=0,100,minecraft:vine-4
rule16=0,100,minecraft:vine-9

# Planks (Spruce -- decking)
rule17=0,100,minecraft:planks-1

# Redstone Lamp (off)
rule18=0,100,minecraft:redstone_lamp-0

# Stained Glass (alternating green/yellow)
rule19=0,100,minecraft:stained_glass-13
rule20=0,100,minecraft:stained_glass-4

# Air Pocket
#rule21=0,100,minecraft:tripwire
rule21=1,100,minecraft:air

# Loot!
rule22=0,100,ChestGenHook:chests/simple_dungeon:5-3

# Wooden Door
rule23=1,100,minecraft:dark_oak_door-1
rule24=1,100,minecraft:dark_oak_door-8

# Wool (Dark Green - "moldy sail remains")
rule25=0,100,minecraft:wool-13

# Vine
rule26=0,100,minecraft:vine-0

# Log (Oak - yard arms)
rule27=0,100,minecraft:log-8
rule28=0,100,minecraft:log-4

layer
1,1,1,1,1,1,1,1,1,1,1,1,1,1,1,1,1,1,1,1,1,1,1,1,1,1,1,1,1,1,1,1,1,1,1,1
1,1,1,1,1,1,1,1,1,1,1,1,1,1,1,1,1,1,1,1,1,1,1,1,1,1,1,1,1,1,1,1,1,1,1,1
1,1,1,1,1,1,1,1,1,1,1,1,1,1,1,1,1,1,1,1,1,1,1,1,1,1,1,1,1,1,1,1,1,1,1,1
1,1,1,1,1,1,2,2,2,1,1,2,2,2,2,2,2,2,2,2,1,2,2,2,2,1,2,2,2,1,1,1,1,1,1,1
1,1,1,1,1,1,2,2,2,2,2,2,2,2,2,2,2,2,2,2,2,2,2,2,2,1,2,2,2,2,1,1,1,1,1,1
1,3,3,3,1,1,3,3,3,3,3,3,3,3,3,3,3,3,3,3,3,3,3,3,3,3,3,3,3,2,2,1,1,1,1,1
1,1,1,1,1,1,2,2,2,2,2,2,2,2,2,2,2,2,1,1,1,1,2,2,2,1,2,2,2,2,1,1,1,1,1,1
1,1,1,1,1,1,2,2,2,1,2,2,2,2,1,2,2,2,2,2,1,2,2,2,2,2,1,2,2,1,1,1,1,1,1,1
1,1,1,1,1,1,1,1,1,1,1,1,1,1,1,1,1,1,1,1,1,1,1,1,1,1,1,1,1,1,1,1,1,1,1,1
1,1,1,1,1,1,1,1,1,1,1,1,1,1,1,1,1,1,1,1,1,1,1,1,1,1,1,1,1,1,1,1,1,1,1,1
1,1,1,1,1,1,1,1,1,1,1,1,1,1,1,1,1,1,1,1,1,1,1,1,1,1,1,1,1,1,1,1,1,1,1,1
endlayer

layer
1,1,1,1,1,1,1,1,1,1,1,1,1,1,1,1,0,1,1,1,1,1,1,1,1,1,1,1,1,1,1,1,1,1,1,1
1,1,1,1,1,1,1,1,1,1,1,1,1,1,1,1,1,0,0,1,1,1,1,1,1,1,1,1,1,1,1,1,1,1,1,1
1,1,1,1,1,1,2,3,2,2,2,2,3,2,1,2,2,3,2,1,1,2,3,2,2,1,2,3,2,1,1,1,1,1,1,1
1,1,1,1,1,1,1,3,0,0,0,0,3,0,1,0,0,3,1,1,1,0,3,1,0,0,0,3,0,1,1,1,1,1,1,1
1,1,1,1,1,2,0,3,0,0,0,0,3,0,0,0,0,3,1,0,0,0,3,0,0,1,0,3,0,0,0,2,1,1,1,1
1,3,3,1,1,3,3,3,3,3,3,3,3,3,3,3,3,3,3,0,0,3,3,3,0,0,3,3,3,3,3,3,1,1,1,1
1,1,1,1,1,2,0,3,0,1,0,0,3,0,1,0,0,3,0,1,1,0,3,0,1,1,1,3,0,0,0,2,1,1,1,1
1,1,1,1,1,2,0,3,1,1,0,0,3,1,1,1,0,3,0,0,0,0,3,0,1,1,1,3,0,0,1,1,1,1,1,1
1,1,1,1,1,1,2,3,1,1,2,2,3,2,1,1,2,3,2,2,2,2,3,2,1,2,2,3,2,2,1,1,1,1,1,1
1,1,1,1,1,1,1,1,1,1,1,1,1,1,1,1,1,1,1,1,1,1,1,1,1,1,1,1,1,1,1,1,1,1,1,1
1,1,1,1,1,1,1,1,1,1,1,1,1,1,1,1,1,1,1,1,1,1,1,1,1,1,1,1,1,1,1,1,1,1,1,1
endlayer

layer
1,1,1,1,1,1,1,1,1,1,1,1,1,1,0,0,0,0,0,0,0,0,0,0,0,0,1,1,1,1,1,1,1,1,1,1
1,1,1,1,1,1,2,3,2,2,1,2,3,2,1,2,2,3,2,2,0,2,3,2,2,2,2,3,2,2,1,1,1,1,1,1
1,1,1,1,1,1,0,3,0,0,1,0,3,4,0,5,4,3,4,0,0,4,3,4,0,0,4,3,4,0,0,0,0,1,1,1
1,1,1,1,1,1,0,0,0,0,0,0,0,0,0,0,0,0,0,0,0,0,0,0,0,0,0,0,0,0,0,2,3,1,1,1
1,1,1,1,2,0,0,0,0,0,0,0,0,0,0,0,0,6,0,0,0,0,0,0,0,0,0,6,0,0,0,4,3,0,1,1
1,3,3,1,3,3,0,8,0,0,0,0,0,0,0,0,9,8,7,0,0,0,0,0,0,0,9,8,7,0,0,3,3,1,1,1
1,1,1,1,2,0,0,0,0,0,0,0,0,0,0,0,0,10,0,0,0,0,0,0,0,0,0,10,0,0,0,4,3,1,1,1
1,1,1,1,0,0,0,0,0,0,0,0,0,0,0,0,0,0,0,0,0,0,0,0,0,0,0,0,0,0,0,2,3,1,1,1
1,1,1,0,0,0,0,3,0,0,0,0,3,4,0,5,4,3,4,0,0,4,3,4,0,0,4,3,4,0,0,0,0,1,1,1
1,1,1,1,1,1,2,3,2,1,1,2,3,2,2,2,2,3,2,2,2,2,3,2,0,1,2,3,2,0,1,1,1,1,1,1
1,1,1,1,1,1,1,1,1,1,1,1,1,1,1,1,1,1,1,1,1,1,1,1,1,1,1,1,1,1,1,1,1,1,1,1
endlayer

layer
1,1,1,1,1,2,2,3,2,1,0,2,3,2,0,0,2,3,2,2,2,2,3,2,2,2,2,3,2,1,1,1,1,1,1,1
1,1,1,1,0,0,0,3,0,0,0,10,3,4,0,4,10,3,10,4,0,4,3,10,4,0,4,3,4,0,1,1,1,1,1,1
1,1,1,1,0,0,0,0,0,0,0,0,0,0,0,0,0,0,0,0,0,0,0,0,0,0,0,5,0,0,0,2,3,2,1,1
1,1,1,2,0,0,0,0,0,0,0,0,0,0,0,0,0,0,0,0,0,0,0,0,0,0,0,0,0,0,0,4,3,1,1,1
1,1,1,2,0,0,0,0,0,0,0,0,0,0,0,0,0,6,0,0,0,0,0,0,0,0,0,6,0,0,0,0,0,2,0,1
1,1,11,3,3,0,0,8,0,0,0,0,0,0,0,0,9,8,7,0,0,0,0,0,0,0,9,8,7,0,0,0,3,3,3,1
1,1,1,2,0,0,0,0,0,0,0,0,0,0,0,0,0,10,0,0,0,0,0,0,0,0,0,10,0,0,0,0,0,2,1,1
1,1,0,0,0,0,0,0,0,0,0,0,0,0,0,0,0,0,0,0,0,0,0,0,0,0,0,0,0,0,0,4,3,1,1,1
1,1,0,0,0,0,0,0,0,0,0,0,0,0,0,0,0,0,0,0,0,0,0,0,0,0,0,5,0,0,0,2,3,2,1,1
1,1,1,1,0,0,0,3,0,0,0,6,3,6,0,4,6,3,4,0,0,4,3,4,0,0,6,3,0,0,0,1,1,1,1,1
1,1,1,1,1,0,2,3,2,2,2,2,3,2,1,2,2,3,2,1,1,2,3,2,2,2,2,3,2,0,1,1,1,1,1,1
endlayer

layer
1,1,1,1,1,1,2,3,0,0,0,2,3,0,0,0,2,3,2,2,0,2,3,2,2,0,0,3,2,2,0,1,1,1,1,1
1,1,1,1,0,0,0,0,0,0,0,10,10,12,0,0,10,10,10,0,0,0,10,10,0,0,12,10,0,0,0,2,3,2,1,1
1,1,1,0,0,0,0,0,0,0,0,0,0,0,0,0,0,0,0,0,0,0,0,0,0,0,0,0,0,0,0,10,3,10,1,1
1,1,2,0,0,0,0,0,0,0,0,0,0,0,0,0,0,0,0,0,0,0,0,13,0,0,0,0,0,0,0,0,10,0,0,1
1,1,2,0,0,0,0,0,0,0,0,0,0,0,0,0,0,6,0,0,0,0,0,0,0,0,0,6,0,0,0,0,0,13,0,1
1,1,3,3,0,0,0,8,0,0,0,0,0,0,0,0,9,8,7,0,0,0,0,0,0,0,9,8,7,0,0,0,5,13,3,3
1,1,2,0,0,0,0,0,0,0,0,0,0,0,0,0,0,10,13,0,0,0,0,0,0,0,0,10,0,0,0,0,12,13,0,1
1,0,2,0,0,0,0,0,0,0,0,0,0,0,0,0,0,0,0,0,0,0,0,0,0,0,0,0,0,0,0,0,6,0,1,1
1,1,0,0,0,0,0,0,0,0,0,0,0,0,0,0,0,0,0,0,0,0,0,13,0,0,0,0,0,0,0,6,3,6,1,1
1,1,1,0,0,0,0,0,0,0,0,6,6,6,0,14,6,6,14,0,0,0,6,0,0,0,6,6,0,0,0,2,3,2,1,1
1,1,1,1,0,0,1,3,1,0,2,2,3,2,0,0,2,3,1,0,0,0,3,2,0,0,2,3,0,0,0,1,1,1,1,1
endlayer

layer
1,1,1,1,2,2,2,3,2,0,2,2,3,2,0,2,2,3,2,0,0,0,3,2,0,0,2,3,0,0,0,0,0,1,1,1
1,1,1,0,0,0,0,0,0,0,0,10,10,12,0,12,10,10,10,0,0,0,10,10,0,0,12,10,0,0,0,2,3,2,1,1
1,1,2,0,0,0,0,0,0,0,0,0,0,0,0,0,0,0,13,0,0,15,0,13,0,0,15,0,0,0,0,10,3,10,0,1
1,1,2,0,0,0,0,0,0,0,0,0,0,0,0,0,0,0,0,0,0,0,0,13,0,0,0,0,0,0,0,0,10,0,0,1
1,1,2,0,0,0,0,0,0,0,0,0,0,0,0,0,0,6,0,0,0,0,0,0,0,0,0,6,0,0,0,0,0,13,0,0
1,1,3,0,0,0,0,8,0,0,0,0,0,0,0,0,9,8,7,0,0,0,0,0,0,0,9,8,7,0,0,0,0,0,0,0
1,0,2,0,0,0,0,0,0,0,0,0,0,0,0,0,0,10,13,0,0,0,0,0,0,0,0,10,0,0,0,0,0,13,0,0
1,0,2,0,0,0,0,0,0,0,0,0,0,13,0,0,15,0,0,0,0,0,0,0,0,0,0,0,0,0,0,0,6,0,0,0
1,0,2,0,0,0,0,0,0,0,0,0,0,13,0,0,0,0,0,0,0,15,0,13,0,0,15,0,0,0,0,6,3,6,0,1
1,1,0,0,0,0,0,0,0,0,0,6,6,6,0,14,6,6,16,0,0,0,6,14,0,14,6,6,0,0,0,2,3,2,1,1
1,1,1,0,0,2,2,3,2,2,2,2,3,2,2,0,2,3,2,0,0,2,3,0,0,0,2,3,2,2,0,0,1,1,1,1
endlayer

# Cabin Floor
layer
1,1,3,3,3,3,3,3,3,3,3,3,3,2,0,0,2,3,2,2,2,2,3,2,2,0,2,3,2,2,0,0,0,0,1,1
1,0,3,17,17,17,17,3,17,17,17,17,3,12,0,0,10,3,10,0,0,15,3,10,0,0,12,3,0,0,0,2,3,2,0,1
1,0,3,17,17,17,17,3,17,17,17,17,3,13,0,0,15,3,13,0,0,15,3,13,0,0,15,3,0,0,0,10,3,10,0,0
3,3,3,17,17,17,17,3,17,0,17,17,3,13,0,0,0,3,0,0,0,0,3,13,0,0,15,3,0,0,0,0,3,13,0,0
3,2,3,17,17,17,17,3,17,0,0,17,3,0,0,0,15,3,13,0,0,0,3,0,0,0,15,3,0,0,0,0,3,13,0,0
3,2,3,17,17,17,17,5,17,0,0,17,3,17,17,0,9,8,7,0,0,0,3,0,0,0,9,8,7,0,0,0,3,18,0,0
3,2,3,17,17,17,17,3,17,0,0,17,3,0,0,0,15,3,13,0,0,0,3,0,0,0,15,3,0,0,0,0,3,13,0,0
3,3,3,17,17,17,17,3,17,0,17,17,3,13,0,0,15,3,0,0,0,0,3,0,0,0,0,3,0,0,0,0,3,13,0,0
0,0,3,17,17,17,17,3,17,17,17,17,3,13,0,0,15,3,13,0,0,15,3,13,0,0,15,3,0,0,0,6,3,6,0,0
1,0,3,17,17,17,17,3,17,17,17,17,3,6,14,14,6,3,13,0,14,15,3,14,0,14,6,3,0,0,0,2,3,2,0,1
1,1,3,3,3,3,3,3,3,3,3,3,3,2,2,2,2,3,2,2,2,2,3,2,0,2,2,3,2,0,0,0,0,0,1,1
endlayer

layer
1,0,3,20,19,20,19,3,20,19,2,2,3,3,3,3,3,3,3,0,0,3,3,3,0,0,3,3,3,3,3,0,0,0,0,1
0,0,19,21,21,21,21,10,21,21,10,9,2,17,17,17,17,17,17,0,0,17,17,17,0,0,17,17,17,0,3,3,3,3,3,0
0,0,20,21,21,21,21,21,21,21,22,9,2,17,0,0,17,17,17,0,0,17,17,17,17,17,17,17,17,0,17,17,17,17,3,3
11,11,19,21,21,21,21,21,21,21,22,9,2,17,0,0,0,17,0,0,0,0,17,17,0,17,17,17,17,0,0,17,17,17,17,0
0,9,3,7,21,21,21,6,21,21,21,9,3,0,0,0,17,17,17,0,0,0,17,0,0,0,17,17,17,0,0,17,17,17,0,0
11,21,23,21,21,21,9,8,7,21,21,21,23,0,0,17,17,8,17,0,0,0,0,0,0,0,17,8,17,0,0,0,17,0,0,0
11,9,3,7,21,21,21,10,21,21,21,9,3,0,0,17,17,17,17,0,0,0,0,0,0,0,17,17,17,0,0,17,17,17,0,0
11,11,19,21,21,21,21,21,21,21,22,9,2,17,0,17,17,17,0,0,0,0,17,0,0,0,0,17,17,0,17,17,17,17,17,0
0,0,20,21,21,21,21,21,21,21,22,9,2,17,17,17,17,17,17,0,0,17,17,17,0,0,17,17,17,17,17,17,17,17,3,3
0,0,19,21,21,21,21,6,21,21,6,9,2,17,17,17,17,17,17,0,17,17,17,17,0,17,17,17,17,17,3,3,3,3,3,0
1,0,3,20,19,20,19,3,20,19,2,2,3,0,3,3,3,3,3,0,3,3,3,3,3,3,3,3,3,3,3,0,0,0,0,1
endlayer

layer
0,0,3,19,20,19,20,3,19,20,2,2,3,18,11,11,11,11,0,0,0,0,11,0,0,0,0,11,11,0,11,0,0,0,0,0
0,0,20,21,21,21,21,10,21,21,10,9,2,0,0,0,0,0,0,0,0,0,0,0,0,0,0,0,0,0,11,11,11,11,0,0
0,0,19,21,21,21,21,21,21,21,21,9,2,0,0,0,0,0,0,0,0,0,0,0,0,0,0,0,0,0,0,0,0,0,11,11
0,0,20,21,21,21,21,21,21,21,21,9,2,0,0,0,0,0,0,0,0,0,0,0,0,0,0,0,0,0,0,0,0,0,0,0
0,9,3,7,21,21,21,6,21,21,21,9,3,0,0,0,0,0,0,0,0,0,0,0,0,0,0,0,0,0,0,0,0,0,0,0
0,0,24,21,21,21,9,8,7,21,21,21,24,0,0,0,0,8,0,0,0,0,0,0,0,0,0,8,0,0,0,0,0,0,0,0
0,9,3,7,21,21,21,10,21,21,21,9,3,0,0,0,0,0,0,0,0,0,0,0,0,0,0,0,0,0,0,0,0,0,0,0
0,0,20,21,21,21,21,21,21,21,21,9,2,0,0,0,0,0,0,0,0,0,0,0,0,0,0,0,0,0,0,0,0,0,0,0
0,0,19,21,21,21,21,21,21,21,21,9,2,0,0,0,0,0,0,0,0,0,0,0,0,0,0,0,0,0,0,0,0,0,11,0
0,0,20,21,21,21,21,6,21,21,6,9,2,0,0,0,0,0,0,0,0,0,0,0,0,0,0,0,0,0,11,11,11,11,0,0
0,0,3,19,20,19,20,3,19,20,2,2,3,0,0,11,11,0,11,0,11,0,11,11,11,11,11,11,0,11,0,0,0,0,0,0
endlayer

layer
0,0,3,3,3,3,3,3,3,3,3,3,3,0,0,0,0,0,0,0,0,0,0,0,0,0,0,0,0,0,0,0,0,0,0,0
0,0,3,17,17,17,17,17,17,17,17,17,3,0,0,0,0,0,0,0,0,0,0,0,0,0,0,0,0,0,0,0,0,0,0,0
0,0,3,17,17,17,17,17,17,17,17,17,3,0,0,0,0,0,0,0,0,0,0,0,0,0,0,0,0,0,0,0,0,0,0,0
0,0,3,17,17,17,17,17,17,17,17,17,3,0,0,0,0,0,0,0,0,0,0,0,0,0,0,0,0,0,0,0,0,0,0,0
0,18,3,17,17,17,17,17,17,17,17,17,3,0,0,0,0,0,0,0,0,0,0,0,0,0,0,0,0,0,0,0,0,0,0,0
0,0,3,17,17,25,17,8,17,17,17,17,3,0,0,0,0,8,0,0,0,0,0,0,0,0,0,8,0,0,0,0,0,0,0,0
0,18,3,17,17,17,17,17,17,17,17,17,3,0,0,0,0,0,0,0,0,0,0,0,0,0,0,0,0,0,0,0,0,0,0,0
0,0,3,17,17,17,17,17,17,17,17,17,3,0,0,0,0,0,0,0,0,0,0,0,0,0,0,0,0,0,0,0,0,0,0,0
0,0,3,17,17,17,17,17,17,17,17,17,3,0,0,0,0,0,0,0,0,0,0,0,0,0,0,0,0,0,0,0,0,0,0,0
0,0,3,17,17,17,17,17,17,17,17,17,3,0,0,0,0,0,0,0,0,0,0,0,0,0,0,0,0,0,0,0,0,0,0,0
0,0,3,3,3,3,3,3,3,3,3,3,3,0,0,0,0,0,0,0,0,0,0,0,0,0,0,0,0,0,0,0,0,0,0,0
endlayer

layer
0,0,11,11,11,11,0,11,0,11,11,11,11,0,0,0,0,0,0,0,0,0,0,0,0,0,0,0,0,0,0,0,0,0,0,0
0,0,11,0,0,0,0,0,0,0,0,0,0,0,0,0,0,0,25,0,0,0,0,0,0,0,0,0,0,0,0,0,0,0,0,0
0,0,3,0,0,0,0,0,0,0,0,0,11,0,0,0,0,0,0,0,0,0,0,0,0,0,0,25,0,0,0,0,0,0,0,0
0,0,3,0,0,0,0,0,0,0,0,0,11,0,0,0,0,0,0,0,0,0,0,0,0,0,0,0,0,0,0,0,0,0,0,0
0,0,2,0,0,0,0,0,0,0,0,0,11,0,0,0,0,0,0,0,0,0,0,0,0,0,0,0,0,0,0,0,0,0,0,0
0,0,2,0,0,25,0,8,0,0,0,0,11,0,0,0,18,8,18,0,0,0,0,0,0,0,0,8,25,0,0,0,0,0,0,0
0,0,2,0,0,0,0,0,0,0,0,0,11,0,0,0,0,0,0,0,0,0,0,0,0,0,0,12,12,0,0,0,0,0,0,0
0,0,3,0,0,0,0,0,0,0,0,0,11,0,0,0,0,0,25,0,0,0,0,0,0,0,0,0,0,0,0,0,0,0,0,0
0,0,3,0,0,0,0,0,0,0,0,0,11,0,0,0,0,0,0,0,0,0,0,0,0,0,0,25,0,0,0,0,0,0,0,0
0,0,0,0,0,0,0,0,0,0,0,0,0,0,0,0,0,0,25,0,0,0,0,0,0,0,0,0,0,0,0,0,0,0,0,0
0,0,0,11,11,11,0,11,0,11,0,11,11,0,0,0,0,0,0,0,0,0,0,0,0,0,0,0,0,0,0,0,0,0,0,0
endlayer

layer
0,0,0,0,0,0,0,0,0,0,0,0,0,0,0,0,0,0,0,0,0,0,0,0,0,0,0,0,0,0,0,0,0,0,0,0
0,0,0,0,0,0,0,0,0,0,0,0,0,0,0,0,0,0,25,0,0,0,0,0,0,0,0,0,0,0,0,0,0,0,0,0
0,0,0,0,0,0,0,0,0,0,0,0,0,0,0,0,0,0,25,0,0,0,0,0,0,0,0,25,0,0,0,0,0,0,0,0
0,0,3,0,0,0,0,0,0,0,0,0,0,0,0,0,0,0,0,0,0,0,0,0,0,0,0,0,0,0,0,0,0,0,0,0
0,0,3,0,0,0,0,0,0,0,0,0,0,0,0,0,0,0,0,0,0,0,0,0,0,0,0,0,0,0,0,0,0,0,0,0
0,0,3,0,25,25,25,8,0,0,0,0,0,0,0,0,0,8,25,0,0,0,0,0,0,0,0,8,25,0,0,0,0,0,0,0
0,0,3,0,0,0,0,0,0,0,0,0,0,0,0,0,0,0,0,0,0,0,0,0,0,0,0,12,0,0,0,0,0,0,0,0
0,0,3,0,0,0,0,0,0,0,0,0,0,0,0,0,0,0,25,0,0,0,0,0,0,0,0,0,0,0,0,0,0,0,0,0
0,0,0,0,0,0,0,0,0,0,0,0,0,0,0,0,0,0,0,0,0,0,0,0,0,0,0,25,0,0,0,0,0,0,0,0
0,0,0,0,0,0,0,0,0,0,0,0,0,0,0,0,0,0,25,0,0,0,0,0,0,0,0,0,0,0,0,0,0,0,0,0
0,0,0,0,0,0,0,0,0,0,0,0,0,0,0,0,0,0,0,0,0,0,0,0,0,0,0,0,0,0,0,0,0,0,0,0
endlayer

layer
0,0,0,0,0,0,0,0,0,0,0,0,0,0,0,0,0,0,0,0,0,0,0,0,0,0,0,0,0,0,0,0,0,0,0,0
0,0,0,0,0,0,0,0,0,0,0,0,0,0,0,0,0,0,25,0,0,0,0,0,0,0,0,25,0,0,0,0,0,0,0,0
0,0,0,0,0,0,0,0,0,0,0,0,0,0,0,0,0,0,25,0,0,0,0,0,0,0,0,25,0,0,0,0,0,0,0,0
0,0,0,0,0,0,0,0,0,0,0,0,0,0,0,0,0,0,0,0,0,0,0,0,0,0,0,25,0,0,0,0,0,0,0,0
0,0,0,0,0,0,0,0,0,0,0,0,0,0,0,0,0,14,25,0,0,0,0,0,0,0,0,14,25,0,0,0,0,0,0,0
0,0,0,25,25,0,25,8,0,0,0,0,0,0,0,0,15,8,25,0,0,0,0,0,0,0,0,8,25,0,0,0,0,0,0,0
0,12,0,0,0,0,0,25,0,0,0,0,0,0,0,0,0,0,25,0,0,0,0,0,0,0,0,12,25,0,0,0,0,0,0,0
0,0,0,0,0,0,0,0,0,0,0,0,0,0,0,0,0,0,25,0,0,0,0,0,0,0,0,0,25,0,0,0,0,0,0,0
0,0,0,0,0,0,0,0,0,0,0,0,0,0,0,0,0,0,25,0,0,0,0,0,0,0,0,25,0,0,0,0,0,0,0,0
0,0,0,0,0,0,0,0,0,0,0,0,0,0,0,0,0,0,25,0,0,0,0,0,0,0,0,0,0,0,0,0,0,0,0,0
0,0,0,0,0,0,0,0,0,0,0,0,0,0,0,0,0,25,0,0,0,0,0,0,0,0,0,0,0,0,0,0,0,0,0,0
endlayer

layer
0,0,0,0,0,0,0,0,0,0,0,0,0,0,0,0,0,0,0,0,0,0,0,0,0,0,0,14,0,0,0,0,0,0,0,0
0,0,0,0,0,0,0,0,0,0,0,0,0,0,0,0,0,0,25,0,0,0,0,0,0,0,0,25,0,0,0,0,0,0,0,0
0,0,0,0,0,0,0,0,0,0,0,0,0,0,0,0,0,0,0,0,0,0,0,0,0,0,0,0,0,0,0,0,0,0,0,0
0,0,0,0,0,0,0,0,0,0,0,0,0,0,0,0,0,26,25,0,0,0,0,0,0,0,0,25,0,0,0,0,0,0,0,0
0,0,0,0,0,0,0,0,0,0,0,0,0,0,0,0,0,14,0,0,0,0,0,0,0,0,0,14,25,0,0,0,0,0,0,0
15,27,27,27,27,27,27,8,0,0,0,0,0,0,0,0,0,8,13,0,0,0,0,0,0,0,0,8,0,0,0,0,0,0,0,0
0,12,0,0,0,0,25,25,0,0,0,0,0,0,0,0,0,0,25,0,0,0,0,0,0,0,0,12,25,0,0,0,0,0,0,0
0,0,0,0,0,0,0,0,0,0,0,0,0,0,0,0,0,0,25,0,0,0,0,0,0,0,0,25,25,0,0,0,0,0,0,0
0,0,0,0,0,0,0,0,0,0,0,0,0,0,0,0,0,0,0,0,0,0,0,0,0,0,0,25,25,0,0,0,0,0,0,0
0,0,0,0,0,0,0,0,0,0,0,0,0,0,0,0,0,0,25,0,0,0,0,0,0,0,0,0,0,0,0,0,0,0,0,0
0,0,0,0,0,0,0,0,0,0,0,0,0,0,0,0,0,25,25,0,0,0,0,0,0,0,0,0,0,0,0,0,0,0,0,0
endlayer

layer
0,0,0,0,0,0,0,0,0,0,0,0,0,0,0,0,0,28,0,0,0,0,0,0,0,0,0,14,0,0,0,0,0,0,0,0
0,0,0,0,0,0,0,0,0,0,0,0,0,0,0,0,0,28,25,0,0,0,0,0,0,0,15,28,0,0,0,0,0,0,0,0
0,0,0,0,0,0,0,0,0,0,0,0,0,0,0,0,0,28,0,0,0,0,0,0,0,0,0,28,0,0,0,0,0,0,0,0
0,0,0,0,0,0,0,0,0,0,0,0,0,0,0,0,0,28,25,0,0,0,0,0,0,0,0,28,0,0,0,0,0,0,0,0
0,0,0,0,0,0,0,0,0,0,0,0,0,0,0,0,0,28,0,0,0,0,0,0,0,0,0,28,0,0,0,0,0,0,0,0
0,0,0,0,0,0,0,8,0,0,0,0,0,0,0,0,0,8,0,0,0,0,0,0,0,0,0,8,0,0,0,0,0,0,0,0
0,0,0,0,0,0,25,0,0,0,0,0,0,0,0,0,0,28,25,0,0,0,0,0,0,0,0,28,0,0,0,0,0,0,0,0
0,0,0,0,0,0,0,0,0,0,0,0,0,0,0,0,0,28,0,0,0,0,0,0,0,0,15,28,0,0,0,0,0,0,0,0
0,0,0,0,0,0,0,0,0,0,0,0,0,0,0,0,0,28,0,0,0,0,0,0,0,0,15,28,0,0,0,0,0,0,0,0
0,0,0,0,0,0,0,0,0,0,0,0,0,0,0,0,0,28,25,0,0,0,0,0,0,0,0,12,0,0,0,0,0,0,0,0
0,0,0,0,0,0,0,0,0,0,0,0,0,0,0,0,0,28,25,13,0,0,0,0,0,0,0,0,0,0,0,0,0,0,0,0
endlayer

layer
0,0,0,0,0,0,0,0,0,0,0,0,0,0,0,0,0,0,0,0,0,0,0,0,0,0,0,0,0,0,0,0,0,0,0,0
0,0,0,0,0,0,0,0,0,0,0,0,0,0,0,0,0,0,0,0,0,0,0,0,0,0,0,0,0,0,0,0,0,0,0,0
0,0,0,0,0,0,0,0,0,0,0,0,0,0,0,0,0,0,0,0,0,0,0,0,0,0,0,0,0,0,0,0,0,0,0,0
0,0,0,0,0,0,0,0,0,0,0,0,0,0,0,0,0,0,0,0,0,0,0,0,0,0,0,0,0,0,0,0,0,0,0,0
0,0,0,0,0,0,0,0,0,0,0,0,0,0,0,0,0,0,0,0,0,0,0,0,0,0,0,0,0,0,0,0,0,0,0,0
0,0,0,0,0,0,25,8,0,0,0,0,0,0,0,0,0,8,0,0,0,0,0,0,0,0,0,8,0,0,0,0,0,0,0,0
0,0,0,0,0,0,25,0,0,0,0,0,0,0,0,0,0,0,0,0,0,0,0,0,0,0,0,0,0,0,0,0,0,0,0,0
0,0,0,0,0,0,0,0,0,0,0,0,0,0,0,0,0,25,0,0,0,0,0,0,0,0,0,0,0,0,0,0,0,0,0,0
0,0,0,0,0,0,0,0,0,0,0,0,0,0,0,0,0,0,0,0,0,0,0,0,0,0,0,0,0,0,0,0,0,0,0,0
0,0,0,0,0,0,0,0,0,0,0,0,0,0,0,0,0,0,0,0,0,0,0,0,0,0,0,0,0,0,0,0,0,0,0,0
0,0,0,0,0,0,0,0,0,0,0,0,0,0,0,0,0,0,0,0,0,0,0,0,0,0,0,0,0,0,0,0,0,0,0,0
endlayer

layer
0,0,0,0,0,0,0,0,0,0,0,0,0,0,0,0,0,0,0,0,0,0,0,0,0,0,0,0,0,0,0,0,0,0,0,0
0,0,0,0,0,0,0,0,0,0,0,0,0,0,0,0,0,0,0,0,0,0,0,0,0,0,0,0,0,0,0,0,0,0,0,0
0,0,0,0,0,0,0,0,0,0,0,0,0,0,0,0,0,0,0,0,0,0,0,0,0,0,0,0,0,0,0,0,0,0,0,0
0,0,0,0,0,0,0,0,0,0,0,0,0,0,0,0,0,0,0,0,0,0,0,0,0,0,0,0,0,0,0,0,0,0,0,0
0,0,0,0,0,0,0,0,0,0,0,0,0,0,0,0,0,0,0,0,0,0,0,0,0,0,0,0,0,0,0,0,0,0,0,0
0,0,0,0,0,0,0,8,0,0,0,0,0,0,0,0,0,8,0,0,0,0,0,0,0,0,0,8,0,0,0,0,0,0,0,0
0,0,0,0,0,0,25,25,0,0,0,0,0,0,0,0,0,0,0,0,0,0,0,0,0,0,0,0,0,0,0,0,0,0,0,0
0,0,0,0,0,0,0,0,0,0,0,0,0,0,0,0,0,0,25,0,0,0,0,0,0,0,0,0,0,0,0,0,0,0,0,0
0,0,0,0,0,0,0,0,0,0,0,0,0,0,0,0,0,0,0,0,0,0,0,0,0,0,0,0,0,0,0,0,0,0,0,0
0,0,0,0,0,0,0,0,0,0,0,0,0,0,0,0,0,0,0,0,0,0,0,0,0,0,0,0,0,0,0,0,0,0,0,0
0,0,0,0,0,0,0,0,0,0,0,0,0,0,0,0,0,0,0,0,0,0,0,0,0,0,0,0,0,0,0,0,0,0,0,0
endlayer

layer
0,0,0,0,0,0,0,0,0,0,0,0,0,0,0,0,0,0,0,0,0,0,0,0,0,0,0,0,0,0,0,0,0,0,0,0
0,0,0,0,0,0,0,0,0,0,0,0,0,0,0,0,0,0,0,0,0,0,0,0,0,0,0,0,0,0,0,0,0,0,0,0
0,0,0,0,0,0,0,0,0,0,0,0,0,0,0,0,0,0,0,0,0,0,0,0,0,0,0,0,0,0,0,0,0,0,0,0
0,0,0,0,0,0,0,0,0,0,0,0,0,0,0,0,0,0,0,0,0,0,0,0,0,0,0,0,0,0,0,0,0,0,0,0
0,0,0,0,0,0,0,0,0,0,0,0,0,0,0,0,0,0,0,0,0,0,0,0,0,0,0,0,0,0,0,0,0,0,0,0
0,0,0,0,0,0,0,8,0,0,0,0,0,0,0,0,0,8,25,0,0,0,0,0,0,0,0,8,0,0,0,0,0,0,0,0
0,0,0,0,0,0,0,25,0,0,0,0,0,0,0,0,0,0,25,0,0,0,0,0,0,0,0,0,0,0,0,0,0,0,0,0
0,0,0,0,0,0,0,0,0,0,0,0,0,0,0,0,0,0,0,0,0,0,0,0,0,0,0,0,0,0,0,0,0,0,0,0
0,0,0,0,0,0,0,0,0,0,0,0,0,0,0,0,0,0,0,0,0,0,0,0,0,0,0,0,0,0,0,0,0,0,0,0
0,0,0,0,0,0,0,0,0,0,0,0,0,0,0,0,0,0,0,0,0,0,0,0,0,0,0,0,0,0,0,0,0,0,0,0
0,0,0,0,0,0,0,0,0,0,0,0,0,0,0,0,0,0,0,0,0,0,0,0,0,0,0,0,0,0,0,0,0,0,0,0
endlayer

layer
0,0,0,0,0,0,0,0,0,0,0,0,0,0,0,0,0,0,0,0,0,0,0,0,0,0,0,0,0,0,0,0,0,0,0,0
0,0,0,0,0,0,0,0,0,0,0,0,0,0,0,0,0,0,0,0,0,0,0,0,0,0,0,0,0,0,0,0,0,0,0,0
0,0,0,0,0,0,0,0,0,0,0,0,0,0,0,0,0,0,0,0,0,0,0,0,0,0,0,0,0,0,0,0,0,0,0,0
0,0,0,0,0,0,0,0,0,0,0,0,0,0,0,0,0,0,0,0,0,0,0,0,0,0,0,0,0,0,0,0,0,0,0,0
0,0,0,0,0,0,0,0,0,0,0,0,0,0,0,0,0,0,0,0,0,0,0,0,0,0,0,0,0,0,0,0,0,0,0,0
0,0,0,0,0,0,0,8,0,0,0,0,0,0,0,0,0,8,25,0,0,0,0,0,0,0,0,0,0,0,0,0,0,0,0,0
0,0,0,0,0,0,0,0,0,0,0,0,0,0,0,0,0,0,0,0,0,0,0,0,0,0,0,0,0,0,0,0,0,0,0,0
0,0,0,0,0,0,0,0,0,0,0,0,0,0,0,0,0,0,0,0,0,0,0,0,0,0,0,0,0,0,0,0,0,0,0,0
0,0,0,0,0,0,0,0,0,0,0,0,0,0,0,0,0,0,0,0,0,0,0,0,0,0,0,0,0,0,0,0,0,0,0,0
0,0,0,0,0,0,0,0,0,0,0,0,0,0,0,0,0,0,0,0,0,0,0,0,0,0,0,0,0,0,0,0,0,0,0,0
0,0,0,0,0,0,0,0,0,0,0,0,0,0,0,0,0,0,0,0,0,0,0,0,0,0,0,0,0,0,0,0,0,0,0,0
endlayer

layer
0,0,0,0,0,0,0,0,0,0,0,0,0,0,0,0,0,0,0,0,0,0,0,0,0,0,0,0,0,0,0,0,0,0,0,0
0,0,0,0,0,0,0,0,0,0,0,0,0,0,0,0,0,0,0,0,0,0,0,0,0,0,0,0,0,0,0,0,0,0,0,0
0,0,0,0,0,0,0,0,0,0,0,0,0,0,0,0,0,0,0,0,0,0,0,0,0,0,0,0,0,0,0,0,0,0,0,0
0,0,0,0,0,0,0,0,0,0,0,0,0,0,0,0,0,0,0,0,0,0,0,0,0,0,0,0,0,0,0,0,0,0,0,0
0,0,0,0,0,0,0,0,0,0,0,0,0,0,0,0,0,0,0,0,0,0,0,0,0,0,0,0,0,0,0,0,0,0,0,0
0,0,0,0,0,0,0,0,0,0,0,0,0,0,0,0,0,8,25,0,0,0,0,0,0,0,0,0,0,0,0,0,0,0,0,0
0,0,0,0,0,0,0,0,0,0,0,0,0,0,0,0,0,0,0,0,0,0,0,0,0,0,0,0,0,0,0,0,0,0,0,0
0,0,0,0,0,0,0,0,0,0,0,0,0,0,0,0,0,0,0,0,0,0,0,0,0,0,0,0,0,0,0,0,0,0,0,0
0,0,0,0,0,0,0,0,0,0,0,0,0,0,0,0,0,0,0,0,0,0,0,0,0,0,0,0,0,0,0,0,0,0,0,0
0,0,0,0,0,0,0,0,0,0,0,0,0,0,0,0,0,0,0,0,0,0,0,0,0,0,0,0,0,0,0,0,0,0,0,0
0,0,0,0,0,0,0,0,0,0,0,0,0,0,0,0,0,0,0,0,0,0,0,0,0,0,0,0,0,0,0,0,0,0,0,0
endlayer

layer
0,0,0,0,0,0,0,0,0,0,0,0,0,0,0,0,0,0,0,0,0,0,0,0,0,0,0,0,0,0,0,0,0,0,0,0
0,0,0,0,0,0,0,0,0,0,0,0,0,0,0,0,0,0,0,0,0,0,0,0,0,0,0,0,0,0,0,0,0,0,0,0
0,0,0,0,0,0,0,0,0,0,0,0,0,0,0,0,0,0,0,0,0,0,0,0,0,0,0,0,0,0,0,0,0,0,0,0
0,0,0,0,0,0,0,0,0,0,0,0,0,0,0,0,0,0,0,0,0,0,0,0,0,0,0,0,0,0,0,0,0,0,0,0
0,0,0,0,0,0,0,0,0,0,0,0,0,0,0,0,0,0,0,0,0,0,0,0,0,0,0,0,0,0,0,0,0,0,0,0
0,0,0,0,0,0,0,0,0,0,0,0,0,0,0,0,0,8,0,0,0,0,0,0,0,0,0,0,0,0,0,0,0,0,0,0
0,0,0,0,0,0,0,0,0,0,0,0,0,0,0,0,0,0,0,0,0,0,0,0,0,0,0,0,0,0,0,0,0,0,0,0
0,0,0,0,0,0,0,0,0,0,0,0,0,0,0,0,0,0,0,0,0,0,0,0,0,0,0,0,0,0,0,0,0,0,0,0
0,0,0,0,0,0,0,0,0,0,0,0,0,0,0,0,0,0,0,0,0,0,0,0,0,0,0,0,0,0,0,0,0,0,0,0
0,0,0,0,0,0,0,0,0,0,0,0,0,0,0,0,0,0,0,0,0,0,0,0,0,0,0,0,0,0,0,0,0,0,0,0
0,0,0,0,0,0,0,0,0,0,0,0,0,0,0,0,0,0,0,0,0,0,0,0,0,0,0,0,0,0,0,0,0,0,0,0
endlayer

