
# Sunken_Treasure_1
# Updated to MC 1.7.10, 13 Oct 2014
# Created by Ruins mod version 12.3 Ingame Parser
# authoring Player: Jordan_Greywolf
# Last Updated: 22 Nov 2015
# Verified for MC 1.8: 5 Mar 2016
# Verified for MC 1.10: 13 Sep 2016
# Updated for MC 1.11: 13 Jan 2017
# Updated for MC 1.12: 21 Jun 2017
# Updated to MC 1.12.1: 10 Sep 2017
# Last Updated: 8 Dec 2018

biomesToSpawnIn=kelp_forest,kelp_forest,ocean,ocean oil field,ocean_oil_field,oceanic abyss,oceanic_abyss,coral reef,coral_reef,deep ocean,deep_ocean,frozen ocean,frozen_ocean,rwg_oceanhot,rwg_oceantemperate,rwg_oceanwet



weight=1
embed_into_distance=2

biomeTypesToSpawnIn=OCEAN
unacceptable_target_blocks=lava,flowing_lava,cloud,Natura:Cloud,slime_congealed,slime_dirt,slime_grass,command_block,planks,planks2,concrete,cobblestone,stonebrick,brick_block,glass,torch,oak_stairs,stone_stairs,brick_stairs,stone_brick_stairs,nether_brick_stairs,sandstone_stairs,spruce_stairs,birch_stairs,jungle_stairs,quartz_stairs,acacia_stairs,dark_oak_stairs,cobblestone_wall,stone_slab,double_stone_slab,stone_slab2,wooden_slab,double_wooden_slab,nether_brick,fence,ice,snow,blue_ice

dimensions=7,12,12
allowable_overhang=2
max_cut_in=0
cut_in_buffer=0
max_leveling=2
leveling_buffer=-1
preserve_water=1
preserve_lava=0
preserve_plants=1

rule1=0,100,preserveBlock
rule2=0,100,minecraft:wool-13
rule3=0,100,minecraft:sand-0
rule4=0,100,minecraft:tnt-1
rule5=0,100,minecraft:sponge-1
rule6=0,100,IInventory;minecraft:trapped_chest;minecraft:fish#8#0-4,IInventory;minecraft:trapped_chest;minecraft:tnt#12#0-4,IInventory;minecraft:trapped_chest;minecraft:glass#16#0-4,IInventory;minecraft:trapped_chest;minecraft:iron_bars#16#0-4,IInventory;minecraft:trapped_chest;minecraft:gold_nugget#8#0-4,IInventory;minecraft:trapped_chest;minecraft:prismarine_shard#16#0-4

layer
1,1,1,1,1,1,1,1,1,1,1,1
1,1,1,1,1,2,1,1,1,1,1,1
1,1,1,1,1,1,1,1,1,1,1,1
1,1,1,1,1,3,3,1,1,1,2,1
1,2,1,1,3,3,4,3,1,1,1,1
1,1,1,1,3,4,4,4,3,1,1,1
1,1,1,5,1,3,4,3,1,1,1,1
1,1,1,5,1,1,3,1,2,1,1,1
1,1,1,1,1,1,1,1,1,1,1,1
1,1,1,1,1,1,1,1,1,1,1,1
1,2,1,1,1,1,1,2,1,1,1,1
1,1,1,1,1,1,1,1,1,1,1,1
endlayer

layer
1,1,1,1,1,1,1,1,1,1,1,1
1,1,1,1,1,2,1,1,1,1,1,1
1,1,1,1,1,1,1,1,1,1,1,1
1,1,1,1,1,1,1,1,1,1,2,1
1,2,1,1,1,3,3,1,1,1,1,1
1,1,1,1,1,3,3,3,1,1,1,1
1,1,1,5,1,1,3,1,1,1,1,1
1,1,1,5,5,1,1,1,2,1,1,1
1,1,1,1,1,1,1,1,1,1,1,1
1,1,1,1,1,1,1,1,1,1,1,1
1,2,1,1,1,1,1,2,1,1,1,1
1,1,1,1,1,1,1,1,1,1,1,1
endlayer

layer
1,1,1,1,1,2,1,1,1,1,1,1
1,1,1,1,1,0,0,1,1,1,1,1
1,1,1,0,0,0,0,0,0,1,1,1
1,2,0,0,0,0,0,0,0,0,1,2
1,0,0,0,0,0,0,0,0,0,0,1
1,0,0,0,0,0,6,0,0,0,0,1
1,0,0,0,0,0,0,0,0,0,0,1
1,0,0,5,0,0,0,0,2,0,1,1
1,1,0,0,0,0,0,0,0,0,1,1
1,1,0,0,0,0,0,0,0,1,1,1
1,2,1,0,0,0,0,2,1,1,1,1
1,1,1,1,0,0,0,1,1,1,1,1
endlayer

layer
1,1,1,1,1,0,0,1,1,1,1,1
1,1,1,0,0,2,0,0,0,1,1,1
1,1,0,0,0,0,0,0,0,0,1,1
1,0,0,0,0,0,0,0,0,0,2,1
0,2,0,0,0,0,0,0,0,0,0,0
0,0,0,0,0,0,0,0,0,0,0,0
0,0,5,0,0,0,0,0,0,0,0,0
0,0,0,5,5,0,0,0,0,2,0,1
1,0,0,5,0,0,0,0,0,0,0,1
1,0,0,0,0,0,0,0,0,0,1,1
2,1,0,0,0,0,0,0,0,1,1,1
1,1,1,0,0,0,0,2,1,1,1,1
endlayer

layer
1,1,1,0,0,2,0,0,0,1,1,1
1,1,0,0,0,0,0,0,0,0,1,1
1,0,0,0,0,0,0,0,0,0,0,1
0,2,0,0,0,0,0,0,0,0,0,2
0,0,0,0,0,0,0,0,0,0,0,0
0,0,0,0,0,0,0,0,0,0,0,0
0,0,0,0,0,0,0,0,0,0,0,0
0,0,5,0,0,0,0,0,2,0,0,0
0,0,0,5,5,0,0,0,0,0,0,0
0,0,0,0,0,0,0,0,0,0,0,1
1,2,0,0,0,0,0,2,0,0,1,1
1,1,0,0,0,0,0,0,0,1,1,1
endlayer

layer
1,1,0,0,0,0,0,0,0,0,1,1
1,0,0,0,0,0,0,0,0,0,0,1
0,0,0,0,0,0,0,0,0,0,0,0
0,0,0,0,0,0,0,0,0,0,2,0
0,2,0,0,0,0,0,0,0,0,0,0
0,0,0,0,0,0,0,0,0,0,0,0
0,0,0,0,0,0,0,0,0,0,0,0
0,0,0,0,0,0,0,0,0,2,0,0
0,0,0,0,0,0,0,0,0,0,0,0
0,0,0,0,0,0,0,0,0,0,0,0
2,0,0,0,0,0,0,0,0,0,0,1
1,0,0,0,0,0,0,2,0,0,1,1
endlayer

layer
1,0,0,0,0,0,0,0,0,0,0,0
0,0,0,0,0,0,0,0,0,0,0,0
0,0,0,0,0,0,0,0,0,0,0,0
0,0,0,0,0,0,0,0,0,0,0,0
0,0,0,0,0,0,0,0,0,0,0,0
0,0,0,0,0,0,0,0,0,0,0,0
0,0,0,0,0,0,0,0,0,0,0,0
0,0,0,0,0,0,0,0,2,0,0,0
0,0,0,0,0,0,0,0,0,0,0,0
0,0,0,0,0,0,0,0,0,0,0,0
0,2,0,0,0,0,0,2,0,0,0,0
0,0,0,0,0,0,0,0,0,0,0,1
endlayer

