# Sunken Quartz Shrine -- 16 Apr 2014
# Updated to MC 1.7.10, 13 Oct 2014
# Created by Ruins mod version 12.3 Ingame Parser
# authoring Player: Jordan_Greywolf
# Verified for MC 1.8: 22 Jul 2015
# Updated for MC 1.11: 13 Jan 2017
# Verified for MC 1.12: 21 Jun 2017
# Updated to MC 1.12.1: 10 Sep 2017

# Last Updated: 6 Apr 2018

uniqueMinDistance=4000
spawnMinDistance=1000

biomesToSpawnIn=arctic_ocean,deep_ocean,kelp_forest,ocean,ocean_oil_field,oceanic_abyss,coral_reef

weight=1
embed_into_distance=19

acceptable_target_blocks=water,flowing_water,ice

dimensions=24,11,11
allowable_overhang=999
max_cut_in=0
cut_in_buffer=0
max_leveling=0
leveling_buffer=0
preserve_water=0
preserve_lava=0
preserve_plants=0

rule1=0,100,preserveBlock
rule2=0,100,minecraft:quartz_block-0
rule3=0,100,minecraft:sandstone-2
rule4=0,100,minecraft:glowstone
rule5=0,100,minecraft:vine-2
rule6=0,100,minecraft:vine-4
rule7=0,100,minecraft:vine-1
rule8=0,100,minecraft:vine-8
rule9=0,100,minecraft:water
rule10=0,100,minecraft:quartz_block-2
rule11=0,100,minecraft:quartz_block-1
rule12=0,100,minecraft:quartz_stairs-0
rule13=0,100,minecraft:stone_slab-7
rule14=0,100,minecraft:quartz_stairs-2
rule15=0,100,minecraft:quartz_stairs-3
rule16=0,100,minecraft:quartz_stairs-1
rule17=0,100,minecraft:glowstone

layer
1,1,1,1,2,2,2,1,1,1,1
1,1,2,2,2,2,2,2,2,1,1
1,2,2,2,3,3,3,2,2,2,1
1,2,2,3,3,3,3,3,2,2,1
2,2,3,3,3,3,3,3,3,2,2
2,2,3,3,3,3,3,3,3,2,2
2,2,3,3,3,3,3,3,3,2,2
1,2,2,3,3,3,3,3,2,2,1
1,2,2,2,3,3,3,2,2,2,1
1,1,2,2,2,2,2,2,2,1,1
1,1,1,1,2,2,2,1,1,1,1
endlayer

layer
1,1,1,1,2,2,2,1,1,1,1
1,1,2,2,0,0,0,2,2,1,1
1,2,0,0,2,2,2,0,0,2,1
1,2,0,2,4,4,4,2,0,2,1
2,0,2,4,4,4,4,4,2,0,2
2,0,2,4,4,4,4,4,2,0,2
2,0,2,4,4,4,4,4,2,0,2
1,2,0,2,4,4,4,2,0,2,1
1,2,0,0,2,2,2,0,0,2,1
1,1,2,2,0,0,0,2,2,1,1
1,1,1,1,2,2,2,1,1,1,1
endlayer

layer
1,1,1,1,2,2,2,1,1,1,1
1,1,2,2,0,0,0,2,2,1,1
1,2,0,0,2,2,2,0,0,2,1
1,2,0,2,0,0,0,2,0,2,1
2,0,2,0,0,0,0,0,2,0,2
2,0,2,0,0,0,0,0,2,0,2
2,0,2,0,0,0,0,0,2,0,2
1,2,0,2,0,0,0,2,0,2,1
1,2,0,0,2,2,2,0,0,2,1
1,1,2,2,0,0,0,2,2,1,1
1,1,1,1,2,2,2,1,1,1,1
endlayer

layer
1,1,1,1,2,2,2,1,1,1,1
1,1,2,2,0,0,0,2,2,1,1
1,2,0,0,0,0,0,0,0,2,1
1,2,0,0,0,0,0,0,0,2,1
2,0,0,0,0,0,0,0,0,0,2
2,0,0,0,0,0,0,0,0,0,2
2,0,0,0,0,0,0,0,0,0,2
1,2,0,0,0,0,0,0,0,2,1
1,2,0,0,0,0,0,0,0,2,1
1,1,2,2,0,0,0,2,2,1,1
1,1,1,1,2,2,2,1,1,1,1
endlayer

layer
1,1,1,1,2,2,2,1,1,1,1
1,1,2,2,0,5,0,2,2,1,1
1,2,0,5,0,0,0,5,0,2,1
1,2,7,0,0,0,0,0,6,2,1
2,0,0,0,0,0,0,0,0,0,2
2,7,0,0,0,0,0,0,0,6,2
2,0,0,0,0,0,0,0,0,0,2
1,2,7,0,0,0,0,0,6,2,1
1,2,0,8,0,0,0,8,0,2,1
1,1,2,2,0,8,0,2,2,1,1
1,1,1,1,2,2,2,1,1,1,1
endlayer

layer
1,1,1,9,9,10,9,9,1,1,1
1,1,9,10,0,5,0,10,9,1,1
1,9,9,5,0,0,0,5,9,9,1
9,10,7,0,0,0,0,0,6,10,9
9,0,0,0,0,0,0,0,0,0,9
10,7,0,0,0,0,0,0,0,6,10
9,0,0,0,0,0,0,0,0,0,9
9,10,7,0,0,0,0,0,6,10,9
1,9,0,8,0,0,0,8,9,9,1
1,1,9,10,0,8,0,10,9,1,1
1,1,1,9,9,10,9,9,1,1,1
endlayer

layer
1,1,9,9,9,10,9,9,9,1,1
1,9,9,10,0,5,0,10,9,9,1
9,9,9,5,0,0,0,5,9,9,9
9,10,7,0,0,0,0,0,6,10,9
9,0,0,0,0,0,0,0,0,0,9
10,7,0,0,0,0,0,0,0,6,10
9,0,0,0,0,0,0,0,0,0,9
9,10,7,0,0,0,0,0,6,10,9
9,9,0,8,0,0,0,8,9,9,9
1,9,9,10,0,8,0,10,9,9,1
1,1,9,9,9,10,9,9,9,1,1
endlayer

layer
1,9,9,9,9,10,9,9,9,9,1
9,9,9,10,0,5,0,10,9,9,9
9,9,9,5,0,0,0,5,9,9,9
9,10,7,0,0,0,0,0,6,10,9
9,0,0,0,0,0,0,0,0,0,9
10,7,0,0,0,0,0,0,0,6,10
9,0,0,0,0,0,0,0,0,0,9
9,10,7,0,0,0,0,0,6,10,9
9,9,0,8,0,0,0,8,9,9,9
9,9,9,10,0,8,0,10,9,9,9
1,9,9,9,9,10,9,9,9,9,1
endlayer

layer
9,9,9,9,9,10,9,9,9,9,9
9,9,9,10,0,5,0,10,9,9,9
9,9,9,5,0,0,0,5,9,9,9
9,10,7,0,0,0,0,0,6,10,9
9,0,0,0,0,0,0,0,0,0,9
10,7,0,0,0,0,0,0,0,6,10
9,0,0,0,0,0,0,0,0,0,9
9,10,7,0,0,0,0,0,6,10,9
9,9,0,8,0,0,0,8,9,9,9
9,9,9,10,0,8,0,10,9,9,9
9,9,9,9,9,10,9,9,9,9,9
endlayer

layer
9,9,9,9,9,10,9,9,9,9,9
9,9,9,10,0,5,0,10,9,9,9
9,9,9,5,0,0,0,5,9,9,9
9,10,7,0,0,0,0,0,6,10,9
9,0,0,0,0,0,0,0,0,0,9
10,7,0,0,0,0,0,0,0,6,10
9,0,0,0,0,0,0,0,0,0,9
9,10,7,0,0,0,0,0,6,10,9
9,9,0,8,0,0,0,8,9,9,9
9,9,9,10,0,8,0,10,9,9,9
9,9,9,9,9,10,9,9,9,9,9
endlayer

layer
9,9,9,9,9,10,9,9,9,9,9
9,9,9,10,0,5,0,10,9,9,9
9,9,9,5,0,0,0,5,9,9,9
9,10,7,0,0,0,0,0,6,10,9
9,0,0,0,0,0,0,0,0,0,9
10,7,0,0,0,0,0,0,0,6,10
9,0,0,0,0,0,0,0,0,0,9
9,10,7,0,0,0,0,0,6,10,9
9,9,0,8,0,0,0,8,9,9,9
9,9,9,10,0,8,0,10,9,9,9
9,9,9,9,9,10,9,9,9,9,9
endlayer

layer
9,9,9,9,9,10,9,9,9,9,9
9,9,9,10,0,5,0,10,9,9,9
9,9,9,5,0,0,0,5,9,9,9
9,10,7,0,0,0,0,0,6,10,9
9,0,0,0,0,0,0,0,0,0,9
10,7,0,0,0,0,0,0,0,6,10
9,0,0,0,0,0,0,0,0,0,9
9,10,7,0,0,0,0,0,6,10,9
9,9,0,8,0,0,0,8,9,9,9
9,9,9,10,0,8,0,10,9,9,9
9,9,9,9,9,10,9,9,9,9,9
endlayer

layer
9,9,9,9,9,10,9,9,9,9,9
9,9,9,10,0,5,0,10,9,9,9
9,9,9,5,0,0,0,5,9,0,9
9,10,7,0,0,0,0,0,6,10,9
9,0,0,0,0,0,0,0,0,0,9
10,7,0,0,0,0,0,0,0,6,10
9,0,0,0,0,0,0,0,0,0,9
9,10,7,0,0,0,0,0,6,10,9
9,9,0,8,0,0,0,8,9,9,9
9,9,9,10,0,8,0,10,9,9,9
9,9,9,9,9,10,9,9,9,9,9
endlayer

layer
9,9,9,9,9,10,9,9,9,9,9
9,9,9,10,0,5,0,10,9,9,9
9,9,9,5,0,0,0,5,9,9,9
9,10,7,0,0,0,0,0,6,10,9
9,0,0,0,0,0,0,0,0,0,9
10,7,0,0,0,0,0,0,0,6,10
9,0,0,0,0,0,0,0,0,0,9
9,10,7,0,0,0,0,0,6,10,9
9,9,0,8,0,0,0,8,9,9,9
9,9,9,10,0,8,0,10,9,9,9
9,9,9,9,9,10,9,9,9,9,9
endlayer

layer
9,9,9,9,9,10,9,9,9,9,9
9,9,9,10,0,5,0,10,9,9,9
9,9,9,5,0,0,0,5,9,9,9
9,10,7,0,0,0,0,0,6,10,9
9,0,0,0,0,0,0,0,0,0,9
10,7,0,0,0,0,0,0,0,6,10
9,0,0,0,0,0,0,0,0,0,9
9,10,7,0,0,0,0,0,6,10,9
9,9,0,8,0,0,0,8,9,9,9
9,9,9,10,0,8,0,10,9,9,9
9,9,9,9,9,10,9,9,9,9,9
endlayer

layer
9,9,9,9,9,10,9,9,9,9,9
9,9,9,10,0,5,0,10,9,9,9
9,9,9,5,0,0,0,5,9,9,9
9,10,7,0,0,0,0,0,6,10,9
9,0,0,0,0,0,0,0,0,0,9
10,7,0,0,0,0,0,0,0,6,10
9,0,0,0,0,0,0,0,0,0,9
9,10,7,0,0,0,0,0,6,10,9
9,9,0,8,0,0,0,8,9,9,9
9,9,9,10,0,8,0,10,9,9,9
9,9,9,9,9,10,9,9,9,9,9
endlayer

layer
9,9,9,9,9,10,9,9,9,9,9
9,9,9,10,0,5,0,10,9,9,9
9,9,9,5,0,0,0,5,9,9,9
9,10,7,0,0,0,0,0,6,10,9
9,0,0,0,0,0,0,0,0,0,9
10,7,0,0,0,0,0,0,0,6,10
9,0,0,0,0,0,0,0,0,0,9
9,10,7,0,0,0,0,0,6,10,9
9,9,0,8,0,0,0,8,9,9,9
9,9,9,10,0,8,0,10,9,9,9
9,9,9,9,9,10,9,9,9,9,9
endlayer

layer
9,9,9,9,9,11,9,9,9,9,9
9,9,9,11,0,5,0,11,9,9,9
9,9,9,5,0,0,0,5,9,9,9
9,11,7,0,0,0,0,0,6,11,9
9,0,0,0,0,0,0,0,0,0,9
11,7,0,0,0,0,0,0,0,6,11
9,0,0,0,0,0,0,0,0,0,9
9,11,7,0,0,0,0,0,6,11,9
9,9,0,8,0,0,0,8,9,9,9
9,9,9,11,0,8,0,11,9,9,9
9,9,9,9,9,11,9,9,9,9,9
endlayer

layer
9,9,9,9,2,2,2,9,9,9,9
9,9,2,2,2,5,2,2,2,9,9
9,2,2,0,0,0,0,0,2,2,9
9,2,0,0,0,0,0,0,0,2,9
2,2,0,0,0,0,0,0,0,2,2
2,0,0,0,0,0,0,0,0,0,2
2,2,0,0,0,0,0,0,0,2,2
9,2,0,0,0,0,0,0,0,2,9
9,2,2,0,0,0,0,0,2,2,9
9,9,2,2,2,0,2,2,2,9,9
9,9,9,9,2,2,2,9,9,9,9
endlayer

layer
0,0,0,0,12,2,12,0,0,0,0
0,0,13,2,2,2,2,2,13,0,0
0,13,2,0,0,0,0,0,2,13,0
0,2,0,0,0,0,0,0,0,2,0
15,2,0,0,0,0,0,0,0,2,14
2,2,0,0,0,0,0,0,0,2,2
15,2,0,0,0,0,0,0,0,2,14
0,2,0,0,0,0,0,0,0,2,0
0,13,2,0,0,0,0,0,2,13,0
0,0,13,2,2,2,2,2,13,0,0
0,0,0,0,16,2,16,0,0,0,0
endlayer

layer
0,0,0,0,0,0,0,0,0,0,0
0,0,0,2,2,2,2,2,0,0,0
0,0,2,0,0,0,0,0,2,0,0
0,2,0,0,0,0,0,0,0,2,0
0,2,0,0,0,0,0,0,0,2,0
0,2,0,0,0,0,0,0,0,2,0
0,2,0,0,0,0,0,0,0,2,0
0,2,0,0,0,0,0,0,0,2,0
0,0,2,0,0,0,0,0,2,0,0
0,0,0,2,2,2,2,2,0,0,0
0,0,0,0,0,0,0,0,0,0,0
endlayer

layer
0,0,0,0,0,0,0,0,0,0,0
0,0,0,0,0,12,0,0,0,0,0
0,0,0,2,2,2,2,2,0,0,0
0,0,2,0,0,0,0,0,2,0,0
0,0,2,0,0,0,0,0,2,0,0
0,15,2,0,0,0,0,0,2,14,0
0,0,2,0,0,0,0,0,2,0,0
0,0,2,0,0,0,0,0,2,0,0
0,0,0,2,2,2,2,2,0,0,0
0,0,0,0,0,16,0,0,0,0,0
0,0,0,0,0,0,0,0,0,0,0
endlayer

layer
0,0,0,0,0,0,0,0,0,0,0
0,0,0,0,0,0,0,0,0,0,0
0,0,0,0,0,13,0,0,0,0,0
0,0,0,13,2,2,2,13,0,0,0
0,0,0,2,2,2,2,2,0,0,0
0,0,13,2,2,17,2,2,13,0,0
0,0,0,2,2,2,2,2,0,0,0
0,0,0,13,2,2,2,13,0,0,0
0,0,0,0,0,13,0,0,0,0,0
0,0,0,0,0,0,0,0,0,0,0
0,0,0,0,0,0,0,0,0,0,0
endlayer

layer
0,0,0,0,0,0,0,0,0,0,0
0,0,0,0,0,0,0,0,0,0,0
0,0,0,0,0,0,0,0,0,0,0
0,0,0,0,0,0,0,0,0,0,0
0,0,0,0,13,2,13,0,0,0,0
0,0,0,0,2,17,2,0,0,0,0
0,0,0,0,13,2,13,0,0,0,0
0,0,0,0,0,0,0,0,0,0,0
0,0,0,0,0,0,0,0,0,0,0
0,0,0,0,0,0,0,0,0,0,0
0,0,0,0,0,0,0,0,0,0,0
endlayer

