# Titan Ribcage
# Created by Ruins mod version 16.8 Ingame Parser
# authoring Player: Jordan_Greywolf

# Last Updated: 1 Aug 2018

biomesToSpawnIn=boneyard,corrupted sands,corrupted_sands,fungi_forest,hell,phantasmagoric inferno,phantasmagoric_inferno,spectral garden,spectral_garden,undergarden,visceral heap,visceral_heap

weight=1
embed_into_distance=0
acceptable_target_blocks=

unacceptable_target_blocks=flowing_water,water,command_block

dimensions=64,7,6
allowable_overhang=99
max_leveling=12
leveling_buffer=-1
preserve_water=1
preserve_lava=1
preserve_plants=1

rule1=0,100,preserveBlock
rule2=0,100,minecraft:bone_block-8
rule3=0,100,minecraft:bone_block-4
rule4=0,100,minecraft:bone_block-0
rule5=0,100,minecraft:vine-4

layer
1,2,2,2,1,1
2,1,1,1,3,1
1,1,1,1,3,1
1,1,1,5,4,2
1,1,1,1,3,1
2,1,1,1,3,1
1,2,2,2,1,1
endlayer

layer
1,1,1,1,1,1
1,1,1,1,1,1
1,1,1,1,1,1
1,1,1,5,4,1
1,1,1,1,1,1
1,1,1,1,1,1
1,1,1,1,1,1
endlayer

layer
1,2,2,2,1,1
2,1,1,1,3,1
1,1,1,1,3,1
1,1,1,5,4,2
1,1,1,1,3,1
2,1,1,1,3,1
1,2,2,2,1,1
endlayer

layer
1,1,1,1,1,1
1,1,1,1,1,1
1,1,1,1,1,1
1,1,1,5,4,1
1,1,1,1,1,1
1,1,1,1,1,1
1,1,1,1,1,1
endlayer

layer
1,2,2,2,1,1
2,1,1,1,3,1
1,1,1,1,3,1
1,1,1,5,4,2
1,1,1,1,3,1
2,1,1,1,3,1
1,2,2,2,1,1
endlayer

layer
1,1,1,1,1,1
1,1,1,1,1,1
1,1,1,1,1,1
1,1,1,5,4,1
1,1,1,1,1,1
1,1,1,1,1,1
1,1,1,1,1,1
endlayer

layer
1,2,2,2,1,1
2,1,1,1,3,1
1,1,1,1,3,1
1,1,1,5,4,2
1,1,1,1,3,1
2,1,1,1,3,1
1,2,2,2,1,1
endlayer

layer
1,1,1,1,1,1
1,1,1,1,1,1
1,1,1,1,1,1
1,1,1,5,4,1
1,1,1,1,1,1
1,1,1,1,1,1
1,1,1,1,1,1
endlayer

layer
1,2,2,2,1,1
2,1,1,1,3,1
1,1,1,1,3,1
1,1,1,5,4,2
1,1,1,1,3,1
2,1,1,1,3,1
1,2,2,2,1,1
endlayer

layer
1,1,1,1,1,1
1,1,1,1,1,1
1,1,1,1,1,1
1,1,1,5,4,1
1,1,1,1,1,1
1,1,1,1,1,1
1,1,1,1,1,1
endlayer

layer
1,2,2,2,1,1
2,1,1,1,3,1
1,1,1,1,3,1
1,1,1,5,4,2
1,1,1,1,3,1
2,1,1,1,3,1
1,2,2,2,1,1
endlayer

layer
1,1,1,1,1,1
1,1,1,1,1,1
1,1,1,1,1,1
1,1,1,5,4,1
1,1,1,1,1,1
1,1,1,1,1,1
1,1,1,1,1,1
endlayer

layer
1,2,2,2,1,1
2,1,1,1,3,1
1,1,1,1,3,1
1,1,1,5,4,2
1,1,1,1,3,1
2,1,1,1,3,1
1,2,2,2,1,1
endlayer

layer
1,1,1,1,1,1
1,1,1,1,1,1
1,1,1,1,1,1
1,1,1,5,4,1
1,1,1,1,1,1
1,1,1,1,1,1
1,1,1,1,1,1
endlayer

layer
1,2,2,2,1,1
2,1,1,1,3,1
1,1,1,1,3,1
1,1,1,5,4,2
1,1,1,1,3,1
2,1,1,1,3,1
1,2,2,2,1,1
endlayer

layer
1,1,1,1,1,1
1,1,1,1,1,1
1,1,1,1,1,1
1,1,1,5,4,1
1,1,1,1,1,1
1,1,1,1,1,1
1,1,1,1,1,1
endlayer

layer
1,2,2,2,1,1
2,1,1,1,3,1
1,1,1,1,3,1
1,1,1,5,4,2
1,1,1,1,3,1
2,1,1,1,3,1
1,2,2,2,1,1
endlayer

layer
1,1,1,1,1,1
1,1,1,1,1,1
1,1,1,1,1,1
1,1,1,5,4,1
1,1,1,1,1,1
1,1,1,1,1,1
1,1,1,1,1,1
endlayer

layer
1,2,2,2,1,1
2,1,1,1,3,1
1,1,1,1,3,1
1,1,1,5,4,2
1,1,1,1,3,1
2,1,1,1,3,1
1,2,2,2,1,1
endlayer

layer
1,1,1,1,1,1
1,1,1,1,1,1
1,1,1,1,1,1
1,1,1,5,4,1
1,1,1,1,1,1
1,1,1,1,1,1
1,1,1,1,1,1
endlayer

layer
1,2,2,2,1,1
2,1,1,1,3,1
1,1,1,1,3,1
1,1,1,5,4,2
1,1,1,1,3,1
2,1,1,1,3,1
1,2,2,2,1,1
endlayer

layer
1,1,1,1,1,1
1,1,1,1,1,1
1,1,1,1,1,1
1,1,1,5,4,1
1,1,1,1,1,1
1,1,1,1,1,1
1,1,1,1,1,1
endlayer

layer
1,2,2,2,1,1
2,1,1,1,3,1
1,1,1,1,3,1
1,1,1,5,4,2
1,1,1,1,3,1
2,1,1,1,3,1
1,2,2,2,1,1
endlayer

layer
1,1,1,1,1,1
1,1,1,1,1,1
1,1,1,1,1,1
1,1,1,5,4,1
1,1,1,1,1,1
1,1,1,1,1,1
1,1,1,1,1,1
endlayer

layer
1,2,2,2,1,1
2,1,1,1,3,1
1,1,1,1,3,1
1,1,1,5,4,2
1,1,1,1,3,1
2,1,1,1,3,1
1,2,2,2,1,1
endlayer

layer
1,1,1,1,1,1
1,1,1,1,1,1
1,1,1,1,1,1
1,1,1,5,4,1
1,1,1,1,1,1
1,1,1,1,1,1
1,1,1,1,1,1
endlayer

layer
1,2,2,2,1,1
2,1,1,1,3,1
1,1,1,1,3,1
1,1,1,5,4,2
1,1,1,1,3,1
2,1,1,1,3,1
1,2,2,2,1,1
endlayer

layer
1,1,1,1,1,1
1,1,1,1,1,1
1,1,1,1,1,1
1,1,1,5,4,1
1,1,1,1,1,1
1,1,1,1,1,1
1,1,1,1,1,1
endlayer

layer
1,2,2,2,1,1
2,1,1,1,3,1
1,1,1,1,3,1
1,1,1,5,4,2
1,1,1,1,3,1
2,1,1,1,3,1
1,2,2,2,1,1
endlayer

layer
1,1,1,1,1,1
1,1,1,1,1,1
1,1,1,1,1,1
1,1,1,5,4,1
1,1,1,1,1,1
1,1,1,1,1,1
1,1,1,1,1,1
endlayer

layer
1,2,2,2,1,1
2,1,1,1,3,1
1,1,1,1,3,1
1,1,1,5,4,2
1,1,1,1,3,1
2,1,1,1,3,1
1,2,2,2,1,1
endlayer

layer
1,1,1,1,1,1
1,1,1,1,1,1
1,1,1,1,1,1
1,1,1,5,4,1
1,1,1,1,1,1
1,1,1,1,1,1
1,1,1,1,1,1
endlayer

layer
1,2,2,2,1,1
2,1,1,1,3,1
1,1,1,1,3,1
1,1,1,5,4,2
1,1,1,1,3,1
2,1,1,1,3,1
1,2,2,2,1,1
endlayer

layer
1,1,1,1,1,1
1,1,1,1,1,1
1,1,1,1,1,1
1,1,1,5,4,1
1,1,1,1,1,1
1,1,1,1,1,1
1,1,1,1,1,1
endlayer

layer
1,2,2,2,1,1
2,1,1,1,3,1
1,1,1,1,3,1
1,1,1,5,4,2
1,1,1,1,3,1
2,1,1,1,3,1
1,2,2,2,1,1
endlayer

layer
1,1,1,1,1,1
1,1,1,1,1,1
1,1,1,1,1,1
1,1,1,5,4,1
1,1,1,1,1,1
1,1,1,1,1,1
1,1,1,1,1,1
endlayer

layer
1,2,2,2,1,1
2,1,1,1,3,1
1,1,1,1,3,1
1,1,1,5,4,2
1,1,1,1,3,1
2,1,1,1,3,1
1,2,2,2,1,1
endlayer

layer
1,1,1,1,1,1
1,1,1,1,1,1
1,1,1,1,1,1
1,1,1,5,4,1
1,1,1,1,1,1
1,1,1,1,1,1
1,1,1,1,1,1
endlayer

layer
1,2,2,2,1,1
2,1,1,1,3,1
1,1,1,1,3,1
1,1,1,5,4,2
1,1,1,1,3,1
2,1,1,1,3,1
1,2,2,2,1,1
endlayer

layer
1,1,1,1,1,1
1,1,1,1,1,1
1,1,1,1,1,1
1,1,1,5,4,1
1,1,1,1,1,1
1,1,1,1,1,1
1,1,1,1,1,1
endlayer

layer
1,2,2,2,1,1
2,1,1,1,3,1
1,1,1,1,3,1
1,1,1,5,4,2
1,1,1,1,3,1
2,1,1,1,3,1
1,2,2,2,1,1
endlayer

layer
1,1,1,1,1,1
1,1,1,1,1,1
1,1,1,1,1,1
1,1,1,5,4,1
1,1,1,1,1,1
1,1,1,1,1,1
1,1,1,1,1,1
endlayer

layer
1,2,2,2,1,1
2,1,1,1,3,1
1,1,1,1,3,1
1,1,1,5,4,2
1,1,1,1,3,1
2,1,1,1,3,1
1,2,2,2,1,1
endlayer

layer
1,1,1,1,1,1
1,1,1,1,1,1
1,1,1,1,1,1
1,1,1,5,4,1
1,1,1,1,1,1
1,1,1,1,1,1
1,1,1,1,1,1
endlayer

layer
1,2,2,2,1,1
2,1,1,1,3,1
1,1,1,1,3,1
1,1,1,5,4,2
1,1,1,1,3,1
2,1,1,1,3,1
1,2,2,2,1,1
endlayer

layer
1,1,1,1,1,1
1,1,1,1,1,1
1,1,1,1,1,1
1,1,1,5,4,1
1,1,1,1,1,1
1,1,1,1,1,1
1,1,1,1,1,1
endlayer

layer
1,2,2,2,1,1
2,1,1,1,3,1
1,1,1,1,3,1
1,1,1,5,4,2
1,1,1,1,3,1
2,1,1,1,3,1
1,2,2,2,1,1
endlayer

layer
1,1,1,1,1,1
1,1,1,1,1,1
1,1,1,1,1,1
1,1,1,5,4,1
1,1,1,1,1,1
1,1,1,1,1,1
1,1,1,1,1,1
endlayer

layer
1,2,2,2,1,1
2,1,1,1,3,1
1,1,1,1,3,1
1,1,1,5,4,2
1,1,1,1,3,1
2,1,1,1,3,1
1,2,2,2,1,1
endlayer

layer
1,1,1,1,1,1
1,1,1,1,1,1
1,1,1,1,1,1
1,1,1,5,4,1
1,1,1,1,1,1
1,1,1,1,1,1
1,1,1,1,1,1
endlayer

layer
1,2,2,2,1,1
2,1,1,1,3,1
1,1,1,1,3,1
1,1,1,5,4,2
1,1,1,1,3,1
2,1,1,1,3,1
1,2,2,2,1,1
endlayer

layer
1,1,1,1,1,1
1,1,1,1,1,1
1,1,1,1,1,1
1,1,1,5,4,1
1,1,1,1,1,1
1,1,1,1,1,1
1,1,1,1,1,1
endlayer

layer
1,2,2,2,1,1
2,1,1,1,3,1
1,1,1,1,3,1
1,1,1,5,4,2
1,1,1,1,3,1
2,1,1,1,3,1
1,2,2,2,1,1
endlayer

layer
1,1,1,1,1,1
1,1,1,1,1,1
1,1,1,1,1,1
1,1,1,5,4,1
1,1,1,1,1,1
1,1,1,1,1,1
1,1,1,1,1,1
endlayer

layer
1,2,2,2,1,1
2,1,1,1,3,1
1,1,1,1,3,1
1,1,1,5,4,2
1,1,1,1,3,1
2,1,1,1,3,1
1,2,2,2,1,1
endlayer

layer
1,1,1,1,1,1
1,1,1,1,1,1
1,1,1,1,1,1
1,1,1,5,4,1
1,1,1,1,1,1
1,1,1,1,1,1
1,1,1,1,1,1
endlayer

layer
1,2,2,2,1,1
2,1,1,1,3,1
1,1,1,1,3,1
1,1,1,5,4,2
1,1,1,1,3,1
2,1,1,1,3,1
1,2,2,2,1,1
endlayer

layer
1,1,1,1,1,1
1,1,1,1,1,1
1,1,1,1,1,1
1,1,1,5,4,1
1,1,1,1,1,1
1,1,1,1,1,1
1,1,1,1,1,1
endlayer

layer
1,2,2,2,1,1
2,1,1,1,3,1
1,1,1,1,3,1
1,1,1,5,4,2
1,1,1,1,3,1
2,1,1,1,3,1
1,2,2,2,1,1
endlayer

layer
1,1,1,1,1,1
1,1,1,1,1,1
1,1,1,1,1,1
1,1,1,5,4,1
1,1,1,1,1,1
1,1,1,1,1,1
1,1,1,1,1,1
endlayer

layer
1,2,2,2,1,1
2,1,1,1,3,1
1,1,1,1,3,1
1,1,1,5,4,2
1,1,1,1,3,1
2,1,1,1,3,1
1,2,2,2,1,1
endlayer

layer
1,1,1,1,1,1
1,1,1,1,1,1
1,1,1,1,1,1
1,1,1,5,4,1
1,1,1,1,1,1
1,1,1,1,1,1
1,1,1,1,1,1
endlayer

layer
1,2,2,2,1,1
2,1,1,1,3,1
1,1,1,1,3,1
1,1,1,5,4,2
1,1,1,1,3,1
2,1,1,1,3,1
1,2,2,2,1,1
endlayer

layer
1,1,1,1,1,1
1,1,1,1,1,1
1,1,1,1,1,1
1,1,1,5,4,1
1,1,1,1,1,1
1,1,1,1,1,1
1,1,1,1,1,1
endlayer


