# Chisel / Twilight Forest Cloud Tower
# Created by Ruins mod version 17.1 Ingame Parser
# authoring Player: Jordan_Greywolf
# Created for MC 1.12 with Twilight Forest & Chisel mods: 4 Jul 2018

biomesToSpawnIn=alps,alps_foothills,bayou,beaches,biome_meneglin,bog,boreal_forest,brushland,chaparral,cold_beach,cold_desert,coniferous_forest,coral_reef,crag,dead_forest,dead_swamp,deep_ocean,enchanted_forest,eucalyptus_forest,extreme_hills,extreme_hills_with_trees,fen,firefly_forest,flower_field,flower_island,frozen_ocean,frozen_river,glacier,gravel_beach,grove,ice_mountains,land_of_lakes,lavender_fields,lush_desert,lush_swamp,maple_woods,marsh,miningbiome,moor,mountain,mountain_foothills,mutated_birch_forest,mutated_birch_forest_hills,mutated_extreme_hills,mutated_extreme_hills_with_trees,mutated_forest,mutated_ice_flats,mutated_plains,mystic_grove,oak_savannah,ominous_woods,orchard,origin_beach,origin_island,outback,overgrown_cliffs,quagmire,rainforest,river,rwg_plains,sacred_springs,seasonal_forest,shield,smaller_extreme_hills,snowy_coniferous_forest,steppe,stone_beach,twilight_clearing,twilight_forest,twilight_lake,twilight_stream,twilight_swamp,volcanic_island,wasteland,woodland,xeric_shrubland

uniqueMinDistance=2000

weight=1
embed_into_distance=-128
acceptable_target_blocks=
unacceptable_target_blocks=command_block

dimensions=19,16,16
allowable_overhang=999
max_leveling=64
leveling_buffer=-1
preserve_water=0
preserve_lava=0

rule1=0,100,twilightforest:wispy_cloud-0
rule2=0,100,chisel:cloud-0
rule3=0,100,chisel:cloud-4
rule4=0,100,chisel:cloud-2
rule5=0,100,twilightforest:fluffy_cloud-0
rule6=0,100,chisel:cloud-3
rule7=0,100,ChestGenHook:chests/simple_dungeon:5-3

layer
0,0,0,0,0,0,0,0,0,0,0,0,0,0,0,0
0,0,0,0,1,0,0,1,1,0,0,0,0,0,0,0
0,1,1,0,0,0,1,1,1,1,0,0,1,1,0,0
0,1,1,0,0,0,1,1,1,1,0,1,1,1,1,0
0,0,0,0,0,0,0,1,1,0,0,1,1,1,1,0
0,0,0,1,1,0,0,0,0,0,0,0,1,1,0,0
0,0,0,1,1,0,0,0,0,0,0,0,0,0,0,0
0,0,0,0,0,0,0,1,1,0,0,0,0,0,0,0
0,1,0,0,0,0,0,1,1,0,0,1,1,0,0,0
0,0,0,0,0,0,0,0,0,0,1,1,1,1,0,0
0,0,0,0,1,1,0,0,0,1,1,1,1,1,1,0
0,0,0,1,1,1,1,0,0,1,1,1,1,1,1,0
0,0,0,1,1,1,1,0,0,0,1,1,1,1,0,0
0,0,0,0,1,1,0,0,0,0,0,1,1,0,0,0
0,0,0,0,0,0,0,0,0,0,0,0,0,0,0,0
0,0,0,0,0,0,0,0,0,0,0,0,0,0,0,0
endlayer

layer
0,0,0,0,0,0,0,1,1,0,0,0,0,0,0,0
0,1,1,0,0,0,1,1,1,1,0,0,1,1,0,0
1,2,2,1,0,1,1,2,2,1,1,1,1,1,1,0
1,2,2,1,0,1,1,2,2,1,1,1,2,2,1,1
0,1,1,1,1,0,1,1,1,1,1,1,2,2,1,1
0,0,1,2,2,1,0,1,1,0,0,1,1,1,1,0
0,0,1,2,2,1,0,0,0,0,0,0,1,1,0,0
0,0,0,1,1,0,0,0,0,0,0,1,1,0,0,0
0,0,0,0,0,0,0,0,0,0,1,1,1,1,0,0
0,0,0,0,1,1,0,0,0,1,1,1,1,1,1,0
0,0,0,1,1,1,1,0,1,1,1,2,2,1,1,1
0,0,1,1,2,2,1,1,1,1,1,2,2,1,1,1
0,0,1,1,2,2,1,1,0,1,1,1,1,1,1,0
0,0,0,1,1,1,1,0,0,0,1,1,1,1,0,0
0,0,0,0,1,1,0,0,0,0,0,1,1,0,0,0
0,0,0,0,0,0,0,0,0,0,0,0,0,0,0,0
endlayer

layer
0,0,0,0,0,0,0,0,0,0,0,0,0,0,0,0
0,0,0,0,0,0,0,1,1,0,0,0,1,1,0,0
0,1,1,0,0,0,1,1,1,1,0,1,2,2,1,0
0,1,1,0,0,0,1,1,1,1,1,2,2,2,2,1
0,0,0,0,0,0,0,1,1,0,1,2,2,2,2,1
0,0,0,1,1,0,0,0,0,0,0,1,2,2,1,0
0,0,0,1,1,0,1,1,1,0,0,0,1,1,0,0
0,0,0,0,0,0,1,1,1,0,0,1,1,0,0,0
0,0,0,0,1,1,1,1,1,0,1,1,1,1,0,0
0,0,0,1,1,1,1,0,0,1,1,2,2,1,1,0
0,0,1,1,2,2,1,1,1,1,2,2,2,2,1,1
0,1,1,2,2,2,2,1,1,1,2,2,2,2,1,1
0,1,1,2,2,2,2,1,1,1,1,2,2,1,1,0
0,0,1,1,2,2,1,1,0,0,1,1,1,1,0,0
0,0,0,1,1,1,1,0,0,0,0,1,1,0,0,0
0,0,0,0,1,1,0,0,0,0,0,0,0,0,0,0
endlayer

layer
0,0,0,0,0,0,0,0,0,0,0,0,0,0,0,0
0,0,0,0,0,0,0,0,0,0,0,0,0,0,0,0
0,0,0,0,0,0,0,0,0,0,0,0,1,1,0,0
0,0,0,0,0,0,0,0,0,0,0,1,2,2,1,0
0,0,0,0,0,0,0,0,0,0,0,1,2,2,1,0
0,0,0,0,0,0,1,1,1,0,0,0,1,1,0,0
0,0,0,0,0,1,2,2,2,1,0,0,0,0,0,0
0,0,0,0,0,1,2,2,2,1,0,0,0,0,0,0
0,0,0,0,0,1,2,2,2,1,0,1,1,0,0,0
0,0,0,0,1,1,1,1,1,0,1,1,1,1,0,0
0,0,0,1,1,1,1,0,0,1,1,2,2,1,1,0
0,0,1,1,2,2,1,1,0,1,1,2,2,1,1,0
0,0,1,1,2,2,1,1,0,0,1,1,1,1,0,0
0,0,0,1,1,1,1,0,0,0,0,1,1,0,0,0
0,0,0,0,1,1,0,0,0,0,0,0,0,0,0,0
0,0,0,0,0,0,0,0,0,0,0,0,0,0,0,0
endlayer

layer
0,0,0,0,0,0,0,0,0,0,0,0,0,0,0,0
0,0,0,0,0,0,0,0,0,0,0,0,0,0,0,0
0,0,0,0,0,0,0,0,0,0,0,0,0,0,0,0
0,0,0,0,0,0,0,0,0,0,0,0,1,1,0,0
0,0,0,0,0,0,1,1,1,0,0,0,1,1,0,0
0,0,0,0,0,1,2,2,2,1,0,0,0,0,0,0
0,0,0,0,1,2,2,2,2,2,1,0,0,0,0,0
0,0,0,0,1,2,2,2,2,2,1,0,0,0,0,0
0,0,0,0,1,2,2,2,2,2,1,0,0,0,0,0
0,0,0,0,0,1,2,2,2,1,0,1,1,0,0,0
0,0,0,0,1,1,1,1,1,0,1,1,1,1,0,0
0,0,0,1,1,1,1,0,0,0,1,1,1,1,0,0
0,0,0,1,1,1,1,0,0,0,0,1,1,0,0,0
0,0,0,0,1,1,0,0,0,0,0,0,0,0,0,0
0,0,0,0,0,0,0,0,0,0,0,0,0,0,0,0
0,0,0,0,0,0,0,0,0,0,0,0,0,0,0,0
endlayer

layer
0,0,0,0,0,0,0,0,0,0,0,0,0,0,0,0
0,0,0,0,0,0,0,0,0,0,0,0,0,0,0,0
0,0,0,0,0,0,0,0,0,0,0,0,0,0,0,0
0,0,0,0,0,0,0,0,0,0,0,0,0,0,0,0
0,0,0,0,0,0,1,1,1,0,0,0,0,0,0,0
0,0,0,0,0,1,2,2,2,1,0,0,0,0,0,0
0,0,0,0,1,2,3,3,3,2,1,0,0,0,0,0
0,0,0,0,1,2,3,3,3,2,1,0,0,0,0,0
0,0,0,0,1,2,3,3,3,2,1,0,0,0,0,0
0,0,0,0,0,1,2,2,2,1,0,0,0,0,0,0
0,0,0,0,0,0,1,1,1,0,0,0,0,0,0,0
0,0,0,0,0,0,0,0,0,0,0,0,0,0,0,0
0,0,0,0,0,0,0,0,0,0,0,0,0,0,0,0
0,0,0,0,0,0,0,0,0,0,0,0,0,0,0,0
0,0,0,0,0,0,0,0,0,0,0,0,0,0,0,0
0,0,0,0,0,0,0,0,0,0,0,0,0,0,0,0
endlayer

layer
0,0,0,0,0,0,0,0,0,0,0,0,0,0,0,0
0,0,0,0,0,0,0,0,0,0,0,0,0,0,0,0
0,0,0,0,0,0,0,0,0,0,0,0,0,0,0,0
0,0,0,0,0,0,0,0,0,0,0,0,0,0,0,0
0,0,0,0,0,0,0,0,0,0,0,0,0,0,0,0
0,0,0,0,0,0,4,4,4,0,0,0,0,0,0,0
0,0,0,0,0,4,0,0,0,4,0,0,0,0,0,0
0,0,0,0,0,4,0,0,0,0,0,0,0,0,0,0
0,0,0,0,0,4,5,0,0,4,0,0,0,0,0,0
0,0,0,0,0,0,4,4,4,0,0,0,0,0,0,0
0,0,0,0,0,0,0,0,0,0,0,0,0,0,0,0
0,0,0,0,0,0,0,0,0,0,0,0,0,0,0,0
0,0,0,0,0,0,0,0,0,0,0,0,0,0,0,0
0,0,0,0,0,0,0,0,0,0,0,0,0,0,0,0
0,0,0,0,0,0,0,0,0,0,0,0,0,0,0,0
0,0,0,0,0,0,0,0,0,0,0,0,0,0,0,0
endlayer

layer
0,0,0,0,0,0,0,0,0,0,0,0,0,0,0,0
0,0,0,0,0,0,0,0,0,0,0,0,0,0,0,0
0,0,0,0,0,0,0,0,0,0,0,0,0,0,0,0
0,0,0,0,0,0,0,0,0,0,0,0,0,0,0,0
0,0,0,0,0,0,0,0,0,0,0,0,0,0,0,0
0,0,0,0,0,0,4,1,4,0,0,0,0,0,0,0
0,0,0,0,0,4,0,0,0,4,0,0,0,0,0,0
0,0,0,0,0,1,5,0,0,0,0,0,0,0,0,0
0,0,0,0,0,4,0,0,0,4,0,0,0,0,0,0
0,0,0,0,0,0,4,1,4,0,0,0,0,0,0,0
0,0,0,0,0,0,0,0,0,0,0,0,0,0,0,0
0,0,0,0,0,0,0,0,0,0,0,0,0,0,0,0
0,0,0,0,0,0,0,0,0,0,0,0,0,0,0,0
0,0,0,0,0,0,0,0,0,0,0,0,0,0,0,0
0,0,0,0,0,0,0,0,0,0,0,0,0,0,0,0
0,0,0,0,0,0,0,0,0,0,0,0,0,0,0,0
endlayer

layer
0,0,0,0,0,0,0,0,0,0,0,0,0,0,0,0
0,0,0,0,0,0,0,0,0,0,0,0,0,0,0,0
0,0,0,0,0,0,0,0,0,0,0,0,0,0,0,0
0,0,0,0,0,0,0,0,0,0,0,0,0,0,0,0
0,0,0,0,0,0,0,0,0,0,0,0,0,0,0,0
0,0,0,0,0,0,4,1,4,0,0,0,0,0,0,0
0,0,0,0,0,4,5,0,0,4,0,0,0,0,0,0
0,0,0,0,0,1,0,0,0,1,0,0,0,0,0,0
0,0,0,0,0,4,0,0,0,4,0,0,0,0,0,0
0,0,0,0,0,0,4,1,4,0,0,0,0,0,0,0
0,0,0,0,0,0,0,0,0,0,0,0,0,0,0,0
0,0,0,0,0,0,0,0,0,0,0,0,0,0,0,0
0,0,0,0,0,0,0,0,0,0,0,0,0,0,0,0
0,0,0,0,0,0,0,0,0,0,0,0,0,0,0,0
0,0,0,0,0,0,0,0,0,0,0,0,0,0,0,0
0,0,0,0,0,0,0,0,0,0,0,0,0,0,0,0
endlayer

layer
0,0,0,0,0,0,0,0,0,0,0,0,0,0,0,0
0,0,0,0,0,0,0,0,0,0,0,0,0,0,0,0
0,0,0,0,0,0,0,0,0,0,0,0,0,0,0,0
0,0,0,0,0,0,0,0,0,0,0,0,0,0,0,0
0,0,0,0,0,0,0,0,0,0,0,0,0,0,0,0
0,0,0,0,0,0,4,4,4,0,0,0,0,0,0,0
0,0,0,0,0,4,0,5,0,4,0,0,0,0,0,0
0,0,0,0,0,4,0,0,0,4,0,0,0,0,0,0
0,0,0,0,0,4,0,0,0,4,0,0,0,0,0,0
0,0,0,0,0,0,4,4,4,0,0,0,0,0,0,0
0,0,0,0,0,0,0,0,0,0,0,0,0,0,0,0
0,0,0,0,0,0,0,0,0,0,0,0,0,0,0,0
0,0,0,0,0,0,0,0,0,0,0,0,0,0,0,0
0,0,0,0,0,0,0,0,0,0,0,0,0,0,0,0
0,0,0,0,0,0,0,0,0,0,0,0,0,0,0,0
0,0,0,0,0,0,0,0,0,0,0,0,0,0,0,0
endlayer

layer
0,0,0,0,0,0,0,0,0,0,0,0,0,0,0,0
0,0,0,0,0,0,0,0,0,0,0,0,0,0,0,0
0,0,0,0,0,0,0,0,0,0,0,0,0,0,0,0
0,0,0,0,0,0,0,0,0,0,0,0,0,0,0,0
0,0,0,0,0,0,0,0,0,0,0,0,0,0,0,0
0,0,0,0,0,0,4,4,4,0,0,0,0,0,0,0
0,0,0,0,0,4,0,0,5,4,0,0,0,0,0,0
0,0,0,0,0,4,0,5,5,4,0,0,0,0,0,0
0,0,0,0,0,4,5,5,5,4,0,0,0,0,0,0
0,0,0,0,0,0,4,4,4,0,0,0,0,0,0,0
0,0,0,0,0,0,0,0,0,0,0,0,0,0,0,0
0,0,0,0,0,0,0,0,0,0,0,0,0,0,0,0
0,0,0,0,0,0,0,0,0,0,0,0,0,0,0,0
0,0,0,0,0,0,0,0,0,0,0,0,0,0,0,0
0,0,0,0,0,0,0,0,0,0,0,0,0,0,0,0
0,0,0,0,0,0,0,0,0,0,0,0,0,0,0,0
endlayer

layer
0,0,0,0,0,0,0,0,0,0,0,0,0,0,0,0
0,0,0,0,0,0,0,0,0,0,0,0,0,0,0,0
0,0,0,0,0,0,0,0,0,0,0,0,0,0,0,0
0,0,0,0,0,0,0,0,0,0,0,0,0,0,0,0
0,0,0,0,0,0,0,0,0,0,0,0,0,0,0,0
0,0,0,0,0,0,4,4,4,0,0,0,0,0,0,0
0,0,0,0,0,4,0,0,0,4,0,0,0,0,0,0
0,0,0,0,0,4,0,0,5,4,0,0,0,0,0,0
0,0,0,0,0,4,0,0,0,4,0,0,0,0,0,0
0,0,0,0,0,0,4,4,4,0,0,0,0,0,0,0
0,0,0,0,0,0,0,0,0,0,0,0,0,0,0,0
0,0,0,0,0,0,0,0,0,0,0,0,0,0,0,0
0,0,0,0,0,0,0,0,0,0,0,0,0,0,0,0
0,0,0,0,0,0,0,0,0,0,0,0,0,0,0,0
0,0,0,0,0,0,0,0,0,0,0,0,0,0,0,0
0,0,0,0,0,0,0,0,0,0,0,0,0,0,0,0
endlayer

layer
0,0,0,0,0,0,0,0,0,0,0,0,0,0,0,0
0,0,0,0,0,0,0,0,0,0,0,0,0,0,0,0
0,0,0,0,0,0,0,0,0,0,0,0,0,0,0,0
0,0,0,0,0,0,0,0,0,0,0,0,0,0,0,0
0,0,0,0,0,0,0,0,0,0,0,0,0,0,0,0
0,0,0,0,0,0,4,1,4,0,0,0,0,0,0,0
0,0,0,0,0,4,0,0,0,4,0,0,0,0,0,0
0,0,0,0,0,1,0,0,0,1,0,0,0,0,0,0
0,0,0,0,0,4,0,0,5,4,0,0,0,0,0,0
0,0,0,0,0,0,4,1,4,0,0,0,0,0,0,0
0,0,0,0,0,0,0,0,0,0,0,0,0,0,0,0
0,0,0,0,0,0,0,0,0,0,0,0,0,0,0,0
0,0,0,0,0,0,0,0,0,0,0,0,0,0,0,0
0,0,0,0,0,0,0,0,0,0,0,0,0,0,0,0
0,0,0,0,0,0,0,0,0,0,0,0,0,0,0,0
0,0,0,0,0,0,0,0,0,0,0,0,0,0,0,0
endlayer

layer
0,0,0,0,0,0,0,0,0,0,0,0,0,0,0,0
0,0,0,0,0,0,0,0,0,0,0,0,0,0,0,0
0,0,0,0,0,0,0,0,0,0,0,0,0,0,0,0
0,0,0,0,0,0,0,0,0,0,0,0,0,0,0,0
0,0,0,0,0,0,0,0,0,0,0,0,0,0,0,0
0,0,0,0,0,0,4,1,4,0,0,0,0,0,0,0
0,0,0,0,0,4,0,0,0,4,0,0,0,0,0,0
0,0,0,0,0,1,0,0,0,1,0,0,0,0,0,0
0,0,0,0,0,4,0,5,0,4,0,0,0,0,0,0
0,0,0,0,0,0,4,1,4,0,0,0,0,0,0,0
0,0,0,0,0,0,0,0,0,0,0,0,0,0,0,0
0,0,0,0,0,0,0,0,0,0,0,0,0,0,0,0
0,0,0,0,0,0,0,0,0,0,0,0,0,0,0,0
0,0,0,0,0,0,0,0,0,0,0,0,0,0,0,0
0,0,0,0,0,0,0,0,0,0,0,0,0,0,0,0
0,0,0,0,0,0,0,0,0,0,0,0,0,0,0,0
endlayer

layer
0,0,0,0,0,0,0,0,0,0,0,0,0,0,0,0
0,0,0,0,0,0,0,0,0,0,0,0,0,0,0,0
0,0,0,0,0,0,0,0,0,0,0,0,0,0,0,0
0,0,0,0,0,0,0,0,0,0,0,0,0,0,0,0
0,0,0,0,0,0,0,0,0,0,0,0,0,0,0,0
0,0,0,0,0,0,4,1,4,0,0,0,0,0,0,0
0,0,0,0,0,4,0,0,0,4,0,0,0,0,0,0
0,0,0,0,0,1,0,0,0,1,0,0,0,0,0,0
0,0,0,0,0,4,5,0,0,4,0,0,0,0,0,0
0,0,0,0,0,0,4,1,4,0,0,0,0,0,0,0
0,0,0,0,0,0,0,0,0,0,0,0,0,0,0,0
0,0,0,0,0,0,0,0,0,0,0,0,0,0,0,0
0,0,0,0,0,0,0,0,0,0,0,0,0,0,0,0
0,0,0,0,0,0,0,0,0,0,0,0,0,0,0,0
0,0,0,0,0,0,0,0,0,0,0,0,0,0,0,0
0,0,0,0,0,0,0,0,0,0,0,0,0,0,0,0
endlayer

layer
0,0,0,0,0,0,0,0,0,0,0,0,0,0,0,0
0,0,0,0,0,0,0,0,0,0,0,0,0,0,0,0
0,0,0,0,0,0,0,0,0,0,0,0,0,0,0,0
0,0,0,0,0,0,0,0,0,0,0,0,0,0,0,0
0,0,0,0,0,0,0,0,0,0,0,0,0,0,0,0
0,0,0,0,0,0,4,4,4,0,0,0,0,0,0,0
0,0,0,0,0,4,0,0,0,4,0,0,0,0,0,0
0,0,0,0,0,4,5,0,0,4,0,0,0,0,0,0
0,0,0,0,0,4,0,0,0,4,0,0,0,0,0,0
0,0,0,0,0,0,4,4,4,0,0,0,0,0,0,0
0,0,0,0,0,0,0,0,0,0,0,0,0,0,0,0
0,0,0,0,0,0,0,0,0,0,0,0,0,0,0,0
0,0,0,0,0,0,0,0,0,0,0,0,0,0,0,0
0,0,0,0,0,0,0,0,0,0,0,0,0,0,0,0
0,0,0,0,0,0,0,0,0,0,0,0,0,0,0,0
0,0,0,0,0,0,0,0,0,0,0,0,0,0,0,0
endlayer

layer
0,0,0,0,0,0,0,0,0,0,0,0,0,0,0,0
0,0,0,0,0,0,0,0,0,0,0,0,0,0,0,0
0,0,0,0,0,0,0,0,0,0,0,0,0,0,0,0
0,0,0,0,0,0,0,0,0,0,0,0,0,0,0,0
0,0,0,0,0,0,0,6,0,0,0,0,0,0,0,0
0,0,0,0,0,6,4,4,4,6,0,0,0,0,0,0
0,0,0,0,0,4,5,5,5,4,0,0,0,0,0,0
0,0,0,0,6,4,0,5,5,4,6,0,0,0,0,0
0,0,0,0,0,4,0,0,5,4,0,0,0,0,0,0
0,0,0,0,0,6,4,4,4,6,0,0,0,0,0,0
0,0,0,0,0,0,0,6,0,0,0,0,0,0,0,0
0,0,0,0,0,0,0,0,0,0,0,0,0,0,0,0
0,0,0,0,0,0,0,0,0,0,0,0,0,0,0,0
0,0,0,0,0,0,0,0,0,0,0,0,0,0,0,0
0,0,0,0,0,0,0,0,0,0,0,0,0,0,0,0
0,0,0,0,0,0,0,0,0,0,0,0,0,0,0,0
endlayer

layer
0,0,0,0,0,0,0,0,0,0,0,0,0,0,0,0
0,0,0,0,0,0,0,0,0,0,0,0,0,0,0,0
0,0,0,0,0,0,0,0,0,0,0,0,0,0,0,0
0,0,0,0,0,0,0,0,0,0,0,0,0,0,0,0
0,0,0,0,0,4,4,4,4,4,0,0,0,0,0,0
0,0,0,0,4,0,0,0,0,0,4,0,0,0,0,0
0,0,0,0,4,0,0,0,0,0,4,0,0,0,0,0
0,0,0,0,4,0,0,7,0,0,4,0,0,0,0,0
0,0,0,0,4,0,0,0,0,0,4,0,0,0,0,0
0,0,0,0,4,0,0,0,0,0,4,0,0,0,0,0
0,0,0,0,0,4,4,4,4,4,0,0,0,0,0,0
0,0,0,0,0,0,0,0,0,0,0,0,0,0,0,0
0,0,0,0,0,0,0,0,0,0,0,0,0,0,0,0
0,0,0,0,0,0,0,0,0,0,0,0,0,0,0,0
0,0,0,0,0,0,0,0,0,0,0,0,0,0,0,0
0,0,0,0,0,0,0,0,0,0,0,0,0,0,0,0
endlayer

layer
0,0,0,0,0,0,0,0,0,0,0,0,0,0,0,0
0,0,0,0,0,0,0,0,0,0,0,0,0,0,0,0
0,0,0,0,0,0,0,0,0,0,0,0,0,0,0,0
0,0,0,0,0,0,0,0,0,0,0,0,0,0,0,0
0,0,0,0,0,4,0,4,0,4,0,0,0,0,0,0
0,0,0,0,4,0,0,0,0,0,4,0,0,0,0,0
0,0,0,0,0,0,0,0,0,0,0,0,0,0,0,0
0,0,0,0,4,0,0,0,0,0,4,0,0,0,0,0
0,0,0,0,0,0,0,0,0,0,0,0,0,0,0,0
0,0,0,0,4,0,0,0,0,0,4,0,0,0,0,0
0,0,0,0,0,4,0,4,0,4,0,0,0,0,0,0
0,0,0,0,0,0,0,0,0,0,0,0,0,0,0,0
0,0,0,0,0,0,0,0,0,0,0,0,0,0,0,0
0,0,0,0,0,0,0,0,0,0,0,0,0,0,0,0
0,0,0,0,0,0,0,0,0,0,0,0,0,0,0,0
0,0,0,0,0,0,0,0,0,0,0,0,0,0,0,0
endlayer

