# Water Dungeon Temple - 9 Jan 2016 (MC 1.7.10)
# Created by Ruins mod version 15.1 Ingame Parser
# authoring Player: Jordan_Greywolf
# Note: Place in biome folder; associated "water dungeon" templates go in \templateparser.

# Verified for MC 1.12: 23 Jun 2017
# Updated to MC 1.12.1: 9 Sep 2017

# Last Updated: 9 Jun 2018

biomesToSpawnIn=birch forest,boreal forest,boreal_forest,brushland,chaparral,cherry blossom grove,cherry_blossom_grove,cold taiga,coniferous forest,coniferous_forest,corrupted land,corrupted sands,dead forest,dead_forest,deciduous forest,dense forest,dreadlands,eucalyptus forest,eucalyptus_forest,extreme hills edge,flower field,flower_field,flower forest,forest,foresthills,grassland,grove,heathland,highland,jungleedge,jungle_edge,land of lakes,land_of_lakes,lavender fields,lavender_fields,lush desert,lush_desert,maple woods,maple_woods,meadow,meadow forest,mega taiga,mountain,mystic grove,ominous woods,orchard,origin valley,origin_valley,outback,prairie,rwg_hotforest,rwg_hotplains,rwg_temperateforest,sacred springs,savanna,scrubland,seasonal forest,seasonal_forest,shield,shrubland,silkglades,spruce woods,sunflower plains,taiga,woodland,xeric shrubland,xeric_shrubland,birch_forest,forest_hills,jungle_edge,mutated_forest,mutated_jungle_edge,mutated_plains,taiga_cold,smaller_extreme_hills,redwood_taiga,redwood_taiga_hills

uniqueMinDistance=3000

weight=1
embed_into_distance=1
acceptable_target_blocks=

unacceptable_target_blocks=cloud,Natura:Cloud,slime_congealed,slime_dirt,slime_grass,command_block,planks,planks2,concrete,cobblestone,stonebrick,brick_block,glass,torch,oak_stairs,stone_stairs,brick_stairs,stone_brick_stairs,nether_brick_stairs,sandstone_stairs,spruce_stairs,birch_stairs,jungle_stairs,quartz_stairs,acacia_stairs,dark_oak_stairs,cobblestone_wall,stone_slab,double_stone_slab,stone_slab2,wooden_slab,double_wooden_slab,nether_brick,fence

dimensions=10,13,13
allowable_overhang=0
max_leveling=6
leveling_buffer=0
preserve_water=0
preserve_lava=0
preserve_plants=1

rule1=0,100,minecraft:mossy_cobblestone-0,minecraft:mossy_cobblestone-0,minecraft:cobblestone-0

rule2=0,100,minecraft:water-0

rule3=0,100,minecraft:stonebrick-0,minecraft:stonebrick-0,minecraft:stonebrick-1,minecraft:stonebrick-2

rule4=0,100,minecraft:glowstone-0
rule5=0,100,minecraft:stone_brick_stairs-0
rule6=0,100,minecraft:stone_brick_stairs-3
rule7=0,100,minecraft:stone_brick_stairs-2
rule8=0,100,minecraft:stone_brick_stairs-1
rule9=0,100,minecraft:stone_stairs-0
rule10=0,100,minecraft:stone_stairs-3
rule11=0,100,minecraft:stone_stairs-2
rule12=0,100,minecraft:stonebrick-3
rule13=0,100,minecraft:stained_glass-10
rule14=0,100,minecraft:stained_glass-11
rule15=0,100,minecraft:stained_glass-14
rule16=0,100,minecraft:stained_glass-1

rule17=0,100,CommandBlock:/tp @p[r=3] ~0 ~-50 ~0:@

rule18=0,100,minecraft:stone_stairs-1
rule19=2,100,minecraft:stone_button-2
rule20=2,100,minecraft:stone_button-4
rule21=2,100,minecraft:stone_button-3
rule22=2,100,minecraft:stone_button-1

rule23=0,100,CommandBlock:RUINSTRIGGER /testruin TP_WaterDungeonEntry ~0 ~-54 ~0:@

rule24=0,100,minecraft:stone_brick_stairs-4
rule25=0,100,minecraft:stone_brick_stairs-7
rule26=0,100,minecraft:stone_brick_stairs-6
rule27=0,100,minecraft:stone_brick_stairs-5
rule28=0,100,minecraft:stone_slab-0
rule29=0,100,minecraft:double_stone_slab-0
rule30=0,100,minecraft:stone_slab-8

layer
1,1,1,1,1,1,1,1,1,1,1,1,1
1,1,1,2,2,1,1,1,2,2,1,1,1
1,1,1,2,1,1,1,1,1,2,1,1,1
1,2,2,1,1,3,3,3,1,1,2,2,1
1,2,1,1,3,3,4,3,3,1,1,2,1
1,1,1,3,3,3,3,3,3,3,1,1,1
1,1,1,3,4,3,3,3,4,3,1,1,1
1,1,1,3,3,3,3,3,3,3,1,1,1
1,2,1,1,3,3,4,3,3,1,1,2,1
1,2,2,1,1,3,3,3,1,1,2,2,1
1,1,1,2,1,1,1,1,1,2,1,1,1
1,1,1,2,2,1,1,1,2,2,1,1,1
1,1,1,1,1,1,1,1,1,1,1,1,1
endlayer

layer
5,5,5,0,0,0,0,0,0,0,6,5,5
6,3,7,0,0,0,0,0,0,0,6,3,7
6,8,8,0,10,9,9,9,9,0,8,8,7
0,0,0,10,9,3,12,3,11,9,0,0,0
0,0,10,9,12,13,14,13,12,11,9,0,0
0,0,10,3,13,15,16,15,13,3,11,0,0
0,0,10,12,14,16,17,16,14,12,11,0,0
0,0,10,3,13,15,16,15,13,3,11,0,0
0,0,18,10,12,13,14,13,12,18,11,0,0
0,0,0,18,10,3,12,3,18,11,0,0,0
6,5,5,0,18,18,18,18,11,0,6,5,5
6,3,7,0,0,0,0,0,0,0,6,3,7
8,8,7,0,0,0,0,0,0,0,8,8,7
endlayer

layer
0,0,0,0,0,0,0,0,0,0,0,0,0
0,12,0,0,0,0,0,0,0,0,0,12,0
0,0,0,0,0,0,0,0,0,0,0,0,0
0,0,0,0,0,0,0,0,0,0,0,0,0
0,0,0,0,0,0,0,0,0,0,0,0,0
0,0,0,0,0,0,19,0,0,0,0,0,0
0,0,0,0,0,21,12,20,0,0,0,0,0
0,0,0,0,0,0,22,0,0,0,0,0,0
0,0,0,0,0,0,0,0,0,0,0,0,0
0,0,0,0,0,0,0,0,0,0,0,0,0
0,0,0,0,0,0,0,0,0,0,0,0,0
0,12,0,0,0,0,0,0,0,0,0,12,0
0,0,0,0,0,0,0,0,0,0,0,0,0
endlayer

layer
0,0,0,0,0,0,0,0,0,0,0,0,0
0,3,0,0,0,0,0,0,0,0,0,3,0
0,0,0,0,0,0,0,0,0,0,0,0,0
0,0,0,0,0,0,0,0,0,0,0,0,0
0,0,0,0,0,0,0,0,0,0,0,0,0
0,0,0,0,0,0,0,0,0,0,0,0,0
0,0,0,0,0,0,23,0,0,0,0,0,0
0,0,0,0,0,0,0,0,0,0,0,0,0
0,0,0,0,0,0,0,0,0,0,0,0,0
0,0,0,0,0,0,0,0,0,0,0,0,0
0,0,0,0,0,0,0,0,0,0,0,0,0
0,3,0,0,0,0,0,0,0,0,0,3,0
0,0,0,0,0,0,0,0,0,0,0,0,0
endlayer

layer
0,0,0,0,0,0,0,0,0,0,0,0,0
0,3,0,0,0,0,0,0,0,0,0,3,0
0,0,0,0,0,0,0,0,0,0,0,0,0
0,0,0,0,0,0,0,0,0,0,0,0,0
0,0,0,0,0,0,0,0,0,0,0,0,0
0,0,0,0,0,0,0,0,0,0,0,0,0
0,0,0,0,0,0,0,0,0,0,0,0,0
0,0,0,0,0,0,0,0,0,0,0,0,0
0,0,0,0,0,0,0,0,0,0,0,0,0
0,0,0,0,0,0,0,0,0,0,0,0,0
0,0,0,0,0,0,0,0,0,0,0,0,0
0,3,0,0,0,0,0,0,0,0,0,3,0
0,0,0,0,0,0,0,0,0,0,0,0,0
endlayer

layer
0,0,0,0,0,0,0,0,0,0,0,0,0
0,12,0,0,0,0,0,0,0,0,0,12,0
0,0,0,0,0,0,0,0,0,0,0,0,0
0,0,0,0,0,0,0,0,0,0,0,0,0
0,0,0,0,0,0,0,0,0,0,0,0,0
0,0,0,0,0,0,0,0,0,0,0,0,0
0,0,0,0,0,0,0,0,0,0,0,0,0
0,0,0,0,0,0,0,0,0,0,0,0,0
0,0,0,0,0,0,0,0,0,0,0,0,0
0,0,0,0,0,0,0,0,0,0,0,0,0
0,0,0,0,0,0,0,0,0,0,0,0,0
0,12,0,0,0,0,0,0,0,0,0,12,0
0,0,0,0,0,0,0,0,0,0,0,0,0
endlayer

layer
24,24,26,0,0,0,0,0,0,0,25,24,24
25,3,26,0,0,0,0,0,0,0,25,3,26
25,27,27,0,0,0,0,0,0,0,27,27,26
0,0,0,0,0,0,0,0,0,0,0,0,0
0,0,0,0,0,0,0,0,0,0,0,0,0
0,0,0,0,0,0,0,0,0,0,0,0,0
0,0,0,0,0,0,0,0,0,0,0,0,0
0,0,0,0,0,0,0,0,0,0,0,0,0
0,0,0,0,0,0,0,0,0,0,0,0,0
0,0,0,0,0,0,0,0,0,0,0,0,0
25,24,24,0,0,0,0,0,0,0,25,24,24
25,3,26,0,0,0,0,0,0,0,25,3,26
27,27,26,0,0,0,0,0,0,0,27,27,26
endlayer

layer
28,28,28,0,0,0,0,0,0,0,28,28,28
28,29,28,28,28,28,28,28,28,28,28,29,28
28,28,28,28,29,29,29,29,29,28,28,28,28
0,28,28,29,29,29,29,29,29,29,28,28,0
0,28,29,29,29,30,30,30,29,29,29,28,0
0,28,29,29,30,0,0,0,30,29,29,28,0
0,28,29,29,30,0,0,0,30,29,29,28,0
0,28,29,29,30,0,0,0,30,29,29,28,0
0,28,29,29,29,30,30,30,29,29,29,28,0
0,28,28,29,29,29,29,29,29,29,28,28,0
28,28,28,28,29,29,29,29,29,28,28,28,28
28,29,28,28,28,28,28,28,28,28,28,29,28
28,28,28,0,0,0,0,0,0,0,28,28,28
endlayer

layer
0,0,0,0,0,0,0,0,0,0,0,0,0
0,28,0,0,0,0,0,0,0,0,0,28,0
0,0,0,0,0,0,0,0,0,0,0,0,0
0,0,0,0,0,28,28,28,0,0,0,0,0
0,0,0,0,28,29,29,29,28,0,0,0,0
0,0,0,28,29,29,30,29,29,28,0,0,0
0,0,0,28,29,30,4,30,29,28,0,0,0
0,0,0,28,29,29,30,29,29,28,0,0,0
0,0,0,0,28,29,29,29,28,0,0,0,0
0,0,0,0,0,28,28,28,0,0,0,0,0
0,0,0,0,0,0,0,0,0,0,0,0,0
0,28,0,0,0,0,0,0,0,0,0,28,0
0,0,0,0,0,0,0,0,0,0,0,0,0
endlayer

layer
0,0,0,0,0,0,0,0,0,0,0,0,0
0,0,0,0,0,0,0,0,0,0,0,0,0
0,0,0,0,0,0,0,0,0,0,0,0,0
0,0,0,0,0,0,0,0,0,0,0,0,0
0,0,0,0,0,0,0,0,0,0,0,0,0
0,0,0,0,0,28,28,28,0,0,0,0,0
0,0,0,0,0,28,28,28,0,0,0,0,0
0,0,0,0,0,28,28,28,0,0,0,0,0
0,0,0,0,0,0,0,0,0,0,0,0,0
0,0,0,0,0,0,0,0,0,0,0,0,0
0,0,0,0,0,0,0,0,0,0,0,0,0
0,0,0,0,0,0,0,0,0,0,0,0,0
0,0,0,0,0,0,0,0,0,0,0,0,0
endlayer

