# MineRollerCoaster (24 Apr 2014)
# Created by Ruins mod version 12.3 Ingame Parser
# authoring Player: Jordan_Greywolf
# Updated 26 Feb 2016
# Verified for MC 1.12: 23 Jun 2017
# Updated to MC 1.12.1: 9 Sep 2017

# Last Updated: 9 Jun 2018

BiomesToSpawnIn=badlands,dead_forest,deadlands,desert,extreme hills,extreme hills edge,ice mountains,ice plains,ice wasteland,lavender fields,meadow,mountain ridge,pasture,plains,prairie,savanna,shield,taiga,tundra,temperate_rainforest,extreme_hills,ice_flats,ice_mountains,smaller_extreme_hills,taiga_cold

weight=1
embed_into_distance=25

unacceptable_target_blocks=water,flowing_water,lava,flowing_lava,cloud,Natura:Cloud,slime_congealed,slime_dirt,slime_grass,command_block,planks,planks2,concrete,cobblestone,stonebrick,brick_block,glass,torch,oak_stairs,stone_stairs,brick_stairs,stone_brick_stairs,nether_brick_stairs,sandstone_stairs,spruce_stairs,birch_stairs,jungle_stairs,quartz_stairs,acacia_stairs,dark_oak_stairs,cobblestone_wall,stone_slab,double_stone_slab,stone_slab2,wooden_slab,double_wooden_slab,nether_brick,fence

dimensions=31,23,24
allowable_overhang=500
max_cut_in=0
cut_in_buffer=0
max_leveling=25
leveling_buffer=-1
preserve_water=0
preserve_lava=0
preserve_plants=1

preventRotation=1

rule1=0,100,minecraft:stone-0
rule2=0,100,minecraft:water-5

# Cobblestone / Moss Cobblestone
rule3=0,100,minecraft:cobblestone-0,minecraft:mossy_cobblestone-0
rule4=0,100,minecraft:water-0
rule5=0,100,minecraft:water-4
rule6=0,100,minecraft:water-3

# Monster Spawners
rule7=0,100,MobSpawner:Skeleton,MobSpawner:Cave_Spider,MobSpawner:Zombie

rule8=0,100,minecraft:water-1
rule9=0,100,minecraft:water-2
rule10=0,100,minecraft:water-9
rule11=0,100,minecraft:water-8
rule12=0,100,minecraft:lava-12
rule13=0,100,minecraft:lava-4
rule14=0,100,minecraft:lava-2
rule15=0,100,minecraft:lava-0
rule16=0,100,minecraft:lava-10
rule17=0,100,minecraft:lava-8
rule18=0,100,minecraft:water-14
rule19=0,100,minecraft:rail-6
rule20=0,100,minecraft:golden_rail-8
rule21=0,100,minecraft:rail-9

# Randomized Treasure
rule22=0,100,minecraft:lapis_block-0,HardChest,minecraft:diamond_ore,minecraft:gold_ore,minecraft:emerald_ore

rule23=0,100,minecraft:rail-2
rule24=7,100,minecraft:redstone_torch-5
rule25=0,100,minecraft:fence-0
rule26=0,100,minecraft:golden_rail-9
rule27=0,100,minecraft:glowstone-0
rule28=0,100,minecraft:rail-7
rule29=0,100,minecraft:rail-3
rule30=0,100,minecraft:golden_rail-1
rule31=0,100,minecraft:rail-4
rule32=0,100,minecraft:gravel-0
rule33=0,100,minecraft:water-10
rule34=0,100,minecraft:rail-0
rule35=0,100,minecraft:rail-8
rule36=0,100,minecraft:water-15
rule37=0,100,minecraft:planks-0
rule38=0,100,minecraft:water-6
rule39=0,100,minecraft:golden_rail-11

# Cobblestone Wall / Mossy Cobblestone Wall
rule40=0,100,minecraft:cobblestone_wall-0,minecraft:cobblestone_wall-1

rule41=0,100,minecraft:wooden_button-4
rule42=0,100,minecraft:rail-1
rule43=0,100,minecraft:rail-5
rule44=0,100,minecraft:golden_rail-12
rule45=0,100,minecraft:web-0
rule46=0,100,minecraft:golden_rail-10
rule47=0,100,minecraft:water-11
rule48=0,100,minecraft:golden_rail-13
rule49=0,100,minecraft:ladder-3
rule50=0,100,minecraft:golden_rail-0

# TNT!
rule51=0,100,minecraft:tnt-0

rule52=0,100,minecraft:lava-6
rule53=0,100,minecraft:mycelium-0

# Randomized Mushrooms
rule54=0,100,minecraft:red_mushroom-0,minecraft:brown_mushroom-0

rule55=0,100,minecraft:dirt-0
rule56=0,100,minecraft:red_mushroom_block-10
rule57=0,100,minecraft:red_mushroom_block-1
rule58=0,100,minecraft:red_mushroom_block-4
rule59=0,100,minecraft:red_mushroom_block-7
rule60=0,100,minecraft:red_mushroom_block-2
rule61=0,100,minecraft:red_mushroom_block-8
rule62=0,100,minecraft:water-7
rule63=0,100,minecraft:red_mushroom_block-3
rule64=0,100,minecraft:red_mushroom_block-9
rule65=0,100,minecraft:red_mushroom_block-6
rule66=0,100,minecraft:wooden_button-1
rule67=0,100,minecraft:grass-0
rule68=0,100,minecraft:red_mushroom_block-5

# Preserve Terrain
rule69=0,100,PreserveBlock

rule70=0,100,Skull:0:0-1
rule71=0,100,minecraft:lit_redstone_lamp-0


# Randomized Grass
rule72=0,100,minecraft:tallgrass-1,minecraft:tallgrass-2,minecraft:red_flower,minecraft:yellow_flower,preserveBlock,preserveBlock

# Minecraft Chest (at start)
rule73=0,100,IInventory;minecraft:chest;minecraft:minecart#2#0+minecraft:redstone_torch#10#0+minecraft:rail#10#0-2

rule74=0,100,minecraft:stone_button-3

layer
1,1,1,1,3,3,3,3,3,3,3,3,3,1,1,1,2,1,1,1,1,1,1,1
1,1,1,1,3,1,1,1,1,1,1,1,3,1,1,2,5,1,1,4,4,4,1,1
1,1,1,1,3,1,7,1,1,1,1,1,1,1,1,1,6,1,4,4,4,4,4,1
1,1,1,3,3,1,1,1,1,1,1,1,1,1,1,8,9,8,4,4,4,4,1,1
1,1,1,3,3,1,1,1,1,1,1,1,1,1,1,4,8,8,4,4,4,4,1,1
1,3,1,3,1,3,1,1,1,1,1,1,1,1,1,1,8,10,4,4,4,4,4,1
1,3,1,3,1,3,3,1,1,1,1,1,1,1,1,1,10,11,4,4,4,4,1,1
1,3,1,1,1,3,1,1,1,1,1,1,1,1,1,1,1,1,4,4,4,4,1,1
1,3,1,1,1,3,3,1,1,1,1,1,1,1,1,1,1,1,4,4,4,4,4,1
1,3,1,1,1,3,3,1,1,1,1,1,1,1,1,1,1,1,1,4,4,4,1,1
1,3,1,1,1,3,3,1,1,1,1,1,1,1,1,1,1,1,1,1,4,4,4,1
1,3,1,1,1,3,1,1,1,1,1,1,1,1,1,1,1,1,1,1,1,4,4,1
1,3,1,1,3,3,1,1,1,1,1,1,1,1,1,1,1,1,1,1,1,1,1,1
1,3,1,1,3,3,1,1,1,1,1,1,1,1,1,1,1,1,1,1,1,1,1,1
1,3,1,3,3,1,1,1,1,1,1,1,1,1,1,12,1,1,1,1,1,1,1,1
1,3,1,3,1,1,1,1,1,1,1,1,1,1,1,1,1,1,1,1,1,1,1,1
1,3,1,3,1,1,1,1,16,16,15,14,14,1,14,13,1,1,1,1,1,1,1,1
1,3,1,3,1,3,1,1,15,14,16,17,17,17,17,1,1,1,1,1,1,1,1,1
1,3,1,3,3,3,3,3,1,1,1,1,1,1,1,1,1,1,1,1,1,1,1,1
1,3,1,1,1,3,3,3,1,1,1,1,10,11,1,1,1,1,1,1,1,1,1,0
1,3,1,1,1,3,3,1,1,1,1,1,1,10,1,1,1,1,18,1,1,1,0,0
1,3,3,3,3,3,3,3,3,3,3,3,3,3,3,3,1,1,8,1,1,1,0,0
1,1,1,1,1,1,1,1,1,1,1,1,1,1,0,0,1,0,9,1,1,1,0,0
endlayer

layer
1,1,1,1,1,1,1,1,1,1,1,1,1,1,1,1,0,1,1,1,0,0,1,1
1,1,1,0,21,20,20,20,20,20,20,20,19,1,1,0,0,1,0,0,0,0,0,1
1,1,1,25,26,25,22,24,1,1,1,1,23,1,1,22,0,1,0,0,0,0,0,0
1,1,1,24,26,1,1,1,0,1,1,1,3,1,1,0,0,0,0,0,0,0,27,1
1,3,3,21,28,3,1,1,0,0,0,1,1,1,1,0,0,0,0,0,0,27,27,1
3,29,0,30,0,29,0,0,1,1,1,1,1,1,1,1,0,10,0,0,0,0,27,1
1,26,1,30,0,26,24,0,1,1,1,15,15,15,1,1,10,11,10,10,0,0,0,1
1,26,1,1,0,26,0,1,1,1,15,14,14,14,15,1,1,4,8,0,0,0,0,1
32,26,32,0,0,26,0,31,1,15,14,15,15,14,15,16,1,1,10,0,0,0,0,1
25,26,25,0,25,26,0,1,1,15,15,15,1,1,15,15,1,1,1,10,0,10,0,1
32,26,0,21,34,28,0,1,1,15,15,1,1,1,15,15,1,1,1,1,33,0,0,1
32,26,24,26,1,0,1,1,1,15,14,15,1,1,14,15,1,1,1,1,1,9,0,1
1,26,1,35,19,0,1,15,1,15,15,15,15,14,15,15,1,1,9,6,9,8,1,1
1,26,1,1,26,24,1,14,15,15,15,15,15,15,15,1,1,1,8,1,1,10,1,1
1,26,1,21,28,1,13,14,15,15,1,15,15,15,14,13,1,10,36,18,8,10,10,1
1,26,0,26,0,0,1,15,15,15,1,14,14,15,1,1,10,8,8,0,0,0,8,1
1,26,0,26,0,0,1,1,14,14,15,3,3,1,3,3,1,1,9,1,10,8,8,10
1,26,24,26,1,0,3,3,0,0,14,15,15,15,15,15,1,1,6,1,0,0,0,0
32,26,0,35,34,19,3,29,1,1,1,1,1,1,1,1,1,1,5,0,1,0,22,1
32,26,0,32,1,35,20,28,0,0,0,0,10,11,1,1,37,0,2,0,0,0,1,0
25,26,25,1,1,0,24,32,1,1,1,0,25,10,1,1,1,1,38,0,0,1,0,0
32,35,20,20,20,20,20,20,20,20,20,20,20,31,3,3,1,1,0,0,0,1,0,0
25,32,25,32,32,1,1,1,1,1,1,1,25,1,0,0,1,0,0,0,0,1,0,0
endlayer

layer
1,1,1,1,1,1,1,1,1,1,1,1,1,1,1,1,0,1,1,0,0,0,1,1
1,3,3,0,0,0,0,0,0,0,0,0,0,1,1,0,0,1,0,0,0,0,0,1
1,3,1,25,0,25,0,1,0,1,1,1,0,1,1,0,0,1,0,0,0,0,0,0
1,3,1,0,0,3,1,0,0,0,1,1,26,24,1,0,0,0,0,0,0,0,0,0
3,39,24,0,0,39,24,1,0,0,0,0,35,20,31,3,0,0,0,0,0,0,27,1
1,0,0,0,0,0,0,0,1,1,0,0,0,0,1,3,0,8,0,0,0,0,0,1
1,0,1,41,0,0,0,0,1,1,40,0,0,12,16,1,8,4,8,10,0,0,0,1
1,0,1,0,0,0,0,1,1,0,0,0,0,0,12,16,1,1,0,0,0,0,0,1
32,0,0,0,0,0,0,0,19,0,0,0,0,0,0,14,0,1,10,0,0,0,0,1
25,0,25,0,25,0,0,1,42,0,0,0,1,0,0,0,0,1,1,10,0,10,0,1
32,0,0,0,0,0,0,1,42,0,0,1,1,1,0,0,0,1,1,1,33,0,0,1
32,0,0,0,1,0,1,0,42,0,0,0,1,1,0,0,1,1,1,1,1,0,1,1
1,0,1,0,0,0,1,0,42,0,0,0,0,0,0,0,1,1,0,0,0,0,1,1
1,0,1,0,0,0,1,0,0,0,0,0,0,0,0,0,1,1,0,1,0,10,10,1
1,0,1,0,0,0,0,0,0,0,1,0,0,0,0,0,1,10,36,18,0,10,10,1
1,0,1,0,0,0,0,0,0,0,3,0,0,0,24,1,10,0,0,0,0,0,0,1
1,0,0,0,0,0,1,3,3,3,3,43,20,20,20,31,3,1,0,1,10,0,0,10
1,0,0,0,1,0,24,39,0,0,0,0,0,0,0,0,3,3,0,1,0,0,0,0
1,0,0,0,0,0,0,0,0,0,0,1,1,1,1,0,1,1,0,0,1,0,0,0
32,0,0,0,1,0,0,0,0,0,0,0,10,11,1,1,0,0,0,0,0,0,0,0
25,0,25,1,1,0,0,0,1,1,1,0,25,10,1,1,1,1,0,0,0,0,0,0
32,0,0,0,0,0,0,0,0,0,0,0,0,0,31,3,1,1,0,0,0,1,0,0
25,32,25,1,32,1,1,1,1,1,1,1,25,1,1,1,1,1,0,0,0,0,0,0
endlayer

layer
1,1,1,1,1,1,0,0,0,1,0,1,1,1,1,1,1,1,1,0,0,0,1,1
1,21,44,37,37,37,1,1,1,0,1,0,0,1,0,0,0,1,1,0,0,0,1,0
22,26,24,37,37,37,1,1,1,0,1,0,0,1,0,0,0,1,0,0,0,0,0,0
1,26,1,0,0,29,1,0,0,0,1,1,0,0,0,0,0,0,0,0,0,0,0,1
1,0,1,0,0,0,0,1,0,0,0,0,0,0,0,20,0,0,0,0,0,0,0,1
1,0,0,0,0,0,0,0,1,1,0,0,0,0,0,24,0,0,0,0,0,0,1,1
1,0,0,0,0,0,0,45,1,1,40,0,0,12,14,1,0,0,0,10,0,0,0,1
1,0,1,0,0,0,0,1,1,1,0,0,0,0,12,14,1,1,0,0,0,0,0,1
32,0,0,0,0,0,0,0,0,0,0,0,0,0,0,0,0,1,10,0,0,0,0,1
37,37,37,3,37,0,0,1,0,0,0,0,0,0,0,0,0,1,1,10,0,10,0,1
32,0,0,0,0,0,0,1,0,0,1,1,1,1,0,0,0,1,1,1,33,0,1,1
1,0,0,0,1,0,1,0,0,0,0,0,1,1,0,0,1,1,1,1,1,0,1,1
1,0,1,0,0,0,1,0,0,0,0,0,0,0,0,0,1,1,1,1,1,0,1,1
1,0,1,0,0,0,1,0,0,0,0,0,0,0,0,0,1,1,1,1,0,10,10,1
1,0,1,0,0,0,0,0,0,0,1,0,0,0,0,1,1,10,36,18,0,10,10,1
1,0,1,0,0,0,0,0,0,0,24,0,0,0,0,1,10,0,0,0,0,0,1,1
1,1,0,0,0,0,1,21,20,20,20,0,0,0,0,0,19,1,0,1,10,0,0,10
1,0,0,0,1,0,0,0,0,0,0,0,0,0,0,0,46,24,0,1,0,0,0,0
1,0,0,0,0,0,0,0,0,0,0,1,1,1,3,0,3,40,0,0,1,0,0,0
1,0,0,0,1,0,0,0,0,0,0,0,10,11,1,0,3,0,0,0,0,0,0,0
37,37,37,1,1,0,0,0,1,1,1,0,25,10,1,1,3,40,0,0,0,0,0,0
37,37,37,0,0,0,0,0,0,0,0,0,0,0,0,31,3,1,1,0,0,1,0,0
37,37,37,1,1,1,1,1,1,1,1,1,25,1,1,1,1,0,0,0,0,0,0,0
endlayer

layer
1,1,1,1,1,1,1,0,0,1,0,0,0,0,0,1,1,1,1,0,0,1,1,1
1,0,0,20,20,19,1,0,0,1,1,1,1,1,0,0,0,1,1,0,0,0,1,1
1,0,0,1,24,26,1,0,0,1,1,0,0,1,0,0,0,1,0,27,0,0,0,1
1,0,1,1,0,0,1,0,0,0,1,0,0,0,0,0,0,0,0,0,0,0,0,1
1,0,1,1,1,0,1,1,0,0,0,0,0,0,0,0,0,0,0,0,0,0,1,1
10,3,3,3,3,0,1,45,1,1,0,0,0,0,0,0,0,0,0,0,0,0,1,0
3,3,3,3,3,1,1,1,1,1,40,0,0,12,0,0,0,0,0,10,0,0,0,0
1,1,1,3,3,1,0,1,1,1,40,0,0,0,12,0,0,1,0,0,0,0,0,1
1,1,1,3,1,1,45,0,0,1,40,0,0,0,0,0,0,1,10,0,0,0,27,1
1,3,3,3,3,3,3,3,3,0,40,0,0,0,0,0,0,1,1,10,0,10,0,1
1,3,3,45,3,0,3,0,0,0,40,1,1,1,0,0,0,1,1,1,33,0,1,1
1,3,3,3,1,0,1,0,0,0,0,0,1,3,0,0,1,1,1,1,1,0,1,1
1,0,3,0,0,0,40,0,0,0,0,0,0,0,0,0,1,1,1,1,1,1,1,1
1,0,1,0,0,0,0,0,0,0,0,0,0,0,0,1,1,1,1,1,0,10,10,1
1,0,1,0,0,0,0,0,0,0,1,0,0,0,0,1,10,10,36,18,0,10,10,1
1,0,1,0,0,0,0,0,0,0,0,0,0,0,0,1,8,0,0,0,0,1,1,10
1,1,1,0,0,0,1,0,0,0,0,0,0,0,0,0,0,40,0,1,10,0,0,8
1,1,1,1,1,0,0,0,0,0,0,0,0,0,0,0,0,0,0,1,0,0,0,0
1,1,1,1,0,0,0,0,0,0,0,1,0,3,3,3,26,24,0,1,1,0,0,0
1,1,1,0,1,3,0,0,0,0,0,0,8,4,1,0,23,0,0,0,0,0,0,0
1,1,1,1,1,0,0,0,34,34,34,0,37,8,3,3,3,40,0,0,0,0,0,0
1,1,1,0,1,1,0,1,1,1,1,1,37,0,0,0,31,3,1,1,0,1,0,0
0,1,1,1,1,1,1,0,0,1,1,1,37,1,1,1,1,1,0,0,0,0,0,0
endlayer

layer
1,1,1,1,1,1,1,1,0,0,0,0,0,0,0,1,1,1,1,1,1,1,1,1
1,0,0,0,0,0,0,0,0,1,1,0,0,0,0,0,0,1,1,1,0,1,1,1
1,0,0,1,0,0,1,0,0,1,1,3,3,3,0,0,0,1,1,27,27,0,1,1
1,1,1,1,0,0,1,1,3,3,3,3,3,3,3,0,0,0,0,27,0,0,0,1
1,3,4,1,1,0,0,1,3,3,3,3,3,3,3,0,0,0,0,0,0,0,1,0
10,3,4,4,1,0,1,1,3,3,3,3,3,0,0,0,0,0,0,0,0,0,1,0
10,3,4,4,4,1,1,1,3,3,3,3,0,12,0,0,0,0,0,10,0,0,0,0
10,1,1,4,4,1,45,3,3,3,37,3,3,0,12,0,0,1,0,0,0,0,0,0
1,1,1,1,1,1,0,3,3,3,37,3,3,0,0,0,0,1,8,0,0,0,0,0
1,21,20,20,20,20,19,3,3,3,37,3,3,0,0,0,0,1,47,8,0,10,0,1
1,26,24,0,0,0,23,3,3,3,3,1,1,1,0,0,0,1,1,10,33,0,1,1
1,26,0,0,1,0,3,3,3,3,3,3,1,3,3,3,3,1,1,1,1,1,1,1
1,0,0,0,0,0,40,3,3,3,3,3,3,3,3,3,1,1,1,1,1,1,1,1
1,0,1,0,0,0,0,0,0,0,3,3,3,3,3,1,1,1,1,1,1,10,10,1
1,0,0,0,0,0,0,0,0,0,1,3,3,3,3,1,10,10,36,18,0,10,8,10
1,0,0,0,0,0,0,0,0,0,3,3,3,3,3,1,1,3,0,0,1,1,1,8
1,26,0,0,0,1,1,37,37,0,0,0,0,3,3,0,0,3,3,1,10,0,0,0
1,26,24,0,1,0,0,0,0,0,0,0,0,3,3,3,0,3,0,1,0,0,0,0
1,26,0,1,0,0,0,0,0,0,0,1,3,3,3,48,0,3,0,3,0,0,0,0
25,26,25,1,1,1,0,0,0,0,0,0,0,0,0,0,0,0,0,3,0,0,0,0
1,1,1,1,1,0,0,0,0,0,0,0,3,3,3,43,28,40,1,3,1,1,0,0
0,1,1,0,1,1,1,1,1,1,1,1,0,1,40,0,0,31,3,3,0,1,0,0
0,0,1,1,1,1,0,0,0,0,0,0,1,1,1,1,1,1,0,0,0,0,0,0
endlayer

layer
1,1,1,1,10,8,1,0,0,0,0,0,0,0,1,1,1,1,1,1,0,1,1,1
1,0,0,0,1,1,1,1,0,1,1,0,0,0,1,1,0,0,0,0,0,0,7,1
1,0,0,1,1,0,0,0,1,1,1,21,20,31,3,3,0,1,0,27,0,0,0,1
1,1,1,0,0,0,0,1,21,20,20,28,24,0,40,0,0,0,0,0,0,0,0,0
1,8,9,0,0,0,0,1,26,24,0,0,40,40,40,0,0,0,0,0,0,0,1,0
8,10,8,0,0,0,1,0,42,0,42,0,3,0,0,0,0,0,0,0,0,0,1,0
10,3,10,0,0,0,1,0,42,0,42,1,0,12,0,0,0,3,0,10,0,0,0,0
10,3,1,10,49,1,0,0,42,0,42,22,1,0,12,0,0,1,27,0,0,0,0,0
1,1,1,1,1,25,0,25,30,0,42,22,1,0,0,0,0,3,0,0,0,0,0,1
1,0,0,0,0,0,0,3,30,0,42,1,1,0,0,0,40,3,6,0,0,10,1,1
1,0,0,0,0,0,0,0,37,0,42,1,1,1,0,0,0,3,9,8,33,0,1,1
1,0,0,0,1,0,46,24,0,0,42,0,1,0,0,0,0,3,1,1,1,1,1,1
1,0,0,0,0,0,37,40,40,40,35,34,19,0,0,1,1,3,1,1,1,1,1,1
1,0,1,0,0,40,37,0,0,0,22,0,42,0,0,1,3,3,1,1,1,10,10,10
1,0,0,0,0,0,37,0,0,0,1,0,35,34,34,34,10,10,36,18,1,10,0,8
1,0,0,0,0,0,37,40,0,0,3,3,0,0,0,1,0,26,0,1,1,1,0,0
1,0,0,0,0,1,37,37,43,0,0,0,0,0,0,1,0,26,24,1,10,0,0,0
1,0,0,0,1,1,0,0,0,0,0,0,0,0,0,0,0,23,0,1,0,0,0,0
1,0,0,0,0,0,0,0,0,0,0,1,1,48,20,0,0,3,3,3,0,0,0,0
25,0,25,1,3,1,0,0,0,0,0,0,3,0,0,0,0,0,0,29,0,1,0,0
0,1,1,1,1,1,0,0,0,0,3,3,3,43,20,0,0,40,25,42,25,1,0,0
0,0,1,0,0,1,1,1,1,1,3,1,0,1,24,0,0,0,34,28,0,1,0,0
0,0,0,1,1,1,0,0,0,0,0,0,1,0,1,1,1,1,1,1,1,0,0,0
endlayer

layer
1,0,0,0,10,0,1,1,0,0,1,0,1,1,1,1,1,1,1,1,0,0,1,1
1,1,1,1,1,1,1,0,0,0,1,1,0,0,0,0,0,0,0,0,0,0,0,1
1,0,0,0,0,0,0,1,1,1,1,0,0,0,31,3,3,37,0,0,0,0,0,1
1,1,1,1,0,0,0,1,0,0,0,0,0,0,0,0,40,37,0,0,0,0,0,0
0,0,0,0,0,0,0,1,0,0,0,0,0,0,0,0,0,3,0,0,0,0,0,0
0,8,0,0,0,0,1,0,0,0,0,0,3,0,0,0,0,3,0,0,0,0,1,0
8,10,8,0,0,0,1,0,0,0,0,1,0,12,0,0,0,3,0,10,0,0,0,0
8,10,4,8,49,1,0,0,0,0,0,0,1,0,12,0,0,3,0,0,0,0,0,0
1,1,1,1,1,25,0,25,0,0,0,0,1,0,0,0,0,29,0,0,0,0,0,0
1,0,0,0,0,0,0,3,41,0,0,1,1,0,0,0,24,26,0,0,0,10,1,0
1,0,0,0,0,0,0,0,0,0,0,1,1,1,0,0,0,26,0,0,33,0,1,1
1,0,0,0,1,0,0,0,0,0,0,0,0,0,0,0,0,26,1,1,1,1,1,1
1,0,0,0,0,0,26,0,0,0,0,0,0,0,0,1,22,26,7,1,1,1,1,1
1,0,1,0,0,24,26,0,0,0,0,0,0,0,0,0,24,26,0,0,1,10,10,10
1,0,0,0,0,0,26,0,0,0,1,0,0,0,0,0,8,10,36,18,1,10,0,0
1,0,0,0,0,0,26,24,0,0,0,1,0,0,0,0,0,0,0,1,1,1,0,0
1,0,0,0,0,1,35,20,0,0,0,0,0,0,0,1,0,0,0,1,10,0,0,0
1,0,0,0,1,1,0,0,0,0,0,1,0,0,0,0,0,0,0,1,0,0,0,0
1,1,0,0,3,3,3,3,3,3,3,1,48,0,0,0,0,35,34,19,1,1,0,0
37,37,37,1,3,1,0,0,0,0,0,0,24,0,0,0,0,0,0,0,1,1,0,0
0,0,1,1,1,1,0,0,0,0,37,3,48,0,0,0,0,40,25,0,25,1,1,0
0,0,0,1,1,0,1,1,1,1,1,1,1,1,1,1,1,0,0,0,0,0,1,0
0,0,0,0,1,0,0,0,0,0,0,0,0,0,0,0,0,1,1,1,1,1,0,0
endlayer

layer
1,0,0,0,8,0,1,1,0,1,1,1,1,1,1,1,1,1,1,1,0,0,0,1
1,1,0,0,10,0,0,1,1,0,1,0,0,0,0,0,0,0,0,0,0,0,0,1
0,1,1,1,1,1,1,0,0,0,1,0,0,0,0,20,20,19,0,0,0,0,0,1
1,1,1,1,1,1,1,0,0,0,0,0,0,0,0,0,24,26,0,0,0,0,0,0
0,1,0,0,0,0,1,1,0,0,0,0,0,0,0,0,0,26,0,0,0,0,1,0
0,0,0,0,0,0,1,0,0,0,0,0,0,0,0,0,0,26,0,0,0,0,1,0
0,10,0,0,0,0,1,0,0,0,0,1,0,12,0,0,0,26,0,10,0,0,0,0
0,10,0,0,49,1,37,0,0,0,0,0,1,0,12,0,0,26,0,0,0,0,0,0
1,1,1,1,1,37,37,37,0,0,0,0,1,0,0,0,0,0,0,0,0,0,0,0
1,0,0,0,0,0,37,40,0,0,0,0,1,0,0,0,0,0,0,0,0,10,1,1
1,0,0,0,0,0,0,40,0,0,0,1,1,1,0,0,0,0,0,0,33,1,1,1
1,0,0,0,1,0,0,0,0,0,0,0,0,0,0,0,0,0,1,1,1,1,1,1
1,0,0,0,0,0,0,0,0,0,0,0,0,0,0,1,1,0,1,1,1,1,1,1
0,1,1,0,0,0,0,0,0,0,1,1,0,0,0,0,0,0,1,1,1,10,10,10
1,1,0,0,0,0,0,0,0,1,1,0,0,0,0,0,0,10,36,18,1,10,0,0
1,1,0,0,0,0,0,0,0,0,1,1,0,0,0,0,0,0,0,1,10,1,1,0
1,1,0,0,0,0,0,0,0,0,0,1,0,0,0,1,0,0,0,1,8,1,0,0
0,1,0,0,25,0,0,0,0,0,0,1,0,0,0,1,0,0,0,1,1,1,1,1
1,1,1,0,50,34,20,20,20,20,20,20,0,0,0,0,0,0,0,0,1,1,1,1
1,1,1,0,25,0,1,0,0,0,0,0,0,0,0,0,0,0,0,0,1,1,1,0
0,0,1,1,1,1,1,1,1,37,37,43,0,0,0,0,0,1,37,37,37,1,1,1
0,0,0,1,0,0,0,0,1,1,1,1,1,1,1,1,1,1,0,0,1,1,1,1
0,0,0,0,1,0,0,0,0,0,1,0,0,0,0,0,0,1,1,1,1,1,1,1
endlayer

layer
1,0,0,0,0,0,0,1,1,1,1,1,1,1,1,1,1,1,1,1,1,1,1,1
1,0,0,0,10,0,0,1,0,1,1,0,0,0,0,0,0,0,0,0,0,0,0,1
0,1,0,0,0,0,0,0,0,0,1,0,0,0,0,0,0,0,0,0,0,0,0,0
1,1,1,1,1,1,0,0,0,0,0,0,0,0,0,0,0,0,0,0,0,0,0,0
1,1,0,0,0,0,1,1,0,0,0,0,0,0,0,0,0,0,0,0,0,0,1,0
0,0,0,0,0,0,1,45,0,0,0,0,0,0,0,0,0,0,0,0,0,27,1,0
0,10,0,0,0,0,37,0,0,0,0,1,0,12,0,0,0,0,0,10,0,0,0,0
0,10,0,0,49,1,37,0,0,0,0,0,1,0,12,0,0,0,0,0,0,0,0,0
0,1,1,1,1,1,29,0,0,0,0,0,0,0,0,0,0,0,0,0,0,0,0,0
1,1,0,0,0,0,26,24,0,0,0,0,1,0,0,0,0,0,0,0,0,10,0,0
1,0,0,0,0,0,0,40,0,0,0,1,1,1,0,0,0,0,0,0,33,0,0,1
1,0,0,0,1,0,0,0,0,0,0,0,0,0,0,0,1,0,0,1,1,1,1,1
1,0,0,0,0,0,0,0,0,0,0,0,0,0,0,0,1,0,1,1,1,1,1,10
0,1,1,0,25,0,0,0,0,0,1,1,0,0,0,0,0,0,1,1,1,10,10,8
0,0,1,0,0,0,0,0,0,0,0,0,0,0,0,0,0,10,36,18,1,10,0,0
0,0,1,0,0,0,0,0,1,1,1,1,0,0,0,0,0,3,3,1,10,0,1,0
0,0,1,0,0,0,0,0,0,0,0,1,45,0,0,37,37,37,37,1,0,1,1,1
0,0,1,0,25,0,0,0,0,0,0,1,0,0,0,1,1,37,37,1,43,19,0,1
0,0,1,0,0,0,0,0,0,0,0,0,0,0,0,0,0,0,0,0,25,26,25,1
0,0,1,0,25,0,1,0,0,0,0,0,0,0,0,0,0,0,0,0,1,26,1,0
0,0,0,1,1,1,1,37,37,37,43,0,0,0,0,0,0,1,1,1,1,26,1,0
0,0,0,1,0,0,0,0,1,40,1,1,1,1,1,1,1,1,1,22,24,26,7,1
0,0,0,0,1,0,0,0,0,0,1,0,0,0,1,0,0,0,0,0,25,26,25,0
endlayer

layer
1,1,0,0,0,0,0,0,1,1,1,1,3,1,1,1,1,1,1,1,1,1,1,1
1,1,0,0,10,0,0,1,0,1,1,3,3,3,3,3,45,0,0,0,0,0,0,0
40,1,0,0,0,0,1,0,0,0,1,3,3,3,3,3,0,0,0,0,0,0,0,0
37,37,37,37,37,37,37,37,3,3,3,3,3,3,3,3,0,0,0,0,0,0,0,0
1,1,1,0,37,0,1,1,1,1,3,3,3,3,3,3,0,0,0,0,0,27,1,0
1,0,0,0,37,37,37,37,37,1,3,3,3,3,3,3,0,0,0,0,27,27,1,0
0,10,0,0,0,37,37,0,37,40,3,1,3,12,3,3,0,0,0,10,0,27,0,0
0,10,0,0,49,1,29,0,37,0,3,0,1,0,12,0,0,0,0,0,0,0,0,0
0,1,1,1,1,1,0,0,37,0,3,0,0,0,0,0,0,0,0,0,0,0,0,1
1,1,1,0,25,0,0,0,37,0,45,0,0,0,0,0,0,0,0,0,0,10,0,1
1,1,0,0,0,0,0,40,37,0,45,1,0,1,1,0,0,0,0,0,33,0,0,1
1,0,0,0,1,25,0,0,37,0,0,0,0,0,0,0,1,0,0,1,1,1,1,1
0,1,0,0,0,0,0,40,37,0,0,0,0,0,0,0,1,0,27,1,1,1,10,8
0,1,1,0,25,0,0,0,37,0,0,1,0,0,0,0,0,0,1,0,1,10,8,0
0,0,1,0,0,0,0,0,37,0,0,1,0,0,0,0,0,10,36,18,36,8,0,0
0,0,1,0,0,0,0,0,37,1,1,1,0,0,0,0,0,51,51,1,8,0,0,1
0,0,1,0,25,0,25,0,37,37,37,37,37,37,37,37,43,19,51,1,1,0,0,1
0,0,1,0,37,0,0,0,0,0,0,1,1,1,1,1,1,35,34,34,0,0,0,1
0,0,1,0,37,0,0,0,0,0,0,0,0,0,0,0,0,0,0,0,25,0,25,1
0,0,1,1,37,40,1,0,0,0,25,0,0,0,0,0,0,0,0,0,0,0,1,0
0,0,0,1,37,37,37,37,43,20,0,0,0,0,0,0,0,1,1,1,1,0,1,0
0,0,0,1,0,1,1,0,1,24,1,1,1,1,0,1,1,1,0,0,0,0,0,1
0,0,0,0,1,0,1,0,1,1,1,1,0,1,1,0,0,0,0,0,25,0,25,0
endlayer

layer
1,1,1,1,0,0,0,1,1,1,1,1,1,13,1,1,1,1,1,1,1,1,1,1
1,1,1,0,10,0,0,0,0,1,13,14,15,14,15,1,1,45,0,0,0,1,1,1
24,25,1,0,0,0,25,0,0,0,1,14,15,15,15,15,1,0,0,0,0,0,0,0
20,20,31,37,43,20,20,20,20,20,19,1,15,15,15,1,1,0,0,0,0,0,1,0
0,25,1,0,0,0,25,24,0,0,26,1,14,15,1,1,3,0,0,0,0,0,1,0
1,1,0,0,0,0,21,20,19,0,26,1,13,14,15,1,0,0,0,0,0,27,1,0
0,10,0,0,0,0,42,0,26,24,46,3,52,13,14,1,0,0,0,10,0,0,1,1
0,10,0,0,49,1,0,0,26,0,3,0,1,0,13,0,0,0,0,0,0,0,0,1
0,1,1,1,1,1,0,0,26,0,3,0,0,0,0,0,0,0,0,0,0,0,0,1
0,0,1,0,37,0,0,0,26,0,3,0,0,0,0,0,0,0,0,0,0,10,0,1
1,1,0,0,37,0,0,24,26,0,3,1,0,0,1,0,0,0,0,0,33,0,0,1
1,0,0,0,1,37,0,0,26,0,0,0,0,0,0,0,1,0,0,0,1,1,1,1
0,1,0,0,37,0,0,24,26,0,0,0,0,0,0,0,1,0,0,1,1,1,10,1
0,1,1,0,37,0,0,0,26,0,0,1,0,0,0,0,0,0,1,0,0,10,0,1
0,0,1,0,0,0,0,0,26,0,0,0,0,0,0,0,0,10,36,18,36,0,0,1
0,0,1,0,0,0,0,0,26,24,0,25,0,0,0,0,0,37,0,1,0,0,0,1
0,0,1,0,37,37,37,0,35,20,20,20,20,20,20,20,0,0,51,1,0,0,0,1
0,0,1,0,37,0,0,0,0,0,0,25,53,53,1,24,1,0,0,0,0,0,0,1
0,0,1,0,39,0,0,0,0,0,0,0,1,1,1,1,1,0,0,0,37,37,37,1
0,0,1,0,26,24,25,0,0,0,25,0,0,0,0,0,0,0,0,0,1,0,1,0
0,0,0,1,35,20,20,20,0,0,0,0,0,0,0,1,1,1,1,1,1,0,1,0
0,0,0,1,1,1,25,0,1,1,1,1,1,1,1,1,1,1,0,0,1,0,1,0
0,0,0,0,0,0,1,1,1,1,1,0,0,0,0,0,0,0,0,0,37,37,37,0
endlayer

layer
1,1,1,1,1,1,1,1,1,1,1,1,1,1,1,1,1,1,1,1,1,1,1,1
1,1,0,0,10,0,0,0,0,0,0,0,0,0,0,1,1,1,1,1,1,1,1,1
0,25,0,0,0,0,25,0,0,0,0,0,0,0,0,0,1,1,0,0,0,0,0,1
0,0,0,34,0,0,0,0,0,0,0,0,0,0,0,1,1,0,0,0,0,0,1,1
0,25,0,0,0,0,25,0,0,0,0,0,0,0,0,1,0,0,0,0,0,0,1,0
1,1,0,0,0,0,0,0,0,0,0,0,0,0,0,1,0,0,0,0,0,0,1,0
0,10,0,0,0,0,0,0,0,0,0,0,0,0,0,0,0,0,0,10,0,1,1,1
0,10,0,0,49,1,0,0,0,0,46,0,0,0,0,0,0,0,0,0,0,0,0,1
1,1,1,0,1,1,0,0,0,0,3,0,0,0,0,0,0,0,0,0,0,0,1,1
1,0,1,0,0,0,0,0,0,0,37,0,0,0,0,0,0,0,0,0,0,10,1,1
1,1,0,0,0,0,0,0,0,0,37,1,0,0,1,1,0,0,0,0,33,1,1,1
1,0,0,0,1,0,0,0,0,0,0,0,0,0,0,1,1,0,0,1,1,1,1,1
1,0,0,0,0,0,0,0,0,0,0,0,0,0,0,0,1,0,45,1,1,10,10,1
0,1,1,0,0,0,0,0,0,0,1,1,0,0,0,0,0,0,1,0,0,8,0,1
0,0,1,0,0,0,0,0,0,0,0,0,0,0,0,0,0,10,36,18,36,0,0,1
0,0,1,0,37,0,0,0,0,0,0,25,0,0,0,0,0,37,0,1,0,0,0,1
0,0,1,0,37,0,0,0,0,0,0,0,0,0,0,0,0,0,0,1,0,0,0,1
0,1,1,0,39,0,0,0,0,0,0,25,54,54,53,1,1,0,0,0,1,0,0,1
0,0,1,0,0,0,0,0,0,0,0,0,1,1,1,1,1,0,0,0,1,1,1,1
0,0,1,0,0,0,25,0,0,0,37,0,0,1,0,1,1,0,0,0,1,1,1,1
0,0,1,1,0,0,0,0,0,0,37,0,0,1,0,1,1,1,1,1,1,1,1,0
0,0,0,1,1,1,25,0,1,1,1,1,1,1,1,0,0,1,0,0,1,1,1,0
0,0,0,0,0,1,1,1,0,1,1,0,0,0,0,0,0,0,0,0,1,1,1,0
endlayer

layer
1,1,1,1,4,1,1,1,1,1,1,1,1,1,1,1,1,1,1,1,1,1,1,1
1,0,0,0,8,0,0,0,0,0,0,0,0,0,0,1,0,0,0,0,0,0,1,1
1,37,0,0,0,0,37,0,0,0,0,0,0,0,0,0,0,0,0,0,0,0,0,1
0,37,0,0,0,0,0,0,0,0,0,0,0,0,0,0,0,0,0,0,0,0,0,1
1,37,0,0,0,0,37,0,0,0,0,0,0,0,0,1,0,0,0,0,0,0,1,0
1,0,0,0,0,0,0,0,0,0,0,0,0,0,0,1,1,0,0,0,0,1,1,0
1,10,0,0,0,0,0,0,0,0,0,0,0,0,0,1,0,0,0,10,1,1,1,1
1,10,0,0,49,1,0,0,0,0,0,0,0,0,0,0,0,0,0,0,0,1,1,1
1,1,1,1,1,1,0,0,0,0,46,0,0,0,0,0,0,0,0,0,0,0,1,33
1,0,0,0,0,0,0,0,0,0,37,0,0,0,0,0,0,0,0,0,0,8,10,0
1,0,0,0,0,0,0,0,0,0,37,1,0,0,0,1,3,0,0,0,9,8,10,1
1,0,0,0,1,0,0,0,0,0,37,45,0,0,0,1,1,0,45,1,1,1,8,1
1,0,0,0,0,0,0,0,0,0,0,0,0,0,0,1,1,0,1,1,1,10,8,1
0,1,1,0,0,0,0,0,0,1,1,1,0,0,0,1,0,0,1,0,0,0,0,1
0,1,0,0,37,0,0,0,0,0,0,45,0,0,0,0,0,10,36,18,36,0,0,1
0,0,1,0,37,0,0,0,0,0,0,37,0,0,0,0,0,23,0,1,0,0,0,1
0,1,0,0,39,0,0,0,0,0,0,37,0,0,0,0,0,37,40,53,0,0,0,1
1,1,0,0,0,0,0,0,0,0,0,37,0,0,54,53,53,37,0,0,53,53,55,1
0,1,0,0,0,0,0,0,0,0,0,1,1,1,53,53,1,37,0,0,53,53,53,1
0,0,1,0,0,0,37,0,0,0,1,0,0,1,1,1,1,1,0,45,53,53,53,1
0,0,1,1,1,0,37,0,0,0,1,0,0,1,1,0,1,1,1,1,1,53,53,1
0,0,0,0,1,0,37,0,0,1,1,1,1,0,0,0,1,1,0,0,1,53,53,0
0,0,0,0,0,1,1,1,1,1,1,0,0,0,0,0,0,0,0,0,55,55,55,0
endlayer

layer
1,1,1,0,0,1,0,1,1,1,1,1,1,1,1,1,1,1,1,1,1,1,1,1
1,0,0,1,1,1,1,45,0,0,45,0,0,0,0,1,0,0,0,0,0,1,1,1
1,1,1,1,1,1,1,0,0,0,0,0,0,0,0,0,0,0,0,0,0,0,1,1
1,1,1,1,1,0,0,0,0,0,0,0,0,0,0,0,0,0,0,0,0,0,1,1
1,1,1,1,1,1,1,1,1,0,0,0,0,0,0,0,0,0,0,0,0,1,1,1
1,0,0,0,0,0,0,0,0,0,0,0,0,0,0,0,1,1,1,0,1,1,1,1
4,8,0,0,0,0,0,0,0,0,0,0,0,0,0,1,1,1,3,10,1,1,1,1
4,8,0,0,49,1,0,0,0,0,0,0,0,0,0,55,1,3,3,1,1,1,10,8
1,1,1,1,1,1,0,0,0,0,0,0,0,0,0,3,3,3,3,1,1,1,1,33
1,0,0,0,0,0,0,0,0,1,46,0,0,0,0,3,3,3,3,3,1,1,10,0
1,0,0,0,0,0,0,0,0,1,37,40,0,0,0,1,1,3,3,3,1,1,10,0
1,0,0,0,1,1,1,0,0,1,37,1,0,0,0,1,1,3,3,1,1,1,0,1
1,0,0,0,37,1,1,1,0,1,37,0,0,0,0,1,1,0,1,1,1,10,0,1
1,1,1,0,37,1,1,1,0,1,1,1,0,0,0,55,0,0,1,1,1,0,0,1
0,1,0,0,37,40,1,0,0,1,1,1,1,1,1,0,0,8,36,18,36,0,0,1
0,1,1,0,39,0,0,0,0,0,0,1,1,1,1,1,0,0,0,1,55,55,1,1
1,1,0,0,0,0,0,0,0,0,0,1,1,0,0,0,0,26,24,54,53,53,55,55
1,1,0,0,0,0,0,0,0,0,1,1,1,1,0,54,54,23,0,0,54,54,53,55
0,1,1,0,0,0,1,1,3,1,1,1,1,1,54,54,53,37,0,0,54,54,54,55
0,1,1,1,0,0,1,3,3,1,1,1,1,1,1,1,1,37,0,0,54,54,54,55
0,1,1,1,1,1,1,1,1,1,1,1,1,0,1,1,1,1,1,1,1,54,54,55
0,0,0,0,0,1,1,1,1,1,1,1,0,0,0,1,1,1,0,0,1,54,54,55
0,0,0,0,0,0,0,0,1,1,1,0,0,0,0,0,0,0,0,0,1,1,55,55
endlayer

layer
1,1,1,1,1,1,1,1,1,1,1,1,1,1,1,1,1,1,1,1,1,1,1,1
1,1,1,1,1,1,1,1,1,1,1,1,1,1,1,1,1,1,1,1,1,1,1,1
1,1,1,1,1,1,1,1,1,1,1,1,1,1,1,1,1,1,0,0,0,1,1,1
1,1,37,37,37,0,0,0,0,1,1,1,1,1,1,1,0,1,1,0,1,1,1,1
1,1,37,1,1,1,1,1,1,1,1,1,1,1,1,1,1,1,1,0,1,1,1,1
1,1,37,1,1,1,1,1,1,1,1,1,1,1,53,53,1,1,1,1,1,1,1,1
1,1,37,1,1,1,1,1,1,1,0,1,1,1,53,1,1,1,4,8,4,1,1,0
1,1,37,1,49,1,1,1,0,1,0,0,0,1,53,53,53,4,4,4,4,4,8,0
1,1,37,37,37,1,1,0,0,1,0,0,0,0,1,53,4,4,4,4,4,4,8,9
1,1,1,1,37,1,1,0,0,1,0,0,0,0,53,53,4,4,4,4,4,4,8,0
1,1,1,37,37,1,1,0,0,0,26,24,0,0,0,53,4,4,4,4,4,1,10,0
1,3,1,37,1,1,1,0,0,25,46,25,0,0,0,1,4,4,4,4,1,1,1,1
1,3,1,37,37,1,1,0,0,0,37,45,0,0,0,1,4,55,4,4,47,8,0,1
1,3,1,1,29,1,0,1,0,0,37,1,1,55,53,56,53,1,1,1,55,1,0,1
1,3,1,1,26,24,0,1,0,0,1,1,55,55,53,53,53,0,36,18,36,0,0,55
1,3,1,1,0,0,0,0,0,0,1,1,55,53,55,55,55,0,0,1,53,53,55,55
1,3,1,0,0,0,0,0,0,0,1,1,53,53,53,53,0,0,0,0,54,54,55,55
3,3,3,0,0,0,0,0,0,0,0,53,1,53,53,0,0,0,0,0,0,0,54,56
1,3,1,1,3,1,1,0,42,0,0,53,53,53,53,0,54,23,0,0,0,0,0,55
1,3,3,3,3,3,3,43,28,0,0,53,53,53,53,53,53,37,0,0,0,0,0,55
1,1,1,1,1,1,1,0,0,0,0,53,0,0,1,37,37,37,53,1,1,0,0,55
0,0,0,0,0,0,1,1,0,1,0,1,1,0,0,1,1,1,1,0,53,0,0,55
0,0,0,0,0,0,0,0,1,1,1,0,0,0,0,0,0,0,0,55,55,1,1,1
endlayer

layer
1,1,1,1,1,1,1,1,1,1,1,1,1,1,0,0,0,1,1,0,1,1,1,1
1,1,1,1,0,51,51,51,0,1,1,0,0,0,1,1,1,0,0,1,0,0,0,0
1,1,0,0,0,25,0,0,0,0,0,25,0,0,0,25,0,0,0,0,0,0,0,25
1,0,21,20,34,0,0,0,0,34,34,34,34,34,34,34,0,34,34,0,34,34,34,34
1,1,26,24,0,25,0,0,0,0,0,25,0,0,0,25,0,0,0,0,0,0,0,25
1,0,42,1,1,0,0,0,0,0,0,0,0,1,54,54,53,53,53,0,1,1,1,1
1,25,42,25,1,1,0,0,0,0,0,0,0,0,54,53,53,1,0,0,0,0,0,0
1,0,42,1,49,1,1,0,0,0,0,0,0,0,54,54,54,0,0,0,0,0,0,0
1,0,35,20,19,1,0,0,0,0,0,0,0,0,0,54,0,0,0,0,0,0,0,0
1,1,1,24,26,1,0,0,0,0,0,0,0,0,54,54,0,0,0,0,0,8,0,0
1,1,0,21,28,1,0,0,0,0,0,0,0,0,0,54,0,0,0,0,8,4,8,0
1,30,25,42,25,1,0,0,0,25,0,25,0,0,59,58,57,0,0,6,9,1,0,1
1,30,0,35,19,1,0,0,0,0,46,0,0,59,0,0,0,57,2,5,6,1,53,1
1,30,1,1,0,1,0,0,0,0,37,1,1,61,54,56,54,60,1,2,53,1,53,1
32,42,1,0,0,0,0,1,0,0,37,1,53,64,54,54,54,63,62,38,62,53,53,55
32,26,32,0,0,0,0,1,1,1,1,1,53,54,64,65,63,0,0,1,54,54,59,58
1,26,0,0,0,0,0,0,0,0,1,1,54,54,54,54,0,0,0,0,0,59,53,53
1,26,24,0,0,0,0,0,0,0,0,54,1,54,54,0,0,0,0,0,0,61,53,56
32,26,32,0,24,25,0,0,0,0,0,54,54,54,54,0,0,0,0,0,0,64,53,53
32,35,20,20,20,20,20,0,0,0,0,54,54,54,54,54,54,42,0,0,0,0,64,65
32,1,1,1,1,25,1,0,0,0,0,54,0,0,37,37,43,28,54,53,53,0,0,55
0,0,0,0,0,0,1,0,0,1,0,0,1,0,0,1,1,1,53,53,54,0,0,1
0,0,0,0,0,0,1,0,1,1,1,1,0,0,0,0,0,0,55,55,1,1,1,1
endlayer

layer
1,1,1,1,0,1,1,1,1,1,1,1,1,0,0,0,0,1,1,0,1,1,1,1
1,51,0,1,1,0,0,0,0,1,1,0,0,1,1,1,1,0,0,1,0,0,1,1
1,0,0,0,0,25,0,0,0,0,0,25,0,0,0,25,0,0,0,0,0,0,0,25
1,0,0,0,0,0,0,0,0,0,0,0,0,0,0,0,0,0,0,0,0,0,0,0
1,0,0,0,0,25,0,0,0,0,0,25,0,0,0,25,0,0,0,0,0,0,0,25
1,0,0,0,1,0,0,0,0,0,0,0,0,1,0,0,54,54,54,1,1,1,0,1
1,25,0,25,1,1,0,0,0,0,0,0,0,0,0,54,54,1,0,0,0,0,0,0
1,1,0,1,49,1,0,0,0,0,0,0,0,0,0,0,0,0,0,0,0,0,0,0
1,0,0,0,0,1,0,0,0,0,0,0,0,0,0,0,0,0,0,0,0,0,0,0
1,0,1,0,0,1,0,0,0,0,0,0,0,0,0,0,0,0,0,0,0,0,0,0
1,1,0,0,0,1,0,0,0,0,0,0,0,0,0,0,0,0,0,0,0,0,0,1
1,66,25,0,25,1,0,0,0,25,0,25,0,0,59,58,57,0,0,0,0,1,0,1
32,0,0,0,0,1,0,0,0,0,0,0,0,59,0,0,0,57,0,0,0,1,0,1
1,0,1,1,0,1,0,0,0,0,46,1,0,61,0,56,0,60,54,0,54,1,0,1
1,0,1,0,0,0,0,1,37,1,37,1,54,64,0,0,0,63,0,0,0,54,0,55
1,0,0,0,0,0,0,1,37,1,37,53,54,0,64,65,63,0,0,1,0,0,59,58
1,0,0,0,0,0,0,0,37,1,37,37,0,0,0,0,0,0,0,0,0,59,0,0
1,0,0,0,0,0,0,0,37,0,1,37,1,0,0,0,0,0,0,0,0,61,0,56
1,0,0,0,0,25,0,0,0,0,37,37,0,0,0,0,0,0,0,0,0,64,0,0
32,0,0,0,0,0,0,0,0,0,37,1,0,0,0,0,0,0,0,0,0,0,64,65
32,1,1,1,1,25,1,0,0,1,37,37,37,37,37,43,0,0,0,54,54,0,0,1
0,0,1,0,0,0,1,0,0,1,1,53,53,1,55,53,53,53,54,54,0,0,0,1
0,0,0,0,0,0,1,1,1,1,1,55,55,55,55,55,1,55,1,1,1,1,1,1
endlayer

layer
1,1,1,1,0,0,1,1,1,1,1,1,1,0,0,0,1,1,1,1,1,1,1,55
1,51,0,1,1,1,0,0,0,0,1,0,0,1,1,1,0,0,0,0,0,0,1,1
1,0,0,0,0,37,0,0,0,0,0,37,0,0,0,37,0,0,0,0,0,0,0,37
1,0,0,0,0,37,0,0,0,0,0,37,0,0,0,37,0,0,0,0,0,0,0,37
1,0,0,0,0,37,0,0,0,0,0,37,0,0,0,37,0,0,0,1,0,0,0,37
1,0,0,1,1,0,0,0,0,0,0,0,0,1,0,0,0,0,0,1,1,1,0,1
1,37,37,37,1,1,0,0,0,0,0,0,0,0,0,0,0,1,0,0,0,0,0,1
1,1,1,1,49,1,0,0,0,0,0,0,0,0,0,0,0,0,0,0,0,0,0,0
1,1,0,0,0,1,0,0,0,0,0,0,0,0,0,0,0,0,0,0,0,0,0,0
1,1,0,0,0,1,0,0,0,0,0,0,0,0,0,0,0,0,0,0,0,0,0,0
1,1,0,0,0,1,0,0,0,0,0,0,0,0,0,0,0,0,0,0,0,0,0,1
1,1,37,37,37,1,0,0,0,37,37,37,0,0,59,58,57,0,0,0,0,1,0,1
32,0,0,0,0,1,0,0,0,0,0,0,0,59,0,0,0,57,0,0,1,1,0,1
1,1,1,1,0,1,0,0,0,0,0,1,0,61,0,56,0,60,0,0,1,1,0,1
1,0,1,0,0,0,0,7,26,0,26,0,0,64,0,0,0,63,0,0,0,0,0,55
1,0,1,1,0,0,0,1,26,24,26,54,0,0,64,65,63,0,0,1,0,0,59,58
1,1,1,0,0,0,0,0,23,0,35,19,0,0,0,0,0,0,0,0,0,59,0,0
1,0,0,0,0,0,0,1,37,1,25,42,25,0,0,0,0,0,0,0,0,61,0,56
1,0,1,0,0,37,0,0,37,0,21,28,0,0,0,0,0,0,0,0,0,64,0,0
1,1,1,1,1,37,0,1,37,0,26,24,0,0,0,0,0,0,0,0,0,0,64,65
1,1,1,1,1,37,37,37,37,1,35,20,20,20,20,0,0,0,0,0,0,0,0,1
0,1,1,1,0,0,1,1,1,1,1,54,54,0,56,54,54,54,0,0,0,0,0,1
0,0,1,0,0,0,1,1,1,1,1,1,1,1,1,1,1,1,1,1,1,1,1,1
endlayer

layer
1,1,1,1,0,0,0,1,1,1,1,1,1,0,0,0,1,1,1,1,1,1,55,67
1,1,1,1,1,1,1,0,0,0,1,0,1,1,1,1,0,0,0,1,1,1,1,55
1,1,1,1,1,1,0,0,0,0,0,1,0,0,0,1,0,0,0,0,1,1,1,1
1,1,1,1,1,1,0,0,0,0,0,1,0,0,1,1,0,0,0,0,1,1,0,1
1,1,1,3,1,1,0,0,0,0,0,1,0,0,0,1,0,0,1,1,1,0,0,1
1,1,1,3,1,0,0,0,0,0,0,0,0,1,0,0,0,0,0,1,1,1,1,1
1,1,1,3,1,1,0,0,0,0,0,0,0,0,0,0,0,1,1,0,1,0,0,1
1,1,1,3,49,1,0,0,0,0,0,0,0,0,0,0,1,1,0,0,0,0,0,0
1,1,1,3,1,1,0,0,0,0,0,0,0,0,0,0,0,0,0,0,0,0,0,0
1,1,1,3,1,1,0,0,0,0,0,0,0,0,0,0,0,0,0,0,0,0,0,0
1,1,1,3,1,1,0,0,0,0,0,0,0,0,0,0,0,0,0,0,0,0,0,1
1,1,1,3,1,1,0,0,0,1,1,1,0,0,0,0,0,0,0,0,0,0,0,1
0,1,1,3,1,1,0,0,0,0,0,1,0,0,59,58,57,0,0,0,0,1,0,1
0,1,1,3,1,1,1,0,0,0,0,1,0,0,61,68,60,0,0,0,0,1,0,1
0,1,1,3,1,1,1,0,0,0,0,0,0,0,64,65,63,0,0,0,0,0,0,1
0,1,1,3,1,1,1,0,0,0,0,0,0,0,0,0,0,0,0,1,0,0,0,55
1,1,1,3,1,0,0,0,0,0,0,0,0,0,0,0,0,0,0,0,0,0,59,58
1,1,3,3,1,0,0,25,26,25,25,0,25,0,0,0,0,0,0,0,0,0,61,68
1,1,3,1,37,0,0,0,26,0,0,0,0,0,0,0,0,0,0,0,0,0,64,65
1,1,1,1,37,40,1,24,26,0,0,0,0,59,58,57,0,0,0,0,0,0,0,55
1,1,1,1,37,37,37,48,28,51,0,0,0,0,0,0,57,0,0,0,0,0,0,1
0,1,1,1,1,1,1,0,0,51,53,0,61,0,56,0,60,0,0,0,0,0,0,1
0,1,1,1,1,1,1,1,1,1,1,1,64,1,1,1,63,1,1,1,1,1,1,1
endlayer

layer
67,55,1,1,1,0,1,1,1,1,1,1,1,0,1,1,1,1,55,55,67,67,67,69
67,55,1,1,1,1,1,0,0,1,1,1,0,1,0,1,1,1,1,55,55,67,1,67
55,1,0,1,45,1,0,0,0,0,0,1,0,0,1,1,0,1,1,1,55,55,1,67
1,1,45,1,0,1,0,0,0,0,1,1,0,1,1,1,0,0,1,1,55,55,1,1
1,45,0,30,0,1,0,0,0,0,0,1,0,0,0,1,0,1,1,1,55,1,1,1
1,0,25,30,25,0,0,0,0,0,0,0,0,1,0,0,0,0,0,1,1,1,1,1
0,1,0,30,25,25,0,0,0,0,0,0,0,0,0,0,0,1,1,1,1,1,0,1
1,45,0,30,0,25,0,0,0,0,0,1,0,0,0,0,1,1,0,0,1,0,0,1
1,0,0,42,0,25,0,0,0,0,0,0,0,0,0,0,1,0,0,0,0,0,0,0
1,0,0,26,0,25,0,1,0,0,0,0,0,0,0,0,0,0,0,0,0,0,0,1
1,0,0,26,0,25,0,0,0,0,0,0,0,0,0,0,0,0,0,0,0,0,0,1
1,1,1,26,0,25,0,0,0,1,1,1,0,0,0,0,0,0,0,0,0,0,0,1
1,1,0,26,45,25,0,0,0,0,0,1,0,0,0,0,0,0,0,0,0,1,0,1
0,1,70,26,1,25,25,0,0,0,0,1,0,0,0,0,0,0,0,0,0,0,0,1
0,71,24,26,0,0,25,0,0,0,0,0,0,0,0,0,0,0,0,0,0,0,0,1
0,0,1,26,25,25,25,0,0,0,0,0,0,0,0,0,0,0,0,1,0,0,0,55
1,1,21,28,25,0,0,0,0,0,0,0,0,0,0,0,0,0,0,0,0,0,0,55
7,25,26,24,37,0,0,25,0,25,37,37,37,0,0,0,0,0,0,0,0,0,0,1
32,0,46,24,37,0,0,0,0,0,0,0,0,0,0,0,0,0,0,0,0,0,0,55
1,25,3,1,39,24,25,0,0,0,0,0,0,59,58,57,0,0,0,0,0,0,0,55
1,0,3,3,35,20,20,0,0,51,0,0,59,0,0,0,57,0,0,0,0,0,0,1
0,1,1,1,1,0,25,0,0,51,54,0,61,0,56,0,60,0,0,0,0,0,0,1
0,0,0,1,0,1,1,1,1,1,1,1,64,1,0,1,63,1,1,1,1,1,1,1
endlayer

layer
69,67,67,67,55,1,1,1,1,1,1,1,1,1,1,1,1,55,67,67,69,69,69,69
69,67,55,67,55,1,1,1,1,1,1,1,1,1,1,1,1,55,55,67,67,69,67,69
67,67,1,1,1,1,1,1,0,0,1,1,0,1,1,1,1,55,67,67,67,67,67,69
67,55,1,1,45,1,1,0,0,1,1,1,1,1,1,1,0,1,55,67,67,67,67,67
55,1,0,66,0,1,0,0,0,0,1,1,1,1,1,1,1,1,55,55,67,67,1,67
1,45,25,0,25,0,0,0,0,0,1,0,1,1,1,0,0,0,1,55,55,1,1,1
0,1,0,0,0,24,0,0,0,0,0,0,0,1,0,0,0,1,0,0,0,1,1,1
0,1,0,0,0,0,0,0,0,0,0,1,0,0,0,0,1,1,0,0,0,0,0,1
1,0,0,0,0,0,0,0,0,0,0,0,0,0,0,0,1,0,0,0,0,0,0,1
1,0,0,0,0,0,0,1,0,0,0,0,0,0,0,0,0,0,0,0,0,0,0,1
1,0,0,0,0,0,0,0,0,0,0,0,0,0,0,0,0,0,0,0,0,0,0,1
1,1,1,0,0,0,0,0,0,0,1,1,0,0,0,0,0,0,0,0,0,0,0,1
1,1,0,0,0,0,0,0,0,0,45,1,0,0,0,0,0,0,0,0,0,1,0,1
0,1,0,49,1,0,24,0,0,0,0,1,1,0,0,0,0,0,0,0,0,0,0,1
1,1,0,0,0,0,0,0,0,0,0,0,0,0,0,0,0,0,0,0,0,0,0,1
0,1,1,0,0,0,24,0,0,0,0,0,0,0,0,0,0,0,0,1,0,0,0,55
1,1,0,0,37,0,0,0,0,0,0,0,1,0,0,0,0,0,0,0,0,0,0,1
1,25,0,0,37,0,0,37,37,37,1,1,1,0,0,0,0,0,0,0,0,0,0,1
32,45,0,0,29,0,0,0,0,0,0,0,0,0,0,0,0,0,0,0,0,0,0,1
1,25,26,24,0,0,25,0,0,0,0,0,0,59,58,57,0,0,0,0,0,0,1,1
1,45,35,20,0,0,0,0,0,0,0,0,59,0,0,0,57,0,0,0,0,1,1,1
0,1,1,1,1,0,25,0,0,0,0,0,61,0,56,0,60,0,0,0,0,1,1,1
0,0,0,1,0,1,1,1,1,1,1,1,64,1,1,1,63,55,1,1,1,1,1,67
endlayer

layer
69,69,69,69,67,67,67,67,67,67,67,55,55,67,67,67,67,67,69,69,69,69,69,69
69,69,67,69,67,67,67,55,67,67,1,1,55,55,55,55,55,67,67,69,69,69,69,69
69,69,67,67,55,1,1,1,1,1,1,1,1,1,1,1,55,67,69,69,69,69,69,69
69,67,67,55,1,1,1,1,1,1,1,1,1,1,1,1,1,55,67,69,69,69,69,69
67,55,1,1,1,1,1,1,1,1,1,1,1,1,1,1,1,55,55,67,69,69,67,69
55,1,37,37,37,1,1,1,1,1,1,1,1,1,1,1,1,1,1,55,67,67,67,67
1,1,1,0,0,0,1,1,1,0,0,1,1,1,1,1,1,1,1,1,1,55,55,55
1,45,0,0,0,0,0,0,0,0,1,1,1,1,1,1,1,1,1,1,1,1,1,1
1,45,0,0,0,0,0,0,0,0,0,0,0,0,1,1,1,0,1,0,1,0,1,1
1,0,0,0,0,0,1,1,1,0,0,0,0,0,0,0,0,0,0,0,0,0,0,1
1,45,0,0,0,0,0,0,0,0,0,0,0,0,0,0,0,0,0,0,0,0,0,1
1,1,1,0,0,0,0,0,0,0,1,1,0,0,0,0,0,0,0,0,0,0,0,1
1,45,0,0,0,0,0,0,0,0,45,1,1,0,0,0,0,0,0,0,0,1,0,1
1,0,0,49,1,0,0,0,0,0,0,1,1,1,0,0,0,0,0,0,0,0,0,1
1,1,0,0,0,0,0,0,0,0,0,0,0,0,0,0,0,0,0,0,0,0,0,1
1,1,0,0,37,0,0,0,0,0,0,0,0,0,0,0,0,0,0,1,0,0,0,1
1,1,0,0,37,0,0,0,0,0,45,45,1,0,0,0,0,0,0,1,0,0,0,1
1,37,0,0,29,0,0,1,1,1,1,1,1,0,0,0,0,0,0,0,0,0,1,1
32,37,0,0,0,0,0,1,1,1,0,0,0,0,0,0,0,0,0,0,0,1,1,67
1,37,0,0,0,0,37,0,0,0,0,0,0,0,0,0,0,0,0,0,1,1,67,67
1,45,0,0,0,0,37,0,0,0,0,0,0,59,58,57,0,0,0,0,1,1,67,67
1,1,1,1,1,45,37,0,0,0,0,0,0,61,68,60,0,0,0,1,1,67,67,67
0,0,1,0,0,1,1,1,1,1,1,1,1,64,65,63,55,55,67,67,67,67,67,69
endlayer

layer
69,69,69,69,69,69,69,69,69,69,69,67,67,69,69,69,69,69,69,69,69,69,69,69
69,69,69,69,69,69,69,67,69,69,67,67,67,67,67,67,67,69,69,69,69,69,69,69
69,69,69,69,67,67,67,67,67,67,67,67,67,67,67,67,67,69,69,69,69,69,69,69
69,69,69,67,67,67,67,67,67,67,67,67,67,67,67,67,67,67,69,69,69,69,69,69
69,67,67,67,67,67,67,55,55,55,67,67,67,67,67,67,67,67,67,69,69,69,69,69
67,67,67,67,67,67,55,55,55,55,1,1,55,55,67,67,67,67,67,67,69,69,69,69
67,55,55,1,1,1,55,55,55,1,1,1,55,55,55,67,67,67,67,67,67,67,67,67
67,1,1,1,1,1,1,1,1,1,1,1,1,1,55,55,55,55,55,55,55,55,55,55
1,1,1,1,1,1,1,1,1,1,1,1,1,1,1,1,1,1,1,1,1,1,1,1
1,1,1,1,1,1,1,1,1,1,1,1,1,1,1,1,1,1,1,1,1,1,1,1
1,45,1,45,0,0,1,1,1,1,1,1,1,0,1,1,1,1,1,1,1,1,1,1
1,1,1,1,0,0,0,0,0,1,1,1,0,1,1,1,1,1,1,1,1,1,0,1
1,45,1,0,0,0,0,0,0,0,1,1,1,0,0,1,1,1,1,1,1,1,0,1
1,45,0,49,1,0,0,0,0,0,1,1,1,1,1,1,1,1,1,1,1,0,0,1
1,0,0,0,37,0,0,0,0,0,0,0,0,0,0,0,1,1,1,1,1,0,0,1
1,0,0,0,37,0,0,0,0,0,0,0,1,0,0,0,0,0,1,1,0,0,0,1
1,1,0,0,29,0,0,0,0,1,1,1,1,1,1,1,1,1,1,1,1,1,1,1
1,1,1,0,0,0,0,1,1,1,1,1,1,1,1,1,1,1,1,1,1,1,1,67
1,1,1,1,0,0,1,1,55,1,1,1,1,1,1,1,1,1,1,1,1,1,67,69
1,1,1,0,0,0,1,1,0,1,1,1,1,1,1,1,1,1,1,1,1,67,69,69
1,1,0,0,0,0,1,1,0,0,1,1,1,1,1,1,1,1,1,1,67,67,69,69
1,0,0,45,1,45,1,1,0,0,1,1,1,1,1,1,1,67,67,67,67,69,69,69
1,1,1,1,1,1,55,55,67,67,67,67,1,67,67,67,67,67,69,69,69,69,69,69
endlayer

layer
69,69,69,69,69,69,69,69,69,69,69,69,69,69,69,69,69,69,69,69,69,69,69,69
69,69,69,69,69,69,69,69,69,69,69,69,69,69,69,69,69,69,69,69,69,69,69,69
69,69,69,69,69,69,69,69,69,69,69,69,69,69,69,69,69,69,69,69,69,69,69,69
69,69,69,69,69,69,69,69,69,69,69,69,69,69,69,69,69,69,69,69,69,69,69,69
69,69,69,69,69,69,69,67,67,67,69,69,69,69,69,69,69,69,69,69,69,69,69,69
69,69,69,69,69,69,67,67,67,67,67,67,67,67,69,69,69,69,69,69,69,69,69,69
69,67,67,67,67,67,67,67,67,67,55,67,67,67,67,69,69,69,69,69,69,69,69,69
69,67,67,67,55,67,67,67,67,55,55,55,67,67,67,67,67,67,67,67,67,67,67,67
67,67,67,55,55,55,55,55,55,55,55,55,55,55,55,67,67,67,67,67,67,55,55,67
1,1,1,1,1,1,55,55,55,55,55,55,55,55,55,55,67,67,67,67,55,55,55,55
1,1,1,1,1,1,1,1,1,1,1,1,1,1,55,67,67,1,1,1,1,1,1,55
1,1,1,1,1,1,1,1,1,1,1,1,1,1,1,67,1,1,4,4,4,1,1,1
1,1,1,1,1,1,1,1,1,1,1,1,1,1,1,1,1,4,4,4,4,1,1,1
1,1,1,49,37,37,37,37,37,37,37,37,3,3,3,3,1,4,4,4,4,1,1,1
1,1,1,1,37,1,1,1,1,1,1,1,1,1,1,1,1,1,4,4,4,1,1,1
1,1,1,1,29,1,1,1,1,1,1,1,1,1,1,1,1,1,1,1,1,1,1,1
1,1,1,1,0,1,1,1,1,1,55,55,55,55,67,67,67,67,67,67,67,67,55,55
1,1,1,1,0,1,1,1,55,1,55,55,55,67,67,67,67,67,67,67,67,67,67,69
1,1,1,1,1,1,1,1,55,55,55,67,67,67,67,69,69,69,67,67,67,67,69,69
1,1,1,1,1,1,1,55,55,67,67,67,67,67,69,69,69,69,69,67,67,69,69,69
1,1,1,1,1,1,1,55,55,67,67,67,67,67,69,69,69,69,67,67,69,69,69,69
1,1,1,1,1,1,1,55,55,67,67,67,67,67,67,69,67,69,69,69,69,69,69,69
67,67,67,67,67,67,67,67,69,69,69,0,67,69,69,69,69,69,69,69,69,69,69,69
endlayer

layer
69,69,69,69,69,69,69,69,0,0,0,0,0,0,0,0,69,69,69,69,69,69,69,69
69,69,69,69,69,69,0,0,0,0,0,0,0,0,0,0,0,69,69,69,69,69,69,69
69,69,69,69,0,0,0,0,0,0,0,0,0,0,0,0,0,0,0,0,69,69,69,69
69,69,69,0,0,0,0,0,0,0,0,0,0,0,0,0,0,0,0,0,0,69,69,69
69,69,69,0,0,0,0,72,0,0,0,0,0,0,0,0,0,0,0,0,0,0,69,69
69,69,0,0,0,0,0,72,72,72,72,72,72,72,0,0,0,0,0,0,0,0,0,69
69,69,0,0,0,72,72,0,72,72,67,72,0,72,72,0,0,0,0,0,0,0,0,69
69,0,0,72,67,72,72,72,72,67,55,67,72,0,0,0,0,72,72,72,0,72,0,0
72,0,72,67,55,55,67,67,67,55,55,55,67,67,67,72,0,72,72,0,0,67,67,0
67,67,55,1,1,1,55,55,55,55,55,55,55,55,67,67,0,72,0,72,67,55,55,67
1,1,1,1,1,1,1,1,1,1,51,1,1,1,67,72,72,0,0,0,0,67,1,67
1,1,1,51,51,51,0,1,1,0,0,0,51,1,73,72,0,0,0,0,0,0,1,1
1,51,25,45,0,0,25,45,70,25,24,25,51,0,0,0,0,0,0,0,8,10,11,1
1,34,34,0,21,20,20,20,20,20,20,20,34,34,50,50,37,0,0,0,9,8,10,1
1,51,25,0,26,24,25,45,0,25,0,25,51,0,0,0,0,0,0,0,0,0,1,1
1,1,45,25,0,25,1,1,51,0,0,0,0,1,0,0,0,0,0,0,67,67,1,1
55,1,1,51,0,51,1,1,1,1,55,55,55,67,72,0,0,72,0,72,0,72,67,67
55,55,1,51,0,51,1,55,55,55,55,55,67,72,72,72,0,72,72,0,69,72,69,69
55,55,1,51,42,51,1,55,67,67,67,0,72,72,72,0,0,0,0,69,69,69,69,69
55,55,1,51,42,51,1,55,67,72,72,72,72,0,0,0,0,0,0,69,69,69,69,69
67,55,1,51,42,51,1,55,67,69,0,69,72,69,0,69,69,69,69,69,69,69,69,69
67,55,1,25,42,25,1,55,67,69,69,69,69,69,69,69,69,69,69,69,69,69,69,69
69,69,69,69,0,69,69,69,69,69,69,69,69,69,69,69,69,69,69,69,69,69,69,69
endlayer

layer
69,69,69,69,69,69,0,0,0,0,0,0,0,0,0,0,0,0,69,69,69,69,69,69
69,69,69,69,69,0,0,0,0,0,0,0,0,0,0,0,0,0,0,69,69,69,69,69
69,69,69,0,0,0,0,0,0,0,0,0,0,0,0,0,0,0,0,0,0,69,69,69
69,69,0,0,0,0,0,0,0,0,0,0,0,0,0,0,0,0,0,0,0,0,69,69
69,0,0,0,0,0,0,0,0,0,0,0,0,0,0,0,0,0,0,0,0,0,0,69
0,0,0,0,0,0,0,0,0,0,0,0,0,0,0,0,0,0,0,0,0,0,0,0
0,0,0,0,0,0,0,0,0,0,72,0,0,0,0,0,0,0,0,0,0,0,0,0
0,0,0,0,72,0,0,0,0,72,67,0,0,0,0,0,0,0,0,0,0,0,0,0
0,0,0,72,55,67,72,72,72,67,55,67,72,72,0,0,0,0,0,0,0,72,0,0
0,72,67,55,1,1,55,67,67,55,55,55,67,67,0,72,0,0,0,0,72,67,67,0
67,55,55,1,1,1,1,1,1,1,1,1,1,67,72,0,0,0,0,0,0,0,67,0
1,1,1,51,51,51,45,45,0,45,0,0,0,70,0,0,0,0,0,0,0,0,0,1
1,51,25,0,0,0,25,0,0,25,0,25,0,0,0,0,0,0,0,0,0,8,4,1
1,45,0,0,0,0,0,0,0,0,0,0,0,0,0,74,37,0,0,0,0,0,8,0
1,51,25,0,0,0,25,0,0,25,0,25,0,0,0,0,0,0,0,0,0,0,67,0
1,1,45,25,0,25,1,1,51,0,0,0,0,70,0,0,0,0,0,0,72,72,67,67
67,55,1,51,0,51,1,55,55,55,55,55,67,72,0,0,0,0,0,0,0,0,72,72
67,55,1,51,0,51,1,67,67,67,67,67,72,0,0,0,0,0,0,0,0,0,0,69
67,55,1,51,0,51,1,67,72,72,72,0,0,0,0,0,0,0,0,0,0,69,69,69
67,55,1,51,45,51,1,55,72,0,0,0,0,0,0,0,0,0,0,0,0,69,69,69
69,67,1,51,0,51,1,55,72,0,0,0,0,0,0,0,0,0,0,0,69,69,69,69
69,67,1,25,0,25,1,67,0,0,69,69,0,0,0,0,0,0,69,69,69,69,69,69
69,69,69,0,0,0,0,69,69,69,69,69,69,69,0,0,69,69,69,69,69,69,69,69
endlayer

layer
69,69,69,69,0,0,0,0,0,0,0,0,0,0,0,0,0,0,0,0,69,69,69,69
69,69,69,0,0,0,0,0,0,0,0,0,0,0,0,0,0,0,0,0,0,69,69,69
69,0,0,0,0,0,0,0,0,0,0,0,0,0,0,0,0,0,0,0,0,0,69,69
0,0,0,0,0,0,0,0,0,0,0,0,0,0,0,0,0,0,0,0,0,0,0,69
0,0,0,0,0,0,0,0,0,0,0,0,0,0,0,0,0,0,0,0,0,0,0,0
0,0,0,0,0,0,0,0,0,0,0,0,0,0,0,0,0,0,0,0,0,0,0,0
0,0,0,0,0,0,0,0,0,0,0,0,0,0,0,0,0,0,0,0,0,0,0,0
0,0,0,0,0,0,0,0,0,0,72,0,0,0,0,0,0,0,0,0,0,0,0,0
0,0,0,0,67,72,0,0,0,72,67,0,0,0,0,0,0,0,0,0,0,0,0,0
0,0,72,67,67,55,67,72,0,67,67,67,72,0,0,0,0,0,0,0,0,72,72,0
72,67,67,1,1,1,1,67,67,55,55,55,67,0,0,0,0,0,0,0,0,0,0,0
67,1,1,1,1,1,1,1,1,1,1,1,1,0,0,0,0,0,0,0,0,0,0,0
67,1,37,45,0,45,37,0,0,37,45,37,0,0,0,0,0,0,0,0,0,0,0,0
67,1,37,0,0,0,37,0,0,37,45,37,0,0,0,0,0,0,0,0,0,0,0,0
67,1,37,45,0,0,37,0,45,37,45,37,0,0,0,0,0,0,0,0,0,0,72,0
67,1,1,37,37,37,1,1,1,1,1,1,0,0,0,0,0,0,0,0,0,0,72,72
72,55,55,1,0,1,1,67,67,67,67,67,72,0,0,0,0,0,0,0,0,0,0,0
72,67,55,1,0,1,55,0,72,72,72,72,0,0,0,0,0,0,0,0,0,0,0,0
72,67,55,1,0,1,55,72,0,0,0,0,0,0,0,0,0,0,0,0,0,0,0,0
72,67,55,1,0,1,1,67,0,0,0,0,0,0,0,0,0,0,0,0,0,0,0,69
69,72,55,1,0,1,1,67,0,0,0,0,0,0,0,0,0,0,0,0,0,0,69,69
69,69,67,37,37,37,67,0,0,0,0,0,0,0,0,0,0,0,0,0,69,69,69,69
69,69,69,0,0,0,0,0,0,0,0,0,0,0,0,0,0,0,69,69,69,69,69,69
endlayer

layer
69,69,69,0,0,0,0,0,0,0,0,0,0,0,0,0,0,0,0,0,0,69,69,69
69,0,0,0,0,0,0,0,0,0,0,0,0,0,0,0,0,0,0,0,0,0,69,69
0,0,0,0,0,0,0,0,0,0,0,0,0,0,0,0,0,0,0,0,0,0,0,69
0,0,0,0,0,0,0,0,0,0,0,0,0,0,0,0,0,0,0,0,0,0,0,0
0,0,0,0,0,0,0,0,0,0,0,0,0,0,0,0,0,0,0,0,0,0,0,0
0,0,0,0,0,0,0,0,0,0,0,0,0,0,0,0,0,0,0,0,0,0,0,0
0,0,0,0,0,0,0,0,0,0,0,0,0,0,0,0,0,0,0,0,0,0,0,0
0,0,0,0,0,0,0,0,0,0,0,0,0,0,0,0,0,0,0,0,0,0,0,0
0,0,0,0,72,0,0,0,0,0,72,0,0,0,0,0,0,0,0,0,0,0,0,0
0,0,0,72,72,67,72,0,0,72,72,72,0,0,0,0,0,0,0,0,0,0,0,0
0,72,72,67,67,67,67,72,72,67,67,67,72,0,0,0,0,0,0,0,0,0,0,0
72,67,67,1,1,1,67,67,67,1,1,1,67,0,0,0,0,0,0,0,0,0,0,0
72,67,1,1,1,1,1,1,1,1,1,1,1,0,0,0,0,0,0,0,0,0,0,0
72,67,1,1,45,1,1,1,1,1,1,1,0,0,0,0,0,0,0,0,0,0,0,0
72,67,1,1,1,1,1,1,1,1,1,1,0,0,0,0,0,0,0,0,0,0,0,0
72,67,55,1,1,1,67,67,67,67,67,67,0,0,0,0,0,0,0,0,0,0,0,0
0,67,67,1,1,1,67,0,72,72,72,72,0,0,0,0,0,0,0,0,0,0,0,0
0,72,67,1,1,1,67,0,0,0,0,0,0,0,0,0,0,0,0,0,0,0,0,0
0,72,67,1,1,1,67,0,0,0,0,0,0,0,0,0,0,0,0,0,0,0,0,0
0,72,67,1,1,1,67,72,0,0,0,0,0,0,0,0,0,0,0,0,0,0,0,0
0,0,67,1,1,1,67,0,0,0,0,0,0,0,0,0,0,0,0,0,0,0,0,69
69,0,72,67,67,67,72,0,0,0,0,0,0,0,0,0,0,0,0,0,0,0,69,69
69,69,0,0,0,0,0,0,0,0,0,0,0,0,0,0,0,0,0,0,69,69,69,69
endlayer

layer
69,69,0,0,0,0,0,0,0,0,0,0,0,0,0,0,0,0,0,0,0,0,69,69
0,0,0,0,0,0,0,0,0,0,0,0,0,0,0,0,0,0,0,0,0,0,0,69
0,0,0,0,0,0,0,0,0,0,0,0,0,0,0,0,0,0,0,0,0,0,0,0
0,0,0,0,0,0,0,0,0,0,0,0,0,0,0,0,0,0,0,0,0,0,0,0
0,0,0,0,0,0,0,0,0,0,0,0,0,0,0,0,0,0,0,0,0,0,0,0
0,0,0,0,0,0,0,0,0,0,0,0,0,0,0,0,0,0,0,0,0,0,0,0
0,0,0,0,0,0,0,0,0,0,0,0,0,0,0,0,0,0,0,0,0,0,0,0
0,0,0,0,0,0,0,0,0,0,0,0,0,0,0,0,0,0,0,0,0,0,0,0
0,0,0,0,0,0,0,0,0,0,0,0,0,0,0,0,0,0,0,0,0,0,0,0
0,0,0,0,0,72,0,0,0,0,0,0,0,0,0,0,0,0,0,0,0,0,0,0
0,0,0,72,72,72,0,0,0,72,72,0,0,0,0,0,0,0,0,0,0,0,0,0
0,72,72,67,67,67,72,72,0,67,67,67,72,0,0,0,0,0,0,0,0,0,0,0
0,72,67,67,67,67,67,67,67,67,67,67,67,0,0,0,0,0,0,0,0,0,0,0
0,72,67,67,67,67,67,67,67,67,67,67,0,0,0,0,0,0,0,0,0,0,0,0
0,72,67,67,67,67,67,67,67,67,67,67,0,0,0,0,0,0,0,0,0,0,0,0
0,72,67,67,67,67,72,72,72,72,72,0,0,0,0,0,0,0,0,0,0,0,0,0
0,72,72,67,67,67,72,0,0,0,0,0,0,0,0,0,0,0,0,0,0,0,0,0
0,0,72,67,67,67,72,0,0,0,0,0,0,0,0,0,0,0,0,0,0,0,0,0
0,0,72,67,67,67,0,0,0,0,0,0,0,0,0,0,0,0,0,0,0,0,0,0
0,0,72,67,67,67,72,0,0,0,0,0,0,0,0,0,0,0,0,0,0,0,0,0
0,0,72,67,67,67,0,0,0,0,0,0,0,0,0,0,0,0,0,0,0,0,0,0
0,0,0,72,72,72,0,0,0,0,0,0,0,0,0,0,0,0,0,0,0,0,0,69
69,0,0,0,0,0,0,0,0,0,0,0,0,0,0,0,0,0,0,0,0,69,69,69
endlayer

layer
69,0,0,0,0,0,0,0,0,0,0,0,0,0,0,0,0,0,0,0,0,0,0,69
0,0,0,0,0,0,0,0,0,0,0,0,0,0,0,0,0,0,0,0,0,0,0,0
0,0,0,0,0,0,0,0,0,0,0,0,0,0,0,0,0,0,0,0,0,0,0,0
0,0,0,0,0,0,0,0,0,0,0,0,0,0,0,0,0,0,0,0,0,0,0,0
0,0,0,0,0,0,0,0,0,0,0,0,0,0,0,0,0,0,0,0,0,0,0,0
0,0,0,0,0,0,0,0,0,0,0,0,0,0,0,0,0,0,0,0,0,0,0,0
0,0,0,0,0,0,0,0,0,0,0,0,0,0,0,0,0,0,0,0,0,0,0,0
0,0,0,0,0,0,0,0,0,0,0,0,0,0,0,0,0,0,0,0,0,0,0,0
0,0,0,0,0,0,0,0,0,0,0,0,0,0,0,0,0,0,0,0,0,0,0,0
0,0,0,0,0,0,0,0,0,0,0,0,0,0,0,0,0,0,0,0,0,0,0,0
0,0,0,0,0,0,0,0,0,0,0,0,0,0,0,0,0,0,0,0,0,0,0,0
0,0,0,0,0,0,0,0,0,0,0,0,0,0,0,0,0,0,0,0,0,0,0,0
0,0,0,0,0,0,0,0,0,0,0,0,0,0,0,0,0,0,0,0,0,0,0,0
0,0,0,0,0,0,0,0,0,0,0,0,0,0,0,0,0,0,0,0,0,0,0,0
0,0,0,0,0,0,0,0,0,0,0,0,0,0,0,0,0,0,0,0,0,0,0,0
0,0,0,0,0,0,0,0,0,0,0,0,0,0,0,0,0,0,0,0,0,0,0,0
0,0,0,0,0,0,0,0,0,0,0,0,0,0,0,0,0,0,0,0,0,0,0,0
0,0,0,0,0,0,0,0,0,0,0,0,0,0,0,0,0,0,0,0,0,0,0,0
0,0,0,0,0,0,0,0,0,0,0,0,0,0,0,0,0,0,0,0,0,0,0,0
0,0,0,0,0,0,0,0,0,0,0,0,0,0,0,0,0,0,0,0,0,0,0,0
0,0,0,0,0,0,0,0,0,0,0,0,0,0,0,0,0,0,0,0,0,0,0,0
0,0,0,0,0,0,0,0,0,0,0,0,0,0,0,0,0,0,0,0,0,0,0,0
0,0,0,0,0,0,0,0,0,0,0,0,0,0,0,0,0,0,0,0,0,0,0,69
endlayer


