# Small Cottage No. 2 10/25/2014
# Created by Ruins mod version 13.8 Ingame Parser
# authoring Player: Kujaku10
# Last Updated 6 Apr 2018
# Updated to MC 1.8: 5 Mar 2016
# Updated to MC 1.9: 18 Apr 2016
# Updated to MC 1.11.2: 11 Jan 2017
# Updated to MC 1.12: 22 Jun 2017

weight=1
embed_into_distance=4
acceptable_target_blocks=

unacceptable_target_blocks=flowing_lava,lava,cloud,Natura:Cloud,red_mushroom_block,brown_mushroom_block,planks,cobblestone,torch,stone_slab,double_stone_slab,oak_stairs,spruce_stairs,birch_stairs,dark_oak_stairs,acacia_stairs,jungle_stairs,slime_congealed,slime_dirt,slime_grass,fence,stone_brick,cobblestone_wall,command_block

dimensions=14,13,11
allowable_overhang=0
max_leveling=4
leveling_buffer=-1
preserve_water=0
preserve_lava=0
preserve_plants=1

rule1=0,100,preserveBlock
rule2=0,100,minecraft:grass-0
rule3=1,100,minecraft:red_flower-1
rule4=1,100,minecraft:leaves-14
rule5=0,100,minecraft:stonebrick-0
rule6=0,100,minecraft:stonebrick-3
rule7=0,100,minecraft:stone_brick_stairs-0
rule8=0,100,minecraft:netherrack-0
rule9=0,100,minecraft:stone_brick_stairs-3
rule10=0,100,minecraft:stone_brick_stairs-1
rule11=0,100,minecraft:planks-2
rule12=0,100,minecraft:quartz_block-0
rule13=0,100,IInventory;minecraft:lit_furnace;minecraft:coal#6#1#1-5

# Flower Pot: Jungle Sapling
rule14=0,100,teBlock;minecraft:flower_pot;{Item:"minecraft:sapling",x:0,y:0,z:0,Data:3,id:"flower_pot"}-0

rule15=0,100,minecraft:brick_block-0
rule16=0,100,minecraft:iron_bars-0
rule17=0,100,minecraft:fire-15
rule18=1,100,minecraft:wooden_door-3
rule19=0,100,minecraft:crafting_table-0
rule20=0,100,minecraft:noteblock-0
rule21=0,100,minecraft:glass_pane-0

# Flower Pot: Oak Sapling
rule22=0,100,teBlock;minecraft:flower_pot;{Item:"minecraft:sapling",x:0,y:0,z:0,Data:0,id:"flower_pot"}-0

rule23=0,100,minecraft:fence-0
rule24=1,100,minecraft:wooden_door-8
rule25=2,100,minecraft:torch-5
rule26=0,100,minecraft:stained_hardened_clay-13
rule27=0,100,minecraft:spruce_stairs-2
rule28=0,100,minecraft:spruce_stairs-3
rule29=0,100,minecraft:planks-1
rule30=0,100,minecraft:wooden_slab-9
rule31=0,100,minecraft:brick_stairs-0
rule32=0,100,minecraft:quartz_stairs-7
rule33=0,100,minecraft:brick_stairs-1
rule34=0,100,minecraft:stained_hardened_clay-3
rule35=0,100,minecraft:brick_stairs-2
rule36=0,100,minecraft:spruce_stairs-1
rule37=0,100,minecraft:spruce_stairs-0
rule38=0,100,minecraft:wooden_slab-1
rule39=0,100,minecraft:cobblestone_wall-0

# Bandit
rule40=0,100,CommandBlock:RUINSTRIGGER /summon Skeleton ~0 ~0 ~0 {HandItems:[{Count:1,id:wooden_sword,tag:{display:{Name:"Bandit Bludgeon"},ench:[{id:19,lvl:2},{id:21,lvl:2},{id:16,lvl:3}]}},{}],ArmorItems:[{Count:1,id:leather_boots},{Count:1,id:leather_leggings},{Count:1,id:leather_chestplate},{Count:1,id:skull,Damage:3,tag:{SkullOwner:MHF_Villager}}],CustomName:Bandit,HandDropChances:[1.0F,0.0F],ArmorDropChances:[0.5F,0.5F,0.5F,0.0F],Silent:1,PersistenceRequired:1,Health:15.0f}:@

layer
1,1,1,1,1,1,1,1,1,1,1
1,2,1,1,1,1,1,1,1,1,1
2,2,5,5,5,5,5,5,5,1,1
2,2,5,15,15,15,15,15,5,1,1
2,2,5,15,15,15,15,15,5,1,1
2,5,5,15,15,15,15,15,5,5,1
2,5,5,15,15,15,15,15,15,5,1
2,5,5,15,15,15,15,15,15,5,1
2,2,5,15,15,15,15,15,5,5,1
2,2,5,15,15,15,15,15,5,1,1
2,2,5,5,5,5,5,5,5,1,1
1,2,1,1,1,1,1,1,1,1,1
1,1,1,1,1,1,1,1,1,1,1
endlayer

layer
1,1,1,1,1,1,1,1,1,1,1
1,1,1,1,1,1,1,1,1,1,1
1,2,5,5,5,5,5,5,5,1,1
2,2,5,0,0,0,0,0,5,1,1
2,2,5,0,0,0,0,0,5,1,1
2,5,5,0,0,0,0,0,5,5,1
2,5,5,0,0,0,0,0,0,5,1
2,5,5,0,0,0,0,0,0,5,1
2,2,5,0,0,0,0,0,5,5,1
2,2,5,0,0,0,0,0,5,1,1
1,2,5,5,5,5,5,5,5,1,1
1,1,1,1,1,1,1,1,1,1,1
1,1,1,1,1,1,1,1,1,1,1
endlayer



layer
1,1,1,1,1,1,1,1,1,1,1
1,1,1,1,1,1,1,1,1,1,1
1,1,5,5,5,5,5,5,5,1,1
1,2,5,0,0,0,0,0,5,1,1
2,2,5,0,0,0,0,0,5,1,1
2,5,5,0,0,0,0,0,5,5,1
2,5,5,0,0,0,0,0,0,5,1
2,5,5,0,0,0,0,0,0,5,1
2,2,5,0,0,0,0,0,5,5,1
1,2,5,0,0,0,0,0,5,1,1
1,1,5,5,5,5,5,5,5,1,1
1,1,1,1,1,1,1,1,1,1,1
1,1,1,1,1,1,1,1,1,1,1
endlayer

layer
1,1,1,1,1,1,1,1,1,1,1
1,1,1,1,1,1,1,1,1,1,1
1,1,5,5,5,5,5,5,5,1,1
1,1,5,0,0,0,0,0,5,1,1
1,2,5,0,0,0,0,0,5,1,1
2,5,5,0,0,0,0,0,5,5,1
2,5,5,0,0,0,0,0,0,5,1
2,5,5,0,0,0,0,0,0,5,1
1,2,5,0,0,0,0,0,5,5,1
1,1,5,0,0,0,0,0,5,1,1
1,1,5,5,5,5,5,5,5,1,1
1,1,1,1,1,1,1,1,1,1,1
1,1,1,1,1,1,1,1,1,1,1
endlayer


layer
1,1,1,0,0,0,0,0,1,1,1
1,3,3,4,4,4,4,4,3,3,1
1,4,5,5,5,5,5,5,5,0,1
0,4,5,5,5,5,5,5,5,0,0
0,4,5,5,5,5,5,5,5,0,0
0,7,5,5,5,5,6,6,5,5,0
0,9,5,5,5,5,6,5,8,5,0
0,10,5,5,5,5,6,5,8,5,0
0,4,5,5,5,5,6,6,5,5,0
0,4,5,5,5,5,5,5,5,0,0
1,4,5,5,5,5,5,5,5,0,1
1,3,3,4,4,4,4,4,3,3,1
1,1,1,0,0,0,0,0,1,1,1
endlayer

layer
1,1,0,0,0,0,0,0,0,1,1
1,0,0,0,0,0,0,0,0,0,1
0,0,11,12,12,12,12,12,11,0,0
0,0,12,14,0,0,0,13,12,0,0
0,0,11,0,0,0,0,0,12,0,0
0,0,12,0,0,0,0,16,15,15,0
0,0,0,18,0,40,0,16,17,15,0
0,0,12,0,0,0,0,16,17,15,0
0,0,11,19,0,0,0,16,15,15,0
0,0,12,20,0,0,0,0,12,0,0
0,0,11,12,12,12,12,12,11,0,0
1,0,0,0,0,0,0,0,0,0,1
1,1,0,0,0,0,0,0,0,1,1
endlayer

layer
1,0,0,0,0,0,0,0,0,0,1
0,0,0,0,0,0,0,0,0,0,0
0,0,11,12,12,21,12,12,11,0,0
0,0,21,0,23,0,23,22,12,0,0
0,0,11,0,0,0,0,0,12,0,0
0,0,12,0,0,0,0,0,15,15,0
0,0,0,24,0,0,0,0,0,15,0
0,0,12,0,0,0,0,0,0,15,0
0,0,11,0,0,0,0,0,15,15,0
0,0,21,14,23,0,23,0,12,0,0
0,0,11,12,12,21,12,12,11,0,0
0,0,0,0,0,0,0,0,0,0,0
1,0,0,0,0,0,0,0,0,0,1
endlayer

layer
0,0,0,0,0,0,0,0,0,0,0
0,0,0,0,0,0,0,0,0,0,0
0,0,11,12,12,21,12,12,11,0,0
0,0,21,0,25,0,25,0,12,0,0
0,0,11,0,0,0,0,0,12,0,0
0,0,12,0,0,0,0,16,15,15,0
0,0,26,0,0,0,0,16,0,15,0
0,0,12,0,0,0,0,16,0,15,0
0,0,11,0,0,0,0,16,15,15,0
0,0,21,0,25,0,25,0,12,0,0
0,0,11,12,12,21,12,12,11,0,0
0,0,0,0,0,0,0,0,0,0,0
0,0,0,0,0,0,0,0,0,0,0
endlayer

layer
0,0,0,0,0,0,0,0,0,0,0
0,28,0,0,0,0,0,0,0,27,0
0,28,29,29,29,29,29,29,29,27,0
0,28,29,0,0,0,0,30,29,27,0
0,28,29,0,0,0,0,30,29,27,0
0,28,29,0,0,0,0,32,15,31,0
0,28,29,0,0,0,0,32,0,15,0
0,28,29,0,0,0,0,32,0,15,0
0,28,29,0,0,0,0,32,15,33,0
0,28,29,0,0,0,0,30,29,27,0
0,28,29,29,34,29,34,29,29,27,0
0,28,0,0,0,0,0,0,0,27,0
0,0,0,0,0,0,0,0,0,0,0
endlayer

layer
0,0,0,0,0,0,0,0,0,0,0
0,0,28,0,0,0,0,0,27,0,0
0,0,28,11,12,12,12,11,27,0,0
0,0,28,34,0,0,0,34,27,0,0
0,0,28,34,0,0,0,34,27,0,0
0,0,28,34,0,0,0,34,35,0,0
0,0,28,34,0,0,0,34,15,35,0
0,0,28,34,0,0,0,34,15,35,0
0,0,28,34,0,0,0,34,35,0,0
0,0,28,34,0,0,0,34,27,0,0
0,0,28,11,12,12,12,11,27,0,0
0,0,28,0,0,0,0,0,27,0,0
0,0,0,0,0,0,0,0,0,0,0
endlayer

layer
0,0,0,0,0,0,0,0,0,0,0
0,0,0,28,0,0,0,27,0,0,0
0,0,0,28,11,26,11,27,0,0,0
0,0,0,28,26,0,26,27,0,0,0
0,0,0,28,26,0,26,27,0,0,0
0,0,0,28,26,0,26,27,0,0,0
0,0,0,28,26,0,26,15,15,0,0
0,0,0,28,26,0,26,15,15,0,0
0,0,0,28,26,0,26,27,0,0,0
0,0,0,28,26,0,26,27,0,0,0
0,0,0,28,11,26,11,27,0,0,0
0,0,0,28,0,0,0,27,0,0,0
0,0,0,0,0,0,0,0,0,0,0
endlayer

layer
0,0,0,0,0,0,0,0,0,0,0
0,0,0,0,29,0,29,0,0,0,0
0,0,0,0,36,11,27,0,0,0,0
0,0,0,0,28,34,27,0,0,0,0
0,0,0,0,28,34,27,0,0,0,0
0,0,0,0,28,34,27,0,0,0,0
0,0,0,0,28,34,27,15,15,0,0
0,0,0,0,28,34,27,15,15,0,0
0,0,0,0,28,34,27,0,0,0,0
0,0,0,0,28,34,27,0,0,0,0
0,0,0,0,37,11,37,0,0,0,0
0,0,0,0,29,0,29,0,0,0,0
0,0,0,0,0,0,0,0,0,0,0
endlayer

layer
0,0,0,0,0,0,0,0,0,0,0
0,0,0,0,28,29,27,0,0,0,0
0,0,0,0,0,36,0,0,0,0,0
0,0,0,0,0,38,0,0,0,0,0
0,0,0,0,0,38,0,0,0,0,0
0,0,0,0,0,38,0,0,0,0,0
0,0,0,0,0,38,0,5,5,0,0
0,0,0,0,0,38,0,5,5,0,0
0,0,0,0,0,38,0,0,0,0,0
0,0,0,0,0,38,0,0,0,0,0
0,0,0,0,0,37,0,0,0,0,0
0,0,0,0,28,29,27,0,0,0,0
0,0,0,0,0,0,0,0,0,0,0
endlayer

layer
0,0,0,0,0,0,0,0,0,0,0
0,0,0,0,0,36,0,0,0,0,0
0,0,0,0,0,0,0,0,0,0,0
0,0,0,0,0,0,0,0,0,0,0
0,0,0,0,0,0,0,0,0,0,0
0,0,0,0,0,0,0,0,0,0,0
0,0,0,0,0,0,0,39,39,0,0
0,0,0,0,0,0,0,39,39,0,0
0,0,0,0,0,0,0,0,0,0,0
0,0,0,0,0,0,0,0,0,0,0
0,0,0,0,0,0,0,0,0,0,0
0,0,0,0,0,37,0,0,0,0,0
0,0,0,0,0,0,0,0,0,0,0
endlayer

