# Large Cottage No. 1 10/21/2014
# Created by Ruins mod version 13.8 Ingame Parser
# authoring Player: Kujaku10
# Last Updated 9 Nov 2015
# Updated to MC 1.8: 5 Mar 2016
# Updated to MC 1.9: 18 Apr 2016
# Updated to MC 1.11.2: 11 Jan 2017
# Updated to MC 1.12: 21 Jun 2017

weight=1
embed_into_distance=2
acceptable_target_blocks=

unacceptable_target_blocks=flowing_lava,lava,cloud,Natura:Cloud,red_mushroom_block,brown_mushroom_block,planks,cobblestone,torch,stone_slab,double_stone_slab,oak_stairs,spruce_stairs,birch_stairs,dark_oak_stairs,acacia_stairs,jungle_stairs,slime_congealed,slime_dirt,slime_grass,fence,stone_brick,cobblestone_wall,command_block

dimensions=19,14,17
allowable_overhang=0
max_leveling=2
leveling_buffer=-1
preserve_water=0
preserve_lava=0
preserve_plants=1

rule1=0,100,preserveBlock
rule2=0,100,minecraft:grass-0
rule3=0,100,minecraft:stonebrick-0
rule4=0,100,minecraft:quartz_block-1
rule5=0,100,minecraft:sand-0
rule6=0,100,minecraft:red_flower-3
rule7=0,100,minecraft:leaves-14
rule8=0,100,minecraft:planks-2
rule9=0,100,minecraft:quartz_block-0
rule10=0,100,minecraft:quartz_stairs-2
rule11=2,100,minecraft:ladder-5

rule12=0,100,IInventory;minecraft:lit_furnace;minecraft:coal#6#1#1-3

rule13=0,100,IInventory;minecraft:chest;minecraft:stone#16#0#4-2,IInventory;minecraft:chest;minecraft:stone#16#2#6-2,IInventory;minecraft:chest;minecraft:stone#16#4#1-2,IInventory;minecraft:chest;minecraft:stone#16#6#3-2,IInventory;minecraft:chest;minecraft:brick_block#16#0#2-2,IInventory;minecraft:chest;minecraft:torch#16#0#9-2,IInventory;minecraft:chest;minecraft:clay#6#0#12-2,IInventory;minecraft:chest;minecraft:stonebrick#16#1#8-2,IInventory;minecraft:chest;minecraft:stonebrick#16#3#5-2,IInventory;minecraft:chest;minecraft:stonebrick#16#2#14-2


rule14=0,100,minecraft:crafting_table-0

# Flower Pot: Cactus
rule2=0,100,teBlock;minecraft:flower_pot;{Item:"minecraft:cactus",x:0,y:0,z:0,Data:0,id:flower_pot}-0

rule16=1,100,minecraft:birch_door-2
rule17=0,100,minecraft:cactus-0
rule18=0,100,minecraft:glass_pane-0
rule19=0,100,minecraft:birch_fence-0
rule20=1,100,minecraft:birch_door-8
rule21=0,100,minecraft:cactus-9
rule22=0,100,minecraft:cactus-5
rule23=0,100,minecraft:quartz_block-2
rule24=0,100,minecraft:birch_stairs-2
rule25=2,100,minecraft:torch-5
rule26=0,100,minecraft:quartz_stairs-5
rule27=0,100,minecraft:quartz_stairs-4
rule28=0,100,minecraft:quartz_stairs-7
rule29=0,100,minecraft:quartz_stairs-6
rule30=0,100,minecraft:quartz_block-3
rule31=0,100,minecraft:brick_block-0
rule32=0,100,minecraft:netherrack-0
rule33=0,100,minecraft:birch_stairs-3
rule34=0,100,minecraft:birch_stairs-1

rule35=0,100,IInventory;minecraft:chest;minecraft:iron_bars#16#0#3-4,IInventory;minecraft:chest;minecraft:stonebrick#16#0#11-4,IInventory;minecraft:chest;minecraft:hardened_clay#16#0#7-4,IInventory;minecraft:chest;minecraft:sandstone#16#0#10-4,IInventory;minecraft:chest;minecraft:red_sandstone#16#0#8-4,IInventory;minecraft:chest;minecraft:iron_ingot#1#0#4-4,IInventory;minecraft:chest;minecraft:gold_ingot#1#0#6-4,IInventory;minecraft:chest;minecraft:flint#16#0#9-4,IInventory;minecraft:chest;minecraft:leather#4#0#1-4

rule36=0,100,minecraft:bookshelf-0
rule37=0,100,minecraft:bed-9
rule38=0,100,minecraft:bed-1
rule39=0,100,minecraft:fire-15
rule40=0,100,minecraft:birch_stairs-0
rule41=0,100,minecraft:glowstone-0
rule42=0,100,minecraft:wooden_slab-2
rule43=0,100,minecraft:brick_stairs-0
rule44=0,100,minecraft:brick_stairs-2

# Bandit
rule45=0,100,CommandBlock:RUINSTRIGGER /summon Skeleton ~0 ~0 ~0 {HandItems:[{Count:1,id:wooden_sword,tag:{display:{Name:"Bandit Bludgeon"},ench:[{id:19,lvl:2},{id:21,lvl:2},{id:16,lvl:3}]}},{}],ArmorItems:[{Count:1,id:leather_boots},{Count:1,id:leather_leggings},{Count:1,id:leather_chestplate},{Count:1,id:skull,Damage:3,tag:{SkullOwner:MHF_Villager}}],CustomName:Bandit,HandDropChances:[1.0F,0.0F],ArmorDropChances:[0.5F,0.5F,0.5F,0.0F],Silent:1,PersistenceRequired:1,Health:15.0f}:@

rule46=0,100,minecraft:iron_bars-0



layer
2,2,2,2,2,2,2,2,2,2,2,2,2,2,2,1,1
2,2,2,2,2,2,2,2,2,2,2,2,2,2,2,2,1
2,2,3,3,3,3,3,3,3,3,3,2,2,2,2,2,2
2,2,3,3,3,3,3,3,3,3,3,3,3,3,3,2,2
2,2,3,3,3,3,3,3,3,3,3,3,3,3,2,2,2
2,2,3,3,4,4,3,4,4,3,4,4,3,3,2,2,2
2,2,3,3,4,4,3,4,4,3,4,4,3,3,2,2,2
2,2,3,3,3,3,3,3,3,3,3,3,3,3,2,2,2
2,2,3,3,3,3,3,3,3,3,3,3,3,3,3,2,2
2,2,3,3,3,3,3,3,3,3,3,2,2,2,2,2,2
2,5,3,3,3,3,3,3,3,3,3,5,2,2,2,1,1
2,2,3,3,3,3,3,3,3,3,3,2,2,1,1,1,1
2,2,3,3,3,3,3,3,3,3,3,2,2,1,1,1,1
2,2,2,2,2,2,2,2,2,2,2,2,1,1,1,1,1
endlayer

layer
2,2,2,2,2,2,2,2,2,2,2,2,2,2,2,1,1
2,2,2,2,2,2,2,2,2,2,2,2,2,2,2,2,1
2,2,3,3,3,3,3,3,3,3,3,2,2,2,2,2,2
2,2,3,3,3,3,3,3,3,3,3,3,3,3,3,2,2
2,2,3,3,3,3,3,3,3,3,3,3,3,3,2,2,2
2,2,3,3,4,4,3,4,4,3,4,4,3,3,2,2,2
2,2,3,3,4,4,3,4,4,3,4,4,3,3,2,2,2
2,2,3,3,3,3,3,3,3,3,3,3,3,3,2,2,2
2,2,3,3,3,3,3,3,3,3,3,3,3,3,3,2,2
2,2,3,3,3,3,3,3,3,3,3,2,2,2,2,2,2
2,5,3,3,3,3,3,3,3,3,3,5,2,2,2,1,1
2,2,3,3,3,3,3,3,3,3,3,2,2,1,1,1,1
2,2,3,3,3,3,3,3,3,3,3,2,2,1,1,1,1
2,2,2,2,2,2,2,2,2,2,2,2,1,1,1,1,1
endlayer


layer
0,0,0,0,0,0,0,0,0,0,0,0,0,0,0,0,0
0,0,6,6,7,7,7,7,7,6,6,0,0,0,0,0,0
0,0,8,9,9,9,9,9,9,9,8,0,0,0,0,0,0
0,6,9,11,0,0,0,0,0,0,0,9,9,9,9,10,0
0,7,9,15,0,0,0,0,0,0,0,0,12,9,0,0,0
0,7,9,13,0,0,0,45,0,0,0,0,0,9,0,0,0
0,7,9,14,0,0,0,0,0,0,0,0,0,9,0,0,0
0,7,9,15,0,0,0,0,0,0,0,0,15,9,0,0,0
0,6,9,0,0,0,16,0,0,0,0,9,9,9,9,10,0
0,0,8,9,9,8,0,8,9,9,8,0,0,0,0,0,0
0,17,0,0,0,0,0,0,0,0,0,17,0,0,0,0,0
0,0,0,0,0,0,0,0,0,0,0,0,0,0,0,0,0
0,0,4,0,0,0,0,0,0,0,4,0,0,0,0,0,0
0,0,0,0,0,0,0,0,0,0,0,0,0,0,0,0,0
endlayer

layer
0,0,0,0,0,0,0,0,0,0,0,0,0,0,0,0,0
0,0,0,0,0,0,0,0,0,0,0,0,0,0,0,0,0
0,0,8,9,8,18,18,18,8,9,8,0,0,0,0,0,0
0,0,18,11,0,0,0,0,0,0,19,9,9,9,10,0,0
0,0,18,0,0,0,0,0,0,0,0,0,0,9,0,0,0
0,0,9,0,0,0,0,0,0,0,0,0,19,9,0,0,0
0,0,9,0,0,0,0,0,0,0,0,0,19,9,0,0,0
0,0,18,0,0,0,0,0,0,0,0,0,0,9,0,0,0
0,0,18,0,0,0,20,0,0,0,19,9,9,9,10,0,0
0,0,8,18,9,8,0,8,9,18,8,0,0,0,0,0,0
0,22,0,0,0,19,0,19,0,0,0,21,0,0,0,0,0
0,0,0,0,0,0,0,0,0,0,0,0,0,0,0,0,0
0,0,23,0,0,0,0,0,0,0,23,0,0,0,0,0,0
0,0,0,0,0,0,0,0,0,0,0,0,0,0,0,0,0
endlayer

layer
0,0,0,0,0,0,0,0,0,0,0,0,0,0,0,0,0
0,0,0,0,0,0,0,0,0,0,0,0,0,0,0,0,0
0,0,8,9,8,18,18,18,8,9,8,0,0,0,24,0,0
0,0,18,11,0,0,0,0,0,0,25,9,9,9,24,0,0
0,0,18,0,0,0,0,0,0,0,0,0,0,9,24,0,0
0,0,9,0,0,0,0,0,0,0,0,0,25,9,24,0,0
0,0,9,0,0,0,0,0,0,0,0,0,25,9,24,0,0
0,0,18,0,0,0,0,0,0,0,0,0,0,9,24,0,0
0,0,18,0,0,0,0,0,0,0,25,9,9,9,24,0,0
0,0,8,18,9,8,8,8,9,18,8,0,0,0,24,0,0
0,0,0,0,0,25,0,25,0,0,0,0,0,0,0,0,0
0,0,0,0,0,0,0,0,0,0,0,0,0,0,0,0,0
0,0,23,0,0,0,0,0,0,0,23,0,0,0,0,0,0
0,0,0,0,0,0,0,0,0,0,0,0,0,0,0,0,0
endlayer

layer
0,0,0,0,0,0,0,0,0,0,0,0,0,0,0,0,0
0,0,0,0,0,0,0,0,0,0,0,0,0,0,0,0,0
0,0,8,9,8,18,18,18,8,9,8,0,0,24,0,0,0
0,0,18,11,0,0,0,0,0,0,0,9,9,24,0,0,0
0,0,18,0,0,0,0,0,0,0,0,0,9,24,0,0,0
0,0,9,0,0,0,0,0,0,0,0,0,9,24,0,0,0
0,0,9,0,0,0,0,0,0,0,0,0,9,24,0,0,0
0,0,18,0,0,0,0,0,0,0,0,0,9,24,0,0,0
0,0,18,0,0,0,0,0,0,0,0,9,9,24,0,0,0
0,0,8,9,9,9,9,9,9,9,8,0,0,24,0,0,0
0,0,26,0,0,0,0,0,0,0,26,0,0,0,0,0,0
0,0,27,0,0,0,0,0,0,0,27,0,0,0,0,0,0
0,0,9,29,0,0,0,0,0,28,9,0,0,0,0,0,0
0,0,0,0,0,0,0,0,0,0,0,0,0,0,0,0,0
endlayer

layer
0,0,0,0,0,0,0,0,0,0,0,0,0,0,0,0,0
0,0,0,0,0,0,0,0,0,0,0,0,0,0,0,0,0
0,0,8,8,8,8,8,8,8,8,8,0,24,0,0,0,0
0,0,8,11,4,30,4,30,4,30,4,9,24,0,0,0,0
0,0,8,30,4,30,4,30,4,30,4,9,24,0,0,0,0
0,0,8,30,4,30,4,30,4,30,4,9,31,0,0,0,0
0,0,8,30,4,30,4,30,4,30,4,9,31,0,0,0,0
0,0,8,30,4,30,4,30,4,30,4,9,31,0,0,0,0
0,0,8,30,4,30,4,30,4,30,4,9,24,0,0,0,0
0,0,8,9,9,9,9,9,9,9,8,0,24,0,0,0,0
0,0,8,8,8,8,8,8,8,8,8,0,0,0,0,0,0
0,0,8,8,8,8,8,8,8,8,8,0,0,0,0,0,0
0,0,8,8,8,8,8,8,8,8,8,0,0,0,0,0,0
0,0,0,0,0,0,0,0,0,0,0,0,0,0,0,0,0
endlayer

layer
0,0,0,0,0,0,0,0,0,0,0,0,0,0,0,0,0
0,0,0,0,0,0,0,0,0,0,0,0,0,0,0,0,0
0,0,9,9,9,9,9,9,9,9,9,24,0,0,0,0,0
0,0,9,11,8,8,8,8,9,9,9,24,0,0,0,0,0
0,0,9,8,8,8,8,8,9,9,9,24,0,0,0,0,0
0,0,9,8,8,8,8,9,9,9,9,31,31,0,0,0,0
0,0,9,8,8,8,8,9,9,9,9,32,31,0,0,0,0
0,0,9,8,8,8,8,9,9,9,9,31,31,0,0,0,0
0,0,9,8,8,8,8,8,9,9,9,24,0,0,0,0,0
0,0,9,24,34,34,34,34,34,33,9,24,0,0,0,0,0
0,0,9,0,0,0,0,0,0,0,9,0,0,0,0,0,0
0,0,9,0,0,35,0,35,0,0,9,0,0,0,0,0,0
0,0,9,8,9,9,9,9,9,8,9,0,0,0,0,0,0
0,0,0,0,0,0,0,0,0,0,0,0,0,0,0,0,0
endlayer

layer
0,0,0,0,0,0,0,0,0,0,0,0,0,0,0,0,0
0,0,0,0,0,0,0,0,0,0,0,0,0,0,0,0,0
0,0,9,9,18,9,9,9,18,9,9,0,0,0,0,0,0
0,0,9,0,0,36,37,36,0,0,9,0,0,0,0,0,0
0,0,9,0,0,0,38,0,0,0,9,0,0,0,0,0,0
0,0,8,0,0,0,0,0,0,0,31,31,31,0,0,0,0
0,0,9,0,0,0,0,0,0,0,46,39,31,0,0,0,0
0,0,9,0,0,0,0,45,0,0,31,31,31,0,0,0,0
0,0,9,0,0,0,0,0,0,0,9,0,0,0,0,0,0
0,0,8,0,0,0,45,0,0,0,9,0,0,0,0,0,0
0,0,9,0,0,0,0,0,0,0,9,0,0,0,0,0,0
0,0,9,19,0,0,0,0,0,19,9,0,0,0,0,0,0
0,0,9,8,18,18,18,18,18,8,9,0,0,0,0,0,0
0,0,0,0,0,0,0,0,0,0,0,0,0,0,0,0,0
endlayer

layer
0,0,0,0,0,0,0,0,0,0,0,0,0,0,0,0,0
0,0,0,0,0,0,0,0,0,0,0,0,0,0,0,0,0
0,0,9,9,18,9,9,9,18,9,9,0,0,0,0,0,0
0,0,9,0,0,36,0,36,0,0,9,0,0,0,0,0,0
0,0,9,0,0,0,0,0,0,0,9,0,0,0,0,0,0
0,0,8,0,0,0,0,0,0,0,31,31,31,0,0,0,0
0,0,18,0,0,0,0,0,0,0,46,0,31,0,0,0,0
0,0,18,0,0,0,0,0,0,0,31,31,31,0,0,0,0
0,0,18,0,0,0,0,0,0,0,9,0,0,0,0,0,0
0,0,8,0,0,0,0,0,0,0,9,0,0,0,0,0,0
0,0,9,0,0,0,0,0,0,0,9,0,0,0,0,0,0
0,0,9,25,0,0,0,0,0,25,9,0,0,0,0,0,0
0,0,9,8,18,18,18,18,18,8,9,0,0,0,0,0,0
0,0,0,0,0,0,0,0,0,0,0,0,0,0,0,0,0
endlayer

layer
0,0,0,0,0,0,0,0,0,0,0,0,0,0,0,0,0
0,40,40,40,0,0,40,0,0,0,40,40,0,0,0,0,0
0,0,9,9,18,9,9,9,18,9,9,0,0,0,0,0,0
0,0,9,0,0,36,41,36,0,0,9,0,0,0,0,0,0
0,0,9,0,0,0,0,0,0,0,9,0,0,0,0,0,0
0,0,8,19,0,0,0,0,0,0,31,31,31,0,0,0,0
0,0,18,0,0,0,0,0,0,0,31,0,31,0,0,0,0
0,0,18,0,0,0,0,0,0,0,31,31,31,0,0,0,0
0,0,18,0,0,0,0,0,0,0,9,0,0,0,0,0,0
0,0,8,19,0,0,0,0,0,0,9,0,0,0,0,0,0
0,0,9,0,0,0,0,0,0,0,9,0,0,0,0,0,0
0,0,9,0,0,0,0,0,0,0,9,0,0,0,0,0,0
0,0,9,9,9,9,9,9,9,9,9,0,0,0,0,0,0
0,34,34,34,34,34,34,34,34,34,34,34,0,0,0,0,0
endlayer

layer
0,0,0,0,0,0,0,0,0,0,0,0,0,0,0,0,0
0,0,0,33,0,24,0,33,0,24,0,0,0,0,0,0,0
0,40,40,33,9,24,40,33,9,24,40,40,0,0,0,0,0
0,0,9,8,8,8,8,8,8,8,9,0,0,0,0,0,0
0,0,9,0,0,0,0,0,0,0,9,0,0,0,0,0,0
0,0,8,25,0,0,0,0,0,28,9,31,31,0,0,0,0
0,0,18,0,0,0,0,0,0,28,9,0,31,0,0,0,0
0,0,18,0,0,0,0,0,0,28,9,31,31,0,0,0,0
0,0,18,0,0,0,0,0,0,0,9,0,0,0,0,0,0
0,0,8,25,0,0,0,0,0,0,9,0,0,0,0,0,0
0,0,9,0,0,0,0,0,0,0,9,0,0,0,0,0,0
0,0,9,8,8,8,8,8,8,8,9,0,0,0,0,0,0
0,34,34,34,34,34,34,34,34,34,34,34,0,0,0,0,0
0,0,0,0,0,0,0,0,0,0,0,0,0,0,0,0,0
endlayer

layer
0,0,0,0,0,0,0,0,0,0,0,0,0,0,0,0,0
0,0,0,0,42,0,0,0,42,0,0,0,0,0,0,0,0
0,0,0,0,42,0,0,0,42,0,0,0,0,0,0,0,0
0,40,40,40,40,40,40,40,40,40,40,40,0,0,0,0,0
0,0,9,8,8,8,8,8,8,8,9,0,0,0,0,0,0
0,0,9,0,0,0,0,0,0,0,9,31,31,0,0,0,0
0,0,9,0,0,0,0,0,0,0,9,31,31,0,0,0,0
0,0,9,0,0,0,0,0,0,0,9,31,31,0,0,0,0
0,0,9,0,0,0,0,0,0,0,9,0,0,0,0,0,0
0,0,9,0,0,0,0,0,0,0,9,0,0,0,0,0,0
0,0,9,8,8,8,8,8,8,8,9,0,0,0,0,0,0
0,34,34,34,34,34,34,34,34,34,34,34,0,0,0,0,0
0,0,0,0,0,0,0,0,0,0,0,0,0,0,0,0,0
0,0,0,0,0,0,0,0,0,0,0,0,0,0,0,0,0
endlayer

layer
0,0,0,0,0,0,0,0,0,0,0,0,0,0,0,0,0
0,0,0,0,0,0,0,0,0,0,0,0,0,0,0,0,0
0,0,0,0,0,0,0,0,0,0,0,0,0,0,0,0,0
0,0,0,0,0,0,0,0,0,0,0,0,0,0,0,0,0
0,40,40,40,40,40,40,40,40,40,40,40,0,0,0,0,0
0,0,9,8,8,8,8,8,8,8,9,31,31,0,0,0,0
0,0,9,0,0,0,0,0,0,0,9,31,31,0,0,0,0
0,0,18,0,0,0,0,0,0,0,9,31,31,0,0,0,0
0,0,9,0,0,0,0,0,0,0,9,0,0,0,0,0,0
0,0,9,8,8,8,8,8,8,8,9,0,0,0,0,0,0
0,34,34,34,34,34,34,34,34,34,34,34,0,0,0,0,0
0,0,0,0,0,0,0,0,0,0,0,0,0,0,0,0,0
0,0,0,0,0,0,0,0,0,0,0,0,0,0,0,0,0
0,0,0,0,0,0,0,0,0,0,0,0,0,0,0,0,0
endlayer

layer
0,0,0,0,0,0,0,0,0,0,0,0,0,0,0,0,0
0,0,0,0,0,0,0,0,0,0,0,0,0,0,0,0,0
0,0,0,0,0,0,0,0,0,0,0,0,0,0,0,0,0
0,0,0,0,0,0,0,0,0,0,0,0,0,0,0,0,0
0,0,0,0,0,0,0,0,0,0,0,0,0,0,0,0,0
0,40,40,40,40,40,40,40,40,40,40,43,43,0,0,0,0
0,0,9,8,8,8,8,8,8,8,9,31,31,0,0,0,0
0,0,9,0,0,0,0,0,0,0,9,31,31,0,0,0,0
0,0,9,8,8,8,8,8,8,8,9,0,0,0,0,0,0
0,34,34,34,34,34,34,34,34,34,34,34,0,0,0,0,0
0,0,0,0,0,0,0,0,0,0,0,0,0,0,0,0,0
0,0,0,0,0,0,0,0,0,0,0,0,0,0,0,0,0
0,0,0,0,0,0,0,0,0,0,0,0,0,0,0,0,0
0,0,0,0,0,0,0,0,0,0,0,0,0,0,0,0,0
endlayer

layer
0,0,0,0,0,0,0,0,0,0,0,0,0,0,0,0,0
0,0,0,0,0,0,0,0,0,0,0,0,0,0,0,0,0
0,0,0,0,0,0,0,0,0,0,0,0,0,0,0,0,0
0,0,0,0,0,0,0,0,0,0,0,0,0,0,0,0,0
0,0,0,0,0,0,0,0,0,0,0,0,0,0,0,0,0
0,0,0,0,0,0,0,0,0,0,0,0,0,0,0,0,0
0,40,40,40,40,40,40,40,40,40,40,31,31,0,0,0,0
0,0,9,8,8,8,8,8,8,8,9,31,31,0,0,0,0
0,34,34,34,34,34,34,34,34,34,34,34,0,0,0,0,0
0,0,0,0,0,0,0,0,0,0,0,0,0,0,0,0,0
0,0,0,0,0,0,0,0,0,0,0,0,0,0,0,0,0
0,0,0,0,0,0,0,0,0,0,0,0,0,0,0,0,0
0,0,0,0,0,0,0,0,0,0,0,0,0,0,0,0,0
0,0,0,0,0,0,0,0,0,0,0,0,0,0,0,0,0
endlayer

layer
0,0,0,0,0,0,0,0,0,0,0,0,0,0,0,0,0
0,0,0,0,0,0,0,0,0,0,0,0,0,0,0,0,0
0,0,0,0,0,0,0,0,0,0,0,0,0,0,0,0,0
0,0,0,0,0,0,0,0,0,0,0,0,0,0,0,0,0
0,0,0,0,0,0,0,0,0,0,0,0,0,0,0,0,0
0,0,0,0,0,0,0,0,0,0,0,0,0,0,0,0,0
0,0,0,0,0,0,0,0,0,0,0,31,44,0,0,0,0
0,42,42,42,42,42,42,42,42,42,42,31,44,0,0,0,0
0,0,0,0,0,0,0,0,0,0,0,0,0,0,0,0,0
0,0,0,0,0,0,0,0,0,0,0,0,0,0,0,0,0
0,0,0,0,0,0,0,0,0,0,0,0,0,0,0,0,0
0,0,0,0,0,0,0,0,0,0,0,0,0,0,0,0,0
0,0,0,0,0,0,0,0,0,0,0,0,0,0,0,0,0
0,0,0,0,0,0,0,0,0,0,0,0,0,0,0,0,0
endlayer

layer
0,0,0,0,0,0,0,0,0,0,0,0,0,0,0,0,0
0,0,0,0,0,0,0,0,0,0,0,0,0,0,0,0,0
0,0,0,0,0,0,0,0,0,0,0,0,0,0,0,0,0
0,0,0,0,0,0,0,0,0,0,0,0,0,0,0,0,0
0,0,0,0,0,0,0,0,0,0,0,0,0,0,0,0,0
0,0,0,0,0,0,0,0,0,0,0,0,0,0,0,0,0
0,0,0,0,0,0,0,0,0,0,0,31,0,0,0,0,0
0,0,0,0,0,0,0,0,0,0,0,31,0,0,0,0,0
0,0,0,0,0,0,0,0,0,0,0,0,0,0,0,0,0
0,0,0,0,0,0,0,0,0,0,0,0,0,0,0,0,0
0,0,0,0,0,0,0,0,0,0,0,0,0,0,0,0,0
0,0,0,0,0,0,0,0,0,0,0,0,0,0,0,0,0
0,0,0,0,0,0,0,0,0,0,0,0,0,0,0,0,0
0,0,0,0,0,0,0,0,0,0,0,0,0,0,0,0,0
endlayer

layer
0,0,0,0,0,0,0,0,0,0,0,0,0,0,0,0,0
0,0,0,0,0,0,0,0,0,0,0,0,0,0,0,0,0
0,0,0,0,0,0,0,0,0,0,0,0,0,0,0,0,0
0,0,0,0,0,0,0,0,0,0,0,0,0,0,0,0,0
0,0,0,0,0,0,0,0,0,0,0,0,0,0,0,0,0
0,0,0,0,0,0,0,0,0,0,0,0,0,0,0,0,0
0,0,0,0,0,0,0,0,0,0,0,3,0,0,0,0,0
0,0,0,0,0,0,0,0,0,0,0,3,0,0,0,0,0
0,0,0,0,0,0,0,0,0,0,0,0,0,0,0,0,0
0,0,0,0,0,0,0,0,0,0,0,0,0,0,0,0,0
0,0,0,0,0,0,0,0,0,0,0,0,0,0,0,0,0
0,0,0,0,0,0,0,0,0,0,0,0,0,0,0,0,0
0,0,0,0,0,0,0,0,0,0,0,0,0,0,0,0,0
0,0,0,0,0,0,0,0,0,0,0,0,0,0,0,0,0
endlayer

