# Stackable Store No. 2 10/26/2014
# Created by Ruins mod version 13.8 Ingame Parser
# authoring Player: Kujaku10
# Updated to MC 1.8: 21 Mar 2016
# Updated to MC 1.9: 18 Apr 2016
# Updated to MC 1.11: 11 Jan 2017
# Updated to MC 1.12: 22 Jun 2017

weight=1
embed_into_distance=5

acceptable_target_blocks=
unacceptable_target_blocks=flowing_lava,lava,cloud,Natura:Cloud,red_mushroom_block,brown_mushroom_block,planks,cobblestone,torch,stone_slab,double_stone_slab,oak_stairs,spruce_stairs,birch_stairs,dark_oak_stairs,acacia_stairs,jungle_stairs,slime_congealed,slime_dirt,slime_grass,fence,stone_brick,cobblestone_wall,command_block

dimensions=15,9,13
allowable_overhang=0
max_leveling=5
leveling_buffer=-1
preserve_water=0
preserve_lava=0
preserve_plants=1

rule1=0,100,preserveBlock
rule2=0,100,minecraft:stonebrick-0
rule3=0,100,minecraft:sandstone-0
rule4=0,100,minecraft:grass-0
rule5=1,100,minecraft:leaves-14
rule6=0,100,minecraft:planks-0
rule7=0,100,minecraft:wooden_slab-0
rule8=1,100,minecraft:leaves-14
rule9=0,100,minecraft:fence-0
rule10=0,100,minecraft:stone_brick_stairs-0
rule11=0,100,minecraft:planks-1
rule12=0,100,minecraft:spruce_stairs-0
rule13=0,100,minecraft:stone_brick_stairs-3
rule14=0,100,minecraft:spruce_stairs-2
rule15=0,100,minecraft:spruce_stairs-1
rule16=0,100,minecraft:stone_brick_stairs-1
rule17=0,100,minecraft:quartz_block-0
rule18=0,100,minecraft:glass_pane-0
rule19=1,100,minecraft:wooden_door-3
rule20=2,100,minecraft:torch-1
rule21=1,100,minecraft:wooden_door-8
rule22=2,100,minecraft:torch-2
rule23=0,100,minecraft:oak_stairs-7
rule24=0,100,minecraft:dark_oak_stairs-2
rule25=0,100,minecraft:dark_oak_stairs-3
rule26=0,100,minecraft:dark_oak_stairs-0
rule27=0,100,minecraft:planks-5
rule28=0,100,minecraft:dark_oak_stairs-1
rule29=0,100,minecraft:wooden_slab-5
rule30=0,100,minecraft:fence_gate-2
rule31=0,100,minecraft:ladder-5

rule32=0,100,IInventory;minecraft:chest;minecraft:log2#8#1#0+minecraft:log#8#2#2+minecraft:log#8#0#8+minecraft:log#8#3#15+minecraft:log2#8#0#19+minecraft:log#8#1#22-3

# Highwayman (Bandit Archer)
rule33=0,100,CommandBlock:RUINSTRIGGER /summon Skeleton ~0 ~0 ~0 {HandItems:[{Count:1,id:bow,tag:{display:{Name:"Bandit Bow"},ench:[{id:48,lvl:3},{id:49,lvl:2}]}},{Count:8,id:tipped_arrow,tag:{Potion:"minecraft:strong_harming"}}],ArmorItems:[{Count:1,id:leather_boots},{Count:1,id:leather_leggings},{Count:1,id:leather_chestplate},{Count:1,id:skull,Damage:3,tag:{SkullOwner:MHF_Villager}}],CustomName:Highwayman,HandDropChances:[1.0F,0.0F],ArmorDropChances:[0.5F,0.5F,0.5F,0.0F],Silent:1,PersistenceRequired:1,Health:15.0f}:@

# Bandit
rule34=0,100,CommandBlock:RUINSTRIGGER /summon Skeleton ~0 ~0 ~0 {HandItems:[{Count:1,id:wooden_sword,tag:{display:{Name:"Bandit Bludgeon"},ench:[{id:19,lvl:2},{id:21,lvl:2},{id:16,lvl:3}]}},{}],ArmorItems:[{Count:1,id:leather_boots},{Count:1,id:leather_leggings},{Count:1,id:leather_chestplate},{Count:1,id:skull,Damage:3,tag:{SkullOwner:MHF_Villager}}],CustomName:Bandit,HandDropChances:[1.0F,0.0F],ArmorDropChances:[0.5F,0.5F,0.5F,0.0F],Silent:1,PersistenceRequired:1,Health:15.0f}:@

rule35=0,100,CommandBlock:RUINSTRIGGER /summon Villager ~0 ~0 ~0:@

# -5
layer
4,4,4,2,2,2,3,2,2,2,2,2,4
4,4,4,2,2,2,2,2,2,2,2,2,4
4,4,4,2,2,2,2,2,2,2,2,2,4
4,4,4,2,2,2,2,2,2,2,2,2,4
4,4,4,2,2,2,2,2,2,2,2,2,4
4,4,4,2,2,2,2,2,2,2,2,2,4
4,4,4,2,2,2,2,2,2,2,2,2,4
4,4,4,2,2,2,2,2,2,2,2,2,4
4,4,4,2,2,2,3,2,2,2,2,2,4
endlayer

# -4
layer
4,4,4,2,2,2,3,2,2,2,2,2,4
4,4,4,2,0,0,0,31,0,0,0,2,4
4,4,4,2,0,0,0,0,0,0,32,2,4
4,4,4,2,0,0,0,0,0,0,32,2,4
4,4,4,2,33,0,0,34,0,0,0,2,4
4,4,4,2,0,0,0,0,0,0,32,2,4
4,4,4,2,0,0,0,0,0,0,32,2,4
4,4,4,2,0,0,0,33,0,0,0,2,4
4,4,4,2,2,2,3,2,2,2,2,2,4
endlayer

# -3
layer
4,4,4,2,2,2,3,2,2,2,2,2,4
4,4,4,2,0,20,0,31,0,20,0,2,4
4,4,4,2,0,0,0,0,0,0,0,2,4
4,4,4,2,0,0,0,0,0,0,0,2,4
4,4,4,2,0,0,0,0,0,0,0,2,4
4,4,4,2,0,0,0,0,0,0,0,2,4
4,4,4,2,0,0,0,0,0,0,0,2,4
4,4,4,2,0,22,0,0,0,22,0,2,4
4,4,4,2,2,2,3,2,2,2,2,2,4
endlayer

# -2
layer
4,4,4,2,2,2,3,2,2,2,2,2,4
4,4,4,2,0,0,0,31,0,0,0,2,4
4,4,4,2,0,0,0,0,0,0,0,2,4
4,4,4,2,0,0,0,0,0,0,0,2,4
4,4,4,2,0,0,0,0,0,0,0,2,4
4,4,4,2,0,0,0,0,0,0,0,2,4
4,4,4,2,0,0,0,0,0,0,0,2,4
4,4,4,2,0,0,0,0,0,0,0,2,4
4,4,4,2,2,2,3,2,2,2,2,2,4
endlayer


# -1
layer
1,1,1,2,2,2,3,2,2,2,2,2,1
1,4,4,2,2,2,2,31,2,2,2,2,1
1,4,4,2,2,2,2,2,2,2,2,2,1
1,4,4,2,2,2,2,2,2,2,2,2,1
1,4,4,2,2,2,2,2,2,2,2,2,1
1,4,4,2,2,2,2,2,2,2,2,2,1
1,4,4,2,2,2,2,2,2,2,2,2,1
1,4,4,2,2,2,2,2,2,2,2,2,1
1,1,1,2,2,2,3,2,2,2,2,2,1
endlayer

layer
1,1,5,2,2,2,2,2,2,2,2,2,5
1,9,8,2,7,7,7,31,7,7,6,2,5
0,10,10,2,0,0,0,0,30,0,7,2,8
0,13,2,2,12,0,0,0,11,35,7,2,8
0,13,2,2,14,0,33,0,11,0,7,2,8
0,13,2,2,15,0,34,0,11,35,7,2,8
0,16,16,2,0,0,0,0,11,0,7,2,8
1,9,8,2,7,7,7,0,11,0,7,2,8
1,1,8,2,2,2,2,2,2,2,2,2,8
endlayer

layer
1,0,0,11,17,17,17,6,17,17,17,11,0
0,9,0,18,7,7,7,31,7,7,6,17,0
0,0,0,18,0,0,0,0,0,0,7,17,0
0,0,0,17,0,0,0,0,0,0,7,17,0
0,0,0,19,0,0,0,0,0,0,7,17,0
0,0,0,17,0,0,0,0,0,0,7,17,0
0,0,0,18,0,0,0,0,0,0,7,17,0
0,9,0,18,7,7,7,0,0,0,7,17,0
1,0,0,11,17,17,17,6,17,17,17,11,0
endlayer

layer
0,0,0,11,17,17,17,6,17,17,17,11,0
0,9,0,18,7,7,7,20,9,7,6,17,0
0,0,0,18,0,0,0,0,9,0,7,17,0
0,0,0,17,0,0,0,0,9,0,7,17,0
0,0,0,21,0,0,0,0,9,0,7,17,0
0,0,0,17,0,0,0,0,9,0,7,17,0
0,0,0,18,0,0,0,0,9,0,7,17,0
0,9,0,18,7,7,7,22,9,0,7,17,0
0,0,0,11,17,17,17,6,17,17,17,11,0
endlayer

layer
0,0,0,11,11,11,11,11,11,11,11,11,0
0,9,9,11,0,0,0,0,0,0,0,11,0
0,0,0,11,0,0,0,0,0,0,0,11,0
0,0,0,11,0,0,0,0,0,0,0,11,0
0,0,0,11,0,0,0,0,0,0,0,11,0
0,0,0,11,0,0,0,0,0,0,0,11,0
0,0,0,11,0,0,0,0,0,0,0,11,0
0,9,9,11,0,0,0,0,0,0,0,11,0
0,0,0,11,11,11,11,11,11,11,11,11,0
endlayer

layer
0,23,6,17,17,6,17,17,6,17,17,6,0
0,23,6,0,0,0,0,0,0,0,0,17,0
0,23,6,0,0,0,0,0,0,0,0,18,0
0,23,6,0,0,0,0,0,0,0,0,18,0
0,23,6,0,0,0,0,0,0,0,0,17,0
0,23,6,0,0,0,0,0,0,0,0,18,0
0,23,6,0,0,0,0,0,0,0,0,18,0
0,23,6,0,0,0,0,0,0,0,0,17,0
0,23,6,17,17,6,17,17,6,17,17,6,0
endlayer

layer
0,9,11,17,17,6,17,17,6,17,17,11,0
0,9,17,20,0,0,0,0,0,0,20,17,0
0,9,18,0,0,0,0,0,0,0,0,18,0
0,9,18,0,0,0,0,0,0,0,0,18,0
0,9,17,0,0,0,0,0,0,0,0,17,0
0,9,18,0,0,0,0,0,0,0,0,18,0
0,9,18,0,0,0,0,0,0,0,0,18,0
0,9,17,22,0,0,0,0,0,0,22,17,0
0,9,11,17,17,6,17,17,6,17,17,11,0
endlayer

layer
0,9,11,11,11,11,11,11,11,11,11,11,24
0,0,17,0,0,0,0,0,0,0,0,11,24
0,0,18,0,0,0,0,0,0,0,0,11,24
0,0,18,0,0,0,0,0,0,0,0,11,24
0,0,17,0,0,0,0,0,0,0,0,11,24
0,0,18,0,0,0,0,0,0,0,0,11,24
0,0,18,0,0,0,0,0,0,0,0,11,24
0,0,17,0,0,0,0,0,0,0,0,11,24
0,9,11,11,11,11,11,11,11,11,11,11,24
endlayer

layer
0,25,6,17,17,17,17,17,17,17,6,24,0
0,0,6,0,0,0,0,0,0,0,6,24,0
0,0,18,0,0,0,0,0,0,0,6,24,0
0,0,18,0,0,0,0,0,0,0,6,24,0
0,0,6,0,0,0,0,0,0,0,6,24,0
0,0,18,0,0,0,0,0,0,0,6,24,0
0,0,18,0,0,0,0,0,0,0,6,24,0
0,0,6,0,0,0,0,0,0,0,6,24,0
0,25,6,17,17,17,17,17,17,17,6,24,0
endlayer

layer
0,0,25,11,11,11,11,11,11,11,24,0,0
0,26,26,11,11,11,11,11,11,11,24,0,0
0,0,6,11,11,11,11,11,11,11,24,0,0
0,0,6,11,11,11,11,11,11,11,24,0,0
0,25,27,11,11,11,11,11,11,11,24,0,0
0,0,6,11,11,11,11,11,11,11,24,0,0
0,0,6,11,11,11,11,11,11,11,24,0,0
0,28,28,11,11,11,11,11,11,11,24,0,0
0,0,25,11,11,11,11,11,11,11,24,0,0
endlayer

layer
0,0,0,29,29,29,29,29,29,29,0,0,0
0,0,0,29,29,29,29,29,29,29,0,0,0
0,29,29,29,29,29,29,29,29,29,0,0,0
0,29,29,29,29,29,29,29,29,29,0,0,0
0,0,29,29,29,29,29,29,29,29,0,0,0
0,29,29,29,29,29,29,29,29,29,0,0,0
0,29,29,29,29,29,29,29,29,29,0,0,0
0,0,0,29,29,29,29,29,29,29,0,0,0
0,0,0,29,29,29,29,29,29,29,0,0,0
endlayer

