# MC 1.7.10; originally made using Direwolf20 ModPack
# 16 Dec 2014
# Created by Ruins mod version 14.4 Ingame Parser
# authoring Player: Kujaku10

# Converted to "Vanilla" Minecraft blocks & MC 1.11: 15 Jan 2017
# Updated for MC 1.12: 22 Jun 2017
# Last Updated: 8 Dec 2018

# Note: Rule44 is an example of how to place paintings on walls
# in Ruins structures.

# Facing: 0 is south, 1 is west, 2 is north, and 3 is east 
# If the painting is not properly positioned with the correct 
# facing to be up against a wall, it will spawn into existence
# floating in mid-air for a moment, but then "pop" after a second
# or two.

# Motive: This is the simple name of the painting, and is caps-
# sensitive. If Motive is not specified, or if an invalid name is
# specified, it defaults to the first painting design, "Kebab" 
# (1x1).

weight=1
embed_into_distance=4
acceptable_target_blocks=

# "preventRotation" is chosen to ensure that paintings will align
# to walls as intended.
preventRotation=1

unacceptable_target_blocks=flowing_lava,lava,cloud,Natura:Cloud,red_mushroom_block,brown_mushroom_block,planks,cobblestone,torch,stone_slab,double_stone_slab,oak_stairs,spruce_stairs,birch_stairs,dark_oak_stairs,acacia_stairs,jungle_stairs,slime_congealed,slime_dirt,slime_grass,fence,stone_brick,cobblestone_wall,command_block

dimensions=16,15,15
allowable_overhang=0
max_leveling=4
leveling_buffer=-1
preserve_water=0
preserve_lava=0
preserve_plants=1

rule1=0,100,minecraft:grass-0
rule2=0,100,minecraft:dirt-0
rule3=0,100,minecraft:dirt-1
rule4=0,100,minecraft:cobblestone-0
rule5=0,100,minecraft:log-1
rule6=0,100,preserveBlock
rule7=0,100,minecraft:fence-0

rule8=0,100,CommandBlock:RUINSTRIGGER /summon Skeleton ~0 ~0 ~0 {HandItems:[{Count:1,id:bow,tag:{display:{Name:"Bandit Bow"},ench:[{id:48,lvl:3},{id:49,lvl:2}]}},{Count:8,id:tipped_arrow,tag:{Potion:"minecraft:strong_harming"}}],ArmorItems:[{Count:1,id:leather_boots},{Count:1,id:leather_leggings},{Count:1,id:leather_chestplate},{Count:1,id:skull,Damage:3,tag:{SkullOwner:MHF_Villager}}],CustomName:Highwayman,HandDropChances:[1.0F,0.0F],ArmorDropChances:[0.5F,0.5F,0.5F,0.0F],Silent:1,PersistenceRequired:1,Health:15.0f}:@,CommandBlock:RUINSTRIGGER /summon Skeleton ~0 ~0 ~0 {HandItems:[{Count:1,id:wooden_sword,tag:{display:{Name:"Bandit Bludgeon"},ench:[{id:19,lvl:2},{id:21,lvl:2},{id:16,lvl:3}]}},{}],ArmorItems:[{Count:1,id:leather_boots},{Count:1,id:leather_leggings},{Count:1,id:leather_chestplate},{Count:1,id:skull,Damage:3,tag:{SkullOwner:MHF_Villager}}],CustomName:Bandit,HandDropChances:[1.0F,0.0F],ArmorDropChances:[0.5F,0.5F,0.5F,0.0F],Silent:1,PersistenceRequired:1,Health:15.0f}:@

rule9=0,100,ChestGenHook:chests/simple_dungeon:3-2
rule10=0,100,minecraft:ladder-3
rule11=1,100,minecraft:torch-5
rule12=0,100,minecraft:planks-0
rule13=0,100,minecraft:planks-1
rule14=0,100,minecraft:planks-3
rule15=0,100,minecraft:planks-2
rule16=0,100,minecraft:oak_stairs-0
rule17=0,100,minecraft:oak_stairs-2
rule18=0,100,minecraft:oak_stairs-1
rule19=0,100,minecraft:stonebrick-0
rule20=0,100,minecraft:jungle_stairs-1
rule21=0,100,minecraft:jungle_stairs-3
rule22=0,100,minecraft:jungle_stairs-6
rule23=0,100,minecraft:wooden_door-1
rule24=0,100,minecraft:trapdoor-1
rule25=0,100,minecraft:jungle_stairs-0
rule26=0,100,minecraft:trapdoor-6
rule27=0,100,minecraft:glass_pane-0
rule28=0,100,teBlock;minecraft:flower_pot;{Item:"minecraft:sapling",x:0,y:0,z:0,Data:3,id:"minecraft:flower_pot"}-0
rule29=0,100,minecraft:quartz_block-1
rule30=0,100,minecraft:wooden_door-8
rule31=0,100,teBlock;minecraft:flower_pot;{Item:"minecraft:sapling",x:0,y:0,z:0,Data:3,id:"minecraft:flower_pot"}-0
rule32=0,100,minecraft:trapdoor-7
rule33=0,100,minecraft:birch_stairs-7
rule34=0,100,minecraft:birch_stairs-6
rule35=0,100,minecraft:spruce_stairs-2
rule36=0,100,minecraft:spruce_stairs-3
rule37=0,100,IInventory;minecraft:chest;minecraft:red_mushroom#8#0#2+minecraft:sapling#8#1#9+minecraft:sapling#8#2#16+minecraft:sapling#8#4#23-3
rule38=0,100,IInventory;minecraft:chest;minecraft:sapling#8#0#2+minecraft:sapling#8#3#16+minecraft:brown_mushroom#8#0#19+minecraft:sapling#8#5#22-3
rule39=2,100,minecraft:torch-1
rule40=0,100,minecraft:spruce_stairs-0
rule41=0,100,minecraft:spruce_stairs-1
rule42=2,100,minecraft:torch-2
rule43=0,100,minecraft:wooden_slab-1

# Place painting on wall:
rule44=0,100,CommandBlock:RUINSTRIGGER /summon painting ~ ~1 ~ {Facing:2,Motive:Match}:@,CommandBlock:RUINSTRIGGER /summon painting ~ ~1 ~ {Facing:2,Motive:Bust}:@,CommandBlock:RUINSTRIGGER /summon painting ~ ~1 ~ {Facing:2,Motive:Void}:@

layer
1,2,2,2,2,2,2,2,2,2,2,2,2,2,1
2,4,4,4,4,4,4,4,4,4,4,4,3,2,2
2,4,5,5,5,5,5,5,5,5,5,4,3,2,2
2,4,5,5,5,5,5,5,5,5,5,4,3,2,2
2,4,5,5,5,5,5,5,5,5,5,4,2,2,2
2,4,5,5,5,5,5,5,5,5,5,4,2,2,2
2,4,5,5,5,5,5,5,5,5,5,4,2,2,2
2,4,5,5,5,5,5,5,5,5,5,4,2,2,2
2,4,5,5,5,5,5,5,5,5,5,4,2,2,2
2,4,5,5,5,5,5,5,5,5,5,4,2,2,2
2,4,5,5,5,5,5,5,5,5,5,4,2,2,2
2,4,5,5,5,5,5,5,5,5,5,4,2,2,2
2,4,5,5,5,5,5,5,5,5,5,4,2,2,2
2,4,4,4,4,4,4,4,4,4,4,4,2,2,2
1,2,2,2,2,2,2,2,2,2,2,2,2,2,1
endlayer

layer
6,1,2,2,2,2,2,2,2,2,2,2,2,1,6
1,4,4,4,4,4,4,4,4,4,4,4,3,2,1
2,4,7,0,0,0,7,0,0,0,7,4,3,2,2
2,4,0,0,0,0,0,0,0,0,0,4,3,2,2
2,4,0,0,0,0,0,0,0,0,0,4,2,2,2
2,4,0,0,0,0,0,0,0,0,0,4,2,2,2
2,4,9,0,0,0,8,0,0,0,0,4,2,2,2
2,4,7,0,0,8,7,8,0,0,7,4,2,2,2
2,4,9,0,0,0,8,0,0,0,10,4,2,2,2
2,4,0,0,0,0,0,0,0,0,0,4,2,2,2
2,4,0,0,0,0,0,0,0,0,0,4,2,2,2
2,4,0,0,0,0,0,0,0,0,0,4,2,2,2
2,4,7,0,0,0,7,0,0,0,7,4,2,2,2
1,4,4,4,4,4,4,4,4,4,4,4,2,2,1
6,1,2,2,2,2,2,2,2,2,2,2,2,1,6
endlayer

layer
6,6,1,2,2,2,2,2,2,2,2,2,1,6,6
6,4,4,4,4,4,4,4,4,4,4,4,3,1,6
1,4,11,0,0,0,11,0,0,0,11,4,3,1,1
2,4,0,0,0,0,0,0,0,0,0,4,3,2,1
2,4,0,0,0,0,0,0,0,0,0,4,2,2,1
2,4,0,0,0,0,0,0,0,0,0,4,2,2,2
2,4,0,0,0,0,0,0,0,0,0,4,2,2,2
2,4,11,0,0,0,11,0,0,0,11,4,2,2,2
2,4,0,0,0,0,0,0,0,0,10,4,2,2,2
2,4,0,0,0,0,0,0,0,0,0,4,2,2,2
2,4,0,0,0,0,0,0,0,0,0,4,2,2,1
2,4,0,0,0,0,0,0,0,0,0,4,2,2,1
1,4,11,0,0,0,11,0,0,0,11,4,2,1,1
6,4,4,4,4,4,4,4,4,4,4,4,2,1,6
6,6,1,2,2,2,2,2,2,2,2,2,1,6,6
endlayer

layer
6,6,6,1,1,1,1,1,1,1,1,1,6,6,6
6,4,4,4,4,4,4,4,4,4,4,4,1,6,6
6,4,0,0,0,0,0,0,0,0,0,4,1,6,6
1,4,0,0,0,0,0,0,0,0,0,4,1,1,6
1,4,0,0,0,0,0,0,0,0,0,4,1,1,6
1,4,0,0,0,0,0,0,0,0,0,4,1,1,1
1,4,0,0,0,0,0,0,0,0,0,4,2,1,1
1,4,0,0,0,0,0,0,0,0,0,4,2,1,1
1,4,0,0,0,0,0,0,0,0,10,4,2,1,1
1,4,0,0,0,0,0,0,0,0,0,4,2,2,1
1,4,0,0,0,0,0,0,0,0,0,4,1,1,6
1,4,0,0,0,0,0,0,0,0,0,4,1,1,6
6,4,0,0,0,0,0,0,0,0,0,4,1,6,6
6,4,4,4,4,4,4,4,4,4,4,4,1,6,6
6,6,6,1,1,1,1,1,1,1,1,1,6,6,6
endlayer

layer
6,6,6,6,6,6,6,6,6,6,6,6,6,6,6
6,4,4,4,4,4,4,4,4,4,4,4,6,6,6
6,4,12,12,12,12,12,12,12,12,12,4,0,6,6
6,4,12,14,13,15,15,14,14,13,12,4,0,0,6
6,4,12,14,14,14,15,15,13,13,12,4,0,0,6
6,4,12,14,14,14,14,13,13,13,12,4,16,16,0
6,4,12,14,14,14,15,15,15,13,12,4,13,17,0
6,4,12,14,14,15,15,15,14,14,12,4,13,17,0
6,4,12,13,15,15,15,14,14,14,10,4,13,17,0
6,4,12,13,13,13,14,14,14,14,12,4,18,18,0
6,4,12,13,13,15,15,14,14,14,12,4,0,0,6
6,4,12,13,14,14,15,15,13,14,12,4,11,0,6
6,4,12,12,12,12,12,12,12,12,12,4,0,6,6
6,4,4,4,4,4,4,4,4,4,4,4,6,6,6
6,6,6,6,6,6,6,6,6,6,6,6,6,6,6
endlayer

layer
6,6,6,0,0,0,0,0,0,0,0,0,6,6,6
6,13,19,19,19,19,13,19,19,19,19,13,0,6,6
6,19,0,0,20,20,14,20,20,0,0,19,0,0,6
0,19,0,0,0,0,0,0,0,0,21,19,0,0,0
0,19,0,0,0,0,0,0,0,0,21,19,0,0,0
0,19,44,0,0,8,7,8,0,0,7,19,0,0,0
0,19,22,0,0,0,7,0,0,0,0,15,0,0,0
0,19,22,0,0,0,7,0,0,0,23,0,0,0,0
0,19,22,0,0,0,7,0,0,0,24,15,0,0,0
0,19,0,0,0,8,7,8,0,0,7,19,0,0,0
0,19,44,0,0,0,0,0,0,0,21,19,0,0,0
0,19,0,0,0,0,0,0,0,0,21,19,0,0,0
6,19,0,0,25,25,14,25,25,0,0,19,0,0,6
6,13,19,19,19,19,13,19,19,19,19,13,0,6,6
6,6,6,0,0,0,0,0,0,0,0,0,6,6,6
endlayer

layer
6,6,26,0,0,26,0,26,0,0,26,0,0,6,6
6,13,19,27,27,19,13,19,27,27,19,13,0,0,6
0,19,0,0,0,0,28,0,0,0,0,19,0,0,0
0,29,0,0,0,0,0,0,0,0,0,19,0,0,0
0,29,0,0,0,0,0,0,0,0,0,19,0,0,0
0,29,0,0,0,0,7,0,0,0,7,19,0,0,0
0,29,0,0,0,0,11,0,0,0,0,15,0,0,0
0,29,11,0,0,0,0,0,0,0,30,0,0,0,0
0,29,0,0,0,0,11,0,0,0,10,15,0,0,0
0,29,0,0,0,0,7,0,0,0,7,19,0,0,0
0,29,0,0,0,0,0,0,0,0,0,19,0,0,0
0,29,0,0,0,0,0,0,0,0,0,19,0,0,0
0,19,0,0,0,0,31,0,0,0,0,19,0,0,0
6,13,19,27,27,19,13,19,27,27,19,13,0,0,6
6,6,32,0,0,32,0,32,0,0,32,0,0,6,6
endlayer

layer
6,0,26,0,0,26,0,26,0,0,26,0,0,0,6
0,13,19,27,27,19,13,19,27,27,19,13,0,0,0
7,19,7,0,0,7,0,7,0,0,7,15,7,0,0
0,29,0,0,0,0,0,0,0,0,0,15,0,0,0
0,29,0,0,0,0,0,0,0,0,0,15,7,0,0
0,29,0,0,0,0,34,7,7,7,33,15,0,0,0
0,29,0,0,0,0,7,0,0,0,0,15,0,0,0
0,29,0,0,0,0,7,0,0,0,0,15,0,0,0
0,29,0,0,0,0,7,0,0,0,10,15,0,0,0
0,29,0,0,0,0,34,7,7,7,33,15,0,0,0
0,29,0,0,0,0,0,0,0,0,0,15,7,0,0
0,29,0,0,0,0,0,0,0,0,0,15,0,0,0
7,19,7,0,0,7,0,7,0,0,7,15,7,0,0
0,13,19,27,27,19,13,19,27,27,19,13,0,0,0
6,0,32,0,0,32,0,32,0,0,32,0,0,0,6
endlayer

layer
36,7,0,0,0,0,0,0,0,0,0,7,35,0,0
36,15,15,15,15,15,15,15,15,15,15,15,35,0,0
36,15,11,0,0,11,0,11,0,0,11,19,35,0,0
36,15,0,0,0,0,0,0,0,0,0,19,35,0,0
36,15,0,0,0,0,0,0,0,0,0,19,35,0,0
36,15,0,0,0,0,15,15,15,15,15,19,0,0,0
36,15,0,0,0,0,15,15,15,15,15,15,0,0,0
36,15,0,0,0,0,15,15,15,15,15,19,0,0,0
36,15,0,0,0,0,15,15,15,15,10,15,0,0,0
36,15,0,0,0,0,15,15,15,15,15,19,0,0,0
36,15,0,0,0,0,0,0,0,0,0,19,35,0,0
36,15,0,0,0,0,0,0,0,0,0,19,35,0,0
36,15,11,0,0,11,0,11,0,0,11,19,35,0,0
36,15,15,15,15,15,15,15,15,15,15,15,35,0,0
36,7,0,0,0,0,0,0,0,0,0,7,35,0,0
endlayer

layer
0,36,0,0,0,0,0,0,0,0,0,35,0,0,0
0,36,12,19,19,19,13,19,19,19,12,35,0,0,0
0,36,12,0,0,0,0,0,0,0,12,35,0,0,0
0,36,12,0,0,0,0,0,0,0,12,35,0,0,0
0,36,12,0,0,0,0,0,0,0,12,35,0,0,0
0,36,12,0,0,0,7,7,7,7,12,15,0,0,0
0,36,12,0,0,0,7,0,0,0,37,15,0,0,0
0,36,12,0,0,0,7,8,0,0,38,15,0,0,0
0,36,12,0,0,0,7,0,0,0,0,15,0,0,0
0,36,12,0,0,0,7,7,7,7,12,15,0,0,0
0,36,12,0,0,0,0,0,0,0,12,35,0,0,0
0,36,12,0,0,0,0,0,0,0,12,35,0,0,0
0,36,12,0,0,0,0,0,0,0,12,35,0,0,0
0,36,12,19,19,19,13,19,19,19,12,35,0,0,0
0,36,0,0,0,0,0,0,0,0,0,35,0,0,0
endlayer

layer
0,0,36,7,0,0,0,0,0,7,35,0,0,0,0
0,0,36,15,15,12,13,12,15,15,35,0,0,0,0
0,0,36,15,0,0,0,0,0,15,35,0,0,0,0
0,0,36,15,0,0,0,0,0,15,35,0,0,0,0
0,0,36,15,0,0,0,0,0,15,35,0,0,0,0
0,0,36,15,0,0,11,0,0,15,19,19,0,0,0
0,0,36,15,0,0,0,0,0,0,0,19,0,0,0
0,0,36,15,0,0,0,0,0,0,0,11,0,0,0
0,0,36,15,0,0,0,0,0,0,0,19,0,0,0
0,0,36,15,0,0,11,0,0,15,19,19,0,0,0
0,0,36,15,0,0,0,0,0,15,35,0,0,0,0
0,0,36,15,0,0,0,0,0,15,35,0,0,0,0
0,0,36,15,0,0,0,0,0,15,35,0,0,0,0
0,0,36,15,15,12,13,12,15,15,35,0,0,0,0
0,0,36,7,0,0,0,0,0,7,35,0,0,0,0
endlayer

layer
0,0,0,36,0,0,0,0,0,35,0,0,0,0,0
0,0,0,36,12,19,13,19,12,35,0,0,0,0,0
0,0,0,36,12,0,39,0,12,35,0,0,0,0,0
0,0,0,36,12,0,0,0,12,35,0,0,0,0,0
0,0,0,36,12,0,0,0,12,35,40,40,40,0,0
0,0,0,36,12,0,0,0,12,19,19,19,7,0,0
0,0,0,36,12,0,0,0,0,0,0,19,0,0,0
0,0,0,36,12,0,0,0,0,0,0,19,0,0,0
0,0,0,36,12,0,0,0,0,0,0,19,0,0,0
0,0,0,36,12,0,0,0,12,19,19,19,7,0,0
0,0,0,36,12,0,0,0,12,35,41,41,41,0,0
0,0,0,36,12,0,0,0,12,35,0,0,0,0,0
0,0,0,36,12,0,42,0,12,35,0,0,0,0,0
0,0,0,36,12,19,13,19,12,35,0,0,0,0,0
0,0,0,36,0,0,0,0,0,35,0,0,0,0,0
endlayer

layer
0,0,0,0,36,7,0,7,35,0,0,0,0,0,0
0,0,0,0,36,15,13,15,35,0,0,0,0,0,0
0,0,0,0,36,15,0,15,35,0,0,0,0,0,0
0,0,0,0,36,15,0,15,35,0,0,0,0,0,0
0,0,0,0,36,15,0,15,35,0,0,0,0,0,0
0,0,0,0,36,15,0,15,35,40,40,40,40,0,0
0,0,0,0,36,15,0,15,12,12,12,12,0,0,0
0,0,0,0,36,15,0,15,0,0,0,19,0,0,0
0,0,0,0,36,15,0,15,12,12,12,12,0,0,0
0,0,0,0,36,15,0,15,35,41,41,41,41,0,0
0,0,0,0,36,15,0,15,35,0,0,0,0,0,0
0,0,0,0,36,15,0,15,35,0,0,0,0,0,0
0,0,0,0,36,15,0,15,35,0,0,0,0,0,0
0,0,0,0,36,15,13,15,35,0,0,0,0,0,0
0,0,0,0,36,7,0,7,35,0,0,0,0,0,0
endlayer

layer
0,0,0,0,0,13,13,13,0,0,0,0,0,0,0
0,0,0,0,0,36,13,35,0,0,0,0,0,0,0
0,0,0,0,0,36,13,35,0,0,0,0,0,0,0
0,0,0,0,0,36,13,35,0,0,0,0,0,0,0
0,0,0,0,0,36,13,35,0,0,0,0,0,0,0
0,0,0,0,0,36,13,35,0,0,0,0,0,0,0
0,0,0,0,0,36,13,35,40,40,40,40,13,0,0
0,0,0,0,0,36,13,15,15,15,15,15,13,0,0
0,0,0,0,0,36,13,35,41,41,41,41,13,0,0
0,0,0,0,0,36,13,35,0,0,0,0,0,0,0
0,0,0,0,0,36,13,35,0,0,0,0,0,0,0
0,0,0,0,0,36,13,35,0,0,0,0,0,0,0
0,0,0,0,0,36,13,35,0,0,0,0,0,0,0
0,0,0,0,0,36,13,35,0,0,0,0,0,0,0
0,0,0,0,0,13,13,13,0,0,0,0,0,0,0
endlayer

layer
0,0,0,0,0,36,13,35,0,0,0,0,0,0,0
0,0,0,0,0,0,41,0,0,0,0,0,0,0,0
0,0,0,0,0,0,43,0,0,0,0,0,0,0,0
0,0,0,0,0,0,43,0,0,0,0,0,0,0,0
0,0,0,0,0,0,43,0,0,0,0,0,0,0,0
0,0,0,0,0,0,43,0,0,0,0,0,0,0,0
0,0,0,0,0,0,43,0,0,0,0,0,40,0,0
0,0,0,0,0,0,43,43,43,43,43,36,13,0,0
0,0,0,0,0,0,43,0,0,0,0,0,41,0,0
0,0,0,0,0,0,43,0,0,0,0,0,0,0,0
0,0,0,0,0,0,43,0,0,0,0,0,0,0,0
0,0,0,0,0,0,43,0,0,0,0,0,0,0,0
0,0,0,0,0,0,43,0,0,0,0,0,0,0,0
0,0,0,0,0,0,40,0,0,0,0,0,0,0,0
0,0,0,0,0,36,13,35,0,0,0,0,0,0,0
endlayer

layer
0,0,0,0,0,0,41,0,0,0,0,0,0,0,0
0,0,0,0,0,0,0,0,0,0,0,0,0,0,0
0,0,0,0,0,0,0,0,0,0,0,0,0,0,0
0,0,0,0,0,0,0,0,0,0,0,0,0,0,0
0,0,0,0,0,0,0,0,0,0,0,0,0,0,0
0,0,0,0,0,0,0,0,0,0,0,0,0,0,0
0,0,0,0,0,0,0,0,0,0,0,0,0,0,0
0,0,0,0,0,0,0,0,0,0,0,0,36,0,0
0,0,0,0,0,0,0,0,0,0,0,0,0,0,0
0,0,0,0,0,0,0,0,0,0,0,0,0,0,0
0,0,0,0,0,0,0,0,0,0,0,0,0,0,0
0,0,0,0,0,0,0,0,0,0,0,0,0,0,0
0,0,0,0,0,0,0,0,0,0,0,0,0,0,0
0,0,0,0,0,0,0,0,0,0,0,0,0,0,0
0,0,0,0,0,0,40,0,0,0,0,0,0,0,0
endlayer

