# Small Tower No. 1b (Corner) original 10/26/2014
# Created by Ruins mod version 15.1 Ingame Parser
# authoring Player: Kujaku10
# Modified 10/21/2015 by JordanGreywolf
# Last Updated 7 Feb 2016
# Updated to MC 1.8: 5 Mar 2016
# Updated to MC 1.9: 18 Apr 2016
# Updated to MC 1.11: 11 Jan 2017
# Updated to MC 1.12: 22 Jun 2017

weight=1
embed_into_distance=9
acceptable_target_blocks=

unacceptable_target_blocks=flowing_lava,lava,cloud,Natura:Cloud,red_mushroom_block,brown_mushroom_block,planks,cobblestone,torch,stone_slab,double_stone_slab,oak_stairs,spruce_stairs,birch_stairs,dark_oak_stairs,acacia_stairs,jungle_stairs,slime_congealed,slime_dirt,slime_grass,fence,stone_brick,cobblestone_wall,command_block

dimensions=29,9,9
allowable_overhang=0
max_leveling=5
leveling_buffer=-1
preserve_water=0
preserve_lava=0
preserve_plants=1

rule1=0,100,preserveBlock
rule2=0,100,minecraft:stonebrick-0,minecraft:stonebrick-0,minecraft:stonebrick-2
rule3=0,100,MobSpawner:Creeper
rule4=0,100,minecraft:stone_brick_stairs-1
rule5=0,100,minecraft:iron_bars-0
rule6=0,100,ChestGenHook:chests/simple_dungeon:5-2
rule7=0,100,minecraft:stone_brick_stairs-3
rule8=0,100,minecraft:stone_brick_stairs-0
rule9=2,100,minecraft:torch-2
rule10=0,100,minecraft:stone_brick_stairs-2
rule11=2,100,minecraft:torch-4
rule12=2,100,minecraft:torch-1
rule13=2,100,minecraft:torch-3
rule14=0,100,minecraft:stone_slab-5
rule15=0,100,minecraft:wooden_door-1
rule16=0,100,minecraft:wooden_door-2
rule17=0,100,minecraft:stone_brick_stairs-5
rule18=0,100,minecraft:wooden_door-8
rule19=0,100,minecraft:stone_slab-8
rule20=0,100,minecraft:stone_brick_stairs-4
rule21=0,100,minecraft:stone_brick_stairs-6
rule22=0,100,minecraft:stone_brick_stairs-7
rule23=0,100,minecraft:stone_slab-0

# Bandit
rule24=0,100,CommandBlock:RUINSTRIGGER /summon Skeleton ~0 ~0 ~0 {HandItems:[{Count:1,id:wooden_sword,tag:{display:{Name:"Bandit Bludgeon"},ench:[{id:19,lvl:2},{id:21,lvl:2},{id:16,lvl:3}]}},{}],ArmorItems:[{Count:1,id:leather_boots},{Count:1,id:leather_leggings},{Count:1,id:leather_chestplate},{Count:1,id:skull,Damage:3,tag:{SkullOwner:MHF_Villager}}],CustomName:Bandit,HandDropChances:[1.0F,0.0F],ArmorDropChances:[0.5F,0.5F,0.5F,0.0F],Silent:1,PersistenceRequired:1,Health:15.0f}:@

layer
1,1,1,2,2,2,1,1,1
1,1,2,2,2,2,2,1,1
1,2,2,2,2,2,2,2,1
2,2,2,2,2,2,2,2,2
2,2,2,2,2,2,2,2,2
2,2,2,2,2,2,2,2,2
1,2,2,2,2,2,2,2,2
1,1,2,2,2,2,2,2,2
1,1,1,2,2,2,2,2,2
endlayer

layer
1,1,1,2,2,2,1,1,1
1,1,2,2,2,2,2,1,1
1,2,2,2,2,2,2,2,1
2,2,2,2,2,2,2,2,2
2,4,4,4,2,0,0,3,2
2,0,0,0,2,0,0,0,2
1,2,0,0,5,0,0,0,2
1,1,2,0,2,0,0,6,2
1,1,1,2,2,2,2,2,2
endlayer

layer
1,1,1,2,2,2,1,1,1
1,1,2,0,7,2,2,1,1
1,2,0,0,7,2,2,2,1
2,0,0,0,7,2,2,2,2
2,0,0,0,2,0,0,0,2
2,0,0,0,2,0,0,0,2
1,2,0,0,5,0,0,0,2
1,1,2,0,2,0,0,0,2
1,1,1,2,2,2,2,2,2
endlayer

layer
1,1,1,2,2,2,1,1,1
1,1,2,0,0,0,2,1,1
1,2,0,0,0,0,0,2,1
2,0,0,0,0,0,0,0,2
2,0,0,0,2,8,8,8,2
2,0,0,0,2,2,2,2,2
1,2,0,0,2,2,2,2,2
1,1,2,0,2,2,2,2,2
1,1,1,2,2,2,2,2,2
endlayer

layer
1,1,1,2,2,2,1,1,1
1,1,2,0,0,0,2,1,1
1,2,0,0,0,0,0,2,1
2,0,0,0,0,0,0,0,2
2,0,0,9,2,0,0,0,2
2,2,2,2,10,0,0,0,2
1,2,2,2,10,0,0,0,2
1,1,2,2,10,0,0,0,2
1,1,1,2,2,2,2,2,2
endlayer

layer
1,1,1,2,2,2,1,1,1
1,1,2,2,0,0,2,1,1
1,2,2,2,0,0,0,2,1
2,2,2,2,11,0,0,0,2
2,4,4,4,2,0,0,0,2
2,0,0,0,0,0,0,0,2
1,2,0,0,0,0,0,0,2
1,1,2,0,0,0,0,13,2
1,1,1,2,2,2,2,2,2
endlayer

layer
1,1,1,2,2,2,1,1,1
1,1,2,2,2,2,2,1,1
1,2,0,0,7,2,2,2,1
2,0,0,0,7,2,2,2,2
2,0,0,0,2,12,0,2,2
2,0,0,0,0,0,0,0,2
1,2,0,0,0,0,0,0,2
1,1,2,0,0,0,0,0,2
1,1,1,2,2,2,2,2,2
endlayer

layer
1,1,1,2,2,2,1,1,1
1,1,2,2,2,2,2,1,1
1,2,0,0,0,0,0,2,1
2,0,0,0,0,0,0,2,2
2,0,0,0,2,8,8,2,2
2,0,0,0,13,2,2,2,2
1,2,0,0,0,0,0,0,2
1,1,2,0,0,0,0,0,2
1,1,1,2,2,2,2,2,2
endlayer

layer
1,1,1,2,2,2,1,1,1
1,1,2,2,2,2,2,1,1
1,2,2,0,0,0,0,2,1
2,2,2,9,0,0,0,2,2
2,2,2,2,2,0,0,2,2
2,2,2,2,2,8,8,2,2
1,2,2,2,2,2,2,2,2
1,1,2,2,2,2,2,2,2
1,1,1,2,2,2,2,2,2
endlayer

layer
1,1,1,2,2,2,1,1,1
1,1,14,2,2,2,14,1,1
1,14,2,2,2,2,2,14,1
2,2,2,2,2,0,0,2,2
2,2,4,4,2,0,0,2,2
2,2,0,0,0,0,0,2,2
1,14,2,0,0,0,0,0,2
1,1,14,2,0,2,0,0,15
1,1,1,2,2,2,2,16,2
endlayer

layer
1,1,1,7,2,10,1,1,1
1,1,1,2,2,2,1,1,1
1,1,2,0,7,2,2,1,1
8,2,0,0,7,17,17,2,2
2,2,0,0,2,0,0,2,2
4,2,0,0,0,0,13,2,2
1,1,2,0,0,0,0,0,2
1,1,1,2,0,2,0,0,18
1,1,1,2,2,2,2,18,2
endlayer

layer
1,1,1,1,8,1,1,1,1
1,1,1,2,2,2,1,1,1
1,1,2,0,0,0,2,1,1
1,2,11,0,0,0,0,2,2
7,2,0,0,2,8,8,2,10
1,2,11,0,0,2,2,2,10
1,1,2,0,0,2,2,19,10
1,1,1,2,2,2,19,19,10
1,1,1,2,4,4,4,4,10
endlayer

layer
1,1,1,1,1,1,1,1,1
1,1,1,2,2,2,1,1,1
1,1,2,0,0,0,2,1,1
1,2,0,0,0,0,0,2,2
1,2,0,0,2,0,0,2,1
1,2,2,2,10,0,0,2,1
1,1,2,2,10,0,2,10,1
1,1,1,2,2,2,4,10,1
1,1,1,2,1,1,1,1,1
endlayer

layer
1,1,1,1,1,1,1,1,1
1,1,1,2,5,2,1,1,1
1,1,2,2,0,0,2,1,1
1,2,2,2,0,0,13,2,10
1,5,4,4,2,0,0,5,1
1,2,0,0,0,0,13,2,1
1,1,2,0,0,0,2,1,1
1,1,1,2,5,2,1,1,1
1,1,1,4,1,1,1,1,1
endlayer

layer
1,1,1,1,1,1,1,1,1
1,1,1,2,5,2,1,1,1
1,1,2,0,7,2,2,1,1
1,2,11,0,7,2,2,2,1
1,5,0,0,2,0,0,5,1
1,2,11,0,0,0,0,2,1
1,1,2,0,0,0,2,1,1
1,1,1,2,5,2,1,1,1
1,1,1,1,1,1,1,1,1
endlayer

layer
1,1,1,1,1,1,1,1,1
1,1,1,2,2,2,1,1,1
1,1,2,0,0,0,2,1,1
1,2,0,0,0,0,0,2,1
1,2,0,0,2,8,8,2,1
1,2,0,0,0,2,2,2,1
1,1,2,0,0,2,2,1,1
1,1,1,2,2,2,1,1,1
1,1,1,1,1,1,1,1,1
endlayer

layer
1,1,1,20,20,20,1,1,1
1,1,22,2,2,2,21,1,1
1,20,2,0,0,0,2,20,1
22,2,0,0,0,0,0,2,21
22,2,0,0,2,0,0,2,21
22,2,2,2,10,0,0,2,21
1,17,2,2,10,0,2,17,1
1,1,22,2,2,2,21,1,1
1,1,1,17,17,17,1,1,1
endlayer

layer
1,1,1,23,23,23,1,1,1
1,1,23,2,2,2,23,1,1
1,23,2,2,2,0,2,23,1
23,2,2,2,2,0,13,2,23
23,2,4,4,2,0,0,2,23
23,2,0,0,0,0,13,2,23
1,23,2,0,0,0,2,23,1
1,1,23,2,2,2,23,1,1
1,1,1,23,23,23,1,1,1
endlayer

layer
1,1,1,1,1,1,1,1,1
1,1,1,2,2,2,1,1,1
1,1,2,0,7,2,2,1,1
1,2,0,0,7,2,2,2,1
1,2,0,0,2,0,0,2,1
1,2,0,0,0,0,0,2,1
1,1,2,0,0,0,2,1,1
1,1,1,2,2,2,1,1,1
1,1,1,1,1,1,1,1,1
endlayer

layer
1,1,1,1,1,1,1,1,1
1,1,1,2,5,2,1,1,1
1,1,2,0,0,0,2,1,1
1,2,11,0,0,0,0,2,1
1,5,0,0,2,8,8,5,1
1,2,11,0,0,2,2,2,1
1,1,2,0,0,2,2,1,1
1,1,1,2,5,2,1,1,1
1,1,1,1,1,1,1,1,1
endlayer

layer
1,1,1,1,1,1,1,1,1
1,1,1,2,5,2,1,1,1
1,1,2,0,0,0,2,1,1
1,2,0,0,0,0,13,2,1
1,5,0,0,2,0,0,5,1
1,2,2,2,10,0,13,2,1
1,1,2,2,10,0,2,1,1
1,1,1,2,5,2,1,1,1
1,1,1,1,1,1,1,1,1
endlayer

layer
1,1,1,1,1,1,1,1,1
1,1,1,2,2,2,1,1,1
1,1,2,2,0,0,2,1,1
1,2,2,2,0,0,0,2,1
1,2,4,4,2,0,0,2,1
1,2,0,0,0,0,0,2,1
1,1,2,0,0,0,2,1,1
1,1,1,2,2,2,1,1,1
1,1,1,1,1,1,1,1,1
endlayer

layer
1,1,1,1,1,1,1,1,1
1,1,1,2,2,2,1,1,1
1,1,2,0,7,2,2,1,1
1,2,11,0,7,2,2,2,1
1,2,0,0,2,0,0,2,1
1,2,11,0,0,0,0,2,1
1,1,2,0,0,0,2,1,1
1,1,1,2,2,2,1,1,1
1,1,1,1,1,1,1,1,1
endlayer

layer
1,1,1,20,20,20,1,1,1
1,1,22,2,2,2,21,1,1
1,20,2,0,0,0,2,20,1
22,2,0,0,0,0,0,2,21
22,2,0,0,2,8,8,2,21
22,2,0,0,0,2,2,2,21
1,17,2,0,0,2,2,17,1
1,1,22,2,2,2,21,1,1
1,1,1,17,17,17,1,1,1
endlayer

layer
1,1,1,23,23,23,1,1,1
1,1,23,2,2,2,23,1,1
1,23,2,0,0,0,2,23,1
23,2,2,0,0,0,13,2,23
23,2,2,2,2,0,0,2,23
23,2,2,2,10,0,13,2,23
1,23,2,2,10,0,2,23,1
1,1,23,2,2,2,23,1,1
1,1,1,23,23,23,1,1,1
endlayer

layer
1,1,2,2,2,2,2,1,1
1,2,2,2,2,2,2,2,1
2,2,2,2,0,0,2,2,2
2,2,2,2,0,0,0,2,2
2,2,4,4,2,0,0,2,2
2,2,0,0,0,0,0,2,2
2,2,2,0,0,0,2,2,2
1,2,2,2,2,2,2,2,1
1,0,2,2,2,2,2,1,1
endlayer

layer
1,1,2,2,2,2,2,1,1
1,2,14,14,14,14,14,2,1
2,14,14,0,0,0,14,14,2
2,14,0,0,24,0,0,14,2
2,14,0,0,14,0,0,14,2
2,14,0,0,24,0,0,14,2
2,14,14,0,0,0,14,14,2
1,2,14,14,14,14,14,2,1
1,1,2,2,2,2,2,1,1
endlayer

layer
1,1,14,2,14,2,14,1,1
1,2,0,0,0,0,0,2,1
14,0,0,0,0,0,0,0,14
2,0,0,0,0,0,0,0,2
14,0,0,0,0,0,0,0,14
2,0,0,0,0,0,0,0,2
14,0,0,0,0,0,0,0,14
1,2,0,0,0,0,0,2,1
1,1,14,2,14,2,14,1,1
endlayer

layer
1,1,1,14,1,14,1,1,1
1,14,0,0,0,0,0,14,1
1,0,0,0,0,0,0,0,1
14,0,0,0,0,0,0,0,14
1,0,0,0,0,0,0,0,1
14,0,0,0,0,0,0,0,14
1,0,0,0,0,0,0,0,1
1,14,0,0,0,0,0,14,1
1,1,1,14,1,14,1,1,1
endlayer

