# Small Cottage No. 1 10/2014
# Created by Ruins mod version 13.8 Ingame Parser
# authoring Player: Kujaku10

# Updated to MC 1.8: 5 Mar 2016
# Updated to MC 1.9: 18 Apr 2016
# Updated to MC 1.11.2: 11 Jan 2017
# Updated to MC 1.12: 22 Jun 2017


weight=1
embed_into_distance=4
acceptable_target_blocks=

unacceptable_target_blocks=flowing_lava,lava,cloud,Natura:Cloud,red_mushroom_block,brown_mushroom_block,planks,cobblestone,torch,stone_slab,double_stone_slab,oak_stairs,spruce_stairs,birch_stairs,dark_oak_stairs,acacia_stairs,jungle_stairs,slime_congealed,slime_dirt,slime_grass,fence,stone_brick,cobblestone_wall,command_block

dimensions=15,10,13
allowable_overhang=0
max_leveling=4
leveling_buffer=-1
preserve_water=0
preserve_lava=0
preserve_plants=1

rule1=0,100,preserveBlock
rule2=0,100,minecraft:grass-0
rule3=1,100,minecraft:red_flower-5
rule4=0,100,minecraft:brick_block-0
rule5=1,100,minecraft:red_flower-7
rule6=0,100,minecraft:stonebrick-0
rule7=0,100,minecraft:netherrack-0
rule8=0,100,minecraft:stonebrick-0
rule9=1,100,minecraft:red_flower-6
rule10=0,100,minecraft:stonebrick-3
rule11=1,100,minecraft:leaves-6
rule12=0,100,minecraft:brick_stairs-0
rule13=0,100,minecraft:brick_stairs-3
rule14=0,100,minecraft:brick_stairs-1
rule15=1,100,minecraft:leaves-14
rule16=0,100,minecraft:planks-4
rule17=0,100,minecraft:quartz_block-0
rule18=0,100,minecraft:fire-15
rule19=0,100,minecraft:iron_bars-0
rule20=1,100,minecraft:wooden_door-3
rule21=0,100,minecraft:noteblock-0
rule22=0,100,IInventory;minecraft:lit_furnace;minecraft:coal#4#0#1-4
rule23=0,100,ChestGenHook:chests/village_blacksmith:2-4
rule24=0,100,minecraft:sandstone-2
rule25=0,100,minecraft:glass_pane-0
rule26=1,100,minecraft:wooden_door-8

# Flower Pot: Red Mushroom
rule27=0,100,teBlock;minecraft:flower_pot;{Item:"minecraft:red_mushroom",x:0,y:0,z:0,Data:0,id:"flower_pot"}-0

rule28=0,100,minecraft:quartz_stairs-5
rule29=2,100,minecraft:torch-2
rule30=0,100,minecraft:brick_stairs-2
rule31=0,100,minecraft:planks-2

# Flower Pot: Birch Sapling
rule32=0,100,teBlock;minecraft:flower_pot;{Item:"minecraft:sapling",x:0,y:0,z:0,Data:2,id:"flower_pot"}-0

# Flower Pot: Dark Oak Sapling
rule33=0,100,teBlock;minecraft:flower_pot;{Item:"minecraft:sapling",x:0,y:0,z:0,Data:5,id:"flower_pot"}-0

# Flower Pot: Dandelion
rule34=0,100,teBlock;minecraft:flower_pot;{Item:"minecraft:yellow_flower",x:0,y:0,z:0,Data:0,id:"flower_pot"}-0

# Flower Pot: Jungle Sapling
rule35=0,100,teBlock;minecraft:flower_pot;{Item:"minecraft:sapling",x:0,y:0,z:0,Data:3,id:"flower_pot"}-0

rule36=0,100,minecraft:spruce_stairs-0
rule37=0,100,minecraft:spruce_stairs-1
rule38=0,100,minecraft:stained_hardened_clay-4
rule39=0,100,minecraft:stained_hardened_clay-1
rule40=0,100,minecraft:planks-1
rule41=0,100,minecraft:spruce_stairs-3
rule42=0,100,minecraft:spruce_stairs-2
rule43=0,100,minecraft:stone_slab-4
rule44=0,100,minecraft:wooden_slab-1

# Bandit
rule45=0,100,CommandBlock:RUINSTRIGGER /summon Skeleton ~0 ~0 ~0 {HandItems:[{Count:1,id:wooden_sword,tag:{display:{Name:"Bandit Bludgeon"},ench:[{id:19,lvl:2},{id:21,lvl:2},{id:16,lvl:3}]}},{}],ArmorItems:[{Count:1,id:leather_boots},{Count:1,id:leather_leggings},{Count:1,id:leather_chestplate},{Count:1,id:skull,Damage:3,tag:{SkullOwner:MHF_Villager}}],CustomName:Bandit,HandDropChances:[1.0F,0.0F],ArmorDropChances:[0.5F,0.5F,0.5F,0.0F],Silent:1,PersistenceRequired:1,Health:15.0f}:@

layer
1,2,1,1,1,1,1,1,1,1,1,1,1
2,2,2,1,1,6,6,6,6,1,1,1,1
2,2,6,6,6,6,10,10,6,6,6,1,1
2,2,6,10,10,10,10,10,10,10,6,1,1
2,6,6,10,10,10,10,10,10,10,6,1,1
2,6,6,10,10,10,10,10,10,10,6,1,1
2,6,6,10,10,10,10,10,10,10,6,1,1
2,2,6,10,10,10,10,10,10,10,6,1,1
2,2,6,6,6,6,6,6,6,6,6,1,1
2,2,2,1,1,1,1,1,1,1,1,1,1
endlayer


layer
1,1,1,1,1,1,1,1,1,1,1,1,1
1,2,1,1,1,6,6,6,6,1,1,1,1
2,2,6,6,6,6,0,0,6,6,6,1,1
2,2,6,0,0,0,0,0,0,0,6,1,1
2,6,6,0,0,0,0,0,0,0,6,1,1
2,6,6,0,0,0,0,0,0,0,6,1,1
2,6,6,0,0,0,0,0,0,0,6,1,1
2,2,6,0,0,0,0,0,0,0,6,1,1
2,2,6,6,6,6,6,6,6,6,6,1,1
1,2,1,1,1,1,1,1,1,1,1,1,1
endlayer

layer
1,1,1,1,1,1,1,1,1,1,1,1,1
1,1,1,1,1,6,6,6,6,1,1,1,1
1,2,6,6,6,6,0,0,6,6,6,1,1
2,2,6,0,0,0,0,0,0,0,6,1,1
2,6,6,0,0,0,0,0,0,0,6,1,1
2,6,6,0,0,0,0,0,0,0,6,1,1
2,6,6,0,0,0,0,0,0,0,6,1,1
2,2,6,0,0,0,0,0,0,0,6,1,1
1,2,6,6,6,6,6,6,6,6,6,1,1
1,1,1,1,1,1,1,1,1,1,1,1,1
endlayer



layer
1,1,1,1,1,1,1,1,1,1,1,1,1
1,1,1,1,1,6,6,6,6,1,1,1,1
1,1,6,6,6,6,0,0,6,6,6,1,1
1,2,6,0,0,0,0,0,0,0,6,1,1
2,6,6,0,0,0,0,0,0,0,6,1,1
2,6,6,0,0,0,0,0,0,0,6,1,1
2,6,6,0,0,0,0,0,0,0,6,1,1
1,2,6,0,0,0,0,0,0,0,6,1,1
1,1,6,6,6,6,6,6,6,6,6,1,1
1,1,1,1,1,1,1,1,1,1,1,1,1
endlayer


layer
1,1,1,0,0,0,0,0,0,0,1,1,1
1,3,0,0,0,4,4,4,4,0,0,3,1
1,5,6,8,6,4,7,7,4,6,6,5,1
0,9,6,6,10,4,4,4,4,6,6,9,0
0,12,6,6,10,6,6,6,10,6,6,11,0
0,13,6,6,10,6,10,6,10,6,6,11,0
0,14,6,6,10,6,6,6,10,6,6,11,0
1,9,6,6,10,6,6,6,10,6,6,9,1
1,5,6,6,6,6,6,6,6,6,6,5,1
1,3,11,15,11,11,11,11,11,11,11,3,1
endlayer

layer
1,1,0,0,0,0,0,0,0,0,0,1,1
1,0,0,0,0,4,4,4,4,0,0,0,1
0,0,16,17,17,4,18,18,4,17,16,0,0
0,0,17,0,0,19,19,19,19,0,17,0,0
0,0,16,0,0,0,0,0,0,0,17,0,0
0,0,0,20,0,0,0,45,45,0,17,0,0
0,0,16,0,0,0,0,0,0,0,17,0,0
0,0,17,24,0,23,22,22,0,21,17,0,0
1,0,16,17,17,17,17,17,17,17,16,0,1
1,1,0,0,0,0,0,0,0,0,0,1,1
endlayer

layer
1,0,0,0,0,0,0,0,0,0,0,0,1
0,0,0,0,0,4,4,4,4,0,0,0,0
0,0,16,17,17,4,0,0,4,17,16,0,0
0,0,17,0,0,0,0,0,0,0,17,0,0
0,0,16,0,0,0,0,0,0,0,16,0,0
0,0,0,26,0,0,0,0,0,0,25,0,0
0,0,16,0,0,0,0,0,0,0,16,0,0
0,0,17,27,0,0,0,0,0,0,17,0,0
0,0,16,17,16,25,25,25,16,17,16,0,0
1,0,0,0,0,0,0,0,0,0,0,0,1
endlayer

layer
0,0,0,0,0,0,0,0,0,0,0,0,0
0,0,0,0,0,4,4,4,4,0,0,0,0
0,0,16,17,17,4,0,0,4,17,16,0,0
0,0,17,0,0,28,28,28,28,0,17,0,0
0,0,17,0,0,0,0,0,0,0,16,0,0
0,0,16,0,0,0,0,0,0,0,25,0,0
0,0,17,0,0,0,0,0,0,0,16,0,0
0,0,17,0,29,0,0,0,29,0,17,0,0
0,0,16,17,16,25,25,25,16,17,16,0,0
0,0,0,0,0,0,0,0,0,0,0,0,0
endlayer

layer
0,0,0,0,0,0,0,0,0,0,0,0,0
0,0,0,0,0,13,4,4,30,0,0,0,0
0,0,16,17,17,4,4,4,4,17,16,0,0
0,0,31,0,0,35,34,33,32,0,31,0,0
0,0,17,0,0,0,0,0,0,0,17,0,0
0,0,17,0,0,0,0,0,0,0,17,0,0
0,0,17,0,0,0,0,0,0,0,17,0,0
0,0,31,0,0,0,0,0,0,0,31,0,0
0,0,16,31,17,17,17,17,17,31,16,0,0
0,0,0,0,0,0,0,0,0,0,0,0,0
endlayer

layer
0,0,0,0,0,0,0,0,0,0,0,0,0
0,36,36,36,36,36,12,12,36,36,36,36,0
0,0,16,17,17,17,4,4,17,17,16,0,0
0,0,16,0,0,0,0,0,0,0,16,0,0
0,0,16,0,0,0,0,0,0,0,16,0,0
0,0,16,0,0,0,0,0,0,0,16,0,0
0,0,16,0,0,0,0,0,0,0,16,0,0
0,0,16,0,0,0,0,0,0,0,16,0,0
0,0,16,16,16,16,16,16,16,16,16,0,0
0,37,37,37,37,37,37,37,37,37,37,37,0
endlayer

layer
0,0,0,0,0,0,0,0,0,0,0,0,0
0,0,0,0,0,0,0,0,0,0,0,0,0
0,36,36,36,36,36,4,4,36,36,36,36,0
0,0,31,38,38,38,38,38,38,38,31,0,0
0,0,17,0,0,0,0,0,0,0,17,0,0
0,0,25,0,0,0,0,0,0,0,25,0,0
0,0,17,0,0,0,0,0,0,0,17,0,0
0,0,31,38,38,38,38,38,38,38,31,0,0
0,37,37,37,37,37,37,37,37,37,37,37,0
0,0,0,0,0,0,0,0,0,0,0,0,0
endlayer

layer
0,0,0,0,0,0,0,0,0,0,0,0,0
0,0,0,0,0,0,0,0,0,0,0,0,0
0,0,0,0,0,0,4,4,0,0,0,0,0
0,36,36,36,36,36,4,4,36,36,36,36,0
0,0,16,39,39,39,39,39,39,39,16,0,0
0,0,17,0,0,0,0,0,0,0,17,0,0
0,0,16,39,39,39,39,39,39,39,16,0,0
0,37,37,37,37,37,37,37,37,37,37,37,0
0,0,0,0,0,0,0,0,0,0,0,0,0
0,0,0,0,0,0,0,0,0,0,0,0,0
endlayer

layer
0,0,0,0,0,0,0,0,0,0,0,0,0
0,0,0,0,0,0,0,0,0,0,0,0,0
0,0,0,0,0,0,4,4,0,0,0,0,0
0,0,0,0,0,0,4,4,0,0,0,0,0
0,40,42,36,36,36,36,36,36,36,41,40,0
0,0,31,38,38,38,38,38,38,38,31,0,0
0,40,42,37,37,37,37,37,37,37,41,40,0
0,0,0,0,0,0,0,0,0,0,0,0,0
0,0,0,0,0,0,0,0,0,0,0,0,0
0,0,0,0,0,0,0,0,0,0,0,0,0
endlayer

layer
0,0,0,0,0,0,0,0,0,0,0,0,0
0,0,0,0,0,0,0,0,0,0,0,0,0
0,0,0,0,0,0,43,43,0,0,0,0,0
0,0,0,0,0,0,43,43,0,0,0,0,0
0,44,0,0,0,0,0,0,0,0,0,44,0
0,40,42,44,44,44,44,44,44,44,41,40,0
0,44,0,0,0,0,0,0,0,0,0,44,0
0,0,0,0,0,0,0,0,0,0,0,0,0
0,0,0,0,0,0,0,0,0,0,0,0,0
0,0,0,0,0,0,0,0,0,0,0,0,0
endlayer

layer
0,0,0,0,0,0,0,0,0,0,0,0,0
0,0,0,0,0,0,0,0,0,0,0,0,0
0,0,0,0,0,0,0,0,0,0,0,0,0
0,0,0,0,0,0,0,0,0,0,0,0,0
0,0,0,0,0,0,0,0,0,0,0,0,0
0,42,0,0,0,0,0,0,0,0,0,41,0
0,0,0,0,0,0,0,0,0,0,0,0,0
0,0,0,0,0,0,0,0,0,0,0,0,0
0,0,0,0,0,0,0,0,0,0,0,0,0
0,0,0,0,0,0,0,0,0,0,0,0,0
endlayer

