# A Giant Fountain with Flowers 10/18/2014
# Created by Ruins mod version 13.8 Ingame Parser
# authoring Player: Kujaku10
# Last Updated 9 Nov 2015
# Updated to MC 1.8: 5 Mar 2016
# Updated to MC 1.11.2: 11 Jan 2017
# Verified for MC 1.12: 22 Jun 2017
# Updated to MC 1.12.1: 10 Sep 2017

biomesToSpawnIn=plains,sunflower plains,mutated_plains

weight=1
embed_into_distance=11
acceptable_target_blocks=

unacceptable_target_blocks=flowing_lava,lava,cloud,Natura:Cloud,red_mushroom_block,brown_mushroom_block,planks,cobblestone,torch,stone_slab,double_stone_slab,oak_stairs,spruce_stairs,birch_stairs,dark_oak_stairs,acacia_stairs,jungle_stairs,slime_congealed,slime_dirt,slime_grass,fence,stone_brick,cobblestone_wall,command_block

dimensions=27,32,22
allowable_overhang=0
max_leveling=2
leveling_buffer=-1
preserve_water=0
preserve_lava=0
preserve_plants=1

rule1=0,100,preserveBlock
rule2=0,100,minecraft:grass-0
rule3=0,100,minecraft:stonebrick-0
rule4=0,100,minecraft:stonebrick-1
rule5=0,100,minecraft:stonebrick-2
rule6=0,100,minecraft:stone_slab-5
rule7=0,100,minecraft:water-6
rule8=0,100,minecraft:water-7
rule9=0,100,minecraft:water-4
rule10=0,100,minecraft:water-5
rule11=0,100,minecraft:water-2
rule12=0,100,minecraft:water-3
rule13=0,100,minecraft:red_flower-7
rule14=0,100,minecraft:water-1
rule15=0,100,minecraft:red_flower-5
rule16=0,100,minecraft:red_flower-4
rule17=0,100,minecraft:water-0
rule18=0,100,minecraft:red_flower-1
rule19=0,100,minecraft:red_flower-6
rule20=0,100,minecraft:red_flower-2
rule21=0,100,minecraft:water-10
rule22=0,100,minecraft:stone_brick_stairs-4
rule23=0,100,minecraft:stone_brick_stairs-7
rule24=0,100,minecraft:stone_brick_stairs-6
rule25=0,100,minecraft:stone_brick_stairs-5
rule26=0,100,minecraft:water-9

layer
1,1,1,1,1,1,1,2,2,2,2,2,2,2,2,1,1,1,1,1,1,1
1,1,1,1,1,1,2,2,2,3,3,3,3,2,2,2,1,1,1,1,1,1
1,1,1,1,1,2,2,2,3,3,3,3,3,3,2,2,2,1,1,1,1,1
1,1,1,1,1,2,2,3,3,3,3,3,3,3,3,2,2,1,1,1,1,1
1,1,1,1,1,2,3,3,3,3,2,2,3,3,3,3,2,1,1,1,1,1
1,1,1,1,1,2,3,3,3,2,2,2,2,3,3,3,2,1,1,1,1,1
1,1,1,1,2,2,3,3,3,2,3,3,2,3,3,3,2,2,1,1,1,1
1,1,1,2,2,2,3,3,3,4,3,3,3,3,3,3,2,2,2,1,1,1
1,1,1,2,2,2,3,3,3,3,3,3,5,3,3,5,2,2,2,1,1,1
1,1,2,2,3,3,3,3,3,3,3,3,3,3,3,3,3,3,2,2,1,1
1,1,2,2,3,3,3,3,5,3,3,3,3,3,3,3,3,3,2,2,1,1
1,2,2,5,3,3,3,3,3,3,3,3,3,3,3,3,3,3,3,2,2,1
1,2,2,3,3,3,3,3,3,3,3,3,3,3,3,3,3,3,3,2,2,1
2,2,3,3,3,3,3,3,3,3,3,3,3,3,4,3,3,3,3,3,2,2
2,2,3,3,3,3,3,4,3,3,3,3,3,3,3,3,3,3,3,3,2,2
2,3,3,3,3,3,3,3,3,3,3,3,3,3,3,3,3,3,3,3,3,2
2,3,3,3,3,3,3,3,3,3,3,3,3,3,3,3,3,3,3,3,3,2
2,2,3,3,3,3,3,3,3,3,3,3,3,3,3,3,3,3,3,3,2,2
2,2,3,4,3,3,3,3,3,3,3,3,3,3,3,3,3,3,3,3,2,2
1,2,2,3,3,5,3,3,3,3,3,3,3,3,3,5,3,3,3,2,2,1
1,2,2,3,3,3,3,3,3,3,4,3,3,3,3,3,3,3,4,2,2,1
1,1,2,2,3,3,3,3,3,3,3,3,3,3,3,3,3,3,2,2,1,1
1,1,2,2,3,3,3,3,3,3,3,3,3,3,3,3,3,3,2,2,1,1
1,1,1,2,2,2,3,3,3,3,3,3,3,3,3,3,2,2,2,1,1,1
1,1,1,2,2,2,3,3,3,3,3,3,3,3,3,3,2,2,2,1,1,1
1,1,1,1,2,2,3,3,3,2,5,3,2,3,3,3,2,2,1,1,1,1
1,1,1,1,1,2,3,3,3,2,2,2,2,3,3,3,2,1,1,1,1,1
1,1,1,1,1,2,3,3,3,3,2,2,3,3,3,3,2,1,1,1,1,1
1,1,1,1,1,2,2,3,3,3,3,3,3,3,3,3,2,1,1,1,1,1
1,1,1,1,1,2,2,2,3,3,3,3,3,3,3,2,2,1,1,1,1,1
1,1,1,1,1,1,2,2,2,3,3,3,3,2,2,2,1,1,1,1,1,1
1,1,1,1,1,1,1,2,2,2,2,2,2,2,2,1,1,1,1,1,1,1
endlayer

layer
1,1,1,1,1,1,1,2,2,2,2,2,2,2,2,1,1,1,1,1,1,1
1,1,1,1,1,1,2,2,2,3,3,3,3,2,2,2,1,1,1,1,1,1
1,1,1,1,1,2,2,2,3,3,3,3,3,3,2,2,2,1,1,1,1,1
1,1,1,1,1,2,2,3,3,3,3,3,3,3,3,2,2,1,1,1,1,1
1,1,1,1,1,2,3,3,3,3,2,2,3,3,3,3,2,1,1,1,1,1
1,1,1,1,1,2,3,3,3,2,2,2,2,3,3,3,2,1,1,1,1,1
1,1,1,1,2,2,3,3,3,2,3,3,2,3,3,3,2,2,1,1,1,1
1,1,1,2,2,2,3,3,3,4,3,3,3,3,3,3,2,2,2,1,1,1
1,1,1,2,2,2,3,3,3,3,3,3,5,3,3,5,2,2,2,1,1,1
1,1,2,2,3,3,3,3,3,3,3,3,3,3,3,3,3,3,2,2,1,1
1,1,2,2,3,3,3,3,5,3,3,3,3,3,3,3,3,3,2,2,1,1
1,2,2,5,3,3,3,3,3,3,3,3,3,3,3,3,3,3,3,2,2,1
1,2,2,3,3,3,3,3,3,3,3,3,3,3,3,3,3,3,3,2,2,1
2,2,3,3,3,3,3,3,3,3,3,3,3,3,4,3,3,3,3,3,2,2
2,2,3,3,3,3,3,4,3,3,3,3,3,3,3,3,3,3,3,3,2,2
2,3,3,3,3,3,3,3,3,3,3,3,3,3,3,3,3,3,3,3,3,2
2,3,3,3,3,3,3,3,3,3,3,3,3,3,3,3,3,3,3,3,3,2
2,2,3,3,3,3,3,3,3,3,3,3,3,3,3,3,3,3,3,3,2,2
2,2,3,4,3,3,3,3,3,3,3,3,3,3,3,3,3,3,3,3,2,2
1,2,2,3,3,5,3,3,3,3,3,3,3,3,3,5,3,3,3,2,2,1
1,2,2,3,3,3,3,3,3,3,4,3,3,3,3,3,3,3,4,2,2,1
1,1,2,2,3,3,3,3,3,3,3,3,3,3,3,3,3,3,2,2,1,1
1,1,2,2,3,3,3,3,3,3,3,3,3,3,3,3,3,3,2,2,1,1
1,1,1,2,2,2,3,3,3,3,3,3,3,3,3,3,2,2,2,1,1,1
1,1,1,2,2,2,3,3,3,3,3,3,3,3,3,3,2,2,2,1,1,1
1,1,1,1,2,2,3,3,3,2,5,3,2,3,3,3,2,2,1,1,1,1
1,1,1,1,1,2,3,3,3,2,2,2,2,3,3,3,2,1,1,1,1,1
1,1,1,1,1,2,3,3,3,3,2,2,3,3,3,3,2,1,1,1,1,1
1,1,1,1,1,2,2,3,3,3,3,3,3,3,3,3,2,1,1,1,1,1
1,1,1,1,1,2,2,2,3,3,3,3,3,3,3,2,2,1,1,1,1,1
1,1,1,1,1,1,2,2,2,3,3,3,3,2,2,2,1,1,1,1,1,1
1,1,1,1,1,1,1,2,2,2,2,2,2,2,2,1,1,1,1,1,1,1
endlayer

layer
1,1,1,1,1,1,1,2,2,2,2,2,2,2,2,1,1,1,1,1,1,1
1,1,1,1,1,1,2,2,2,3,3,3,3,2,2,2,1,1,1,1,1,1
1,1,1,1,1,2,2,2,3,3,3,3,3,3,2,2,2,1,1,1,1,1
1,1,1,1,1,2,2,3,3,3,3,3,3,3,3,2,2,1,1,1,1,1
1,1,1,1,1,2,3,3,3,3,2,2,3,3,3,3,2,1,1,1,1,1
1,1,1,1,1,2,3,3,3,2,2,2,2,3,3,3,2,1,1,1,1,1
1,1,1,1,2,2,3,3,3,2,3,3,2,3,3,3,2,2,1,1,1,1
1,1,1,2,2,2,3,3,3,4,3,3,3,3,3,3,2,2,2,1,1,1
1,1,1,2,2,2,3,3,3,3,3,3,5,3,3,5,2,2,2,1,1,1
1,1,2,2,3,3,3,3,3,3,3,3,3,3,3,3,3,3,2,2,1,1
1,1,2,2,3,3,3,3,5,3,3,3,3,3,3,3,3,3,2,2,1,1
1,2,2,5,3,3,3,3,3,3,3,3,3,3,3,3,3,3,3,2,2,1
1,2,2,3,3,3,3,3,3,3,3,3,3,3,3,3,3,3,3,2,2,1
2,2,3,3,3,3,3,3,3,3,3,3,3,3,4,3,3,3,3,3,2,2
2,2,3,3,3,3,3,4,3,3,3,3,3,3,3,3,3,3,3,3,2,2
2,3,3,3,3,3,3,3,3,3,3,3,3,3,3,3,3,3,3,3,3,2
2,3,3,3,3,3,3,3,3,3,3,3,3,3,3,3,3,3,3,3,3,2
2,2,3,3,3,3,3,3,3,3,3,3,3,3,3,3,3,3,3,3,2,2
2,2,3,4,3,3,3,3,3,3,3,3,3,3,3,3,3,3,3,3,2,2
1,2,2,3,3,5,3,3,3,3,3,3,3,3,3,5,3,3,3,2,2,1
1,2,2,3,3,3,3,3,3,3,4,3,3,3,3,3,3,3,4,2,2,1
1,1,2,2,3,3,3,3,3,3,3,3,3,3,3,3,3,3,2,2,1,1
1,1,2,2,3,3,3,3,3,3,3,3,3,3,3,3,3,3,2,2,1,1
1,1,1,2,2,2,3,3,3,3,3,3,3,3,3,3,2,2,2,1,1,1
1,1,1,2,2,2,3,3,3,3,3,3,3,3,3,3,2,2,2,1,1,1
1,1,1,1,2,2,3,3,3,2,5,3,2,3,3,3,2,2,1,1,1,1
1,1,1,1,1,2,3,3,3,2,2,2,2,3,3,3,2,1,1,1,1,1
1,1,1,1,1,2,3,3,3,3,2,2,3,3,3,3,2,1,1,1,1,1
1,1,1,1,1,2,2,3,3,3,3,3,3,3,3,3,2,1,1,1,1,1
1,1,1,1,1,2,2,2,3,3,3,3,3,3,3,2,2,1,1,1,1,1
1,1,1,1,1,1,2,2,2,3,3,3,3,2,2,2,1,1,1,1,1,1
1,1,1,1,1,1,1,2,2,2,2,2,2,2,2,1,1,1,1,1,1,1
endlayer

layer
1,1,1,1,1,1,1,2,2,2,2,2,2,2,2,1,1,1,1,1,1,1
1,1,1,1,1,1,2,2,2,3,3,3,3,2,2,2,1,1,1,1,1,1
1,1,1,1,1,2,2,2,3,3,3,3,3,3,2,2,2,1,1,1,1,1
1,1,1,1,1,2,2,3,3,3,3,3,3,3,3,2,2,1,1,1,1,1
1,1,1,1,1,2,3,3,3,3,2,2,3,3,3,3,2,1,1,1,1,1
1,1,1,1,1,2,3,3,3,2,2,2,2,3,3,3,2,1,1,1,1,1
1,1,1,1,2,2,3,3,3,2,3,3,2,3,3,3,2,2,1,1,1,1
1,1,1,2,2,2,3,3,3,4,3,3,3,3,3,3,2,2,2,1,1,1
1,1,1,2,2,2,3,3,3,3,3,3,5,3,3,5,2,2,2,1,1,1
1,1,2,2,3,3,3,3,3,3,3,3,3,3,3,3,3,3,2,2,1,1
1,1,2,2,3,3,3,3,5,3,3,3,3,3,3,3,3,3,2,2,1,1
1,2,2,5,3,3,3,3,3,3,3,3,3,3,3,3,3,3,3,2,2,1
1,2,2,3,3,3,3,3,3,3,3,3,3,3,3,3,3,3,3,2,2,1
2,2,3,3,3,3,3,3,3,3,3,3,3,3,4,3,3,3,3,3,2,2
2,2,3,3,3,3,3,4,3,3,3,3,3,3,3,3,3,3,3,3,2,2
2,3,3,3,3,3,3,3,3,3,3,3,3,3,3,3,3,3,3,3,3,2
2,3,3,3,3,3,3,3,3,3,3,3,3,3,3,3,3,3,3,3,3,2
2,2,3,3,3,3,3,3,3,3,3,3,3,3,3,3,3,3,3,3,2,2
2,2,3,4,3,3,3,3,3,3,3,3,3,3,3,3,3,3,3,3,2,2
1,2,2,3,3,5,3,3,3,3,3,3,3,3,3,5,3,3,3,2,2,1
1,2,2,3,3,3,3,3,3,3,4,3,3,3,3,3,3,3,4,2,2,1
1,1,2,2,3,3,3,3,3,3,3,3,3,3,3,3,3,3,2,2,1,1
1,1,2,2,3,3,3,3,3,3,3,3,3,3,3,3,3,3,2,2,1,1
1,1,1,2,2,2,3,3,3,3,3,3,3,3,3,3,2,2,2,1,1,1
1,1,1,2,2,2,3,3,3,3,3,3,3,3,3,3,2,2,2,1,1,1
1,1,1,1,2,2,3,3,3,2,5,3,2,3,3,3,2,2,1,1,1,1
1,1,1,1,1,2,3,3,3,2,2,2,2,3,3,3,2,1,1,1,1,1
1,1,1,1,1,2,3,3,3,3,2,2,3,3,3,3,2,1,1,1,1,1
1,1,1,1,1,2,2,3,3,3,3,3,3,3,3,3,2,1,1,1,1,1
1,1,1,1,1,2,2,2,3,3,3,3,3,3,3,2,2,1,1,1,1,1
1,1,1,1,1,1,2,2,2,3,3,3,3,2,2,2,1,1,1,1,1,1
1,1,1,1,1,1,1,2,2,2,2,2,2,2,2,1,1,1,1,1,1,1
endlayer

layer
1,1,1,1,1,1,1,2,2,2,2,2,2,2,2,1,1,1,1,1,1,1
1,1,1,1,1,1,2,2,2,3,3,3,3,2,2,2,1,1,1,1,1,1
1,1,1,1,1,2,2,2,3,3,3,3,3,3,2,2,2,1,1,1,1,1
1,1,1,1,1,2,2,3,3,3,3,3,3,3,3,2,2,1,1,1,1,1
1,1,1,1,1,2,3,3,3,3,2,2,3,3,3,3,2,1,1,1,1,1
1,1,1,1,1,2,3,3,3,2,2,2,2,3,3,3,2,1,1,1,1,1
1,1,1,1,2,2,3,3,3,2,3,3,2,3,3,3,2,2,1,1,1,1
1,1,1,2,2,2,3,3,3,4,3,3,3,3,3,3,2,2,2,1,1,1
1,1,1,2,2,2,3,3,3,3,3,3,5,3,3,5,2,2,2,1,1,1
1,1,2,2,3,3,3,3,3,3,3,3,3,3,3,3,3,3,2,2,1,1
1,1,2,2,3,3,3,3,5,3,3,3,3,3,3,3,3,3,2,2,1,1
1,2,2,5,3,3,3,3,3,3,3,3,3,3,3,3,3,3,3,2,2,1
1,2,2,3,3,3,3,3,3,3,3,3,3,3,3,3,3,3,3,2,2,1
2,2,3,3,3,3,3,3,3,3,3,3,3,3,4,3,3,3,3,3,2,2
2,2,3,3,3,3,3,4,3,3,3,3,3,3,3,3,3,3,3,3,2,2
2,3,3,3,3,3,3,3,3,3,3,3,3,3,3,3,3,3,3,3,3,2
2,3,3,3,3,3,3,3,3,3,3,3,3,3,3,3,3,3,3,3,3,2
2,2,3,3,3,3,3,3,3,3,3,3,3,3,3,3,3,3,3,3,2,2
2,2,3,4,3,3,3,3,3,3,3,3,3,3,3,3,3,3,3,3,2,2
1,2,2,3,3,5,3,3,3,3,3,3,3,3,3,5,3,3,3,2,2,1
1,2,2,3,3,3,3,3,3,3,4,3,3,3,3,3,3,3,4,2,2,1
1,1,2,2,3,3,3,3,3,3,3,3,3,3,3,3,3,3,2,2,1,1
1,1,2,2,3,3,3,3,3,3,3,3,3,3,3,3,3,3,2,2,1,1
1,1,1,2,2,2,3,3,3,3,3,3,3,3,3,3,2,2,2,1,1,1
1,1,1,2,2,2,3,3,3,3,3,3,3,3,3,3,2,2,2,1,1,1
1,1,1,1,2,2,3,3,3,2,5,3,2,3,3,3,2,2,1,1,1,1
1,1,1,1,1,2,3,3,3,2,2,2,2,3,3,3,2,1,1,1,1,1
1,1,1,1,1,2,3,3,3,3,2,2,3,3,3,3,2,1,1,1,1,1
1,1,1,1,1,2,2,3,3,3,3,3,3,3,3,3,2,1,1,1,1,1
1,1,1,1,1,2,2,2,3,3,3,3,3,3,3,2,2,1,1,1,1,1
1,1,1,1,1,1,2,2,2,3,3,3,3,2,2,2,1,1,1,1,1,1
1,1,1,1,1,1,1,2,2,2,2,2,2,2,2,1,1,1,1,1,1,1
endlayer

layer
1,1,1,1,1,1,1,2,2,2,2,2,2,2,2,1,1,1,1,1,1,1
1,1,1,1,1,1,2,2,2,3,3,3,3,2,2,2,1,1,1,1,1,1
1,1,1,1,1,2,2,2,3,3,3,3,3,3,2,2,2,1,1,1,1,1
1,1,1,1,1,2,2,3,3,3,3,3,3,3,3,2,2,1,1,1,1,1
1,1,1,1,1,2,3,3,3,3,2,2,3,3,3,3,2,1,1,1,1,1
1,1,1,1,1,2,3,3,3,2,2,2,2,3,3,3,2,1,1,1,1,1
1,1,1,1,2,2,3,3,3,2,3,3,2,3,3,3,2,2,1,1,1,1
1,1,1,2,2,2,3,3,3,4,3,3,3,3,3,3,2,2,2,1,1,1
1,1,1,2,2,2,3,3,3,3,3,3,5,3,3,5,2,2,2,1,1,1
1,1,2,2,3,3,3,3,3,3,3,3,3,3,3,3,3,3,2,2,1,1
1,1,2,2,3,3,3,3,5,3,3,3,3,3,3,3,3,3,2,2,1,1
1,2,2,5,3,3,3,3,3,3,3,3,3,3,3,3,3,3,3,2,2,1
1,2,2,3,3,3,3,3,3,3,3,3,3,3,3,3,3,3,3,2,2,1
2,2,3,3,3,3,3,3,3,3,3,3,3,3,4,3,3,3,3,3,2,2
2,2,3,3,3,3,3,4,3,3,3,3,3,3,3,3,3,3,3,3,2,2
2,3,3,3,3,3,3,3,3,3,3,3,3,3,3,3,3,3,3,3,3,2
2,3,3,3,3,3,3,3,3,3,3,3,3,3,3,3,3,3,3,3,3,2
2,2,3,3,3,3,3,3,3,3,3,3,3,3,3,3,3,3,3,3,2,2
2,2,3,4,3,3,3,3,3,3,3,3,3,3,3,3,3,3,3,3,2,2
1,2,2,3,3,5,3,3,3,3,3,3,3,3,3,5,3,3,3,2,2,1
1,2,2,3,3,3,3,3,3,3,4,3,3,3,3,3,3,3,4,2,2,1
1,1,2,2,3,3,3,3,3,3,3,3,3,3,3,3,3,3,2,2,1,1
1,1,2,2,3,3,3,3,3,3,3,3,3,3,3,3,3,3,2,2,1,1
1,1,1,2,2,2,3,3,3,3,3,3,3,3,3,3,2,2,2,1,1,1
1,1,1,2,2,2,3,3,3,3,3,3,3,3,3,3,2,2,2,1,1,1
1,1,1,1,2,2,3,3,3,2,5,3,2,3,3,3,2,2,1,1,1,1
1,1,1,1,1,2,3,3,3,2,2,2,2,3,3,3,2,1,1,1,1,1
1,1,1,1,1,2,3,3,3,3,2,2,3,3,3,3,2,1,1,1,1,1
1,1,1,1,1,2,2,3,3,3,3,3,3,3,3,3,2,1,1,1,1,1
1,1,1,1,1,2,2,2,3,3,3,3,3,3,3,2,2,1,1,1,1,1
1,1,1,1,1,1,2,2,2,3,3,3,3,2,2,2,1,1,1,1,1,1
1,1,1,1,1,1,1,2,2,2,2,2,2,2,2,1,1,1,1,1,1,1
endlayer

layer
1,1,1,1,1,1,1,2,2,2,2,2,2,2,2,1,1,1,1,1,1,1
1,1,1,1,1,1,2,2,2,3,3,3,3,2,2,2,1,1,1,1,1,1
1,1,1,1,1,2,2,2,3,3,3,3,3,3,2,2,2,1,1,1,1,1
1,1,1,1,1,2,2,3,3,3,3,3,3,3,3,2,2,1,1,1,1,1
1,1,1,1,1,2,3,3,3,3,2,2,3,3,3,3,2,1,1,1,1,1
1,1,1,1,1,2,3,3,3,2,2,2,2,3,3,3,2,1,1,1,1,1
1,1,1,1,2,2,3,3,3,2,3,3,2,3,3,3,2,2,1,1,1,1
1,1,1,2,2,2,3,3,3,4,3,3,3,3,3,3,2,2,2,1,1,1
1,1,1,2,2,2,3,3,3,3,3,3,5,3,3,5,2,2,2,1,1,1
1,1,2,2,3,3,3,3,3,3,3,3,3,3,3,3,3,3,2,2,1,1
1,1,2,2,3,3,3,3,5,3,3,3,3,3,3,3,3,3,2,2,1,1
1,2,2,5,3,3,3,3,3,3,3,3,3,3,3,3,3,3,3,2,2,1
1,2,2,3,3,3,3,3,3,3,3,3,3,3,3,3,3,3,3,2,2,1
2,2,3,3,3,3,3,3,3,3,3,3,3,3,4,3,3,3,3,3,2,2
2,2,3,3,3,3,3,4,3,3,3,3,3,3,3,3,3,3,3,3,2,2
2,3,3,3,3,3,3,3,3,3,3,3,3,3,3,3,3,3,3,3,3,2
2,3,3,3,3,3,3,3,3,3,3,3,3,3,3,3,3,3,3,3,3,2
2,2,3,3,3,3,3,3,3,3,3,3,3,3,3,3,3,3,3,3,2,2
2,2,3,4,3,3,3,3,3,3,3,3,3,3,3,3,3,3,3,3,2,2
1,2,2,3,3,5,3,3,3,3,3,3,3,3,3,5,3,3,3,2,2,1
1,2,2,3,3,3,3,3,3,3,4,3,3,3,3,3,3,3,4,2,2,1
1,1,2,2,3,3,3,3,3,3,3,3,3,3,3,3,3,3,2,2,1,1
1,1,2,2,3,3,3,3,3,3,3,3,3,3,3,3,3,3,2,2,1,1
1,1,1,2,2,2,3,3,3,3,3,3,3,3,3,3,2,2,2,1,1,1
1,1,1,2,2,2,3,3,3,3,3,3,3,3,3,3,2,2,2,1,1,1
1,1,1,1,2,2,3,3,3,2,5,3,2,3,3,3,2,2,1,1,1,1
1,1,1,1,1,2,3,3,3,2,2,2,2,3,3,3,2,1,1,1,1,1
1,1,1,1,1,2,3,3,3,3,2,2,3,3,3,3,2,1,1,1,1,1
1,1,1,1,1,2,2,3,3,3,3,3,3,3,3,3,2,1,1,1,1,1
1,1,1,1,1,2,2,2,3,3,3,3,3,3,3,2,2,1,1,1,1,1
1,1,1,1,1,1,2,2,2,3,3,3,3,2,2,2,1,1,1,1,1,1
1,1,1,1,1,1,1,2,2,2,2,2,2,2,2,1,1,1,1,1,1,1
endlayer

layer
1,1,1,1,1,1,1,2,2,2,2,2,2,2,2,1,1,1,1,1,1,1
1,1,1,1,1,1,2,2,2,3,3,3,3,2,2,2,1,1,1,1,1,1
1,1,1,1,1,2,2,2,3,3,3,3,3,3,2,2,2,1,1,1,1,1
1,1,1,1,1,2,2,3,3,3,3,3,3,3,3,2,2,1,1,1,1,1
1,1,1,1,1,2,3,3,3,3,2,2,3,3,3,3,2,1,1,1,1,1
1,1,1,1,1,2,3,3,3,2,2,2,2,3,3,3,2,1,1,1,1,1
1,1,1,1,2,2,3,3,3,2,3,3,2,3,3,3,2,2,1,1,1,1
1,1,1,2,2,2,3,3,3,4,3,3,3,3,3,3,2,2,2,1,1,1
1,1,1,2,2,2,3,3,3,3,3,3,5,3,3,5,2,2,2,1,1,1
1,1,2,2,3,3,3,3,3,3,3,3,3,3,3,3,3,3,2,2,1,1
1,1,2,2,3,3,3,3,5,3,3,3,3,3,3,3,3,3,2,2,1,1
1,2,2,5,3,3,3,3,3,3,3,3,3,3,3,3,3,3,3,2,2,1
1,2,2,3,3,3,3,3,3,3,3,3,3,3,3,3,3,3,3,2,2,1
2,2,3,3,3,3,3,3,3,3,3,3,3,3,4,3,3,3,3,3,2,2
2,2,3,3,3,3,3,4,3,3,3,3,3,3,3,3,3,3,3,3,2,2
2,3,3,3,3,3,3,3,3,3,3,3,3,3,3,3,3,3,3,3,3,2
2,3,3,3,3,3,3,3,3,3,3,3,3,3,3,3,3,3,3,3,3,2
2,2,3,3,3,3,3,3,3,3,3,3,3,3,3,3,3,3,3,3,2,2
2,2,3,4,3,3,3,3,3,3,3,3,3,3,3,3,3,3,3,3,2,2
1,2,2,3,3,5,3,3,3,3,3,3,3,3,3,5,3,3,3,2,2,1
1,2,2,3,3,3,3,3,3,3,4,3,3,3,3,3,3,3,4,2,2,1
1,1,2,2,3,3,3,3,3,3,3,3,3,3,3,3,3,3,2,2,1,1
1,1,2,2,3,3,3,3,3,3,3,3,3,3,3,3,3,3,2,2,1,1
1,1,1,2,2,2,3,3,3,3,3,3,3,3,3,3,2,2,2,1,1,1
1,1,1,2,2,2,3,3,3,3,3,3,3,3,3,3,2,2,2,1,1,1
1,1,1,1,2,2,3,3,3,2,5,3,2,3,3,3,2,2,1,1,1,1
1,1,1,1,1,2,3,3,3,2,2,2,2,3,3,3,2,1,1,1,1,1
1,1,1,1,1,2,3,3,3,3,2,2,3,3,3,3,2,1,1,1,1,1
1,1,1,1,1,2,2,3,3,3,3,3,3,3,3,3,2,1,1,1,1,1
1,1,1,1,1,2,2,2,3,3,3,3,3,3,3,2,2,1,1,1,1,1
1,1,1,1,1,1,2,2,2,3,3,3,3,2,2,2,1,1,1,1,1,1
1,1,1,1,1,1,1,2,2,2,2,2,2,2,2,1,1,1,1,1,1,1
endlayer

layer
1,1,1,1,1,1,1,2,2,2,2,2,2,2,2,1,1,1,1,1,1,1
1,1,1,1,1,1,2,2,2,3,3,3,3,2,2,2,1,1,1,1,1,1
1,1,1,1,1,2,2,2,3,3,3,3,3,3,2,2,2,1,1,1,1,1
1,1,1,1,1,2,2,3,3,3,3,3,3,3,3,2,2,1,1,1,1,1
1,1,1,1,1,2,3,3,3,3,2,2,3,3,3,3,2,1,1,1,1,1
1,1,1,1,1,2,3,3,3,2,2,2,2,3,3,3,2,1,1,1,1,1
1,1,1,1,2,2,3,3,3,2,3,3,2,3,3,3,2,2,1,1,1,1
1,1,1,2,2,2,3,3,3,4,3,3,3,3,3,3,2,2,2,1,1,1
1,1,1,2,2,2,3,3,3,3,3,3,5,3,3,5,2,2,2,1,1,1
1,1,2,2,3,3,3,3,3,3,3,3,3,3,3,3,3,3,2,2,1,1
1,1,2,2,3,3,3,3,5,3,3,3,3,3,3,3,3,3,2,2,1,1
1,2,2,5,3,3,3,3,3,3,3,3,3,3,3,3,3,3,3,2,2,1
1,2,2,3,3,3,3,3,3,3,3,3,3,3,3,3,3,3,3,2,2,1
2,2,3,3,3,3,3,3,3,3,3,3,3,3,4,3,3,3,3,3,2,2
2,2,3,3,3,3,3,4,3,3,3,3,3,3,3,3,3,3,3,3,2,2
2,3,3,3,3,3,3,3,3,3,3,3,3,3,3,3,3,3,3,3,3,2
2,3,3,3,3,3,3,3,3,3,3,3,3,3,3,3,3,3,3,3,3,2
2,2,3,3,3,3,3,3,3,3,3,3,3,3,3,3,3,3,3,3,2,2
2,2,3,4,3,3,3,3,3,3,3,3,3,3,3,3,3,3,3,3,2,2
1,2,2,3,3,5,3,3,3,3,3,3,3,3,3,5,3,3,3,2,2,1
1,2,2,3,3,3,3,3,3,3,4,3,3,3,3,3,3,3,4,2,2,1
1,1,2,2,3,3,3,3,3,3,3,3,3,3,3,3,3,3,2,2,1,1
1,1,2,2,3,3,3,3,3,3,3,3,3,3,3,3,3,3,2,2,1,1
1,1,1,2,2,2,3,3,3,3,3,3,3,3,3,3,2,2,2,1,1,1
1,1,1,2,2,2,3,3,3,3,3,3,3,3,3,3,2,2,2,1,1,1
1,1,1,1,2,2,3,3,3,2,5,3,2,3,3,3,2,2,1,1,1,1
1,1,1,1,1,2,3,3,3,2,2,2,2,3,3,3,2,1,1,1,1,1
1,1,1,1,1,2,3,3,3,3,2,2,3,3,3,3,2,1,1,1,1,1
1,1,1,1,1,2,2,3,3,3,3,3,3,3,3,3,2,1,1,1,1,1
1,1,1,1,1,2,2,2,3,3,3,3,3,3,3,2,2,1,1,1,1,1
1,1,1,1,1,1,2,2,2,3,3,3,3,2,2,2,1,1,1,1,1,1
1,1,1,1,1,1,1,2,2,2,2,2,2,2,2,1,1,1,1,1,1,1
endlayer

layer
1,1,1,1,1,1,1,2,2,2,2,2,2,2,2,1,1,1,1,1,1,1
1,1,1,1,1,1,2,2,2,3,3,3,3,2,2,2,1,1,1,1,1,1
1,1,1,1,1,2,2,2,3,3,3,3,3,3,2,2,2,1,1,1,1,1
1,1,1,1,1,2,2,3,3,3,3,3,3,3,3,2,2,1,1,1,1,1
1,1,1,1,1,2,3,3,3,3,2,2,3,3,3,3,2,1,1,1,1,1
1,1,1,1,1,2,3,3,3,2,2,2,2,3,3,3,2,1,1,1,1,1
1,1,1,1,2,2,3,3,3,2,3,3,2,3,3,3,2,2,1,1,1,1
1,1,1,2,2,2,3,3,3,4,3,3,3,3,3,3,2,2,2,1,1,1
1,1,1,2,2,2,3,3,3,3,3,3,5,3,3,5,2,2,2,1,1,1
1,1,2,2,3,3,3,3,3,3,3,3,3,3,3,3,3,3,2,2,1,1
1,1,2,2,3,3,3,3,5,3,3,3,3,3,3,3,3,3,2,2,1,1
1,2,2,5,3,3,3,3,3,3,3,3,3,3,3,3,3,3,3,2,2,1
1,2,2,3,3,3,3,3,3,3,3,3,3,3,3,3,3,3,3,2,2,1
2,2,3,3,3,3,3,3,3,3,3,3,3,3,4,3,3,3,3,3,2,2
2,2,3,3,3,3,3,4,3,3,3,3,3,3,3,3,3,3,3,3,2,2
2,3,3,3,3,3,3,3,3,3,3,3,3,3,3,3,3,3,3,3,3,2
2,3,3,3,3,3,3,3,3,3,3,3,3,3,3,3,3,3,3,3,3,2
2,2,3,3,3,3,3,3,3,3,3,3,3,3,3,3,3,3,3,3,2,2
2,2,3,4,3,3,3,3,3,3,3,3,3,3,3,3,3,3,3,3,2,2
1,2,2,3,3,5,3,3,3,3,3,3,3,3,3,5,3,3,3,2,2,1
1,2,2,3,3,3,3,3,3,3,4,3,3,3,3,3,3,3,4,2,2,1
1,1,2,2,3,3,3,3,3,3,3,3,3,3,3,3,3,3,2,2,1,1
1,1,2,2,3,3,3,3,3,3,3,3,3,3,3,3,3,3,2,2,1,1
1,1,1,2,2,2,3,3,3,3,3,3,3,3,3,3,2,2,2,1,1,1
1,1,1,2,2,2,3,3,3,3,3,3,3,3,3,3,2,2,2,1,1,1
1,1,1,1,2,2,3,3,3,2,5,3,2,3,3,3,2,2,1,1,1,1
1,1,1,1,1,2,3,3,3,2,2,2,2,3,3,3,2,1,1,1,1,1
1,1,1,1,1,2,3,3,3,3,2,2,3,3,3,3,2,1,1,1,1,1
1,1,1,1,1,2,2,3,3,3,3,3,3,3,3,3,2,1,1,1,1,1
1,1,1,1,1,2,2,2,3,3,3,3,3,3,3,2,2,1,1,1,1,1
1,1,1,1,1,1,2,2,2,3,3,3,3,2,2,2,1,1,1,1,1,1
1,1,1,1,1,1,1,2,2,2,2,2,2,2,2,1,1,1,1,1,1,1
endlayer


layer
1,1,1,1,1,1,1,2,2,2,2,2,2,2,2,1,1,1,1,1,1,1
1,1,1,1,1,1,2,2,2,3,3,3,3,2,2,2,1,1,1,1,1,1
1,1,1,1,1,2,2,2,3,3,3,3,3,3,2,2,2,1,1,1,1,1
1,1,1,1,1,2,2,3,3,3,3,3,3,3,3,2,2,1,1,1,1,1
1,1,1,1,1,2,3,3,3,3,2,2,3,3,3,3,2,1,1,1,1,1
1,1,1,1,1,2,3,3,3,2,2,2,2,3,3,3,2,1,1,1,1,1
1,1,1,1,2,2,3,3,3,2,3,3,2,3,3,3,2,2,1,1,1,1
1,1,1,2,2,2,3,3,3,4,3,3,3,3,3,3,2,2,2,1,1,1
1,1,1,2,2,2,3,3,3,3,3,3,5,3,3,5,2,2,2,1,1,1
1,1,2,2,3,3,3,3,3,3,3,3,3,3,3,3,3,3,2,2,1,1
1,1,2,2,3,3,3,3,5,3,3,3,3,3,3,3,3,3,2,2,1,1
1,2,2,5,3,3,3,3,3,3,3,3,3,3,3,3,3,3,3,2,2,1
1,2,2,3,3,3,3,3,3,3,3,3,3,3,3,3,3,3,3,2,2,1
2,2,3,3,3,3,3,3,3,3,3,3,3,3,4,3,3,3,3,3,2,2
2,2,3,3,3,3,3,4,3,3,3,3,3,3,3,3,3,3,3,3,2,2
2,3,3,3,3,3,3,3,3,3,3,3,3,3,3,3,3,3,3,3,3,2
2,3,3,3,3,3,3,3,3,3,3,3,3,3,3,3,3,3,3,3,3,2
2,2,3,3,3,3,3,3,3,3,3,3,3,3,3,3,3,3,3,3,2,2
2,2,3,4,3,3,3,3,3,3,3,3,3,3,3,3,3,3,3,3,2,2
1,2,2,3,3,5,3,3,3,3,3,3,3,3,3,5,3,3,3,2,2,1
1,2,2,3,3,3,3,3,3,3,4,3,3,3,3,3,3,3,4,2,2,1
1,1,2,2,3,3,3,3,3,3,3,3,3,3,3,3,3,3,2,2,1,1
1,1,2,2,3,3,3,3,3,3,3,3,3,3,3,3,3,3,2,2,1,1
1,1,1,2,2,2,3,3,3,3,3,3,3,3,3,3,2,2,2,1,1,1
1,1,1,2,2,2,3,3,3,3,3,3,3,3,3,3,2,2,2,1,1,1
1,1,1,1,2,2,3,3,3,2,5,3,2,3,3,3,2,2,1,1,1,1
1,1,1,1,1,2,3,3,3,2,2,2,2,3,3,3,2,1,1,1,1,1
1,1,1,1,1,2,3,3,3,3,2,2,3,3,3,3,2,1,1,1,1,1
1,1,1,1,1,2,2,3,3,3,3,3,3,3,3,3,2,1,1,1,1,1
1,1,1,1,1,2,2,2,3,3,3,3,3,3,3,2,2,1,1,1,1,1
1,1,1,1,1,1,2,2,2,3,3,3,3,2,2,2,1,1,1,1,1,1
1,1,1,1,1,1,1,2,2,2,2,2,2,2,2,1,1,1,1,1,1,1
endlayer

layer
1,1,1,1,1,1,1,1,1,1,1,1,1,1,1,1,1,1,1,1,1,1
1,1,1,1,1,1,1,1,1,6,6,6,6,1,1,1,1,1,1,1,1,1
1,1,1,1,1,1,1,1,6,7,8,8,7,6,1,1,1,1,1,1,1,1
1,1,1,1,1,1,1,6,9,10,6,6,10,9,6,1,1,1,1,1,1,1
1,1,1,1,1,1,6,11,12,6,13,13,6,12,11,6,1,1,1,1,1,1
1,1,1,1,1,1,6,14,6,15,16,16,15,6,14,6,1,1,1,1,1,1
1,1,1,1,1,1,6,17,6,18,6,6,18,6,17,6,1,1,1,1,1,1
1,1,1,1,1,19,6,17,6,6,17,17,6,6,17,6,19,1,1,1,1,1
1,1,1,1,19,20,6,17,17,17,17,17,17,17,17,6,20,19,1,1,1,1
1,1,1,1,6,6,17,17,17,17,17,17,17,17,17,17,6,6,1,1,1,1
1,1,1,1,6,17,17,17,17,17,17,17,17,17,17,17,17,6,1,1,1,1
1,1,1,6,17,17,17,17,17,17,17,17,17,17,17,17,17,17,6,1,1,1
1,1,1,6,17,17,17,17,17,17,17,17,17,17,17,17,17,17,6,1,1,1
1,1,6,17,17,17,17,17,17,17,3,3,17,17,17,17,17,17,17,6,1,1
1,1,6,17,17,17,17,17,17,3,3,3,3,17,17,17,17,17,17,6,1,1
1,6,17,17,17,17,17,17,3,3,3,3,3,3,17,17,17,17,17,17,6,1
1,6,17,17,17,17,17,17,3,3,3,3,3,3,17,17,17,17,17,17,6,1
1,1,6,17,17,17,17,17,17,3,3,3,3,17,17,17,17,17,17,6,1,1
1,1,6,17,17,17,17,17,17,17,3,3,17,17,17,17,17,17,17,6,1,1
1,1,1,6,17,17,17,17,17,17,17,17,17,17,17,17,17,17,6,1,1,1
1,1,1,6,17,17,17,17,17,17,17,17,17,17,17,17,17,17,6,1,1,1
1,1,1,1,6,17,17,17,17,17,17,17,17,17,17,17,17,6,1,1,1,1
1,1,1,1,6,6,17,17,17,17,17,17,17,17,17,17,6,6,1,1,1,1
1,1,1,1,19,20,6,17,17,17,17,17,17,17,17,6,20,19,1,1,1,1
1,1,1,1,1,19,6,17,6,6,17,17,6,6,17,6,19,1,1,1,1,1
1,1,1,1,1,1,6,17,6,18,6,6,18,6,17,6,1,1,1,1,1,1
1,1,1,1,1,1,6,14,6,15,16,16,15,6,14,6,1,1,1,1,1,1
1,1,1,1,1,1,6,11,12,6,13,13,6,12,11,6,1,1,1,1,1,1
1,1,1,1,1,1,1,6,9,10,6,6,10,9,12,6,1,1,1,1,1,1
1,1,1,1,1,1,1,1,6,7,8,8,7,6,6,1,1,1,1,1,1,1
1,1,1,1,1,1,1,1,1,6,6,6,6,1,1,1,1,1,1,1,1,1
1,1,1,1,1,1,1,1,1,1,1,1,1,1,1,1,1,1,1,1,1,1
endlayer


layer
1,1,1,1,1,1,1,1,0,0,0,0,0,0,1,1,1,1,1,1,1,1
1,1,1,1,1,1,0,0,0,0,0,0,0,0,0,0,1,1,1,1,1,1
1,1,1,1,1,0,0,0,0,0,0,0,0,0,0,0,0,1,1,1,1,1
1,1,1,1,0,0,0,0,0,0,0,0,0,0,0,0,0,0,1,1,1,1
1,1,1,0,0,0,0,0,0,0,0,0,0,0,0,0,0,0,0,1,1,1
1,1,0,0,0,0,0,0,0,0,0,0,0,0,0,0,0,0,0,0,1,1
1,0,0,0,0,0,0,0,0,0,0,0,0,0,0,0,0,0,0,0,0,1
1,0,0,0,0,0,0,0,0,0,0,0,0,0,0,0,0,0,0,0,0,1
0,0,0,0,0,0,0,0,0,0,0,0,0,0,0,0,0,0,0,0,0,0
0,0,0,0,0,0,0,0,0,0,0,0,0,0,0,0,0,0,0,0,0,0
0,0,0,0,0,0,0,0,0,0,21,21,0,0,0,0,0,0,0,0,0,0
0,0,0,0,0,0,0,0,0,0,0,0,0,0,0,0,0,0,0,0,0,0
0,0,0,0,0,0,0,0,0,0,0,0,0,0,0,0,0,0,0,0,0,0
0,0,0,0,0,0,0,0,0,0,0,0,0,0,0,0,0,0,0,0,0,0
0,0,0,0,0,0,0,0,0,0,3,3,0,0,0,0,0,0,0,0,0,0
0,0,0,0,0,21,0,0,0,3,3,3,3,0,0,0,21,0,0,0,0,0
0,0,0,0,0,21,0,0,0,3,3,3,3,0,0,0,21,0,0,0,0,0
0,0,0,0,0,0,0,0,0,0,3,3,0,0,0,0,0,0,0,0,0,0
0,0,0,0,0,0,0,0,0,0,0,0,0,0,0,0,0,0,0,0,0,0
0,0,0,0,0,0,0,0,0,0,0,0,0,0,0,0,0,0,0,0,0,0
0,0,0,0,0,0,0,0,0,0,0,0,0,0,0,0,0,0,0,0,0,0
0,0,0,0,0,0,0,0,0,0,21,21,0,0,0,0,0,0,0,0,0,0
0,0,0,0,0,0,0,0,0,0,0,0,0,0,0,0,0,0,0,0,0,0
0,0,0,0,0,0,0,0,0,0,0,0,0,0,0,0,0,0,0,0,0,0
1,0,0,0,0,0,0,0,0,0,0,0,0,0,0,0,0,0,0,0,0,1
1,0,0,0,0,0,0,0,0,0,0,0,0,0,0,0,0,0,0,0,0,1
1,1,0,0,0,0,0,0,0,0,0,0,0,0,0,0,0,0,0,0,1,1
1,1,1,0,0,0,0,0,0,0,0,0,0,0,0,0,0,0,0,1,1,1
1,1,1,1,0,0,0,0,0,0,0,0,0,0,0,0,0,0,1,1,1,1
1,1,1,1,1,0,0,0,0,0,0,0,0,0,0,0,0,1,1,1,1,1
1,1,1,1,1,1,0,0,0,0,0,0,0,0,0,0,1,1,1,1,1,1
1,1,1,1,1,1,1,1,0,0,0,0,0,0,1,1,1,1,1,1,1,1
endlayer

layer
1,1,1,1,1,1,0,0,0,0,0,0,0,0,0,0,1,1,1,1,1,1
1,1,1,1,1,0,0,0,0,0,0,0,0,0,0,0,0,1,1,1,1,1
1,1,1,1,0,0,0,0,0,0,0,0,0,0,0,0,0,0,1,1,1,1
1,1,1,0,0,0,0,0,0,0,0,0,0,0,0,0,0,0,0,1,1,1
1,1,0,0,0,0,0,0,0,0,0,0,0,0,0,0,0,0,0,0,1,1
1,0,0,0,0,0,0,0,0,0,0,0,0,0,0,0,0,0,0,0,0,1
0,0,0,0,0,0,0,0,0,0,0,0,0,0,0,0,0,0,0,0,0,0
0,0,0,0,0,0,0,0,0,0,0,0,0,0,0,0,0,0,0,0,0,0
0,0,0,0,0,0,0,0,0,0,0,0,0,0,0,0,0,0,0,0,0,0
0,0,0,0,0,0,0,0,0,0,0,0,0,0,0,0,0,0,0,0,0,0
0,0,0,0,0,0,0,0,0,0,21,21,0,0,0,0,0,0,0,0,0,0
0,0,0,0,0,0,0,0,0,0,0,0,0,0,0,0,0,0,0,0,0,0
0,0,0,0,0,0,0,0,0,0,0,0,0,0,0,0,0,0,0,0,0,0
0,0,0,0,0,0,0,0,0,0,0,0,0,0,0,0,0,0,0,0,0,0
0,0,0,0,0,0,0,0,0,23,22,22,22,0,0,0,0,0,0,0,0,0
0,0,0,0,0,21,0,0,0,23,3,3,24,0,0,0,21,0,0,0,0,0
0,0,0,0,0,21,0,0,0,23,3,3,24,0,0,0,21,0,0,0,0,0
0,0,0,0,0,0,0,0,0,23,25,25,24,0,0,0,0,0,0,0,0,0
0,0,0,0,0,0,0,0,0,0,0,0,0,0,0,0,0,0,0,0,0,0
0,0,0,0,0,0,0,0,0,0,0,0,0,0,0,0,0,0,0,0,0,0
0,0,0,0,0,0,0,0,0,0,0,0,0,0,0,0,0,0,0,0,0,0
0,0,0,0,0,0,0,0,0,0,21,21,0,0,0,0,0,0,0,0,0,0
0,0,0,0,0,0,0,0,0,0,0,0,0,0,0,0,0,0,0,0,0,0
0,0,0,0,0,0,0,0,0,0,0,0,0,0,0,0,0,0,0,0,0,0
0,0,0,0,0,0,0,0,0,0,0,0,0,0,0,0,0,0,0,0,0,0
0,0,0,0,0,0,0,0,0,0,0,0,0,0,0,0,0,0,0,0,0,0
1,0,0,0,0,0,0,0,0,0,0,0,0,0,0,0,0,0,0,0,0,1
1,1,0,0,0,0,0,0,0,0,0,0,0,0,0,0,0,0,0,0,1,1
1,1,1,0,0,0,0,0,0,0,0,0,0,0,0,0,0,0,0,1,1,1
1,1,1,1,0,0,0,0,0,0,0,0,0,0,0,0,0,0,1,1,1,1
1,1,1,1,1,0,0,0,0,0,0,0,0,0,0,0,0,1,1,1,1,1
1,1,1,1,1,1,0,0,0,0,0,0,0,0,0,0,1,1,1,1,1,1
endlayer

layer
1,1,1,1,1,0,0,0,0,0,0,0,0,0,0,0,0,1,1,1,1,1
1,1,1,1,0,0,0,0,0,0,0,0,0,0,0,0,0,0,1,1,1,1
1,1,1,0,0,0,0,0,0,0,0,0,0,0,0,0,0,0,0,1,1,1
1,1,0,0,0,0,0,0,0,0,0,0,0,0,0,0,0,0,0,0,1,1
1,0,0,0,0,0,0,0,0,0,0,0,0,0,0,0,0,0,0,0,0,1
0,0,0,0,0,0,0,0,0,0,0,0,0,0,0,0,0,0,0,0,0,0
0,0,0,0,0,0,0,0,0,0,0,0,0,0,0,0,0,0,0,0,0,0
0,0,0,0,0,0,0,0,0,0,0,0,0,0,0,0,0,0,0,0,0,0
0,0,0,0,0,0,0,0,0,0,0,0,0,0,0,0,0,0,0,0,0,0
0,0,0,0,0,0,0,0,0,0,0,0,0,0,0,0,0,0,0,0,0,0
0,0,0,0,0,0,0,0,0,0,21,21,0,0,0,0,0,0,0,0,0,0
0,0,0,0,0,0,0,0,0,0,0,0,0,0,0,0,0,0,0,0,0,0
0,0,0,0,0,0,0,0,0,0,0,0,0,0,0,0,0,0,0,0,0,0
0,0,0,0,0,0,0,0,0,0,0,0,0,0,0,0,0,0,0,0,0,0
0,0,0,0,0,0,0,0,0,0,0,0,0,0,0,0,0,0,0,0,0,0
0,0,0,0,0,21,0,0,0,0,3,3,0,0,0,0,21,0,0,0,0,0
0,0,0,0,0,21,0,0,0,0,4,3,0,0,0,0,21,0,0,0,0,0
0,0,0,0,0,0,0,0,0,0,0,0,0,0,0,0,0,0,0,0,0,0
0,0,0,0,0,0,0,0,0,0,0,0,0,0,0,0,0,0,0,0,0,0
0,0,0,0,0,0,0,0,0,0,0,0,0,0,0,0,0,0,0,0,0,0
0,0,0,0,0,0,0,0,0,0,0,0,0,0,0,0,0,0,0,0,0,0
0,0,0,0,0,0,0,0,0,0,21,21,0,0,0,0,0,0,0,0,0,0
0,0,0,0,0,0,0,0,0,0,0,0,0,0,0,0,0,0,0,0,0,0
0,0,0,0,0,0,0,0,0,0,0,0,0,0,0,0,0,0,0,0,0,0
0,0,0,0,0,0,0,0,0,0,0,0,0,0,0,0,0,0,0,0,0,0
0,0,0,0,0,0,0,0,0,0,0,0,0,0,0,0,0,0,0,0,0,0
0,0,0,0,0,0,0,0,0,0,0,0,0,0,0,0,0,0,0,0,0,0
1,0,0,0,0,0,0,0,0,0,0,0,0,0,0,0,0,0,0,0,0,1
1,1,0,0,0,0,0,0,0,0,0,0,0,0,0,0,0,0,0,0,1,1
1,1,1,0,0,0,0,0,0,0,0,0,0,0,0,0,0,0,0,1,1,1
1,1,1,1,0,0,0,0,0,0,0,0,0,0,0,0,0,0,1,1,1,1
1,1,1,1,1,0,0,0,0,0,0,0,0,0,0,0,0,1,1,1,1,1
endlayer

layer
1,1,1,1,0,0,0,0,0,0,0,0,0,0,0,0,0,0,1,1,1,1
1,1,1,0,0,0,0,0,0,0,0,0,0,0,0,0,0,0,0,1,1,1
1,1,0,0,0,0,0,0,0,0,0,0,0,0,0,0,0,0,0,0,1,1
1,0,0,0,0,0,0,0,0,0,0,0,0,0,0,0,0,0,0,0,0,1
0,0,0,0,0,0,0,0,0,0,0,0,0,0,0,0,0,0,0,0,0,0
0,0,0,0,0,0,0,0,0,0,0,0,0,0,0,0,0,0,0,0,0,0
0,0,0,0,0,0,0,0,0,0,0,0,0,0,0,0,0,0,0,0,0,0
0,0,0,0,0,0,0,0,0,0,0,0,0,0,0,0,0,0,0,0,0,0
0,0,0,0,0,0,0,0,0,0,0,0,0,0,0,0,0,0,0,0,0,0
0,0,0,0,0,0,0,0,0,0,0,0,0,0,0,0,0,0,0,0,0,0
0,0,0,0,0,0,0,0,0,0,21,21,0,0,0,0,0,0,0,0,0,0
0,0,0,0,0,0,0,0,0,0,0,0,0,0,0,0,0,0,0,0,0,0
0,0,0,0,0,0,0,0,0,0,0,0,0,0,0,0,0,0,0,0,0,0
0,0,0,0,0,0,0,0,0,0,0,0,0,0,0,0,0,0,0,0,0,0
0,0,0,0,0,0,0,0,0,0,0,0,0,0,0,0,0,0,0,0,0,0
0,0,0,0,0,21,0,0,0,0,3,3,0,0,0,0,21,0,0,0,0,0
0,0,0,0,0,21,0,0,0,0,3,3,0,0,0,0,21,0,0,0,0,0
0,0,0,0,0,0,0,0,0,0,0,0,0,0,0,0,0,0,0,0,0,0
0,0,0,0,0,0,0,0,0,0,0,0,0,0,0,0,0,0,0,0,0,0
0,0,0,0,0,0,0,0,0,0,0,0,0,0,0,0,0,0,0,0,0,0
0,0,0,0,0,0,0,0,0,0,0,0,0,0,0,0,0,0,0,0,0,0
0,0,0,0,0,0,0,0,0,0,21,21,0,0,0,0,0,0,0,0,0,0
0,0,0,0,0,0,0,0,0,0,0,0,0,0,0,0,0,0,0,0,0,0
0,0,0,0,0,0,0,0,0,0,0,0,0,0,0,0,0,0,0,0,0,0
0,0,0,0,0,0,0,0,0,0,0,0,0,0,0,0,0,0,0,0,0,0
0,0,0,0,0,0,0,0,0,0,0,0,0,0,0,0,0,0,0,0,0,0
0,0,0,0,0,0,0,0,0,0,0,0,0,0,0,0,0,0,0,0,0,0
0,0,0,0,0,0,0,0,0,0,0,0,0,0,0,0,0,0,0,0,0,0
1,0,0,0,0,0,0,0,0,0,0,0,0,0,0,0,0,0,0,0,0,1
1,1,0,0,0,0,0,0,0,0,0,0,0,0,0,0,0,0,0,0,1,1
1,1,1,0,0,0,0,0,0,0,0,0,0,0,0,0,0,0,0,1,1,1
1,1,1,1,0,0,0,0,0,0,0,0,0,0,0,0,0,0,1,1,1,1
endlayer

layer
1,1,1,0,0,0,0,0,0,0,0,0,0,0,0,0,0,0,0,1,1,1
1,1,0,0,0,0,0,0,0,0,0,0,0,0,0,0,0,0,0,0,1,1
1,0,0,0,0,0,0,0,0,0,0,0,0,0,0,0,0,0,0,0,0,1
0,0,0,0,0,0,0,0,0,0,0,0,0,0,0,0,0,0,0,0,0,0
0,0,0,0,0,0,0,0,0,0,0,0,0,0,0,0,0,0,0,0,0,0
0,0,0,0,0,0,0,0,0,0,0,0,0,0,0,0,0,0,0,0,0,0
0,0,0,0,0,0,0,0,0,0,0,0,0,0,0,0,0,0,0,0,0,0
0,0,0,0,0,0,0,0,0,0,0,0,0,0,0,0,0,0,0,0,0,0
0,0,0,0,0,0,0,0,0,0,0,0,0,0,0,0,0,0,0,0,0,0
0,0,0,0,0,0,0,0,0,0,0,0,0,0,0,0,0,0,0,0,0,0
0,0,0,0,0,0,0,0,0,0,21,21,0,0,0,0,0,0,0,0,0,0
0,0,0,0,0,0,0,0,0,0,0,0,0,0,0,0,0,0,0,0,0,0
0,0,0,0,0,0,0,0,0,0,0,0,0,0,0,0,0,0,0,0,0,0
0,0,0,0,0,0,0,0,0,0,0,0,0,0,0,0,0,0,0,0,0,0
0,0,0,0,0,0,0,0,0,0,0,0,0,0,0,0,0,0,0,0,0,0
0,0,0,0,0,21,0,0,0,0,3,5,0,0,0,0,21,0,0,0,0,0
0,0,0,0,0,21,0,0,0,0,3,3,0,0,0,0,21,0,0,0,0,0
0,0,0,0,0,0,0,0,0,0,0,0,0,0,0,0,0,0,0,0,0,0
0,0,0,0,0,0,0,0,0,0,0,0,0,0,0,0,0,0,0,0,0,0
0,0,0,0,0,0,0,0,0,0,0,0,0,0,0,0,0,0,0,0,0,0
0,0,0,0,0,0,0,0,0,0,0,0,0,0,0,0,0,0,0,0,0,0
0,0,0,0,0,0,0,0,0,0,21,21,0,0,0,0,0,0,0,0,0,0
0,0,0,0,0,0,0,0,0,0,0,0,0,0,0,0,0,0,0,0,0,0
0,0,0,0,0,0,0,0,0,0,0,0,0,0,0,0,0,0,0,0,0,0
0,0,0,0,0,0,0,0,0,0,0,0,0,0,0,0,0,0,0,0,0,0
0,0,0,0,0,0,0,0,0,0,0,0,0,0,0,0,0,0,0,0,0,0
0,0,0,0,0,0,0,0,0,0,0,0,0,0,0,0,0,0,0,0,0,0
0,0,0,0,0,0,0,0,0,0,0,0,0,0,0,0,0,0,0,0,0,0
0,0,0,0,0,0,0,0,0,0,0,0,0,0,0,0,0,0,0,0,0,0
1,0,0,0,0,0,0,0,0,0,0,0,0,0,0,0,0,0,0,0,0,1
1,1,0,0,0,0,0,0,0,0,0,0,0,0,0,0,0,0,0,0,1,1
1,1,1,0,0,0,0,0,0,0,0,0,0,0,0,0,0,0,0,1,1,1
endlayer

layer
1,1,0,0,0,0,0,0,0,0,0,0,0,0,0,0,0,0,0,0,1,1
1,0,0,0,0,0,0,0,0,0,0,0,0,0,0,0,0,0,0,0,0,1
0,0,0,0,0,0,0,0,0,0,0,0,0,0,0,0,0,0,0,0,0,0
0,0,0,0,0,0,0,0,0,0,0,0,0,0,0,0,0,0,0,0,0,0
0,0,0,0,0,0,0,0,0,0,0,0,0,0,0,0,0,0,0,0,0,0
0,0,0,0,0,0,0,0,0,0,0,0,0,0,0,0,0,0,0,0,0,0
0,0,0,0,0,0,0,0,0,0,0,0,0,0,0,0,0,0,0,0,0,0
0,0,0,0,0,0,0,0,0,0,0,0,0,0,0,0,0,0,0,0,0,0
0,0,0,0,0,0,0,0,0,0,0,0,0,0,0,0,0,0,0,0,0,0
0,0,0,0,0,0,0,0,0,0,0,0,0,0,0,0,0,0,0,0,0,0
0,0,0,0,0,0,0,0,0,0,21,21,0,0,0,0,0,0,0,0,0,0
0,0,0,0,0,0,0,0,0,5,3,3,3,0,0,0,0,0,0,0,0,0
0,0,0,0,0,0,0,0,0,3,3,3,3,0,0,0,0,0,0,0,0,0
0,0,0,0,0,0,0,0,4,3,3,3,3,3,0,0,0,0,0,0,0,0
0,0,0,0,0,0,3,3,3,3,3,3,3,3,3,3,0,0,0,0,0,0
0,0,0,0,0,21,3,3,3,3,3,3,3,3,3,3,21,0,0,0,0,0
0,0,0,0,0,21,3,3,3,3,3,3,3,3,3,3,21,0,0,0,0,0
0,0,0,0,0,0,5,3,3,3,3,3,3,3,3,4,0,0,0,0,0,0
0,0,0,0,0,0,0,0,3,3,3,3,3,3,0,0,0,0,0,0,0,0
0,0,0,0,0,0,0,0,0,3,3,3,3,0,0,0,0,0,0,0,0,0
0,0,0,0,0,0,0,0,0,3,3,3,3,0,0,0,0,0,0,0,0,0
0,0,0,0,0,0,0,0,0,0,21,21,0,0,0,0,0,0,0,0,0,0
0,0,0,0,0,0,0,0,0,0,0,0,0,0,0,0,0,0,0,0,0,0
0,0,0,0,0,0,0,0,0,0,0,0,0,0,0,0,0,0,0,0,0,0
0,0,0,0,0,0,0,0,0,0,0,0,0,0,0,0,0,0,0,0,0,0
0,0,0,0,0,0,0,0,0,0,0,0,0,0,0,0,0,0,0,0,0,0
0,0,0,0,0,0,0,0,0,0,0,0,0,0,0,0,0,0,0,0,0,0
0,0,0,0,0,0,0,0,0,0,0,0,0,0,0,0,0,0,0,0,0,0
0,0,0,0,0,0,0,0,0,0,0,0,0,0,0,0,0,0,0,0,0,0
0,0,0,0,0,0,0,0,0,0,0,0,0,0,0,0,0,0,0,0,0,0
1,0,0,0,0,0,0,0,0,0,0,0,0,0,0,0,0,0,0,0,0,1
1,1,0,0,0,0,0,0,0,0,0,0,0,0,0,0,0,0,0,0,1,1
endlayer

layer
1,0,0,0,0,0,0,0,0,0,0,0,0,0,0,0,0,0,0,0,0,1
0,0,0,0,0,0,0,0,0,0,0,0,0,0,0,0,0,0,0,0,0,0
0,0,0,0,0,0,0,0,0,0,0,0,0,0,0,0,0,0,0,0,0,0
0,0,0,0,0,0,0,0,0,0,0,0,0,0,0,0,0,0,0,0,0,0
0,0,0,0,0,0,0,0,0,0,0,0,0,0,0,0,0,0,0,0,0,0
0,0,0,0,0,0,0,0,0,0,0,0,0,0,0,0,0,0,0,0,0,0
0,0,0,0,0,0,0,0,0,0,0,0,0,0,0,0,0,0,0,0,0,0
0,0,0,0,0,0,0,0,0,0,0,0,0,0,0,0,0,0,0,0,0,0
0,0,0,0,0,0,0,0,0,0,0,0,0,0,0,0,0,0,0,0,0,0
0,0,0,0,0,0,0,0,0,0,0,0,0,0,0,0,0,0,0,0,0,0
0,0,0,0,0,0,0,0,0,0,11,11,0,0,0,0,0,0,0,0,0,0
0,0,0,0,0,0,0,0,0,6,14,14,6,0,0,0,0,0,0,0,0,0
0,0,0,0,0,0,0,0,0,6,21,21,6,0,0,0,0,0,0,0,0,0
0,0,0,0,0,0,0,0,6,17,17,17,17,6,0,0,0,0,0,0,0,0
0,0,0,0,0,0,6,6,17,17,17,17,17,17,6,6,0,0,0,0,0,0
0,0,0,0,0,11,14,21,17,17,3,3,17,17,21,14,11,0,0,0,0,0
0,0,0,0,0,11,14,21,17,17,3,3,17,17,21,14,11,0,0,0,0,0
0,0,0,0,0,0,6,6,17,17,17,17,17,17,6,6,0,0,0,0,0,0
0,0,0,0,0,0,0,0,6,17,17,17,17,6,0,0,0,0,0,0,0,0
0,0,0,0,0,0,0,0,0,6,21,21,6,0,0,0,0,0,0,0,0,0
0,0,0,0,0,0,0,0,0,6,14,14,6,0,0,0,0,0,0,0,0,0
0,0,0,0,0,0,0,0,0,0,11,11,0,0,0,0,0,0,0,0,0,0
0,0,0,0,0,0,0,0,0,0,0,0,0,0,0,0,0,0,0,0,0,0
0,0,0,0,0,0,0,0,0,0,0,0,0,0,0,0,0,0,0,0,0,0
0,0,0,0,0,0,0,0,0,0,0,0,0,0,0,0,0,0,0,0,0,0
0,0,0,0,0,0,0,0,0,0,0,0,0,0,0,0,0,0,0,0,0,0
0,0,0,0,0,0,0,0,0,0,0,0,0,0,0,0,0,0,0,0,0,0
0,0,0,0,0,0,0,0,0,0,0,0,0,0,0,0,0,0,0,0,0,0
0,0,0,0,0,0,0,0,0,0,0,0,0,0,0,0,0,0,0,0,0,0
0,0,0,0,0,0,0,0,0,0,0,0,0,0,0,0,0,0,0,0,0,0
0,0,0,0,0,0,0,0,0,0,0,0,0,0,0,0,0,0,0,0,0,0
1,0,0,0,0,0,0,0,0,0,0,0,0,0,0,0,0,0,0,0,0,1
endlayer

layer
1,0,0,0,0,0,0,0,0,0,0,0,0,0,0,0,0,0,0,0,0,1
0,0,0,0,0,0,0,0,0,0,0,0,0,0,0,0,0,0,0,0,0,0
0,0,0,0,0,0,0,0,0,0,0,0,0,0,0,0,0,0,0,0,0,0
0,0,0,0,0,0,0,0,0,0,0,0,0,0,0,0,0,0,0,0,0,0
0,0,0,0,0,0,0,0,0,0,0,0,0,0,0,0,0,0,0,0,0,0
0,0,0,0,0,0,0,0,0,0,0,0,0,0,0,0,0,0,0,0,0,0
0,0,0,0,0,0,0,0,0,0,0,0,0,0,0,0,0,0,0,0,0,0
0,0,0,0,0,0,0,0,0,0,0,0,0,0,0,0,0,0,0,0,0,0
0,0,0,0,0,0,0,0,0,0,0,0,0,0,0,0,0,0,0,0,0,0
0,0,0,0,0,0,0,0,0,0,0,0,0,0,0,0,0,0,0,0,0,0
0,0,0,0,0,0,0,0,0,0,0,0,0,0,0,0,0,0,0,0,0,0
0,0,0,0,0,0,0,0,0,0,0,0,0,0,0,0,0,0,0,0,0,0
0,0,0,0,0,0,0,0,0,0,21,21,0,0,0,0,0,0,0,0,0,0
0,0,0,0,0,0,0,0,0,0,0,0,0,0,0,0,0,0,0,0,0,0
0,0,0,0,0,0,0,0,0,0,0,0,0,0,0,0,0,0,0,0,0,0
0,0,0,0,0,0,0,21,0,0,3,3,0,0,21,0,0,0,0,0,0,0
0,0,0,0,0,0,0,21,14,0,3,3,0,0,21,0,0,0,0,0,0,0
0,0,0,0,0,0,0,0,0,0,0,0,0,0,0,0,0,0,0,0,0,0
0,0,0,0,0,0,0,0,0,0,0,0,0,0,0,0,0,0,0,0,0,0
0,0,0,0,0,0,0,0,0,0,21,21,0,0,0,0,0,0,0,0,0,0
0,0,0,0,0,0,0,0,0,0,0,0,0,0,0,0,0,0,0,0,0,0
0,0,0,0,0,0,0,0,0,0,0,0,0,0,0,0,0,0,0,0,0,0
0,0,0,0,0,0,0,0,0,0,0,0,0,0,0,0,0,0,0,0,0,0
0,0,0,0,0,0,0,0,0,0,0,0,0,0,0,0,0,0,0,0,0,0
0,0,0,0,0,0,0,0,0,0,0,0,0,0,0,0,0,0,0,0,0,0
0,0,0,0,0,0,0,0,0,0,0,0,0,0,0,0,0,0,0,0,0,0
0,0,0,0,0,0,0,0,0,0,0,0,0,0,0,0,0,0,0,0,0,0
0,0,0,0,0,0,0,0,0,0,0,0,0,0,0,0,0,0,0,0,0,0
0,0,0,0,0,0,0,0,0,0,0,0,0,0,0,0,0,0,0,0,0,0
0,0,0,0,0,0,0,0,0,0,0,0,0,0,0,0,0,0,0,0,0,0
0,0,0,0,0,0,0,0,0,0,0,0,0,0,0,0,0,0,0,0,0,0
1,0,0,0,0,0,0,0,0,0,0,0,0,0,0,0,0,0,0,0,0,1
endlayer

layer
0,0,0,0,0,0,0,0,0,0,0,0,0,0,0,0,0,0,0,0,0,0
0,0,0,0,0,0,0,0,0,0,0,0,0,0,0,0,0,0,0,0,0,0
0,0,0,0,0,0,0,0,0,0,0,0,0,0,0,0,0,0,0,0,0,0
0,0,0,0,0,0,0,0,0,0,0,0,0,0,0,0,0,0,0,0,0,0
0,0,0,0,0,0,0,0,0,0,0,0,0,0,0,0,0,0,0,0,0,0
0,0,0,0,0,0,0,0,0,0,0,0,0,0,0,0,0,0,0,0,0,0
0,0,0,0,0,0,0,0,0,0,0,0,0,0,0,0,0,0,0,0,0,0
0,0,0,0,0,0,0,0,0,0,0,0,0,0,0,0,0,0,0,0,0,0
0,0,0,0,0,0,0,0,0,0,0,0,0,0,0,0,0,0,0,0,0,0
0,0,0,0,0,0,0,0,0,0,0,0,0,0,0,0,0,0,0,0,0,0
0,0,0,0,0,0,0,0,0,0,0,0,0,0,0,0,0,0,0,0,0,0
0,0,0,0,0,0,0,0,0,0,0,0,0,0,0,0,0,0,0,0,0,0
0,0,0,0,0,0,0,0,0,0,21,21,0,0,0,0,0,0,0,0,0,0
0,0,0,0,0,0,0,0,0,0,0,0,0,0,0,0,0,0,0,0,0,0
0,0,0,0,0,0,0,0,0,0,0,0,0,0,0,0,0,0,0,0,0,0
0,0,0,0,0,0,0,21,0,0,3,3,0,0,21,0,0,0,0,0,0,0
0,0,0,0,0,0,0,21,0,0,3,3,0,0,21,0,0,0,0,0,0,0
0,0,0,0,0,0,0,0,0,0,0,0,0,0,0,0,0,0,0,0,0,0
0,0,0,0,0,0,0,0,0,0,0,0,0,0,0,0,0,0,0,0,0,0
0,0,0,0,0,0,0,0,0,0,21,21,0,0,0,0,0,0,0,0,0,0
0,0,0,0,0,0,0,0,0,0,0,0,0,0,0,0,0,0,0,0,0,0
0,0,0,0,0,0,0,0,0,0,0,0,0,0,0,0,0,0,0,0,0,0
0,0,0,0,0,0,0,0,0,0,0,0,0,0,0,0,0,0,0,0,0,0
0,0,0,0,0,0,0,0,0,0,0,0,0,0,0,0,0,0,0,0,0,0
0,0,0,0,0,0,0,0,0,0,0,0,0,0,0,0,0,0,0,0,0,0
0,0,0,0,0,0,0,0,0,0,0,0,0,0,0,0,0,0,0,0,0,0
0,0,0,0,0,0,0,0,0,0,0,0,0,0,0,0,0,0,0,0,0,0
0,0,0,0,0,0,0,0,0,0,0,0,0,0,0,0,0,0,0,0,0,0
0,0,0,0,0,0,0,0,0,0,0,0,0,0,0,0,0,0,0,0,0,0
0,0,0,0,0,0,0,0,0,0,0,0,0,0,0,0,0,0,0,0,0,0
0,0,0,0,0,0,0,0,0,0,0,0,0,0,0,0,0,0,0,0,0,0
0,0,0,0,0,0,0,0,0,0,0,0,0,0,0,0,0,0,0,0,0,0
endlayer

layer
0,0,0,0,0,0,0,0,0,0,0,0,0,0,0,0,0,0,0,0,0,0
0,0,0,0,0,0,0,0,0,0,0,0,0,0,0,0,0,0,0,0,0,0
0,0,0,0,0,0,0,0,0,0,0,0,0,0,0,0,0,0,0,0,0,0
0,0,0,0,0,0,0,0,0,0,0,0,0,0,0,0,0,0,0,0,0,0
0,0,0,0,0,0,0,0,0,0,0,0,0,0,0,0,0,0,0,0,0,0
0,0,0,0,0,0,0,0,0,0,0,0,0,0,0,0,0,0,0,0,0,0
0,0,0,0,0,0,0,0,0,0,0,0,0,0,0,0,0,0,0,0,0,0
0,0,0,0,0,0,0,0,0,0,0,0,0,0,0,0,0,0,0,0,0,0
0,0,0,0,0,0,0,0,0,0,0,0,0,0,0,0,0,0,0,0,0,0
0,0,0,0,0,0,0,0,0,0,0,0,0,0,0,0,0,0,0,0,0,0
0,0,0,0,0,0,0,0,0,0,0,0,0,0,0,0,0,0,0,0,0,0
0,0,0,0,0,0,0,0,0,0,0,0,0,0,0,0,0,0,0,0,0,0
0,0,0,0,0,0,0,0,0,0,21,21,0,0,0,0,0,0,0,0,0,0
0,0,0,0,0,0,0,0,0,0,0,0,0,0,0,0,0,0,0,0,0,0
0,0,0,0,0,0,0,0,0,0,0,0,0,0,0,0,0,0,0,0,0,0
0,0,0,0,0,0,0,21,0,0,3,3,0,0,21,0,0,0,0,0,0,0
0,0,0,0,0,0,0,21,0,0,4,3,0,0,21,0,0,0,0,0,0,0
0,0,0,0,0,0,0,0,0,0,0,0,0,0,0,0,0,0,0,0,0,0
0,0,0,0,0,0,0,0,0,0,0,0,0,0,0,0,0,0,0,0,0,0
0,0,0,0,0,0,0,0,0,0,21,21,0,0,0,0,0,0,0,0,0,0
0,0,0,0,0,0,0,0,0,0,0,0,0,0,0,0,0,0,0,0,0,0
0,0,0,0,0,0,0,0,0,0,0,0,0,0,0,0,0,0,0,0,0,0
0,0,0,0,0,0,0,0,0,0,0,0,0,0,0,0,0,0,0,0,0,0
0,0,0,0,0,0,0,0,0,0,0,0,0,0,0,0,0,0,0,0,0,0
0,0,0,0,0,0,0,0,0,0,0,0,0,0,0,0,0,0,0,0,0,0
0,0,0,0,0,0,0,0,0,0,0,0,0,0,0,0,0,0,0,0,0,0
0,0,0,0,0,0,0,0,0,0,0,0,0,0,0,0,0,0,0,0,0,0
0,0,0,0,0,0,0,0,0,0,0,0,0,0,0,0,0,0,0,0,0,0
0,0,0,0,0,0,0,0,0,0,0,0,0,0,0,0,0,0,0,0,0,0
0,0,0,0,0,0,0,0,0,0,0,0,0,0,0,0,0,0,0,0,0,0
0,0,0,0,0,0,0,0,0,0,0,0,0,0,0,0,0,0,0,0,0,0
0,0,0,0,0,0,0,0,0,0,0,0,0,0,0,0,0,0,0,0,0,0
endlayer

layer
0,0,0,0,0,0,0,0,0,0,0,0,0,0,0,0,0,0,0,0,0,0
0,0,0,0,0,0,0,0,0,0,0,0,0,0,0,0,0,0,0,0,0,0
0,0,0,0,0,0,0,0,0,0,0,0,0,0,0,0,0,0,0,0,0,0
0,0,0,0,0,0,0,0,0,0,0,0,0,0,0,0,0,0,0,0,0,0
0,0,0,0,0,0,0,0,0,0,0,0,0,0,0,0,0,0,0,0,0,0
0,0,0,0,0,0,0,0,0,0,0,0,0,0,0,0,0,0,0,0,0,0
0,0,0,0,0,0,0,0,0,0,0,0,0,0,0,0,0,0,0,0,0,0
0,0,0,0,0,0,0,0,0,0,0,0,0,0,0,0,0,0,0,0,0,0
0,0,0,0,0,0,0,0,0,0,0,0,0,0,0,0,0,0,0,0,0,0
0,0,0,0,0,0,0,0,0,0,0,0,0,0,0,0,0,0,0,0,0,0
0,0,0,0,0,0,0,0,0,0,0,0,0,0,0,0,0,0,0,0,0,0
0,0,0,0,0,0,0,0,0,0,0,0,0,0,0,0,0,0,0,0,0,0
0,0,0,0,0,0,0,0,0,0,21,21,0,0,0,0,0,0,0,0,0,0
0,0,0,0,0,0,0,0,0,0,0,0,0,0,0,0,0,0,0,0,0,0
0,0,0,0,0,0,0,0,0,0,0,0,0,0,0,0,0,0,0,0,0,0
0,0,0,0,0,0,0,21,0,0,3,3,0,0,21,0,0,0,0,0,0,0
0,0,0,0,0,0,0,21,0,0,3,5,0,0,21,0,0,0,0,0,0,0
0,0,0,0,0,0,0,0,0,0,0,0,0,0,0,0,0,0,0,0,0,0
0,0,0,0,0,0,0,0,0,0,0,0,0,0,0,0,0,0,0,0,0,0
0,0,0,0,0,0,0,0,0,0,21,21,0,0,0,0,0,0,0,0,0,0
0,0,0,0,0,0,0,0,0,0,0,0,0,0,0,0,0,0,0,0,0,0
0,0,0,0,0,0,0,0,0,0,0,0,0,0,0,0,0,0,0,0,0,0
0,0,0,0,0,0,0,0,0,0,0,0,0,0,0,0,0,0,0,0,0,0
0,0,0,0,0,0,0,0,0,0,0,0,0,0,0,0,0,0,0,0,0,0
0,0,0,0,0,0,0,0,0,0,0,0,0,0,0,0,0,0,0,0,0,0
0,0,0,0,0,0,0,0,0,0,0,0,0,0,0,0,0,0,0,0,0,0
0,0,0,0,0,0,0,0,0,0,0,0,0,0,0,0,0,0,0,0,0,0
0,0,0,0,0,0,0,0,0,0,0,0,0,0,0,0,0,0,0,0,0,0
0,0,0,0,0,0,0,0,0,0,0,0,0,0,0,0,0,0,0,0,0,0
0,0,0,0,0,0,0,0,0,0,0,0,0,0,0,0,0,0,0,0,0,0
0,0,0,0,0,0,0,0,0,0,0,0,0,0,0,0,0,0,0,0,0,0
0,0,0,0,0,0,0,0,0,0,0,0,0,0,0,0,0,0,0,0,0,0
endlayer

layer
0,0,0,0,0,0,0,0,0,0,0,0,0,0,0,0,0,0,0,0,0,0
0,0,0,0,0,0,0,0,0,0,0,0,0,0,0,0,0,0,0,0,0,0
0,0,0,0,0,0,0,0,0,0,0,0,0,0,0,0,0,0,0,0,0,0
0,0,0,0,0,0,0,0,0,0,0,0,0,0,0,0,0,0,0,0,0,0
0,0,0,0,0,0,0,0,0,0,0,0,0,0,0,0,0,0,0,0,0,0
0,0,0,0,0,0,0,0,0,0,0,0,0,0,0,0,0,0,0,0,0,0
0,0,0,0,0,0,0,0,0,0,0,0,0,0,0,0,0,0,0,0,0,0
0,0,0,0,0,0,0,0,0,0,0,0,0,0,0,0,0,0,0,0,0,0
0,0,0,0,0,0,0,0,0,0,0,0,0,0,0,0,0,0,0,0,0,0
0,0,0,0,0,0,0,0,0,0,0,0,0,0,0,0,0,0,0,0,0,0
0,0,0,0,0,0,0,0,0,0,0,0,0,0,0,0,0,0,0,0,0,0
0,0,0,0,0,0,0,0,0,0,0,0,0,0,0,0,0,0,0,0,0,0
0,0,0,0,0,0,0,0,0,0,21,21,0,0,0,0,0,0,0,0,0,0
0,0,0,0,0,0,0,0,0,5,3,3,3,0,0,0,0,0,0,0,0,0
0,0,0,0,0,0,0,0,3,3,3,3,3,3,0,0,0,0,0,0,0,0
0,0,0,0,0,0,0,21,3,3,3,3,3,3,21,0,0,0,0,0,0,0
0,0,0,0,0,0,0,21,3,3,3,3,3,3,21,0,0,0,0,0,0,0
0,0,0,0,0,0,0,0,3,3,3,3,3,3,0,0,0,0,0,0,0,0
0,0,0,0,0,0,0,0,0,3,3,3,3,0,0,0,0,0,0,0,0,0
0,0,0,0,0,0,0,0,0,0,21,21,0,0,0,0,0,0,0,0,0,0
0,0,0,0,0,0,0,0,0,0,0,0,0,0,0,0,0,0,0,0,0,0
0,0,0,0,0,0,0,0,0,0,0,0,0,0,0,0,0,0,0,0,0,0
0,0,0,0,0,0,0,0,0,0,0,0,0,0,0,0,0,0,0,0,0,0
0,0,0,0,0,0,0,0,0,0,0,0,0,0,0,0,0,0,0,0,0,0
0,0,0,0,0,0,0,0,0,0,0,0,0,0,0,0,0,0,0,0,0,0
0,0,0,0,0,0,0,0,0,0,0,0,0,0,0,0,0,0,0,0,0,0
0,0,0,0,0,0,0,0,0,0,0,0,0,0,0,0,0,0,0,0,0,0
0,0,0,0,0,0,0,0,0,0,0,0,0,0,0,0,0,0,0,0,0,0
0,0,0,0,0,0,0,0,0,0,0,0,0,0,0,0,0,0,0,0,0,0
0,0,0,0,0,0,0,0,0,0,0,0,0,0,0,0,0,0,0,0,0,0
0,0,0,0,0,0,0,0,0,0,0,0,0,0,0,0,0,0,0,0,0,0
0,0,0,0,0,0,0,0,0,0,0,0,0,0,0,0,0,0,0,0,0,0
endlayer

layer
0,0,0,0,0,0,0,0,0,0,0,0,0,0,0,0,0,0,0,0,0,0
0,0,0,0,0,0,0,0,0,0,0,0,0,0,0,0,0,0,0,0,0,0
0,0,0,0,0,0,0,0,0,0,0,0,0,0,0,0,0,0,0,0,0,0
0,0,0,0,0,0,0,0,0,0,0,0,0,0,0,0,0,0,0,0,0,0
0,0,0,0,0,0,0,0,0,0,0,0,0,0,0,0,0,0,0,0,0,0
0,0,0,0,0,0,0,0,0,0,0,0,0,0,0,0,0,0,0,0,0,0
0,0,0,0,0,0,0,0,0,0,0,0,0,0,0,0,0,0,0,0,0,0
0,0,0,0,0,0,0,0,0,0,0,0,0,0,0,0,0,0,0,0,0,0
0,0,0,0,0,0,0,0,0,0,0,0,0,0,0,0,0,0,0,0,0,0
0,0,0,0,0,0,0,0,0,0,0,0,0,0,0,0,0,0,0,0,0,0
0,0,0,0,0,0,0,0,0,0,0,0,0,0,0,0,0,0,0,0,0,0
0,0,0,0,0,0,0,0,0,0,0,0,0,0,0,0,0,0,0,0,0,0
0,0,0,0,0,0,0,0,0,0,11,11,0,0,0,0,0,0,0,0,0,0
0,0,0,0,0,0,0,0,0,6,14,14,6,0,0,0,0,0,0,0,0,0
0,0,0,0,0,0,0,0,6,17,17,17,17,6,0,0,0,0,0,0,0,0
0,0,0,0,0,0,0,11,14,26,3,3,26,14,11,0,0,0,0,0,0,0
0,0,0,0,0,0,0,11,14,26,3,3,26,14,11,0,0,0,0,0,0,0
0,0,0,0,0,0,0,0,6,17,26,26,17,6,0,0,0,0,0,0,0,0
0,0,0,0,0,0,0,0,0,6,14,14,6,0,0,0,0,0,0,0,0,0
0,0,0,0,0,0,0,0,0,0,11,11,0,0,0,0,0,0,0,0,0,0
0,0,0,0,0,0,0,0,0,0,0,0,0,0,0,0,0,0,0,0,0,0
0,0,0,0,0,0,0,0,0,0,0,0,0,0,0,0,0,0,0,0,0,0
0,0,0,0,0,0,0,0,0,0,0,0,0,0,0,0,0,0,0,0,0,0
0,0,0,0,0,0,0,0,0,0,0,0,0,0,0,0,0,0,0,0,0,0
0,0,0,0,0,0,0,0,0,0,0,0,0,0,0,0,0,0,0,0,0,0
0,0,0,0,0,0,0,0,0,0,0,0,0,0,0,0,0,0,0,0,0,0
0,0,0,0,0,0,0,0,0,0,0,0,0,0,0,0,0,0,0,0,0,0
0,0,0,0,0,0,0,0,0,0,0,0,0,0,0,0,0,0,0,0,0,0
0,0,0,0,0,0,0,0,0,0,0,0,0,0,0,0,0,0,0,0,0,0
0,0,0,0,0,0,0,0,0,0,0,0,0,0,0,0,0,0,0,0,0,0
0,0,0,0,0,0,0,0,0,0,0,0,0,0,0,0,0,0,0,0,0,0
0,0,0,0,0,0,0,0,0,0,0,0,0,0,0,0,0,0,0,0,0,0
endlayer

layer
0,0,0,0,0,0,0,0,0,0,0,0,0,0,0,0,0,0,0,0,0,0
0,0,0,0,0,0,0,0,0,0,0,0,0,0,0,0,0,0,0,0,0,0
0,0,0,0,0,0,0,0,0,0,0,0,0,0,0,0,0,0,0,0,0,0
0,0,0,0,0,0,0,0,0,0,0,0,0,0,0,0,0,0,0,0,0,0
0,0,0,0,0,0,0,0,0,0,0,0,0,0,0,0,0,0,0,0,0,0
0,0,0,0,0,0,0,0,0,0,0,0,0,0,0,0,0,0,0,0,0,0
0,0,0,0,0,0,0,0,0,0,0,0,0,0,0,0,0,0,0,0,0,0
0,0,0,0,0,0,0,0,0,0,0,0,0,0,0,0,0,0,0,0,0,0
0,0,0,0,0,0,0,0,0,0,0,0,0,0,0,0,0,0,0,0,0,0
0,0,0,0,0,0,0,0,0,0,0,0,0,0,0,0,0,0,0,0,0,0
0,0,0,0,0,0,0,0,0,0,0,0,0,0,0,0,0,0,0,0,0,0
0,0,0,0,0,0,0,0,0,0,0,0,0,0,0,0,0,0,0,0,0,0
0,0,0,0,0,0,0,0,0,0,0,0,0,0,0,0,0,0,0,0,0,0
0,0,0,0,0,0,0,0,0,0,0,0,0,0,0,0,0,0,0,0,0,0
0,0,0,0,0,0,0,0,0,0,26,26,0,0,0,0,0,0,0,0,0,0
0,0,0,0,0,0,0,0,0,26,3,3,26,0,0,0,0,0,0,0,0,0
0,0,0,0,0,0,0,0,0,26,3,3,26,0,0,0,0,0,0,0,0,0
0,0,0,0,0,0,0,0,0,0,26,26,0,0,0,0,0,0,0,0,0,0
0,0,0,0,0,0,0,0,0,0,0,0,0,0,0,0,0,0,0,0,0,0
0,0,0,0,0,0,0,0,0,0,0,0,0,0,0,0,0,0,0,0,0,0
0,0,0,0,0,0,0,0,0,0,0,0,0,0,0,0,0,0,0,0,0,0
0,0,0,0,0,0,0,0,0,0,0,0,0,0,0,0,0,0,0,0,0,0
0,0,0,0,0,0,0,0,0,0,0,0,0,0,0,0,0,0,0,0,0,0
0,0,0,0,0,0,0,0,0,0,0,0,0,0,0,0,0,0,0,0,0,0
0,0,0,0,0,0,0,0,0,0,0,0,0,0,0,0,0,0,0,0,0,0
0,0,0,0,0,0,0,0,0,0,0,0,0,0,0,0,0,0,0,0,0,0
0,0,0,0,0,0,0,0,0,0,0,0,0,0,0,0,0,0,0,0,0,0
0,0,0,0,0,0,0,0,0,0,0,0,0,0,0,0,0,0,0,0,0,0
0,0,0,0,0,0,0,0,0,0,0,0,0,0,0,0,0,0,0,0,0,0
0,0,0,0,0,0,0,0,0,0,0,0,0,0,0,0,0,0,0,0,0,0
0,0,0,0,0,0,0,0,0,0,0,0,0,0,0,0,0,0,0,0,0,0
0,0,0,0,0,0,0,0,0,0,0,0,0,0,0,0,0,0,0,0,0,0
endlayer

layer
0,0,0,0,0,0,0,0,0,0,0,0,0,0,0,0,0,0,0,0,0,0
0,0,0,0,0,0,0,0,0,0,0,0,0,0,0,0,0,0,0,0,0,0
0,0,0,0,0,0,0,0,0,0,0,0,0,0,0,0,0,0,0,0,0,0
0,0,0,0,0,0,0,0,0,0,0,0,0,0,0,0,0,0,0,0,0,0
0,0,0,0,0,0,0,0,0,0,0,0,0,0,0,0,0,0,0,0,0,0
0,0,0,0,0,0,0,0,0,0,0,0,0,0,0,0,0,0,0,0,0,0
0,0,0,0,0,0,0,0,0,0,0,0,0,0,0,0,0,0,0,0,0,0
0,0,0,0,0,0,0,0,0,0,0,0,0,0,0,0,0,0,0,0,0,0
0,0,0,0,0,0,0,0,0,0,0,0,0,0,0,0,0,0,0,0,0,0
0,0,0,0,0,0,0,0,0,0,0,0,0,0,0,0,0,0,0,0,0,0
0,0,0,0,0,0,0,0,0,0,0,0,0,0,0,0,0,0,0,0,0,0
0,0,0,0,0,0,0,0,0,0,0,0,0,0,0,0,0,0,0,0,0,0
0,0,0,0,0,0,0,0,0,0,0,0,0,0,0,0,0,0,0,0,0,0
0,0,0,0,0,0,0,0,0,0,0,0,0,0,0,0,0,0,0,0,0,0
0,0,0,0,0,0,0,0,0,0,14,14,0,0,0,0,0,0,0,0,0,0
0,0,0,0,0,0,0,0,0,14,17,17,14,0,0,0,0,0,0,0,0,0
0,0,0,0,0,0,0,0,0,14,17,17,14,0,0,0,0,0,0,0,0,0
0,0,0,0,0,0,0,0,0,0,14,14,0,0,0,0,0,0,0,0,0,0
0,0,0,0,0,0,0,0,0,0,0,0,0,0,0,0,0,0,0,0,0,0
0,0,0,0,0,0,0,0,0,0,0,0,0,0,0,0,0,0,0,0,0,0
0,0,0,0,0,0,0,0,0,0,0,0,0,0,0,0,0,0,0,0,0,0
0,0,0,0,0,0,0,0,0,0,0,0,0,0,0,0,0,0,0,0,0,0
0,0,0,0,0,0,0,0,0,0,0,0,0,0,0,0,0,0,0,0,0,0
0,0,0,0,0,0,0,0,0,0,0,0,0,0,0,0,0,0,0,0,0,0
0,0,0,0,0,0,0,0,0,0,0,0,0,0,0,0,0,0,0,0,0,0
0,0,0,0,0,0,0,0,0,0,0,0,0,0,0,0,0,0,0,0,0,0
0,0,0,0,0,0,0,0,0,0,0,0,0,0,0,0,0,0,0,0,0,0
0,0,0,0,0,0,0,0,0,0,0,0,0,0,0,0,0,0,0,0,0,0
0,0,0,0,0,0,0,0,0,0,0,0,0,0,0,0,0,0,0,0,0,0
0,0,0,0,0,0,0,0,0,0,0,0,0,0,0,0,0,0,0,0,0,0
0,0,0,0,0,0,0,0,0,0,0,0,0,0,0,0,0,0,0,0,0,0
0,0,0,0,0,0,0,0,0,0,0,0,0,0,0,0,0,0,0,0,0,0
endlayer

