# Town Barn #1
# MC 1.7.10; 20 Oct 2014
# Created by Ruins mod version 13.8 Ingame Parser
# authoring Player: Kujaku10
# Last Updated 7 Feb 2016
# Updated to MC 1.8: 5 Mar 2016
# Updated to MC 1.9: 18 Apr 2016
# Updated to MC 1.11.2: 11 Jan 2017
# Updated to MC 1.12: 21 Jun 2017

biomesToSpawnIn=plains,sunflower plains

preventRotation=1

weight=1
embed_into_distance=4
acceptable_target_blocks=

unacceptable_target_blocks=flowing_lava,lava,cloud,Natura:Cloud,red_mushroom_block,brown_mushroom_block,planks,cobblestone,torch,stone_slab,double_stone_slab,oak_stairs,spruce_stairs,birch_stairs,dark_oak_stairs,acacia_stairs,jungle_stairs,slime_congealed,slime_dirt,slime_grass,fence,stone_brick,cobblestone_wall,command_block,concrete

dimensions=14,12,15
allowable_overhang=0
max_leveling=2
leveling_buffer=-1
preserve_water=0
preserve_lava=0
preserve_plants=1

rule1=0,100,preserveBlock
rule2=0,100,minecraft:grass-0
rule3=0,100,minecraft:double_plant-3
rule4=1,100,minecraft:leaves-14
rule5=0,100,minecraft:cobblestone-0
rule6=0,100,minecraft:cobblestone-0
rule7=0,100,minecraft:stonebrick-2
rule8=0,100,minecraft:stonebrick-1
rule9=0,100,minecraft:stonebrick-3
rule10=0,100,minecraft:stonebrick-1
rule11=0,100,minecraft:stone_stairs-2
rule12=0,100,minecraft:stonebrick-3
rule13=0,100,minecraft:stone_stairs-3
rule14=0,100,minecraft:hay_block-0
rule15=0,100,minecraft:hay_block-4
rule16=0,100,minecraft:hay_block-8
rule17=0,100,minecraft:double_plant-10
rule18=0,100,minecraft:double_plant-8
rule19=0,100,minecraft:planks-1
rule20=2,100,minecraft:ladder-5
rule21=1,100,minecraft:wooden_door-1
rule22=1,100,minecraft:wooden_door-3
rule23=0,100,minecraft:fence-0
rule24=0,100,minecraft:double_plant-11
rule25=2,100,minecraft:torch-3
rule26=2,100,minecraft:torch-4
rule27=1,100,minecraft:wooden_door-9
rule28=1,100,minecraft:wooden_door-8
rule29=0,100,minecraft:oak_stairs-0
rule30=0,100,minecraft:oak_stairs-5
rule31=0,100,minecraft:planks-0
rule32=0,100,minecraft:wooden_slab-8
rule33=0,100,minecraft:wooden_slab-1
rule34=0,100,minecraft:oak_stairs-4
rule35=0,100,minecraft:oak_stairs-1
rule36=0,100,ChestGenHook:chests/village_blacksmith:2-5,ChestGenHook:chests/spawn_bonus_chest:4-5,ChestGenHook:chests/simple_dungeon:2-5

rule37=0,100,ChestGenHook:chests/spawn_bonus_chest:3-4
rule38=1,100,minecraft:torch-5
rule39=0,100,minecraft:spruce_stairs-5
rule40=0,100,minecraft:spruce_stairs-4
rule41=0,100,minecraft:wooden_slab-0
rule42=0,100,minecraft:oak_stairs-3
rule43=0,100,minecraft:oak_stairs-2

# Highwayman (Bandit Archer)
rule44=0,100,CommandBlock:RUINSTRIGGER /summon Skeleton ~0 ~0 ~0 {HandItems:[{Count:1,id:bow,tag:{display:{Name:"Bandit Bow"},ench:[{id:48,lvl:3},{id:49,lvl:2}]}},{Count:8,id:tipped_arrow,tag:{Potion:"minecraft:strong_harming"}}],ArmorItems:[{Count:1,id:leather_boots},{Count:1,id:leather_leggings},{Count:1,id:leather_chestplate},{Count:1,id:skull,Damage:3,tag:{SkullOwner:MHF_Villager}}],CustomName:Highwayman,HandDropChances:[1.0F,0.0F],ArmorDropChances:[0.5F,0.5F,0.5F,0.0F],Silent:1,PersistenceRequired:1,Health:15.0f}:@


rule45=0,100,minecraft:fence_gate-1

rule46=0,100,CommandBlock:RUINSTRIGGER /summon Cow ~0 ~0 ~0:@

layer
1,1,1,1,1,1,1,1,1,1,1,1,1,1,1
2,2,2,2,2,2,2,2,2,2,2,2,2,2,2
2,2,5,5,5,5,5,5,5,5,5,5,5,2,2
2,2,5,5,5,5,5,5,5,5,5,5,5,2,2
2,2,5,5,5,5,5,5,5,5,5,5,5,2,2
2,2,5,5,5,5,5,5,5,5,5,5,5,2,2
2,2,5,5,5,5,5,5,5,5,5,5,5,2,2
2,2,5,5,5,5,5,5,5,5,5,5,5,2,2
2,2,5,5,5,5,5,5,5,5,5,5,5,2,2
1,1,5,5,5,5,5,5,5,5,5,5,5,1,1
1,1,1,1,1,1,1,1,1,1,1,1,1,1,1
1,1,1,1,1,1,1,1,1,1,1,1,1,1,1
endlayer

layer
1,1,1,1,1,1,1,1,1,1,1,1,1,1,1
1,1,1,1,1,1,1,1,1,1,1,1,1,1,1
2,2,5,5,5,5,5,5,5,5,5,5,5,2,2
2,2,5,5,5,5,5,5,5,5,5,5,5,2,2
2,2,5,5,5,5,5,5,5,5,5,5,5,2,2
2,2,5,5,5,5,5,5,5,5,5,5,5,2,2
2,2,5,5,5,5,5,5,5,5,5,5,5,2,2
2,2,5,5,5,5,5,5,5,5,5,5,5,2,2
1,1,5,5,5,5,5,5,5,5,5,5,5,1,1
1,1,5,5,5,5,5,5,5,5,5,5,5,1,1
1,1,1,1,1,1,1,1,1,1,1,1,1,1,1
1,1,1,1,1,1,1,1,1,1,1,1,1,1,1
endlayer

layer
1,1,1,1,1,1,1,1,1,1,1,1,1,1,1
1,1,1,1,1,1,1,1,1,1,1,1,1,1,1
1,2,5,5,5,5,5,5,5,5,5,5,5,2,1
2,2,5,5,5,5,5,5,5,5,5,5,5,2,2
2,2,5,5,5,5,5,5,5,5,5,5,5,2,2
2,2,5,5,5,5,5,5,5,5,5,5,5,2,2
2,2,5,5,5,5,5,5,5,5,5,5,5,2,2
1,2,5,5,5,5,5,5,5,5,5,5,5,2,1
1,1,5,5,5,5,5,5,5,5,5,5,5,1,1
1,1,5,5,5,5,5,5,5,5,5,5,5,1,1
1,1,1,1,1,1,1,1,1,1,1,1,1,1,1
1,1,1,1,1,1,1,1,1,1,1,1,1,1,1
endlayer

layer
1,1,1,1,1,1,1,1,1,1,1,1,1,1,1
1,1,1,1,1,1,1,1,1,1,1,1,1,1,1
1,2,5,5,5,5,5,5,5,5,5,5,5,2,1
1,2,5,5,5,5,5,5,5,5,5,5,5,2,1
2,2,5,5,5,5,5,5,5,5,5,5,5,2,2
2,2,5,5,5,5,5,5,5,5,5,5,5,2,2
1,2,5,5,5,5,5,5,5,5,5,5,5,2,1
1,2,5,5,5,5,5,5,5,5,5,5,5,2,1
1,1,5,5,5,5,5,5,5,5,5,5,5,1,1
1,1,5,5,5,5,5,5,5,5,5,5,5,1,1
1,1,1,1,1,1,1,1,1,1,1,1,1,1,1
1,1,1,1,1,1,1,1,1,1,1,1,1,1,1
endlayer


layer
1,1,1,1,1,1,1,1,1,1,1,1,1,1,1
1,3,4,4,0,4,0,4,0,4,0,4,4,3,1
1,4,5,5,6,5,5,5,5,5,5,5,5,4,1
1,4,5,9,7,10,9,7,8,9,8,7,5,4,1
1,13,5,7,10,7,8,12,7,10,7,8,5,11,1
1,13,5,10,7,12,7,8,12,7,8,12,5,11,1
1,4,5,12,8,7,8,12,7,10,9,7,5,4,1
1,0,5,15,14,14,14,14,14,14,15,14,5,0,1
1,4,5,14,14,14,16,14,14,14,14,14,5,4,1
1,4,5,5,5,5,5,5,5,5,5,5,5,4,1
1,3,4,4,0,4,0,4,0,4,0,4,4,3,1
1,1,1,1,1,1,1,1,1,1,1,1,1,1,1
endlayer

layer
0,0,0,0,0,0,0,0,0,0,0,0,0,0,0
0,18,0,0,0,0,0,0,0,0,0,0,0,17,0
0,0,19,19,0,19,0,19,0,19,0,19,19,0,0
0,0,19,0,0,0,0,20,0,0,0,0,19,0,0
0,0,22,0,0,0,0,0,44,0,0,0,21,0,0
0,0,22,0,0,0,0,0,0,0,0,0,21,0,0
0,0,19,23,23,23,45,23,23,23,23,23,19,0,0
0,0,0,0,0,46,0,0,0,0,0,46,0,0,0
0,0,19,0,0,0,0,0,0,0,0,0,19,0,0
0,0,19,19,0,19,0,19,0,19,0,19,19,0,0
0,24,0,0,0,0,0,0,0,0,0,0,0,17,0
0,0,0,0,0,0,0,0,0,0,0,0,0,0,0
endlayer

layer
0,0,0,0,0,0,0,0,0,0,0,0,0,0,0
0,0,0,0,0,0,0,0,0,0,0,0,0,0,0
0,0,19,19,19,19,19,19,19,19,19,19,19,0,0
0,0,19,26,0,0,0,20,0,0,0,25,19,0,0
0,0,28,0,0,0,0,0,0,0,0,0,27,0,0
0,0,27,0,0,0,0,0,0,0,0,0,28,0,0
0,0,19,26,0,0,0,38,0,0,0,25,19,0,0
0,0,19,0,0,0,0,0,0,0,0,0,19,0,0
0,0,19,0,0,0,0,0,0,0,0,0,19,0,0
0,0,19,19,19,19,19,19,19,19,19,19,19,0,0
0,0,0,0,0,0,0,0,0,0,0,0,0,0,0
0,0,0,0,0,0,0,0,0,0,0,0,0,0,0
endlayer

layer
0,0,0,0,0,0,0,0,0,0,0,0,0,0,0
0,29,29,29,29,29,29,29,29,29,29,29,29,29,0
0,30,31,31,31,31,31,31,31,31,31,31,31,30,0
0,32,19,19,19,33,33,20,33,33,19,19,19,32,0
0,32,19,33,33,33,33,33,33,33,33,33,19,32,0
0,32,19,33,33,33,33,33,33,33,33,33,19,32,0
0,32,19,33,33,33,33,33,33,33,33,33,19,32,0
0,32,19,33,33,33,33,33,33,33,33,33,19,32,0
0,32,19,19,19,33,33,33,33,33,19,19,19,32,0
0,34,31,31,31,31,31,31,31,31,31,31,31,34,0
0,35,35,35,35,35,35,35,35,35,35,35,35,35,0
0,0,0,0,0,0,0,0,0,0,0,0,0,0,0
endlayer

layer
0,0,0,0,0,0,0,0,0,0,0,0,0,0,0
0,0,0,0,0,0,0,0,0,0,0,0,0,0,0
0,31,31,31,31,31,31,31,31,31,31,31,31,31,0
0,38,19,36,36,23,0,0,0,23,36,36,19,38,0
0,0,19,0,0,0,0,0,0,0,0,0,19,0,0
0,0,23,0,0,0,0,44,0,0,44,0,23,0,0
0,0,23,0,0,0,0,0,0,0,0,0,23,0,0
0,0,19,0,0,0,0,0,0,0,0,0,19,0,0
0,38,19,37,37,23,0,0,0,23,37,37,19,38,0
0,31,31,31,31,31,31,31,31,31,31,31,31,31,0
0,0,0,0,0,0,0,0,0,0,0,0,0,0,0
0,0,0,0,0,0,0,0,0,0,0,0,0,0,0
endlayer

layer
0,0,0,0,0,0,0,0,0,0,0,0,0,0,0
0,0,0,0,0,0,0,0,0,0,0,0,0,0,0
0,31,31,31,31,31,31,31,31,31,31,31,31,31,0
0,0,19,0,0,38,0,0,0,38,0,0,19,0,0
0,0,19,0,0,0,0,0,0,0,0,0,19,0,0
0,0,0,0,0,0,0,0,0,0,0,0,0,0,0
0,0,0,0,0,0,0,0,0,0,0,0,0,0,0
0,0,19,0,0,0,0,0,0,0,0,0,19,0,0
0,0,19,0,0,38,0,0,0,38,0,0,19,0,0
0,31,31,31,31,31,31,31,31,31,31,31,31,31,0
0,0,0,0,0,0,0,0,0,0,0,0,0,0,0
0,0,0,0,0,0,0,0,0,0,0,0,0,0,0
endlayer

layer
0,0,0,0,0,0,0,0,0,0,0,0,0,0,0
0,0,0,0,0,0,0,0,0,0,0,0,0,0,0
0,29,29,29,29,29,29,29,29,29,29,29,29,29,0
0,30,19,30,30,30,30,30,30,30,30,30,19,30,0
0,0,19,0,0,0,0,0,0,0,0,0,19,0,0
0,0,39,0,0,0,0,0,0,0,0,0,39,0,0
0,0,40,0,0,0,0,0,0,0,0,0,40,0,0
0,0,19,0,0,0,0,0,0,0,0,0,19,0,0
0,34,19,34,34,34,34,34,34,34,34,34,19,34,0
0,35,35,35,35,35,35,35,35,35,35,35,35,35,0
0,0,0,0,0,0,0,0,0,0,0,0,0,0,0
0,0,0,0,0,0,0,0,0,0,0,0,0,0,0
endlayer

layer
0,0,0,0,0,0,0,0,0,0,0,0,0,0,0
0,0,0,0,0,0,0,0,0,0,0,0,0,0,0
0,0,0,0,0,0,0,0,0,0,0,0,0,0,0
0,29,29,29,29,29,29,29,29,29,29,29,29,29,0
0,31,31,31,31,31,31,31,31,31,31,31,31,31,0
31,31,31,31,31,31,31,31,31,31,31,31,31,31,31
31,31,31,31,31,31,31,31,31,31,31,31,31,31,31
0,31,31,31,31,31,31,31,31,31,31,31,31,31,0
0,35,35,35,35,35,35,35,35,35,35,35,35,35,0
0,0,0,0,0,0,0,0,0,0,0,0,0,0,0
0,0,0,0,0,0,0,0,0,0,0,0,0,0,0
0,0,0,0,0,0,0,0,0,0,0,0,0,0,0
endlayer

layer
0,0,0,0,0,0,0,0,0,0,0,0,0,0,0
0,0,0,0,0,0,0,0,0,0,0,0,0,0,0
0,0,0,0,0,0,0,0,0,0,0,0,0,0,0
0,0,0,0,0,0,0,0,0,0,0,0,0,0,0
0,41,41,41,41,41,41,41,41,41,41,41,41,41,0
31,43,41,41,41,41,41,41,41,41,41,41,41,42,31
31,43,41,41,41,41,41,41,41,41,41,41,41,42,31
0,41,41,41,41,41,41,41,41,41,41,41,41,41,0
0,0,0,0,0,0,0,0,0,0,0,0,0,0,0
0,0,0,0,0,0,0,0,0,0,0,0,0,0,0
0,0,0,0,0,0,0,0,0,0,0,0,0,0,0
0,0,0,0,0,0,0,0,0,0,0,0,0,0,0
endlayer

layer
0,0,0,0,0,0,0,0,0,0,0,0,0,0,0
0,0,0,0,0,0,0,0,0,0,0,0,0,0,0
0,0,0,0,0,0,0,0,0,0,0,0,0,0,0
0,0,0,0,0,0,0,0,0,0,0,0,0,0,0
0,0,0,0,0,0,0,0,0,0,0,0,0,0,0
43,0,0,0,0,0,0,0,0,0,0,0,0,0,42
43,0,0,0,0,0,0,0,0,0,0,0,0,0,42
0,0,0,0,0,0,0,0,0,0,0,0,0,0,0
0,0,0,0,0,0,0,0,0,0,0,0,0,0,0
0,0,0,0,0,0,0,0,0,0,0,0,0,0,0
0,0,0,0,0,0,0,0,0,0,0,0,0,0,0
0,0,0,0,0,0,0,0,0,0,0,0,0,0,0
endlayer

