# Town Guard House 10/20/2014
# Created by Ruins mod version 13.8 Ingame Parser
# authoring Player: Kujaku10
# Updated to MC 1.8: 5 Mar 2016
# Updated to MC 1.9: 18 Apr 2016
# Updated to MC 1.11.2: 11 Jan 2017
# Updated to MC 1.12: 22 Jun 2017
# Updated to MC 1.12.1: 10 Sep 2017

biomesToSpawnIn=plains,sunflower plains,mutated_plains

weight=1
embed_into_distance=4
acceptable_target_blocks=

unacceptable_target_blocks=flowing_lava,lava,cloud,Natura:Cloud,red_mushroom_block,brown_mushroom_block,planks,cobblestone,torch,stone_slab,double_stone_slab,oak_stairs,spruce_stairs,birch_stairs,dark_oak_stairs,acacia_stairs,jungle_stairs,slime_congealed,slime_dirt,slime_grass,fence,stone_brick,cobblestone_wall,command_block

dimensions=19,14,14
allowable_overhang=0
max_leveling=2
leveling_buffer=-1
preserve_water=0
preserve_lava=0
preserve_plants=1

rule1=0,100,preserveBlock
rule2=0,100,minecraft:grass
rule3=1,100,minecraft:leaves-6
rule4=1,100,minecraft:leaves-14
rule5=0,100,minecraft:stone_brick_stairs-2
rule6=0,100,minecraft:stone_brick_stairs-0
rule7=0,100,minecraft:stonebrick-0
rule8=0,100,minecraft:stone_brick_stairs-3
rule9=0,100,minecraft:stone_brick_stairs-1
rule10=0,100,minecraft:planks-3
rule11=0,100,minecraft:bone_block-0
rule12=2,100,minecraft:ladder-3
rule13=1,100,minecraft:wooden_door-3
rule14=0,100,minecraft:glass_pane-0
rule15=2,100,minecraft:torch-1
rule16=1,100,minecraft:wooden_door-8
rule17=1,100,minecraft:wooden_door-9
rule18=2,100,minecraft:torch-2
rule19=0,100,minecraft:noteblock-0
rule20=0,100,minecraft:jungle_stairs-0
rule21=0,100,minecraft:jungle_stairs-2
rule22=0,100,minecraft:jungle_stairs-3
rule23=0,100,minecraft:planks-4
rule24=0,100,minecraft:jungle_stairs-1
rule25=0,100,minecraft:wooden_slab-4

rule26=0,100,IInventory;minecraft:chest;minecraft:iron_ingot#2#0#3,IInventory;minecraft:chest;minecraft:coal#8#0#5,IInventory;minecraft:chest;minecraft:arrow#12#0#9,IInventory;minecraft:chest;minecraft:flint_and_steel#1#0#2,IInventory;minecraft:chest;minecraft:apple#6#0#7


# Bandit
rule27=0,100,CommandBlock:RUINSTRIGGER /summon Skeleton ~0 ~0 ~0 {HandItems:[{Count:1,id:wooden_sword,tag:{display:{Name:"Bandit Bludgeon"},ench:[{id:19,lvl:2},{id:21,lvl:2},{id:16,lvl:3}]}},{}],ArmorItems:[{Count:1,id:leather_boots},{Count:1,id:leather_leggings},{Count:1,id:leather_chestplate},{Count:1,id:skull,Damage:3,tag:{SkullOwner:MHF_Villager}}],CustomName:Bandit,HandDropChances:[1.0F,0.0F],ArmorDropChances:[0.5F,0.5F,0.5F,0.1F],Silent:1,PersistenceRequired:1,Health:15.0f}:@

# Villager: Armorer
rule28=0,100,CommandBlock:RUINSTRIGGER /summon Villager ~0 ~0 ~0 {Profession:3,Career:1,CustomName:Armorer,Offers:{Recipes:[{buy:{id:iron_ingot,Count:9},sell:{id:emerald,Count:1}},{buy:{id:emerald,Count:5},sell:{id:chainmail_helmet,Count:1}},{buy:{id:emerald,Count:11},sell:{id:chainmail_chestplate,Count:1}},{buy:{id:emerald,Count:9},sell:{id:chainmail_leggings,Count:1}},{buy:{id:emerald,Count:5},sell:{id:chainmail_boots,Count:1}},{buy:{id:emerald,Count:4},sell:{id:iron_helmet,Count:1}},{buy:{id:emerald,Count:10},sell:{id:iron_chestplate,Count:1}},{buy:{id:emerald,Count:9},sell:{id:iron_sword,Count:1}},{buy:{id:coal,Count:24},sell:{id:emerald,Count:1}}]}}:@

# Villager: Fletcher
rule29=0,100,CommandBlock:RUINSTRIGGER /summon Villager ~0 ~0 ~0 {Profession:0,Career:4,CustomName:Fletcher,Offers:{Recipes:[{buy:{id:emerald,Count:1},sell:{id:arrow,Count:12}},{buy:{id:arrow,Count:32},sell:{id:emerald,Count:1}},{buy:{id:flint,Count:32},sell:{id:emerald,Count:1}},{buy:{id:feather,Count:32},sell:{id:emerald,Count:1}},{buy:{id:emerald,Count:2},sell:{id:bow,Count:1}},{buy:{id:string,Count:20},sell:{id:emerald,Count:1}}]}}:@

# Villager: Leatherworker
rule30=0,100,CommandBlock:RUINSTRIGGER /summon Villager ~0 ~0 ~0 {Profession:3,Career:1,CustomName:Leatherworker,Offers:{Recipes:[{buy:{id:emerald,Count:1},sell:{id:leather_helmet,Count:1}},{buy:{id:emerald,Count:7},sell:{id:leather_chestplate,Count:1}},{buy:{id:emerald,Count:2},sell:{id:leather_leggings,Count:1}},{buy:{id:emerald,Count:1},sell:{id:leather_boots,Count:1}},{buy:{id:saddle,Count:1},sell:{id:leather,Count:3}},{buy:{id:leather_helmet,Count:1},sell:{id:leather,Count:3}},{buy:{id:leather_chestplate,Count:1},sell:{id:leather,Count:4}},{buy:{id:leather_leggings,Count:1},sell:{id:leather,Count:3}},{buy:{id:leather_boots,Count:1},sell:{id:leather,Count:2}},{buy:{id:book,Count:1},sell:{id:leather,Count:1}},{buy:{id:leather,Count:12},sell:{id:emerald,Count:1}}]}}:@

rule31=0,100,ChestGenHook:chests/simple_dungeon:4-1



layer
1,1,1,1,1,1,1,1,1,1,1,1,1,1
1,1,1,1,1,1,1,1,1,1,1,1,1,1
1,1,7,7,7,7,7,7,7,7,7,7,1,1
7,7,7,7,7,7,7,7,7,7,7,7,1,1
7,7,7,7,7,7,7,7,7,7,7,7,1,1
7,7,7,7,7,7,7,7,7,7,7,7,1,1
7,7,7,7,7,7,7,7,7,7,7,7,1,1
7,7,7,7,7,7,7,7,7,7,7,7,1,1
7,7,7,7,7,7,7,7,7,7,7,7,1,1
7,7,7,7,7,7,7,7,7,7,7,7,1,1
7,7,7,7,7,7,7,7,7,7,7,7,1,1
1,1,7,7,7,7,7,7,7,7,7,7,1,1
1,1,1,1,1,1,1,1,1,1,1,1,1,1
1,1,1,1,1,1,1,1,1,1,1,1,1,1
endlayer

layer
1,1,1,1,1,1,1,1,1,1,1,1,1,1
1,1,1,1,1,1,1,1,1,1,1,1,1,1
1,1,7,7,7,7,7,7,7,7,7,7,1,1
1,1,7,7,7,7,7,7,7,7,7,7,1,1
7,7,7,7,7,7,7,7,7,7,7,7,1,1
7,7,7,7,7,7,7,7,7,7,7,7,1,1
7,7,7,7,7,7,7,7,7,7,7,7,1,1
7,7,7,7,7,7,7,7,7,7,7,7,1,1
7,7,7,7,7,7,7,7,7,7,7,7,1,1
7,7,7,7,7,7,7,7,7,7,7,7,1,1
1,1,7,7,7,7,7,7,7,7,7,7,1,1
1,1,7,7,7,7,7,7,7,7,7,7,1,1
1,1,1,1,1,1,1,1,1,1,1,1,1,1
1,1,1,1,1,1,1,1,1,1,1,1,1,1
endlayer

layer
1,1,1,1,1,1,1,1,1,1,1,1,1,1
1,1,1,1,1,1,1,1,1,1,1,1,1,1
1,1,7,7,7,7,7,7,7,7,7,7,1,1
1,1,7,7,7,7,7,7,7,7,7,7,1,1
1,1,7,7,7,7,7,7,7,7,7,7,1,1
7,7,7,7,7,7,7,7,7,7,7,7,1,1
7,7,7,7,7,7,7,7,7,7,7,7,1,1
7,7,7,7,7,7,7,7,7,7,7,7,1,1
7,7,7,7,7,7,7,7,7,7,7,7,1,1
1,1,7,7,7,7,7,7,7,7,7,7,1,1
1,1,7,7,7,7,7,7,7,7,7,7,1,1
1,1,7,7,7,7,7,7,7,7,7,7,1,1
1,1,1,1,1,1,1,1,1,1,1,1,1,1
1,1,1,1,1,1,1,1,1,1,1,1,1,1
endlayer

layer
1,1,1,1,1,1,1,1,1,1,1,1,1,1
1,1,1,1,1,1,1,1,1,1,1,1,1,1
1,1,7,7,7,7,7,7,7,7,7,7,1,1
1,1,7,7,7,7,7,7,7,7,7,7,1,1
1,1,7,7,7,7,7,7,7,7,7,7,1,1
1,1,7,7,7,7,7,7,7,7,7,7,1,1
7,7,7,7,7,7,7,7,7,7,7,7,1,1
7,7,7,7,7,7,7,7,7,7,7,7,1,1
1,1,7,7,7,7,7,7,7,7,7,7,1,1
1,1,7,7,7,7,7,7,7,7,7,7,1,1
1,1,7,7,7,7,7,7,7,7,7,7,1,1
1,1,7,7,7,7,7,7,7,7,7,7,1,1
1,1,1,1,1,1,1,1,1,1,1,1,1,1
1,1,1,1,1,1,1,1,1,1,1,1,1,1
endlayer


layer
1,1,1,1,1,1,1,1,1,1,1,1,1,1
1,4,4,4,4,4,4,4,3,3,3,3,3,1
1,4,6,6,6,6,6,6,6,6,6,5,3,1
1,4,8,7,7,7,7,7,7,7,7,5,3,1
1,4,8,7,7,7,7,7,7,7,7,5,3,1
1,4,8,7,7,7,7,7,7,7,7,5,3,1
0,8,7,7,7,7,7,7,7,7,7,5,3,1
0,8,7,7,7,7,7,7,7,7,7,5,3,1
1,3,8,7,7,7,7,7,7,7,7,5,3,1
1,3,8,7,7,7,7,7,7,7,7,5,3,1
1,3,8,7,7,7,7,7,7,7,7,5,3,1
1,4,8,9,9,9,9,9,9,9,9,9,3,1
1,4,4,4,4,4,4,4,3,3,3,3,3,1
1,1,1,1,1,1,1,1,1,1,1,1,1,1
endlayer

layer
0,0,0,0,0,0,0,0,0,0,0,0,0,0
0,0,0,0,0,0,0,4,3,3,3,3,3,0
0,0,0,0,0,0,0,0,0,0,0,0,3,0
0,0,0,7,7,7,7,7,7,7,7,0,3,0
0,0,0,7,7,7,7,7,7,7,7,0,3,0
0,0,0,7,7,7,7,7,7,7,7,0,3,0
0,0,8,7,7,7,7,7,7,7,7,0,3,0
0,0,8,7,7,7,7,7,7,7,7,0,3,0
0,0,0,7,7,7,7,7,7,7,7,0,3,0
0,0,0,7,7,7,7,7,7,7,7,0,3,0
0,0,0,7,7,7,7,7,7,7,7,0,3,0
0,0,0,0,0,0,0,0,0,0,0,0,3,0
0,0,0,0,0,0,0,4,3,3,3,3,3,0
0,0,0,0,0,0,0,0,0,0,0,0,0,0
endlayer

layer
0,0,0,0,0,0,0,0,0,0,0,0,0,0
0,0,0,0,0,0,0,0,0,0,0,0,0,0
0,0,0,0,0,0,0,0,0,0,0,0,0,0
0,0,0,10,11,11,11,11,11,11,10,0,0,0
0,0,0,11,29,19,0,0,0,0,11,0,0,0
0,0,0,11,19,19,0,0,0,12,11,0,0,0
0,0,0,13,0,0,0,0,0,0,11,0,0,0
0,0,0,13,0,0,0,0,0,0,11,0,0,0
0,0,0,11,19,19,0,0,19,19,11,0,0,0
0,0,0,11,30,19,0,0,19,28,11,0,0,0
0,0,0,10,11,11,11,11,11,11,10,0,0,0
0,0,0,0,0,0,0,0,0,0,0,0,0,0
0,0,0,0,0,0,0,0,0,0,0,0,0,0
0,0,0,0,0,0,0,0,0,0,0,0,0,0
endlayer

layer
0,0,0,0,0,0,0,0,0,0,0,0,0,0
0,0,0,0,0,0,0,0,0,0,0,0,0,0
0,0,0,0,0,0,0,0,0,0,0,0,0,0
0,0,0,10,11,11,14,14,11,11,10,0,0,0
0,0,0,11,0,15,0,0,15,0,11,0,0,0
0,0,0,11,0,0,0,0,0,12,11,0,0,0
0,0,0,16,0,0,0,0,0,0,14,0,0,0
0,0,0,17,0,0,0,0,0,0,14,0,0,0
0,0,0,11,0,0,0,0,0,0,11,0,0,0
0,0,0,11,0,18,0,0,18,0,11,0,0,0
0,0,0,10,11,11,14,14,11,11,10,0,0,0
0,0,0,0,0,0,0,0,0,0,0,0,0,0
0,0,0,0,0,0,0,0,0,0,0,0,0,0
0,0,0,0,0,0,0,0,0,0,0,0,0,0
endlayer

layer
0,0,0,0,0,0,0,0,0,0,0,0,0,0
0,0,0,0,0,0,0,0,0,0,0,0,0,0
0,0,0,0,0,0,0,0,0,0,0,0,0,0
0,0,0,10,11,11,14,14,11,11,10,0,0,0
0,0,0,11,0,19,0,0,0,0,11,0,0,0
0,0,0,11,19,19,0,0,0,12,11,0,0,0
0,0,0,19,0,0,0,0,0,0,14,0,0,0
0,0,0,19,0,0,0,0,0,0,14,0,0,0
0,0,0,11,19,19,0,0,19,19,11,0,0,0
0,0,0,11,0,19,0,0,19,0,11,0,0,0
0,0,0,10,11,11,14,14,11,11,10,0,0,0
0,0,0,0,0,0,0,0,0,0,0,0,0,0
0,0,0,0,0,0,0,0,0,0,0,0,0,0
0,0,0,0,0,0,0,0,0,0,0,0,0,0
endlayer

layer
0,0,0,0,0,0,0,0,0,0,0,0,0,0
0,0,0,0,0,0,0,0,0,0,0,0,0,0
0,0,10,10,10,10,10,10,10,10,10,10,0,0
0,0,10,10,10,10,10,10,10,10,10,10,0,0
0,0,10,10,10,10,10,10,10,10,10,10,0,0
0,0,10,10,10,10,10,10,10,12,10,10,0,0
0,0,10,10,10,10,10,10,10,10,10,10,0,0
0,0,10,10,10,10,10,10,10,10,10,10,0,0
0,0,10,10,10,10,10,10,10,10,10,10,0,0
0,0,10,10,10,10,10,10,10,10,10,10,0,0
0,0,10,10,10,10,10,10,10,10,10,10,0,0
0,0,10,10,10,10,10,10,10,10,10,10,0,0
0,0,0,0,0,0,0,0,0,0,0,0,0,0
0,0,0,0,0,0,0,0,0,0,0,0,0,0
endlayer

layer
0,0,0,0,0,0,0,0,0,0,0,0,0,0
0,0,0,0,0,0,0,0,0,0,0,0,0,0
0,0,10,19,19,10,19,19,10,19,19,10,0,0
0,0,19,0,0,0,0,0,0,0,0,19,0,0
0,0,19,0,0,0,0,27,0,0,0,19,0,0
0,0,10,0,0,0,0,0,0,0,0,10,0,0
0,0,19,0,27,0,0,0,0,27,26,19,0,0
0,0,19,0,0,0,0,0,0,0,31,19,0,0
0,0,10,0,0,0,0,0,0,0,0,10,0,0
0,0,19,0,0,0,0,27,0,0,0,19,0,0
0,0,19,0,0,0,0,0,0,0,0,19,0,0
0,0,10,19,19,10,19,19,10,19,19,10,0,0
0,0,0,0,0,0,0,0,0,0,0,0,0,0
0,0,0,0,0,0,0,0,0,0,0,0,0,0
endlayer

layer
0,0,0,0,0,0,0,0,0,0,0,0,0,0
0,0,0,0,0,0,0,0,0,0,0,0,0,0
0,0,10,11,11,10,14,14,10,11,11,10,0,0
0,0,11,0,0,15,0,0,15,0,0,11,0,0
0,0,11,0,0,0,0,0,0,0,0,11,0,0
0,0,10,0,0,0,0,0,0,0,0,10,0,0
0,0,14,0,0,0,0,0,0,0,0,14,0,0
0,0,14,0,0,0,0,0,0,0,0,14,0,0
0,0,10,0,0,0,0,0,0,0,0,10,0,0
0,0,11,0,0,0,0,0,0,0,0,11,0,0
0,0,11,0,0,18,0,0,18,0,0,11,0,0
0,0,10,11,11,10,14,14,10,11,11,10,0,0
0,0,0,0,0,0,0,0,0,0,0,0,0,0
0,0,0,0,0,0,0,0,0,0,0,0,0,0
endlayer

layer
0,0,0,0,0,0,0,0,0,0,0,0,0,0
0,0,0,0,0,0,0,0,0,0,0,0,0,0
0,0,10,11,11,10,14,14,10,11,11,10,0,0
0,0,11,0,0,0,0,0,0,0,0,11,0,0
0,0,11,0,0,0,0,0,0,0,0,11,0,0
0,0,10,0,0,0,0,0,0,0,0,10,0,0
0,0,14,0,0,0,0,0,0,0,0,14,0,0
0,0,14,0,0,0,0,0,0,0,0,14,0,0
0,0,10,0,0,0,0,0,0,0,0,10,0,0
0,0,11,0,0,0,0,0,0,0,0,11,0,0
0,0,11,0,0,0,0,0,0,0,0,11,0,0
0,0,10,11,11,10,14,14,10,11,11,10,0,0
0,0,0,0,0,0,0,0,0,0,0,0,0,0
0,0,0,0,0,0,0,0,0,0,0,0,0,0
endlayer

layer
0,0,0,0,0,0,0,0,0,0,0,0,0,0
0,0,0,0,0,0,0,0,0,0,0,0,0,0
0,0,10,11,11,10,14,14,10,11,11,10,0,0
0,0,11,0,0,0,0,0,0,0,0,11,0,0
0,0,11,0,0,0,0,0,0,0,0,11,0,0
0,0,10,0,0,0,0,0,0,0,0,10,0,0
0,0,14,0,0,0,0,0,0,0,0,14,0,0
0,0,14,0,0,0,0,0,0,0,0,14,0,0
0,0,10,0,0,0,0,0,0,0,0,10,0,0
0,0,11,0,0,0,0,0,0,0,0,11,0,0
0,0,11,0,0,0,0,0,0,0,0,11,0,0
0,0,10,11,11,10,14,14,10,11,11,10,0,0
0,0,0,0,0,0,0,0,0,0,0,0,0,0
0,0,0,0,0,0,0,0,0,0,0,0,0,0
endlayer

layer
0,0,0,0,0,0,0,0,0,0,0,0,0,0
0,20,20,20,20,20,20,20,20,20,20,20,20,0
0,22,10,10,10,10,10,10,10,10,10,10,21,0
0,22,10,23,0,0,0,0,0,0,23,10,21,0
0,22,10,0,0,0,0,0,0,0,0,10,21,0
0,22,10,0,0,0,0,0,0,0,0,10,21,0
0,22,10,0,0,0,0,0,0,0,0,10,21,0
0,22,10,0,0,0,0,0,0,0,0,10,21,0
0,22,10,0,0,0,0,0,0,0,0,10,21,0
0,22,10,0,0,0,0,0,0,0,0,10,21,0
0,22,10,23,0,0,0,0,0,0,23,10,21,0
0,22,10,10,10,10,10,10,10,10,10,10,21,0
0,24,24,24,24,24,24,24,24,24,24,24,21,0
0,0,0,0,0,0,0,0,0,0,0,0,0,0
endlayer

layer
0,0,0,0,0,0,0,0,0,0,0,0,0,0
0,0,0,0,0,0,0,0,0,0,0,0,0,0
0,0,22,20,20,20,20,20,20,20,20,20,0,0
0,0,22,10,10,10,10,10,10,10,10,21,0,0
0,0,22,10,23,0,0,0,0,23,10,21,0,0
0,0,22,10,0,0,0,0,0,0,10,21,0,0
0,0,22,10,0,0,0,0,0,0,10,21,0,0
0,0,22,10,0,0,0,0,0,0,10,21,0,0
0,0,22,10,0,0,0,0,0,0,10,21,0,0
0,0,22,10,23,0,0,0,0,23,10,21,0,0
0,0,22,10,10,10,10,10,10,10,10,21,0,0
0,0,22,24,24,24,24,24,24,24,24,21,0,0
0,0,0,0,0,0,0,0,0,0,0,0,0,0
0,0,0,0,0,0,0,0,0,0,0,0,0,0
endlayer

layer
0,0,0,0,0,0,0,0,0,0,0,0,0,0
0,0,0,0,0,0,0,0,0,0,0,0,0,0
0,0,0,0,0,0,0,0,0,0,0,0,0,0
0,0,0,20,20,20,20,20,20,20,21,0,0,0
0,0,0,22,10,10,10,10,10,10,21,0,0,0
0,0,0,22,10,23,0,0,23,10,21,0,0,0
0,0,0,22,10,0,0,0,0,10,21,0,0,0
0,0,0,22,10,0,0,0,0,10,21,0,0,0
0,0,0,22,10,23,0,0,23,10,21,0,0,0
0,0,0,22,10,10,10,10,10,10,21,0,0,0
0,0,0,24,24,24,24,24,24,24,24,0,0,0
0,0,0,0,0,0,0,0,0,0,0,0,0,0
0,0,0,0,0,0,0,0,0,0,0,0,0,0
0,0,0,0,0,0,0,0,0,0,0,0,0,0
endlayer

layer
0,0,0,0,0,0,0,0,0,0,0,0,0,0
0,0,0,0,0,0,0,0,0,0,0,0,0,0
0,0,0,0,0,0,0,0,0,0,0,0,0,0
0,0,0,0,0,0,0,0,0,0,0,0,0,0
0,0,0,0,22,20,20,20,20,21,0,0,0,0
0,0,0,0,22,10,10,10,10,21,0,0,0,0
0,0,0,0,22,10,23,23,10,21,0,0,0,0
0,0,0,0,22,10,23,23,10,21,0,0,0,0
0,0,0,0,22,10,10,10,10,21,0,0,0,0
0,0,0,0,24,24,24,24,24,21,0,0,0,0
0,0,0,0,0,0,0,0,0,0,0,0,0,0
0,0,0,0,0,0,0,0,0,0,0,0,0,0
0,0,0,0,0,0,0,0,0,0,0,0,0,0
0,0,0,0,0,0,0,0,0,0,0,0,0,0
endlayer

layer
0,0,0,0,0,0,0,0,0,0,0,0,0,0
0,0,0,0,0,0,0,0,0,0,0,0,0,0
0,0,0,0,0,0,0,0,0,0,0,0,0,0
0,0,0,0,0,0,0,0,0,0,0,0,0,0
0,0,0,0,0,0,0,0,0,0,0,0,0,0
0,0,0,0,0,25,25,25,25,0,0,0,0,0
0,0,0,0,0,25,25,25,25,0,0,0,0,0
0,0,0,0,0,25,25,25,25,0,0,0,0,0
0,0,0,0,0,25,25,25,25,0,0,0,0,0
0,0,0,0,0,0,0,0,0,0,0,0,0,0
0,0,0,0,0,0,0,0,0,0,0,0,0,0
0,0,0,0,0,0,0,0,0,0,0,0,0,0
0,0,0,0,0,0,0,0,0,0,0,0,0,0
0,0,0,0,0,0,0,0,0,0,0,0,0,0
endlayer

