# Created 10/26/2014 -- MC 1.7.10
# Created by Ruins mod version 13.8 Ingame Parser
# authoring Player: Kujaku10

# Updated to MC 1.8: 5 Mar 2016
# Updated to MC 1.9: 18 Apr 2016
# Updated to MC 1.11.2: 11 Jan 2017
# Updated to MC 1.12: 22 Jun 2017

weight=1
embed_into_distance=3
acceptable_target_blocks=

unacceptable_target_blocks=flowing_lava,lava,cloud,Natura:Cloud,red_mushroom_block,brown_mushroom_block,planks,cobblestone,torch,stone_slab,double_stone_slab,oak_stairs,spruce_stairs,birch_stairs,dark_oak_stairs,acacia_stairs,jungle_stairs,slime_congealed,slime_dirt,slime_grass,fence,stone_brick,cobblestone_wall,command_block

dimensions=14,13,15
allowable_overhang=0
max_leveling=3
leveling_buffer=-1
preserve_water=0
preserve_lava=0
preserve_plants=1

rule1=0,100,preserveBlock
rule2=0,100,minecraft:grass-0
rule3=0,100,minecraft:double_plant-1
rule4=1,100,minecraft:leaves-14
rule5=1,100,minecraft:leaves-6

rule6=0,100,minecraft:stonebrick-0,minecraft:stonebrick-0,minecraft:stonebrick-0,minecraft:stonebrick-2

rule7=0,100,minecraft:planks-5
rule8=0,100,minecraft:planks-1
rule9=0,100,minecraft:planks-2
rule10=0,100,minecraft:red_flower-1
rule11=0,100,minecraft:red_flower-0
rule12=0,100,minecraft:brick_stairs-0
rule13=0,100,minecraft:brick_stairs-3
rule14=0,100,minecraft:brick_stairs-1
rule15=0,100,minecraft:double_plant-9
rule16=0,100,minecraft:quartz_block-0
rule17=0,100,minecraft:acacia_stairs-6
rule18=0,100,minecraft:wooden_slab-12
rule19=0,100,minecraft:acacia_stairs-7
rule20=0,100,minecraft:crafting_table-0

rule21=0,100,IInventory;minecraft:lit_furnace;minecraft:coal#4#0-3

rule22=0,100,minecraft:wooden_door-3

rule23=0,100,ChestGenHook:chests/spawn_bonus_chest:3-3

rule24=0,100,minecraft:wooden_slab-2
rule25=0,100,minecraft:acacia_stairs-0
rule26=0,100,minecraft:double_plant-11
rule27=0,100,minecraft:double_plant-8
rule28=0,100,minecraft:glass_pane-0

# Flower Pot: Yellow Flower (original)
rule29=0,100,teBlock;minecraft:flower_pot;{Item:"minecraft:yellow_flower",x:0,y:0,z:0,Data:0,id:"flower_pot"}-0

# Flower Pot: Jungle Sapling
rule30=0,100,teBlock;minecraft:flower_pot;{Item:"minecraft:sapling",x:0,y:0,z:0,Data:3,id:"flower_pot"}-0


rule31=0,100,minecraft:fence-0
rule32=0,100,minecraft:wooden_door-8
rule33=2,100,minecraft:torch-5
rule34=0,100,minecraft:birch_stairs-0
rule35=0,100,minecraft:spruce_stairs-5
rule36=0,100,minecraft:spruce_stairs-4
rule37=0,100,minecraft:birch_stairs-1
rule38=0,100,minecraft:spruce_stairs-7
rule39=0,100,minecraft:spruce_stairs-6
rule40=0,100,minecraft:birch_stairs-3
rule41=0,100,minecraft:birch_stairs-2

# Bandit
rule42=0,100,CommandBlock:RUINSTRIGGER /summon Skeleton ~0 ~0 ~0 {HandItems:[{Count:1,id:wooden_sword,tag:{display:{Name:"Bandit Bludgeon"},ench:[{id:19,lvl:2},{id:21,lvl:2},{id:16,lvl:3}]}},{}],ArmorItems:[{Count:1,id:leather_boots},{Count:1,id:leather_leggings},{Count:1,id:leather_chestplate},{Count:1,id:skull,Damage:3,tag:{SkullOwner:MHF_Villager}}],CustomName:Bandit,HandDropChances:[1.0F,0.0F],ArmorDropChances:[0.5F,0.5F,0.5F,0.0F],Silent:1,PersistenceRequired:1,Health:15.0f}:@



layer
2,2,2,2,2,2,2,2,2,2,2,2,2,2,2
2,2,2,2,2,2,2,2,2,2,2,2,2,2,2
2,2,6,6,6,6,6,6,6,6,6,6,6,2,2
2,2,6,7,8,9,8,7,8,9,8,7,6,2,2
2,2,6,8,9,8,7,8,7,8,9,8,6,2,2
2,2,6,9,8,7,8,9,8,7,8,9,6,2,2
2,2,6,8,7,8,9,8,9,8,7,8,6,2,2
2,2,6,9,8,7,8,9,8,7,8,9,6,2,2
2,2,6,8,9,8,7,8,7,8,9,8,6,2,2
2,2,6,7,8,9,8,7,8,9,8,7,6,2,2
2,2,6,6,6,6,6,6,6,6,6,6,6,2,2
2,2,2,2,2,2,2,2,2,2,2,2,2,2,2
2,2,2,2,2,2,2,2,2,2,2,2,2,2,2
endlayer

layer
2,2,2,2,2,2,2,2,2,2,2,2,2,2,2
2,2,2,2,2,2,2,2,2,2,2,2,2,2,2
2,2,6,6,6,6,6,6,6,6,6,6,6,2,2
2,2,6,30,0,0,0,29,0,0,0,30,6,2,2
2,2,6,0,0,0,0,0,0,0,0,0,6,2,2
2,2,6,0,0,0,0,0,0,0,0,0,6,2,2
2,2,6,29,0,0,0,0,0,0,0,29,6,2,2
2,2,6,0,0,0,0,0,0,0,0,0,6,2,2
2,2,6,0,0,0,0,0,0,0,0,0,6,2,2
2,2,6,30,0,0,0,29,0,0,0,30,6,2,2
2,2,6,6,6,6,6,6,6,6,6,6,6,2,2
2,2,2,2,2,2,2,2,2,2,2,2,2,2,2
2,2,2,2,2,2,2,2,2,2,2,2,2,2,2
endlayer


layer
1,1,1,1,1,1,1,1,1,1,1,1,1,1,1
1,2,2,2,2,2,2,2,2,2,2,2,2,2,1
1,2,6,6,6,6,6,6,6,6,6,6,6,2,1
1,2,6,0,0,0,0,0,0,0,0,0,6,2,1
1,2,6,0,0,0,0,0,0,0,0,0,6,2,1
1,2,6,0,0,0,0,0,0,0,0,0,6,2,1
1,2,6,0,0,0,0,0,0,0,0,0,6,2,1
1,2,6,0,0,0,0,0,0,0,0,0,6,2,1
1,2,6,0,0,0,0,0,0,0,0,0,6,2,1
1,2,6,0,0,0,0,0,0,0,0,0,6,2,1
1,2,6,6,6,6,6,6,6,6,6,6,6,2,1
1,2,2,2,2,2,2,2,2,2,2,2,2,2,1
1,1,1,1,1,1,1,1,1,1,1,1,1,1,1
endlayer


layer
1,1,1,0,0,0,0,0,0,0,0,0,1,1,1
1,3,5,5,5,5,5,5,5,5,5,4,4,3,1
1,5,6,6,6,6,6,6,6,6,6,6,6,5,1
0,10,6,7,8,9,8,7,8,9,8,7,6,5,0
0,11,6,8,9,8,7,8,7,8,9,8,6,10,0
0,12,6,9,8,7,8,9,8,7,8,9,6,11,0
0,13,6,8,7,8,9,8,9,8,7,8,6,5,0
0,14,6,9,8,7,8,9,8,7,8,9,6,11,0
0,11,6,8,9,8,7,8,7,8,9,8,6,10,0
0,10,6,7,8,9,8,7,8,9,8,7,6,5,0
1,5,6,6,6,6,6,6,6,6,6,6,6,5,1
1,3,5,5,5,5,5,5,5,5,5,5,5,3,1
1,1,1,0,0,0,0,0,0,0,0,0,1,1,1
endlayer

layer
1,1,0,0,0,0,0,0,0,0,0,0,0,1,1
1,15,0,0,0,0,0,0,0,0,0,0,0,15,1
0,0,9,16,16,9,16,16,16,9,16,16,9,0,0
0,0,16,17,0,0,19,18,17,0,0,0,16,0,0
0,0,7,0,0,0,0,0,0,0,0,0,16,0,0
0,0,8,0,0,0,0,0,0,0,0,20,16,0,0
0,0,0,22,0,0,42,0,42,0,0,21,9,0,0
0,0,8,0,0,0,0,0,0,0,0,23,16,0,0
0,0,7,0,0,0,0,0,0,0,0,0,16,0,0
0,0,16,17,0,24,25,25,25,24,0,0,16,0,0
0,0,9,16,16,9,16,16,16,9,16,16,9,0,0
1,27,0,0,0,0,0,0,0,0,0,0,0,26,1
1,1,0,0,0,0,0,0,0,0,0,0,0,1,1
endlayer

layer
1,0,0,0,0,0,0,0,0,0,0,0,0,0,1
0,0,0,0,0,0,0,0,0,0,0,0,0,0,0
0,0,9,16,28,9,16,28,16,9,28,16,9,0,0
0,0,16,30,0,0,0,29,0,0,0,0,16,0,0
0,0,7,0,0,0,0,0,0,0,0,0,28,0,0
0,31,8,0,0,0,0,0,0,0,0,0,28,0,0
0,0,0,32,0,0,0,0,0,0,0,0,9,0,0
0,31,8,0,0,0,0,0,0,0,0,0,28,0,0
0,0,7,0,0,0,0,0,0,0,0,0,28,0,0
0,0,16,30,0,0,0,0,0,0,0,0,16,0,0
0,0,9,16,28,9,16,28,16,9,28,16,9,0,0
0,0,0,0,0,0,0,0,0,0,0,0,0,0,0
1,0,0,0,0,0,0,0,0,0,0,0,0,0,1
endlayer

layer
0,0,0,0,0,0,0,0,0,0,0,0,0,0,0
0,0,0,0,0,0,0,0,0,0,0,0,0,0,0
0,0,9,16,28,9,16,28,16,9,28,16,9,0,0
0,0,16,0,0,31,0,0,0,31,0,0,16,0,0
0,0,8,0,0,0,0,0,0,0,0,0,28,0,0
0,33,7,0,0,0,0,0,0,0,0,0,28,0,0
0,0,7,0,0,0,0,0,0,0,0,0,9,0,0
0,33,7,0,0,0,0,0,0,0,0,0,28,0,0
0,0,8,0,0,0,0,0,0,0,0,0,28,0,0
0,0,16,0,0,31,0,0,0,31,0,0,16,0,0
0,0,9,16,28,9,16,28,16,9,28,16,9,0,0
0,0,0,0,0,0,0,0,0,0,0,0,0,0,0
0,0,0,0,0,0,0,0,0,0,0,0,0,0,0
endlayer

layer
0,0,0,0,0,0,0,0,0,0,0,0,0,0,0
0,0,0,0,0,0,0,0,0,0,0,0,0,0,0
0,0,9,16,16,9,16,16,16,9,16,16,9,0,0
0,0,16,0,0,33,0,0,0,33,0,0,16,0,0
0,0,16,0,0,0,0,0,0,0,0,0,16,0,0
0,0,16,0,0,0,0,0,0,0,0,0,16,0,0
0,0,16,0,0,0,0,0,0,0,0,0,9,0,0
0,0,16,0,0,0,0,0,0,0,0,0,16,0,0
0,0,16,0,0,0,0,0,0,0,0,0,16,0,0
0,0,16,0,0,33,0,0,0,33,0,0,16,0,0
0,0,9,16,16,9,16,16,16,9,16,16,9,0,0
0,0,0,0,0,0,0,0,0,0,0,0,0,0,0
0,0,0,0,0,0,0,0,0,0,0,0,0,0,0
endlayer

layer
0,0,0,0,0,0,0,0,0,0,0,0,0,0,0
0,34,34,34,34,34,34,34,34,34,34,34,34,34,0
0,0,7,8,8,8,8,8,8,8,8,8,7,0,0
0,0,8,35,0,0,0,35,0,0,0,35,8,0,0
0,0,8,0,0,0,0,0,0,0,0,0,8,0,0
0,0,8,0,0,0,0,0,0,0,0,0,8,0,0
0,0,7,0,0,0,0,0,0,0,0,0,7,0,0
0,0,8,0,0,0,0,0,0,0,0,0,8,0,0
0,0,8,0,0,0,0,0,0,0,0,0,8,0,0
0,0,8,36,0,0,0,36,0,0,0,36,8,0,0
0,0,7,8,8,8,8,8,8,8,8,8,7,0,0
0,37,37,37,37,37,37,37,37,37,37,37,37,37,0
0,0,0,0,0,0,0,0,0,0,0,0,0,0,0
endlayer

layer
0,0,0,0,0,0,0,0,0,0,0,0,0,0,0
0,0,0,0,0,0,0,0,0,0,0,0,0,0,0
0,34,34,34,34,34,34,34,34,34,34,34,34,34,0
0,0,7,7,7,7,7,7,7,7,7,7,7,0,0
0,0,16,0,0,0,0,0,0,0,0,0,16,0,0
0,0,16,0,0,0,0,0,0,0,0,0,16,0,0
0,0,7,0,0,0,0,0,0,0,0,0,7,0,0
0,0,16,0,0,0,0,0,0,0,0,0,16,0,0
0,0,16,0,0,0,0,0,0,0,0,0,16,0,0
0,0,7,7,7,7,7,7,7,7,7,7,7,0,0
0,37,37,37,37,37,37,37,37,37,37,37,37,37,0
0,0,0,0,0,0,0,0,0,0,0,0,0,0,0
0,0,0,0,0,0,0,0,0,0,0,0,0,0,0
endlayer

layer
0,0,0,0,0,0,0,0,0,0,0,0,0,0,0
0,0,0,0,0,0,0,0,0,0,0,0,0,0,0
0,0,0,0,0,0,0,0,0,0,0,0,0,0,0
0,34,34,34,34,34,34,34,34,34,34,34,34,34,0
0,0,8,8,8,8,8,8,8,8,8,8,8,0,0
0,0,16,0,0,0,0,0,0,0,0,0,16,0,0
0,0,7,0,0,0,0,0,0,0,0,0,7,0,0
0,0,16,0,0,0,0,0,0,0,0,0,16,0,0
0,0,8,8,8,8,8,8,8,8,8,8,8,0,0
0,37,37,37,37,37,37,37,37,37,37,37,37,37,0
0,0,0,0,0,0,0,0,0,0,0,0,0,0,0
0,0,0,0,0,0,0,0,0,0,0,0,0,0,0
0,0,0,0,0,0,0,0,0,0,0,0,0,0,0
endlayer

layer
0,0,0,0,0,0,0,0,0,0,0,0,0,0,0
0,0,0,0,0,0,0,0,0,0,0,0,0,0,0
0,0,0,0,0,0,0,0,0,0,0,0,0,0,0
0,0,0,0,0,0,0,0,0,0,0,0,0,0,0
0,34,34,34,34,34,34,34,34,34,34,34,34,34,0
0,0,7,7,7,7,7,7,7,7,7,7,7,0,0
0,0,7,39,0,0,0,8,0,0,0,38,7,0,0
0,0,7,7,7,7,7,7,7,7,7,7,7,0,0
0,37,37,37,37,37,37,37,37,37,37,37,37,37,0
0,0,0,0,0,0,0,0,0,0,0,0,0,0,0
0,0,0,0,0,0,0,0,0,0,0,0,0,0,0
0,0,0,0,0,0,0,0,0,0,0,0,0,0,0
0,0,0,0,0,0,0,0,0,0,0,0,0,0,0
endlayer

layer
0,0,0,0,0,0,0,0,0,0,0,0,0,0,0
0,0,0,0,0,0,0,0,0,0,0,0,0,0,0
0,0,0,0,0,0,0,0,0,0,0,0,0,0,0
0,0,0,0,0,0,0,0,0,0,0,0,0,0,0
0,0,0,0,0,0,0,0,0,0,0,0,0,0,0
0,9,34,34,34,34,34,34,34,34,34,34,34,9,0
0,0,8,8,8,8,8,8,8,8,8,8,8,0,0
0,9,37,37,37,37,37,37,37,37,37,37,37,9,0
0,0,0,0,0,0,0,0,0,0,0,0,0,0,0
0,0,0,0,0,0,0,0,0,0,0,0,0,0,0
0,0,0,0,0,0,0,0,0,0,0,0,0,0,0
0,0,0,0,0,0,0,0,0,0,0,0,0,0,0
0,0,0,0,0,0,0,0,0,0,0,0,0,0,0
endlayer

layer
0,0,0,0,0,0,0,0,0,0,0,0,0,0,0
0,0,0,0,0,0,0,0,0,0,0,0,0,0,0
0,0,0,0,0,0,0,0,0,0,0,0,0,0,0
0,0,0,0,0,0,0,0,0,0,0,0,0,0,0
0,0,0,0,0,0,0,0,0,0,0,0,0,0,0
0,34,0,0,0,0,0,0,0,0,0,0,0,34,0
0,9,41,24,24,24,24,24,24,24,24,24,40,9,0
0,37,0,0,0,0,0,0,0,0,0,0,0,37,0
0,0,0,0,0,0,0,0,0,0,0,0,0,0,0
0,0,0,0,0,0,0,0,0,0,0,0,0,0,0
0,0,0,0,0,0,0,0,0,0,0,0,0,0,0
0,0,0,0,0,0,0,0,0,0,0,0,0,0,0
0,0,0,0,0,0,0,0,0,0,0,0,0,0,0
endlayer

layer
0,0,0,0,0,0,0,0,0,0,0,0,0,0,0
0,0,0,0,0,0,0,0,0,0,0,0,0,0,0
0,0,0,0,0,0,0,0,0,0,0,0,0,0,0
0,0,0,0,0,0,0,0,0,0,0,0,0,0,0
0,0,0,0,0,0,0,0,0,0,0,0,0,0,0
0,0,0,0,0,0,0,0,0,0,0,0,0,0,0
0,41,0,0,0,0,0,0,0,0,0,0,0,40,0
0,0,0,0,0,0,0,0,0,0,0,0,0,0,0
0,0,0,0,0,0,0,0,0,0,0,0,0,0,0
0,0,0,0,0,0,0,0,0,0,0,0,0,0,0
0,0,0,0,0,0,0,0,0,0,0,0,0,0,0
0,0,0,0,0,0,0,0,0,0,0,0,0,0,0
0,0,0,0,0,0,0,0,0,0,0,0,0,0,0
endlayer

