# Town Hall 10/19/2014
# Created by Ruins mod version 13.8 Ingame Parser
# authoring Player: Kujaku10
# Last Updated 7 Feb 2016
# Updated to MC 1.8: 5 Mar 2016
# Updated to MC 1.9: 18 Apr 2016
# Updated to MC 1.11.2: 11 Jan 2017
# Updated to MC 1.12: 22 Jun 2017

biomesToSpawnIn=plains,sunflower plains

weight=1
embed_into_distance=4
acceptable_target_blocks=

unacceptable_target_blocks=flowing_lava,lava,cloud,Natura:Cloud,red_mushroom_block,brown_mushroom_block,planks,cobblestone,torch,stone_slab,double_stone_slab,oak_stairs,spruce_stairs,birch_stairs,dark_oak_stairs,acacia_stairs,jungle_stairs,slime_congealed,slime_dirt,slime_grass,fence,stone_brick,cobblestone_wall,command_block

dimensions=25,14,17
allowable_overhang=0

max_leveling=2

leveling_buffer=-1
preserve_water=0
preserve_lava=0
preserve_plants=1

rule1=0,100,preserveBlock
rule2=0,100,minecraft:stonebrick-0,minecraft:stonebrick-1,minecraft:stonebrick-2
rule3=1,100,minecraft:leaves-6
rule4=0,100,minecraft:double_plant-3
rule5=0,100,minecraft:stonebrick-0
rule6=0,100,minecraft:stone_brick_stairs-2
rule7=0,100,minecraft:stone_brick_stairs-1
rule8=0,100,minecraft:stone_brick_stairs-3
rule9=0,100,minecraft:double_plant-9
rule10=0,100,minecraft:quartz_block-0
rule11=0,100,minecraft:planks-5
rule12=0,100,minecraft:oak_stairs-1
rule13=0,100,minecraft:oak_stairs-3
rule14=0,100,minecraft:planks-0
rule15=0,100,minecraft:double_plant-11
rule16=0,100,minecraft:oak_stairs-0
rule17=0,100,minecraft:crafting_table-0
rule18=1,100,minecraft:dark_oak_door-2
rule19=0,100,minecraft:stonebrick-3
rule20=0,100,minecraft:double_plant-10
rule21=0,100,minecraft:glass_pane-0
rule22=0,100,minecraft:jungle_stairs-3
rule23=0,100,minecraft:bookshelf-0
rule24=2,100,minecraft:torch-2
rule25=1,100,minecraft:dark_oak_door-8
rule26=2,100,minecraft:torch-1
rule27=2,100,minecraft:torch-3
rule28=0,100,minecraft:oak_stairs-2
rule29=0,100,minecraft:oak_stairs-5
rule30=0,100,minecraft:oak_stairs-4
rule31=0,100,minecraft:stone_brick_stairs-0
rule32=0,100,minecraft:oak_stairs-7
rule33=0,100,minecraft:oak_stairs-6
rule34=0,100,minecraft:dark_oak_fence-0
rule35=0,100,minecraft:wooden_slab-0
rule36=2,100,minecraft:torch-4

# Bandit
rule37=0,100,CommandBlock:RUINSTRIGGER /summon Skeleton ~0 ~0 ~0 {HandItems:[{Count:1,id:wooden_sword,tag:{display:{Name:"Bandit Bludgeon"},ench:[{id:19,lvl:2},{id:21,lvl:2},{id:16,lvl:3}]}},{}],ArmorItems:[{Count:1,id:leather_boots},{Count:1,id:leather_leggings},{Count:1,id:leather_chestplate},{Count:1,id:skull,Damage:3,tag:{SkullOwner:MHF_Villager}}],CustomName:Bandit,HandDropChances:[1.0F,0.0F],ArmorDropChances:[0.5F,0.5F,0.5F,0.0F],Silent:1,PersistenceRequired:1,Health:15.0f}:@

rule38=0,100,ChestGenHook:chests/simple_dungeon:4-5

rule39=0,100,ChestGenHook:chests/spawn_bonus_chest:6-5,ChestGenHook:chests/village_blacksmith:3-5

layer
1,1,1,1,1,1,1,1,1,1,1,1,1,1,1,1,1
1,1,1,1,1,1,1,1,1,1,1,1,1,1,1,1,1
1,1,1,2,2,2,2,2,2,2,2,2,2,2,1,1,1
1,1,2,2,2,2,2,2,2,2,2,2,2,2,2,1,1
1,2,2,2,2,2,2,2,2,2,2,2,2,2,2,2,1
1,2,2,2,2,2,2,2,2,2,2,2,2,2,2,2,1
1,1,2,2,2,2,2,2,2,2,2,2,2,2,2,1,1
1,1,1,2,2,2,2,2,2,2,2,2,2,2,2,1,1
1,1,1,1,1,1,1,2,2,2,2,2,2,2,2,1,1
1,1,1,1,1,1,1,2,2,2,2,2,2,2,2,1,1
1,1,1,1,1,1,1,2,2,2,2,2,2,2,2,1,1
1,1,1,1,1,1,1,1,1,1,2,2,2,2,2,1,1
1,1,1,1,1,1,1,1,1,1,1,2,2,2,1,1,1
1,1,1,1,1,1,1,1,1,1,1,2,2,2,1,1,1
endlayer

layer
1,1,1,1,1,1,1,1,1,1,1,1,1,1,1,1,1
1,1,1,1,1,1,1,1,1,1,1,1,1,1,1,1,1
1,1,1,2,2,2,2,2,2,2,2,2,2,2,1,1,1
1,1,2,2,2,2,2,2,2,2,2,2,2,2,2,1,1
1,2,2,2,2,2,2,2,2,2,2,2,2,2,2,2,1
1,2,2,2,2,2,2,2,2,2,2,2,2,2,2,2,1
1,1,2,2,2,2,2,2,2,2,2,2,2,2,2,1,1
1,1,1,2,2,2,2,2,2,2,2,2,2,2,2,1,1
1,1,1,1,1,1,1,2,2,2,2,2,2,2,2,1,1
1,1,1,1,1,1,1,2,2,2,2,2,2,2,2,1,1
1,1,1,1,1,1,1,2,2,2,2,2,2,2,2,1,1
1,1,1,1,1,1,1,1,1,1,2,2,2,2,2,1,1
1,1,1,1,1,1,1,1,1,1,1,2,2,2,1,1,1
1,1,1,1,1,1,1,1,1,1,1,2,2,2,1,1,1
endlayer

layer
1,1,1,1,1,1,1,1,1,1,1,1,1,1,1,1,1
1,1,1,1,1,1,1,1,1,1,1,1,1,1,1,1,1
1,1,1,2,2,2,2,2,2,2,2,2,2,2,1,1,1
1,1,2,2,2,2,2,2,2,2,2,2,2,2,2,1,1
1,2,2,2,2,2,2,2,2,2,2,2,2,2,2,2,1
1,2,2,2,2,2,2,2,2,2,2,2,2,2,2,2,1
1,1,2,2,2,2,2,2,2,2,2,2,2,2,2,1,1
1,1,1,2,2,2,2,2,2,2,2,2,2,2,2,1,1
1,1,1,1,1,1,1,2,2,2,2,2,2,2,2,1,1
1,1,1,1,1,1,1,2,2,2,2,2,2,2,2,1,1
1,1,1,1,1,1,1,2,2,2,2,2,2,2,2,1,1
1,1,1,1,1,1,1,1,1,1,2,2,2,2,2,1,1
1,1,1,1,1,1,1,1,1,1,1,2,2,2,1,1,1
1,1,1,1,1,1,1,1,1,1,1,2,2,2,1,1,1
endlayer

layer
1,1,1,1,1,1,1,1,1,1,1,1,1,1,1,1,1
1,1,1,1,1,1,1,1,1,1,1,1,1,1,1,1,1
1,1,1,2,2,2,2,2,2,2,2,2,2,2,1,1,1
1,1,2,2,2,2,2,2,2,2,2,2,2,2,2,1,1
1,2,2,2,2,2,2,2,2,2,2,2,2,2,2,2,1
1,2,2,2,2,2,2,2,2,2,2,2,2,2,2,2,1
1,1,2,2,2,2,2,2,2,2,2,2,2,2,2,1,1
1,1,1,2,2,2,2,2,2,2,2,2,2,2,2,1,1
1,1,1,1,1,1,1,2,2,2,2,2,2,2,2,1,1
1,1,1,1,1,1,1,2,2,2,2,2,2,2,2,1,1
1,1,1,1,1,1,1,2,2,2,2,2,2,2,2,1,1
1,1,1,1,1,1,1,1,1,1,2,2,2,2,2,1,1
1,1,1,1,1,1,1,1,1,1,1,2,2,2,1,1,1
1,1,1,1,1,1,1,1,1,1,1,2,2,2,1,1,1
endlayer


layer
1,1,1,1,1,0,0,0,0,0,0,0,1,1,1,1,1
1,1,1,3,3,3,3,3,3,3,3,3,3,3,1,1,1
1,1,4,5,5,5,5,5,5,5,5,5,5,5,4,1,1
1,1,5,5,5,5,5,5,5,5,5,5,5,5,5,1,1
1,5,5,5,5,5,5,5,5,5,5,5,5,5,5,5,1
1,5,5,5,5,5,5,5,5,5,5,5,5,5,5,5,1
0,0,5,5,5,5,5,5,5,5,5,5,5,5,5,4,0
1,0,4,5,5,5,5,5,5,5,5,5,5,5,5,3,0
1,1,0,3,3,3,3,5,5,5,5,5,5,5,5,3,1
1,1,1,0,0,0,0,5,5,5,5,5,5,5,5,3,1
1,1,1,1,0,0,0,5,5,5,5,5,5,5,5,3,0
1,1,1,1,1,0,0,0,0,0,5,5,5,5,5,3,1
1,1,1,1,1,1,1,0,0,0,4,8,7,6,4,1,1
1,1,1,1,1,1,1,1,1,0,0,0,0,1,1,1,1
endlayer

layer
1,1,1,0,0,0,0,0,0,0,0,0,0,0,1,1,1
1,1,0,0,0,0,0,0,0,0,0,0,0,0,0,1,1
1,0,9,10,11,11,11,11,11,11,11,11,11,10,9,0,1
0,0,11,11,14,0,13,0,13,0,13,0,0,12,11,0,0
0,10,11,11,14,0,0,0,0,37,0,0,37,0,13,10,0
0,10,11,11,14,0,0,0,0,0,0,0,0,0,13,10,0
0,0,11,11,14,0,13,0,13,0,13,0,0,16,11,15,0
0,0,15,11,11,11,11,11,10,10,14,0,0,0,11,0,0
0,0,0,0,0,0,0,10,17,0,10,0,0,0,11,0,0
1,0,0,0,0,0,0,10,5,6,0,0,0,0,11,0,0
1,1,0,0,0,0,0,14,10,10,14,0,18,0,11,0,0
1,1,1,0,0,0,0,0,0,0,19,5,0,5,19,0,1
1,1,1,1,0,0,0,0,0,0,20,0,0,0,20,1,1
1,1,1,1,1,0,0,0,0,0,0,0,0,0,1,1,1
endlayer

layer
1,1,0,0,0,0,0,0,0,0,0,0,0,0,0,1,1
1,0,0,0,0,0,0,0,0,0,0,0,0,0,0,0,1
0,0,0,10,11,10,21,21,10,21,21,10,11,10,0,0,0
0,0,11,0,0,0,0,0,0,0,0,0,0,0,11,0,0
0,10,23,0,22,0,0,0,0,0,0,0,0,0,0,10,0
0,10,23,0,22,0,0,0,0,0,0,0,0,0,0,10,0
0,0,11,0,0,0,0,0,0,0,0,0,0,0,11,0,0
0,0,0,10,21,10,21,11,10,10,14,0,0,0,10,0,0
0,0,0,0,0,0,0,10,0,0,10,0,0,0,21,0,0
0,0,0,0,0,0,0,10,6,0,0,0,0,0,21,0,0
1,0,0,0,0,0,0,14,10,10,14,24,25,24,10,0,0
1,1,0,0,0,0,0,0,0,0,11,5,0,5,11,0,0
1,1,1,0,0,0,0,0,0,0,0,0,0,0,0,0,1
1,1,1,1,0,0,0,0,0,0,0,0,0,0,0,1,1
endlayer

layer
1,0,0,0,0,0,0,0,0,0,0,0,0,0,0,0,1
0,0,0,0,0,0,0,0,0,0,0,0,0,0,0,0,0
0,0,0,10,11,10,21,21,10,21,21,10,11,10,0,0,0
0,0,11,0,26,0,0,0,0,0,0,0,26,0,11,0,0
0,10,23,0,0,0,0,0,0,0,0,0,0,0,0,10,0
0,10,23,0,0,0,0,0,0,0,0,0,0,0,0,10,0
0,0,11,0,0,0,0,24,0,0,0,0,0,27,11,0,0
0,0,0,10,21,10,21,11,10,10,14,0,0,0,10,0,0
0,0,0,0,0,0,0,10,7,26,10,0,0,0,21,0,0
0,0,0,0,0,0,0,10,0,0,0,0,0,0,21,0,0
0,0,0,0,0,0,0,14,10,10,14,0,0,0,10,0,0
1,0,0,0,0,0,0,0,0,0,11,5,5,5,11,0,0
1,1,0,0,0,0,0,0,0,0,0,0,0,0,0,0,0
1,1,1,0,0,0,0,0,0,0,0,0,0,0,0,0,1
endlayer

layer
0,0,0,0,0,0,0,0,0,0,0,0,0,0,0,0,0
0,0,0,0,0,0,0,0,0,0,0,0,0,0,0,0,0
0,0,0,10,11,11,11,11,11,11,11,11,11,10,0,0,0
0,0,11,0,0,0,0,0,0,0,0,0,0,0,11,0,0
0,10,23,0,0,0,0,0,0,0,0,0,0,0,0,10,0
0,10,23,0,0,0,0,0,0,0,0,0,0,0,0,10,0
0,0,11,0,0,0,0,0,0,0,0,0,0,0,11,0,0
0,0,0,11,11,11,11,11,10,10,14,0,0,0,11,0,0
0,0,0,0,0,0,0,10,0,8,10,0,0,0,11,0,0
0,0,0,0,0,0,0,10,0,0,10,0,0,0,11,0,0
0,0,0,0,0,0,0,14,10,10,14,0,0,0,11,0,0
0,0,0,0,0,0,0,0,0,0,11,10,19,10,11,0,0
1,0,0,0,0,0,0,0,0,0,0,0,0,0,0,0,0
1,1,0,0,0,0,0,0,0,0,0,0,0,0,0,0,0
endlayer

layer
0,0,0,0,0,0,0,0,0,0,0,0,0,0,0,0,0
0,13,16,16,16,16,16,16,16,16,16,16,16,16,16,28,0
16,16,14,14,14,14,14,14,14,14,14,14,14,14,14,16,28
13,14,14,29,0,29,0,0,29,0,0,29,0,0,14,14,28
13,14,23,0,0,0,0,0,0,0,0,0,0,0,0,14,28
13,14,23,0,0,0,0,0,0,0,0,0,0,0,0,14,28
13,14,14,30,0,30,0,0,30,0,0,0,0,0,11,14,28
12,13,14,14,14,14,14,14,14,14,14,0,0,0,10,12,12
0,12,12,12,12,12,12,14,0,0,14,0,0,0,10,0,0
0,0,0,0,0,0,0,14,0,31,14,0,0,0,10,0,0
0,0,0,0,0,0,0,14,14,14,14,0,0,0,10,0,0
0,0,0,0,0,0,0,0,0,0,11,10,10,10,11,0,0
0,0,0,0,0,0,0,0,0,0,0,0,0,0,0,0,0
1,0,0,0,0,0,0,0,0,0,0,0,0,0,0,0,0
endlayer

layer
0,0,0,0,0,0,0,0,0,0,0,0,0,0,0,0,0
0,0,0,0,0,0,0,0,0,0,0,0,0,0,0,0,0
0,0,16,16,16,16,16,16,16,16,16,16,16,16,28,0,0
0,16,13,14,14,14,14,14,14,14,14,14,14,14,14,14,0
0,13,14,0,0,0,0,0,0,0,0,0,0,0,14,14,0
0,13,14,0,0,0,0,0,0,0,0,0,0,0,14,14,0
0,12,12,14,14,14,14,14,14,14,14,33,0,32,11,14,0
0,0,13,12,12,12,12,14,10,10,14,0,0,0,14,0,0
0,0,0,0,0,0,0,10,0,0,34,0,0,0,14,0,0
0,0,0,0,0,0,0,10,6,0,34,0,0,0,14,0,0
0,0,0,0,0,0,0,14,10,10,14,0,0,0,14,0,0
0,0,0,0,0,0,0,0,0,0,11,10,10,10,11,0,0
0,0,0,0,0,0,0,0,0,0,0,32,29,33,0,0,0
0,0,0,0,0,0,0,0,0,0,0,0,0,0,0,0,0
endlayer

layer
0,0,0,0,0,0,0,0,0,0,0,0,0,0,0,0,0
0,0,0,0,0,0,0,0,0,0,0,0,0,0,0,0,0
0,0,0,0,0,0,0,0,0,0,0,0,0,0,0,0,0
0,0,0,14,14,14,14,14,14,14,14,14,14,14,28,16,0
0,0,14,33,0,0,0,0,0,0,0,0,0,0,14,28,0
0,0,14,33,0,0,0,0,0,0,0,0,0,0,14,28,0
0,0,0,14,14,14,14,14,14,14,14,14,14,14,14,28,0
0,0,0,0,0,0,0,14,10,10,14,33,0,32,14,28,0
0,0,0,0,0,0,0,10,7,0,0,0,0,0,14,28,0
0,0,0,0,0,0,0,10,0,0,0,0,0,0,14,28,0
0,0,0,0,0,0,0,14,10,10,14,33,0,32,14,28,0
0,0,0,0,0,0,0,0,0,13,14,10,10,10,14,28,0
0,0,0,0,0,0,0,0,0,13,0,34,34,34,0,28,0
0,0,0,0,0,0,0,0,0,0,0,0,0,0,0,0,0
endlayer

layer
0,0,0,0,0,0,0,0,0,0,0,0,0,0,0,0,0
0,0,0,0,0,0,0,0,0,0,0,0,0,0,0,0,0
0,0,0,0,0,0,0,0,0,0,0,0,0,0,0,0,0
0,0,0,16,16,16,16,16,16,16,16,16,16,16,0,0,0
0,0,13,14,14,14,14,14,14,14,14,14,14,14,28,0,0
0,0,13,14,14,14,14,14,14,14,14,14,14,14,28,0,0
0,0,0,12,12,12,12,12,12,12,12,14,14,14,28,0,0
0,0,0,0,0,0,0,14,10,10,14,14,0,14,28,0,0
0,0,0,0,0,0,0,10,0,8,10,14,0,14,28,0,0
0,0,0,0,0,0,0,10,0,24,10,14,0,14,28,0,0
0,0,0,0,0,0,0,14,10,10,14,14,0,14,28,0,0
0,0,0,0,0,0,0,0,0,0,13,14,10,14,28,0,0
0,0,0,0,0,0,0,0,0,0,13,0,34,0,28,0,0
0,0,0,0,0,0,0,0,0,0,0,0,0,0,0,0,0
endlayer

layer
0,0,0,0,0,0,0,0,0,0,0,0,0,0,0,0,0
0,0,0,0,0,0,0,0,0,0,0,0,0,0,0,0,0
0,0,0,0,0,0,0,0,0,0,0,0,0,0,0,0,0
0,0,0,0,0,0,0,0,0,0,0,0,0,0,0,0,0
0,0,0,35,35,35,35,35,35,35,35,35,35,35,0,0,0
0,0,0,35,35,35,35,35,35,35,35,35,35,35,0,0,0
0,0,0,0,0,0,0,0,0,0,0,13,16,16,0,0,0
0,0,0,0,0,0,0,14,14,14,14,13,14,28,0,0,0
0,0,0,0,0,0,0,14,0,0,14,13,14,28,0,0,0
0,0,0,0,0,0,0,14,0,31,14,13,14,28,0,0,0
0,0,0,0,0,0,0,14,14,14,14,13,14,28,0,0,0
0,0,0,0,0,0,0,0,0,0,0,13,14,28,0,0,0
0,0,0,0,0,0,0,0,0,0,0,13,0,28,0,0,0
0,0,0,0,0,0,0,0,0,0,0,0,0,0,0,0,0
endlayer

layer
0,0,0,0,0,0,0,0,0,0,0,0,0,0,0,0,0
0,0,0,0,0,0,0,0,0,0,0,0,0,0,0,0,0
0,0,0,0,0,0,0,0,0,0,0,0,0,0,0,0,0
0,0,0,0,0,0,0,0,0,0,0,0,0,0,0,0,0
0,0,0,0,0,0,0,0,0,0,0,0,0,0,0,0,0
0,0,0,0,0,0,0,0,0,0,0,0,0,0,0,0,0
0,0,0,0,0,0,0,0,0,0,0,0,0,0,0,0,0
0,0,0,0,0,0,0,14,21,21,14,0,35,0,0,0,0
0,0,0,0,0,0,0,21,0,0,21,0,35,0,0,0,0
0,0,0,0,0,0,0,21,6,0,21,0,35,0,0,0,0
0,0,0,0,0,0,0,14,21,21,14,0,35,0,0,0,0
0,0,0,0,0,0,0,0,0,0,0,0,35,0,0,0,0
0,0,0,0,0,0,0,0,0,0,0,0,35,0,0,0,0
0,0,0,0,0,0,0,0,0,0,0,0,0,0,0,0,0
endlayer

layer
0,0,0,0,0,0,0,0,0,0,0,0,0,0,0,0,0
0,0,0,0,0,0,0,0,0,0,0,0,0,0,0,0,0
0,0,0,0,0,0,0,0,0,0,0,0,0,0,0,0,0
0,0,0,0,0,0,0,0,0,0,0,0,0,0,0,0,0
0,0,0,0,0,0,0,0,0,0,0,0,0,0,0,0,0
0,0,0,0,0,0,0,0,0,0,0,0,0,0,0,0,0
0,0,0,0,0,0,0,0,0,0,0,0,0,0,0,0,0
0,0,0,0,0,0,0,14,10,10,14,0,0,0,0,0,0
0,0,0,0,0,0,0,10,7,0,10,0,0,0,0,0,0
0,0,0,0,0,0,0,10,0,0,10,0,0,0,0,0,0
0,0,0,0,0,0,0,14,10,10,14,0,0,0,0,0,0
0,0,0,0,0,0,0,0,0,0,0,0,0,0,0,0,0
0,0,0,0,0,0,0,0,0,0,0,0,0,0,0,0,0
0,0,0,0,0,0,0,0,0,0,0,0,0,0,0,0,0
endlayer

layer
0,0,0,0,0,0,0,0,0,0,0,0,0,0,0,0,0
0,0,0,0,0,0,0,0,0,0,0,0,0,0,0,0,0
0,0,0,0,0,0,0,0,0,0,0,0,0,0,0,0,0
0,0,0,0,0,0,0,0,0,0,0,0,0,0,0,0,0
0,0,0,0,0,0,0,0,0,0,0,0,0,0,0,0,0
0,0,0,0,0,0,0,0,0,0,0,0,0,0,0,0,0
0,0,0,0,0,0,14,14,14,14,14,14,0,0,0,0,0
0,0,0,0,0,0,14,14,14,14,14,14,0,0,0,0,0
0,0,0,0,0,0,14,14,0,8,14,14,0,0,0,0,0
0,0,0,0,0,0,14,14,0,0,14,14,0,0,0,0,0
0,0,0,0,0,0,14,14,14,14,14,14,0,0,0,0,0
0,0,0,0,0,0,14,14,14,14,14,14,0,0,0,0,0
0,0,0,0,0,0,0,0,0,0,0,0,0,0,0,0,0
0,0,0,0,0,0,0,0,0,0,0,0,0,0,0,0,0
endlayer

layer
0,0,0,0,0,0,0,0,0,0,0,0,0,0,0,0,0
0,0,0,0,0,0,0,0,0,0,0,0,0,0,0,0,0
0,0,0,0,0,0,0,0,0,0,0,0,0,0,0,0,0
0,0,0,0,0,0,0,0,0,0,0,0,0,0,0,0,0
0,0,0,0,0,0,0,0,0,0,0,0,0,0,0,0,0
0,0,0,0,0,0,0,0,0,0,0,0,0,0,0,0,0
0,0,0,0,0,0,14,10,10,10,10,14,0,0,0,0,0
0,0,0,0,0,0,10,37,0,0,0,10,0,0,0,0,0
0,0,0,0,0,0,10,38,0,0,0,10,0,0,0,0,0
0,0,0,0,0,0,10,39,0,0,0,10,0,0,0,0,0
0,0,0,0,0,0,10,0,0,0,37,10,0,0,0,0,0
0,0,0,0,0,0,14,10,10,10,10,14,0,0,0,0,0
0,0,0,0,0,0,0,0,0,0,0,0,0,0,0,0,0
0,0,0,0,0,0,0,0,0,0,0,0,0,0,0,0,0
endlayer

layer
0,0,0,0,0,0,0,0,0,0,0,0,0,0,0,0,0
0,0,0,0,0,0,0,0,0,0,0,0,0,0,0,0,0
0,0,0,0,0,0,0,0,0,0,0,0,0,0,0,0,0
0,0,0,0,0,0,0,0,0,0,0,0,0,0,0,0,0
0,0,0,0,0,0,0,0,0,0,0,0,0,0,0,0,0
0,0,0,0,0,0,0,0,0,0,0,0,0,0,0,0,0
0,0,0,0,0,0,14,10,21,21,10,14,0,0,0,0,0
0,0,0,0,0,0,10,0,0,0,0,10,0,0,0,0,0
0,0,0,0,0,0,21,0,0,0,0,21,0,0,0,0,0
0,0,0,0,0,0,21,0,0,0,0,21,0,0,0,0,0
0,0,0,0,0,0,10,0,0,0,0,10,0,0,0,0,0
0,0,0,0,0,0,14,10,21,21,10,14,0,0,0,0,0
0,0,0,0,0,0,0,0,0,0,0,0,0,0,0,0,0
0,0,0,0,0,0,0,0,0,0,0,0,0,0,0,0,0
endlayer

layer
0,0,0,0,0,0,0,0,0,0,0,0,0,0,0,0,0
0,0,0,0,0,0,0,0,0,0,0,0,0,0,0,0,0
0,0,0,0,0,0,0,0,0,0,0,0,0,0,0,0,0
0,0,0,0,0,0,0,0,0,0,0,0,0,0,0,0,0
0,0,0,0,0,0,0,0,0,0,0,0,0,0,0,0,0
0,0,0,0,0,0,0,0,0,0,0,0,0,0,0,0,0
0,0,0,0,0,0,14,10,21,21,10,14,0,0,0,0,0
0,0,0,0,0,0,10,36,0,0,27,10,0,0,0,0,0
0,0,0,0,0,0,21,0,0,0,0,21,0,0,0,0,0
0,0,0,0,0,0,21,0,0,0,0,21,0,0,0,0,0
0,0,0,0,0,0,10,36,0,0,27,10,0,0,0,0,0
0,0,0,0,0,0,14,10,21,21,10,14,0,0,0,0,0
0,0,0,0,0,0,0,0,0,0,0,0,0,0,0,0,0
0,0,0,0,0,0,0,0,0,0,0,0,0,0,0,0,0
endlayer

layer
0,0,0,0,0,0,0,0,0,0,0,0,0,0,0,0,0
0,0,0,0,0,0,0,0,0,0,0,0,0,0,0,0,0
0,0,0,0,0,0,0,0,0,0,0,0,0,0,0,0,0
0,0,0,0,0,0,0,0,0,0,0,0,0,0,0,0,0
0,0,0,0,0,0,0,0,0,0,0,0,0,0,0,0,0
0,0,0,0,0,0,0,0,0,0,0,0,0,0,0,0,0
0,0,0,0,0,0,14,10,10,10,10,14,0,0,0,0,0
0,0,0,0,0,0,10,0,0,0,0,10,0,0,0,0,0
0,0,0,0,0,0,10,0,0,0,0,10,0,0,0,0,0
0,0,0,0,0,0,10,0,0,0,0,10,0,0,0,0,0
0,0,0,0,0,0,10,0,0,0,0,10,0,0,0,0,0
0,0,0,0,0,0,14,10,10,10,10,14,0,0,0,0,0
0,0,0,0,0,0,0,0,0,0,0,0,0,0,0,0,0
0,0,0,0,0,0,0,0,0,0,0,0,0,0,0,0,0
endlayer

layer
0,0,0,0,0,0,0,0,0,0,0,0,0,0,0,0,0
0,0,0,0,0,0,0,0,0,0,0,0,0,0,0,0,0
0,0,0,0,0,0,0,0,0,0,0,0,0,0,0,0,0
0,0,0,0,0,0,0,0,0,0,0,0,0,0,0,0,0
0,0,0,0,0,0,0,0,0,0,0,0,0,0,0,0,0
0,0,0,0,0,16,16,16,16,16,16,16,16,0,0,0,0
0,0,0,0,0,13,14,14,14,14,14,14,28,0,0,0,0
0,0,0,0,0,13,14,0,0,0,0,14,28,0,0,0,0
0,0,0,0,0,13,14,0,0,0,0,14,28,0,0,0,0
0,0,0,0,0,13,14,0,0,0,0,14,28,0,0,0,0
0,0,0,0,0,13,14,0,0,0,0,14,28,0,0,0,0
0,0,0,0,0,13,14,14,14,14,14,14,28,0,0,0,0
0,0,0,0,0,13,12,12,12,12,12,12,12,0,0,0,0
0,0,0,0,0,0,0,0,0,0,0,0,0,0,0,0,0
endlayer

layer
0,0,0,0,0,0,0,0,0,0,0,0,0,0,0,0,0
0,0,0,0,0,0,0,0,0,0,0,0,0,0,0,0,0
0,0,0,0,0,0,0,0,0,0,0,0,0,0,0,0,0
0,0,0,0,0,0,0,0,0,0,0,0,0,0,0,0,0
0,0,0,0,0,0,0,0,0,0,0,0,0,0,0,0,0
0,0,0,0,0,0,0,0,0,0,0,0,0,0,0,0,0
0,0,0,0,0,0,13,16,16,16,16,28,0,0,0,0,0
0,0,0,0,0,0,13,14,14,14,14,28,0,0,0,0,0
0,0,0,0,0,0,13,14,0,0,14,28,0,0,0,0,0
0,0,0,0,0,0,13,14,0,0,14,28,0,0,0,0,0
0,0,0,0,0,0,13,14,14,14,14,28,0,0,0,0,0
0,0,0,0,0,0,13,12,12,12,12,28,0,0,0,0,0
0,0,0,0,0,0,0,0,0,0,0,0,0,0,0,0,0
0,0,0,0,0,0,0,0,0,0,0,0,0,0,0,0,0
endlayer

layer
0,0,0,0,0,0,0,0,0,0,0,0,0,0,0,0,0
0,0,0,0,0,0,0,0,0,0,0,0,0,0,0,0,0
0,0,0,0,0,0,0,0,0,0,0,0,0,0,0,0,0
0,0,0,0,0,0,0,0,0,0,0,0,0,0,0,0,0
0,0,0,0,0,0,0,0,0,0,0,0,0,0,0,0,0
0,0,0,0,0,0,0,0,0,0,0,0,0,0,0,0,0
0,0,0,0,0,0,0,0,0,0,0,0,0,0,0,0,0
0,0,0,0,0,0,0,13,16,16,28,0,0,0,0,0,0
0,0,0,0,0,0,0,13,14,14,28,0,0,0,0,0,0
0,0,0,0,0,0,0,13,14,14,28,0,0,0,0,0,0
0,0,0,0,0,0,0,13,12,12,28,0,0,0,0,0,0
0,0,0,0,0,0,0,0,0,0,0,0,0,0,0,0,0
0,0,0,0,0,0,0,0,0,0,0,0,0,0,0,0,0
0,0,0,0,0,0,0,0,0,0,0,0,0,0,0,0,0
endlayer

layer
0,0,0,0,0,0,0,0,0,0,0,0,0,0,0,0,0
0,0,0,0,0,0,0,0,0,0,0,0,0,0,0,0,0
0,0,0,0,0,0,0,0,0,0,0,0,0,0,0,0,0
0,0,0,0,0,0,0,0,0,0,0,0,0,0,0,0,0
0,0,0,0,0,0,0,0,0,0,0,0,0,0,0,0,0
0,0,0,0,0,0,0,0,0,0,0,0,0,0,0,0,0
0,0,0,0,0,0,0,0,0,0,0,0,0,0,0,0,0
0,0,0,0,0,0,0,0,0,0,0,0,0,0,0,0,0
0,0,0,0,0,0,0,0,35,35,0,0,0,0,0,0,0
0,0,0,0,0,0,0,0,35,35,0,0,0,0,0,0,0
0,0,0,0,0,0,0,0,0,0,0,0,0,0,0,0,0
0,0,0,0,0,0,0,0,0,0,0,0,0,0,0,0,0
0,0,0,0,0,0,0,0,0,0,0,0,0,0,0,0,0
0,0,0,0,0,0,0,0,0,0,0,0,0,0,0,0,0
endlayer

