# Gatehouse 10/20/2014
# Created by Ruins mod version 13.8 Ingame Parser
# authoring Player: Kujaku10
# Updated to MC 1.8: 5 Mar 2016
# Updated to MC 1.9: 18 Apr 2016
# Updated to MC 1.10: 13 Sep 2016
# Updated to MC 1.11.2: 11 Jan 2017
# Updated to MC 1.12: 22 Jun 2017
# Updated to MC 1.12.1: 10 Sep 2017

# Last Updated: 9 Jun 2018

biomesToSpawnIn=plains,sunflower plains,mutated_plains

weight=1
embed_into_distance=3
acceptable_target_blocks=

unacceptable_target_blocks=flowing_lava,lava,cloud,Natura:Cloud,red_mushroom_block,brown_mushroom_block,planks,cobblestone,torch,stone_slab,double_stone_slab,oak_stairs,spruce_stairs,birch_stairs,dark_oak_stairs,acacia_stairs,jungle_stairs,slime_congealed,slime_dirt,slime_grass,fence,stone_brick,cobblestone_wall,command_block

dimensions=16,15,12
allowable_overhang=0
max_leveling=2
leveling_buffer=-1
preserve_water=0
preserve_lava=0
preserve_plants=1

rule1=0,100,minecraft:grass-0
rule2=0,100,preserveBlock
rule3=0,100,minecraft:stonebrick-0
rule4=0,100,minecraft:stone_brick_stairs-1
rule5=0,100,minecraft:stone_brick_stairs-2
rule6=0,100,minecraft:stone_brick_stairs-3
rule7=0,100,minecraft:stone_slab-0
rule8=0,100,minecraft:stone_brick_stairs-0
rule9=0,100,minecraft:double_stone_slab-0
rule10=1,100,minecraft:leaves-6
rule11=0,100,minecraft:concrete-0
rule12=2,100,minecraft:ladder-5
rule13=1,100,minecraft:wooden_door-1
rule14=0,100,minecraft:cobblestone-0
rule15=0,100,minecraft:red_flower-3
rule16=0,100,minecraft:fence-0
rule17=0,100,minecraft:fence_gate-2
rule18=1,100,minecraft:wooden_door-0
rule19=2,100,minecraft:ladder-4
rule20=0,100,minecraft:glass_pane-0
rule21=2,100,minecraft:torch-3
rule22=1,100,minecraft:wooden_door-8
rule23=2,100,minecraft:torch-1
rule24=0,100,minecraft:oak_stairs-0
rule25=0,100,minecraft:oak_stairs-2
rule26=0,100,minecraft:oak_stairs-1
rule27=0,100,minecraft:stone_stairs-5
rule28=0,100,minecraft:stone_stairs-4
rule29=0,100,minecraft:planks-2
rule30=2,100,minecraft:torch-4
rule31=2,100,minecraft:torch-2
rule32=0,100,minecraft:oak_stairs-3
rule33=0,100,minecraft:wooden_slab-0

# Bandit
rule34=0,100,CommandBlock:RUINSTRIGGER /summon Skeleton ~0 ~0 ~0 {HandItems:[{Count:1,id:wooden_sword,tag:{display:{Name:"Bandit Bludgeon"},ench:[{id:19,lvl:2},{id:21,lvl:2},{id:16,lvl:3}]}},{}],ArmorItems:[{Count:1,id:leather_boots},{Count:1,id:leather_leggings},{Count:1,id:leather_chestplate},{Count:1,id:skull,Damage:3,tag:{SkullOwner:MHF_Villager}}],CustomName:Bandit,HandDropChances:[1.0F,0.0F],ArmorDropChances:[0.5F,0.5F,0.5F,0.1F],Silent:1,PersistenceRequired:1,Health:15.0f}:@

rule35=0,100,ChestGenHook:chests/village_blacksmith:4-5,ChestGenHook:chests/spawn_bonus_chest:8-5,IInventory;minecraft:chest;minecraft:arrow#16#4#3-5,IInventory;minecraft:chest;minecraft:torch#16#2#5-5

rule36=1,100,minecraft:torch-5

rule37=0,100,minecraft:stone_pressure_plate-0

layer
1,1,1,1,1,1,1,1,1,1,1,1
1,1,1,1,1,1,1,1,1,1,1,1
1,1,1,1,1,1,1,1,1,1,1,1
1,1,1,1,1,1,1,1,1,1,1,1
1,1,1,1,1,1,1,1,1,1,1,1
1,1,1,1,1,1,1,1,1,1,1,1
2,1,1,1,1,1,1,1,1,1,2,2
2,1,1,1,1,1,1,1,1,1,2,2
2,1,1,1,1,1,1,1,1,1,2,2
1,1,1,1,1,1,1,1,1,1,1,1
1,1,1,1,1,1,1,1,1,1,1,1
1,1,1,1,1,1,1,1,1,1,1,1
1,1,1,1,1,1,1,1,1,1,1,1
1,1,1,1,1,1,1,1,1,1,1,1
1,1,1,1,1,1,1,1,1,1,1,1
endlayer

layer
1,1,1,1,1,1,1,1,1,1,1,1
1,1,1,1,1,1,1,1,1,1,1,1
1,1,1,1,1,1,1,1,1,1,1,1
1,1,1,1,1,1,1,1,1,1,1,1
1,1,1,1,1,1,1,1,1,1,1,1
1,1,1,1,1,1,1,1,1,1,1,1
2,1,1,1,1,1,1,1,1,1,2,2
2,1,1,1,1,1,1,1,1,1,2,2
2,1,1,1,1,1,1,1,1,1,2,2
1,1,1,1,1,1,1,1,1,1,1,1
1,1,1,1,1,1,1,1,1,1,1,1
1,1,1,1,1,1,1,1,1,1,1,1
1,1,1,1,1,1,1,1,1,1,1,1
1,1,1,1,1,1,1,1,1,1,1,1
1,1,1,1,1,1,1,1,1,1,1,1
endlayer


layer
2,2,2,2,2,3,2,2,2,2,2,2
2,2,2,2,2,3,2,2,2,2,2,2
2,2,2,3,3,3,3,3,2,2,2,2
2,2,2,3,3,3,3,3,5,4,4,2
2,2,2,3,3,3,3,3,7,7,6,2
2,2,2,3,3,3,3,3,8,7,6,2
4,4,6,3,3,3,3,3,5,7,4,4
7,7,7,9,9,9,9,9,7,7,7,7
8,8,6,3,3,3,3,3,5,8,8,8
2,2,2,3,3,3,3,3,2,2,2,2
2,2,2,3,3,3,3,3,2,2,2,2
2,2,2,3,3,3,3,3,2,2,2,2
2,2,2,3,3,3,3,3,2,2,2,2
2,2,2,2,2,3,2,2,2,2,2,2
2,2,2,2,2,3,2,2,2,2,2,2
endlayer

layer
0,0,0,0,0,3,0,0,0,0,0,0
0,0,10,10,10,3,10,10,10,0,0,0
0,0,10,11,11,11,11,11,10,0,0,0
0,0,10,11,34,12,0,11,0,0,0,0
0,0,10,11,0,0,13,0,0,0,0,0
0,0,15,14,11,11,11,14,0,0,0,0
0,0,0,16,0,16,0,0,0,0,0,0
0,0,0,17,37,17,0,0,0,0,0,0
0,0,0,16,0,16,0,0,0,0,0,0
0,0,15,14,11,11,0,14,15,0,0,0
0,0,10,11,34,0,18,11,10,0,0,0
0,0,10,11,0,19,0,11,10,0,0,0
0,0,10,11,11,11,11,11,10,0,0,0
0,0,10,10,10,3,10,10,10,0,0,0
0,0,0,0,0,3,0,0,0,0,0,0
endlayer

layer
0,0,0,0,0,3,0,0,0,0,0,0
0,0,0,0,0,3,0,0,0,0,0,0
0,0,0,11,20,11,20,11,0,0,0,0
0,0,0,20,0,12,21,11,0,0,0,0
0,0,0,20,0,0,22,0,0,0,0,0
0,0,0,14,11,20,20,14,0,0,0,0
0,0,0,36,0,36,0,0,0,0,0,0
0,0,0,0,0,0,0,0,0,0,0,0
0,0,0,36,0,36,0,0,0,0,0,0
0,0,0,14,11,11,0,14,0,0,0,0
0,0,0,20,0,23,22,20,0,0,0,0
0,0,0,20,0,19,0,20,0,0,0,0
0,0,0,11,20,11,20,11,0,0,0,0
0,0,0,0,0,3,0,0,0,0,0,0
0,0,0,0,0,3,0,0,0,0,0,0
endlayer

layer
0,0,0,0,0,3,0,0,0,0,0,0
0,0,0,0,0,3,0,0,0,0,0,0
0,0,0,11,20,11,20,11,0,0,0,0
0,0,0,20,0,12,0,11,24,0,0,0
0,0,0,20,0,0,0,11,25,0,0,0
0,0,0,14,11,20,20,14,26,0,0,0
0,0,0,0,0,0,0,0,0,0,0,0
0,0,0,0,0,0,0,0,0,0,0,0
0,0,0,0,0,0,0,0,0,0,0,0
0,0,0,14,11,11,11,14,0,0,0,0
0,0,0,20,0,0,0,20,0,0,0,0
0,0,0,20,0,19,0,20,0,0,0,0
0,0,0,11,20,11,20,11,0,0,0,0
0,0,0,0,0,3,0,0,0,0,0,0
0,0,0,0,0,3,0,0,0,0,0,0
endlayer

layer
0,0,0,0,0,3,0,0,0,0,0,0
0,0,0,0,0,3,0,0,0,0,0,0
0,0,0,11,11,11,11,11,0,0,0,0
0,0,0,11,0,12,0,11,0,0,0,0
0,0,0,11,0,0,0,11,0,0,0,0
0,0,0,11,11,11,11,11,0,0,0,0
0,0,0,27,27,27,27,27,0,0,0,0
0,0,0,0,0,0,0,0,0,0,0,0
0,0,0,28,28,28,28,28,0,0,0,0
0,0,0,11,11,11,11,11,0,0,0,0
0,0,0,11,0,0,0,11,0,0,0,0
0,0,0,11,0,19,0,11,0,0,0,0
0,0,0,11,11,11,11,11,0,0,0,0
0,0,0,0,0,3,0,0,0,0,0,0
0,0,0,0,0,3,0,0,0,0,0,0
endlayer

layer
0,0,0,0,0,8,0,0,0,0,0,0
0,0,14,11,11,11,11,11,14,0,0,0
0,0,11,29,29,29,29,29,11,0,0,0
0,0,11,29,29,12,29,29,11,0,0,0
0,0,11,29,29,29,29,29,11,0,0,0
0,0,11,29,29,29,29,29,11,0,0,0
0,0,11,29,29,29,29,29,11,0,0,0
0,0,11,29,29,29,29,29,11,0,0,0
0,0,11,29,29,29,29,29,11,0,0,0
0,0,11,29,29,29,29,29,11,0,0,0
0,0,11,29,29,29,29,29,11,0,0,0
0,0,11,29,29,19,29,29,11,0,0,0
0,0,11,29,29,29,29,29,11,0,0,0
0,0,14,11,11,11,11,11,14,0,0,0
0,0,0,0,0,4,0,0,0,0,0,0
endlayer

layer
0,0,0,0,0,0,0,0,0,0,0,0
0,0,14,11,11,11,11,11,14,0,0,0
0,0,11,0,0,0,0,0,11,0,0,0
0,0,11,0,0,34,0,0,11,0,0,0
0,0,20,0,0,0,0,0,20,0,0,0
0,0,20,0,0,0,0,0,20,0,0,0
0,0,11,0,0,0,0,0,11,0,0,0
0,0,11,35,0,0,0,35,11,0,0,0
0,0,11,0,0,0,0,0,11,0,0,0
0,0,20,0,0,0,0,0,20,0,0,0
0,0,20,0,0,34,0,0,20,0,0,0
0,0,11,0,0,0,0,0,11,0,0,0
0,0,11,0,0,0,0,0,11,0,0,0
0,0,14,11,11,11,11,11,14,0,0,0
0,0,0,0,0,0,0,0,0,0,0,0
endlayer

layer
0,0,0,0,0,0,0,0,0,0,0,0
0,0,14,11,11,11,11,11,14,0,0,0
0,0,11,0,23,0,23,0,11,0,0,0
0,0,11,0,0,0,0,0,11,0,0,0
0,0,20,0,0,0,0,0,20,0,0,0
0,0,20,0,0,0,0,0,20,0,0,0
0,0,11,30,0,0,0,21,11,0,0,0
0,0,11,0,0,0,0,0,11,0,0,0
0,0,11,30,0,0,0,21,11,0,0,0
0,0,20,0,0,0,0,0,20,0,0,0
0,0,20,0,0,0,0,0,20,0,0,0
0,0,11,0,0,0,0,0,11,0,0,0
0,0,11,0,31,0,31,0,11,0,0,0
0,0,14,11,11,11,11,11,14,0,0,0
0,0,0,0,0,0,0,0,0,0,0,0
endlayer

layer
0,0,0,0,0,0,0,0,0,0,0,0
0,0,29,29,29,29,29,29,29,0,0,0
0,0,29,0,0,0,0,0,29,0,0,0
0,0,29,0,0,0,0,0,29,0,0,0
0,0,29,0,0,0,0,0,29,0,0,0
0,0,29,0,0,0,0,0,29,0,0,0
0,0,29,0,0,0,0,0,29,0,0,0
0,0,29,0,0,0,0,0,29,0,0,0
0,0,29,0,0,0,0,0,29,0,0,0
0,0,29,0,0,0,0,0,29,0,0,0
0,0,29,0,0,0,0,0,29,0,0,0
0,0,29,0,0,0,0,0,29,0,0,0
0,0,29,0,0,0,0,0,29,0,0,0
0,0,29,29,29,29,29,29,29,0,0,0
0,0,0,0,0,0,0,0,0,0,0,0
endlayer

layer
0,32,0,0,0,0,0,0,0,25,0,0
0,32,29,29,29,29,29,29,29,25,0,0
0,32,29,0,0,0,0,0,29,25,0,0
0,32,29,0,0,0,0,0,29,25,0,0
0,32,29,0,0,0,0,0,29,25,0,0
0,32,29,0,0,0,0,0,29,25,0,0
0,32,29,0,0,0,0,0,29,25,0,0
0,32,29,0,0,0,0,0,29,25,0,0
0,32,29,0,0,0,0,0,29,25,0,0
0,32,29,0,0,0,0,0,29,25,0,0
0,32,29,0,0,0,0,0,29,25,0,0
0,32,29,0,0,0,0,0,29,25,0,0
0,32,29,0,0,0,0,0,29,25,0,0
0,32,29,29,29,29,29,29,29,25,0,0
0,32,0,0,0,0,0,0,0,25,0,0
endlayer

layer
0,0,32,0,0,0,0,0,25,0,0,0
0,0,32,29,29,29,29,29,25,0,0,0
0,0,11,29,0,0,0,29,11,0,0,0
0,0,20,0,0,0,0,0,20,0,0,0
0,0,11,29,0,0,0,29,11,0,0,0
0,0,32,29,0,0,0,29,25,0,0,0
0,0,11,29,0,0,0,29,11,0,0,0
0,0,20,0,0,0,0,0,20,0,0,0
0,0,11,29,0,0,0,29,11,0,0,0
0,0,32,29,0,0,0,29,25,0,0,0
0,0,11,29,0,0,0,29,11,0,0,0
0,0,20,0,0,0,0,0,20,0,0,0
0,0,11,29,0,0,0,29,11,0,0,0
0,0,32,29,29,29,29,29,25,0,0,0
0,0,32,0,0,0,0,0,25,0,0,0
endlayer

layer
0,0,0,32,0,0,0,25,0,0,0,0
0,0,0,32,29,29,29,25,0,0,0,0
0,0,11,11,29,0,29,11,11,0,0,0
0,0,11,0,0,0,0,11,11,0,0,0
0,0,11,11,29,0,29,11,11,0,0,0
0,0,0,32,29,0,29,25,0,0,0,0
0,0,11,11,29,0,29,11,11,0,0,0
0,0,11,0,0,0,0,0,11,0,0,0
0,0,11,11,29,0,29,11,11,0,0,0
0,0,0,32,29,0,29,25,0,0,0,0
0,0,11,11,29,0,29,11,11,0,0,0
0,0,11,0,0,0,0,0,11,0,0,0
0,0,11,11,29,0,29,11,11,0,0,0
0,0,0,32,29,29,29,25,0,0,0,0
0,0,0,32,0,0,0,25,0,0,0,0
endlayer

layer
0,0,0,0,32,0,25,0,0,0,0,0
0,0,0,0,32,29,25,0,0,0,0,0
0,24,24,24,24,29,25,24,24,24,0,0
0,0,11,11,29,29,29,11,11,0,0,0
0,26,26,26,32,29,25,26,26,26,0,0
0,0,0,0,32,29,25,0,0,0,0,0
0,24,24,24,32,29,24,24,24,24,0,0
0,0,11,11,29,29,29,11,11,0,0,0
0,26,26,26,26,29,25,26,26,26,0,0
0,0,0,0,32,29,25,0,0,0,0,0
0,24,24,24,32,29,25,24,24,24,0,0
0,0,11,11,29,29,29,11,11,0,0,0
0,26,26,26,32,29,26,26,26,26,0,0
0,0,0,0,32,29,25,0,0,0,0,0
0,0,0,0,32,0,25,0,0,0,0,0
endlayer

layer
0,0,0,0,0,33,0,0,0,0,0,0
0,0,0,0,0,33,0,0,0,0,0,0
0,0,0,0,0,33,0,0,0,0,0,0
0,33,33,33,33,33,33,33,33,33,0,0
0,0,0,0,0,33,0,0,0,0,0,0
0,0,0,0,0,33,0,0,0,0,0,0
0,0,0,0,0,33,0,0,0,0,0,0
0,33,33,33,33,33,33,33,33,33,0,0
0,0,0,0,0,33,0,0,0,0,0,0
0,0,0,0,0,33,0,0,0,0,0,0
0,0,0,0,0,33,0,0,0,0,0,0
0,33,33,33,33,33,33,33,33,33,0,0
0,0,0,0,0,33,0,0,0,0,0,0
0,0,0,0,0,33,0,0,0,0,0,0
0,0,0,0,0,33,0,0,0,0,0,0
endlayer

