# Stackable Store No. 3 10/26/2014
# Created by Ruins mod version 13.8 Ingame Parser
# authoring Player: Kujaku10
# Updated to MC 1.8: 23 Mar 2016
# Updated to MC 1.9: 18 Apr 2016
# Updated to MC 1.11: 11 Jan 2017
# Updated to MC 1.12: 22 Jun 2017

weight=1
embed_into_distance=5
acceptable_target_blocks=

unacceptable_target_blocks=flowing_lava,lava,cloud,Natura:Cloud,red_mushroom_block,brown_mushroom_block,planks,cobblestone,torch,stone_slab,double_stone_slab,oak_stairs,spruce_stairs,birch_stairs,dark_oak_stairs,acacia_stairs,jungle_stairs,slime_congealed,slime_dirt,slime_grass,fence,stone_brick,cobblestone_wall,command_block

dimensions=22,9,13
allowable_overhang=0
max_leveling=4
leveling_buffer=-1
preserve_water=0
preserve_lava=0
preserve_plants=1

rule1=0,100,minecraft:grass-0
rule2=0,100,minecraft:stonebrick-0
rule3=0,100,minecraft:sandstone-0
rule4=1,100,minecraft:leaves-14
rule5=0,100,minecraft:red_flower-7
rule6=0,100,minecraft:oak_stairs-2
rule7=0,100,minecraft:leaves-14
rule8=0,100,minecraft:planks-0
rule9=0,100,minecraft:oak_stairs-0
rule10=0,100,minecraft:fence-0
rule11=0,100,minecraft:brick_stairs-0
rule12=0,100,minecraft:brick_stairs-3
rule13=0,100,minecraft:brick_stairs-1
rule14=0,100,minecraft:oak_stairs-1
rule15=0,100,minecraft:planks-3
rule16=0,100,minecraft:quartz_block-0
rule17=0,100,minecraft:planks-4
rule18=0,100,minecraft:glass_pane-0
rule19=1,100,minecraft:wooden_door-3
rule20=2,100,minecraft:ladder-4
rule21=2,100,minecraft:torch-1
rule22=1,100,minecraft:wooden_door-8
rule23=2,100,minecraft:torch-2
rule24=0,100,minecraft:jungle_stairs-4
rule25=0,100,minecraft:acacia_stairs-7
rule26=0,100,minecraft:jungle_stairs-5
rule27=0,100,minecraft:dark_oak_stairs-2
rule28=0,100,minecraft:dark_oak_stairs-3
rule29=0,100,minecraft:quartz_stairs-5
rule30=0,100,minecraft:quartz_stairs-4
rule31=0,100,minecraft:wooden_slab-5
rule32=0,100,minecraft:quartz_block-2
rule33=0,100,minecraft:dark_oak_stairs-0
rule34=0,100,minecraft:dark_oak_stairs-1
rule35=0,100,minecraft:ladder-5

rule36=0,100,ChestGenHook:chests/simple_dungeon:3-3

# Highwayman (Bandit Archer)
rule37=0,100,CommandBlock:RUINSTRIGGER /summon Skeleton ~0 ~0 ~0 {HandItems:[{Count:1,id:bow,tag:{display:{Name:"Bandit Bow"},ench:[{id:48,lvl:3},{id:49,lvl:2}]}},{Count:8,id:tipped_arrow,tag:{Potion:"minecraft:strong_harming"}}],ArmorItems:[{Count:1,id:leather_boots},{Count:1,id:leather_leggings},{Count:1,id:leather_chestplate},{Count:1,id:skull,Damage:3,tag:{SkullOwner:MHF_Villager}}],CustomName:Highwayman,HandDropChances:[1.0F,0.0F],ArmorDropChances:[0.5F,0.5F,0.5F,0.0F],Silent:1,PersistenceRequired:1,Health:15.0f}:@

# Bandit
rule38=0,100,CommandBlock:RUINSTRIGGER /summon Skeleton ~0 ~0 ~0 {HandItems:[{Count:1,id:wooden_sword,tag:{display:{Name:"Bandit Bludgeon"},ench:[{id:19,lvl:2},{id:21,lvl:2},{id:16,lvl:3}]}},{}],ArmorItems:[{Count:1,id:leather_boots},{Count:1,id:leather_leggings},{Count:1,id:leather_chestplate},{Count:1,id:skull,Damage:3,tag:{SkullOwner:MHF_Villager}}],CustomName:Bandit,HandDropChances:[1.0F,0.0F],ArmorDropChances:[0.5F,0.5F,0.5F,0.0F],Silent:1,PersistenceRequired:1,Health:15.0f}:@

# Villager: Merchant
rule39=0,100,CommandBlock:RUINSTRIGGER /summon Villager ~0 ~0 ~0 {Profession:2,Career:1,CustomName:Merchant,Offers:{Recipes:[{buy:{id:emerald,Count:4},sell:{id:skull,Count:1,Damage:3,tag:{display:{Name:"Wax Cake"},SkullOwner:"MHF_Cake"}}},{buy:{id:emerald,Count:4},sell:{id:skull,Count:1,Damage:3,tag:{display:{Name:"Jewelry Box"},SkullOwner:"MHF_Chest"}}},{buy:{id:emerald,Count:4},sell:{id:skull,Count:1,Damage:3,tag:{display:{Name:"Coconut Souvenir"},SkullOwner:"MHF_CoconutB"}}},{buy:{id:emerald,Count:4},sell:{id:skull,Count:1,Damage:3,tag:{display:{Name:"Gift"},SkullOwner:"MHF_Present1"}}},{buy:{id:emerald,Count:4},sell:{id:skull,Count:1,Damage:3,tag:{display:{Name:"Present"},SkullOwner:"MHF_Present2"}}},{buy:{id:emerald,Count:4},sell:{id:skull,Count:1,Damage:3,tag:{display:{Name:"Mask"},SkullOwner:"MHF_Alex"}}},{buy:{id:emerald,Count:4},sell:{id:skull,Count:1,Damage:3,tag:{display:{Name:"Golem Mask"},SkullOwner:"MHF_Golem"}}},{buy:{id:emerald,Count:4},sell:{id:skull,Count:1,Damage:3,tag:{display:{Name:"Mini Slime"},SkullOwner:"MHF_Slime"}}},{buy:{id:emerald,Count:4},sell:{id:skull,Count:1,Damage:3,tag:{display:{Name:"Safe Cactus"},SkullOwner:"MHF_Cactus"}}}]}}:@

rule40=0,100,IInventory;minecraft:chest;minecraft:torch#12#0#3,IInventory;minecraft:chest;minecraft:emerald#1#0#2,IInventory;minecraft:chest;minecraft:feather#12#0#1,IInventory;minecraft:chest;minecraft:apple#8#0#0,IInventory;minecraft:chest;minecraft:painting#12#0#5,IInventory;minecraft:chest;minecraft:item_frame#12#0#6


# -5
layer
1,1,1,2,2,2,3,2,2,2,2,2,1
1,1,1,2,2,2,2,2,2,2,2,2,1
1,1,1,2,2,2,2,2,2,2,2,2,1
1,1,1,2,2,2,2,2,2,2,2,2,1
1,1,1,2,2,2,2,2,2,2,2,2,1
1,1,1,2,2,2,2,2,2,2,2,2,1
1,1,1,2,2,2,2,2,2,2,2,2,1
1,1,1,2,2,2,2,2,2,2,2,2,1
1,1,1,2,2,2,3,2,2,2,2,2,1
endlayer

# -4
layer
1,1,1,2,2,2,3,2,2,2,2,2,1
1,1,1,2,0,0,35,0,0,0,40,2,1
1,1,1,2,0,0,0,0,0,0,40,2,1
1,1,1,2,0,37,0,37,0,0,0,2,1
1,1,1,2,0,0,0,0,0,0,36,2,1
1,1,1,2,0,38,0,38,0,0,0,2,1
1,1,1,2,0,0,0,0,0,0,40,2,1
1,1,1,2,0,0,0,0,0,0,40,2,1
1,1,1,2,2,2,3,2,2,2,2,2,1
endlayer

# -3
layer
1,1,1,2,2,2,3,2,2,2,2,2,1
1,1,1,2,0,21,35,0,0,21,0,2,1
1,1,1,2,0,0,0,0,0,0,0,2,1
1,1,1,2,0,0,0,0,0,0,0,2,1
1,1,1,2,0,0,0,0,0,0,0,2,1
1,1,1,2,0,0,0,0,0,0,0,2,1
1,1,1,2,0,0,0,0,0,0,0,2,1
1,1,1,2,0,23,0,0,0,23,0,2,1
1,1,1,2,2,2,3,2,2,2,2,2,1
endlayer

# -2
layer
1,1,1,2,2,2,3,2,2,2,2,2,1
1,1,1,2,0,0,35,0,0,0,0,2,1
1,1,1,2,0,0,0,0,0,0,0,2,1
1,1,1,2,0,0,0,0,0,0,0,2,1
1,1,1,2,0,0,0,0,0,0,0,2,1
1,1,1,2,0,0,0,0,0,0,0,2,1
1,1,1,2,0,0,0,0,0,0,0,2,1
1,1,1,2,0,0,0,0,0,0,0,2,1
1,1,1,2,2,2,3,2,2,2,2,2,1
endlayer



# -1
layer
1,1,1,2,2,2,3,2,2,2,2,2,1
1,1,1,2,2,2,35,2,2,2,2,2,1
1,1,1,2,2,2,2,2,2,2,2,2,1
1,1,1,2,2,2,2,2,2,2,2,2,1
1,1,1,2,2,2,2,2,2,2,2,2,1
1,1,1,2,2,2,2,2,2,2,2,2,1
1,1,1,2,2,2,2,2,2,2,2,2,1
1,1,1,2,2,2,2,2,2,2,2,2,1
1,1,1,2,2,2,3,2,2,2,2,2,1
endlayer

layer
0,0,5,2,2,2,2,2,2,2,2,2,4
0,0,7,2,6,0,0,0,0,0,0,2,4
0,10,4,2,9,6,0,37,0,0,8,2,4
0,0,11,2,8,6,0,0,0,0,8,2,7
0,0,12,2,8,6,0,0,0,0,8,2,7
0,0,13,2,8,6,0,0,0,0,8,2,4
0,10,4,2,6,14,0,38,0,0,8,2,4
0,0,7,2,6,0,0,0,0,0,0,2,4
0,0,5,2,2,2,2,2,2,2,2,2,4
endlayer

layer
0,0,0,15,16,17,16,16,16,17,16,15,0
0,0,0,18,0,0,0,0,0,0,0,16,0
0,10,0,18,0,0,0,0,0,0,0,17,0
0,0,0,16,0,0,0,0,0,0,0,18,0
0,0,0,19,0,0,0,0,0,0,0,18,0
0,0,0,16,0,0,0,0,0,0,0,18,0
0,10,0,18,0,0,0,0,0,0,0,17,0
0,0,0,18,20,0,0,0,0,0,0,16,0
0,0,0,15,16,17,16,16,16,17,16,15,0
endlayer

layer
0,0,0,15,16,15,16,16,16,15,16,15,0
0,0,0,18,0,21,0,0,0,21,0,16,0
0,10,0,18,0,0,0,0,0,0,0,15,0
0,0,0,16,0,0,0,0,0,0,0,18,0
0,0,0,22,0,0,0,0,0,0,0,18,0
0,0,0,16,0,0,0,0,0,0,0,18,0
0,10,0,18,0,0,0,0,0,0,0,15,0
0,0,0,18,20,23,0,0,0,23,0,16,0
0,0,0,15,16,15,16,16,16,15,16,15,0
endlayer

layer
0,0,0,15,16,17,16,16,16,17,16,15,0
0,0,0,18,0,0,0,0,0,0,0,16,0
0,10,0,18,0,0,0,0,0,0,0,17,0
0,0,0,16,0,0,0,0,0,0,0,18,0
0,0,0,17,0,0,0,0,0,0,0,18,0
0,0,0,16,0,0,0,0,0,0,0,18,0
0,10,0,18,0,0,0,0,0,0,0,17,0
0,0,0,18,20,0,0,0,0,0,0,16,0
0,0,0,15,16,17,16,16,16,17,16,15,0
endlayer

layer
0,0,10,17,15,15,15,15,15,15,15,17,0
0,0,10,15,0,0,0,0,0,0,0,15,0
0,10,10,15,0,0,0,0,0,0,0,15,0
0,0,10,15,0,0,0,0,0,0,0,15,0
0,0,10,15,0,0,0,0,0,0,0,15,0
0,0,10,15,0,0,0,0,0,0,0,15,0
0,10,10,15,0,0,0,0,0,0,0,15,0
0,0,10,15,20,0,0,0,0,0,0,15,0
0,0,10,17,15,15,15,15,15,15,15,17,0
endlayer

layer
0,0,17,15,15,15,15,15,15,15,15,15,0
0,24,15,8,8,8,8,8,8,8,8,15,0
0,25,17,8,8,8,8,8,8,8,8,15,0
0,26,15,8,8,8,0,0,0,8,8,15,0
0,0,17,8,8,8,0,0,0,8,8,15,0
0,24,15,8,8,8,0,0,0,8,8,15,0
0,25,17,8,8,8,8,8,8,8,8,15,0
0,26,15,8,20,8,8,8,8,8,8,15,0
0,0,17,15,15,15,15,15,15,15,15,15,0
endlayer

layer
0,0,15,16,16,17,16,16,17,16,16,15,0
0,10,17,0,0,0,0,0,0,0,0,16,0
0,10,18,0,0,10,10,10,10,10,0,17,0
0,10,17,0,0,10,0,0,0,10,0,18,0
0,0,16,39,0,10,0,0,0,10,0,17,0
0,10,17,0,0,10,0,0,0,10,0,18,0
0,10,18,0,0,10,10,10,10,10,0,17,0
0,10,17,0,0,0,0,0,0,0,0,16,0
0,0,15,16,16,17,16,16,17,16,16,15,0
endlayer

layer
0,0,15,16,16,15,16,16,15,16,16,15,0
0,10,15,0,0,21,0,0,21,0,0,16,0
0,0,18,0,0,0,0,0,0,0,0,15,0
0,10,15,0,0,0,0,0,0,0,0,18,0
0,0,16,0,0,0,0,0,0,0,0,15,0
0,10,15,0,0,0,0,0,0,0,0,18,0
0,0,18,0,0,0,0,0,0,0,0,15,0
0,10,15,0,0,23,0,0,23,0,0,16,0
0,0,15,16,16,15,16,16,15,16,16,15,0
endlayer

layer
0,0,15,16,16,17,16,16,17,16,16,15,0
0,10,17,0,0,0,0,0,0,0,0,16,0
0,0,18,0,0,0,0,0,0,0,0,17,0
0,10,17,0,0,0,0,0,0,0,0,18,0
0,0,16,0,0,0,0,0,0,0,0,17,0
0,10,17,0,0,0,0,0,0,0,0,18,0
0,0,18,0,0,0,0,0,0,0,0,17,0
0,10,17,0,0,0,0,0,0,0,0,16,0
0,0,15,16,16,17,16,16,17,16,16,15,0
endlayer

layer
0,28,17,15,15,15,15,15,15,15,15,17,27
0,28,17,0,0,0,0,0,0,0,0,17,27
0,28,17,0,0,0,0,0,0,0,0,17,27
0,28,17,0,0,0,0,0,0,0,0,17,27
0,28,17,0,0,0,0,0,0,0,0,17,27
0,28,17,0,0,0,0,0,0,0,0,17,27
0,28,17,0,0,0,0,0,0,0,0,17,27
0,28,17,0,0,0,0,0,0,0,0,17,27
0,28,17,15,15,15,15,15,15,15,15,17,27
endlayer

layer
0,0,28,17,16,16,16,16,16,16,17,27,0
0,0,28,17,0,0,0,0,0,0,17,27,0
0,0,28,17,0,0,0,0,0,0,17,27,0
0,0,28,17,0,0,0,0,0,0,17,27,0
0,0,28,17,0,0,0,0,0,0,17,27,0
0,0,28,17,0,0,0,0,0,0,17,27,0
0,0,28,17,0,0,0,0,0,0,17,27,0
0,0,28,17,0,0,0,0,0,0,17,27,0
0,0,28,17,16,16,16,16,16,16,17,27,0
endlayer

layer
0,0,0,28,15,15,15,15,15,15,27,0,0
0,0,0,28,15,15,15,15,15,15,27,0,0
0,0,0,28,15,15,15,15,15,15,27,0,0
0,0,0,28,15,15,29,0,29,15,27,0,0
0,0,0,28,15,15,0,0,0,15,27,0,0
0,0,0,28,15,15,30,0,30,15,27,0,0
0,0,0,28,15,15,15,15,15,15,27,0,0
0,0,0,28,15,15,15,15,15,15,27,0,0
0,0,0,28,15,15,15,15,15,15,27,0,0
endlayer

layer
0,0,0,0,31,31,31,31,31,31,0,0,0
0,0,0,0,31,31,31,31,31,31,0,0,0
0,0,0,0,31,31,31,31,31,31,0,0,0
0,0,0,0,31,31,32,0,32,31,0,0,0
0,0,0,0,31,31,0,0,0,31,0,0,0
0,0,0,0,31,31,32,0,32,31,0,0,0
0,0,0,0,31,31,31,31,31,31,0,0,0
0,0,0,0,31,31,31,31,31,31,0,0,0
0,0,0,0,31,31,31,31,31,31,0,0,0
endlayer

layer
0,0,0,0,0,0,0,0,0,0,0,0,0
0,0,0,0,0,0,0,0,0,0,0,0,0
0,0,0,0,0,0,0,0,0,0,0,0,0
0,0,0,0,0,0,32,0,32,0,0,0,0
0,0,0,0,0,0,0,0,0,0,0,0,0
0,0,0,0,0,0,32,0,32,0,0,0,0
0,0,0,0,0,0,0,0,0,0,0,0,0
0,0,0,0,0,0,0,0,0,0,0,0,0
0,0,0,0,0,0,0,0,0,0,0,0,0
endlayer

layer
0,0,0,0,0,0,0,0,0,0,0,0,0
0,0,0,0,0,0,0,0,0,0,0,0,0
0,0,0,0,0,33,33,33,33,27,0,0,0
0,0,0,0,0,28,17,17,17,27,0,0,0
0,0,0,0,0,28,17,0,17,27,0,0,0
0,0,0,0,0,28,17,17,17,27,0,0,0
0,0,0,0,0,28,34,34,34,27,0,0,0
0,0,0,0,0,0,0,0,0,0,0,0,0
0,0,0,0,0,0,0,0,0,0,0,0,0
endlayer

layer
0,0,0,0,0,0,0,0,0,0,0,0,0
0,0,0,0,0,0,0,0,0,0,0,0,0
0,0,0,0,0,0,0,0,0,0,0,0,0
0,0,0,0,0,0,33,33,33,0,0,0,0
0,0,0,0,0,0,28,17,27,0,0,0,0
0,0,0,0,0,0,28,34,34,0,0,0,0
0,0,0,0,0,0,0,0,0,0,0,0,0
0,0,0,0,0,0,0,0,0,0,0,0,0
0,0,0,0,0,0,0,0,0,0,0,0,0
endlayer

layer
0,0,0,0,0,0,0,0,0,0,0,0,0
0,0,0,0,0,0,0,0,0,0,0,0,0
0,0,0,0,0,0,0,0,0,0,0,0,0
0,0,0,0,0,0,0,0,0,0,0,0,0
0,0,0,0,0,0,0,31,0,0,0,0,0
0,0,0,0,0,0,0,0,0,0,0,0,0
0,0,0,0,0,0,0,0,0,0,0,0,0
0,0,0,0,0,0,0,0,0,0,0,0,0
0,0,0,0,0,0,0,0,0,0,0,0,0
endlayer

