# Large Cottage No. 2 10/25/2014
# Created by Ruins mod version 13.8 Ingame Parser
# authoring Player: Kujaku10
# Last Updated 9 Nov 2015
# Updated to MC 1.8: 5 Mar 2016
# Updated to MC 1.9: 18 Apr 2016
# Updated to MC 1.11.2: 11 Jan 2017
# Updated to MC 1.12: 21 Jun 2017

weight=1
embed_into_distance=1
acceptable_target_blocks=

unacceptable_target_blocks=flowing_lava,lava,cloud,Natura:Cloud,red_mushroom_block,brown_mushroom_block,planks,cobblestone,torch,stone_slab,double_stone_slab,oak_stairs,spruce_stairs,birch_stairs,dark_oak_stairs,acacia_stairs,jungle_stairs,slime_congealed,slime_dirt,slime_grass,fence,stone_brick,cobblestone_wall,command_block

dimensions=16,11,11
allowable_overhang=0
max_leveling=2
leveling_buffer=-1
preserve_water=0
preserve_lava=0
preserve_plants=1

rule1=0,100,minecraft:grass-0
rule2=0,100,minecraft:brick_block-0
rule3=0,100,minecraft:cobblestone-0
rule4=0,100,minecraft:netherrack-0
rule5=0,100,minecraft:stonebrick-3
rule6=0,100,minecraft:double_stone_slab-0
rule7=0,100,minecraft:stonebrick-0
rule8=0,100,minecraft:stonebrick-2
rule9=0,100,minecraft:leaves-14
rule10=0,100,minecraft:red_flower-8
rule11=0,100,minecraft:yellow_flower-0
rule12=0,100,minecraft:leaves-14
rule13=0,100,minecraft:fire-15
rule14=0,100,minecraft:cobblestone_wall-0
rule15=0,100,minecraft:crafting_table-0
rule16=1,100,minecraft:wooden_door-2
rule17=2,100,minecraft:ladder-4
rule18=0,100,minecraft:red_flower-3
rule19=0,100,minecraft:glass_pane-0
rule20=2,100,minecraft:torch-3
rule21=2,100,minecraft:torch-4
rule22=1,100,minecraft:wooden_door-8
rule23=0,100,minecraft:stone_stairs-4
rule24=0,100,minecraft:stone_stairs-6
rule25=0,100,minecraft:stone_stairs-7
rule26=0,100,minecraft:stone_stairs-5
rule27=0,100,minecraft:planks-1
rule28=0,100,minecraft:birch_stairs-6
rule29=0,100,minecraft:birch_stairs-5
rule30=0,100,minecraft:birch_stairs-7
rule31=0,100,minecraft:planks-0

rule32=0,100,ChestGenHook:chests/spawn_bonus_chest:1-5

rule33=0,100,minecraft:fence-0
rule34=0,100,minecraft:noteblock-0

rule35=0,100,ChestGenHook:chests/spawn_bonus_chest:3-4

rule36=0,100,minecraft:birch_stairs-2
rule37=0,100,minecraft:birch_stairs-3
rule38=0,100,minecraft:planks-2
rule39=0,100,minecraft:wooden_slab-2
rule40=0,100,minecraft:brick_stairs-0
rule41=0,100,minecraft:birch_stairs-0
rule42=0,100,minecraft:birch_stairs-1
rule43=0,100,minecraft:stone_slab-5

rule44=0,100,preserveBlock

# Bandit
rule45=0,100,CommandBlock:RUINSTRIGGER /summon Skeleton ~0 ~0 ~0 {HandItems:[{Count:1,id:wooden_sword,tag:{display:{Name:"Bandit Bludgeon"},ench:[{id:19,lvl:2},{id:21,lvl:2},{id:16,lvl:3}]}},{}],ArmorItems:[{Count:1,id:leather_boots},{Count:1,id:leather_leggings},{Count:1,id:leather_chestplate},{Count:1,id:skull,Damage:3,tag:{SkullOwner:MHF_Villager}}],CustomName:Bandit,HandDropChances:[1.0F,0.0F],ArmorDropChances:[0.5F,0.5F,0.5F,0.0F],Silent:1,PersistenceRequired:1,Health:15.0f}:@


layer
44,44,44,1,1,1,1,1,44,44,44
44,1,1,1,2,2,2,1,1,1,44
44,1,3,3,3,4,3,3,3,1,44
1,1,3,5,6,6,6,5,3,1,1
1,1,3,5,8,7,7,5,3,1,1
1,1,3,5,7,7,8,5,3,1,1
1,1,3,5,8,7,7,5,3,1,1
1,1,3,5,5,5,5,5,3,1,1
44,1,3,3,3,3,3,3,3,1,44
44,44,1,1,1,1,1,1,1,44,44
44,44,44,1,1,1,1,1,44,44,44
endlayer

layer
44,44,44,0,0,0,0,0,44,44,44
44,12,10,11,2,2,2,11,10,9,44
44,12,3,3,2,13,2,3,3,9,44
0,9,3,0,14,14,14,0,3,9,0
0,12,3,0,0,0,0,0,3,9,0
0,12,3,15,0,45,0,0,3,9,0
0,12,3,0,0,0,0,0,3,9,0
0,9,3,0,17,16,0,0,3,9,0
44,9,3,3,3,0,3,3,3,9,44
44,44,10,11,18,0,18,11,10,44,44
44,44,44,0,0,0,0,0,44,44,44
endlayer

layer
44,44,0,0,0,0,0,0,0,44,44
44,0,0,0,2,2,2,0,0,0,44
0,0,3,3,2,0,2,3,3,0,0
0,0,19,0,14,0,14,0,19,0,0
0,0,3,21,0,0,0,20,3,0,0
0,0,19,0,0,0,0,0,19,0,0
0,0,3,21,0,0,0,20,3,0,0
0,0,19,0,17,22,0,0,19,0,0
0,0,3,19,3,0,3,19,3,0,0
44,0,0,0,0,0,0,0,0,0,44
44,44,0,0,0,0,0,0,0,44,44
endlayer

layer
44,0,0,0,0,0,0,0,0,0,44
0,0,23,0,2,2,2,0,23,0,0
0,25,3,3,2,0,2,3,3,24,0
0,0,3,0,14,14,14,0,3,0,0
0,25,3,0,0,0,0,0,3,24,0
0,0,3,0,0,0,0,0,3,0,0
0,25,3,0,0,0,0,0,3,24,0
0,0,3,0,17,0,0,0,3,0,0
0,25,3,3,3,5,3,3,3,24,0
0,0,26,0,26,0,26,0,26,0,0
44,0,0,0,0,0,0,0,0,0,44
endlayer

layer
0,0,0,0,0,0,0,0,0,0,0
0,27,27,27,2,2,2,27,27,27,0
0,27,27,27,2,7,2,27,27,27,0
0,27,27,27,14,14,14,27,27,27,0
0,27,27,27,0,0,0,27,27,27,0
0,27,27,27,27,27,27,27,27,27,0
0,27,27,27,27,27,27,27,27,27,0
0,27,27,27,17,27,27,27,27,27,0
0,27,27,27,27,27,27,27,27,27,0
0,27,27,27,27,27,27,27,27,27,0
0,0,0,0,30,29,28,0,0,0,0
endlayer

layer
0,0,0,0,0,0,0,0,0,0,0
0,27,31,27,2,2,2,27,31,27,0
0,31,0,33,2,2,2,33,32,31,0
0,27,0,33,14,0,14,33,0,27,0
0,19,0,33,0,0,0,33,0,19,0
0,27,0,33,33,33,33,33,0,27,0
0,19,0,0,0,0,0,0,0,19,0
0,27,0,0,0,45,0,0,0,27,0
0,31,34,0,0,0,0,35,34,31,0
0,27,31,27,31,16,31,27,31,27,0
0,0,0,0,33,33,33,0,0,0,0
endlayer

layer
0,0,0,0,0,0,0,0,0,0,0
0,27,31,27,2,2,2,27,31,27,0
0,31,0,0,2,2,2,0,0,31,0
0,27,21,0,14,14,14,0,20,27,0
0,19,0,0,0,0,0,0,0,19,0
0,27,0,0,0,0,0,0,0,27,0
0,19,0,0,0,0,0,0,0,19,0
0,27,21,0,0,0,0,0,20,27,0
0,31,0,0,0,0,0,0,34,31,0
0,27,31,27,31,22,31,27,31,27,0
0,0,0,0,0,0,0,0,0,0,0
endlayer

layer
37,0,0,0,0,0,0,0,0,0,36
37,27,27,27,2,2,2,27,27,27,36
37,27,0,0,2,2,2,0,0,27,36
37,27,0,0,0,0,0,0,0,27,36
37,27,0,0,0,0,0,0,0,27,36
37,27,0,0,0,0,0,0,0,27,36
37,27,0,0,0,0,0,0,0,27,36
37,27,0,0,0,0,0,0,0,27,36
37,27,0,0,0,0,0,0,0,27,36
37,27,27,27,27,27,27,27,27,27,36
37,0,0,0,0,0,0,0,0,0,36
endlayer

layer
0,38,0,0,0,0,0,0,0,38,0
0,38,31,27,2,2,2,27,31,38,0
0,38,0,0,2,5,2,0,0,38,0
0,38,0,0,0,0,0,0,0,38,0
0,38,0,0,0,0,0,0,0,38,0
0,38,0,0,0,0,0,0,0,38,0
0,38,0,0,0,0,0,0,0,38,0
0,38,0,0,0,0,0,0,0,38,0
0,38,0,0,0,0,0,0,0,38,0
0,38,31,27,19,19,19,27,31,38,0
0,38,0,33,33,33,33,33,0,38,0
endlayer

layer
0,38,0,0,0,0,0,0,0,38,0
0,38,31,27,2,2,2,27,31,38,0
0,38,0,0,2,2,2,0,0,38,0
0,38,0,0,0,0,0,0,0,38,0
0,38,0,0,0,0,0,0,0,38,0
0,38,0,0,0,0,0,0,0,38,0
0,38,0,0,0,0,0,0,0,38,0
0,38,0,0,0,0,0,0,0,38,0
0,38,0,0,0,0,0,0,0,38,0
0,38,31,27,19,19,19,27,31,38,0
0,38,0,0,0,0,0,0,0,38,0
endlayer

layer
0,37,38,0,0,0,0,0,38,36,0
0,37,38,27,2,2,2,27,38,36,0
0,37,38,0,2,2,2,0,38,36,0
0,37,38,0,0,0,0,0,38,36,0
0,37,38,0,0,0,0,0,38,36,0
0,37,38,0,0,0,0,0,38,36,0
0,37,38,0,0,0,0,0,38,36,0
0,37,38,0,0,0,0,0,38,36,0
0,37,38,0,0,0,0,0,38,36,0
0,37,38,27,27,27,27,27,38,36,0
0,37,38,0,0,0,0,0,38,36,0
endlayer

layer
0,0,37,38,0,0,0,38,36,0,0
0,0,37,38,2,2,2,38,36,0,0
0,0,37,38,2,2,2,38,36,0,0
0,0,37,38,38,38,38,38,36,0,0
0,0,37,38,38,38,38,38,36,0,0
0,0,37,38,38,38,38,38,36,0,0
0,0,37,38,38,38,38,38,36,0,0
0,0,37,38,38,38,38,38,36,0,0
0,0,37,38,38,38,38,38,36,0,0
0,0,37,38,38,38,38,38,36,0,0
0,0,37,38,38,38,38,38,36,0,0
endlayer

layer
0,0,0,37,38,38,38,36,0,0,0
0,0,0,39,40,40,40,39,0,0,0
0,0,0,39,2,2,2,39,0,0,0
0,0,0,39,39,39,39,39,0,0,0
0,0,0,39,39,39,39,39,0,0,0
0,0,0,39,39,39,39,39,0,0,0
0,0,0,39,39,39,39,39,0,0,0
0,0,0,39,39,39,39,39,0,0,0
0,0,0,39,39,39,39,39,0,0,0
0,0,0,39,41,41,41,39,0,0,0
0,0,0,37,38,38,38,36,0,0,0
endlayer

layer
0,0,0,0,42,42,42,0,0,0,0
0,0,0,0,0,0,0,0,0,0,0
0,0,0,0,2,2,2,0,0,0,0
0,0,0,0,0,0,0,0,0,0,0
0,0,0,0,0,0,0,0,0,0,0
0,0,0,0,0,0,0,0,0,0,0
0,0,0,0,0,0,0,0,0,0,0
0,0,0,0,0,0,0,0,0,0,0
0,0,0,0,0,0,0,0,0,0,0
0,0,0,0,0,0,0,0,0,0,0
0,0,0,0,41,41,41,0,0,0,0
endlayer

layer
0,0,0,0,0,0,0,0,0,0,0
0,0,0,0,0,0,0,0,0,0,0
0,0,0,0,7,7,7,0,0,0,0
0,0,0,0,0,0,0,0,0,0,0
0,0,0,0,0,0,0,0,0,0,0
0,0,0,0,0,0,0,0,0,0,0
0,0,0,0,0,0,0,0,0,0,0
0,0,0,0,0,0,0,0,0,0,0
0,0,0,0,0,0,0,0,0,0,0
0,0,0,0,0,0,0,0,0,0,0
0,0,0,0,0,0,0,0,0,0,0
endlayer

layer
0,0,0,0,0,0,0,0,0,0,0
0,0,0,0,0,0,0,0,0,0,0
0,0,0,0,14,43,14,0,0,0,0
0,0,0,0,0,0,0,0,0,0,0
0,0,0,0,0,0,0,0,0,0,0
0,0,0,0,0,0,0,0,0,0,0
0,0,0,0,0,0,0,0,0,0,0
0,0,0,0,0,0,0,0,0,0,0
0,0,0,0,0,0,0,0,0,0,0
0,0,0,0,0,0,0,0,0,0,0
0,0,0,0,0,0,0,0,0,0,0
endlayer

