# Bedrock Dungeon Tower -- MC 1.7.10 -- 29 Jan 2016
# Created by Ruins mod version 15.1 Ingame Parser
# authoring Player: Jordan_Greywolf
# Note: Place in \templateparser folder.
# Updated to MC 1.8: 5 Mar 2016
# Updated to MC 1.9: 26 Apr 2016
# Updated to MC 1.11: 11 Jan 2017
# Updated to MC 1.12: 22 Jun 2017

weight=1
embed_into_distance=7
acceptable_target_blocks=
unacceptable_target_blocks=flowing_water,water,flowing_lava,lava
dimensions=39,13,13
allowable_overhang=0
max_leveling=0
leveling_buffer=-1
preserve_water=0
preserve_lava=0

rule1=0,100,preserveBlock
rule2=0,100,minecraft:stonebrick-3
rule3=0,100,minecraft:stone_brick_stairs-6
rule4=0,100,minecraft:stone_brick_stairs-4
rule5=0,100,minecraft:stonebrick-0,minecraft:stonebrick-1,minecraft:stonebrick-2
rule6=0,100,minecraft:stone_brick_stairs-7
rule7=0,100,minecraft:stone_brick_stairs-5
rule8=0,100,minecraft:water-10
rule9=0,100,minecraft:water-9
rule10=0,100,minecraft:water-1
rule11=0,100,minecraft:water-2
rule12=0,100,minecraft:water-8
rule13=0,100,minecraft:water-0
rule14=0,100,minecraft:stone_slab-8
rule15=0,100,minecraft:stained_glass-3
rule16=0,100,minecraft:stained_glass-10
rule17=0,100,minecraft:stained_glass-11
rule18=0,100,minecraft:glowstone-0
rule19=0,100,minecraft:double_stone_slab-0
rule20=0,100,minecraft:stone_brick_stairs-0
rule21=0,100,minecraft:stone_brick_stairs-2
rule22=0,100,minecraft:iron_bars-0
rule23=0,100,minecraft:stone_brick_stairs-3
rule24=0,100,minecraft:cobblestone_wall-0,minecraft:cobblestone_wall-1

rule25=0,100,CommandBlock:RUINSTRIGGER /summon skeleton ~0 ~0 ~0 {HandItems:[{Count:1,id:rail},{}],ArmorItems:[{Count:1,id:leather_boots},{Count:1,id:leather_leggings},{Count:1,id:leather_chestplate},{Count:1,id:iron_helmet,tag:{ench:[{id:3,lvl:2},{id:5,lvl:2}]}}],HandDropChances:[2.0F,0.0F],ActiveEffects:[{Id:21,Amplifier:1,Duration:999999},{Id:14,Amplifier:1,Duration:999999},{Id:5,Amplifier:1,Duration:999999}],PersistenceRequired:1}:@

rule26=0,100,minecraft:stone_slab-0
rule27=2,100,minecraft:stone_button-2
rule28=2,100,minecraft:stone_button-4
rule29=0,100,CommandBlock:/tp @p[r=3] ~0 9 ~0:@
rule30=2,100,minecraft:stone_button-3
rule31=0,100,minecraft:fence_gate-0
rule32=2,100,minecraft:stone_button-1
rule33=0,100,minecraft:stone_brick_stairs-1
rule34=0,100,minecraft:ladder-2
rule35=0,100,minecraft:fence_gate-2
rule36=0,100,minecraft:stained_hardened_clay-15
rule37=0,100,minecraft:stained_hardened_clay-11
rule38=0,100,minecraft:trapdoor-0

rule39=0,100,CommandBlock:RUINSTRIGGER /summon blaze ~0 ~0 ~0 {CustomName:"Vengeful Spirit",ActiveEffects:[{Id:14,Amplifier:1,Duration:999999},{Id:10,Amplifier:1,Duration:999999},{Id:13,Amplifier:1,Duration:999999}],PersistenceRequired:1}:@

rule40=0,100,minecraft:stone_slab-6
rule41=0,100,minecraft:nether_brick_stairs-0
rule42=0,100,minecraft:nether_brick_stairs-2
rule43=0,100,minecraft:nether_brick-0
rule44=0,100,minecraft:nether_brick_stairs-3
rule45=0,100,ChestGenHook:chests/simple_dungeon:3-5
rule46=0,100,ChestGenHook:chests/simple_dungeon:3-3
rule47=0,100,ChestGenHook:chests/simple_dungeon:3-2
rule48=0,100,ChestGenHook:chests/simple_dungeon:3-4
rule49=0,100,minecraft:nether_brick_stairs-1
rule50=0,100,minecraft:nether_brick_stairs-7
rule51=0,100,minecraft:nether_brick_stairs-5
rule52=0,100,minecraft:nether_brick_stairs-6
rule53=0,100,minecraft:nether_brick_stairs-4
rule54=0,100,minecraft:nether_brick_fence-0



layer
1,1,1,1,1,1,1,1,1,1,1,1,1
1,1,1,1,1,1,1,1,1,1,1,1,1
1,1,1,1,1,1,1,1,1,1,1,1,1
1,1,1,1,1,1,1,1,1,1,1,1,1
1,1,1,1,1,1,1,1,1,1,1,1,1
1,1,1,1,1,1,1,1,1,1,1,1,1
1,1,1,1,1,1,2,1,1,1,1,1,1
1,1,1,1,1,1,1,1,1,1,1,1,1
1,1,1,1,1,1,1,1,1,1,1,1,1
1,1,1,1,1,1,1,1,1,1,1,1,1
1,1,1,1,1,1,1,1,1,1,1,1,1
1,1,1,1,1,1,1,1,1,1,1,1,1
1,1,1,1,1,1,1,1,1,1,1,1,1
endlayer

layer
1,1,1,1,1,1,1,1,1,1,1,1,1
1,1,1,1,1,1,1,1,1,1,1,1,1
1,1,1,1,1,1,1,1,1,1,1,1,1
1,1,1,1,1,1,1,1,1,1,1,1,1
1,1,1,1,1,1,1,1,1,1,1,1,1
1,1,1,1,1,4,4,3,1,1,1,1,1
1,1,1,1,1,6,5,3,1,1,1,1,1
1,1,1,1,1,6,7,7,1,1,1,1,1
1,1,1,1,1,1,1,1,1,1,1,1,1
1,1,1,1,1,1,1,1,1,1,1,1,1
1,1,1,1,1,1,1,1,1,1,1,1,1
1,1,1,1,1,1,1,1,1,1,1,1,1
1,1,1,1,1,1,1,1,1,1,1,1,1
endlayer

layer
1,1,1,1,1,1,1,1,1,1,1,1,1
1,1,1,1,1,1,1,1,1,1,1,1,1
1,1,1,1,1,1,1,1,1,1,1,1,1
1,1,1,1,1,1,1,1,1,1,1,1,1
1,1,1,1,6,4,4,4,4,1,1,1,1
1,1,1,1,6,5,5,5,3,1,1,1,1
1,1,1,1,6,5,5,5,3,1,1,1,1
1,1,1,1,6,5,5,5,3,1,1,1,1
1,1,1,1,7,7,7,7,7,1,1,1,1
1,1,1,1,1,1,1,1,1,1,1,1,1
1,1,1,1,1,1,1,1,1,1,1,1,1
1,1,1,1,1,1,1,1,1,1,1,1,1
1,1,1,1,1,1,1,1,1,1,1,1,1
endlayer

layer
1,1,1,1,1,1,1,1,1,1,1,1,1
1,1,1,1,1,1,1,1,1,1,1,1,1
1,1,1,1,1,1,1,1,1,1,1,1,1
1,1,1,6,4,4,4,4,4,4,1,1,1
1,1,1,6,5,5,5,5,5,3,1,1,1
1,1,1,6,5,8,9,8,5,3,1,1,1
1,1,1,6,5,9,5,9,5,3,1,1,1
1,1,1,6,5,8,9,8,5,3,1,1,1
1,1,1,6,5,5,5,5,5,3,1,1,1
1,1,1,7,7,7,7,7,7,7,1,1,1
1,1,1,1,1,1,1,1,1,1,1,1,1
1,1,1,1,1,1,1,1,1,1,1,1,1
1,1,1,1,1,1,1,1,1,1,1,1,1
endlayer

layer
1,1,1,1,1,1,1,1,1,1,1,1,1
1,1,1,1,1,1,1,1,1,1,1,1,1
1,1,6,4,4,4,4,4,4,4,4,1,1
1,1,6,5,5,5,5,5,5,5,3,1,1
1,1,6,5,8,10,9,10,8,5,3,1,1
1,1,6,5,10,11,10,11,10,5,3,1,1
1,1,6,5,9,10,5,10,9,5,3,1,1
1,1,6,5,10,11,10,11,10,5,3,1,1
1,1,6,5,8,10,9,10,8,5,3,1,1
1,1,6,5,5,5,5,5,5,5,3,1,1
1,1,6,7,7,7,7,7,7,7,3,1,1
1,1,1,1,1,1,1,1,1,1,1,1,1
1,1,1,1,1,1,1,1,1,1,1,1,1
endlayer

layer
1,1,1,1,1,1,1,1,1,1,1,1,1
1,4,4,4,4,4,4,4,4,4,4,4,1
1,6,5,5,5,5,5,5,5,5,5,3,1
1,6,5,12,10,0,13,0,10,12,5,3,1
1,6,5,10,11,0,10,0,11,10,5,3,1
1,6,5,0,0,6,4,4,0,0,5,3,1
1,6,5,13,10,6,5,3,10,13,5,3,1
1,6,5,0,0,7,7,3,0,0,5,3,1
1,6,5,10,11,0,10,0,11,10,5,3,1
1,6,5,12,10,0,13,0,10,12,5,3,1
1,6,5,5,5,5,5,5,5,5,5,3,1
1,7,7,7,7,7,7,7,7,7,7,3,1
1,1,1,1,1,1,1,1,1,1,1,1,1
endlayer

layer
4,4,4,4,4,4,4,4,4,4,4,4,4
6,5,5,5,5,5,5,5,5,5,5,5,3
6,5,13,13,14,15,14,15,14,13,13,5,3
6,5,13,13,14,15,14,15,14,13,13,5,3
6,5,14,14,6,4,4,4,4,14,14,5,3
6,5,15,15,6,16,17,16,3,15,15,5,3
6,5,14,14,6,17,18,17,3,14,14,5,3
6,5,15,15,6,16,17,16,3,15,15,5,3
6,5,14,14,7,7,7,7,3,14,14,5,3
6,5,13,13,14,15,14,15,14,13,13,5,3
6,5,13,13,14,15,14,15,14,13,13,5,3
6,5,5,5,5,5,5,5,5,5,5,5,3
7,7,7,7,7,7,7,7,7,7,7,7,3
endlayer

layer
19,20,20,19,0,0,0,0,0,19,20,20,19
23,0,0,0,5,19,22,19,5,0,0,0,21
23,0,0,0,24,0,25,0,24,0,0,0,21
19,0,0,19,19,0,0,0,19,19,0,0,19
0,5,24,19,26,0,0,0,26,19,24,5,0
0,19,0,0,0,0,27,0,0,0,0,19,0
0,31,0,0,0,30,29,28,0,0,25,22,0
0,19,0,0,0,0,32,0,0,0,0,19,0
0,5,24,19,26,0,0,0,26,19,24,5,0
19,0,0,19,19,0,0,0,19,19,0,0,19
23,0,0,0,24,0,25,0,24,0,0,0,21
23,0,0,0,5,19,22,19,5,0,0,0,21
19,33,33,19,0,0,0,0,0,19,33,33,19
endlayer

layer
19,22,22,19,0,0,0,0,0,19,22,22,19
22,0,0,0,5,19,22,19,5,0,0,0,22
22,0,0,0,0,0,0,0,0,0,0,0,22
19,0,0,19,24,0,0,0,24,19,0,0,19
0,5,0,24,0,0,0,0,0,24,0,5,0
0,19,0,0,0,0,0,0,0,0,0,19,0
0,0,0,0,0,0,5,34,0,0,0,22,0
0,19,0,0,0,0,0,0,0,0,0,19,0
0,5,0,24,0,0,0,0,0,24,0,5,0
19,0,0,19,24,0,0,0,24,19,0,0,19
22,0,0,0,0,0,0,0,0,0,0,0,22
22,0,0,0,5,19,22,19,5,0,0,0,22
19,22,22,19,0,0,0,0,0,19,22,22,19
endlayer

layer
19,4,4,19,0,0,0,0,0,19,4,4,19
6,0,0,0,5,19,2,19,5,0,0,0,3
6,0,0,0,24,0,0,0,24,0,0,0,3
19,0,0,19,19,0,0,0,19,19,0,0,19
0,5,24,19,14,0,0,0,14,19,24,5,0
0,19,0,0,0,0,0,0,0,0,0,19,0
0,2,0,0,0,0,5,34,0,0,0,2,0
0,19,0,0,0,0,0,0,0,0,0,19,0
0,5,24,19,14,0,0,0,14,19,24,5,0
19,0,0,19,19,0,0,0,19,19,0,0,19
6,0,0,0,24,0,0,0,24,0,0,0,3
6,0,0,0,5,19,2,19,5,0,0,0,3
19,7,7,19,0,0,0,0,0,19,7,7,19
endlayer

layer
5,5,5,5,4,4,4,4,4,5,5,5,5
5,19,19,19,5,5,5,5,5,19,19,19,5
5,19,26,26,26,26,26,26,26,26,26,19,5
5,19,26,26,26,26,26,26,26,26,26,19,5
6,5,26,26,5,5,19,5,5,26,26,5,3
6,5,26,26,5,26,26,26,5,26,26,5,3
6,5,26,26,19,26,5,34,19,26,26,5,3
6,5,26,26,5,26,26,26,5,26,26,5,3
6,5,26,26,5,5,19,5,5,26,26,5,3
5,19,26,26,26,26,26,26,26,26,26,19,5
5,19,26,26,26,26,26,26,26,26,26,19,5
5,19,19,19,5,5,5,5,5,19,19,19,5
5,5,5,5,7,7,7,7,7,5,5,5,5
endlayer

layer
5,5,5,5,19,26,26,26,19,5,5,5,5
5,33,33,33,5,5,5,5,5,33,33,23,5
5,21,0,0,0,0,0,0,0,0,0,23,5
5,21,0,0,0,0,0,0,0,0,0,23,5
19,5,0,0,5,5,22,5,5,0,0,5,19
26,5,0,0,5,0,0,0,5,0,0,5,26
26,5,0,0,35,0,5,34,22,0,0,5,26
26,5,0,0,5,0,0,0,5,0,0,5,26
19,5,0,0,5,5,22,5,5,0,0,5,19
5,21,0,0,0,0,0,0,0,0,0,23,5
5,21,0,0,0,0,0,0,0,0,0,23,5
5,21,20,20,5,5,5,5,5,20,20,20,5
5,5,5,5,19,26,26,26,19,5,5,5,5
endlayer

layer
24,24,24,24,24,1,1,1,24,24,24,24,24
24,0,0,0,24,24,24,24,24,0,0,0,24
24,0,0,0,0,0,0,0,0,0,0,0,24
24,0,0,0,0,0,0,0,0,0,0,0,24
24,24,0,0,5,5,22,5,5,0,0,24,24
1,24,0,0,5,0,0,0,5,0,0,24,1
1,24,0,0,0,0,5,34,22,0,0,24,1
1,24,0,0,5,0,0,0,5,0,0,24,1
24,24,0,0,5,5,22,5,5,0,0,24,24
24,0,0,0,0,0,0,0,0,0,0,0,24
24,0,0,0,0,0,0,0,0,0,0,0,24
24,0,0,0,24,24,24,24,24,0,0,0,24
24,24,24,24,24,1,1,1,24,24,24,24,24
endlayer

layer
1,1,1,1,1,1,1,1,1,1,1,1,1
1,0,0,0,1,1,1,1,1,0,0,0,1
1,0,0,0,0,0,0,0,0,0,0,0,1
1,0,0,0,0,0,0,0,0,0,0,0,1
1,1,0,0,5,5,22,5,5,0,0,1,1
1,1,0,0,5,0,0,0,5,0,0,1,1
1,1,0,0,0,0,5,34,22,0,0,1,1
1,1,0,0,5,0,0,0,5,0,0,1,1
1,1,0,0,5,5,22,5,5,0,0,1,1
1,0,0,0,0,0,0,0,0,0,0,0,1
1,0,0,0,0,0,0,0,0,0,0,0,1
1,0,0,0,1,1,1,1,1,0,0,0,1
1,1,1,1,1,1,1,1,1,1,1,1,1
endlayer

layer
1,1,1,1,1,1,1,1,1,1,1,1,1
1,0,0,0,1,1,1,1,1,0,0,0,1
1,0,0,0,0,0,0,0,0,0,0,0,1
1,0,0,0,0,0,0,0,0,0,0,0,1
1,1,0,0,5,5,19,5,5,0,0,1,1
1,1,0,0,5,26,26,26,5,0,0,1,1
1,1,0,0,19,26,5,34,19,0,0,1,1
1,1,0,0,5,26,26,26,5,0,0,1,1
1,1,0,0,5,5,19,5,5,0,0,1,1
1,0,0,0,0,0,0,0,0,0,0,0,1
1,0,0,0,0,0,0,0,0,0,0,0,1
1,0,0,0,1,1,1,1,1,0,0,0,1
1,1,1,1,1,1,1,1,1,1,1,1,1
endlayer

layer
1,1,1,1,1,1,1,1,1,1,1,1,1
1,1,1,1,1,1,1,1,1,1,1,1,1
1,1,1,1,1,1,1,1,1,1,1,1,1
1,1,1,1,1,1,1,1,1,1,1,1,1
1,1,1,1,5,5,22,5,5,1,1,1,1
1,1,1,1,5,0,0,0,5,1,1,1,1
1,1,1,1,22,0,5,34,22,1,1,1,1
1,1,1,1,5,0,0,0,5,1,1,1,1
1,1,1,1,5,5,22,5,5,1,1,1,1
1,1,1,1,1,1,1,1,1,1,1,1,1
1,1,1,1,1,1,1,1,1,1,1,1,1
1,1,1,1,1,1,1,1,1,1,1,1,1
1,1,1,1,1,1,1,1,1,1,1,1,1
endlayer

layer
1,1,1,1,1,1,1,1,1,1,1,1,1
1,1,1,1,1,1,1,1,1,1,1,1,1
1,1,1,1,1,1,1,1,1,1,1,1,1
1,1,1,1,1,1,1,1,1,1,1,1,1
1,1,1,1,5,5,22,5,5,1,1,1,1
1,1,1,1,5,0,0,0,5,1,1,1,1
1,1,1,1,22,0,5,34,22,1,1,1,1
1,1,1,1,5,0,0,0,5,1,1,1,1
1,1,1,1,5,5,22,5,5,1,1,1,1
1,1,1,1,1,1,1,1,1,1,1,1,1
1,1,1,1,1,1,1,1,1,1,1,1,1
1,1,1,1,1,1,1,1,1,1,1,1,1
1,1,1,1,1,1,1,1,1,1,1,1,1
endlayer

layer
1,1,1,1,1,1,1,1,1,1,1,1,1
1,1,1,1,1,1,1,1,1,1,1,1,1
1,1,1,1,1,1,1,1,1,1,1,1,1
1,1,1,1,1,1,1,1,1,1,1,1,1
1,1,1,1,5,5,22,5,5,1,1,1,1
1,1,1,1,5,0,0,0,5,1,1,1,1
1,1,1,1,22,0,5,34,22,1,1,1,1
1,1,1,1,5,0,0,0,5,1,1,1,1
1,1,1,1,5,5,22,5,5,1,1,1,1
1,1,1,1,1,1,1,1,1,1,1,1,1
1,1,1,1,1,1,1,1,1,1,1,1,1
1,1,1,1,1,1,1,1,1,1,1,1,1
1,1,1,1,1,1,1,1,1,1,1,1,1
endlayer

layer
1,1,1,1,1,1,1,1,1,1,1,1,1
1,1,1,1,1,1,1,1,1,1,1,1,1
1,1,1,1,1,1,1,1,1,1,1,1,1
1,1,1,1,1,1,1,1,1,1,1,1,1
1,1,1,1,5,5,19,5,5,1,1,1,1
1,1,1,1,5,19,19,19,5,1,1,1,1
1,1,1,1,19,19,5,34,19,1,1,1,1
1,1,1,1,5,19,19,19,5,1,1,1,1
1,1,1,1,5,5,19,5,5,1,1,1,1
1,1,1,1,1,1,1,1,1,1,1,1,1
1,1,1,1,1,1,1,1,1,1,1,1,1
1,1,1,1,1,1,1,1,1,1,1,1,1
1,1,1,1,1,1,1,1,1,1,1,1,1
endlayer

layer
1,1,1,1,1,1,1,1,1,1,1,1,1
1,1,1,1,1,1,1,1,1,1,1,1,1
1,1,1,1,1,1,1,1,1,1,1,1,1
1,1,1,1,1,4,1,4,1,1,1,1,1
1,1,1,1,5,5,5,5,5,1,1,1,1
1,1,1,6,5,19,19,19,5,3,1,1,1
1,1,1,1,5,19,5,34,5,1,1,1,1
1,1,1,6,5,19,19,19,5,3,1,1,1
1,1,1,1,5,5,5,5,5,1,1,1,1
1,1,1,1,1,7,1,7,1,1,1,1,1
1,1,1,1,1,1,1,1,1,1,1,1,1
1,1,1,1,1,1,1,1,1,1,1,1,1
1,1,1,1,1,1,1,1,1,1,1,1,1
endlayer

layer
0,0,0,0,0,0,0,0,0,0,0,0,0
0,0,0,0,0,0,0,0,0,0,0,0,0
0,0,14,14,14,14,14,14,14,14,14,0,0
0,0,14,5,5,5,5,5,5,5,14,0,0
0,0,14,5,36,37,36,37,36,5,14,0,0
0,0,14,5,37,36,37,36,37,5,14,0,0
0,0,14,5,36,37,36,34,36,5,14,0,0
0,0,14,5,37,36,37,36,37,5,14,0,0
0,0,14,5,36,37,36,37,36,5,14,0,0
0,0,14,5,5,5,5,5,5,5,14,0,0
0,0,14,14,14,14,14,14,14,14,14,0,0
0,0,0,0,0,0,0,0,0,0,0,0,0
0,0,0,0,0,0,0,0,0,0,0,0,0
endlayer

layer
0,0,0,0,0,0,0,0,0,0,0,0,0
0,0,0,0,0,0,0,0,0,0,0,0,0
0,0,23,20,20,20,20,20,20,20,20,0,0
0,0,23,5,5,5,5,5,5,5,21,0,0
0,0,23,5,0,0,0,0,0,5,21,0,0
0,0,23,5,0,0,0,0,0,5,21,0,0
0,0,23,5,0,39,5,38,0,5,21,0,0
0,0,23,5,0,0,0,0,0,5,21,0,0
0,0,23,5,0,0,0,0,0,5,21,0,0
0,0,23,5,5,5,5,5,5,5,21,0,0
0,0,33,33,33,33,33,33,33,33,21,0,0
0,0,0,0,0,0,0,0,0,0,0,0,0
0,0,0,0,0,0,0,0,0,0,0,0,0
endlayer

layer
0,0,0,0,0,0,0,0,0,0,0,0,0
0,0,0,0,0,0,0,0,0,0,0,0,0
0,0,0,0,0,0,0,0,0,0,0,0,0
0,0,0,5,19,5,22,5,19,5,0,0,0
0,0,0,19,0,0,0,0,0,19,0,0,0
0,0,0,5,0,0,0,0,0,5,0,0,0
0,0,0,22,0,0,5,34,0,22,0,0,0
0,0,0,5,0,0,0,0,0,5,0,0,0
0,0,0,19,0,0,0,0,0,19,0,0,0
0,0,0,5,19,5,22,5,19,5,0,0,0
0,0,0,0,0,0,0,0,0,0,0,0,0
0,0,0,0,0,0,0,0,0,0,0,0,0
0,0,0,0,0,0,0,0,0,0,0,0,0
endlayer

layer
0,0,0,0,0,0,0,0,0,0,0,0,0
0,0,0,0,0,0,0,0,0,0,0,0,0
0,0,0,0,0,0,0,0,0,0,0,0,0
0,0,0,5,19,5,22,5,19,5,0,0,0
0,0,0,19,0,0,0,0,0,19,0,0,0
0,0,0,5,0,0,0,0,0,5,0,0,0
0,0,0,22,0,0,5,34,0,22,0,0,0
0,0,0,5,0,0,0,0,0,5,0,0,0
0,0,0,19,0,0,0,0,0,19,0,0,0
0,0,0,5,19,5,22,5,19,5,0,0,0
0,0,0,0,0,0,0,0,0,0,0,0,0
0,0,0,0,0,0,0,0,0,0,0,0,0
0,0,0,0,0,0,0,0,0,0,0,0,0
endlayer

layer
0,0,0,0,0,0,0,0,0,0,0,0,0
0,0,0,0,0,0,0,0,0,0,0,0,0
0,0,0,0,0,0,0,0,0,0,0,0,0
0,0,0,5,19,5,22,5,19,5,0,0,0
0,0,0,19,7,7,14,7,6,19,0,0,0
0,0,0,5,3,14,14,14,6,5,0,0,0
0,0,0,22,14,14,5,34,14,22,0,0,0
0,0,0,5,3,14,14,14,6,5,0,0,0
0,0,0,19,3,4,14,4,4,19,0,0,0
0,0,0,5,19,5,22,5,19,5,0,0,0
0,0,0,0,0,0,0,0,0,0,0,0,0
0,0,0,0,0,0,0,0,0,0,0,0,0
0,0,0,0,0,0,0,0,0,0,0,0,0
endlayer

layer
0,0,0,0,0,0,0,0,0,0,0,0,0
0,0,0,0,0,0,0,0,0,0,0,0,0
0,0,4,4,4,4,4,4,4,4,4,0,0
0,0,6,5,5,5,5,5,5,5,3,0,0
0,0,6,5,36,37,36,37,36,5,3,0,0
0,0,6,5,37,36,37,36,37,5,3,0,0
0,0,6,5,36,37,36,34,36,5,3,0,0
0,0,6,5,37,36,37,36,37,5,3,0,0
0,0,6,5,36,37,36,37,36,5,3,0,0
0,0,6,5,5,5,5,5,5,5,3,0,0
0,0,7,7,7,7,7,7,7,7,3,0,0
0,0,0,0,0,0,0,0,0,0,0,0,0
0,0,0,0,0,0,0,0,0,0,0,0,0
endlayer

layer
40,40,40,40,40,40,40,40,40,40,40,40,40
40,41,41,41,41,41,41,41,41,41,41,41,40
40,44,43,43,43,43,43,43,43,43,43,42,40
40,44,43,43,43,43,45,43,43,43,43,42,40
40,44,43,43,0,0,0,0,0,43,43,42,40
40,44,43,43,0,0,0,0,0,43,43,42,40
40,44,43,47,0,0,2,38,0,46,43,42,40
40,44,43,43,0,0,0,0,0,43,43,42,40
40,44,43,43,0,0,0,0,0,43,43,42,40
40,44,43,43,43,43,48,43,43,43,43,42,40
40,44,43,43,43,43,43,43,43,43,43,42,40
40,49,49,49,49,49,49,49,49,49,49,42,40
40,40,40,40,40,40,40,40,40,40,40,40,40
endlayer

layer
0,0,0,0,0,0,0,0,0,0,0,0,0
0,0,0,0,0,0,0,0,0,0,0,0,0
0,0,40,40,44,43,22,43,40,40,40,0,0
0,0,40,43,43,43,0,43,43,43,40,0,0
0,0,41,43,51,51,0,51,50,43,40,0,0
0,0,43,43,52,0,0,0,50,43,43,0,0
0,0,22,0,0,0,39,0,0,0,22,0,0
0,0,43,43,52,0,0,0,50,43,43,0,0
0,0,49,43,52,53,0,53,53,43,49,0,0
0,0,40,43,43,43,0,43,43,43,40,0,0
0,0,40,40,44,43,22,43,42,40,40,0,0
0,0,0,0,0,0,0,0,0,0,0,0,0
0,0,0,0,0,0,0,0,0,0,0,0,0
endlayer

layer
0,0,0,0,0,0,0,0,0,0,0,0,0
0,0,0,0,0,0,0,0,0,0,0,0,0
0,0,0,0,0,43,22,43,0,0,0,0,0
0,0,0,0,44,43,0,43,0,0,0,0,0
0,0,0,41,43,43,0,43,43,0,0,0,0
0,0,43,43,43,0,0,0,43,43,43,0,0
0,0,22,0,0,0,0,0,0,0,22,0,0
0,0,43,43,43,0,0,0,43,43,43,0,0
0,0,0,49,43,43,0,43,43,49,0,0,0
0,0,0,0,44,43,0,43,42,0,0,0,0
0,0,0,0,0,43,22,43,0,0,0,0,0
0,0,0,0,0,0,0,0,0,0,0,0,0
0,0,0,0,0,0,0,0,0,0,0,0,0
endlayer

layer
0,0,0,0,0,0,0,0,0,0,0,0,0
0,0,0,0,0,0,0,0,0,0,0,0,0
0,0,0,0,0,44,43,42,0,0,0,0,0
0,0,0,0,0,44,43,42,0,0,0,0,0
0,0,0,0,44,41,43,42,41,0,0,0,0
0,0,41,41,41,0,0,0,42,41,41,0,0
0,0,43,43,43,0,0,0,43,43,43,0,0
0,0,49,49,44,0,0,0,49,49,49,0,0
0,0,0,0,49,44,43,49,42,0,0,0,0
0,0,0,0,0,44,43,42,0,0,0,0,0
0,0,0,0,0,44,43,42,0,0,0,0,0
0,0,0,0,0,0,0,0,0,0,0,0,0
0,0,0,0,0,0,0,0,0,0,0,0,0
endlayer

layer
0,0,0,0,0,0,0,0,0,0,0,0,0
0,0,0,0,0,0,0,0,0,0,0,0,0
0,0,0,0,0,0,40,0,0,0,0,0,0
0,0,0,0,0,0,40,0,0,0,0,0,0
0,0,0,0,0,0,40,0,0,0,0,0,0
0,0,0,0,0,43,43,43,0,0,0,0,0
0,0,40,40,40,43,0,43,40,40,40,0,0
0,0,0,0,0,43,43,43,0,0,0,0,0
0,0,0,0,0,0,40,0,0,0,0,0,0
0,0,0,0,0,0,40,0,0,0,0,0,0
0,0,0,0,0,0,40,0,0,0,0,0,0
0,0,0,0,0,0,0,0,0,0,0,0,0
0,0,0,0,0,0,0,0,0,0,0,0,0
endlayer

layer
0,0,0,0,0,0,0,0,0,0,0,0,0
0,0,0,0,0,0,0,0,0,0,0,0,0
0,0,0,0,0,0,0,0,0,0,0,0,0
0,0,0,0,0,0,0,0,0,0,0,0,0
0,0,0,0,0,0,0,0,0,0,0,0,0
0,0,0,0,0,43,43,43,0,0,0,0,0
0,0,0,0,0,43,43,43,0,0,0,0,0
0,0,0,0,0,43,43,43,0,0,0,0,0
0,0,0,0,0,0,0,0,0,0,0,0,0
0,0,0,0,0,0,0,0,0,0,0,0,0
0,0,0,0,0,0,0,0,0,0,0,0,0
0,0,0,0,0,0,0,0,0,0,0,0,0
0,0,0,0,0,0,0,0,0,0,0,0,0
endlayer

layer
0,0,0,0,0,0,0,0,0,0,0,0,0
0,0,0,0,0,0,0,0,0,0,0,0,0
0,0,0,0,0,0,0,0,0,0,0,0,0
0,0,0,0,0,0,0,0,0,0,0,0,0
0,0,0,0,0,0,0,0,0,0,0,0,0
0,0,0,0,0,44,41,41,0,0,0,0,0
0,0,0,0,0,44,43,42,0,0,0,0,0
0,0,0,0,0,49,49,42,0,0,0,0,0
0,0,0,0,0,0,0,0,0,0,0,0,0
0,0,0,0,0,0,0,0,0,0,0,0,0
0,0,0,0,0,0,0,0,0,0,0,0,0
0,0,0,0,0,0,0,0,0,0,0,0,0
0,0,0,0,0,0,0,0,0,0,0,0,0
endlayer

layer
0,0,0,0,0,0,0,0,0,0,0,0,0
0,0,0,0,0,0,0,0,0,0,0,0,0
0,0,0,0,0,0,0,0,0,0,0,0,0
0,0,0,0,0,0,0,0,0,0,0,0,0
0,0,0,0,0,0,0,0,0,0,0,0,0
0,0,0,0,0,0,0,0,0,0,0,0,0
0,0,0,0,0,0,43,0,0,0,0,0,0
0,0,0,0,0,0,0,0,0,0,0,0,0
0,0,0,0,0,0,0,0,0,0,0,0,0
0,0,0,0,0,0,0,0,0,0,0,0,0
0,0,0,0,0,0,0,0,0,0,0,0,0
0,0,0,0,0,0,0,0,0,0,0,0,0
0,0,0,0,0,0,0,0,0,0,0,0,0
endlayer

layer
0,0,0,0,0,0,0,0,0,0,0,0,0
0,0,0,0,0,0,0,0,0,0,0,0,0
0,0,0,0,0,0,0,0,0,0,0,0,0
0,0,0,0,0,0,0,0,0,0,0,0,0
0,0,0,0,0,0,0,0,0,0,0,0,0
0,0,0,0,0,0,0,0,0,0,0,0,0
0,0,0,0,0,0,43,0,0,0,0,0,0
0,0,0,0,0,0,0,0,0,0,0,0,0
0,0,0,0,0,0,0,0,0,0,0,0,0
0,0,0,0,0,0,0,0,0,0,0,0,0
0,0,0,0,0,0,0,0,0,0,0,0,0
0,0,0,0,0,0,0,0,0,0,0,0,0
0,0,0,0,0,0,0,0,0,0,0,0,0
endlayer

layer
0,0,0,0,0,0,0,0,0,0,0,0,0
0,0,0,0,0,0,0,0,0,0,0,0,0
0,0,0,0,0,0,0,0,0,0,0,0,0
0,0,0,0,0,0,0,0,0,0,0,0,0
0,0,0,0,0,0,0,0,0,0,0,0,0
0,0,0,0,0,0,0,0,0,0,0,0,0
0,0,0,0,0,0,43,0,0,0,0,0,0
0,0,0,0,0,0,0,0,0,0,0,0,0
0,0,0,0,0,0,0,0,0,0,0,0,0
0,0,0,0,0,0,0,0,0,0,0,0,0
0,0,0,0,0,0,0,0,0,0,0,0,0
0,0,0,0,0,0,0,0,0,0,0,0,0
0,0,0,0,0,0,0,0,0,0,0,0,0
endlayer

layer
0,0,0,0,0,0,0,0,0,0,0,0,0
0,0,0,0,0,0,0,0,0,0,0,0,0
0,0,0,0,0,0,0,0,0,0,0,0,0
0,0,0,0,0,0,0,0,0,0,0,0,0
0,0,0,0,0,0,0,0,0,0,0,0,0
0,0,0,0,0,0,0,0,0,0,0,0,0
0,0,0,0,0,0,54,0,0,0,0,0,0
0,0,0,0,0,0,0,0,0,0,0,0,0
0,0,0,0,0,0,0,0,0,0,0,0,0
0,0,0,0,0,0,0,0,0,0,0,0,0
0,0,0,0,0,0,0,0,0,0,0,0,0
0,0,0,0,0,0,0,0,0,0,0,0,0
0,0,0,0,0,0,0,0,0,0,0,0,0
endlayer

layer
0,0,0,0,0,0,0,0,0,0,0,0,0
0,0,0,0,0,0,0,0,0,0,0,0,0
0,0,0,0,0,0,0,0,0,0,0,0,0
0,0,0,0,0,0,0,0,0,0,0,0,0
0,0,0,0,0,0,0,0,0,0,0,0,0
0,0,0,0,0,0,0,0,0,0,0,0,0
0,0,0,0,0,0,54,0,0,0,0,0,0
0,0,0,0,0,0,0,0,0,0,0,0,0
0,0,0,0,0,0,0,0,0,0,0,0,0
0,0,0,0,0,0,0,0,0,0,0,0,0
0,0,0,0,0,0,0,0,0,0,0,0,0
0,0,0,0,0,0,0,0,0,0,0,0,0
0,0,0,0,0,0,0,0,0,0,0,0,0
endlayer

layer
0,0,0,0,0,0,0,0,0,0,0,0,0
0,0,0,0,0,0,0,0,0,0,0,0,0
0,0,0,0,0,0,0,0,0,0,0,0,0
0,0,0,0,0,0,0,0,0,0,0,0,0
0,0,0,0,0,0,0,0,0,0,0,0,0
0,0,0,0,0,0,0,0,0,0,0,0,0
0,0,0,0,0,0,54,0,0,0,0,0,0
0,0,0,0,0,0,0,0,0,0,0,0,0
0,0,0,0,0,0,0,0,0,0,0,0,0
0,0,0,0,0,0,0,0,0,0,0,0,0
0,0,0,0,0,0,0,0,0,0,0,0,0
0,0,0,0,0,0,0,0,0,0,0,0,0
0,0,0,0,0,0,0,0,0,0,0,0,0
endlayer

