# Cursed Village Pig Pen
# MC 1.7.10; 8 Nov 2014
# Created by Ruins mod version 14.2 Ingame Parser
# authoring Player: Jordan_Greywolf
# Special Instructions: Place in /templateparser folder.

# Updated to MC 1.9: 20 Apr 2016
# Updated to MC 1.11: 12 Jan 2017
# Updated to MC 1.12: 22 Jun 2017
# Last Updated: 16 May 2018

weight=1
embed_into_distance=6
acceptable_target_blocks=

unacceptable_target_blocks=flowing_lava,lava,cloud,Natura:Cloud,red_mushroom_block,brown_mushroom_block,planks,cobblestone,mossy_cobblestone,iron_bars,glass,redstone_torch,torch,stone_slab,double_stone_slab,oak_stairs,spruce_stairs,birch_stairs,dark_oak_stairs,acacia_stairs,jungle_stairs,slime_congealed,slime_dirt,slime_grass,fence,stone_brick,cobblestone_wall,command_block

dimensions=12,12,9
allowable_overhang=0
max_leveling=6
leveling_buffer=0
preserve_water=0
preserve_lava=0
preserve_plants=1

rule1=0,100,minecraft:dirt-0,minecraft:grass,minecraft:mycelium,minecraft:sand,minecraft:gravel
rule2=0,100,minecraft:cobblestone,minecraft:cobblestone,minecraft:cobblestone,minecraft:mossy_cobblestone,minecraft:mossy_cobblestone
rule3=0,100,minecraft:planks-0
rule4=0,100,minecraft:planks-0,minecraft:wooden_slab,minecraft:grass
rule5=0,100,minecraft:double_stone_slab-0
rule6=0,100,minecraft:gravel-0
rule7=0,100,minecraft:fence-0
rule8=0,90,minecraft:oak_stairs-1
rule9=0,90,minecraft:oak_stairs-3
rule10=0,100,minecraft:web-0
rule11=0,75,minecraft:glass_pane-0
rule12=0,100,minecraft:log-0
rule13=1,90,minecraft:wooden_pressure_plate-0
rule14=0,90,minecraft:oak_stairs-0
rule15=0,100,CommandBlock:RUINSTRIGGER /summon zombie_horse ~0 ~0 ~0 {Tame:1,PersistenceRequired:1}:@,CommandBlock:RUINSTRIGGER /summon skeleton_horse ~0 ~0 ~0 {NoAI:1,PersistenceRequired:1}:@,CommandBlock:RUINSTRIGGER /summon skeleton_horse ~0 ~0 ~0 {PersistenceRequired:1}:@

layer
1,1,1,1,1,1,1,1,1
1,1,1,1,1,1,1,1,1
1,1,1,1,1,1,1,1,1
1,1,1,1,1,1,1,1,1
1,1,2,1,1,1,1,1,1
2,2,2,2,2,2,2,2,2
2,5,5,5,5,5,5,5,2
2,5,5,5,5,5,5,5,2
2,5,5,5,5,5,5,5,2
2,5,5,5,5,5,5,5,2
2,2,2,2,2,2,2,2,2
1,1,1,1,1,1,1,1,1
endlayer

layer
1,1,1,1,1,1,1,1,1
1,1,1,1,1,1,1,1,1
1,1,1,1,1,1,1,1,1
1,1,1,1,1,1,1,1,1
1,1,2,1,1,1,1,1,1
2,2,2,2,2,2,2,2,2
2,10,0,0,0,0,0,10,2
2,0,0,0,0,0,0,0,2
2,0,0,0,0,0,0,10,2
2,10,10,0,0,0,0,10,2
2,2,2,2,2,2,2,2,2
1,1,1,1,1,1,1,1,1
endlayer

layer
1,1,1,1,1,1,1,1,1
1,1,1,1,1,1,1,1,1
1,1,1,1,1,1,1,1,1
1,1,1,1,1,1,1,1,1
1,1,2,1,1,1,1,1,1
2,2,2,2,2,2,2,2,2
2,0,0,0,0,0,0,0,2
2,0,0,0,0,0,0,0,2
2,0,0,0,0,0,0,0,2
2,0,0,0,0,0,0,0,2
2,2,2,2,2,2,2,2,2
1,1,1,1,1,1,1,1,1
endlayer

layer
1,1,1,1,1,1,1,1,1
1,1,1,1,1,1,1,1,1
1,1,1,1,1,1,1,1,1
1,1,1,1,1,1,1,1,1
1,1,2,1,1,1,1,1,1
2,2,2,2,2,2,2,2,2
2,0,0,0,0,0,0,10,2
2,0,0,0,0,0,0,0,2
2,0,0,0,0,0,0,0,2
2,10,0,0,0,0,0,0,2
2,2,2,2,2,2,2,2,2
1,1,1,1,1,1,1,1,1
endlayer

layer
1,1,1,1,1,1,1,1,1
1,1,1,1,1,1,1,1,1
1,1,1,1,1,1,1,1,1
1,1,1,1,1,1,1,1,1
1,1,2,1,1,1,1,1,1
2,2,2,2,2,2,2,2,2
2,10,0,0,0,0,10,10,2
2,0,0,0,0,0,0,10,2
2,10,0,0,0,0,0,0,2
2,10,10,0,0,0,0,10,2
2,2,2,2,2,2,2,2,2
1,1,1,1,1,1,1,1,1
endlayer




layer
1,1,1,1,1,1,1,1,1
1,1,1,1,1,1,1,1,1
1,1,1,1,1,1,1,1,1
1,1,1,1,1,1,1,1,1
1,1,2,1,1,1,1,1,1
2,2,2,2,2,2,2,2,2
2,4,4,4,4,4,4,3,2
2,5,5,5,4,4,4,4,2
2,5,5,5,4,4,4,4,2
2,5,5,5,4,4,4,4,2
2,2,2,2,2,2,2,2,2
6,6,6,6,6,6,6,6,6
endlayer

layer
7,7,7,7,7,7,7,0,0
7,0,0,0,0,0,7,0,0
7,0,0,15,0,0,7,0,0
7,0,0,0,0,0,7,0,0
7,0,0,0,0,0,7,0,0
2,2,0,2,2,2,2,2,2
2,0,0,0,0,0,8,3,2
2,0,0,0,0,0,7,9,2
2,0,5,0,0,0,0,0,2
2,10,5,0,0,0,0,0,2
2,2,2,2,2,2,0,2,2
0,0,0,0,0,0,0,0,0
endlayer

layer
0,0,0,0,0,0,0,0,0
0,0,0,0,0,0,0,0,0
0,0,0,0,0,0,0,0,0
0,0,0,0,0,0,0,0,0
0,0,0,0,0,0,0,0,0
2,3,0,3,3,11,11,3,2
12,0,0,0,0,0,0,0,12
11,0,0,0,0,0,13,0,11
11,0,0,0,0,0,0,0,11
12,0,0,0,0,0,0,0,12
2,3,3,11,3,3,0,3,2
0,0,0,0,0,0,0,0,0
endlayer

layer
0,0,0,0,0,0,0,0,0
0,0,0,0,0,0,0,0,0
0,0,0,0,0,0,0,0,0
0,0,0,0,0,0,0,0,0
14,14,14,14,14,14,14,14,14
2,3,3,3,3,3,3,3,2
2,10,0,0,10,0,0,10,2
2,0,0,0,0,0,0,0,2
2,0,0,0,0,0,0,0,2
2,10,0,0,0,0,0,10,2
2,3,3,3,3,3,3,3,2
8,8,8,8,8,8,8,8,8
endlayer

layer
0,0,0,0,0,0,0,0,0
0,0,0,0,0,0,0,0,0
0,0,0,0,0,0,0,0,0
0,0,0,0,0,0,0,0,0
0,0,0,0,0,0,0,0,0
14,14,14,14,14,14,14,14,14
3,3,3,3,3,3,3,3,3
3,10,0,0,0,0,0,0,3
3,0,0,10,10,0,0,10,3
3,3,3,3,3,3,3,3,3
8,8,8,8,8,8,8,8,8
0,0,0,0,0,0,0,0,0
endlayer

layer
0,0,0,0,0,0,0,0,0
0,0,0,0,0,0,0,0,0
0,0,0,0,0,0,0,0,0
0,0,0,0,0,0,0,0,0
0,0,0,0,0,0,0,0,0
0,0,0,0,0,0,0,0,0
14,14,14,14,14,14,14,14,14
3,3,3,3,3,3,3,3,3
3,3,3,3,3,3,3,3,3
8,8,8,8,8,8,8,8,8
0,0,0,0,0,0,0,0,0
0,0,0,0,0,0,0,0,0
endlayer

layer
0,0,0,0,0,0,0,0,0
0,0,0,0,0,0,0,0,0
0,0,0,0,0,0,0,0,0
0,0,0,0,0,0,0,0,0
0,0,0,0,0,0,0,0,0
0,0,0,0,0,0,0,0,0
0,0,0,0,0,0,0,0,0
14,14,14,14,14,14,14,14,14
8,8,8,8,8,8,8,8,8
0,0,0,0,0,0,0,0,0
0,0,0,0,0,0,0,0,0
0,0,0,0,0,0,0,0,0
endlayer

