# Cursed Village Plot
# MC 1.7.10; 8 Nov 2014
# Created by Ruins mod version 14.2 Ingame Parser
# authoring Player: Jordan_Greywolf

# Updated to MC 1.8: 5 Mar 2016
# Updated to MC 1.9: 20 Apr 2016
# Updated to MC 1.11: 12 Jan 2017
# Last Updated 16 May 2018

weight=1
embed_into_distance=5
acceptable_target_blocks=

unacceptable_target_blocks=flowing_lava,lava,cloud,Natura:Cloud,red_mushroom_block,brown_mushroom_block,planks,cobblestone,mossy_cobblestone,iron_bars,glass,redstone_torch,torch,stone_slab,double_stone_slab,oak_stairs,spruce_stairs,birch_stairs,dark_oak_stairs,acacia_stairs,jungle_stairs,slime_congealed,slime_dirt,slime_grass,fence,stone_brick,cobblestone_wall,command_block

dimensions=8,9,13
allowable_overhang=0
max_leveling=5
leveling_buffer=0
preserve_water=0
preserve_lava=0
preserve_plants=1

rule1=0,100,minecraft:log-0
rule2=0,100,minecraft:dirt,minecraft:farmland-4,minecraft:farmland-5,minecraft:farmland-7,minecraft:farmland-1,minecraft:grass,minecraft:sand,minecraft:mycelium
rule3=0,100,minecraft:water-0
rule4=0,75,minecraft:tallgrass-1,minecraft:wheat-4,minecraft:skull,minecraft:wheat-1,minecraft:tallgrass,minecraft:wheat-2,minecraft:wheat-3
rule5=0,100,minecraft:double_plant-2
rule6=0,100,minecraft:double_plant-8
rule7=0,100,minecraft:double_plant-11
rule8=0,100,minecraft:double_plant-9

rule9=0,100,CommandBlock:RUINSTRIGGER /summon rabbit ~0 ~0 ~0 {RabbitType:99,PersistenceRequired:1}:@

layer
1,1,1,1,1,1,1,1,1,1,1,1,1
1,2,2,2,2,2,1,2,2,2,2,2,1
1,2,2,2,2,2,1,2,2,2,2,2,1
1,2,2,2,2,2,1,2,2,2,2,2,1
1,2,2,2,2,2,1,2,2,2,2,2,1
1,2,2,2,2,2,1,2,2,2,2,2,1
1,2,2,2,2,2,1,2,2,2,2,2,1
1,2,2,2,2,2,1,2,2,2,2,2,1
1,1,1,1,1,1,1,1,1,1,1,1,1
endlayer

layer
1,1,1,1,1,1,1,1,1,1,1,1,1
1,2,2,2,2,2,1,2,2,2,2,2,1
1,2,2,2,2,2,1,2,2,2,2,2,1
1,2,2,2,2,2,1,2,2,2,2,2,1
1,2,2,2,2,2,1,2,2,2,2,2,1
1,2,2,2,2,2,1,2,2,2,2,2,1
1,2,2,2,2,2,1,2,2,2,2,2,1
1,2,2,2,2,2,1,2,2,2,2,2,1
1,1,1,1,1,1,1,1,1,1,1,1,1
endlayer

layer
1,1,1,1,1,1,1,1,1,1,1,1,1
1,2,2,2,2,2,1,2,2,2,2,2,1
1,2,2,2,2,2,1,2,2,2,2,2,1
1,2,2,2,2,2,1,2,2,2,2,2,1
1,2,2,2,2,2,1,2,2,2,2,2,1
1,2,2,2,2,2,1,2,2,2,2,2,1
1,2,2,2,2,2,1,2,2,2,2,2,1
1,2,2,2,2,2,1,2,2,2,2,2,1
1,1,1,1,1,1,1,1,1,1,1,1,1
endlayer

layer
1,1,1,1,1,1,1,1,1,1,1,1,1
1,2,2,2,2,2,1,2,2,2,2,2,1
1,2,2,2,2,2,1,2,2,2,2,2,1
1,2,2,2,2,2,1,2,2,2,2,2,1
1,2,2,2,2,2,1,2,2,2,2,2,1
1,2,2,2,2,2,1,2,2,2,2,2,1
1,2,2,2,2,2,1,2,2,2,2,2,1
1,2,2,2,2,2,1,2,2,2,2,2,1
1,1,1,1,1,1,1,1,1,1,1,1,1
endlayer

layer
1,1,1,1,1,1,1,1,1,1,1,1,1
1,2,2,2,2,2,1,2,2,2,2,2,1
1,2,2,2,2,2,1,2,2,2,2,2,1
1,2,2,2,2,2,1,2,2,2,2,2,1
1,2,2,2,2,2,1,2,2,2,2,2,1
1,2,2,2,2,2,1,2,2,2,2,2,1
1,2,2,2,2,2,1,2,2,2,2,2,1
1,2,2,2,2,2,1,2,2,2,2,2,1
1,1,1,1,1,1,1,1,1,1,1,1,1
endlayer


layer
1,1,1,1,1,1,1,1,1,1,1,1,1
1,2,2,3,2,2,1,2,2,3,2,2,1
1,2,2,3,2,2,1,2,2,3,2,2,1
1,2,2,3,2,2,1,2,2,3,2,2,1
1,2,2,3,2,2,1,2,2,3,2,2,1
1,2,2,3,2,2,1,2,2,3,2,2,1
1,2,2,3,2,2,1,2,2,3,2,2,1
1,2,2,3,2,2,1,2,2,3,2,2,1
1,1,1,1,1,1,1,1,1,1,1,1,1
endlayer

layer
0,0,0,0,0,0,0,0,0,0,0,0,0
0,4,4,0,4,4,0,4,4,0,5,4,0
0,4,4,0,4,5,0,4,4,0,4,5,0
0,5,4,0,4,4,0,4,5,0,4,4,0
0,4,4,0,4,4,9,4,4,0,4,4,0
0,4,4,0,4,4,0,5,4,0,4,4,0
0,4,4,0,5,4,0,4,4,0,4,4,0
0,4,4,0,4,4,0,4,4,0,4,5,0
0,0,0,0,0,0,0,0,0,0,0,0,0
endlayer

layer
0,0,0,0,0,0,0,0,0,0,0,0,0
0,0,0,0,0,0,0,0,0,0,6,0,0
0,0,0,0,0,7,0,0,0,0,0,6,0
0,7,0,0,0,0,0,0,8,0,0,0,0
0,0,0,0,0,0,0,0,0,0,0,0,0
0,0,0,0,0,0,0,7,0,0,0,0,0
0,0,0,0,7,0,0,0,0,0,0,0,0
0,0,0,0,0,0,0,0,0,0,0,6,0
0,0,0,0,0,0,0,0,0,0,0,0,0
endlayer

