# Cave Garden Quarter
# Created by Ruins mod version 16.8 Ingame Parser
# authoring Player: Jordan_Greywolf
# Created 2 Dec 2017 for MC 1.12.1

weight=1
embed_into_distance=0
acceptable_target_blocks=
unacceptable_target_blocks=flowing_water,water,flowing_lava,lava

dimensions=25,13,13
allowable_overhang=0
max_leveling=0
leveling_buffer=-1
preserve_water=0
preserve_lava=0
preserve_plants=1

rule1=0,100,preserveBlock

rule2=0,100,minecraft:dirt-0

rule3=0,100,minecraft:grass-0

rule4=1,100,minecraft:grass-0,minecraft:flowing_water-0

rule5=0,100,minecraft:flowing_water-0
rule6=1,100,minecraft:tallgrass-2,minecraft:tallgrass-1

rule7=0,100,CommandBlock:RUINSTRIGGER /testruin TP_Tree_GnarledOak ~0 ~0 ~0:@-1,CommandBlock:RUINSTRIGGER /testruin TP_Tree_GnarledOak ~0 ~0 ~0 1:@-1,CommandBlock:RUINSTRIGGER /testruin TP_Tree_GnarledOak ~0 ~0 ~0 2:@-1,CommandBlock:RUINSTRIGGER /testruin TP_Tree_GnarledOak ~0 ~0 ~0 3:@-1,CommandBlock:RUINSTRIGGER /testruin TP_Tree_GreatGnarledOak ~0 ~0 ~0:@-1

rule8=1,100,minecraft:red_mushroom-0,minecraft:brown_mushroom-0
rule9=0,100,minecraft:double_plant-3
rule10=1,100,minecraft:grass-0
rule11=0,100,minecraft:double_plant-10

layer
1,1,1,1,2,2,2,1,1,1,1,1,1
1,1,1,1,2,2,2,1,1,1,1,1,1
1,1,1,1,2,2,2,1,1,1,1,1,1
1,1,1,2,2,3,2,2,1,1,1,1,1
1,1,2,2,2,2,2,2,1,1,1,1,1
1,2,2,2,2,2,2,1,1,1,1,1,1
2,2,2,2,2,2,2,2,1,1,1,1,1
2,2,2,2,2,2,2,1,1,1,1,1,1
1,2,2,2,2,2,1,1,1,1,1,1,1
1,1,1,2,1,1,1,1,1,1,1,1,1
1,1,1,1,1,1,1,1,1,1,1,1,1
1,1,1,1,1,1,1,1,1,1,1,1,1
1,1,1,1,1,1,1,1,1,1,1,1,1
endlayer

layer
2,3,3,3,3,4,4,3,1,1,1,1,1
3,3,3,3,4,5,5,2,2,1,1,1,1
3,3,3,3,4,5,4,1,1,1,1,1,1
3,3,3,4,5,5,5,4,1,1,1,1,1
3,3,4,5,5,5,5,4,2,1,1,1,1
3,4,5,5,5,5,5,2,1,1,1,1,1
4,5,5,5,5,5,5,4,1,1,1,1,1
4,5,5,5,5,5,4,3,1,1,1,1,1
3,4,4,5,4,4,1,1,1,1,1,1,1
1,3,3,4,3,1,1,1,1,1,1,1,1
1,1,1,1,2,1,1,1,1,1,1,1,1
1,1,1,1,1,1,1,1,1,1,1,1,1
1,1,1,1,1,1,1,1,1,1,1,1,1
endlayer

layer
7,0,0,0,0,0,0,6,3,3,1,1,1
0,0,0,0,0,0,0,3,3,1,1,1,1
0,0,8,9,8,0,8,3,1,1,1,1,1
0,0,8,8,0,0,0,8,3,1,1,1,1
0,9,8,0,0,0,0,8,4,1,1,1,1
0,0,0,0,0,0,0,4,1,1,1,1,1
0,0,0,0,0,0,0,8,3,1,1,1,1
0,0,0,0,0,0,8,6,3,1,1,1,1
6,0,8,0,8,8,3,3,1,1,1,1,1
3,6,6,8,6,3,3,1,1,1,1,1,1
1,1,1,3,4,1,1,1,1,1,1,1,1
1,1,1,1,1,1,1,1,1,1,1,1,1
1,1,1,1,1,1,1,1,1,1,1,1,1
endlayer

layer
0,0,0,0,0,0,0,0,6,6,10,1,1
0,0,0,0,0,0,0,6,9,1,1,1,1
0,0,0,11,0,0,0,6,1,1,1,1,1
0,0,0,0,0,0,0,0,6,1,1,1,1
0,11,0,0,0,0,0,0,8,1,1,1,1
0,0,0,0,0,0,0,8,3,1,1,1,1
0,0,0,0,0,0,0,0,6,1,1,1,1
0,0,0,0,0,0,0,0,6,1,1,1,1
0,0,0,0,0,0,6,6,1,1,1,1,1
6,0,0,0,0,6,9,1,1,1,1,1,1
1,1,10,6,10,1,1,1,1,1,1,1,1
1,1,1,1,1,1,1,1,1,1,1,1,1
1,1,1,1,1,1,1,1,1,1,1,1,1
endlayer

layer
0,0,0,0,0,0,0,0,0,0,6,1,1
0,0,0,0,0,0,0,0,11,10,1,1,1
0,0,0,0,0,0,0,0,10,1,1,1,1
0,0,0,0,0,0,0,0,0,1,1,1,1
0,0,0,0,0,0,0,0,0,1,1,1,1
0,0,0,0,0,0,0,0,9,10,1,1,1
0,0,0,0,0,0,0,0,0,1,1,1,1
0,0,0,0,0,0,0,0,0,1,1,1,1
0,0,0,0,0,0,0,0,10,1,1,1,1
0,0,0,0,0,0,11,8,1,1,1,1,1
0,10,6,0,6,10,10,10,1,1,1,1,1
1,1,1,10,1,1,1,1,1,1,1,1,1
1,1,1,1,1,1,1,1,1,1,1,1,1
endlayer

layer
0,0,0,0,0,0,0,0,0,0,0,1,1
0,0,0,0,0,0,0,0,0,6,1,1,1
0,0,0,0,0,0,0,0,6,1,1,1,1
0,0,0,0,0,0,0,0,0,1,1,1,1
0,0,0,0,0,0,0,0,0,10,1,1,1
0,0,0,0,0,0,0,0,11,6,1,1,1
0,0,0,0,0,0,0,0,0,10,1,1,1
0,0,0,0,0,0,0,0,0,1,1,1,1
0,0,0,0,0,0,0,0,6,8,1,1,1
0,0,0,0,0,0,0,0,8,4,1,1,1
0,6,0,0,0,6,6,6,1,1,1,1,1
0,1,8,6,8,8,1,1,1,1,1,1,1
1,1,1,1,1,1,1,1,1,1,1,1,1
endlayer

layer
0,0,0,0,0,0,0,0,0,0,0,1,1
0,0,0,0,0,0,0,0,0,0,1,1,1
0,0,0,0,0,0,0,0,0,8,1,1,1
0,0,0,0,0,0,0,0,0,10,1,1,1
0,0,0,0,0,0,0,0,0,6,10,1,1
0,0,0,0,0,0,0,0,0,0,8,1,1
0,0,0,0,0,0,0,0,0,6,8,1,1
0,0,0,0,0,0,0,0,0,8,10,1,1
0,0,0,0,0,0,0,0,0,1,1,1,1
0,0,0,0,0,0,0,0,0,1,1,1,1
0,0,0,0,0,0,0,0,1,1,1,1,1
0,10,0,0,0,0,10,1,1,1,1,1,1
1,1,1,1,1,1,1,1,1,1,1,1,1
endlayer

layer
0,0,0,0,0,0,0,0,0,0,0,1,1
0,0,0,0,0,0,0,0,0,0,1,1,1
0,0,0,0,0,0,0,0,0,0,1,1,1
0,0,0,0,0,0,0,0,0,6,1,1,1
0,0,0,0,0,0,0,0,0,0,6,1,1
0,0,0,0,0,0,0,0,0,0,0,10,1
0,0,0,0,0,0,0,0,0,0,0,10,1
0,0,0,0,0,0,0,0,0,0,6,1,1
0,0,0,0,0,0,0,0,0,8,10,1,1
0,0,0,0,0,0,0,0,0,8,10,10,1
0,0,0,0,0,0,0,0,8,10,1,1,1
0,6,0,0,0,0,9,8,10,1,1,1,1
1,1,1,0,0,10,1,1,1,1,1,1,1
endlayer

layer
0,0,0,0,0,0,0,0,0,0,1,1,1
0,0,0,0,0,0,0,0,0,0,1,1,1
0,0,0,0,0,0,0,0,0,0,1,1,1
0,0,0,0,0,0,0,0,0,0,1,1,1
0,0,0,0,0,0,0,0,0,0,0,1,1
0,0,0,0,0,0,0,0,0,0,0,6,1
0,0,0,0,0,0,0,0,0,0,0,6,1
0,0,0,0,0,0,0,0,0,0,0,1,1
0,0,0,0,0,0,0,0,0,0,6,1,1
0,0,0,0,0,0,0,0,0,0,6,6,0
0,0,0,0,0,0,0,0,0,6,8,8,10
0,0,0,0,0,0,11,0,6,0,8,4,1
1,1,4,0,0,6,0,10,0,0,10,1,1
endlayer

layer
0,0,0,0,0,0,0,0,0,1,1,1,1
0,0,0,0,0,0,0,0,0,0,1,1,1
0,0,0,0,0,0,0,0,0,0,1,1,1
0,0,0,0,0,0,0,0,0,0,10,1,1
0,0,0,0,0,0,0,0,0,0,0,1,1
0,0,0,0,0,0,0,0,0,0,0,0,1
0,0,0,0,0,0,0,0,0,0,0,0,1
0,0,0,0,0,0,0,0,0,0,0,10,1
0,0,0,0,0,0,0,0,0,0,0,1,1
0,0,0,0,0,0,0,0,0,0,0,0,0
0,0,0,0,0,0,0,0,0,0,0,0,6
1,1,0,0,0,0,0,0,0,0,0,8,10
1,1,0,0,0,0,0,6,0,0,6,10,1
endlayer

layer
0,0,0,0,0,0,0,0,0,10,1,1,1
0,0,0,0,0,0,0,0,0,0,1,1,1
0,0,0,0,0,0,0,0,0,0,10,1,1
0,0,0,0,0,0,0,0,0,0,6,1,1
0,0,0,0,0,0,0,0,0,0,0,1,1
0,0,0,0,0,0,0,0,0,0,0,0,1
0,0,0,0,0,0,0,0,0,0,0,0,1
0,0,0,0,0,0,0,0,0,0,0,6,1
0,0,0,0,0,0,0,0,0,0,0,10,10
0,0,0,0,0,0,0,0,0,0,0,0,0
1,0,0,0,0,0,0,0,0,0,0,0,0
1,1,0,0,0,0,0,0,0,0,0,0,6
1,1,0,0,0,0,0,0,0,0,0,6,1
endlayer

layer
0,0,0,0,0,0,0,0,0,6,1,1,1
0,0,0,0,0,0,0,0,0,0,1,1,1
0,0,0,0,0,0,0,0,0,0,6,1,1
0,0,0,0,0,0,0,0,0,0,0,1,1
0,0,0,0,0,0,0,0,0,0,0,1,1
0,0,0,0,0,0,0,0,0,0,0,0,1
0,0,0,0,0,0,0,0,0,0,0,0,1
0,0,0,0,0,0,0,0,0,0,0,0,10
0,0,0,0,0,0,0,0,0,0,0,6,6
0,0,0,0,0,0,0,0,0,0,0,0,0
10,0,0,0,0,0,0,0,0,0,0,0,0
1,10,0,0,0,0,0,0,0,0,0,0,0
1,1,0,0,0,0,0,0,0,0,0,0,1
endlayer

layer
0,0,0,0,0,0,0,0,0,0,10,1,1
0,0,0,0,0,0,0,0,0,0,1,1,1
0,0,0,0,0,0,0,0,0,0,0,1,1
0,0,0,0,0,0,0,0,0,0,0,1,1
0,0,0,0,0,0,0,0,0,0,0,4,1
0,0,0,0,0,0,0,0,0,0,0,0,10
0,0,0,0,0,0,0,0,0,0,0,0,10
0,0,0,0,0,0,0,0,0,0,0,0,6
0,0,0,0,0,0,0,0,0,0,0,0,0
0,0,0,0,0,0,0,0,0,0,0,0,0
6,0,0,0,0,0,0,0,0,0,0,0,0
10,6,0,0,0,0,0,0,0,0,0,0,1
1,1,0,0,0,0,0,0,0,0,0,1,1
endlayer

layer
0,0,0,0,0,0,0,0,0,0,6,1,1
0,0,0,0,0,0,0,0,0,0,10,1,1
0,0,0,0,0,0,0,0,0,0,0,1,1
0,0,0,0,0,0,0,0,0,0,0,10,1
0,0,0,0,0,0,0,0,0,0,0,8,10
0,0,0,0,0,0,0,0,0,0,0,0,6
0,0,0,0,0,0,0,0,0,0,0,0,6
0,0,0,0,0,0,0,0,0,0,0,0,0
0,0,0,0,0,0,0,0,0,0,0,0,0
0,0,0,0,0,0,0,0,0,0,0,0,0
0,0,0,0,0,0,0,0,0,0,0,0,0
6,0,0,0,0,0,0,0,0,0,0,0,1
1,10,0,0,0,0,0,0,0,0,0,1,1
endlayer

layer
0,0,0,0,0,0,0,0,0,0,0,1,1
0,0,0,0,0,0,0,0,0,0,6,1,1
0,0,0,0,0,0,0,0,0,0,0,1,1
0,0,0,0,0,0,0,0,0,0,0,6,0
0,0,0,0,0,0,0,0,0,0,0,0,6
0,0,0,0,0,0,0,0,0,0,0,0,0
0,0,0,0,0,0,0,0,0,0,0,0,0
0,0,0,0,0,0,0,0,0,0,0,0,0
0,0,0,0,0,0,0,0,0,0,0,0,0
0,0,0,0,0,0,0,0,0,0,0,0,0
0,0,0,0,0,0,0,0,0,0,0,0,1
0,0,0,0,0,0,0,0,0,0,0,0,1
1,6,0,0,0,0,0,0,0,0,1,1,1
endlayer

layer
0,0,0,0,0,0,0,0,0,0,0,1,1
0,0,0,0,0,0,0,0,0,0,0,1,1
0,0,0,0,0,0,0,0,0,0,0,1,1
0,0,0,0,0,0,0,0,0,0,0,0,0
0,0,0,0,0,0,0,0,0,0,0,0,0
0,0,0,0,0,0,0,0,0,0,0,0,0
0,0,0,0,0,0,0,0,0,0,0,0,0
0,0,0,0,0,0,0,0,0,0,0,0,0
0,0,0,0,0,0,0,0,0,0,0,0,0
0,0,0,0,0,0,0,0,0,0,0,0,0
0,0,0,0,0,0,0,0,0,0,0,0,1
0,0,0,0,0,0,0,0,0,0,0,0,1
1,0,0,0,0,0,0,0,0,0,1,1,1
endlayer

layer
0,0,0,0,0,0,0,0,0,0,0,1,1
0,0,0,0,0,0,0,0,0,0,1,1,1
0,0,0,0,0,0,0,0,0,0,0,1,1
0,0,0,0,0,0,0,0,0,0,0,0,0
0,0,0,0,0,0,0,0,0,0,0,0,0
0,0,0,0,0,0,0,0,0,0,0,0,0
0,0,0,0,0,0,0,0,0,0,0,0,0
0,0,0,0,0,0,0,0,0,0,0,0,0
0,0,0,0,0,0,0,0,0,0,0,0,0
0,0,0,0,0,0,0,0,0,0,0,0,0
0,0,0,0,0,0,0,0,0,0,0,0,1
1,0,0,0,0,0,0,0,0,0,0,0,1
1,1,0,0,0,0,0,0,0,0,1,1,1
endlayer

layer
0,0,0,0,0,0,0,0,0,0,1,1,1
0,0,0,0,0,0,0,0,0,0,1,1,1
0,0,0,0,0,0,0,0,0,0,0,1,1
0,0,0,0,0,0,0,0,0,0,0,1,1
0,0,0,0,0,0,0,0,0,0,0,0,0
0,0,0,0,0,0,0,0,0,0,0,0,0
0,0,0,0,0,0,0,0,0,0,0,0,0
0,0,0,0,0,0,0,0,0,0,0,0,1
0,0,0,0,0,0,0,0,0,0,0,0,1
0,0,0,0,0,0,0,0,0,0,0,0,1
0,0,0,0,0,0,0,0,0,0,0,0,1
1,0,0,0,0,0,0,0,0,0,0,1,1
1,1,1,0,0,0,0,0,0,1,1,1,1
endlayer

layer
0,0,0,0,0,0,0,0,0,0,1,1,1
0,0,0,0,0,0,0,0,0,0,1,1,1
0,0,0,0,0,0,0,0,0,0,1,1,1
0,0,0,0,0,0,0,0,0,0,1,1,1
0,0,0,0,0,0,0,0,0,0,0,1,1
0,0,0,0,0,0,0,0,0,0,0,0,1
0,0,0,0,0,0,0,0,0,0,0,1,1
0,0,0,0,0,0,0,0,0,0,0,1,1
1,1,0,0,0,0,0,0,0,0,0,1,1
1,0,0,0,0,0,0,0,0,0,0,1,1
1,0,0,0,0,0,0,0,0,0,0,1,1
1,1,0,0,0,0,0,0,0,0,0,1,1
1,1,0,0,0,0,0,1,1,1,1,1,1
endlayer

layer
0,0,0,0,0,0,0,0,0,1,1,1,1
0,0,0,0,0,0,0,0,0,1,1,1,1
0,0,0,0,0,0,0,0,0,0,1,1,1
0,0,0,0,0,0,0,0,0,0,1,1,1
0,0,0,0,0,0,0,0,0,0,1,1,1
0,0,0,0,0,0,0,0,0,0,1,1,1
0,1,0,0,0,0,0,0,0,0,1,1,1
1,1,1,1,0,0,0,0,0,0,0,1,1
1,1,1,0,0,0,0,0,0,0,1,1,1
1,1,1,0,0,0,0,0,0,0,1,1,1
1,1,1,0,0,0,0,0,0,0,1,1,1
1,1,1,0,0,0,0,0,0,0,1,1,1
1,1,1,1,1,0,1,1,1,1,1,1,1
endlayer

layer
0,0,0,0,0,0,0,0,0,1,1,1,1
0,0,0,0,0,0,0,0,1,1,1,1,1
0,0,0,0,0,0,0,0,1,1,1,1,1
0,0,0,0,0,0,0,0,0,1,1,1,1
0,0,0,0,0,0,0,0,0,1,1,1,1
0,0,0,0,0,0,0,0,0,1,1,1,1
0,1,1,0,0,1,0,0,0,1,1,1,1
1,1,1,1,1,0,0,0,0,0,1,1,1
1,1,1,1,1,1,0,0,0,0,1,1,1
1,1,1,1,1,0,0,0,0,0,1,1,1
1,1,1,1,1,0,0,0,0,0,1,1,1
1,1,1,1,1,1,0,0,1,1,1,1,1
1,1,1,1,1,1,1,1,1,1,1,1,1
endlayer

layer
0,0,0,0,0,0,0,1,1,1,1,1,1
0,0,0,0,0,0,0,1,1,1,1,1,1
0,0,0,0,0,0,0,1,1,1,1,1,1
0,0,0,0,0,0,0,1,1,1,1,1,1
0,0,0,0,0,0,0,1,1,1,1,1,1
0,0,0,0,0,0,0,1,1,1,1,1,1
1,1,1,1,1,1,0,0,1,1,1,1,1
1,1,1,1,1,1,1,1,1,1,1,1,1
1,1,1,1,1,1,1,1,1,1,1,1,1
1,1,1,1,1,1,1,1,1,1,1,1,1
1,1,1,1,1,1,1,1,1,1,1,1,1
1,1,1,1,1,1,1,1,1,1,1,1,1
1,1,1,1,1,1,1,1,1,1,1,1,1
endlayer

layer
0,0,0,0,0,0,1,1,1,1,1,1,1
0,0,0,0,0,0,1,1,1,1,1,1,1
0,0,0,0,0,0,1,1,1,1,1,1,1
0,0,0,0,0,0,1,1,1,1,1,1,1
0,0,0,0,0,1,1,1,1,1,1,1,1
1,0,0,0,1,1,1,1,1,1,1,1,1
1,1,1,1,1,1,1,1,1,1,1,1,1
1,1,1,1,1,1,1,1,1,1,1,1,1
1,1,1,1,1,1,1,1,1,1,1,1,1
1,1,1,1,1,1,1,1,1,1,1,1,1
1,1,1,1,1,1,1,1,1,1,1,1,1
1,1,1,1,1,1,1,1,1,1,1,1,1
1,1,1,1,1,1,1,1,1,1,1,1,1
endlayer

layer
0,0,0,1,1,1,1,1,1,1,1,1,1
0,0,0,0,1,1,1,1,1,1,1,1,1
0,0,0,0,0,1,1,1,1,1,1,1,1
0,0,0,0,1,1,1,1,1,1,1,1,1
1,0,0,0,1,1,1,1,1,1,1,1,1
1,1,1,1,1,1,1,1,1,1,1,1,1
1,1,1,1,1,1,1,1,1,1,1,1,1
1,1,1,1,1,1,1,1,1,1,1,1,1
1,1,1,1,1,1,1,1,1,1,1,1,1
1,1,1,1,1,1,1,1,1,1,1,1,1
1,1,1,1,1,1,1,1,1,1,1,1,1
1,1,1,1,1,1,1,1,1,1,1,1,1
1,1,1,1,1,1,1,1,1,1,1,1,1
endlayer

layer
1,1,1,1,1,1,1,1,1,1,1,1,1
1,1,1,1,1,1,1,1,1,1,1,1,1
1,1,1,1,1,1,1,1,1,1,1,1,1
1,1,1,1,1,1,1,1,1,1,1,1,1
1,1,1,1,1,1,1,1,1,1,1,1,1
1,1,1,1,1,1,1,1,1,1,1,1,1
1,1,1,1,1,1,1,1,1,1,1,1,1
1,1,1,1,1,1,1,1,1,1,1,1,1
1,1,1,1,1,1,1,1,1,1,1,1,1
1,1,1,1,1,1,1,1,1,1,1,1,1
1,1,1,1,1,1,1,1,1,1,1,1,1
1,1,1,1,1,1,1,1,1,1,1,1,1
1,1,1,1,1,1,1,1,1,1,1,1,1
endlayer

