# Cave_LavaHollow (Adventure) -- underground lava-filled cave room
# 27 Sep 2014 -- Minecraft 1.7.10
# Created by Ruins mod version 13.8 Ingame Parser
# authoring Player: Jordan_Greywolf
# Last Updated: 27 Apr 2015
# Note: Put in \templateparser folder; meant to be called.
# Updated to MC 1.8: 5 Mar 2016
# Updated to MC 1.9: 19 Apr 2016
# Updated to MC 1.12: 22 Jun 2017

biomesToSpawnIn=extreme hills

weight=1
embed_into_distance=20

unacceptable_target_blocks=water_flowing,water,cloud,Natura:Cloud

dimensions=13,16,16
allowable_overhang=200
max_leveling=0
leveling_buffer=0
preserve_water=1
preserve_lava=1
preserve_plants=1

# Terrain preservation
rule1=0,100,preserveBlock

# Shell (originally stone, but set to obsidian for now)
rule2=0,100,minecraft:obsidian-0

# Lava Rim
rule3=0,100,minecraft:obsidian-0

# Lava
rule4=0,100,minecraft:flowing_lava

rule5=0,100,ChestGenHook:chests/simple_dungeon:5,ChestGenHook:chests/village_blacksmith:5

rule6=0,100,CommandBlock:RUINSTRIGGER /summon fireball ~0 ~1 ~0 {direction:[0.0,0.0,0.0],ExplosionPower:5,PersistenceRequired:1}:@

rule7=0,100,CommandBlock:RUINSTRIGGER /summon zombie ~0 ~1 ~0 {HandItems:[{},{}],ArmorItems:[{},{},{},{Count:1,id:skull,Damage:3,tag:{SkullOwner:MHF_Blaze,display:{Name:"Flaming Head"}}}],CustomName:"Fire Planar",ArmorDropChances:[0.0F,0.0F,0.0F,0.5F],ActiveEffects:[{Id:12,Amplifier:1,Duration:999999,Ambient:1},{Id:3,Amplifier:1,Duration:999999,Ambient:1},{Id:14,Amplifier:1,Duration:999999,Ambient:1},{Id:8,Amplifier:1,Duration:999999,Ambient:1}],Silent:1,PersistenceRequired:1,Passengers:[{id:Fireball,direction:[0.0,0.0,0.0],ExplosionPower:3,PersistenceRequired:1}]}:@

rule8=0,100,minecraft:glowstone-0

rule9=0,100,minecraft:iron_ore-0,minecraft:gold_ore-0,minecraft:diamond_ore-0,minecraft:emerald_ore-0

rule10=0,100,minecraft:iron_bars-0

layer
1,1,1,1,1,1,1,1,1,1,1,1,1,1,1,1
1,1,1,1,1,1,1,1,1,1,1,1,1,1,1,1
1,1,1,1,1,1,1,1,1,1,1,1,1,1,1,1
1,1,1,1,1,1,1,1,1,1,1,1,1,1,1,1
1,1,1,1,1,1,1,1,1,1,1,1,1,1,1,1
1,1,1,1,1,1,1,1,1,1,1,1,1,1,1,1
1,1,1,1,1,1,1,1,1,1,1,1,1,1,1,1
1,1,1,1,1,1,1,2,2,1,1,1,1,1,1,1
1,1,1,1,1,1,1,2,2,1,1,1,1,1,1,1
1,1,1,1,1,1,1,1,1,1,1,1,1,1,1,1
1,1,1,1,1,1,1,1,1,1,1,1,1,1,1,1
1,1,1,1,1,1,1,1,1,1,1,1,1,1,1,1
1,1,1,1,1,1,1,1,1,1,1,1,1,1,1,1
1,1,1,1,1,1,1,1,1,1,1,1,1,1,1,1
1,1,1,1,1,1,1,1,1,1,1,1,1,1,1,1
1,1,1,1,1,1,1,1,1,1,1,1,1,1,1,1
endlayer

layer
1,1,1,1,1,1,1,1,1,1,1,1,1,1,1,1
1,1,1,1,1,1,1,1,1,1,1,1,1,1,1,1
1,1,1,1,1,1,1,1,1,1,1,1,1,1,1,1
1,1,1,1,1,1,1,1,1,1,1,1,1,1,1,1
1,1,1,1,1,1,1,1,1,1,1,1,1,1,1,1
1,1,1,1,1,1,1,2,2,1,1,1,1,1,1,1
1,1,1,1,1,1,2,2,2,2,1,1,1,1,1,1
1,1,1,1,1,2,2,4,4,2,2,1,1,1,1,1
1,1,1,1,1,2,2,4,4,2,2,1,1,1,1,1
1,1,1,1,1,1,2,2,2,2,1,1,1,1,1,1
1,1,1,1,1,1,1,2,2,1,1,1,1,1,1,1
1,1,1,1,1,1,1,1,1,1,1,1,1,1,1,1
1,1,1,1,1,1,1,1,1,1,1,1,1,1,1,1
1,1,1,1,1,1,1,1,1,1,1,1,1,1,1,1
1,1,1,1,1,1,1,1,1,1,1,1,1,1,1,1
1,1,1,1,1,1,1,1,1,1,1,1,1,1,1,1
endlayer


layer
1,1,1,1,1,1,2,2,2,2,1,1,1,1,1,1
1,1,1,1,2,2,2,2,2,2,2,2,1,1,1,1
1,1,1,2,2,2,2,2,2,2,2,2,2,1,1,1
1,1,2,2,2,2,2,2,2,2,2,2,2,2,1,1
1,2,2,2,2,2,2,2,2,2,2,2,2,2,2,1
1,2,2,2,2,2,2,2,2,2,2,2,2,2,2,1
2,2,2,2,2,2,2,4,4,2,2,2,2,2,2,2
2,2,2,2,2,2,4,4,4,4,2,2,2,2,2,2
2,2,2,2,2,2,4,4,4,4,2,2,2,2,2,2
2,2,2,2,2,2,2,4,4,2,2,2,2,2,2,2
1,2,2,2,2,2,2,2,2,2,2,2,2,2,2,1
1,2,2,2,2,2,2,2,2,2,2,2,2,2,2,1
1,1,2,2,2,2,2,2,2,2,2,2,2,2,1,1
1,1,1,2,2,2,2,2,2,2,2,2,2,1,1,1
1,1,1,1,2,2,2,2,2,2,2,2,1,1,1,1
1,1,1,1,1,1,2,2,2,2,1,1,1,1,1,1
endlayer

layer
1,1,1,1,1,1,2,2,2,2,1,1,1,1,1,1
1,1,1,1,2,2,3,3,3,3,2,2,1,1,1,1
1,1,1,2,3,3,4,4,4,4,3,3,2,1,1,1
1,1,2,3,4,4,4,4,4,4,4,4,3,2,1,1
1,2,3,4,4,4,4,4,4,4,4,4,4,3,2,1
1,2,3,4,4,4,4,4,4,4,4,4,4,3,2,1
2,3,4,4,4,4,4,4,4,4,4,4,4,4,3,2
2,3,4,4,4,4,4,8,8,4,4,4,4,4,3,2
2,3,4,4,4,4,4,8,8,4,4,4,4,4,3,2
2,3,4,4,4,4,4,4,4,4,4,4,4,4,3,2
1,2,3,4,4,4,4,4,4,4,4,4,4,3,2,1
1,2,3,4,4,4,4,4,4,4,4,4,4,3,2,1
1,1,2,3,4,4,4,4,4,4,4,4,3,2,1,1
1,1,1,2,3,3,4,4,4,4,3,3,2,1,1,1
1,1,1,1,2,2,3,3,3,3,2,2,1,1,1,1
1,1,1,1,1,1,2,2,2,2,1,1,1,1,1,1
endlayer

layer
1,1,1,1,1,1,2,2,2,2,1,1,1,1,1,1
1,1,1,1,2,2,0,0,0,0,2,2,1,1,1,1
1,1,1,2,0,0,0,0,0,0,0,0,2,1,1,1
1,1,2,0,0,0,0,0,0,0,0,0,0,2,1,1
1,2,0,0,0,0,0,0,0,0,0,0,0,0,2,1
1,2,0,0,0,4,0,0,0,0,4,0,0,0,2,1
2,0,0,0,0,0,0,0,0,0,0,0,0,0,0,2
2,0,0,0,0,0,0,9,9,0,0,0,0,0,0,2
2,0,0,0,0,0,0,9,9,0,0,0,0,0,0,2
2,0,0,0,0,0,0,0,0,0,0,0,0,0,0,2
1,2,0,0,0,4,0,0,0,0,4,0,0,0,2,1
1,2,0,0,0,0,0,0,0,0,0,0,0,0,2,1
1,1,2,0,0,0,0,0,0,0,0,0,0,2,1,1
1,1,1,2,0,0,0,0,0,0,0,0,2,1,1,1
1,1,1,1,2,2,0,0,0,0,2,2,1,1,1,1
1,1,1,1,1,1,2,2,2,2,1,1,1,1,1,1
endlayer

layer
1,1,1,1,1,1,2,2,2,2,1,1,1,1,1,1
1,1,1,1,2,2,0,2,2,0,2,2,1,1,1,1
1,1,1,2,0,0,0,2,2,0,0,0,2,1,1,1
1,1,2,0,0,0,0,2,2,0,0,0,0,2,1,1
1,2,0,0,0,0,0,2,2,0,0,0,0,0,2,1
1,2,0,0,0,0,0,2,2,0,0,0,0,0,2,1
2,0,0,0,0,0,2,2,2,2,0,0,0,0,0,2
2,2,2,2,2,2,2,0,0,2,2,2,2,2,2,2
2,2,2,2,2,2,2,0,0,2,2,2,2,2,2,2
2,0,0,0,0,0,2,2,2,2,0,0,0,0,0,2
1,2,0,0,0,0,0,2,2,0,0,0,0,0,2,1
1,2,0,0,0,0,0,2,2,0,0,0,0,0,2,1
1,1,2,0,0,0,0,2,2,0,0,0,0,2,1,1
1,1,1,2,0,0,0,2,2,0,0,0,2,1,1,1
1,1,1,1,2,2,0,2,2,0,2,2,1,1,1,1
1,1,1,1,1,1,2,2,2,2,1,1,1,1,1,1
endlayer

layer
1,1,1,1,1,1,2,10,10,2,1,1,1,1,1,1
1,1,1,1,2,2,2,7,7,2,2,2,1,1,1,1
1,1,1,2,2,2,0,0,0,0,2,2,2,1,1,1
1,1,2,2,0,0,0,0,0,0,0,0,2,2,1,1
1,2,2,0,0,0,0,0,0,0,0,0,0,2,2,1
1,2,2,0,0,0,0,0,0,0,0,0,0,2,2,1
2,2,0,0,0,0,0,7,7,0,0,0,0,0,2,2
10,7,0,0,0,0,5,0,0,6,0,0,0,0,7,10
10,7,0,0,0,0,6,0,0,5,0,0,0,0,7,10
2,2,0,0,0,0,0,7,7,0,0,0,0,0,2,2
1,2,2,0,0,0,0,0,0,0,0,0,0,2,2,1
1,2,2,0,0,0,0,0,0,0,0,0,0,2,2,1
1,1,2,2,0,0,0,0,0,0,0,0,2,2,1,1
1,1,1,2,2,2,0,0,0,0,2,2,2,1,1,1
1,1,1,1,2,2,2,7,7,2,2,2,1,1,1,1
1,1,1,1,1,1,2,10,10,2,1,1,1,1,1,1
endlayer

layer
1,1,1,1,1,1,2,10,10,2,1,1,1,1,1,1
1,1,1,1,1,2,2,0,0,2,2,1,1,1,1,1
1,1,1,1,2,2,0,0,0,0,2,2,1,1,1,1
1,1,1,2,0,0,0,0,0,0,0,0,2,1,1,1
1,1,2,0,0,0,0,0,0,0,0,0,0,2,1,1
1,2,2,0,0,0,0,0,0,0,0,0,0,2,2,1
2,2,0,0,0,0,0,0,0,0,0,0,0,0,2,2
10,0,0,0,0,0,0,0,0,0,0,0,0,0,0,10
10,0,0,0,0,0,0,0,0,0,0,0,0,0,0,10
2,2,0,0,0,0,0,0,0,0,0,0,0,0,2,2
1,2,2,0,0,0,0,0,0,0,0,0,0,2,2,1
1,1,2,0,0,0,0,0,0,0,0,0,0,2,1,1
1,1,1,2,0,0,0,0,0,0,0,0,2,1,1,1
1,1,1,1,2,2,0,0,0,0,2,2,1,1,1,1
1,1,1,1,1,2,2,0,0,2,2,1,1,1,1,1
1,1,1,1,1,1,2,10,10,2,1,1,1,1,1,1
endlayer

layer
1,1,1,1,1,1,1,2,2,1,1,1,1,1,1,1
1,1,1,1,1,1,2,2,2,2,1,1,1,1,1,1
1,1,1,1,2,2,2,0,0,2,2,2,1,1,1,1
1,1,1,1,2,0,0,0,0,0,0,2,1,1,1,1
1,1,2,2,0,0,0,0,0,0,0,0,2,2,1,1
1,1,2,0,0,0,0,0,0,0,0,0,0,2,1,1
1,2,2,0,0,0,0,0,0,0,0,0,0,2,2,1
2,2,0,0,0,0,0,0,0,0,0,0,0,0,2,2
2,2,0,0,0,0,0,0,0,0,0,0,0,0,2,2
1,2,2,0,0,0,0,0,0,0,0,0,0,2,2,1
1,1,2,0,0,0,0,0,0,0,0,0,0,2,1,1
1,1,2,2,0,0,0,0,0,0,0,0,2,2,1,1
1,1,1,1,2,0,0,0,0,0,0,2,1,1,1,1
1,1,1,1,2,2,2,0,0,2,2,2,1,1,1,1
1,1,1,1,1,1,2,2,2,2,1,1,1,1,1,1
1,1,1,1,1,1,1,2,2,1,1,1,1,1,1,1
endlayer

layer
1,1,1,1,1,1,1,1,1,1,1,1,1,1,1,1
1,1,1,1,1,1,1,1,1,1,1,1,1,1,1,1
1,1,1,1,1,2,2,2,2,2,2,1,1,1,1,1
1,1,1,1,2,2,2,0,0,2,2,2,1,1,1,1
1,1,1,2,2,2,0,0,0,0,2,2,2,1,1,1
1,1,2,2,2,0,0,0,0,0,0,2,2,2,1,1
1,1,2,2,0,0,0,0,0,0,0,0,2,2,1,1
1,1,2,0,0,0,0,0,0,0,0,0,0,2,1,1
1,1,2,0,0,0,0,0,0,0,0,0,0,2,1,1
1,1,2,2,0,0,0,0,0,0,0,0,2,2,1,1
1,1,2,2,2,0,0,0,0,0,0,2,2,2,1,1
1,1,1,2,2,2,0,0,0,0,2,2,2,1,1,1
1,1,1,1,2,2,2,0,0,2,2,2,1,1,1,1
1,1,1,1,1,2,2,2,2,2,2,1,1,1,1,1
1,1,1,1,1,1,1,1,1,1,1,1,1,1,1,1
1,1,1,1,1,1,1,1,1,1,1,1,1,1,1,1
endlayer

layer
1,1,1,1,1,1,1,1,1,1,1,1,1,1,1,1
1,1,1,1,1,1,1,1,1,1,1,1,1,1,1,1
1,1,1,1,1,1,1,1,1,1,1,1,1,1,1,1
1,1,1,1,1,1,1,2,2,1,1,1,1,1,1,1
1,1,1,1,1,2,2,2,2,2,2,1,1,1,1,1
1,1,1,1,2,4,2,8,8,2,4,2,1,1,1,1
1,1,1,1,2,2,2,8,8,2,2,2,1,1,1,1
1,1,1,2,2,8,8,0,0,8,8,2,2,1,1,1
1,1,1,2,2,8,8,0,0,8,8,2,2,1,1,1
1,1,1,1,2,2,2,8,8,2,2,2,1,1,1,1
1,1,1,1,2,4,2,8,8,2,4,2,1,1,1,1
1,1,1,1,1,2,2,2,2,2,2,1,1,1,1,1
1,1,1,1,1,1,1,2,2,1,1,1,1,1,1,1
1,1,1,1,1,1,1,1,1,1,1,1,1,1,1,1
1,1,1,1,1,1,1,1,1,1,1,1,1,1,1,1
1,1,1,1,1,1,1,1,1,1,1,1,1,1,1,1
endlayer

layer
1,1,1,1,1,1,1,1,1,1,1,1,1,1,1,1
1,1,1,1,1,1,1,1,1,1,1,1,1,1,1,1
1,1,1,1,1,1,1,1,1,1,1,1,1,1,1,1
1,1,1,1,1,1,1,1,1,1,1,1,1,1,1,1
1,1,1,1,1,1,1,1,1,1,1,1,1,1,1,1
1,1,1,1,1,1,1,2,2,1,1,1,1,1,1,1
1,1,1,1,1,1,2,2,2,2,1,1,1,1,1,1
1,1,1,1,1,2,2,4,4,2,2,1,1,1,1,1
1,1,1,1,1,2,2,4,4,2,2,1,1,1,1,1
1,1,1,1,1,1,2,2,2,2,1,1,1,1,1,1
1,1,1,1,1,1,1,2,2,1,1,1,1,1,1,1
1,1,1,1,1,1,1,1,1,1,1,1,1,1,1,1
1,1,1,1,1,1,1,1,1,1,1,1,1,1,1,1
1,1,1,1,1,1,1,1,1,1,1,1,1,1,1,1
1,1,1,1,1,1,1,1,1,1,1,1,1,1,1,1
1,1,1,1,1,1,1,1,1,1,1,1,1,1,1,1
endlayer

layer
1,1,1,1,1,1,1,1,1,1,1,1,1,1,1,1
1,1,1,1,1,1,1,1,1,1,1,1,1,1,1,1
1,1,1,1,1,1,1,1,1,1,1,1,1,1,1,1
1,1,1,1,1,1,1,1,1,1,1,1,1,1,1,1
1,1,1,1,1,1,1,1,1,1,1,1,1,1,1,1
1,1,1,1,1,1,1,1,1,1,1,1,1,1,1,1
1,1,1,1,1,1,1,1,1,1,1,1,1,1,1,1
1,1,1,1,1,1,1,2,2,1,1,1,1,1,1,1
1,1,1,1,1,1,1,2,2,1,1,1,1,1,1,1
1,1,1,1,1,1,1,1,1,1,1,1,1,1,1,1
1,1,1,1,1,1,1,1,1,1,1,1,1,1,1,1
1,1,1,1,1,1,1,1,1,1,1,1,1,1,1,1
1,1,1,1,1,1,1,1,1,1,1,1,1,1,1,1
1,1,1,1,1,1,1,1,1,1,1,1,1,1,1,1
1,1,1,1,1,1,1,1,1,1,1,1,1,1,1,1
1,1,1,1,1,1,1,1,1,1,1,1,1,1,1,1
endlayer

