# CrystalCavern_1v7v10 - 9 Oct 2014
# Created by Ruins mod version 13.8 Ingame Parser
# authoring Player: Jordan_Greywolf
# Last Updated: 27 Apr 2015
# Note: Put in /templateparser folder.  Meant to be called.

weight=1
biomesToSpawnIn=extreme hills


embed_into_distance=20
acceptable_target_blocks=

unacceptable_target_blocks=flowing_water,water,flowing_lava,lava,cloud,Natura:Cloud

dimensions=12,15,15
allowable_overhang=400
max_leveling=0
leveling_buffer=-1
preserve_water=0
preserve_lava=0
preserve_plants=1

rule1=0,100,preserveBlock

rule2=0,100,minecraft:stone-0
rule3=0,100,minecraft:dirt-2
rule4=0,100,minecraft:glowstone-0
rule5=0,100,minecraft:water-0
rule6=0,100,minecraft:stained_glass-0
rule7=0,100,minecraft:tallgrass-2,minecraft:red_mushroom-0,minecraft:tallgrass-2
rule8=0,100,minecraft:double_plant-3
rule9=0,100,minecraft:water-1
rule10=0,100,minecraft:water-9
rule11=0,100,minecraft:water-10
rule12=0,100,minecraft:water-2
rule13=0,100,minecraft:red_mushroom-0,minecraft:brown_mushroom-0
rule14=0,100,minecraft:vine-2
rule15=0,100,minecraft:double_plant-8
rule16=0,100,minecraft:vine-4
rule17=0,100,minecraft:double_plant-9
rule18=0,100,minecraft:double_plant-11
rule19=0,100,minecraft:double_plant-10
rule20=0,100,minecraft:vine-1
rule21=0,100,minecraft:vine-8
rule22=0,100,minecraft:vine-0
rule23=0,100,minecraft:water-8

layer
1,1,1,1,1,1,1,1,1,1,1,1,1,1,1
1,1,1,1,1,1,1,1,1,1,1,1,1,1,1
1,1,1,1,1,1,1,1,1,1,1,1,1,1,1
1,1,1,1,1,1,1,1,2,1,1,1,1,1,1
1,1,1,1,1,1,1,2,2,2,1,2,1,1,1
1,1,1,1,1,1,1,2,2,2,2,2,1,1,1
1,1,1,1,1,2,2,2,2,2,2,2,2,1,1
1,1,1,1,1,2,2,2,2,2,2,2,2,1,1
1,1,1,1,1,2,2,2,2,2,2,2,1,1,1
1,1,1,1,1,1,2,2,2,2,1,2,1,1,1
1,1,1,1,1,1,1,1,2,1,1,1,1,1,1
1,1,1,1,1,1,1,1,1,1,1,1,1,1,1
1,1,1,1,1,1,1,1,1,1,1,1,1,1,1
1,1,1,1,1,1,1,1,1,1,1,1,1,1,1
1,1,1,1,1,1,1,1,1,1,1,1,1,1,1
endlayer

layer
1,1,1,1,1,1,1,1,1,1,1,1,1,1,1
1,1,1,1,1,1,1,1,1,1,1,1,1,1,1
1,1,1,1,1,1,1,3,3,2,1,1,1,1,1
1,1,1,1,1,1,2,3,3,2,1,1,1,1,1
1,1,1,1,2,2,2,5,5,4,3,3,1,1,1
1,1,1,2,6,6,2,5,5,5,5,3,3,2,1
1,1,1,2,2,5,5,5,5,5,5,5,5,2,1
1,1,1,2,2,5,5,5,5,5,5,5,5,2,1
1,1,1,1,2,5,5,5,5,5,5,5,3,1,1
1,1,1,1,1,2,2,5,5,5,3,4,2,1,1
1,1,1,1,1,2,2,2,5,3,3,3,1,1,1
1,1,1,1,1,1,2,2,2,2,2,1,1,1,1
1,1,1,1,1,1,1,2,2,2,1,1,1,1,1
1,1,1,1,1,1,1,1,1,1,1,1,1,1,1
1,1,1,1,1,1,1,1,1,1,1,1,1,1,1
endlayer

layer
1,1,1,1,1,1,1,1,1,1,1,1,1,1,1
1,1,1,1,1,1,1,2,2,2,1,1,1,1,1
1,1,1,1,2,2,3,7,7,6,2,1,1,1,1
1,1,1,1,2,2,3,7,7,3,3,2,1,1,1
1,1,1,2,6,3,3,0,0,0,7,7,2,1,1
1,1,2,9,10,9,3,0,0,0,0,8,0,2,1
1,3,3,10,4,10,0,0,0,0,0,0,0,6,2
1,1,3,11,6,11,0,0,0,0,0,0,0,2,1
1,1,1,2,10,10,9,0,0,0,0,0,7,2,1
1,1,1,1,2,2,10,9,0,0,7,0,2,1,1
1,1,1,1,2,10,9,9,12,7,8,7,2,1,1
1,1,1,1,1,2,6,10,9,13,6,2,2,1,1
1,1,1,1,1,1,2,6,10,2,2,1,1,1,1
1,1,1,1,1,1,1,2,2,2,1,1,1,1,1
1,1,1,1,1,1,1,1,1,1,1,1,1,1,1
endlayer

layer
1,1,1,1,1,1,1,2,2,2,1,1,1,1,1
1,1,1,1,2,2,3,6,0,6,2,1,1,1,1
1,1,1,2,6,3,7,0,0,0,6,2,1,1,1
1,1,1,2,3,3,7,0,0,7,8,2,2,1,1
1,1,2,3,0,7,7,0,0,0,0,14,6,2,1
1,2,6,0,10,0,8,0,0,0,0,15,0,6,2
2,7,7,10,6,10,0,0,0,0,0,0,6,6,6
1,2,7,11,6,11,0,0,0,0,0,0,0,6,2
1,1,3,6,10,9,0,0,0,0,0,0,16,2,1
1,1,1,2,6,10,9,0,0,0,0,0,13,2,1
1,1,1,1,2,9,0,0,0,0,17,0,6,2,1
1,1,1,1,1,3,0,9,0,0,0,13,2,1,1
1,1,1,1,1,2,6,10,9,6,2,2,1,1,1
1,1,1,1,1,1,2,4,2,2,1,1,1,1,1
1,1,1,1,1,1,1,2,1,1,1,1,1,1,1
endlayer

layer
1,1,1,1,1,1,2,2,6,1,1,1,1,1,1
1,1,1,1,2,2,6,0,6,2,1,1,1,1,1
1,1,1,2,0,14,0,0,0,0,2,1,1,1,1
1,1,2,6,0,8,0,0,0,0,18,2,1,1,1
1,2,6,7,0,0,0,0,0,0,0,6,2,1,1
1,2,20,0,9,0,19,0,0,0,0,0,16,2,1
1,2,20,9,11,9,0,0,0,0,0,16,0,6,2
1,2,20,11,6,11,0,0,0,0,0,0,16,2,1
1,2,7,0,10,0,0,0,0,0,0,16,2,1,1
1,1,2,6,10,9,0,0,0,0,0,0,2,1,1
1,1,1,2,6,0,0,0,0,0,21,16,2,1,1
1,1,1,1,2,7,0,0,0,0,2,2,1,1,1
1,1,1,1,2,6,0,9,21,0,2,1,1,1,1
1,1,1,1,1,2,6,5,2,2,1,1,1,1,1
1,1,1,1,1,1,6,5,1,1,1,1,1,1,1
endlayer

layer
1,1,1,1,1,1,1,1,1,1,1,1,1,1,1
1,1,1,1,2,2,2,2,2,1,1,1,1,1,1
1,1,1,2,6,14,0,14,6,2,1,1,1,1,1
1,1,2,20,0,18,0,0,0,16,2,1,1,1,1
1,2,0,0,0,0,0,0,0,0,6,2,1,1,1
2,6,0,0,0,0,0,0,0,14,0,6,2,1,1
2,20,0,0,11,0,0,0,0,0,0,16,2,2,1
6,6,20,12,9,11,0,0,0,0,0,16,2,1,1
1,2,6,0,9,0,0,0,0,0,0,6,2,1,1
1,2,0,0,10,0,0,0,0,0,0,16,2,1,1
1,1,2,0,0,0,0,0,0,0,6,2,1,1,1
1,1,1,2,6,21,0,0,21,21,2,1,1,1,1
1,1,1,1,2,2,6,21,2,2,1,1,1,1,1
1,1,1,1,1,1,2,2,1,1,1,1,1,1,1
1,1,1,1,1,1,1,2,1,1,1,1,1,1,1
endlayer

layer
1,1,1,1,1,1,1,1,1,1,1,1,1,1,1
1,1,1,1,1,1,2,1,1,1,1,1,1,1,1
1,1,1,1,2,2,6,2,2,1,1,1,1,1,1
1,1,1,2,2,2,2,14,2,2,1,1,1,1,1
1,2,2,2,6,0,6,0,6,2,2,1,1,1,1
2,0,0,0,0,0,0,0,0,14,6,2,1,1,1
2,20,0,0,11,0,0,0,0,0,16,2,1,1,1
1,2,20,0,6,11,6,0,0,0,6,2,1,1,1
1,2,6,6,6,0,0,0,0,0,16,2,1,1,1
1,1,2,6,10,0,6,0,0,0,16,2,1,1,1
1,1,1,2,20,21,0,0,0,6,2,2,1,1,1
1,1,1,1,2,2,21,21,6,2,2,1,1,1,1
1,1,1,1,1,1,2,2,2,2,1,1,1,1,1
1,1,1,1,1,1,1,1,1,1,1,1,1,1,1
1,1,1,1,1,1,1,1,1,1,1,1,1,1,1
endlayer

layer
1,1,1,1,1,1,1,1,1,1,1,1,1,1,1
1,1,1,1,1,1,1,1,1,1,1,1,1,1,1
1,1,1,1,1,1,2,1,1,1,1,1,1,1,1
1,1,1,1,1,1,1,2,2,1,1,1,1,1,1
1,1,1,1,2,2,2,6,6,2,1,1,1,1,1
1,2,2,2,2,6,14,0,6,2,2,1,1,1,1
2,6,2,2,12,6,0,0,16,2,2,1,1,1,1
1,2,2,6,9,12,6,6,22,16,2,1,1,1,1
1,1,2,0,10,6,0,0,0,6,2,1,1,1,1
1,1,1,2,9,0,6,0,6,2,2,1,1,1,1
1,1,1,1,2,2,0,6,2,2,2,1,1,1,1
1,1,1,1,1,1,2,2,2,2,1,1,1,1,1
1,1,1,1,1,1,1,1,1,1,1,1,1,1,1
1,1,1,1,1,1,1,1,1,1,1,1,1,1,1
1,1,1,1,1,1,1,1,1,1,1,1,1,1,1
endlayer

layer
1,1,1,1,1,1,1,1,1,1,1,1,1,1,1
1,1,1,1,1,1,1,1,1,1,1,1,1,1,1
1,1,1,1,1,1,1,1,1,1,1,1,1,1,1
1,1,1,1,1,1,1,1,1,1,1,1,1,1,1
1,1,1,1,1,1,1,2,2,1,1,1,1,1,1
1,1,1,1,1,2,2,2,2,1,1,1,1,1,1
1,2,1,1,0,2,6,14,2,1,1,1,1,1,1
1,1,1,2,0,6,2,2,4,2,1,1,1,1,1
1,1,1,2,9,23,2,2,6,2,1,1,1,1,1
1,1,1,1,2,2,2,2,2,2,1,1,1,1,1
1,1,1,1,1,1,2,2,2,2,1,1,1,1,1
1,1,1,1,1,1,1,1,2,1,1,1,1,1,1
1,1,1,1,1,1,1,1,1,1,1,1,1,1,1
1,1,1,1,1,1,1,1,1,1,1,1,1,1,1
1,1,1,1,1,1,1,1,1,1,1,1,1,1,1
endlayer

layer
1,1,1,1,1,1,1,1,1,1,1,1,1,1,1
1,1,1,1,1,1,1,1,1,1,1,1,1,1,1
1,1,1,1,1,1,1,1,1,1,1,1,1,1,1
1,1,1,1,1,1,1,1,1,1,1,1,1,1,1
1,1,1,1,1,1,1,1,1,1,1,1,1,1,1
1,1,1,1,1,1,1,1,1,1,1,1,1,1,1
1,1,1,1,1,1,2,2,1,1,1,1,1,1,1
1,1,1,1,2,2,12,12,2,1,1,1,1,1,1
1,1,1,1,0,23,9,9,2,1,1,1,1,1,1
1,1,1,1,2,5,5,5,5,2,1,1,1,1,1
1,1,1,1,1,2,5,5,5,2,1,1,1,1,1
1,1,1,1,1,1,2,2,2,1,1,1,1,1,1
1,1,1,1,1,1,1,1,1,1,1,1,1,1,1
1,1,1,1,1,1,1,1,1,1,1,1,1,1,1
1,1,1,1,1,1,1,1,1,1,1,1,1,1,1
endlayer

layer
1,1,1,1,1,1,1,1,1,1,1,1,1,1,1
1,1,1,1,1,1,1,1,1,1,1,1,1,1,1
1,1,1,1,1,1,1,1,1,1,1,1,1,1,1
1,1,1,1,1,1,1,1,1,1,1,1,1,1,1
1,1,1,1,1,1,1,1,1,1,1,1,1,1,1
1,1,1,1,1,1,1,1,1,1,1,1,1,1,1
1,1,1,1,1,1,2,2,1,1,1,1,1,1,1
1,1,1,1,1,2,2,2,2,1,1,1,1,1,1
1,1,1,1,2,23,2,2,2,2,1,1,1,1,1
1,1,1,2,2,5,5,5,5,2,2,1,1,1,1
1,1,1,1,2,2,5,5,5,2,1,1,1,1,1
1,1,1,1,2,2,5,5,2,2,1,1,1,1,1
1,1,1,1,1,2,2,2,2,1,1,1,1,1,1
1,1,1,1,1,1,2,2,1,1,1,1,1,1,1
1,1,1,1,1,1,1,1,1,1,1,1,1,1,1
endlayer

layer
1,1,1,1,1,1,1,1,1,1,1,1,1,1,1
1,1,1,1,1,1,1,1,1,1,1,1,1,1,1
1,1,1,1,1,1,1,1,1,1,1,1,1,1,1
1,1,1,1,1,1,1,1,1,1,1,1,1,1,1
1,1,1,1,1,1,1,1,1,1,1,1,1,1,1
1,1,1,1,1,1,1,1,1,1,1,1,1,1,1
1,1,1,1,1,1,2,2,1,1,1,1,1,1,1
1,1,1,1,1,2,5,5,2,1,1,1,1,1,1
1,1,1,1,2,5,5,5,5,2,2,1,1,1,1
1,1,1,2,5,5,5,5,5,5,2,1,1,1,1
1,1,1,1,2,5,5,5,5,5,2,1,1,1,1
1,1,1,1,2,5,5,5,5,2,1,1,1,1,1
1,1,1,1,1,2,5,5,2,1,1,1,1,1,1
1,1,1,1,1,1,2,2,1,1,1,1,1,1,1
1,1,1,1,1,1,1,1,1,1,1,1,1,1,1
endlayer

