# Dark Crystal Tower Pinnacle
# Created by Ruins mod version 15.1 Ingame Parser
# authoring Player: Jordan_Greywolf
# Note: Place in \templateparser folder
# Updated to MC 1.8: 25 Mar 2016
# Updated to MC 1.9: 22 Apr 2016
# Updated to MC 1.11: 12 Jan 2017
# Updated to MC 1.12: 22 Jun 2017


weight=0
embed_into_distance=0
acceptable_target_blocks=
unacceptable_target_blocks=flowing_water,water,flowing_lava,lava
dimensions=32,11,11
allowable_overhang=0
max_leveling=0
leveling_buffer=-1
preserve_water=0
preserve_lava=0

rule1=0,100,minecraft:obsidian-0
rule2=0,100,minecraft:stained_glass-15

rule3=0,100,CommandBlock:RUINSTRIGGER /weather thunder 300:@
rule4=0,100,minecraft:lever-5

# Monsters!
rule5=0,100,CommandBlock:RUINSTRIGGER /summon blaze ~0 ~1 ~0 {SpawnData:{CustomName:"Vengeful Spirit",ActiveEffects:[{Id:14,Amplifier:1,Duration:999999,Ambient:1},{Id:1,Amplifier:1,Duration:999999,Ambient:1},{Id:5,Amplifier:1,Duration:999999,Ambient:1}],PersistenceRequired:1}}:@

rule6=0,100,ChestGenHook:chests/simple_dungeon:5-2

rule7=0,100,minecraft:stained_glass-11

rule8=0,100,IInventory;minecraft:chest;minecraft:stained_glass#64#9#0+minecraft:stained_glass#64#10#1+minecraft:stained_glass#64#11#2+minecraft:stained_glass#64#15#3+minecraft:stained_glass#64#0#4+minecraft:stained_glass#64#1#5+minecraft:stained_glass#64#4#6+minecraft:stained_glass#64#14#7+minecraft:stained_glass#64#2#8-5

rule9=0,100,CommandBlock:RUINSTRIGGER /summon skeleton ~0 ~1 ~0 {HandItems:[{Count:1,id:diamond_sword,tag:{display:{Name:"Fire Blade",Lore:["A jagged shard of fiery crystal, bound and held as if a blade."]},ench:[{id:20,lvl:2},{id:21,lvl:2},{id:16,lvl:5}]}},{Count:1,id:shield}],ArmorItems:[{Count:1,id:leather_boots,tag:{display:{color:16711680}}},{Count:1,id:leather_leggings,tag:{display:{color:16711680}}},{Count:1,id:leather_chestplate,tag:{display:{color:16711680}}},{Count:1,id:redstone_block,tag:{ench:[{id:6,lvl:1},{id:0,lvl:4},{id:7,lvl:3}]}}],CustomName:"Furious Guardian",Attributes:[{Name:generic.movementSpeed,Base:0.5},{Name:generic.knockbackResistance,Base:1.0}],HandDropChances:[0.5F,0.0F],ActiveEffects:[{Id:12,Amplifier:1,Duration:999999},{Id:8,Amplifier:1,Duration:999999}],Silent:1,PersistenceRequired:1,Health:60.0f}:@

rule10=0,100,ChestGenHook:chests/pyramid_desert_chest:3-3
rule11=0,100,CommandBlock:/testruin TP_DarkCrystal_LavaSphere ~0 ~0 ~0:@
rule12=0,100,ChestGenHook:chests/simple_dungeon:3-4
rule13=0,100,minecraft:stained_glass-14
rule14=0,100,minecraft:packed_ice
rule15=0,100,preserveBlock

layer
15,15,15,1,2,2,2,1,15,15,15
15,15,2,0,0,0,0,0,2,15,15
15,2,0,0,0,0,0,0,0,2,15
1,0,0,0,0,0,0,0,0,0,1
2,0,0,0,0,0,0,0,0,0,2
2,0,0,0,0,3,0,0,0,0,2
2,0,0,0,0,0,0,0,0,0,2
1,0,0,0,0,0,0,0,0,0,1
15,2,0,0,0,0,0,0,0,2,15
15,15,2,0,2,2,0,0,2,15,15
15,15,15,1,2,2,2,1,15,15,15
endlayer

layer
0,0,0,1,2,2,2,1,0,0,0
0,0,2,0,0,0,0,0,2,0,0
0,2,0,0,0,0,0,0,0,2,0
1,0,0,0,0,0,0,0,0,0,1
2,0,0,0,0,0,0,0,0,0,2
2,0,0,0,0,0,0,0,0,0,2
2,0,0,0,0,0,0,0,0,0,2
1,0,0,0,0,0,0,0,0,0,1
0,2,0,0,0,0,0,0,0,2,0
0,0,2,0,0,2,2,0,2,0,0
0,0,0,1,2,2,2,1,0,0,0
endlayer

layer
0,0,0,1,2,2,2,1,0,0,0
0,0,2,0,0,0,0,0,2,0,0
0,2,0,0,0,0,0,0,0,2,0
1,0,0,0,0,0,0,0,0,0,1
2,0,0,0,0,0,0,0,0,0,2
2,0,0,0,0,0,0,0,0,0,2
2,0,0,0,0,0,0,0,0,0,2
1,0,0,0,0,0,0,0,0,0,1
0,2,0,0,0,0,0,0,0,2,0
0,0,2,0,0,0,2,2,2,0,0
0,0,0,1,2,2,2,1,0,0,0
endlayer

layer
0,0,0,1,2,2,2,1,0,0,0
0,0,2,0,0,0,0,0,2,0,0
0,2,0,0,0,0,0,0,0,2,0
1,0,0,0,0,0,0,0,0,0,1
2,0,0,0,0,0,0,0,0,0,2
2,0,0,0,0,0,0,0,0,0,2
2,0,0,0,0,0,0,0,0,0,2
1,0,0,0,0,0,0,0,0,0,1
0,2,0,0,0,0,0,2,0,2,0
0,0,2,0,0,0,0,2,2,0,0
0,0,0,1,2,2,2,1,0,0,0
endlayer

layer
0,0,0,1,2,2,2,1,0,0,0
0,0,2,0,0,0,0,0,2,0,0
0,2,0,0,0,0,0,0,0,2,0
1,0,0,0,0,0,0,0,0,0,1
2,0,0,0,0,0,0,0,0,0,2
2,0,0,0,0,0,0,0,0,0,2
2,0,0,0,0,0,0,0,0,0,2
1,0,0,0,0,0,0,0,0,0,1
0,2,0,0,0,0,0,2,2,2,0
0,0,2,0,0,0,0,0,2,0,0
0,0,0,1,2,2,2,1,0,0,0
endlayer

layer
0,0,0,1,1,1,1,1,0,0,0
0,0,1,2,2,2,2,2,1,0,0
0,1,2,2,2,2,2,2,2,1,0
1,2,2,2,2,2,2,2,2,2,1
1,2,2,2,2,2,2,2,2,2,1
1,2,2,2,2,2,2,2,2,2,1
1,2,2,2,2,2,2,2,2,2,1
1,2,2,2,2,2,2,2,2,2,1
0,1,2,2,2,2,2,0,0,1,0
0,0,1,2,2,2,0,0,1,0,0
0,0,0,1,1,1,1,1,0,0,0
endlayer

layer
0,0,0,1,2,2,2,1,0,0,0
0,0,2,0,0,5,0,0,2,0,0
0,2,0,0,0,0,0,0,0,2,0
1,0,0,0,0,0,0,0,0,0,1
2,0,0,0,0,0,0,0,0,0,2
2,5,0,0,0,6,0,0,0,2,2
2,0,0,0,0,0,0,0,0,2,2
1,0,0,0,0,0,0,0,0,0,1
0,2,0,0,0,0,0,0,0,2,0
0,0,2,0,0,5,0,0,2,0,0
0,0,0,1,2,2,2,1,0,0,0
endlayer

layer
0,0,0,1,2,2,2,1,0,0,0
0,0,2,0,0,0,0,0,2,0,0
0,2,0,0,0,0,0,0,0,2,0
1,0,0,0,0,0,0,0,0,0,1
2,0,0,0,0,0,0,0,0,2,2
2,0,0,0,0,0,0,0,0,2,2
2,0,0,0,0,0,0,0,0,0,2
1,0,0,0,0,0,0,0,0,0,1
0,2,0,0,0,0,0,0,0,2,0
0,0,2,0,0,0,0,0,2,0,0
0,0,0,1,2,2,2,1,0,0,0
endlayer

layer
0,0,0,1,2,2,2,1,0,0,0
0,0,2,0,0,0,0,0,2,0,0
0,2,0,0,0,0,0,0,0,2,0
1,0,0,0,0,0,0,0,0,2,1
2,0,0,0,0,0,0,0,0,2,2
2,0,0,0,0,0,0,0,0,0,2
2,0,0,0,0,0,0,0,0,0,2
1,0,0,0,0,0,0,0,0,0,1
0,2,0,0,0,0,0,0,0,2,0
0,0,2,0,0,0,0,0,2,0,0
0,0,0,1,2,2,2,1,0,0,0
endlayer

layer
0,0,0,1,2,2,2,1,0,0,0
0,0,2,0,0,0,0,0,2,0,0
0,2,0,0,0,0,0,0,0,2,0
1,0,0,0,0,0,0,0,2,2,1
2,0,0,0,0,0,0,0,0,0,2
2,0,0,0,0,0,0,0,0,0,2
2,0,0,0,0,0,0,0,0,0,2
1,0,0,0,0,0,0,0,0,0,1
0,2,0,0,0,0,0,0,0,2,0
0,0,2,0,0,0,0,0,2,0,0
0,0,0,1,2,2,2,1,0,0,0
endlayer

layer
0,0,0,1,2,2,2,1,0,0,0
0,0,2,0,0,0,0,0,2,0,0
0,2,0,0,0,0,0,2,2,2,0
1,0,0,0,0,0,0,0,2,0,1
2,0,0,0,0,0,0,0,0,0,2
2,0,0,0,0,0,0,0,0,0,2
2,0,0,0,0,0,0,0,0,0,2
1,0,0,0,0,0,0,0,0,0,1
0,2,0,0,0,0,0,0,0,2,0
0,0,2,0,0,0,0,0,2,0,0
0,0,0,1,2,2,2,1,0,0,0
endlayer

layer
0,0,0,1,2,2,2,1,0,0,0
0,0,2,0,0,0,2,2,2,0,0
0,2,0,0,0,0,0,2,0,2,0
1,0,0,0,0,0,0,0,0,0,1
2,0,0,0,0,0,0,0,0,0,2
2,0,0,0,0,0,0,0,0,0,2
2,0,0,0,0,0,0,0,0,0,2
1,0,0,0,0,0,0,0,0,0,1
0,2,0,0,0,0,0,0,0,2,0
0,0,2,0,0,0,0,0,2,0,0
0,0,0,1,2,2,2,1,0,0,0
endlayer

layer
0,0,0,1,1,1,1,1,0,0,0
0,0,1,2,2,2,2,0,1,0,0
0,1,2,2,2,2,2,0,0,1,0
1,2,2,2,2,7,2,2,0,0,1
1,2,2,2,2,2,2,2,2,0,1
1,2,2,7,2,7,2,7,2,2,1
1,2,2,2,2,2,2,2,2,2,1
1,2,2,2,2,7,2,2,2,2,1
0,1,2,2,2,2,2,2,2,1,0
0,0,1,2,2,2,2,2,1,0,0
0,0,0,1,1,1,1,1,0,0,0
endlayer

layer
0,0,0,2,2,2,2,2,0,0,0
0,0,2,0,0,8,0,0,2,0,0
0,2,9,0,0,0,0,0,0,2,0
2,0,0,0,0,0,0,0,0,0,2
2,0,0,0,0,0,0,0,0,0,2
2,6,0,0,4,11,0,0,0,10,2
2,0,0,0,0,0,0,0,0,0,2
2,0,0,0,0,0,0,0,0,0,2
0,2,9,0,0,0,0,0,9,2,0
0,0,2,0,0,12,0,0,2,0,0
0,0,0,2,2,2,2,2,0,0,0
endlayer

layer
0,0,0,2,2,2,2,2,0,0,0
0,0,2,0,0,0,0,0,2,0,0
0,2,0,0,0,0,0,0,0,2,0
2,0,0,0,0,0,0,0,0,0,2
2,0,0,0,0,0,0,0,0,0,2
2,0,0,0,0,0,0,0,0,0,2
2,0,0,0,0,0,0,0,0,0,2
2,0,0,0,0,0,0,0,0,0,2
0,2,0,0,0,0,0,0,0,2,0
0,0,2,0,0,0,0,0,2,0,0
0,0,0,2,2,2,2,2,0,0,0
endlayer

layer
0,0,0,2,0,0,0,2,0,0,0
0,0,2,0,0,0,0,0,2,0,0
0,2,0,0,0,0,0,0,0,2,0
2,0,0,0,0,0,0,0,0,0,2
0,0,0,0,13,13,13,0,0,0,0
0,0,0,0,13,13,13,0,0,0,0
0,0,0,0,13,13,13,0,0,0,0
2,0,0,0,0,0,0,0,0,0,2
0,2,0,0,0,0,0,0,0,2,0
0,0,2,0,0,0,0,0,2,0,0
0,0,0,2,0,0,0,2,0,0,0
endlayer

layer
0,0,0,2,2,0,2,2,0,0,0
0,0,2,2,0,0,0,2,2,0,0
0,2,2,0,0,0,0,0,2,2,0
2,2,0,0,13,13,13,0,0,2,2
2,0,0,13,13,14,13,13,0,0,2
0,0,0,13,14,14,14,13,0,0,0
2,0,0,13,13,14,13,13,0,0,2
2,2,0,0,13,13,13,0,0,2,2
0,2,2,0,0,0,0,0,2,2,0
0,0,2,2,0,0,0,2,2,0,0
0,0,0,2,2,0,2,2,0,0,0
endlayer

layer
0,0,0,0,2,0,2,0,0,0,0
0,0,0,2,0,0,0,2,0,0,0
0,0,2,0,0,0,0,0,2,0,0
0,2,0,0,13,13,13,0,0,2,0
2,0,0,13,14,14,14,13,0,0,2
0,0,0,13,14,14,14,13,0,0,0
2,0,0,13,14,14,14,13,0,0,2
0,2,0,0,13,13,13,0,0,2,0
0,0,2,0,0,0,0,0,2,0,0
0,0,0,2,0,0,0,2,0,0,0
0,0,0,0,2,0,2,0,0,0,0
endlayer

layer
0,0,0,0,2,2,2,0,0,0,0
0,0,0,2,2,2,2,2,0,0,0
0,0,2,2,0,0,0,2,2,0,0
0,2,2,13,13,13,13,0,2,2,0
2,2,0,13,13,14,13,13,0,2,2
2,2,0,13,14,14,14,13,0,2,2
2,2,0,13,13,14,13,13,0,2,2
0,2,2,0,13,13,13,0,2,2,0
0,0,2,2,0,0,0,2,2,0,0
0,0,0,2,2,2,2,2,0,0,0
0,0,0,0,2,2,2,0,0,0,0
endlayer

layer
0,0,0,0,0,2,0,0,0,0,0
0,0,0,0,2,2,2,0,0,0,0
0,0,0,2,0,0,0,2,0,0,0
0,0,2,0,0,0,0,0,2,0,0
0,2,0,0,13,13,13,0,0,2,0
2,2,0,0,13,13,13,0,0,2,2
0,2,0,0,13,13,13,0,0,2,0
0,0,2,0,0,0,0,0,2,0,0
0,0,0,2,0,0,0,2,0,0,0
0,0,0,0,2,2,2,0,0,0,0
0,0,0,0,0,2,0,0,0,0,0
endlayer

layer
0,0,0,0,0,2,0,0,0,0,0
0,0,0,0,2,2,2,0,0,0,0
0,0,0,2,2,0,2,2,0,0,0
0,0,2,2,0,0,0,2,2,0,0
0,2,2,0,0,0,0,0,2,2,0
2,2,0,0,0,0,0,0,0,2,2
0,2,2,0,0,0,0,0,2,2,0
0,0,2,2,0,0,0,2,2,0,0
0,0,0,2,2,0,2,2,0,0,0
0,0,0,0,2,2,2,0,0,0,0
0,0,0,0,0,2,0,0,0,0,0
endlayer

layer
0,0,0,0,0,0,0,0,0,0,0
0,0,0,0,0,2,0,0,0,0,0
0,0,0,0,2,2,2,0,0,0,0
0,0,0,2,2,0,2,2,0,0,0
0,0,2,2,0,0,0,2,2,0,0
0,2,2,0,0,0,0,0,2,2,0
0,0,2,2,0,0,0,2,2,0,0
0,0,0,2,2,0,2,2,0,0,0
0,0,0,0,2,2,2,0,0,0,0
0,0,0,0,0,2,0,0,0,0,0
0,0,0,0,0,0,0,0,0,0,0
endlayer

layer
0,0,0,0,0,0,0,0,0,0,0
0,0,0,0,0,0,0,0,0,0,0
0,0,0,0,0,2,0,0,0,0,0
0,0,0,0,2,0,2,0,0,0,0
0,0,0,2,0,0,0,2,0,0,0
0,0,2,0,0,0,0,0,2,0,0
0,0,0,2,0,0,0,2,0,0,0
0,0,0,0,2,0,2,0,0,0,0
0,0,0,0,0,2,0,0,0,0,0
0,0,0,0,0,0,0,0,0,0,0
0,0,0,0,0,0,0,0,0,0,0
endlayer

layer
0,0,0,0,0,0,0,0,0,0,0
0,0,0,0,0,0,0,0,0,0,0
0,0,0,0,0,2,0,0,0,0,0
0,0,0,0,2,2,2,0,0,0,0
0,0,0,2,0,0,0,2,0,0,0
0,0,2,2,0,0,0,2,2,0,0
0,0,0,2,0,0,0,2,0,0,0
0,0,0,0,2,2,2,0,0,0,0
0,0,0,0,0,2,0,0,0,0,0
0,0,0,0,0,0,0,0,0,0,0
0,0,0,0,0,0,0,0,0,0,0
endlayer

layer
0,0,0,0,0,0,0,0,0,0,0
0,0,0,0,0,0,0,0,0,0,0
0,0,0,0,0,0,0,0,0,0,0
0,0,0,0,0,2,0,0,0,0,0
0,0,0,0,2,0,2,0,0,0,0
0,0,0,2,0,0,0,2,0,0,0
0,0,0,0,2,0,2,0,0,0,0
0,0,0,0,0,2,0,0,0,0,0
0,0,0,0,0,0,0,0,0,0,0
0,0,0,0,0,0,0,0,0,0,0
0,0,0,0,0,0,0,0,0,0,0
endlayer

layer
0,0,0,0,0,0,0,0,0,0,0
0,0,0,0,0,0,0,0,0,0,0
0,0,0,0,0,0,0,0,0,0,0
0,0,0,0,0,2,0,0,0,0,0
0,0,0,0,2,2,2,0,0,0,0
0,0,0,2,2,0,2,2,0,0,0
0,0,0,0,2,2,2,0,0,0,0
0,0,0,0,0,2,0,0,0,0,0
0,0,0,0,0,0,0,0,0,0,0
0,0,0,0,0,0,0,0,0,0,0
0,0,0,0,0,0,0,0,0,0,0
endlayer

layer
0,0,0,0,0,0,0,0,0,0,0
0,0,0,0,0,0,0,0,0,0,0
0,0,0,0,0,0,0,0,0,0,0
0,0,0,0,0,0,0,0,0,0,0
0,0,0,0,0,2,0,0,0,0,0
0,0,0,0,2,0,2,0,0,0,0
0,0,0,0,0,2,0,0,0,0,0
0,0,0,0,0,0,0,0,0,0,0
0,0,0,0,0,0,0,0,0,0,0
0,0,0,0,0,0,0,0,0,0,0
0,0,0,0,0,0,0,0,0,0,0
endlayer

layer
0,0,0,0,0,0,0,0,0,0,0
0,0,0,0,0,0,0,0,0,0,0
0,0,0,0,0,0,0,0,0,0,0
0,0,0,0,0,0,0,0,0,0,0
0,0,0,0,0,2,0,0,0,0,0
0,0,0,0,2,2,2,0,0,0,0
0,0,0,0,0,2,0,0,0,0,0
0,0,0,0,0,0,0,0,0,0,0
0,0,0,0,0,0,0,0,0,0,0
0,0,0,0,0,0,0,0,0,0,0
0,0,0,0,0,0,0,0,0,0,0
endlayer

layer
0,0,0,0,0,0,0,0,0,0,0
0,0,0,0,0,0,0,0,0,0,0
0,0,0,0,0,0,0,0,0,0,0
0,0,0,0,0,0,0,0,0,0,0
0,0,0,0,0,0,0,0,0,0,0
0,0,0,0,0,2,0,0,0,0,0
0,0,0,0,0,0,0,0,0,0,0
0,0,0,0,0,0,0,0,0,0,0
0,0,0,0,0,0,0,0,0,0,0
0,0,0,0,0,0,0,0,0,0,0
0,0,0,0,0,0,0,0,0,0,0
endlayer

layer
0,0,0,0,0,0,0,0,0,0,0
0,0,0,0,0,0,0,0,0,0,0
0,0,0,0,0,0,0,0,0,0,0
0,0,0,0,0,0,0,0,0,0,0
0,0,0,0,0,0,0,0,0,0,0
0,0,0,0,0,2,0,0,0,0,0
0,0,0,0,0,0,0,0,0,0,0
0,0,0,0,0,0,0,0,0,0,0
0,0,0,0,0,0,0,0,0,0,0
0,0,0,0,0,0,0,0,0,0,0
0,0,0,0,0,0,0,0,0,0,0
endlayer

layer
0,0,0,0,0,0,0,0,0,0,0
0,0,0,0,0,0,0,0,0,0,0
0,0,0,0,0,0,0,0,0,0,0
0,0,0,0,0,0,0,0,0,0,0
0,0,0,0,0,0,0,0,0,0,0
0,0,0,0,0,2,0,0,0,0,0
0,0,0,0,0,0,0,0,0,0,0
0,0,0,0,0,0,0,0,0,0,0
0,0,0,0,0,0,0,0,0,0,0
0,0,0,0,0,0,0,0,0,0,0
0,0,0,0,0,0,0,0,0,0,0
endlayer

layer
0,0,0,0,0,0,0,0,0,0,0
0,0,0,0,0,0,0,0,0,0,0
0,0,0,0,0,0,0,0,0,0,0
0,0,0,0,0,0,0,0,0,0,0
0,0,0,0,0,0,0,0,0,0,0
0,0,0,0,0,2,0,0,0,0,0
0,0,0,0,0,0,0,0,0,0,0
0,0,0,0,0,0,0,0,0,0,0
0,0,0,0,0,0,0,0,0,0,0
0,0,0,0,0,0,0,0,0,0,0
0,0,0,0,0,0,0,0,0,0,0
endlayer

