# Dark Crystal Tower - Conjured Base
# Created by Ruins mod version 15.1 Ingame Parser
# authoring Player: Jordan_Greywolf
# Note: Place in /templateparser folder.
# Last Updated 2 Nov 2015
# Updated to MC 1.11: 12 Jan 2017


weight=0
embed_into_distance=5
acceptable_target_blocks=
unacceptable_target_blocks=flowing_water,water,flowing_lava,lava
dimensions=14,5,5
allowable_overhang=0
max_leveling=0
leveling_buffer=0
preserve_water=0
preserve_lava=0

rule1=0,100,preserveBlock
rule2=0,100,minecraft:stained_glass-15
rule3=0,100,CommandBlock:/tp @p[r=3] ~0 ~70 ~0:@
rule4=2,100,minecraft:wooden_button-3


layer
1,1,1,1,1
1,1,1,1,1
1,1,2,1,1
1,1,1,1,1
1,1,1,1,1
endlayer


layer
1,1,1,1,1
1,1,1,1,1
1,1,2,1,1
1,1,1,1,1
1,1,1,1,1
endlayer


layer
1,1,1,1,1
1,1,2,1,1
1,2,2,2,1
1,1,2,1,1
1,1,1,1,1
endlayer


layer
1,1,2,1,1
1,2,2,2,1
2,2,0,2,2
1,2,2,2,1
1,1,2,1,1
endlayer


layer
1,2,2,2,1
2,2,2,2,2
2,2,2,2,2
2,2,2,2,2
1,2,2,2,1
endlayer

layer
1,2,2,2,1
2,0,0,0,2
0,4,3,0,2
2,0,0,0,2
1,2,2,2,1
endlayer

layer
1,2,2,2,1
2,0,0,0,2
0,0,0,0,2
2,0,0,0,2
1,2,2,2,1
endlayer

layer
1,2,2,2,1
2,0,0,0,2
2,0,0,0,2
2,0,0,0,2
1,2,2,2,1
endlayer

layer
1,1,2,1,1
1,2,0,2,1
2,0,0,0,2
1,2,0,2,1
1,1,2,1,1
endlayer

layer
1,1,2,1,1
1,2,2,2,1
2,2,0,2,2
1,2,2,2,1
1,1,2,1,1
endlayer

layer
1,1,1,1,1
1,1,2,1,1
1,2,0,2,1
1,1,2,1,1
1,1,1,1,1
endlayer

layer
1,1,1,1,1
1,1,2,1,1
1,2,2,2,1
1,1,2,1,1
1,1,1,1,1
endlayer

layer
1,1,1,1,1
1,1,1,1,1
1,1,2,1,1
1,1,1,1,1
1,1,1,1,1
endlayer

layer
1,1,1,1,1
1,1,1,1,1
1,1,2,1,1
1,1,1,1,1
1,1,1,1,1
endlayer

