# Dungeon Mineshaft -- 4 Apr 2016
# Created by Ruins mod version 15.5 Ingame Parser
# authoring Player: Jordan_Greywolf
# Note: Place in /templateparser folder.
# Intended purpose: Spawn in larger structure via /testruin to have extended
# lower layer & mine shafts.

# Updated to MC 1.9: 30 Apr 2016
# Updated to MC 1.12: 22 Jun 2017

weight=1
embed_into_distance=53
acceptable_target_blocks=
unacceptable_target_blocks=flowing_water,water,flowing_lava,lava
dimensions=52,5,5
allowable_overhang=0
max_leveling=0
leveling_buffer=-1
preserve_water=0
preserve_lava=0

rule1=0,100,minecraft:mossy_cobblestone-0
rule2=0,100,minecraft:double_stone_slab-0
rule3=0,100,minecraft:iron_bars-0
rule4=0,100,CommandBlock:RUINSTRIGGER /testruin TP_Mine_Tunnel ~-32 ~-1 ~0 1:@
rule5=0,100,CommandBlock:RUINSTRIGGER /testruin TP_Mine_Tunnel ~0 ~-1 ~-32:@
rule6=0,100,minecraft:stone_slab-0
rule7=0,100,CommandBlock:RUINSTRIGGER /testruin TP_Mine_Tunnel ~0 ~-1 ~32:@
rule8=0,100,minecraft:stonebrick-3
rule9=0,100,CommandBlock:RUINSTRIGGER /testruin TP_Mine_Tunnel ~32 ~-1 ~0 1:@
rule10=0,100,minecraft:ladder-4
rule11=0,100,minecraft:stone_slab-8
rule12=0,100,CommandBlock:RUINSTRIGGER /testruin TP_Mine_Tunnel ~-11 ~-3 ~0 1:@
rule13=0,100,CommandBlock:RUINSTRIGGER /testruin TP_Mine_Tunnel ~0 ~-3 ~-11:@
rule14=0,100,CommandBlock:RUINSTRIGGER /testruin TP_Mine_Tunnel ~0 ~-3 ~11:@
rule15=0,100,CommandBlock:RUINSTRIGGER /testruin TP_Mine_Tunnel ~11 ~-3 ~0 1:@
rule16=0,100,minecraft:stonebrick-1,minecraft:stonebrick-1,minecraft:stonebrick,minecraft:stonebrick-2
rule17=0,100,CommandBlock:RUINSTRIGGER /testruin TP_Mine_Tunnel ~-11 ~-1 ~0 1:@
rule18=0,100,CommandBlock:RUINSTRIGGER /testruin TP_Mine_Tunnel ~0 ~-1 ~-11:@
rule19=0,100,CommandBlock:RUINSTRIGGER /testruin TP_Mine_Tunnel ~0 ~-1 ~11:@
rule20=0,100,CommandBlock:RUINSTRIGGER /testruin TP_Mine_Tunnel ~11 ~-1 ~0 1:@
rule21=0,100,CommandBlock:RUINSTRIGGER /testruin TP_Mine_Tunnel ~-32 ~-2 ~0 1:@
rule22=0,100,CommandBlock:RUINSTRIGGER /testruin TP_Mine_Tunnel ~0 ~-2 ~-32:@
rule23=0,100,CommandBlock:RUINSTRIGGER /testruin TP_Mine_Tunnel ~0 ~-2 ~32:@
rule24=0,100,CommandBlock:RUINSTRIGGER /testruin TP_Mine_Tunnel ~32 ~-2 ~0 1:@
rule25=0,100,CommandBlock:RUINSTRIGGER /testruin TP_Mine_Tunnel ~-53 ~-3 ~0 1:@
rule26=0,100,CommandBlock:RUINSTRIGGER /testruin TP_Mine_Tunnel ~0 ~-3 ~-53:@
rule27=0,100,CommandBlock:RUINSTRIGGER /testruin TP_Mine_Tunnel ~0 ~-3 ~53:@
rule28=0,100,CommandBlock:RUINSTRIGGER /testruin TP_Mine_Tunnel ~53 ~-3 ~0 1:@

rule29=0,100,CommandBlock:RUINSTRIGGER /summon Skeleton ~0 ~1 ~0 {HandItems:[{Count:1,id:bow,tag:{display:{Name:"Recurve Bow"},ench:[{id:48,lvl:3},{id:49,lvl:2}]}},{Count:8,id:tipped_arrow,tag:{Potion:"minecraft:strong_harming"}}],ArmorItems:[{Count:1,id:leather_boots,tag:{display:{color:2880}}},{Count:1,id:leather_leggings,tag:{display:{color:5188119}}},{Count:1,id:leather_chestplate,tag:{display:{color:4013373}}},{Count:1,id:skull,Damage:3,tag:{SkullOwner:MHF_Villager}}],CustomName:Bandit,HandDropChances:[0.3F,2.0F],ArmorDropChances:[0.1F,0.1F,0.1F,0.1F],Silent:1,PersistenceRequired:1}:@

rule30=0,100,ChestGenHook:chests/simple_dungeon:5-5
rule31=0,100,minecraft:trapdoor-1

layer
1,1,1,1,1
1,1,1,1,1
1,1,1,1,1
1,1,1,1,1
1,1,1,1,1
endlayer

layer
2,3,4,3,2
3,0,0,0,3
7,0,6,0,5
3,0,8,0,3
2,3,9,3,2
endlayer

layer
2,3,3,3,2
3,0,0,0,3
3,0,10,0,3
3,0,8,0,3
2,3,3,3,2
endlayer

layer
2,11,12,11,2
11,0,0,0,11
14,0,10,0,13
11,0,8,0,11
2,11,15,11,2
endlayer

layer
2,2,2,2,2
2,11,11,11,2
2,11,10,11,2
2,11,8,11,2
2,2,2,2,2
endlayer

layer
16,16,16,16,16
16,16,16,16,16
16,16,10,16,16
16,16,16,16,16
16,16,16,16,16
endlayer

layer
16,16,16,16,16
16,16,16,16,16
16,16,10,16,16
16,16,16,16,16
16,16,16,16,16
endlayer


layer
0,0,0,0,0
0,16,3,16,0
0,3,10,3,0
0,16,16,16,0
0,0,0,0,0
endlayer

layer
0,0,0,0,0
0,16,3,16,0
0,3,10,3,0
0,16,16,16,0
0,0,0,0,0
endlayer


layer
0,0,0,0,0
0,16,3,16,0
0,3,10,3,0
0,16,16,16,0
0,0,0,0,0
endlayer

layer
16,16,16,16,16
16,16,16,16,16
16,16,10,16,16
16,16,16,16,16
16,16,16,16,16
endlayer

layer
16,16,16,16,16
16,16,16,16,16
16,16,10,16,16
16,16,16,16,16
16,16,16,16,16
endlayer


layer
0,0,0,0,0
0,16,3,16,0
0,3,10,3,0
0,16,16,16,0
0,0,0,0,0
endlayer

layer
0,0,0,0,0
0,16,3,16,0
0,3,10,3,0
0,16,16,16,0
0,0,0,0,0
endlayer


layer
0,0,0,0,0
0,16,3,16,0
0,3,10,3,0
0,16,16,16,0
0,0,0,0,0
endlayer

layer
16,16,16,16,16
16,16,16,16,16
16,16,10,16,16
16,16,16,16,16
16,16,16,16,16
endlayer

layer
16,16,16,16,16
16,16,16,16,16
16,16,10,16,16
16,16,16,16,16
16,16,16,16,16
endlayer



layer
0,0,0,0,0
0,16,3,16,0
0,3,10,3,0
0,16,16,16,0
0,0,0,0,0
endlayer

layer
0,0,0,0,0
0,16,3,16,0
0,3,10,3,0
0,16,16,16,0
0,0,0,0,0
endlayer


layer
0,0,0,0,0
0,16,3,16,0
0,3,10,3,0
0,16,16,16,0
0,0,0,0,0
endlayer

layer
16,16,16,16,16
16,16,16,16,16
16,16,10,16,16
16,16,16,16,16
16,16,16,16,16
endlayer

layer
16,16,16,16,16
16,16,16,16,16
16,16,10,16,16
16,16,16,16,16
16,16,16,16,16
endlayer



layer
0,0,0,0,0
0,16,3,16,0
0,3,10,3,0
0,16,16,16,0
0,0,0,0,0
endlayer

layer
0,0,0,0,0
0,16,3,16,0
0,3,10,3,0
0,16,16,16,0
0,0,0,0,0
endlayer


layer
0,0,0,0,0
0,16,3,16,0
0,3,10,3,0
0,16,16,16,0
0,0,0,0,0
endlayer

layer
16,16,16,16,16
16,16,16,16,16
16,16,10,16,16
16,16,16,16,16
16,16,16,16,16
endlayer


layer
16,16,16,16,16
16,16,16,16,16
16,16,10,16,16
16,16,16,16,16
16,16,16,16,16
endlayer



layer
0,0,17,0,0
0,16,3,16,0
19,3,10,3,18
0,16,16,16,0
0,0,20,0,0
endlayer

layer
0,0,21,0,0
0,16,3,16,0
23,3,10,3,22
0,16,16,16,0
0,0,24,0,0
endlayer

layer
0,0,25,0,0
0,16,3,16,0
27,3,10,3,26
0,16,16,16,0
0,0,28,0,0
endlayer

layer
1,1,1,1,1
1,16,16,16,1
1,16,10,16,1
1,16,16,16,1
1,1,1,1,1
endlayer

layer
1,1,1,1,1
1,16,16,16,1
1,16,10,16,1
1,16,16,16,1
1,1,1,1,1
endlayer


layer
0,0,17,0,0
0,16,3,16,0
19,3,10,3,18
0,16,16,16,0
0,0,20,0,0
endlayer

layer
0,0,21,0,0
0,16,3,16,0
23,3,10,3,22
0,16,16,16,0
0,0,24,0,0
endlayer

layer
0,0,25,0,0
0,16,3,16,0
27,3,10,3,26
0,16,16,16,0
0,0,28,0,0
endlayer

layer
1,1,1,1,1
1,16,16,16,1
1,16,10,16,1
1,16,16,16,1
1,1,1,1,1
endlayer

layer
1,1,1,1,1
1,16,16,16,1
1,16,10,16,1
1,16,16,16,1
1,1,1,1,1
endlayer


layer
0,0,0,0,0
0,16,3,16,0
0,3,10,3,0
0,16,16,16,0
0,29,30,29,0
endlayer

layer
0,0,0,0,0
0,16,3,16,0
0,3,10,3,0
0,16,16,16,0
0,0,0,0,0
endlayer

layer
0,0,0,0,0
0,16,3,16,0
0,3,10,3,0
0,16,16,16,0
0,0,0,0,0
endlayer

layer
16,16,16,16,16
16,16,16,16,16
16,16,10,16,16
16,16,16,16,16
16,16,16,16,16
endlayer

layer
16,16,16,16,16
16,16,16,16,16
16,16,10,16,16
16,16,16,16,16
16,16,16,16,16
endlayer


layer
0,0,0,0,0
0,16,3,16,0
0,3,10,3,0
0,16,16,16,0
0,0,0,0,0
endlayer

layer
0,0,0,0,0
0,16,3,16,0
0,3,10,3,0
0,16,16,16,0
0,0,0,0,0
endlayer


layer
0,0,0,0,0
0,16,3,16,0
0,3,10,3,0
0,16,16,16,0
0,0,0,0,0
endlayer


layer
16,16,16,16,16
16,16,16,16,16
16,16,10,16,16
16,16,16,16,16
16,16,16,16,16
endlayer

layer
16,16,16,16,16
16,16,16,16,16
16,16,10,16,16
16,16,16,16,16
16,16,16,16,16
endlayer


layer
0,0,0,0,0
0,16,3,16,0
0,3,10,3,0
0,16,16,16,0
0,0,0,0,0
endlayer

layer
0,0,0,0,0
0,16,3,16,0
0,3,10,3,0
0,16,16,16,0
0,0,0,0,0
endlayer


layer
0,0,0,0,0
0,16,3,16,0
0,3,10,3,0
0,16,16,16,0
0,0,0,0,0
endlayer


layer
16,16,16,16,16
16,16,16,16,16
16,16,10,16,16
16,16,16,16,16
16,16,16,16,16
endlayer

layer
16,16,16,16,16
16,16,16,16,16
16,16,10,16,16
16,16,16,16,16
16,16,16,16,16
endlayer


layer
1,1,1,1,1
1,2,2,2,1
1,2,10,2,1
1,2,2,2,1
1,1,1,1,1
endlayer

layer
0,0,0,0,0
0,0,0,0,0
0,0,31,6,0
0,0,0,0,0
0,0,0,0,0
endlayer

