# Generic Dungeon Room - 4-Way
# Created by Ruins mod version 15.1 Ingame Parser
# authoring Player: Jordan_Greywolf
# 26 Jan 2016 -- MC 1.7.10
# Note: Place in \templateparser folder.
# Updated to MC 1.9: 24 Apr 2016

weight=1
embed_into_distance=1
acceptable_target_blocks=

unacceptable_target_blocks=flowing_water,water,flowing_lava,lava

dimensions=10,16,16
allowable_overhang=0
max_leveling=0
leveling_buffer=-1
preserve_water=0
preserve_lava=0
preserve_plants=1

rule1=0,100,minecraft:stonebrick-1,minecraft:stonebrick,minecraft:stonebrick-2
rule2=0,100,minecraft:stonebrick-3
rule3=0,100,minecraft:mossy_cobblestone-0,minecraft:cobblestone
rule4=0,100,minecraft:double_stone_slab-0
rule5=0,100,minecraft:stone_brick_stairs-3
rule6=0,100,minecraft:stone_brick_stairs-2
rule7=0,100,minecraft:wooden_door-0
rule8=0,100,minecraft:stone_brick_stairs-1
rule9=0,100,minecraft:cobblestone_wall-1,minecraft:cobblestone_wall-0
rule10=0,100,minecraft:stone_brick_stairs-0
rule11=0,100,minecraft:wooden_door-1
rule12=0,100,ChestGenHook:chests/simple_dungeon:3-2
rule13=0,100,MobSpawner:Skeleton,MobSpawner:Spider,MobSpawner:Zombie
rule14=0,100,minecraft:wooden_door-3
rule15=0,100,ChestGenHook:chests/simple_dungeon:3-3
rule16=0,100,minecraft:wooden_door-2
rule17=0,100,minecraft:wooden_door-8
rule18=0,100,minecraft:wooden_door-9
rule19=1,100,minecraft:redstone_torch-5
rule20=0,100,minecraft:stone_brick_stairs-5
rule21=0,100,minecraft:stone_brick_stairs-7
rule22=0,100,minecraft:stone_brick_stairs-6

rule23=0,100,CommandBlock:RUINSTRIGGER /testruin TP_GenFeature_Garden ~1 ~-1 ~0:@,CommandBlock:RUINSTRIGGER /testruin TP_GenFeature_WaterShrine ~1 ~-1 ~0:@,CommandBlock:RUINSTRIGGER /testruin TP_GenFeature_LavaShrine ~1 ~-1 ~0:@,CommandBlock:RUINSTRIGGER /testruin TP_VaultStatues_Adventure ~1 ~18 ~0:@,CommandBlock:RUINSTRIGGER /summon bat ~0 ~0 ~0 {PersistenceRequired:1,ActiveEffects:[{Id:14,Amplifier:0,Duration:999999,Ambient:1}],Passengers:[{id:fireball,EntityId:fireball,direction:[0.0,0.0,0.0],ExplosionPower:5,PersistenceRequired:1}]}:@,CommandBlock:RUINSTRIGGER /testruin TP_Cave_LavaHollow_Adventure ~1 ~13 ~0:@,CommandBlock:RUINSTRIGGER /testruin TP_Cave_WaterHollow_Adventure ~1 ~13 ~0:@,CommandBlock:RUINSTRIGGER /testruin TP_ForestPool ~1 ~-1 ~0:@

rule24=0,100,minecraft:stone_brick_stairs-4
rule25=0,100,minecraft:stone_slab-5
rule26=0,100,minecraft:stone_slab-8
rule27=0,100,preserveBlock

layer
1,1,1,1,1,1,1,2,2,1,1,1,1,1,1,1
1,3,3,3,3,3,3,2,2,3,3,3,3,3,3,1
1,3,4,3,3,3,4,3,3,4,3,3,3,4,3,1
1,3,3,3,3,3,3,3,3,3,3,3,3,3,3,1
1,3,3,3,3,3,3,3,3,3,3,3,3,3,3,1
1,3,3,3,3,3,3,3,3,3,3,3,3,3,3,1
1,3,4,3,3,3,4,2,2,4,3,3,3,4,3,1
2,2,3,3,3,3,2,1,1,2,3,3,3,3,2,2
2,2,3,3,3,3,2,1,1,2,3,3,3,3,2,2
1,3,4,3,3,3,4,2,2,4,3,3,3,4,3,1
1,3,3,3,3,3,3,3,3,3,3,3,3,3,3,1
1,3,3,3,3,3,3,3,3,3,3,3,3,3,3,1
1,3,3,3,3,3,3,3,3,3,3,3,3,3,3,1
1,3,4,3,3,3,4,3,3,4,3,3,3,4,3,1
1,3,3,3,3,3,3,2,2,3,3,3,3,3,3,1
1,1,1,1,1,1,1,2,2,1,1,1,1,1,1,1
endlayer

layer
1,1,1,1,1,1,1,0,0,1,1,1,1,1,1,1
1,1,6,0,0,5,1,7,7,1,6,0,0,5,1,1
1,8,9,0,0,0,9,0,0,9,0,0,0,9,8,1
1,0,0,0,0,0,0,0,0,0,0,0,0,0,0,1
1,0,0,0,0,0,0,0,0,0,0,0,0,0,0,1
1,10,0,0,0,0,0,0,0,0,0,0,0,0,10,1
1,1,9,0,0,0,9,0,0,9,0,0,0,9,1,1
0,14,0,0,0,0,0,13,12,0,0,0,0,0,11,0
0,14,0,0,0,0,0,15,13,0,0,0,0,0,11,0
1,1,9,0,0,0,9,0,0,9,0,0,0,9,1,1
1,8,0,0,0,0,0,0,0,0,0,0,0,0,8,1
1,0,0,0,0,0,0,0,0,0,0,0,0,0,0,1
1,0,0,0,0,0,0,0,0,0,0,0,0,0,0,1
1,10,9,0,0,0,9,0,0,9,0,0,0,9,10,1
1,1,6,0,0,5,1,16,16,1,6,0,0,5,1,1
1,1,1,1,1,1,1,0,0,1,1,1,1,1,1,1
endlayer

layer
1,1,1,1,1,1,1,0,0,1,1,1,1,1,1,1
1,1,0,0,0,0,1,18,17,1,0,0,0,0,1,1
1,0,19,0,0,0,20,0,0,20,0,0,0,19,0,1
1,0,0,0,0,0,0,0,0,0,0,0,0,0,0,1
1,0,0,0,0,0,0,0,0,0,0,0,0,0,0,1
1,0,0,0,0,0,0,0,0,0,0,0,0,0,0,1
1,1,22,0,0,0,19,0,0,19,0,0,0,21,1,1
0,17,0,0,0,0,0,23,0,0,0,0,0,0,18,0
0,18,0,0,0,0,0,0,0,0,0,0,0,0,17,0
1,1,22,0,0,0,19,0,0,19,0,0,0,21,1,1
1,0,0,0,0,0,0,0,0,0,0,0,0,0,0,1
1,0,0,0,0,0,0,0,0,0,0,0,0,0,0,1
1,0,0,0,0,0,0,0,0,0,0,0,0,0,0,1
1,0,19,0,0,0,24,0,0,24,0,0,0,19,0,1
1,1,0,0,0,0,1,17,18,1,0,0,0,0,1,1
1,1,1,1,1,1,1,0,0,1,1,1,1,1,1,1
endlayer

layer
1,1,1,1,1,1,1,25,25,1,1,1,1,1,1,1
1,1,0,0,0,0,1,25,25,1,0,0,0,0,1,1
1,0,0,0,0,0,9,0,0,9,0,0,0,0,0,1
1,0,0,0,0,0,0,0,0,0,0,0,0,0,0,1
1,0,0,0,0,0,0,0,0,0,0,0,0,0,0,1
1,0,0,0,0,0,0,0,0,0,0,0,0,0,0,1
1,1,9,0,0,0,0,0,0,0,0,0,0,9,1,1
25,25,0,0,0,0,0,0,0,0,0,0,0,0,25,25
25,25,0,0,0,0,0,0,0,0,0,0,0,0,25,25
1,1,9,0,0,0,0,0,0,0,0,0,0,9,1,1
1,0,0,0,0,0,0,0,0,0,0,0,0,0,0,1
1,0,0,0,0,0,0,0,0,0,0,0,0,0,0,1
1,0,0,0,0,0,0,0,0,0,0,0,0,0,0,1
1,0,0,0,0,0,9,0,0,9,0,0,0,0,0,1
1,1,0,0,0,0,1,25,25,1,0,0,0,0,1,1
1,1,1,1,1,1,1,25,25,1,1,1,1,1,1,1
endlayer

layer
1,1,1,1,1,1,1,22,21,1,1,1,1,1,1,1
1,1,22,0,0,21,1,22,21,1,22,0,0,21,1,1
1,20,0,0,0,0,19,0,0,19,0,0,0,0,20,1
1,0,0,0,0,0,0,0,0,0,0,0,0,0,0,1
1,0,0,0,0,0,0,0,0,0,0,0,0,0,0,1
1,24,0,0,0,0,0,0,0,0,0,0,0,0,24,1
1,1,19,0,0,0,0,0,0,0,0,0,0,19,1,1
20,20,0,0,0,0,0,0,0,0,0,0,0,0,20,20
24,24,0,0,0,0,0,0,0,0,0,0,0,0,24,24
1,1,19,0,0,0,0,0,0,0,0,0,0,19,1,1
1,20,0,0,0,0,0,0,0,0,0,0,0,0,20,1
1,0,0,0,0,0,0,0,0,0,0,0,0,0,0,1
1,0,0,0,0,0,0,0,0,0,0,0,0,0,0,1
1,24,0,0,0,0,19,0,0,19,0,0,0,0,24,1
1,1,22,0,0,21,1,22,21,1,22,0,0,21,1,1
1,1,1,1,1,1,1,22,21,1,1,1,1,1,1,1
endlayer

layer
1,1,1,1,1,1,1,1,1,1,1,1,1,1,1,1
1,1,1,20,20,1,1,1,1,1,1,20,20,1,1,1
1,1,0,0,0,0,0,0,0,0,0,0,0,0,1,1
1,22,0,0,0,0,0,0,0,0,0,0,0,0,21,1
1,22,0,0,0,0,0,0,0,0,0,0,0,0,21,1
1,1,0,0,0,0,0,0,0,0,0,0,0,0,1,1
1,1,0,0,0,0,0,0,0,0,0,0,0,0,1,1
1,1,0,0,0,0,0,0,0,0,0,0,0,0,1,1
1,1,0,0,0,0,0,0,0,0,0,0,0,0,1,1
1,1,0,0,0,0,0,0,0,0,0,0,0,0,1,1
1,1,0,0,0,0,0,0,0,0,0,0,0,0,1,1
1,22,0,0,0,0,0,0,0,0,0,0,0,0,21,1
1,22,0,0,0,0,0,0,0,0,0,0,0,0,21,1
1,1,0,0,0,0,0,0,0,0,0,0,0,0,1,1
1,1,1,24,24,1,1,1,1,1,1,24,24,1,1,1
1,1,1,1,1,1,1,1,1,1,1,1,1,1,1,1
endlayer

layer
4,4,4,4,4,4,4,4,4,4,4,4,4,4,4,4
4,4,4,4,4,4,4,4,4,4,4,4,4,4,4,4
4,4,26,26,26,26,26,26,26,26,26,26,26,26,4,4
4,4,26,0,0,0,0,0,0,0,0,0,0,26,4,4
4,4,26,0,0,0,0,0,0,0,0,0,0,26,4,4
4,4,26,0,0,0,0,0,0,0,0,0,0,26,4,4
4,4,26,0,0,0,0,0,0,0,0,0,0,26,4,4
4,4,26,0,0,0,0,0,0,0,0,0,0,26,4,4
4,4,26,0,0,0,0,0,0,0,0,0,0,26,4,4
4,4,26,0,0,0,0,0,0,0,0,0,0,26,4,4
4,4,26,0,0,0,0,0,0,0,0,0,0,26,4,4
4,4,26,0,0,0,0,0,0,0,0,0,0,26,4,4
4,4,26,0,0,0,0,0,0,0,0,0,0,26,4,4
4,4,26,26,26,26,26,26,26,26,26,26,26,26,4,4
4,4,4,4,4,4,4,4,4,4,4,4,4,4,4,4
4,4,4,4,4,4,4,4,4,4,4,4,4,4,4,4
endlayer

layer
27,27,27,27,27,27,27,27,27,27,27,27,27,27,27,27
27,27,27,27,27,27,27,27,27,27,27,27,27,27,27,27
27,27,4,4,4,4,4,4,4,4,4,4,4,4,27,27
27,27,4,4,4,4,4,4,4,4,4,4,4,4,27,27
27,27,4,4,26,26,26,26,26,26,26,26,4,4,27,27
27,27,4,4,26,0,0,0,0,0,0,26,4,4,27,27
27,27,4,4,26,0,0,0,0,0,0,26,4,4,27,27
27,27,4,4,26,0,0,0,0,0,0,26,4,4,27,27
27,27,4,4,26,0,0,0,0,0,0,26,4,4,27,27
27,27,4,4,26,0,0,0,0,0,0,26,4,4,27,27
27,27,4,4,26,0,0,0,0,0,0,26,4,4,27,27
27,27,4,4,26,26,26,26,26,26,26,26,4,4,27,27
27,27,4,4,4,4,4,4,4,4,4,4,4,4,27,27
27,27,4,4,4,4,4,4,4,4,4,4,4,4,27,27
27,27,27,27,27,27,27,27,27,27,27,27,27,27,27,27
27,27,27,27,27,27,27,27,27,27,27,27,27,27,27,27
endlayer

layer
27,27,27,27,27,27,27,27,27,27,27,27,27,27,27,27
27,27,27,27,27,27,27,27,27,27,27,27,27,27,27,27
27,27,27,27,27,27,27,27,27,27,27,27,27,27,27,27
27,27,27,27,27,27,27,27,27,27,27,27,27,27,27,27
27,27,27,27,4,4,4,4,4,4,4,4,27,27,27,27
27,27,27,27,4,4,4,4,4,4,4,4,27,27,27,27
27,27,27,27,4,4,26,26,26,26,4,4,27,27,27,27
27,27,27,27,4,4,26,0,0,26,4,4,27,27,27,27
27,27,27,27,4,4,26,0,0,26,4,4,27,27,27,27
27,27,27,27,4,4,26,26,26,26,4,4,27,27,27,27
27,27,27,27,4,4,4,4,4,4,4,4,27,27,27,27
27,27,27,27,4,4,4,4,4,4,4,4,27,27,27,27
27,27,27,27,27,27,27,27,27,27,27,27,27,27,27,27
27,27,27,27,27,27,27,27,27,27,27,27,27,27,27,27
27,27,27,27,27,27,27,27,27,27,27,27,27,27,27,27
27,27,27,27,27,27,27,27,27,27,27,27,27,27,27,27
endlayer

layer
27,27,27,27,27,27,27,27,27,27,27,27,27,27,27,27
27,27,27,27,27,27,27,27,27,27,27,27,27,27,27,27
27,27,27,27,27,27,27,27,27,27,27,27,27,27,27,27
27,27,27,27,27,27,27,27,27,27,27,27,27,27,27,27
27,27,27,27,27,27,27,27,27,27,27,27,27,27,27,27
27,27,27,27,27,27,27,27,27,27,27,27,27,27,27,27
27,27,27,27,27,27,4,4,4,4,27,27,27,27,27,27
27,27,27,27,27,27,4,4,4,4,27,27,27,27,27,27
27,27,27,27,27,27,4,4,4,4,27,27,27,27,27,27
27,27,27,27,27,27,4,4,4,4,27,27,27,27,27,27
27,27,27,27,27,27,27,27,27,27,27,27,27,27,27,27
27,27,27,27,27,27,27,27,27,27,27,27,27,27,27,27
27,27,27,27,27,27,27,27,27,27,27,27,27,27,27,27
27,27,27,27,27,27,27,27,27,27,27,27,27,27,27,27
27,27,27,27,27,27,27,27,27,27,27,27,27,27,27,27
27,27,27,27,27,27,27,27,27,27,27,27,27,27,27,27
endlayer

