# GargoyleStone -- 5 May 2014
# Updated to MC 1.7.10, 13 Oct 2014
# Created by Ruins mod version 12.3 Ingame Parser
# authoring Player: Jordan_Greywolf
# Last Updated: 27 Apr 2015
# \templateparser version (no leveling)

biomesToSpawnIn=extreme hills,extreme hills edge,extreme hills m,extreme hills+,extreme hills+ m,hell,twilight forest,twilight clearing,roofed forest,ominous woods,mystic grove,magical forest,crag

weight=1
embed_into_distance=1
acceptable_target_blocks=

unacceptable_target_blocks=water,flowing_water,cloud,Natura:Cloud,slime_dirt,slime_grass,slime_congealed,command_block

dimensions=13,8,9
allowable_overhang=0
max_cut_in=0
cut_in_buffer=0
max_leveling=0
leveling_buffer=1
preserve_water=0
preserve_lava=0
preserve_plants=1

rule1=0,100,minecraft:stonebrick,minecraft:stonebrick-1,minecraft:stonebrick-2

rule2=0,100,preserveBlock

layer
2,2,2,2,2,2,2,2,2
2,2,2,2,1,2,2,2,2
2,2,1,1,1,1,1,2,2
2,2,1,1,1,1,1,2,2
2,2,2,2,2,2,2,2,2
2,2,2,2,2,2,2,2,2
2,2,1,2,2,2,1,2,2
2,2,1,2,2,2,1,2,2
endlayer

layer
2,2,2,2,1,2,2,2,2
2,2,2,2,2,2,2,2,2
2,2,1,1,1,1,1,2,2
2,2,2,1,1,1,2,2,2
2,2,2,2,2,2,2,2,2
2,2,1,2,2,2,1,2,2
2,2,1,2,2,2,1,2,2
2,2,2,2,2,2,2,2,2
endlayer

layer
2,2,2,2,1,2,2,2,2
2,2,2,2,2,2,2,2,2
2,2,1,1,1,1,1,2,2
2,2,1,1,1,1,1,2,2
2,2,2,1,1,2,2,2,2
2,2,1,2,2,2,1,2,2
2,2,2,2,2,2,2,2,2
2,2,2,2,2,2,2,2,2
endlayer

layer
2,2,2,2,1,2,2,2,2
2,2,2,2,2,2,2,2,2
2,2,2,2,1,2,2,2,2
2,2,2,1,1,1,2,2,2
2,2,2,1,1,1,2,2,2
2,2,1,1,1,1,1,2,2
2,2,2,2,2,2,2,2,2
2,2,2,2,2,2,2,2,2
endlayer

layer
2,2,2,2,1,2,2,2,2
2,2,2,2,2,2,2,2,2
2,2,2,2,1,2,2,2,2
2,2,2,2,1,2,2,2,2
2,2,2,1,1,1,2,2,2
2,2,2,1,1,1,2,2,2
2,2,2,2,2,2,2,2,2
2,2,2,2,2,2,2,2,2
endlayer

layer
2,2,1,2,1,2,1,2,2
2,2,2,2,2,2,2,2,2
2,2,2,2,1,2,2,2,2
2,2,2,1,1,1,2,2,2
2,2,2,1,1,1,2,2,2
2,2,2,2,1,2,2,2,2
2,2,2,2,2,2,2,2,2
2,2,2,2,2,2,2,2,2
endlayer

layer
1,2,1,2,2,2,1,2,1
2,2,1,2,2,2,1,2,2
2,2,2,2,2,2,2,2,2
2,2,1,1,1,1,1,2,2
2,2,2,2,1,2,2,2,2
2,2,2,2,1,2,2,2,2
2,2,2,1,1,1,2,2,2
2,2,2,2,1,2,2,2,2
endlayer

layer
1,1,1,2,2,2,1,1,1
2,2,1,2,2,2,1,2,2
2,2,1,2,2,2,1,2,2
2,2,1,2,2,2,1,2,2
2,2,2,2,1,2,2,2,2
2,2,2,1,1,1,2,2,2
2,2,2,1,1,1,2,2,2
2,2,2,2,2,2,2,2,2
endlayer

layer
1,1,1,2,2,2,1,1,1
2,2,1,2,2,2,1,2,2
2,2,1,2,2,2,1,2,2
2,2,2,2,2,2,2,2,2
2,2,2,2,2,2,2,2,2
2,2,2,1,2,1,2,2,2
2,2,2,2,2,2,2,2,2
2,2,2,2,2,2,2,2,2
endlayer

layer
1,1,1,2,2,2,1,1,1
2,2,1,2,2,2,1,2,2
2,2,2,2,2,2,2,2,2
2,2,2,2,2,2,2,2,2
2,2,2,2,2,2,2,2,2
2,2,2,2,2,2,2,2,2
2,2,2,2,2,2,2,2,2
2,2,2,2,2,2,2,2,2
endlayer

layer
2,1,1,2,2,2,1,1,2
2,2,1,2,2,2,1,2,2
2,2,2,2,2,2,2,2,2
2,2,2,2,2,2,2,2,2
2,2,2,2,2,2,2,2,2
2,2,2,2,2,2,2,2,2
2,2,2,2,2,2,2,2,2
2,2,2,2,2,2,2,2,2
endlayer

layer
2,2,2,2,2,2,2,2,2
2,1,1,2,2,2,1,1,2
2,2,2,2,2,2,2,2,2
2,2,2,2,2,2,2,2,2
2,2,2,2,2,2,2,2,2
2,2,2,2,2,2,2,2,2
2,2,2,2,2,2,2,2,2
2,2,2,2,2,2,2,2,2
endlayer

layer
2,2,2,2,2,2,2,2,2
2,2,2,2,2,2,2,2,2
2,2,1,2,2,2,1,2,2
2,2,2,2,2,2,2,2,2
2,2,2,2,2,2,2,2,2
2,2,2,2,2,2,2,2,2
2,2,2,2,2,2,2,2,2
2,2,2,2,2,2,2,2,2
endlayer


