
# Jungle_Ziggurat_Buried (Scenery Version)
# 15 Mar 2014; updated to MC 1.7.10, 10 Oct 2014
# Created by Ruins mod version 12.3 Ingame Parser
# authoring Player: Jordan_Greywolf

# Note: Place in \templateparser folder.
# Updated to MC 1.9: 24 Apr 2016
# Updated to MC 1.11: 12 Jan 2017

biomesToSpawnIn=bayou,bog,dead swamp,fen,fire swamp,green swampland,jungle,junglehills,lush river,lush swamp,marsh,ominous woods,quagmire,sludgepit,swamp,swampland,swampland m,tropics,tropical rainforest,wetland,wetlands


weight=1
embed_into_distance=8

dimensions=20,22,22
allowable_overhang=0
max_cut_in=0
cut_in_buffer=0
max_leveling=0

leveling_buffer=0
preserve_water=0
preserve_lava=0
preserve_plants=1

rule1=0,100,minecraft:stonebrick-1,minecraft:stonebrick-0,minecraft:stonebrick-2
rule2=0,100,minecraft:water-11
rule3=0,100,minecraft:stonebrick-3
rule4=0,100,preserveBlock
rule5=0,100,minecraft:flowing_water
rule6=0,100,minecraft:cobblestone_wall
rule7=0,100,minecraft:stonebrick
rule8=0,100,minecraft:cobblestone_wall
rule9=0,100,ChestGenHook:chests/spawn_bonus_chest:5-4,ChestGenHook:chests/jungle_temple:2-4
rule10=0,100,minecraft:stonebrick-1
rule11=0,100,minecraft:water-13
rule12=0,100,minecraft:water-1
rule13=0,100,minecraft:stonebrick-3
rule14=0,100,minecraft:cobblestone_wall
rule15=0,100,minecraft:water-2
rule16=0,100,minecraft:cobblestone_wall
rule17=0,100,minecraft:stonebrick-3
rule18=0,100,minecraft:stonebrick
rule19=0,100,ChestGenHook:chests/spawn_bonus_chest:5-2,ChestGenHook:chests/jungle_temple:2-2
rule20=0,100,minecraft:water-3
rule21=0,100,ChestGenHook:chests/spawn_bonus_chest:5-3,ChestGenHook:chests/jungle_temple:2-3
rule22=0,100,minecraft:cobblestone_wall
rule23=0,100,minecraft:cobblestone_wall
rule24=0,100,ChestGenHook:chests/spawn_bonus_chest:5-5,ChestGenHook:chests/jungle_temple:2-5
rule25=0,100,minecraft:stonebrick-3
rule26=0,100,minecraft:stonebrick-3
rule27=0,100,minecraft:cobblestone_wall-1
rule28=0,100,minecraft:stone_brick_stairs-4
rule29=0,100,minecraft:stone_brick_stairs-6
rule30=0,100,minecraft:stone_brick_stairs-7
rule31=0,100,minecraft:stone_brick_stairs-5
rule32=1,100,minecraft:torch-5
rule33=2,100,WallSign:null:null:null:null-3
rule34=2,100,WallSign:null:null:null:null-2
rule35=2,100,WallSign:null:null:null:null-5
rule36=2,100,WallSign:null:null:null:null-4
rule37=0,100,minecraft:stone_brick_stairs-0
rule38=0,100,minecraft:stone_brick_stairs-1
rule39=0,100,minecraft:stone_brick_stairs-2
rule40=0,100,minecraft:stone_brick_stairs-3
rule41=0,100,minecraft:water-0
rule42=0,100,minecraft:water-4
rule43=0,100,minecraft:water-5
rule44=0,100,minecraft:stone_slab-13

layer
1,1,1,1,1,1,1,1,1,1,1,1,1,1,1,1,1,1,1,1,1,1
1,1,1,1,1,1,1,1,1,1,1,1,1,1,1,1,1,1,1,1,1,1
1,1,1,1,1,1,1,1,1,1,1,1,1,1,1,1,1,1,1,1,1,1
1,1,1,1,1,1,1,1,1,1,1,1,1,1,1,1,1,1,1,1,1,1
1,1,1,1,1,1,1,1,1,1,1,1,1,1,1,1,1,1,1,1,1,1
1,1,1,1,1,1,1,1,1,1,1,1,1,1,1,1,1,1,1,1,1,1
1,1,1,1,1,1,1,1,1,1,1,1,1,1,1,1,1,1,1,1,1,1
1,1,1,1,1,1,1,1,1,1,1,1,1,1,1,1,1,1,1,1,1,1
1,1,1,1,1,1,1,1,1,1,1,1,1,1,1,1,1,1,1,1,1,1
1,1,1,1,1,1,1,1,1,1,7,7,1,1,1,1,1,1,1,1,1,1
1,1,1,1,1,1,1,1,1,18,2,2,18,1,1,1,1,1,1,1,1,1
1,1,1,1,1,1,1,1,1,18,2,2,18,1,1,1,1,1,1,1,1,1
1,1,1,1,1,1,1,1,1,1,7,7,1,1,1,1,1,1,1,1,1,1
1,1,1,1,1,1,1,1,1,1,1,1,1,1,1,1,1,1,1,1,1,1
1,1,1,1,1,1,1,1,1,1,1,1,1,1,1,1,1,1,1,1,1,1
1,1,1,1,1,1,1,1,1,1,1,1,1,1,1,1,1,1,1,1,1,1
1,1,1,1,1,1,1,1,1,1,1,1,1,1,1,1,1,1,1,1,1,1
1,1,1,1,1,1,1,1,1,1,1,1,1,1,1,1,1,1,1,1,1,1
1,1,1,1,1,1,1,1,1,1,1,1,1,1,1,1,1,1,1,1,1,1
1,1,1,1,1,1,1,1,1,1,1,1,1,1,1,1,1,1,1,1,1,1
1,1,1,1,1,1,1,1,1,1,1,1,1,1,1,1,1,1,1,1,1,1
1,1,1,1,1,1,1,1,1,1,1,1,1,1,1,1,1,1,1,1,1,1
endlayer

layer
1,1,1,1,1,1,1,1,1,3,1,1,3,1,1,1,1,1,1,1,1,1
1,0,0,0,0,0,0,0,0,0,0,0,0,0,0,0,0,0,0,0,0,1
1,0,0,0,0,0,0,0,0,0,0,0,0,0,0,0,0,0,0,0,0,1
1,0,0,1,1,1,1,1,1,1,0,0,1,1,1,1,1,1,1,0,0,1
1,0,0,1,5,5,5,5,1,8,0,0,6,1,5,5,5,5,1,0,0,1
1,0,0,1,5,5,5,5,1,1,9,9,1,1,5,5,5,5,1,0,0,1
1,0,0,1,5,5,5,5,5,1,10,10,1,5,5,5,5,5,1,0,0,1
1,0,0,1,5,5,5,5,5,1,11,11,1,5,5,5,5,5,1,0,0,1
1,0,0,1,1,1,5,5,5,1,12,12,1,5,5,5,1,1,1,0,0,1
17,0,0,1,16,1,1,1,1,1,15,15,1,1,1,1,1,14,1,0,0,13
1,0,0,0,0,21,1,11,12,15,20,20,15,12,11,1,19,0,0,0,0,1
1,0,0,0,0,21,1,11,12,15,20,20,15,12,11,1,19,0,0,0,0,1
17,0,0,1,23,1,1,1,1,1,15,15,1,1,1,1,1,22,1,0,0,13
1,0,0,1,1,1,5,5,5,1,12,12,1,5,5,5,1,1,1,0,0,1
1,0,0,1,5,5,5,5,5,1,11,11,1,5,5,5,5,5,1,0,0,1
1,0,0,1,5,5,5,5,5,1,1,1,1,5,5,5,5,5,1,0,0,1
1,0,0,1,5,5,5,5,1,1,24,24,1,1,5,5,5,5,1,0,0,1
1,0,0,1,5,5,5,5,1,8,0,0,6,1,5,5,5,5,1,0,0,1
1,0,0,1,1,1,1,1,1,1,0,0,1,1,1,1,1,1,1,0,0,1
1,0,0,0,0,0,0,0,0,0,0,0,0,0,0,0,0,0,0,0,0,1
1,0,0,0,0,0,0,0,0,0,0,0,0,0,0,0,0,0,0,0,0,1
1,1,1,1,1,1,1,1,1,25,1,1,25,1,1,1,1,1,1,1,1,1
endlayer

layer
1,1,26,1,26,26,26,26,26,1,1,1,1,26,26,26,26,26,1,26,1,1
1,0,0,0,0,0,0,0,0,0,0,0,0,0,0,0,0,0,0,0,0,1
26,0,0,0,0,0,0,0,0,0,0,0,0,0,0,0,0,0,0,0,0,26
1,0,0,27,27,27,27,27,1,1,0,0,1,1,27,27,27,27,27,0,0,1
26,0,0,27,0,0,0,0,1,17,0,0,13,1,0,0,0,0,27,0,0,26
26,0,0,27,0,0,0,0,1,1,0,0,1,1,0,0,0,0,27,0,0,26
26,0,0,27,0,0,0,0,0,0,10,10,0,0,0,0,0,0,27,0,0,26
26,0,0,27,0,0,0,0,0,0,11,11,0,0,0,0,0,0,27,0,0,26
26,0,0,1,1,1,0,0,0,27,0,0,27,0,0,0,1,1,1,0,0,26
1,0,0,1,3,1,0,0,27,10,28,28,1,27,0,0,1,3,1,0,0,1
1,0,0,0,0,0,1,11,0,30,10,10,29,0,11,1,0,0,0,0,0,1
1,0,0,0,0,0,1,11,0,30,10,10,29,0,11,1,0,0,0,0,0,1
1,0,0,1,25,1,0,0,27,1,31,31,1,27,0,0,1,25,1,0,0,1
26,0,0,1,1,1,0,0,0,27,0,0,27,0,0,0,1,1,1,0,0,26
26,0,0,27,0,0,0,0,0,0,11,11,0,0,0,0,0,0,27,0,0,26
26,0,0,27,0,0,0,0,0,0,1,1,0,0,0,0,0,0,27,0,0,26
26,0,0,27,0,0,0,0,1,1,0,0,1,1,0,0,0,0,27,0,0,26
26,0,0,27,0,0,0,0,1,17,0,0,13,1,0,0,0,0,27,0,0,26
1,0,0,27,27,27,27,27,1,1,0,0,1,1,27,27,27,27,27,0,0,1
26,0,0,0,0,0,0,0,0,0,0,0,0,0,0,0,0,0,0,0,0,26
1,0,0,0,0,0,0,0,0,0,0,0,0,0,0,0,0,0,0,0,0,1
1,1,26,1,26,26,26,26,26,1,1,1,1,26,26,26,26,26,1,26,1,1
endlayer

layer
1,1,26,1,26,1,1,1,26,1,1,1,1,26,1,1,1,26,1,26,1,1
1,0,0,0,0,0,0,0,0,0,0,0,0,0,0,0,0,0,0,0,0,1
26,0,0,0,0,0,0,0,0,0,0,0,0,0,0,0,0,0,0,0,0,26
1,0,0,32,0,0,0,27,27,1,1,1,1,27,27,0,0,0,32,0,0,1
26,0,0,0,0,0,0,0,0,1,34,33,1,0,0,0,0,0,0,0,0,26
1,0,0,0,0,0,0,0,0,1,34,33,1,0,0,0,0,0,0,0,0,1
1,0,0,0,0,0,0,0,0,0,1,1,0,0,0,0,0,0,0,0,0,1
1,0,0,27,0,0,0,0,0,0,11,11,0,0,0,0,0,0,27,0,0,1
26,0,0,27,0,0,0,0,0,32,0,0,32,0,0,0,0,0,27,0,0,26
1,0,0,1,1,1,0,0,32,1,10,10,1,32,0,0,1,1,1,0,0,1
1,0,0,1,35,35,1,11,0,10,5,5,10,0,11,1,35,35,1,0,0,1
1,0,0,1,36,36,1,11,0,10,5,5,10,0,11,1,36,36,1,0,0,1
1,0,0,1,1,1,0,0,32,1,10,10,1,32,0,0,1,1,1,0,0,1
26,0,0,27,0,0,0,0,0,32,0,0,32,0,0,0,0,0,27,0,0,26
1,0,0,27,0,0,0,0,0,0,11,11,0,0,0,0,0,0,27,0,0,1
1,0,0,0,0,0,0,0,0,0,1,1,0,0,0,0,0,0,0,0,0,1
1,0,0,0,0,0,0,0,0,1,34,33,1,0,0,0,0,0,0,0,0,1
26,0,0,0,0,0,0,0,0,1,34,33,1,0,0,0,0,0,0,0,0,26
1,0,0,32,0,0,0,27,27,1,1,1,1,27,27,0,0,0,32,0,0,1
26,0,0,0,0,0,0,0,0,0,0,0,0,0,0,0,0,0,0,0,0,26
1,0,0,0,0,0,0,0,0,0,0,0,0,0,0,0,0,0,0,0,0,1
1,1,26,1,26,1,1,1,26,1,1,1,1,26,1,1,1,26,1,26,1,1
endlayer

layer
1,1,26,1,26,26,26,1,26,1,1,1,1,26,1,26,26,26,1,26,1,1
1,0,0,0,0,0,0,0,0,0,0,0,0,0,0,0,0,0,0,0,0,1
26,0,0,0,0,0,0,0,0,0,0,0,0,0,0,0,0,0,0,0,0,26
1,0,0,0,0,0,0,0,0,1,1,1,1,0,0,0,0,0,0,0,0,1
26,0,0,0,0,0,0,0,0,1,5,5,1,0,0,0,0,0,0,0,0,26
26,0,0,0,0,0,0,0,0,1,5,5,1,0,0,0,0,0,0,0,0,26
26,0,0,0,0,0,0,0,0,0,1,1,0,0,0,0,0,0,0,0,0,26
1,0,0,0,0,0,0,0,0,0,11,11,0,0,0,0,0,0,0,0,0,1
26,0,0,0,0,0,0,0,0,0,0,0,0,0,0,0,0,0,0,0,0,26
1,0,0,1,1,1,0,0,0,1,10,10,1,0,0,0,1,1,1,0,0,1
1,0,0,1,5,5,1,11,0,10,0,0,10,0,11,1,5,5,1,0,0,1
1,0,0,1,5,5,1,11,0,10,0,0,10,0,11,1,5,5,1,0,0,1
1,0,0,1,1,1,0,0,0,1,10,10,1,0,0,0,1,1,1,0,0,1
26,0,0,0,0,0,0,0,0,0,0,0,0,0,0,0,0,0,0,0,0,26
1,0,0,0,0,0,0,0,0,0,11,11,0,0,0,0,0,0,0,0,0,1
26,0,0,0,0,0,0,0,0,0,1,1,0,0,0,0,0,0,0,0,0,26
26,0,0,0,0,0,0,0,0,1,5,5,1,0,0,0,0,0,0,0,0,26
26,0,0,0,0,0,0,0,0,1,5,5,1,0,0,0,0,0,0,0,0,26
1,0,0,0,0,0,0,0,0,1,1,1,1,0,0,0,0,0,0,0,0,1
26,0,0,0,0,0,0,0,0,0,0,0,0,0,0,0,0,0,0,0,0,26
1,0,0,0,0,0,0,0,0,0,0,0,0,0,0,0,0,0,0,0,0,1
1,1,26,1,26,26,26,1,26,1,1,1,1,26,1,26,26,26,1,26,1,1
endlayer

layer
1,1,26,1,1,1,26,1,26,1,1,1,1,26,1,26,1,1,1,26,1,1
1,0,0,0,0,0,0,0,0,0,0,0,0,0,0,0,0,0,0,0,0,1
26,0,0,0,0,0,0,0,0,0,0,0,0,0,0,0,0,0,0,0,0,26
1,0,0,0,0,0,0,0,0,1,1,1,1,0,0,0,0,0,0,0,0,1
1,0,0,0,0,0,0,0,0,1,0,0,1,0,0,0,0,0,0,0,0,1
1,0,0,0,0,0,0,0,0,1,0,0,1,0,0,0,0,0,0,0,0,1
26,0,0,0,0,0,0,0,0,0,1,1,0,0,0,0,0,0,0,0,0,26
1,0,0,0,0,0,0,0,0,0,11,11,0,0,0,0,0,0,0,0,0,1
26,0,0,0,0,0,0,0,0,0,0,0,0,0,0,0,0,0,0,0,0,26
1,0,0,1,1,1,0,0,0,1,0,0,1,0,0,0,1,1,1,0,0,1
1,0,0,1,0,0,1,11,0,0,0,0,0,0,11,1,0,0,1,0,0,1
1,0,0,1,0,0,1,11,0,0,0,0,0,0,11,1,0,0,1,0,0,1
1,0,0,1,1,1,0,0,0,1,0,0,1,0,0,0,1,1,1,0,0,1
26,0,0,0,0,0,0,0,0,0,0,0,0,0,0,0,0,0,0,0,0,26
1,0,0,0,0,0,0,0,0,0,11,11,0,0,0,0,0,0,0,0,0,1
26,0,0,0,0,0,0,0,0,0,1,1,0,0,0,0,0,0,0,0,0,26
1,0,0,0,0,0,0,0,0,1,0,0,1,0,0,0,0,0,0,0,0,1
1,0,0,0,0,0,0,0,0,1,0,0,1,0,0,0,0,0,0,0,0,1
1,0,0,0,0,0,0,0,0,1,1,1,1,0,0,0,0,0,0,0,0,1
26,0,0,0,0,0,0,0,0,0,0,0,0,0,0,0,0,0,0,0,0,26
1,0,0,0,0,0,0,0,0,0,0,0,0,0,0,0,0,0,0,0,0,1
1,1,26,1,1,1,26,1,26,1,1,1,1,26,1,26,1,1,1,26,1,1
endlayer

layer
1,1,26,26,26,26,26,1,26,1,1,1,1,26,1,26,26,26,26,26,1,1
1,0,0,0,0,0,0,0,0,0,0,0,0,0,0,0,0,0,0,0,0,1
26,0,0,0,0,0,0,0,0,0,0,0,0,0,0,0,0,0,0,0,0,26
26,0,0,0,0,0,0,0,0,1,1,1,1,0,0,0,0,0,0,0,0,26
26,0,0,0,0,0,0,0,0,0,1,1,0,0,0,0,0,0,0,0,0,26
26,0,0,0,0,0,0,0,0,0,1,1,0,0,0,0,0,0,0,0,0,26
26,0,0,0,0,0,0,0,0,0,1,1,0,0,0,0,0,0,0,0,0,26
1,0,0,0,0,0,0,0,0,0,11,11,0,0,0,0,0,0,0,0,0,1
26,0,0,0,0,0,0,0,0,0,0,0,0,0,0,0,0,0,0,0,0,26
1,0,0,1,0,0,0,0,0,1,0,0,1,0,0,0,0,0,1,0,0,1
1,0,0,1,1,1,1,11,0,0,0,0,0,0,11,1,1,1,1,0,0,1
1,0,0,1,1,1,1,11,0,0,0,0,0,0,11,1,1,1,1,0,0,1
1,0,0,1,0,0,0,0,0,1,0,0,1,0,0,0,0,0,1,0,0,1
26,0,0,0,0,0,0,0,0,0,0,0,0,0,0,0,0,0,0,0,0,26
1,0,0,0,0,0,0,0,0,0,11,11,0,0,0,0,0,0,0,0,0,1
26,0,0,0,0,0,0,0,0,0,1,1,0,0,0,0,0,0,0,0,0,26
26,0,0,0,0,0,0,0,0,0,1,1,0,0,0,0,0,0,0,0,0,26
26,0,0,0,0,0,0,0,0,0,1,1,0,0,0,0,0,0,0,0,0,26
26,0,0,0,0,0,0,0,0,1,1,1,1,0,0,0,0,0,0,0,0,26
26,0,0,0,0,0,0,0,0,0,0,0,0,0,0,0,0,0,0,0,0,26
1,0,0,0,0,0,0,0,0,0,0,0,0,0,0,0,0,0,0,0,0,1
1,1,26,26,26,26,26,1,26,1,1,1,1,26,1,26,26,26,26,26,1,1
endlayer

layer
1,1,1,1,1,1,1,1,1,1,1,1,1,1,1,1,1,1,1,1,1,1
1,0,0,0,0,0,0,0,0,0,0,0,0,0,0,0,0,0,0,0,0,1
1,0,0,0,0,0,0,0,0,0,0,0,0,0,0,0,0,0,0,0,0,1
1,0,0,0,0,0,0,0,0,1,1,1,1,0,0,0,0,0,0,0,0,1
1,0,0,0,0,0,0,0,0,0,0,0,0,0,0,0,0,0,0,0,0,1
1,0,0,0,0,0,0,0,0,0,0,0,0,0,0,0,0,0,0,0,0,1
1,0,0,0,0,0,0,0,0,0,0,0,0,0,0,0,0,0,0,0,0,1
1,0,0,0,0,0,0,0,0,0,11,11,0,0,0,0,0,0,0,0,0,1
1,0,0,0,0,0,0,0,0,0,0,0,0,0,0,0,0,0,0,0,0,1
1,0,0,1,0,0,0,0,0,1,0,0,1,0,0,0,0,0,1,0,0,1
1,0,0,1,0,0,0,11,0,0,0,0,0,0,11,0,0,0,1,0,0,1
1,0,0,1,0,0,0,11,0,0,0,0,0,0,11,0,0,0,1,0,0,1
1,0,0,1,0,0,0,0,0,1,0,0,1,0,0,0,0,0,1,0,0,1
1,0,0,0,0,0,0,0,0,0,0,0,0,0,0,0,0,0,0,0,0,1
1,0,0,0,0,0,0,0,0,0,11,11,0,0,0,0,0,0,0,0,0,1
1,0,0,0,0,0,0,0,0,0,0,0,0,0,0,0,0,0,0,0,0,1
1,0,0,0,0,0,0,0,0,0,0,0,0,0,0,0,0,0,0,0,0,1
1,0,0,0,0,0,0,0,0,0,0,0,0,0,0,0,0,0,0,0,0,1
1,0,0,0,0,0,0,0,0,1,1,1,1,0,0,0,0,0,0,0,0,1
1,0,0,0,0,0,0,0,0,0,0,0,0,0,0,0,0,0,0,0,0,1
1,0,0,0,0,0,0,0,0,0,0,0,0,0,0,0,0,0,0,0,0,1
1,1,1,1,1,1,1,1,1,1,1,1,1,1,1,1,1,1,1,1,1,1
endlayer

layer
4,4,4,4,4,4,4,4,4,26,37,37,26,4,4,4,4,4,4,4,4,4
4,1,1,1,1,1,1,1,1,1,1,1,1,1,1,1,1,1,1,1,1,4
4,1,1,1,1,1,1,1,1,1,1,1,1,1,1,1,1,1,1,1,1,4
4,1,1,1,1,1,1,1,1,1,1,1,1,1,1,1,1,1,1,1,1,4
4,1,1,1,1,0,0,0,0,0,38,38,0,0,0,0,0,1,1,1,1,4
4,1,1,1,0,0,0,0,0,0,38,38,0,0,0,0,0,0,1,1,1,4
4,1,1,1,0,0,0,0,0,0,38,38,0,0,0,0,0,0,1,1,1,4
4,1,1,1,0,0,0,0,0,0,11,11,0,0,0,0,0,0,1,1,1,4
4,1,1,1,0,0,0,0,0,0,0,0,0,0,0,0,0,0,1,1,1,4
26,1,1,1,0,0,0,0,0,1,0,0,1,0,0,0,0,0,1,1,1,26
40,1,1,1,39,39,39,11,0,0,0,0,0,0,11,40,40,40,1,1,1,39
40,1,1,1,39,39,39,11,0,0,0,0,0,0,11,40,40,40,1,1,1,39
26,1,1,1,0,0,0,0,0,1,0,0,1,0,0,0,0,0,1,1,1,26
4,1,1,1,0,0,0,0,0,0,0,0,0,0,0,0,0,0,1,1,1,4
4,1,1,1,0,0,0,0,0,0,11,11,0,0,0,0,0,0,1,1,1,4
4,1,1,1,0,0,0,0,0,0,37,37,0,0,0,0,0,0,1,1,1,4
4,1,1,1,0,0,0,0,0,0,37,37,0,0,0,0,0,0,1,1,1,4
4,1,1,1,1,0,0,0,0,0,37,37,0,0,0,0,0,1,1,1,1,4
4,1,1,1,1,1,1,1,1,1,1,1,1,1,1,1,1,1,1,1,1,4
4,1,1,1,1,1,1,1,1,1,1,1,1,1,1,1,1,1,1,1,1,4
4,1,1,1,1,1,1,1,1,1,1,1,1,1,1,1,1,1,1,1,1,4
4,4,4,4,4,4,4,4,4,26,38,38,26,4,4,4,4,4,4,4,4,4
endlayer

layer
4,4,4,4,4,4,4,4,4,4,4,4,4,4,4,4,4,4,4,4,4,4
4,4,4,4,4,4,4,4,4,26,37,37,26,4,4,4,4,4,4,4,4,4
4,4,1,1,1,1,1,1,1,1,41,41,1,1,1,1,1,1,1,1,4,4
4,4,1,1,1,1,1,1,1,26,12,12,26,1,1,1,1,1,1,1,4,4
4,4,1,1,1,0,0,0,0,27,15,15,27,0,0,0,0,1,1,1,4,4
4,4,1,1,0,0,0,0,0,27,20,20,27,0,0,0,0,0,1,1,4,4
4,4,1,1,0,0,0,0,0,27,42,42,27,0,0,0,0,0,1,1,4,4
4,4,1,1,0,0,0,0,0,0,43,43,0,0,0,0,0,0,1,1,4,4
4,4,1,1,0,0,0,0,0,0,0,0,0,0,0,0,0,0,1,1,4,4
4,26,1,26,27,27,27,0,0,1,0,0,1,0,0,27,27,27,26,1,26,4
4,40,41,12,15,20,42,43,0,0,0,0,0,0,43,42,20,15,12,41,39,4
4,40,41,12,15,20,42,43,0,0,0,0,0,0,43,42,20,15,12,41,39,4
4,26,1,26,27,27,27,0,0,1,0,0,1,0,0,27,27,27,26,1,26,4
4,4,1,1,0,0,0,0,0,0,0,0,0,0,0,0,0,0,1,1,4,4
4,4,1,1,0,0,0,0,0,0,43,43,0,0,0,0,0,0,1,1,4,4
4,4,1,1,0,0,0,0,0,27,42,42,27,0,0,0,0,0,1,1,4,4
4,4,1,1,0,0,0,0,0,27,20,20,27,0,0,0,0,0,1,1,4,4
4,4,1,1,1,0,0,0,0,27,15,15,27,0,0,0,0,1,1,1,4,4
4,4,1,1,1,1,1,1,1,26,12,12,26,1,1,1,1,1,1,1,4,4
4,4,1,1,1,1,1,1,1,1,41,41,1,1,1,1,1,1,1,1,4,4
4,4,4,4,4,4,4,4,4,26,38,38,26,4,4,4,4,4,4,4,4,4
4,4,4,4,4,4,4,4,4,4,4,4,4,4,4,4,4,4,4,4,4,4
endlayer

layer
4,4,4,4,4,4,4,4,4,4,4,4,4,4,4,4,4,4,4,4,4,4
4,4,4,4,4,4,4,4,4,4,4,4,4,4,4,4,4,4,4,4,4,4
4,4,4,4,4,4,4,4,4,26,37,37,26,4,4,4,4,4,4,4,4,4
4,4,4,1,1,1,1,1,1,1,1,1,1,1,1,1,1,1,1,4,4,4
4,4,4,1,1,0,0,0,0,0,31,31,0,0,0,0,0,1,1,4,4,4
4,4,4,1,0,0,0,0,0,0,31,31,0,0,0,0,0,0,1,4,4,4
4,4,4,1,0,0,0,0,0,32,31,31,32,0,0,0,0,0,1,4,4,4
4,4,4,1,0,0,0,0,0,0,0,0,0,0,0,0,0,0,1,4,4,4
4,4,4,1,0,0,0,0,0,0,0,0,0,0,0,0,0,0,1,4,4,4
4,4,26,1,0,0,32,0,0,1,0,0,1,0,0,32,0,0,1,26,4,4
4,4,40,1,29,29,29,0,0,0,0,0,0,0,0,30,30,30,1,39,4,4
4,4,40,1,29,29,29,0,0,0,0,0,0,0,0,30,30,30,1,39,4,4
4,4,26,1,0,0,32,0,0,1,0,0,1,0,0,32,0,0,1,26,4,4
4,4,4,1,0,0,0,0,0,0,0,0,0,0,0,0,0,0,1,4,4,4
4,4,4,1,0,0,0,0,0,0,0,0,0,0,0,0,0,0,1,4,4,4
4,4,4,1,0,0,0,0,0,32,28,28,32,0,0,0,0,0,1,4,4,4
4,4,4,1,0,0,0,0,0,0,28,28,0,0,0,0,0,0,1,4,4,4
4,4,4,1,1,0,0,0,0,0,28,28,0,0,0,0,0,1,1,4,4,4
4,4,4,1,1,1,1,1,1,1,1,1,1,1,1,1,1,1,1,4,4,4
4,4,4,4,4,4,4,4,4,26,38,38,26,4,4,4,4,4,4,4,4,4
4,4,4,4,4,4,4,4,4,4,4,4,4,4,4,4,4,4,4,4,4,4
4,4,4,4,4,4,4,4,4,4,4,4,4,4,4,4,4,4,4,4,4,4
endlayer

layer
4,4,4,4,4,4,4,4,4,4,4,4,4,4,4,4,4,4,4,4,4,4
4,4,4,4,4,4,4,4,4,4,4,4,4,4,4,4,4,4,4,4,4,4
4,4,4,4,4,4,4,4,4,4,4,4,4,4,4,4,4,4,4,4,4,4
4,4,4,4,4,4,4,4,4,26,37,37,26,4,4,4,4,4,4,4,4,4
4,4,4,4,1,1,1,1,1,1,26,26,1,1,1,1,1,1,4,4,4,4
4,4,4,4,1,1,0,0,0,0,0,0,0,0,0,0,1,1,4,4,4,4
4,4,4,4,1,0,0,0,0,0,0,0,0,0,0,0,0,1,4,4,4,4
4,4,4,4,1,0,0,0,0,0,0,0,0,0,0,0,0,1,4,4,4,4
4,4,4,4,1,0,0,0,0,0,0,0,0,0,0,0,0,1,4,4,4,4
4,4,4,26,1,0,0,0,0,1,10,10,1,0,0,0,0,1,26,4,4,4
4,4,4,40,26,0,0,0,0,10,34,35,10,0,0,0,0,26,39,4,4,4
4,4,4,40,26,0,0,0,0,10,36,33,10,0,0,0,0,26,39,4,4,4
4,4,4,26,1,0,0,0,0,1,10,10,1,0,0,0,0,1,26,4,4,4
4,4,4,4,1,0,0,0,0,0,0,0,0,0,0,0,0,1,4,4,4,4
4,4,4,4,1,0,0,0,0,0,0,0,0,0,0,0,0,1,4,4,4,4
4,4,4,4,1,0,0,0,0,0,0,0,0,0,0,0,0,1,4,4,4,4
4,4,4,4,1,1,0,0,0,0,0,0,0,0,0,0,1,1,4,4,4,4
4,4,4,4,1,1,1,1,1,1,26,26,1,1,1,1,1,1,4,4,4,4
4,4,4,4,4,4,4,4,4,26,38,38,26,4,4,4,4,4,4,4,4,4
4,4,4,4,4,4,4,4,4,4,4,4,4,4,4,4,4,4,4,4,4,4
4,4,4,4,4,4,4,4,4,4,4,4,4,4,4,4,4,4,4,4,4,4
4,4,4,4,4,4,4,4,4,4,4,4,4,4,4,4,4,4,4,4,4,4
endlayer

layer
4,4,4,4,4,4,4,4,4,4,4,4,4,4,4,4,4,4,4,4,4,4
4,4,4,4,4,4,4,4,4,4,4,4,4,4,4,4,4,4,4,4,4,4
4,4,4,4,4,4,4,4,4,4,4,4,4,4,4,4,4,4,4,4,4,4
4,4,4,4,4,4,4,4,4,4,4,4,4,4,4,4,4,4,4,4,4,4
4,4,4,4,4,4,4,4,4,26,37,37,26,4,4,4,4,4,4,4,4,4
4,4,4,4,4,1,1,1,1,1,1,1,1,1,1,1,1,4,4,4,4,4
4,4,4,4,4,1,1,0,0,0,0,0,0,0,0,1,1,4,4,4,4,4
4,4,4,4,4,1,0,0,0,0,0,0,0,0,0,0,1,4,4,4,4,4
4,4,4,4,4,1,0,0,0,0,0,0,0,0,0,0,1,4,4,4,4,4
4,4,4,4,26,1,0,0,0,1,10,10,1,0,0,0,1,26,4,4,4,4
4,4,4,4,40,1,0,0,0,10,41,41,10,0,0,0,1,39,4,4,4,4
4,4,4,4,40,1,0,0,0,10,41,41,10,0,0,0,1,39,4,4,4,4
4,4,4,4,26,1,0,0,0,1,10,10,1,0,0,0,1,26,4,4,4,4
4,4,4,4,4,1,0,0,0,0,0,0,0,0,0,0,1,4,4,4,4,4
4,4,4,4,4,1,0,0,0,0,0,0,0,0,0,0,1,4,4,4,4,4
4,4,4,4,4,1,1,0,0,0,0,0,0,0,0,1,1,4,4,4,4,4
4,4,4,4,4,1,1,1,1,1,1,1,1,1,1,1,1,4,4,4,4,4
4,4,4,4,4,4,4,4,4,26,38,38,26,4,4,4,4,4,4,4,4,4
4,4,4,4,4,4,4,4,4,4,4,4,4,4,4,4,4,4,4,4,4,4
4,4,4,4,4,4,4,4,4,4,4,4,4,4,4,4,4,4,4,4,4,4
4,4,4,4,4,4,4,4,4,4,4,4,4,4,4,4,4,4,4,4,4,4
4,4,4,4,4,4,4,4,4,4,4,4,4,4,4,4,4,4,4,4,4,4
endlayer

layer
4,4,4,4,4,4,4,4,4,4,4,4,4,4,4,4,4,4,4,4,4,4
4,4,4,4,4,4,4,4,4,4,4,4,4,4,4,4,4,4,4,4,4,4
4,4,4,4,4,4,4,4,4,4,4,4,4,4,4,4,4,4,4,4,4,4
4,4,4,4,4,4,4,4,4,4,4,4,4,4,4,4,4,4,4,4,4,4
4,4,4,4,4,4,4,4,4,4,4,4,4,4,4,4,4,4,4,4,4,4
4,4,4,4,4,4,4,4,4,26,37,37,26,4,4,4,4,4,4,4,4,4
4,4,4,4,4,4,1,1,1,1,1,1,1,1,1,1,4,4,4,4,4,4
4,4,4,4,4,4,1,1,0,0,0,0,0,0,1,1,4,4,4,4,4,4
4,4,4,4,4,4,1,0,0,0,0,0,0,0,0,1,4,4,4,4,4,4
4,4,4,4,4,26,1,0,0,1,0,0,1,0,0,1,26,4,4,4,4,4
4,4,4,4,4,40,1,0,0,0,0,0,0,0,0,1,39,4,4,4,4,4
4,4,4,4,4,40,1,0,0,0,0,0,0,0,0,1,39,4,4,4,4,4
4,4,4,4,4,26,1,0,0,1,0,0,1,0,0,1,26,4,4,4,4,4
4,4,4,4,4,4,1,0,0,0,0,0,0,0,0,1,4,4,4,4,4,4
4,4,4,4,4,4,1,1,0,0,0,0,0,0,1,1,4,4,4,4,4,4
4,4,4,4,4,4,1,1,1,1,1,1,1,1,1,1,4,4,4,4,4,4
4,4,4,4,4,4,4,4,4,26,38,38,26,4,4,4,4,4,4,4,4,4
4,4,4,4,4,4,4,4,4,4,4,4,4,4,4,4,4,4,4,4,4,4
4,4,4,4,4,4,4,4,4,4,4,4,4,4,4,4,4,4,4,4,4,4
4,4,4,4,4,4,4,4,4,4,4,4,4,4,4,4,4,4,4,4,4,4
4,4,4,4,4,4,4,4,4,4,4,4,4,4,4,4,4,4,4,4,4,4
4,4,4,4,4,4,4,4,4,4,4,4,4,4,4,4,4,4,4,4,4,4
endlayer

layer
4,4,4,4,4,4,4,4,4,4,4,4,4,4,4,4,4,4,4,4,4,4
4,4,4,4,4,4,4,4,4,4,4,4,4,4,4,4,4,4,4,4,4,4
4,4,4,4,4,4,4,4,4,4,4,4,4,4,4,4,4,4,4,4,4,4
4,4,4,4,4,4,4,4,4,4,4,4,4,4,4,4,4,4,4,4,4,4
4,4,4,4,4,4,4,4,4,4,4,4,4,4,4,4,4,4,4,4,4,4
4,4,4,4,4,4,4,4,4,4,4,4,4,4,4,4,4,4,4,4,4,4
4,4,4,4,4,4,4,4,4,26,37,37,26,4,4,4,4,4,4,4,4,4
4,4,4,4,4,4,4,1,1,1,1,1,1,1,1,4,4,4,4,4,4,4
4,4,4,4,4,4,4,1,1,0,0,0,0,1,1,4,4,4,4,4,4,4
4,4,4,4,4,4,26,1,0,1,10,10,1,0,1,26,4,4,4,4,4,4
4,4,4,4,4,4,40,1,0,10,41,41,10,0,1,39,4,4,4,4,4,4
4,4,4,4,4,4,40,1,0,10,41,41,10,0,1,39,4,4,4,4,4,4
4,4,4,4,4,4,26,1,0,1,10,10,1,0,1,26,4,4,4,4,4,4
4,4,4,4,4,4,4,1,1,0,0,0,0,1,1,4,4,4,4,4,4,4
4,4,4,4,4,4,4,1,1,1,1,1,1,1,1,4,4,4,4,4,4,4
4,4,4,4,4,4,4,4,4,26,38,38,26,4,4,4,4,4,4,4,4,4
4,4,4,4,4,4,4,4,4,4,4,4,4,4,4,4,4,4,4,4,4,4
4,4,4,4,4,4,4,4,4,4,4,4,4,4,4,4,4,4,4,4,4,4
4,4,4,4,4,4,4,4,4,4,4,4,4,4,4,4,4,4,4,4,4,4
4,4,4,4,4,4,4,4,4,4,4,4,4,4,4,4,4,4,4,4,4,4
4,4,4,4,4,4,4,4,4,4,4,4,4,4,4,4,4,4,4,4,4,4
4,4,4,4,4,4,4,4,4,4,4,4,4,4,4,4,4,4,4,4,4,4
endlayer

layer
4,4,4,4,4,4,4,4,4,4,4,4,4,4,4,4,4,4,4,4,4,4
4,4,4,4,4,4,4,4,4,4,4,4,4,4,4,4,4,4,4,4,4,4
4,4,4,4,4,4,4,4,4,4,4,4,4,4,4,4,4,4,4,4,4,4
4,4,4,4,4,4,4,4,4,4,4,4,4,4,4,4,4,4,4,4,4,4
4,4,4,4,4,4,4,4,4,4,4,4,4,4,4,4,4,4,4,4,4,4
4,4,4,4,4,4,4,4,4,4,4,4,4,4,4,4,4,4,4,4,4,4
4,4,4,4,4,4,4,4,4,4,4,4,4,4,4,4,4,4,4,4,4,4
4,4,4,4,4,4,4,4,4,26,37,37,26,4,4,4,4,4,4,4,4,4
4,4,4,4,4,4,4,4,1,1,1,1,1,1,4,4,4,4,4,4,4,4
4,4,4,4,4,4,4,26,1,1,1,1,1,1,26,4,4,4,4,4,4,4
4,4,4,4,4,4,4,40,1,1,41,41,1,1,39,4,4,4,4,4,4,4
4,4,4,4,4,4,4,40,1,1,41,41,1,1,39,4,4,4,4,4,4,4
4,4,4,4,4,4,4,26,1,1,1,1,1,1,26,4,4,4,4,4,4,4
4,4,4,4,4,4,4,4,1,1,1,1,1,1,4,4,4,4,4,4,4,4
4,4,4,4,4,4,4,4,4,26,38,38,26,4,4,4,4,4,4,4,4,4
4,4,4,4,4,4,4,4,4,4,4,4,4,4,4,4,4,4,4,4,4,4
4,4,4,4,4,4,4,4,4,4,4,4,4,4,4,4,4,4,4,4,4,4
4,4,4,4,4,4,4,4,4,4,4,4,4,4,4,4,4,4,4,4,4,4
4,4,4,4,4,4,4,4,4,4,4,4,4,4,4,4,4,4,4,4,4,4
4,4,4,4,4,4,4,4,4,4,4,4,4,4,4,4,4,4,4,4,4,4
4,4,4,4,4,4,4,4,4,4,4,4,4,4,4,4,4,4,4,4,4,4
4,4,4,4,4,4,4,4,4,4,4,4,4,4,4,4,4,4,4,4,4,4
endlayer

layer
4,4,4,4,4,4,4,4,4,4,4,4,4,4,4,4,4,4,4,4,4,4
4,4,4,4,4,4,4,4,4,4,4,4,4,4,4,4,4,4,4,4,4,4
4,4,4,4,4,4,4,4,4,4,4,4,4,4,4,4,4,4,4,4,4,4
4,4,4,4,4,4,4,4,4,4,4,4,4,4,4,4,4,4,4,4,4,4
4,4,4,4,4,4,4,4,4,4,4,4,4,4,4,4,4,4,4,4,4,4
4,4,4,4,4,4,4,4,4,4,4,4,4,4,4,4,4,4,4,4,4,4
4,4,4,4,4,4,4,4,4,4,4,4,4,4,4,4,4,4,4,4,4,4
4,4,4,4,4,4,4,4,4,4,4,4,4,4,4,4,4,4,4,4,4,4
4,4,4,4,4,4,4,4,4,4,4,4,4,4,4,4,4,4,4,4,4,4
4,4,4,4,4,4,4,4,4,1,0,0,1,4,4,4,4,4,4,4,4,4
4,4,4,4,4,4,4,4,4,0,0,0,0,4,4,4,4,4,4,4,4,4
4,4,4,4,4,4,4,4,4,0,0,0,0,4,4,4,4,4,4,4,4,4
4,4,4,4,4,4,4,4,4,1,0,0,1,4,4,4,4,4,4,4,4,4
4,4,4,4,4,4,4,4,4,4,4,4,4,4,4,4,4,4,4,4,4,4
4,4,4,4,4,4,4,4,4,4,4,4,4,4,4,4,4,4,4,4,4,4
4,4,4,4,4,4,4,4,4,4,4,4,4,4,4,4,4,4,4,4,4,4
4,4,4,4,4,4,4,4,4,4,4,4,4,4,4,4,4,4,4,4,4,4
4,4,4,4,4,4,4,4,4,4,4,4,4,4,4,4,4,4,4,4,4,4
4,4,4,4,4,4,4,4,4,4,4,4,4,4,4,4,4,4,4,4,4,4
4,4,4,4,4,4,4,4,4,4,4,4,4,4,4,4,4,4,4,4,4,4
4,4,4,4,4,4,4,4,4,4,4,4,4,4,4,4,4,4,4,4,4,4
4,4,4,4,4,4,4,4,4,4,4,4,4,4,4,4,4,4,4,4,4,4
endlayer

layer
4,4,4,4,4,4,4,4,4,4,4,4,4,4,4,4,4,4,4,4,4,4
4,4,4,4,4,4,4,4,4,4,4,4,4,4,4,4,4,4,4,4,4,4
4,4,4,4,4,4,4,4,4,4,4,4,4,4,4,4,4,4,4,4,4,4
4,4,4,4,4,4,4,4,4,4,4,4,4,4,4,4,4,4,4,4,4,4
4,4,4,4,4,4,4,4,4,4,4,4,4,4,4,4,4,4,4,4,4,4
4,4,4,4,4,4,4,4,4,4,4,4,4,4,4,4,4,4,4,4,4,4
4,4,4,4,4,4,4,4,4,4,4,4,4,4,4,4,4,4,4,4,4,4
4,4,4,4,4,4,4,4,4,4,4,4,4,4,4,4,4,4,4,4,4,4
4,4,4,4,4,4,4,4,4,4,4,4,4,4,4,4,4,4,4,4,4,4
4,4,4,4,4,4,4,4,4,26,0,0,26,4,4,4,4,4,4,4,4,4
4,4,4,4,4,4,4,4,4,0,0,0,0,4,4,4,4,4,4,4,4,4
4,4,4,4,4,4,4,4,4,0,0,0,0,4,4,4,4,4,4,4,4,4
4,4,4,4,4,4,4,4,4,26,0,0,26,4,4,4,4,4,4,4,4,4
4,4,4,4,4,4,4,4,4,4,4,4,4,4,4,4,4,4,4,4,4,4
4,4,4,4,4,4,4,4,4,4,4,4,4,4,4,4,4,4,4,4,4,4
4,4,4,4,4,4,4,4,4,4,4,4,4,4,4,4,4,4,4,4,4,4
4,4,4,4,4,4,4,4,4,4,4,4,4,4,4,4,4,4,4,4,4,4
4,4,4,4,4,4,4,4,4,4,4,4,4,4,4,4,4,4,4,4,4,4
4,4,4,4,4,4,4,4,4,4,4,4,4,4,4,4,4,4,4,4,4,4
4,4,4,4,4,4,4,4,4,4,4,4,4,4,4,4,4,4,4,4,4,4
4,4,4,4,4,4,4,4,4,4,4,4,4,4,4,4,4,4,4,4,4,4
4,4,4,4,4,4,4,4,4,4,4,4,4,4,4,4,4,4,4,4,4,4
endlayer

layer
4,4,4,4,4,4,4,4,4,4,4,4,4,4,4,4,4,4,4,4,4,4
4,4,4,4,4,4,4,4,4,4,4,4,4,4,4,4,4,4,4,4,4,4
4,4,4,4,4,4,4,4,4,4,4,4,4,4,4,4,4,4,4,4,4,4
4,4,4,4,4,4,4,4,4,4,4,4,4,4,4,4,4,4,4,4,4,4
4,4,4,4,4,4,4,4,4,4,4,4,4,4,4,4,4,4,4,4,4,4
4,4,4,4,4,4,4,4,4,4,4,4,4,4,4,4,4,4,4,4,4,4
4,4,4,4,4,4,4,4,4,4,4,4,4,4,4,4,4,4,4,4,4,4
4,4,4,4,4,4,4,4,4,4,4,4,4,4,4,4,4,4,4,4,4,4
4,4,4,4,4,4,4,4,4,4,4,4,4,4,4,4,4,4,4,4,4,4
4,4,4,4,4,4,4,4,4,37,37,37,39,4,4,4,4,4,4,4,4,4
4,4,4,4,4,4,4,4,4,40,44,44,39,4,4,4,4,4,4,4,4,4
4,4,4,4,4,4,4,4,4,40,44,44,39,4,4,4,4,4,4,4,4,4
4,4,4,4,4,4,4,4,4,40,38,38,38,4,4,4,4,4,4,4,4,4
4,4,4,4,4,4,4,4,4,4,4,4,4,4,4,4,4,4,4,4,4,4
4,4,4,4,4,4,4,4,4,4,4,4,4,4,4,4,4,4,4,4,4,4
4,4,4,4,4,4,4,4,4,4,4,4,4,4,4,4,4,4,4,4,4,4
4,4,4,4,4,4,4,4,4,4,4,4,4,4,4,4,4,4,4,4,4,4
4,4,4,4,4,4,4,4,4,4,4,4,4,4,4,4,4,4,4,4,4,4
4,4,4,4,4,4,4,4,4,4,4,4,4,4,4,4,4,4,4,4,4,4
4,4,4,4,4,4,4,4,4,4,4,4,4,4,4,4,4,4,4,4,4,4
4,4,4,4,4,4,4,4,4,4,4,4,4,4,4,4,4,4,4,4,4,4
4,4,4,4,4,4,4,4,4,4,4,4,4,4,4,4,4,4,4,4,4,4
endlayer

layer
4,4,4,4,4,4,4,4,4,4,4,4,4,4,4,4,4,4,4,4,4,4
4,4,4,4,4,4,4,4,4,4,4,4,4,4,4,4,4,4,4,4,4,4
4,4,4,4,4,4,4,4,4,4,4,4,4,4,4,4,4,4,4,4,4,4
4,4,4,4,4,4,4,4,4,4,4,4,4,4,4,4,4,4,4,4,4,4
4,4,4,4,4,4,4,4,4,4,4,4,4,4,4,4,4,4,4,4,4,4
4,4,4,4,4,4,4,4,4,4,4,4,4,4,4,4,4,4,4,4,4,4
4,4,4,4,4,4,4,4,4,4,4,4,4,4,4,4,4,4,4,4,4,4
4,4,4,4,4,4,4,4,4,4,4,4,4,4,4,4,4,4,4,4,4,4
4,4,4,4,4,4,4,4,4,4,4,4,4,4,4,4,4,4,4,4,4,4
4,4,4,4,4,4,4,4,4,30,28,28,28,4,4,4,4,4,4,4,4,4
4,4,4,4,4,4,4,4,4,30,26,26,29,4,4,4,4,4,4,4,4,4
4,4,4,4,4,4,4,4,4,30,26,26,29,4,4,4,4,4,4,4,4,4
4,4,4,4,4,4,4,4,4,31,31,31,31,4,4,4,4,4,4,4,4,4
4,4,4,4,4,4,4,4,4,4,4,4,4,4,4,4,4,4,4,4,4,4
4,4,4,4,4,4,4,4,4,4,4,4,4,4,4,4,4,4,4,4,4,4
4,4,4,4,4,4,4,4,4,4,4,4,4,4,4,4,4,4,4,4,4,4
4,4,4,4,4,4,4,4,4,4,4,4,4,4,4,4,4,4,4,4,4,4
4,4,4,4,4,4,4,4,4,4,4,4,4,4,4,4,4,4,4,4,4,4
4,4,4,4,4,4,4,4,4,4,4,4,4,4,4,4,4,4,4,4,4,4
4,4,4,4,4,4,4,4,4,4,4,4,4,4,4,4,4,4,4,4,4,4
4,4,4,4,4,4,4,4,4,4,4,4,4,4,4,4,4,4,4,4,4,4
4,4,4,4,4,4,4,4,4,4,4,4,4,4,4,4,4,4,4,4,4,4
endlayer

