# Jungle Tree Stand
# MC 1.7.10; 4 Nov 2014
# Created by Ruins mod version 14.1 Ingame Parser
# authoring Player: Jordan_Greywolf
# Last Updated: 27 Apr 2015
# Updated to MC 1.11: 12 Jan 2017
# Note: Place in \templateparser folder

biomesToSpawnIn=jungle,jungle m,junglehills,jungleedge,jungleedge m,temperate rainforest,rainforest

weight=1
embed_into_distance=0
acceptable_target_blocks=

unacceptable_target_blocks=flowing_water,water,flowing_lava,lava,cloud,Natura:Cloud

dimensions=30,16,14
allowable_overhang=0
max_leveling=0
leveling_buffer=0
preserve_water=0
preserve_lava=0
preserve_plants=1

rule1=0,100,minecraft:grass-0
rule2=0,100,minecraft:dirt-0
rule3=0,100,minecraft:double_plant-2
rule4=0,100,minecraft:leaves-7
rule5=0,100,minecraft:vine-1
rule6=0,100,minecraft:log-3
rule7=0,100,minecraft:vine-4
rule8=0,100,minecraft:vine-2
rule9=0,100,minecraft:double_plant-9
rule10=0,100,minecraft:vine-8
rule11=0,100,minecraft:double_plant-8
rule12=0,100,minecraft:double_plant-11
rule13=0,100,minecraft:double_plant-10
rule14=0,100,minecraft:leaves-7
rule15=0,100,minecraft:leaves-7
rule16=0,100,minecraft:leaves-7
rule17=0,100,minecraft:planks-3
rule18=0,100,minecraft:wooden_slab-3
rule19=0,100,minecraft:jungle_stairs-0
rule20=0,100,minecraft:jungle_stairs-1
rule21=0,100,minecraft:fence-0
rule22=0,100,minecraft:trapdoor-2
rule23=0,100,preserveBlock

layer
23,23,23,23,23,23,23,23,23,23,23,23,23,23
23,23,23,23,23,23,23,23,23,23,23,23,23,23
23,23,23,23,23,23,23,23,23,23,23,23,23,23
23,23,23,23,23,23,23,23,23,23,23,23,23,23
23,23,23,23,23,23,1,1,1,1,23,23,23,23
23,23,23,23,23,1,1,2,2,1,1,23,23,23
23,23,23,23,23,1,2,2,2,2,1,23,23,23
23,23,23,23,23,1,2,2,2,2,1,23,23,23
23,23,23,23,23,1,1,2,2,1,1,23,23,23
23,23,23,23,23,23,1,1,1,1,23,23,23,23
23,23,23,23,23,23,23,23,23,23,23,23,23,23
23,23,23,23,23,23,23,23,23,23,23,23,23,23
23,23,23,23,23,23,23,23,23,23,23,23,23,23
23,23,23,23,23,23,23,23,23,23,23,23,23,23
23,23,23,23,23,23,23,23,23,23,23,23,23,23
23,23,23,23,23,23,23,23,23,23,23,23,23,23
endlayer

layer
23,23,23,23,23,23,23,23,23,23,23,23,23,23
23,23,23,23,23,23,23,23,23,23,23,23,23,23
23,23,23,23,23,23,23,23,23,23,23,23,23,23
23,23,23,23,23,23,23,23,23,23,23,23,23,23
23,23,23,23,23,23,3,23,23,3,23,23,23,23
23,23,23,23,23,23,4,6,6,5,4,23,23,23
23,23,23,23,23,7,6,6,6,6,3,23,23,23
23,23,23,23,23,3,6,6,6,6,4,23,23,23
23,23,23,23,23,23,4,6,6,5,4,23,23,23
23,23,23,23,23,23,3,23,8,3,23,23,23,23
23,23,23,23,23,23,23,23,23,23,23,23,23,23
23,23,23,23,23,23,23,23,23,23,23,23,23,23
23,23,23,23,23,23,23,23,23,23,23,23,23,23
23,23,23,23,23,23,23,23,23,23,23,23,23,23
23,23,23,23,23,23,23,23,23,23,23,23,23,23
23,23,23,23,23,23,23,23,23,23,23,23,23,23
endlayer

layer
23,23,23,23,23,23,23,23,23,23,23,23,23,23
23,23,23,23,23,23,23,23,23,23,23,23,23,23
23,23,23,23,23,23,23,23,23,23,23,23,23,23
23,23,23,23,23,23,23,23,23,23,23,23,23,23
23,23,23,23,23,23,11,XX,23,9,23,23,23,23
23,23,23,23,23,23,7,6,6,5,23,23,23,23
23,23,23,23,23,7,6,XX,6,6,9,23,23,23
23,23,23,23,23,12,6,6,6,6,5,23,23,23
23,23,23,23,23,23,7,6,6,5,23,23,23,23
23,23,23,23,23,23,12,23,8,13,23,23,23,23
23,23,23,23,23,23,23,23,23,23,23,23,23,23
23,23,23,23,23,23,23,23,23,23,23,23,23,23
23,23,23,23,23,23,23,23,23,23,23,23,23,23
23,23,23,23,23,23,23,23,23,23,23,23,23,23
23,23,23,23,23,23,23,23,23,23,23,23,23,23
23,23,23,23,23,23,23,23,23,23,23,23,23,23
endlayer

layer
23,23,23,23,23,23,23,23,23,23,23,23,23,23
23,23,23,23,23,23,23,23,23,23,23,23,23,23
23,23,23,23,23,23,23,23,23,23,23,23,23,23
23,23,23,23,23,23,23,23,23,23,23,23,23,23
23,23,23,23,23,23,23,XX,23,23,23,23,23,23
23,23,23,23,23,23,7,6,6,5,23,23,23,23
23,23,23,23,23,7,6,XX,XX,6,23,23,23,23
23,23,23,23,23,23,6,6,6,6,5,23,23,23
23,23,23,23,23,23,7,6,6,5,23,23,23,23
23,23,23,23,23,23,23,8,8,23,23,23,23,23
23,23,23,23,23,23,23,23,23,23,23,23,23,23
23,23,23,23,23,23,23,23,23,23,23,23,23,23
23,23,23,23,23,23,23,23,23,23,23,23,23,23
23,23,23,23,23,23,23,23,23,23,23,23,23,23
23,23,23,23,23,23,23,23,23,23,23,23,23,23
23,23,23,23,23,23,23,23,23,23,23,23,23,23
endlayer

layer
23,23,23,23,23,23,23,23,23,23,23,23,23,23
23,23,23,23,23,23,23,23,23,23,23,23,23,23
23,23,23,23,23,23,23,23,23,23,23,23,23,23
23,23,23,23,23,23,23,23,23,23,23,23,23,23
23,23,23,23,23,23,23,XX,23,23,23,23,23,23
23,23,23,23,23,23,7,6,6,5,23,23,23,23
23,23,23,23,23,7,6,XX,XX,6,23,23,23,23
23,23,23,23,23,23,6,6,6,6,5,23,23,23
23,23,23,23,23,23,7,6,6,5,23,23,23,23
23,23,23,23,23,23,23,8,8,23,23,23,23,23
23,23,23,23,23,23,23,23,23,23,23,23,23,23
23,23,23,23,23,23,23,23,23,23,23,23,23,23
23,23,23,23,23,23,23,23,23,23,23,23,23,23
23,23,23,23,23,23,23,23,23,23,23,23,23,23
23,23,23,23,23,23,23,23,23,23,23,23,23,23
23,23,23,23,23,23,23,23,23,23,23,23,23,23
endlayer

layer
23,23,23,23,23,23,23,23,23,23,23,23,23,23
23,23,23,23,23,23,23,23,23,23,23,23,23,23
23,23,23,23,23,23,23,23,23,23,23,23,23,23
23,23,23,23,23,23,23,23,23,23,23,23,23,23
23,23,23,23,23,23,23,XX,23,23,23,23,23,23
23,23,23,23,23,23,7,6,6,5,23,23,23,23
23,23,23,23,23,7,6,XX,XX,6,23,23,23,23
23,23,23,23,23,23,6,6,6,6,5,23,23,23
23,23,23,23,23,23,7,6,6,5,23,23,23,23
23,23,23,23,23,23,23,8,8,23,23,23,23,23
23,23,23,23,23,23,23,23,23,23,23,23,23,23
23,23,23,23,23,23,23,23,23,23,23,23,23,23
23,23,23,23,23,23,23,23,23,23,23,23,23,23
23,23,23,23,23,23,23,23,23,23,23,23,23,23
23,23,23,23,23,23,23,23,23,23,23,23,23,23
23,23,23,23,23,23,23,23,23,23,23,23,23,23
endlayer

layer
23,23,23,23,23,23,23,23,23,23,23,23,23,23
23,23,23,23,23,23,23,23,23,23,23,23,23,23
23,23,23,23,23,23,23,23,23,23,23,23,23,23
23,23,23,23,23,23,23,23,23,23,23,23,23,23
23,23,23,23,23,23,23,XX,23,23,23,23,23,23
23,23,23,23,23,23,7,6,6,5,23,23,23,23
23,23,23,23,23,7,6,XX,XX,6,23,23,23,23
23,23,23,23,23,23,6,6,6,6,5,23,23,23
23,23,23,23,23,23,7,6,6,5,23,23,23,23
23,23,23,23,23,23,23,8,8,23,23,23,23,23
23,23,23,23,23,23,23,23,23,23,23,23,23,23
23,23,23,23,23,23,23,23,23,23,23,23,23,23
23,23,23,23,23,23,23,23,23,23,23,23,23,23
23,23,23,23,23,23,23,23,23,23,23,23,23,23
23,23,23,23,23,23,23,23,23,23,23,23,23,23
23,23,23,23,23,23,23,23,23,23,23,23,23,23
endlayer

layer
23,23,23,23,23,23,23,23,23,23,23,23,23,23
23,23,23,23,23,23,23,23,23,23,23,23,23,23
23,23,23,23,23,23,23,23,23,23,23,23,23,23
23,23,23,23,23,23,23,23,23,23,23,23,23,23
23,23,23,23,23,23,23,XX,23,23,23,23,23,23
23,23,23,23,23,23,7,6,6,5,23,23,23,23
23,23,23,23,23,7,6,XX,XX,6,23,23,23,23
23,23,23,23,23,23,6,6,6,6,5,23,23,23
23,23,23,23,23,23,7,6,6,5,23,23,23,23
23,23,23,23,23,23,23,8,8,23,23,23,23,23
23,23,23,23,23,23,23,23,23,23,23,23,23,23
23,23,23,23,23,23,23,23,23,23,23,23,23,23
23,23,23,23,23,23,23,23,23,23,23,23,23,23
23,23,23,23,23,23,23,23,23,23,23,23,23,23
23,23,23,23,23,23,23,23,23,23,23,23,23,23
23,23,23,23,23,23,23,23,23,23,23,23,23,23
endlayer


layer
23,23,23,23,23,23,23,23,23,23,23,23,23,23
23,23,23,23,23,23,23,23,23,23,23,23,23,23
23,23,23,23,23,23,23,23,23,23,23,23,23,23
23,23,23,23,23,23,23,23,23,23,23,23,23,23
23,23,23,23,23,23,23,XX,23,23,23,23,23,23
23,23,23,23,23,23,7,6,6,5,23,23,23,23
23,23,23,23,23,7,6,XX,XX,6,23,23,23,23
23,23,23,23,23,23,6,6,6,6,5,23,23,23
23,23,23,23,23,23,7,6,6,5,23,23,23,23
23,23,23,23,23,23,23,8,8,23,23,23,23,23
23,23,23,23,23,23,23,23,23,23,23,23,23,23
23,23,23,23,23,23,23,23,23,23,23,23,23,23
23,23,23,23,23,23,23,23,23,23,23,23,23,23
23,23,23,23,23,23,23,23,23,23,23,23,23,23
23,23,23,23,23,23,23,23,23,23,23,23,23,23
23,23,23,23,23,23,23,23,23,23,23,23,23,23
endlayer

layer
23,23,23,23,23,23,23,23,23,23,23,23,23,23
23,23,23,23,23,23,23,23,23,23,23,23,23,23
23,23,23,23,23,23,23,23,23,23,23,23,23,23
23,23,23,23,23,23,23,23,23,23,23,23,23,23
23,23,23,23,23,23,23,XX,XX,23,23,23,23,23
23,23,23,23,23,23,7,6,6,5,23,23,23,23
23,23,23,23,14,7,6,6,6,5,23,23,23,23
23,23,23,23,14,14,7,6,6,6,5,23,23,23
23,23,23,23,14,14,7,6,6,5,23,23,23,23
23,23,23,23,23,14,14,8,8,23,23,23,23,23
23,23,23,23,23,23,23,23,23,23,23,23,23,23
23,23,23,23,23,23,23,23,23,23,23,23,23,23
23,23,23,23,23,23,23,23,23,23,23,23,23,23
23,23,23,23,23,23,23,23,23,23,23,23,23,23
23,23,23,23,23,23,23,23,23,23,23,23,23,23
23,23,23,23,23,23,23,23,23,23,23,23,23,23
endlayer

layer
23,23,23,23,23,23,23,23,23,23,23,23,23,23
23,23,23,23,23,23,23,23,23,23,23,23,23,23
23,23,23,23,23,23,23,23,23,23,23,23,23,23
23,23,23,23,23,23,23,23,23,23,23,23,23,23
23,23,23,23,23,23,23,XX,XX,23,23,23,23,23
23,23,23,23,23,23,7,6,6,5,23,23,23,23
23,23,23,23,14,7,6,XX,6,5,23,23,23,23
23,23,23,23,14,14,6,6,6,5,23,23,23,23
23,23,23,23,14,14,7,6,6,5,23,23,23,23
23,23,23,23,23,14,14,14,8,23,23,23,23,23
23,23,23,23,23,23,23,23,23,23,23,23,23,23
23,23,23,23,23,23,23,23,23,23,23,23,23,23
23,23,23,23,23,23,23,23,23,23,23,23,23,23
23,23,23,23,23,23,23,23,23,23,23,23,23,23
23,23,23,23,23,23,23,23,23,23,23,23,23,23
23,23,23,23,23,23,23,23,23,23,23,23,23,23
endlayer

layer
23,23,23,23,23,23,23,23,23,23,23,23,23,23
23,23,23,23,23,23,23,23,23,23,23,23,23,23
23,23,23,23,23,23,23,23,23,23,23,23,23,23
23,23,23,23,23,23,23,23,23,23,23,23,23,23
23,23,23,23,23,14,14,XX,23,23,23,23,23,23
23,23,23,23,23,23,7,6,6,5,23,23,23,23
23,23,23,23,14,7,6,XX,6,5,23,23,23,23
23,23,23,23,14,14,7,6,6,5,23,23,23,23
23,23,23,23,14,14,7,6,6,5,23,23,23,23
23,23,23,23,23,23,23,8,8,23,23,23,23,23
23,23,23,23,23,23,23,23,23,23,23,23,23,23
23,23,23,23,23,23,23,23,23,23,23,23,23,23
23,23,23,23,23,23,23,23,23,23,23,23,23,23
23,23,23,23,23,23,23,23,23,23,23,23,23,23
23,23,23,23,23,23,23,23,23,23,23,23,23,23
23,23,23,23,23,23,23,23,23,23,23,23,23,23
endlayer

layer
23,23,23,23,23,23,23,23,23,23,23,23,23,23
23,23,23,23,23,23,23,23,23,23,23,23,23,23
23,23,23,23,23,23,23,23,23,23,23,23,23,23
23,23,23,23,23,23,23,23,23,23,23,23,23,23
23,23,23,23,14,14,14,14,14,14,14,14,23,23
23,23,23,23,23,14,7,6,6,5,14,14,23,23
23,23,23,23,23,7,6,XX,XX,6,14,14,23,23
23,23,23,23,14,14,7,6,6,6,14,14,23,23
23,23,23,23,14,14,14,6,6,5,14,14,23,23
23,23,23,23,23,23,23,8,8,23,23,23,23,23
23,23,23,23,23,23,23,23,23,23,23,23,23,23
23,23,23,23,23,23,23,23,23,23,23,23,23,23
23,23,23,23,23,23,23,23,23,23,23,23,23,23
23,23,23,23,23,23,23,23,23,23,23,23,23,23
23,23,23,23,23,23,23,23,23,23,23,23,23,23
23,23,23,23,23,23,23,23,23,23,23,23,23,23
endlayer


layer
0,0,0,0,0,0,0,0,0,0,0,0,0,0
0,0,0,0,0,0,0,0,0,0,0,0,0,0
0,0,0,0,0,0,0,0,0,0,0,0,0,0
0,0,0,0,0,0,0,0,0,0,0,0,0,0
0,0,0,0,0,0,0,10,14,14,14,0,0,0
0,0,0,0,0,0,14,6,6,14,14,14,0,0
0,0,0,0,0,7,6,10,6,6,14,14,0,0
0,0,0,0,0,0,14,6,6,6,14,14,0,0
0,0,0,0,0,0,7,6,6,5,14,14,0,0
0,0,0,0,0,0,0,0,8,0,0,0,0,0
0,0,0,0,0,0,0,0,0,0,0,0,0,0
0,0,0,0,0,0,0,0,0,0,0,0,0,0
0,0,0,0,0,0,0,0,0,0,0,0,0,0
0,0,0,0,0,0,0,0,0,0,0,0,0,0
0,0,0,0,0,0,0,0,0,0,0,0,0,0
0,0,0,0,0,0,0,0,0,0,0,0,0,0
endlayer

layer
0,0,0,0,0,0,0,0,0,0,0,0,0,0
0,0,0,0,0,0,0,0,0,0,0,0,0,0
0,0,0,0,0,0,0,0,0,0,0,0,0,0
0,0,0,0,0,0,0,0,0,0,0,0,0,0
0,0,0,0,0,0,0,10,10,0,0,0,0,0
0,0,0,0,0,0,7,6,6,5,14,0,0,0
0,0,0,0,0,7,6,6,10,6,14,0,0,0
0,0,0,0,0,0,7,6,6,5,14,0,0,0
0,0,0,0,0,0,7,6,6,5,0,0,0,0
0,0,0,0,0,0,0,0,8,0,0,0,0,0
0,0,0,0,0,0,0,0,0,0,0,0,0,0
0,0,0,0,0,0,0,0,0,0,0,0,0,0
0,0,0,0,0,0,0,0,0,0,0,0,0,0
0,0,0,0,0,0,0,0,0,0,0,0,0,0
0,0,0,0,0,0,0,0,0,0,0,0,0,0
0,0,0,0,0,0,0,0,0,0,0,0,0,0
endlayer

layer
0,0,0,0,0,0,0,0,0,0,0,0,0,0
0,0,0,0,0,0,0,0,0,0,0,0,0,0
0,0,0,0,0,0,0,0,0,0,0,0,0,0
0,0,0,0,0,0,0,0,0,0,0,0,0,0
0,0,0,0,0,0,0,10,10,0,0,0,0,0
0,0,0,0,0,0,7,6,6,5,14,14,0,0
0,0,0,0,0,7,6,6,6,5,14,14,0,0
0,0,0,0,0,0,7,6,6,5,14,14,0,0
0,0,0,0,0,0,0,6,6,14,14,14,0,0
0,0,0,0,0,0,0,14,14,14,14,0,0,0
0,0,0,0,0,0,0,0,0,0,0,0,0,0
0,0,0,0,0,0,0,0,0,0,0,0,0,0
0,0,0,0,0,0,0,0,0,0,0,0,0,0
0,0,0,0,0,0,0,0,0,0,0,0,0,0
0,0,0,0,0,0,0,0,0,0,0,0,0,0
0,0,0,0,0,0,0,0,0,0,0,0,0,0
endlayer

layer
0,0,0,0,0,0,0,0,0,0,0,0,0,0
0,0,0,0,0,0,0,0,0,0,0,0,0,0
0,0,0,0,0,0,0,0,0,0,0,0,0,0
0,0,0,0,0,0,0,0,0,0,0,0,0,0
0,0,0,0,0,0,0,10,10,0,0,0,0,0
0,0,0,0,0,0,0,6,6,5,14,14,0,0
0,0,0,0,0,7,6,6,6,5,14,14,0,0
0,0,0,0,0,0,7,6,6,6,14,14,0,0
0,0,0,0,0,0,0,6,6,5,14,14,0,0
0,0,0,0,0,0,0,8,8,14,14,0,0,0
0,0,0,0,0,0,0,0,0,0,0,0,0,0
0,0,0,0,0,0,0,0,0,0,0,0,0,0
0,0,0,0,0,0,0,0,0,0,0,0,0,0
0,0,0,0,0,0,0,0,0,0,0,0,0,0
0,0,0,0,0,0,0,0,0,0,0,0,0,0
0,0,0,0,0,0,0,0,0,0,0,0,0,0
endlayer

layer
0,0,0,0,0,0,0,0,0,0,0,0,0,0
0,0,0,0,0,0,0,0,0,0,0,0,0,0
0,0,0,0,0,0,0,0,0,0,0,0,0,0
0,0,0,0,0,0,0,0,0,0,0,0,0,0
0,0,0,0,0,0,6,10,10,0,0,0,0,0
0,0,0,0,0,0,6,6,6,5,14,0,0,0
0,0,0,0,0,7,6,6,6,14,14,14,0,0
0,0,0,0,0,0,7,6,6,6,6,14,15,0
0,0,0,0,0,0,0,6,6,14,14,14,0,0
0,0,0,0,0,0,0,8,6,0,14,0,0,0
0,0,0,0,0,0,0,0,0,0,0,0,0,0
0,0,0,0,0,0,0,0,0,0,0,0,0,0
0,0,0,0,0,0,0,0,0,0,0,0,0,0
0,0,0,0,0,0,0,0,0,0,0,0,0,0
0,0,0,0,0,0,0,0,0,0,0,0,0,0
0,0,0,0,0,0,0,0,0,0,0,0,0,0
endlayer

layer
0,0,0,0,0,0,0,0,0,0,0,0,0,0
0,0,0,0,0,14,0,0,0,0,0,0,0,0
0,0,0,0,14,14,14,0,0,0,0,0,0,0
0,0,0,14,14,6,16,14,0,0,0,0,0,0
0,0,0,0,14,14,14,0,10,0,0,0,0,0
0,0,0,0,0,14,7,6,6,5,0,0,0,0
0,0,0,0,0,7,6,6,10,16,14,0,0,0
0,0,0,0,0,0,7,6,6,14,14,14,0,0
0,0,0,0,0,0,7,6,6,5,14,0,0,0
0,0,0,0,0,0,0,8,6,0,0,0,0,0
0,0,0,0,0,0,0,0,6,0,0,0,0,0
0,0,0,0,0,0,0,0,0,0,0,0,0,0
0,0,0,0,0,0,0,0,0,0,0,0,0,0
0,0,0,0,0,0,0,0,0,0,0,0,0,0
0,0,0,0,0,0,0,0,0,0,0,0,0,0
0,0,0,0,0,0,0,0,0,0,0,0,0,0
endlayer

layer
0,0,0,0,0,0,0,0,0,0,0,0,0,0
0,0,0,0,0,0,0,0,0,0,15,0,0,0
0,0,0,0,0,14,0,0,0,15,15,15,0,0
0,0,0,0,14,16,14,0,0,15,6,15,0,0
0,0,0,0,0,14,0,10,10,6,15,15,0,0
0,0,0,0,0,6,7,6,6,5,15,15,0,0
0,0,0,0,0,7,6,6,6,6,6,15,15,0
0,0,0,0,0,0,0,6,6,5,4,4,0,0
0,0,0,0,0,0,0,6,6,5,4,0,0,0
0,0,0,0,0,0,0,6,8,14,0,0,0,0
0,0,0,0,0,0,0,0,14,14,14,0,0,0
0,0,0,0,0,0,0,14,14,6,14,15,0,0
0,0,0,0,0,0,0,0,15,14,15,0,0,0
0,0,0,0,0,0,0,0,0,15,0,0,0,0
0,0,0,0,0,0,0,0,0,0,0,0,0,0
0,0,0,0,0,0,0,0,0,0,0,0,0,0
endlayer

layer
0,0,0,0,0,0,0,0,0,0,0,0,0,0
0,0,0,0,0,0,0,0,0,4,4,4,0,0
0,0,0,0,0,0,0,0,4,4,6,4,4,0
0,0,0,0,17,17,17,17,17,17,17,4,4,0
0,0,0,14,17,18,18,18,18,18,17,15,0,0
0,14,14,14,17,19,19,6,6,18,17,15,15,0
15,14,14,14,6,7,6,6,6,18,17,6,15,15
15,14,14,14,17,6,20,6,6,18,17,4,15,0
15,14,14,14,17,18,18,6,6,18,17,4,0,0
0,0,16,14,17,18,18,18,18,18,17,0,0,0
0,0,0,14,17,17,6,17,17,17,17,0,0,0
0,0,0,0,0,0,6,0,14,14,15,0,0,0
0,0,0,0,0,0,15,0,0,14,0,0,0,0
0,0,0,0,0,0,15,0,0,0,0,0,0,0
0,0,0,0,0,0,0,0,0,0,0,0,0,0
0,0,0,0,0,0,0,0,0,0,0,0,0,0
endlayer

layer
0,0,0,0,0,0,0,0,0,0,0,0,0,0
0,0,0,0,0,0,0,0,0,0,0,0,0,0
0,0,0,0,0,0,0,0,0,4,4,4,0,0
0,0,0,0,21,21,21,21,21,21,21,4,0,0
0,0,0,0,21,0,0,10,0,0,21,0,0,0
0,0,0,14,21,0,7,6,6,5,21,15,15,0
0,0,14,14,21,22,18,6,6,0,21,15,15,0
0,15,14,6,21,6,0,6,6,5,21,4,4,0
0,0,15,14,21,0,7,6,6,5,21,0,0,0
0,0,0,14,21,0,0,0,0,0,21,0,0,0
0,0,0,0,21,21,21,21,21,21,21,0,0,0
0,0,0,0,0,14,14,14,0,0,0,0,0,0
0,0,0,0,15,14,6,14,15,0,0,0,0,0
0,0,0,0,0,14,14,14,0,0,0,0,0,0
0,0,0,0,0,0,4,0,0,0,0,0,0,0
0,0,0,0,0,0,0,0,0,0,0,0,0,0
endlayer

layer
0,0,0,0,0,0,0,0,0,0,0,0,0,0
0,0,0,0,0,0,0,0,0,0,0,0,0,0
0,0,0,0,0,0,0,0,0,0,0,0,0,0
0,0,0,0,0,0,0,0,0,0,0,0,0,0
0,0,0,0,0,0,0,10,10,0,0,0,0,0
0,0,0,0,0,0,7,6,6,5,0,0,0,0
0,0,0,14,0,0,7,6,6,5,0,0,0,0
0,0,14,14,14,18,7,6,6,5,0,0,0,0
0,0,0,14,0,0,0,6,6,5,0,0,0,0
0,0,0,0,0,0,0,0,0,0,0,0,0,0
0,0,0,0,0,0,0,0,0,0,0,0,0,0
0,0,0,0,0,0,14,0,0,0,0,0,0,0
0,0,0,0,0,14,14,14,0,0,0,0,0,0
0,0,0,0,0,0,14,0,0,0,0,0,0,0
0,0,0,0,0,0,0,0,0,0,0,0,0,0
0,0,0,0,0,0,0,0,0,0,0,0,0,0
endlayer

layer
0,0,0,0,0,0,0,0,0,0,0,0,0,0
0,0,0,0,0,0,0,0,0,0,0,0,0,0
0,0,0,0,0,0,0,0,0,0,0,0,0,0
0,0,0,0,0,0,0,0,0,0,0,0,0,0
0,0,0,0,0,0,0,10,10,0,0,0,0,0
0,0,0,0,0,0,7,6,6,5,0,0,0,0
0,0,0,0,0,0,7,6,6,5,0,0,0,0
0,0,0,0,0,0,7,6,6,5,0,0,0,0
0,0,0,0,0,0,7,6,6,5,0,0,0,0
0,0,0,0,0,0,0,6,6,14,0,0,0,0
0,0,0,0,0,14,14,6,6,14,15,0,0,0
0,0,0,0,0,14,14,6,14,14,15,0,0,0
0,0,0,0,15,14,14,14,14,14,14,0,0,0
0,0,0,0,0,14,14,14,14,14,0,0,0,0
0,0,0,0,0,4,14,14,14,14,0,0,0,0
0,0,0,0,0,0,0,4,0,0,0,0,0,0
endlayer

layer
0,0,0,0,0,0,0,0,0,0,0,0,0,0
0,0,0,0,0,0,0,0,0,0,0,0,0,0
0,0,0,0,0,0,0,0,0,0,0,0,0,0
0,0,0,0,0,0,0,0,0,0,0,0,0,0
0,0,0,0,0,0,0,10,10,0,0,0,0,0
0,0,0,0,0,0,7,6,6,5,0,0,0,0
0,0,0,0,0,0,7,6,6,5,0,0,0,0
0,0,0,0,0,0,0,6,6,5,0,0,0,0
0,0,0,0,0,0,7,6,6,5,0,0,0,0
0,0,0,0,0,0,0,15,15,0,0,0,0,0
0,0,0,0,0,0,0,14,14,14,0,0,0,0
0,0,0,0,0,0,14,14,14,0,0,0,0,0
0,0,0,0,0,14,14,6,14,14,0,0,0,0
0,0,0,0,0,0,14,14,14,0,0,0,0,0
0,0,0,0,0,0,0,14,0,0,0,0,0,0
0,0,0,0,0,0,0,0,0,0,0,0,0,0
endlayer

layer
0,0,0,0,0,0,0,0,0,0,0,0,0,0
0,0,0,0,0,0,0,0,0,0,0,0,0,0
0,0,0,0,0,0,0,14,14,0,0,0,0,0
0,0,0,0,14,14,14,14,16,14,16,0,0,0
0,0,0,14,14,14,14,14,14,16,16,16,0,0
0,0,0,14,14,14,14,6,6,16,14,16,14,0
0,0,0,14,14,14,14,6,6,14,14,14,14,0
0,0,0,14,14,14,14,6,6,14,14,14,14,0
0,0,0,14,14,14,14,6,6,14,14,14,14,0
0,0,0,15,14,14,14,14,14,14,14,14,15,0
0,0,0,0,15,14,14,14,14,14,14,15,0,0
0,0,0,15,15,14,14,14,14,14,15,0,0,0
0,0,0,15,14,14,14,14,14,14,14,0,0,0
0,0,0,0,0,0,0,14,14,0,0,0,0,0
0,0,0,0,0,0,0,0,0,0,0,0,0,0
0,0,0,0,0,0,0,0,0,0,0,0,0,0
endlayer

layer
0,0,0,0,0,0,0,0,0,0,0,0,0,0
0,0,0,0,0,0,0,0,0,0,0,0,0,0
0,0,0,0,0,0,0,0,0,0,0,0,0,0
0,0,0,0,0,0,0,14,14,0,0,0,0,0
0,0,0,0,0,14,14,14,14,14,14,0,0,0
0,0,0,0,14,14,14,6,6,14,14,16,15,0
0,0,0,0,14,14,14,6,6,14,14,14,15,0
0,0,0,0,14,14,14,14,6,14,14,14,14,0
0,0,0,0,14,14,14,14,14,14,14,14,0,0
0,0,0,0,0,14,14,14,14,14,14,0,0,0
0,0,0,0,0,0,14,14,14,14,0,0,0,0
0,0,0,0,0,0,14,14,14,0,0,0,0,0
0,0,0,0,0,0,0,14,14,0,0,0,0,0
0,0,0,0,0,0,0,0,0,0,0,0,0,0
0,0,0,0,0,0,0,0,0,0,0,0,0,0
0,0,0,0,0,0,0,0,0,0,0,0,0,0
endlayer

layer
0,0,0,0,0,0,0,15,15,0,0,0,0,0
0,0,0,0,15,0,15,14,14,4,4,15,0,0
0,0,0,15,0,15,14,14,14,4,15,15,15,0
0,0,0,15,15,14,14,14,14,14,14,15,15,0
0,0,0,15,14,14,14,14,14,14,14,14,0,0
0,0,0,14,14,14,14,6,6,14,14,14,14,15
0,0,4,14,14,14,14,6,6,14,14,14,14,0
0,0,15,15,14,14,14,14,14,14,14,14,0,0
0,0,4,4,15,14,14,14,14,14,14,0,0,0
0,0,0,4,15,4,14,14,14,14,0,0,0,0
0,0,0,0,15,4,0,14,14,0,0,0,0,0
0,0,0,0,0,0,0,14,0,0,0,0,0,0
0,0,0,0,0,0,0,0,0,0,0,0,0,0
0,0,0,0,0,0,0,0,0,0,0,0,0,0
0,0,0,0,0,0,0,0,0,0,0,0,0,0
0,0,0,0,0,0,0,0,0,0,0,0,0,0
endlayer

layer
0,0,0,0,0,0,0,0,0,0,0,0,0,0
0,0,0,0,0,0,0,0,14,0,0,0,0,0
0,0,0,0,0,15,15,14,14,14,15,0,0,0
0,0,0,0,15,15,15,14,14,14,14,0,0,0
0,0,0,0,0,15,14,14,14,14,14,14,0,0
0,0,0,0,14,14,14,14,6,14,14,14,14,0
0,0,0,0,14,14,14,14,14,14,14,14,0,0
0,0,0,15,15,14,14,14,14,14,14,0,0,0
0,0,0,0,0,4,14,14,14,14,0,0,0,0
0,0,0,0,0,0,0,14,14,0,0,0,0,0
0,0,0,0,0,0,0,0,0,0,0,0,0,0
0,0,0,0,0,0,0,0,0,0,0,0,0,0
0,0,0,0,0,0,0,0,0,0,0,0,0,0
0,0,0,0,0,0,0,0,0,0,0,0,0,0
0,0,0,0,0,0,0,0,0,0,0,0,0,0
0,0,0,0,0,0,0,0,0,0,0,0,0,0
endlayer

layer
0,0,0,0,0,0,0,0,0,0,0,0,0,0
0,0,0,0,0,0,0,0,0,0,0,0,0,0
0,0,0,0,0,0,0,0,14,4,0,0,0,0
0,0,0,0,0,0,15,14,14,14,15,0,0,0
0,0,0,0,0,15,4,14,14,14,14,0,0,0
0,0,0,0,0,14,14,14,14,14,14,14,0,0
0,0,0,0,0,14,14,14,14,14,14,0,0,0
0,0,0,0,0,15,14,14,14,14,4,0,0,0
0,0,0,0,0,0,0,14,14,4,0,0,0,0
0,0,0,0,0,0,0,0,0,0,0,0,0,0
0,0,0,0,0,0,0,0,0,0,0,0,0,0
0,0,0,0,0,0,0,0,0,0,0,0,0,0
0,0,0,0,0,0,0,0,0,0,0,0,0,0
0,0,0,0,0,0,0,0,0,0,0,0,0,0
0,0,0,0,0,0,0,0,0,0,0,0,0,0
0,0,0,0,0,0,0,0,0,0,0,0,0,0
endlayer

