# Limbo Dungeon - Hall of Tormented Souls
# Created by Ruins mod version 15.1 Ingame Parser
# authoring Player: Jordan_Greywolf
# Note: Place in \templateparser folder.
# Last Updated 19 Feb 2016
# Updated to MC 1.11: 12 Jan 2017

weight=1
embed_into_distance=7
acceptable_target_blocks=
unacceptable_target_blocks=flowing_water,water,flowing_lava,lava
dimensions=7,9,13
allowable_overhang=99999
max_leveling=2
leveling_buffer=0
preserve_water=0
preserve_lava=0

rule1=0,100,preserveBlock
rule2=0,100,minecraft:nether_brick-0
rule3=0,100,minecraft:nether_brick_stairs-4
rule4=0,100,minecraft:nether_brick_stairs-5
rule5=0,100,minecraft:nether_brick_stairs-7
rule6=0,100,minecraft:nether_brick_stairs-6
rule7=0,100,minecraft:netherrack-0
rule8=0,100,minecraft:double_stone_slab-0
rule9=0,100,minecraft:stone_slab-0
rule10=0,100,minecraft:fire-15
rule11=0,100,minecraft:nether_brick_fence-0

rule12=0,100,CommandBlock:RUINSTRIGGER /summon zombie ~0 ~0 ~0 {ActiveEffects:[{Id:12,Amplifier:1,Duration:999999},{Id:14,Amplifier:1,Duration:999999,Ambient:1},{Id:10,Amplifier:1,Duration:999999,Ambient:1},{Id:5,Amplifier:1,Duration:999999,Ambient:1}],PersistenceRequired:1}:@,CommandBlock:RUINSTRIGGER /summon skeleton ~0 ~0 ~0 {ActiveEffects:[{Id:12,Amplifier:1,Duration:999999},{Id:14,Amplifier:1,Duration:999999,Ambient:1},{Id:10,Amplifier:1,Duration:999999,Ambient:1},{Id:5,Amplifier:1,Duration:999999,Ambient:1}],PersistenceRequired:1}:@,CommandBlock:RUINSTRIGGER /summon villager ~0 ~0 ~0 {ActiveEffects:[{Id:12,Amplifier:1,Duration:999999},{Id:14,Amplifier:1,Duration:999999,Ambient:1},{Id:10,Amplifier:1,Duration:999999,Ambient:1},{Id:5,Amplifier:1,Duration:999999,Ambient:1}],PersistenceRequired:1}:@,CommandBlock:RUINSTRIGGER /summon blaze ~0 ~0 ~0 {ActiveEffects:[{Id:12,Amplifier:1,Duration:999999},{Id:14,Amplifier:1,Duration:999999,Ambient:1},{Id:10,Amplifier:1,Duration:999999,Ambient:1},{Id:5,Amplifier:1,Duration:999999,Ambient:1}],PersistenceRequired:1}:@
rule13=0,100,minecraft:stained_glass-14

rule14=0,100,minecraft:stone_slab-6

layer
1,1,1,1,1,1,1,1,1,1,1,1,1
1,2,2,2,2,2,2,2,2,2,2,2,1
1,2,2,2,2,2,2,2,2,2,2,2,1
3,2,2,2,2,2,2,2,2,2,2,2,3
2,2,2,2,2,2,2,2,2,2,2,2,2
4,2,2,2,2,2,2,2,2,2,2,2,4
1,2,2,2,2,2,2,2,2,2,2,2,1
1,2,2,2,2,2,2,2,2,2,2,2,1
1,1,1,1,1,1,1,1,1,1,1,1,1
endlayer

layer
2,6,3,3,3,3,3,3,3,3,3,5,2
4,7,2,7,2,7,2,7,2,7,2,7,4
3,2,2,2,2,2,2,2,2,2,2,2,3
8,9,9,9,9,9,9,9,9,9,9,9,8
9,9,9,9,9,9,9,9,9,9,9,9,9
8,9,9,9,9,9,9,9,9,9,9,9,8
4,2,2,2,2,2,2,2,2,2,2,2,4
3,7,2,7,2,7,2,7,2,7,2,7,3
2,6,4,4,4,4,4,4,4,4,4,5,2
endlayer

layer
2,2,2,2,2,2,2,2,2,2,2,2,2
2,10,11,10,11,10,11,10,11,10,11,10,2
2,11,11,11,11,11,11,11,11,11,11,11,2
11,0,0,0,0,0,0,0,0,0,0,0,11
0,0,0,0,0,0,0,0,0,0,0,0,0
11,0,0,0,0,0,0,0,0,0,0,0,11
2,11,11,11,11,11,11,11,11,11,11,11,2
2,10,11,10,11,10,11,10,11,10,11,10,2
2,2,2,2,2,2,2,2,2,2,2,2,2
endlayer

layer
2,2,2,2,2,2,2,2,2,2,2,2,2
2,12,0,0,0,12,0,12,0,0,0,12,2
2,0,11,0,11,0,11,0,11,0,11,0,2
11,0,0,0,0,0,0,0,0,0,0,0,11
0,0,0,0,0,0,0,0,0,0,0,0,0
11,0,0,0,0,0,0,0,0,0,0,0,11
2,0,11,0,11,0,11,0,11,0,11,0,2
2,12,0,0,0,12,0,12,0,0,0,12,2
2,2,2,2,2,2,2,2,2,2,2,2,2
endlayer

layer
2,2,2,2,2,2,2,2,2,2,2,2,2
2,0,11,0,11,0,11,0,11,0,11,0,2
2,11,11,11,11,11,11,11,11,11,11,11,2
4,0,0,0,0,0,0,0,0,0,0,0,4
0,0,0,0,0,0,0,0,0,0,0,0,0
3,0,0,0,0,0,0,0,0,0,0,0,3
2,11,11,11,11,11,11,11,11,11,11,11,2
2,0,11,0,11,0,11,0,11,0,11,0,2
2,2,2,2,2,2,2,2,2,2,2,2,2
endlayer

layer
2,2,2,2,2,2,2,2,2,2,2,2,2
2,13,2,13,2,13,2,13,2,13,2,13,2
2,2,2,2,2,2,2,2,2,2,2,2,2
2,13,2,13,2,13,2,13,2,13,2,13,2
2,2,2,2,2,2,2,2,2,2,2,2,2
2,13,2,13,2,13,2,13,2,13,2,13,2
2,2,2,2,2,2,2,2,2,2,2,2,2
2,13,2,13,2,13,2,13,2,13,2,13,2
2,2,2,2,2,2,2,2,2,2,2,2,2
endlayer

layer
14,14,14,14,14,14,14,14,14,14,14,14,14
14,0,14,0,14,0,14,0,14,0,14,0,14
14,14,14,14,14,14,14,14,14,14,14,14,14
14,0,14,0,14,0,14,0,14,0,14,0,14
14,14,14,14,14,14,14,14,14,14,14,14,14
14,0,14,0,14,0,14,0,14,0,14,0,14
14,14,14,14,14,14,14,14,14,14,14,14,14
14,0,14,0,14,0,14,0,14,0,14,0,14
14,14,14,14,14,14,14,14,14,14,14,14,14
endlayer


