# MushroomGarden -- hidden underground mushroom garden
# 1 Oct 2014 -- Minecraft 1.7.10
# Created by Ruins mod version 13.8 Ingame Parser
# authoring Player: Jordan_Greywolf
# Updated for MC 1.8: 22 Jul 2015
# Verified for MC 1.9: 17 Apr 2016
# Modified as "Dungeon Seed": 30 Apr 2016

biomesToSpawnIn=forest,foresthills,fungi forest,roofed forest,extreme hills,extreme hills edge,plains,savanna,mushroomisland,swampland,jungle,savanna plateau,mushroom forest

weight=1
embed_into_distance=20

unacceptable_target_blocks=flowing_water,water,flowing_lava,lava,cloud,Natura:Cloud,mushroom,red_mushroom_block,brown_mushroom_block

dimensions=22,17,17
allowable_overhang=200
max_leveling=4
leveling_buffer=-1
preserve_water=0
preserve_lava=0
preserve_plants=1

rule1=0,100,preserveBlock
rule2=0,100,minecraft:stone-0
rule3=0,100,minecraft:obsidian-0
rule4=0,100,minecraft:grass-0

rule5=0,100,minecraft:flowing_water
rule6=0,100,minecraft:dirt-0

rule7=0,100,minecraft:flowing_lava

# Randomized Mushrooms
rule8=0,100,minecraft:red_mushroom-0,minecraft:brown_mushroom-0

# Giant Mushrooms
rule9=0,100,minecraft:red_mushroom_block-10
rule10=0,100,minecraft:red_mushroom_block-1
rule11=0,100,minecraft:red_mushroom_block-4
rule12=0,100,minecraft:red_mushroom_block-7
rule13=0,100,minecraft:red_mushroom_block-2
rule14=0,100,minecraft:red_mushroom_block-8
rule15=0,100,minecraft:red_mushroom_block-3
rule16=0,100,minecraft:red_mushroom_block-9
rule17=0,100,minecraft:red_mushroom_block-6
rule18=0,100,minecraft:red_mushroom_block-5

# Well Base
rule19=0,100,minecraft:double_stone_slab-0
rule20=0,100,minecraft:stone_stairs-0
rule21=0,100,minecraft:stone_stairs-2
rule22=0,100,minecraft:stone_stairs-3
rule23=0,100,minecraft:stone_stairs-1

# Well Support
rule24=0,100,minecraft:fence-0

rule25=0,100,minecraft:gold_ore,minecraft:emerald_ore

layer
1,1,1,1,1,1,1,1,1,1,1,1,1,1,1,1,1
1,1,1,1,1,1,1,1,1,1,1,1,1,1,1,1,1
1,1,1,1,1,1,1,1,1,1,1,1,1,1,1,1,1
1,1,1,1,1,1,1,1,1,1,1,1,2,1,1,1,1
1,1,1,1,1,2,2,2,2,1,1,1,2,2,1,1,1
1,1,1,1,2,2,2,2,2,2,1,1,1,2,2,1,1
1,1,1,2,2,2,2,2,2,2,2,1,1,2,1,1,1
1,1,1,2,2,2,2,25,2,2,2,2,1,1,1,1,1
1,1,1,2,2,3,3,2,2,2,2,2,2,1,1,1,1
1,1,2,2,3,3,3,2,2,2,2,2,2,1,1,1,1
1,1,2,2,3,3,3,3,2,2,2,2,2,1,1,1,1
1,1,2,2,3,3,3,2,2,2,2,2,2,1,1,1,1
1,1,1,2,2,2,2,2,2,2,2,2,1,1,1,1,1
1,1,1,1,2,2,2,2,2,2,2,1,1,1,1,1,1
1,1,1,1,1,1,1,1,1,1,1,1,1,1,1,1,1
1,1,1,1,1,1,1,1,1,1,1,1,1,1,1,1,1
1,1,1,1,1,1,1,1,1,1,1,1,1,1,1,1,1
endlayer

layer
1,1,1,1,1,1,1,1,1,1,1,1,1,1,1,1,1
1,1,1,1,1,1,1,1,1,1,1,1,1,1,1,1,1
1,1,1,1,1,1,1,1,1,1,1,2,2,2,1,1,1
1,1,1,1,1,2,2,2,2,1,1,2,2,2,1,1,1
1,1,1,1,2,2,2,2,2,2,1,2,2,2,2,1,1
1,1,1,2,2,4,4,5,4,25,2,1,2,2,2,2,1
1,1,1,2,4,4,5,5,5,5,4,2,6,6,2,2,1
1,1,2,2,4,3,3,5,5,5,5,4,2,2,2,1,1
1,1,2,2,3,7,7,3,5,5,5,5,4,2,1,1,1
1,1,2,3,7,7,7,3,3,5,5,4,6,2,1,1,1
1,2,2,3,7,7,7,7,3,5,5,4,2,2,1,1,1
1,2,2,3,7,7,7,3,4,5,4,4,2,2,1,1,1
1,1,2,2,3,3,3,2,2,6,6,2,2,1,1,1,1
1,1,1,2,2,2,2,2,2,2,2,2,1,1,1,1,1
1,1,1,1,1,1,2,2,2,2,2,1,1,1,1,1,1
1,1,1,1,1,1,1,1,1,1,1,1,1,1,1,1,1
1,1,1,1,1,1,1,1,1,1,1,1,1,1,1,1,1
endlayer

layer
1,1,1,1,1,1,1,2,1,1,1,1,2,1,1,1,1
1,1,1,1,1,1,2,2,1,1,1,2,2,2,1,1,1
1,1,1,1,2,2,2,2,2,2,2,2,7,2,2,1,1
1,1,1,2,2,6,4,4,6,2,2,6,2,2,2,2,1
1,1,2,2,6,4,4,0,4,4,2,4,4,6,2,2,1
1,1,2,6,6,8,8,0,8,4,4,4,4,4,6,2,1
1,2,2,6,8,8,0,0,0,0,8,0,5,5,4,2,1
1,2,4,4,8,0,0,0,0,0,0,8,4,4,2,2,1
1,2,4,4,0,0,0,3,0,0,0,0,8,3,3,1,1
2,25,0,0,0,0,0,3,3,0,0,8,4,2,1,1,1
2,6,6,0,0,0,0,0,0,0,0,8,4,2,1,1,1
2,6,6,0,0,0,0,0,8,0,8,8,6,2,1,1,1
2,2,6,3,0,7,3,2,4,5,4,6,2,1,1,1,1
1,1,2,2,3,2,2,6,6,6,2,2,1,1,1,1,1
1,1,1,1,1,1,2,2,2,2,2,1,1,1,1,1,1
1,1,1,1,1,1,1,1,1,1,1,1,1,1,1,1,1
1,1,1,1,1,1,1,1,1,1,1,1,1,1,1,1,1
endlayer

layer
1,1,1,1,1,1,1,1,1,1,1,2,2,1,1,1,1
1,1,1,1,1,1,2,2,1,1,1,2,2,2,1,1,1
1,1,1,1,2,2,2,5,2,2,2,2,0,2,2,1,1
1,1,1,2,2,4,8,0,4,4,2,4,0,0,2,2,1
1,1,2,2,4,8,8,0,8,8,4,8,8,4,4,2,1
1,1,2,4,9,0,0,0,0,8,8,8,8,8,5,2,1
1,2,2,4,0,0,0,0,0,0,0,0,0,0,8,2,1
1,2,8,8,0,0,0,0,0,0,0,0,8,8,3,2,1
1,2,0,8,0,0,0,8,0,0,0,0,0,3,0,25,1
2,7,0,0,0,0,0,0,8,0,0,0,8,4,3,1,1
2,0,0,0,0,0,0,0,0,0,0,0,8,4,2,1,1
2,0,8,0,0,0,0,0,0,0,0,0,6,2,2,1,1
2,6,8,8,0,0,0,8,8,0,8,4,2,2,1,1,1
1,2,2,2,0,7,2,4,4,5,4,2,2,3,1,1,1
1,1,1,2,2,2,2,2,2,4,2,2,2,1,1,1,1
1,1,1,1,1,2,1,1,2,2,2,2,1,1,1,1,1
1,1,1,1,1,1,1,1,1,1,1,1,1,1,1,1,1
endlayer

layer
1,1,1,1,1,1,1,1,1,1,1,2,2,1,1,1,1
1,1,1,1,1,1,2,2,1,1,1,2,2,2,1,1,1
1,1,1,2,2,2,2,0,2,2,2,4,0,2,2,1,1
1,1,2,8,8,8,0,0,8,8,4,8,0,0,2,2,1
1,2,2,8,8,0,0,0,0,0,8,0,0,8,8,2,1
1,2,2,8,9,0,0,0,0,0,0,0,0,0,0,5,1
1,2,2,8,0,0,0,0,0,0,0,0,0,0,0,2,1
1,2,2,0,0,0,0,0,0,0,0,0,0,0,0,2,1
1,2,0,0,0,0,0,0,0,0,0,0,0,0,0,7,1
1,2,0,0,0,0,0,0,0,0,0,0,0,8,2,2,1
2,0,0,0,0,0,0,0,0,0,0,0,0,8,2,1,1
2,0,0,0,0,0,0,0,0,0,0,0,9,4,2,1,1
2,8,0,0,0,0,0,0,0,0,0,8,4,3,2,1,1
2,2,2,8,0,0,0,8,8,0,8,4,4,0,3,1,1
1,1,2,2,2,7,2,4,4,0,4,6,2,3,1,1,1
1,1,1,1,2,2,2,2,2,5,5,2,2,1,1,1,1
1,1,1,1,1,1,1,1,1,2,2,2,1,1,1,1,1
endlayer

layer
1,1,1,1,1,1,1,1,1,1,1,2,2,1,1,1,1
1,1,1,1,1,2,2,2,1,1,1,2,7,2,1,1,1
1,1,1,2,2,2,2,2,2,2,2,0,0,2,2,1,1
1,1,2,12,11,10,0,0,0,0,8,0,0,0,2,2,1
1,2,12,0,0,0,10,0,0,0,0,0,0,0,0,2,1
1,2,14,0,9,0,13,0,0,0,0,0,0,0,0,2,1
1,2,16,0,0,0,15,0,0,0,0,0,0,0,0,2,1
1,2,0,16,17,15,0,0,0,0,0,0,0,0,0,2,1
1,2,0,0,0,0,0,0,0,0,0,0,0,0,0,2,1
1,2,0,0,0,0,0,0,0,0,0,0,0,0,2,2,1
2,2,0,0,0,0,0,0,0,0,0,0,0,0,2,2,1
2,0,0,0,0,0,0,0,0,0,0,0,9,8,4,1,1
2,2,0,0,0,0,0,0,0,0,0,0,8,4,2,1,1
1,2,2,2,0,0,0,0,0,0,0,8,0,0,0,2,1
1,1,1,2,2,0,0,8,8,0,8,4,2,2,2,1,1
1,1,1,1,2,2,2,2,2,0,0,0,2,1,1,1,1
1,1,1,1,1,1,1,1,1,2,2,2,1,1,1,1,1
endlayer

layer
1,1,1,1,1,1,1,1,1,1,1,2,2,1,1,1,1
1,1,1,1,1,1,1,1,1,1,1,2,2,1,1,1,1
1,1,1,2,2,2,2,2,2,2,2,2,2,2,1,1,1
1,1,2,12,11,10,0,0,0,0,0,0,0,2,2,1,1
1,2,12,0,0,0,10,0,0,0,0,0,0,0,2,2,1
1,2,14,0,9,0,13,0,0,0,0,0,0,0,2,2,1
1,2,16,0,0,0,15,0,0,0,0,0,0,0,2,2,1
1,2,0,16,17,15,0,0,0,0,0,0,0,0,2,2,1
1,2,0,0,0,0,0,0,0,0,0,0,0,0,2,2,1
1,2,0,0,0,0,0,0,0,0,0,0,0,2,2,2,1
2,2,0,0,0,0,0,0,0,0,0,0,0,0,8,2,1
2,0,0,0,0,0,0,0,0,0,0,0,9,0,8,2,1
1,2,0,0,0,0,0,0,0,0,0,0,0,8,0,2,1
1,1,2,2,0,0,0,0,0,0,0,0,0,0,0,7,1
1,1,1,1,2,0,0,0,0,0,0,8,2,2,2,2,1
1,1,1,1,1,2,2,2,2,2,0,0,5,1,1,1,1
1,1,1,1,1,1,1,1,1,2,2,2,1,1,1,1,1
endlayer

layer
1,1,1,1,1,1,1,1,1,1,1,1,1,1,1,1,1
1,1,1,1,1,1,1,1,1,1,1,1,1,1,1,1,1
1,1,1,2,2,2,2,1,1,2,1,2,2,1,1,1,1
1,1,2,12,11,10,2,2,2,2,2,2,2,2,1,1,1
1,2,12,0,0,0,10,0,0,0,0,0,0,0,2,1,1
1,2,14,0,9,0,13,0,0,0,0,0,0,0,2,1,1
1,2,16,0,0,0,15,0,0,0,0,0,0,0,2,1,1
1,2,0,16,17,15,0,0,0,0,0,0,0,0,2,1,1
1,2,0,0,0,0,0,0,0,0,0,0,0,0,2,1,1
1,2,0,0,0,0,0,0,0,0,0,12,11,10,2,2,1
2,2,0,0,0,0,0,0,0,0,12,0,0,0,10,2,1
2,2,0,0,0,0,0,0,0,0,14,0,9,0,13,2,1
1,2,2,2,0,0,0,0,0,0,16,0,0,0,15,2,1
1,1,2,2,2,0,0,0,0,0,0,16,17,15,2,2,1
1,1,1,1,2,2,0,0,0,0,0,2,2,2,2,1,1
1,1,1,1,1,2,2,2,2,2,2,2,2,1,1,1,1
1,1,1,1,1,1,1,1,1,1,1,1,1,1,1,1,1
endlayer

layer
1,1,1,1,1,1,1,1,1,1,1,1,1,1,1,1,1
1,1,1,1,1,1,1,1,1,1,1,1,1,1,1,1,1
1,1,1,2,2,2,1,1,1,1,1,1,1,1,1,1,1
1,1,2,2,2,2,2,2,2,2,2,2,2,2,1,1,1
1,2,2,12,11,10,0,0,0,0,0,0,0,2,1,1,1
1,2,2,14,18,13,0,0,0,0,0,0,0,2,1,1,1
1,2,2,16,17,15,0,0,0,0,0,0,0,2,1,1,1
1,2,2,0,0,0,0,0,0,0,0,0,0,2,2,1,1
1,1,2,0,0,0,0,0,0,0,0,0,0,0,2,1,1
1,1,2,0,0,0,0,0,0,0,0,12,11,10,2,1,1
1,1,2,0,0,0,0,0,0,0,12,0,0,0,10,2,1
1,1,2,0,0,0,0,0,0,0,14,0,9,0,13,2,1
1,1,2,2,2,0,0,0,0,0,16,0,0,0,15,2,1
1,1,0,0,2,2,0,0,0,0,0,16,17,15,2,1,1
1,1,1,1,1,2,2,2,2,2,2,2,2,2,1,1,1
1,1,1,1,1,1,1,1,1,2,2,2,1,1,1,1,1
1,1,1,1,1,1,1,1,1,1,1,1,1,1,1,1,1
endlayer

layer
1,1,1,1,1,1,1,1,1,1,1,1,1,1,1,1,1
1,1,1,1,1,1,1,1,1,1,1,1,1,1,1,1,1
1,1,1,1,1,1,1,1,1,1,1,1,1,1,1,1,1
1,1,1,2,2,2,2,2,2,2,2,2,2,1,1,1,1
1,1,2,0,0,0,0,0,0,0,0,0,0,2,1,1,1
1,1,2,0,0,0,0,0,0,0,0,0,0,2,1,1,1
1,1,2,0,0,0,0,0,0,0,0,0,0,2,1,1,1
1,1,2,2,0,0,0,0,0,0,0,0,0,2,1,1,1
1,1,1,2,0,0,0,0,0,0,0,0,0,0,2,1,1
1,1,1,2,0,0,0,0,0,0,0,12,11,10,2,1,1
1,1,1,2,0,0,0,0,0,0,12,0,0,0,10,2,1
1,1,2,2,2,2,0,0,0,0,14,0,9,0,13,2,1
1,1,1,1,1,2,2,0,0,0,16,0,0,0,15,2,1
1,1,1,1,1,2,2,2,2,2,2,16,17,15,2,1,1
1,1,1,1,1,1,1,1,1,1,2,2,2,2,1,1,1
1,1,1,1,1,1,1,1,1,1,1,1,1,1,1,1,1
1,1,1,1,1,1,1,1,1,1,1,1,1,1,1,1,1
endlayer

layer
1,1,1,1,1,1,1,1,1,1,1,1,1,1,1,1,1
1,1,1,1,1,1,1,1,1,1,1,1,1,1,1,1,1
1,1,1,1,1,1,1,1,1,1,1,1,1,1,1,1,1
1,1,1,1,1,1,2,1,1,1,1,2,1,1,1,1,1
1,1,1,2,2,2,2,2,2,2,2,2,2,2,1,1,1
1,1,2,2,2,2,2,2,2,2,2,2,2,1,1,1,1
1,1,2,2,2,2,2,2,0,2,2,2,2,1,1,1,1
1,1,1,2,2,2,0,0,0,0,0,2,2,1,1,1,1
1,1,1,2,2,0,0,0,0,0,0,2,2,2,1,1,1
1,1,1,2,2,0,0,0,0,0,0,2,2,2,2,1,1
1,1,1,2,2,0,0,0,0,0,0,12,11,10,2,1,1
1,1,1,1,2,2,0,0,0,0,0,14,18,13,2,1,1
1,1,1,1,1,1,2,2,2,2,2,16,17,15,2,1,1
1,1,1,1,1,1,1,1,1,1,2,2,2,2,2,1,1
1,1,1,1,1,1,1,1,1,1,1,2,2,1,1,1,1
1,1,1,1,1,1,1,1,1,1,1,1,1,1,1,1,1
1,1,1,1,1,1,1,1,1,1,1,1,1,1,1,1,1
endlayer

layer
1,1,1,1,1,1,1,1,1,1,1,1,1,1,1,1,1
1,1,1,1,1,1,1,1,1,1,1,1,1,1,1,1,1
1,1,1,1,1,1,1,1,1,1,1,1,1,1,1,1,1
1,1,1,1,1,1,1,1,1,1,1,1,1,1,1,1,1
1,1,1,1,1,1,1,1,1,1,1,1,1,1,1,1,1
1,1,1,1,1,1,1,1,2,2,1,1,1,1,1,1,1
1,1,1,1,1,1,2,2,2,2,2,2,1,1,1,1,1
1,1,1,1,1,2,0,0,0,2,2,2,1,1,1,1,1
1,1,1,1,2,0,0,0,0,0,2,2,1,1,1,1,1
1,1,1,1,2,0,0,0,0,0,2,2,2,2,1,1,1
1,1,1,1,2,2,0,2,2,2,2,2,2,2,1,1,1
1,1,1,1,1,2,2,2,2,2,2,2,2,2,2,1,1
1,1,1,1,1,1,2,1,1,1,2,2,2,2,1,1,1
1,1,1,1,1,1,1,1,1,1,1,1,2,1,1,1,1
1,1,1,1,1,1,1,1,1,1,1,1,1,1,1,1,1
1,1,1,1,1,1,1,1,1,1,1,1,1,1,1,1,1
1,1,1,1,1,1,1,1,1,1,1,1,1,1,1,1,1
endlayer

layer
1,1,1,1,1,1,1,1,1,1,1,1,1,1,1,1,1
1,1,1,1,1,1,1,1,1,1,1,1,1,1,1,1,1
1,1,1,1,1,1,1,1,1,1,1,1,1,1,1,1,1
1,1,1,1,1,1,1,1,1,1,1,1,1,1,1,1,1
1,1,1,1,1,1,1,1,1,1,1,1,1,1,1,1,1
1,1,1,1,1,1,1,1,1,1,1,1,1,1,1,1,1
1,1,1,1,1,1,1,2,2,1,1,1,1,1,1,1,1
1,1,1,1,1,2,2,2,2,2,1,1,1,1,1,1,1
1,1,1,1,2,2,2,2,0,2,2,1,1,1,1,1,1
1,1,1,1,2,2,2,2,2,2,2,2,1,1,1,1,1
1,1,1,1,1,2,2,2,2,2,2,2,1,1,1,1,1
1,1,1,1,1,1,1,1,1,1,1,1,2,1,1,1,1
1,1,1,1,1,1,1,1,1,1,1,1,1,1,1,1,1
1,1,1,1,1,1,1,1,1,1,1,1,1,1,1,1,1
1,1,1,1,1,1,1,1,1,1,1,1,1,1,1,1,1
1,1,1,1,1,1,1,1,1,1,1,1,1,1,1,1,1
1,1,1,1,1,1,1,1,1,1,1,1,1,1,1,1,1
endlayer

layer
1,1,1,1,1,1,1,1,1,1,1,1,1,1,1,1,1
1,1,1,1,1,1,1,1,1,1,1,1,1,1,1,1,1
1,1,1,1,1,1,1,1,1,1,1,1,1,1,1,1,1
1,1,1,1,1,1,1,1,1,1,1,1,1,1,1,1,1
1,1,1,1,1,1,1,1,1,1,1,1,1,1,1,1,1
1,1,1,1,1,1,1,1,1,1,1,1,1,1,1,1,1
1,1,1,1,1,1,1,1,1,1,1,1,1,1,1,1,1
1,1,1,1,1,1,1,2,2,2,1,1,1,1,1,1,1
1,1,1,1,1,1,1,2,5,2,1,1,1,1,1,1,1
1,1,1,1,1,1,1,2,2,2,1,1,1,1,1,1,1
1,1,1,1,1,1,1,1,1,1,1,1,1,1,1,1,1
1,1,1,1,1,1,1,1,1,1,1,1,1,1,1,1,1
1,1,1,1,1,1,1,1,1,1,1,1,1,1,1,1,1
1,1,1,1,1,1,1,1,1,1,1,1,1,1,1,1,1
1,1,1,1,1,1,1,1,1,1,1,1,1,1,1,1,1
1,1,1,1,1,1,1,1,1,1,1,1,1,1,1,1,1
1,1,1,1,1,1,1,1,1,1,1,1,1,1,1,1,1
endlayer

layer
1,1,1,1,1,1,1,1,1,1,1,1,1,1,1,1,1
1,1,1,1,1,1,1,1,1,1,1,1,1,1,1,1,1
1,1,1,1,1,1,1,1,1,1,1,1,1,1,1,1,1
1,1,1,1,1,1,1,1,1,1,1,1,1,1,1,1,1
1,1,1,1,1,1,1,1,1,1,1,1,1,1,1,1,1
1,1,1,1,1,1,1,1,1,1,1,1,1,1,1,1,1
1,1,1,1,1,1,1,1,1,1,1,1,1,1,1,1,1
1,1,1,1,1,1,1,2,2,2,1,1,1,1,1,1,1
1,1,1,1,1,1,1,2,5,2,1,1,1,1,1,1,1
1,1,1,1,1,1,1,2,2,2,1,1,1,1,1,1,1
1,1,1,1,1,1,1,1,1,1,1,1,1,1,1,1,1
1,1,1,1,1,1,1,1,1,1,1,1,1,1,1,1,1
1,1,1,1,1,1,1,1,1,1,1,1,1,1,1,1,1
1,1,1,1,1,1,1,1,1,1,1,1,1,1,1,1,1
1,1,1,1,1,1,1,1,1,1,1,1,1,1,1,1,1
1,1,1,1,1,1,1,1,1,1,1,1,1,1,1,1,1
1,1,1,1,1,1,1,1,1,1,1,1,1,1,1,1,1
endlayer

layer
1,1,1,1,1,1,1,1,1,1,1,1,1,1,1,1,1
1,1,1,1,1,1,1,1,1,1,1,1,1,1,1,1,1
1,1,1,1,1,1,1,1,1,1,1,1,1,1,1,1,1
1,1,1,1,1,1,1,1,1,1,1,1,1,1,1,1,1
1,1,1,1,1,1,1,1,1,1,1,1,1,1,1,1,1
1,1,1,1,1,1,1,1,1,1,1,1,1,1,1,1,1
1,1,1,1,1,1,1,1,1,1,1,1,1,1,1,1,1
1,1,1,1,1,1,1,2,2,2,1,1,1,1,1,1,1
1,1,1,1,1,1,1,2,5,2,1,1,1,1,1,1,1
1,1,1,1,1,1,1,2,2,2,1,1,1,1,1,1,1
1,1,1,1,1,1,1,1,1,1,1,1,1,1,1,1,1
1,1,1,1,1,1,1,1,1,1,1,1,1,1,1,1,1
1,1,1,1,1,1,1,1,1,1,1,1,1,1,1,1,1
1,1,1,1,1,1,1,1,1,1,1,1,1,1,1,1,1
1,1,1,1,1,1,1,1,1,1,1,1,1,1,1,1,1
1,1,1,1,1,1,1,1,1,1,1,1,1,1,1,1,1
1,1,1,1,1,1,1,1,1,1,1,1,1,1,1,1,1
endlayer

layer
1,1,1,1,1,1,1,1,1,1,1,1,1,1,1,1,1
1,1,1,1,1,1,1,1,1,1,1,1,1,1,1,1,1
1,1,1,1,1,1,1,1,1,1,1,1,1,1,1,1,1
1,1,1,1,1,1,1,1,1,1,1,1,1,1,1,1,1
1,1,1,1,1,1,1,1,1,1,1,1,1,1,1,1,1
1,1,1,1,1,1,1,1,1,1,1,1,1,1,1,1,1
1,1,1,1,1,1,1,1,1,1,1,1,1,1,1,1,1
1,1,1,1,1,1,1,2,2,2,1,1,1,1,1,1,1
1,1,1,1,1,1,1,2,5,2,1,1,1,1,1,1,1
1,1,1,1,1,1,1,2,2,2,1,1,1,1,1,1,1
1,1,1,1,1,1,1,1,1,1,1,1,1,1,1,1,1
1,1,1,1,1,1,1,1,1,1,1,1,1,1,1,1,1
1,1,1,1,1,1,1,1,1,1,1,1,1,1,1,1,1
1,1,1,1,1,1,1,1,1,1,1,1,1,1,1,1,1
1,1,1,1,1,1,1,1,1,1,1,1,1,1,1,1,1
1,1,1,1,1,1,1,1,1,1,1,1,1,1,1,1,1
1,1,1,1,1,1,1,1,1,1,1,1,1,1,1,1,1
endlayer

layer
1,1,1,1,1,1,1,1,1,1,1,1,1,1,1,1,1
1,1,1,1,1,1,1,1,1,1,1,1,1,1,1,1,1
1,1,1,1,1,1,1,1,1,1,1,1,1,1,1,1,1
1,1,1,1,1,1,1,1,1,1,1,1,1,1,1,1,1
1,1,1,1,1,1,1,1,1,1,1,1,1,1,1,1,1
1,1,1,1,1,1,1,1,1,1,1,1,1,1,1,1,1
1,1,1,1,1,1,1,1,1,1,1,1,1,1,1,1,1
1,1,1,1,1,1,1,2,2,2,1,1,1,1,1,1,1
1,1,1,1,1,1,1,2,5,2,1,1,1,1,1,1,1
1,1,1,1,1,1,1,2,2,2,1,1,1,1,1,1,1
1,1,1,1,1,1,1,1,1,1,1,1,1,1,1,1,1
1,1,1,1,1,1,1,1,1,1,1,1,1,1,1,1,1
1,1,1,1,1,1,1,1,1,1,1,1,1,1,1,1,1
1,1,1,1,1,1,1,1,1,1,1,1,1,1,1,1,1
1,1,1,1,1,1,1,1,1,1,1,1,1,1,1,1,1
1,1,1,1,1,1,1,1,1,1,1,1,1,1,1,1,1
1,1,1,1,1,1,1,1,1,1,1,1,1,1,1,1,1
endlayer

# Ground Level (-1)
layer
1,1,1,1,1,1,1,1,1,1,1,1,1,1,1,1,1
1,1,1,1,1,1,1,1,1,1,1,1,1,1,1,1,1
1,1,1,1,1,1,1,1,1,1,1,1,1,1,1,1,1
1,1,1,1,1,1,1,1,1,1,1,1,1,1,1,1,1
1,1,1,1,1,1,1,1,1,1,1,1,1,1,1,1,1
1,1,1,1,1,1,1,1,1,1,1,1,1,1,1,1,1
1,1,1,1,1,1,1,1,1,1,1,1,1,1,1,1,1
1,1,1,1,1,1,1,2,2,2,1,1,1,1,1,1,1
1,1,1,1,1,1,1,2,5,2,1,1,1,1,1,1,1
1,1,1,1,1,1,1,2,2,2,1,1,1,1,1,1,1
1,1,1,1,1,1,1,1,1,1,1,1,1,1,1,1,1
1,1,1,1,1,1,1,1,1,1,1,1,1,1,1,1,1
1,1,1,1,1,1,1,1,1,1,1,1,1,1,1,1,1
1,1,1,1,1,1,1,1,1,1,1,1,1,1,1,1,1
1,1,1,1,1,1,1,1,1,1,1,1,1,1,1,1,1
1,1,1,1,1,1,1,1,1,1,1,1,1,1,1,1,1
1,1,1,1,1,1,1,1,1,1,1,1,1,1,1,1,1
endlayer

# Well Base (+1)
layer
1,1,1,1,1,1,1,1,1,1,1,1,1,1,1,1,1
1,1,1,1,1,1,1,1,1,1,1,1,1,1,1,1,1
1,1,1,1,1,1,1,1,1,1,1,1,1,1,1,1,1
1,1,1,1,1,1,1,1,1,1,1,1,1,1,1,1,1
1,1,1,1,1,1,1,1,1,1,1,1,1,1,1,1,1
1,1,1,1,1,1,1,1,1,1,1,1,1,1,1,1,1
1,1,1,1,1,1,1,1,1,1,1,1,1,1,1,1,1
1,1,1,1,1,1,1,19,20,19,1,1,1,1,1,1,1
1,1,1,1,1,1,1,22,5,21,1,1,1,1,1,1,1
1,1,1,1,1,1,1,19,23,19,1,1,1,1,1,1,1
1,1,1,1,1,1,1,1,1,1,1,1,1,1,1,1,1
1,1,1,1,1,1,1,1,1,1,1,1,1,1,1,1,1
1,1,1,1,1,1,1,1,1,1,1,1,1,1,1,1,1
1,1,1,1,1,1,1,1,1,1,1,1,1,1,1,1,1
1,1,1,1,1,1,1,1,1,1,1,1,1,1,1,1,1
1,1,1,1,1,1,1,1,1,1,1,1,1,1,1,1,1
1,1,1,1,1,1,1,1,1,1,1,1,1,1,1,1,1
endlayer

# Well Support (+2)
layer
1,1,1,1,1,1,1,1,1,1,1,1,1,1,1,1,1
1,1,1,1,1,1,1,1,1,1,1,1,1,1,1,1,1
1,1,1,1,1,1,1,1,1,1,1,1,1,1,1,1,1
1,1,1,1,1,1,1,1,1,1,1,1,1,1,1,1,1
1,1,1,1,1,1,1,1,1,1,1,1,1,1,1,1,1
1,1,1,1,1,1,1,1,1,1,1,1,1,1,1,1,1
1,1,1,1,1,1,1,1,1,1,0,1,1,1,1,1,1
1,1,1,1,1,1,1,24,24,24,0,1,1,1,1,1,1
1,1,1,1,1,1,1,24,0,0,0,1,1,1,1,1,1
1,1,1,1,1,1,1,24,24,24,0,1,1,1,1,1,1
1,1,1,1,1,1,1,1,1,1,0,1,1,1,1,1,1
1,1,1,1,1,1,1,1,1,1,1,1,1,1,1,1,1
1,1,1,1,1,1,1,1,1,1,1,1,1,1,1,1,1
1,1,1,1,1,1,1,1,1,1,1,1,1,1,1,1,1
1,1,1,1,1,1,1,1,1,1,1,1,1,1,1,1,1
1,1,1,1,1,1,1,1,1,1,1,1,1,1,1,1,1
1,1,1,1,1,1,1,1,1,1,1,1,1,1,1,1,1
endlayer

# Well Support (+3)
layer
1,1,1,1,1,1,1,1,1,1,1,1,1,1,1,1,1
1,1,1,1,1,1,1,1,1,1,1,1,1,1,1,1,1
1,1,1,1,1,1,1,1,1,1,1,1,1,1,1,1,1
1,1,1,1,1,1,1,1,1,1,1,1,1,1,1,1,1
1,1,1,1,1,1,1,1,1,1,1,1,1,1,1,1,1
1,1,1,1,1,1,1,0,0,0,1,1,1,1,1,1,1
1,1,1,1,1,1,0,0,0,0,0,1,1,1,1,1,1
1,1,1,1,1,0,0,24,0,24,0,0,1,1,1,1,1
1,1,1,1,1,0,0,0,0,0,0,0,1,1,1,1,1
1,1,1,1,1,0,0,24,0,24,0,0,1,1,1,1,1
1,1,1,1,1,1,0,0,0,0,0,1,1,1,1,1,1
1,1,1,1,1,1,1,0,0,0,1,1,1,1,1,1,1
1,1,1,1,1,1,1,1,1,1,1,1,1,1,1,1,1
1,1,1,1,1,1,1,1,1,1,1,1,1,1,1,1,1
1,1,1,1,1,1,1,1,1,1,1,1,1,1,1,1,1
1,1,1,1,1,1,1,1,1,1,1,1,1,1,1,1,1
1,1,1,1,1,1,1,1,1,1,1,1,1,1,1,1,1
endlayer



