
# MineshaftSpiders
# 7 Mar 2014; updated to 1.7.10, 9 Oct 2014
# Created by Ruins mod version 12.3 Ingame Parser
# authoring Player: Jordan_Greywolf
# Last Updated: 30 Apr 2015
# Updated to MC 1.9: 24 Apr 2016
# Updated to MC 1.11: 11 Jan 2017

biomesToSpawnIn=alps,alps forest,alpine,birch forest hills,cold taiga hills,extreme hills,extreme hills edge,extreme hills+,extreme hills m,extreme hills+ m,flower field,flower forest,foresthills,highlands,plains,mega spruce taiga,mega taiga,mega taiga hills,oak savanna,silkglades,snowy forest,sunflower plains,taiga,taigahills

weight=1
embed_into_distance=15

uniqueMinDistance=1000

unacceptable_target_blocks=water,flowing_water,lava,flowing_lava,cloud,Natura:Cloud

dimensions=21,9,12
allowable_overhang=500
max_leveling=0
leveling_buffer=0
preserve_water=0
preserve_lava=0
preserve_plants=1

rule1=0,100,preserveBlock
rule2=0,100,minecraft:stone-0
rule3=0,100,minecraft:emerald_ore-0,minecraft:gold_ore-0,minecraft:diamond_ore-0,minecraft:iron_ore-0,minecraft:redstone_ore
rule4=0,100,minecraft:fence-0
rule5=0,90,minecraft:rail-1
rule6=0,100,minecraft:web-0,minecraft:web-0,minecraft:gravel-0
rule7=0,100,minecraft:tnt-1,minecraft:tnt-0
rule8=0,100,IInventory;minecraft:trapped_chest;minecraft:coal_ore#4#0#1+minecraft:torch#20#0#5+minecraft:iron_helmet#1#0#9+minecraft:rail#8#0#11
rule9=0,100,MobSpawner:Cave_Spider,MobSpawner:Spider
rule10=0,100,minecraft:planks-0
rule11=2,90,minecraft:ladder-3
rule12=0,90,minecraft:rail-0
rule13=0,100,IInventory;minecraft:trapped_chest;minecraft:iron_ingot#4#0#1+minecraft:iron_pickaxe#1#0#4+minecraft:minecart#1#0#6+minecraft:rail#8#0#9
rule14=1,100,minecraft:redstone_torch-5
rule15=0,100,minecraft:grass-0
rule16=0,90,minecraft:tallgrass-1,minecraft:tallgrass-2,minecraft:red_flower,minecraft:yellow_flower

rule17=0,100,minecraft:dirt-0

rule18=1,100,minecraft:crafting_table-0,minecraft:tnt-1,minecraft:torch-5,minecraft:redstone_torch-5,IInventory;minecraft:lit_furnace;minecraft:coal#4#1#1

layer
1,1,1,1,1,1,1,1,1,1,1,1
1,1,1,2,2,2,1,1,2,1,1,1
1,1,2,2,2,2,2,2,2,1,1,1
1,2,2,2,2,2,2,2,2,2,1,1
1,2,2,7,2,2,2,2,2,1,1,1
1,1,2,2,2,2,2,2,1,1,1,1
1,1,1,1,2,2,2,2,1,1,1,1
1,1,1,1,1,1,1,1,1,1,1,1
1,1,1,1,1,1,1,1,1,1,1,1
endlayer

layer
1,1,1,1,1,1,1,1,2,1,1,1
1,1,2,2,2,2,2,2,2,1,1,1
1,2,2,2,2,2,2,2,2,2,1,1
1,2,2,2,7,2,2,2,2,2,2,1
2,2,2,2,2,2,2,2,2,2,2,1
1,1,2,2,2,2,2,2,2,2,1,1
1,1,1,2,2,2,2,2,2,1,1,1
1,1,1,1,2,2,2,1,1,1,1,1
1,1,1,1,1,1,1,1,1,1,1,1
endlayer

layer
1,1,1,1,1,1,2,2,2,2,1,1
1,2,2,2,2,2,2,2,2,2,2,1
2,2,2,2,2,2,2,2,2,2,2,1
2,2,3,2,2,7,2,2,2,2,2,1
2,2,2,2,2,2,2,2,2,2,2,2
2,2,2,2,2,2,2,2,2,2,2,2
1,2,2,2,2,2,2,2,2,2,2,1
1,1,2,2,2,2,2,2,2,2,2,1
1,1,1,1,1,1,1,2,2,2,1,1
endlayer

layer
1,1,1,1,1,2,2,4,5,4,2,1
2,2,2,2,7,2,2,6,5,6,2,1
2,2,6,9,8,2,6,0,5,6,2,1
4,7,6,0,0,0,0,4,5,4,2,2
12,12,12,12,12,12,12,12,11,10,2,2
4,0,6,6,0,6,7,4,5,4,2,2
2,6,3,7,6,3,7,7,5,6,6,2
1,2,2,2,2,2,2,2,5,2,2,1
1,1,1,1,2,1,2,4,5,4,2,1
endlayer

layer
1,1,1,1,1,2,2,4,6,4,2,1
2,2,3,2,2,2,2,6,6,6,2,1
2,6,6,6,6,2,6,6,6,6,2,2
4,0,0,0,0,6,0,4,0,4,2,2
6,0,0,0,0,0,0,0,11,10,2,2
4,6,6,0,0,0,0,4,0,4,2,2
2,2,2,6,0,2,7,0,0,0,2,2
1,1,2,6,6,2,2,6,0,6,2,2
1,1,1,2,2,2,2,4,0,4,2,1
endlayer

layer
1,1,2,1,1,2,2,10,10,10,2,1
2,2,2,2,2,2,2,2,2,2,2,1
2,2,2,2,2,2,2,2,2,2,2,2
10,2,2,2,2,2,2,10,10,10,2,2
10,2,2,2,2,2,2,10,11,10,2,2
10,2,2,2,2,2,2,10,10,10,2,2
2,2,2,2,2,2,2,2,2,2,2,2
1,1,2,2,2,2,2,2,2,2,2,2
1,1,1,2,2,1,2,10,10,10,2,1
endlayer

layer
1,1,2,2,1,2,2,4,5,4,2,1
1,2,2,2,2,2,2,7,5,0,2,2
2,2,7,2,2,2,7,13,5,0,6,2
4,9,0,6,2,6,6,4,5,4,2,2
12,12,12,12,12,12,12,12,11,10,2,2
4,6,0,2,0,0,2,4,5,4,6,2
2,2,2,2,2,7,2,2,5,0,2,2
2,2,2,2,2,2,2,6,5,2,2,2
1,1,1,2,1,1,2,4,5,4,2,2
endlayer

layer
1,1,2,1,1,1,2,4,6,4,2,1
1,2,2,2,2,2,2,0,6,6,2,2
2,2,2,6,2,6,6,0,0,0,0,2
4,0,0,0,0,6,0,4,0,4,6,2
6,0,0,0,0,0,0,0,11,10,2,2
4,0,0,0,0,0,0,4,0,4,6,2
2,6,0,6,0,0,2,0,0,0,0,2
9,2,6,2,6,2,2,6,0,0,6,2
1,1,2,1,2,2,2,4,6,4,2,2
endlayer

layer
1,2,2,2,1,2,2,10,10,10,2,1
2,2,2,2,2,2,2,2,2,2,2,2
2,2,2,2,2,2,2,2,2,2,2,2
10,2,2,2,2,2,2,10,10,10,2,2
10,2,2,2,2,2,2,10,11,10,2,2
10,2,2,2,2,2,2,10,10,10,2,2
2,2,2,2,2,2,2,2,2,2,2,2
3,2,2,2,2,2,2,2,2,2,2,2
1,1,2,2,1,2,2,10,10,10,2,2
endlayer

layer
1,2,2,2,1,2,2,4,5,4,2,1
2,2,2,2,2,2,2,7,5,2,2,2
2,2,2,2,6,2,2,0,5,2,2,2
4,6,6,7,0,6,2,4,5,4,2,2
12,12,12,12,12,12,12,12,11,10,2,2
4,6,0,9,7,0,0,4,5,4,6,2
2,2,6,2,2,6,2,0,5,0,2,2
2,2,2,2,2,2,2,7,5,6,0,2
1,2,2,2,2,2,2,4,5,4,2,2
endlayer

layer
1,2,2,2,2,2,2,4,6,4,2,1
1,2,2,2,2,2,2,6,6,6,2,2
2,6,2,2,6,2,6,0,0,6,2,2
4,0,6,6,0,0,6,4,0,4,6,2
6,0,6,0,6,0,0,0,11,10,2,2
4,0,0,0,6,0,0,4,0,4,6,2
2,6,0,6,0,0,0,0,0,0,0,2
2,2,6,2,6,2,6,7,0,6,6,2
1,2,2,2,2,2,2,4,6,4,2,2
endlayer

layer
1,2,2,2,2,2,2,10,10,10,2,1
1,2,2,2,2,2,2,2,2,2,2,2
2,2,2,2,2,2,2,2,2,2,2,2
10,2,2,2,2,2,2,10,10,10,2,2
10,2,2,2,2,2,2,10,11,10,2,2
10,2,2,2,2,2,2,10,10,10,2,2
2,2,2,2,2,2,2,2,2,2,2,2
2,2,2,2,2,2,2,2,2,2,2,2
1,2,2,2,1,2,2,10,10,10,2,1
endlayer

layer
1,1,2,2,2,2,2,4,5,4,2,1
1,2,2,2,2,2,2,0,5,0,2,2
2,2,6,3,2,2,2,6,5,6,6,2
4,6,14,7,7,2,6,4,5,4,6,2
12,12,12,12,12,12,12,12,11,10,6,2
4,0,0,6,7,0,0,4,5,4,6,2
2,6,0,2,6,0,2,6,5,0,6,2
1,2,6,2,2,6,2,6,5,6,2,2
1,2,2,2,1,2,2,4,5,4,2,1
endlayer

layer
1,1,2,2,2,2,2,4,6,4,2,1
1,2,2,2,2,2,2,6,6,0,2,2
2,2,2,6,6,6,6,6,0,0,6,2
4,6,6,7,0,6,0,4,0,4,6,2
6,6,6,0,0,6,0,0,11,10,6,2
4,6,6,0,0,0,0,4,0,4,0,2
2,2,6,6,0,6,6,0,0,0,2,2
1,2,2,2,6,2,2,6,6,6,2,2
1,1,2,2,2,1,2,4,6,4,2,1
endlayer

layer
1,1,15,15,2,2,2,10,10,10,15,1
1,15,2,2,2,2,2,2,2,2,2,15
15,15,2,2,2,2,2,2,2,2,2,2
10,2,2,2,2,2,2,10,10,10,2,2
10,2,2,2,2,2,2,10,11,10,2,2
10,2,2,2,2,2,2,10,10,10,2,2
15,2,2,2,2,2,2,2,2,2,2,2
1,15,2,2,2,2,2,2,2,2,2,15
1,1,15,2,2,2,2,10,10,10,15,1
endlayer

layer
0,0,16,16,15,15,17,15,17,15,16,0
0,16,0,2,2,2,2,2,2,2,15,16
16,16,2,2,2,2,2,2,18,2,2,15
0,4,4,7,0,0,7,4,6,4,2,2
12,12,12,12,12,12,12,12,0,6,2,2
0,4,4,7,6,0,6,4,5,4,2,2
16,2,2,2,2,2,2,7,5,7,2,15
0,16,2,2,2,2,2,6,0,2,2,16
0,0,16,15,2,2,2,2,2,15,16,0
endlayer

layer
0,0,0,0,16,16,15,16,15,16,0,0
0,0,0,15,2,15,2,17,2,17,16,0
0,0,0,2,2,2,2,2,6,2,17,16
0,14,4,6,0,6,0,4,0,4,2,15
0,0,0,0,6,6,0,0,0,6,7,2
0,14,4,6,0,0,6,4,6,4,2,15
0,0,2,2,2,2,2,6,6,2,2,16
0,0,15,17,2,2,2,0,6,2,15,0
0,0,0,16,15,15,15,2,2,16,0,0
endlayer

layer
0,0,0,0,0,0,16,0,16,0,0,0
0,0,0,16,15,16,15,15,15,15,0,0
0,0,0,2,2,2,2,2,2,2,15,0
0,0,10,2,2,0,6,10,10,10,2,0
0,0,10,6,6,6,0,10,6,10,2,15
0,0,10,2,6,2,0,10,10,10,2,16
0,0,2,2,2,2,2,2,2,2,15,0
0,0,16,15,15,15,15,2,2,15,16,0
0,0,0,0,16,16,16,0,15,0,0,0
endlayer

layer
0,0,0,0,0,0,0,0,0,0,0,0
0,0,0,0,16,0,16,16,16,16,0,0
0,0,0,15,15,15,0,15,15,15,16,0
0,0,0,2,2,2,2,2,2,2,15,0
0,0,0,2,2,2,2,2,2,7,0,16
0,0,0,2,2,2,2,2,2,2,15,0
0,0,0,0,15,15,0,15,15,15,16,0
0,0,0,16,16,16,16,0,0,16,0,0
0,0,0,0,0,0,0,0,16,0,0,0
endlayer

layer
0,0,0,0,0,0,0,0,0,0,0,0
0,0,0,0,0,0,0,0,0,0,0,0
0,0,0,16,16,16,0,16,16,16,0,0
0,0,0,0,15,15,15,7,15,15,16,0
0,0,0,7,15,2,2,17,15,0,0,0
0,0,0,0,15,15,15,15,15,15,16,0
0,0,0,0,16,16,0,16,16,16,0,0
0,0,0,0,0,0,0,0,0,0,0,0
0,0,0,0,0,0,0,0,0,0,0,0
endlayer

layer
0,0,0,0,0,0,0,0,0,0,0,0
0,0,0,0,0,0,0,0,0,0,0,0
0,0,0,0,0,0,0,0,0,0,0,0
0,0,0,0,16,16,16,16,16,16,0,0
0,0,0,16,16,15,7,15,16,0,0,0
0,0,0,0,16,16,16,16,16,16,0,0
0,0,0,0,0,0,0,0,0,0,0,0
0,0,0,0,0,0,0,0,0,0,0,0
0,0,0,0,0,0,0,0,0,0,0,0
endlayer

