# Mushroom Tower -- Side Tower #2
# Created by Ruins mod version 15.5 Ingame Parser
# authoring Player: Jordan_Greywolf
# Updated to MC 1.9: 24 Apr 2016
# Updated to MC 1.11: 12 Jan 2017
# Updated to MC 1.12: 22 Jun 2017

weight=1
embed_into_distance=2
acceptable_target_blocks=
unacceptable_target_blocks=flowing_water,water,flowing_lava,lava
dimensions=14,13,9
allowable_overhang=0
max_leveling=0
leveling_buffer=0
preserve_water=0
preserve_lava=0

rule1=0,100,preserveBlock
rule2=0,100,minecraft:red_mushroom_block-15
rule3=0,100,minecraft:brown_mushroom_block-14
rule4=0,100,minecraft:red_mushroom_block-14
rule5=0,100,ChestGenHook:chests/simple_dungeon:5-5

rule6=0,100,CommandBlock:RUINSTRIGGER /setblock ~0 ~-1 ~0 mob_spawner 0 replace {SpawnData:{HandItems:[{Count:1,id:red_mushroom,tag:{ench:[{id:16,lvl:3}]}},{Count:1,id:brown_mushroom,tag:{ench:[{id:16,lvl:3}]}}],ArmorItems:[{Count:1,id:leather_boots,tag:{display:{color:16768967,Name:"Shroom Boots"}}},{Count:1,id:leather_leggings,tag:{display:{color:16771522,Name:"Shroom Leggings"}}},{Count:1,id:leather_chestplate,tag:{display:{color:16728642,Name:"Shroom Chest"}}},{Count:1,id:red_mushroom_block}],CustomName:"Shroom Zombie",HandDropChances:[0.5F,0.5F],ArmorDropChances:[0.2F,0.2F,0.2F,0.5F],Silent:1,id:zombie}}:@


rule7=0,100,minecraft:ladder-4
rule8=0,100,minecraft:jungle_door-0
rule9=0,100,minecraft:jungle_door-8
rule10=0,100,minecraft:jungle_fence-0

layer
1,1,1,1,1,1,1,1,1
1,1,1,1,1,1,1,1,1
1,1,1,1,1,1,1,1,1
1,1,1,1,2,1,1,1,1
1,1,1,2,2,2,1,1,1
1,1,1,1,2,1,1,1,1
1,1,1,1,1,1,1,1,1
1,1,1,1,1,1,1,1,1
1,1,1,1,1,1,1,1,1
1,1,1,1,1,1,1,1,1
1,1,1,1,1,1,1,1,1
1,1,1,1,1,1,1,1,1
1,1,1,1,1,1,1,1,1
endlayer

layer
1,1,1,1,1,1,1,1,1
1,1,1,1,1,1,1,1,1
1,1,1,1,2,1,1,1,1
1,1,1,2,3,2,1,1,1
1,1,2,3,3,3,2,1,1
1,1,1,2,3,2,1,1,1
1,1,1,1,2,1,1,1,1
1,1,1,1,2,1,1,1,1
1,1,1,1,2,1,1,1,1
1,1,1,1,2,1,1,1,1
1,1,1,1,2,1,1,1,1
1,1,1,1,2,1,1,1,1
1,1,1,1,2,1,1,1,1
endlayer

layer
1,1,1,1,1,1,1,1,1
1,1,1,1,1,1,1,1,1
1,1,1,2,2,2,1,1,1
1,1,2,4,3,4,2,1,1
1,1,2,3,4,3,2,1,1
1,1,2,4,3,4,2,1,1
1,1,1,2,3,2,1,1,1
1,1,1,2,3,2,1,1,1
1,1,1,2,3,2,1,1,1
1,1,1,2,3,2,1,1,1
1,1,1,2,3,2,1,1,1
1,1,1,2,3,2,1,1,1
1,1,1,2,3,2,1,1,1
endlayer

layer
1,1,1,1,1,1,1,1,1
1,1,1,1,1,1,1,1,1
1,1,1,2,2,2,1,1,1
1,1,2,5,0,5,2,1,1
1,1,2,0,0,0,2,1,1
1,1,2,0,0,7,2,1,1
1,1,1,2,0,2,1,1,1
1,1,1,2,0,2,1,1,1
1,1,1,2,0,2,1,1,1
1,1,1,2,0,2,1,1,1
1,1,1,2,0,2,1,1,1
1,1,1,2,0,2,1,1,1
1,1,1,2,8,2,1,1,1
endlayer

layer
1,1,1,1,1,1,1,1,1
1,1,1,1,1,1,1,1,1
1,1,1,2,10,2,1,1,1
1,1,2,0,6,0,2,1,1
1,1,10,0,0,0,10,1,1
1,1,2,0,0,7,2,1,1
1,1,1,2,0,2,1,1,1
1,1,1,10,0,10,1,1,1
1,1,1,2,0,2,1,1,1
1,1,1,10,0,10,1,1,1
1,1,1,2,0,2,1,1,1
1,1,1,10,0,10,1,1,1
1,1,1,2,9,2,1,1,1
endlayer

layer
1,1,1,1,1,1,1,1,1
1,1,1,1,1,1,1,1,1
1,1,1,2,10,2,1,1,1
1,1,2,0,0,0,2,1,1
1,1,10,0,0,0,10,1,1
1,1,2,0,0,7,2,1,1
1,1,1,2,0,2,1,1,1
1,1,1,10,0,10,1,1,1
1,1,1,2,0,2,1,1,1
1,1,1,10,0,10,1,1,1
1,1,1,2,0,2,1,1,1
1,1,1,10,0,10,1,1,1
1,1,1,2,2,2,1,1,1
endlayer

layer
1,1,1,1,1,1,1,1,1
1,1,1,1,1,1,1,1,1
1,1,1,2,10,2,1,1,1
1,1,2,0,0,0,2,1,1
1,1,10,0,0,0,10,1,1
1,1,2,0,0,7,2,1,1
1,1,1,2,0,2,1,1,1
1,1,1,2,0,2,1,1,1
1,1,1,2,0,2,1,1,1
1,1,1,2,0,2,1,1,1
1,1,1,2,0,2,1,1,1
1,1,1,2,0,2,1,1,1
1,1,1,2,2,2,1,1,1
endlayer

layer
1,1,1,1,1,1,1,1,1
1,1,1,1,1,1,1,1,1
1,1,1,2,2,2,1,1,1
1,1,2,0,0,0,2,1,1
1,1,2,0,0,0,2,1,1
1,1,2,0,0,7,2,1,1
1,1,1,2,2,2,1,1,1
1,1,1,1,2,1,1,1,1
1,1,1,1,2,1,1,1,1
1,1,1,1,2,1,1,1,1
1,1,1,1,2,1,1,1,1
1,1,1,1,2,1,1,1,1
1,1,1,1,2,1,1,1,1
endlayer

layer
1,1,1,4,4,4,1,1,1
1,1,4,4,4,4,4,1,1
1,4,4,4,4,4,4,4,1
4,4,4,4,3,4,4,4,4
4,4,4,3,4,3,4,4,4
4,4,4,4,3,7,4,4,4
1,4,4,4,4,4,4,4,1
1,1,4,4,4,4,4,1,1
1,1,1,1,1,1,1,1,1
1,1,1,1,1,1,1,1,1
1,1,1,1,1,1,1,1,1
1,1,1,1,1,1,1,1,1
1,1,1,1,1,1,1,1,1
endlayer

layer
1,1,1,1,1,1,1,1,1
1,1,1,4,4,4,1,1,1
1,1,4,2,2,2,4,1,1
1,4,2,5,0,0,2,4,1
1,4,2,0,0,0,2,4,1
1,4,2,0,0,0,2,4,1
1,1,4,2,2,2,4,1,1
1,1,1,4,4,4,1,1,1
1,1,1,1,1,1,1,1,1
1,1,1,1,1,1,1,1,1
1,1,1,1,1,1,1,1,1
1,1,1,1,1,1,1,1,1
1,1,1,1,1,1,1,1,1
endlayer

layer
1,1,1,1,1,1,1,1,1
1,1,1,4,4,4,1,1,1
1,1,4,2,2,2,4,1,1
1,4,2,6,0,0,2,4,1
1,4,2,0,0,0,2,4,1
1,4,2,0,0,0,2,4,1
1,1,4,2,2,2,4,1,1
1,1,1,4,4,4,1,1,1
1,1,1,1,1,1,1,1,1
1,1,1,1,1,1,1,1,1
1,1,1,1,1,1,1,1,1
1,1,1,1,1,1,1,1,1
1,1,1,1,1,1,1,1,1
endlayer

layer
1,1,1,1,1,1,1,1,1
1,1,1,4,4,4,1,1,1
1,1,4,2,2,2,4,1,1
1,4,2,2,0,2,2,4,1
1,4,2,0,0,0,2,4,1
1,4,2,2,0,2,2,4,1
1,1,4,2,2,2,4,1,1
1,1,1,4,4,4,1,1,1
1,1,1,1,1,1,1,1,1
1,1,1,1,1,1,1,1,1
1,1,1,1,1,1,1,1,1
1,1,1,1,1,1,1,1,1
1,1,1,1,1,1,1,1,1
endlayer

layer
1,1,1,1,1,1,1,1,1
1,1,1,1,1,1,1,1,1
1,1,1,4,4,4,1,1,1
1,1,4,2,2,2,4,1,1
1,1,4,2,2,2,4,1,1
1,1,4,2,2,2,4,1,1
1,1,1,4,4,4,1,1,1
1,1,1,1,1,1,1,1,1
1,1,1,1,1,1,1,1,1
1,1,1,1,1,1,1,1,1
1,1,1,1,1,1,1,1,1
1,1,1,1,1,1,1,1,1
1,1,1,1,1,1,1,1,1
endlayer

layer
1,1,1,1,1,1,1,1,1
1,1,1,1,1,1,1,1,1
1,1,1,1,1,1,1,1,1
1,1,1,4,4,4,1,1,1
1,1,1,4,4,4,1,1,1
1,1,1,4,4,4,1,1,1
1,1,1,1,1,1,1,1,1
1,1,1,1,1,1,1,1,1
1,1,1,1,1,1,1,1,1
1,1,1,1,1,1,1,1,1
1,1,1,1,1,1,1,1,1
1,1,1,1,1,1,1,1,1
1,1,1,1,1,1,1,1,1
endlayer

