# Mushroom Tower Roof -- MC 1.8; 2 Apr 2016
# Created by Ruins mod version 15.5 Ingame Parser
# authoring Player: Jordan_Greywolf
# Updated to MC 1.9: 24 Apr 2016
# Updated to MC 1.11: 12 Jan 2017
# Updated to MC 1.12: 22 Jun 2017

weight=1
embed_into_distance=0
acceptable_target_blocks=
unacceptable_target_blocks=flowing_water,water,flowing_lava,lava
dimensions=10,27,27
allowable_overhang=0
max_leveling=0
leveling_buffer=0
preserve_water=0
preserve_lava=0

rule1=0,100,minecraft:red_mushroom_block-14
rule2=0,100,minecraft:red_mushroom_block-15

# Experimental (does not work)
#rule3=0,100,CommandBlock:RUINSTRIGGER /summon "BattleTowers.Battletower Golem" ~0 ~2 ~0:@

# No-Pickup Version
#rule3=0,100,CommandBlock:RUINSTRIGGER /summon Item ~ ~2 ~ {Item:{id:red_mushroom_block,Count:1},Age:-32768,PickupDelay:32767,Health:32768,Passengers:[{id:"Blaze",CustomName:"Mushroom Spirit",HandItems:[{id:spawn_egg,Damage:96,Count:8,tag:{EntityTag:{id:"MushroomCow"}}},{}],Armoritems:[{},{},{},{id:red_mushroom_block,Count:64}],HandDropChances:[2.0F,0.0F],ArmorDropChances:[0.0F,0.0F,0.0F,2.0F],Attributes:[{Name:generic.movementSpeed,Base:0.1}],ActiveEffects:[{Id:14,Amplifier:1,Duration:999999,Ambient:1}],Silent:1,PersistenceRequired:1,Health:150.0f}]}:@

rule3=0,100,CommandBlock:RUINSTRIGGER /summon Item ~ ~2 ~ {Item:{id:red_mushroom_block,Count:1},Age:-32768,Health:32768,Passengers:[{id:"blaze",CustomName:"Mushroom Spirit",HandItems:[{id:spawn_egg,Damage:96,Count:8,tag:{EntityTag:{id:"mooshroom"}}},{}],Armoritems:[{},{},{},{id:red_mushroom_block,Count:64}],HandDropChances:[2.0F,0.0F],ArmorDropChances:[0.0F,0.0F,0.0F,2.0F],Attributes:[{Name:generic.movementSpeed,Base:0.1}],ActiveEffects:[{Id:14,Amplifier:1,Duration:999999,Ambient:1}],Silent:1,PersistenceRequired:1,Health:150.0f}]}:@

rule4=0,100,ChestGenHook:chests/simple_dungeon:5-4
rule5=0,100,ChestGenHook:chests/simple_dungeon:5-2
rule6=0,100,ChestGenHook:chests/simple_dungeon:5-3
rule7=0,100,ChestGenHook:chests/simple_dungeon:5-5

rule8=0,100,CommandBlock:RUINSTRIGGER /setblock ~0 ~-1 ~0 mob_spawner 0 replace {SpawnData:{HandItems:[{Count:1,id:red_mushroom,tag:{ench:[{id:16,lvl:3}]}},{Count:1,id:brown_mushroom,tag:{ench:[{id:16,lvl:3}]}}],ArmorItems:[{Count:1,id:leather_boots,tag:{display:{color:16768967,Name:"Shroom Boots"}}},{Count:1,id:leather_leggings,tag:{display:{color:16771522,Name:"Shroom Leggings"}}},{Count:1,id:leather_chestplate,tag:{display:{color:16728642,Name:"Shroom Chest"}}},{Count:1,id:red_mushroom_block}],CustomName:"Shroom Zombie",HandDropChances:[0.5F,0.5F],ArmorDropChances:[0.2F,0.2F,0.2F,0.5F],Silent:1,id:zombie}}:@

rule9=0,100,preserveBlock

layer
9,9,9,9,9,9,9,9,9,9,1,1,1,1,1,1,1,9,9,9,9,9,9,9,9,9,9
9,9,9,9,9,9,1,1,1,1,9,9,9,9,9,9,9,1,1,1,1,9,9,9,9,9,9
9,9,9,9,1,1,9,9,9,9,9,9,9,9,9,9,9,9,9,9,9,1,1,9,9,9,9
9,9,9,1,9,9,9,9,9,9,9,9,9,9,9,9,9,9,9,9,9,9,9,1,9,9,9
9,9,1,9,9,9,9,9,9,9,9,9,9,9,9,9,9,9,9,9,9,9,9,9,1,9,9
9,9,1,9,9,9,9,9,9,9,9,9,9,9,9,9,9,9,9,9,9,9,9,9,1,9,9
9,1,9,9,9,9,9,9,9,9,9,9,9,9,9,9,9,9,9,9,9,9,9,9,9,1,9
9,1,9,9,9,9,9,9,9,9,9,9,9,9,9,9,9,9,9,9,9,9,9,9,9,1,9
9,1,9,9,9,9,9,9,9,9,9,9,9,9,9,9,9,9,9,9,9,9,9,9,9,1,9
9,1,9,9,9,9,9,9,9,9,9,9,9,9,9,9,9,9,9,9,9,9,9,9,9,1,9
1,9,9,9,9,9,9,9,9,9,9,9,9,9,9,9,9,9,9,9,9,9,9,9,9,9,1
1,9,9,9,9,9,9,9,9,9,9,9,9,2,9,9,9,9,9,9,9,9,9,9,9,9,1
1,9,9,9,9,9,9,9,9,9,9,9,2,2,2,9,9,9,9,9,3,9,9,9,9,9,1
1,9,9,9,9,9,9,9,9,9,9,2,2,2,2,2,9,9,9,9,9,9,9,9,9,9,1
1,9,9,9,9,9,9,9,9,9,9,9,2,2,2,9,9,9,9,9,9,9,9,9,9,9,1
1,9,9,9,9,9,9,9,9,9,9,9,9,2,9,9,9,9,9,9,9,9,9,9,9,9,1
1,9,9,9,9,9,9,9,9,9,9,9,9,9,9,9,9,9,9,9,9,9,9,9,9,9,1
9,1,9,9,9,9,9,9,9,9,9,9,9,9,9,9,9,9,9,9,9,9,9,9,9,1,9
9,1,9,9,9,9,9,9,9,9,9,9,9,9,9,9,9,9,9,9,9,9,9,9,9,1,9
9,1,9,9,9,9,9,9,9,9,9,9,9,9,9,9,9,9,9,9,9,9,9,9,9,1,9
9,1,9,9,9,9,9,9,9,9,9,9,9,9,9,9,9,9,9,9,9,9,9,9,9,1,9
9,9,1,9,9,9,9,9,9,9,9,9,9,9,9,9,9,9,9,9,9,9,9,9,1,9,9
9,9,1,9,9,9,9,9,9,9,9,9,9,9,9,9,9,9,9,9,9,9,9,9,1,9,9
9,9,9,1,9,9,9,9,9,9,9,9,9,9,9,9,9,9,9,9,9,9,9,1,9,9,9
9,9,9,9,1,1,9,9,9,9,9,9,9,9,9,9,9,9,9,9,9,1,1,9,9,9,9
9,9,9,9,9,9,1,1,1,1,9,9,9,9,9,9,9,1,1,1,1,9,9,9,9,9,9
9,9,9,9,9,9,9,9,9,9,1,1,1,1,1,1,1,9,9,9,9,9,9,9,9,9,9
endlayer

layer
9,9,9,9,9,9,9,9,9,9,1,1,1,1,1,1,1,9,9,9,9,9,9,9,9,9,9
9,9,9,9,9,9,1,1,1,1,1,9,9,9,9,9,1,1,1,1,1,9,9,9,9,9,9
9,9,9,9,1,1,9,9,9,9,9,9,9,9,9,9,9,9,9,9,9,1,1,9,9,9,9
9,9,9,1,9,9,9,9,9,9,9,9,9,9,9,9,9,9,9,9,9,9,9,1,9,9,9
9,9,1,9,9,9,9,9,9,9,9,9,9,9,9,9,9,9,9,9,9,9,9,9,1,9,9
9,9,1,9,9,9,9,9,9,9,9,9,9,9,9,9,9,9,9,9,9,9,9,9,1,9,9
9,1,9,9,9,9,9,9,9,9,9,9,9,9,9,9,9,9,9,9,9,9,9,9,9,1,9
9,1,9,9,9,9,9,9,9,9,9,9,9,9,9,9,9,9,9,9,9,9,9,9,9,1,9
9,1,9,9,9,9,9,9,9,9,9,9,9,9,9,9,9,9,9,9,9,9,9,9,9,1,9
9,1,9,9,9,9,9,9,9,9,9,9,9,9,9,9,9,9,9,9,9,9,9,9,9,1,9
1,1,9,9,9,9,9,9,9,9,9,9,9,9,9,9,9,9,9,9,9,9,9,9,9,1,1
1,9,9,9,9,9,9,9,9,9,9,9,9,4,9,9,9,9,9,9,9,9,9,9,9,9,1
1,9,9,9,9,9,9,9,9,9,9,9,2,2,2,9,9,9,9,9,9,9,9,9,9,9,1
1,9,9,9,9,9,9,9,9,9,9,6,2,2,2,5,9,9,9,9,9,9,9,9,9,9,1
1,9,9,9,9,9,9,9,9,9,9,9,2,2,2,9,9,9,9,9,9,9,9,9,9,9,1
1,9,9,9,9,9,9,9,9,9,9,9,9,7,9,9,9,9,9,9,9,9,9,9,9,9,1
1,1,9,9,9,9,9,9,9,9,9,9,9,9,9,9,9,9,9,9,9,9,9,9,9,1,1
9,1,9,9,9,9,9,9,9,9,9,9,9,9,9,9,9,9,9,9,9,9,9,9,9,1,9
9,1,9,9,9,9,9,9,9,9,9,9,9,9,9,9,9,9,9,9,9,9,9,9,9,1,9
9,1,9,9,9,9,9,9,9,9,9,9,9,9,9,9,9,9,9,9,9,9,9,9,9,1,9
9,1,9,9,9,9,9,9,9,9,9,9,9,9,9,9,9,9,9,9,9,9,9,9,9,1,9
9,9,1,9,9,9,9,9,9,9,9,9,9,9,9,9,9,9,9,9,9,9,9,9,1,9,9
9,9,1,9,9,9,9,9,9,9,9,9,9,9,9,9,9,9,9,9,9,9,9,9,1,9,9
9,9,9,1,9,9,9,9,9,9,9,9,9,9,9,9,9,9,9,9,9,9,9,1,9,9,9
9,9,9,9,1,1,9,9,9,9,9,9,9,9,9,9,9,9,9,9,9,1,1,9,9,9,9
9,9,9,9,9,9,1,1,1,1,1,9,9,9,9,9,1,1,1,1,1,9,9,9,9,9,9
9,9,9,9,9,9,9,9,9,9,1,1,1,1,1,1,1,9,9,9,9,9,9,9,9,9,9
endlayer

layer
9,9,9,9,9,9,9,9,9,9,9,1,1,1,1,1,9,9,9,9,9,9,9,9,9,9,9
9,9,9,9,9,9,9,1,1,1,1,9,9,9,9,9,1,1,1,1,9,9,9,9,9,9,9
9,9,9,9,9,1,1,1,9,9,9,9,9,9,9,9,9,9,9,1,1,1,9,9,9,9,9
9,9,9,9,1,1,9,9,9,9,9,9,9,9,9,9,9,9,9,9,9,1,1,9,9,9,9
9,9,9,1,9,9,9,9,9,9,9,9,9,9,9,9,9,9,9,9,9,9,9,1,9,9,9
9,9,1,1,9,9,9,9,9,9,9,9,9,9,9,9,9,9,9,9,9,9,9,1,1,9,9
9,9,1,9,9,9,9,9,9,9,9,9,9,9,9,9,9,9,9,9,9,9,9,9,1,9,9
9,1,1,9,9,9,9,9,9,9,9,9,9,9,9,9,9,9,9,9,9,9,9,9,1,1,9
9,1,9,9,9,9,9,9,9,9,9,9,9,9,9,9,9,9,9,9,9,9,9,9,9,1,9
9,1,9,9,9,9,9,9,9,9,9,9,9,9,9,9,9,9,9,9,9,9,9,9,9,1,9
9,1,9,9,9,9,9,9,9,9,9,9,9,9,9,9,9,9,9,9,9,9,9,9,9,1,9
1,9,9,9,9,9,9,9,9,9,9,9,9,9,9,9,9,9,9,9,9,9,9,9,9,9,1
1,9,9,9,9,9,9,9,9,9,9,9,9,2,9,9,9,9,9,9,9,9,9,9,9,9,1
1,9,9,9,9,9,9,9,9,9,9,9,2,2,2,9,9,9,9,9,9,9,9,9,9,9,1
1,9,9,9,9,9,9,9,9,9,9,9,9,2,9,9,9,9,9,9,9,9,9,9,9,9,1
1,9,9,9,9,9,9,9,9,9,9,9,9,9,9,9,9,9,9,9,9,9,9,9,9,9,1
9,1,9,9,9,9,9,9,9,9,9,9,9,9,9,9,9,9,9,9,9,9,9,9,9,1,9
9,1,9,9,9,9,9,9,9,9,9,9,9,9,9,9,9,9,9,9,9,9,9,9,9,1,9
9,1,9,9,9,9,9,9,9,9,9,9,9,9,9,9,9,9,9,9,9,9,9,9,9,1,9
9,1,1,9,9,9,9,9,9,9,9,9,9,9,9,9,9,9,9,9,9,9,9,9,1,1,9
9,9,1,9,9,9,9,9,9,9,9,9,9,9,9,9,9,9,9,9,9,9,9,9,1,9,9
9,9,1,1,9,9,9,9,9,9,9,9,9,9,9,9,9,9,9,9,9,9,9,1,1,9,9
9,9,9,1,9,9,9,9,9,9,9,9,9,9,9,9,9,9,9,9,9,9,9,1,9,9,9
9,9,9,9,1,1,9,9,9,9,9,9,9,9,9,9,9,9,9,9,9,1,1,9,9,9,9
9,9,9,9,9,1,1,1,9,9,9,9,9,9,9,9,9,9,9,1,1,1,9,9,9,9,9
9,9,9,9,9,9,9,1,1,1,1,9,9,9,9,9,1,1,1,1,9,9,9,9,9,9,9
9,9,9,9,9,9,9,9,9,9,9,1,1,1,1,1,9,9,9,9,9,9,9,9,9,9,9
endlayer

layer
9,9,9,9,9,9,9,9,9,9,9,1,1,1,1,1,9,9,9,9,9,9,9,9,9,9,9
9,9,9,9,9,9,9,9,1,1,1,9,9,9,9,9,1,1,1,9,9,9,9,9,9,9,9
9,9,9,9,9,9,1,1,9,9,9,9,9,9,9,9,9,9,9,1,1,9,9,9,9,9,9
9,9,9,9,1,1,9,9,9,9,9,9,9,9,9,9,9,9,9,9,9,1,1,9,9,9,9
9,9,9,1,9,9,9,9,9,9,9,9,9,9,9,9,9,9,9,9,9,9,9,1,9,9,9
9,9,9,1,9,9,9,9,9,9,9,9,9,9,9,9,9,9,9,9,9,9,9,1,9,9,9
9,9,1,9,9,9,9,9,9,9,9,9,9,9,9,9,9,9,9,9,9,9,9,9,1,9,9
9,9,1,9,9,9,9,9,9,9,9,9,9,9,9,9,9,9,9,9,9,9,9,9,1,9,9
9,1,9,9,9,9,9,9,9,9,9,9,9,9,9,9,9,9,9,9,9,9,9,9,9,1,9
9,1,9,9,9,9,9,9,9,9,9,9,9,9,9,9,9,9,9,9,9,9,9,9,9,1,9
9,1,9,9,9,9,9,9,9,9,9,9,9,9,9,9,9,9,9,9,9,9,9,9,9,1,9
1,9,9,9,9,9,9,9,9,9,9,9,9,9,9,9,9,9,9,9,9,9,9,9,9,9,1
1,9,9,9,9,9,9,9,9,9,9,9,8,2,8,9,9,9,9,9,9,9,9,9,9,9,1
1,9,9,9,9,9,9,9,9,9,9,9,2,2,2,9,9,9,9,9,9,9,9,9,9,9,1
1,9,9,9,9,9,9,9,9,9,9,9,8,2,8,9,9,9,9,9,9,9,9,9,9,9,1
1,9,9,9,9,9,9,9,9,9,9,9,9,9,9,9,9,9,9,9,9,9,9,9,9,9,1
9,1,9,9,9,9,9,9,9,9,9,9,9,9,9,9,9,9,9,9,9,9,9,9,9,1,9
9,1,9,9,9,9,9,9,9,9,9,9,9,9,9,9,9,9,9,9,9,9,9,9,9,1,9
9,1,9,9,9,9,9,9,9,9,9,9,9,9,9,9,9,9,9,9,9,9,9,9,9,1,9
9,9,1,9,9,9,9,9,9,9,9,9,9,9,9,9,9,9,9,9,9,9,9,9,1,9,9
9,9,1,9,9,9,9,9,9,9,9,9,9,9,9,9,9,9,9,9,9,9,9,9,1,9,9
9,9,9,1,9,9,9,9,9,9,9,9,9,9,9,9,9,9,9,9,9,9,9,1,9,9,9
9,9,9,1,9,9,9,9,9,9,9,9,9,9,9,9,9,9,9,9,9,9,9,1,9,9,9
9,9,9,9,1,1,9,9,9,9,9,9,9,9,9,9,9,9,9,9,9,1,1,9,9,9,9
9,9,9,9,9,9,1,1,9,9,9,9,9,9,9,9,9,9,9,1,1,9,9,9,9,9,9
9,9,9,9,9,9,9,9,1,1,1,9,9,9,9,9,1,1,1,9,9,9,9,9,9,9,9
9,9,9,9,9,9,9,9,9,9,9,1,1,1,1,1,9,9,9,9,9,9,9,9,9,9,9
endlayer

layer
9,9,9,9,9,9,9,9,9,9,9,9,1,1,1,9,9,9,9,9,9,9,9,9,9,9,9
9,9,9,9,9,9,9,9,9,9,1,1,1,1,1,1,1,9,9,9,9,9,9,9,9,9,9
9,9,9,9,9,9,9,1,1,1,1,1,9,9,9,1,1,1,1,1,9,9,9,9,9,9,9
9,9,9,9,9,1,1,1,9,9,9,9,9,9,9,9,9,9,9,1,1,1,9,9,9,9,9
9,9,9,9,1,1,9,9,9,9,9,9,9,9,9,9,9,9,9,9,9,1,1,9,9,9,9
9,9,9,1,1,9,9,9,9,9,9,9,9,9,9,9,9,9,9,9,9,9,1,1,9,9,9
9,9,9,1,9,9,9,9,9,9,9,9,9,9,9,9,9,9,9,9,9,9,9,1,9,9,9
9,9,1,1,9,9,9,9,9,9,9,9,9,9,9,9,9,9,9,9,9,9,9,1,1,9,9
9,9,1,9,9,9,9,9,9,9,9,9,9,9,9,9,9,9,9,9,9,9,9,9,1,9,9
9,9,1,9,9,9,9,9,9,9,9,9,9,9,9,9,9,9,9,9,9,9,9,9,1,9,9
9,1,1,9,9,9,9,9,9,9,9,9,9,9,9,9,9,9,9,9,9,9,9,9,1,1,9
9,1,1,9,9,9,9,9,9,9,9,9,9,9,9,9,9,9,9,9,9,9,9,9,1,1,9
1,1,9,9,9,9,9,9,9,9,9,9,9,9,9,9,9,9,9,9,9,9,9,9,9,1,1
1,1,9,9,9,9,9,9,9,9,9,9,9,2,9,9,9,9,9,9,9,9,9,9,9,1,1
1,1,9,9,9,9,9,9,9,9,9,9,9,9,9,9,9,9,9,9,9,9,9,9,9,1,1
9,1,1,9,9,9,9,9,9,9,9,9,9,9,9,9,9,9,9,9,9,9,9,9,1,1,9
9,1,1,9,9,9,9,9,9,9,9,9,9,9,9,9,9,9,9,9,9,9,9,9,1,1,9
9,9,1,9,9,9,9,9,9,9,9,9,9,9,9,9,9,9,9,9,9,9,9,9,1,9,9
9,9,1,9,9,9,9,9,9,9,9,9,9,9,9,9,9,9,9,9,9,9,9,9,1,9,9
9,9,1,1,9,9,9,9,9,9,9,9,9,9,9,9,9,9,9,9,9,9,9,1,1,9,9
9,9,9,1,9,9,9,9,9,9,9,9,9,9,9,9,9,9,9,9,9,9,9,1,9,9,9
9,9,9,1,1,9,9,9,9,9,9,9,9,9,9,9,9,9,9,9,9,9,1,1,9,9,9
9,9,9,9,1,1,9,9,9,9,9,9,9,9,9,9,9,9,9,9,9,1,1,9,9,9,9
9,9,9,9,9,1,1,1,9,9,9,9,9,9,9,9,9,9,9,1,1,1,9,9,9,9,9
9,9,9,9,9,9,9,1,1,1,1,1,9,9,9,1,1,1,1,1,9,9,9,9,9,9,9
9,9,9,9,9,9,9,9,9,9,1,1,1,1,1,1,1,9,9,9,9,9,9,9,9,9,9
9,9,9,9,9,9,9,9,9,9,9,9,1,1,1,9,9,9,9,9,9,9,9,9,9,9,9
endlayer

layer
9,9,9,9,9,9,9,9,9,9,9,9,9,9,9,9,9,9,9,9,9,9,9,9,9,9,9
9,9,9,9,9,9,9,9,9,9,9,9,9,1,9,9,9,9,9,9,9,9,9,9,9,9,9
9,9,9,9,9,9,9,9,9,9,9,1,1,1,1,1,9,9,9,9,9,9,9,9,9,9,9
9,9,9,9,9,9,9,9,1,1,1,1,1,1,1,1,1,1,1,9,9,9,9,9,9,9,9
9,9,9,9,9,9,1,1,1,1,9,9,9,9,9,9,9,1,1,1,1,9,9,9,9,9,9
9,9,9,9,9,1,1,1,9,9,9,9,9,9,9,9,9,9,9,1,1,1,9,9,9,9,9
9,9,9,9,1,1,1,9,9,9,9,9,9,9,9,9,9,9,9,9,1,1,1,9,9,9,9
9,9,9,9,1,1,9,9,9,9,9,9,9,9,9,9,9,9,9,9,9,1,1,9,9,9,9
9,9,9,1,1,9,9,9,9,9,9,9,9,9,9,9,9,9,9,9,9,9,1,1,9,9,9
9,9,9,1,1,9,9,9,9,9,9,9,9,9,9,9,9,9,9,9,9,9,1,1,9,9,9
9,9,9,1,9,9,9,9,9,9,9,9,9,9,9,9,9,9,9,9,9,9,9,1,9,9,9
9,9,1,1,9,9,9,9,9,9,9,9,9,9,9,9,9,9,9,9,9,9,9,1,1,9,9
9,9,1,1,9,9,9,9,9,9,9,9,9,9,9,9,9,9,9,9,9,9,9,1,1,9,9
9,1,1,1,9,9,9,9,9,9,9,9,9,2,9,9,9,9,9,9,9,9,9,1,1,1,9
9,9,1,1,9,9,9,9,9,9,9,9,9,9,9,9,9,9,9,9,9,9,9,1,1,9,9
9,9,1,1,9,9,9,9,9,9,9,9,9,9,9,9,9,9,9,9,9,9,9,1,1,9,9
9,9,9,1,9,9,9,9,9,9,9,9,9,9,9,9,9,9,9,9,9,9,9,1,9,9,9
9,9,9,1,1,9,9,9,9,9,9,9,9,9,9,9,9,9,9,9,9,9,1,1,9,9,9
9,9,9,1,1,9,9,9,9,9,9,9,9,9,9,9,9,9,9,9,9,9,1,1,9,9,9
9,9,9,9,1,1,9,9,9,9,9,9,9,9,9,9,9,9,9,9,9,1,1,9,9,9,9
9,9,9,9,1,1,1,9,9,9,9,9,9,9,9,9,9,9,9,9,1,1,1,9,9,9,9
9,9,9,9,9,1,1,1,9,9,9,9,9,9,9,9,9,9,9,1,1,1,9,9,9,9,9
9,9,9,9,9,9,1,1,1,1,9,9,9,9,9,9,9,1,1,1,1,9,9,9,9,9,9
9,9,9,9,9,9,9,9,1,1,1,1,1,1,1,1,1,1,1,9,9,9,9,9,9,9,9
9,9,9,9,9,9,9,9,9,9,9,1,1,1,1,1,9,9,9,9,9,9,9,9,9,9,9
9,9,9,9,9,9,9,9,9,9,9,9,9,1,9,9,9,9,9,9,9,9,9,9,9,9,9
9,9,9,9,9,9,9,9,9,9,9,9,9,9,9,9,9,9,9,9,9,9,9,9,9,9,9
endlayer

layer
0,0,0,0,0,0,0,0,0,0,0,0,0,0,0,0,0,0,0,0,0,0,0,0,0,0,0
0,0,0,0,0,0,0,0,0,0,0,0,0,0,0,0,0,0,0,0,0,0,0,0,0,0,0
0,0,0,0,0,0,0,0,0,0,0,0,0,0,0,0,0,0,0,0,0,0,0,0,0,0,0
0,0,0,0,0,0,0,0,0,0,0,0,0,1,0,0,0,0,0,0,0,0,0,0,0,0,0
0,0,0,0,0,0,0,0,0,0,1,1,1,1,1,1,1,0,0,0,0,0,0,0,0,0,0
0,0,0,0,0,0,0,1,1,1,1,1,1,1,1,1,1,1,1,1,0,0,0,0,0,0,0
0,0,0,0,0,0,1,1,1,1,1,0,0,0,0,0,1,1,1,1,1,0,0,0,0,0,0
0,0,0,0,0,1,1,1,0,0,0,0,0,0,0,0,0,0,0,1,1,1,0,0,0,0,0
0,0,0,0,0,1,1,0,0,0,0,0,0,0,0,0,0,0,0,0,1,1,0,0,0,0,0
0,0,0,0,0,1,1,0,0,0,0,0,0,0,0,0,0,0,0,0,1,1,0,0,0,0,0
0,0,0,0,1,1,1,0,0,0,0,0,0,0,0,0,0,0,0,0,1,1,1,0,0,0,0
0,0,0,0,1,1,0,0,0,0,0,0,0,0,0,0,0,0,0,0,0,1,1,0,0,0,0
0,0,0,0,1,1,0,0,0,0,0,0,0,2,0,0,0,0,0,0,0,1,1,0,0,0,0
0,0,0,1,1,1,0,0,0,0,0,0,2,2,2,0,0,0,0,0,0,1,1,1,0,0,0
0,0,0,0,1,1,0,0,0,0,0,0,0,2,0,0,0,0,0,0,0,1,1,0,0,0,0
0,0,0,0,1,1,0,0,0,0,0,0,0,0,0,0,0,0,0,0,0,1,1,0,0,0,0
0,0,0,0,1,1,1,0,0,0,0,0,0,0,0,0,0,0,0,0,1,1,1,0,0,0,0
0,0,0,0,0,1,1,0,0,0,0,0,0,0,0,0,0,0,0,0,1,1,0,0,0,0,0
0,0,0,0,0,1,1,0,0,0,0,0,0,0,0,0,0,0,0,0,1,1,0,0,0,0,0
0,0,0,0,0,1,1,1,0,0,0,0,0,0,0,0,0,0,0,1,1,1,0,0,0,0,0
0,0,0,0,0,0,1,1,1,1,1,0,0,0,0,0,1,1,1,1,1,0,0,0,0,0,0
0,0,0,0,0,0,0,1,1,1,1,1,1,1,1,1,1,1,1,1,0,0,0,0,0,0,0
0,0,0,0,0,0,0,0,0,0,1,1,1,1,1,1,1,0,0,0,0,0,0,0,0,0,0
0,0,0,0,0,0,0,0,0,0,0,0,0,1,0,0,0,0,0,0,0,0,0,0,0,0,0
0,0,0,0,0,0,0,0,0,0,0,0,0,0,0,0,0,0,0,0,0,0,0,0,0,0,0
0,0,0,0,0,0,0,0,0,0,0,0,0,0,0,0,0,0,0,0,0,0,0,0,0,0,0
0,0,0,0,0,0,0,0,0,0,0,0,0,0,0,0,0,0,0,0,0,0,0,0,0,0,0
endlayer

layer
0,0,0,0,0,0,0,0,0,0,0,0,0,0,0,0,0,0,0,0,0,0,0,0,0,0,0
0,0,0,0,0,0,0,0,0,0,0,0,0,0,0,0,0,0,0,0,0,0,0,0,0,0,0
0,0,0,0,0,0,0,0,0,0,0,0,0,0,0,0,0,0,0,0,0,0,0,0,0,0,0
0,0,0,0,0,0,0,0,0,0,0,0,0,0,0,0,0,0,0,0,0,0,0,0,0,0,0
0,0,0,0,0,0,0,0,0,0,0,0,0,0,0,0,0,0,0,0,0,0,0,0,0,0,0
0,0,0,0,0,0,0,0,0,0,0,1,1,1,1,1,0,0,0,0,0,0,0,0,0,0,0
0,0,0,0,0,0,0,0,1,1,1,1,1,1,1,1,1,1,1,0,0,0,0,0,0,0,0
0,0,0,0,0,0,0,1,1,1,1,1,0,0,0,1,1,1,1,1,0,0,0,0,0,0,0
0,0,0,0,0,0,1,1,1,1,0,0,0,0,0,0,0,1,1,1,1,0,0,0,0,0,0
0,0,0,0,0,0,1,1,1,0,0,0,0,0,0,0,0,0,1,1,1,0,0,0,0,0,0
0,0,0,0,0,0,1,1,0,0,0,0,0,0,0,0,0,0,0,1,1,0,0,0,0,0,0
0,0,0,0,0,1,1,1,0,0,0,0,0,0,0,0,0,0,0,1,1,1,0,0,0,0,0
0,0,0,0,0,1,1,0,0,0,0,0,2,2,2,0,0,0,0,0,1,1,0,0,0,0,0
0,0,0,0,0,1,1,0,0,0,0,0,2,2,2,0,0,0,0,0,1,1,0,0,0,0,0
0,0,0,0,0,1,1,0,0,0,0,0,2,2,2,0,0,0,0,0,1,1,0,0,0,0,0
0,0,0,0,0,1,1,1,0,0,0,0,0,0,0,0,0,0,0,1,1,1,0,0,0,0,0
0,0,0,0,0,0,1,1,0,0,0,0,0,0,0,0,0,0,0,1,1,0,0,0,0,0,0
0,0,0,0,0,0,1,1,1,0,0,0,0,0,0,0,0,0,1,1,1,0,0,0,0,0,0
0,0,0,0,0,0,1,1,1,1,0,0,0,0,0,0,0,1,1,1,1,0,0,0,0,0,0
0,0,0,0,0,0,0,1,1,1,1,1,0,0,0,1,1,1,1,1,0,0,0,0,0,0,0
0,0,0,0,0,0,0,0,1,1,1,1,1,1,1,1,1,1,1,0,0,0,0,0,0,0,0
0,0,0,0,0,0,0,0,0,0,0,1,1,1,1,1,0,0,0,0,0,0,0,0,0,0,0
0,0,0,0,0,0,0,0,0,0,0,0,0,0,0,0,0,0,0,0,0,0,0,0,0,0,0
0,0,0,0,0,0,0,0,0,0,0,0,0,0,0,0,0,0,0,0,0,0,0,0,0,0,0
0,0,0,0,0,0,0,0,0,0,0,0,0,0,0,0,0,0,0,0,0,0,0,0,0,0,0
0,0,0,0,0,0,0,0,0,0,0,0,0,0,0,0,0,0,0,0,0,0,0,0,0,0,0
0,0,0,0,0,0,0,0,0,0,0,0,0,0,0,0,0,0,0,0,0,0,0,0,0,0,0
endlayer

layer
0,0,0,0,0,0,0,0,0,0,0,0,0,0,0,0,0,0,0,0,0,0,0,0,0,0,0
0,0,0,0,0,0,0,0,0,0,0,0,0,0,0,0,0,0,0,0,0,0,0,0,0,0,0
0,0,0,0,0,0,0,0,0,0,0,0,0,0,0,0,0,0,0,0,0,0,0,0,0,0,0
0,0,0,0,0,0,0,0,0,0,0,0,0,0,0,0,0,0,0,0,0,0,0,0,0,0,0
0,0,0,0,0,0,0,0,0,0,0,0,0,0,0,0,0,0,0,0,0,0,0,0,0,0,0
0,0,0,0,0,0,0,0,0,0,0,0,0,0,0,0,0,0,0,0,0,0,0,0,0,0,0
0,0,0,0,0,0,0,0,0,0,0,0,0,0,0,0,0,0,0,0,0,0,0,0,0,0,0
0,0,0,0,0,0,0,0,0,0,0,1,1,1,1,1,0,0,0,0,0,0,0,0,0,0,0
0,0,0,0,0,0,0,0,0,1,1,1,1,1,1,1,1,1,0,0,0,0,0,0,0,0,0
0,0,0,0,0,0,0,0,1,1,1,1,1,1,1,1,1,1,1,0,0,0,0,0,0,0,0
0,0,0,0,0,0,0,0,1,1,1,1,1,0,1,1,1,1,1,0,0,0,0,0,0,0,0
0,0,0,0,0,0,0,1,1,1,1,1,0,2,0,1,1,1,1,1,0,0,0,0,0,0,0
0,0,0,0,0,0,0,1,1,1,1,0,2,2,2,0,1,1,1,1,0,0,0,0,0,0,0
0,0,0,0,0,0,0,1,1,1,0,2,2,2,2,2,0,1,1,1,0,0,0,0,0,0,0
0,0,0,0,0,0,0,1,1,1,1,0,2,2,2,0,1,1,1,1,0,0,0,0,0,0,0
0,0,0,0,0,0,0,1,1,1,1,1,0,2,0,1,1,1,1,1,0,0,0,0,0,0,0
0,0,0,0,0,0,0,0,1,1,1,1,1,0,1,1,1,1,1,0,0,0,0,0,0,0,0
0,0,0,0,0,0,0,0,1,1,1,1,1,1,1,1,1,1,1,0,0,0,0,0,0,0,0
0,0,0,0,0,0,0,0,0,1,1,1,1,1,1,1,1,1,0,0,0,0,0,0,0,0,0
0,0,0,0,0,0,0,0,0,0,0,1,1,1,1,1,0,0,0,0,0,0,0,0,0,0,0
0,0,0,0,0,0,0,0,0,0,0,0,0,0,0,0,0,0,0,0,0,0,0,0,0,0,0
0,0,0,0,0,0,0,0,0,0,0,0,0,0,0,0,0,0,0,0,0,0,0,0,0,0,0
0,0,0,0,0,0,0,0,0,0,0,0,0,0,0,0,0,0,0,0,0,0,0,0,0,0,0
0,0,0,0,0,0,0,0,0,0,0,0,0,0,0,0,0,0,0,0,0,0,0,0,0,0,0
0,0,0,0,0,0,0,0,0,0,0,0,0,0,0,0,0,0,0,0,0,0,0,0,0,0,0
0,0,0,0,0,0,0,0,0,0,0,0,0,0,0,0,0,0,0,0,0,0,0,0,0,0,0
0,0,0,0,0,0,0,0,0,0,0,0,0,0,0,0,0,0,0,0,0,0,0,0,0,0,0
endlayer

layer
0,0,0,0,0,0,0,0,0,0,0,0,0,0,0,0,0,0,0,0,0,0,0,0,0,0,0
0,0,0,0,0,0,0,0,0,0,0,0,0,0,0,0,0,0,0,0,0,0,0,0,0,0,0
0,0,0,0,0,0,0,0,0,0,0,0,0,0,0,0,0,0,0,0,0,0,0,0,0,0,0
0,0,0,0,0,0,0,0,0,0,0,0,0,0,0,0,0,0,0,0,0,0,0,0,0,0,0
0,0,0,0,0,0,0,0,0,0,0,0,0,0,0,0,0,0,0,0,0,0,0,0,0,0,0
0,0,0,0,0,0,0,0,0,0,0,0,0,0,0,0,0,0,0,0,0,0,0,0,0,0,0
0,0,0,0,0,0,0,0,0,0,0,0,0,0,0,0,0,0,0,0,0,0,0,0,0,0,0
0,0,0,0,0,0,0,0,0,0,0,0,0,0,0,0,0,0,0,0,0,0,0,0,0,0,0
0,0,0,0,0,0,0,0,0,0,0,0,0,0,0,0,0,0,0,0,0,0,0,0,0,0,0
0,0,0,0,0,0,0,0,0,0,0,0,0,0,0,0,0,0,0,0,0,0,0,0,0,0,0
0,0,0,0,0,0,0,0,0,0,0,0,1,1,1,0,0,0,0,0,0,0,0,0,0,0,0
0,0,0,0,0,0,0,0,0,0,0,1,1,1,1,1,0,0,0,0,0,0,0,0,0,0,0
0,0,0,0,0,0,0,0,0,0,1,1,1,1,1,1,1,0,0,0,0,0,0,0,0,0,0
0,0,0,0,0,0,0,0,0,0,1,1,1,1,1,1,1,0,0,0,0,0,0,0,0,0,0
0,0,0,0,0,0,0,0,0,0,1,1,1,1,1,1,1,0,0,0,0,0,0,0,0,0,0
0,0,0,0,0,0,0,0,0,0,0,1,1,1,1,1,0,0,0,0,0,0,0,0,0,0,0
0,0,0,0,0,0,0,0,0,0,0,0,1,1,1,0,0,0,0,0,0,0,0,0,0,0,0
0,0,0,0,0,0,0,0,0,0,0,0,0,0,0,0,0,0,0,0,0,0,0,0,0,0,0
0,0,0,0,0,0,0,0,0,0,0,0,0,0,0,0,0,0,0,0,0,0,0,0,0,0,0
0,0,0,0,0,0,0,0,0,0,0,0,0,0,0,0,0,0,0,0,0,0,0,0,0,0,0
0,0,0,0,0,0,0,0,0,0,0,0,0,0,0,0,0,0,0,0,0,0,0,0,0,0,0
0,0,0,0,0,0,0,0,0,0,0,0,0,0,0,0,0,0,0,0,0,0,0,0,0,0,0
0,0,0,0,0,0,0,0,0,0,0,0,0,0,0,0,0,0,0,0,0,0,0,0,0,0,0
0,0,0,0,0,0,0,0,0,0,0,0,0,0,0,0,0,0,0,0,0,0,0,0,0,0,0
0,0,0,0,0,0,0,0,0,0,0,0,0,0,0,0,0,0,0,0,0,0,0,0,0,0,0
0,0,0,0,0,0,0,0,0,0,0,0,0,0,0,0,0,0,0,0,0,0,0,0,0,0,0
0,0,0,0,0,0,0,0,0,0,0,0,0,0,0,0,0,0,0,0,0,0,0,0,0,0,0
endlayer

