# Mine Tunnel
# Created by Ruins mod version 15.1 Ingame Parser
# authoring Player: Jordan_Greywolf
# Note: Place in \templateparser folder.
# Called by MineTower template.
# Created 26 Nov 2015
# Updated to MC 1.9: 24 Apr 2016
# Updated to MC 1.11: 11 Jan 2017

weight=1
embed_into_distance=1
acceptable_target_blocks=
unacceptable_target_blocks=flowing_lava,lava,cloud,Natura:Cloud

dimensions=6,6,21
allowable_overhang=0
max_leveling=0
leveling_buffer=-1
preserve_water=0
preserve_lava=0
preserve_plants=1

rule1=0,100,minecraft:log-0
rule2=0,100,minecraft:planks-0
rule3=0,100,minecraft:log-4
rule4=0,100,minecraft:web-0
rule5=0,100,minecraft:tnt,minecraft:tnt-1,MobSpawner:Spider,MobSpawner:Skeleton,ChestGenHook:chests/abandoned_mineshaft:3,ChestGenHook:chests/simple_dungeon:3,IInventory;minecraft:trapped_chest;minecraft:golden_rail#3#0#0+minecraft:rail#12#0#1+minecraft:redstone_torch#3#0#2+minecraft:torch#2#0#3-4

rule6=0,100,minecraft:fence-0
rule7=0,100,minecraft:rail-0

layer
1,2,2,2,2,1,2,2,2,2,1,2,2,2,2,1,2,2,2,2,1
3,2,2,2,2,3,2,2,2,2,3,2,2,2,2,3,2,2,2,2,3
3,2,2,2,2,3,2,2,2,2,3,2,2,2,2,3,2,2,2,2,3
3,2,2,2,2,3,2,2,2,2,3,2,2,2,2,3,2,2,2,2,3
3,2,2,2,2,3,2,2,2,2,3,2,2,2,2,3,2,2,2,2,3
1,2,2,2,2,1,2,2,2,2,1,2,2,2,2,1,2,2,2,2,1
endlayer

layer
1,4,0,0,4,1,4,0,5,4,1,4,5,0,4,1,4,0,0,4,1
6,0,0,0,0,6,0,0,0,0,6,0,0,0,0,6,0,0,0,0,6
0,0,0,0,0,0,0,0,0,0,0,0,0,0,0,0,0,0,0,0,4
7,7,7,7,7,7,7,7,7,7,7,7,7,7,7,7,7,7,7,7,7
6,0,0,0,0,6,0,0,0,0,6,0,0,0,0,6,0,0,0,0,6
1,4,0,0,4,1,4,0,5,4,1,4,5,0,4,1,4,0,0,4,1
endlayer

layer
1,0,0,0,0,1,0,0,0,0,1,0,0,0,0,1,0,0,0,0,1
6,0,0,0,0,6,0,0,0,0,6,0,0,0,0,6,0,0,0,0,6
0,0,0,0,0,0,0,0,0,0,0,0,0,0,0,0,0,0,0,0,0
0,0,0,0,0,0,0,0,0,0,0,0,0,0,0,0,0,0,0,0,0
6,0,0,0,0,6,0,0,0,0,6,0,0,0,0,6,0,0,0,0,6
1,0,0,0,0,1,0,0,0,0,1,0,0,0,0,1,0,0,0,0,1
endlayer

layer
1,0,0,0,0,1,4,0,0,4,1,4,0,0,0,1,4,0,0,4,1
6,0,0,0,0,6,0,0,0,0,6,0,0,0,0,6,0,0,0,0,6
0,0,0,0,0,0,0,0,0,0,0,0,0,0,0,0,0,0,0,0,0
0,0,0,0,0,0,0,0,0,0,0,0,0,0,0,0,0,0,0,0,0
6,0,0,0,0,6,0,0,0,0,6,0,0,0,0,6,0,0,0,0,6
1,4,0,0,0,1,4,0,0,4,1,4,0,0,4,1,4,0,0,4,1
endlayer

layer
1,4,0,0,4,1,4,0,4,4,1,4,4,0,4,1,4,0,4,4,1
6,0,0,0,0,6,0,0,0,0,6,0,0,0,0,6,0,0,0,0,6
0,0,0,0,0,0,0,0,0,0,0,0,0,0,0,0,0,0,0,0,4
4,0,0,0,0,4,0,0,0,0,4,0,0,0,0,4,0,0,0,0,0
6,0,0,0,0,6,0,0,0,0,6,0,0,0,0,6,0,0,0,0,6
1,4,4,0,4,1,4,0,4,4,1,4,4,4,4,1,4,0,4,4,1
endlayer

layer
1,2,2,2,2,1,2,2,2,2,1,2,2,2,2,1,2,2,2,2,1
3,2,2,2,2,3,2,2,2,2,3,2,2,2,2,3,2,2,2,2,3
3,2,2,2,2,3,2,2,2,2,3,2,2,2,2,3,2,2,2,2,3
3,2,2,2,2,3,2,2,2,2,3,2,2,2,2,3,2,2,2,2,3
3,2,2,2,2,3,2,2,2,2,3,2,2,2,2,3,2,2,2,2,3
1,2,2,2,2,1,2,2,2,2,1,2,2,2,2,1,2,2,2,2,1
endlayer

