# Tower of Eeevil - MC 1.7.10
# Created by Ruins mod version 15.1 Ingame Parser
# authoring Player: Jordan_Greywolf
# Last Updated 5 Feb 2016
# Note: Place in \templateparser folder.
# Updated to MC 1.8: 5 Mar 2016
# Updated to MC 1.9: 24 Apr 2016
# Updated to MC 1.12: 22 Jun 2017

biomesToSpawnIn=boneyard,corrupted sands,deadlands,eerie,eldritch,hell,phantasmagoric inferno,spectral garden,tainted land,undergarden,visceral heap,volcano

uniqueMinDistance=2000

weight=1

#embed_into_distance=11
embed_into_distance=0

acceptable_target_blocks=
unacceptable_target_blocks=flowing_lava,lava,cloud,Natura:Cloud
dimensions=51,29,29
allowable_overhang=25
max_leveling=11
leveling_buffer=-1
preserve_water=0
preserve_lava=0
preserve_plants=1

# Terrain Preservation
rule1=0,100,preserveBlock

# Obsidian Wall
rule2=0,100,minecraft:obsidian-0

# Soul Sand
rule3=0,100,minecraft:soul_sand-0

rule4=0,100,minecraft:flowing_lava

rule5=0,100,minecraft:nether_brick_fence-0

rule6=0,100,minecraft:nether_brick_stairs-5
rule7=0,100,minecraft:nether_brick_stairs-7
rule8=0,100,minecraft:nether_brick_stairs-4
rule9=0,100,minecraft:nether_brick_stairs-6

# Nether Slab (bottom)
rule10=0,100,minecraft:stone_slab-6

# Nether Brick Floor
rule11=0,100,minecraft:nether_brick-0

# Upper Nether Brick Stair
rule12=0,100,minecraft:stone_slab-14

# Nether Brick Wall
rule13=0,100,minecraft:nether_brick-0

# Randomized Skull
rule14=0,100,minecraft:skull,minecraft:skull-1,minecraft:skull-2,minecraft:skull-3

# Nether Brick Stairs Slab (double)
rule15=0,100,minecraft:double_stone_slab-6

# Nether Brick Stairs Slab (bottom)
rule16=0,100,minecraft:stone_slab-6

rule17=1,100,minecraft:redstone_torch-5
rule18=0,100,minecraft:iron_bars-0
rule19=0,100,minecraft:netherrack-0

# Obsidian (formerly stonebrick-3)
rule20=0,100,minecraft:obsidian-0

# Nether Brick Floor (missing pieces)
rule21=0,50,minecraft:nether_brick-0

# Quartz Slab (upper)
rule22=0,100,minecraft:stone_slab-6

rule23=0,100,CommandBlock:RUINSTRIGGER /summon skeleton ~0 ~0 ~0 {HandItems:[{},{}],ArmorItems:[{},{},{},{}],CustomName:"Withering Spirit",SkeletonType:1,Health:60.0f,ActiveEffects:[{Id:12,Amplifier:1,Duration:999999,Ambient:1},{Id:3,Amplifier:1,Duration:999999,Ambient:1},{Id:14,Amplifier:1,Duration:999999,Ambient:1},{Id:10,Amplifier:1,Duration:999999,Ambient:1},{Id:11,Amplifier:1,Duration:999999,Ambient:1},{Id:5,Amplifier:1,Duration:999999,Ambient:1},{Id:13,Amplifier:1,Duration:999999,Ambient:1}],CanPickUpLoot:1,Silent:1,PersistenceRequired:1}:@

# "Blood" Spot
rule24=0,100,minecraft:redstone_wire-0

rule25=0,100,ChestGenHook:chests/jungle_temple:2

rule26=0,100,MobSpawner:Skeleton

rule27=0,100,minecraft:oak_stairs-3
rule28=0,100,minecraft:crafting_table-0
rule29=0,100,minecraft:oak_stairs-7
rule30=0,100,minecraft:oak_stairs-6

# "Window"
rule31=0,100,minecraft:redstone_lamp-0

rule32=0,100,minecraft:stone_pressure_plate-0

rule33=0,100,minecraft:oak_stairs-1
rule34=0,100,minecraft:oak_stairs-2
rule35=0,100,minecraft:oak_stairs-0
rule36=0,100,minecraft:fire-15

rule37=0,100,minecraft:soul_sand
rule38=0,100,minecraft:nether_wart-3

rule39=0,100,minecraft:quartz_block-1

rule40=0,100,IInventory;minecraft:chest;minecraft:enchanted_book#{StoredEnchantments:[{lvl:4,id:3}]}#0#0+minecraft:feather#3#0#5+minecraft:paper#4#0#11+minecraft:book#2#0#18+minecraft:dye#3#0#24-5,IInventory;minecraft:chest;minecraft:enchanted_book#{StoredEnchantments:[{lvl:1,id:33}]}#0#4+minecraft:feather#3#0#5+minecraft:enchanted_book#{StoredEnchantments:[{lvl:4,id:1}]}#0#8+minecraft:paper#4#0#11+minecraft:book#2#0#18+minecraft:dye#3#0#24-5,IInventory;minecraft:chest;minecraft:enchanted_book#{StoredEnchantments:[{lvl:4,id:1}]}#0#8+minecraft:enchanted_book#{StoredEnchantments:[{lvl:3,id:34}]}#0#11+minecraft:enchanted_book#{StoredEnchantments:[{lvl:2,id:20}]}#0#16+minecraft:enchanted_book#{StoredEnchantments:[{lvl:1,id:50}]}#0#21+minecraft:enchanted_book#{StoredEnchantments:[{lvl:3,id:35}]}#0#26-5

rule41=0,100,minecraft:bookshelf-0

rule42=0,100,minecraft:redstone_wire-15
rule43=0,100,minecraft:redstone_wire-14

# Pool
rule44=0,100,minecraft:slime-0

rule45=0,100,minecraft:glowstone-0

rule46=0,100,minecraft:quartz_block-0

# Roof Treasure
rule47=0,100,ChestGenHook:chests/simple_dungeon:3

# Nasty Monster
rule48=0,100,CommandBlock:RUINSTRIGGER /summon skeleton ~0 ~2 ~0 {SkeletonType:1,DropChances:[0.5F,0.2F,0.2F,0.2F,0.5F],ActiveEffects:[{Id:1,Amplifier:0,Duration:99999,Ambient:1},{Id:8,Amplifier:7,Duration:99999,Ambient:1},{Id:18,Amplifier:0,Duration:99999,Ambient:1}],CustomName:"Vile Cultist",HandItems:[{Count:1,id:golden_hoe,tag:{display:{color:0,Name:"Ceremonial Scythe"},ench:[{id:16,lvl:5},{id:19,lvl:5},{id:20,lvl:5}]}},{}],ArmorItems:[{Count:1,id:leather_boots,tag:{display:{Name:"Dark Boots",color:0}}},{Count:1,id:leather_leggings,tag:{display:{Name:"Dark Pants",color:0}}},{Count:1,id:leather_chestplate,tag:{display:{Name:"Dark Tunic",color:0}}},{Count:1,id:skull,Damage:3,tag:{display:{Name:"Death Mask"},ench:[{id:0,lvl:5},{id:5,lvl:15},{id:6,lvl:1},{id:3,lvl:4}]}}],Silent:1,PersistenceRequired:1}:@

layer
1,1,1,1,1,1,1,1,1,1,1,1,1,1,1,1,1,1,1,1,1,1,1,1,1,1,1,1,1
1,1,1,1,1,1,1,1,1,1,1,1,1,1,1,1,1,1,1,1,1,1,1,1,1,1,1,1,1
1,1,1,1,1,1,1,1,1,1,1,1,1,1,1,1,1,1,1,1,1,1,1,1,1,1,1,1,1
1,1,1,1,1,1,1,1,1,1,1,1,1,1,1,1,1,1,1,1,1,1,1,1,1,1,1,1,1
1,1,1,1,1,1,1,2,2,2,2,1,1,1,1,1,1,1,2,2,2,2,1,1,1,1,1,1,1
1,1,1,1,1,1,3,4,4,4,4,3,1,1,1,1,1,3,4,4,4,4,3,1,1,1,1,1,1
1,1,1,1,1,3,4,4,4,4,4,4,3,1,1,1,3,4,4,4,4,4,4,3,1,1,1,1,1
1,1,1,1,2,4,4,4,4,4,4,4,4,2,5,2,4,4,4,4,4,4,4,4,2,1,1,1,1
1,1,1,1,2,4,4,4,4,4,4,4,4,4,4,4,4,4,4,4,4,4,4,4,2,1,1,1,1
1,1,1,1,2,4,4,4,4,4,4,4,4,4,4,4,4,4,4,4,4,4,4,4,2,1,1,1,1
1,1,1,1,2,4,4,4,4,4,4,4,4,2,5,2,4,4,4,4,4,4,4,4,2,1,1,1,1
1,1,1,1,1,3,4,4,4,4,4,4,3,4,0,4,3,4,4,4,4,4,4,3,1,1,1,1,1
1,1,1,1,1,1,3,4,4,4,4,3,4,0,4,0,4,3,4,4,4,4,3,1,1,1,1,1,1
1,1,1,1,1,1,1,2,4,4,2,4,0,4,0,4,0,4,2,4,4,2,1,1,1,1,1,1,1
1,1,1,1,1,1,1,5,4,4,5,0,4,0,4,0,4,0,5,4,4,5,1,1,1,1,1,1,1
1,1,1,1,1,1,1,2,4,4,2,4,0,4,0,4,0,4,2,4,4,2,1,1,1,1,1,1,1
1,1,1,1,1,1,3,4,4,4,4,3,4,0,4,0,4,3,4,4,4,4,3,1,1,1,1,1,1
1,1,1,1,1,3,4,4,4,4,4,4,3,4,0,4,3,4,4,4,4,4,4,3,1,1,1,1,1
1,1,1,1,2,4,4,4,4,4,4,4,4,2,5,2,4,4,4,4,4,4,4,4,2,1,1,1,1
1,1,1,1,2,4,4,4,4,4,4,4,4,4,4,4,4,4,4,4,4,4,4,4,2,1,1,1,1
1,1,1,1,2,4,4,4,4,4,4,4,4,4,4,4,4,4,4,4,4,4,4,4,2,1,1,1,1
1,1,1,1,2,4,4,4,4,4,4,4,4,2,5,2,4,4,4,4,4,4,4,4,2,1,1,1,1
1,1,1,1,1,3,4,4,4,4,4,4,3,1,1,1,3,4,4,4,4,4,4,3,1,1,1,1,1
1,1,1,1,1,1,3,4,4,4,4,3,1,1,1,1,1,3,4,4,4,4,3,1,1,1,1,1,1
1,1,1,1,1,1,1,2,2,2,2,1,1,1,1,1,1,1,2,2,2,2,1,1,1,1,1,1,1
1,1,1,1,1,1,1,1,1,1,1,1,1,1,1,1,1,1,1,1,1,1,1,1,1,1,1,1,1
1,1,1,1,1,1,1,1,1,1,1,1,1,1,1,1,1,1,1,1,1,1,1,1,1,1,1,1,1
1,1,1,1,1,1,1,1,1,1,1,1,1,1,1,1,1,1,1,1,1,1,1,1,1,1,1,1,1
1,1,1,1,1,1,1,1,1,1,1,1,1,1,1,1,1,1,1,1,1,1,1,1,1,1,1,1,1
endlayer

layer
1,1,1,1,1,1,1,1,1,1,1,1,1,1,1,1,1,1,1,1,1,1,1,1,1,1,1,1,1
1,1,1,1,1,1,1,1,1,1,1,1,1,1,1,1,1,1,1,1,1,1,1,1,1,1,1,1,1
1,1,1,3,3,3,1,1,1,1,1,1,1,1,1,1,1,1,1,1,1,1,1,3,3,3,1,1,1
1,1,3,3,1,3,3,1,1,1,1,1,1,1,1,1,1,1,1,1,1,1,3,3,1,3,3,1,1
1,1,3,1,1,1,3,2,2,2,2,1,1,1,1,1,1,1,2,2,2,2,3,1,1,1,3,1,1
1,1,3,3,1,1,3,0,0,0,0,3,1,1,1,1,1,3,0,0,0,0,3,1,1,3,3,1,1
1,1,1,3,3,3,0,0,0,0,0,0,3,1,1,1,3,0,0,0,0,0,0,3,3,3,1,1,1
1,1,1,1,2,0,0,0,0,0,0,0,0,2,5,2,0,0,0,0,0,0,0,0,2,1,1,1,1
1,1,1,1,2,0,0,0,0,0,0,0,0,0,0,0,0,0,0,0,0,0,0,0,2,1,1,1,1
1,1,1,1,2,0,0,0,0,0,0,0,0,0,0,0,0,0,0,0,0,0,0,0,2,1,1,1,1
1,1,1,1,2,0,0,0,0,0,0,0,0,2,5,2,0,0,0,0,0,0,0,0,2,1,1,1,1
1,1,1,1,1,3,0,0,0,0,0,0,3,0,0,0,3,0,0,0,0,0,0,3,1,1,1,1,1
1,1,1,1,1,1,3,0,0,0,0,3,0,0,0,0,0,3,0,0,0,0,3,1,1,1,1,1,1
1,1,1,1,1,1,1,2,0,0,2,0,0,0,0,0,0,0,2,0,0,2,1,1,1,1,1,1,1
1,1,1,1,1,1,1,5,0,0,5,0,0,0,0,0,0,0,5,0,0,5,1,1,1,1,1,1,1
1,1,1,1,1,1,1,2,0,0,2,0,0,0,0,0,0,0,2,0,0,2,1,1,1,1,1,1,1
1,1,1,1,1,1,3,0,0,0,0,3,0,0,0,0,0,3,0,0,0,0,3,1,1,1,1,1,1
1,1,1,1,1,3,0,0,0,0,0,0,3,0,0,0,3,0,0,0,0,0,0,3,1,1,1,1,1
1,1,1,1,2,0,0,0,0,0,0,0,0,2,5,2,0,0,0,0,0,0,0,0,2,1,1,1,1
1,1,1,1,2,0,0,0,0,0,0,0,0,0,0,0,0,0,0,0,0,0,0,0,2,1,1,1,1
1,1,1,1,2,0,0,0,0,0,0,0,0,0,0,0,0,0,0,0,0,0,0,0,2,1,1,1,1
1,1,1,1,2,0,0,0,0,0,0,0,0,2,5,2,0,0,0,0,0,0,0,0,2,1,1,1,1
1,1,1,3,3,3,0,0,0,0,0,0,3,1,1,1,3,0,0,0,0,0,0,3,3,3,1,1,1
1,1,3,3,1,1,3,0,0,0,0,3,1,1,1,1,1,3,0,0,0,0,3,1,1,3,3,1,1
1,1,3,1,1,1,3,2,2,2,2,1,1,1,1,1,1,1,2,2,2,2,3,1,1,1,3,1,1
1,1,3,3,1,3,3,1,1,1,1,1,1,1,1,1,1,1,1,1,1,1,3,3,1,3,3,1,1
1,1,1,3,3,3,1,1,1,1,1,1,1,1,1,1,1,1,1,1,1,1,1,3,3,3,1,1,1
1,1,1,1,1,1,1,1,1,1,1,1,1,1,1,1,1,1,1,1,1,1,1,1,1,1,1,1,1
1,1,1,1,1,1,1,1,1,1,1,1,1,1,1,1,1,1,1,1,1,1,1,1,1,1,1,1,1
endlayer

layer
1,1,1,1,1,1,1,1,1,1,1,1,1,1,1,1,1,1,1,1,1,1,1,1,1,1,1,1,1
1,1,1,1,1,1,1,1,1,1,1,1,1,1,1,1,1,1,1,1,1,1,1,1,1,1,1,1,1
1,1,1,3,3,3,1,1,1,1,1,1,1,1,1,1,1,1,1,1,1,1,1,3,3,3,1,1,1
1,1,3,3,1,3,3,1,1,1,1,1,1,1,1,1,1,1,1,1,1,1,3,3,1,3,3,1,1
1,1,3,1,1,1,3,2,2,2,2,1,1,1,1,1,1,1,2,2,2,2,3,1,1,1,3,1,1
1,1,3,3,1,1,3,0,0,0,0,3,1,1,1,1,1,3,0,0,0,0,3,1,1,3,3,1,1
1,1,1,3,3,3,0,0,0,0,0,0,3,1,1,1,3,0,0,0,0,0,0,3,3,3,1,1,1
1,1,1,1,2,0,0,0,0,0,0,0,0,2,5,2,0,0,0,0,0,0,0,0,2,1,1,1,1
1,1,1,1,2,0,0,0,0,0,0,0,0,0,0,0,0,0,0,0,0,0,0,0,2,1,1,1,1
1,1,1,1,2,0,0,0,0,0,0,0,0,0,0,0,0,0,0,0,0,0,0,0,2,1,1,1,1
1,1,1,1,2,0,0,0,0,0,0,0,0,2,5,2,0,0,0,0,0,0,0,0,2,1,1,1,1
1,1,1,1,1,3,0,0,0,0,0,0,3,0,0,0,3,0,0,0,0,0,0,3,1,1,1,1,1
1,1,1,1,1,1,3,0,0,0,0,3,0,0,0,0,0,3,0,0,0,0,3,1,1,1,1,1,1
1,1,1,1,1,1,1,2,0,0,2,0,0,0,0,0,0,0,2,0,0,2,1,1,1,1,1,1,1
1,1,1,1,1,1,1,5,0,0,5,0,0,0,0,0,0,0,5,0,0,5,1,1,1,1,1,1,1
1,1,1,1,1,1,1,2,0,0,2,0,0,0,0,0,0,0,2,0,0,2,1,1,1,1,1,1,1
1,1,1,1,1,1,3,0,0,0,0,3,0,0,0,0,0,3,0,0,0,0,3,1,1,1,1,1,1
1,1,1,1,1,3,0,0,0,0,0,0,3,0,0,0,3,0,0,0,0,0,0,3,1,1,1,1,1
1,1,1,1,2,0,0,0,0,0,0,0,0,2,5,2,0,0,0,0,0,0,0,0,2,1,1,1,1
1,1,1,1,2,0,0,0,0,0,0,0,0,0,0,0,0,0,0,0,0,0,0,0,2,1,1,1,1
1,1,1,1,2,0,0,0,0,0,0,0,0,0,0,0,0,0,0,0,0,0,0,0,2,1,1,1,1
1,1,1,1,2,0,0,0,0,0,0,0,0,2,5,2,0,0,0,0,0,0,0,0,2,1,1,1,1
1,1,1,3,3,3,0,0,0,0,0,0,3,1,1,1,3,0,0,0,0,0,0,3,3,3,1,1,1
1,1,3,3,1,1,3,0,0,0,0,3,1,1,1,1,1,3,0,0,0,0,3,1,1,3,3,1,1
1,1,3,1,1,1,3,2,2,2,2,1,1,1,1,1,1,1,2,2,2,2,3,1,1,1,3,1,1
1,1,3,3,1,3,3,1,1,1,1,1,1,1,1,1,1,1,1,1,1,1,3,3,1,3,3,1,1
1,1,1,3,3,3,1,1,1,1,1,1,1,1,1,1,1,1,1,1,1,1,1,3,3,3,1,1,1
1,1,1,1,1,1,1,1,1,1,1,1,1,1,1,1,1,1,1,1,1,1,1,1,1,1,1,1,1
1,1,1,1,1,1,1,1,1,1,1,1,1,1,1,1,1,1,1,1,1,1,1,1,1,1,1,1,1
endlayer

layer
1,1,1,1,1,1,1,1,1,1,1,1,1,1,1,1,1,1,1,1,1,1,1,1,1,1,1,1,1
1,1,1,1,1,1,1,1,1,1,1,1,1,1,1,1,1,1,1,1,1,1,1,1,1,1,1,1,1
1,1,1,3,3,3,1,1,1,1,1,1,1,1,1,1,1,1,1,1,1,1,1,3,3,3,1,1,1
1,1,3,3,1,3,3,1,1,1,1,1,1,1,1,1,1,1,1,1,1,1,3,3,1,3,3,1,1
1,1,3,1,1,1,3,2,2,2,2,1,1,1,1,1,1,1,2,2,2,2,3,1,1,1,3,1,1
1,1,3,3,1,1,3,0,0,0,0,3,1,1,1,1,1,3,0,0,0,0,3,1,1,3,3,1,1
1,1,1,3,3,3,0,0,0,0,0,0,3,1,1,1,3,0,0,0,0,0,0,3,3,3,1,1,1
1,1,1,1,2,0,0,0,0,0,0,0,0,2,5,2,0,0,0,0,0,0,0,0,2,1,1,1,1
1,1,1,1,2,0,0,0,0,0,0,0,0,0,0,0,0,0,0,0,0,0,0,0,2,1,1,1,1
1,1,1,1,2,0,0,0,0,0,0,0,0,0,0,0,0,0,0,0,0,0,0,0,2,1,1,1,1
1,1,1,1,2,0,0,0,0,0,0,0,0,2,5,2,0,0,0,0,0,0,0,0,2,1,1,1,1
1,1,1,1,1,3,0,0,0,0,0,0,3,0,0,0,3,0,0,0,0,0,0,3,1,1,1,1,1
1,1,1,1,1,1,3,0,0,0,0,3,0,0,0,0,0,3,0,0,0,0,3,1,1,1,1,1,1
1,1,1,1,1,1,1,2,0,0,2,0,0,0,0,0,0,0,2,0,0,2,1,1,1,1,1,1,1
1,1,1,1,1,1,1,5,0,0,5,0,0,0,0,0,0,0,5,0,0,5,1,1,1,1,1,1,1
1,1,1,1,1,1,1,2,0,0,2,0,0,0,0,0,0,0,2,0,0,2,1,1,1,1,1,1,1
1,1,1,1,1,1,3,0,0,0,0,3,0,0,0,0,0,3,0,0,0,0,3,1,1,1,1,1,1
1,1,1,1,1,3,0,0,0,0,0,0,3,0,0,0,3,0,0,0,0,0,0,3,1,1,1,1,1
1,1,1,1,2,0,0,0,0,0,0,0,0,2,5,2,0,0,0,0,0,0,0,0,2,1,1,1,1
1,1,1,1,2,0,0,0,0,0,0,0,0,0,0,0,0,0,0,0,0,0,0,0,2,1,1,1,1
1,1,1,1,2,0,0,0,0,0,0,0,0,0,0,0,0,0,0,0,0,0,0,0,2,1,1,1,1
1,1,1,1,2,0,0,0,0,0,0,0,0,2,5,2,0,0,0,0,0,0,0,0,2,1,1,1,1
1,1,1,3,3,3,0,0,0,0,0,0,3,1,1,1,3,0,0,0,0,0,0,3,3,3,1,1,1
1,1,3,3,1,1,3,0,0,0,0,3,1,1,1,1,1,3,0,0,0,0,3,1,1,3,3,1,1
1,1,3,1,1,1,3,2,2,2,2,1,1,1,1,1,1,1,2,2,2,2,3,1,1,1,3,1,1
1,1,3,3,1,3,3,1,1,1,1,1,1,1,1,1,1,1,1,1,1,1,3,3,1,3,3,1,1
1,1,1,3,3,3,1,1,1,1,1,1,1,1,1,1,1,1,1,1,1,1,1,3,3,3,1,1,1
1,1,1,1,1,1,1,1,1,1,1,1,1,1,1,1,1,1,1,1,1,1,1,1,1,1,1,1,1
1,1,1,1,1,1,1,1,1,1,1,1,1,1,1,1,1,1,1,1,1,1,1,1,1,1,1,1,1
endlayer

layer
1,1,1,1,1,1,1,1,1,1,1,1,1,1,1,1,1,1,1,1,1,1,1,1,1,1,1,1,1
1,1,1,1,1,1,1,1,1,1,1,1,1,1,1,1,1,1,1,1,1,1,1,1,1,1,1,1,1
1,1,1,3,3,3,1,1,1,1,1,1,1,1,1,1,1,1,1,1,1,1,1,3,3,3,1,1,1
1,1,3,3,1,3,3,1,1,1,1,1,1,1,1,1,1,1,1,1,1,1,3,3,1,3,3,1,1
1,1,3,1,1,1,3,2,2,2,2,1,1,1,1,1,1,1,2,2,2,2,3,1,1,1,3,1,1
1,1,3,3,1,1,3,0,0,0,0,3,1,1,1,1,1,3,0,0,0,0,3,1,1,3,3,1,1
1,1,1,3,3,3,0,0,0,0,0,0,3,1,1,1,3,0,0,0,0,0,0,3,3,3,1,1,1
1,1,1,1,2,0,0,0,0,0,0,0,0,2,5,2,0,0,0,0,0,0,0,0,2,1,1,1,1
1,1,1,1,2,0,0,0,0,0,0,0,0,0,0,0,0,0,0,0,0,0,0,0,2,1,1,1,1
1,1,1,1,2,0,0,0,0,0,0,0,0,0,0,0,0,0,0,0,0,0,0,0,2,1,1,1,1
1,1,1,1,2,0,0,0,0,0,0,0,0,2,5,2,0,0,0,0,0,0,0,0,2,1,1,1,1
1,1,1,1,1,3,0,0,0,0,0,0,3,0,0,0,3,0,0,0,0,0,0,3,1,1,1,1,1
1,1,1,1,1,1,3,0,0,0,0,3,0,0,0,0,0,3,0,0,0,0,3,1,1,1,1,1,1
1,1,1,1,1,1,1,2,0,0,2,0,0,0,0,0,0,0,2,0,0,2,1,1,1,1,1,1,1
1,1,1,1,1,1,1,5,0,0,5,0,0,0,0,0,0,0,5,0,0,5,1,1,1,1,1,1,1
1,1,1,1,1,1,1,2,0,0,2,0,0,0,0,0,0,0,2,0,0,2,1,1,1,1,1,1,1
1,1,1,1,1,1,3,0,0,0,0,3,0,0,0,0,0,3,0,0,0,0,3,1,1,1,1,1,1
1,1,1,1,1,3,0,0,0,0,0,0,3,0,0,0,3,0,0,0,0,0,0,3,1,1,1,1,1
1,1,1,1,2,0,0,0,0,0,0,0,0,2,5,2,0,0,0,0,0,0,0,0,2,1,1,1,1
1,1,1,1,2,0,0,0,0,0,0,0,0,0,0,0,0,0,0,0,0,0,0,0,2,1,1,1,1
1,1,1,1,2,0,0,0,0,0,0,0,0,0,0,0,0,0,0,0,0,0,0,0,2,1,1,1,1
1,1,1,1,2,0,0,0,0,0,0,0,0,2,5,2,0,0,0,0,0,0,0,0,2,1,1,1,1
1,1,1,3,3,3,0,0,0,0,0,0,3,1,1,1,3,0,0,0,0,0,0,3,3,3,1,1,1
1,1,3,3,1,1,3,0,0,0,0,3,1,1,1,1,1,3,0,0,0,0,3,1,1,3,3,1,1
1,1,3,1,1,1,3,2,2,2,2,1,1,1,1,1,1,1,2,2,2,2,3,1,1,1,3,1,1
1,1,3,3,1,3,3,1,1,1,1,1,1,1,1,1,1,1,1,1,1,1,3,3,1,3,3,1,1
1,1,1,3,3,3,1,1,1,1,1,1,1,1,1,1,1,1,1,1,1,1,1,3,3,3,1,1,1
1,1,1,1,1,1,1,1,1,1,1,1,1,1,1,1,1,1,1,1,1,1,1,1,1,1,1,1,1
1,1,1,1,1,1,1,1,1,1,1,1,1,1,1,1,1,1,1,1,1,1,1,1,1,1,1,1,1
endlayer

layer
1,1,1,1,1,1,1,1,1,1,1,1,1,1,1,1,1,1,1,1,1,1,1,1,1,1,1,1,1
1,1,1,1,1,1,1,1,1,1,1,1,1,1,1,1,1,1,1,1,1,1,1,1,1,1,1,1,1
1,1,1,3,3,3,1,1,1,1,1,1,1,1,1,1,1,1,1,1,1,1,1,3,3,3,1,1,1
1,1,3,3,1,3,3,1,1,1,1,1,1,1,1,1,1,1,1,1,1,1,3,3,1,3,3,1,1
1,1,3,1,1,1,3,2,2,2,2,1,1,1,1,1,1,1,2,2,2,2,3,1,1,1,3,1,1
1,1,3,3,1,1,3,0,0,0,0,3,1,1,1,1,1,3,0,0,0,0,3,1,1,3,3,1,1
1,1,1,3,3,3,0,0,0,0,0,0,3,1,1,1,3,0,0,0,0,0,0,3,3,3,1,1,1
1,1,1,1,2,0,0,0,0,0,0,0,0,2,5,2,0,0,0,0,0,0,0,0,2,1,1,1,1
1,1,1,1,2,0,0,0,0,0,0,0,0,0,0,0,0,0,0,0,0,0,0,0,2,1,1,1,1
1,1,1,1,2,0,0,0,0,0,0,0,0,0,0,0,0,0,0,0,0,0,0,0,2,1,1,1,1
1,1,1,1,2,0,0,0,0,0,0,0,0,2,5,2,0,0,0,0,0,0,0,0,2,1,1,1,1
1,1,1,1,1,3,0,0,0,0,0,0,3,0,0,0,3,0,0,0,0,0,0,3,1,1,1,1,1
1,1,1,1,1,1,3,0,0,0,0,3,0,0,0,0,0,3,0,0,0,0,3,1,1,1,1,1,1
1,1,1,1,1,1,1,2,0,0,2,0,0,0,0,0,0,0,2,0,0,2,1,1,1,1,1,1,1
1,1,1,1,1,1,1,5,0,0,5,0,0,0,0,0,0,0,5,0,0,5,1,1,1,1,1,1,1
1,1,1,1,1,1,1,2,0,0,2,0,0,0,0,0,0,0,2,0,0,2,1,1,1,1,1,1,1
1,1,1,1,1,1,3,0,0,0,0,3,0,0,0,0,0,3,0,0,0,0,3,1,1,1,1,1,1
1,1,1,1,1,3,0,0,0,0,0,0,3,0,0,0,3,0,0,0,0,0,0,3,1,1,1,1,1
1,1,1,1,2,0,0,0,0,0,0,0,0,2,5,2,0,0,0,0,0,0,0,0,2,1,1,1,1
1,1,1,1,2,0,0,0,0,0,0,0,0,0,0,0,0,0,0,0,0,0,0,0,2,1,1,1,1
1,1,1,1,2,0,0,0,0,0,0,0,0,0,0,0,0,0,0,0,0,0,0,0,2,1,1,1,1
1,1,1,1,2,0,0,0,0,0,0,0,0,2,5,2,0,0,0,0,0,0,0,0,2,1,1,1,1
1,1,1,3,3,3,0,0,0,0,0,0,3,1,1,1,3,0,0,0,0,0,0,3,3,3,1,1,1
1,1,3,3,1,1,3,0,0,0,0,3,1,1,1,1,1,3,0,0,0,0,3,1,1,3,3,1,1
1,1,3,1,1,1,3,2,2,2,2,1,1,1,1,1,1,1,2,2,2,2,3,1,1,1,3,1,1
1,1,3,3,1,3,3,1,1,1,1,1,1,1,1,1,1,1,1,1,1,1,3,3,1,3,3,1,1
1,1,1,3,3,3,1,1,1,1,1,1,1,1,1,1,1,1,1,1,1,1,1,3,3,3,1,1,1
1,1,1,1,1,1,1,1,1,1,1,1,1,1,1,1,1,1,1,1,1,1,1,1,1,1,1,1,1
1,1,1,1,1,1,1,1,1,1,1,1,1,1,1,1,1,1,1,1,1,1,1,1,1,1,1,1,1
endlayer

layer
1,1,1,1,1,1,1,1,1,1,1,1,1,1,1,1,1,1,1,1,1,1,1,1,1,1,1,1,1
1,1,1,1,1,1,1,1,1,1,1,1,1,1,1,1,1,1,1,1,1,1,1,1,1,1,1,1,1
1,1,1,3,3,3,1,1,1,1,1,1,1,1,1,1,1,1,1,1,1,1,1,3,3,3,1,1,1
1,1,3,3,1,3,3,1,1,1,1,1,1,1,1,1,1,1,1,1,1,1,3,3,1,3,3,1,1
1,1,3,1,1,1,3,2,2,2,2,1,1,1,1,1,1,1,2,2,2,2,3,1,1,1,3,1,1
1,1,3,3,1,1,3,0,0,0,0,3,1,1,1,1,1,3,0,0,0,0,3,1,1,3,3,1,1
1,1,1,3,3,3,0,0,0,0,0,0,3,1,1,1,3,0,0,0,0,0,0,3,3,3,1,1,1
1,1,1,1,2,0,0,0,0,0,0,0,0,2,5,2,0,0,0,0,0,0,0,0,2,1,1,1,1
1,1,1,1,2,0,0,0,0,0,0,0,0,0,0,0,0,0,0,0,0,0,0,0,2,1,1,1,1
1,1,1,1,2,0,0,0,0,0,0,0,0,0,0,0,0,0,0,0,0,0,0,0,2,1,1,1,1
1,1,1,1,2,0,0,0,0,0,0,0,0,2,5,2,0,0,0,0,0,0,0,0,2,1,1,1,1
1,1,1,1,1,3,0,0,0,0,0,0,3,0,0,0,3,0,0,0,0,0,0,3,1,1,1,1,1
1,1,1,1,1,1,3,0,0,0,0,3,0,0,0,0,0,3,0,0,0,0,3,1,1,1,1,1,1
1,1,1,1,1,1,1,2,0,0,2,0,0,0,0,0,0,0,2,0,0,2,1,1,1,1,1,1,1
1,1,1,1,1,1,1,5,0,0,5,0,0,0,0,0,0,0,5,0,0,5,1,1,1,1,1,1,1
1,1,1,1,1,1,1,2,0,0,2,0,0,0,0,0,0,0,2,0,0,2,1,1,1,1,1,1,1
1,1,1,1,1,1,3,0,0,0,0,3,0,0,0,0,0,3,0,0,0,0,3,1,1,1,1,1,1
1,1,1,1,1,3,0,0,0,0,0,0,3,0,0,0,3,0,0,0,0,0,0,3,1,1,1,1,1
1,1,1,1,2,0,0,0,0,0,0,0,0,2,5,2,0,0,0,0,0,0,0,0,2,1,1,1,1
1,1,1,1,2,0,0,0,0,0,0,0,0,0,0,0,0,0,0,0,0,0,0,0,2,1,1,1,1
1,1,1,1,2,0,0,0,0,0,0,0,0,0,0,0,0,0,0,0,0,0,0,0,2,1,1,1,1
1,1,1,1,2,0,0,0,0,0,0,0,0,2,5,2,0,0,0,0,0,0,0,0,2,1,1,1,1
1,1,1,3,3,3,0,0,0,0,0,0,3,1,1,1,3,0,0,0,0,0,0,3,3,3,1,1,1
1,1,3,3,1,1,3,0,0,0,0,3,1,1,1,1,1,3,0,0,0,0,3,1,1,3,3,1,1
1,1,3,1,1,1,3,2,2,2,2,1,1,1,1,1,1,1,2,2,2,2,3,1,1,1,3,1,1
1,1,3,3,1,3,3,1,1,1,1,1,1,1,1,1,1,1,1,1,1,1,3,3,1,3,3,1,1
1,1,1,3,3,3,1,1,1,1,1,1,1,1,1,1,1,1,1,1,1,1,1,3,3,3,1,1,1
1,1,1,1,1,1,1,1,1,1,1,1,1,1,1,1,1,1,1,1,1,1,1,1,1,1,1,1,1
1,1,1,1,1,1,1,1,1,1,1,1,1,1,1,1,1,1,1,1,1,1,1,1,1,1,1,1,1
endlayer

layer
1,1,1,1,1,1,1,1,1,1,1,1,1,1,1,1,1,1,1,1,1,1,1,1,1,1,1,1,1
1,1,1,1,1,1,1,1,1,1,1,1,1,1,1,1,1,1,1,1,1,1,1,1,1,1,1,1,1
1,1,1,3,3,3,1,1,1,1,1,1,1,1,1,1,1,1,1,1,1,1,1,3,3,3,1,1,1
1,1,3,3,1,3,3,1,1,1,1,1,1,1,1,1,1,1,1,1,1,1,3,3,1,3,3,1,1
1,1,3,1,1,1,3,2,2,2,2,1,1,1,1,1,1,1,2,2,2,2,3,1,1,1,3,1,1
1,1,3,3,1,1,3,0,0,0,0,3,1,1,1,1,1,3,0,0,0,0,3,1,1,3,3,1,1
1,1,1,3,3,3,0,0,0,0,0,0,3,1,1,1,3,0,0,0,0,0,0,3,3,3,1,1,1
1,1,1,1,2,0,0,0,0,0,0,0,0,2,5,2,0,0,0,0,0,0,0,0,2,1,1,1,1
1,1,1,1,2,0,0,0,0,0,0,0,0,0,0,0,0,0,0,0,0,0,0,0,2,1,1,1,1
1,1,1,1,2,0,0,0,0,0,0,0,0,0,0,0,0,0,0,0,0,0,0,0,2,1,1,1,1
1,1,1,1,2,0,0,0,0,0,0,0,0,2,5,2,0,0,0,0,0,0,0,0,2,1,1,1,1
1,1,1,1,1,3,0,0,0,0,0,0,3,0,0,0,3,0,0,0,0,0,0,3,1,1,1,1,1
1,1,1,1,1,1,3,0,0,0,0,3,0,0,0,0,0,3,0,0,0,0,3,1,1,1,1,1,1
1,1,1,1,1,1,1,2,0,0,2,0,0,0,0,0,0,0,2,0,0,2,1,1,1,1,1,1,1
1,1,1,1,1,1,1,5,0,0,5,0,0,0,0,0,0,0,5,0,0,5,1,1,1,1,1,1,1
1,1,1,1,1,1,1,2,0,0,2,0,0,0,0,0,0,0,2,0,0,2,1,1,1,1,1,1,1
1,1,1,1,1,1,3,0,0,0,0,3,0,0,0,0,0,3,0,0,0,0,3,1,1,1,1,1,1
1,1,1,1,1,3,0,0,0,0,0,0,3,0,0,0,3,0,0,0,0,0,0,3,1,1,1,1,1
1,1,1,1,2,0,0,0,0,0,0,0,0,2,5,2,0,0,0,0,0,0,0,0,2,1,1,1,1
1,1,1,1,2,0,0,0,0,0,0,0,0,0,0,0,0,0,0,0,0,0,0,0,2,1,1,1,1
1,1,1,1,2,0,0,0,0,0,0,0,0,0,0,0,0,0,0,0,0,0,0,0,2,1,1,1,1
1,1,1,1,2,0,0,0,0,0,0,0,0,2,5,2,0,0,0,0,0,0,0,0,2,1,1,1,1
1,1,1,3,3,3,0,0,0,0,0,0,3,1,1,1,3,0,0,0,0,0,0,3,3,3,1,1,1
1,1,3,3,1,1,3,0,0,0,0,3,1,1,1,1,1,3,0,0,0,0,3,1,1,3,3,1,1
1,1,3,1,1,1,3,2,2,2,2,1,1,1,1,1,1,1,2,2,2,2,3,1,1,1,3,1,1
1,1,3,3,1,3,3,1,1,1,1,1,1,1,1,1,1,1,1,1,1,1,3,3,1,3,3,1,1
1,1,1,3,3,3,1,1,1,1,1,1,1,1,1,1,1,1,1,1,1,1,1,3,3,3,1,1,1
1,1,1,1,1,1,1,1,1,1,1,1,1,1,1,1,1,1,1,1,1,1,1,1,1,1,1,1,1
1,1,1,1,1,1,1,1,1,1,1,1,1,1,1,1,1,1,1,1,1,1,1,1,1,1,1,1,1
endlayer

layer
1,1,1,1,1,1,1,1,1,1,1,1,1,1,1,1,1,1,1,1,1,1,1,1,1,1,1,1,1
1,1,1,1,1,1,1,1,1,1,1,1,1,1,1,1,1,1,1,1,1,1,1,1,1,1,1,1,1
1,1,1,3,3,3,1,1,1,1,1,1,1,1,1,1,1,1,1,1,1,1,1,3,3,3,1,1,1
1,1,3,3,1,3,3,1,1,1,1,1,1,1,1,1,1,1,1,1,1,1,3,3,1,3,3,1,1
1,1,3,1,1,1,3,2,2,2,2,1,1,1,1,1,1,1,2,2,2,2,3,1,1,1,3,1,1
1,1,3,3,1,1,3,0,0,0,0,3,1,1,1,1,1,3,0,0,0,0,3,1,1,3,3,1,1
1,1,1,3,3,3,0,0,0,0,0,0,3,1,1,1,3,0,0,0,0,0,0,3,3,3,1,1,1
1,1,1,1,2,0,0,0,0,0,0,0,0,2,5,2,0,0,0,0,0,0,0,0,2,1,1,1,1
1,1,1,1,2,0,0,0,0,0,0,0,0,0,0,0,0,0,0,0,0,0,0,0,2,1,1,1,1
1,1,1,1,2,0,0,0,0,0,0,0,0,0,0,0,0,0,0,0,0,0,0,0,2,1,1,1,1
1,1,1,1,2,0,0,0,0,0,0,0,0,2,5,2,0,0,0,0,0,0,0,0,2,1,1,1,1
1,1,1,1,1,3,0,0,0,0,0,0,3,0,0,0,3,0,0,0,0,0,0,3,1,1,1,1,1
1,1,1,1,1,1,3,0,0,0,0,3,0,0,0,0,0,3,0,0,0,0,3,1,1,1,1,1,1
1,1,1,1,1,1,1,2,0,0,2,0,0,0,0,0,0,0,2,0,0,2,1,1,1,1,1,1,1
1,1,1,1,1,1,1,5,0,0,5,0,0,0,0,0,0,0,5,0,0,5,1,1,1,1,1,1,1
1,1,1,1,1,1,1,2,0,0,2,0,0,0,0,0,0,0,2,0,0,2,1,1,1,1,1,1,1
1,1,1,1,1,1,3,0,0,0,0,3,0,0,0,0,0,3,0,0,0,0,3,1,1,1,1,1,1
1,1,1,1,1,3,0,0,0,0,0,0,3,0,0,0,3,0,0,0,0,0,0,3,1,1,1,1,1
1,1,1,1,2,0,0,0,0,0,0,0,0,2,5,2,0,0,0,0,0,0,0,0,2,1,1,1,1
1,1,1,1,2,0,0,0,0,0,0,0,0,0,0,0,0,0,0,0,0,0,0,0,2,1,1,1,1
1,1,1,1,2,0,0,0,0,0,0,0,0,0,0,0,0,0,0,0,0,0,0,0,2,1,1,1,1
1,1,1,1,2,0,0,0,0,0,0,0,0,2,5,2,0,0,0,0,0,0,0,0,2,1,1,1,1
1,1,1,3,3,3,0,0,0,0,0,0,3,1,1,1,3,0,0,0,0,0,0,3,3,3,1,1,1
1,1,3,3,1,1,3,0,0,0,0,3,1,1,1,1,1,3,0,0,0,0,3,1,1,3,3,1,1
1,1,3,1,1,1,3,2,2,2,2,1,1,1,1,1,1,1,2,2,2,2,3,1,1,1,3,1,1
1,1,3,3,1,3,3,1,1,1,1,1,1,1,1,1,1,1,1,1,1,1,3,3,1,3,3,1,1
1,1,1,3,3,3,1,1,1,1,1,1,1,1,1,1,1,1,1,1,1,1,1,3,3,3,1,1,1
1,1,1,1,1,1,1,1,1,1,1,1,1,1,1,1,1,1,1,1,1,1,1,1,1,1,1,1,1
1,1,1,1,1,1,1,1,1,1,1,1,1,1,1,1,1,1,1,1,1,1,1,1,1,1,1,1,1
endlayer

layer
1,1,1,1,1,1,1,1,1,1,1,1,1,1,1,1,1,1,1,1,1,1,1,1,1,1,1,1,1
1,1,1,1,1,1,1,1,1,1,1,1,1,1,1,1,1,1,1,1,1,1,1,1,1,1,1,1,1
1,1,1,3,3,3,1,1,1,1,1,1,1,1,1,1,1,1,1,1,1,1,1,3,3,3,1,1,1
1,1,3,3,1,3,3,1,1,1,1,1,1,1,1,1,1,1,1,1,1,1,3,3,1,3,3,1,1
1,1,3,1,1,1,3,2,2,2,2,1,1,1,1,1,1,1,2,2,2,2,3,1,1,1,3,1,1
1,1,3,3,1,1,3,0,6,6,0,3,1,1,1,1,1,3,0,6,6,0,3,1,1,3,3,1,1
1,1,1,3,3,3,0,0,0,0,0,0,3,1,1,1,3,0,0,0,0,0,0,3,3,3,1,1,1
1,1,1,1,2,0,0,0,0,0,0,0,0,2,5,2,0,0,0,0,0,0,0,0,2,1,1,1,1
1,1,1,1,2,9,0,0,7,8,0,0,0,0,0,0,0,0,0,7,8,0,0,7,2,1,1,1,1
1,1,1,1,2,9,0,0,6,9,0,0,0,0,0,0,0,0,0,6,9,0,0,7,2,1,1,1,1
1,1,1,1,2,0,0,0,0,0,0,0,0,2,5,2,0,0,0,0,0,0,0,0,2,1,1,1,1
1,1,1,1,1,3,0,0,0,0,0,0,3,0,0,0,3,0,0,0,0,0,0,3,1,1,1,1,1
1,1,1,1,1,1,3,0,0,0,0,3,0,0,0,0,0,3,0,0,0,0,3,1,1,1,1,1,1
1,1,1,1,1,1,1,2,0,0,2,0,0,0,0,0,0,0,2,0,0,2,1,1,1,1,1,1,1
1,1,1,1,1,1,1,5,0,0,5,0,0,0,0,0,0,0,5,0,0,5,1,1,1,1,1,1,1
1,1,1,1,1,1,1,2,0,0,2,0,0,0,0,0,0,0,2,0,0,2,1,1,1,1,1,1,1
1,1,1,1,1,1,3,0,0,0,0,3,0,0,0,0,0,3,0,0,0,0,3,1,1,1,1,1,1
1,1,1,1,1,3,0,0,0,0,0,0,3,0,0,0,3,0,0,0,0,0,0,3,1,1,1,1,1
1,1,1,1,2,0,0,0,0,0,0,0,0,2,5,2,0,0,0,0,0,0,0,0,2,1,1,1,1
1,1,1,1,2,9,0,0,7,8,0,0,0,0,0,0,0,0,0,7,8,0,0,7,2,1,1,1,1
1,1,1,1,2,9,0,0,6,9,0,0,0,0,0,0,0,0,0,6,9,0,0,7,2,1,1,1,1
1,1,1,1,2,0,0,0,0,0,0,0,0,2,5,2,0,0,0,0,0,0,0,0,2,1,1,1,1
1,1,1,3,3,3,0,0,0,0,0,0,3,1,1,1,3,0,0,0,0,0,0,3,3,3,1,1,1
1,1,3,3,1,1,3,0,8,8,0,3,1,1,1,1,1,3,0,8,8,0,3,1,1,3,3,1,1
1,1,3,1,1,1,3,2,2,2,2,1,1,1,1,1,1,1,2,2,2,2,3,1,1,1,3,1,1
1,1,3,3,1,3,3,1,1,1,1,1,1,1,1,1,1,1,1,1,1,1,3,3,1,3,3,1,1
1,1,1,3,3,3,1,1,1,1,1,1,1,1,1,1,1,1,1,1,1,1,1,3,3,3,1,1,1
1,1,1,1,1,1,1,1,1,1,1,1,1,1,1,1,1,1,1,1,1,1,1,1,1,1,1,1,1
1,1,1,1,1,1,1,1,1,1,1,1,1,1,1,1,1,1,1,1,1,1,1,1,1,1,1,1,1
endlayer

# Ground Level
layer
1,1,1,1,1,1,1,1,1,1,1,1,1,1,1,1,1,1,1,1,1,1,1,1,1,1,1,1,1
1,1,1,1,1,1,1,1,1,1,1,1,1,1,1,1,1,1,1,1,1,1,1,1,1,1,1,1,1
1,1,1,3,3,3,1,1,1,1,1,1,1,1,1,1,1,1,1,1,1,1,1,3,3,3,1,1,1
1,1,3,3,0,3,3,1,1,1,1,1,1,1,1,1,1,1,1,1,1,1,3,3,0,3,3,1,1
1,1,3,0,0,0,3,2,10,10,2,1,1,1,0,1,1,1,2,10,10,2,3,0,0,0,3,1,1
1,1,3,3,0,0,3,11,10,10,0,3,1,0,0,0,1,3,0,10,10,0,3,0,0,3,3,1,1
1,1,1,3,3,3,0,12,10,10,0,0,3,0,0,0,3,0,0,10,10,0,0,3,3,3,1,1,1
1,1,1,1,2,0,0,0,10,10,0,0,0,2,13,2,0,0,0,10,10,0,12,11,2,1,1,1,1
1,1,1,1,10,10,10,10,10,10,10,10,10,10,10,10,10,10,10,10,10,10,10,10,10,1,1,1,1
1,1,1,1,10,10,10,10,10,10,10,10,10,10,10,10,10,10,10,10,10,10,10,10,10,1,1,1,1
1,1,1,1,2,0,14,0,10,10,0,0,0,2,13,2,0,0,0,10,10,0,0,0,2,1,1,1,1
1,1,1,1,1,3,0,0,10,10,0,0,3,13,13,13,3,0,0,10,10,0,0,3,1,1,1,1,1
1,1,1,1,1,1,3,0,10,10,0,3,13,4,0,4,13,3,0,10,10,0,3,1,1,1,1,1,1
1,1,1,1,1,0,0,2,10,10,2,13,4,0,4,0,4,13,2,10,10,2,0,0,1,1,1,1,1
1,1,1,1,0,0,0,13,10,10,13,13,0,4,0,4,0,13,13,10,10,13,0,0,0,1,1,1,1
1,1,1,1,1,0,0,2,10,10,2,13,4,0,4,0,4,13,2,10,10,2,0,0,1,1,1,1,1
1,1,1,1,1,1,3,0,10,10,0,3,13,4,0,4,13,3,0,10,10,0,3,1,1,1,1,1,1
1,1,1,1,1,3,0,0,10,10,0,0,3,13,13,13,3,0,0,10,10,0,0,3,1,1,1,1,1
1,1,1,1,2,0,0,0,10,10,0,0,0,2,13,2,0,0,0,10,10,0,0,0,2,1,1,1,1
1,1,1,1,10,10,10,10,10,10,10,10,10,10,10,10,10,10,10,10,10,10,10,10,10,1,1,1,1
1,1,1,1,10,10,10,10,10,10,10,10,10,10,10,10,10,10,10,10,10,10,10,10,10,1,1,1,1
1,1,1,1,2,11,12,0,10,10,0,0,0,2,13,2,0,0,0,10,10,0,0,0,2,1,1,1,1
1,1,1,3,3,3,0,0,10,10,0,0,3,0,0,0,3,0,0,10,10,12,0,3,3,3,1,1,1
1,1,3,3,0,0,3,0,10,10,0,3,1,0,0,0,1,3,0,10,10,11,3,0,0,3,3,1,1
1,1,3,0,0,0,3,2,10,10,2,1,1,1,0,1,1,1,2,10,10,2,3,0,0,0,3,1,1
1,1,3,3,0,3,3,1,1,1,1,1,1,1,1,1,1,1,1,1,1,1,3,3,0,3,3,1,1
1,1,1,3,3,3,1,1,1,1,1,1,1,1,1,1,1,1,1,1,1,1,1,3,3,3,1,1,1
1,1,1,1,1,1,1,1,1,1,1,1,1,1,1,1,1,1,1,1,1,1,1,1,1,1,1,1,1
1,1,1,1,1,1,1,1,1,1,1,1,1,1,1,1,1,1,1,1,1,1,1,1,1,1,1,1,1
endlayer

# Ground Floor
layer
1,1,1,1,1,1,1,1,1,1,1,1,1,1,1,1,1,1,1,1,1,1,1,1,1,1,1,1,1
1,1,1,1,1,1,1,1,1,1,1,1,1,1,1,1,1,1,1,1,1,1,1,1,1,1,1,1,1
1,1,1,0,0,0,1,1,1,1,1,1,0,0,0,0,0,1,1,1,1,1,1,0,0,0,1,1,1
1,1,0,0,0,0,0,0,0,0,0,0,0,0,0,0,0,0,0,0,0,0,0,0,0,0,0,1,1
1,1,0,0,0,0,0,2,0,0,2,0,0,0,0,0,0,0,2,0,0,2,0,0,0,0,0,1,1
1,1,0,0,0,0,3,0,0,0,0,3,0,0,0,0,0,3,0,0,0,0,3,0,0,0,0,1,1
1,1,1,0,0,3,11,16,0,0,0,0,3,0,0,0,3,0,14,0,0,12,11,3,0,0,1,1,1
1,1,1,0,2,0,12,0,0,0,0,0,0,2,5,2,0,0,0,0,0,0,16,0,2,0,1,1,1
1,1,1,0,0,0,0,0,0,0,0,0,0,0,0,0,0,0,0,0,0,0,0,0,0,0,1,1,1
1,1,1,0,0,0,0,0,0,0,0,0,0,0,0,0,0,0,0,0,0,0,0,0,0,0,1,1,1
1,1,1,0,2,0,5,0,0,0,0,0,0,2,5,2,0,0,0,0,0,0,0,0,2,0,1,1,1
1,1,1,0,0,3,0,14,0,0,14,0,3,0,0,0,3,0,14,0,0,14,0,3,0,0,1,1,1
1,1,0,0,0,0,3,0,0,0,0,3,0,0,0,0,0,3,0,0,0,0,3,0,0,0,0,1,1
1,1,0,0,0,0,0,2,0,0,2,0,0,0,0,0,0,0,2,0,0,2,0,0,0,0,0,1,1
1,1,0,0,0,0,0,5,0,0,5,0,0,0,0,0,0,0,5,0,0,5,0,0,0,0,0,1,1
1,1,0,0,0,0,0,2,0,0,2,0,0,0,0,0,0,0,2,0,0,2,0,0,0,0,0,1,1
1,1,0,0,0,0,3,0,0,0,0,3,0,0,0,0,0,3,0,0,0,0,3,0,0,0,0,1,1
1,1,1,0,0,3,0,0,0,0,0,0,3,0,0,0,3,0,0,0,0,0,0,3,0,0,1,1,1
1,1,1,0,2,0,14,0,0,0,0,0,0,2,5,2,0,0,0,0,0,0,0,0,2,0,1,1,1
1,1,1,0,0,0,0,0,0,0,0,0,0,0,0,0,0,0,14,0,0,0,0,0,0,0,1,1,1
1,1,1,0,0,0,0,0,0,0,0,0,0,0,0,0,0,0,0,0,0,0,0,0,0,0,1,1,1
1,1,1,0,2,0,16,0,0,0,0,0,0,2,5,2,0,14,0,0,0,0,12,0,2,0,1,1,1
1,1,1,0,0,3,11,12,0,0,14,0,3,0,0,0,3,0,0,0,0,16,11,3,0,0,1,1,1
1,1,0,0,0,0,3,0,0,0,0,3,0,0,0,0,0,3,0,0,0,0,3,0,0,0,0,1,1
1,1,0,0,0,0,14,2,0,0,2,0,0,0,0,0,0,0,2,0,0,2,0,0,0,0,0,1,1
1,1,0,0,0,0,0,0,0,0,0,0,0,0,0,0,0,0,0,0,0,0,0,0,0,0,0,1,1
1,1,1,0,0,0,1,1,1,1,1,1,0,0,0,0,1,1,1,1,1,1,1,0,0,0,1,1,1
1,1,1,1,1,1,1,1,1,1,1,1,1,1,1,1,1,1,1,1,1,1,1,1,1,1,1,1,1
1,1,1,1,1,1,1,1,1,1,1,1,1,1,1,1,1,1,1,1,1,1,1,1,1,1,1,1,1
endlayer

# Ground Floor
layer
1,1,1,1,1,1,1,0,0,0,0,0,1,1,1,1,1,0,0,0,0,0,1,1,1,1,1,1,1
1,1,1,1,0,0,0,0,0,0,0,0,0,0,0,0,0,0,0,0,0,0,0,0,0,1,1,1,1
1,1,0,0,0,0,0,0,0,0,0,0,0,0,0,0,0,0,0,0,0,0,0,0,0,0,0,1,1
1,1,0,0,0,0,0,0,0,0,0,0,0,0,0,0,0,0,0,0,0,0,0,0,0,0,0,1,1
1,0,0,0,0,0,0,2,0,0,2,0,0,0,0,0,0,0,2,0,0,2,0,0,0,0,0,0,1
1,0,0,0,0,0,3,0,0,0,0,3,0,0,0,0,0,3,0,0,12,11,3,0,0,0,0,0,1
1,0,0,0,0,3,0,0,0,0,0,0,3,0,0,0,3,0,5,0,0,16,0,3,0,0,0,0,1
0,0,0,0,2,11,16,0,14,0,0,14,0,2,17,2,0,0,0,0,0,0,0,0,2,0,0,0,0
0,0,0,0,0,12,0,0,0,0,0,0,0,0,0,0,0,0,14,0,0,0,0,0,0,0,0,0,0
0,0,0,0,0,0,0,0,0,0,0,0,0,0,0,0,0,14,0,0,0,0,14,0,0,0,0,0,0
0,0,0,0,2,0,5,0,0,0,0,0,0,2,0,2,0,0,0,0,0,0,0,0,2,0,0,0,0
0,0,0,0,0,3,0,5,0,0,5,0,3,0,0,0,3,0,5,0,0,5,0,3,0,0,0,0,0
1,0,0,0,0,0,3,0,0,0,0,3,0,0,0,0,0,3,0,0,0,0,3,0,0,0,0,0,1
1,0,0,0,0,0,0,2,0,0,2,0,0,0,0,0,0,0,2,0,0,2,0,0,0,0,0,0,1
1,0,0,0,0,0,0,17,0,0,0,0,0,0,0,0,0,0,0,0,0,17,0,0,0,0,0,0,1
1,0,0,0,0,0,0,2,0,0,2,0,0,0,0,0,0,0,2,0,0,2,0,0,0,0,0,0,1
1,0,0,0,0,0,3,0,0,0,0,3,0,0,0,0,0,3,0,0,0,0,3,0,0,0,0,0,1
0,0,0,0,0,3,0,0,0,0,0,0,3,0,0,0,3,0,0,0,0,0,0,3,0,0,0,0,0
0,0,0,0,2,0,5,0,0,0,0,0,0,2,0,2,0,0,0,14,0,0,0,0,2,0,0,0,0
0,0,0,0,0,0,0,0,0,14,0,0,0,0,0,0,0,0,5,0,0,0,0,0,0,0,0,0,0
0,0,0,0,0,0,0,0,0,0,0,0,0,0,0,0,0,0,0,0,0,14,0,12,0,0,0,0,0
0,0,0,0,2,0,0,0,0,0,0,14,0,2,17,2,0,5,0,0,0,0,16,11,2,0,0,0,0
1,0,0,0,0,3,0,16,0,0,5,0,3,0,0,0,3,0,14,0,0,0,0,3,0,0,0,0,1
1,0,0,0,0,0,3,11,12,0,0,3,0,0,0,0,0,3,0,0,0,0,3,0,0,0,0,0,1
1,0,0,0,0,0,0,2,0,0,2,0,0,0,0,0,0,0,2,0,0,2,0,0,0,0,0,0,1
1,1,0,0,0,0,0,0,0,0,0,0,0,0,0,0,0,0,0,0,0,0,0,0,0,0,0,1,1
1,1,0,0,0,0,0,0,0,0,0,0,0,0,0,0,0,0,0,0,0,0,0,0,0,0,0,1,1
1,1,1,1,0,0,0,0,0,0,0,0,0,0,0,0,0,0,0,0,0,0,0,0,0,1,1,1,1
1,1,1,1,1,1,1,0,0,0,0,0,1,1,1,1,0,0,0,0,0,0,1,1,1,1,1,1,1
endlayer

layer
1,1,1,1,0,0,0,0,0,0,0,0,0,0,0,0,0,0,0,0,0,0,0,0,0,1,1,1,1
1,1,0,0,0,0,0,0,0,0,0,0,0,0,0,0,0,0,0,0,0,0,0,0,0,0,0,1,1
1,0,0,0,0,0,0,0,0,0,0,0,0,0,0,0,0,0,0,0,0,0,0,0,0,0,0,0,1
1,0,0,0,0,0,0,0,0,0,0,0,0,0,0,0,0,0,0,0,0,0,0,0,0,0,0,0,1
0,0,0,0,0,0,0,2,2,2,2,0,0,0,0,0,0,0,2,2,2,2,0,0,0,0,0,0,0
0,0,0,0,0,0,3,0,0,0,0,3,0,0,0,0,0,3,12,11,16,0,3,0,0,0,0,0,0
0,0,0,0,0,3,0,0,0,0,0,0,3,0,0,0,3,0,5,0,0,0,0,3,0,0,0,0,0
0,0,0,0,2,0,0,0,5,0,0,5,0,2,0,2,0,0,0,0,0,0,0,0,2,0,0,0,0
0,0,0,0,2,16,0,0,0,0,0,0,0,2,0,2,0,0,5,0,0,0,0,0,2,0,0,0,0
0,0,0,0,2,11,0,0,0,0,0,0,0,2,0,2,0,5,0,0,0,0,5,0,2,0,0,0,0
0,0,0,0,2,12,5,0,0,0,0,0,0,2,0,2,0,0,0,0,0,0,0,0,2,0,0,0,0
0,0,0,0,0,3,0,5,0,0,5,0,3,0,0,0,3,0,5,0,0,5,0,3,0,0,0,0,0
0,0,0,0,0,0,3,0,0,0,0,3,0,0,0,0,0,3,0,0,0,0,3,0,0,0,0,0,0
0,0,0,0,0,0,0,2,2,2,2,0,0,0,0,0,0,0,2,2,2,2,0,0,0,0,0,0,0
0,0,0,0,0,0,0,0,0,0,0,0,0,0,0,0,0,0,0,0,0,0,0,0,0,0,0,0,0
0,0,0,0,0,0,0,2,2,2,2,0,0,0,0,0,0,0,2,2,2,2,0,0,0,0,0,0,0
0,0,0,0,0,0,3,0,0,0,0,3,0,0,0,0,0,3,0,0,0,0,3,0,0,0,0,0,0
0,0,0,0,0,3,0,0,0,0,0,0,3,0,0,0,3,0,0,0,0,0,0,3,0,0,0,0,0
0,0,0,0,2,0,5,0,0,0,0,0,0,2,0,2,0,0,0,5,0,0,0,12,2,0,0,0,0
0,0,0,0,2,0,0,0,0,5,0,0,0,2,0,2,0,0,5,0,0,0,0,11,2,0,0,0,0
0,0,0,0,2,0,0,0,0,0,0,0,0,2,0,2,0,0,0,0,0,5,0,16,2,0,0,0,0
0,0,0,0,2,0,0,0,0,0,0,5,0,2,0,2,0,5,0,0,0,0,0,0,2,0,0,0,0
0,0,0,0,0,3,0,0,0,0,5,0,3,0,0,0,3,0,5,0,0,0,0,3,0,0,0,0,0
0,0,0,0,0,0,3,0,16,11,12,3,0,0,0,0,0,3,0,0,0,0,3,0,0,0,0,0,0
0,0,0,0,0,0,0,2,2,2,2,0,0,0,0,0,0,0,2,2,2,2,0,0,0,0,0,0,0
1,0,0,0,0,0,0,0,0,0,0,0,0,0,0,0,0,0,0,0,0,0,0,0,0,0,0,0,1
1,0,0,0,0,0,0,0,0,0,0,0,0,0,0,0,0,0,0,0,0,0,0,0,0,0,0,0,1
1,1,0,0,0,0,0,0,0,0,0,0,0,0,0,0,0,0,0,0,0,0,0,0,0,0,0,1,1
1,1,1,1,0,0,0,0,0,0,0,0,0,0,0,0,0,0,0,0,0,0,0,0,0,1,1,1,1
endlayer

layer
1,1,0,0,0,0,0,0,0,0,0,0,0,0,0,0,0,18,18,18,0,0,0,0,0,0,0,1,1
1,0,0,0,0,0,0,0,0,0,0,0,0,0,0,0,0,18,19,18,0,0,0,0,0,0,0,0,1
0,0,0,0,0,0,0,0,0,0,0,0,0,0,0,0,0,18,18,18,0,0,0,0,0,0,0,0,0
0,0,0,0,0,0,0,0,5,5,0,0,0,0,0,0,0,0,0,5,5,0,0,0,0,0,0,0,0
0,0,0,0,0,0,0,20,3,3,20,0,0,0,0,0,0,0,20,3,3,20,0,0,0,0,0,0,0
0,0,0,0,0,0,3,11,21,21,11,3,0,0,0,0,0,3,16,0,0,0,3,0,0,0,0,0,0
0,0,0,0,0,3,12,11,11,11,11,11,3,0,0,0,3,11,11,11,11,0,12,3,0,0,0,0,0
0,0,0,0,20,0,0,21,11,21,21,11,11,20,5,20,11,21,11,11,21,11,11,11,20,0,0,0,0
0,0,0,5,3,0,11,11,11,11,11,11,11,3,22,3,21,11,11,21,21,11,11,21,3,5,0,0,0
0,0,0,5,3,0,21,21,11,11,11,21,11,3,22,3,11,11,11,21,21,11,11,11,3,5,0,0,0
0,0,0,0,20,16,11,11,11,21,11,21,11,20,5,20,11,21,11,11,11,11,21,11,20,0,0,0,0
0,0,0,0,0,3,11,11,11,11,11,11,3,0,0,0,3,11,11,11,11,11,11,3,0,0,0,0,0
0,0,0,0,0,0,3,11,11,11,11,3,0,0,0,0,0,3,11,11,11,11,3,0,0,0,0,0,0
0,0,0,0,0,0,0,20,3,3,20,0,0,0,0,0,0,0,20,3,3,20,0,0,0,0,0,0,0
0,0,0,0,0,0,0,5,22,22,5,0,0,0,0,0,0,0,5,22,22,5,0,0,0,0,0,0,0
0,0,0,0,0,0,0,20,3,3,20,0,0,0,0,0,0,0,20,3,3,20,0,0,0,0,0,0,0
0,0,0,0,0,0,3,11,11,11,11,3,0,0,0,0,0,3,11,21,11,11,3,0,0,0,0,0,0
0,0,0,0,0,3,11,21,11,11,21,11,3,0,0,0,3,11,11,11,11,11,21,3,0,0,0,0,0
0,0,0,0,20,21,11,11,11,21,11,11,11,20,5,20,11,11,21,11,11,11,11,16,20,0,0,0,0
0,0,0,5,3,11,11,21,11,11,21,21,11,3,22,3,11,11,11,21,11,11,21,0,3,5,0,0,0
0,0,0,5,3,11,21,11,11,11,21,11,11,3,22,3,11,11,21,11,11,11,11,0,3,5,0,0,0
0,0,0,0,20,11,11,11,21,11,11,11,11,20,5,20,11,11,11,11,21,11,0,0,20,0,0,0,0
0,0,0,0,0,3,12,0,11,11,11,11,3,0,0,0,3,11,11,11,11,11,12,3,0,0,0,0,0
0,0,0,0,0,0,3,0,0,0,16,3,0,0,0,0,0,3,11,11,11,11,3,0,0,0,0,0,0
0,0,0,0,0,0,0,20,3,3,20,0,0,0,0,0,0,0,20,3,3,20,0,0,0,0,0,0,0
0,0,0,0,0,0,0,0,5,5,0,0,0,0,0,0,0,0,0,5,5,0,0,0,0,0,0,0,0
0,0,0,0,0,0,0,0,0,0,0,0,0,0,0,0,0,0,0,0,0,0,0,0,0,0,0,0,0
1,0,0,0,0,0,0,0,0,0,0,0,0,0,0,0,0,0,0,0,0,0,0,0,0,0,0,0,1
1,1,0,0,0,0,0,0,0,0,0,0,0,0,0,0,0,0,0,0,0,0,0,0,0,0,0,1,1
endlayer

# 2nd Floor
layer
1,0,0,0,0,0,0,0,0,0,0,0,0,0,0,0,0,18,18,18,0,0,0,0,0,0,0,0,1
0,0,0,0,0,0,0,0,0,0,0,0,0,0,0,0,0,18,23,18,0,0,0,0,0,0,0,0,0
0,0,0,0,0,0,0,0,0,0,0,0,0,0,0,0,0,18,18,18,0,0,0,0,0,0,0,0,0
0,0,0,0,0,0,0,0,0,0,0,0,0,0,0,0,0,0,0,0,0,0,0,0,0,0,0,0,0
0,0,0,0,0,0,0,2,2,2,2,0,0,0,0,0,0,0,2,2,2,2,0,0,0,0,0,0,0
0,0,0,0,0,0,3,11,16,0,0,3,0,0,0,0,0,3,0,0,0,0,3,0,0,0,0,0,0
0,0,0,0,0,3,14,12,0,0,0,14,3,0,0,0,3,14,0,0,0,0,14,3,0,0,0,0,0
0,0,0,0,2,0,0,0,0,0,0,0,0,2,13,2,0,0,0,0,0,0,12,11,2,0,0,0,0
0,0,0,0,2,0,0,0,0,0,0,0,0,10,10,10,0,0,0,0,0,0,24,16,2,0,0,0,0
0,0,0,0,2,0,0,0,0,0,0,0,0,10,10,10,0,0,0,0,0,24,0,0,2,0,0,0,0
0,0,0,0,2,0,0,0,0,0,0,0,0,2,13,2,0,0,0,0,0,0,0,25,2,0,0,0,0
0,0,0,0,0,3,14,0,0,0,0,14,3,0,0,0,3,14,0,0,0,0,14,3,0,0,0,0,0
0,0,0,0,0,0,3,0,0,0,0,3,0,0,0,0,0,3,26,0,0,0,3,0,0,0,0,0,0
0,0,0,0,0,0,0,2,10,10,2,0,0,0,0,0,0,0,2,10,10,2,0,0,0,0,0,0,0
0,0,0,0,0,0,0,13,10,10,13,0,0,0,0,0,0,0,13,10,10,13,0,0,0,0,0,0,0
0,0,0,0,0,0,0,2,10,10,2,0,0,0,0,0,0,0,2,10,10,2,0,0,0,0,0,0,0
0,0,0,0,0,0,3,0,0,0,0,3,0,0,0,0,0,3,0,0,0,0,3,0,0,0,0,0,0
0,0,0,0,0,3,14,0,0,0,0,14,3,0,0,0,3,14,0,0,0,0,14,3,0,0,0,0,0
0,0,0,0,2,26,0,0,0,0,0,0,25,2,13,2,0,0,0,18,18,0,0,0,2,0,0,0,0
0,0,0,0,2,0,0,0,0,0,0,0,0,10,10,10,0,0,0,18,5,27,0,0,2,0,0,0,0
0,0,0,0,2,16,0,30,29,28,0,0,0,10,10,10,0,0,0,18,5,27,0,0,2,14,0,0,0
0,0,0,0,2,11,12,0,0,0,0,0,0,2,13,2,0,0,0,18,18,0,0,0,2,0,0,0,0
0,0,0,0,0,3,14,0,0,0,0,14,3,0,0,0,3,14,0,0,0,12,14,3,0,0,0,0,0
0,0,0,0,0,0,3,0,0,0,0,3,0,0,0,0,0,3,0,0,16,11,3,0,0,0,0,0,0
0,0,0,0,0,0,0,2,2,2,2,0,0,0,0,0,0,0,2,2,2,2,0,0,0,0,0,0,0
0,0,0,0,0,0,0,0,0,0,0,0,0,0,0,0,0,0,0,0,0,0,0,0,0,0,0,0,0
0,0,0,0,0,0,0,0,0,0,0,0,0,0,0,0,0,0,0,0,0,0,0,0,0,0,0,0,0
0,0,0,0,0,0,0,0,0,0,0,0,0,0,0,0,0,0,0,0,0,0,0,0,0,0,0,0,0
1,0,0,0,0,0,0,0,0,0,0,0,0,0,0,0,0,0,0,0,0,0,0,0,0,0,0,0,1
endlayer

layer
0,0,0,0,0,0,0,0,0,0,0,0,0,0,0,0,0,18,18,18,0,0,0,0,0,0,0,0,0
0,0,0,0,0,0,0,0,0,0,0,0,0,0,0,0,0,18,0,18,0,0,0,0,0,0,0,0,0
0,0,0,0,0,0,0,0,0,0,0,0,0,0,0,0,0,18,18,18,0,0,0,0,0,0,0,0,0
0,0,0,0,0,0,0,0,0,0,0,0,0,0,0,0,0,0,0,0,0,0,0,0,0,0,0,0,0
0,0,0,0,0,0,0,2,31,31,2,0,0,0,0,0,0,0,2,31,31,2,0,0,0,0,0,0,0
0,0,0,0,0,0,3,0,0,0,0,3,0,0,0,0,0,3,0,0,0,0,3,0,0,0,0,0,0
0,0,0,0,0,3,11,16,0,0,0,0,3,0,0,0,3,0,0,0,0,12,11,3,0,0,0,0,0
0,0,0,0,2,0,12,0,0,0,0,0,0,2,5,2,0,0,0,0,0,0,16,0,2,0,0,0,0
0,0,0,0,31,0,0,0,0,0,0,0,0,0,0,0,0,0,0,0,0,0,0,0,31,0,0,0,0
0,0,0,0,31,0,0,0,0,0,0,0,0,0,0,0,0,0,0,0,0,0,0,0,31,0,0,0,0
0,0,0,0,2,0,0,0,0,0,0,0,0,2,5,2,0,0,0,0,0,0,0,0,2,0,0,0,0
0,0,0,0,0,3,0,0,0,0,0,0,3,0,0,0,3,0,0,0,0,0,0,3,0,0,0,0,0
0,0,0,0,0,0,3,0,0,0,0,3,0,0,0,0,0,3,0,0,0,0,3,0,0,0,0,0,0
0,0,0,0,0,0,0,2,0,0,2,0,0,0,0,0,0,0,2,0,0,2,0,0,0,0,0,0,0
0,0,0,0,0,0,0,5,0,0,5,0,0,0,0,0,0,0,5,0,0,5,0,0,0,0,0,0,0
0,0,0,0,0,0,0,2,0,0,2,0,0,0,0,0,0,0,2,0,0,2,0,0,0,0,0,0,0
0,0,0,0,0,0,3,0,0,0,0,3,0,0,0,0,0,3,0,0,0,0,3,0,0,0,0,0,0
0,0,0,0,0,3,0,0,0,0,0,0,3,0,0,0,3,0,0,0,0,0,0,3,0,0,0,0,0
0,0,0,0,2,0,0,0,0,0,0,0,0,2,5,2,0,0,0,18,18,0,0,0,2,0,0,0,0
0,0,0,0,31,0,0,0,0,0,0,0,0,0,0,0,0,0,0,0,32,0,0,0,31,0,0,0,0
0,0,0,0,31,0,0,24,14,0,0,0,0,0,0,0,0,0,0,0,32,0,0,0,31,0,0,0,0
0,0,0,0,2,0,0,0,0,0,0,0,0,2,5,2,0,0,0,18,18,0,12,0,2,0,0,0,0
0,0,0,0,0,3,0,0,0,0,0,0,3,0,0,0,3,0,0,0,0,16,11,3,0,0,0,0,0
0,0,0,0,0,0,3,0,0,0,0,3,0,0,0,0,0,3,0,0,0,0,3,0,0,0,0,0,0
0,0,0,0,0,0,0,2,31,31,2,0,0,0,0,0,0,0,2,31,31,2,0,0,0,0,0,0,0
0,0,0,0,0,0,0,0,0,0,0,0,0,0,0,0,0,0,0,0,0,0,0,0,0,0,0,0,0
0,0,0,0,0,0,0,0,0,0,0,0,0,0,0,0,0,0,0,0,0,0,0,0,0,0,0,0,0
0,0,0,0,0,0,0,0,0,0,0,0,0,0,0,0,0,0,0,0,0,0,0,0,0,0,0,0,0
0,0,0,0,0,0,0,0,0,0,0,0,0,0,0,0,0,0,0,0,0,0,0,0,0,0,0,0,0
endlayer

layer
0,0,0,0,0,0,0,0,0,0,0,0,0,0,0,0,0,18,18,18,0,0,0,0,0,0,0,0,0
0,0,0,0,0,0,0,0,0,0,0,0,0,0,0,0,0,18,13,18,0,0,0,0,0,0,0,0,0
0,0,0,0,0,0,0,0,0,0,0,0,0,0,0,0,0,18,18,18,0,0,0,0,0,0,0,0,0
0,0,0,0,0,0,0,0,0,0,0,0,0,0,0,0,0,0,0,0,0,0,0,0,0,0,0,0,0
0,0,0,0,0,0,0,2,31,31,2,0,0,0,0,0,0,0,2,31,31,2,0,0,0,0,0,0,0
0,0,0,0,0,0,3,0,0,0,0,3,0,0,0,0,0,3,0,0,12,11,3,0,0,0,0,0,0
0,0,0,0,0,3,0,0,0,0,0,0,3,0,0,0,3,0,0,0,0,16,0,3,0,0,0,0,0
0,0,0,0,2,11,16,0,0,0,0,0,0,2,17,2,0,0,0,0,0,0,0,0,2,0,0,0,0
0,0,0,0,31,12,0,0,0,0,0,0,0,0,0,0,0,0,0,0,0,0,0,0,31,0,0,0,0
0,0,0,0,31,0,0,0,0,0,0,0,0,0,0,0,0,0,0,0,0,0,0,0,31,0,0,0,0
0,0,0,0,2,0,0,0,0,0,0,0,0,2,0,2,0,0,0,0,0,0,0,0,2,0,0,0,0
0,0,0,0,0,3,0,0,0,0,0,0,3,0,0,0,3,0,0,0,0,0,0,3,0,0,0,0,0
0,0,0,0,0,0,3,0,0,0,0,3,0,0,0,0,0,3,0,0,0,0,3,0,0,0,0,0,0
0,0,0,0,0,0,0,2,0,0,2,0,0,0,0,0,0,0,2,0,0,2,0,0,0,0,0,0,0
0,0,0,0,0,0,0,17,0,0,0,0,0,0,0,0,0,0,0,0,0,17,0,0,0,0,0,0,0
0,0,0,0,0,0,0,2,0,0,2,0,0,0,0,0,0,0,2,0,0,2,0,0,0,0,0,0,0
0,0,0,0,0,0,3,0,0,0,0,3,0,0,0,0,0,3,0,0,0,0,3,0,0,0,0,0,0
0,0,0,0,0,3,0,0,0,0,0,0,3,0,0,0,3,0,0,0,0,0,0,3,0,0,0,0,0
0,0,0,0,2,0,0,0,0,0,0,0,0,2,0,2,0,0,0,0,0,0,0,0,2,0,0,0,0
0,0,0,0,31,0,0,0,0,0,0,0,0,0,0,0,0,0,0,0,0,0,0,0,31,0,0,0,0
0,0,0,0,31,0,0,0,0,0,0,0,0,0,0,0,0,0,0,0,0,0,0,12,31,0,0,0,0
0,0,0,0,2,0,0,0,0,0,0,0,0,2,17,2,0,0,0,0,0,0,16,11,2,0,0,0,0
0,0,0,0,0,3,0,0,0,0,0,0,3,0,0,0,3,0,0,0,0,0,0,3,0,0,0,0,0
0,0,0,0,0,0,3,0,0,0,0,3,0,0,0,0,0,3,0,0,0,0,3,0,0,0,0,0,0
0,0,0,0,0,0,0,2,31,31,2,0,0,0,0,0,0,0,2,31,31,2,0,0,0,0,0,0,0
0,0,0,0,0,0,0,0,0,0,0,0,0,0,0,0,0,0,0,0,0,0,0,0,0,0,0,0,0
0,0,0,0,0,0,0,0,0,0,0,0,0,0,0,0,0,0,0,0,0,0,0,0,0,0,0,0,0
0,0,0,0,0,0,0,0,0,0,0,0,0,0,0,0,0,0,0,0,0,0,0,0,0,0,0,0,0
0,0,0,0,0,0,0,0,0,0,0,0,0,0,0,0,0,0,0,0,0,0,0,0,0,0,0,0,0
endlayer

layer
0,0,0,0,0,0,0,0,0,0,0,0,0,0,0,0,0,14,0,0,0,0,0,0,0,0,0,0,0
0,0,0,0,0,0,0,0,0,0,0,0,0,0,0,0,0,0,18,0,0,0,0,0,0,0,0,0,0
0,0,0,0,0,0,0,0,0,0,0,0,0,0,0,0,0,0,0,0,0,0,0,0,0,0,0,0,0
0,0,0,0,0,0,0,0,0,0,0,0,0,0,0,0,0,0,0,0,0,0,0,0,0,0,0,0,0
0,0,0,0,0,0,0,2,2,2,2,0,0,0,0,0,0,0,2,2,2,2,0,0,0,0,0,0,0
0,0,0,0,0,0,3,0,0,0,0,3,0,0,0,0,0,3,12,11,16,0,3,0,0,0,0,0,0
0,0,0,0,0,3,0,0,0,0,0,0,3,0,0,0,3,0,0,0,0,0,0,3,0,0,0,0,0
0,0,0,0,2,0,0,0,0,0,0,0,0,2,0,2,0,0,0,0,0,0,0,0,2,0,0,0,0
0,0,0,0,2,16,0,0,0,0,0,0,0,2,0,2,0,0,0,0,0,0,0,0,2,0,0,0,0
0,0,0,0,2,11,0,0,0,0,0,0,0,2,0,2,0,0,0,0,0,0,0,0,2,0,0,0,0
0,0,0,0,2,12,0,0,0,0,0,0,0,2,0,2,0,0,0,0,0,0,0,0,2,0,0,0,0
0,0,0,0,0,3,0,0,0,0,0,0,3,0,0,0,3,0,0,0,0,0,0,3,0,0,0,0,0
0,0,0,0,0,0,3,0,0,0,0,3,0,0,0,0,0,3,0,0,0,0,3,0,0,0,0,0,0
0,0,0,0,0,0,0,2,2,2,2,0,0,0,0,0,0,0,2,2,2,2,0,0,0,0,0,0,0
0,0,0,0,0,0,0,0,0,0,0,0,0,0,0,0,0,0,0,0,0,0,0,0,0,0,0,0,0
0,0,0,0,0,0,0,2,2,2,2,0,0,0,0,0,0,0,2,2,2,2,0,0,0,0,0,0,0
0,0,0,0,0,0,3,0,0,0,0,3,0,0,0,0,0,3,0,0,0,0,3,0,0,0,0,0,0
0,0,0,0,0,3,0,0,0,0,0,0,3,0,0,0,3,0,0,0,0,0,0,3,0,0,0,0,0
0,0,0,0,2,0,0,0,0,0,0,0,0,2,0,2,0,0,0,0,0,0,0,12,2,0,0,0,0
0,0,0,0,2,0,0,0,0,0,0,0,0,2,0,2,0,0,0,0,0,0,0,11,2,0,0,0,0
0,0,0,0,2,0,0,0,0,0,0,0,0,2,0,2,0,0,0,0,0,0,0,16,2,0,0,0,0
0,0,0,0,2,0,0,0,0,0,0,0,0,2,0,2,0,0,0,0,0,0,0,0,2,0,0,0,0
0,0,0,0,0,3,0,0,0,0,0,0,3,0,0,0,3,0,0,0,0,0,0,3,0,0,0,0,0
0,0,0,0,0,0,3,0,0,0,0,3,0,0,0,0,0,3,0,0,0,0,3,0,0,0,0,0,0
0,0,0,0,0,0,0,2,2,2,2,0,0,0,0,0,0,0,2,2,2,2,0,0,0,0,0,0,0
0,0,0,0,0,0,0,0,0,0,0,0,0,0,0,0,0,0,0,0,0,0,0,0,0,0,0,0,0
0,0,0,0,0,0,0,0,0,18,18,18,0,0,0,0,0,0,0,0,0,0,0,0,0,0,0,0,0
0,0,0,0,0,0,0,0,0,18,19,18,0,0,0,0,0,0,0,0,0,0,0,0,0,0,0,0,0
0,0,0,0,0,0,0,0,0,18,18,18,0,0,0,0,0,0,0,0,0,0,0,0,0,0,0,0,0
endlayer

layer
0,0,0,0,0,0,0,0,0,0,0,0,0,0,0,0,0,0,0,0,0,0,0,0,0,0,0,0,0
0,0,0,0,0,0,0,0,0,0,0,0,0,0,0,0,0,0,18,0,0,0,0,0,0,0,0,0,0
0,0,0,0,0,0,0,0,0,0,0,0,0,0,0,0,0,0,0,0,0,0,0,0,0,0,0,0,0
0,0,0,0,0,0,0,0,5,5,0,0,0,0,0,0,0,0,0,5,5,0,0,0,0,0,0,0,0
0,0,0,0,0,0,0,20,3,3,20,0,0,0,0,0,0,0,20,3,3,20,0,0,0,0,0,0,0
0,0,0,0,0,0,3,11,21,21,11,3,0,0,0,0,0,3,16,0,0,0,3,0,0,0,0,0,0
0,0,0,0,0,3,12,11,11,11,11,11,3,0,0,0,3,11,11,11,11,0,12,3,0,0,0,0,0
0,0,0,0,20,0,0,21,11,21,21,11,11,20,5,20,11,21,11,11,21,11,11,11,20,0,0,0,0
0,0,0,5,3,0,11,11,11,11,11,11,11,3,22,3,21,11,21,11,11,11,11,21,3,5,0,0,0
0,0,0,5,3,0,21,21,11,21,21,11,11,3,22,3,11,11,11,11,11,11,11,11,3,5,0,0,0
0,0,0,0,20,16,11,11,11,21,11,11,11,20,5,20,11,21,11,11,11,11,21,11,20,0,0,0,0
0,0,0,0,0,3,11,11,11,11,11,11,3,0,0,0,3,11,11,11,11,11,11,3,0,0,0,0,0
0,0,0,0,0,0,3,11,11,11,11,3,0,0,0,0,0,3,11,11,11,11,3,0,0,0,0,0,0
0,0,0,0,0,0,0,20,3,3,20,0,0,0,0,0,0,0,20,3,3,20,0,0,0,0,0,0,0
0,0,0,0,0,0,0,5,22,22,5,0,0,0,0,0,0,0,5,22,22,5,0,0,0,0,0,0,0
0,0,0,0,0,0,0,20,3,3,20,0,0,0,0,0,0,0,20,3,3,20,0,0,0,0,0,0,0
0,0,0,0,0,0,3,0,0,0,0,3,0,0,0,0,0,3,11,21,11,11,3,0,0,0,0,0,0
0,0,0,0,0,3,0,0,0,0,0,0,3,0,0,0,3,11,11,11,11,11,21,3,0,0,0,0,0
0,0,0,0,20,11,0,0,0,0,0,0,0,20,5,20,11,11,11,11,11,11,11,16,20,0,0,0,0
0,0,0,5,3,11,0,0,0,0,0,0,11,3,22,3,11,11,11,21,21,11,21,0,3,5,0,0,0
0,0,0,5,3,11,0,0,0,0,0,0,11,3,22,3,11,11,21,11,21,11,11,0,3,5,0,0,0
0,0,0,0,20,0,0,0,0,0,0,11,11,20,5,20,11,11,11,11,21,11,0,0,20,0,0,0,0
0,0,0,0,0,3,0,0,0,0,0,0,3,0,0,0,3,11,11,11,11,11,12,3,0,0,0,0,0
0,0,0,0,0,0,3,0,0,0,0,3,0,0,0,0,0,3,11,11,11,11,3,0,0,0,0,0,0
0,0,0,0,0,0,0,20,3,3,20,0,0,0,0,0,0,0,20,3,3,20,0,0,0,0,0,0,0
0,0,0,0,0,0,0,0,5,5,0,0,0,0,0,0,0,0,0,5,5,0,0,0,0,0,0,0,0
0,0,0,0,0,0,0,0,0,18,18,18,0,0,0,0,0,0,0,0,0,0,0,0,0,0,0,0,0
0,0,0,0,0,0,0,0,0,18,14,18,0,0,0,0,0,0,0,0,0,0,0,0,0,0,0,0,0
0,0,0,0,0,0,0,0,0,18,18,18,0,0,0,0,0,0,0,0,0,0,0,0,0,0,0,0,0
endlayer

# 3rd Floor
layer
0,0,0,0,0,0,0,0,0,0,0,0,0,0,0,0,0,0,0,0,0,0,0,0,0,0,0,0,0
0,0,0,0,0,0,0,0,0,0,0,0,0,0,0,0,0,0,18,0,0,0,0,0,0,0,0,0,0
0,0,0,0,0,0,0,0,0,0,0,0,0,0,0,0,0,0,0,0,0,0,0,0,0,0,0,0,0
0,0,0,0,0,0,0,0,0,14,0,0,0,0,0,0,0,0,0,0,0,0,0,0,0,0,0,0,0
0,0,0,0,0,0,0,2,2,2,2,0,0,0,0,0,0,0,2,2,2,2,0,0,0,0,0,0,0
0,0,0,0,0,0,3,11,16,0,0,3,0,0,0,0,0,3,0,0,0,0,3,0,0,0,0,0,0
0,0,0,0,0,3,0,12,0,0,0,0,3,0,0,0,3,0,0,0,0,0,0,3,0,0,0,0,0
0,0,0,0,2,0,0,0,0,0,0,0,0,2,13,2,0,0,0,0,0,0,12,11,2,0,0,0,0
0,0,0,14,2,0,0,0,0,0,0,0,0,10,10,10,0,0,0,0,0,0,0,16,2,0,0,0,0
0,0,0,0,2,0,0,0,0,18,18,18,0,10,10,10,0,18,18,18,0,0,0,0,2,0,0,0,0
0,0,0,0,2,0,0,0,0,18,26,18,25,2,13,2,0,18,26,18,0,0,0,0,2,0,0,0,0
0,0,0,0,0,3,0,0,0,18,18,18,3,0,0,0,3,18,18,18,0,0,0,3,0,0,0,0,0
0,0,0,0,0,0,3,0,0,0,25,3,0,0,0,0,0,3,0,0,0,0,3,0,0,0,0,0,0
0,0,0,0,0,0,0,2,10,10,2,0,0,0,0,0,0,0,2,10,10,2,0,0,0,0,0,0,0
0,0,0,0,0,0,0,13,10,10,13,0,0,0,0,0,0,0,13,10,10,13,0,0,0,0,0,0,0
0,0,0,0,0,0,0,2,10,10,2,0,0,0,0,0,0,0,2,10,10,2,0,0,0,0,0,0,0
0,0,0,0,0,0,3,0,0,0,0,3,0,0,0,0,0,3,0,0,0,0,3,0,0,0,0,0,0
0,0,0,0,0,3,0,0,0,18,18,18,3,0,0,0,3,18,18,18,0,0,0,3,0,0,0,0,0
0,0,0,0,2,25,0,0,0,18,26,18,0,2,13,2,0,18,26,18,0,0,0,0,2,0,0,0,0
0,0,0,0,2,0,0,0,0,18,18,18,0,10,10,10,0,18,18,18,0,0,0,0,2,0,0,0,0
0,0,0,0,2,16,0,0,0,0,0,0,0,10,10,10,0,0,0,0,0,0,0,0,2,0,0,0,0
0,0,0,0,2,0,0,0,0,0,0,0,0,2,13,2,0,0,0,0,0,0,0,0,2,0,0,0,0
0,0,0,0,0,3,0,0,0,0,0,0,3,0,0,0,3,0,0,0,0,12,0,3,0,0,0,0,0
0,0,0,0,0,0,3,0,0,0,0,3,0,0,0,0,0,3,0,0,16,11,3,0,0,0,0,0,0
0,0,0,0,0,0,0,2,2,2,2,0,0,0,0,0,0,0,2,2,2,2,0,0,0,0,0,0,0
0,0,0,0,0,0,0,0,0,0,0,0,0,0,0,0,0,0,0,0,14,0,0,0,0,0,0,0,0
0,0,0,0,0,0,0,0,0,18,18,18,0,0,0,0,0,0,0,0,0,0,0,0,0,0,0,0,0
0,0,0,0,0,0,0,0,0,18,0,18,0,0,0,0,0,0,0,0,0,0,0,0,0,0,0,0,0
0,0,0,0,0,0,0,0,0,18,18,18,0,0,0,0,0,0,0,0,0,0,0,0,0,0,0,0,0
endlayer

layer
0,0,0,0,0,0,0,0,0,0,0,0,0,0,0,0,0,0,0,0,0,0,0,0,0,0,0,0,0
0,0,0,0,0,0,0,0,0,0,0,0,0,0,0,0,0,0,18,0,0,0,0,0,0,0,0,0,0
0,0,0,0,0,0,0,0,0,0,0,0,0,0,0,0,0,0,0,0,0,0,0,0,0,0,0,0,0
0,0,0,0,0,0,0,0,0,0,0,0,0,0,0,0,0,0,0,0,0,0,0,0,0,0,0,0,0
0,0,0,0,0,0,0,2,31,31,2,0,0,0,0,0,0,0,2,31,31,2,0,0,0,0,0,0,0
0,0,0,0,0,0,3,0,0,0,0,3,0,0,0,0,0,3,0,0,0,0,3,0,0,0,0,0,0
0,0,0,0,0,3,11,16,0,0,0,0,3,0,0,0,3,0,0,0,0,12,11,3,0,0,0,0,0
0,0,0,0,2,0,12,0,0,0,0,0,0,2,5,2,0,0,0,0,0,0,16,0,2,0,0,0,0
0,0,0,0,31,0,0,0,0,0,0,0,0,0,0,0,0,0,0,0,0,0,0,0,31,0,0,0,0
0,0,0,0,31,0,0,0,0,18,18,18,0,0,0,0,0,18,18,18,0,0,0,0,31,0,0,0,0
0,0,0,0,2,0,0,0,0,18,0,18,0,2,5,2,0,18,0,18,0,0,0,0,2,0,0,0,0
0,0,0,0,0,3,0,0,0,18,18,18,3,0,0,0,3,18,18,18,0,0,0,3,0,0,0,0,0
0,0,0,0,0,0,3,0,0,0,0,3,0,0,0,0,0,3,0,0,0,0,3,0,0,0,0,0,0
0,0,0,0,0,0,0,2,0,0,2,0,0,0,0,0,0,0,2,0,0,2,0,0,0,0,0,0,0
0,0,0,0,0,0,0,5,0,0,5,0,0,0,0,0,0,0,5,0,0,5,0,0,0,0,0,0,0
0,0,0,0,0,0,0,2,0,0,2,0,0,0,0,0,0,0,2,0,0,2,0,0,0,0,0,0,0
0,0,0,0,0,0,3,0,0,0,0,3,0,0,0,0,0,3,0,0,0,0,3,0,0,0,0,0,0
0,0,0,0,0,3,0,0,0,18,18,18,3,0,0,0,3,18,18,18,0,0,0,3,0,0,0,0,0
0,0,0,0,2,0,0,0,0,18,0,18,0,2,5,2,0,18,0,18,0,0,0,0,2,0,0,0,0
0,0,0,0,31,0,0,0,0,18,18,18,0,0,0,0,0,18,18,18,0,0,0,0,31,0,0,0,0
0,0,0,0,31,0,0,0,0,0,0,0,0,0,0,0,0,0,0,0,0,0,0,0,31,0,0,0,0
0,0,0,0,2,0,0,0,0,0,0,0,0,2,5,2,0,0,0,0,0,0,12,0,2,0,0,0,0
0,0,0,0,0,3,0,0,0,0,0,0,3,0,0,0,3,0,0,0,0,16,11,3,0,0,0,0,0
0,0,0,0,0,0,3,0,0,0,0,3,0,0,0,0,0,3,0,0,0,0,3,0,0,0,0,0,0
0,0,0,0,0,0,0,2,31,31,2,0,0,0,0,0,0,0,2,31,31,2,0,0,0,0,0,0,0
0,0,0,0,0,0,0,0,0,0,0,0,0,0,0,0,0,0,0,0,0,0,0,0,0,0,0,0,0
0,0,0,0,0,0,0,0,0,18,18,18,0,0,0,0,0,0,0,0,0,0,0,0,0,0,0,0,0
0,0,0,0,0,0,0,0,0,18,13,18,0,0,0,0,0,0,0,0,0,0,0,0,0,0,0,0,0
0,0,0,0,0,0,0,0,0,18,18,18,0,0,0,0,0,0,0,0,0,0,0,0,0,0,0,0,0
endlayer

layer
0,0,0,0,0,0,0,0,0,0,0,0,0,0,0,0,0,0,0,0,0,0,0,0,0,0,0,0,0
0,0,0,0,0,0,0,0,0,0,0,0,0,0,0,0,0,0,18,0,0,0,0,0,0,0,0,0,0
0,0,0,0,0,0,0,0,0,0,0,0,0,0,0,0,0,0,0,0,0,0,0,0,0,0,0,0,0
0,0,0,0,0,0,0,0,0,0,0,0,0,0,0,0,0,0,0,0,0,0,0,0,0,0,0,0,0
0,0,0,0,0,0,0,2,31,31,2,0,0,0,0,0,0,0,2,31,31,2,0,0,0,0,0,0,0
0,0,0,0,0,0,3,0,0,0,0,3,0,0,0,0,0,3,0,0,12,11,3,0,0,0,0,0,0
0,0,0,0,0,3,0,0,0,0,0,0,3,0,0,0,3,0,0,0,0,16,0,3,0,0,0,0,0
0,0,0,0,2,11,16,0,0,0,0,0,0,2,17,2,0,0,0,0,0,0,0,0,2,0,0,0,0
0,0,0,0,31,12,0,0,0,0,0,0,0,0,0,0,0,0,0,0,0,0,0,0,31,0,0,0,0
0,0,0,0,31,0,0,0,0,18,18,18,0,0,0,0,0,18,18,18,0,0,0,0,31,0,0,0,0
0,0,0,0,2,0,0,0,0,18,0,18,0,2,0,2,0,18,0,18,0,0,0,0,2,0,0,0,0
0,0,0,0,0,3,0,0,0,18,18,18,3,0,0,0,3,18,18,18,0,0,0,3,0,0,0,0,0
0,0,0,0,0,0,3,0,0,0,0,3,0,0,0,0,0,3,0,0,0,0,3,0,0,0,0,0,0
0,0,0,0,0,0,0,2,0,0,2,0,0,0,0,0,0,0,2,0,0,2,0,0,0,0,0,0,0
0,0,0,0,0,0,0,17,0,0,0,0,0,0,0,0,0,0,0,0,0,17,0,0,0,0,0,0,0
0,0,0,0,0,0,0,2,0,0,2,0,0,0,0,0,0,0,2,0,0,2,0,0,0,0,0,0,0
0,0,0,0,0,0,3,0,0,0,0,3,0,0,0,0,0,3,0,0,0,0,3,0,0,0,0,0,0
0,0,0,0,0,3,0,0,0,18,18,18,3,0,0,0,3,18,18,18,0,0,0,3,0,0,0,0,0
0,0,0,0,2,0,0,0,0,18,0,18,0,2,0,2,0,18,0,18,0,0,0,0,2,0,0,0,0
0,0,0,0,31,0,0,0,0,18,18,18,0,0,0,0,0,18,18,18,0,0,0,0,31,0,0,0,0
0,0,0,0,31,0,0,0,0,0,0,0,0,0,0,0,0,0,0,0,0,0,0,12,31,0,0,0,0
0,0,0,0,2,0,0,0,0,0,0,0,0,2,17,2,0,0,0,0,0,0,16,11,2,0,0,0,0
0,0,0,0,0,3,0,0,0,0,0,0,3,0,0,0,3,0,0,0,0,0,0,3,0,0,0,0,0
0,0,0,0,0,0,3,0,0,0,0,3,0,0,0,0,0,3,0,0,0,0,3,0,0,0,0,0,0
0,0,0,0,0,0,0,2,31,31,2,0,0,0,0,0,0,0,2,31,31,2,0,0,0,0,0,0,0
0,0,0,0,0,0,0,0,0,0,0,0,0,0,0,0,0,0,0,0,0,0,0,0,0,0,0,0,0
0,0,0,0,0,0,0,0,0,0,0,0,0,0,0,0,0,0,0,0,0,0,0,0,0,0,0,0,0
0,0,0,0,0,0,0,0,0,0,18,0,0,0,0,0,0,0,0,0,0,0,0,0,0,0,0,0,0
0,0,0,0,0,0,0,0,0,0,0,0,0,0,0,0,0,0,0,0,0,0,0,0,0,0,0,0,0
endlayer

layer
0,0,0,0,0,0,0,0,0,0,0,0,0,0,0,0,0,0,0,0,0,0,0,0,0,0,0,0,0
0,0,0,0,0,0,0,0,0,0,0,0,0,0,0,0,0,0,18,0,0,0,0,0,0,0,0,0,0
0,0,0,0,0,0,0,0,0,0,0,0,0,0,0,0,0,0,0,0,0,0,0,0,0,0,0,0,0
0,0,0,0,0,0,0,0,0,0,0,0,0,0,0,0,0,0,0,0,0,0,0,0,0,0,0,0,0
0,0,0,0,0,0,0,2,2,2,2,0,0,0,0,0,0,0,2,2,2,2,0,0,0,0,0,0,0
0,0,0,0,0,0,3,0,0,0,0,3,0,0,0,0,0,3,12,11,16,0,3,0,0,0,0,0,0
0,0,0,0,0,3,0,0,0,0,0,0,3,0,0,0,3,0,0,0,0,0,0,3,0,0,0,0,0
0,0,0,0,2,0,0,0,0,0,0,0,0,2,0,2,0,0,0,0,0,0,0,0,2,0,0,0,0
0,0,0,0,2,16,0,0,0,0,0,0,0,2,0,2,0,0,0,0,0,0,0,0,2,0,0,0,0
0,0,0,0,2,11,0,0,0,18,18,18,0,2,0,2,0,18,18,18,0,0,0,0,2,0,0,0,0
0,0,0,0,2,12,0,0,0,18,0,18,0,2,0,2,0,18,0,18,0,0,0,0,2,0,0,0,0
0,0,0,0,0,3,0,0,0,18,18,18,3,0,0,0,3,18,18,18,0,0,0,3,0,0,0,0,0
0,0,0,0,0,0,3,0,0,0,0,3,0,0,0,0,0,3,0,0,0,0,3,0,0,0,0,0,0
0,0,0,0,0,0,0,2,2,2,2,0,0,0,0,0,0,0,2,2,2,2,0,0,0,0,0,0,0
0,0,0,0,0,0,0,0,0,0,0,0,0,0,0,0,0,0,0,0,0,0,0,0,0,0,0,0,0
0,0,0,0,0,0,0,2,2,2,2,0,0,0,0,0,0,0,2,2,2,2,0,0,0,0,0,0,0
0,0,0,0,0,0,3,0,0,0,0,3,0,0,0,0,0,3,0,0,0,0,3,0,0,0,0,0,0
0,0,0,0,0,3,0,0,0,18,18,18,3,0,0,0,3,18,18,18,0,0,0,3,0,0,0,0,0
0,0,0,0,2,0,0,0,0,18,0,18,0,2,0,2,0,18,0,18,0,0,0,12,2,0,0,0,0
0,0,0,0,2,0,0,0,0,18,18,18,0,2,0,2,0,18,18,18,0,0,0,11,2,0,0,0,0
0,0,0,0,2,0,0,0,0,0,0,0,0,2,0,2,0,0,0,0,0,0,0,16,2,0,0,0,0
0,0,0,0,2,0,0,0,0,0,0,0,0,2,0,2,0,0,0,0,0,0,0,0,2,0,0,0,0
0,0,0,0,0,3,0,0,0,0,0,0,3,0,0,0,3,0,0,0,0,0,0,3,0,0,0,0,0
0,0,0,0,0,0,3,0,0,0,0,3,0,0,0,0,0,3,0,0,0,0,3,0,0,0,0,0,0
0,0,0,0,0,0,0,2,2,2,2,0,0,0,0,0,0,0,2,2,2,2,0,0,0,0,0,0,0
0,0,0,0,0,0,0,0,0,0,0,0,0,0,0,0,0,0,0,0,0,0,0,0,0,0,0,0,0
0,0,0,0,0,0,0,0,0,0,0,0,0,0,0,0,0,0,0,0,0,0,0,0,0,0,0,0,0
0,0,0,0,0,0,0,0,0,0,18,0,0,0,0,0,0,0,0,0,0,0,0,0,0,0,0,0,0
0,0,0,0,0,0,0,0,0,0,0,0,0,0,0,0,0,0,0,0,0,0,0,0,0,0,0,0,0
endlayer

layer
0,0,0,0,0,0,0,0,0,0,0,0,0,0,0,0,0,0,0,0,0,0,0,0,0,0,0,0,0
0,0,0,0,0,0,0,0,0,0,0,0,0,0,0,0,0,0,18,0,0,0,0,0,0,0,0,0,0
0,0,0,0,0,0,0,0,0,0,0,0,0,0,0,0,0,0,0,0,0,0,0,0,0,0,0,0,0
0,0,0,0,0,0,0,0,5,5,0,0,0,0,0,0,0,0,0,5,5,0,0,0,0,0,0,0,0
0,0,0,0,0,0,0,20,3,3,20,0,0,0,0,0,0,0,20,3,3,20,0,0,0,0,0,0,0
0,0,0,0,0,0,3,11,21,21,11,3,0,0,0,0,0,3,16,0,0,0,3,0,0,0,0,0,0
0,0,0,0,0,3,12,11,11,11,11,11,3,0,0,0,3,11,11,11,11,0,12,3,0,0,0,0,0
0,0,0,0,20,0,0,21,11,21,21,11,11,20,5,20,11,21,11,11,21,11,11,11,20,0,0,0,0
0,0,0,5,3,0,11,11,11,11,11,11,11,3,22,3,21,11,11,11,11,11,11,21,3,5,0,0,0
0,0,0,5,3,0,21,21,11,11,11,21,11,3,22,3,11,11,11,21,11,11,11,11,3,5,0,0,0
0,0,0,0,20,16,11,11,21,21,11,21,11,20,5,20,11,21,11,11,11,11,21,11,20,0,0,0,0
0,0,0,0,0,3,11,11,11,11,11,11,3,0,0,0,3,11,11,11,11,11,11,3,0,0,0,0,0
0,0,0,0,0,0,3,11,11,11,11,3,0,0,0,0,0,3,11,11,11,11,3,0,0,0,0,0,0
0,0,0,0,0,0,0,20,3,3,20,0,0,0,0,0,0,0,20,3,3,20,0,0,0,0,0,0,0
0,0,0,0,0,0,0,5,22,22,5,0,0,0,0,0,0,0,5,22,22,5,0,0,0,0,0,0,0
0,0,0,0,0,0,0,20,3,3,20,0,0,0,0,0,0,0,20,3,3,20,0,0,0,0,0,0,0
0,0,0,0,0,0,3,0,11,11,0,3,0,0,0,0,0,3,11,21,11,11,3,0,0,0,0,0,0
0,0,0,0,0,3,0,0,0,11,11,11,3,0,0,0,3,11,11,11,11,11,21,3,0,0,0,0,0
0,0,0,0,20,21,0,0,0,0,0,11,11,20,5,20,11,11,21,11,11,11,11,16,20,0,0,0,0
0,0,0,5,3,11,0,0,0,0,0,11,11,3,22,3,11,11,11,21,11,11,21,0,3,5,0,0,0
0,0,0,5,3,11,11,0,0,0,0,0,0,3,22,3,11,11,21,11,11,11,11,0,3,5,0,0,0
0,0,0,0,20,0,0,0,0,0,0,0,0,20,5,20,11,11,11,11,11,11,0,0,20,0,0,0,0
0,0,0,0,0,3,0,0,0,0,0,0,3,0,0,0,3,11,11,11,11,11,12,3,0,0,0,0,0
0,0,0,0,0,0,3,0,0,0,0,3,0,0,0,0,0,3,11,11,11,11,3,0,0,0,0,0,0
0,0,0,0,0,0,0,20,3,3,20,0,0,0,0,0,0,0,20,3,3,20,0,0,0,0,0,0,0
0,0,0,0,0,0,0,0,5,5,0,0,0,0,0,0,0,0,0,5,5,0,0,0,0,0,0,0,0
0,0,0,0,0,0,0,0,0,0,0,0,0,0,0,0,0,0,0,0,0,0,0,0,0,0,0,0,0
0,0,0,0,0,0,0,0,0,0,18,0,0,0,0,0,0,0,0,0,0,0,0,0,0,0,0,0,0
0,0,0,0,0,0,0,0,0,0,0,0,0,0,0,0,0,0,0,0,0,0,0,0,0,0,0,0,0
endlayer

# 4th Floor
layer
0,0,0,0,0,0,0,0,0,0,0,0,0,0,0,0,0,0,0,0,0,0,0,0,0,0,0,0,0
0,0,0,0,0,0,0,0,0,0,0,0,0,0,0,0,0,0,18,0,0,0,0,0,0,0,0,0,0
0,0,0,0,0,0,0,0,0,0,0,0,0,0,0,0,0,0,0,0,0,0,0,0,0,0,0,0,0
0,0,0,0,0,0,0,0,0,0,0,0,0,0,0,0,0,0,0,0,0,0,0,0,0,0,0,0,0
0,0,0,0,0,0,0,2,2,2,2,0,0,0,0,0,0,0,2,2,2,2,0,0,0,0,0,0,0
0,0,0,0,0,0,3,11,16,0,0,3,0,0,0,0,0,3,0,0,0,0,3,0,0,0,0,0,0
0,0,0,0,0,3,0,12,0,0,0,0,3,0,0,0,3,0,0,0,0,0,0,3,0,0,0,0,0
0,0,0,0,2,0,0,0,0,0,0,0,0,2,13,2,0,0,0,0,0,0,12,11,2,0,0,0,0
0,0,0,0,2,0,0,0,18,18,0,0,0,10,10,10,0,0,0,0,0,0,0,16,2,0,0,0,0
18,18,18,0,2,0,0,18,18,18,0,0,0,10,10,10,0,0,0,0,0,0,0,0,2,14,0,0,0
18,19,18,0,2,0,0,0,0,0,0,0,0,2,13,2,0,0,0,0,0,0,0,0,2,0,0,0,0
18,18,18,0,0,3,0,0,0,0,0,25,3,0,0,0,3,0,0,0,0,0,26,3,0,0,0,0,0
0,0,0,0,0,0,3,0,0,0,0,3,0,0,0,0,0,3,14,0,0,14,3,0,0,0,0,0,0
0,0,0,0,0,0,0,2,10,10,2,0,0,0,0,0,0,0,2,10,10,2,0,0,0,0,0,0,0
0,0,0,0,0,0,0,13,10,10,13,0,0,0,0,0,0,0,13,10,10,13,0,0,0,0,0,0,0
0,0,0,0,0,0,0,2,10,10,2,0,0,0,0,0,0,0,2,10,10,2,0,0,0,0,0,0,0
0,0,0,0,0,0,3,0,0,0,0,3,0,0,0,0,0,3,0,0,0,0,3,0,0,0,0,0,0
0,0,0,0,0,3,0,0,0,0,0,0,3,0,0,0,3,14,0,0,0,0,0,3,0,0,0,0,0
0,0,0,0,2,0,0,0,0,0,0,0,0,2,13,2,0,0,0,33,0,0,0,0,2,0,0,0,0
0,0,0,0,2,25,0,0,0,0,0,0,0,10,10,10,0,0,34,5,27,0,0,0,2,0,0,0,0
0,0,0,0,2,16,0,0,0,0,0,0,0,10,10,10,0,0,0,5,0,0,0,0,2,0,0,0,0
0,0,0,0,2,11,12,0,0,0,0,0,0,2,13,2,0,0,34,5,27,0,0,0,2,0,0,0,0
0,0,0,0,0,3,0,0,0,0,0,0,3,0,0,0,3,0,0,35,0,12,0,3,0,0,0,0,0
0,0,0,0,0,0,3,0,0,0,0,3,0,0,0,0,0,3,0,0,16,11,3,0,0,0,0,0,0
0,0,0,0,0,0,0,2,2,2,2,0,0,0,0,0,0,0,2,2,2,2,0,0,0,0,0,0,0
0,0,0,0,0,0,0,0,0,0,0,0,0,0,0,0,0,0,0,0,0,0,0,0,0,0,0,0,0
0,0,0,0,0,0,0,0,0,0,0,0,0,0,0,0,0,0,0,0,0,0,0,0,0,0,0,0,0
0,0,0,0,0,0,0,0,0,0,18,0,0,0,0,0,0,0,0,0,0,0,0,0,0,0,0,0,0
0,0,0,0,0,0,0,0,0,0,0,0,0,0,0,0,0,0,0,0,0,0,0,0,0,0,0,0,0
endlayer

layer
0,0,0,0,0,0,0,0,0,0,0,0,0,0,0,0,0,0,0,0,0,0,0,0,0,0,0,0,0
0,0,0,0,0,0,0,0,0,0,0,0,0,0,0,0,0,0,18,0,0,0,0,0,0,0,0,0,0
0,0,0,0,0,0,0,0,0,0,0,0,0,0,0,0,0,0,0,0,0,0,0,0,0,0,0,0,0
0,0,0,0,0,0,0,0,0,0,0,0,0,0,0,0,0,0,0,0,0,0,0,0,0,0,0,0,0
0,0,0,0,0,0,0,2,31,31,2,0,0,0,0,0,0,0,2,31,31,2,0,0,0,0,0,0,0
0,0,0,0,0,0,3,0,0,0,0,3,0,0,0,0,0,3,0,0,0,0,3,0,0,0,0,0,0
0,0,0,0,0,3,11,16,0,0,0,0,3,0,0,0,3,0,0,0,0,12,11,3,0,0,0,0,0
0,0,0,0,2,0,12,0,18,0,0,0,0,2,5,2,0,0,0,0,0,0,16,0,2,0,0,0,0
0,0,0,0,31,0,0,0,18,18,0,0,0,0,0,0,0,0,0,0,0,0,0,0,31,0,0,0,0
18,18,18,0,31,0,0,14,18,18,0,0,0,0,0,0,0,0,0,0,0,0,0,0,31,0,0,0,0
18,23,18,0,2,0,0,0,0,0,0,0,0,2,5,2,0,0,0,0,0,0,0,0,2,0,0,0,0
18,18,18,0,0,3,0,0,0,0,0,0,3,0,0,0,3,0,0,0,0,0,0,3,0,0,0,0,0
0,0,0,0,0,0,3,0,0,0,0,3,0,0,0,0,0,3,0,0,0,0,3,0,0,0,0,0,0
0,0,0,0,0,0,0,2,0,0,2,0,0,0,0,0,0,0,2,0,0,2,0,0,0,0,0,0,0
0,0,0,0,0,0,0,5,0,0,5,0,0,0,0,0,0,0,5,0,0,5,0,0,0,0,0,0,0
0,0,0,0,0,0,0,2,0,0,2,0,0,0,0,0,0,0,2,0,0,2,0,0,0,0,0,0,0
0,0,0,0,0,0,3,0,0,0,0,3,0,0,0,0,0,3,0,0,0,0,3,0,0,0,0,0,0
0,0,0,0,0,3,0,0,0,0,0,0,3,0,0,0,3,0,0,0,0,0,0,3,0,0,0,0,0
0,0,0,0,2,0,0,0,0,0,0,0,0,2,5,2,0,0,0,0,0,0,0,0,2,0,0,0,0
0,0,0,0,31,0,0,0,0,0,0,0,0,0,0,0,0,0,0,32,0,0,0,0,31,0,0,0,0
0,0,0,0,31,0,0,0,0,0,0,0,0,0,0,0,0,0,0,32,0,0,0,0,31,0,0,0,0
0,0,0,0,2,0,16,0,0,0,0,0,0,2,5,2,0,0,0,32,0,0,12,0,2,0,0,0,0
0,0,0,0,0,3,11,12,0,0,0,0,3,0,0,0,3,0,0,0,0,16,11,3,0,0,0,0,0
0,0,0,0,0,0,3,0,0,0,0,3,0,0,0,0,0,3,0,0,0,0,3,0,0,0,0,0,0
0,0,0,0,0,0,0,2,31,31,2,0,0,0,0,0,0,0,2,31,31,2,0,0,0,0,0,0,0
0,0,0,0,0,0,0,0,0,0,0,0,0,0,0,0,0,0,0,0,0,0,0,0,0,0,0,0,0
0,0,0,0,0,0,0,0,0,0,0,0,0,0,0,0,0,0,0,0,0,0,0,0,0,0,0,0,0
0,0,0,0,0,0,0,0,0,0,18,0,0,0,0,0,0,0,0,0,0,0,0,0,0,0,0,0,0
0,0,0,0,0,0,0,0,0,0,0,0,0,0,0,0,0,0,0,0,0,0,0,0,0,0,0,0,0
endlayer

layer
0,0,0,0,0,0,0,0,0,18,18,18,0,0,0,0,0,0,0,0,0,0,0,0,0,0,0,0,0
0,0,0,0,0,0,0,0,0,18,19,18,0,0,0,0,0,0,18,0,0,0,0,0,0,0,0,0,0
0,0,0,0,0,0,0,0,0,18,18,18,0,0,0,0,0,0,0,0,0,0,0,0,0,0,0,0,0
0,0,0,0,0,0,0,0,0,0,0,0,0,0,0,0,0,0,0,0,0,0,0,0,0,0,0,0,0
0,0,0,0,0,0,0,2,31,31,2,0,0,0,0,0,0,0,2,31,31,2,0,0,0,0,0,0,0
0,0,0,0,0,0,3,0,0,0,0,3,0,0,0,0,0,3,0,0,12,11,3,0,0,0,0,0,0
0,0,0,0,0,3,0,0,0,0,0,0,3,0,0,0,3,0,0,0,0,16,0,3,0,0,0,0,0
0,0,0,0,2,11,16,0,14,0,0,0,0,2,17,2,0,0,0,0,0,0,0,0,2,0,0,0,0
0,0,0,0,31,12,0,0,18,18,18,0,0,0,0,0,0,0,0,0,0,0,0,0,31,0,0,0,0
18,18,18,0,31,0,0,0,18,18,0,0,0,0,0,0,0,0,0,0,0,0,0,0,31,0,0,0,0
18,0,18,0,2,0,0,0,0,0,0,0,0,2,0,2,0,0,0,0,0,0,0,0,2,0,0,0,0
18,18,18,0,0,3,0,0,0,0,0,0,3,0,0,0,3,0,0,0,0,0,0,3,0,0,0,0,0
0,0,0,0,0,0,3,0,0,0,0,3,0,0,0,0,0,3,0,0,0,0,3,0,0,0,0,0,0
0,0,0,0,0,0,0,2,0,0,2,0,0,0,0,0,0,0,2,0,0,2,0,0,0,0,0,0,0
0,0,0,0,0,0,0,17,0,0,0,0,0,0,0,0,0,0,0,0,0,17,0,0,0,0,0,0,0
0,0,0,0,0,0,0,2,0,0,2,0,0,0,0,0,0,0,2,0,0,2,0,0,0,0,0,0,0
0,0,0,0,0,0,3,0,0,0,0,3,0,0,0,0,0,3,0,0,0,0,3,0,0,0,0,0,0
0,0,0,0,0,3,0,0,0,0,0,0,3,0,0,0,3,0,0,0,0,0,0,3,0,0,18,18,18
0,0,0,0,2,0,0,0,0,0,0,0,0,2,0,2,0,0,0,0,0,0,0,0,2,0,18,19,18
0,0,0,0,31,0,0,0,0,0,0,0,0,0,0,0,0,0,0,0,0,0,0,0,31,0,18,18,18
0,0,0,0,31,0,0,0,0,0,0,0,0,0,0,0,0,0,0,0,0,0,0,12,31,0,0,0,0
0,0,0,0,2,0,0,0,0,0,0,0,0,2,17,2,0,0,0,0,0,0,16,11,2,0,0,0,0
0,0,0,0,0,3,0,16,0,0,0,0,3,0,0,0,3,0,0,0,0,0,0,3,0,0,0,0,0
0,0,0,0,0,0,3,11,12,0,0,3,0,0,0,0,0,3,0,0,0,0,3,0,0,0,0,0,0
0,0,0,0,0,0,0,2,31,31,2,0,0,0,0,0,0,0,2,31,31,2,0,0,0,0,0,0,0
0,0,0,0,0,0,0,0,0,0,0,0,0,0,0,0,0,0,0,0,0,0,0,0,0,0,0,0,0
0,0,0,0,0,0,0,0,0,0,0,0,0,0,0,0,0,0,0,0,0,0,0,0,0,0,0,0,0
0,0,0,0,0,0,0,0,0,0,18,0,0,0,0,0,0,0,0,0,0,0,0,0,0,0,0,0,0
0,0,0,0,0,0,0,0,0,0,0,0,0,0,0,0,0,0,0,0,0,0,0,0,0,0,0,0,0
endlayer

layer
0,0,0,0,0,0,0,0,0,18,18,18,0,0,0,0,0,0,0,0,0,0,0,0,0,0,0,0,0
0,0,0,0,0,0,0,0,0,18,36,18,0,0,0,0,0,0,18,0,0,0,0,0,0,0,0,0,0
0,0,0,0,0,0,0,0,0,18,18,18,0,0,0,0,0,0,0,0,0,0,0,0,0,0,0,0,0
0,0,0,0,0,0,0,0,0,0,0,0,0,0,0,0,0,0,0,0,0,0,0,0,0,0,0,0,0
0,0,0,0,0,0,0,2,2,2,2,0,0,0,0,0,0,0,2,2,2,2,0,0,0,0,0,0,0
0,0,0,0,0,0,3,0,0,0,0,3,0,0,0,0,0,3,12,11,16,0,3,0,0,0,0,0,0
0,0,0,0,0,3,0,0,0,0,0,0,3,0,0,0,3,0,0,0,0,0,0,3,0,0,0,0,0
0,0,0,0,2,0,0,0,0,0,0,0,0,2,0,2,0,0,0,0,0,0,0,0,2,0,0,0,0
0,0,0,0,2,16,0,0,18,18,14,0,0,2,0,2,0,0,0,0,0,0,0,0,2,0,0,0,0
18,18,18,0,2,11,0,0,18,18,0,0,0,2,0,2,0,0,0,0,0,0,0,0,2,0,0,0,0
18,13,18,0,2,12,0,0,0,18,0,0,0,2,0,2,0,0,0,0,0,0,0,0,2,0,0,0,0
18,18,18,0,0,3,0,0,0,0,0,0,3,0,0,0,3,0,0,0,0,0,0,3,0,0,0,0,0
0,0,0,0,0,0,3,0,0,0,0,3,0,0,0,0,0,3,0,0,0,0,3,0,0,0,0,0,0
0,0,0,0,0,0,0,2,2,2,2,0,0,0,0,0,0,0,2,2,2,2,0,0,0,0,0,0,0
0,0,0,0,0,0,0,0,0,0,0,0,0,0,0,0,0,0,0,0,0,0,0,0,0,0,0,0,0
0,0,0,0,0,0,0,2,2,2,2,0,0,0,0,0,0,0,2,2,2,2,0,0,0,0,0,0,0
0,0,0,0,0,0,3,0,0,0,0,3,0,0,0,0,0,3,0,0,0,0,3,0,0,0,0,0,0
0,0,0,0,0,3,0,0,0,0,0,0,3,0,0,0,3,0,0,0,0,0,0,3,0,0,18,18,18
0,0,0,0,2,0,0,0,0,0,0,0,0,2,0,2,0,0,0,0,0,0,0,12,2,0,18,36,18
0,0,0,0,2,0,0,0,0,0,0,0,0,2,0,2,0,0,0,0,0,0,0,11,2,0,18,18,18
0,0,0,0,2,0,0,0,0,0,0,0,0,2,0,2,0,0,0,0,0,0,0,16,2,0,0,0,0
0,0,0,0,2,0,0,0,0,0,0,0,0,2,0,2,0,0,0,0,0,0,0,0,2,0,0,0,0
0,0,0,0,0,3,0,0,0,0,0,0,3,0,0,0,3,0,0,0,0,0,0,3,0,0,0,0,0
0,0,0,0,0,0,3,0,16,11,12,3,0,0,0,0,0,3,0,0,0,0,3,0,0,0,0,0,0
0,0,0,0,0,0,0,2,2,2,2,0,0,0,0,0,0,0,2,2,2,2,0,0,0,0,0,0,0
0,0,0,0,0,0,0,0,0,0,0,0,0,0,0,0,0,0,0,0,0,0,0,0,0,0,0,0,0
0,0,0,0,0,0,0,0,0,0,0,0,0,0,0,0,0,0,0,0,0,0,0,0,0,0,0,0,0
0,0,0,0,0,0,0,0,0,0,18,0,0,0,0,0,0,0,0,0,0,0,0,0,0,0,0,0,0
0,0,0,0,0,0,0,0,0,0,0,0,0,0,0,0,0,0,0,0,0,0,0,0,0,0,0,0,0
endlayer

layer
0,0,0,0,0,0,0,0,0,18,18,18,0,0,0,0,0,0,0,0,0,0,0,0,0,0,0,0,0
0,0,0,0,0,0,0,0,0,18,0,18,0,0,0,0,0,0,18,0,0,0,0,0,0,0,0,0,0
0,0,0,0,0,0,0,0,0,18,18,18,0,0,0,0,0,0,0,0,0,0,0,0,0,0,0,0,0
0,0,0,0,0,0,0,0,5,5,0,0,0,0,0,0,0,0,0,5,5,0,0,0,0,0,0,0,0
0,0,0,0,0,0,0,20,3,3,20,0,0,0,0,0,0,0,20,3,3,20,0,0,0,0,0,0,0
0,0,0,0,0,0,3,11,21,21,11,3,0,0,0,0,0,3,16,0,0,0,3,0,0,0,0,0,0
0,0,0,0,0,3,12,11,11,11,11,11,3,0,0,0,3,11,11,11,11,0,12,3,0,0,0,0,0
0,0,0,0,20,0,0,21,11,21,21,11,11,20,5,20,11,11,11,11,21,11,11,11,20,0,0,0,0
0,0,0,5,3,0,11,11,11,11,11,21,11,3,22,3,21,11,11,11,11,11,11,21,3,5,0,0,0
0,0,0,5,3,0,21,21,11,11,11,21,11,3,22,3,11,11,11,11,11,11,11,11,3,5,0,0,0
0,18,0,0,20,16,11,11,11,21,11,11,11,20,5,20,11,11,11,11,11,11,11,11,20,0,0,0,0
0,0,0,0,0,3,11,11,11,11,11,11,3,0,0,0,3,11,11,11,11,11,11,3,0,0,0,0,0
0,0,0,0,0,0,3,11,11,11,11,3,0,0,0,0,0,3,11,11,11,11,3,0,0,0,0,0,0
0,0,0,0,0,0,0,20,3,3,20,0,0,0,0,0,0,0,20,3,3,20,0,0,0,0,0,0,0
0,0,0,0,0,0,0,5,22,22,5,0,0,0,0,0,0,0,5,22,22,5,0,0,0,0,0,0,0
0,0,0,0,0,0,0,20,3,3,20,0,0,0,0,0,0,0,20,3,3,20,0,0,0,0,0,0,0
0,0,0,0,0,0,3,11,11,0,0,3,0,0,0,0,0,3,11,21,11,11,3,0,0,0,0,0,0
0,0,0,0,0,3,11,0,0,0,0,0,3,0,0,0,3,11,11,11,11,11,11,3,0,0,18,18,18
0,0,0,0,20,11,0,0,0,0,0,0,11,20,5,20,11,11,21,11,11,11,11,16,20,0,18,0,18
0,0,0,5,3,11,11,0,0,0,0,11,11,3,22,3,11,11,11,11,11,11,21,0,3,5,18,18,18
0,0,0,5,3,11,0,0,0,0,0,11,11,3,22,3,11,11,21,11,11,11,11,0,3,5,0,0,0
0,0,0,0,20,0,0,0,0,0,11,11,0,20,5,20,11,11,11,11,21,11,0,0,20,0,0,0,0
0,0,0,0,0,3,0,0,0,11,11,0,3,0,0,0,3,11,11,11,11,11,12,3,0,0,0,0,0
0,0,0,0,0,0,3,0,0,0,16,3,0,0,0,0,0,3,11,11,11,11,3,0,0,0,0,0,0
0,0,0,0,0,0,0,20,3,3,20,0,0,0,0,0,0,0,20,3,3,20,0,0,0,0,0,0,0
0,0,0,0,0,0,0,0,5,5,0,0,0,0,0,0,0,0,0,5,5,0,0,0,0,0,0,0,0
0,0,0,0,0,0,0,0,0,0,0,0,0,0,0,0,0,0,0,0,0,0,0,0,0,0,0,0,0
0,0,0,0,0,0,0,0,0,0,18,0,0,0,0,0,0,0,0,0,0,0,0,0,0,0,0,0,0
0,0,0,0,0,0,0,0,0,0,0,0,0,0,0,0,0,0,0,0,0,0,0,0,0,0,0,0,0
endlayer

# 5th Floor
layer
0,0,0,0,0,0,0,0,0,18,18,18,0,0,0,0,0,0,0,0,0,0,0,0,0,0,0,0,0
0,0,0,0,0,0,0,0,0,18,13,18,0,0,0,0,0,0,18,0,0,0,0,0,0,0,0,0,0
0,0,0,0,0,0,0,0,0,18,18,18,0,0,0,0,0,0,0,0,0,0,0,0,0,0,0,0,0
0,0,0,0,0,0,0,0,0,0,0,0,0,0,0,0,0,0,0,0,0,0,0,0,0,0,0,0,0
0,0,0,0,0,0,0,2,2,2,2,0,0,0,0,0,0,0,2,2,2,2,0,0,0,0,0,0,0
0,0,0,0,0,0,3,11,16,0,37,3,0,0,0,0,0,3,0,0,0,0,3,0,0,0,0,0,0
0,0,0,0,0,3,26,12,0,0,37,37,3,0,0,0,3,37,0,0,0,0,26,3,0,0,0,0,0
0,0,0,0,2,0,0,0,0,0,0,37,37,2,13,2,37,37,0,0,0,0,12,11,2,0,0,0,0
0,0,0,0,2,0,0,0,37,37,0,0,0,10,10,10,0,0,0,37,37,0,0,16,2,0,0,0,0
0,0,0,0,2,0,0,0,37,37,0,0,0,10,10,10,0,0,0,37,37,0,0,0,2,0,0,0,0
0,18,0,0,2,0,0,0,0,0,0,37,37,2,13,2,37,37,0,0,0,0,37,37,2,0,0,0,0
0,0,0,0,0,3,37,37,0,0,37,37,3,0,0,0,3,37,37,0,0,37,37,3,0,0,0,0,0
0,0,0,0,0,0,3,37,0,0,37,3,0,0,0,0,0,3,37,0,0,37,3,0,0,0,0,0,0
0,0,0,0,0,0,0,2,10,10,2,0,0,0,0,0,0,0,2,10,10,2,0,0,0,0,0,0,0
0,0,0,0,0,0,0,13,10,10,13,0,0,0,0,0,0,0,13,10,10,13,0,0,0,0,0,0,0
0,0,0,0,0,0,0,2,10,10,2,0,0,0,0,0,0,0,2,10,10,2,0,0,0,0,0,0,0
0,0,0,0,0,0,3,37,0,0,0,3,0,0,0,0,0,3,37,0,0,37,3,0,0,0,0,0,0
0,0,0,0,0,3,37,0,0,0,0,0,3,0,0,0,3,37,37,0,0,37,37,3,0,0,18,18,18
0,0,0,0,2,37,0,0,0,0,0,0,37,2,13,2,37,37,0,0,0,0,0,0,2,0,18,13,18
0,0,0,0,2,0,0,0,0,0,0,0,0,10,10,10,0,0,0,37,37,0,0,0,2,0,18,18,18
0,0,0,14,2,0,0,0,0,0,0,0,0,10,10,10,0,0,0,37,37,0,0,0,2,0,0,0,0
0,0,0,0,2,0,0,0,0,0,0,0,0,2,13,2,37,37,0,0,0,0,0,0,2,0,0,0,0
0,0,0,0,0,3,0,0,0,0,0,0,3,0,0,0,3,37,37,0,0,12,26,3,0,0,0,0,0
0,0,0,0,0,0,3,0,0,0,0,3,0,0,0,0,0,3,37,0,16,11,3,0,0,0,0,0,0
0,0,0,0,0,0,0,2,2,2,2,0,0,0,0,0,0,0,2,2,2,2,0,0,0,0,0,0,0
0,0,0,0,0,0,0,0,0,0,0,0,0,0,0,0,0,0,0,14,0,0,0,0,0,0,0,0,0
0,0,0,0,0,0,0,0,0,0,0,0,0,0,0,0,0,0,0,0,0,0,0,0,0,0,0,0,0
0,0,0,0,0,0,0,0,0,0,18,0,0,0,0,0,0,0,0,0,0,0,0,0,0,0,0,0,0
0,0,0,0,0,0,0,0,0,0,0,0,0,0,0,0,0,0,0,0,0,0,0,0,0,0,0,0,0
endlayer

layer
0,0,0,0,0,0,0,0,0,0,0,0,0,0,0,0,0,0,0,0,0,0,0,0,0,0,0,0,0
0,0,0,0,0,0,0,0,0,0,18,0,0,0,0,0,0,0,18,0,0,0,0,0,0,0,0,0,0
0,0,0,0,0,0,0,0,0,0,0,0,0,0,0,0,0,0,0,0,0,0,0,0,0,0,0,0,0
0,0,0,0,0,0,0,0,0,0,0,0,0,0,0,0,0,0,0,0,0,0,0,0,0,0,0,0,0
0,0,0,0,0,0,0,2,31,31,2,0,0,0,0,0,0,0,2,31,31,2,0,0,0,0,0,0,0
0,0,0,0,0,0,3,0,0,0,38,3,0,0,0,0,0,3,0,0,0,0,3,0,0,0,0,0,0
0,0,0,0,0,3,11,16,0,0,38,38,3,0,0,0,3,38,0,0,0,12,11,3,0,0,0,0,0
0,0,0,0,2,0,12,0,0,0,0,38,38,2,5,2,38,38,0,0,0,0,16,0,2,0,0,0,0
0,0,0,0,31,0,0,0,38,38,0,0,0,0,0,0,0,0,0,38,38,0,0,0,31,0,0,0,0
0,0,0,0,31,0,0,0,38,38,0,0,0,0,0,0,0,0,0,38,38,0,0,0,31,0,0,0,0
0,18,0,0,2,0,0,0,0,0,0,38,38,2,5,2,38,38,0,0,0,0,38,38,2,0,0,0,0
0,0,0,0,0,3,38,38,0,0,38,38,3,0,0,0,3,38,38,0,0,38,38,3,0,0,0,0,0
0,0,0,0,0,0,3,38,0,0,38,3,0,0,0,0,0,3,38,0,0,38,3,0,0,0,0,0,0
0,0,0,0,0,0,0,2,0,0,2,0,0,0,0,0,0,0,2,0,0,2,0,0,0,0,0,0,0
0,0,0,0,0,0,0,5,0,0,5,0,0,0,0,0,0,0,5,0,0,5,0,0,0,0,0,0,0
0,0,0,0,0,0,0,2,0,0,2,0,0,0,0,0,0,0,2,0,0,2,0,0,0,0,0,0,0
0,0,0,0,0,0,3,38,0,0,0,3,0,0,0,0,0,3,38,0,0,38,3,0,0,0,0,0,0
0,0,0,0,0,3,38,0,0,0,0,0,3,0,0,0,3,38,38,0,0,38,38,3,0,0,0,0,14
0,0,0,0,2,38,0,0,0,0,0,0,38,2,5,2,38,38,0,0,0,0,0,0,2,0,0,18,0
0,0,0,0,31,0,0,0,0,0,0,0,0,0,0,0,0,0,0,38,38,0,0,0,31,0,0,0,0
0,0,0,0,31,0,0,0,0,0,0,0,0,0,0,0,0,0,0,38,38,0,0,0,31,0,0,0,0
0,0,0,0,2,0,0,0,0,0,0,0,0,2,5,2,38,38,0,0,0,0,12,0,2,0,0,0,0
0,0,0,0,0,3,0,0,0,0,0,0,3,0,0,0,3,38,38,0,0,16,11,3,0,0,0,0,0
0,0,0,0,0,0,3,0,0,0,0,3,0,0,0,0,0,3,38,0,0,0,3,0,0,0,0,0,0
0,0,0,0,0,0,0,2,31,31,2,0,0,0,0,0,0,0,2,31,31,2,0,0,0,0,0,0,0
0,0,0,0,0,0,0,0,0,0,0,0,0,0,0,0,0,0,0,0,0,0,0,0,0,0,0,0,0
0,0,0,0,0,0,0,0,0,0,0,0,0,0,0,0,0,0,0,0,0,0,0,0,0,0,0,0,0
0,0,0,0,0,0,0,0,0,0,18,0,0,0,0,0,0,0,0,0,0,0,0,0,0,0,0,0,0
0,0,0,0,0,0,0,0,0,0,0,0,0,0,0,0,0,0,0,0,0,0,0,0,0,0,0,0,0
endlayer

layer
0,0,0,0,0,0,0,0,0,0,0,0,0,0,0,0,0,0,0,0,0,0,0,0,0,0,0,0,0
0,0,0,0,0,0,0,0,0,0,18,0,0,0,0,0,0,0,18,0,0,0,0,0,0,0,0,0,0
0,0,0,0,0,0,0,0,0,0,0,0,0,0,0,0,0,0,0,0,0,0,0,0,0,0,0,0,0
0,0,0,0,0,0,0,0,0,0,0,0,0,0,0,0,0,0,0,0,0,0,0,0,0,0,0,0,0
0,0,0,0,0,0,0,2,31,31,2,0,0,0,0,0,0,0,2,31,31,2,0,0,0,0,0,0,0
0,0,0,0,0,0,3,0,0,0,0,3,0,0,0,0,0,3,0,0,12,11,3,0,0,0,0,0,0
0,0,0,0,0,3,0,0,0,0,0,0,3,0,0,0,3,0,0,0,0,16,0,3,0,0,0,0,0
0,0,0,0,2,11,16,0,0,0,0,0,0,2,17,2,0,0,0,0,0,0,0,0,2,0,0,0,0
0,0,0,0,31,12,0,0,0,0,0,0,0,0,0,0,0,0,0,0,0,0,0,0,31,0,0,0,0
0,0,0,0,31,0,0,0,0,0,0,0,0,0,0,0,0,0,0,0,0,0,0,0,31,0,0,0,0
0,18,0,0,2,0,0,0,0,0,0,0,0,2,0,2,0,0,0,0,0,0,0,0,2,0,0,0,0
0,0,0,0,0,3,0,0,0,0,0,0,3,0,0,0,3,0,0,0,0,0,0,3,0,0,0,0,0
0,0,0,0,0,0,3,0,0,0,0,3,0,0,0,0,0,3,0,0,0,0,3,0,0,0,0,0,0
0,0,0,0,0,0,0,2,0,0,2,0,0,0,0,0,0,0,2,0,0,2,0,0,0,0,0,0,0
0,0,0,0,0,0,0,17,0,0,0,0,0,13,0,0,0,0,0,0,0,17,0,0,0,0,0,0,0
0,0,0,0,0,0,0,2,0,0,2,0,13,4,13,0,0,0,2,0,0,2,0,0,0,0,0,0,0
0,0,0,0,0,0,3,0,0,0,0,3,0,13,0,0,0,3,0,0,0,0,3,0,0,0,0,0,0
0,0,0,0,0,3,0,0,0,0,0,0,3,0,0,0,3,0,0,0,0,0,0,3,0,0,0,0,0
0,0,0,0,2,0,0,0,0,0,0,0,0,2,0,2,0,0,0,0,0,0,0,0,2,0,0,18,0
0,0,0,0,31,0,0,0,0,0,0,0,0,0,0,0,0,0,0,0,0,0,0,0,31,0,0,0,0
0,0,0,0,31,0,0,0,0,0,0,0,0,0,0,0,0,0,0,0,0,0,0,12,31,0,0,0,0
0,0,0,0,2,0,0,0,0,0,0,0,0,2,17,2,0,0,0,0,0,0,16,11,2,0,0,0,0
0,0,0,0,0,3,0,0,0,0,0,0,3,0,0,0,3,0,0,0,0,0,0,3,0,0,0,0,0
0,0,0,0,0,0,3,0,0,0,0,3,0,0,0,0,0,3,0,0,0,0,3,0,0,0,0,0,0
0,0,0,0,0,0,0,2,31,31,2,0,0,0,0,0,0,0,2,31,31,2,0,0,0,0,0,0,0
0,0,0,0,0,0,0,0,0,0,0,0,0,0,0,0,0,0,0,0,0,0,0,0,0,0,0,0,0
0,0,0,0,0,0,0,0,0,0,0,0,0,0,0,0,0,18,18,18,0,0,0,0,0,0,0,0,0
0,0,0,0,0,0,0,0,0,0,18,0,0,0,0,0,0,18,19,18,0,0,0,0,0,0,0,0,0
0,0,0,0,0,0,0,0,0,0,0,0,0,0,0,0,0,18,18,18,0,0,0,0,0,0,0,0,0
endlayer

layer
0,0,0,0,0,0,0,0,0,0,0,0,0,0,0,0,0,0,0,0,0,0,0,0,0,0,0,0,0
0,0,0,0,0,0,0,0,0,0,18,0,0,0,0,0,0,0,18,0,0,0,0,0,0,0,0,0,0
0,0,0,0,0,0,0,0,0,0,0,0,0,0,0,0,0,0,0,0,0,0,0,0,0,0,0,0,0
0,0,0,0,0,0,0,0,0,0,0,0,0,0,0,0,0,0,0,0,0,0,0,0,0,0,0,0,0
0,0,0,0,0,0,0,2,2,2,2,0,0,0,0,0,0,0,2,2,2,2,0,0,0,0,0,0,0
0,0,0,0,0,0,3,0,0,0,0,3,0,0,0,0,0,3,12,11,16,0,3,0,0,0,0,0,0
0,0,0,0,0,3,0,0,0,0,0,0,3,0,0,0,3,0,0,0,0,0,0,3,0,0,0,0,0
0,0,0,0,2,0,0,0,0,0,0,0,0,2,0,2,0,0,0,0,0,0,0,0,2,0,0,0,0
0,0,0,0,2,16,0,0,0,0,0,0,0,2,0,2,0,0,0,0,0,0,0,0,2,0,0,0,0
0,0,0,0,2,11,0,0,0,0,0,0,0,2,0,2,0,0,0,0,0,0,0,0,2,0,0,0,0
0,18,0,0,2,12,0,0,0,0,0,0,0,2,0,2,0,0,0,0,0,0,0,0,2,0,0,0,0
0,0,0,0,0,3,0,0,0,0,0,0,3,0,0,0,3,0,0,0,0,0,0,3,0,0,0,0,0
0,0,0,0,0,0,3,0,0,0,0,3,0,0,0,0,0,3,0,0,0,0,3,0,0,0,0,0,0
0,0,0,0,0,0,0,2,2,2,2,0,0,0,0,0,0,0,2,2,2,2,0,0,0,0,0,0,0
0,0,0,0,0,0,0,0,0,0,0,0,0,10,0,0,0,0,0,0,0,0,0,0,0,0,0,0,0
0,0,0,0,0,0,0,2,2,2,2,0,10,13,10,0,0,0,2,2,2,2,0,0,0,0,0,0,0
0,0,0,0,0,0,3,0,0,0,0,3,0,10,0,0,0,3,0,0,0,0,3,0,0,0,0,0,0
0,0,0,0,0,3,0,0,0,0,0,0,3,0,0,0,3,0,0,0,0,0,0,3,0,0,0,0,0
0,0,0,0,2,0,0,0,0,0,0,0,0,2,0,2,0,0,0,0,0,0,0,12,2,0,0,18,0
0,0,0,0,2,0,0,0,0,0,0,0,0,2,0,2,0,0,0,0,0,0,0,11,2,0,0,0,0
0,0,0,0,2,0,0,0,0,0,0,0,0,2,0,2,0,0,0,0,0,0,0,16,2,0,0,0,0
0,0,0,0,2,0,0,0,0,0,0,0,0,2,0,2,0,0,0,0,0,0,0,0,2,0,0,0,0
0,0,0,0,0,3,0,0,0,0,0,0,3,0,0,0,3,0,0,0,0,0,0,3,0,0,0,0,0
0,0,0,0,0,0,3,0,0,0,12,3,0,0,0,0,0,3,0,0,0,0,3,0,0,0,0,0,0
0,0,0,0,0,0,0,2,2,2,2,0,0,0,0,0,0,0,2,2,2,2,0,0,0,0,0,0,0
0,0,0,0,0,0,0,0,0,0,0,0,0,0,0,0,0,0,0,0,0,0,0,0,0,0,0,0,0
0,0,0,0,0,0,0,0,0,0,0,0,0,0,0,0,0,18,18,18,0,0,0,0,0,0,0,0,0
0,0,0,0,0,0,0,0,0,0,18,0,0,0,0,0,0,18,23,18,0,0,0,0,0,0,0,0,0
0,0,0,0,0,0,0,0,0,0,0,0,0,0,0,0,0,18,18,18,0,0,0,0,0,0,0,0,0
endlayer

layer
0,0,0,0,0,0,0,0,0,0,0,0,0,0,0,0,0,0,0,0,0,0,0,0,0,0,0,0,0
0,0,0,0,0,0,0,0,0,0,18,0,0,0,0,0,0,0,18,0,0,0,0,0,0,0,0,0,0
0,0,0,0,0,0,0,0,0,0,0,0,0,0,0,0,0,0,0,0,0,0,0,0,0,0,0,0,0
0,0,0,0,0,0,0,0,5,5,0,0,0,0,0,0,0,0,0,5,5,0,0,0,0,0,0,0,0
0,0,0,0,0,0,0,20,3,3,20,0,0,0,0,0,0,0,20,3,3,20,0,0,0,0,0,0,0
0,0,0,0,0,0,3,11,21,21,11,3,0,0,0,0,0,3,16,0,0,0,3,0,0,0,0,0,0
0,0,0,0,0,3,12,11,11,11,11,11,3,0,0,0,3,11,11,11,11,0,12,3,0,0,0,0,0
0,0,0,0,20,0,0,21,11,21,21,11,11,20,5,20,11,21,11,11,21,11,11,11,20,0,0,0,0
0,0,0,5,3,0,11,11,11,11,11,11,11,3,22,3,21,11,11,21,21,11,11,21,3,5,0,0,0
0,0,0,5,3,0,21,21,11,21,11,21,11,3,22,3,11,11,11,21,21,11,11,11,3,5,0,0,0
0,18,0,0,20,16,11,11,11,21,11,21,11,20,5,20,11,21,11,11,11,11,21,11,20,0,0,0,0
0,0,0,0,0,3,11,11,11,11,11,11,3,0,0,0,3,11,11,11,11,11,11,3,0,0,0,0,0
0,0,0,0,0,0,3,11,11,11,11,3,0,0,0,0,0,3,11,11,11,11,3,0,0,0,0,0,0
0,0,0,0,0,0,0,20,3,3,20,0,0,0,0,0,0,0,20,3,3,20,0,0,0,0,0,0,0
0,0,0,0,0,0,0,5,22,22,5,0,0,0,0,0,0,0,5,22,22,5,0,0,0,0,0,0,0
0,0,0,0,0,0,0,20,3,3,20,0,0,18,0,0,0,0,20,3,3,20,0,0,0,0,0,0,0
0,0,0,0,0,0,3,11,11,11,0,3,0,0,0,0,0,3,11,21,11,11,3,0,0,0,0,0,0
0,0,0,0,0,3,0,0,0,0,21,11,3,0,0,0,3,11,11,11,11,11,11,3,0,0,0,0,0
0,0,0,0,20,11,0,0,0,21,11,11,11,20,5,20,11,11,21,11,11,11,11,16,20,0,0,18,0
0,0,0,5,3,11,0,0,0,11,0,21,11,3,22,3,11,11,11,21,21,11,21,0,3,5,0,0,0
0,0,0,5,3,0,0,0,0,11,0,21,11,3,22,3,11,11,21,11,21,11,11,0,3,5,0,0,0
0,0,0,0,20,11,11,11,11,11,11,11,11,20,5,20,11,11,11,11,21,11,0,0,20,0,0,0,0
0,0,0,0,0,3,0,0,0,0,11,11,3,0,0,0,3,11,11,11,11,11,12,3,0,0,0,0,0
0,0,0,0,0,0,3,0,0,0,16,3,0,0,0,0,0,3,11,11,11,11,3,0,0,0,0,0,0
0,0,0,0,0,0,0,20,3,3,20,0,0,0,0,0,0,0,20,3,3,20,0,0,0,0,0,0,0
0,0,0,0,0,0,0,0,5,5,0,0,0,0,0,0,0,0,0,5,5,0,0,0,0,0,0,0,0
0,0,0,0,0,0,0,0,0,0,0,0,0,0,0,0,0,18,18,18,0,0,0,0,0,0,0,0,0
0,0,0,0,0,0,0,0,0,0,18,0,0,0,0,0,0,18,0,18,0,0,0,0,0,0,0,0,0
0,0,0,0,0,0,0,0,0,0,0,0,0,0,0,0,0,18,18,18,0,0,0,0,0,0,0,0,0
endlayer

layer
0,0,0,0,0,0,0,0,0,0,0,0,0,0,0,0,0,0,0,0,0,0,0,0,0,0,0,0,0
0,0,0,0,0,0,0,0,0,0,18,0,0,0,0,0,0,0,18,0,0,0,0,0,0,0,0,0,0
0,0,0,0,0,0,0,0,0,0,0,0,0,0,0,0,0,0,0,0,0,0,0,0,0,0,0,0,0
0,0,0,0,0,0,0,0,14,0,0,0,0,0,0,0,0,0,0,0,14,0,0,0,0,0,0,0,0
0,0,0,0,0,0,0,2,2,2,2,0,0,0,0,0,0,0,2,2,2,2,0,0,0,0,0,0,0
0,0,0,0,0,0,3,11,16,40,39,3,0,0,0,0,0,3,0,0,0,0,3,0,0,0,0,0,0
0,0,0,0,0,3,26,12,0,0,0,39,3,0,0,0,3,39,0,0,0,0,26,3,0,0,0,0,0
0,0,0,0,2,0,0,0,0,0,0,0,39,2,13,2,39,0,0,0,0,0,12,11,2,0,0,0,0
0,0,0,0,2,0,0,0,0,0,0,0,0,10,10,10,0,0,0,0,0,0,0,16,2,0,0,0,0
0,0,0,0,2,0,0,0,0,0,24,0,0,10,10,10,0,0,0,0,0,0,0,40,2,0,0,0,0
0,18,0,0,2,0,0,0,0,0,0,0,39,2,13,2,39,0,0,0,0,0,0,39,2,0,0,0,0
0,0,0,0,0,3,39,0,0,0,0,39,3,0,0,0,3,39,0,0,0,0,39,3,0,0,0,0,0
0,0,0,0,0,0,3,39,0,0,39,3,0,0,0,0,0,3,39,0,0,39,3,0,0,0,0,0,0
0,0,0,0,0,0,0,2,10,10,2,0,0,0,0,0,0,0,2,10,10,2,0,0,0,0,0,0,0
0,0,0,0,0,0,0,13,10,10,13,0,0,0,0,0,0,0,13,10,10,13,0,0,0,0,0,0,0
0,0,0,0,0,0,0,2,10,10,2,0,0,18,0,0,0,0,2,10,10,2,0,0,0,0,0,0,0
0,0,0,0,0,0,3,39,0,0,0,3,0,0,0,0,0,3,39,0,0,39,3,0,0,0,0,0,0
0,0,0,0,0,3,39,0,0,0,0,39,3,0,0,0,3,39,0,0,0,0,39,3,0,0,0,0,0
0,0,0,0,2,39,0,0,0,0,0,0,39,2,13,2,39,0,0,0,0,0,0,0,2,0,0,18,0
0,0,0,0,2,40,0,0,0,0,0,0,0,10,10,10,0,0,0,0,0,0,0,0,2,0,0,0,0
0,0,0,0,2,0,0,0,0,0,0,0,0,10,10,10,0,0,0,0,0,0,0,0,2,0,0,0,0
0,0,0,0,2,0,0,0,0,0,0,0,39,2,13,2,39,0,0,0,0,0,0,0,2,0,0,0,0
0,0,0,0,0,3,0,0,0,0,0,39,3,0,0,0,3,39,0,0,0,12,26,3,0,0,0,0,0
0,0,0,0,0,0,3,0,0,0,0,3,0,0,0,0,0,3,39,40,16,11,3,0,0,0,0,0,0
0,0,0,0,0,0,0,2,2,2,2,0,0,0,0,0,0,0,2,2,2,2,0,0,0,0,0,0,0
0,0,0,0,0,0,0,0,0,0,0,0,0,0,0,0,0,0,0,0,0,0,0,0,0,0,0,0,0
0,0,0,0,0,0,0,0,0,0,0,0,0,0,0,0,0,18,18,18,0,0,0,0,0,0,0,0,0
0,0,0,0,0,0,0,0,0,0,18,0,0,0,0,0,0,18,13,18,0,0,0,0,0,0,0,0,0
0,0,0,0,0,0,0,0,0,0,0,0,0,0,0,0,0,18,18,18,0,0,0,0,0,0,0,0,0
endlayer

layer
0,0,0,0,0,0,0,0,0,0,0,0,0,0,0,0,0,0,0,0,0,0,0,0,0,0,0,0,0
0,0,0,0,0,0,0,0,0,0,18,0,0,0,0,0,0,0,18,0,0,0,0,0,0,0,0,0,0
0,0,0,0,0,0,0,0,0,0,0,0,0,0,0,0,0,0,0,0,0,0,0,0,0,0,0,0,0
0,0,0,0,0,0,0,0,0,0,0,0,0,0,0,0,0,0,0,0,0,0,0,0,0,0,0,0,0
0,0,0,0,0,0,0,2,31,31,2,0,0,0,0,0,0,0,2,31,31,2,0,0,0,0,0,0,0
0,0,0,0,0,0,3,0,0,0,41,3,0,0,0,0,0,3,0,0,0,0,3,0,0,0,0,0,0
0,0,0,0,0,3,11,16,0,0,0,41,3,0,0,0,3,41,0,0,0,12,11,3,0,0,0,0,0
0,0,0,0,2,0,12,0,0,0,0,0,41,2,5,2,41,0,0,0,0,0,16,0,2,0,0,0,0
0,0,0,0,31,0,0,0,0,0,0,0,0,0,0,0,0,0,0,0,0,0,0,0,31,0,0,0,0
0,0,0,0,31,0,0,0,0,0,0,0,0,0,0,0,0,0,0,0,0,0,0,0,31,0,0,0,0
0,18,0,0,2,0,0,0,0,0,0,0,41,2,5,2,41,0,0,0,0,0,0,41,2,0,0,0,0
0,0,0,0,0,3,41,0,0,0,0,41,3,0,0,0,3,41,0,0,0,0,41,3,0,0,0,0,0
0,0,0,0,0,0,3,41,0,0,41,3,0,0,0,0,0,3,41,0,0,41,3,0,0,0,0,0,0
0,0,0,0,0,0,0,2,0,0,2,0,0,0,0,0,0,0,2,0,0,2,0,0,0,0,0,0,0
0,0,0,0,0,0,0,5,0,0,5,0,0,0,0,0,0,0,5,0,0,5,0,0,0,0,0,0,0
0,0,0,0,0,0,0,2,0,0,2,0,0,18,0,0,0,0,2,0,0,2,0,0,0,0,0,0,0
0,0,0,0,0,0,3,41,0,0,0,3,0,0,0,0,0,3,41,0,0,41,3,0,0,0,0,0,0
0,0,0,0,0,3,41,0,0,0,0,41,3,0,0,0,3,41,0,0,0,0,41,3,0,0,0,0,0
0,0,0,0,2,41,0,0,0,0,0,0,41,2,5,2,41,0,0,0,0,0,0,0,2,0,0,18,0
0,0,0,0,31,0,0,0,0,0,0,0,0,0,0,0,0,0,0,0,0,0,0,0,31,0,0,0,0
0,0,0,0,31,0,0,0,0,0,0,0,0,0,0,0,0,0,0,0,0,0,0,0,31,0,0,0,0
0,0,0,0,2,0,0,0,0,0,0,0,41,2,5,2,41,0,0,0,0,0,12,0,2,0,0,0,0
0,0,0,0,0,3,0,0,0,0,0,41,3,0,0,0,3,41,0,0,0,16,11,3,0,0,0,0,0
0,0,0,0,0,0,3,0,0,0,0,3,0,0,0,0,0,3,41,0,0,0,3,0,0,0,0,0,0
0,0,0,0,0,0,0,2,31,31,2,0,0,0,0,0,0,0,2,31,31,2,0,0,0,0,0,0,0
0,0,0,0,0,0,0,0,0,0,0,0,0,0,0,0,0,0,0,0,0,0,0,0,0,0,0,0,0
0,0,0,0,0,0,0,0,0,0,0,0,0,0,0,0,0,0,0,0,0,0,0,0,0,0,0,0,0
0,0,0,0,0,0,0,0,0,0,18,0,0,0,0,0,0,0,18,0,0,0,0,0,0,0,0,0,0
0,0,0,0,0,0,0,0,0,0,0,0,0,0,0,0,0,0,0,0,0,0,0,0,0,0,0,0,0
endlayer

layer
0,0,0,0,0,0,0,0,0,0,0,0,0,0,0,0,0,0,0,0,0,0,0,0,0,0,0,0,0
0,0,0,0,0,0,0,0,0,0,18,0,0,0,0,0,0,0,18,0,0,0,0,0,0,0,0,0,0
0,0,0,0,0,0,0,0,0,0,0,0,0,0,0,0,0,0,0,0,0,0,0,0,0,0,0,0,0
0,0,0,0,0,0,0,0,0,0,0,0,0,0,0,0,0,0,0,0,0,0,0,0,0,0,0,0,0
0,0,0,0,0,0,0,2,31,31,2,0,0,0,0,0,0,0,2,31,31,2,0,0,0,0,0,0,0
0,0,0,0,0,0,3,0,0,0,41,3,0,0,0,0,0,3,0,0,12,11,3,0,0,0,0,0,0
0,0,0,0,0,3,0,0,0,0,0,41,3,0,0,0,3,41,0,0,0,16,0,3,0,0,0,0,0
0,0,0,0,2,11,16,0,0,0,0,0,41,2,17,2,41,0,0,0,0,0,0,0,2,0,0,0,0
0,0,0,0,31,12,0,0,0,0,0,0,0,0,0,0,0,0,0,0,0,0,0,0,31,0,0,0,0
0,0,0,0,31,0,0,0,0,0,0,0,0,0,0,0,0,0,0,0,0,0,0,0,31,0,0,0,0
0,18,0,0,2,0,0,0,0,0,0,0,41,2,0,2,41,0,0,0,0,0,0,41,2,0,0,0,0
0,0,0,0,0,3,41,0,0,0,0,41,3,0,0,0,3,41,0,0,0,0,41,3,0,0,0,0,0
0,0,0,0,0,0,3,41,0,0,41,3,0,0,0,0,0,3,41,0,0,41,3,0,0,0,0,0,0
0,0,0,0,0,0,0,2,0,0,2,0,0,0,0,0,0,0,2,0,0,2,0,0,0,0,0,0,0
0,0,0,0,0,0,0,17,0,0,0,0,0,0,0,0,0,0,0,0,0,17,0,0,0,0,0,0,0
0,0,0,0,0,0,0,2,0,0,2,0,0,18,0,0,0,0,2,0,0,2,0,0,0,0,0,0,0
0,0,0,0,0,0,3,41,0,0,0,3,0,0,0,0,0,3,41,0,0,41,3,0,0,0,0,0,0
0,0,0,0,0,3,41,0,0,0,0,41,3,0,0,0,3,41,0,0,0,0,41,3,0,0,0,0,0
0,0,0,0,2,41,0,0,0,0,0,0,41,2,0,2,41,0,0,0,0,0,0,0,2,0,0,18,0
0,0,0,0,31,0,0,0,0,0,0,0,0,0,0,0,0,0,0,0,0,0,0,0,31,0,0,0,0
0,0,0,0,31,0,0,0,0,0,0,0,0,0,0,0,0,0,0,0,0,0,0,12,31,0,0,0,0
0,0,0,0,2,0,0,0,0,0,0,0,41,2,17,2,41,0,0,0,0,0,16,11,2,0,0,0,0
0,0,0,0,0,3,0,0,0,0,0,41,3,0,0,0,3,41,0,0,0,0,0,3,0,0,0,0,0
0,0,0,0,0,0,3,0,0,0,0,3,0,0,0,0,0,3,41,0,0,0,3,0,0,0,0,0,0
0,0,0,0,0,0,0,2,31,31,2,0,0,0,0,0,0,0,2,31,31,2,0,0,0,0,0,0,0
0,0,0,0,0,0,0,0,0,0,0,0,0,0,0,0,0,0,0,0,0,0,0,0,0,0,0,0,0
0,0,0,0,0,0,0,0,0,0,0,0,0,0,0,0,0,0,0,0,0,0,0,0,0,0,0,0,0
0,0,0,0,0,0,0,0,0,0,18,0,0,0,0,0,0,0,18,0,0,0,0,0,0,0,0,0,0
0,0,0,0,0,0,0,0,0,0,0,0,0,0,0,0,0,0,0,0,0,0,0,0,0,0,0,0,0
endlayer

layer
0,0,0,0,0,0,0,0,0,0,0,0,0,0,0,0,0,0,0,0,0,0,0,0,0,0,0,0,0
0,0,0,0,0,0,0,0,0,0,18,0,0,0,0,0,0,0,18,0,0,0,0,0,0,0,0,0,0
0,0,0,0,0,0,0,0,0,0,0,0,0,0,0,0,0,0,0,0,0,0,0,0,0,0,0,0,0
0,0,0,0,0,0,0,0,0,0,0,0,0,0,0,0,0,0,0,0,0,0,0,0,0,0,0,0,0
0,0,0,0,0,0,0,2,2,2,2,0,0,0,0,0,0,0,2,2,2,2,0,0,0,0,0,0,0
0,0,0,0,0,0,3,0,0,0,41,3,0,0,0,0,0,3,12,11,16,0,3,0,0,0,0,0,0
0,0,0,0,0,3,0,0,0,0,0,41,3,0,0,0,3,41,0,0,0,0,0,3,0,0,0,0,0
0,0,0,0,2,0,0,0,0,0,0,0,41,2,0,2,41,0,0,0,0,0,0,0,2,0,0,0,0
0,0,0,0,2,16,0,0,0,0,0,0,0,2,0,2,0,0,0,0,0,0,0,0,2,0,0,0,0
0,0,0,0,2,11,0,0,0,0,0,0,0,2,0,2,0,0,0,0,0,0,0,0,2,0,18,18,18
0,18,0,0,2,12,0,0,0,0,0,0,41,2,0,2,41,0,0,0,0,0,0,41,2,0,18,19,18
0,0,0,0,0,3,41,0,0,0,0,41,3,0,0,0,3,41,0,0,0,0,41,3,0,0,18,18,18
0,0,0,0,0,0,3,41,0,0,41,3,0,0,0,13,0,3,41,0,0,41,3,0,0,0,0,0,0
0,0,0,0,0,0,0,2,2,2,2,0,0,0,13,4,13,0,2,2,2,2,0,0,0,0,0,0,0
0,0,0,0,0,0,0,0,0,0,0,0,0,0,0,13,0,0,0,0,0,0,0,0,0,0,0,0,0
0,0,0,0,0,0,0,2,2,2,2,0,0,18,0,0,0,0,2,2,2,2,0,0,0,0,0,0,0
0,0,0,0,0,0,3,41,0,0,0,3,0,0,0,0,0,3,41,0,0,41,3,0,0,0,0,0,0
0,0,0,0,0,3,41,0,0,0,0,41,3,0,0,0,3,41,0,0,0,0,41,3,0,0,0,0,0
0,0,0,0,2,41,0,0,0,0,0,0,41,2,0,2,41,0,0,0,0,0,0,12,2,0,0,18,0
0,0,0,0,2,0,0,0,0,0,0,0,0,2,0,2,0,0,0,0,0,0,0,11,2,0,0,0,0
0,0,0,0,2,0,0,0,0,0,0,0,0,2,0,2,0,0,0,0,0,0,0,16,2,0,0,0,0
0,0,0,0,2,0,0,0,0,0,0,0,41,2,0,2,41,0,0,0,0,0,0,0,2,0,0,0,0
0,0,0,0,0,3,0,0,0,0,0,41,3,0,0,0,3,41,0,0,0,0,0,3,0,0,0,0,0
0,0,0,0,0,0,3,0,0,0,12,3,0,0,0,0,0,3,41,0,0,0,3,0,0,0,0,0,0
0,0,0,0,0,0,0,2,2,2,2,0,0,0,0,0,0,0,2,2,2,2,0,0,0,0,0,0,0
0,0,0,0,0,0,0,0,0,0,0,0,0,0,0,0,0,0,0,0,0,0,0,0,0,0,0,0,0
0,0,0,0,0,0,0,0,0,0,0,0,0,0,0,0,0,0,0,0,0,0,0,0,0,0,0,0,0
0,0,0,0,0,0,0,0,0,0,18,0,0,0,0,0,0,0,18,0,0,0,0,0,0,0,0,0,0
0,0,0,0,0,0,0,0,0,0,0,0,0,0,0,0,0,0,0,0,0,0,0,0,0,0,0,0,0
endlayer

layer
0,0,0,0,0,0,0,0,0,0,0,0,0,0,0,0,0,0,0,0,0,0,0,0,0,0,0,0,0
0,0,0,0,0,0,0,0,0,0,18,0,0,0,0,0,0,0,18,0,0,0,0,0,0,0,0,0,0
0,0,0,0,0,0,0,0,0,0,0,0,0,0,0,0,0,0,0,0,0,0,0,0,0,0,0,0,0
0,0,0,0,0,0,0,0,5,5,0,0,0,0,0,0,0,0,0,5,5,0,0,0,0,0,0,0,0
0,0,0,0,0,0,0,20,3,3,20,0,0,0,0,0,0,0,20,3,3,20,0,0,0,0,0,0,0
0,0,0,0,0,0,3,11,21,21,11,3,0,0,0,0,0,3,16,0,0,0,3,0,0,0,0,0,0
0,0,0,0,0,3,12,11,11,11,11,11,3,0,0,0,3,11,11,11,11,0,12,3,0,0,0,0,0
0,0,0,0,20,0,0,11,11,11,11,11,11,20,5,20,11,21,11,11,11,11,11,11,20,0,0,0,0
0,0,0,5,3,0,11,11,11,11,11,11,11,3,22,3,21,11,11,39,39,11,11,21,3,5,0,0,0
0,0,0,5,3,0,11,11,11,11,11,21,11,3,22,3,11,11,11,39,39,11,11,11,3,5,18,18,18
0,18,0,0,20,16,11,11,11,11,11,21,11,20,5,20,11,21,11,11,11,11,21,11,20,0,18,23,18
0,0,0,0,0,3,11,11,11,11,11,11,3,0,0,0,3,11,11,11,11,11,11,3,0,0,18,18,18
0,0,0,0,0,0,3,11,11,11,11,3,0,0,0,10,0,3,11,11,11,11,3,0,0,0,0,0,0
0,0,0,0,0,0,0,20,3,3,20,0,0,0,10,13,10,0,20,3,3,20,0,0,0,0,0,0,0
0,0,0,0,0,0,0,5,22,22,5,0,0,0,0,10,0,0,5,22,22,5,0,0,0,0,0,0,0
0,0,0,0,0,0,0,20,3,3,20,0,0,18,0,0,0,0,20,3,3,20,0,0,0,0,0,0,0
0,0,0,0,0,0,3,11,11,11,11,3,0,0,0,0,0,3,11,21,11,11,3,0,0,0,0,0,0
18,18,18,0,0,3,11,21,0,11,21,11,3,0,0,0,3,11,11,11,11,11,21,3,0,0,0,0,0
18,19,18,0,20,21,11,0,0,0,11,11,11,20,5,20,11,11,21,11,11,11,11,16,20,0,0,18,0
18,18,18,5,3,11,0,0,0,0,0,21,11,3,22,3,11,11,11,21,21,11,21,0,3,5,0,0,0
0,0,0,5,3,11,0,0,0,0,0,0,11,3,22,3,11,11,21,11,21,11,11,0,3,5,0,0,0
0,0,0,0,20,11,11,0,0,0,0,0,0,20,5,20,11,11,11,11,21,11,0,0,20,0,0,0,0
0,0,0,0,0,3,0,0,0,0,0,0,3,0,0,0,3,11,11,11,11,11,12,3,0,0,0,0,0
0,0,0,0,0,0,3,0,0,0,0,3,0,0,0,0,0,3,11,11,11,11,3,0,0,0,0,0,0
0,0,0,0,0,0,0,20,3,3,20,0,0,0,0,0,0,0,20,3,3,20,0,0,0,0,0,0,0
0,0,0,0,0,0,0,0,5,5,0,0,0,0,0,0,0,0,0,5,5,0,0,0,0,0,0,0,0
0,0,0,0,0,0,0,0,0,0,0,0,0,0,0,0,0,0,0,0,0,0,0,0,0,0,0,0,0
0,0,0,0,0,0,0,0,0,0,18,0,0,0,0,0,0,0,18,0,0,0,0,0,0,0,0,0,0
0,0,0,0,0,0,0,0,0,0,0,0,0,0,0,0,0,0,0,0,0,0,0,0,0,0,0,0,0
endlayer

layer
0,0,0,0,0,0,0,0,0,0,0,0,0,0,0,0,0,0,0,0,0,0,0,0,0,0,0,0,0
0,0,0,0,0,0,0,0,0,0,18,0,0,0,0,0,0,0,18,0,0,0,0,0,0,0,0,0,0
0,0,0,0,0,0,0,0,0,0,0,0,0,0,0,0,0,0,0,0,0,0,0,0,0,0,0,0,0
0,0,0,0,0,0,0,0,0,0,0,0,0,0,0,0,0,0,0,0,0,0,0,0,0,0,0,0,0
0,0,0,0,0,0,0,2,2,2,2,0,0,0,0,0,0,0,2,2,2,2,0,0,0,0,0,0,0
0,0,0,0,0,0,3,11,16,0,0,3,0,0,0,0,0,3,0,0,0,0,3,0,0,0,0,0,0
0,0,0,0,0,3,26,12,42,17,0,0,3,0,0,0,3,0,0,0,0,0,26,3,0,0,0,0,0
0,0,0,0,2,0,0,43,43,42,43,0,0,2,13,2,0,0,10,39,39,10,12,11,2,0,0,0,0
0,0,0,0,2,0,17,42,25,14,43,42,0,10,10,10,0,0,39,44,44,39,0,16,2,0,0,0,0
0,0,0,0,2,0,42,43,14,25,42,17,0,10,10,10,0,0,39,44,44,39,0,0,2,0,18,18,18
0,18,0,0,2,0,0,43,42,43,43,0,0,2,13,2,0,0,10,39,39,10,0,0,2,0,18,0,18
0,0,0,0,0,3,0,0,17,42,0,0,3,0,0,0,3,0,0,0,0,0,0,3,0,0,18,18,18
0,0,0,0,0,0,3,0,0,0,0,3,0,0,0,0,0,3,0,0,0,0,3,0,0,0,0,0,0
0,0,0,0,0,0,0,2,10,10,2,0,0,0,0,18,0,0,2,10,10,2,0,0,0,0,0,0,0
0,0,0,0,0,0,0,13,10,10,13,0,0,0,0,0,0,0,13,10,10,13,0,0,0,0,0,0,0
0,0,0,0,0,0,0,2,10,10,2,0,0,18,0,45,0,0,2,10,10,2,0,0,0,0,0,0,0
0,0,0,0,0,0,3,0,0,0,0,3,0,0,0,0,0,3,0,0,0,0,3,0,0,0,0,0,0
18,18,18,0,0,3,25,0,0,0,0,26,3,0,0,0,3,5,0,0,0,0,5,3,0,0,0,0,0
18,36,18,0,2,0,0,0,0,0,24,0,0,2,13,2,0,0,0,0,0,0,0,0,2,0,0,18,0
18,18,18,0,2,0,0,0,0,0,0,0,0,10,10,10,0,0,0,0,0,0,0,0,2,0,0,0,0
0,0,0,0,2,16,0,0,0,0,0,0,0,10,10,10,0,24,0,0,0,0,0,0,2,14,0,0,0
0,0,0,0,2,11,12,0,0,0,0,0,0,2,13,2,0,0,0,0,0,0,0,0,2,0,0,0,0
0,0,0,0,0,3,0,0,0,0,0,0,3,0,0,0,3,5,0,0,0,12,26,3,0,0,0,0,0
0,0,0,0,0,0,3,0,0,0,0,3,0,0,0,0,0,3,25,0,16,11,3,0,0,0,0,0,0
0,0,0,0,0,0,0,2,2,2,2,0,0,0,0,0,0,0,2,2,2,2,0,0,0,0,0,0,0
0,0,0,0,0,0,0,0,0,0,0,0,0,0,0,0,0,0,0,0,0,0,0,0,0,0,0,0,0
0,0,0,0,0,0,0,0,0,0,0,0,0,0,0,0,0,0,0,0,0,0,0,0,0,0,0,0,0
0,0,0,0,0,0,0,0,0,0,18,0,0,0,0,0,0,0,18,0,0,0,0,0,0,0,0,0,0
0,0,0,0,0,0,0,0,0,0,0,0,0,0,0,0,0,0,0,0,0,0,0,0,0,0,0,0,0
endlayer

layer
0,0,0,0,0,0,0,0,0,0,0,0,0,0,0,0,0,0,0,0,0,0,0,0,0,0,0,0,0
0,0,0,0,0,0,0,0,0,0,18,0,0,0,0,0,0,0,18,0,0,0,0,0,0,0,0,0,0
0,0,0,0,0,0,0,0,0,0,0,0,0,0,0,0,0,0,0,0,0,0,0,0,0,0,0,0,0
0,0,0,0,0,0,0,0,0,0,0,0,0,0,0,0,0,0,0,0,0,0,0,0,0,0,0,0,0
0,0,0,0,0,0,46,2,31,31,2,0,0,0,0,0,0,0,2,31,31,2,46,0,0,0,0,0,0
0,0,0,0,0,46,3,0,0,0,0,3,0,0,0,0,0,3,0,0,0,0,3,46,0,0,0,0,0
0,0,0,0,46,3,11,16,0,0,0,0,3,0,0,0,3,0,0,0,0,12,11,3,46,0,0,0,0
0,0,0,0,2,0,12,0,0,0,0,0,0,2,5,2,0,0,0,0,0,0,16,0,2,0,0,0,0
0,0,0,0,31,0,0,0,0,0,0,0,0,0,0,0,0,0,0,0,0,0,0,0,31,0,0,0,0
0,0,0,0,31,0,0,0,0,0,0,0,0,0,0,0,0,0,0,0,0,0,0,0,31,0,18,18,18
0,18,0,0,2,0,0,0,0,0,0,0,0,2,5,2,0,0,0,0,0,0,0,0,2,0,18,13,18
0,0,0,0,0,3,0,0,0,0,0,0,3,0,0,0,3,0,0,0,0,0,0,3,0,0,18,18,18
0,0,0,0,0,0,3,0,0,0,0,3,0,0,0,0,0,3,0,0,0,0,3,0,0,0,0,0,0
0,0,0,0,0,0,0,2,0,0,2,0,0,0,0,18,0,0,2,0,0,2,0,0,0,0,0,0,0
0,0,0,0,0,0,0,5,0,0,5,0,0,0,0,0,0,0,5,0,0,5,0,0,0,0,0,0,0
0,0,0,0,0,0,0,2,0,0,2,0,0,18,0,18,0,0,2,0,0,2,0,0,0,0,0,0,0
0,0,0,0,0,0,3,0,0,0,0,3,0,0,0,0,0,3,0,0,0,0,3,0,0,0,0,0,0
18,18,18,0,0,3,0,0,0,0,0,0,3,0,0,0,3,17,0,0,0,0,17,3,0,0,0,0,0
18,0,18,0,2,0,0,0,0,0,0,0,0,2,5,2,0,0,0,0,0,0,0,0,2,0,0,18,0
18,18,18,0,31,0,0,0,0,0,0,0,0,0,0,0,0,0,0,0,0,0,0,0,31,0,0,0,0
0,0,0,0,31,0,0,0,0,0,0,0,0,0,0,0,0,0,0,0,0,0,0,0,31,0,0,0,0
0,0,0,0,2,0,16,0,0,0,0,0,0,2,5,2,0,0,0,0,0,0,12,0,2,0,0,0,0
0,0,0,0,46,3,11,12,0,0,0,0,3,0,0,0,3,17,0,0,0,16,11,3,46,0,0,0,0
0,0,0,0,0,46,3,0,0,0,0,3,0,0,0,0,0,3,0,0,0,0,3,46,0,0,0,0,0
0,0,0,0,0,0,46,2,31,31,2,0,0,0,0,0,0,0,2,31,31,2,46,0,0,0,0,0,0
0,0,0,0,0,0,0,0,0,0,0,0,0,0,0,0,0,0,0,0,0,0,0,0,0,0,0,0,0
0,0,0,0,0,0,0,0,0,0,0,0,0,0,0,0,0,0,0,0,0,0,0,0,0,0,0,0,0
0,0,0,0,0,0,0,0,0,0,18,0,0,0,0,0,0,0,18,0,0,0,0,0,0,0,0,0,0
0,0,0,0,0,0,0,0,0,0,0,0,0,0,0,0,0,0,0,0,0,0,0,0,0,0,0,0,0
endlayer

layer
0,0,0,0,0,0,0,0,0,0,0,0,0,0,0,0,0,0,0,0,0,0,0,0,0,0,0,0,0
0,0,0,0,0,0,0,0,0,0,18,0,0,0,0,0,0,0,18,0,0,0,0,0,0,0,0,0,0
0,0,0,0,0,0,0,0,0,0,0,0,0,0,0,0,0,0,0,0,0,0,0,0,0,0,0,0,0
0,0,0,0,0,0,0,0,0,0,0,0,0,0,0,0,0,0,0,0,0,0,0,0,0,0,0,0,0
0,0,0,0,0,0,46,2,31,31,2,0,0,0,0,0,0,0,2,31,31,2,46,0,0,0,0,0,0
0,0,0,0,0,4,3,0,0,0,0,3,0,0,0,0,0,3,0,0,12,11,3,4,0,0,0,0,0
0,0,0,0,46,3,0,0,0,0,0,0,3,0,0,0,3,0,0,0,0,16,0,3,46,0,0,0,0
0,0,0,0,2,11,16,0,0,0,0,0,0,2,17,2,0,0,0,0,0,0,0,0,2,0,0,0,0
0,0,0,0,31,12,0,0,0,0,0,0,0,0,0,0,0,0,0,0,0,0,0,0,31,0,0,0,0
0,0,0,0,31,0,0,0,0,0,0,0,0,0,0,0,0,0,0,0,0,0,0,0,31,0,0,0,0
0,18,0,0,2,0,0,0,0,0,0,0,0,2,0,2,0,0,0,0,0,0,0,0,2,0,0,18,0
0,0,0,0,0,3,0,0,0,0,0,0,3,0,0,0,3,0,0,0,0,0,0,3,0,0,0,0,0
0,0,0,0,0,0,3,0,0,0,0,3,0,0,0,0,0,3,0,0,0,0,3,0,0,0,0,0,0
0,0,0,0,0,0,0,2,0,0,2,0,0,0,0,18,0,0,2,0,0,2,0,0,0,0,0,0,0
0,0,0,0,0,0,0,17,0,0,0,0,0,0,0,0,0,0,0,0,0,17,0,0,0,0,0,0,0
0,0,0,0,0,0,0,2,0,0,2,0,0,18,0,18,0,0,2,0,0,2,0,0,0,0,0,0,0
0,0,0,0,0,0,3,0,0,0,0,3,0,0,0,0,0,3,0,0,0,0,3,0,0,0,0,0,0
18,18,18,0,0,3,0,0,0,0,0,0,3,0,0,0,3,0,0,0,0,0,0,3,0,0,0,0,0
18,13,18,0,2,0,0,0,0,0,0,0,0,2,0,2,0,0,0,0,0,0,0,0,2,0,0,18,0
18,18,18,0,31,0,0,0,0,0,0,0,0,0,0,0,0,0,0,0,0,0,0,0,31,0,0,0,0
0,0,0,0,31,0,0,0,0,0,0,0,0,0,0,0,0,0,0,0,0,0,0,12,31,0,0,0,0
0,0,0,0,2,0,0,0,0,0,0,0,0,2,17,2,0,0,0,0,0,0,16,11,2,0,0,0,0
0,0,0,0,46,3,0,16,0,0,0,0,3,0,0,0,3,0,0,0,0,0,0,3,46,0,0,0,0
0,0,0,0,0,4,3,11,12,0,0,3,0,0,0,0,0,3,0,0,0,0,3,4,0,0,0,0,0
0,0,0,0,0,0,46,2,31,31,2,0,0,0,0,0,0,0,2,31,31,2,46,0,0,0,0,0,0
0,0,0,0,0,0,0,0,0,0,0,0,0,0,0,0,0,0,0,0,0,0,0,0,0,0,0,0,0
0,0,0,0,0,0,0,0,0,0,0,0,0,0,0,0,0,0,0,0,0,0,0,0,0,0,0,0,0
0,0,0,0,0,0,0,0,0,0,18,0,0,0,0,0,0,0,18,0,0,0,0,0,0,0,0,0,0
0,0,0,0,0,0,0,0,0,0,0,0,0,0,0,0,0,0,0,0,0,0,0,0,0,0,0,0,0
endlayer

layer
0,0,0,0,0,0,0,0,0,0,0,0,0,0,0,0,0,0,0,0,0,0,0,0,0,0,0,0,0
0,0,0,0,0,0,0,0,0,0,18,0,0,0,0,0,0,0,18,0,0,0,0,0,0,0,0,0,0
0,0,0,0,0,0,0,0,0,0,0,0,0,0,0,0,0,0,0,0,0,0,0,0,0,0,0,0,0
0,0,0,0,0,0,0,0,0,0,0,0,0,0,0,0,0,0,0,0,0,0,0,0,0,0,0,0,0
0,0,0,0,0,0,46,2,2,2,2,0,0,0,0,0,0,0,2,2,2,2,46,0,0,0,0,0,0
0,0,0,0,0,46,3,0,0,0,0,3,0,0,0,0,0,3,12,11,16,0,3,46,0,0,0,0,0
0,0,0,0,46,3,0,0,0,0,0,0,3,0,0,0,3,0,0,0,0,0,0,3,46,0,0,0,0
0,0,0,0,2,0,0,0,0,0,0,0,0,2,0,2,0,0,0,0,0,0,0,0,2,0,0,0,0
0,0,0,0,2,16,0,0,0,0,0,0,0,2,0,2,0,0,0,0,0,0,0,0,2,0,0,0,0
0,0,0,0,2,11,0,0,0,0,0,0,0,2,0,2,0,0,0,0,0,0,0,0,2,0,0,0,0
0,18,0,0,2,12,0,0,0,0,0,0,0,2,0,2,0,0,0,0,0,0,0,0,2,0,0,18,0
0,0,0,0,0,3,0,0,0,0,0,0,3,0,0,0,3,0,0,0,0,0,0,3,0,0,0,0,0
0,0,0,0,0,0,3,0,0,0,0,3,0,0,0,0,0,3,0,0,0,0,3,0,0,0,0,0,0
0,0,0,0,0,0,0,2,2,2,2,0,0,45,0,18,0,0,2,2,2,2,0,0,0,0,0,0,0
0,0,0,0,0,0,0,0,0,0,0,0,0,0,0,0,0,0,0,0,0,0,0,0,0,0,0,0,0
0,0,0,0,0,0,0,2,2,2,2,0,0,18,0,18,0,0,2,2,2,2,0,0,0,0,0,0,0
0,0,0,0,0,0,3,0,0,0,0,3,0,0,0,0,0,3,0,0,0,0,3,0,0,0,0,0,0
0,0,0,0,0,3,0,0,0,0,0,0,3,0,0,0,3,0,0,0,0,0,0,3,0,0,0,0,0
0,18,0,0,2,0,0,0,0,0,0,0,0,2,0,2,0,0,0,0,0,0,0,12,2,0,0,18,0
0,0,0,0,2,0,0,0,0,0,0,0,0,2,0,2,0,0,0,0,0,0,0,11,2,0,0,0,0
0,0,0,0,2,0,0,0,0,0,0,0,0,2,0,2,0,0,0,0,0,0,0,16,2,0,0,0,0
0,0,0,0,2,0,0,0,0,0,0,0,0,2,0,2,0,0,0,0,0,0,0,0,2,0,0,0,0
0,0,0,0,46,3,0,0,0,0,0,0,3,0,0,0,3,0,0,0,0,0,0,3,46,0,0,0,0
0,0,0,0,0,46,3,0,16,11,12,3,0,0,0,0,0,3,0,0,0,0,3,46,0,0,0,0,0
0,0,0,0,0,0,46,2,2,2,2,0,0,0,0,0,0,0,2,2,2,2,46,0,0,0,0,0,0
0,0,0,0,0,0,0,0,0,0,0,0,0,0,0,0,0,0,0,0,0,0,0,0,0,0,0,0,0
0,0,0,0,0,0,0,0,0,0,0,0,0,0,0,0,0,0,0,0,0,0,0,0,0,0,0,0,0
0,0,0,0,0,0,0,0,0,0,18,0,0,0,0,0,0,0,18,0,0,0,0,0,0,0,0,0,0
0,0,0,0,0,0,0,0,0,0,0,0,0,0,0,0,0,0,0,0,0,0,0,0,0,0,0,0,0
endlayer

layer
0,0,0,0,0,0,0,0,0,0,0,0,0,0,0,0,0,0,0,0,0,0,0,0,0,0,0,0,0
0,0,0,0,0,0,0,0,0,0,18,0,0,0,0,0,0,0,18,0,0,0,0,0,0,0,0,0,0
0,0,0,0,0,0,0,0,0,0,0,0,0,0,0,0,0,0,0,0,0,0,0,0,0,0,0,0,0
0,0,0,0,0,0,0,0,5,5,0,0,0,0,0,0,0,0,0,5,5,0,0,0,0,0,0,0,0
0,0,0,0,0,0,46,20,3,3,20,0,0,0,0,0,0,0,20,3,3,20,46,0,0,0,0,0,0
0,0,0,0,0,46,3,11,11,11,11,3,0,0,0,0,0,3,16,0,0,0,3,46,0,0,0,0,0
0,0,0,0,46,3,12,11,11,11,11,11,3,0,0,0,3,11,11,11,11,0,12,3,46,0,0,0,0
0,0,0,0,20,0,0,21,11,21,21,11,11,20,5,20,11,21,11,11,21,11,11,11,20,0,0,0,0
0,0,0,5,3,0,11,11,11,11,11,11,11,3,22,3,21,11,11,11,11,11,11,11,3,5,0,0,0
0,0,0,5,3,0,21,21,11,11,11,21,11,3,22,3,11,11,11,11,11,11,11,11,3,5,0,0,0
0,18,0,0,20,16,11,11,11,21,11,21,11,20,5,20,11,21,11,11,11,11,21,11,20,0,0,18,0
0,0,0,0,0,3,11,11,11,11,11,11,3,0,0,0,3,11,11,11,11,11,11,3,0,0,0,0,0
0,0,0,0,0,0,3,11,11,11,11,3,0,0,0,0,0,3,11,11,11,11,3,0,0,0,0,0,0
0,0,0,0,0,0,0,20,3,3,20,0,0,18,0,18,0,0,20,3,3,20,0,0,0,0,0,0,0
0,0,0,0,0,0,0,5,22,22,5,0,0,0,0,0,0,0,5,22,22,5,0,0,0,0,0,0,0
0,0,0,0,0,0,0,20,3,3,20,0,0,18,0,18,0,0,20,3,3,20,0,0,0,0,0,0,0
0,0,0,0,0,0,3,11,11,11,11,3,0,0,0,0,0,3,11,21,11,11,3,0,0,0,0,0,0
0,0,0,0,0,3,11,21,11,11,11,11,3,0,0,0,3,11,11,11,11,11,21,3,0,0,0,0,0
0,18,0,0,20,21,11,11,11,0,0,0,11,20,5,20,11,11,21,11,11,11,11,16,20,0,0,18,0
0,0,0,5,3,11,11,21,0,0,0,21,11,3,22,3,11,11,11,21,21,11,21,0,3,5,0,0,0
0,0,0,5,3,11,11,11,0,0,0,11,11,3,22,3,11,11,21,11,21,11,11,0,3,5,0,0,0
0,0,0,0,20,11,0,0,0,0,0,0,11,20,5,20,11,11,11,11,21,11,0,0,20,0,0,0,0
0,0,0,0,46,3,0,0,0,0,11,11,3,0,0,0,3,11,11,11,11,11,12,3,46,0,0,0,0
0,0,0,0,0,46,3,0,0,0,16,3,0,0,0,0,0,3,11,11,11,11,3,46,0,0,0,0,0
0,0,0,0,0,0,46,20,3,3,20,0,0,0,0,0,0,0,20,3,3,20,46,0,0,0,0,0,0
0,0,0,0,0,0,0,0,5,5,0,0,0,0,0,0,0,0,0,5,5,0,0,0,0,0,0,0,0
0,0,0,0,0,0,0,0,0,0,0,0,0,0,0,0,0,0,0,0,0,0,0,0,0,0,0,0,0
0,0,0,0,0,0,0,0,0,0,18,0,0,0,0,0,0,0,18,0,0,0,0,0,0,0,0,0,0
0,0,0,0,0,0,0,0,0,0,0,0,0,0,0,0,0,0,0,0,0,0,0,0,0,0,0,0,0
endlayer

layer
0,0,0,0,0,0,0,0,0,0,0,0,0,0,0,0,0,0,0,0,0,0,0,0,0,0,0,0,0
0,0,0,0,0,0,0,0,0,0,18,0,0,0,0,0,0,0,18,0,0,0,0,0,0,0,0,0,0
0,0,0,0,0,0,0,0,0,0,0,0,0,0,0,0,0,0,0,0,0,0,0,0,0,0,0,0,0
0,0,0,0,0,0,0,46,46,0,0,0,0,0,0,0,0,0,0,0,46,46,0,0,0,0,0,0,0
0,0,0,0,0,0,46,46,46,46,46,0,0,0,0,0,0,0,46,46,46,46,46,0,0,0,0,0,0
0,0,0,0,0,0,46,0,47,47,0,46,0,0,0,0,0,46,0,0,0,0,46,0,0,0,0,0,0
0,0,0,0,46,46,0,0,0,0,0,0,46,0,0,0,46,0,0,0,0,0,0,46,46,0,0,0,0
0,0,0,46,46,0,0,0,0,0,0,0,0,46,17,46,0,0,0,0,0,0,0,0,46,46,0,0,0
0,0,0,46,46,0,0,0,0,0,0,0,47,46,10,46,0,0,0,0,0,0,0,47,46,46,0,0,0
0,0,0,0,46,0,0,0,0,48,0,0,47,46,10,46,0,0,0,0,48,0,0,47,46,0,0,0,0
0,18,0,0,46,0,0,0,0,0,0,0,0,46,0,46,0,0,0,0,0,0,0,0,46,0,0,18,0
0,0,0,0,0,46,0,0,0,0,0,0,46,0,0,0,46,0,0,0,0,0,0,46,0,0,0,0,0
0,0,0,0,0,0,46,0,0,0,0,46,0,0,0,0,0,46,0,47,47,0,46,0,0,0,0,0,0
0,0,0,0,0,0,0,46,46,46,46,0,0,18,0,18,0,0,46,46,46,46,0,0,0,0,0,0,0
0,0,0,0,0,0,0,17,10,10,0,0,0,0,0,0,0,0,0,10,10,17,0,0,0,0,0,0,0
0,0,0,0,0,0,0,46,46,46,46,0,0,18,0,18,0,0,46,46,46,46,0,0,0,0,0,0,0
0,0,0,0,0,0,46,0,47,47,0,46,0,0,0,0,0,46,0,0,0,0,46,0,0,0,0,0,0
0,0,0,0,0,46,0,0,0,0,0,0,46,0,0,0,46,0,0,0,0,0,0,46,0,0,0,0,0
0,18,0,0,46,0,0,0,48,0,0,0,0,46,0,46,0,0,0,0,0,0,0,0,46,0,0,18,0
0,0,0,0,46,47,0,0,0,0,0,0,0,46,10,46,47,0,0,0,0,0,0,0,46,0,0,0,0
0,0,0,46,46,47,0,0,0,0,0,0,0,46,10,46,47,0,0,48,0,0,0,0,46,46,0,0,0
0,0,0,46,46,0,0,0,0,0,0,0,0,46,17,46,0,0,0,0,0,0,0,0,46,46,0,0,0
0,0,0,0,46,46,0,0,0,0,0,0,46,0,0,0,46,0,0,0,0,0,0,46,46,0,0,0,0
0,0,0,0,0,0,46,0,0,0,0,46,0,0,0,0,0,46,0,47,47,0,46,0,0,0,0,0,0
0,0,0,0,0,0,46,46,46,46,46,0,0,0,0,0,0,0,46,46,46,46,46,0,0,0,0,0,0
0,0,0,0,0,0,0,46,46,0,0,0,0,0,0,0,0,0,0,0,46,46,0,0,0,0,0,0,0
0,0,0,0,0,0,0,0,0,0,0,0,0,0,0,0,0,0,0,0,0,0,0,0,0,0,0,0,0
0,0,0,0,0,0,0,0,0,0,18,0,0,0,0,0,0,0,18,0,0,0,0,0,0,0,0,0,0
0,0,0,0,0,0,0,0,0,0,0,0,0,0,0,0,0,0,0,0,0,0,0,0,0,0,0,0,0
endlayer

layer
0,0,0,0,0,0,0,0,0,0,0,0,0,0,0,0,0,0,0,0,0,0,0,0,0,0,0,0,0
0,0,0,0,0,0,0,0,0,0,5,0,0,0,0,0,0,0,5,0,0,0,0,0,0,0,0,0,0
0,0,0,0,0,0,0,0,0,0,5,0,0,0,0,0,0,0,5,0,0,0,0,0,0,0,0,0,0
0,0,0,0,0,0,0,0,46,0,5,0,0,0,0,0,0,0,5,0,46,0,0,0,0,0,0,0,0
0,0,0,0,0,0,0,17,46,46,46,0,0,0,0,0,0,0,46,46,46,17,0,0,0,0,0,0,0
0,0,0,0,0,46,46,46,0,0,46,46,0,0,0,0,0,46,0,0,0,46,46,46,0,0,0,0,0
0,0,0,0,0,46,0,0,0,0,0,0,46,0,0,0,46,0,0,0,0,0,0,46,0,0,0,0,0
0,0,0,0,17,46,0,0,0,0,0,0,46,46,0,46,46,0,0,0,0,0,0,46,17,0,0,0,0
0,0,0,46,46,0,0,0,0,0,0,0,0,46,0,46,0,0,0,0,0,0,0,0,46,46,0,0,0
0,0,0,0,46,0,0,0,0,0,0,0,0,46,0,46,0,0,0,0,0,0,0,0,46,0,0,0,0
0,5,5,5,46,0,0,0,0,0,0,0,46,46,0,46,46,0,0,0,0,0,0,46,46,5,5,5,0
0,0,0,0,0,46,0,0,0,0,0,0,46,0,0,0,46,0,0,0,0,0,0,46,0,0,0,0,0
0,0,0,0,0,0,46,46,0,0,46,46,5,5,5,5,5,46,46,0,0,46,46,0,0,0,0,0,0
0,0,0,0,0,0,0,46,46,46,46,0,5,5,5,5,5,0,46,46,46,46,0,0,0,0,0,0,0
0,0,0,0,0,0,0,0,0,0,0,0,5,5,5,5,5,0,0,0,0,0,0,0,0,0,0,0,0
0,0,0,0,0,0,0,46,46,46,46,0,5,5,5,5,5,0,46,46,46,46,0,0,0,0,0,0,0
0,0,0,0,0,0,46,46,0,0,46,46,5,5,5,5,5,46,46,0,0,46,46,0,0,0,0,0,0
0,0,0,0,0,46,0,0,0,0,0,0,46,0,0,0,46,0,0,0,0,0,0,46,0,0,0,0,0
0,5,5,5,46,46,0,0,0,0,0,0,46,46,0,46,46,0,0,0,0,0,0,0,46,5,5,5,0
0,0,0,0,46,0,0,0,0,0,0,0,0,46,0,46,0,0,0,0,0,0,0,0,46,0,0,0,0
0,0,0,46,46,0,0,0,0,0,0,0,0,46,0,46,0,0,0,0,0,0,0,0,46,46,0,0,0
0,0,0,0,17,46,0,0,0,0,0,0,46,46,0,46,46,0,0,0,0,0,0,46,17,0,0,0,0
0,0,0,0,0,46,0,0,0,0,0,0,46,0,0,0,46,0,0,0,0,0,0,46,0,0,0,0,0
0,0,0,0,0,46,46,46,0,0,0,46,0,0,0,0,0,46,46,0,0,46,46,46,0,0,0,0,0
0,0,0,0,0,0,0,17,46,46,46,0,0,0,0,0,0,0,46,46,46,17,0,0,0,0,0,0,0
0,0,0,0,0,0,0,0,46,0,5,0,0,0,0,0,0,0,5,0,46,0,0,0,0,0,0,0,0
0,0,0,0,0,0,0,0,0,0,5,0,0,0,0,0,0,0,5,0,0,0,0,0,0,0,0,0,0
0,0,0,0,0,0,0,0,0,0,5,0,0,0,0,0,0,0,5,0,0,0,0,0,0,0,0,0,0
0,0,0,0,0,0,0,0,0,0,0,0,0,0,0,0,0,0,0,0,0,0,0,0,0,0,0,0,0
endlayer

layer
0,0,0,0,0,0,0,0,0,0,0,0,0,0,0,0,0,0,0,0,0,0,0,0,0,0,0,0,0
0,0,0,0,0,0,0,0,0,0,17,0,0,0,0,0,0,0,17,0,0,0,0,0,0,0,0,0,0
0,0,0,0,0,0,0,0,0,0,0,0,0,0,0,0,0,0,0,0,0,0,0,0,0,0,0,0,0
0,0,0,0,0,0,0,0,46,0,0,0,0,0,0,0,0,0,0,0,46,0,0,0,0,0,0,0,0
0,0,0,0,0,0,46,0,46,46,0,0,0,0,0,0,0,0,0,46,46,0,46,0,0,0,0,0,0
0,0,0,0,0,0,46,46,46,46,46,46,0,0,0,0,0,46,46,46,46,46,46,0,0,0,0,0,0
0,0,0,0,46,46,46,0,0,0,0,46,46,0,0,0,46,46,0,0,0,0,46,46,46,0,0,0,0
0,0,0,0,0,46,0,0,0,0,0,0,46,0,0,0,46,0,0,0,0,0,0,46,0,0,0,0,0
0,0,0,46,46,46,0,0,0,0,0,0,46,46,0,46,46,0,0,0,0,0,0,46,46,46,0,0,0
0,0,0,0,46,46,0,0,0,0,0,0,46,46,0,46,46,0,0,0,0,0,0,46,46,0,0,0,0
0,17,0,0,0,46,0,0,0,0,0,0,46,0,0,0,46,0,0,0,0,0,0,46,0,0,0,17,0
0,0,0,0,0,46,46,0,0,0,0,46,46,0,0,0,46,46,0,0,0,0,46,46,0,0,0,0,0
0,0,0,0,0,0,46,46,46,46,46,46,0,0,0,0,0,46,46,46,46,46,46,0,0,0,0,0,0
0,0,0,0,0,0,0,0,46,46,0,0,0,0,0,0,0,0,0,46,46,0,0,0,0,0,0,0,0
0,0,0,0,0,0,0,0,0,0,0,0,0,0,17,0,0,0,0,0,0,0,0,0,0,0,0,0,0
0,0,0,0,0,0,0,0,46,46,0,0,0,0,0,0,0,0,0,46,46,0,0,0,0,0,0,0,0
0,0,0,0,0,0,46,46,46,46,46,46,0,0,0,0,0,46,46,46,46,46,46,0,0,0,0,0,0
0,0,0,0,0,46,46,0,0,0,0,46,46,0,0,0,46,46,0,0,0,0,46,46,0,0,0,0,0
0,17,0,0,0,46,0,0,0,0,0,0,46,0,0,0,46,0,0,0,0,0,0,46,0,0,0,17,0
0,0,0,0,46,46,0,0,0,0,0,0,46,46,0,46,46,0,0,0,0,0,0,46,46,0,0,0,0
0,0,0,46,46,46,0,0,0,0,0,0,46,46,0,46,46,0,0,0,0,0,0,46,46,46,0,0,0
0,0,0,0,0,46,0,0,0,0,0,0,46,0,0,0,46,0,0,0,0,0,0,46,0,0,0,0,0
0,0,0,0,46,46,46,0,0,0,0,46,46,0,0,0,46,46,0,0,0,0,46,46,46,0,0,0,0
0,0,0,0,0,0,46,46,46,46,46,46,0,0,0,0,0,46,46,46,46,46,46,0,0,0,0,0,0
0,0,0,0,0,0,46,0,46,46,0,0,0,0,0,0,0,0,0,46,46,0,46,0,0,0,0,0,0
0,0,0,0,0,0,0,0,46,0,0,0,0,0,0,0,0,0,0,0,46,0,0,0,0,0,0,0,0
0,0,0,0,0,0,0,0,0,0,0,0,0,0,0,0,0,0,0,0,0,0,0,0,0,0,0,0,0
0,0,0,0,0,0,0,0,0,0,17,0,0,0,0,0,0,0,17,0,0,0,0,0,0,0,0,0,0
0,0,0,0,0,0,0,0,0,0,0,0,0,0,0,0,0,0,0,0,0,0,0,0,0,0,0,0,0
endlayer

layer
0,0,0,0,0,0,0,0,0,0,0,0,0,0,0,0,0,0,0,0,0,0,0,0,0,0,0,0,0
0,0,0,0,0,0,0,0,0,0,0,0,0,0,0,0,0,0,0,0,0,0,0,0,0,0,0,0,0
0,0,0,0,0,0,0,0,0,0,0,0,0,0,0,0,0,0,0,0,0,0,0,0,0,0,0,0,0
0,0,0,0,0,0,0,46,46,0,0,0,0,0,0,0,0,0,0,0,46,46,0,0,0,0,0,0,0
0,0,0,0,0,0,0,46,46,0,0,0,0,0,0,0,0,0,0,0,46,46,0,0,0,0,0,0,0
0,0,0,0,0,0,0,46,46,46,46,0,0,0,0,0,0,0,46,46,46,46,0,0,0,0,0,0,0
0,0,0,0,0,0,46,46,46,46,46,46,0,0,0,0,0,46,46,46,46,46,46,0,0,0,0,0,0
0,0,0,46,46,46,46,0,0,0,0,46,46,0,0,0,46,46,0,0,0,0,46,46,46,46,0,0,0
0,0,0,46,46,46,46,0,0,0,0,46,46,0,0,0,46,46,0,0,0,0,46,46,46,46,0,0,0
0,0,0,0,0,46,46,0,0,0,0,46,46,0,0,0,46,46,0,0,0,0,46,46,0,0,0,0,0
0,0,0,0,0,46,46,0,0,0,0,46,46,0,0,0,46,46,0,0,0,0,46,46,0,0,0,0,0
0,0,0,0,0,0,46,46,46,46,46,46,0,0,0,0,0,46,46,46,46,46,46,0,0,0,0,0,0
0,0,0,0,0,0,0,46,46,46,46,0,0,0,0,0,0,0,46,46,46,46,0,0,0,0,0,0,0
0,0,0,0,0,0,0,0,0,0,0,0,0,0,0,0,0,0,0,0,0,0,0,0,0,0,0,0,0
0,0,0,0,0,0,0,0,0,0,0,0,0,0,0,0,0,0,0,0,0,0,0,0,0,0,0,0,0
0,0,0,0,0,0,0,0,0,0,0,0,0,0,0,0,0,0,0,0,0,0,0,0,0,0,0,0,0
0,0,0,0,0,0,0,46,46,46,46,0,0,0,0,0,0,0,46,46,46,46,0,0,0,0,0,0,0
0,0,0,0,0,0,46,46,46,46,46,46,0,0,0,0,0,46,46,46,46,46,46,0,0,0,0,0,0
0,0,0,0,0,46,46,0,0,0,0,46,46,0,0,0,46,46,0,0,0,0,46,46,0,0,0,0,0
0,0,0,0,0,46,46,0,0,0,0,46,46,0,0,0,46,46,0,0,0,0,46,46,0,0,0,0,0
0,0,0,46,46,46,46,0,0,0,0,46,46,0,0,0,46,46,0,0,0,0,46,46,46,46,0,0,0
0,0,0,46,46,46,46,0,0,0,0,46,46,0,0,0,46,46,0,0,0,0,46,46,46,46,0,0,0
0,0,0,0,0,0,46,46,46,46,46,46,0,0,0,0,0,46,46,46,46,46,46,0,0,0,0,0,0
0,0,0,0,0,0,0,46,46,46,46,0,0,0,0,0,0,0,46,46,46,46,0,0,0,0,0,0,0
0,0,0,0,0,0,0,46,46,0,0,0,0,0,0,0,0,0,0,0,46,46,0,0,0,0,0,0,0
0,0,0,0,0,0,0,46,46,0,0,0,0,0,0,0,0,0,0,0,46,46,0,0,0,0,0,0,0
0,0,0,0,0,0,0,0,0,0,0,0,0,0,0,0,0,0,0,0,0,0,0,0,0,0,0,0,0
0,0,0,0,0,0,0,0,0,0,0,0,0,0,0,0,0,0,0,0,0,0,0,0,0,0,0,0,0
0,0,0,0,0,0,0,0,0,0,0,0,0,0,0,0,0,0,0,0,0,0,0,0,0,0,0,0,0
endlayer

layer
0,0,0,0,0,0,0,0,0,0,0,0,0,0,0,0,0,0,0,0,0,0,0,0,0,0,0,0,0
0,0,0,0,0,0,0,0,0,0,0,0,0,0,0,0,0,0,0,0,0,0,0,0,0,0,0,0,0
0,0,0,0,0,0,0,0,0,0,0,0,0,0,0,0,0,0,0,0,0,0,0,0,0,0,0,0,0
0,0,0,0,0,0,0,0,0,0,0,0,0,0,0,0,0,0,0,0,0,0,0,0,0,0,0,0,0
0,0,0,0,0,0,0,0,0,0,0,0,0,0,0,0,0,0,0,0,0,0,0,0,0,0,0,0,0
0,0,0,0,0,0,0,0,0,0,0,0,0,0,0,0,0,0,0,0,0,0,0,0,0,0,0,0,0
0,0,0,0,0,0,0,46,46,46,46,0,0,0,0,0,0,0,46,46,46,46,0,0,0,0,0,0,0
0,0,0,0,0,0,46,46,46,46,46,46,0,0,0,0,0,46,46,46,46,46,46,0,0,0,0,0,0
0,0,0,0,0,0,46,46,0,0,46,46,0,0,0,0,0,46,46,0,0,46,46,0,0,0,0,0,0
0,0,0,0,0,0,46,46,0,0,46,46,0,0,0,0,0,46,46,0,0,46,46,0,0,0,0,0,0
0,0,0,0,0,0,46,46,46,46,46,46,0,0,0,0,0,46,46,46,46,46,46,0,0,0,0,0,0
0,0,0,0,0,0,0,46,46,46,46,0,0,0,0,0,0,0,46,46,46,46,0,0,0,0,0,0,0
0,0,0,0,0,0,0,0,0,0,0,0,0,0,0,0,0,0,0,0,0,0,0,0,0,0,0,0,0
0,0,0,0,0,0,0,0,0,0,0,0,0,0,0,0,0,0,0,0,0,0,0,0,0,0,0,0,0
0,0,0,0,0,0,0,0,0,0,0,0,0,0,0,0,0,0,0,0,0,0,0,0,0,0,0,0,0
0,0,0,0,0,0,0,0,0,0,0,0,0,0,0,0,0,0,0,0,0,0,0,0,0,0,0,0,0
0,0,0,0,0,0,0,0,0,0,0,0,0,0,0,0,0,0,0,0,0,0,0,0,0,0,0,0,0
0,0,0,0,0,0,0,46,46,46,46,0,0,0,0,0,0,0,46,46,46,46,0,0,0,0,0,0,0
0,0,0,0,0,0,46,46,46,46,46,46,0,0,0,0,0,46,46,46,46,46,46,0,0,0,0,0,0
0,0,0,0,0,0,46,46,0,0,46,46,0,0,0,0,0,46,46,0,0,46,46,0,0,0,0,0,0
0,0,0,0,0,0,46,46,0,0,46,46,0,0,0,0,0,46,46,0,0,46,46,0,0,0,0,0,0
0,0,0,0,0,0,46,46,46,46,46,46,0,0,0,0,0,46,46,46,46,46,46,0,0,0,0,0,0
0,0,0,0,0,0,0,46,46,46,46,0,0,0,0,0,0,0,46,46,46,46,0,0,0,0,0,0,0
0,0,0,0,0,0,0,0,0,0,0,0,0,0,0,0,0,0,0,0,0,0,0,0,0,0,0,0,0
0,0,0,0,0,0,0,0,0,0,0,0,0,0,0,0,0,0,0,0,0,0,0,0,0,0,0,0,0
0,0,0,0,0,0,0,0,0,0,0,0,0,0,0,0,0,0,0,0,0,0,0,0,0,0,0,0,0
0,0,0,0,0,0,0,0,0,0,0,0,0,0,0,0,0,0,0,0,0,0,0,0,0,0,0,0,0
0,0,0,0,0,0,0,0,0,0,0,0,0,0,0,0,0,0,0,0,0,0,0,0,0,0,0,0,0
0,0,0,0,0,0,0,0,0,0,0,0,0,0,0,0,0,0,0,0,0,0,0,0,0,0,0,0,0
endlayer

layer
0,0,0,0,0,0,0,0,0,0,0,0,0,0,0,0,0,0,0,0,0,0,0,0,0,0,0,0,0
0,0,0,0,0,0,0,0,0,0,0,0,0,0,0,0,0,0,0,0,0,0,0,0,0,0,0,0,0
0,0,0,0,0,0,0,0,0,0,0,0,0,0,0,0,0,0,0,0,0,0,0,0,0,0,0,0,0
0,0,0,0,0,0,0,0,0,0,0,0,0,0,0,0,0,0,0,0,0,0,0,0,0,0,0,0,0
0,0,0,0,0,0,0,0,0,0,0,0,0,0,0,0,0,0,0,0,0,0,0,0,0,0,0,0,0
0,0,0,0,0,0,0,0,0,0,0,0,0,0,0,0,0,0,0,0,0,0,0,0,0,0,0,0,0
0,0,0,0,0,0,0,0,0,0,0,0,0,0,0,0,0,0,0,0,0,0,0,0,0,0,0,0,0
0,0,0,0,0,0,0,0,46,46,0,0,0,0,0,0,0,0,0,46,46,0,0,0,0,0,0,0,0
0,0,0,0,0,0,0,46,46,46,46,0,0,0,0,0,0,0,46,46,46,46,0,0,0,0,0,0,0
0,0,0,0,0,0,0,46,46,46,46,0,0,0,0,0,0,0,46,46,46,46,0,0,0,0,0,0,0
0,0,0,0,0,0,0,0,46,46,0,0,0,0,0,0,0,0,0,46,46,0,0,0,0,0,0,0,0
0,0,0,0,0,0,0,0,0,0,0,0,0,0,0,0,0,0,0,0,0,0,0,0,0,0,0,0,0
0,0,0,0,0,0,0,0,0,0,0,0,0,0,0,0,0,0,0,0,0,0,0,0,0,0,0,0,0
0,0,0,0,0,0,0,0,0,0,0,0,0,0,0,0,0,0,0,0,0,0,0,0,0,0,0,0,0
0,0,0,0,0,0,0,0,0,0,0,0,0,0,0,0,0,0,0,0,0,0,0,0,0,0,0,0,0
0,0,0,0,0,0,0,0,0,0,0,0,0,0,0,0,0,0,0,0,0,0,0,0,0,0,0,0,0
0,0,0,0,0,0,0,0,0,0,0,0,0,0,0,0,0,0,0,0,0,0,0,0,0,0,0,0,0
0,0,0,0,0,0,0,0,0,0,0,0,0,0,0,0,0,0,0,0,0,0,0,0,0,0,0,0,0
0,0,0,0,0,0,0,0,46,46,0,0,0,0,0,0,0,0,0,46,46,0,0,0,0,0,0,0,0
0,0,0,0,0,0,0,46,46,46,46,0,0,0,0,0,0,0,46,46,46,46,0,0,0,0,0,0,0
0,0,0,0,0,0,0,46,46,46,46,0,0,0,0,0,0,0,46,46,46,46,0,0,0,0,0,0,0
0,0,0,0,0,0,0,0,46,46,0,0,0,0,0,0,0,0,0,46,46,0,0,0,0,0,0,0,0
0,0,0,0,0,0,0,0,0,0,0,0,0,0,0,0,0,0,0,0,0,0,0,0,0,0,0,0,0
0,0,0,0,0,0,0,0,0,0,0,0,0,0,0,0,0,0,0,0,0,0,0,0,0,0,0,0,0
0,0,0,0,0,0,0,0,0,0,0,0,0,0,0,0,0,0,0,0,0,0,0,0,0,0,0,0,0
0,0,0,0,0,0,0,0,0,0,0,0,0,0,0,0,0,0,0,0,0,0,0,0,0,0,0,0,0
0,0,0,0,0,0,0,0,0,0,0,0,0,0,0,0,0,0,0,0,0,0,0,0,0,0,0,0,0
0,0,0,0,0,0,0,0,0,0,0,0,0,0,0,0,0,0,0,0,0,0,0,0,0,0,0,0,0
0,0,0,0,0,0,0,0,0,0,0,0,0,0,0,0,0,0,0,0,0,0,0,0,0,0,0,0,0
endlayer

