
# Dark Altar (Nether Version)
# original: 7 Mar 2014; updated to MC 1.7.10, 16 Oct 2014
# Created by Ruins mod version 12.1 Ingame Parser
# authoring Player: Jordan_Greywolf
# Last Updated: 18 Feb 2016
# Updated to MC 1.8: 5 Mar 2016
# Updated to MC 1.9: 24 Apr 2016
# Updated to MC 1.12: 22 Jun 2017

biomesToSpawnIn=hell

#uniqueMinDistance=1000

weight=1
embed_into_distance=1

unacceptable_target_blocks=lava,flowing_lava,cloud,Natura:Cloud

dimensions=11,9,9
allowable_overhang=99999
max_cut_in=0
cut_in_buffer=0
max_leveling=0
leveling_buffer=-7
preserve_water=0
preserve_lava=0
preserve_plants=1

#Corners do not spawn, to leave existing terrain.
rule1=0,100,preserveBlock

#Circle Base
rule2=0,100,minecraft:obsidian

#Inner Base; nether brick slabs
rule3=0,100,minecraft:double_stone_slab-6

#Monster-Trapped Engraved Blocks
rule4=0,100,minecraft:monster_egg-5

#Pillars (random chance of not spawning; must be supported from below)

rule5=1,95,minecraft:nether_brick

rule6=0,100,minecraft:nether_brick_stairs-0
rule7=0,100,minecraft:nether_brick_stairs-2
rule8=0,100,MobSpawner:Skeleton,MobSpawner:Blaze
rule9=0,100,minecraft:nether_brick_stairs-3
rule10=0,100,minecraft:nether_brick_stairs-1
rule11=0,100,minecraft:nether_brick_stairs-4
rule12=0,100,minecraft:nether_brick_stairs-6
rule13=0,100,minecraft:netherrack-0
rule14=0,100,minecraft:nether_brick_stairs-7
rule15=0,100,minecraft:nether_brick_stairs-5
rule16=0,100,minecraft:fire-15

#Stone Caps (must be supported adjacent, or won't spawn)

rule17=2,100,minecraft:nether_brick

#Stone Heart; random chance of solid stone or unusual block at heart

rule18=0,100,minecraft:quartz_block,minecraft:soul_sand-0,minecraft:glowstone-0,minecraft:lapis_block,minecraft:lava,minecraft:quartz_ore-0,minecraft:emerald_block,ChestGenHook:chests/nether_bridge:3

rule19=0,100,CommandBlock:RUINSTRIGGER /summon Blaze ~0 ~2 ~0 {HandItems:[{Count:1,id:diamond_hoe,tag:{display:{Name:"Death Scythe"},ench:[{id:16,lvl:10},{id:21,lvl:6}]}},{}],ArmorItems:[{},{},{},{Count:1,id:skull,Damage:0,tag:{display:{Name:"Death Mask"},ench:[{id:0,lvl:5},{id:7,lvl:10}]}}],CustomName:Phantom,Health:25.0f,HandDropChances:[0.4F,0.0F],ArmorDropChances:[0.0F,0.0F,0.0F,0.4F],ActiveEffects:[{Id:14,Amplifier:1,Duration:999999},{Id:1,Amplifier:1,Duration:999999},{Id:5,Amplifier:1,Duration:999999}]}:@

layer
1,1,1,5,5,5,1,1,1
1,5,5,5,5,5,5,5,1
1,5,5,5,5,5,5,5,1
5,5,5,5,5,5,5,5,5
5,5,5,5,5,5,5,5,5
5,5,5,5,5,5,5,5,5
1,5,5,5,5,5,5,5,1
1,5,5,5,5,5,5,5,1
1,1,1,5,5,5,1,1,1
endlayer

layer
1,1,1,5,5,5,1,1,1
1,5,5,5,5,5,5,5,1
1,5,5,5,5,5,5,5,1
5,5,5,5,5,5,5,5,5
5,5,5,5,5,5,5,5,5
5,5,5,5,5,5,5,5,5
1,5,5,5,5,5,5,5,1
1,5,5,5,5,5,5,5,1
1,1,1,5,5,5,1,1,1
endlayer

layer
1,1,1,5,5,5,1,1,1
1,5,5,5,5,5,5,5,1
1,5,5,5,5,5,5,5,1
5,5,5,5,5,5,5,5,5
5,5,5,5,5,5,5,5,5
5,5,5,5,5,5,5,5,5
1,5,5,5,5,5,5,5,1
1,5,5,5,5,5,5,5,1
1,1,1,5,5,5,1,1,1
endlayer

layer
1,1,1,5,5,5,1,1,1
1,5,5,5,5,5,5,5,1
1,5,5,5,5,5,5,5,1
5,5,5,5,5,5,5,5,5
5,5,5,5,5,5,5,5,5
5,5,5,5,5,5,5,5,5
1,5,5,5,5,5,5,5,1
1,5,5,5,5,5,5,5,1
1,1,1,5,5,5,1,1,1
endlayer

layer
1,1,1,5,5,5,1,1,1
1,5,5,5,5,5,5,5,1
1,5,5,5,5,5,5,5,1
5,5,5,5,5,5,5,5,5
5,5,5,5,5,5,5,5,5
5,5,5,5,5,5,5,5,5
1,5,5,5,5,5,5,5,1
1,5,5,5,5,5,5,5,1
1,1,1,5,5,5,1,1,1
endlayer

layer
1,1,1,5,5,5,1,1,1
1,5,5,5,5,5,5,5,1
1,5,5,5,5,5,5,5,1
5,5,5,5,5,5,5,5,5
5,5,5,5,5,5,5,5,5
5,5,5,5,5,5,5,5,5
1,5,5,5,5,5,5,5,1
1,5,5,5,5,5,5,5,1
1,1,1,5,5,5,1,1,1
endlayer




layer
1,1,1,2,2,2,1,1,1
1,2,2,2,2,2,2,2,1
1,2,2,3,3,3,2,2,1
2,2,3,4,4,4,3,2,2
2,2,3,4,18,4,3,2,2
2,2,3,4,4,4,3,2,2
1,2,2,3,3,3,2,2,1
1,2,2,2,2,2,2,2,1
1,1,1,2,2,2,1,1,1
endlayer

layer
1,1,1,5,0,5,1,1,1
1,5,0,0,19,0,0,5,1
1,0,0,0,0,0,0,0,1
5,0,0,0,6,0,0,0,5
0,19,0,9,8,7,0,19,0
5,0,0,0,10,0,0,0,5
1,0,0,0,0,0,0,0,1
1,5,0,0,19,0,0,5,1
1,1,1,5,0,5,1,1,1
endlayer

layer
1,1,1,5,0,5,1,1,1
1,5,0,0,0,0,0,5,1
1,0,0,0,0,0,0,0,1
5,0,0,0,11,0,0,0,5
0,0,0,14,13,12,0,0,0
5,0,0,0,15,0,0,0,5
1,0,0,0,0,0,0,0,1
1,5,0,0,0,0,0,5,1
1,1,1,5,0,5,1,1,1
endlayer

layer
1,1,1,5,0,5,1,1,1
1,5,0,0,0,0,0,5,1
1,0,0,0,0,0,0,0,1
5,0,0,0,10,0,0,0,5
0,0,0,7,16,9,0,0,0
5,0,0,0,6,0,0,0,5
1,0,0,0,0,0,0,0,1
1,5,0,0,0,0,0,5,1
1,1,1,5,0,5,1,1,1
endlayer

layer
1,1,1,5,17,5,1,1,1
1,5,17,0,0,0,17,5,1
1,17,0,0,0,0,0,17,1
5,0,0,0,0,0,0,0,5
17,0,0,0,0,0,0,0,17
5,0,0,0,0,0,0,0,5
1,17,0,0,0,0,0,17,1
1,5,17,0,0,0,17,5,1
1,1,1,5,17,5,1,1,1
endlayer

