# Nether Tower - Crazy Village
# Created by Ruins mod version 12.3 Ingame Parser
# authoring Player: Jordan_Greywolf
# Last Updated: 5 Feb 2016
# Note: Place in \templateparser folder.
# Updated to MC 1.8: 5 Mar 2016
# Updated to MC 1.9: 24 Apr 2016
# Updated to MC 1.12: 22 Jun 2017

biomesToSpawnIn=hell

uniqueMinDistance=2000

weight=1
embed_into_distance=0
#embed_into_distance=5

unacceptable_target_blocks=lava,flowing_lava,water,flowing_water,cloud,Natura:Cloud

dimensions=58,29,27
allowable_overhang=0
max_cut_in=0
cut_in_buffer=0
max_leveling=0
leveling_buffer=-1
preserve_water=0
preserve_lava=0
preserve_plants=1

rule1=0,100,minecraft:log-0
rule2=0,100,minecraft:cobblestone-0
rule3=0,100,minecraft:stone_stairs-2
rule4=0,100,minecraft:stone_stairs-1
rule5=0,100,minecraft:water-9
rule6=0,100,ChestGenHook:chests/simple_dungeon:4-3
rule7=0,100,minecraft:ladder-3

rule8=0,100,CommandBlock:RUINSTRIGGER /summon Skeleton ~0 ~0 ~0 {SkeletonType:1,HandItems:[{Count:1,id:iron_sword,tag:{display:{Name:"Bloody Cutlass"}}},{Count:1,id:shield}],ArmorItems:[{Count:1,id:leather_boots,tag:{display:{color:0}}},{},{Count:1,id:leather_chestplate,tag:{display:{color:0}}},{Count:1,id:leather_helmet,tag:{display:{color:0}}}],CustomName:"Undead Warrior",Health:30.0f,HandDropChances:[0.5F,0.5F],ArmorDropChances:[0.1F,0.1F,0.1F,0.1F],CanPickUpLoot:1,Silent:1,PersistenceRequired:1}:@

rule9=0,100,minecraft:dirt-0
rule10=0,100,minecraft:fence-0
rule11=0,100,minecraft:planks-0
rule12=0,100,minecraft:ladder-5
rule13=0,100,minecraft:oak_stairs-1
rule14=0,100,minecraft:oak_stairs-3
rule15=0,100,minecraft:crafting_table-0
rule16=0,100,minecraft:wooden_door-0
rule17=0,100,minecraft:water-0
rule18=0,100,minecraft:water-1
rule19=0,100,minecraft:stone_stairs-3
rule20=0,100,minecraft:glass_pane-0
rule21=0,100,minecraft:ladder-4
rule22=0,100,minecraft:wooden_pressure_plate-0
rule23=0,100,minecraft:wooden_door-8
rule24=0,100,minecraft:bookshelf-0
rule25=0,100,minecraft:oak_stairs-0
rule26=0,100,minecraft:oak_stairs-6
rule27=0,100,minecraft:oak_stairs-2
rule28=0,100,minecraft:farmland-7
rule29=0,100,minecraft:double_stone_slab-0
rule30=0,100,minecraft:melon_block-0
rule31=0,100,minecraft:melon_stem-7
rule32=0,100,minecraft:carrots-7
rule33=0,100,minecraft:torch-1
rule34=0,100,minecraft:stone_stairs-0
rule35=0,100,minecraft:stone_stairs-6
rule36=0,100,minecraft:stone_stairs-4
rule37=0,100,minecraft:stone_stairs-5
rule38=0,100,minecraft:lava-0
rule39=0,100,minecraft:stone_slab-3
rule40=0,100,minecraft:iron_bars-0
rule41=0,100,IInventory;minecraft:furnace;minecraft:coal#4#0#1-5
rule42=0,100,minecraft:stone_slab-0
rule43=0,100,minecraft:torch-3
rule44=0,100,minecraft:wooden_door-2
rule45=0,100,minecraft:torch-2
rule46=0,100,minecraft:wooden_door-3
rule47=0,100,ChestGenHook:chests/nether_bridge:3-0,ChestGenHook:chests/spawn_bonus_chest:8-0
rule48=0,100,preserveBlock

layer
48,48,48,48,48,48,48,48,48,48,48,48,48,48,48,48,48,48,48,48,48,48,48,48,48,48,48
48,48,48,48,48,48,48,48,48,48,48,48,48,48,48,48,48,48,48,48,48,48,48,48,48,48,48
48,48,48,48,48,48,48,48,48,48,48,48,48,48,48,48,48,48,48,48,48,48,48,48,48,48,48
48,48,48,48,48,48,48,48,48,48,48,48,48,48,48,48,48,48,48,48,48,48,48,48,48,48,48
48,48,48,48,48,48,48,48,48,48,48,48,48,48,48,48,48,48,48,48,1,1,1,1,1,48,48
48,48,48,48,48,48,48,48,48,48,48,48,48,48,2,2,2,48,48,48,1,48,48,48,1,48,48
48,48,48,48,48,48,48,48,48,48,48,48,48,2,2,2,2,2,48,48,1,48,48,48,1,48,48
48,48,48,48,48,48,48,48,48,48,48,48,48,2,2,2,2,2,48,48,1,48,48,48,1,48,48
48,48,48,48,48,48,48,48,48,48,48,48,48,2,2,2,2,2,48,48,1,1,1,1,1,48,48
48,48,48,48,48,48,2,2,2,2,2,48,48,2,2,2,2,2,48,48,48,2,1,2,48,48,48
48,48,48,48,48,48,2,48,48,48,2,48,48,2,2,2,2,2,48,48,48,2,1,2,48,48,48
48,48,48,48,48,48,2,48,48,48,2,48,48,2,2,2,2,2,48,48,2,2,2,2,48,48,48
48,48,48,48,48,48,2,48,48,48,2,48,48,2,2,2,2,2,48,48,2,48,48,2,48,48,48
48,48,48,48,48,48,2,2,2,2,2,48,48,48,2,2,2,48,48,48,2,48,48,2,48,48,48
48,48,48,48,48,48,48,48,48,48,48,48,48,48,2,2,2,48,48,48,2,48,48,2,48,48,48
48,48,48,48,48,48,48,48,48,48,48,48,48,2,2,2,2,2,2,2,2,48,2,2,48,48,48
48,48,48,48,2,2,2,2,2,2,2,2,2,2,2,2,2,2,2,2,2,2,2,48,48,48,48
48,48,48,48,2,2,2,2,2,2,2,2,2,2,2,2,2,2,2,2,2,2,2,48,48,48,48
48,48,48,48,2,2,2,2,2,2,2,2,2,2,2,2,2,2,2,2,2,2,2,48,48,48,48
48,48,48,48,2,2,2,2,2,2,2,2,2,2,2,2,2,2,2,2,2,2,2,48,48,48,48
48,48,48,48,2,2,2,2,2,2,2,2,2,48,48,48,48,2,2,2,2,2,48,48,48,48,48
48,48,48,48,2,2,2,2,2,2,2,2,2,48,48,48,48,2,2,2,2,2,48,48,48,48,48
2,2,2,2,2,48,48,48,48,48,4,3,48,48,48,48,48,2,2,2,2,2,48,48,48,48,48
2,2,2,2,2,2,48,48,48,48,48,48,48,48,48,48,48,2,2,2,2,2,48,48,48,48,48
2,2,2,2,5,2,48,48,48,48,48,48,48,48,48,48,48,48,48,48,48,48,48,48,48,48,48
2,2,2,2,2,2,48,48,48,48,48,48,48,48,48,48,48,48,48,48,48,48,48,48,48,48,48
48,48,48,48,48,48,48,48,48,48,48,48,48,48,48,48,48,48,48,48,48,48,48,48,48,48,48
48,48,48,48,48,48,48,48,48,48,48,48,48,48,48,48,48,48,48,48,48,48,48,48,48,48,48
48,48,48,48,48,48,48,48,48,48,48,48,48,48,48,48,48,48,48,48,48,48,48,48,48,48,48
endlayer

layer
48,48,48,48,48,48,48,48,48,48,48,48,48,48,48,48,48,48,48,48,48,48,48,48,48,48,48
48,48,48,48,48,48,48,48,48,48,48,48,48,48,48,48,48,48,48,48,48,48,48,48,48,48,48
48,48,48,48,48,48,48,48,48,48,48,48,48,48,48,48,48,48,48,48,48,48,48,48,48,48,48
48,48,48,48,48,48,48,48,48,48,48,48,48,48,48,48,48,48,48,48,48,48,48,48,48,48,48
48,48,48,48,48,48,48,48,48,48,48,48,48,48,48,48,48,48,48,48,1,1,1,1,1,48,48
48,48,48,48,48,48,48,48,48,48,48,48,48,48,2,2,2,48,48,48,1,48,48,48,1,48,48
48,48,48,48,48,48,48,48,48,48,48,48,48,2,2,2,2,2,48,48,1,48,48,48,1,48,48
48,48,48,48,48,48,48,48,48,48,48,48,48,2,2,2,2,2,48,48,1,48,48,48,1,48,48
48,48,48,48,48,48,48,48,48,48,48,48,48,2,2,2,2,2,48,48,1,1,1,1,1,48,48
48,48,48,48,48,48,2,2,2,2,2,48,48,2,2,2,2,2,48,48,48,2,1,2,48,48,48
48,48,48,48,48,48,2,48,48,48,2,48,48,2,2,2,2,2,48,48,48,2,1,2,48,48,48
48,48,48,48,48,48,2,48,48,48,2,48,48,2,2,2,2,2,48,48,2,2,2,2,48,48,48
48,48,48,48,48,48,2,48,48,48,2,48,48,2,2,2,2,2,48,48,2,48,48,2,48,48,48
48,48,48,48,48,48,2,2,2,2,2,48,48,48,2,2,2,48,48,48,2,48,48,2,48,48,48
48,48,48,48,48,48,48,48,48,48,48,48,48,48,2,2,2,48,48,48,2,48,48,2,48,48,48
48,48,48,48,48,48,48,48,48,48,48,48,48,2,2,2,2,2,2,2,2,48,2,2,48,48,48
48,48,48,48,2,2,2,2,2,2,2,2,2,2,2,2,2,2,2,2,2,2,2,48,48,48,48
48,48,48,48,2,2,2,2,2,2,2,2,2,2,2,2,2,2,2,2,2,2,2,48,48,48,48
48,48,48,48,2,2,2,2,2,2,2,2,2,2,2,2,2,2,2,2,2,2,2,48,48,48,48
48,48,48,48,2,2,2,2,2,2,2,2,2,2,2,2,2,2,2,2,2,2,2,48,48,48,48
48,48,48,48,2,2,2,2,2,2,2,2,2,48,48,48,48,2,2,2,2,2,48,48,48,48,48
48,48,48,48,2,2,2,2,2,2,2,2,2,48,48,48,48,2,2,2,2,2,48,48,48,48,48
2,2,2,2,2,48,48,48,48,4,3,48,48,48,48,48,48,2,2,2,2,2,48,48,48,48,48
2,2,2,2,2,2,48,48,48,48,48,48,48,48,48,48,48,2,2,2,2,2,48,48,48,48,48
2,2,2,2,5,2,48,48,48,48,48,48,48,48,48,48,48,48,48,48,48,48,48,48,48,48,48
2,2,2,2,2,2,48,48,48,48,48,48,48,48,48,48,48,48,48,48,48,48,48,48,48,48,48
48,48,48,48,48,48,48,48,48,48,48,48,48,48,48,48,48,48,48,48,48,48,48,48,48,48,48
48,48,48,48,48,48,48,48,48,48,48,48,48,48,48,48,48,48,48,48,48,48,48,48,48,48,48
48,48,48,48,48,48,48,48,48,48,48,48,48,48,48,48,48,48,48,48,48,48,48,48,48,48,48
endlayer

layer
48,48,48,48,48,48,48,48,48,48,48,48,48,48,48,48,48,48,48,48,48,48,48,48,48,48,48
48,48,48,48,48,48,48,48,48,48,48,48,48,48,48,48,48,48,48,48,48,48,48,48,48,48,48
48,48,48,48,48,48,48,48,48,48,48,48,48,48,48,48,48,48,48,48,48,48,48,48,48,48,48
48,48,48,48,48,48,48,48,48,48,48,48,48,48,48,48,48,48,48,48,48,48,48,48,48,48,48
48,48,48,48,48,48,48,48,48,48,48,48,48,48,48,48,48,48,48,48,1,1,1,1,1,48,48
48,48,48,48,48,48,48,48,48,48,48,48,48,48,2,2,2,48,48,48,1,48,48,48,1,48,48
48,48,48,48,48,48,48,48,48,48,48,48,48,2,2,2,2,2,48,48,1,48,48,48,1,48,48
48,48,48,48,48,48,48,48,48,48,48,48,48,2,2,2,2,2,48,48,1,48,48,48,1,48,48
48,48,48,48,48,48,48,48,48,48,48,48,48,2,2,2,2,2,48,48,1,1,1,1,1,48,48
48,48,48,48,48,48,2,2,2,2,2,48,48,2,2,2,2,2,48,48,48,2,1,2,48,48,48
48,48,48,48,48,48,2,48,48,48,2,48,48,2,2,2,2,2,48,48,48,2,1,2,48,48,48
48,48,48,48,48,48,2,48,48,48,2,48,48,2,2,2,2,2,48,48,2,2,2,2,48,48,48
48,48,48,48,48,48,2,48,48,48,2,48,48,2,2,2,2,2,48,48,2,48,48,2,48,48,48
48,48,48,48,48,48,2,2,2,2,2,48,48,48,2,2,2,48,48,48,2,48,48,2,48,48,48
48,48,48,48,48,48,48,48,48,48,48,48,48,48,2,2,2,48,48,48,2,48,48,2,48,48,48
48,48,48,48,48,48,48,48,48,48,48,48,48,2,2,2,2,2,2,2,2,48,2,2,48,48,48
48,48,48,48,2,2,2,2,2,2,2,2,2,2,2,2,2,2,2,2,2,2,2,48,48,48,48
48,48,48,48,2,2,2,2,2,2,2,2,2,2,2,2,2,2,2,2,2,2,2,48,48,48,48
48,48,48,48,2,2,2,2,2,2,2,2,2,2,2,2,2,2,2,2,2,2,2,48,48,48,48
48,48,48,48,2,2,2,2,2,2,2,2,2,2,2,2,2,2,2,2,2,2,2,48,48,48,48
48,48,48,48,2,2,2,2,2,2,2,2,2,48,48,48,48,2,2,2,2,2,48,48,48,48,48
48,48,48,48,2,2,2,2,2,2,2,2,2,48,48,48,48,2,2,2,2,2,48,48,48,48,48
2,2,2,2,2,48,48,48,4,3,48,48,48,48,48,48,48,2,2,2,2,2,48,48,48,48,48
2,2,2,2,2,2,48,48,48,48,48,48,48,48,48,48,48,2,2,2,2,2,48,48,48,48,48
2,2,2,2,5,2,48,48,48,48,48,48,48,48,48,48,48,48,48,48,48,48,48,48,48,48,48
2,2,2,2,2,2,48,48,48,48,48,48,48,48,48,48,48,48,48,48,48,48,48,48,48,48,48
48,48,48,48,48,48,48,48,48,48,48,48,48,48,48,48,48,48,48,48,48,48,48,48,48,48,48
48,48,48,48,48,48,48,48,48,48,48,48,48,48,48,48,48,48,48,48,48,48,48,48,48,48,48
48,48,48,48,48,48,48,48,48,48,48,48,48,48,48,48,48,48,48,48,48,48,48,48,48,48,48
endlayer

layer
48,48,48,48,48,48,48,48,48,48,48,48,48,48,48,48,48,48,48,48,48,48,48,48,48,48,48
48,48,48,48,48,48,48,48,48,48,48,48,48,48,48,48,48,48,48,48,48,48,48,48,48,48,48
48,48,48,48,48,48,48,48,48,48,48,48,48,48,48,48,48,48,48,48,48,48,48,48,48,48,48
48,48,48,48,48,48,48,48,48,48,48,48,48,48,48,48,48,48,48,48,48,48,48,48,48,48,48
48,48,48,48,48,48,48,48,48,48,48,48,48,48,48,48,48,48,48,48,1,1,1,1,1,48,48
48,48,48,48,48,48,48,48,48,48,48,48,48,48,2,2,2,48,48,48,1,48,48,48,1,48,48
48,48,48,48,48,48,48,48,48,48,48,48,48,2,2,2,2,2,48,48,1,48,48,48,1,48,48
48,48,48,48,48,48,48,48,48,48,48,48,48,2,2,2,2,2,48,48,1,48,48,48,1,48,48
48,48,48,48,48,48,48,48,48,48,48,48,48,2,2,2,2,2,48,48,1,1,1,1,1,48,48
48,48,48,48,48,48,2,2,2,2,2,48,48,2,2,2,2,2,48,48,48,2,1,2,48,48,48
48,48,48,48,48,48,2,48,48,48,2,48,48,2,2,2,2,2,48,48,48,2,1,2,48,48,48
48,48,48,48,48,48,2,48,48,48,2,48,48,2,2,2,2,2,48,48,2,2,2,2,48,48,48
48,48,48,48,48,48,2,48,48,48,2,48,48,2,2,2,2,2,48,48,2,48,48,2,48,48,48
48,48,48,48,48,48,2,2,2,2,2,48,48,48,2,2,2,48,48,48,2,48,48,2,48,48,48
48,48,48,48,48,48,48,48,48,48,48,48,48,48,2,2,2,48,48,48,2,48,48,2,48,48,48
48,48,48,48,48,48,48,48,48,48,48,48,48,2,2,2,2,2,2,2,2,48,2,2,48,48,48
48,48,48,48,2,2,2,2,2,2,2,2,2,2,2,2,2,2,2,2,2,2,2,48,48,48,48
48,48,48,48,2,2,2,2,2,2,2,2,2,2,2,2,2,2,2,2,2,2,2,48,48,48,48
48,48,48,48,2,2,2,2,2,2,2,2,2,2,2,2,2,2,2,2,2,2,2,48,48,48,48
48,48,48,48,2,2,2,2,2,2,2,2,2,2,2,2,2,2,2,2,2,2,2,48,48,48,48
48,48,48,48,2,2,2,2,2,2,2,2,2,48,48,48,48,2,2,2,2,2,48,48,48,48,48
48,48,48,48,2,2,2,2,2,2,2,2,2,48,48,48,48,2,2,2,2,2,48,48,48,48,48
2,2,2,2,2,48,48,4,3,48,48,48,48,48,48,48,48,2,2,2,2,2,48,48,48,48,48
2,2,2,2,2,2,48,48,48,48,48,48,48,48,48,48,48,2,2,2,2,2,48,48,48,48,48
2,2,2,2,5,2,48,48,48,48,48,48,48,48,48,48,48,48,48,48,48,48,48,48,48,48,48
2,2,2,2,2,2,48,48,48,48,48,48,48,48,48,48,48,48,48,48,48,48,48,48,48,48,48
48,48,48,48,48,48,48,48,48,48,48,48,48,48,48,48,48,48,48,48,48,48,48,48,48,48,48
48,48,48,48,48,48,48,48,48,48,48,48,48,48,48,48,48,48,48,48,48,48,48,48,48,48,48
48,48,48,48,48,48,48,48,48,48,48,48,48,48,48,48,48,48,48,48,48,48,48,48,48,48,48
endlayer

layer
48,48,48,48,48,48,48,48,48,48,48,48,48,48,48,48,48,48,48,48,48,48,48,48,48,48,48
48,48,48,48,48,48,48,48,48,48,48,48,48,48,48,48,48,48,48,48,48,48,48,48,48,48,48
48,48,48,48,48,48,48,48,48,48,48,48,48,48,48,48,48,48,48,48,48,48,48,48,48,48,48
48,48,48,48,48,48,48,48,48,48,48,48,48,48,48,48,48,48,48,48,48,48,48,48,48,48,48
48,48,48,48,48,48,48,48,48,48,48,48,48,48,48,48,48,48,48,48,1,1,1,1,1,48,48
48,48,48,48,48,48,48,48,48,48,48,48,48,48,2,2,2,48,48,48,1,48,48,48,1,48,48
48,48,48,48,48,48,48,48,48,48,48,48,48,2,2,2,2,2,48,48,1,48,48,48,1,48,48
48,48,48,48,48,48,48,48,48,48,48,48,48,2,2,2,2,2,48,48,1,48,48,48,1,48,48
48,48,48,48,48,48,48,48,48,48,48,48,48,2,2,2,2,2,48,48,1,1,1,1,1,48,48
48,48,48,48,48,48,2,2,2,2,2,48,48,2,2,2,2,2,48,48,48,2,1,2,48,48,48
48,48,48,48,48,48,2,48,48,48,2,48,48,2,2,2,2,2,48,48,48,2,1,2,48,48,48
48,48,48,48,48,48,2,48,48,48,2,48,48,2,2,2,2,2,48,48,2,2,2,2,48,48,48
48,48,48,48,48,48,2,48,48,48,2,48,48,2,2,2,2,2,48,48,2,48,48,2,48,48,48
48,48,48,48,48,48,2,2,2,2,2,48,48,48,2,2,2,48,48,48,2,48,48,2,48,48,48
48,48,48,48,48,48,48,48,48,48,48,48,48,48,2,2,2,48,48,48,2,48,48,2,48,48,48
48,48,48,48,48,48,48,48,48,48,48,48,48,2,2,2,2,2,2,2,2,48,2,2,48,48,48
48,48,48,48,2,2,2,2,2,2,2,2,2,2,2,2,2,2,2,2,2,2,2,48,48,48,48
48,48,48,48,2,2,2,2,2,2,2,2,2,2,2,2,2,2,2,2,2,2,2,48,48,48,48
48,48,48,48,2,2,2,2,2,2,2,2,2,2,2,2,2,2,2,2,2,2,2,48,48,48,48
48,48,48,48,2,2,2,2,2,2,2,2,2,2,2,2,2,2,2,2,2,2,2,48,48,48,48
48,48,48,48,2,2,2,2,2,2,2,2,2,48,48,48,48,2,2,2,2,2,48,48,48,48,48
48,48,48,48,2,2,2,2,2,2,2,2,2,48,48,48,48,2,2,2,2,2,48,48,48,48,48
2,2,2,2,2,48,4,3,48,48,48,48,48,48,48,48,48,2,2,2,2,2,48,48,48,48,48
2,2,2,2,2,2,48,48,48,48,48,48,48,48,48,48,48,2,2,2,2,2,48,48,48,48,48
2,2,2,2,5,2,48,48,48,48,48,48,48,48,48,48,48,48,48,48,48,48,48,48,48,48,48
2,2,2,2,2,2,48,48,48,48,48,48,48,48,48,48,48,48,48,48,48,48,48,48,48,48,48
48,48,48,48,48,48,48,48,48,48,48,48,48,48,48,48,48,48,48,48,48,48,48,48,48,48,48
48,48,48,48,48,48,48,48,48,48,48,48,48,48,48,48,48,48,48,48,48,48,48,48,48,48,48
48,48,48,48,48,48,48,48,48,48,48,48,48,48,48,48,48,48,48,48,48,48,48,48,48,48,48
endlayer


layer
48,48,48,48,48,48,48,48,48,48,48,48,48,48,48,48,48,48,48,48,48,48,48,48,48,48,48
48,48,48,48,48,48,48,48,48,48,48,48,48,48,48,48,48,48,48,48,48,48,48,48,48,48,48
48,48,48,48,48,48,48,48,48,48,48,48,48,48,48,48,48,48,48,48,48,48,48,48,48,48,48
48,48,48,48,48,48,48,48,48,48,48,48,48,48,48,48,48,48,48,48,48,48,48,48,48,48,48
48,48,48,48,48,48,48,48,48,48,48,48,48,48,48,48,48,48,48,48,1,1,1,1,1,48,48
48,48,48,48,48,48,48,48,48,48,48,48,48,48,2,2,2,48,48,48,1,48,48,48,1,48,48
48,48,48,48,48,48,48,48,48,48,48,48,48,2,2,2,2,2,48,48,1,48,48,48,1,48,48
48,48,48,48,48,48,48,48,48,48,48,48,48,2,2,2,2,2,48,48,1,48,48,48,1,48,48
48,48,48,48,48,48,48,48,48,48,48,48,48,2,2,2,2,2,48,48,1,1,1,1,1,48,48
48,48,48,48,48,48,2,2,2,2,2,48,48,2,2,2,2,2,48,48,48,2,1,2,48,48,48
48,48,48,48,48,48,2,48,48,48,2,48,48,2,2,2,2,2,48,48,48,2,1,2,48,48,48
48,48,48,48,48,48,2,48,48,48,2,48,48,2,2,2,2,2,48,48,2,2,2,2,48,48,48
48,48,48,48,48,48,2,48,48,48,2,48,48,2,2,2,2,2,48,48,2,48,48,2,48,48,48
48,48,48,48,48,48,2,2,2,2,2,48,48,48,2,2,2,48,48,48,2,48,48,2,48,48,48
48,48,48,48,48,48,48,48,48,48,48,48,48,48,2,2,2,48,48,48,2,48,48,2,48,48,48
48,48,48,48,48,48,48,48,48,48,48,48,48,2,2,2,2,2,2,2,2,48,2,2,48,48,48
48,48,48,48,2,2,2,2,2,2,2,2,2,2,2,2,2,2,2,2,2,2,2,48,48,48,48
48,48,48,48,2,2,2,2,2,2,2,2,2,2,2,2,2,2,2,2,2,2,2,48,48,48,48
48,48,48,48,2,2,2,2,2,2,2,2,2,2,2,2,2,2,2,2,2,2,2,48,48,48,48
48,48,48,48,2,2,2,2,2,2,2,2,2,2,2,2,2,2,2,2,2,2,2,48,48,48,48
48,48,48,48,2,2,2,2,2,2,2,2,2,48,48,48,48,2,2,2,2,2,48,48,48,48,48
48,48,48,48,2,2,2,2,2,2,2,2,2,48,48,48,48,2,2,2,2,2,48,48,48,48,48
2,2,2,2,2,4,3,48,48,48,48,48,48,48,48,48,48,2,2,2,2,2,48,48,48,48,48
2,2,2,2,2,2,48,48,48,48,48,48,48,48,48,48,48,2,2,2,2,2,48,48,48,48,48
2,2,2,2,5,2,48,48,48,48,48,48,48,48,48,48,48,48,48,48,48,48,48,48,48,48,48
2,2,2,2,2,2,48,48,48,48,48,48,48,48,48,48,48,48,48,48,48,48,48,48,48,48,48
48,48,48,48,48,48,48,48,48,48,48,48,48,48,48,48,48,48,48,48,48,48,48,48,48,48,48
48,48,48,48,48,48,48,48,48,48,48,48,48,48,48,48,48,48,48,48,48,48,48,48,48,48,48
48,48,48,48,48,48,48,48,48,48,48,48,48,48,48,48,48,48,48,48,48,48,48,48,48,48,48
endlayer

layer
48,48,48,48,48,48,48,48,48,48,48,48,48,48,48,48,48,48,48,48,48,48,48,48,48,48,48
48,48,48,48,48,48,48,48,48,48,48,48,48,48,48,48,48,48,48,48,48,48,48,48,48,48,48
48,48,48,48,48,48,48,48,48,48,48,48,48,48,48,48,48,48,48,48,48,48,48,48,48,48,48
48,48,48,48,48,48,48,48,48,48,48,48,48,48,48,48,48,48,48,48,48,48,48,48,48,48,48
48,48,48,48,48,48,48,48,48,48,48,48,48,48,48,48,48,48,48,48,2,2,2,2,2,48,48
48,48,48,48,48,48,48,48,48,48,48,48,48,48,2,2,2,48,48,48,2,2,2,2,2,48,48
48,48,48,48,48,48,48,48,48,48,48,48,48,2,2,2,2,2,48,48,2,2,2,2,2,48,48
48,48,48,48,48,48,48,48,48,48,48,48,48,2,2,4,2,2,48,48,2,2,2,2,2,48,48
48,48,48,48,48,48,48,48,48,48,48,48,48,2,4,48,4,2,48,48,2,2,2,2,2,48,48
48,48,48,48,48,48,2,2,2,2,2,48,48,2,48,48,6,2,48,48,48,2,2,2,48,48,48
48,48,48,48,48,48,2,48,48,48,2,48,48,2,48,48,7,2,48,48,48,2,2,2,48,48,48
48,48,48,48,48,48,2,48,48,48,2,48,2,3,48,48,8,2,48,48,2,2,2,2,48,48,48
48,48,48,48,48,48,2,48,48,48,2,48,48,2,48,48,48,2,48,48,2,9,9,2,48,48,48
48,48,48,48,48,48,2,2,2,2,2,48,48,48,2,48,2,48,48,48,2,9,9,2,48,48,48
48,48,48,48,48,48,48,48,48,48,48,48,48,48,10,48,10,48,48,48,2,9,9,2,48,48,48
48,48,48,48,48,48,48,48,48,48,48,48,48,2,11,48,11,2,10,10,2,2,2,2,48,48,48
48,48,48,48,2,2,2,2,2,2,2,2,2,11,48,48,12,11,10,48,48,4,2,48,48,48,48
48,48,48,48,2,2,48,13,13,13,13,11,2,11,48,48,48,48,48,48,48,48,10,48,48,48,48
48,48,48,48,2,12,48,48,10,48,10,14,2,11,48,48,48,11,10,48,48,48,10,48,48,48,48
48,48,48,48,2,48,48,48,48,48,48,48,2,2,11,11,11,2,11,48,11,2,10,48,48,48,48
48,48,48,48,2,48,48,48,48,48,48,15,2,48,48,48,48,11,48,48,12,11,48,48,48,48,48
48,48,48,48,2,16,2,2,2,2,2,2,2,48,48,48,48,11,48,48,48,11,48,48,48,48,48
2,2,2,2,48,48,48,48,48,48,48,48,48,48,48,48,48,11,48,48,48,11,48,48,48,48,48
2,17,17,2,48,10,48,48,48,48,48,48,48,48,48,48,48,2,11,11,11,2,48,48,48,48,48
2,17,17,5,18,10,48,48,48,48,48,48,48,48,48,48,48,48,48,48,48,48,48,48,48,48,48
2,2,2,2,10,10,48,48,48,48,48,48,48,48,48,48,48,48,48,48,48,48,48,48,48,48,48
48,48,48,48,48,48,48,48,48,48,48,48,48,48,48,48,48,48,48,48,48,48,48,48,48,48,48
48,48,48,48,48,48,48,48,48,48,48,48,48,48,48,48,48,48,48,48,48,48,48,48,48,48,48
48,48,48,48,48,48,48,48,48,48,48,48,48,48,48,48,48,48,48,48,48,48,48,48,48,48,48
endlayer

layer
48,48,48,48,48,48,48,48,48,48,48,48,48,48,48,48,48,48,48,48,48,48,48,48,48,48,48
48,48,48,48,48,48,48,48,48,48,48,48,48,48,48,48,48,48,48,48,48,48,48,48,48,48,48
48,48,48,48,48,48,48,48,48,48,48,48,48,48,48,48,48,48,48,48,48,48,48,48,48,48,48
48,48,48,48,48,48,48,48,48,48,48,48,48,48,48,48,48,48,48,48,48,48,48,48,48,48,48
48,48,48,48,48,48,48,48,48,48,48,48,48,48,48,48,48,48,48,48,2,11,11,11,2,48,48
48,48,48,48,48,48,48,48,48,48,48,48,48,48,2,2,2,48,48,48,11,48,48,48,11,48,48
48,48,48,48,48,48,48,48,48,48,48,48,48,2,3,48,19,2,48,48,11,48,48,48,11,48,48
48,48,48,48,48,48,48,48,48,48,48,48,48,2,48,48,48,2,48,48,11,48,48,48,11,48,48
48,48,48,48,48,48,48,48,48,48,48,48,48,2,48,48,48,2,48,48,2,11,48,11,2,48,48
48,48,48,48,48,48,2,2,2,2,2,48,48,2,48,48,48,2,48,48,48,10,48,10,48,48,48
48,48,48,48,48,48,2,2,2,2,2,2,2,2,48,48,7,2,48,48,48,10,48,10,48,48,48
48,48,48,48,48,48,2,2,2,2,2,3,48,48,48,48,48,20,48,48,1,11,48,1,48,48,48
48,48,48,48,48,48,2,2,2,2,2,2,2,2,48,48,48,2,48,48,11,10,48,11,48,48,48
48,48,48,48,48,48,2,2,2,2,2,48,48,48,2,48,2,48,48,48,11,48,48,11,48,48,48
48,48,48,48,48,48,48,48,48,48,48,48,48,48,48,48,48,48,48,48,11,48,21,11,48,48,48
48,48,48,48,48,48,48,48,48,48,48,48,48,2,11,48,11,2,48,48,1,48,11,1,48,48,48
48,48,48,48,2,11,20,20,11,20,20,11,2,11,48,48,12,11,48,48,48,48,10,48,48,48,48
48,48,48,48,11,11,48,48,48,48,48,48,1,20,48,48,48,48,48,48,48,48,10,48,48,48,48
48,48,48,48,20,12,48,48,22,48,22,48,20,11,48,48,48,11,48,48,48,48,48,48,48,48,48
48,48,48,48,20,48,48,48,48,48,48,48,20,2,11,20,11,2,11,48,11,2,48,48,48,48,48
48,48,48,48,11,48,48,48,48,48,48,48,11,48,48,48,48,11,48,48,12,11,48,48,48,48,48
48,48,48,48,2,23,11,11,20,20,20,11,2,48,48,48,48,20,48,48,48,20,48,48,48,48,48
2,2,2,2,48,48,48,48,48,48,48,48,48,48,48,48,48,11,48,48,48,11,48,48,48,48,48
2,17,17,2,48,48,48,48,48,48,48,48,48,48,48,48,48,2,11,20,11,2,48,48,48,48,48
2,17,17,18,48,48,48,48,48,48,48,48,48,48,48,48,48,48,48,48,48,48,48,48,48,48,48
2,2,2,2,48,48,48,48,48,48,48,48,48,48,48,48,48,48,48,48,48,48,48,48,48,48,48
48,48,48,48,48,48,48,48,48,48,48,48,48,48,48,48,48,48,48,48,48,48,48,48,48,48,48
48,48,48,48,48,48,48,48,48,48,48,48,48,48,48,48,48,48,48,48,48,48,48,48,48,48,48
48,48,48,48,48,48,48,48,48,48,48,48,48,48,48,48,48,48,48,48,48,48,48,48,48,48,48
endlayer

layer
48,48,48,48,48,48,48,48,48,48,48,48,48,48,48,48,48,48,48,48,48,48,48,48,48,48,48
48,48,48,48,48,48,48,48,48,48,48,48,48,48,48,48,48,48,48,48,48,48,48,48,48,48,48
48,48,48,48,48,48,48,48,48,48,48,48,48,48,48,48,48,48,48,48,48,48,48,48,48,48,48
48,48,48,48,48,48,48,48,48,48,48,48,48,48,48,48,48,48,48,48,48,48,48,48,48,48,48
48,48,48,48,48,2,2,2,2,2,48,48,48,48,48,48,48,48,48,48,2,11,20,11,2,48,48
48,48,48,48,48,2,2,2,2,2,48,48,48,48,2,20,2,48,48,48,11,48,48,48,11,48,48
48,48,48,48,48,2,2,2,2,2,48,48,48,2,48,48,48,2,48,48,20,48,48,48,20,48,48
48,48,48,48,48,2,2,2,2,2,48,48,48,20,48,48,48,20,48,48,11,48,48,48,11,48,48
48,48,48,48,48,2,2,2,2,2,48,48,48,2,48,48,48,2,48,48,2,11,48,11,2,48,48
48,48,48,48,48,48,2,4,11,11,2,48,48,2,48,48,48,2,48,48,48,48,48,48,48,48,48
48,48,48,48,48,48,11,48,48,12,11,10,10,2,48,48,7,2,48,48,48,48,48,48,48,48,48
48,48,48,48,48,48,11,48,48,48,48,48,48,48,48,48,48,20,48,48,1,11,48,1,48,48,48
48,48,48,48,48,48,11,48,48,48,11,10,10,2,48,48,48,2,48,48,11,22,48,11,48,48,48
48,48,48,48,48,48,2,11,11,11,2,48,48,48,2,2,2,48,48,48,20,48,48,20,48,48,48
48,48,48,48,48,48,48,48,48,48,48,48,48,48,48,48,48,48,48,48,11,48,21,11,48,48,48
48,48,48,48,48,48,48,48,48,48,48,48,48,2,11,11,11,2,48,48,1,48,11,1,48,48,48
48,48,48,48,2,11,11,11,11,11,11,11,2,11,48,48,12,11,48,48,48,48,48,48,48,48,48
48,48,48,48,11,24,24,24,24,24,24,24,11,11,48,48,48,11,48,48,48,48,48,48,48,48,48
48,48,48,48,20,12,48,48,48,48,48,48,20,11,48,48,48,11,48,48,48,48,48,48,48,48,48
48,48,48,48,20,48,48,48,48,48,48,48,20,2,11,11,11,2,11,11,11,2,48,48,48,48,48
48,48,48,48,11,48,48,48,48,48,48,48,11,48,48,48,48,11,48,48,12,11,48,48,48,48,48
48,48,48,48,2,11,11,11,20,20,20,11,2,48,48,48,48,11,48,48,48,11,48,48,48,48,48
2,2,2,2,48,48,48,48,48,48,48,48,48,48,48,48,48,11,48,48,48,11,48,48,48,48,48
2,17,17,2,48,48,48,48,48,48,48,48,48,48,48,48,48,2,11,11,11,2,48,48,48,48,48
2,17,17,2,48,48,48,48,48,48,48,48,48,48,48,48,48,48,48,48,48,48,48,48,48,48,48
2,2,2,2,48,48,48,48,48,48,48,48,48,48,48,48,48,48,48,48,48,48,48,48,48,48,48
48,48,48,48,48,48,48,48,48,48,48,48,48,48,48,48,48,48,48,48,48,48,48,48,48,48,48
48,48,48,48,48,48,48,48,48,48,48,48,48,48,48,48,48,48,48,48,48,48,48,48,48,48,48
48,48,48,48,48,48,48,48,48,48,48,48,48,48,48,48,48,48,48,48,48,48,48,48,48,48,48
endlayer

layer
48,48,48,48,48,48,48,48,48,48,48,48,48,48,48,48,48,48,48,48,48,48,48,48,48,48,48
48,48,48,48,48,48,48,48,48,48,48,48,48,48,48,48,48,48,48,48,48,48,48,48,48,48,48
48,48,48,48,48,48,48,48,48,48,48,48,48,48,48,48,48,48,48,48,48,48,48,48,48,48,48
48,48,48,48,48,48,48,48,48,48,48,48,48,48,48,48,48,48,48,48,48,48,48,48,48,48,48
48,48,48,48,48,2,11,11,11,2,48,48,48,48,48,48,48,48,48,48,2,11,11,11,2,48,48
48,48,48,48,48,11,48,48,48,11,48,48,48,48,2,2,2,48,48,48,11,48,48,48,11,48,48
48,48,48,48,48,11,48,48,48,11,48,48,48,2,48,48,48,2,48,48,11,48,48,48,11,48,48
48,48,48,48,48,11,48,48,48,11,48,48,48,2,48,48,48,2,48,48,11,48,48,48,11,48,48
48,48,48,48,48,2,11,48,11,2,48,48,48,2,48,48,48,2,48,48,2,11,11,11,2,48,48
48,48,48,48,48,48,2,48,11,11,2,48,48,2,2,2,2,2,48,48,48,48,48,48,48,48,48
48,48,48,48,48,48,11,48,48,12,11,48,48,2,2,2,7,2,48,48,48,48,48,48,48,48,48
48,48,48,48,48,48,20,48,48,48,48,48,48,2,2,2,2,2,48,48,1,11,11,1,48,48,48
48,48,48,48,48,48,11,48,48,48,11,48,48,2,2,2,2,2,48,48,11,48,48,11,48,48,48
48,48,48,48,48,48,2,11,20,11,2,48,48,2,2,2,2,2,48,48,11,48,48,11,48,48,48
48,48,48,48,48,48,48,48,48,48,48,48,48,48,48,48,48,48,48,48,11,48,21,11,48,48,48
48,48,48,48,48,48,48,48,48,48,48,48,48,1,1,1,1,1,48,48,1,11,11,1,48,48,48
48,48,48,48,2,11,11,11,11,11,11,11,2,1,11,11,12,1,48,48,48,48,48,48,48,48,48
48,48,48,48,11,11,11,11,11,11,11,11,11,1,11,11,11,1,1,1,48,48,48,48,48,48,48
48,48,48,48,11,12,48,48,48,48,48,48,11,1,11,11,11,1,11,1,48,48,48,48,48,48,48
48,48,48,48,11,48,48,48,48,48,48,48,11,1,1,1,1,1,1,1,1,1,48,48,48,48,48
48,48,48,48,11,11,11,11,11,11,11,11,11,48,48,48,48,1,11,11,12,1,48,48,48,48,48
48,48,48,48,2,11,11,11,11,11,11,11,2,48,48,48,48,1,11,11,11,1,48,48,48,48,48
2,2,2,2,48,48,48,48,48,48,48,48,48,48,48,48,48,1,11,11,11,1,48,48,48,48,48
2,17,17,2,48,48,48,48,48,48,48,48,48,48,48,48,48,1,1,1,1,1,48,48,48,48,48
2,17,17,2,48,48,48,48,48,48,48,48,48,48,48,48,48,48,48,48,48,48,48,48,48,48,48
2,2,2,2,48,48,48,48,48,48,48,48,48,48,48,48,48,48,48,48,48,48,48,48,48,48,48
48,48,48,48,48,48,48,48,48,48,48,48,48,48,48,48,48,48,48,48,48,48,48,48,48,48,48
48,48,48,48,48,48,48,48,48,48,48,48,48,48,48,48,48,48,48,48,48,48,48,48,48,48,48
48,48,48,48,48,48,48,48,48,48,48,48,48,48,48,48,48,48,48,48,48,48,48,48,48,48,48
endlayer

layer
48,48,48,48,48,48,48,48,48,48,48,48,48,48,48,48,48,48,48,48,48,48,48,48,48,48,48
48,48,48,48,48,48,48,48,48,48,48,48,48,48,48,48,48,48,48,48,48,48,48,48,48,48,48
48,48,48,48,48,48,48,48,48,48,48,48,48,48,48,48,48,48,48,48,48,48,48,48,48,48,48
48,48,48,48,48,48,48,48,48,48,48,48,48,48,48,48,48,48,48,48,48,48,48,48,48,48,48
48,48,48,48,48,2,11,20,11,2,48,48,2,2,2,2,2,48,48,48,1,1,1,1,1,48,48
48,48,48,48,48,11,48,48,48,11,48,48,2,2,2,2,2,48,48,48,1,11,11,11,1,48,48
48,48,48,48,48,20,48,48,48,20,48,48,2,2,2,2,2,48,48,48,1,11,11,11,1,48,48
48,48,48,48,48,11,48,48,48,11,48,48,2,2,2,2,2,48,48,48,1,11,11,11,1,48,48
48,48,48,48,48,2,11,48,11,2,48,48,2,2,2,2,2,48,48,48,1,1,1,1,1,48,48
48,48,48,48,48,48,2,48,11,11,2,48,48,48,2,4,2,48,48,48,48,1,1,1,48,48,48
48,48,48,48,48,48,11,48,48,12,11,48,48,2,48,48,7,2,48,48,48,1,1,1,48,48,48
48,48,48,48,48,48,11,48,48,48,11,48,48,2,48,48,48,2,48,48,48,1,1,1,48,48,48
48,48,48,48,48,48,11,48,48,48,11,48,48,2,48,48,48,2,48,48,2,2,2,2,2,48,48
48,48,48,48,48,48,2,11,11,11,2,48,48,48,2,2,2,48,48,48,2,2,2,2,2,48,48
48,48,48,48,48,48,48,48,48,48,48,48,48,48,48,48,48,48,48,48,2,2,21,2,2,48,48
48,48,48,48,25,25,25,25,25,25,25,25,25,10,10,10,10,10,48,48,2,2,2,2,2,48,48
48,48,48,48,2,2,2,2,2,2,2,2,2,10,48,48,48,10,48,48,2,2,2,2,2,48,48
48,48,48,48,2,2,2,2,2,2,2,2,2,10,48,48,48,10,10,10,48,48,48,48,48,48,48
48,48,48,48,2,12,2,2,2,2,2,2,2,10,48,48,48,48,48,10,48,48,48,48,48,48,48
48,48,48,48,2,2,2,2,2,2,2,2,2,10,10,10,10,10,48,10,10,10,48,48,48,48,48
48,48,48,48,2,2,2,2,2,2,2,2,2,48,48,48,48,10,48,48,48,10,48,48,48,48,48
48,48,48,48,2,2,2,2,2,2,2,2,2,48,48,48,48,10,48,48,7,1,48,48,48,48,48
2,2,2,2,13,13,13,13,13,13,13,13,13,48,48,48,48,10,48,48,48,10,48,48,48,48,48
2,17,17,2,48,48,48,48,48,48,48,48,48,48,48,48,48,10,10,10,10,10,48,48,48,48,48
2,17,17,2,48,48,48,48,48,48,48,48,48,48,48,48,48,48,48,48,48,48,48,48,48,48,48
2,2,2,2,48,48,48,48,48,48,48,48,48,48,48,48,48,48,48,48,48,48,48,48,48,48,48
48,48,48,48,48,48,48,48,48,48,48,48,48,48,48,48,48,48,48,48,48,48,48,48,48,48,48
48,48,48,48,48,48,48,48,48,48,48,48,48,48,48,48,48,48,48,48,48,48,48,48,48,48,48
48,48,48,48,48,48,48,48,48,48,48,48,48,48,48,48,48,48,48,48,48,48,48,48,48,48,48
endlayer


layer
0,0,0,0,0,0,0,0,0,0,0,0,0,0,0,0,0,0,0,0,0,0,0,0,0,0,0
0,0,0,0,0,0,0,0,0,0,0,0,0,0,0,0,0,0,0,0,0,0,0,0,0,0,0
0,0,0,0,0,0,0,0,0,0,0,0,0,0,0,0,0,0,0,0,0,2,2,2,0,0,0
0,0,0,0,0,0,0,0,0,0,0,0,0,0,0,0,0,0,0,0,2,2,2,2,2,0,0
0,0,0,0,0,2,11,11,11,2,0,0,2,11,11,11,2,0,0,0,2,2,2,2,2,0,0
0,0,0,0,0,11,0,0,0,11,0,0,11,0,0,12,11,0,0,0,2,2,2,2,2,0,0
0,0,0,0,0,11,0,0,0,11,0,0,11,0,0,0,11,0,0,0,2,2,2,2,2,0,0
0,0,0,0,0,11,0,0,0,11,0,0,11,0,0,0,11,0,0,0,2,2,2,2,2,0,0
0,0,0,0,0,2,11,11,11,2,0,0,2,11,11,0,2,0,0,0,0,1,4,1,0,0,0
0,0,0,0,0,0,1,1,1,1,1,0,0,0,2,0,2,0,0,0,0,10,0,10,0,0,0
0,0,0,0,0,0,1,11,11,12,1,0,0,2,0,0,7,2,0,0,0,10,0,10,0,0,0
0,0,0,0,0,0,1,11,11,11,1,0,0,20,0,0,0,20,0,0,0,10,0,10,0,0,0
0,0,0,0,0,0,1,11,11,11,1,0,0,2,0,0,0,2,0,0,2,11,0,11,2,0,0
0,0,0,0,0,0,1,1,1,1,1,0,0,0,2,20,2,0,0,0,11,0,0,12,11,0,0
0,0,0,0,0,0,0,0,0,0,0,0,0,0,0,0,0,0,0,0,11,0,0,0,11,0,0
0,0,0,0,0,0,0,0,0,0,0,0,0,0,0,0,0,0,0,0,11,0,0,0,11,0,0
0,0,0,0,25,25,25,25,25,25,25,25,25,0,0,0,0,0,0,0,2,11,11,11,2,0,0
0,0,0,0,2,2,2,2,2,2,2,2,2,0,0,0,0,0,0,0,0,0,0,0,0,0,0
0,0,0,0,2,12,2,2,2,2,2,2,2,0,0,0,0,0,0,0,0,0,0,0,0,0,0
0,0,0,0,2,2,2,2,2,2,2,2,2,0,0,0,0,0,0,0,10,10,0,0,0,0,0
0,0,0,0,2,2,2,2,2,2,2,2,2,0,0,0,0,10,0,0,0,10,0,0,0,0,0
0,0,0,0,13,13,13,13,13,13,13,13,13,0,0,0,0,0,0,0,7,1,0,0,0,0,0
2,2,2,2,0,0,0,0,0,0,0,0,0,0,0,0,0,10,0,0,0,10,0,0,0,0,0
2,17,6,2,0,0,0,0,0,0,0,0,0,0,0,0,0,10,10,0,10,10,0,0,0,0,0
2,17,17,2,0,0,0,0,0,0,0,0,0,0,0,0,0,0,0,0,0,0,0,0,0,0,0
2,2,2,2,0,0,0,0,0,0,0,0,0,0,0,0,0,0,0,0,0,0,0,0,0,0,0
0,0,0,0,0,0,0,0,0,0,0,0,0,0,0,0,0,0,0,0,0,0,0,0,0,0,0
0,0,0,0,0,0,0,0,0,0,0,0,0,0,0,0,0,0,0,0,0,0,0,0,0,0,0
0,0,0,0,0,0,0,0,0,0,0,0,0,0,0,0,0,0,0,0,0,0,0,0,0,0,0
endlayer

layer
0,0,0,0,0,0,0,0,0,0,0,0,0,0,0,0,0,0,0,0,0,0,0,0,0,0,0
0,0,0,0,0,0,0,0,0,0,0,0,0,0,0,0,0,0,0,0,0,0,0,0,0,0,0
0,0,0,0,0,0,0,0,0,0,0,0,0,0,0,0,0,0,0,0,0,10,10,10,0,0,0
0,0,0,0,0,0,0,0,0,0,0,0,0,0,0,0,0,0,0,0,2,11,0,11,2,0,0
0,0,0,0,0,1,1,1,1,1,0,0,2,11,20,11,2,0,0,0,11,0,0,0,11,0,0
0,0,0,0,0,1,2,2,2,1,0,0,11,0,0,12,11,0,0,0,11,0,0,0,11,0,0
0,0,0,0,0,1,2,2,2,1,0,0,20,0,0,0,20,0,0,0,11,0,0,0,11,0,0
0,0,0,0,0,1,2,2,2,1,0,0,11,0,0,0,11,0,0,0,2,11,0,11,2,0,0
0,0,0,0,0,1,2,2,2,1,0,0,2,11,10,0,2,0,0,0,0,10,0,10,0,0,0
0,0,0,0,0,2,2,2,2,2,10,0,0,0,2,0,2,0,0,0,0,10,0,10,0,0,0
0,0,0,0,0,0,10,4,0,0,10,0,0,2,0,0,7,2,0,0,0,0,0,0,0,0,0
0,0,0,0,0,0,10,0,0,0,10,0,0,20,0,0,0,20,0,0,0,0,0,0,0,0,0
0,0,0,0,0,0,10,0,0,0,10,0,0,2,0,0,0,2,0,0,2,11,0,11,2,0,0
0,0,0,0,0,0,10,10,10,10,10,0,0,0,2,20,2,0,0,0,11,0,0,12,11,0,0
0,0,0,0,0,0,0,0,0,0,0,0,0,0,0,0,0,0,0,0,20,0,0,0,20,0,0
0,0,0,0,0,0,0,0,0,0,0,0,0,0,0,0,0,0,0,0,11,0,0,0,11,0,0
0,0,0,0,0,0,0,0,0,0,0,0,0,0,0,0,0,0,0,0,2,11,20,11,2,0,0
0,0,0,0,25,25,25,25,25,25,25,25,25,0,0,0,0,0,0,0,0,0,0,0,0,0,0
0,0,0,0,2,12,2,2,2,2,2,2,2,0,0,0,0,0,0,0,0,0,0,0,0,0,0
0,0,0,0,2,2,2,2,2,2,2,2,2,0,0,0,0,0,0,0,0,0,0,0,0,0,0
0,0,0,0,13,13,13,13,13,13,13,13,13,0,0,0,0,2,2,2,2,2,0,0,0,0,0
0,0,0,0,0,0,0,0,0,0,0,0,0,0,0,0,0,2,2,2,7,2,0,0,0,0,0
2,2,2,2,0,0,0,0,0,0,0,0,0,0,0,0,0,2,2,2,2,2,0,0,0,0,0
2,17,17,2,0,0,0,0,0,0,0,0,0,0,0,0,0,2,2,2,2,2,0,0,0,0,0
2,17,17,2,0,0,0,0,0,0,0,0,0,0,0,0,0,2,2,2,2,2,0,0,0,0,0
2,2,2,2,0,0,0,0,0,0,0,0,0,0,0,0,0,0,0,0,0,0,0,0,0,0,0
0,0,0,0,0,0,0,0,0,0,0,0,0,0,0,0,0,0,0,0,0,0,0,0,0,0,0
0,0,0,0,0,0,0,0,0,0,0,0,0,0,0,0,0,0,0,0,0,0,0,0,0,0,0
0,0,0,0,0,0,0,0,0,0,0,0,0,0,0,0,0,0,0,0,0,0,0,0,0,0,0
endlayer

layer
0,0,0,0,0,0,0,0,0,0,0,0,0,0,0,0,0,0,0,0,0,0,0,0,0,0,0
0,0,0,0,0,0,0,0,0,0,0,0,0,0,0,0,0,0,0,0,0,0,0,0,0,0,0
0,0,0,0,0,0,0,0,0,0,0,0,0,0,0,0,0,0,0,0,0,0,0,0,0,0,0
0,0,0,0,0,0,0,0,0,0,0,0,0,0,0,0,0,0,0,0,2,11,0,11,2,0,0
0,0,0,0,0,10,10,10,10,10,0,0,2,11,11,11,2,0,0,0,11,0,0,0,11,0,0
0,0,0,0,0,2,11,11,11,2,0,11,11,0,0,12,11,0,0,0,20,0,0,0,20,0,0
0,0,0,0,0,11,0,0,12,11,0,11,11,0,0,0,11,0,0,0,11,0,0,0,11,0,0
0,0,0,0,0,11,0,0,0,11,0,11,11,0,0,0,11,0,0,0,2,11,0,11,2,0,0
0,0,0,0,0,11,0,0,0,11,0,0,2,11,11,11,2,0,0,0,0,0,0,0,0,0,0
0,0,0,0,0,2,11,0,11,2,0,0,0,0,2,2,2,0,0,0,0,0,0,0,0,0,0
0,0,0,0,0,0,0,0,0,0,0,0,0,2,0,0,7,2,0,0,0,0,0,0,0,0,0
0,0,0,0,0,0,0,0,0,0,0,0,0,2,0,0,0,2,0,0,0,0,0,0,0,0,0
0,0,0,0,0,0,0,0,0,0,0,0,0,2,0,0,0,2,0,0,2,11,11,11,2,0,0
0,0,0,0,0,0,0,0,0,0,0,0,0,0,2,2,2,0,0,0,11,0,0,12,11,0,0
0,0,0,0,0,0,0,0,0,0,0,0,0,0,0,0,0,0,0,0,11,0,0,0,11,0,0
0,0,0,0,0,0,0,0,0,0,0,0,0,0,0,0,0,0,0,0,11,0,0,0,11,0,0
0,0,0,0,0,0,0,0,0,0,0,0,0,0,0,0,0,0,0,0,2,11,11,11,2,0,0
0,0,2,2,2,2,2,0,0,0,0,0,0,0,0,0,0,0,0,0,0,0,0,0,0,0,0
0,0,2,2,2,12,2,11,11,11,11,11,11,0,0,0,0,0,0,0,0,0,0,0,0,0,0
0,0,2,2,2,2,2,11,11,11,11,11,11,26,0,0,0,0,0,0,0,0,0,0,0,0,0
0,0,2,2,2,2,2,11,11,11,11,11,11,0,0,0,0,2,11,11,11,2,0,0,0,0,0
0,0,2,2,2,2,2,0,0,0,0,0,0,0,0,0,0,11,0,0,12,11,0,0,0,0,0
2,2,2,2,0,0,0,0,0,0,0,0,0,0,0,0,0,11,0,0,0,11,0,0,0,0,0
2,17,17,2,0,0,0,0,0,0,0,0,0,0,0,0,0,11,0,0,0,11,0,0,0,0,0
2,17,17,2,0,0,0,0,0,0,0,0,0,0,0,0,0,2,11,11,11,2,0,0,0,0,0
2,2,2,2,0,0,0,0,0,0,0,0,0,0,0,0,0,0,0,0,0,0,0,0,0,0,0
0,0,0,0,0,0,0,0,0,0,0,0,0,0,0,0,0,0,0,0,0,0,0,0,0,0,0
0,0,0,0,0,0,0,0,0,0,0,0,0,0,0,0,0,0,0,0,0,0,0,0,0,0,0
0,0,0,0,0,0,0,0,0,0,0,0,0,0,0,0,0,0,0,0,0,0,0,0,0,0,0
endlayer

layer
0,0,0,0,0,0,0,0,0,0,0,0,0,0,0,0,0,0,0,0,0,0,0,0,0,0,0
0,0,0,0,0,0,0,0,0,0,0,0,0,0,0,0,0,0,0,0,0,0,0,0,0,0,0
0,0,0,0,0,0,0,0,0,0,0,0,0,0,0,0,0,0,0,0,0,0,0,0,0,0,0
0,0,0,0,0,0,0,0,0,0,0,0,0,0,0,0,0,0,0,0,2,11,11,11,2,0,0
0,0,0,0,0,0,0,0,0,0,0,0,1,1,1,1,1,0,0,0,11,0,0,0,11,0,0
0,0,0,0,0,2,11,20,11,2,11,1,1,11,11,12,1,0,0,0,11,0,0,0,11,0,0
0,0,0,0,0,11,0,0,12,11,11,1,1,11,11,11,1,2,2,2,11,0,0,0,11,0,0
0,0,0,0,0,20,0,0,0,20,11,1,1,11,11,11,1,2,2,2,2,11,11,11,2,0,0
0,0,0,0,0,11,0,0,0,11,0,0,1,1,1,1,1,2,2,2,0,0,11,11,11,0,0
0,0,0,0,0,2,11,0,11,2,0,0,0,2,2,2,2,2,2,2,0,0,11,11,11,0,0
0,0,0,0,0,0,0,0,0,0,0,0,0,2,2,2,7,2,2,2,0,0,11,11,11,0,0
0,0,0,0,0,0,0,0,0,0,0,0,0,2,2,2,2,2,0,0,0,0,11,11,11,0,0
0,0,0,0,0,0,0,0,0,0,0,0,0,2,2,2,2,2,0,0,1,1,1,1,1,0,0
0,0,0,0,0,0,0,0,0,0,0,0,0,2,2,2,2,2,0,0,1,11,11,12,1,0,0
0,0,0,0,0,0,0,0,0,0,0,0,0,0,0,0,0,0,0,0,1,11,11,11,1,0,0
0,0,0,0,0,0,0,0,0,0,0,0,0,0,0,0,0,0,0,0,1,11,11,11,1,0,0
0,0,0,0,0,0,0,0,0,0,0,0,0,0,0,0,0,0,0,0,1,1,1,1,1,0,0
0,0,2,11,11,11,2,0,0,0,0,0,0,0,0,0,0,0,0,0,0,0,0,0,0,0,0
0,0,11,0,0,12,11,10,10,10,10,10,11,11,0,0,0,0,0,0,0,0,0,0,0,0,0
0,0,11,0,0,0,0,0,0,0,0,0,14,11,26,0,0,0,0,0,0,0,0,0,0,0,0
0,0,11,0,0,0,11,10,10,10,10,10,11,11,0,0,0,2,11,20,11,2,0,0,0,0,0
0,0,2,11,11,11,2,0,0,0,0,0,0,0,0,0,0,11,0,0,12,11,0,0,0,0,0
2,2,2,2,0,0,0,0,0,0,0,0,0,0,0,0,0,20,0,0,0,20,0,0,0,0,0
2,17,17,2,0,0,0,0,0,0,0,0,0,0,0,0,0,11,0,0,0,11,0,0,0,0,0
2,17,17,2,0,0,0,0,0,0,0,0,0,0,0,0,0,2,11,20,11,2,0,0,0,0,0
2,2,2,2,0,0,0,0,0,0,0,0,0,0,0,0,0,0,0,0,0,0,0,0,0,0,0
0,0,0,0,0,0,0,0,0,0,0,0,0,0,0,0,0,0,0,0,0,0,0,0,0,0,0
0,0,0,0,0,0,0,0,0,0,0,0,0,0,0,0,0,0,0,0,0,0,0,0,0,0,0
0,0,0,0,0,0,0,0,0,0,0,0,0,0,0,0,0,0,0,0,0,0,0,0,0,0,0
endlayer

layer
0,0,0,0,0,0,0,0,0,0,0,0,0,0,0,0,0,0,0,0,0,0,0,0,0,0,0
0,0,0,0,0,0,0,0,0,0,0,0,0,0,0,0,0,0,0,0,0,0,0,0,0,0,0
0,0,0,0,0,0,0,0,0,0,0,0,0,0,0,0,0,0,0,0,0,0,0,0,0,0,0
0,0,0,0,0,0,0,0,0,0,0,0,0,0,0,0,0,0,0,0,1,1,1,1,1,0,0
0,0,0,0,0,0,0,0,0,0,0,0,10,10,10,10,10,0,0,0,1,11,11,11,1,0,0
0,0,0,0,0,2,11,11,11,2,11,1,10,0,0,0,10,0,0,0,1,11,11,11,1,0,0
0,0,0,0,0,11,0,0,12,11,11,27,0,0,0,0,2,2,2,2,1,11,11,11,1,0,0
0,0,0,0,0,11,0,0,0,11,11,1,10,0,0,0,2,17,17,2,1,1,1,1,1,0,0
0,0,0,0,0,11,0,0,0,11,0,0,10,10,10,10,2,17,17,2,0,0,1,13,1,0,0
0,0,0,0,0,2,11,11,11,2,0,0,0,0,2,2,2,17,17,2,0,0,10,0,10,0,0
0,0,0,0,0,0,0,0,0,11,0,0,0,2,0,0,0,2,2,2,0,0,10,0,10,0,0
0,0,0,0,0,0,0,0,0,11,0,0,0,2,0,0,0,2,0,0,0,0,10,0,10,0,0
0,0,0,0,0,0,0,0,0,11,0,0,0,2,0,0,6,2,0,0,10,10,10,0,10,0,0
0,0,0,0,0,0,0,0,0,0,0,0,0,0,2,2,2,0,0,0,10,0,0,0,10,0,0
0,0,0,0,0,0,0,0,0,0,0,0,0,0,0,0,0,0,0,0,10,0,0,0,10,0,0
0,0,0,0,0,0,0,0,0,0,0,0,0,0,0,0,0,0,0,0,10,0,0,0,10,0,0
0,0,0,0,0,0,0,0,0,0,0,0,0,0,0,0,0,0,0,0,10,10,10,10,10,0,0
0,0,2,11,20,11,2,0,0,0,0,0,0,0,0,0,0,0,0,0,0,0,0,0,0,0,0
0,0,11,0,0,12,11,0,0,0,10,10,10,11,11,0,0,0,0,0,0,0,0,0,0,0,0
0,0,20,0,0,0,0,0,0,0,0,0,0,14,11,26,0,0,0,0,0,0,0,0,0,0,0
0,0,11,0,0,0,11,0,0,0,0,10,10,11,11,0,0,2,11,11,11,2,0,0,0,0,0
0,0,2,11,20,11,2,0,0,0,0,0,0,0,0,0,0,11,0,0,12,11,0,0,0,0,0
2,2,2,2,0,0,0,0,0,0,0,0,0,0,0,11,11,11,0,0,0,11,0,0,0,0,0
2,17,17,2,0,0,0,0,0,0,0,0,0,0,0,0,0,11,0,0,0,11,0,0,0,0,0
2,17,17,2,0,0,0,0,0,0,0,0,0,0,0,0,0,2,11,11,11,2,0,0,0,0,0
2,2,2,2,0,0,0,0,0,0,0,0,0,0,0,0,0,0,0,0,0,0,0,0,0,0,0
0,0,0,0,0,0,0,0,0,0,0,0,0,0,0,0,0,0,0,0,0,0,0,0,0,0,0
0,0,0,0,0,0,0,0,0,0,0,0,0,0,0,0,0,0,0,0,0,0,0,0,0,0,0
0,0,0,0,0,0,0,0,0,0,0,0,0,0,0,0,0,0,0,0,0,0,0,0,0,0,0
endlayer

layer
0,0,0,0,0,0,0,0,0,0,0,0,0,0,0,0,0,0,0,0,0,0,0,0,0,0,0
0,0,0,0,0,0,0,0,0,0,0,0,0,0,0,0,0,0,0,0,0,0,0,0,0,0,0
0,0,0,0,0,0,0,0,0,0,0,0,0,0,0,0,0,0,0,0,0,0,0,0,0,0,0
0,0,0,0,0,0,0,0,0,0,0,0,0,0,0,0,0,0,0,0,2,2,2,1,1,0,0
0,0,0,0,0,0,0,0,0,0,0,0,0,0,0,0,0,0,0,0,2,5,2,10,1,0,0
0,0,0,0,0,1,1,1,1,1,1,10,10,0,0,0,0,0,0,2,2,2,2,13,10,0,0
0,0,0,0,0,1,11,11,12,1,27,0,0,0,0,0,2,2,2,2,2,2,2,0,10,0,0
0,0,0,0,0,1,11,11,11,1,1,10,10,0,0,0,2,17,17,2,2,2,2,0,10,0,0
0,0,0,0,0,1,11,11,11,1,9,9,9,9,9,9,9,17,17,2,2,2,2,0,10,0,0
0,0,0,0,0,1,1,1,1,1,9,28,9,9,28,9,17,17,17,2,0,0,10,0,10,0,0
0,0,0,0,0,0,0,1,1,1,9,28,9,9,28,9,9,2,2,2,0,0,0,0,0,0,0
0,0,0,0,0,0,0,0,11,17,9,28,9,9,28,9,9,2,2,0,0,0,10,0,10,0,0
0,0,0,0,0,0,0,0,11,11,9,28,2,9,28,9,9,2,2,0,10,10,10,0,10,0,0
0,0,0,0,0,0,0,0,0,0,2,2,2,2,2,2,2,2,2,0,10,0,0,0,0,0,0
0,0,0,0,0,0,0,0,0,0,2,11,11,11,11,11,11,11,2,0,0,0,0,0,0,0,0
0,0,0,0,0,0,0,0,0,0,2,29,29,29,11,11,11,11,2,0,10,0,0,0,10,0,0
0,0,0,0,0,0,0,0,0,0,2,29,29,29,11,11,11,11,2,0,10,10,0,10,10,0,0
0,0,2,11,11,11,2,0,0,0,2,29,29,29,11,11,11,11,2,0,0,0,0,0,0,0,0
0,0,11,0,0,12,11,0,0,0,2,2,2,2,2,2,2,2,2,0,0,0,0,0,0,0,0
11,11,11,0,0,0,11,0,0,0,0,0,0,0,14,1,11,11,1,0,0,0,0,0,0,0,0
11,11,11,0,0,0,11,0,0,0,0,0,10,10,11,1,11,11,1,1,1,1,0,0,0,0,0
2,2,2,11,11,11,2,0,0,0,0,0,0,0,0,1,11,11,11,11,12,1,0,0,0,0,0
2,2,2,2,0,0,0,0,0,0,0,0,0,0,0,1,1,1,11,11,11,1,0,0,0,0,0
2,17,17,2,0,0,0,0,0,0,0,0,0,0,0,0,0,1,11,11,11,1,0,0,0,0,0
2,17,17,2,0,0,0,0,0,0,0,0,0,0,0,0,0,1,1,1,1,1,0,0,0,0,0
2,2,2,2,0,0,0,0,0,0,0,0,0,0,0,0,0,0,0,0,0,0,0,0,0,0,0
0,0,0,0,0,0,0,0,0,0,0,0,0,0,0,0,0,0,0,0,0,0,0,0,0,0,0
0,0,0,0,0,0,0,0,0,0,0,0,0,0,0,0,0,0,0,0,0,0,0,0,0,0,0
0,0,0,0,0,0,0,0,0,0,0,0,0,0,0,0,0,0,0,0,0,0,0,0,0,0,0
endlayer

layer
0,0,0,0,0,0,0,0,0,0,0,0,0,0,0,0,0,0,0,0,0,0,0,0,0,0,0
0,0,0,0,0,0,0,0,0,0,0,0,0,0,0,0,0,0,0,0,0,0,0,0,0,0,0
0,0,0,0,0,0,0,0,0,0,0,0,0,0,0,0,0,0,0,0,0,0,0,0,0,0,0
0,0,0,0,0,0,0,0,0,0,0,0,0,0,0,0,0,0,0,0,10,10,10,10,10,0,0
0,0,0,0,0,0,0,0,0,0,0,0,0,0,0,0,0,0,0,0,10,18,0,0,10,0,0
0,0,0,0,0,10,10,10,10,10,10,10,0,0,0,0,0,0,0,2,2,5,2,0,10,0,0
0,0,0,0,0,10,0,0,0,0,0,0,0,0,0,0,10,10,10,2,17,17,2,0,10,0,0
0,0,0,0,0,10,0,0,0,10,10,10,0,0,0,0,10,0,18,5,17,17,2,0,0,0,0
0,0,0,0,0,10,0,0,0,10,10,10,10,10,10,10,10,0,0,2,2,2,2,0,0,0,0
0,0,0,0,0,10,10,10,0,0,0,32,0,30,31,30,10,0,0,10,0,0,0,0,0,0,0
0,0,0,0,0,0,0,10,10,10,10,32,0,30,31,30,10,0,0,10,0,0,0,0,0,0,0
0,0,0,0,0,0,0,0,10,0,10,32,0,30,31,30,0,0,0,2,2,2,2,2,3,0,0
0,0,0,0,0,0,0,0,10,10,10,32,0,30,31,30,10,0,0,2,2,2,2,2,3,0,0
0,0,0,0,0,0,0,0,0,0,2,2,0,2,2,2,2,2,2,2,2,2,2,2,3,0,0
0,0,0,0,0,0,0,0,0,0,2,0,0,0,0,0,13,11,2,2,2,2,2,2,3,0,0
0,0,0,0,0,0,0,0,0,0,2,0,0,0,0,0,10,14,2,2,2,2,2,2,3,0,0
0,0,0,0,0,0,0,0,0,0,2,0,29,0,0,0,0,6,2,4,4,4,4,4,4,0,0
0,0,1,1,1,1,1,0,0,0,2,0,29,0,0,0,0,8,2,0,0,0,0,0,0,0,0
0,0,1,11,11,12,1,0,0,0,2,2,2,2,2,2,0,2,2,0,0,0,0,0,0,0,0
1,1,1,11,11,11,1,0,0,0,0,0,0,0,0,0,0,0,10,0,0,0,0,0,0,0,0
1,11,1,11,11,11,1,0,0,0,0,0,0,10,10,10,0,0,10,10,10,10,0,0,0,0,0
1,1,1,1,1,1,1,2,0,0,0,0,0,0,0,10,0,0,0,0,0,10,0,0,0,0,0
2,2,2,2,0,0,0,0,0,0,0,0,0,0,0,10,10,10,0,0,0,10,0,0,0,0,0
2,17,17,2,0,0,0,0,0,0,0,0,0,0,0,0,0,10,0,0,0,10,0,0,0,0,0
2,17,17,2,0,0,0,0,0,0,0,0,0,0,0,0,0,10,10,10,10,10,0,0,0,0,0
2,2,2,2,0,0,0,0,0,0,0,0,0,0,0,0,0,0,0,0,0,0,0,0,0,0,0
0,0,0,0,0,0,0,0,0,0,0,0,0,0,0,0,0,0,0,0,0,0,0,0,0,0,0
0,0,0,0,0,0,0,0,0,0,0,0,0,0,0,0,0,0,0,0,0,0,0,0,0,0,0
0,0,0,0,0,0,0,0,0,0,0,0,0,0,0,0,0,0,0,0,0,0,0,0,0,0,0
endlayer

layer
0,0,0,0,0,0,0,0,0,0,0,0,0,0,0,0,0,0,0,0,0,0,0,0,0,0,0
0,0,0,0,0,0,0,0,0,0,0,0,0,0,0,0,0,0,0,0,0,0,0,0,0,0,0
0,0,0,0,0,0,0,0,0,0,0,0,0,0,0,0,0,0,0,0,0,0,0,0,0,0,0
0,0,0,0,0,0,0,0,0,0,0,0,0,0,0,0,0,0,0,0,0,0,0,0,0,0,0
0,0,0,0,0,0,0,0,0,0,0,0,0,0,0,0,0,0,0,0,0,0,0,0,0,0,0
0,0,0,0,0,0,0,0,0,10,10,10,0,0,0,0,0,0,0,2,2,18,2,0,0,0,0
0,0,0,0,0,0,0,0,0,0,0,0,0,0,0,0,0,0,0,2,17,17,2,0,0,0,0
0,0,0,0,0,0,0,0,0,0,0,0,0,0,0,0,0,0,0,18,17,17,2,0,0,0,0
0,0,0,0,0,0,0,0,0,10,10,10,0,0,0,0,0,0,0,2,2,2,2,0,0,0,0
0,0,0,0,0,0,0,0,0,0,0,0,0,0,0,0,0,0,0,0,0,0,0,0,0,0,0
0,0,0,0,0,0,0,0,0,0,0,0,0,0,0,0,0,0,0,0,0,0,0,0,0,0,0
0,0,0,0,0,0,0,0,0,0,0,0,0,0,0,0,0,0,0,2,2,2,2,2,0,0,0
0,0,0,0,0,0,0,0,0,0,0,0,0,0,0,0,0,0,0,2,2,2,2,2,0,0,0
0,0,0,0,0,0,0,0,0,0,2,11,0,11,11,20,20,11,11,2,2,2,2,2,0,0,0
0,0,0,0,0,0,0,0,0,0,1,0,0,0,0,0,0,0,1,2,2,2,2,2,0,0,0
0,0,0,0,0,0,0,0,0,0,20,0,0,0,0,0,22,0,20,2,2,2,2,2,0,0,0
0,0,0,0,0,0,0,0,0,0,20,0,0,0,0,0,0,0,20,0,0,0,0,0,0,0,0
0,0,10,10,10,10,10,0,0,0,1,0,0,0,0,0,0,0,1,0,0,0,0,0,0,0,0
0,0,10,0,0,0,10,0,0,0,2,11,11,20,11,11,0,11,2,0,0,0,0,0,0,0,0
10,10,10,0,0,2,10,0,0,0,0,0,0,0,0,0,0,0,0,0,0,0,0,0,0,0,0
10,3,0,0,0,2,10,0,0,0,0,0,0,0,0,0,0,0,10,10,10,10,0,0,0,0,0
10,1,0,10,10,10,10,2,0,0,0,0,0,0,0,0,0,0,0,0,0,10,0,0,0,0,0
10,0,0,10,0,0,0,0,0,0,0,0,0,0,0,0,0,0,0,0,0,0,0,0,0,0,0
10,0,0,10,0,0,0,0,0,0,0,0,0,0,0,0,0,10,0,0,0,10,0,0,0,0,0
10,0,0,10,0,0,0,0,0,0,0,0,0,0,0,0,0,10,10,0,10,10,0,0,0,0,0
10,10,10,10,0,0,0,0,0,0,0,0,0,0,0,0,0,0,0,0,0,0,0,0,0,0,0
0,0,0,0,0,0,0,0,0,0,0,0,0,0,0,0,0,0,0,0,0,0,0,0,0,0,0
0,0,0,0,0,0,0,0,0,0,0,0,0,0,0,0,0,0,0,0,0,0,0,0,0,0,0
0,0,0,0,0,0,0,0,0,0,0,0,0,0,0,0,0,0,0,0,0,0,0,0,0,0,0
endlayer

layer
0,0,0,0,0,0,0,0,0,0,0,0,0,0,0,0,0,0,0,0,0,0,0,0,0,0,0
0,0,0,0,0,0,0,0,0,0,0,0,0,0,0,0,0,0,0,0,0,0,0,0,0,0,0
0,0,0,0,0,0,0,0,0,0,0,0,0,0,0,0,0,0,0,0,0,0,0,0,0,0,0
0,0,0,0,0,0,0,0,0,0,0,0,0,0,0,0,0,0,0,0,0,0,0,0,0,0,0
0,0,0,0,0,0,0,0,0,0,0,0,0,0,0,0,0,0,0,0,0,0,0,0,0,0,0
0,0,0,0,0,0,0,0,0,10,10,10,0,0,0,0,0,0,0,2,2,2,2,0,0,0,0
0,0,0,0,0,0,0,0,0,0,0,0,0,0,0,0,0,0,0,2,17,17,2,0,0,0,0
0,0,0,0,0,0,0,0,0,0,0,0,0,0,0,0,0,0,0,2,17,17,2,0,0,0,0
0,0,0,0,0,0,0,0,0,10,10,10,0,0,0,0,0,0,0,2,2,2,2,0,0,0,0
0,0,0,0,0,0,0,0,0,0,0,0,0,0,0,0,0,0,0,0,0,0,0,0,0,0,0
0,0,0,0,0,0,0,0,0,0,0,0,0,0,0,0,0,0,0,0,0,0,0,0,0,0,0
0,0,0,0,0,0,0,0,0,0,0,0,0,0,0,0,0,0,0,2,11,11,11,2,0,0,0
0,0,0,0,0,0,0,0,0,0,25,25,25,25,25,25,25,25,0,11,0,0,0,11,0,0,0
0,0,0,0,0,0,0,0,0,0,2,11,11,11,11,11,11,11,11,11,0,0,0,11,0,0,0
0,0,0,0,0,0,0,0,0,0,2,11,33,11,11,11,0,0,11,11,0,0,0,11,0,0,0
0,0,0,0,0,0,0,0,0,0,2,11,11,11,11,11,0,0,11,2,11,11,11,2,0,0,0
0,0,0,0,0,0,0,0,0,0,2,11,11,11,11,11,0,0,11,0,0,0,0,0,0,0,0
0,0,0,0,0,0,0,0,0,0,2,11,11,11,11,11,0,0,11,0,0,0,0,0,0,0,0
0,0,0,0,0,0,0,0,0,0,2,11,11,11,11,11,11,11,2,0,0,0,0,0,0,0,0
10,10,10,0,0,2,2,2,2,2,13,13,13,13,11,11,11,11,13,0,0,0,0,0,0,0,0
10,0,0,0,0,2,2,2,2,2,2,2,2,2,2,2,2,2,2,2,2,2,0,0,0,0,0
10,34,0,0,0,2,2,2,2,2,2,2,2,2,2,2,2,2,2,2,2,2,0,0,0,0,0
10,0,0,10,0,2,2,2,2,2,2,2,2,2,2,2,2,2,2,2,2,2,0,0,0,0,0
0,0,0,0,0,2,2,2,2,2,0,0,0,0,0,0,0,2,2,2,2,2,0,0,0,0,0
0,0,0,0,0,0,0,0,0,0,0,0,0,0,0,0,0,2,2,2,2,2,0,0,0,0,0
10,0,0,10,0,0,0,0,0,0,0,0,0,0,0,0,0,0,0,0,0,0,0,0,0,0,0
0,0,0,0,0,0,0,0,0,0,0,0,0,0,0,0,0,0,0,0,0,0,0,0,0,0,0
0,0,0,0,0,0,0,0,0,0,0,0,0,0,0,0,0,0,0,0,0,0,0,0,0,0,0
0,0,0,0,0,0,0,0,0,0,0,0,0,0,0,0,0,0,0,0,0,0,0,0,0,0,0
endlayer

layer
0,0,0,0,0,0,0,0,0,0,0,0,0,0,0,0,0,0,0,0,0,0,0,0,0,0,0
0,0,0,0,0,0,0,0,0,0,0,0,0,0,0,0,0,0,0,0,0,0,0,0,0,0,0
0,0,0,0,0,0,0,0,0,0,0,0,0,0,0,0,0,0,0,0,0,0,0,0,0,0,0
0,0,0,0,0,0,0,0,0,0,0,0,0,0,0,0,0,0,0,0,0,0,0,0,0,0,0
0,0,0,0,0,0,0,0,0,0,0,0,0,0,0,0,0,0,0,0,0,0,0,0,0,0,0
0,0,0,0,0,0,0,0,0,10,10,10,0,0,0,0,0,0,0,2,2,2,2,0,0,0,0
0,0,0,0,0,0,0,0,0,0,0,0,0,0,0,0,0,0,0,2,17,17,2,0,0,0,0
0,0,0,0,0,0,0,0,0,0,0,0,0,0,0,0,0,0,0,2,17,6,2,0,0,0,0
0,0,0,0,0,0,0,0,0,10,10,10,0,0,0,0,0,0,0,2,2,2,2,0,0,0,0
0,0,0,0,0,0,0,0,0,0,0,0,0,0,0,0,0,0,0,0,0,0,0,0,0,0,0
0,0,0,0,0,0,0,0,0,0,0,0,0,0,0,0,0,0,0,0,0,0,0,0,0,0,0
0,0,0,0,0,0,0,0,0,0,0,0,0,0,0,0,0,0,0,2,11,20,11,2,0,0,0
0,0,0,0,0,0,0,0,0,0,0,0,0,0,0,0,0,0,0,11,0,0,0,11,0,0,0
0,0,0,0,0,0,0,0,0,0,25,25,25,25,25,25,25,25,25,20,0,0,0,20,0,0,0
0,0,0,0,0,0,0,0,0,0,11,11,11,11,11,11,11,11,11,11,0,0,0,11,0,0,0
0,0,0,0,0,0,0,0,0,0,11,11,11,11,11,11,0,0,11,2,11,20,11,2,0,0,0
0,0,0,0,0,0,0,0,0,0,11,11,11,11,11,11,0,0,11,0,0,0,0,0,0,0,0
0,0,0,0,0,0,0,0,0,0,11,11,11,11,11,11,11,11,11,0,0,0,0,0,0,0,0
0,0,0,0,0,0,0,0,0,0,13,13,13,13,11,13,13,11,13,0,0,0,0,0,0,0,0
0,0,0,0,0,2,11,13,11,2,10,10,2,2,2,0,0,11,0,0,0,0,0,0,0,0,0
0,0,0,0,0,11,0,0,12,11,0,2,2,2,2,0,0,2,11,11,11,2,0,0,0,0,0
10,0,0,0,0,11,0,0,6,11,2,2,2,2,3,0,0,0,0,0,12,11,0,0,0,0,0
2,34,2,2,0,11,0,0,0,14,9,9,2,2,2,10,10,11,0,0,0,11,0,0,0,0,0
2,2,2,2,0,2,11,11,11,2,9,9,2,0,0,0,0,11,0,0,0,11,0,0,0,0,0
2,2,2,2,0,0,0,0,0,2,9,9,2,0,0,0,0,2,11,11,11,2,0,0,0,0,0
2,2,2,2,0,0,0,0,0,2,2,2,2,0,0,0,0,0,0,0,0,0,0,0,0,0,0
0,0,0,0,0,0,0,0,0,0,0,0,0,0,0,0,0,0,0,0,0,0,0,0,0,0,0
0,0,0,0,0,0,0,0,0,0,0,0,0,0,0,0,0,0,0,0,0,0,0,0,0,0,0
0,0,0,0,0,0,0,0,0,0,0,0,0,0,0,0,0,0,0,0,0,0,0,0,0,0,0
endlayer

layer
0,0,0,0,0,0,0,0,0,0,0,0,0,0,0,0,0,0,0,0,0,0,0,0,0,0,0
0,0,0,0,0,0,0,0,0,0,0,0,0,0,0,0,0,0,0,0,0,0,0,0,0,0,0
0,0,0,0,0,0,0,0,0,0,0,0,0,0,0,0,0,0,0,0,0,0,0,0,0,0,0
0,0,0,0,0,0,0,0,0,0,0,0,0,0,0,0,0,0,0,0,0,0,0,0,0,0,0
0,0,0,0,0,0,0,0,0,0,0,0,0,0,0,0,0,0,0,0,0,0,0,0,0,0,0
0,0,0,0,0,0,0,0,0,10,10,10,0,0,0,0,0,0,0,2,2,2,2,0,0,0,0
0,0,0,0,0,0,0,0,0,0,0,0,0,0,0,0,0,0,0,2,17,17,2,0,0,0,0
0,0,0,0,0,0,0,0,0,0,2,0,0,0,0,0,0,0,0,2,17,17,2,0,0,0,0
0,0,0,0,0,0,0,0,0,2,2,2,0,0,0,0,0,0,0,2,2,2,2,0,0,0,0
0,0,0,0,0,0,0,0,2,2,2,2,2,2,2,0,0,0,0,0,0,0,0,0,0,0,0
0,0,0,0,0,0,0,0,2,11,11,11,11,11,2,0,0,0,0,0,0,0,0,0,0,0,0
0,0,0,0,0,0,0,0,2,11,11,11,11,11,2,0,0,0,0,2,11,11,11,2,0,0,0
0,0,0,0,0,0,0,0,2,11,11,11,11,11,2,0,0,0,0,11,0,0,0,11,0,0,0
0,0,0,0,0,0,0,0,2,11,11,11,11,11,2,0,0,0,0,11,0,0,0,11,0,0,0
0,0,0,0,0,0,2,2,2,11,11,11,11,11,2,25,25,25,25,11,0,0,0,11,0,0,0
0,0,0,0,0,0,2,11,11,11,11,11,11,11,2,11,11,11,11,2,11,11,11,2,0,0,0
0,0,0,0,0,0,2,11,11,11,11,11,11,11,2,11,11,11,11,0,0,0,0,0,0,0,0
0,0,0,0,0,0,2,11,11,11,11,11,11,11,2,13,13,11,13,0,0,0,0,0,0,0,0
0,0,0,0,0,0,2,13,11,11,11,11,11,11,2,0,0,11,0,0,0,0,0,0,0,0,0
0,0,0,0,0,2,11,0,11,2,2,2,2,2,2,0,0,10,0,0,0,0,0,0,0,0,0
0,0,0,0,0,11,0,0,12,11,2,11,27,0,10,0,0,2,11,20,11,2,0,0,0,0,0
0,0,0,0,0,20,0,0,0,11,11,13,1,0,0,0,0,0,0,0,12,11,0,0,0,0,0
10,0,0,2,0,11,0,0,0,0,0,0,11,10,10,10,0,11,0,0,0,20,0,0,0,0,0
10,0,19,2,0,2,11,20,11,11,0,0,11,0,0,0,0,11,0,0,0,11,0,0,0,0,0
10,0,0,2,0,0,0,0,0,11,10,0,11,0,0,0,0,2,11,20,11,2,0,0,0,0,0
10,10,10,10,0,0,0,0,0,1,11,11,1,0,0,0,0,0,0,0,0,0,0,0,0,0,0
0,0,0,0,0,0,0,0,0,0,0,0,0,0,0,0,0,0,0,0,0,0,0,0,0,0,0
0,0,0,0,0,0,0,0,0,0,0,0,0,0,0,0,0,0,0,0,0,0,0,0,0,0,0
0,0,0,0,0,0,0,0,0,0,0,0,0,0,0,0,0,0,0,0,0,0,0,0,0,0,0
endlayer

layer
0,0,0,0,0,0,0,0,0,0,0,0,0,0,0,0,0,0,0,0,0,0,0,0,0,0,0
0,0,0,0,0,0,0,0,0,0,0,0,0,0,0,0,0,0,0,0,0,0,0,0,0,0,0
0,0,0,0,0,0,0,0,2,2,2,2,2,0,0,0,0,0,0,0,0,0,0,0,0,0,0
0,0,0,0,0,0,0,0,2,2,2,2,2,0,0,0,0,0,0,0,0,0,0,0,0,0,0
0,0,0,0,0,0,0,0,2,2,2,2,2,0,0,0,0,0,0,0,0,0,0,0,0,0,0
0,0,0,0,0,0,0,0,2,2,2,2,2,0,0,0,0,0,0,2,2,2,2,0,0,0,0
0,0,0,0,0,0,0,0,2,2,2,2,2,0,0,0,0,0,0,2,17,17,2,0,0,0,0
0,0,0,0,0,0,0,0,0,2,4,2,0,0,0,0,0,0,0,2,17,17,2,0,0,0,0
0,0,0,0,0,0,0,0,0,10,0,10,0,0,0,0,0,0,0,2,2,2,2,0,0,0,0
0,0,0,0,0,0,0,0,2,2,0,2,2,2,2,0,0,0,0,0,0,0,0,0,0,0,0
0,0,0,0,0,0,0,0,2,0,0,0,0,0,2,0,0,0,0,0,0,0,0,0,0,0,0
0,0,0,0,0,0,0,0,2,0,0,0,0,0,2,0,0,0,0,1,1,1,1,1,0,0,0
0,0,0,0,0,0,0,0,2,0,0,0,0,0,2,0,0,0,0,1,11,11,11,1,0,0,0
0,0,0,0,0,0,0,0,2,0,0,0,0,6,2,0,0,0,0,1,11,11,11,1,0,0,0
0,0,0,0,0,0,2,2,2,0,0,0,0,8,2,0,0,0,0,1,11,11,11,1,0,0,0
0,0,0,0,0,0,2,0,0,0,0,0,0,6,2,25,25,25,25,1,1,1,1,1,0,0,0
0,0,0,0,0,0,2,0,0,0,0,0,0,0,2,13,13,11,11,0,0,0,0,0,0,0,0
0,0,0,0,0,0,2,0,0,0,0,0,0,0,2,0,0,11,11,0,0,0,0,0,0,0,0
0,0,0,0,0,0,2,0,0,0,0,0,0,0,2,0,0,10,0,0,0,0,0,0,0,0,0
0,0,0,0,0,2,11,0,11,2,2,0,2,2,2,0,0,10,0,0,0,0,0,0,0,0,0
0,0,0,0,0,11,0,0,12,11,8,0,0,0,0,0,0,2,11,11,11,2,0,0,0,0,0
0,0,0,0,0,11,0,0,0,11,11,0,1,0,0,0,0,11,0,0,12,11,0,0,0,0,0
0,0,0,2,0,11,0,0,0,0,0,0,11,0,0,0,0,11,0,0,0,11,0,0,0,0,0
0,0,0,19,0,2,11,11,11,11,0,0,20,0,0,0,0,11,0,0,0,11,1,0,0,0,0
0,0,0,2,0,0,0,0,0,11,22,0,11,0,0,0,0,2,11,11,11,2,0,0,0,0,0
0,0,0,0,0,0,0,0,0,1,11,11,1,0,0,0,0,0,0,0,0,0,0,0,0,0,0
0,0,0,0,0,0,0,0,0,0,0,0,0,0,0,0,0,0,0,0,0,0,0,0,0,0,0
0,0,0,0,0,0,0,0,0,0,0,0,0,0,0,0,0,0,0,0,0,0,0,0,0,0,0
0,0,0,0,0,0,0,0,0,0,0,0,0,0,0,0,0,0,0,0,0,0,0,0,0,0,0
endlayer

layer
0,0,0,0,0,0,0,0,0,0,0,0,0,0,0,0,0,0,0,0,0,0,0,0,0,0,0
0,0,0,0,0,0,0,0,0,0,0,0,0,0,0,0,0,0,0,0,0,0,0,0,0,0,0
0,0,0,0,0,0,0,0,2,11,11,11,2,0,0,0,0,0,0,0,0,0,0,0,0,0,0
0,0,0,0,0,0,0,0,11,0,0,8,11,0,0,0,0,0,0,0,0,0,0,0,0,0,0
0,0,0,0,0,0,0,0,11,0,0,6,11,0,0,0,0,0,0,0,0,0,0,0,0,0,0
0,0,0,0,0,0,0,0,11,21,0,0,11,0,0,0,0,0,0,2,2,2,2,0,0,0,0
0,0,0,0,0,0,0,0,2,11,0,11,2,0,0,0,0,0,0,2,17,17,2,0,0,0,0
0,0,0,0,0,0,0,0,0,10,0,10,0,0,0,0,0,0,0,2,17,17,2,0,0,0,0
0,0,0,0,0,0,0,0,0,10,0,10,0,0,0,0,0,0,2,2,2,2,2,0,0,0,0
0,0,0,0,0,0,0,0,2,2,0,2,2,2,2,0,0,0,0,0,0,0,0,0,0,0,0
0,0,0,0,0,0,0,0,1,0,0,0,0,0,1,0,0,0,0,36,36,36,36,36,35,0,0
0,0,0,0,0,0,0,0,20,0,0,0,0,0,20,0,0,0,0,10,10,10,10,10,35,0,0
0,0,0,0,0,0,0,0,20,0,0,0,0,0,20,0,0,0,0,10,0,0,0,10,37,0,0
0,0,0,0,0,0,0,0,1,0,0,0,0,0,1,0,0,0,0,10,0,0,0,10,0,0,0
0,0,0,0,0,0,2,11,11,0,0,0,0,0,11,0,0,0,0,10,0,0,0,10,0,0,0
0,0,0,0,0,0,1,0,0,0,0,0,0,0,1,0,2,2,2,10,10,10,10,10,0,0,0
0,0,0,0,0,0,20,0,0,0,0,0,0,0,20,0,0,0,14,35,0,0,0,0,0,0,0
0,0,0,0,0,0,20,0,0,0,0,0,0,0,20,0,0,10,11,26,0,0,0,0,0,0,0
0,0,0,0,0,0,1,0,0,0,0,0,0,0,1,0,0,10,0,0,0,0,0,0,0,0,0
0,0,0,0,0,1,1,0,1,1,1,0,1,11,2,0,0,0,0,0,0,0,0,0,0,0,0
0,0,0,0,0,1,11,11,12,1,10,0,0,0,0,0,0,1,1,1,1,1,0,0,0,0,0
0,0,0,0,0,1,11,11,11,1,11,0,1,0,0,0,0,1,11,11,12,1,0,0,0,0,0
0,0,0,2,2,1,11,11,11,1,0,0,11,0,0,0,0,1,11,11,11,1,1,1,0,0,0
0,0,0,0,19,1,1,1,1,1,0,0,11,0,0,0,0,1,11,11,11,1,1,1,0,0,0
0,0,0,2,2,0,0,0,0,11,0,0,11,0,0,0,0,1,1,1,1,1,1,1,0,0,0
0,0,0,0,0,0,0,0,0,1,11,11,1,0,0,0,0,0,0,0,0,0,0,0,0,0,0
0,0,0,0,0,0,0,0,0,0,0,0,0,0,0,0,0,0,0,0,0,0,0,0,0,0,0
0,0,0,0,0,0,0,0,0,0,0,0,0,0,0,0,0,0,0,0,0,0,0,0,0,0,0
0,0,0,0,0,0,0,0,0,0,0,0,0,0,0,0,0,0,0,0,0,0,0,0,0,0,0
endlayer

layer
0,0,0,0,0,0,0,0,0,0,0,0,0,0,0,0,0,0,0,0,0,0,0,0,0,0,0
0,0,0,0,0,0,0,0,0,0,0,0,0,0,0,0,0,0,0,0,0,0,0,0,0,0,0
0,0,0,0,0,0,0,0,2,11,20,11,2,0,0,0,0,0,0,0,0,0,0,0,0,0,0
0,0,0,0,0,0,0,0,11,0,0,0,11,0,0,0,0,0,0,0,0,0,0,0,0,0,0
0,0,0,0,0,0,0,0,20,0,0,0,20,0,0,0,0,0,0,0,0,0,0,0,0,0,0
0,0,0,0,0,0,0,0,11,21,0,0,11,0,0,0,0,0,0,2,2,2,2,0,0,0,0
0,0,0,0,0,0,0,0,2,11,0,11,2,0,0,0,0,0,0,2,17,17,2,0,0,0,0
0,0,0,0,0,0,0,0,0,0,0,0,0,0,0,0,0,0,0,2,17,17,2,0,0,0,0
0,0,0,0,0,0,0,0,0,0,0,0,0,0,0,0,0,2,2,2,2,2,2,0,0,0,0
0,0,0,0,0,0,0,14,2,2,2,2,2,2,2,2,2,2,2,2,2,2,2,2,2,2,0
0,0,0,0,0,0,0,14,2,0,0,0,0,0,2,2,2,2,2,2,2,2,2,2,2,2,0
0,0,0,0,0,0,10,14,2,0,0,0,0,0,2,2,2,2,2,2,2,2,2,2,2,2,0
0,0,0,0,0,0,10,14,2,0,0,0,0,0,2,2,2,2,2,2,2,2,2,2,2,2,0
0,0,0,0,0,0,25,11,2,0,0,0,0,0,2,2,2,2,2,2,2,2,2,2,2,2,0
0,0,0,0,0,0,2,11,11,0,0,0,0,0,2,0,2,2,2,2,2,2,2,2,2,2,0
0,0,0,0,0,0,2,0,0,0,0,0,0,0,2,0,2,2,2,2,2,2,2,2,2,2,0
0,0,0,0,0,0,2,0,0,0,0,0,0,0,2,0,0,0,0,19,2,2,2,2,2,0,0
0,0,0,0,0,0,2,0,0,0,0,0,0,0,2,0,0,10,10,2,2,2,2,2,2,0,0
0,0,0,0,0,0,2,0,0,0,0,0,0,0,2,0,0,0,0,0,37,37,37,37,37,0,0
0,0,0,0,0,10,10,11,11,11,11,11,11,11,2,0,0,0,0,0,0,0,0,0,0,0,0
0,0,0,0,0,10,10,13,0,10,13,13,13,13,13,0,0,10,10,1,1,1,0,0,0,0,0
0,0,0,0,0,10,0,0,0,10,1,1,0,0,0,0,0,10,0,0,0,1,0,0,0,0,0
0,0,0,10,2,1,10,10,10,10,1,1,1,0,0,0,0,10,0,0,1,1,2,2,0,0,0
0,0,0,0,0,14,10,10,10,10,1,1,1,0,0,0,0,10,0,0,0,14,2,2,0,0,0
0,0,0,10,2,2,0,0,0,1,1,1,1,0,0,0,0,10,10,10,10,10,2,2,0,0,0
0,0,0,0,0,0,0,0,0,0,1,1,0,0,0,0,0,0,0,0,0,0,0,0,0,0,0
0,0,0,0,0,0,0,0,0,0,0,0,0,0,0,0,0,0,0,0,0,0,0,0,0,0,0
0,0,0,0,0,0,0,0,0,0,0,0,0,0,0,0,0,0,0,0,0,0,0,0,0,0,0
0,0,0,0,0,0,0,0,0,0,0,0,0,0,0,0,0,0,0,0,0,0,0,0,0,0,0
endlayer

layer
0,0,0,0,0,0,0,0,0,0,0,0,0,0,0,0,0,0,0,0,0,0,0,0,0,0,0
0,0,0,0,0,0,0,0,0,0,0,0,0,0,0,0,0,0,0,0,0,0,0,0,0,0,0
0,0,0,0,0,0,0,0,2,11,11,11,2,0,0,0,0,0,0,0,0,0,0,0,0,0,0
0,0,0,0,0,0,0,0,11,0,0,0,11,0,0,0,0,0,0,0,0,0,0,0,0,0,0
0,0,0,0,0,0,0,0,11,0,0,0,11,0,0,0,0,0,0,0,0,0,0,0,0,0,0
0,0,0,0,0,0,0,0,11,21,0,0,11,0,0,0,0,0,0,2,2,2,2,0,0,0,0
0,0,0,0,0,0,0,0,2,11,11,11,2,0,0,0,0,0,0,2,17,17,2,0,0,0,0
0,0,0,0,0,0,0,0,0,0,0,0,0,0,0,0,0,0,0,2,17,17,2,0,0,0,0
0,0,0,0,0,0,0,0,0,0,0,0,0,0,0,0,0,2,2,2,2,2,2,0,0,0,0
0,0,0,0,0,0,0,10,14,11,1,20,1,11,27,2,1,11,0,0,0,6,2,2,2,2,0
0,0,0,0,0,0,0,10,14,11,0,0,0,11,27,0,11,11,13,0,0,6,2,38,38,2,0
0,0,0,0,0,0,10,10,14,11,0,0,0,11,27,0,11,27,10,0,0,8,2,2,2,2,0
0,0,0,0,0,0,10,0,14,11,0,0,0,11,27,0,11,0,0,0,11,11,2,0,0,10,0
0,0,0,0,0,0,10,0,14,11,0,0,0,11,27,0,0,0,0,11,0,0,0,0,0,10,0
0,0,0,0,0,0,25,25,11,11,0,0,0,11,27,39,11,0,0,0,0,0,0,0,29,10,0
0,0,0,0,0,0,11,11,11,11,0,0,0,11,11,1,1,11,11,1,10,0,0,0,10,10,0
0,0,0,0,0,0,11,0,0,0,0,0,0,11,11,0,0,0,0,0,0,0,0,0,10,0,0
0,0,0,0,0,0,11,0,0,0,0,0,0,11,11,0,0,0,10,10,10,0,0,0,10,0,0
0,0,0,0,0,0,11,11,11,11,11,11,11,11,11,0,0,0,0,0,2,2,34,2,2,0,0
0,0,0,0,0,0,13,13,13,13,13,13,13,13,13,0,0,0,0,0,2,2,2,2,2,0,0
0,0,0,0,0,0,10,0,0,0,0,0,0,0,10,0,0,0,10,10,2,2,2,2,2,0,0
0,0,0,0,0,0,0,0,0,2,2,2,2,2,10,0,0,0,0,0,0,2,2,2,2,0,0
0,0,0,10,10,2,2,2,2,2,2,2,2,2,0,0,0,10,0,0,2,2,2,2,2,0,0
0,0,0,0,0,0,19,2,2,2,2,2,2,2,0,0,0,10,0,0,0,0,19,2,0,0,0
0,0,0,10,10,2,2,2,2,2,2,2,2,2,0,0,0,10,0,0,0,10,2,2,0,0,0
0,0,0,0,0,0,0,0,0,2,2,2,2,2,0,0,0,0,0,0,0,0,0,0,0,0,0
0,0,0,0,0,0,0,0,0,0,0,0,0,0,0,0,0,0,0,0,0,0,0,0,0,0,0
0,0,0,0,0,0,0,0,0,0,0,0,0,0,0,0,0,0,0,0,0,0,0,0,0,0,0
0,0,0,0,0,0,0,0,0,0,0,0,0,0,0,0,0,0,0,0,0,0,0,0,0,0,0
endlayer

layer
0,0,0,0,0,0,0,0,0,0,0,0,0,0,0,0,0,0,0,0,0,0,0,0,0,0,0
0,0,0,0,0,0,0,0,0,0,0,0,0,0,0,0,0,0,0,0,0,0,0,0,0,0,0
0,0,0,0,0,0,0,0,1,1,1,1,1,0,0,0,0,0,0,0,0,0,0,0,0,0,0
0,0,0,0,0,0,0,0,1,11,11,11,1,0,0,0,0,0,0,0,0,0,0,0,0,0,0
0,0,0,0,0,0,0,2,1,11,11,11,1,2,2,2,0,0,0,0,0,0,0,0,0,0,0
0,0,0,0,0,0,0,2,1,21,11,11,1,2,2,2,0,0,0,2,2,2,2,0,0,0,0
0,0,0,0,0,0,0,2,1,1,1,1,1,2,2,2,0,0,0,2,17,17,2,0,0,0,0
0,0,0,0,0,0,0,2,2,2,2,2,2,2,2,2,0,0,0,2,17,17,2,0,0,0,0
0,0,0,0,0,0,0,2,2,2,2,2,2,2,2,2,0,2,2,2,2,2,2,0,0,0,0
0,0,0,0,0,0,0,2,2,2,2,2,2,2,2,2,1,11,0,0,0,0,2,2,2,2,0
0,0,0,0,0,0,0,10,39,14,11,0,11,27,0,0,11,0,0,0,0,0,2,0,0,40,0
0,0,0,0,0,0,0,10,0,14,11,0,11,27,0,0,20,0,22,0,0,0,2,0,0,40,0
0,0,0,0,0,0,0,0,0,14,11,0,11,27,0,0,11,0,0,0,11,11,41,0,0,0,0
0,0,0,0,0,0,10,0,2,14,11,0,11,27,0,0,0,0,0,11,0,0,0,0,0,0,0
0,0,0,0,0,0,10,0,0,14,11,0,11,27,0,0,11,0,0,0,0,0,0,0,0,0,0
0,0,0,0,0,0,25,25,25,11,11,0,11,11,25,10,1,11,11,1,10,0,0,0,0,10,0
0,0,0,0,0,0,11,11,11,11,11,11,11,11,11,0,0,0,0,0,0,0,0,0,0,0,0
0,0,0,0,0,0,11,11,11,11,11,11,11,11,11,0,0,0,0,0,0,0,0,0,0,0,0
0,0,0,0,0,0,13,13,13,13,13,13,13,13,13,0,0,0,0,0,2,11,0,11,2,0,0
0,0,0,0,0,0,10,0,0,0,0,0,0,0,10,0,0,0,0,0,11,0,0,12,11,0,0
0,0,0,0,0,0,10,0,0,0,0,0,0,0,10,0,0,0,0,0,11,0,0,0,11,0,0
0,0,0,0,0,0,0,0,0,2,11,11,11,2,0,0,0,0,0,0,11,0,0,0,11,0,0
0,0,0,0,10,10,10,10,10,11,0,0,12,11,0,0,0,10,0,0,2,11,0,11,2,0,0
0,0,0,0,0,0,0,0,0,0,0,0,0,11,0,0,0,10,0,0,0,0,0,10,0,0,0
0,0,0,0,10,10,10,10,10,11,0,0,0,11,0,0,0,10,0,0,0,10,10,10,0,0,0
0,0,0,0,0,0,0,0,0,2,11,11,11,2,0,0,0,0,0,0,0,0,0,0,0,0,0
0,0,0,0,0,0,0,0,0,0,0,0,0,0,0,0,0,0,0,0,0,0,0,0,0,0,0
0,0,0,0,0,0,0,0,0,0,0,0,0,0,0,0,0,0,0,0,0,0,0,0,0,0,0
0,0,0,0,0,0,0,0,0,0,0,0,0,0,0,0,0,0,0,0,0,0,0,0,0,0,0
endlayer

layer
0,0,0,0,0,0,0,0,0,0,0,0,0,0,0,0,0,0,0,0,0,0,0,0,0,0,0
0,0,0,0,0,0,0,0,0,0,0,0,0,0,0,0,0,0,0,0,0,0,0,0,0,0,0
0,0,0,0,0,0,0,0,0,0,0,0,0,0,0,0,0,0,0,0,0,0,0,0,0,0,0
0,0,0,0,0,0,0,0,0,0,0,0,0,0,0,0,0,0,0,0,0,0,0,0,0,0,0
0,0,0,0,0,0,0,2,2,2,2,2,2,2,2,2,0,0,0,0,0,0,0,0,0,0,0
0,0,0,0,0,0,0,2,0,0,13,13,13,13,11,2,0,0,0,2,2,2,2,0,0,0,0
0,0,0,0,0,0,0,2,0,0,0,10,0,10,14,2,0,0,0,2,17,17,2,0,0,0,0
0,0,0,0,0,0,0,2,0,0,0,0,0,0,0,2,0,0,0,2,17,17,2,0,0,0,0
0,0,0,0,0,0,0,2,0,0,0,0,0,0,15,2,0,2,2,2,2,2,2,0,0,0,0
0,0,0,0,0,0,0,2,16,2,2,2,2,2,2,2,1,11,0,0,0,0,2,2,2,2,0
0,0,0,0,0,0,0,10,0,0,14,11,27,0,0,0,11,0,0,0,0,0,2,2,2,2,0
0,0,0,0,0,0,0,10,0,0,14,11,27,0,0,0,11,0,0,0,0,0,2,2,2,2,0
0,0,0,0,0,0,0,0,0,0,14,11,27,0,0,0,11,0,0,0,11,11,41,0,0,0,0
0,0,0,0,0,0,0,0,2,0,14,11,27,0,0,0,11,0,0,11,0,0,0,0,0,0,0
0,0,0,0,0,0,10,0,0,21,14,11,27,0,0,0,11,0,0,11,0,0,0,0,0,0,0
0,0,0,0,0,0,10,0,0,2,14,11,27,0,10,10,1,11,11,1,10,0,0,0,0,10,0
0,0,0,0,0,0,25,25,25,25,11,11,11,25,25,0,0,0,0,0,0,0,0,0,0,0,0
0,0,0,0,0,0,13,13,13,13,13,13,13,13,13,0,0,0,0,0,0,0,0,0,0,0,0
0,0,0,0,0,0,10,0,0,0,0,0,0,0,10,0,0,0,0,0,2,11,0,11,2,0,0
0,0,0,0,0,0,10,0,0,0,0,0,0,0,10,0,0,0,0,0,11,0,0,12,11,0,0
0,0,0,0,0,0,0,0,0,0,0,0,0,0,0,0,0,0,0,0,20,0,0,0,20,0,0
0,0,0,0,0,0,0,0,0,2,11,20,11,2,0,0,0,0,0,0,11,0,0,0,11,0,0
0,0,0,0,0,0,0,0,0,11,0,0,12,11,0,0,0,10,0,0,2,11,0,11,2,0,0
0,0,0,0,0,0,0,0,0,0,0,0,0,20,0,0,0,10,0,0,0,0,0,0,0,0,0
0,0,0,0,0,0,0,0,0,11,0,0,0,11,0,0,0,10,0,0,0,0,0,0,0,0,0
0,0,0,0,0,0,0,0,0,2,11,20,11,2,0,0,0,0,0,0,0,0,0,0,0,0,0
0,0,0,0,0,0,0,0,0,0,0,0,0,0,0,0,0,0,0,0,0,0,0,0,0,0,0
0,0,0,0,0,0,0,0,0,0,0,0,0,0,0,0,0,0,0,0,0,0,0,0,0,0,0
0,0,0,0,0,0,0,0,0,0,0,0,0,0,0,0,0,0,0,0,0,0,0,0,0,0,0
endlayer

layer
0,0,0,0,0,0,0,0,0,0,0,0,0,0,0,0,0,0,0,0,0,0,0,0,0,0,0
0,0,0,0,0,0,0,0,0,0,0,0,0,0,0,0,0,0,0,0,0,0,0,0,0,0,0
0,0,0,0,0,0,0,0,0,0,0,0,0,0,0,0,0,0,0,0,0,0,0,0,0,0,0
0,0,0,0,0,0,0,0,0,0,0,0,0,0,0,0,0,0,0,0,0,0,0,0,0,0,0
0,0,0,0,0,0,0,2,11,20,20,11,20,20,11,2,0,0,0,0,0,0,0,0,0,0,0
0,0,0,0,0,0,0,11,0,0,0,0,0,0,0,11,0,0,0,2,2,2,2,0,0,0,0
0,0,0,0,0,0,0,20,0,0,0,22,0,22,0,20,0,0,0,2,17,17,2,0,0,0,0
0,0,0,0,0,0,0,20,0,0,0,0,0,0,0,20,0,0,0,2,17,17,2,0,0,0,0
0,0,0,0,0,0,0,11,0,0,0,0,0,0,0,11,0,2,2,2,2,2,2,0,0,0,0
0,0,0,0,0,0,0,2,23,11,11,20,20,20,11,2,1,2,2,2,2,2,2,2,2,2,0
0,0,0,0,0,0,0,0,0,0,0,0,0,0,0,0,2,2,2,2,2,2,2,2,2,2,0
0,0,0,0,0,0,0,0,0,0,0,0,0,0,0,0,2,2,2,2,2,2,2,2,2,2,0
0,0,0,0,0,0,0,0,0,0,0,0,0,0,0,0,2,2,2,2,2,2,2,2,2,2,0
0,0,0,0,0,0,0,0,2,0,0,0,2,0,0,0,2,2,2,2,2,2,2,2,2,2,0
0,0,0,0,0,0,0,0,0,21,0,0,0,0,0,0,2,2,2,2,2,2,2,2,2,2,0
0,0,0,0,0,0,10,0,0,2,0,0,0,0,10,0,1,2,2,1,2,2,2,2,2,2,0
0,0,0,0,0,0,10,0,0,0,0,0,0,0,10,0,0,0,0,0,0,0,0,0,0,0,0
0,0,0,0,0,0,10,0,2,0,0,0,2,0,10,0,0,0,0,0,0,0,0,0,0,0,0
0,0,0,0,0,0,10,0,0,0,0,0,0,0,10,0,0,0,0,0,2,11,11,11,2,0,0
0,0,0,0,0,0,0,0,0,0,0,0,0,0,0,0,0,0,0,0,11,0,0,12,11,0,0
0,0,0,0,0,0,0,0,0,0,0,0,0,0,2,2,2,2,2,0,11,0,0,0,11,0,0
0,0,0,0,0,0,0,0,0,2,11,11,11,2,2,2,2,2,2,0,11,0,0,0,11,0,0
0,0,0,0,0,0,0,0,0,11,0,0,12,11,2,2,2,2,2,0,2,11,11,11,2,0,0
0,0,0,0,0,0,0,0,0,11,0,0,0,11,2,2,2,2,2,0,0,0,0,0,0,0,0
0,0,0,0,0,0,0,0,0,11,0,0,0,11,2,2,2,2,2,0,0,0,0,0,0,0,0
0,0,0,0,0,0,0,0,0,2,11,11,11,2,0,2,2,2,0,0,0,0,0,0,0,0,0
0,0,0,0,0,0,0,0,0,0,0,0,0,0,0,0,0,0,0,0,0,0,0,0,0,0,0
0,0,0,0,0,0,0,0,0,0,0,0,0,0,0,0,0,0,0,0,0,0,0,0,0,0,0
0,0,0,0,0,0,0,0,0,0,0,0,0,0,0,0,0,0,0,0,0,0,0,0,0,0,0
endlayer

layer
0,0,0,0,0,0,0,0,0,0,0,0,0,0,0,0,0,0,0,0,0,0,0,0,0,0,0
0,0,0,0,0,0,0,0,0,0,0,0,0,0,0,0,0,0,0,0,0,0,0,0,0,0,0
0,0,0,0,0,0,0,0,0,0,0,0,0,0,0,0,0,0,0,0,0,0,0,0,0,0,0
0,0,0,0,0,0,0,0,0,0,0,0,0,0,0,0,0,0,0,0,0,0,0,0,0,0,0
0,0,0,0,0,0,0,2,11,11,11,11,11,11,11,2,0,0,0,0,0,0,0,0,0,0,0
0,0,0,0,0,0,0,11,24,24,24,24,24,24,24,11,0,0,0,10,10,10,10,0,0,0,0
0,0,0,0,0,0,0,20,0,0,0,0,0,0,0,20,0,0,0,10,0,0,10,0,0,0,0
0,0,0,0,0,0,0,20,0,0,0,0,0,0,0,20,0,0,0,10,0,0,10,0,0,0,0
0,0,0,0,0,0,0,11,0,0,0,0,0,0,0,11,0,0,0,10,0,0,10,0,0,0,0
0,0,0,0,0,0,0,2,11,11,11,20,20,20,11,2,29,29,29,29,0,0,29,29,29,29,0
0,0,0,0,0,0,0,0,0,0,0,0,0,0,0,0,29,0,0,0,0,0,0,0,0,29,0
0,0,0,0,0,0,0,0,0,0,0,0,0,0,0,0,29,0,0,0,0,0,0,0,0,29,0
0,0,0,0,0,0,0,0,0,0,0,0,0,0,0,0,29,0,0,0,0,0,0,0,0,29,0
0,0,0,0,0,0,0,0,2,2,2,2,2,0,0,0,29,0,0,0,0,0,0,0,0,29,0
0,0,0,0,0,0,0,0,2,21,2,2,2,0,0,0,29,0,0,0,0,0,0,0,0,29,0
0,0,0,0,0,0,0,0,2,2,2,2,2,0,0,0,29,29,29,29,29,29,42,29,29,29,0
0,0,0,0,0,0,0,0,2,2,2,2,2,0,0,0,0,0,0,0,0,29,42,29,0,0,0
0,0,0,0,0,0,0,0,2,2,2,2,2,0,0,0,0,0,0,0,0,29,29,29,0,0,0
0,0,0,0,0,0,0,0,0,2,2,2,0,0,0,0,0,0,0,0,1,1,1,1,1,0,0
0,0,0,0,0,0,0,0,0,2,2,2,0,0,0,0,0,0,0,0,1,11,11,12,1,0,0
0,0,0,0,0,0,0,0,0,2,2,2,0,0,2,11,11,11,2,0,1,11,11,11,1,0,0
0,0,0,0,0,0,0,0,0,1,1,1,1,1,11,0,0,7,11,0,1,11,11,11,1,0,0
0,0,0,0,0,0,0,0,0,1,11,11,12,0,0,0,0,0,11,0,1,1,1,1,1,0,0
0,0,0,0,0,0,0,0,0,1,11,11,11,1,11,0,0,8,11,0,0,0,0,0,0,0,0
0,0,0,0,0,0,0,0,0,1,11,11,11,1,2,11,16,11,2,0,0,0,0,0,0,0,0
0,0,0,0,0,0,0,0,0,1,1,1,1,1,0,10,10,10,0,0,0,0,0,0,0,0,0
0,0,0,0,0,0,0,0,0,0,0,0,0,0,0,0,0,0,0,0,0,0,0,0,0,0,0
0,0,0,0,0,0,0,0,0,0,0,0,0,0,0,0,0,0,0,0,0,0,0,0,0,0,0
0,0,0,0,0,0,0,0,0,0,0,0,0,0,0,0,0,0,0,0,0,0,0,0,0,0,0
endlayer

layer
0,0,0,0,0,0,0,0,0,0,0,0,0,0,0,0,0,0,0,0,0,0,0,0,0,0,0
0,0,0,0,0,0,0,0,0,0,0,0,0,0,0,0,0,0,0,0,0,0,0,0,0,0,0
0,0,0,0,0,0,0,0,0,0,0,0,0,0,0,0,0,0,0,0,0,0,0,0,0,0,0
0,0,0,0,0,0,0,0,0,0,0,0,0,0,0,0,0,0,0,0,0,0,0,0,0,0,0
0,0,0,0,0,0,0,2,11,11,11,11,11,11,11,2,0,0,0,0,0,0,0,0,0,0,0
0,0,0,0,0,0,0,11,11,11,11,11,11,11,11,11,0,0,0,10,0,0,10,0,0,0,0
0,0,0,0,0,0,0,11,0,0,0,0,0,0,0,11,0,0,0,0,0,0,0,0,0,0,0
0,0,0,0,0,0,0,11,0,0,0,0,0,0,0,11,0,0,0,0,0,0,0,0,0,0,0
0,0,0,0,0,0,0,11,11,11,11,11,11,11,11,11,0,0,0,10,0,0,10,0,0,0,0
0,0,0,0,0,0,0,2,11,11,11,11,11,11,11,2,10,10,10,10,0,0,10,10,10,10,0
0,0,0,0,0,0,0,0,0,0,0,0,0,0,0,0,10,0,0,0,0,0,0,0,0,10,0
0,0,0,0,0,0,0,0,0,0,0,0,0,0,0,0,10,0,0,0,0,0,0,0,0,29,0
0,0,0,0,0,0,0,0,0,0,0,0,0,0,0,0,10,0,0,0,0,0,0,0,0,10,0
0,0,0,0,0,0,0,0,2,11,11,11,2,0,0,0,10,0,0,0,0,0,0,0,0,10,0
0,0,0,0,0,0,0,0,11,0,0,0,11,0,0,0,10,0,0,0,0,0,0,0,0,10,0
0,0,0,0,0,0,0,0,11,0,0,0,11,0,0,0,10,10,10,10,10,29,0,29,10,29,0
0,0,0,0,0,0,0,0,11,0,0,0,11,0,0,0,0,0,0,0,0,10,0,10,0,0,0
0,0,0,0,0,0,0,0,2,11,0,11,2,0,0,0,0,0,0,0,0,10,0,10,0,0,0
0,0,0,0,0,0,0,0,0,10,0,10,0,0,0,0,0,0,0,0,10,10,0,10,10,0,0
0,0,0,0,0,0,0,0,0,10,0,10,0,0,0,0,0,0,0,0,10,0,0,0,10,0,0
0,0,0,0,0,0,0,0,0,10,0,10,0,0,2,11,20,11,2,0,10,0,0,0,10,0,0
0,0,0,0,0,0,0,0,0,10,0,10,1,10,11,0,0,7,11,0,10,0,0,0,10,0,0
0,0,0,0,0,0,0,0,0,10,0,0,12,0,0,0,0,0,20,0,10,10,10,10,10,0,0
0,0,0,0,0,0,0,0,0,10,0,0,0,10,11,0,0,0,11,0,0,0,0,0,0,0,0
0,0,0,0,0,0,0,0,0,10,0,0,0,10,2,11,23,11,2,0,0,0,0,0,0,0,0
0,0,0,0,0,0,0,0,0,10,10,10,10,10,0,0,0,0,0,0,0,0,0,0,0,0,0
0,0,0,0,0,0,0,0,0,0,0,0,0,0,0,0,0,0,0,0,0,0,0,0,0,0,0
0,0,0,0,0,0,0,0,0,0,0,0,0,0,0,0,0,0,0,0,0,0,0,0,0,0,0
0,0,0,0,0,0,0,0,0,0,0,0,0,0,0,0,0,0,0,0,0,0,0,0,0,0,0
endlayer

layer
0,0,0,0,0,0,0,0,0,0,0,0,0,0,0,0,0,0,0,0,0,0,0,0,0,0,0
0,0,0,0,0,0,0,0,0,0,0,0,0,0,0,0,0,0,0,0,0,0,0,0,0,0,0
0,0,0,0,0,0,0,0,0,0,0,0,0,0,0,0,0,0,0,0,0,0,0,0,0,0,0
0,0,0,0,0,0,0,25,25,25,25,25,25,25,25,25,0,0,0,0,0,0,0,0,0,0,0
0,0,0,0,0,0,0,2,2,2,2,2,2,2,2,2,0,0,0,0,0,0,0,0,0,0,0
0,0,0,0,0,0,0,2,2,2,2,2,2,2,2,2,0,0,0,2,2,2,2,0,0,0,0
0,0,0,0,0,0,0,2,2,2,2,2,2,2,2,2,0,0,0,2,2,2,2,0,0,0,0
0,0,0,0,0,0,0,2,2,2,2,2,2,2,2,2,0,0,0,2,2,2,2,0,0,0,0
0,0,0,0,0,0,0,2,2,2,2,2,2,2,2,2,0,0,0,2,2,2,2,0,0,0,0
0,0,0,0,0,0,0,2,2,2,2,2,2,2,2,2,0,0,0,0,0,0,0,0,0,0,0
0,0,0,0,0,0,0,13,13,13,13,13,13,13,13,13,0,0,0,0,0,0,0,0,0,0,0
0,0,0,0,0,0,0,0,0,0,0,0,0,0,0,0,0,0,0,0,0,0,0,0,0,29,0
0,0,0,0,0,0,0,0,0,0,0,0,0,0,0,0,0,0,0,0,0,0,0,0,0,0,0
0,0,0,0,0,0,0,0,2,11,20,11,2,0,0,0,0,0,0,0,0,0,0,0,0,0,0
0,0,0,0,0,0,0,0,11,0,0,0,11,0,0,0,0,0,0,0,0,0,0,0,0,0,0
0,0,0,0,0,0,0,0,20,0,0,0,20,0,0,0,0,0,0,0,0,29,0,29,0,29,0
0,0,0,0,0,0,0,0,11,0,0,0,11,0,0,0,0,0,0,0,0,0,0,0,0,0,0
0,0,0,0,0,0,0,0,2,11,0,11,2,0,0,0,0,0,0,0,0,0,0,0,0,0,0
0,0,0,0,0,0,0,0,0,0,0,0,0,0,0,0,0,0,0,0,10,10,0,10,10,0,0
0,0,0,0,0,0,0,0,0,0,0,0,0,0,0,0,0,0,0,0,10,0,0,0,10,0,0
0,0,0,0,0,0,0,0,0,0,0,0,0,0,2,11,11,11,2,0,0,0,0,0,0,0,0
0,0,0,0,0,0,0,0,0,10,0,0,1,10,11,0,0,7,11,0,10,0,0,0,10,0,0
0,0,0,0,0,0,0,0,0,10,0,0,12,0,11,0,0,0,11,0,0,0,0,0,0,0,0
0,0,0,0,0,0,0,0,0,0,0,0,0,0,11,0,0,0,11,0,0,0,0,0,0,0,0
0,0,0,0,0,0,0,0,0,10,0,0,0,10,2,11,11,11,2,0,0,0,0,0,0,0,0
0,0,0,0,0,0,0,0,0,10,10,0,10,10,0,0,0,0,0,0,0,0,0,0,0,0,0
0,0,0,0,0,0,0,0,0,0,0,0,0,0,0,0,0,0,0,0,0,0,0,0,0,0,0
0,0,0,0,0,0,0,0,0,0,0,0,0,0,0,0,0,0,0,0,0,0,0,0,0,0,0
0,0,0,0,0,0,0,0,0,0,0,0,0,0,0,0,0,0,0,0,0,0,0,0,0,0,0
endlayer

layer
0,0,0,0,0,0,0,0,0,0,0,0,0,0,0,0,0,0,0,0,0,0,0,0,0,0,0
0,0,0,0,0,0,0,0,0,0,0,0,0,0,0,0,0,0,0,0,0,0,0,0,0,0,0
0,0,0,0,0,0,0,0,0,0,0,0,0,0,0,0,0,0,0,0,0,0,0,0,0,0,0
0,0,0,0,0,0,0,0,0,0,0,0,0,0,0,0,0,0,0,2,2,2,0,0,0,0,0
0,0,0,0,0,0,0,25,25,25,25,25,25,25,25,25,0,0,2,2,2,2,2,0,0,0,0
0,0,0,0,0,0,0,2,2,2,2,2,2,2,2,2,0,0,2,2,2,2,2,0,0,0,0
0,0,0,0,0,0,0,2,2,2,2,2,2,2,2,2,0,0,2,2,2,2,2,0,0,0,0
0,0,0,0,0,0,0,2,2,2,2,2,2,2,2,2,0,0,2,2,2,2,2,0,0,0,0
0,0,0,0,0,0,0,2,2,2,2,2,2,2,2,2,0,0,0,2,2,2,2,2,2,0,0
0,0,0,0,0,0,0,13,13,13,13,13,13,13,13,13,0,0,0,2,2,2,2,2,2,0,0
0,0,0,0,0,0,0,0,0,0,0,0,0,0,0,0,0,0,0,2,2,2,2,2,2,0,0
0,0,0,0,0,0,0,0,0,0,0,0,0,0,0,0,0,0,0,2,2,2,2,2,2,2,2
0,0,0,0,0,0,0,0,0,0,0,0,0,0,0,0,0,0,0,0,2,11,11,11,11,11,2
0,0,0,0,0,0,0,0,2,11,11,11,2,0,0,0,0,0,0,0,2,11,11,11,11,11,2
0,0,0,0,0,0,0,0,11,0,0,0,11,0,0,0,0,0,0,0,2,11,11,11,11,11,2
0,0,0,0,0,0,0,0,11,0,0,0,11,0,0,0,0,0,0,0,2,11,11,11,11,11,2
0,0,0,0,0,0,0,0,11,0,0,0,11,0,0,0,0,0,2,2,2,11,11,11,11,11,2
0,0,0,0,0,0,0,0,2,11,11,11,2,0,0,0,0,0,2,11,11,11,11,11,11,11,2
0,0,0,0,0,0,0,0,0,0,0,0,0,0,0,0,0,0,2,11,11,11,11,11,11,11,2
0,0,0,0,0,0,0,0,0,0,0,0,0,0,0,0,0,0,2,11,11,11,11,11,11,11,2
0,0,0,0,0,0,0,0,0,0,0,0,0,0,1,1,1,1,1,11,11,11,11,11,11,11,2
0,0,0,0,0,0,0,0,0,2,2,2,2,2,1,11,11,7,1,2,2,2,2,2,2,2,2
0,0,0,0,0,0,0,0,0,2,2,2,12,2,1,11,11,11,1,2,2,2,0,0,0,0,0
0,0,0,0,0,0,0,0,0,2,2,2,2,2,1,11,11,11,1,2,2,2,0,0,0,0,0
0,0,0,0,0,0,0,0,0,2,2,2,2,2,1,1,1,1,1,0,0,0,0,0,0,0,0
0,0,0,0,0,0,0,0,0,2,2,2,2,2,0,0,0,0,0,0,0,0,0,0,0,0,0
0,0,0,0,0,0,0,0,0,0,0,0,0,0,0,0,0,0,0,0,0,0,0,0,0,0,0
0,0,0,0,0,0,0,0,0,0,0,0,0,0,0,0,0,0,0,0,0,0,0,0,0,0,0
0,0,0,0,0,0,0,0,0,0,0,0,0,0,0,0,0,0,0,0,0,0,0,0,0,0,0
endlayer

layer
0,0,0,0,0,0,0,0,0,0,0,0,0,0,0,0,0,0,0,0,0,0,0,0,0,0,0
0,0,0,0,0,0,0,0,0,0,0,0,0,0,0,0,0,0,0,0,0,0,0,0,0,0,0
0,0,0,0,0,0,0,0,0,0,0,0,0,0,0,0,0,0,0,0,0,0,0,0,0,0,0
0,0,0,0,0,0,0,0,0,0,0,0,0,0,0,0,0,0,0,2,2,2,0,0,0,0,0
0,0,0,0,0,0,0,0,0,0,0,0,0,0,0,0,0,0,2,2,2,2,2,0,0,0,0
0,0,0,0,0,0,0,25,25,25,25,25,25,25,25,25,0,0,2,2,4,2,2,0,0,0,0
0,0,0,0,0,0,0,2,2,2,2,2,2,2,2,2,0,0,2,4,0,4,2,0,0,0,0
0,0,0,0,0,0,0,2,2,2,2,2,2,2,2,2,0,0,2,0,0,0,2,0,0,0,0
0,0,0,0,0,0,0,13,13,13,13,13,13,13,13,13,0,0,2,0,0,7,2,10,10,0,0
0,0,0,0,0,0,0,0,0,0,0,0,0,0,0,0,0,0,2,0,0,0,0,0,10,0,0
0,0,0,0,0,0,0,0,0,0,0,0,0,0,0,0,0,0,2,0,0,0,2,0,10,0,0
0,0,0,0,0,0,0,0,0,0,0,0,0,0,0,0,0,0,0,2,16,2,2,0,2,2,2
0,0,0,0,0,0,0,0,0,0,0,0,0,0,0,0,0,0,0,0,2,8,0,0,0,0,2
0,0,0,0,0,0,0,0,1,1,1,1,1,0,0,0,0,0,0,0,2,0,0,0,0,0,2
0,0,0,0,0,0,0,0,1,11,11,11,1,0,0,0,0,0,0,0,2,0,0,0,0,0,2
0,0,0,0,0,0,0,0,1,11,11,11,1,0,0,0,0,0,0,0,2,0,0,0,0,0,2
0,0,0,0,0,0,0,0,1,11,11,11,1,0,0,0,0,0,2,2,2,6,0,0,0,6,2
0,0,0,0,0,0,0,0,1,1,1,1,1,0,0,0,0,0,2,0,0,0,0,0,0,0,2
0,0,0,0,0,0,0,0,0,0,0,0,0,0,0,0,0,0,2,0,0,0,0,0,0,0,2
0,0,0,0,0,0,0,0,0,0,0,0,0,0,0,0,0,0,2,0,0,0,0,0,0,0,2
0,0,0,0,0,0,0,0,0,0,0,0,0,0,10,10,10,10,2,0,0,0,0,0,0,0,2
0,0,0,0,0,0,0,0,0,2,11,11,11,2,10,0,0,0,2,2,0,2,2,2,2,2,2
0,0,0,0,0,0,0,0,0,11,0,0,12,11,10,0,0,0,0,0,0,10,0,0,0,0,0
0,0,0,0,0,0,0,0,0,11,0,0,0,0,0,0,0,0,10,10,10,10,0,0,0,0,0
0,0,0,0,0,0,0,0,0,11,0,0,0,11,10,10,10,10,10,0,0,0,0,0,0,0,0
0,0,0,0,0,0,0,0,0,2,11,11,11,2,0,0,0,0,0,0,0,0,0,0,0,0,0
0,0,0,0,0,0,0,0,0,0,0,0,0,0,0,0,0,0,0,0,0,0,0,0,0,0,0
0,0,0,0,0,0,0,0,0,0,0,0,0,0,0,0,0,0,0,0,0,0,0,0,0,0,0
0,0,0,0,0,0,0,0,0,0,0,0,0,0,0,0,0,0,0,0,0,0,0,0,0,0,0
endlayer

layer
0,0,0,0,0,0,0,0,0,0,0,0,0,0,0,0,0,0,0,0,0,0,0,0,0,0,0
0,0,0,0,0,0,0,0,0,2,2,2,2,2,2,2,0,0,0,0,0,0,0,0,0,0,0
0,0,0,0,0,0,0,0,0,2,11,11,11,11,11,2,0,0,0,0,0,0,0,0,0,0,0
0,0,0,0,0,0,0,0,0,2,11,11,11,11,11,2,0,0,0,2,2,2,0,0,0,0,0
0,0,0,0,0,0,0,0,0,2,11,11,11,11,11,2,0,0,2,3,0,19,2,0,0,0,0
0,0,0,0,0,0,0,0,0,2,11,11,11,11,11,2,0,0,2,0,0,0,2,0,0,0,0
0,0,0,0,0,0,0,2,2,2,11,11,11,11,11,2,0,0,2,0,0,0,2,0,0,0,0
0,0,0,0,0,0,0,2,11,11,11,11,11,11,11,2,0,0,2,0,0,0,2,0,0,0,0
0,0,0,0,0,0,0,2,11,11,11,11,11,11,11,2,0,0,2,0,0,7,2,0,0,0,0
0,0,0,0,0,0,0,2,11,11,11,11,11,11,11,2,0,0,20,0,0,0,0,0,0,0,0
0,0,0,0,0,0,0,2,11,11,11,11,11,11,11,2,0,0,2,0,0,0,2,0,0,0,0
0,0,0,0,0,0,0,2,2,2,2,2,2,2,2,2,0,0,0,2,23,2,2,0,2,2,2
0,0,0,0,0,0,0,0,0,0,0,0,0,0,0,0,0,0,0,0,1,0,0,0,0,0,1
0,0,0,0,0,0,0,2,2,2,2,2,0,0,0,0,0,0,0,0,20,0,0,0,0,0,20
0,0,0,0,0,0,0,2,2,2,2,2,0,0,0,0,0,0,0,0,20,0,0,0,0,0,20
0,0,0,0,0,0,0,2,2,2,2,2,0,0,0,0,0,0,0,0,1,0,0,0,0,0,1
0,0,0,0,0,0,0,2,2,2,2,2,0,0,0,0,0,0,2,11,11,0,0,0,0,0,11
0,0,0,0,0,0,0,2,2,2,2,2,0,0,0,0,0,0,1,0,0,0,0,0,0,0,1
0,0,0,0,0,0,0,2,2,2,2,2,0,0,0,0,0,0,20,0,0,0,0,0,0,0,20
0,0,0,0,0,0,0,2,2,2,2,2,0,0,0,0,0,0,20,0,0,0,0,0,0,0,20
0,0,0,0,0,0,0,0,2,2,2,0,0,0,0,0,0,0,1,0,0,0,0,0,0,0,1
0,0,0,0,0,0,0,0,0,2,11,20,11,2,0,0,0,0,2,11,0,11,1,20,1,11,2
0,0,0,0,0,0,0,0,0,11,0,0,12,11,0,0,0,0,0,0,0,0,0,0,0,0,0
0,0,0,0,0,0,0,0,0,20,0,0,0,0,0,0,0,0,0,0,0,0,0,0,0,0,0
0,0,0,0,0,0,0,0,0,11,0,0,0,11,0,0,0,0,0,0,0,0,0,0,0,0,0
0,0,0,0,0,0,0,0,0,2,11,20,11,2,0,0,0,0,0,0,0,0,0,0,0,0,0
0,0,0,0,0,0,0,0,0,0,0,0,0,0,0,0,0,0,0,0,0,0,0,0,0,0,0
0,0,0,0,0,0,0,0,0,0,0,0,0,0,0,0,0,0,0,0,0,0,0,0,0,0,0
0,0,0,0,0,0,0,0,0,0,0,0,0,0,0,0,0,0,0,0,0,0,0,0,0,0,0
endlayer

layer
0,0,0,0,0,0,0,0,0,0,0,0,0,0,0,0,0,0,0,0,0,0,0,0,0,0,0
0,0,0,0,0,0,0,0,0,2,2,2,2,2,2,2,0,0,0,0,0,0,0,0,0,0,0
0,0,0,0,0,0,0,0,0,2,0,0,0,0,0,2,0,0,0,0,0,0,0,0,0,0,0
0,0,0,0,0,0,0,0,0,2,0,0,0,0,0,2,0,0,0,2,20,2,0,0,0,0,0
0,0,0,0,0,0,0,0,0,2,0,0,0,0,0,2,0,0,2,0,0,0,2,0,0,0,0
0,0,0,0,0,0,0,0,0,2,0,0,0,0,0,2,0,0,20,0,0,0,20,0,0,0,0
0,0,0,0,0,0,0,2,2,2,0,0,0,0,0,2,0,0,2,0,0,0,2,0,0,0,0
0,0,0,0,0,0,0,2,0,0,0,0,0,0,0,2,0,0,2,0,0,0,2,0,0,0,0
0,0,0,0,0,0,0,2,0,0,0,0,0,0,0,2,0,0,2,0,0,7,2,0,0,0,0
0,0,0,0,0,0,0,2,0,0,0,0,0,0,0,2,0,0,20,0,0,0,0,0,0,0,0
0,0,0,0,0,0,0,2,0,0,0,0,0,0,0,2,0,0,2,0,0,0,2,0,0,0,0
0,0,0,0,0,0,0,2,2,0,2,2,2,2,2,2,0,0,0,2,2,2,2,2,2,2,2
0,0,0,0,0,0,0,0,0,0,0,0,0,0,0,0,0,0,0,14,2,0,0,0,0,0,2
0,0,0,0,0,0,0,2,2,2,2,2,0,0,0,0,0,0,0,14,2,0,0,0,0,0,2
0,0,0,0,0,0,0,2,2,4,2,2,0,0,0,0,0,0,0,14,2,0,0,0,0,0,2
0,0,0,0,0,0,0,2,4,0,4,2,0,0,0,0,0,0,25,11,2,0,0,0,0,0,2
0,0,0,0,0,0,0,2,0,0,0,2,0,0,0,0,0,0,2,11,11,0,0,0,0,0,2
0,0,0,0,0,0,0,2,0,0,7,2,0,0,0,0,0,0,2,0,0,0,0,0,0,0,2
0,0,0,0,0,0,0,2,0,0,0,2,0,0,0,0,0,0,2,0,0,0,0,0,0,0,2
0,0,0,0,0,0,0,2,0,0,0,2,0,0,0,0,0,0,2,0,0,0,0,0,0,0,2
0,0,0,0,0,0,0,0,2,16,2,0,0,0,0,0,0,0,2,0,0,0,0,0,0,0,2
0,0,0,0,0,0,0,0,0,11,11,11,11,2,0,0,0,0,2,11,11,11,11,11,11,11,2
0,0,0,0,0,0,0,0,0,11,0,0,12,11,0,0,0,0,13,13,13,13,13,13,13,13,13
0,0,0,0,0,0,0,0,0,11,0,0,0,11,0,0,0,0,0,0,0,0,0,0,0,0,0
0,0,0,0,0,0,0,0,0,11,0,0,0,11,0,0,0,0,0,0,0,0,0,0,0,0,0
0,0,0,0,0,0,0,0,0,2,11,11,11,2,0,0,0,0,0,0,0,0,0,0,0,0,0
0,0,0,0,0,0,0,0,0,0,0,0,0,0,0,0,0,0,0,0,0,0,0,0,0,0,0
0,0,0,0,0,0,0,0,0,0,0,0,0,0,0,0,0,0,0,0,0,0,0,0,0,0,0
0,0,0,0,0,0,0,0,0,0,0,0,0,0,0,0,0,0,0,0,0,0,0,0,0,0,0
endlayer

layer
0,0,0,0,0,0,0,0,0,0,0,0,0,0,0,0,0,0,0,0,0,0,0,0,0,0,0
0,0,0,0,0,0,0,0,0,2,2,2,2,2,2,2,0,0,0,0,0,0,0,0,0,0,0
0,0,0,0,0,0,0,0,0,1,0,0,0,0,0,1,0,0,0,0,0,0,0,0,0,0,0
0,0,0,0,0,0,0,0,0,20,0,0,0,0,0,20,0,0,0,2,2,2,0,0,0,0,0
0,0,0,0,0,0,0,0,0,20,0,0,0,0,0,20,0,0,2,0,33,0,2,0,0,0,0
0,0,0,0,0,0,0,0,0,1,0,0,0,0,0,1,0,0,2,0,0,43,2,0,0,0,0
0,0,0,0,0,0,0,2,11,11,0,0,0,0,0,11,0,0,2,0,0,0,2,0,0,0,0
0,0,0,0,0,0,0,1,0,0,0,0,0,0,0,1,0,0,2,2,2,2,2,0,0,0,0
0,0,0,0,0,0,0,20,0,0,0,0,0,0,0,20,0,0,2,2,2,7,2,0,0,0,0
0,0,0,0,0,0,0,20,0,0,0,0,0,0,0,20,0,0,2,2,2,2,2,0,0,0,0
0,0,0,0,0,0,0,1,0,0,0,0,0,0,0,1,0,0,2,2,2,2,2,0,0,0,0
0,0,0,0,0,0,0,2,11,0,11,1,20,1,11,2,0,0,2,2,2,2,1,20,1,11,27
0,0,0,0,0,0,0,0,0,0,0,0,0,0,0,0,0,0,0,0,14,11,0,0,0,11,27
0,0,0,0,0,0,0,2,3,4,19,2,0,0,0,0,0,0,0,0,14,11,0,0,0,11,27
0,0,0,0,0,0,0,2,0,0,0,2,0,0,0,0,0,0,0,0,14,11,0,0,0,11,27
0,0,0,0,0,0,0,2,0,0,0,2,0,0,0,0,0,0,0,0,14,11,0,0,0,11,27
0,0,0,0,0,0,0,2,0,0,0,2,0,0,0,0,0,0,25,25,11,11,0,0,0,11,27
0,0,0,0,0,0,0,2,0,0,7,2,0,0,0,0,0,0,11,11,11,11,0,0,0,11,11
0,0,0,0,0,0,0,20,0,0,0,20,0,0,0,0,0,0,11,0,0,0,0,0,0,11,11
0,0,0,0,0,0,0,2,0,0,0,2,0,0,0,0,0,0,11,0,0,0,0,0,0,11,11
0,0,0,0,0,0,0,0,2,23,2,0,0,0,0,0,0,0,11,11,11,11,11,11,11,11,11
0,0,0,0,0,0,0,0,0,1,1,1,1,1,1,1,0,0,13,13,13,13,13,13,13,13,13
0,0,0,0,0,0,0,0,0,1,11,11,12,1,11,1,0,0,0,0,0,0,0,0,0,0,0
0,0,0,0,0,0,0,0,0,1,11,11,11,1,11,1,0,0,0,0,0,0,0,0,0,0,0
0,0,0,0,0,0,0,0,0,1,11,11,11,1,11,1,0,0,0,0,0,0,0,0,0,0,0
0,0,0,0,0,0,0,0,0,1,1,1,1,1,1,1,0,0,0,0,0,0,0,0,0,0,0
0,0,0,0,0,0,0,0,0,0,0,0,0,0,0,0,0,0,0,0,0,0,0,0,0,0,0
0,0,0,0,0,0,0,0,0,0,0,0,0,0,0,0,0,0,0,0,0,0,0,0,0,0,0
0,0,0,0,0,0,0,0,0,0,0,0,0,0,0,0,0,0,0,0,0,0,0,0,0,0,0
endlayer

layer
0,0,0,0,0,0,0,0,0,0,0,0,0,0,0,0,0,0,0,0,0,0,0,0,0,0,0
0,0,0,0,0,0,0,0,14,2,2,2,2,2,2,2,0,0,0,0,0,0,0,0,0,0,0
0,0,0,0,0,0,0,0,14,2,0,0,0,0,0,2,0,0,0,0,0,0,0,0,0,0,0
0,0,0,0,0,0,0,0,14,2,0,0,0,0,0,2,0,0,0,0,2,0,0,0,0,0,0
0,0,0,0,0,0,0,0,14,2,0,0,0,0,0,2,0,0,2,2,2,2,2,0,0,0,0
0,0,0,0,0,0,0,25,11,2,0,0,0,0,0,2,0,0,2,2,2,2,2,0,0,0,0
0,0,0,0,0,0,0,2,11,11,0,0,0,0,0,2,0,0,2,0,2,0,2,0,0,0,0
0,0,0,0,0,0,0,2,0,0,0,0,0,0,0,2,0,0,2,2,2,2,2,0,0,0,0
0,0,0,0,0,0,0,2,0,0,0,0,0,0,0,2,0,0,2,0,4,7,2,0,0,0,0
0,0,0,0,0,0,0,2,0,0,0,0,0,0,0,2,0,0,2,0,0,0,2,0,0,0,0
0,0,0,0,0,0,0,2,0,0,0,0,0,0,0,2,0,0,2,0,0,0,2,0,0,0,0
0,0,0,0,0,0,0,2,11,11,11,11,11,11,11,2,0,0,0,2,2,2,0,11,11,27,0
0,0,0,0,0,0,0,2,13,13,13,2,13,13,13,13,0,0,0,0,0,14,11,0,11,27,0
0,0,0,0,0,0,0,2,0,0,0,2,0,0,0,0,0,0,0,0,0,14,11,0,11,27,0
0,0,0,0,0,0,0,20,0,0,0,20,0,0,0,0,0,0,0,0,0,14,11,0,11,27,0
0,0,0,0,0,0,0,2,0,0,0,2,0,0,0,0,0,0,0,0,0,14,11,0,11,27,0
0,0,0,0,0,0,0,2,0,0,0,2,0,0,0,0,0,0,0,0,0,14,11,0,11,27,0
0,0,0,0,0,0,0,2,0,0,7,2,0,0,0,0,0,0,25,25,25,11,11,0,11,11,25
0,0,0,0,0,0,0,20,0,0,0,20,0,0,0,0,0,0,11,11,11,11,11,11,11,11,11
0,0,0,0,0,0,0,2,0,0,0,2,0,2,2,2,0,0,11,11,11,11,11,11,11,11,11
0,0,0,0,0,0,0,0,2,2,2,0,0,2,4,2,0,0,13,13,13,13,13,13,13,13,13
0,0,0,0,0,0,0,0,0,10,10,10,10,10,0,10,0,0,0,0,0,0,0,0,0,0,0
0,0,0,0,0,0,0,0,0,10,0,0,0,10,0,10,0,0,0,0,0,0,0,0,0,0,0
0,0,0,0,0,0,0,0,0,10,0,0,0,0,0,10,0,0,0,0,0,0,0,0,0,0,0
0,0,0,0,0,0,0,0,0,10,0,0,0,10,0,10,0,0,0,0,0,0,0,0,0,0,0
0,0,0,0,0,0,0,0,0,10,10,10,10,10,10,10,0,0,0,0,0,0,0,0,0,0,0
0,0,0,0,0,0,0,0,0,0,0,0,0,0,0,0,0,0,0,0,0,0,0,0,0,0,0
0,0,0,0,0,0,0,0,0,0,0,0,0,0,0,0,0,0,0,0,0,0,0,0,0,0,0
0,0,0,0,0,0,0,0,0,0,0,0,0,0,0,0,0,0,0,0,0,0,0,0,0,0,0
endlayer

layer
0,0,0,0,0,0,0,0,0,0,0,0,0,0,0,0,0,0,0,0,0,0,0,0,0,0,0
0,0,0,0,0,0,0,0,0,14,11,1,20,1,11,27,0,0,2,2,2,2,2,0,0,0,0
0,0,0,0,0,0,0,0,0,14,11,0,0,0,11,27,0,0,2,2,2,2,2,0,0,0,0
0,0,0,0,0,0,0,0,0,14,11,0,0,0,11,27,0,0,2,2,2,2,2,0,0,0,0
0,0,0,0,0,0,0,0,0,14,11,0,0,0,11,27,0,0,2,2,2,2,2,0,0,0,0
0,0,0,0,0,0,0,0,0,14,11,0,0,0,11,27,0,0,2,2,4,2,2,0,0,0,0
0,0,0,0,0,0,0,25,25,11,11,0,0,0,11,27,0,0,0,2,0,2,0,0,0,0,0
0,0,0,0,0,0,0,11,11,11,11,0,0,0,11,11,0,0,0,2,0,2,0,0,0,0,0
0,0,0,0,0,0,0,11,0,0,0,0,0,0,11,11,0,0,2,0,0,7,2,0,0,0,0
0,0,0,0,0,0,0,11,0,0,0,0,0,0,11,11,0,0,20,0,0,0,20,0,0,0,0
0,0,0,0,0,0,0,11,11,11,11,11,11,11,11,11,0,0,2,0,0,0,2,0,0,0,0
0,0,0,0,0,0,0,2,13,13,13,2,13,13,13,13,0,0,0,2,20,2,0,11,27,0,0
0,0,0,0,0,0,0,2,0,0,0,2,0,0,0,0,0,0,0,0,0,0,14,11,27,0,0
0,0,0,0,0,0,0,2,0,0,0,2,0,0,0,0,0,0,0,0,0,0,14,11,27,0,0
0,0,0,0,0,0,0,2,0,0,43,2,2,2,2,2,2,0,0,0,0,0,14,11,27,0,0
0,0,0,0,0,0,0,2,0,0,0,2,2,2,2,2,2,0,0,0,0,0,14,11,27,0,0
0,0,0,0,0,0,0,2,2,2,2,2,2,2,2,2,2,0,0,0,0,0,14,11,27,0,0
0,0,0,0,0,0,0,2,2,2,7,2,2,2,2,2,2,2,2,2,0,0,14,11,27,0,0
0,0,0,0,0,0,0,2,2,2,2,2,2,2,2,2,2,2,2,2,2,25,11,11,11,25,25
0,0,0,0,0,0,0,2,2,2,2,2,0,2,4,2,2,2,2,2,2,13,13,13,13,13,13
0,0,0,0,0,0,0,2,2,2,2,2,0,10,0,10,2,2,2,2,2,0,0,0,0,0,0
0,0,0,0,0,0,0,0,0,10,10,0,10,10,0,10,2,2,2,2,2,0,0,0,0,0,0
0,0,0,0,0,0,0,0,0,10,0,0,0,10,0,0,2,2,2,2,2,0,0,0,0,0,0
0,0,0,0,0,0,0,0,0,0,0,0,0,0,0,0,2,2,2,2,2,0,0,0,0,0,0
0,0,0,0,0,0,0,0,0,10,0,0,0,10,0,0,2,2,2,2,2,0,0,0,0,0,0
0,0,0,0,0,0,0,0,0,10,10,0,10,10,0,0,0,2,2,2,0,0,0,0,0,0,0
0,0,0,0,0,0,0,0,0,0,0,0,0,0,0,0,0,2,2,2,0,0,0,0,0,0,0
0,0,0,0,0,0,0,0,0,0,0,0,0,0,0,0,0,0,0,0,0,0,0,0,0,0,0
0,0,0,0,0,0,0,0,0,0,0,0,0,0,0,0,0,0,0,0,0,0,0,0,0,0,0
endlayer

layer
0,0,0,0,0,0,0,0,0,0,0,0,0,0,0,0,0,0,0,0,0,0,0,0,0,0,0
0,0,0,0,0,0,0,0,0,0,14,11,11,11,27,0,0,0,2,11,11,11,2,0,0,0,0
0,0,0,0,0,0,0,0,0,0,14,11,0,11,27,0,0,0,11,0,0,0,11,0,0,0,0
0,0,0,0,0,0,0,0,0,0,14,11,0,11,27,0,0,0,11,0,0,0,11,0,0,0,0
0,0,0,0,0,0,0,0,0,0,14,11,0,11,27,0,0,0,11,8,0,6,11,0,0,0,0
0,0,0,0,0,0,0,0,0,0,14,11,0,11,27,0,0,0,2,11,0,11,2,0,0,0,0
0,0,0,0,0,0,0,0,0,0,14,11,0,11,27,0,0,0,0,10,0,10,0,0,0,0,0
0,0,0,0,0,0,0,25,25,25,11,11,0,11,11,25,0,0,0,2,0,2,0,0,0,0,0
0,0,0,0,0,0,0,11,11,11,11,11,11,11,11,11,0,0,2,0,0,7,2,0,0,0,0
0,0,0,0,0,0,0,11,11,11,11,11,11,11,11,11,0,0,20,0,0,0,20,0,0,0,0
0,0,0,0,0,0,0,2,11,13,11,2,2,13,13,13,0,0,2,0,0,0,2,0,0,0,0
0,0,0,0,0,0,0,2,2,0,2,2,0,10,10,10,0,0,0,2,20,2,0,0,0,0,0
0,0,0,0,0,0,0,2,2,0,2,2,0,0,0,0,0,0,0,0,0,0,0,0,0,0,0
0,0,0,0,0,0,0,2,2,0,2,2,0,0,0,0,2,2,2,2,2,0,0,0,0,0,0
0,0,0,0,0,0,0,0,2,2,2,0,2,11,11,11,2,2,2,2,2,0,0,0,0,0,0
0,0,0,0,0,0,0,0,2,2,2,0,11,0,0,12,2,2,2,2,2,0,0,0,0,0,0
0,0,0,0,0,0,0,0,2,4,2,0,11,0,0,0,2,2,2,2,2,2,2,2,2,0,0
0,0,0,0,0,0,0,2,0,0,7,2,11,0,0,0,2,2,2,2,2,2,9,9,2,0,0
0,0,0,0,0,0,0,2,0,0,0,2,2,11,0,11,2,2,2,2,2,2,9,9,2,0,0
0,0,0,0,0,0,0,2,0,8,0,2,0,10,0,10,2,2,4,2,2,2,9,9,2,0,0
0,0,0,0,0,0,0,0,2,2,2,0,0,10,0,10,2,4,0,4,2,2,2,2,2,0,0
0,0,0,0,0,0,0,0,0,2,2,2,2,2,0,0,2,0,0,0,2,0,4,0,0,0,0
0,0,0,0,0,0,0,0,0,2,2,2,2,2,0,0,2,0,0,7,2,0,0,0,0,0,0
0,0,0,0,0,0,0,0,0,2,2,2,2,2,0,0,2,0,0,0,2,0,0,0,0,0,0
0,0,0,0,0,0,0,0,0,2,2,2,2,2,0,0,2,0,0,0,2,0,0,0,0,0,0
0,0,0,0,0,0,0,0,0,2,2,2,2,2,0,0,0,2,44,2,0,0,0,0,0,0,0
0,0,0,0,0,0,0,0,0,0,0,0,0,0,0,0,0,10,10,10,0,0,0,0,0,0,0
0,0,0,0,0,0,0,0,0,0,0,0,0,0,0,0,0,0,0,0,0,0,0,0,0,0,0
0,0,0,0,0,0,0,0,0,0,0,0,0,0,0,0,0,0,0,0,0,0,0,0,0,0,0
endlayer

layer
0,0,0,0,0,0,0,0,0,0,0,0,0,0,0,0,0,0,0,0,0,0,0,0,0,0,0
0,0,0,0,0,0,0,0,0,0,0,14,11,27,0,0,0,0,2,11,20,11,2,0,0,0,0
0,0,0,0,0,0,0,0,0,0,0,14,11,27,0,0,0,0,11,0,0,0,11,0,0,0,0
0,0,0,0,0,0,0,0,0,2,2,2,2,2,0,0,0,0,20,0,0,0,20,0,0,0,0
0,0,0,0,0,0,0,0,0,2,2,2,2,2,0,0,0,0,11,0,0,0,11,0,0,0,0
0,0,0,0,0,0,0,0,0,2,2,2,2,2,0,0,0,0,2,11,0,11,2,0,0,0,0
0,0,0,0,0,0,0,0,0,2,2,2,2,2,0,0,0,0,0,0,0,0,0,0,0,0,0
0,0,0,0,0,0,0,0,0,2,2,2,2,2,2,2,2,2,0,2,2,2,0,0,0,0,0
0,0,0,0,0,0,0,25,11,11,11,11,11,2,2,2,2,2,2,0,0,7,2,0,0,0,0
0,0,0,0,0,0,0,2,13,13,13,11,11,2,2,2,2,2,2,0,0,0,2,0,0,0,0
0,0,0,0,0,0,0,2,0,0,0,2,2,2,2,2,2,2,2,0,0,0,2,0,0,0,0
0,0,0,0,0,0,0,2,0,0,0,2,0,2,2,2,2,2,0,2,2,2,0,0,0,0,0
0,0,0,0,0,0,0,2,0,0,7,2,0,0,0,0,0,0,0,0,0,0,0,0,0,0,0
0,0,0,0,0,0,0,2,0,39,0,2,0,0,0,0,2,11,11,11,2,0,0,0,0,0,0
0,0,0,0,0,0,0,2,0,0,0,2,2,11,20,11,11,0,0,12,11,0,0,0,0,0,0
0,0,0,0,0,0,0,0,2,44,2,0,11,0,0,12,11,0,0,0,11,0,0,0,0,0,0
0,0,0,0,0,0,0,0,2,0,2,0,20,0,0,0,11,0,0,0,11,1,11,11,1,0,0
0,0,0,0,0,0,0,2,0,0,7,2,11,0,0,0,2,11,0,11,2,11,10,0,11,0,0
0,0,0,0,0,0,0,20,0,0,0,20,2,11,0,11,2,3,0,19,2,11,0,0,11,0,0
0,0,0,0,0,0,0,2,0,0,0,2,0,0,0,0,2,0,0,0,2,11,0,0,11,0,0
0,0,0,0,0,0,0,0,2,20,2,0,0,0,0,0,2,0,0,0,2,1,16,11,1,0,0
0,0,0,0,0,0,0,0,0,2,11,11,11,2,0,0,2,0,0,0,2,0,0,0,0,0,0
0,0,0,0,0,0,0,0,0,11,0,0,12,11,0,0,2,0,0,7,2,0,0,0,0,0,0
0,0,0,0,0,0,0,0,0,11,0,0,0,11,0,0,20,0,0,0,20,0,0,0,0,0,0
0,0,0,0,0,0,0,0,0,11,0,0,0,11,0,0,2,0,0,0,2,0,0,0,0,0,0
0,0,0,0,0,0,0,0,0,2,11,0,11,2,0,0,0,2,23,2,0,0,0,0,0,0,0
0,0,0,0,0,0,0,0,0,0,0,0,0,0,0,0,0,0,0,0,0,0,0,0,0,0,0
0,0,0,0,0,0,0,0,0,0,0,0,0,0,0,0,0,0,0,0,0,0,0,0,0,0,0
0,0,0,0,0,0,0,0,0,0,0,0,0,0,0,0,0,0,0,0,0,0,0,0,0,0,0
endlayer

layer
0,0,0,0,0,0,0,0,0,0,0,0,0,0,0,0,0,0,0,0,0,0,0,0,0,0,0
0,0,0,0,0,0,0,0,0,0,0,0,0,0,0,0,0,0,2,11,11,11,2,0,0,0,0
0,0,0,0,0,0,0,0,0,0,0,0,0,0,0,0,0,0,11,0,0,0,11,0,0,0,0
0,0,0,0,0,0,0,0,0,2,11,11,11,2,0,0,0,0,11,0,0,0,11,0,0,0,0
0,0,0,0,0,0,0,0,0,11,0,0,12,11,0,0,0,0,11,0,0,0,11,0,0,0,0
0,0,0,0,0,0,0,0,0,11,0,0,0,11,0,0,0,0,2,11,11,11,2,0,0,0,0
0,0,0,0,0,0,0,0,0,11,0,0,0,11,0,0,0,0,0,0,0,0,0,0,0,0,0
0,0,0,0,0,0,0,0,2,2,11,0,11,2,11,11,11,2,2,2,2,2,2,0,0,0,0
0,0,0,0,0,0,0,2,3,0,0,0,0,11,0,0,12,11,2,2,2,7,2,0,0,0,0
0,0,0,0,0,0,0,2,0,0,0,0,0,0,0,0,0,11,2,2,2,2,2,0,0,0,0
0,0,0,0,0,0,0,2,0,0,0,2,2,11,0,0,0,11,2,2,2,2,2,0,0,0,0
0,0,0,0,0,0,0,2,0,0,0,2,0,2,11,11,11,2,2,2,2,2,2,0,0,0,0
0,0,0,0,0,0,0,2,0,0,7,2,0,0,0,0,0,0,0,0,0,0,0,0,0,0,0
0,0,0,0,0,0,0,20,0,0,0,20,0,0,0,0,2,11,20,11,2,0,0,0,0,0,0
0,0,0,0,0,0,0,2,0,0,0,2,2,11,11,11,11,0,0,12,11,0,0,0,0,0,0
0,0,0,0,0,0,0,0,2,23,2,0,11,0,0,12,20,0,0,0,20,0,0,0,0,0,0
0,0,0,0,0,0,0,0,2,0,2,0,11,0,0,0,11,0,0,0,11,1,11,11,1,0,0
0,0,0,0,0,0,0,2,0,8,7,2,11,0,0,0,2,11,0,11,2,11,22,0,11,0,0
0,0,0,0,0,0,0,20,0,0,0,20,2,11,11,11,2,0,0,0,2,20,0,0,20,0,0
0,0,0,0,0,0,0,2,0,0,0,2,0,0,0,0,20,0,0,0,20,11,0,0,11,0,0
0,0,0,0,0,0,0,0,2,20,2,0,0,0,0,0,2,0,0,0,2,1,23,11,1,0,0
0,0,0,0,0,0,0,0,0,2,11,20,11,2,0,0,2,0,8,0,2,0,0,0,0,0,0
0,0,0,0,0,0,0,0,0,11,0,0,12,11,0,0,2,0,0,7,2,0,0,0,0,0,0
0,0,0,0,0,0,0,0,0,20,0,0,0,20,0,0,20,0,0,0,20,0,0,0,0,0,0
0,0,0,0,0,0,0,0,0,11,0,0,0,11,0,0,2,0,0,0,2,0,0,0,0,0,0
0,0,0,0,0,0,0,0,0,2,11,0,11,2,0,0,0,2,2,2,0,0,0,0,0,0,0
0,0,0,0,0,0,0,0,0,0,0,0,0,0,0,0,0,0,0,0,0,0,0,0,0,0,0
0,0,0,0,0,0,0,0,0,0,0,0,0,0,0,0,0,0,0,0,0,0,0,0,0,0,0
0,0,0,0,0,0,0,0,0,0,0,0,0,0,0,0,0,0,0,0,0,0,0,0,0,0,0
endlayer

layer
0,0,0,0,0,0,0,0,0,0,0,0,0,0,0,0,0,0,0,0,0,0,0,0,0,0,0
0,0,0,0,0,0,0,0,0,0,0,0,0,0,0,0,0,0,1,1,1,1,1,0,0,0,0
0,0,0,0,0,0,0,0,0,0,0,0,0,0,0,0,0,0,1,11,11,11,1,0,0,0,0
0,0,0,0,0,0,0,0,0,2,11,20,11,2,0,0,0,0,1,11,11,11,1,0,0,0,0
0,0,0,0,0,0,0,0,0,11,0,0,12,11,0,0,0,0,1,11,11,11,1,0,0,0,0
0,0,0,0,0,0,0,0,0,20,0,8,0,20,0,0,0,0,1,0,0,0,0,0,0,0,0
0,0,0,0,0,0,0,0,0,11,0,0,0,11,0,0,0,0,0,0,0,0,0,0,0,0,0
0,0,0,0,0,0,0,0,2,2,11,0,11,2,11,20,11,2,0,2,2,2,0,0,0,0,0
0,0,0,0,0,0,0,2,0,0,0,0,0,11,0,0,12,11,2,0,0,0,2,0,0,0,0
0,0,0,0,0,0,0,20,0,0,0,0,0,0,0,0,0,20,2,0,0,6,2,0,0,0,0
0,0,0,0,0,0,0,2,0,0,0,2,20,11,0,0,0,11,2,0,0,0,2,0,0,0,0
0,0,0,0,0,0,0,2,0,0,0,2,0,2,11,20,11,2,0,2,2,2,0,0,0,0,0
0,0,0,0,0,0,0,2,0,0,7,2,0,0,0,0,0,0,0,0,0,0,0,0,0,0,0
0,0,0,0,0,0,0,20,0,0,0,20,0,0,0,0,2,11,11,11,2,0,0,0,0,0,0
0,0,0,0,0,0,0,2,0,0,0,2,1,1,1,1,11,0,0,12,11,0,0,0,0,0,0
0,0,0,0,0,0,0,0,2,2,2,0,1,11,11,12,11,0,0,0,11,0,0,0,0,0,0
0,0,0,0,0,0,0,0,2,2,2,0,1,11,11,11,11,0,45,0,11,1,11,11,1,0,0
0,0,0,0,0,0,0,2,0,0,7,2,1,11,11,11,2,11,11,11,2,11,0,0,11,0,0
0,0,0,0,0,0,0,2,0,0,0,2,1,1,1,1,2,0,33,0,2,11,0,0,11,0,0
0,0,0,0,0,0,0,2,0,0,0,2,0,0,0,0,2,0,0,43,2,11,0,0,11,0,0
0,0,0,0,0,0,0,0,2,2,2,0,0,0,0,0,2,0,0,0,2,1,11,11,1,0,0
0,0,0,0,0,0,0,0,0,2,11,11,11,2,0,0,2,2,2,2,2,0,0,0,0,0,0
0,0,0,0,0,0,0,0,0,11,0,0,12,11,0,0,2,2,2,7,2,0,0,0,0,0,0
0,0,0,0,0,0,0,0,0,11,0,0,0,11,0,0,2,2,2,2,2,0,0,0,0,0,0
0,0,0,0,0,0,0,0,0,11,0,45,0,11,0,0,2,2,2,2,2,0,0,0,0,0,0
0,0,0,0,0,0,0,0,0,2,11,11,11,2,0,0,2,2,2,2,2,0,0,0,0,0,0
0,0,0,0,0,0,0,0,0,0,0,0,0,0,0,0,0,0,0,0,0,0,0,0,0,0,0
0,0,0,0,0,0,0,0,0,0,0,0,0,0,0,0,0,0,0,0,0,0,0,0,0,0,0
0,0,0,0,0,0,0,0,0,0,0,0,0,0,0,0,0,0,0,0,0,0,0,0,0,0,0
endlayer

layer
0,0,0,0,0,0,0,0,0,0,0,0,0,0,0,0,0,0,0,2,2,2,2,0,0,0,0
0,0,0,0,0,0,0,0,0,0,0,0,0,0,0,0,0,0,0,2,9,9,2,0,0,0,0
0,0,0,0,0,0,0,0,0,0,0,0,0,0,0,0,0,0,0,2,9,9,2,0,0,0,0
0,0,0,0,0,0,0,0,0,2,11,11,11,2,0,0,0,0,0,2,9,9,2,0,0,0,0
0,0,0,0,0,0,0,0,0,11,0,0,12,11,0,0,0,0,0,2,2,2,2,0,0,0,0
0,0,0,0,0,0,0,0,0,11,0,0,0,11,11,11,0,0,0,0,4,0,0,0,0,0,0
0,0,0,0,0,0,0,0,0,11,0,0,0,11,11,11,0,0,0,0,0,0,0,0,0,0,0
0,0,0,0,0,0,0,0,2,2,11,11,11,2,11,11,11,2,0,0,2,0,0,0,0,0,0
0,0,0,0,0,0,0,2,0,33,0,2,2,11,0,0,12,11,0,0,0,0,0,0,0,0,0
0,0,0,0,0,0,0,2,0,0,43,2,2,11,0,0,0,11,2,0,0,0,2,0,0,0,0
0,0,0,0,0,0,0,2,0,0,0,2,2,11,0,0,0,11,0,0,0,0,0,0,0,0,0
0,0,0,0,0,0,0,2,2,2,2,2,0,2,11,11,11,2,0,0,2,0,0,0,0,0,0
0,0,0,0,0,0,0,2,2,2,7,2,0,0,0,0,0,0,0,0,0,0,0,0,0,0,0
0,0,0,0,0,0,0,2,2,2,2,2,0,0,0,0,1,1,1,1,1,0,0,0,0,0,0
0,0,0,0,0,0,0,2,2,2,2,2,10,10,10,2,1,11,11,12,1,0,0,0,0,0,0
0,0,0,0,0,0,0,2,2,2,2,2,10,0,0,12,1,11,11,11,1,0,0,0,0,0,0
0,0,0,0,0,0,0,2,2,2,2,2,10,0,0,0,1,11,11,11,1,2,2,2,2,2,0
0,0,0,0,0,0,0,2,2,2,7,2,10,0,0,0,1,1,1,1,1,2,2,2,2,2,2
0,0,0,0,0,0,0,2,2,2,2,2,10,10,10,10,0,2,2,2,0,2,2,2,2,2,2
0,0,0,0,0,0,0,2,2,2,2,2,0,0,0,0,0,2,2,2,0,2,2,2,2,2,2
0,0,0,0,0,0,0,2,2,2,2,2,0,0,0,0,0,2,2,2,0,2,2,2,2,2,0
0,0,0,0,0,0,0,0,0,1,1,1,1,1,0,0,2,0,2,2,2,0,0,0,0,0,0
0,0,0,0,0,0,0,0,0,1,11,11,12,1,2,2,2,0,4,7,2,0,0,0,0,0,0
0,0,0,0,0,0,0,0,0,1,11,11,11,1,2,2,3,0,0,0,2,0,0,0,0,0,0
0,0,0,0,0,0,0,0,0,1,11,11,11,1,2,2,2,0,0,6,2,0,0,0,0,0,0
0,0,0,0,0,0,0,0,0,1,1,1,1,1,0,0,0,2,2,2,0,0,0,0,0,0,0
0,0,0,0,0,0,0,0,0,0,0,0,0,0,0,0,0,0,0,0,0,0,0,0,0,0,0
0,0,0,0,0,0,0,0,0,0,0,0,0,0,0,0,0,0,0,0,0,0,0,0,0,0,0
0,0,0,0,0,0,0,0,0,0,0,0,0,0,0,0,0,0,0,0,0,0,0,0,0,0,0
endlayer

layer
0,0,0,0,0,0,0,0,0,0,0,0,0,0,0,0,0,0,0,1,11,11,1,0,0,0,0
0,0,0,0,0,0,0,0,0,0,0,0,0,0,0,0,0,0,0,11,10,0,11,0,0,0,0
0,0,0,0,0,0,0,0,0,0,0,0,0,0,0,0,0,0,0,11,0,0,11,0,0,0,0
0,0,0,0,0,0,0,0,0,1,1,1,1,1,0,0,0,0,0,11,0,0,11,0,0,0,0
0,0,0,0,0,0,0,0,0,1,11,11,12,1,0,0,0,0,0,1,16,11,1,0,0,0,0
0,0,0,0,0,0,0,0,0,1,11,11,11,1,1,1,0,0,0,0,0,0,0,0,0,0,0
0,0,0,0,0,0,0,0,0,1,11,11,11,1,11,1,0,0,0,0,0,0,0,0,0,0,0
0,0,0,0,0,0,0,0,0,1,1,1,1,1,1,1,1,1,0,0,2,0,0,0,0,0,0
0,0,0,0,0,0,0,0,2,2,2,0,0,1,11,11,12,1,0,0,0,0,0,0,0,0,0
0,0,0,0,0,0,0,0,2,2,2,0,0,1,11,11,11,1,2,0,0,0,2,0,0,0,0
0,0,0,0,0,0,0,0,2,2,2,0,0,1,11,11,11,1,0,0,0,0,0,0,0,0,0
0,0,0,0,0,0,0,0,2,4,2,0,0,1,1,1,1,1,0,0,2,0,0,0,0,0,0
0,0,0,0,0,0,0,2,8,0,7,2,0,2,2,2,2,2,0,0,0,0,0,0,0,0,0
0,0,0,0,0,0,0,2,0,0,6,2,0,2,2,2,1,1,1,1,1,0,0,0,0,0,0
0,0,0,0,0,0,0,2,0,0,0,2,0,2,2,2,3,0,0,0,1,0,0,0,0,0,0
0,0,0,0,0,0,0,0,2,2,2,0,0,2,2,12,1,0,0,11,1,0,0,0,0,0,0
0,0,0,0,0,0,0,0,2,2,2,0,0,2,2,2,1,1,11,11,1,2,11,11,11,2,0
0,0,0,0,0,0,0,2,0,0,0,2,0,0,0,0,1,1,1,1,1,11,0,0,12,11,10
0,0,0,0,0,0,0,2,0,0,7,2,0,0,0,0,0,2,9,9,2,27,0,0,0,46,10
0,0,0,0,0,0,0,2,0,0,0,2,0,0,0,0,0,2,9,9,2,11,0,0,0,11,10
0,0,0,0,0,0,0,0,2,2,2,0,0,0,0,0,0,2,2,2,2,2,11,11,11,2,0
0,0,0,0,0,0,0,0,0,10,10,10,10,10,0,0,2,0,4,2,2,0,0,0,0,0,0
0,0,0,0,0,0,0,0,0,10,0,0,0,10,10,10,2,0,0,7,2,0,0,0,0,0,0
0,0,0,0,0,0,0,0,0,10,0,0,0,0,0,0,0,0,0,0,20,0,0,0,0,0,0
0,0,0,0,0,0,0,0,0,10,0,0,0,10,10,10,2,0,0,0,2,0,0,0,0,0,0
0,0,0,0,0,0,0,0,0,10,10,10,10,10,0,0,0,2,20,2,0,0,0,0,0,0,0
0,0,0,0,0,0,0,0,0,0,0,0,0,0,0,0,0,0,0,0,0,0,0,0,0,0,0
0,0,0,0,0,0,0,0,0,0,0,0,0,0,0,0,0,0,0,0,0,0,0,0,0,0,0
0,0,0,0,0,0,0,0,0,0,0,0,0,0,0,0,0,0,0,0,0,0,0,0,0,0,0
endlayer

layer
0,0,0,0,0,0,0,0,0,0,0,0,0,0,0,0,0,0,0,1,11,11,1,0,0,0,0
0,0,0,0,0,0,0,0,0,0,0,0,0,0,0,0,0,0,0,11,22,0,11,0,0,0,0
0,0,0,0,0,0,0,0,0,0,0,0,0,0,0,0,0,0,0,20,0,0,20,0,0,0,0
0,0,0,0,0,0,0,0,0,10,10,10,10,10,0,0,0,0,0,11,0,0,11,0,0,0,0
0,0,0,0,0,0,0,2,2,2,2,2,0,10,0,0,0,0,0,1,23,11,1,0,0,0,0
0,0,0,0,0,0,0,2,3,0,8,2,0,10,10,10,0,0,0,0,0,0,0,0,0,0,0
0,0,0,0,0,0,0,2,3,0,0,0,0,0,0,10,0,0,0,0,0,0,0,0,0,0,0
0,0,0,0,0,0,0,2,3,0,0,2,10,10,0,10,10,10,0,0,2,0,0,0,0,0,0
0,0,0,0,0,0,0,2,2,0,2,2,0,10,0,0,0,10,0,0,0,0,0,0,0,0,0
0,0,0,0,0,0,0,0,2,0,2,0,0,10,0,0,0,10,2,0,0,0,2,0,0,0,0
0,0,0,0,0,0,0,0,2,0,2,0,0,10,0,0,0,10,2,2,2,2,2,0,0,0,0
0,0,0,0,0,0,0,0,2,0,2,0,0,10,10,0,10,10,2,2,2,2,2,0,0,0,0
0,0,0,0,0,0,0,2,0,0,7,2,0,2,11,0,11,2,2,2,2,2,2,0,0,0,0
0,0,0,0,0,0,0,20,0,0,0,20,0,11,0,0,12,11,2,2,2,2,2,0,0,0,0
0,0,0,0,0,0,0,2,0,0,0,2,0,11,0,0,0,0,0,0,2,2,2,0,0,0,0
0,0,0,0,0,0,0,0,2,20,2,0,0,11,0,0,0,0,0,11,4,2,0,0,0,0,0
0,0,0,0,0,0,0,0,0,2,0,0,0,2,11,11,11,1,11,11,0,2,11,20,11,2,0
0,0,0,0,0,0,0,10,0,0,0,0,0,0,0,0,0,11,10,0,0,11,0,0,12,11,0
0,0,0,0,0,0,0,2,0,0,7,2,0,0,0,0,0,11,0,0,0,0,0,0,0,23,0
0,0,0,0,0,0,0,10,0,0,0,0,0,0,0,0,0,11,0,0,11,11,0,0,0,11,0
0,0,0,0,0,0,0,0,10,2,0,0,0,0,0,0,0,1,0,11,1,2,11,20,11,2,0
0,0,0,0,0,0,0,0,0,10,10,0,10,10,0,0,2,0,0,2,2,0,0,0,0,0,0
0,0,0,0,0,0,0,0,0,10,0,0,0,10,0,0,2,0,0,7,2,0,0,0,0,0,0
0,0,0,0,0,0,0,0,0,0,0,0,0,0,0,0,0,0,0,0,20,0,0,0,0,0,0
0,0,0,0,0,0,0,0,0,10,0,0,0,10,0,0,2,0,0,0,2,0,0,0,0,0,0
0,0,0,0,0,0,0,0,0,10,10,0,10,10,0,0,0,2,20,2,0,0,0,0,0,0,0
0,0,0,0,0,0,0,0,0,0,0,0,0,0,0,0,0,0,0,0,0,0,0,0,0,0,0
0,0,0,0,0,0,0,0,0,0,0,0,0,0,0,0,0,0,0,0,0,0,0,0,0,0,0
0,0,0,0,0,0,0,0,0,0,0,0,0,0,0,0,0,0,0,0,0,0,0,0,0,0,0
endlayer

layer
0,0,0,0,0,0,0,0,0,0,0,0,0,0,0,0,0,0,0,1,11,11,1,0,0,0,0
0,0,0,0,0,0,0,0,0,0,0,0,0,0,0,0,0,0,0,11,0,0,11,0,0,0,0
0,0,0,0,0,0,0,0,0,0,0,0,0,0,0,0,0,0,0,11,0,0,11,0,0,0,0
0,0,0,0,0,0,0,0,0,0,0,0,0,0,0,0,0,0,0,11,0,0,11,0,0,0,0
0,0,0,0,0,0,0,2,11,11,11,2,0,0,0,0,0,0,0,1,11,11,1,0,0,0,0
0,0,0,0,0,0,0,11,0,0,0,11,0,0,0,0,0,0,0,0,0,0,0,0,0,0,0
0,0,0,0,0,0,0,11,0,0,0,0,0,0,0,0,0,0,2,2,2,2,2,0,0,0,0
0,0,0,0,0,0,0,11,0,0,0,11,0,0,0,0,0,0,2,2,2,2,2,0,0,0,0
0,0,0,0,0,0,0,2,11,0,11,2,0,0,0,0,0,0,2,2,2,2,2,0,0,0,0
0,0,0,0,0,0,0,0,10,0,10,0,0,0,0,0,0,0,2,2,2,2,2,0,0,0,0
0,0,0,0,0,0,0,0,10,0,10,0,0,0,0,0,0,0,2,11,4,11,2,0,0,0,0
0,0,0,0,0,0,0,0,2,0,2,0,0,0,0,0,0,0,11,0,0,0,11,0,0,0,0
0,0,0,0,0,0,0,2,0,0,7,2,0,2,11,0,11,2,11,0,0,6,11,0,0,0,0
0,0,0,0,0,0,0,20,0,0,0,20,0,11,0,0,12,11,11,0,0,0,11,0,0,0,0
0,0,0,0,0,0,0,2,0,0,0,2,0,20,0,0,0,0,0,11,0,11,2,0,0,0,0
0,0,0,0,0,0,0,0,2,20,2,0,0,11,0,0,0,0,0,11,0,10,0,0,0,0,0
0,0,0,0,0,0,0,0,0,0,0,0,0,2,11,20,11,1,11,11,0,2,11,11,11,2,0
0,0,0,0,0,0,0,2,2,2,2,2,2,2,0,0,0,11,22,0,0,11,0,0,12,11,0
0,0,0,0,0,0,0,2,11,11,7,11,11,2,0,0,0,20,0,0,0,0,0,0,0,11,0
0,0,0,0,0,0,0,2,11,11,11,11,11,2,0,0,0,11,0,0,11,11,0,0,0,11,0
0,0,0,0,0,0,0,2,11,11,11,11,11,2,0,0,0,1,0,11,1,2,11,11,11,2,0
0,0,0,0,0,0,0,2,11,11,11,11,11,2,0,0,2,0,0,0,2,0,0,0,0,0,0
0,0,0,0,0,2,2,2,11,11,11,11,11,2,0,0,2,0,0,7,2,0,0,0,0,0,0
0,0,0,0,0,2,11,11,11,11,11,11,11,2,0,0,2,0,0,0,2,0,0,0,0,0,0
0,0,0,0,0,2,11,11,11,11,11,11,11,2,0,0,2,0,0,0,2,0,0,0,0,0,0
0,0,0,0,0,2,11,11,11,11,11,11,11,2,0,0,0,2,2,2,0,0,0,0,0,0,0
0,0,0,0,0,2,11,11,11,11,11,11,11,2,0,0,0,0,0,0,0,0,0,0,0,0,0
0,0,0,0,0,2,2,2,2,2,2,2,2,2,0,0,0,0,0,0,0,0,0,0,0,0,0
0,0,0,0,0,0,2,2,2,0,0,0,0,0,0,0,0,0,0,0,0,0,0,0,0,0,0
endlayer

layer
0,0,0,0,0,0,0,0,0,0,0,0,0,0,0,0,0,0,0,0,1,1,0,0,0,0,0
0,0,0,0,0,0,0,0,0,0,0,0,0,0,0,0,0,2,2,2,2,2,1,0,0,0,0
0,0,0,0,0,0,0,0,0,0,0,0,0,0,0,0,0,2,2,2,2,2,1,0,0,0,0
0,0,0,0,0,0,0,0,0,0,0,0,0,0,0,0,0,2,2,2,2,2,1,0,0,0,0
0,0,0,0,0,0,0,2,11,20,11,2,0,0,0,0,0,2,2,2,2,2,0,0,0,0,0
0,0,0,0,0,0,0,11,0,0,0,11,0,0,0,0,0,2,2,2,2,2,0,0,0,0,0
0,0,0,0,0,0,0,20,0,0,0,0,0,0,0,0,0,0,2,13,11,11,2,0,0,0,0
0,0,0,0,0,0,0,11,0,0,0,11,0,0,0,0,0,0,11,0,0,8,11,0,0,0,0
0,0,0,0,0,0,0,2,11,0,11,2,0,0,0,0,0,0,11,0,0,0,11,0,0,0,0
0,0,0,0,0,0,0,0,0,0,0,0,0,0,0,0,0,0,11,0,0,0,11,0,0,0,0
0,0,0,0,0,0,0,0,0,0,0,0,0,0,0,0,0,0,2,11,0,11,2,0,0,0,0
0,0,0,0,0,0,0,0,2,2,2,0,0,0,0,0,0,0,11,0,0,0,11,0,0,0,0
0,0,0,0,0,0,0,2,0,0,7,2,0,2,11,11,11,2,20,0,0,0,20,0,0,0,0
0,0,0,0,0,0,0,2,0,0,0,2,0,11,0,0,12,11,11,0,0,0,11,0,0,0,0
0,0,0,0,0,0,0,2,0,0,0,2,0,11,0,0,0,11,2,11,0,11,2,0,0,0,0
0,0,0,0,0,0,0,0,2,2,2,0,0,11,0,0,0,11,0,11,0,0,0,0,0,0,0
0,0,0,0,0,0,0,0,0,0,0,0,0,2,11,11,11,1,11,11,0,1,1,1,1,1,0
0,0,0,0,0,0,0,2,2,2,2,2,2,2,0,0,0,11,0,0,11,1,11,11,12,1,0
0,0,0,0,0,0,0,2,0,0,0,0,0,2,0,0,0,11,0,0,11,1,11,11,11,1,0
0,0,0,0,0,0,0,2,0,0,0,0,6,2,0,0,0,11,0,0,11,1,11,11,11,1,0
0,0,0,0,0,0,0,2,0,0,0,0,6,2,0,0,0,1,11,11,1,1,1,1,1,1,0
0,0,0,0,0,0,0,2,0,0,0,0,0,2,0,0,2,2,2,2,2,0,0,0,0,0,0
0,0,0,0,0,2,2,2,0,0,0,0,8,2,0,0,2,2,2,7,2,0,0,0,0,0,0
0,0,0,0,0,2,0,0,0,0,0,0,0,2,0,0,2,2,2,2,2,0,0,0,0,0,0
0,0,0,0,0,2,0,0,0,0,0,0,6,2,0,0,2,2,2,2,2,0,0,0,0,0,0
0,0,0,0,0,2,0,0,0,0,0,0,6,2,0,0,2,2,2,2,2,0,0,0,0,0,0
0,0,0,0,0,2,0,0,0,0,0,0,0,2,0,0,0,0,0,0,0,0,0,0,0,0,0
0,0,0,0,0,2,2,16,2,2,2,2,2,2,0,0,0,0,0,0,0,0,0,0,0,0,0
0,0,0,0,0,0,10,10,10,0,0,0,0,0,0,0,0,0,0,0,0,0,0,0,0,0,0
endlayer

layer
0,0,0,0,0,0,0,0,0,0,0,0,0,0,0,0,0,0,0,0,0,0,0,0,0,0,0
0,0,0,0,0,0,0,0,0,0,0,0,0,0,0,0,0,2,11,11,11,2,0,0,0,0,0
0,0,0,0,0,0,0,0,0,0,0,0,0,0,0,0,0,11,0,0,12,11,0,0,0,0,0
0,0,0,0,0,0,0,0,0,0,0,0,0,0,0,0,0,11,0,0,0,11,0,0,0,0,0
0,0,0,0,0,0,0,2,11,11,11,2,0,0,0,0,0,11,0,0,0,11,0,0,0,0,0
0,0,0,0,0,0,0,11,0,0,0,11,0,0,0,0,0,2,11,0,11,2,0,0,0,0,0
0,0,0,0,0,0,0,11,0,0,0,11,0,0,0,0,0,0,2,0,10,11,2,0,0,0,0
0,0,0,0,0,0,0,11,0,0,0,11,0,0,0,0,0,0,11,0,0,0,11,0,0,0,0
0,0,0,0,0,0,0,2,11,11,11,2,0,0,0,0,0,0,20,0,0,0,20,0,0,0,0
0,0,0,0,0,0,0,0,0,0,0,0,0,0,0,0,0,0,11,0,0,0,11,0,0,0,0
0,0,0,0,0,0,0,0,0,0,0,0,0,0,0,0,0,0,2,11,0,11,2,0,0,0,0
0,0,0,0,0,0,0,2,2,2,2,2,0,0,0,0,0,0,11,0,0,0,11,0,0,0,0
0,0,0,0,0,0,0,2,2,2,7,2,0,1,1,1,1,1,11,0,0,0,11,0,0,0,0
0,0,0,0,0,0,0,2,2,2,2,2,0,1,11,11,12,1,11,0,0,0,11,0,0,0,0
0,0,0,0,0,0,0,2,2,2,2,2,0,1,11,11,11,1,2,11,11,11,2,0,0,0,0
0,0,0,0,0,0,0,2,2,2,2,2,0,1,11,11,11,1,11,11,11,0,0,0,0,0,0
0,0,0,0,0,0,0,0,0,0,0,0,0,1,1,1,1,1,1,1,1,10,10,10,10,10,0
0,0,0,0,0,0,0,2,2,2,2,2,2,2,0,0,0,1,1,1,1,10,0,0,0,10,0
0,0,0,0,0,0,0,1,0,0,0,0,0,1,0,0,0,1,1,1,27,0,0,0,0,10,0
0,0,0,0,0,0,0,20,0,0,0,0,0,20,0,0,0,1,1,1,1,10,0,0,0,10,0
0,0,0,0,0,0,0,20,0,0,0,0,0,20,0,0,0,1,1,1,1,10,10,10,10,10,0
0,0,0,0,0,0,0,1,0,0,0,0,0,1,0,0,10,2,2,4,2,0,0,0,0,0,0
0,0,0,0,0,2,11,11,0,0,0,0,0,11,0,0,2,0,0,0,2,0,0,0,0,0,0
0,0,0,0,0,1,0,0,0,0,0,0,0,1,0,0,2,0,0,0,2,0,0,0,0,0,0
0,0,0,0,0,20,0,0,0,0,0,0,0,20,0,0,2,0,0,0,2,0,0,0,0,0,0
0,0,0,0,0,20,0,0,0,0,0,0,0,20,0,0,10,2,2,2,10,0,0,0,0,0,0
0,0,0,0,0,1,0,0,0,0,0,0,0,1,0,0,0,0,0,0,0,0,0,0,0,0,0
0,0,0,0,0,2,11,23,11,1,20,1,11,2,0,0,0,0,0,0,0,0,0,0,0,0,0
0,0,0,0,0,0,0,0,0,0,0,0,0,0,0,0,0,0,0,0,0,0,0,0,0,0,0
endlayer

layer
0,0,0,0,0,0,0,0,0,0,0,0,0,0,0,0,0,0,0,0,0,0,0,0,0,0,0
0,0,0,0,0,0,0,0,0,0,0,0,0,0,0,0,0,2,11,20,11,2,0,0,0,0,0
0,0,0,0,0,0,0,0,0,0,0,0,0,0,0,0,0,11,0,0,12,11,0,0,0,0,0
0,0,0,0,0,0,0,0,0,0,0,0,0,0,0,0,0,20,0,0,0,20,0,0,0,0,0
0,0,0,0,0,0,0,1,1,1,1,1,0,0,0,0,0,11,0,0,0,11,0,0,0,0,0
0,0,0,0,0,0,0,1,11,11,11,1,0,0,0,0,0,2,11,0,11,2,0,0,0,0,0
0,0,0,0,0,0,0,1,11,11,11,1,0,0,0,0,0,0,2,0,11,11,2,0,0,0,0
0,0,0,0,0,0,0,1,11,11,11,1,0,0,0,0,0,0,11,0,0,0,11,0,0,0,0
0,0,0,0,0,0,0,1,1,1,1,1,0,0,0,0,0,0,11,0,0,0,11,0,0,0,0
0,0,0,0,0,0,0,0,0,0,0,0,0,0,0,0,0,0,11,0,0,0,11,0,0,0,0
0,0,0,0,0,0,0,0,0,0,0,0,0,0,0,0,0,0,1,1,1,1,1,0,0,0,0
0,0,0,0,0,0,0,0,2,2,2,0,0,0,0,0,0,0,1,11,11,11,1,0,0,0,0
0,0,0,0,0,0,0,2,0,0,12,2,0,10,10,10,10,10,1,11,11,11,1,0,0,0,0
0,0,0,0,0,0,0,2,0,0,0,2,0,10,0,0,0,10,1,11,11,11,1,0,0,0,0
0,0,0,0,0,0,0,2,0,0,0,2,0,10,0,0,0,0,14,1,1,1,1,0,0,0,0
0,0,0,0,0,0,0,0,2,2,2,0,0,10,0,0,0,0,13,13,1,0,0,0,0,0,0
0,0,0,0,0,0,0,0,0,0,0,0,0,10,10,10,10,10,0,0,10,10,0,0,0,0,0
0,0,0,0,0,0,14,2,2,2,2,2,2,2,0,0,0,10,0,0,0,0,0,0,0,0,0
0,0,0,0,0,0,14,2,0,0,0,0,0,2,0,0,0,10,0,0,0,0,0,0,0,0,0
0,0,0,0,0,0,14,2,0,0,0,0,0,2,0,0,0,10,0,0,0,0,0,0,0,0,0
0,0,0,0,0,0,14,2,0,0,0,0,0,2,0,0,0,10,0,0,10,10,0,0,0,0,0
0,0,0,0,0,25,11,2,0,0,0,0,0,2,0,0,10,10,2,0,10,0,0,0,0,0,0
0,0,0,0,0,2,11,11,0,0,0,0,0,2,0,0,10,0,0,0,10,0,0,0,0,0,0
0,0,0,0,0,2,0,0,0,0,0,0,0,2,0,0,2,0,0,0,2,0,0,0,0,0,0
0,0,0,0,0,2,0,0,0,0,0,0,0,2,0,0,10,0,0,0,10,0,0,0,0,0,0
0,0,0,0,0,2,0,0,0,0,0,0,0,2,0,0,10,10,2,10,10,0,0,0,0,0,0
0,0,0,0,0,2,0,0,0,0,0,0,0,2,0,0,0,0,0,0,0,0,0,0,0,0,0
0,0,0,0,0,2,11,11,11,11,11,11,11,2,0,0,0,0,0,0,0,0,0,0,0,0,0
0,0,0,0,0,13,13,13,13,13,13,13,13,13,0,0,0,0,0,0,0,0,0,0,0,0,0
endlayer

layer
0,0,0,0,0,0,0,0,0,0,0,0,0,0,0,0,0,0,0,0,0,0,0,0,0,0,0
0,0,0,0,0,0,0,0,0,0,0,0,0,0,0,0,0,2,11,11,11,2,0,0,0,0,0
0,0,0,0,0,0,0,0,0,0,0,0,0,0,0,0,0,11,0,0,12,11,0,0,0,0,0
0,0,0,0,0,0,0,0,0,0,0,0,0,0,0,0,0,11,0,0,0,11,0,0,0,0,0
0,0,0,0,0,0,0,0,0,0,0,0,0,0,0,0,0,11,0,0,0,11,0,0,0,0,0
0,0,0,0,0,0,0,0,0,0,0,0,0,0,0,0,0,2,11,11,11,2,0,0,0,0,0
0,0,0,0,0,0,0,0,0,0,0,0,0,0,0,0,0,0,1,1,1,1,1,0,0,0,0
0,0,0,0,0,0,0,0,0,0,0,11,11,11,11,11,11,11,1,11,11,11,1,0,0,0,0
0,0,0,0,0,0,0,0,0,0,0,11,11,11,11,11,11,11,1,11,11,11,1,0,0,0,0
0,0,0,0,0,0,0,0,0,0,0,11,11,11,11,11,11,11,1,11,11,11,1,0,0,0,0
0,0,0,0,0,0,0,0,0,0,0,0,0,0,0,0,0,0,1,1,13,1,1,0,0,0,0
0,0,0,0,0,0,0,0,0,2,2,0,0,0,0,0,0,0,10,0,0,0,10,0,0,0,0
0,0,0,0,0,0,0,0,0,0,12,0,0,0,0,0,0,0,10,0,0,0,10,0,0,0,0
0,0,0,0,0,0,0,2,0,0,0,2,0,0,0,0,0,10,10,0,0,0,10,0,0,0,0
0,0,0,0,0,0,0,0,0,0,0,0,0,10,0,0,0,0,0,0,10,10,10,0,0,0,0
0,0,0,0,0,0,0,0,0,2,0,0,0,10,0,0,0,0,0,0,10,0,0,0,0,0,0
0,0,0,0,0,0,0,0,0,0,0,0,0,10,0,0,0,0,0,0,10,0,0,0,0,0,0
0,0,0,0,0,0,10,14,11,1,20,1,11,27,0,0,0,0,0,0,0,0,0,0,0,0,0
0,0,0,0,0,0,10,14,11,0,0,0,11,27,0,0,0,0,0,0,0,0,0,0,0,0,0
0,0,0,0,0,0,10,14,11,0,0,0,11,27,0,0,0,0,0,0,0,0,0,0,0,0,0
0,0,0,0,0,0,10,14,11,0,0,0,11,27,0,0,0,0,0,0,0,0,0,0,0,0,0
0,0,0,0,0,10,10,14,11,0,0,0,11,27,0,0,0,0,0,0,0,0,0,0,0,0,0
0,0,0,0,0,25,25,11,11,0,0,0,11,27,0,0,0,0,0,0,0,0,0,0,0,0,0
0,0,0,0,0,11,11,11,11,0,0,0,11,11,0,0,0,0,0,0,0,0,0,0,0,0,0
0,0,0,0,0,11,0,0,0,0,0,0,11,11,0,0,0,0,0,0,0,0,0,0,0,0,0
0,0,0,0,0,11,0,0,0,0,0,0,11,11,0,0,0,0,0,0,0,0,0,0,0,0,0
0,0,0,0,0,11,11,11,11,11,11,11,11,11,0,0,0,0,0,0,0,0,0,0,0,0,0
0,0,0,0,0,13,13,13,13,13,13,13,13,13,0,0,0,0,0,0,0,0,0,0,0,0,0
0,0,0,0,0,0,0,0,0,0,0,0,0,0,0,0,0,0,0,0,0,0,0,0,0,0,0
endlayer

layer
0,0,0,0,0,2,2,2,2,2,2,2,2,2,2,0,0,0,0,0,0,0,0,0,0,0,0
0,0,0,0,0,2,2,2,2,2,2,2,2,2,2,0,0,1,1,1,1,1,0,0,0,0,0
0,0,0,0,0,2,2,2,2,2,2,2,2,2,2,0,0,1,11,11,12,1,0,0,0,0,0
0,0,0,0,0,2,2,2,2,2,2,2,2,2,2,0,0,1,11,11,11,1,0,0,0,0,0
0,0,0,0,0,2,2,2,2,2,2,2,2,2,2,0,0,1,11,11,11,1,0,0,0,0,0
0,0,0,0,0,2,2,2,2,2,2,2,2,2,2,0,0,1,1,13,1,1,0,0,0,0,0
0,0,0,0,0,2,2,2,2,2,2,2,2,2,2,0,0,0,10,0,10,10,10,0,0,0,0
0,0,0,0,0,0,0,0,2,2,2,4,4,4,10,10,10,10,10,0,0,0,10,0,0,0,0
0,0,0,0,0,0,0,0,2,2,2,0,0,0,0,0,0,0,0,0,0,0,10,0,0,0,0
0,0,0,0,0,0,0,0,2,2,2,10,10,10,10,10,10,10,10,0,0,0,10,0,0,0,0
0,0,0,0,0,0,0,0,2,2,2,0,0,0,0,0,0,0,10,10,0,10,10,0,0,0,0
0,0,0,0,0,0,0,2,2,2,2,2,0,0,0,0,0,0,10,0,0,0,10,0,0,0,0
0,0,0,0,0,0,0,2,2,2,12,2,0,0,0,0,0,0,0,0,0,0,0,0,0,0,0
0,0,0,0,0,0,0,2,2,2,2,2,0,0,0,0,0,0,0,0,0,0,0,0,0,0,0
0,0,0,0,0,0,0,2,2,2,2,2,10,10,0,0,0,0,0,0,0,0,0,0,0,0,0
0,0,0,0,0,0,0,2,2,2,2,2,2,10,0,0,0,0,0,0,0,0,0,0,0,0,0
0,0,0,0,0,0,0,0,11,11,11,11,11,10,0,0,0,0,0,0,0,0,0,0,0,0,0
0,0,0,0,0,0,10,10,14,11,11,11,27,10,0,0,0,0,0,0,0,0,0,0,0,0,0
0,0,0,0,0,0,10,0,14,11,0,11,27,10,0,0,0,0,0,0,0,0,0,0,0,0,0
0,0,0,0,0,0,10,0,14,11,0,11,27,10,0,0,0,0,0,0,0,0,0,0,0,0,0
0,0,0,0,0,0,10,0,14,11,0,11,27,10,0,0,0,0,0,0,0,0,0,0,0,0,0
0,0,0,0,0,10,10,0,14,11,0,11,27,10,0,0,0,0,0,0,0,0,0,0,0,0,0
0,0,0,0,0,10,0,0,14,11,0,11,27,10,0,0,0,0,0,0,0,0,0,0,0,0,0
0,0,0,0,0,25,25,25,11,11,0,11,11,25,0,0,0,0,0,0,0,0,0,0,0,0,0
0,0,0,0,0,11,11,11,11,11,11,11,11,11,0,0,0,0,0,0,0,0,0,0,0,0,0
0,0,0,0,0,11,11,11,11,11,11,11,11,11,0,0,0,0,0,0,0,0,0,0,0,0,0
0,0,0,0,0,13,13,13,13,13,13,13,13,13,0,0,0,0,0,0,0,0,0,0,0,0,0
0,0,0,0,0,0,0,0,0,0,0,0,0,0,0,0,0,0,0,0,0,0,0,0,0,0,0
0,0,0,0,0,0,0,0,0,0,0,0,0,0,0,0,0,0,0,0,0,0,0,0,0,0,0
endlayer

layer
0,0,0,0,0,1,11,11,11,11,11,2,2,2,2,0,0,0,0,0,0,0,0,0,0,0,0
0,0,0,0,0,11,11,13,0,0,47,2,38,38,2,0,0,10,10,10,10,10,0,0,0,0,0
0,0,0,0,0,11,27,10,0,0,8,2,2,2,2,0,0,10,0,0,0,10,0,0,0,0,0
0,0,0,0,0,11,0,0,0,11,11,2,0,0,10,0,0,10,0,0,0,10,0,0,0,0,0
0,0,0,0,0,11,0,0,11,0,0,0,0,0,10,0,0,10,0,0,0,10,0,0,0,0,0
0,0,0,0,0,11,0,0,0,0,0,0,0,29,10,0,0,10,10,0,10,10,0,0,0,0,0
0,0,0,0,0,1,11,11,1,0,10,0,0,0,10,0,0,0,10,0,10,0,0,0,0,0,0
0,0,0,0,0,0,0,0,10,0,10,0,0,0,10,0,0,0,0,0,0,0,0,0,0,0,0
0,0,0,0,0,0,0,0,10,0,10,0,0,0,0,0,0,0,0,0,0,0,0,0,0,0,0
0,0,0,0,0,0,0,0,10,0,10,10,0,0,0,0,0,0,0,0,0,0,0,0,0,0,0
0,0,0,0,0,0,0,0,10,0,10,0,0,0,0,0,0,0,0,0,0,0,0,0,0,0,0
0,0,0,0,0,0,0,2,11,0,11,2,0,0,0,0,0,0,0,0,0,0,0,0,0,0,0
0,0,0,0,0,0,0,11,0,0,12,11,0,0,0,0,0,0,0,0,0,0,0,0,0,0,0
0,0,0,0,0,0,0,11,0,0,0,11,0,0,0,0,0,0,0,0,0,0,0,0,0,0,0
0,0,0,0,0,0,0,11,0,0,0,11,10,10,0,0,0,0,0,0,0,0,0,0,0,0,0
0,0,0,0,0,0,0,2,11,0,11,2,0,10,0,0,0,0,0,0,0,0,0,0,0,0,0
0,0,0,0,0,0,0,0,10,0,0,0,0,10,0,0,0,0,0,0,0,0,0,0,0,0,0
0,0,0,0,0,0,0,10,10,0,0,0,0,10,0,0,0,0,0,0,0,0,0,0,0,0,0
0,0,0,0,0,0,0,0,0,25,25,25,0,10,0,0,0,0,0,0,0,0,0,0,0,0,0
0,0,0,0,0,0,0,0,0,14,11,27,0,10,0,0,0,0,0,0,0,0,0,0,0,0,0
0,0,0,0,0,0,0,0,0,14,11,27,0,10,0,0,0,0,0,0,0,0,0,0,0,0,0
0,0,0,0,0,0,0,0,0,14,11,27,0,10,0,0,0,0,0,0,0,0,0,0,0,0,0
0,0,0,0,0,10,0,0,0,14,11,27,0,10,0,0,0,0,0,0,0,0,0,0,0,0,0
0,0,0,0,0,10,0,0,0,14,11,27,0,10,0,0,0,0,0,0,0,0,0,0,0,0,0
0,0,0,0,0,25,25,25,25,11,11,11,25,25,0,0,0,0,0,0,0,0,0,0,0,0,0
0,0,0,0,0,13,13,13,13,13,13,13,13,13,0,0,0,0,0,0,0,0,0,0,0,0,0
0,0,0,0,0,0,0,0,0,0,0,0,0,0,0,0,0,0,0,0,0,0,0,0,0,0,0
0,0,0,0,0,0,0,0,0,0,0,0,0,0,0,0,0,0,0,0,0,0,0,0,0,0,0
0,0,0,0,0,0,0,0,0,0,0,0,0,0,0,0,0,0,0,0,0,0,0,0,0,0,0
endlayer

layer
0,0,0,0,0,1,11,20,11,20,11,2,2,2,2,0,0,0,0,0,0,0,0,0,0,0,0
0,0,0,0,0,11,0,0,0,0,0,2,0,0,40,0,0,0,0,0,0,0,0,0,0,0,0
0,0,0,0,0,20,0,22,0,0,0,2,0,0,40,0,0,0,0,0,0,0,0,0,0,0,0
0,0,0,0,0,11,0,0,0,11,11,41,0,0,0,0,0,0,0,0,0,0,0,0,0,0,0
0,0,0,0,0,20,0,0,11,0,0,0,0,0,0,0,0,0,0,0,0,0,0,0,0,0,0
0,0,0,0,0,11,0,0,0,0,0,0,0,0,0,0,0,0,0,0,0,0,0,0,0,0,0
0,0,0,0,0,1,11,11,1,0,10,0,0,0,10,0,0,0,0,0,0,0,0,0,0,0,0
0,0,0,0,0,0,0,0,0,0,0,0,0,0,0,0,0,0,0,0,0,0,0,0,0,0,0
0,0,0,0,0,0,0,0,0,0,0,0,0,0,0,0,0,0,0,0,0,0,0,0,0,0,0
0,0,0,0,0,0,0,0,0,0,0,0,0,0,0,0,0,0,0,0,0,0,0,0,0,0,0
0,0,0,0,0,0,0,0,0,0,0,0,0,0,0,0,0,0,0,0,0,0,0,0,0,0,0
0,0,0,0,0,0,0,2,11,0,11,2,0,0,0,0,0,0,0,0,0,0,0,0,0,0,0
0,0,0,0,0,0,0,11,0,0,12,11,0,0,0,0,0,0,0,0,0,0,0,0,0,0,0
0,0,0,0,0,0,0,20,0,0,0,20,0,0,0,0,0,0,0,0,0,0,0,0,0,0,0
0,0,0,0,0,0,0,11,0,0,0,11,0,0,0,0,0,0,0,0,0,0,0,0,0,0,0
0,0,0,0,0,0,0,2,11,0,11,2,0,0,0,0,0,0,0,0,0,0,0,0,0,0,0
0,0,0,0,0,0,0,0,0,0,0,0,0,0,0,0,0,0,0,0,0,0,0,0,0,0,0
0,0,0,0,0,0,0,0,0,0,0,0,0,0,0,0,0,0,0,0,0,0,0,0,0,0,0
0,0,0,0,0,0,0,0,0,0,0,0,0,0,0,0,0,0,0,0,0,0,0,0,0,0,0
0,0,0,0,0,0,0,0,0,0,0,0,0,0,0,0,0,0,0,0,0,0,0,0,0,0,0
0,0,0,0,0,0,0,0,0,0,0,0,0,0,0,0,0,0,0,0,0,0,0,0,0,0,0
0,0,0,0,0,0,0,0,0,0,0,0,0,0,0,0,0,0,0,0,0,0,0,0,0,0,0
0,0,0,0,0,0,0,0,0,0,0,0,0,0,0,0,0,0,0,0,0,0,0,0,0,0,0
0,0,0,0,0,10,0,0,0,0,0,0,0,10,0,0,0,0,0,0,0,0,0,0,0,0,0
0,0,0,0,0,10,10,10,10,10,10,10,10,10,0,0,0,0,0,0,0,0,0,0,0,0,0
0,0,0,0,0,0,0,0,0,0,0,0,0,0,0,0,0,0,0,0,0,0,0,0,0,0,0
0,0,0,0,0,0,0,0,0,0,0,0,0,0,0,0,0,0,0,0,0,0,0,0,0,0,0
0,0,0,0,0,0,0,0,0,0,0,0,0,0,0,0,0,0,0,0,0,0,0,0,0,0,0
0,0,0,0,0,0,0,0,0,0,0,0,0,0,0,0,0,0,0,0,0,0,0,0,0,0,0
endlayer

layer
0,0,0,0,0,1,11,11,11,11,11,2,2,2,2,0,0,0,0,0,0,0,0,0,0,0,0
0,0,0,0,0,11,0,0,0,0,0,2,2,2,2,0,0,0,0,0,0,0,0,0,0,0,0
0,0,0,0,0,11,0,0,0,0,0,2,2,2,2,0,0,0,0,0,0,0,0,0,0,0,0
0,0,0,0,0,11,0,0,0,11,11,41,0,0,0,0,0,0,0,0,0,0,0,0,0,0,0
0,0,0,0,0,11,0,0,11,0,0,0,0,0,0,0,0,0,0,0,0,0,0,0,0,0,0
0,0,0,0,0,11,0,0,11,0,0,0,0,0,0,0,0,0,0,0,0,0,0,0,0,0,0
0,0,0,0,0,1,11,11,1,0,10,0,0,0,10,0,0,0,0,0,0,0,0,0,0,0,0
0,0,0,0,0,0,0,0,0,0,0,0,0,0,0,0,0,0,0,0,0,0,0,0,0,0,0
0,0,0,0,0,0,0,0,0,0,0,0,0,0,0,0,0,0,0,0,0,0,0,0,0,0,0
0,0,0,0,0,0,0,0,0,0,0,0,0,0,0,0,0,0,0,0,0,0,0,0,0,0,0
0,0,0,0,0,0,0,0,0,0,0,0,0,0,0,0,0,0,0,0,0,0,0,0,0,0,0
0,0,0,0,0,0,0,2,11,11,11,2,0,0,0,0,0,0,0,0,0,0,0,0,0,0,0
0,0,0,0,0,0,0,11,0,0,12,11,0,0,0,0,0,0,0,0,0,0,0,0,0,0,0
0,0,0,0,0,0,0,11,0,0,0,11,0,0,0,0,0,0,0,0,0,0,0,0,0,0,0
0,0,0,0,0,0,0,11,0,0,0,11,0,0,0,0,0,0,0,0,0,0,0,0,0,0,0
0,0,0,0,0,0,0,2,11,11,11,2,0,0,0,0,0,0,0,0,0,0,0,0,0,0,0
0,0,0,0,0,0,0,0,0,0,0,0,0,0,0,0,0,0,0,0,0,0,0,0,0,0,0
0,0,0,0,0,0,0,0,0,0,0,0,0,0,0,0,0,0,0,0,0,0,0,0,0,0,0
0,0,0,0,0,0,0,0,0,0,0,0,0,0,0,0,0,0,0,0,0,0,0,0,0,0,0
