# Nether Gargoyle (Obsidian) -- 5 May 2014
# Updated to MC 1.7.10, 13 Oct 2014
# Updated to MC 1.8: 22 Jul 2015
# Created by Ruins mod version 12.3 Ingame Parser
# authoring Player: Jordan_Greywolf
# Note: Place in \templateparser folder.
# Last updated 5 Feb 2016.

biomesToSpawnIn=badlands,boneyard,corrupted sands,deadlands,eerie,eldritch,fire swamp,hell,ominous woods,phantasmagoric inferno,spectral garden,tainted land,undergarden,visceral heap,volcano

weight=1
embed_into_distance=0
acceptable_target_blocks=
unacceptable_target_blocks=cloud,Natura:Cloud

dimensions=14,8,9
allowable_overhang=9999
max_cut_in=0
cut_in_buffer=0
max_leveling=7
leveling_buffer=-1
preserve_water=1
preserve_lava=1
preserve_plants=1

rule1=0,100,minecraft:obsidian
rule2=0,100,preserveBlock

layer
2,2,2,2,2,2,2,2,2
2,2,2,2,2,2,2,2,2
2,2,2,1,1,1,2,2,2
2,2,1,1,2,1,1,2,2
2,2,1,2,2,2,1,2,2
2,2,2,2,2,2,2,2,2
2,2,2,2,2,2,2,2,2
2,2,1,2,2,2,1,2,2
endlayer


layer
2,2,2,2,2,2,2,2,2
2,2,2,2,1,2,2,2,2
2,2,1,1,1,1,1,2,2
2,2,1,1,1,1,1,2,2
2,2,2,2,2,2,2,2,2
2,2,2,2,2,2,2,2,2
2,2,1,2,2,2,1,2,2
2,2,1,2,2,2,1,2,2
endlayer

layer
2,2,2,2,1,2,2,2,2
2,2,2,2,2,2,2,2,2
2,2,1,1,1,1,1,2,2
2,2,2,1,1,1,2,2,2
2,2,2,2,2,2,2,2,2
2,2,1,2,2,2,1,2,2
2,2,1,2,2,2,1,2,2
2,2,2,2,2,2,2,2,2
endlayer

layer
2,2,2,2,1,2,2,2,2
2,2,2,2,2,2,2,2,2
2,2,1,1,1,1,1,2,2
2,2,1,1,1,1,1,2,2
2,2,2,1,1,2,2,2,2
2,2,1,2,2,2,1,2,2
2,2,2,2,2,2,2,2,2
2,2,2,2,2,2,2,2,2
endlayer

layer
2,2,2,2,1,2,2,2,2
2,2,2,2,2,2,2,2,2
2,2,2,2,1,2,2,2,2
2,2,2,1,1,1,2,2,2
2,2,2,1,1,1,2,2,2
2,2,1,1,1,1,1,2,2
2,2,2,2,2,2,2,2,2
2,2,2,2,2,2,2,2,2
endlayer

layer
2,2,2,2,1,2,2,2,2
2,2,2,2,2,2,2,2,2
2,2,2,2,1,2,2,2,2
2,2,2,2,1,2,2,2,2
2,2,2,1,1,1,2,2,2
2,2,2,1,1,1,2,2,2
2,2,2,2,2,2,2,2,2
2,2,2,2,2,2,2,2,2
endlayer

layer
2,2,1,2,1,2,1,2,2
2,2,2,2,2,2,2,2,2
2,2,2,2,1,2,2,2,2
2,2,2,1,1,1,2,2,2
2,2,2,1,1,1,2,2,2
2,2,2,2,1,2,2,2,2
2,2,2,2,2,2,2,2,2
2,2,2,2,2,2,2,2,2
endlayer

layer
1,2,1,2,2,2,1,2,1
2,2,1,2,2,2,1,2,2
2,2,2,2,2,2,2,2,2
2,2,1,1,1,1,1,2,2
2,2,2,2,1,2,2,2,2
2,2,2,2,1,2,2,2,2
2,2,2,1,1,1,2,2,2
2,2,2,2,1,2,2,2,2
endlayer

layer
1,1,1,2,2,2,1,1,1
2,2,1,2,2,2,1,2,2
2,2,1,2,2,2,1,2,2
2,2,1,2,2,2,1,2,2
2,2,2,2,1,2,2,2,2
2,2,2,1,1,1,2,2,2
2,2,2,1,1,1,2,2,2
2,2,2,2,2,2,2,2,2
endlayer

layer
1,1,1,2,2,2,1,1,1
2,2,1,2,2,2,1,2,2
2,2,1,2,2,2,1,2,2
2,2,2,2,2,2,2,2,2
2,2,2,2,2,2,2,2,2
2,2,2,1,2,1,2,2,2
2,2,2,2,2,2,2,2,2
2,2,2,2,2,2,2,2,2
endlayer

layer
1,1,1,2,2,2,1,1,1
2,2,1,2,2,2,1,2,2
2,2,2,2,2,2,2,2,2
2,2,2,2,2,2,2,2,2
2,2,2,2,2,2,2,2,2
2,2,2,2,2,2,2,2,2
2,2,2,2,2,2,2,2,2
2,2,2,2,2,2,2,2,2
endlayer

layer
2,1,1,2,2,2,1,1,2
2,2,1,2,2,2,1,2,2
2,2,2,2,2,2,2,2,2
2,2,2,2,2,2,2,2,2
2,2,2,2,2,2,2,2,2
2,2,2,2,2,2,2,2,2
2,2,2,2,2,2,2,2,2
2,2,2,2,2,2,2,2,2
endlayer

layer
2,2,2,2,2,2,2,2,2
2,1,1,2,2,2,1,1,2
2,2,2,2,2,2,2,2,2
2,2,2,2,2,2,2,2,2
2,2,2,2,2,2,2,2,2
2,2,2,2,2,2,2,2,2
2,2,2,2,2,2,2,2,2
2,2,2,2,2,2,2,2,2
endlayer

layer
2,2,2,2,2,2,2,2,2
2,2,2,2,2,2,2,2,2
2,2,1,2,2,2,1,2,2
2,2,2,2,2,2,2,2,2
2,2,2,2,2,2,2,2,2
2,2,2,2,2,2,2,2,2
2,2,2,2,2,2,2,2,2
2,2,2,2,2,2,2,2,2
endlayer


