# Gargoyle_Glass (6 May 2014)
# Created by Ruins mod version 12.3 Ingame Parser
# authoring Player: Jordan_Greywolf
# Updated to MC 1.12: 8 Apr 2018

# Creepy "gargoyle" statue of glass -- purely decorative.

biomesToSpawnIn=badlands,boneyard,corrupted sands,deadlands,eerie,eldritch,fire swamp,hell,ominous woods,phantasmagoric inferno,spectral garden,tainted land,undergarden,visceral heap,volcano

weight=1
embed_into_distance=0
acceptable_target_blocks=
unacceptable_target_blocks=cloud,Natura:Cloud

dimensions=16,8,9
allowable_overhang=9999
max_cut_in=0
cut_in_buffer=0
max_leveling=0
leveling_buffer=-1
preserve_water=0
preserve_lava=1
preserve_plants=1

# Stained Glass (red)
rule1=0,100,minecraft:stained_glass-14

rule2=0,100,preserveBlock

# -3
layer
2,2,1,1,1,1,1,2,2
2,2,1,1,1,1,1,2,2
2,2,1,1,1,1,1,2,2
2,2,1,1,1,1,1,2,2
2,2,1,1,1,1,1,2,2
2,2,1,1,1,1,1,2,2
2,2,1,1,1,1,1,2,2
2,2,1,1,1,1,1,2,2
endlayer

# -2
layer
2,2,1,1,1,1,1,2,2
2,2,1,1,1,1,1,2,2
2,2,1,1,1,1,1,2,2
2,2,1,1,1,1,1,2,2
2,2,1,1,1,1,1,2,2
2,2,1,1,1,1,1,2,2
2,2,1,1,1,1,1,2,2
2,2,1,1,1,1,1,2,2
endlayer

# -1
layer
2,2,2,2,2,2,2,2,2
2,2,2,2,2,2,2,2,2
2,2,1,1,1,1,1,2,2
2,2,1,1,1,1,1,2,2
2,2,1,2,2,2,1,2,2
2,2,2,2,2,2,2,2,2
2,2,2,2,2,2,2,2,2
2,2,1,2,2,2,1,2,2
endlayer


# +1
layer
0,0,0,0,0,0,0,0,0
0,0,0,0,1,0,0,0,0
0,0,1,1,1,1,1,0,0
0,0,1,1,1,1,1,0,0
0,0,0,0,0,0,0,0,0
0,0,0,0,0,0,0,0,0
0,0,1,0,0,0,1,0,0
0,0,1,0,0,0,1,0,0
endlayer

# +2
layer
0,0,0,0,1,0,0,0,0
0,0,0,0,0,0,0,0,0
0,0,1,1,1,1,1,0,0
0,0,0,1,1,1,0,0,0
0,0,0,0,0,0,0,0,0
0,0,1,0,0,0,1,0,0
0,0,1,0,0,0,1,0,0
0,0,0,0,0,0,0,0,0
endlayer

# +3
layer
0,0,0,0,1,0,0,0,0
0,0,0,0,0,0,0,0,0
0,0,1,1,1,1,1,0,0
0,0,1,1,1,1,1,0,0
0,0,0,1,1,0,0,0,0
0,0,1,0,0,0,1,0,0
0,0,0,0,0,0,0,0,0
0,0,0,0,0,0,0,0,0
endlayer

# +4
layer
0,0,0,0,1,0,0,0,0
0,0,0,0,0,0,0,0,0
0,0,0,0,1,0,0,0,0
0,0,0,1,1,1,0,0,0
0,0,0,1,1,1,0,0,0
0,0,1,1,1,1,1,0,0
0,0,0,0,0,0,0,0,0
0,0,0,0,0,0,0,0,0
endlayer

# +5
layer
0,0,0,0,1,0,0,0,0
0,0,0,0,0,0,0,0,0
0,0,0,0,1,0,0,0,0
0,0,0,0,1,0,0,0,0
0,0,0,1,1,1,0,0,0
0,0,0,1,1,1,0,0,0
0,0,0,0,0,0,0,0,0
0,0,0,0,0,0,0,0,0
endlayer

# +6
layer
0,0,1,0,1,0,1,0,0
0,0,0,0,0,0,0,0,0
0,0,0,0,1,0,0,0,0
0,0,0,1,1,1,0,0,0
0,0,0,1,1,1,0,0,0
0,0,0,0,1,0,0,0,0
0,0,0,0,0,0,0,0,0
0,0,0,0,0,0,0,0,0
endlayer

# +7
layer
1,0,1,0,0,0,1,0,1
0,0,1,0,0,0,1,0,0
0,0,0,0,0,0,0,0,0
0,0,1,1,1,1,1,0,0
0,0,0,0,1,0,0,0,0
0,0,0,0,1,0,0,0,0
0,0,0,1,1,1,0,0,0
0,0,0,0,1,0,0,0,0
endlayer

# +8
layer
1,1,1,0,0,0,1,1,1
0,0,1,0,0,0,1,0,0
0,0,1,0,0,0,1,0,0
0,0,1,0,0,0,1,0,0
0,0,0,0,1,0,0,0,0
0,0,0,1,1,1,0,0,0
0,0,0,1,1,1,0,0,0
0,0,0,0,0,0,0,0,0
endlayer

# +9
layer
1,1,1,0,0,0,1,1,1
0,0,1,0,0,0,1,0,0
0,0,1,0,0,0,1,0,0
0,0,0,0,0,0,0,0,0
0,0,0,0,0,0,0,0,0
0,0,0,1,0,1,0,0,0
0,0,0,0,0,0,0,0,0
0,0,0,0,0,0,0,0,0
endlayer

# +10
layer
1,1,1,0,0,0,1,1,1
0,0,1,0,0,0,1,0,0
0,0,0,0,0,0,0,0,0
0,0,0,0,0,0,0,0,0
0,0,0,0,0,0,0,0,0
0,0,0,0,0,0,0,0,0
0,0,0,0,0,0,0,0,0
0,0,0,0,0,0,0,0,0
endlayer

# +11
layer
0,1,1,0,0,0,1,1,0
0,0,1,0,0,0,1,0,0
0,0,0,0,0,0,0,0,0
0,0,0,0,0,0,0,0,0
0,0,0,0,0,0,0,0,0
0,0,0,0,0,0,0,0,0
0,0,0,0,0,0,0,0,0
0,0,0,0,0,0,0,0,0
endlayer

# +12
layer
0,0,0,0,0,0,0,0,0
0,1,1,0,0,0,1,1,0
0,0,0,0,0,0,0,0,0
0,0,0,0,0,0,0,0,0
0,0,0,0,0,0,0,0,0
0,0,0,0,0,0,0,0,0
0,0,0,0,0,0,0,0,0
0,0,0,0,0,0,0,0,0
endlayer

# +13
layer
0,0,0,0,0,0,0,0,0
0,0,0,0,0,0,0,0,0
0,0,1,0,0,0,1,0,0
0,0,0,0,0,0,0,0,0
0,0,0,0,0,0,0,0,0
0,0,0,0,0,0,0,0,0
0,0,0,0,0,0,0,0,0
0,0,0,0,0,0,0,0,0
endlayer

