# Nightmare Dungeon (Nether Version)
# MC 1.7.10; 23 Oct 2014
# Created by Ruins mod version 13.8 Ingame Parser
# authoring Player: Jordan_Greywolf
# Last Updated: 5 Feb 2016
# Updated to MC 1.9: 24 Apr 2016
# Updated to MC 1.11: 11 May 2017
# Updated to MC 1.12: 28 May 2018

biomesToSpawnIn=hell

weight=1
#embed_into_distance=23
embed_into_distance=0

unacceptable_target_blocks=flowing_water,water,cloud,Natura:Cloud

dimensions=33,15,15
allowable_overhang=0
max_leveling=8
leveling_buffer=-1
preserve_water=0
preserve_lava=0
preserve_plants=1

uniqueMinDistance=1000

rule1=0,100,minecraft:obsidian-0
rule2=0,100,minecraft:obsidian-0
rule3=0,100,minecraft:lava-0
rule4=0,100,minecraft:lava-10
rule5=0,100,minecraft:sticky_piston-5
rule6=0,100,minecraft:lava-8
rule7=0,100,minecraft:redstone_wire-0
rule8=0,100,CommandBlock:RUINSTRIGGER /summon skeleton_horse ~0 ~2 ~0 {CustomName:Nightmare,Tame:1,Attributes:[{Name:generic.movementSpeed,Base:0.4}],Invulnerable:1,PersistenceRequired:1}:@
rule9=0,100,minecraft:lava-2
rule10=0,100,minecraft:nether_brick-0
rule11=0,100,minecraft:skull-0
rule12=0,100,minecraft:nether_brick_stairs-0
rule13=0,100,minecraft:stone_slab-14
rule14=0,100,minecraft:nether_brick_stairs-5
rule15=0,100,minecraft:nether_brick_stairs-7
rule16=0,100,minecraft:nether_brick_stairs-6
rule17=0,100,minecraft:double_stone_slab-6
rule18=0,100,minecraft:stone_slab-6
rule19=0,100,minecraft:nether_brick_stairs-4
rule20=0,100,minecraft:nether_brick_fence-0
rule21=0,100,ChestGenHook:chests/simple_dungeon:5-5
rule22=0,100,ChestGenHook:chests/simple_dungeon:5-3
rule23=0,100,ChestGenHook:chests/simple_dungeon:5-2
rule24=0,100,ChestGenHook:chests/simple_dungeon:5-4
rule25=1,100,minecraft:redstone_torch-5
rule26=0,100,minecraft:nether_brick_stairs-1
rule27=0,100,minecraft:nether_brick_stairs-2
rule28=0,100,minecraft:nether_brick_stairs-3
rule29=0,100,minecraft:netherrack-0
rule30=0,100,minecraft:fire-15
rule31=0,100,MobSpawner:Creeper,MobSpawner:Blaze,MobSpawner:Wither_Skeleton

layer
1,1,1,1,1,1,1,1,1,1,1,1,1,1,1
1,1,1,1,1,1,1,1,1,1,1,1,1,1,1
1,1,1,1,1,1,1,1,1,1,1,1,1,1,1
1,1,1,1,1,1,1,1,1,1,1,1,1,1,1
1,1,1,1,1,1,1,1,1,1,1,1,1,1,1
1,1,1,1,1,1,1,1,1,1,1,1,1,1,1
1,1,1,1,1,1,2,2,2,1,1,1,1,1,1
1,1,1,1,1,1,2,2,2,1,1,1,1,1,1
1,1,1,1,1,1,2,2,2,1,1,1,1,1,1
1,1,1,1,1,1,1,1,1,1,1,1,1,1,1
1,1,1,1,1,1,1,1,1,1,1,1,1,1,1
1,1,1,1,1,1,1,1,1,1,1,1,1,1,1
1,1,1,1,1,1,1,1,1,1,1,1,1,1,1
1,1,1,1,1,1,1,1,1,1,1,1,1,1,1
1,1,1,1,1,1,1,1,1,1,1,1,1,1,1
endlayer

layer
1,1,1,1,1,1,1,1,1,1,1,1,1,1,1
1,3,3,3,3,3,3,3,3,3,3,3,3,3,1
1,3,1,1,1,1,1,1,1,1,1,1,1,3,1
1,3,1,3,3,3,3,3,3,3,3,3,1,3,1
1,3,1,3,3,3,3,3,3,3,3,3,1,3,1
1,3,1,3,3,3,2,2,2,3,3,3,1,3,1
1,3,1,3,3,2,2,2,2,2,3,3,1,3,1
1,3,1,3,3,2,2,2,2,2,3,3,1,3,1
1,3,1,3,3,2,2,2,2,2,3,3,1,3,1
1,3,1,3,3,3,2,2,2,3,3,3,1,3,1
1,3,1,3,3,3,3,3,3,3,3,3,1,3,1
1,3,1,3,3,3,3,3,3,3,3,3,1,3,1
1,3,1,1,1,1,1,1,1,1,1,1,1,3,1
1,3,3,3,3,3,3,3,3,3,3,3,3,3,1
1,1,1,1,1,1,1,1,1,1,1,1,1,1,1
endlayer

layer
1,1,1,1,1,1,1,1,1,1,1,1,1,1,1
1,3,3,3,3,3,3,3,3,3,3,3,3,3,1
1,3,1,1,1,1,1,1,1,1,1,1,1,3,1
1,3,1,3,3,3,3,3,3,3,3,3,1,3,1
1,3,1,3,4,3,3,3,3,3,4,3,1,3,1
1,3,1,3,3,2,2,2,2,2,3,3,1,3,1
1,3,1,6,3,2,0,5,0,2,3,3,1,3,1
1,3,1,3,3,2,8,7,0,2,3,3,1,3,1
1,3,1,3,3,2,0,0,0,2,3,3,1,3,1
1,3,1,3,3,2,2,2,2,2,3,3,1,3,1
1,3,1,3,4,3,3,3,3,3,4,3,1,3,1
1,3,1,3,3,6,3,3,3,3,3,3,1,3,1
1,3,1,1,1,1,1,1,1,1,1,1,1,3,1
1,3,3,3,3,3,3,3,3,3,3,3,3,3,1
1,1,1,1,1,1,1,1,1,1,1,1,1,1,1
endlayer

layer
1,1,1,1,1,1,1,1,1,1,1,1,1,1,1
1,3,3,3,3,3,3,3,3,3,3,3,3,3,1
1,3,1,1,1,1,1,1,1,1,1,1,1,3,1
1,3,1,3,3,3,3,3,3,3,3,3,1,3,1
1,3,1,3,9,9,9,9,9,9,9,3,1,3,1
1,3,1,3,9,2,1,2,1,2,9,3,1,3,1
1,3,1,3,9,1,2,2,2,1,9,3,1,3,1
1,3,1,3,9,2,2,2,2,2,9,3,1,3,1
1,3,1,3,9,1,2,2,2,1,9,3,1,3,1
1,3,1,3,9,2,1,2,1,2,9,3,1,3,1
1,3,1,3,9,9,9,9,9,9,9,3,1,3,1
1,3,1,3,3,3,3,3,3,3,3,3,1,3,1
1,3,1,1,1,1,1,1,1,1,1,1,1,3,1
1,3,3,3,3,3,3,3,3,3,3,3,3,3,1
1,1,1,1,1,1,1,1,1,1,1,1,1,1,1
endlayer

layer
1,1,1,1,1,1,1,1,1,1,1,1,1,1,1
1,3,3,3,3,3,3,3,3,3,3,3,3,3,1
1,3,1,1,1,1,1,1,1,1,1,1,1,3,1
1,3,1,10,0,0,0,0,0,0,0,10,1,3,1
1,3,1,0,0,0,0,0,0,0,0,0,1,3,1
1,3,1,0,0,0,0,0,0,0,0,0,1,3,1
1,3,1,0,0,0,0,0,0,0,0,0,1,3,1
1,3,1,0,0,0,0,11,0,0,0,0,1,3,1
1,3,1,0,0,0,0,12,0,0,0,0,1,3,1
1,3,1,0,0,0,0,13,0,0,0,0,1,3,1
1,3,1,0,0,0,0,0,0,0,0,0,1,3,1
1,3,1,10,0,0,0,0,0,0,0,10,1,3,1
1,3,1,1,1,1,1,1,1,1,1,1,1,3,1
1,3,3,3,3,3,3,3,3,3,3,3,3,3,1
1,1,1,1,1,1,1,1,1,1,1,1,1,1,1
endlayer

layer
1,1,1,1,1,1,1,1,1,1,1,1,1,1,1
1,3,3,3,3,3,3,3,3,3,3,3,3,3,1
1,3,1,1,1,1,1,1,1,1,1,1,1,3,1
1,3,1,10,0,0,0,14,0,0,0,10,1,3,1
1,3,1,0,0,0,0,0,0,0,0,0,1,3,1
1,3,1,0,0,0,0,0,0,0,0,0,1,3,1
1,3,1,0,0,0,0,0,0,0,0,0,1,3,1
1,3,1,16,0,0,0,0,0,0,0,15,1,3,1
1,3,1,0,0,0,0,0,0,0,0,0,1,3,1
1,3,1,0,0,13,17,18,17,13,0,0,1,3,1
1,3,1,0,0,0,0,0,0,0,0,0,1,3,1
1,3,1,10,0,0,0,19,0,0,0,10,1,3,1
1,3,1,1,1,1,1,1,1,1,1,1,1,3,1
1,3,3,3,3,3,3,3,3,3,3,3,3,3,1
1,1,1,1,1,1,1,1,1,1,1,1,1,1,1
endlayer

layer
1,1,1,1,1,1,1,1,1,1,1,1,1,1,1
1,3,3,3,3,3,3,3,3,3,3,3,3,3,1
1,3,1,1,1,1,1,1,1,1,1,1,1,3,1
1,3,1,10,0,0,20,21,20,0,0,10,1,3,1
1,3,1,0,0,0,0,0,0,0,0,0,1,3,1
1,3,1,0,0,0,0,0,0,0,0,0,1,3,1
1,3,1,20,0,0,0,0,0,0,0,20,1,3,1
1,3,1,23,0,19,0,0,0,19,0,22,1,3,1
1,3,1,20,0,17,0,0,0,10,0,20,1,3,1
1,3,1,0,0,18,0,0,0,18,0,0,1,3,1
1,3,1,0,0,0,0,0,0,0,0,0,1,3,1
1,3,1,10,0,0,20,24,20,0,0,10,1,3,1
1,3,1,1,1,1,1,1,1,1,1,1,1,3,1
1,3,3,3,3,3,3,3,3,3,3,3,3,3,1
1,1,1,1,1,1,1,1,1,1,1,1,1,1,1
endlayer

layer
1,1,1,1,1,1,1,1,1,1,1,1,1,1,1
1,3,3,3,3,3,3,3,3,3,3,3,3,3,1
1,3,1,1,1,1,1,1,1,1,1,1,1,3,1
1,3,1,10,10,0,25,0,25,0,10,10,1,3,1
1,3,1,10,0,0,0,0,0,0,0,10,1,3,1
1,3,1,0,0,0,0,0,0,0,0,0,1,3,1
1,3,1,25,0,19,16,0,15,19,0,25,1,3,1
1,3,1,0,0,26,0,0,0,26,0,0,1,3,1
1,3,1,25,0,0,0,0,0,0,0,25,1,3,1
1,3,1,0,0,0,0,0,0,0,0,0,1,3,1
1,3,1,10,0,0,0,0,0,0,0,10,1,3,1
1,3,1,10,10,0,25,0,25,0,10,10,1,3,1
1,3,1,1,1,1,1,1,1,1,1,1,1,3,1
1,3,3,3,3,3,3,3,3,3,3,3,3,3,1
1,1,1,1,1,1,1,1,1,1,1,1,1,1,1
endlayer

layer
1,1,1,1,1,1,1,1,1,1,1,1,1,1,1
1,3,3,3,3,3,3,3,3,3,3,3,3,3,1
1,3,1,1,1,1,1,1,1,1,1,1,1,3,1
1,3,1,10,10,16,0,0,0,15,10,10,1,3,1
1,3,1,10,0,0,0,0,0,0,0,10,1,3,1
1,3,1,14,0,0,0,0,0,0,0,14,1,3,1
1,3,1,0,0,0,28,10,27,0,0,0,1,3,1
1,3,1,0,0,0,0,14,0,0,0,0,1,3,1
1,3,1,0,0,0,0,0,0,0,0,0,1,3,1
1,3,1,19,0,0,0,0,0,0,0,19,1,3,1
1,3,1,10,0,0,0,0,0,0,0,10,1,3,1
1,3,1,10,10,16,0,0,0,15,10,10,1,3,1
1,3,1,1,1,1,1,1,1,1,1,1,1,3,1
1,3,3,3,3,3,3,3,3,3,3,3,3,3,1
1,1,1,1,1,1,1,1,1,1,1,1,1,1,1
endlayer

layer
1,1,1,1,1,1,1,1,1,1,1,1,1,1,1
1,3,3,3,3,3,3,3,3,3,3,3,3,3,1
1,3,1,1,1,1,1,1,1,1,1,1,1,3,1
1,3,1,29,10,10,16,0,15,10,10,29,1,3,1
1,3,1,10,10,0,0,0,0,0,10,10,1,3,1
1,3,1,10,0,0,0,0,0,0,0,10,1,3,1
1,3,1,14,0,0,0,0,0,0,0,14,1,3,1
1,3,1,0,0,0,0,12,0,0,0,0,1,3,1
1,3,1,19,0,0,0,14,0,0,0,19,1,3,1
1,3,1,10,0,0,0,0,0,0,0,10,1,3,1
1,3,1,10,10,0,0,0,0,0,10,10,1,3,1
1,3,1,29,10,10,16,0,15,10,10,29,1,3,1
1,3,1,1,1,1,1,1,1,1,1,1,1,3,1
1,3,3,3,3,3,3,3,3,3,3,3,3,3,1
1,1,1,1,1,1,1,1,1,1,1,1,1,1,1
endlayer

layer
1,1,1,1,1,1,1,1,1,1,1,1,1,1,1
1,3,3,3,3,3,3,3,3,3,3,3,3,3,1
1,3,1,1,1,1,1,1,1,1,1,1,1,3,1
1,3,1,30,0,0,10,10,10,0,0,30,1,3,1
1,3,1,0,10,20,0,0,0,20,10,0,1,3,1
1,3,1,0,20,0,0,0,0,0,20,0,1,3,1
1,3,1,10,0,0,0,0,0,0,0,10,1,3,1
1,3,1,10,0,0,0,0,0,0,0,10,1,3,1
1,3,1,10,0,0,0,12,0,0,0,10,1,3,1
1,3,1,0,20,0,0,14,0,0,20,0,1,3,1
1,3,1,0,10,20,0,0,0,20,10,0,1,3,1
1,3,1,30,0,0,10,10,10,0,0,30,1,3,1
1,3,1,1,1,1,1,1,1,1,1,1,1,3,1
1,3,3,3,3,3,3,3,3,3,3,3,3,3,1
1,1,1,1,1,1,1,1,1,1,1,1,1,1,1
endlayer

layer
1,1,1,1,1,1,1,1,1,1,1,1,1,1,1
1,3,3,3,3,3,3,3,3,3,3,3,3,3,1
1,3,1,1,1,1,1,1,1,1,1,1,1,3,1
1,3,1,0,1,1,1,1,1,1,1,0,1,3,1
1,3,1,1,1,1,1,31,1,1,1,1,1,3,1
1,3,1,1,1,14,0,0,0,14,1,1,1,3,1
1,3,1,1,1,0,0,0,0,0,1,1,1,3,1
1,3,1,1,31,0,0,0,0,0,31,1,1,3,1
1,3,1,1,1,0,0,0,0,0,1,1,1,3,1
1,3,1,1,1,0,0,12,0,0,1,1,1,3,1
1,3,1,1,1,1,1,31,1,1,1,1,1,3,1
1,3,1,0,1,1,1,1,1,1,1,0,1,3,1
1,3,1,1,1,1,1,1,1,1,1,1,1,3,1
1,3,3,3,3,3,3,3,3,3,3,3,3,3,1
1,1,1,1,1,1,1,1,1,1,1,1,1,1,1
endlayer

layer
1,1,1,1,1,1,1,1,1,1,1,1,1,1,1
1,3,3,3,3,3,3,3,3,3,3,3,3,3,1
1,3,1,1,1,1,1,1,1,1,1,1,1,3,1
1,3,1,0,0,0,0,0,0,0,0,0,1,3,1
1,3,1,0,0,0,0,0,0,0,0,0,1,3,1
1,3,1,0,0,12,0,0,0,12,0,0,1,3,1
1,3,1,0,0,14,0,0,0,14,0,0,1,3,1
1,3,1,0,0,0,0,0,0,0,0,0,1,3,1
1,3,1,0,0,0,0,0,0,0,0,0,1,3,1
1,3,1,0,0,0,0,0,0,0,0,0,1,3,1
1,3,1,0,0,0,0,0,0,0,0,0,1,3,1
1,3,1,0,0,0,0,0,0,0,0,0,1,3,1
1,3,1,1,1,1,1,1,1,1,1,1,1,3,1
1,3,3,3,3,3,3,3,3,3,3,3,3,3,1
1,1,1,1,1,1,1,1,1,1,1,1,1,1,1
endlayer

layer
1,1,1,1,1,1,1,1,1,1,1,1,1,1,1
1,3,3,3,3,3,3,3,3,3,3,3,3,3,1
1,3,1,1,1,1,1,1,1,1,1,1,1,3,1
1,3,1,0,0,0,0,0,0,0,0,0,1,3,1
1,3,1,0,0,0,0,0,0,0,0,0,1,3,1
1,3,1,0,0,0,0,0,0,0,0,0,1,3,1
1,3,1,0,0,12,0,0,0,12,0,0,1,3,1
1,3,1,0,0,14,16,0,15,14,0,0,1,3,1
1,3,1,0,0,0,0,0,0,0,0,0,1,3,1
1,3,1,0,0,0,0,0,0,0,0,0,1,3,1
1,3,1,0,0,0,0,0,0,0,0,0,1,3,1
1,3,1,0,0,0,0,0,0,0,0,0,1,3,1
1,3,1,1,1,1,1,1,1,1,1,1,1,3,1
1,3,3,3,3,3,3,3,3,3,3,3,3,3,1
1,1,1,1,1,1,1,1,1,1,1,1,1,1,1
endlayer

layer
1,1,1,1,1,1,1,1,1,1,1,1,1,1,1
1,3,3,3,3,3,3,3,3,3,3,3,3,3,1
1,3,1,1,1,1,1,1,1,1,1,1,1,3,1
1,3,1,0,0,0,0,0,0,0,0,0,1,3,1
1,3,1,0,0,0,0,0,0,0,0,0,1,3,1
1,3,1,0,0,0,0,0,0,0,0,0,1,3,1
1,3,1,0,0,0,0,0,0,0,0,0,1,3,1
1,3,1,0,0,0,28,10,27,0,0,0,1,3,1
1,3,1,0,0,0,0,14,0,0,0,0,1,3,1
1,3,1,0,0,0,0,0,0,0,0,0,1,3,1
1,3,1,0,0,0,0,0,0,0,0,0,1,3,1
1,3,1,0,0,0,0,0,0,0,0,0,1,3,1
1,3,1,1,1,1,1,1,1,1,1,1,1,3,1
1,3,3,3,3,3,3,3,3,3,3,3,3,3,1
1,1,1,1,1,1,1,1,1,1,1,1,1,1,1
endlayer

layer
1,1,1,1,1,1,1,1,1,1,1,1,1,1,1
1,3,3,3,3,3,3,3,3,3,3,3,3,3,1
1,3,1,1,1,1,1,1,1,1,1,1,1,3,1
1,3,1,0,0,0,0,0,0,0,0,0,1,3,1
1,3,1,0,0,0,0,0,0,0,0,0,1,3,1
1,3,1,0,0,0,0,0,0,0,0,0,1,3,1
1,3,1,0,0,0,0,0,0,0,0,0,1,3,1
1,3,1,0,0,0,0,0,0,0,0,0,1,3,1
1,3,1,0,0,0,0,12,0,0,0,0,1,3,1
1,3,1,0,0,0,0,14,0,0,0,0,1,3,1
1,3,1,0,0,0,0,0,0,0,0,0,1,3,1
1,3,1,0,0,0,0,0,0,0,0,0,1,3,1
1,3,1,1,1,1,1,1,1,1,1,1,1,3,1
1,3,3,3,3,3,3,3,3,3,3,3,3,3,1
1,1,1,1,1,1,1,1,1,1,1,1,1,1,1
endlayer

layer
1,1,1,1,1,1,1,1,1,1,1,1,1,1,1
1,3,3,3,3,3,3,3,3,3,3,3,3,3,1
1,3,1,1,1,1,1,1,1,1,1,1,1,3,1
1,3,1,31,1,1,1,1,1,1,1,31,1,3,1
1,3,1,1,1,1,1,1,1,1,1,1,1,3,1
1,3,1,1,1,16,0,0,0,15,1,1,1,3,1
1,3,1,1,1,0,0,0,0,0,1,1,1,3,1
1,3,1,1,1,0,0,0,0,0,1,1,1,3,1
1,3,1,1,1,0,0,0,0,0,1,1,1,3,1
1,3,1,1,1,0,0,12,0,0,1,1,1,3,1
1,3,1,1,1,1,1,1,1,1,1,1,1,3,1
1,3,1,31,1,1,1,1,1,1,1,31,1,3,1
1,3,1,1,1,1,1,1,1,1,1,1,1,3,1
1,3,3,3,3,3,3,3,3,3,3,3,3,3,1
1,1,1,1,1,1,1,1,1,1,1,1,1,1,1
endlayer

layer
1,1,1,1,1,1,1,1,1,1,1,1,1,1,1
1,3,3,3,3,3,3,3,3,3,3,3,3,3,1
1,3,1,1,1,1,1,1,1,1,1,1,1,3,1
1,3,1,0,0,0,0,0,0,0,0,0,1,3,1
1,3,1,0,0,0,0,0,0,0,0,0,1,3,1
1,3,1,0,0,28,16,0,15,27,0,0,1,3,1
1,3,1,0,0,0,0,0,0,0,0,0,1,3,1
1,3,1,0,0,0,0,0,0,0,0,0,1,3,1
1,3,1,0,0,0,0,0,0,0,0,0,1,3,1
1,3,1,0,0,0,0,0,0,0,0,0,1,3,1
1,3,1,0,0,0,0,0,0,0,0,0,1,3,1
1,3,1,0,0,0,0,0,0,0,0,0,1,3,1
1,3,1,1,1,1,1,1,1,1,1,1,1,3,1
1,3,3,3,3,3,3,3,3,3,3,3,3,3,1
1,1,1,1,1,1,1,1,1,1,1,1,1,1,1
endlayer

layer
1,1,1,1,1,1,1,1,1,1,1,1,1,1,1
1,3,3,3,3,3,3,3,3,3,3,3,3,3,1
1,3,1,1,1,1,1,1,1,1,1,1,1,3,1
1,3,1,0,0,0,0,0,0,0,0,0,1,3,1
1,3,1,0,0,0,0,0,0,0,0,0,1,3,1
1,3,1,0,0,0,28,10,27,0,0,0,1,3,1
1,3,1,0,0,0,0,14,0,0,0,0,1,3,1
1,3,1,0,0,0,0,0,0,0,0,0,1,3,1
1,3,1,0,0,0,0,0,0,0,0,0,1,3,1
1,3,1,0,0,0,0,0,0,0,0,0,1,3,1
1,3,1,0,0,0,0,0,0,0,0,0,1,3,1
1,3,1,0,0,0,0,0,0,0,0,0,1,3,1
1,3,1,1,1,1,1,1,1,1,1,1,1,3,1
1,3,3,3,3,3,3,3,3,3,3,3,3,3,1
1,1,1,1,1,1,1,1,1,1,1,1,1,1,1
endlayer

layer
1,1,1,1,1,1,1,1,1,1,1,1,1,1,1
1,3,3,3,3,3,3,3,3,3,3,3,3,3,1
1,3,1,1,1,1,1,1,1,1,1,1,1,3,1
1,3,1,0,0,0,0,0,0,0,0,0,1,3,1
1,3,1,0,0,0,0,0,0,0,0,0,1,3,1
1,3,1,0,0,0,0,0,0,0,0,0,1,3,1
1,3,1,0,0,0,0,12,0,0,0,0,1,3,1
1,3,1,0,0,0,0,14,0,0,0,0,1,3,1
1,3,1,0,0,0,0,0,0,0,0,0,1,3,1
1,3,1,0,0,0,0,0,0,0,0,0,1,3,1
1,3,1,0,0,0,0,0,0,0,0,0,1,3,1
1,3,1,0,0,0,0,0,0,0,0,0,1,3,1
1,3,1,1,1,1,1,1,1,1,1,1,1,3,1
1,3,3,3,3,3,3,3,3,3,3,3,3,3,1
1,1,1,1,1,1,1,1,1,1,1,1,1,1,1
endlayer

layer
1,1,1,1,1,1,1,1,1,1,1,1,1,1,1
1,3,3,3,3,3,3,3,3,3,3,3,3,3,1
1,3,1,1,1,1,1,1,1,1,1,1,1,3,1
1,3,1,0,0,0,0,0,0,0,0,0,1,3,1
1,3,1,0,0,0,0,0,0,0,0,0,1,3,1
1,3,1,0,0,0,0,0,0,0,0,0,1,3,1
1,3,1,0,0,0,0,0,0,0,0,0,1,3,1
1,3,1,0,0,0,0,12,0,0,0,0,1,3,1
1,3,1,0,0,0,0,14,0,0,0,0,1,3,1
1,3,1,0,0,0,0,0,0,0,0,0,1,3,1
1,3,1,0,0,0,0,0,0,0,0,0,1,3,1
1,3,1,0,0,0,0,0,0,0,0,0,1,3,1
1,3,1,1,1,1,1,1,1,1,1,1,1,3,1
1,3,3,3,3,3,3,3,3,3,3,3,3,3,1
1,1,1,1,1,1,1,1,1,1,1,1,1,1,1
endlayer

layer
1,1,1,1,1,1,1,1,1,1,1,1,1,1,1
1,3,3,3,3,3,3,3,3,3,3,3,3,3,1
1,3,1,1,1,1,1,1,1,1,1,1,1,3,1
1,3,1,0,0,0,0,0,0,0,0,0,1,3,1
1,3,1,0,0,0,0,0,0,0,0,0,1,3,1
1,3,1,0,0,0,0,0,0,0,0,0,1,3,1
1,3,1,0,0,0,0,0,0,0,0,0,1,3,1
1,3,1,0,0,0,0,0,0,0,0,0,1,3,1
1,3,1,0,0,0,0,12,0,0,0,0,1,3,1
1,3,1,0,0,0,0,14,0,0,0,0,1,3,1
1,3,1,0,0,0,0,0,0,0,0,0,1,3,1
1,3,1,0,0,0,0,0,0,0,0,0,1,3,1
1,3,1,1,1,1,1,1,1,1,1,1,1,3,1
1,3,3,3,3,3,3,3,3,3,3,3,3,3,1
1,1,1,1,1,1,1,1,1,1,1,1,1,1,1
endlayer

layer
1,1,1,1,1,1,1,1,1,1,1,1,1,1,1
1,3,3,3,3,3,3,3,3,3,3,3,3,3,1
1,3,1,1,1,1,1,1,1,1,1,1,1,3,1
1,3,1,0,0,0,0,0,0,0,0,0,1,3,1
1,3,1,0,0,0,0,0,0,0,0,0,1,3,1
1,3,1,0,0,0,0,0,0,0,0,0,1,3,1
1,3,1,0,0,0,0,0,0,0,0,0,1,3,1
1,3,1,0,0,0,0,0,0,0,0,0,1,3,1
1,3,1,0,0,0,0,0,0,0,0,0,1,3,1
1,3,1,0,0,0,0,12,0,0,0,0,1,3,1
1,3,1,0,0,0,0,0,0,0,0,0,1,3,1
1,3,1,0,0,0,0,0,0,0,0,0,1,3,1
1,3,1,1,1,1,1,1,1,1,1,1,1,3,1
1,3,3,3,3,3,3,3,3,3,3,3,3,3,1
1,1,1,1,1,1,1,1,1,1,1,1,1,1,1
endlayer

layer
1,1,1,1,1,1,1,1,1,1,1,1,1,1,1
1,3,3,3,3,3,3,3,3,3,3,3,3,3,1
1,3,1,1,1,1,1,1,1,1,1,1,1,3,1
1,3,1,1,1,1,1,1,1,1,1,1,1,3,1
1,3,1,1,1,1,1,26,1,1,1,1,1,3,1
1,3,1,1,1,0,0,0,0,0,1,1,1,3,1
1,3,1,1,1,0,0,0,0,0,1,1,1,3,1
1,3,1,1,27,0,0,0,0,0,28,1,1,3,1
1,3,1,1,1,0,0,0,0,0,1,1,1,3,1
1,3,1,1,1,0,0,0,0,0,1,1,1,3,1
1,3,1,1,1,1,1,12,1,1,1,1,1,3,1
1,3,1,1,1,1,1,1,1,1,1,1,1,3,1
1,3,1,1,1,1,1,1,1,1,1,1,1,3,1
1,3,3,3,3,3,3,3,3,3,3,3,3,3,1
1,1,1,1,1,1,1,1,1,1,1,1,1,1,1
endlayer

layer
0,0,0,0,0,0,0,0,0,0,0,0,0,0,0
0,0,0,0,0,0,0,0,0,0,0,0,0,0,0
0,0,1,1,1,0,0,0,0,0,1,1,1,0,0
0,0,1,0,0,0,0,0,0,0,0,0,1,0,0
0,0,1,0,0,0,0,0,0,0,0,0,1,0,0
0,0,0,0,0,0,0,0,0,0,0,0,0,0,0
0,0,0,0,0,0,0,0,0,0,0,0,0,0,0
0,0,0,0,0,0,0,0,0,0,0,0,0,0,0
0,0,0,0,0,0,0,0,0,0,0,0,0,0,0
0,0,0,0,0,0,0,0,0,0,0,0,0,0,0
0,0,1,0,0,0,0,0,0,0,0,0,1,0,0
0,0,1,0,0,0,0,0,0,0,0,0,1,0,0
0,0,1,1,1,0,0,0,0,0,1,1,1,0,0
0,0,0,0,0,0,0,0,0,0,0,0,0,0,0
0,0,0,0,0,0,0,0,0,0,0,0,0,0,0
endlayer

layer
0,0,0,0,0,0,0,0,0,0,0,0,0,0,0
0,0,0,0,0,0,0,0,0,0,0,0,0,0,0
0,0,20,1,1,0,0,0,0,0,1,1,20,0,0
0,0,1,0,0,0,0,0,0,0,0,0,1,0,0
0,0,1,0,0,0,0,0,0,0,0,0,1,0,0
0,0,0,0,0,0,0,0,0,0,0,0,0,0,0
0,0,0,0,0,0,0,0,0,0,0,0,0,0,0
0,0,0,0,0,0,0,0,0,0,0,0,0,0,0
0,0,0,0,0,0,0,0,0,0,0,0,0,0,0
0,0,0,0,0,0,0,0,0,0,0,0,0,0,0
0,0,1,0,0,0,0,0,0,0,0,0,1,0,0
0,0,1,0,0,0,0,0,0,0,0,0,1,0,0
0,0,20,1,1,0,0,0,0,0,1,1,20,0,0
0,0,0,0,0,0,0,0,0,0,0,0,0,0,0
0,0,0,0,0,0,0,0,0,0,0,0,0,0,0
endlayer

layer
0,0,0,0,0,0,0,0,0,0,0,0,0,0,0
0,0,0,0,0,0,0,0,0,0,0,0,0,0,0
0,0,20,1,1,0,0,0,0,0,1,1,20,0,0
0,0,1,1,0,0,0,0,0,0,0,1,1,0,0
0,0,1,0,0,0,0,0,0,0,0,0,1,0,0
0,0,0,0,0,0,0,0,0,0,0,0,0,0,0
0,0,0,0,0,0,0,0,0,0,0,0,0,0,0
0,0,0,0,0,0,0,20,0,0,0,0,0,0,0
0,0,0,0,0,0,0,0,0,0,0,0,0,0,0
0,0,0,0,0,0,0,0,0,0,0,0,0,0,0
0,0,1,0,0,0,0,0,0,0,0,0,1,0,0
0,0,1,1,0,0,0,0,0,0,0,1,1,0,0
0,0,20,1,1,0,0,0,0,0,1,1,20,0,0
0,0,0,0,0,0,0,0,0,0,0,0,0,0,0
0,0,0,0,0,0,0,0,0,0,0,0,0,0,0
endlayer

layer
0,0,0,0,0,0,0,0,0,0,0,0,0,0,0
0,0,19,0,0,0,0,0,0,0,0,0,19,0,0
0,15,29,16,1,0,0,0,0,0,1,15,29,16,0
0,0,14,1,0,0,0,0,0,0,0,1,14,0,0
0,0,1,0,0,0,0,0,0,0,0,0,1,0,0
0,0,0,0,0,0,0,20,0,0,0,0,0,0,0
0,0,0,0,0,0,20,20,20,0,0,0,0,0,0
0,0,0,0,0,20,20,31,20,20,0,0,0,0,0
0,0,0,0,0,0,20,20,20,0,0,0,0,0,0
0,0,0,0,0,0,0,20,0,0,0,0,0,0,0
0,0,1,0,0,0,0,0,0,0,0,0,1,0,0
0,0,19,1,0,0,0,0,0,0,0,1,19,0,0
0,15,29,16,1,0,0,0,0,0,1,15,29,16,0
0,0,14,0,0,0,0,0,0,0,0,0,14,0,0
0,0,0,0,0,0,0,0,0,0,0,0,0,0,0
endlayer

layer
0,0,0,0,0,0,0,0,0,0,0,0,0,0,0
0,20,20,20,0,0,0,0,0,0,0,20,20,20,0
0,20,30,20,1,1,0,0,0,1,1,20,30,20,0
0,20,20,1,1,0,0,0,0,0,1,1,20,20,0
0,0,1,1,0,0,0,0,0,0,0,1,1,0,0
0,0,1,0,0,0,0,25,0,0,0,0,1,0,0
0,0,0,0,0,0,0,20,0,0,0,0,0,0,0
0,0,0,0,0,25,20,20,20,25,0,0,0,0,0
0,0,0,0,0,0,0,20,0,0,0,0,0,0,0
0,0,1,0,0,0,0,25,0,0,0,0,1,0,0
0,0,1,1,0,0,0,0,0,0,0,1,1,0,0
0,20,20,1,1,0,0,0,0,0,1,1,20,20,0
0,20,30,20,1,1,0,0,0,1,1,20,30,20,0
0,20,20,20,0,0,0,0,0,0,0,20,20,20,0
0,0,0,0,0,0,0,0,0,0,0,0,0,0,0
endlayer

layer
0,0,0,0,0,0,0,0,0,0,0,0,0,0,0
0,0,0,0,0,0,0,0,0,0,0,0,0,0,0
0,0,0,0,0,1,1,0,1,1,0,0,0,0,0
0,0,0,0,1,1,0,0,0,1,1,0,0,0,0
0,0,0,1,1,0,0,0,0,0,1,1,0,0,0
0,0,1,1,0,0,0,0,0,0,0,1,1,0,0
0,0,1,0,0,0,0,25,0,0,0,0,1,0,0
0,0,0,0,0,0,25,20,25,0,0,0,0,0,0
0,0,1,0,0,0,0,25,0,0,0,0,1,0,0
0,0,1,1,0,0,0,0,0,0,0,1,1,0,0
0,0,0,1,1,0,0,0,0,0,1,1,0,0,0
0,0,0,0,1,1,0,0,0,1,1,0,0,0,0
0,0,0,0,0,1,1,0,1,1,0,0,0,0,0
0,0,0,0,0,0,0,0,0,0,0,0,0,0,0
0,0,0,0,0,0,0,0,0,0,0,0,0,0,0
endlayer

layer
0,0,0,0,0,0,0,0,0,0,0,0,0,0,0
0,0,0,0,0,0,0,0,0,0,0,0,0,0,0
0,0,0,0,0,0,1,1,1,0,0,0,0,0,0
0,0,0,0,0,1,1,1,1,1,0,0,0,0,0
0,0,0,0,1,1,0,0,0,1,1,0,0,0,0
0,0,0,1,1,0,0,0,0,0,1,1,0,0,0
0,0,1,1,0,0,0,0,0,0,0,1,1,0,0
0,0,1,1,0,0,0,20,0,0,0,1,1,0,0
0,0,1,1,0,0,0,0,0,0,0,1,1,0,0
0,0,0,1,1,0,0,0,0,0,1,1,0,0,0
0,0,0,0,1,1,0,0,0,1,1,0,0,0,0
0,0,0,0,0,1,1,1,1,1,0,0,0,0,0
0,0,0,0,0,0,1,1,1,0,0,0,0,0,0
0,0,0,0,0,0,0,0,0,0,0,0,0,0,0
0,0,0,0,0,0,0,0,0,0,0,0,0,0,0
endlayer

layer
0,0,0,0,0,0,0,0,0,0,0,0,0,0,0
0,0,0,0,0,0,0,0,0,0,0,0,0,0,0
0,0,0,0,0,0,0,0,0,0,0,0,0,0,0
0,0,0,0,0,0,1,1,1,0,0,0,0,0,0
0,0,0,0,0,1,1,1,1,1,0,0,0,0,0
0,0,0,0,1,1,1,1,1,1,1,0,0,0,0
0,0,0,1,1,1,0,0,0,1,1,1,0,0,0
0,0,0,1,1,1,0,20,0,1,1,1,0,0,0
0,0,0,1,1,1,0,0,0,1,1,1,0,0,0
0,0,0,0,1,1,1,1,1,1,1,0,0,0,0
0,0,0,0,0,1,1,1,1,1,0,0,0,0,0
0,0,0,0,0,0,1,1,1,0,0,0,0,0,0
0,0,0,0,0,0,0,0,0,0,0,0,0,0,0
0,0,0,0,0,0,0,0,0,0,0,0,0,0,0
0,0,0,0,0,0,0,0,0,0,0,0,0,0,0
endlayer

layer
0,0,0,0,0,0,0,0,0,0,0,0,0,0,0
0,0,0,0,0,0,0,0,0,0,0,0,0,0,0
0,0,0,0,0,0,0,0,0,0,0,0,0,0,0
0,0,0,0,0,0,0,0,0,0,0,0,0,0,0
0,0,0,0,0,0,0,0,0,0,0,0,0,0,0
0,0,0,0,0,0,1,1,1,0,0,0,0,0,0
0,0,0,0,0,1,1,1,1,1,0,0,0,0,0
0,0,0,0,0,1,1,1,1,1,0,0,0,0,0
0,0,0,0,0,1,1,1,1,1,0,0,0,0,0
0,0,0,0,0,0,1,1,1,0,0,0,0,0,0
0,0,0,0,0,0,0,0,0,0,0,0,0,0,0
0,0,0,0,0,0,0,0,0,0,0,0,0,0,0
0,0,0,0,0,0,0,0,0,0,0,0,0,0,0
0,0,0,0,0,0,0,0,0,0,0,0,0,0,0
0,0,0,0,0,0,0,0,0,0,0,0,0,0,0
endlayer

