
# NetherTower
# Created 10/8/2014 for MC 1.7.10
# Updated for MC 1.8: 22 Jul 2015
# Created by Ruins mod version 13.8 Ingame Parser
# authoring Player: Jordan_Greywolf

biomesToSpawnIn=badlands,boneyard,corrupted sands,deadlands,eerie,eldritch,hell,phantasmagoric inferno,spectral garden,tainted land,undergarden,visceral heap,volcano

weight=1
embed_into_distance=0

unacceptable_target_blocks=flowing_water,water,flowing_lava,lava,cloud,Natura:Cloud

dimensions=77,7,7
allowable_overhang=500
max_leveling=0
leveling_buffer=-1
preserve_water=0
preserve_lava=0
preserve_plants=1


rule1=0,100,preserveBlock

rule2=0,100,minecraft:nether_brick_fence-0
rule3=0,100,minecraft:netherrack-0
rule4=0,100,minecraft:fire-15
rule5=0,100,minecraft:nether_brick_stairs-5
rule6=0,100,minecraft:nether_brick_stairs-7
rule7=0,100,minecraft:nether_brick_stairs-6
rule8=0,100,minecraft:nether_brick_stairs-4
rule9=0,100,minecraft:nether_brick_stairs-0
rule10=0,100,minecraft:nether_brick-0
rule11=0,100,minecraft:stained_glass-14
rule12=0,100,minecraft:nether_brick_stairs-2
rule13=0,100,minecraft:nether_brick_stairs-3
rule14=0,100,minecraft:nether_brick_stairs-1
rule15=0,100,minecraft:iron_bars-0
rule16=0,100,minecraft:ladder-3
rule17=0,100,minecraft:stone_slab-6
rule18=1,100,minecraft:redstone_torch-5

# Base 1
layer
1,1,1,1,1,1,1
1,1,0,0,0,1,1
1,0,0,0,0,0,1
1,0,0,2,0,0,1
1,0,0,0,0,0,1
1,1,0,0,0,1,1
1,1,1,1,1,1,1
endlayer

# Base 2
layer
1,1,1,1,1,1,1
1,1,0,0,0,1,1
1,0,0,2,0,0,1
1,0,2,3,2,0,1
1,0,0,2,0,0,1
1,1,0,0,0,1,1
1,1,1,1,1,1,1
endlayer

# Base 3
layer
1,1,1,1,1,1,1
1,1,0,0,0,1,1
1,0,0,2,0,0,1
1,0,2,4,2,0,1
1,0,0,2,0,0,1
1,1,0,0,0,1,1
1,1,1,1,1,1,1
endlayer

# Base 4
layer
1,1,1,1,1,1,1
1,1,0,2,0,1,1
1,0,0,2,0,0,1
1,2,2,0,2,2,1
1,0,0,2,0,0,1
1,1,0,2,0,1,1
1,1,1,1,1,1,1
endlayer

# Base 5
layer
1,1,1,5,1,1,1
1,1,0,2,0,1,1
1,0,0,0,0,0,1
7,2,0,2,0,2,6
1,0,0,0,0,0,1
1,1,0,2,0,1,1
1,1,1,8,1,1,1
endlayer

# Base 6 (Bottom Floor)
layer
1,1,1,9,1,1,1
1,1,10,10,10,1,1
1,10,11,10,11,10,1
13,10,10,10,10,10,12
1,10,11,10,11,10,1
1,1,10,10,10,1,1
1,1,1,14,1,1,1
endlayer

# Base 7
layer
1,1,1,1,1,1,1
1,1,10,15,10,1,1
1,10,0,0,0,10,1
1,15,16,10,0,15,1
1,10,0,0,0,10,1
1,1,10,15,10,1,1
1,1,1,1,1,1,1
endlayer

# Base 8
layer
1,1,1,1,1,1,1
1,2,10,15,10,2,1
1,10,0,0,0,10,1
1,15,16,10,0,15,1
1,10,0,0,0,10,1
1,2,10,15,10,2,1
1,1,1,1,1,1,1
endlayer

# Repeating Segment 1 (floor & netherrack)
layer
1,8,8,8,8,8,1
6,3,10,10,10,3,7
6,10,17,17,17,10,7
6,10,16,10,17,10,7
6,10,17,17,17,10,7
6,3,10,10,10,3,7
1,5,5,5,5,5,1
endlayer

# Repeating Segment 2 (flames)
layer
2,2,2,2,2,2,2
2,4,10,15,10,4,2
2,10,0,0,0,10,2
2,15,16,10,0,15,2
2,10,0,0,0,10,2
2,4,10,15,10,4,2
2,2,2,2,2,2,2
endlayer

# Repeating Segment 3
layer
1,1,1,1,1,1,1
1,0,10,15,10,0,1
1,10,0,0,0,10,1
1,15,16,10,0,15,1
1,10,0,0,0,10,1
1,0,10,15,10,0,1
1,1,1,1,1,1,1
endlayer

# Repeating Segment 4
layer
1,1,1,1,1,1,1
1,0,10,15,10,0,1
1,10,0,0,0,10,1
1,15,16,10,0,15,1
1,10,0,0,0,10,1
1,0,10,15,10,0,1
1,1,1,1,1,1,1
endlayer

# Repeating Segment 5
layer
1,1,1,1,1,1,1
1,2,10,15,10,2,1
1,10,0,0,0,10,1
1,15,16,10,0,15,1
1,10,0,0,0,10,1
1,2,10,15,10,2,1
1,1,1,1,1,1,1
endlayer

# Repeating Segment 1 (floor & netherrack)
layer
1,8,8,8,8,8,1
6,3,10,10,10,3,7
6,10,17,17,17,10,7
6,10,16,10,17,10,7
6,10,17,17,17,10,7
6,3,10,10,10,3,7
1,5,5,5,5,5,1
endlayer

# Repeating Segment 2 (flames)
layer
2,2,2,2,2,2,2
2,4,10,15,10,4,2
2,10,0,0,0,10,2
2,15,16,10,0,15,2
2,10,0,0,0,10,2
2,4,10,15,10,4,2
2,2,2,2,2,2,2
endlayer

# Repeating Segment 3
layer
1,1,1,1,1,1,1
1,0,10,15,10,0,1
1,10,0,0,0,10,1
1,15,16,10,0,15,1
1,10,0,0,0,10,1
1,0,10,15,10,0,1
1,1,1,1,1,1,1
endlayer

# Repeating Segment 4
layer
1,1,1,1,1,1,1
1,0,10,15,10,0,1
1,10,0,0,0,10,1
1,15,16,10,0,15,1
1,10,0,0,0,10,1
1,0,10,15,10,0,1
1,1,1,1,1,1,1
endlayer

# Repeating Segment 5
layer
1,1,1,1,1,1,1
1,2,10,15,10,2,1
1,10,0,0,0,10,1
1,15,16,10,0,15,1
1,10,0,0,0,10,1
1,2,10,15,10,2,1
1,1,1,1,1,1,1
endlayer

# Repeating Segment 1 (floor & netherrack)
layer
1,8,8,8,8,8,1
6,3,10,10,10,3,7
6,10,17,17,17,10,7
6,10,16,10,17,10,7
6,10,17,17,17,10,7
6,3,10,10,10,3,7
1,5,5,5,5,5,1
endlayer

# Repeating Segment 2 (flames)
layer
2,2,2,2,2,2,2
2,4,10,15,10,4,2
2,10,0,0,0,10,2
2,15,16,10,0,15,2
2,10,0,0,0,10,2
2,4,10,15,10,4,2
2,2,2,2,2,2,2
endlayer

# Repeating Segment 3
layer
1,1,1,1,1,1,1
1,0,10,15,10,0,1
1,10,0,0,0,10,1
1,15,16,10,0,15,1
1,10,0,0,0,10,1
1,0,10,15,10,0,1
1,1,1,1,1,1,1
endlayer

# Repeating Segment 4
layer
1,1,1,1,1,1,1
1,0,10,15,10,0,1
1,10,0,0,0,10,1
1,15,16,10,0,15,1
1,10,0,0,0,10,1
1,0,10,15,10,0,1
1,1,1,1,1,1,1
endlayer

# Repeating Segment 5
layer
1,1,1,1,1,1,1
1,2,10,15,10,2,1
1,10,0,0,0,10,1
1,15,16,10,0,15,1
1,10,0,0,0,10,1
1,2,10,15,10,2,1
1,1,1,1,1,1,1
endlayer

# Repeating Segment 1 (floor & netherrack)
layer
1,8,8,8,8,8,1
6,3,10,10,10,3,7
6,10,17,17,17,10,7
6,10,16,10,17,10,7
6,10,17,17,17,10,7
6,3,10,10,10,3,7
1,5,5,5,5,5,1
endlayer

# Repeating Segment 2 (flames)
layer
2,2,2,2,2,2,2
2,4,10,15,10,4,2
2,10,0,0,0,10,2
2,15,16,10,0,15,2
2,10,0,0,0,10,2
2,4,10,15,10,4,2
2,2,2,2,2,2,2
endlayer

# Repeating Segment 3
layer
1,1,1,1,1,1,1
1,0,10,15,10,0,1
1,10,0,0,0,10,1
1,15,16,10,0,15,1
1,10,0,0,0,10,1
1,0,10,15,10,0,1
1,1,1,1,1,1,1
endlayer

# Repeating Segment 4
layer
1,1,1,1,1,1,1
1,0,10,15,10,0,1
1,10,0,0,0,10,1
1,15,16,10,0,15,1
1,10,0,0,0,10,1
1,0,10,15,10,0,1
1,1,1,1,1,1,1
endlayer

# Repeating Segment 5
layer
1,1,1,1,1,1,1
1,2,10,15,10,2,1
1,10,0,0,0,10,1
1,15,16,10,0,15,1
1,10,0,0,0,10,1
1,2,10,15,10,2,1
1,1,1,1,1,1,1
endlayer


# Repeating Segment 1 (floor & netherrack)
layer
1,8,8,8,8,8,1
6,3,10,10,10,3,7
6,10,17,17,17,10,7
6,10,16,10,17,10,7
6,10,17,17,17,10,7
6,3,10,10,10,3,7
1,5,5,5,5,5,1
endlayer

# Repeating Segment 2 (flames)
layer
2,2,2,2,2,2,2
2,4,10,15,10,4,2
2,10,0,0,0,10,2
2,15,16,10,0,15,2
2,10,0,0,0,10,2
2,4,10,15,10,4,2
2,2,2,2,2,2,2
endlayer

# Repeating Segment 3
layer
1,1,1,1,1,1,1
1,0,10,15,10,0,1
1,10,0,0,0,10,1
1,15,16,10,0,15,1
1,10,0,0,0,10,1
1,0,10,15,10,0,1
1,1,1,1,1,1,1
endlayer

# Repeating Segment 4
layer
1,1,1,1,1,1,1
1,0,10,15,10,0,1
1,10,0,0,0,10,1
1,15,16,10,0,15,1
1,10,0,0,0,10,1
1,0,10,15,10,0,1
1,1,1,1,1,1,1
endlayer

# Repeating Segment 5
layer
1,1,1,1,1,1,1
1,2,10,15,10,2,1
1,10,0,0,0,10,1
1,15,16,10,0,15,1
1,10,0,0,0,10,1
1,2,10,15,10,2,1
1,1,1,1,1,1,1
endlayer

# Repeating Segment 1 (floor & netherrack)
layer
1,8,8,8,8,8,1
6,3,10,10,10,3,7
6,10,17,17,17,10,7
6,10,16,10,17,10,7
6,10,17,17,17,10,7
6,3,10,10,10,3,7
1,5,5,5,5,5,1
endlayer

# Repeating Segment 2 (flames)
layer
2,2,2,2,2,2,2
2,4,10,15,10,4,2
2,10,0,0,0,10,2
2,15,16,10,0,15,2
2,10,0,0,0,10,2
2,4,10,15,10,4,2
2,2,2,2,2,2,2
endlayer

# Repeating Segment 3
layer
1,1,1,1,1,1,1
1,0,10,15,10,0,1
1,10,0,0,0,10,1
1,15,16,10,0,15,1
1,10,0,0,0,10,1
1,0,10,15,10,0,1
1,1,1,1,1,1,1
endlayer

# Repeating Segment 4
layer
1,1,1,1,1,1,1
1,0,10,15,10,0,1
1,10,0,0,0,10,1
1,15,16,10,0,15,1
1,10,0,0,0,10,1
1,0,10,15,10,0,1
1,1,1,1,1,1,1
endlayer

# Repeating Segment 5
layer
1,1,1,1,1,1,1
1,2,10,15,10,2,1
1,10,0,0,0,10,1
1,15,16,10,0,15,1
1,10,0,0,0,10,1
1,2,10,15,10,2,1
1,1,1,1,1,1,1
endlayer

# Repeating Segment 1 (floor & netherrack)
layer
1,8,8,8,8,8,1
6,3,10,10,10,3,7
6,10,17,17,17,10,7
6,10,16,10,17,10,7
6,10,17,17,17,10,7
6,3,10,10,10,3,7
1,5,5,5,5,5,1
endlayer

# Repeating Segment 2 (flames)
layer
2,2,2,2,2,2,2
2,4,10,15,10,4,2
2,10,0,0,0,10,2
2,15,16,10,0,15,2
2,10,0,0,0,10,2
2,4,10,15,10,4,2
2,2,2,2,2,2,2
endlayer

# Repeating Segment 3
layer
1,1,1,1,1,1,1
1,0,10,15,10,0,1
1,10,0,0,0,10,1
1,15,16,10,0,15,1
1,10,0,0,0,10,1
1,0,10,15,10,0,1
1,1,1,1,1,1,1
endlayer

# Repeating Segment 4
layer
1,1,1,1,1,1,1
1,0,10,15,10,0,1
1,10,0,0,0,10,1
1,15,16,10,0,15,1
1,10,0,0,0,10,1
1,0,10,15,10,0,1
1,1,1,1,1,1,1
endlayer

# Repeating Segment 5
layer
1,1,1,1,1,1,1
1,2,10,15,10,2,1
1,10,0,0,0,10,1
1,15,16,10,0,15,1
1,10,0,0,0,10,1
1,2,10,15,10,2,1
1,1,1,1,1,1,1
endlayer

# Repeating Segment 1 (floor & netherrack)
layer
1,8,8,8,8,8,1
6,3,10,10,10,3,7
6,10,17,17,17,10,7
6,10,16,10,17,10,7
6,10,17,17,17,10,7
6,3,10,10,10,3,7
1,5,5,5,5,5,1
endlayer

# Repeating Segment 2 (flames)
layer
2,2,2,2,2,2,2
2,4,10,15,10,4,2
2,10,0,0,0,10,2
2,15,16,10,0,15,2
2,10,0,0,0,10,2
2,4,10,15,10,4,2
2,2,2,2,2,2,2
endlayer

# Repeating Segment 3
layer
1,1,1,1,1,1,1
1,0,10,15,10,0,1
1,10,0,0,0,10,1
1,15,16,10,0,15,1
1,10,0,0,0,10,1
1,0,10,15,10,0,1
1,1,1,1,1,1,1
endlayer

# Repeating Segment 4
layer
1,1,1,1,1,1,1
1,0,10,15,10,0,1
1,10,0,0,0,10,1
1,15,16,10,0,15,1
1,10,0,0,0,10,1
1,0,10,15,10,0,1
1,1,1,1,1,1,1
endlayer

# Repeating Segment 5
layer
1,1,1,1,1,1,1
1,2,10,15,10,2,1
1,10,0,0,0,10,1
1,15,16,10,0,15,1
1,10,0,0,0,10,1
1,2,10,15,10,2,1
1,1,1,1,1,1,1
endlayer

# Repeating Segment 1 (floor & netherrack)
layer
1,8,8,8,8,8,1
6,3,10,10,10,3,7
6,10,17,17,17,10,7
6,10,16,10,17,10,7
6,10,17,17,17,10,7
6,3,10,10,10,3,7
1,5,5,5,5,5,1
endlayer

# Repeating Segment 2 (flames)
layer
2,2,2,2,2,2,2
2,4,10,15,10,4,2
2,10,0,0,0,10,2
2,15,16,10,0,15,2
2,10,0,0,0,10,2
2,4,10,15,10,4,2
2,2,2,2,2,2,2
endlayer

# Repeating Segment 3
layer
1,1,1,1,1,1,1
1,0,10,15,10,0,1
1,10,0,0,0,10,1
1,15,16,10,0,15,1
1,10,0,0,0,10,1
1,0,10,15,10,0,1
1,1,1,1,1,1,1
endlayer

# Repeating Segment 4
layer
1,1,1,1,1,1,1
1,0,10,15,10,0,1
1,10,0,0,0,10,1
1,15,16,10,0,15,1
1,10,0,0,0,10,1
1,0,10,15,10,0,1
1,1,1,1,1,1,1
endlayer

# Repeating Segment 5
layer
1,1,1,1,1,1,1
1,2,10,15,10,2,1
1,10,0,0,0,10,1
1,15,16,10,0,15,1
1,10,0,0,0,10,1
1,2,10,15,10,2,1
1,1,1,1,1,1,1
endlayer

# Repeating Segment 1 (floor & netherrack)
layer
1,8,8,8,8,8,1
6,3,10,10,10,3,7
6,10,17,17,17,10,7
6,10,16,10,17,10,7
6,10,17,17,17,10,7
6,3,10,10,10,3,7
1,5,5,5,5,5,1
endlayer

# Repeating Segment 2 (flames)
layer
2,2,2,2,2,2,2
2,4,10,15,10,4,2
2,10,0,0,0,10,2
2,15,16,10,0,15,2
2,10,0,0,0,10,2
2,4,10,15,10,4,2
2,2,2,2,2,2,2
endlayer

# Repeating Segment 3
layer
1,1,1,1,1,1,1
1,0,10,15,10,0,1
1,10,0,0,0,10,1
1,15,16,10,0,15,1
1,10,0,0,0,10,1
1,0,10,15,10,0,1
1,1,1,1,1,1,1
endlayer

# Repeating Segment 4
layer
1,1,1,1,1,1,1
1,0,10,15,10,0,1
1,10,0,0,0,10,1
1,15,16,10,0,15,1
1,10,0,0,0,10,1
1,0,10,15,10,0,1
1,1,1,1,1,1,1
endlayer

# Repeating Segment 5
layer
1,1,1,1,1,1,1
1,2,10,15,10,2,1
1,10,0,0,0,10,1
1,15,16,10,0,15,1
1,10,0,0,0,10,1
1,2,10,15,10,2,1
1,1,1,1,1,1,1
endlayer

# Repeating Segment 1 (floor & netherrack)
layer
1,8,8,8,8,8,1
6,3,10,10,10,3,7
6,10,17,17,17,10,7
6,10,16,10,17,10,7
6,10,17,17,17,10,7
6,3,10,10,10,3,7
1,5,5,5,5,5,1
endlayer

# Repeating Segment 2 (flames)
layer
2,2,2,2,2,2,2
2,4,10,15,10,4,2
2,10,0,0,0,10,2
2,15,16,10,0,15,2
2,10,0,0,0,10,2
2,4,10,15,10,4,2
2,2,2,2,2,2,2
endlayer

# Repeating Segment 3
layer
1,1,1,1,1,1,1
1,0,10,15,10,0,1
1,10,0,0,0,10,1
1,15,16,10,0,15,1
1,10,0,0,0,10,1
1,0,10,15,10,0,1
1,1,1,1,1,1,1
endlayer

# Repeating Segment 4
layer
1,1,1,1,1,1,1
1,0,10,15,10,0,1
1,10,0,0,0,10,1
1,15,16,10,0,15,1
1,10,0,0,0,10,1
1,0,10,15,10,0,1
1,1,1,1,1,1,1
endlayer

# Repeating Segment 5
layer
1,1,1,1,1,1,1
1,2,10,15,10,2,1
1,10,0,0,0,10,1
1,15,16,10,0,15,1
1,10,0,0,0,10,1
1,2,10,15,10,2,1
1,1,1,1,1,1,1
endlayer


# Limbo Level (-1)
layer
0,8,8,8,8,8,0
6,3,10,10,10,3,7
6,10,10,17,10,10,7
6,10,16,10,17,10,7
6,10,10,17,10,10,7
6,3,10,10,10,3,7
0,5,5,5,5,5,0
endlayer

# Top (+1)
layer
2,2,2,2,2,2,2
2,4,2,0,2,4,2
2,2,11,0,11,2,2
2,0,0,0,0,0,2
2,2,11,0,11,2,2
2,4,2,0,2,4,2
2,2,2,2,2,2,2
endlayer

# Top (+2)
layer
1,1,1,1,1,1,1
1,1,1,1,1,1,1
1,1,11,0,11,1,1
1,1,0,0,0,1,1
1,1,11,0,11,1,1
1,1,1,1,1,1,1
1,1,1,1,1,1,1
endlayer

# Top (+3)
layer
1,1,1,1,1,1,1
1,1,1,1,1,1,1
1,1,11,0,11,1,1
1,1,0,0,0,1,1
1,1,11,0,11,1,1
1,1,1,1,1,1,1
1,1,1,1,1,1,1
endlayer

# Top (+4)
layer
1,1,1,1,1,1,1
1,2,8,9,8,2,1
1,6,11,11,11,7,1
1,13,11,11,11,12,1
1,6,11,11,11,7,1
1,2,5,14,5,2,1
1,1,1,1,1,1,1
endlayer

# Top (+5)
layer
1,1,1,1,1,1,1
1,2,2,1,2,2,1
1,2,2,9,2,2,1
1,1,13,11,12,1,1
1,2,2,14,2,2,1
1,2,2,1,2,2,1
1,1,1,1,1,1,1
endlayer

# Top (+6)
layer
1,1,1,1,1,1,1
1,2,1,1,1,2,1
1,1,2,2,2,1,1
1,1,2,11,2,1,1
1,1,2,2,2,1,1
1,2,1,1,1,2,1
1,1,1,1,1,1,1
endlayer

# Top (+7)
layer
1,1,1,1,1,1,1
1,18,1,1,1,18,1
1,1,1,9,1,1,1
1,1,13,11,12,1,1
1,1,1,14,1,1,1
1,18,1,1,1,18,1
1,1,1,1,1,1,1
endlayer

# Top (+8)
layer
1,1,1,1,1,1,1
1,1,1,1,1,1,1
1,1,1,1,1,1,1
1,1,1,11,1,1,1
1,1,1,1,1,1,1
1,1,1,1,1,1,1
1,1,1,1,1,1,1
endlayer

# Top (+9)
layer
1,1,1,1,1,1,1
1,1,1,1,1,1,1
1,1,1,1,1,1,1
1,1,1,2,1,1,1
1,1,1,1,1,1,1
1,1,1,1,1,1,1
1,1,1,1,1,1,1
endlayer

# Top (+10)
layer
1,1,1,1,1,1,1
1,1,1,1,1,1,1
1,1,1,2,1,1,1
1,1,2,2,2,1,1
1,1,1,2,1,1,1
1,1,1,1,1,1,1
1,1,1,1,1,1,1
endlayer

# Top (+11)
layer
1,1,1,1,1,1,1
1,1,1,1,1,1,1
1,1,1,2,1,1,1
1,1,2,0,2,1,1
1,1,1,2,1,1,1
1,1,1,1,1,1,1
1,1,1,1,1,1,1
endlayer

# Top (+12)
layer
1,1,1,1,1,1,1
1,1,1,1,1,1,1
1,1,1,2,1,1,1
1,1,2,0,2,1,1
1,1,1,2,1,1,1
1,1,1,1,1,1,1
1,1,1,1,1,1,1
endlayer

# Top (+13)
layer
1,1,1,1,1,1,1
1,1,1,1,1,1,1
1,1,1,18,1,1,1
1,1,18,0,18,1,1
1,1,1,18,1,1,1
1,1,1,1,1,1,1
1,1,1,1,1,1,1
endlayer



