
# Shrine of Eeeeevil!  (Nether version)
# 26 Apr 2014; updated to MC 1.7.10, 10 Oct 2014
# Created by Ruins mod version 12.3 Ingame Parser
# authoring Player: Jordan_Greywolf

# Last Updated: 5 Feb 2016
# Updated to MC 1.8: 5 Mar 2016
# Updated to MC 1.9: 24 Apr 2016
# Updated to MC 1.12: 22 Jun 2017

biomesToSpawnIn=hell

uniqueMinDistance=1500

weight=1
#embed_into_distance=28
embed_into_distance=0


unacceptable_target_blocks=lava,flowing_lava,water,flowing_water,cloud,Natura:Cloud

dimensions=46,12,12
allowable_overhang=0
max_cut_in=0
cut_in_buffer=0
max_leveling=10
leveling_buffer=-1
preserve_water=0
preserve_lava=0
preserve_plants=1

rule1=0,100,minecraft:netherrack
rule2=0,100,minecraft:lava-0
rule3=0,100,minecraft:lava-2
rule4=0,100,minecraft:lava-10
rule5=0,100,minecraft:lava-4
rule6=0,100,minecraft:skull,minecraft:skull-1,minecraft:skull-2,minecraft:skull-3,minecraft:skull-4
rule7=0,100,minecraft:stone_brick_stairs-1

# Random Ore Treasure
rule8=0,100,minecraft:lapis_block,minecraft:emerald_ore,minecraft:iron_ore,minecraft:diamond_ore,minecraft:gold_ore,ChestGenHook:chests/simple_dungeon:3

rule9=0,100,minecraft:stone_brick_stairs-3
rule10=0,100,minecraft:glowstone-0
rule11=0,100,minecraft:glowstone-0
rule12=0,100,minecraft:bedrock-0
rule13=0,100,minecraft:stone_brick_stairs-0
rule14=0,100,MobSpawner:Blaze
rule15=0,100,minecraft:stonebrick-1,minecraft:stonebrick-0,minecraft:stonebrick-2
rule16=0,100,minecraft:nether_brick-0
rule17=0,100,minecraft:web-0
rule18=0,100,minecraft:bookshelf-0
rule19=0,100,minecraft:spruce_stairs-0
rule20=1,100,minecraft:redstone_torch-5
rule21=0,100,minecraft:spruce_stairs-3
rule22=0,100,minecraft:stone_slab-6
rule23=0,100,IInventory;minecraft:trapped_chest;minecraft:quartz#8#0#4-4,IInventory;minecraft:trapped_chest;minecraft:bedrock#4#0#2-4,IInventory;minecraft:trapped_chest;minecraft:experience_bottle#4#0#6-4,IInventory;minecraft:trapped_chest;minecraft:ender_pearl#1#0#3-4
rule24=0,100,minecraft:crafting_table-0
rule25=0,100,IInventory;minecraft:lit_furnace;minecraft:blaze_rod#4#0#1-4
rule26=0,100,minecraft:cauldron-0
rule27=0,100,minecraft:skull,minecraft:skull-1,minecraft:skull-2,minecraft:skull-3,minecraft:skull-4
rule28=0,100,minecraft:wooden_slab-5
rule29=1,100,minecraft:redstone_wire-0
rule30=0,100,minecraft:spruce_stairs-7
rule31=0,100,minecraft:spruce_stairs-6
rule32=0,100,minecraft:tripwire_hook-0

rule33=0,100,minecraft:tnt

rule34=2,100,minecraft:ladder-4
rule35=2,100,minecraft:ladder-2

# Sand (trap)
rule36=0,100,minecraft:sand

rule37=2,100,minecraft:ladder-3
rule38=2,100,minecraft:ladder-5
rule39=0,100,minecraft:redstone_block-0
rule40=0,100,minecraft:dirt-0
rule41=0,100,minecraft:redstone_wire-14
rule42=0,100,minecraft:redstone_wire-15
rule43=0,100,minecraft:soul_sand-0

# Terrain Blend
rule44=0,100,preserveBlock

rule45=0,100,minecraft:monster_egg-3
rule46=2,100,minecraft:trapdoor-11
rule47=1,100,minecraft:wooden_door-2
rule48=1,100,minecraft:wooden_door-3
rule49=1,100,minecraft:wooden_door-1
rule50=1,100,minecraft:wooden_door-0
rule51=1,100,minecraft:wooden_door-8
rule52=1,100,minecraft:wooden_door-9
rule53=0,100,minecraft:nether_brick_fence-0

# Dark Stained Glass
rule54=0,100,minecraft:stained_glass_pane-10,minecraft:stained_glass_pane-15

# Spruce Planks
rule55=0,100,minecraft:planks-1

# Light Stained Glass
rule56=0,100,minecraft:stained_glass_pane-14,minecraft:stained_glass_pane-1
rule57=0,100,minecraft:spruce_stairs-2
rule58=0,100,minecraft:cobblestone_wall-1

rule59=0,100,CommandBlock:RUINSTRIGGER /summon Bat ~0 ~0 ~0 {PersistenceRequired:1}:@

rule60=0,100,ChestGenHook:chests/simple_dungeon:5

rule61=0,100,MobSpawner:Zombie,MobSpawner:Skeleton,MobSpawner:Spider

rule62=0,100,CommandBlock:RUINSTRIGGER /summon Skeleton ~0 ~1 ~0 {HandItems:[{Count:1,id:iron_sword,tag:{display:{Name:"Sacrificial Dagger",Lore:["Wickedly curved and glowing red-hot."]},ench:[{id:20,lvl:2},{id:16,lvl:4}]}},{}],ArmorItems:[{Count:1,id:leather_boots,tag:{display:{color:3014656}}},{Count:1,id:leather_leggings,tag:{display:{color:5373952}}},{Count:1,id:leather_chestplate,tag:{display:{color:3145728}}},{Count:1,id:skull,Damage:3,tag:{SkullOwner:MHF_LavaSlime}}],CustomName:"Cultist of Eeevil",Attributes:[{Name:generic.movementSpeed,Base:0.3},{Name:generic.attackDamage,Base:3},{Name:generic.knockbackResistance,Base:1}],HandDropChances:[0.3F,0.0F],ArmorDropChances:[0.3F,0.3F,0.3F,0.0F],Silent:1,PersistenceRequired:1,Health:30.0f}:@


# ------------------------------------------------------

# -29
layer
1,1,1,1,1,1,1,1,1,1,1,1
1,1,1,1,1,1,2,2,2,1,1,1
1,1,1,1,2,2,3,2,3,2,1,1
1,1,1,2,2,3,3,2,2,3,2,1
1,1,2,3,3,2,2,2,3,3,2,1
1,2,3,3,2,2,1,3,2,2,3,1
1,2,2,2,1,1,1,1,2,2,3,1
1,2,2,2,3,2,1,1,3,3,2,1
1,1,2,2,3,3,3,3,2,2,1,1
1,1,1,2,3,2,4,2,2,2,1,1
1,1,1,1,2,2,2,2,2,1,1,1
1,1,1,1,1,1,1,1,1,1,1,1
endlayer

# -28
layer
1,1,1,1,1,1,1,1,1,1,1,1
1,1,1,4,3,1,0,0,0,1,1,1
1,1,4,3,5,0,0,0,0,0,1,1
1,0,3,5,0,0,0,0,0,0,0,1
1,0,5,0,0,0,0,0,0,0,0,1
1,0,0,0,0,0,6,1,0,0,0,1
1,0,0,0,6,1,1,7,0,0,0,1
1,0,0,0,0,0,60,0,0,0,0,1
1,1,3,0,0,0,0,0,0,0,6,1
1,1,2,3,0,0,4,4,0,0,1,1
1,1,1,1,0,0,1,0,4,1,1,1
1,1,1,1,1,1,1,1,1,1,1,1
endlayer

# -27
layer
1,1,1,1,1,1,1,1,1,1,1,1
1,1,2,3,0,8,1,0,0,6,1,1
1,0,3,0,0,1,0,0,0,0,6,1
1,0,0,0,0,1,0,0,0,0,0,1
1,0,0,0,0,1,0,0,0,0,0,1
1,0,0,0,0,1,1,7,0,0,0,1
1,0,0,0,0,1,1,0,0,0,0,1
1,0,0,0,0,0,0,0,0,0,0,1
1,6,0,0,0,0,0,0,0,0,0,1
1,1,0,0,0,0,4,4,0,0,1,1
1,1,1,6,0,1,1,1,4,6,1,1
1,1,1,1,1,1,1,1,1,1,1,1
endlayer

# -26
layer
1,1,1,1,1,1,1,1,1,1,1,1
1,6,0,0,0,7,1,1,0,0,0,1
1,0,0,0,0,14,0,0,0,0,0,1
1,0,0,0,0,0,0,0,0,0,0,1
1,0,0,0,0,0,0,0,0,0,0,1
1,0,0,0,0,0,0,0,0,0,0,1
1,0,0,0,0,6,1,0,0,0,0,1
1,0,0,0,0,0,0,0,0,0,0,1
1,0,0,0,0,0,0,0,0,0,0,1
1,6,0,0,0,0,3,4,0,0,6,1
1,1,6,0,0,1,2,1,4,0,1,1
1,1,1,1,1,1,1,1,1,1,1,1
endlayer

# -25
layer
1,1,1,1,1,1,1,1,1,1,1,1
1,0,0,0,0,0,9,1,1,1,0,1
1,0,0,0,0,0,0,0,0,0,0,1
1,0,0,0,0,0,0,0,0,0,0,1
1,1,0,0,0,0,0,0,0,0,1,1
1,0,0,0,0,0,0,0,0,0,0,1
1,0,0,0,0,0,1,0,0,0,0,1
1,0,0,0,0,0,0,0,0,0,1,1
1,0,0,0,0,0,0,0,0,0,0,1
1,0,0,0,0,0,0,4,0,0,0,1
1,1,0,0,0,1,1,1,4,0,1,1
1,1,1,1,1,1,1,1,1,1,1,1
endlayer

# -24
layer
1,1,1,1,1,1,1,1,1,1,1,1
1,0,0,0,0,0,0,0,9,1,0,1
1,0,0,0,0,0,0,0,0,1,0,1
1,0,0,0,0,0,0,0,0,1,0,1
1,1,1,1,1,1,1,0,1,1,1,1
1,0,0,0,0,1,1,1,1,0,0,1
1,0,0,0,1,1,1,1,1,0,0,1
1,0,0,0,0,1,1,1,0,0,1,1
1,10,0,0,0,0,1,0,0,0,0,1
1,1,1,0,0,0,0,3,0,0,0,1
1,1,1,1,1,6,1,2,3,0,0,11
1,1,1,1,1,1,1,1,1,1,1,1
endlayer

# -23
layer
1,1,1,1,1,1,1,1,1,1,1,1
1,1,0,0,0,0,0,0,0,0,1,1
1,0,0,0,0,0,0,0,0,0,0,1
1,0,0,0,0,0,0,0,0,0,0,1
1,1,1,0,0,0,0,0,0,0,6,1
1,10,0,0,0,0,12,0,0,0,0,1
1,0,0,0,0,6,0,0,6,0,1,1
1,0,0,0,0,0,0,0,0,0,1,1
1,1,0,0,0,0,13,0,0,0,1,1
1,1,0,0,0,0,1,0,0,0,0,1
1,0,0,6,0,0,8,0,0,0,0,1
1,14,1,1,1,1,1,1,1,1,1,1
endlayer

# -22
layer
1,1,1,1,1,1,1,1,1,1,1,1
1,1,0,0,0,1,1,0,0,0,1,1
1,1,0,0,0,0,1,0,0,0,0,1
1,0,0,0,0,0,0,0,0,0,0,1
1,1,6,0,0,0,0,0,0,0,0,1
1,1,0,0,0,0,12,0,0,0,0,1
1,0,0,0,0,0,0,0,0,0,6,1
1,1,0,0,0,0,0,0,0,0,1,1
1,1,0,0,0,0,0,0,0,0,6,1
1,0,0,0,0,0,13,0,0,0,0,1
1,0,0,0,0,0,1,10,0,0,0,1
1,1,1,1,1,1,1,1,1,1,1,1
endlayer

# -21
layer
1,1,1,1,1,1,11,1,1,1,1,1
1,1,10,0,0,6,0,0,0,10,1,1
1,1,0,0,0,0,6,0,0,0,0,1
1,0,0,0,0,0,0,0,0,0,0,1
1,0,0,0,0,0,0,0,0,0,0,1
1,1,0,0,0,0,12,0,0,0,0,1
1,1,0,0,0,0,0,10,0,0,0,1
1,1,1,0,0,0,0,0,0,0,0,1
1,0,0,0,0,0,0,0,0,0,0,1
1,0,0,0,0,0,0,0,0,0,0,1
1,0,0,10,0,0,13,1,0,0,10,1
1,1,1,1,1,1,1,1,1,1,1,1
endlayer

# -20
layer
1,1,1,1,1,1,1,1,1,1,1,1
1,1,1,0,10,1,0,0,0,1,1,1
1,1,0,0,0,0,0,0,0,10,1,1
1,10,0,0,0,0,0,0,0,0,10,1
1,0,0,0,10,0,0,0,0,0,0,1
1,0,0,0,0,0,12,10,0,0,0,1
1,0,0,0,0,0,0,1,0,0,10,1
8,0,1,10,0,0,0,0,0,0,0,1
1,0,0,0,0,0,0,0,0,0,1,1
1,0,0,10,0,0,0,0,0,1,1,1
1,0,10,1,10,0,0,9,1,1,1,1
1,1,1,1,1,1,1,1,1,1,1,1
endlayer

# -19
layer
1,1,1,1,1,1,1,1,1,1,1,1
1,1,1,1,1,1,0,1,1,1,1,1
1,1,1,0,0,1,0,0,0,1,1,1
1,1,0,0,0,0,0,10,0,0,1,1
1,0,0,0,1,0,0,0,0,0,0,1
1,0,10,0,0,0,12,1,0,0,0,1
1,0,0,0,0,0,1,1,10,0,1,1
1,0,1,1,0,0,0,1,0,0,1,1
1,0,0,0,0,10,0,0,0,1,7,1
1,0,0,1,0,0,0,0,1,1,0,1
1,0,1,1,1,0,0,0,0,0,0,1
1,1,1,1,1,1,1,1,1,1,1,1
endlayer

# -18
layer
1,1,1,1,1,1,1,1,1,1,1,1
1,1,1,1,1,1,1,1,1,1,1,1
1,1,1,1,1,1,10,1,1,1,1,1
1,1,1,1,1,1,1,1,1,1,1,1
1,1,1,1,1,1,1,1,10,10,1,1
1,1,1,1,10,10,1,1,1,10,1,1
1,1,1,1,1,10,1,1,1,1,1,1
1,1,1,1,1,1,1,1,1,1,7,1
1,1,1,1,1,1,1,1,1,1,0,1
1,1,1,1,1,1,1,1,1,1,0,1
1,1,1,1,1,1,0,0,0,0,0,1
1,1,1,1,1,1,1,1,1,1,1,1
endlayer

# -17
layer
15,15,15,15,15,15,15,15,15,15,15,15
15,16,16,16,16,16,16,16,16,16,16,15
15,16,16,16,16,16,16,16,16,16,16,15
15,16,16,16,16,16,16,16,16,16,16,15
15,16,16,16,16,16,16,16,16,16,16,15
15,16,16,16,16,16,16,16,16,16,16,15
15,16,16,16,16,16,16,16,16,16,7,15
15,16,16,16,16,16,16,16,16,16,0,15
15,16,16,16,16,16,16,16,16,16,0,15
15,16,16,16,16,16,16,16,16,16,0,15
15,16,16,16,16,16,16,16,16,16,0,15
15,15,15,15,15,15,15,15,15,15,15,15
endlayer

# -16
layer
15,15,15,15,15,15,15,8,8,15,15,15
15,18,18,18,15,61,17,0,0,17,61,15
15,17,19,17,15,17,0,0,0,0,17,15
15,0,0,0,15,0,0,0,0,0,0,15
15,17,0,0,15,0,0,0,0,0,17,15
15,61,17,0,15,20,0,0,0,0,17,15
15,16,0,0,15,15,17,15,15,15,17,15
15,16,0,0,0,0,0,0,21,15,17,15
15,16,0,0,15,0,0,0,21,15,0,15
15,22,0,0,15,0,0,0,0,15,0,15
15,0,0,0,15,26,25,24,23,15,0,15
15,15,15,15,15,15,15,15,15,15,15,15
endlayer

# -15
layer
15,15,18,15,15,15,15,15,15,15,15,15
15,18,20,18,15,17,0,0,0,0,17,15
15,17,27,17,15,0,0,0,0,0,0,15
15,0,0,0,15,0,0,0,0,0,0,15
15,0,0,0,15,0,0,0,0,0,17,15
15,16,17,0,15,17,0,0,0,0,17,15
15,16,0,0,15,15,17,15,15,15,17,15
15,22,0,0,0,0,0,0,0,15,17,15
15,0,0,0,15,0,0,0,0,15,17,15
15,0,0,0,15,0,0,0,0,15,17,15
15,17,0,17,15,17,20,0,17,15,17,15
15,15,15,15,15,15,15,15,15,15,15,15
endlayer

# -14
layer
15,15,15,15,15,15,15,15,15,15,15,15
15,16,16,16,16,16,16,16,16,16,16,15
15,16,16,16,16,16,16,16,16,16,16,15
15,16,16,16,16,16,16,16,16,16,16,15
15,16,16,16,16,16,16,16,16,16,16,15
15,22,16,16,16,16,16,16,16,16,16,15
15,0,16,16,16,16,16,16,16,16,16,15
15,0,16,16,16,16,16,16,16,16,16,15
15,0,16,16,16,16,16,16,16,16,16,15
15,0,16,16,16,16,16,16,16,16,16,15
15,17,16,16,16,16,16,16,16,16,16,15
15,15,15,15,15,15,15,15,15,15,15,15
endlayer

# -13
layer
15,15,15,15,15,15,15,15,15,15,15,15
15,8,8,15,16,22,15,16,28,0,27,15
15,17,17,15,16,0,15,16,15,0,0,15
15,0,15,15,16,0,15,0,15,0,0,15
15,0,0,15,61,0,15,0,15,0,0,15
15,0,0,15,15,0,15,15,15,0,15,15
15,0,0,0,0,0,15,29,0,0,0,15
15,0,15,15,15,15,15,0,0,0,0,15
15,0,15,8,0,20,15,0,0,0,27,15
15,0,15,61,0,0,0,0,0,0,0,15
15,0,15,8,0,0,15,24,31,30,20,15
15,15,15,15,15,15,15,15,15,15,15,15
endlayer

# -12
layer
15,15,15,15,15,15,15,15,15,15,15,15
15,17,17,15,0,0,15,0,0,0,17,15
15,17,17,15,22,0,15,22,15,0,0,15
15,17,15,15,16,0,15,16,15,0,0,15
15,0,0,15,16,0,15,16,15,0,0,15
15,0,0,15,15,0,15,15,15,0,15,15
15,0,0,0,0,0,15,0,0,0,0,15
15,0,15,15,15,15,15,0,0,0,0,15
15,0,15,0,0,0,15,0,0,0,32,15
15,0,15,0,0,0,0,0,0,0,32,15
15,0,15,0,0,0,15,0,29,27,0,15
15,15,15,15,15,15,15,15,15,15,15,15
endlayer

# -11
layer
15,15,15,15,15,15,15,15,15,15,15,15
15,16,16,16,0,0,15,0,0,0,16,15
15,16,16,16,0,0,15,0,16,16,16,15
15,16,16,16,0,16,16,0,16,16,16,15
15,16,16,16,22,16,16,22,16,16,16,15
15,16,16,16,16,16,16,16,16,16,16,15
15,16,16,16,16,16,16,16,16,16,16,15
15,16,16,16,16,16,16,16,16,16,16,15
15,16,16,16,16,16,16,16,16,16,16,15
15,16,16,16,16,16,16,16,16,16,16,15
15,16,16,16,16,16,16,16,16,16,16,15
15,15,15,15,15,15,15,15,15,15,15,15
endlayer

# -10
layer
15,15,15,15,15,15,15,15,15,15,15,15
15,15,15,0,0,15,15,0,17,15,15,15
15,0,0,0,0,15,15,0,0,0,0,15
15,15,15,0,0,15,15,0,20,15,15,15
15,0,0,0,0,15,15,0,0,0,0,15
15,15,15,0,0,15,15,0,0,15,15,15
15,0,0,0,0,15,15,0,0,0,0,15
15,15,15,0,0,15,15,0,0,15,15,15
15,0,0,0,0,15,15,0,0,0,0,15
15,27,15,0,0,15,15,0,0,15,27,15
15,61,16,16,22,15,15,22,16,16,61,15
15,15,15,15,15,15,15,15,15,15,15,15
endlayer

# -9
layer
15,15,15,15,15,15,15,15,15,15,15,15
15,15,15,0,0,15,15,17,17,15,15,15
15,0,0,0,0,33,33,0,0,0,0,15
15,15,15,0,0,33,33,0,0,15,15,15
15,0,0,0,0,33,33,0,0,0,0,15
15,15,15,0,0,33,33,0,0,15,15,15
15,0,0,0,0,33,33,0,0,0,0,15
15,15,15,0,0,33,33,0,0,15,15,15
15,0,0,0,0,33,33,0,0,17,0,15
15,15,15,0,0,33,33,0,0,15,15,15
15,16,22,0,0,15,15,17,0,22,16,15
15,15,15,15,15,15,15,15,15,15,15,15
endlayer

# -8
layer
15,15,15,15,15,15,15,15,15,15,15,15
15,16,16,16,16,16,16,16,16,16,16,15
15,16,16,16,16,16,16,16,16,16,16,15
15,16,16,16,16,16,16,16,16,16,16,15
15,16,16,16,16,16,16,16,16,16,16,15
15,16,16,16,16,16,16,16,16,16,16,15
15,16,16,16,16,16,16,16,16,16,16,15
15,16,16,16,16,16,16,16,16,16,16,15
15,16,16,16,16,16,16,16,16,16,16,15
15,22,16,16,0,16,16,0,16,16,22,15
15,0,0,0,0,16,16,0,0,0,0,15
15,15,15,15,15,15,15,15,15,15,15,15
endlayer

# -7
layer
15,15,15,15,15,15,15,15,15,15,15,15
15,0,0,0,0,0,0,0,0,0,0,15
15,0,22,0,0,0,0,0,0,22,0,15
15,0,16,0,0,0,0,0,0,16,0,15
15,0,16,0,0,0,0,0,0,16,0,15
15,17,16,0,0,23,23,0,0,16,17,15
15,17,61,0,0,8,8,0,0,61,17,15
15,17,17,0,0,8,8,0,0,17,17,15
15,0,0,0,0,0,0,0,0,0,0,15
15,62,62,62,62,0,0,0,0,0,0,15
15,0,0,0,0,0,0,17,0,0,0,15
15,15,15,15,15,15,15,15,15,15,15,15
endlayer

# -6
layer
15,15,15,15,15,15,15,15,15,15,15,15
15,17,0,0,0,0,0,0,0,0,17,15
15,0,0,0,0,0,0,0,0,0,0,15
15,0,0,0,0,0,0,0,0,0,0,15
15,0,22,0,0,0,0,0,0,22,0,15
15,0,16,0,0,34,34,0,0,16,0,15
15,0,16,0,37,36,36,35,0,16,0,15
15,0,16,0,37,36,36,35,0,16,0,15
15,0,0,0,0,38,38,0,0,0,0,15
15,0,0,0,0,0,0,0,0,0,0,15
15,17,0,0,0,0,0,0,0,0,17,15
15,15,15,15,15,15,15,15,15,15,15,15
endlayer

# -5
layer
15,15,15,15,15,15,15,15,15,15,15,15
15,17,17,17,17,17,17,17,17,17,17,15
15,17,0,0,0,0,0,0,0,0,17,15
15,17,0,0,0,0,0,0,0,0,17,15
15,17,0,0,0,0,0,0,0,0,17,15
15,17,0,0,0,36,36,0,0,0,17,15
15,0,22,0,36,2,2,36,0,22,17,15
15,17,16,0,36,2,2,36,0,16,17,15
15,17,16,0,0,36,36,0,0,16,17,15
15,17,0,0,0,0,0,0,0,16,17,15
15,17,17,17,17,17,17,17,17,17,17,15
15,15,15,15,15,15,15,15,15,15,15,15
endlayer

# -4
layer
15,15,15,15,15,15,15,15,15,15,15,15
15,16,16,16,16,16,16,16,16,16,16,15
15,16,16,16,16,16,16,16,16,16,16,15
15,16,0,16,16,16,16,16,16,0,16,15
15,16,0,16,16,16,16,16,16,0,16,15
15,16,0,16,16,16,16,16,16,0,16,15
15,16,0,16,16,39,39,16,16,0,16,15
15,16,0,16,16,39,39,16,16,0,16,15
15,16,22,16,16,16,16,16,16,22,16,15
15,16,16,16,16,16,16,16,16,16,16,15
15,16,16,16,16,16,16,16,16,16,16,15
15,15,15,15,15,15,15,15,15,15,15,15
endlayer

# -3
layer
40,15,15,40,40,40,40,40,40,15,15,40
15,38,0,15,15,15,15,15,15,0,38,15
15,0,0,0,0,0,0,0,0,62,0,15
40,15,0,0,0,0,0,0,0,0,15,40
40,15,0,0,62,41,41,0,0,0,15,40
40,15,0,0,20,42,42,20,0,0,15,40
40,15,0,41,42,27,27,42,41,0,15,40
40,15,0,41,42,27,27,42,41,0,15,40
40,15,0,0,20,42,42,20,0,0,15,40
15,0,62,0,0,41,41,0,62,0,0,15
15,0,0,15,15,0,0,15,15,0,0,15
40,15,15,40,40,15,15,40,40,15,15,40
endlayer

# -2
layer
43,15,15,43,43,43,43,43,43,15,15,43
15,38,0,15,15,15,15,15,15,0,38,15
15,17,0,0,17,17,17,17,0,0,17,15
43,15,0,0,0,0,0,0,0,0,15,43
43,15,0,0,0,0,0,0,0,0,15,43
43,15,0,0,0,0,59,0,0,0,15,43
43,15,0,0,0,0,0,59,0,0,15,43
43,15,0,0,0,0,0,0,0,0,15,43
43,15,0,0,0,0,0,0,0,0,15,43
15,17,0,0,0,0,0,0,0,0,17,15
15,17,17,15,15,0,0,15,15,17,17,15
43,15,15,43,43,15,15,43,43,15,15,43
endlayer

# Base (-1)
layer
44,45,45,44,44,0,0,44,44,45,45,44
45,38,16,45,45,45,45,45,45,16,38,45
45,16,16,16,16,16,16,16,16,16,16,45
44,45,16,16,16,16,16,16,16,16,45,44
44,45,16,16,16,46,46,16,16,16,45,44
0,45,16,16,16,16,16,16,16,16,45,0
0,45,16,16,16,16,16,16,16,16,45,0
44,45,16,16,16,16,16,16,16,16,45,44
44,45,16,16,16,16,16,16,16,16,45,44
45,16,16,16,16,16,16,16,16,16,16,45
45,16,16,45,45,16,16,45,45,16,16,45
44,45,45,44,44,22,22,44,44,45,45,44
endlayer

layer
44,45,45,44,0,0,0,0,44,45,45,44
45,38,47,45,45,45,45,45,45,47,38,45
45,49,0,16,16,16,16,16,16,0,48,45
44,45,0,16,20,31,30,20,16,0,45,44
0,45,0,0,0,0,62,0,0,0,45,0
0,45,0,59,59,0,0,59,59,0,45,0
0,45,0,19,19,0,0,19,19,0,45,0
0,45,62,0,0,0,0,0,62,0,45,0
44,15,0,19,19,0,0,19,19,0,45,44
45,49,0,0,0,0,62,0,0,0,48,45
45,34,50,45,45,47,47,45,45,50,34,45
44,45,45,44,0,0,0,0,44,45,45,44
endlayer

layer
44,15,15,0,0,0,0,0,0,15,15,44
15,38,52,15,15,15,15,15,15,51,38,15
15,51,0,20,53,20,53,20,20,0,52,15
0,15,0,53,0,27,29,0,53,0,15,0
0,54,0,0,0,0,0,0,0,0,54,0
0,54,0,0,0,0,0,0,0,0,54,0
0,54,0,0,0,0,0,27,0,0,54,0
0,54,0,0,0,0,0,0,0,0,54,0
0,15,0,27,0,0,0,0,0,0,15,0
15,52,0,0,0,0,0,0,0,0,51,15
15,34,51,15,15,51,52,15,15,52,34,15
44,15,15,0,53,0,0,53,0,15,15,44
endlayer

layer
0,15,15,0,0,0,0,0,0,15,15,0
15,38,0,15,54,54,54,54,15,17,38,15
15,0,15,0,20,0,20,0,0,15,0,15
0,15,53,20,0,0,0,0,20,53,15,0
0,54,0,0,0,0,0,0,0,0,54,0
0,54,0,0,0,0,0,0,0,0,54,0
0,54,0,0,0,0,0,0,0,0,54,0
0,54,0,0,0,0,0,0,0,0,54,0
0,15,0,0,0,0,0,0,0,0,15,0
15,0,15,53,0,0,0,0,53,15,0,15
15,34,0,15,15,15,15,15,15,0,34,15
0,15,15,0,20,0,0,20,0,15,15,0
endlayer

layer
0,15,15,0,0,0,0,0,0,15,15,0
15,38,0,15,54,54,54,54,15,0,38,15
15,0,15,0,0,0,0,0,0,15,0,15
55,15,20,0,0,0,0,0,0,20,15,55
55,15,0,0,0,0,0,0,0,0,15,55
55,15,0,0,0,0,0,0,0,0,15,55
55,15,0,0,0,0,0,0,0,0,15,55
55,15,0,0,0,0,0,0,0,0,15,55
55,15,0,0,0,0,0,0,0,0,15,55
15,0,15,20,0,0,0,0,20,15,0,15
15,34,0,15,15,15,15,15,15,0,34,15
0,15,15,0,0,0,0,0,0,15,15,0
endlayer

layer
0,15,15,0,0,0,0,0,0,15,15,0
15,38,0,15,54,56,56,54,15,17,38,15
15,0,15,0,0,0,0,0,0,15,17,15
21,15,0,0,0,0,0,0,0,0,15,57
21,55,0,0,0,0,0,0,0,0,55,57
21,55,0,0,0,0,0,0,0,0,55,57
21,55,0,0,0,0,0,0,0,0,55,57
21,55,0,0,0,0,0,0,0,0,55,57
21,15,0,0,0,0,0,0,0,0,15,57
15,0,15,0,0,0,0,0,0,15,0,15
15,34,0,15,15,54,54,15,15,0,34,15
0,15,15,0,0,0,0,0,0,15,15,0
endlayer

layer
0,15,15,0,0,0,0,0,0,15,15,0
15,38,16,15,54,56,56,54,15,16,38,15
15,16,15,0,0,0,0,0,0,15,16,15
0,15,55,0,0,0,0,0,0,55,15,0
0,21,55,0,0,53,53,0,0,55,57,0
0,21,55,0,53,53,53,53,0,55,57,0
0,21,55,0,53,53,53,53,0,55,57,0
0,21,55,0,0,53,53,0,0,55,57,0
0,15,55,0,0,0,0,0,0,55,15,0
15,16,15,0,0,0,0,0,0,15,16,15
15,34,16,15,54,56,56,54,15,16,34,15
0,15,15,0,0,0,0,0,0,15,15,0
endlayer

layer
0,15,15,0,0,0,0,0,0,15,15,0
15,38,0,15,15,54,54,15,15,0,38,15
15,0,15,0,0,0,0,0,0,15,0,15
0,15,55,0,0,0,0,0,0,55,15,0
0,0,55,0,0,20,20,0,0,55,0,0
0,0,55,0,20,53,53,20,0,55,0,0
0,0,55,0,20,53,53,20,0,55,0,0
0,0,55,0,0,20,20,0,0,55,0,0
0,15,55,0,0,0,0,0,0,55,15,0
15,0,15,0,0,0,0,0,0,15,0,15
15,34,0,15,54,56,56,54,15,0,34,15
0,15,15,0,0,0,0,0,0,15,15,0
endlayer

layer
0,15,0,15,0,0,0,0,15,0,15,0
15,38,0,15,15,54,54,15,15,0,38,15
15,0,15,55,0,0,0,0,55,15,0,15
0,15,21,55,0,0,0,0,55,57,15,0
0,0,21,55,0,0,0,0,55,57,0,0
0,0,21,55,0,53,53,0,55,57,0,0
0,0,21,55,0,53,53,0,55,57,0,0
0,0,21,55,0,0,0,0,55,57,0,0
0,15,21,55,0,0,0,0,55,57,15,0
15,35,15,55,0,0,0,0,55,15,0,15
15,34,0,55,15,54,54,15,55,0,34,15
0,15,0,55,0,0,0,0,55,0,15,0
endlayer

layer
0,15,15,15,0,0,0,0,15,15,15,0
15,38,0,15,15,15,15,15,15,0,38,15
15,0,15,55,0,0,0,0,55,15,0,15
0,15,0,55,0,0,0,0,55,0,15,0
0,0,0,55,0,0,0,0,55,0,0,0
0,0,0,55,0,53,53,0,55,0,0,0
0,0,0,55,0,53,53,0,55,0,0,0
0,0,0,55,0,0,0,0,55,0,0,0
0,15,0,55,0,0,0,0,55,0,15,0
15,35,15,55,0,0,0,0,55,15,0,15
15,34,0,55,15,15,15,15,55,0,34,15
0,15,15,55,0,0,0,0,55,15,15,0
endlayer

layer
0,15,58,21,55,0,0,55,57,58,15,0
15,0,15,21,55,15,15,55,57,15,0,15
58,15,15,21,55,0,0,55,57,15,15,58
0,58,0,21,55,0,0,55,57,0,58,0
0,0,0,21,55,0,0,55,57,0,0,0
0,0,0,21,55,53,53,55,57,0,0,0
0,0,0,21,55,53,53,55,57,0,0,0
0,0,0,21,55,0,0,55,57,0,0,0
0,58,0,21,55,0,0,55,57,0,58,0
58,15,15,21,55,0,0,55,57,15,15,58
15,0,15,21,55,15,15,55,57,15,0,15
0,15,58,21,55,0,0,55,57,58,15,0
endlayer

layer
0,15,0,0,55,0,0,55,0,0,15,0
15,15,15,0,55,15,15,55,0,15,15,15
0,15,58,0,55,0,0,55,0,58,15,0
0,0,0,0,55,0,0,55,0,0,0,0
0,0,0,0,55,0,0,55,0,0,0,0
0,0,0,0,55,53,53,55,0,0,0,0
0,0,0,0,55,53,53,55,0,0,0,0
0,0,0,0,55,0,0,55,0,0,0,0
0,0,0,0,55,0,0,55,0,0,0,0
0,15,58,0,55,0,0,55,0,58,15,0
15,15,15,0,55,15,15,55,0,15,15,15
0,15,0,0,55,0,0,55,0,0,15,0
endlayer

layer
0,58,0,0,21,55,55,57,0,0,58,0
58,15,58,0,21,55,55,57,0,58,15,58
0,58,0,0,21,55,55,57,0,0,58,0
0,0,0,0,21,55,55,57,0,0,0,0
0,0,0,0,21,55,55,57,0,0,0,0
0,0,0,0,21,55,55,57,0,0,0,0
0,0,0,0,21,55,55,57,0,0,0,0
0,0,0,0,21,55,55,57,0,0,0,0
0,0,0,0,21,55,55,57,0,0,0,0
0,58,0,0,21,55,55,57,0,0,58,0
58,15,58,0,21,55,55,57,0,58,15,58
0,58,0,0,21,55,55,57,0,0,58,0
endlayer

layer
0,0,0,0,0,21,57,0,0,0,0,0
0,15,0,0,0,21,57,0,0,0,15,0
0,0,0,0,0,21,57,0,0,0,0,0
0,0,0,0,0,21,57,0,0,0,0,0
0,0,0,0,0,21,57,0,0,0,0,0
0,0,0,0,0,21,57,0,0,0,0,0
0,0,0,0,0,21,57,0,0,0,0,0
0,0,0,0,0,21,57,0,0,0,0,0
0,0,0,0,0,21,57,0,0,0,0,0
0,0,0,0,0,21,57,0,0,0,0,0
0,15,0,0,0,21,57,0,0,0,15,0
0,0,0,0,0,21,57,0,0,0,0,0
endlayer

layer
0,0,0,0,0,0,0,0,0,0,0,0
0,15,0,0,0,0,0,0,0,0,15,0
0,0,0,0,0,0,0,0,0,0,0,0
0,0,0,0,0,0,0,0,0,0,0,0
0,0,0,0,0,0,0,0,0,0,0,0
0,0,0,0,0,0,0,0,0,0,0,0
0,0,0,0,0,0,0,0,0,0,0,0
0,0,0,0,0,0,0,0,0,0,0,0
0,0,0,0,0,0,0,0,0,0,0,0
0,0,0,0,0,0,0,0,0,0,0,0
0,15,0,0,0,0,0,0,0,0,15,0
0,0,0,0,0,0,0,0,0,0,0,0
endlayer

layer
0,0,0,0,0,0,0,0,0,0,0,0
0,58,0,0,0,0,0,0,0,0,58,0
0,0,0,0,0,0,0,0,0,0,0,0
0,0,0,0,0,0,0,0,0,0,0,0
0,0,0,0,0,0,0,0,0,0,0,0
0,0,0,0,0,0,0,0,0,0,0,0
0,0,0,0,0,0,0,0,0,0,0,0
0,0,0,0,0,0,0,0,0,0,0,0
0,0,0,0,0,0,0,0,0,0,0,0
0,0,0,0,0,0,0,0,0,0,0,0
0,58,0,0,0,0,0,0,0,0,58,0
0,0,0,0,0,0,0,0,0,0,0,0
endlayer

layer
0,0,0,0,0,0,0,0,0,0,0,0
0,58,0,0,0,0,0,0,0,0,58,0
0,0,0,0,0,0,0,0,0,0,0,0
0,0,0,0,0,0,0,0,0,0,0,0
0,0,0,0,0,0,0,0,0,0,0,0
0,0,0,0,0,0,0,0,0,0,0,0
0,0,0,0,0,0,0,0,0,0,0,0
0,0,0,0,0,0,0,0,0,0,0,0
0,0,0,0,0,0,0,0,0,0,0,0
0,0,0,0,0,0,0,0,0,0,0,0
0,58,0,0,0,0,0,0,0,0,58,0
0,0,0,0,0,0,0,0,0,0,0,0
endlayer

layer
0,0,0,0,0,0,0,0,0,0,0,0
0,20,0,0,0,0,0,0,0,0,20,0
0,0,0,0,0,0,0,0,0,0,0,0
0,0,0,0,0,0,0,0,0,0,0,0
0,0,0,0,0,0,0,0,0,0,0,0
0,0,0,0,0,0,0,0,0,0,0,0
0,0,0,0,0,0,0,0,0,0,0,0
0,0,0,0,0,0,0,0,0,0,0,0
0,0,0,0,0,0,0,0,0,0,0,0
0,0,0,0,0,0,0,0,0,0,0,0
0,20,0,0,0,0,0,0,0,0,20,0
0,0,0,0,0,0,0,0,0,0,0,0
endlayer

