# Obsidian Cell Dungeon -- North/South Corridor
# Created by Ruins mod version 14.7 Ingame Parser
# authoring Player: Jordan_Greywolf
# MC 1.7.10; 8 Apr 2015
# Note: Please put in \templateparser folder.
# Updated to MC 1.8: 5 Mar 2016
# Updated to MC 1.9: 24 Apr 2016
# Updated to MC 1.11: 12 Jan 2017
# Updated to MC 1.12: 22 Jun 2017

weight=1
embed_into_distance=0
acceptable_target_blocks=
unacceptable_target_blocks=flowing_water,water,flowing_lava,lava
dimensions=6,14,14
allowable_overhang=0
max_leveling=0
leveling_buffer=0
preserve_water=0
preserve_lava=0

rule1=0,100,minecraft:obsidian-0
rule2=0,100,minecraft:stonebrick,minecraft:stonebrick-1,minecraft:stonebrick-2
rule3=0,100,minecraft:stonebrick-3
rule4=0,100,Skull:0:6-1
rule5=0,100,minecraft:flower_pot-0

rule6=0,100,CommandBlock:RUINSTRIGGER /summon Zombie ~0 ~0 ~0 {HandItems:[{Count:1,id:bone,tag:{display:{Name:"Sharpened Bone"},ench:[{id:16,lvl:8},{id:34,lvl:3}]}},{}],ArmorItems:[{Count:1,id:leather_boots,tag:{display:{Name:"Tattered Boots"}}},{Count:1,id:leather_leggings,tag:{display:{Name:"Tattered Leggings"}}},{Count:1,id:leather_chestplate,tag:{display:{Name:"Tattered Coat"}}},{Count:1,id:skull,Damage:3}],CustomName:"Mad Prisoner",Health:30.0f,Attributes:[{Name:generic.followRange,Base:30}],HandDropChances:[1.0F,0.0F],ArmorDropChances:[0.1F,0.1F,0.1F,0.0F],Silent:1,PersistenceRequired:1}:@

rule7=0,100,minecraft:redstone_wire-0
rule8=0,100,ChestGenHook:chests/simple_dungeon:3-5
rule9=0,100,minecraft:web-0
rule10=0,100,minecraft:iron_door-2
rule11=0,100,minecraft:stone_brick_stairs-1
rule12=0,100,minecraft:stone_brick_stairs-0
rule13=0,100,minecraft:iron_door-0
rule14=0,100,Skull:0:10-1
rule15=0,100,ChestGenHook:chests/simple_dungeon:3-4
rule16=0,100,Skull:0:13-1
rule17=0,100,minecraft:tripwire_hook-3
rule18=0,100,minecraft:iron_door-8
rule19=0,100,minecraft:iron_door-9
rule20=0,100,minecraft:iron_bars-0
rule21=0,100,minecraft:lever-1
rule22=0,100,minecraft:lever-2
rule23=0,100,minecraft:tripwire_hook-1
rule24=0,100,minecraft:stone_brick_stairs-5
rule25=0,100,minecraft:stone_brick_stairs-4

layer
1,1,1,1,1,1,1,1,1,1,1,1,1,1
1,1,1,1,1,1,1,1,1,1,1,1,1,1
1,1,1,1,1,1,1,1,1,1,1,1,1,1
1,1,1,1,1,1,1,1,1,1,1,1,1,1
1,1,1,1,1,1,1,1,1,1,1,1,1,1
1,1,1,1,1,1,1,1,1,1,1,1,1,1
1,1,1,1,1,1,1,1,1,1,1,1,1,1
1,1,1,1,1,1,1,1,1,1,1,1,1,1
1,1,1,1,1,1,1,1,1,1,1,1,1,1
1,1,1,1,1,1,1,1,1,1,1,1,1,1
1,1,1,1,1,1,1,1,1,1,1,1,1,1
1,1,1,1,1,1,1,1,1,1,1,1,1,1
1,1,1,1,1,1,1,1,1,1,1,1,1,1
1,1,1,1,1,1,1,1,1,1,1,1,1,1
endlayer

layer
1,1,1,1,1,1,1,1,1,1,1,1,1,1
1,2,3,2,1,2,3,3,2,1,2,3,2,1
1,3,2,3,1,3,2,2,3,1,3,2,3,1
1,2,3,2,1,2,3,3,2,1,2,3,2,1
3,1,2,1,1,1,2,2,1,1,1,2,1,3
3,3,3,3,3,3,3,3,3,3,3,3,3,3
2,3,2,2,3,2,2,2,2,3,2,2,3,2
2,3,2,2,3,2,2,2,2,3,2,2,3,2
3,3,3,3,3,3,3,3,3,3,3,3,3,3
3,1,2,1,1,1,2,2,1,1,1,2,1,3
1,2,3,2,1,2,3,3,2,1,2,3,2,1
1,3,2,3,1,3,2,2,3,1,3,2,3,1
1,2,3,2,1,2,3,3,2,1,2,3,2,1
1,1,1,1,1,1,1,1,1,1,1,1,1,1
endlayer

layer
1,1,1,1,1,1,1,1,1,1,1,1,1,1
1,9,0,0,1,8,7,0,6,1,5,0,4,1
1,5,0,0,1,0,0,0,5,1,0,7,0,1
1,0,0,0,1,0,0,0,0,1,0,0,0,1
3,1,10,1,3,1,10,10,1,3,1,10,1,3
11,0,0,0,11,0,0,0,0,11,0,0,0,11
0,0,0,0,0,0,7,0,0,0,0,0,0,0
0,0,0,0,0,7,0,0,0,0,0,0,0,0
12,0,0,0,12,0,0,0,0,12,0,0,0,12
3,1,13,1,3,1,13,13,1,3,1,13,1,3
1,0,0,0,1,0,0,0,0,1,0,0,0,1
1,0,0,0,1,7,0,5,0,1,5,0,0,1
1,0,5,0,1,6,16,0,15,1,0,0,14,1
1,1,1,1,1,1,1,1,1,1,1,1,1,1
endlayer

layer
1,1,1,1,1,1,1,1,1,1,1,1,1,1
1,0,17,17,1,0,17,17,0,1,0,17,17,1
1,0,0,0,1,0,0,0,0,1,0,0,0,1
1,0,0,0,1,0,0,0,0,1,0,0,0,1
3,1,18,1,3,1,18,19,1,3,1,18,1,3
20,0,0,21,20,21,0,0,21,20,0,0,21,20
0,0,0,0,0,0,0,0,0,0,0,0,0,0
0,0,0,0,0,0,0,0,0,0,0,0,0,0
20,22,0,0,0,22,0,0,22,20,22,0,0,20
3,1,18,1,3,1,19,18,1,3,1,18,1,3
1,0,0,0,1,0,0,0,0,1,0,0,0,1
1,0,0,0,1,0,0,0,0,1,0,0,0,1
1,23,23,0,1,0,23,23,0,1,23,23,0,1
1,1,1,1,1,1,1,1,1,1,1,1,1,1
endlayer

layer
1,1,1,1,1,1,1,1,1,1,1,1,1,1
1,9,0,0,1,9,0,0,9,1,0,0,0,1
1,0,0,0,1,0,0,0,0,1,0,0,0,1
1,0,0,0,1,0,0,0,0,1,0,0,0,1
3,1,1,1,3,1,1,1,1,3,1,1,1,3
24,9,0,0,24,9,0,0,9,24,9,0,9,24
0,0,0,0,0,0,0,0,0,0,0,0,0,0
0,0,0,0,0,0,0,0,0,0,0,0,0,0
25,9,0,9,25,9,0,0,0,25,9,0,9,25
3,1,1,1,3,1,1,1,1,3,1,1,1,3
1,0,0,0,1,9,0,0,0,1,0,0,0,1
1,0,0,0,1,0,0,0,0,1,0,0,0,1
1,0,0,0,1,9,0,0,9,1,0,0,0,1
1,1,1,1,1,1,1,1,1,1,1,1,1,1
endlayer

layer
3,3,3,3,3,3,3,3,3,3,3,3,3,3
3,1,1,1,3,1,1,1,1,3,1,1,1,3
3,1,1,1,3,1,1,1,1,3,1,1,1,3
3,1,1,1,3,1,1,1,1,3,1,1,1,3
3,3,3,3,3,3,3,3,3,3,3,3,3,3
3,1,1,1,3,1,1,1,1,3,1,1,1,3
3,1,1,1,3,1,1,1,1,3,1,1,1,3
3,1,1,1,3,1,1,1,1,3,1,1,1,3
3,1,1,1,3,1,1,1,1,3,1,1,1,3
3,3,3,3,3,3,3,3,3,3,3,3,3,3
3,1,1,1,3,1,1,1,1,3,1,1,1,3
3,1,1,1,3,1,1,1,1,3,1,1,1,3
3,1,1,1,3,1,1,1,1,3,1,1,1,3
3,3,3,3,3,3,3,3,3,3,3,3,3,3
endlayer

