# Obsidian Cell Dungeon: Stairwell Base
# Created by Ruins mod version 14.7 Ingame Parser
# authoring Player: Jordan_Greywolf
# MC 1.7.10; 8 Apr 2015
# Note: Place in \templateparser folder.
# Updated to MC 1.8: 5 Mar 2016
# Updated to MC 1.9: 24 Apr 2016
# Updated to MC 1.11: 12 Jan 2017
# Updated to MC 1.12: 22 Jun 2017

weight=1
embed_into_distance=0
acceptable_target_blocks=
unacceptable_target_blocks=flowing_water,water,flowing_lava,lava
dimensions=6,14,14
allowable_overhang=0
max_leveling=0
leveling_buffer=0
preserve_water=0
preserve_lava=0

rule1=0,100,minecraft:obsidian-0
rule2=0,100,minecraft:stonebrick-3
rule3=0,100,minecraft:stonebrick,minecraft:stonebrick-1,minecraft:stonebrick-2
rule4=0,100,minecraft:stone_brick_stairs-3
rule5=0,100,minecraft:spruce_door-2
rule6=0,100,minecraft:stone_brick_stairs-2
rule7=0,100,minecraft:iron_bars-0
rule8=0,100,minecraft:stone_brick_stairs-1

rule9=0,100,CommandBlock:RUINSTRIGGER /summon Zombie ~0 ~0 ~0 {HandItems:[{Count:1,id:bone,tag:{display:{Name:"Sharpened Bone"},ench:[{id:16,lvl:8},{id:34,lvl:3}]}},{}],ArmorItems:[{Count:1,id:leather_boots,tag:{display:{Name:"Tattered Boots"}}},{Count:1,id:leather_leggings,tag:{display:{Name:"Tattered Leggings"}}},{Count:1,id:leather_chestplate,tag:{display:{Name:"Tattered Coat"}}},{Count:1,id:skull,Damage:3}],CustomName:"Mad Prisoner",Health:30.0f,Attributes:[{Name:generic.followRange,Base:30}],HandDropChances:[1.0F,0.0F],ArmorDropChances:[0.1F,0.1F,0.1F,0.0F],Silent:1,PersistenceRequired:1}:@

rule10=0,100,minecraft:stone_brick_stairs-0
rule11=0,100,minecraft:web-0
rule12=0,100,minecraft:stone_slab-0
rule13=0,100,minecraft:spruce_door-3
rule14=0,100,minecraft:double_stone_slab-0
rule15=0,100,minecraft:spruce_door-1
rule16=0,100,minecraft:stone_slab-8
rule17=0,100,CommandBlock:RUINSTRIGGER /setblock ~0 ~-1 ~0 mob_spawner 0 replace {EntityId:Skeleton,SpawnData:{id:Skeleton,HandItems:[{Count:1,id:bow,tag:{display:{Name:"Cursed Bow"},ench:[{id:50,lvl:1},{id:49,lvl:2}]}},{Count:8,id:arrow}],ArmorItems:[{},{},{Count:1,id:leather_chestplate,tag:{display:{Name:"Rotten Armor"}}},{Count:1,id:leather_helmet,tag:{display:{Name:"Rotten Helm"}}}],CustomName:"Rotting Guard",HandDropChances:[0.1F,0.1F],ArmorDropChances:[0.0F,0.0F,0.2F,0.2F]}}:@

rule18=0,100,minecraft:redstone_wire-0
rule19=0,100,minecraft:spruce_door-0
rule20=0,100,minecraft:spruce_door-9
rule21=0,100,minecraft:spruce_door-8
rule22=0,100,minecraft:tripwire_hook-3
rule23=0,100,minecraft:tripwire_hook-1
rule24=0,100,minecraft:stone_brick_stairs-7
rule25=0,100,minecraft:stone_brick_stairs-6
rule26=0,100,minecraft:stone_brick_stairs-5
rule27=0,100,minecraft:stone_brick_stairs-4

layer
1,1,1,1,1,1,1,1,1,1,1,1,1,1
1,1,1,1,1,1,1,1,1,1,1,1,1,1
1,1,1,1,1,1,1,1,1,1,1,1,1,1
1,1,1,1,1,1,1,1,1,1,1,1,1,1
1,1,1,1,1,1,1,1,1,1,1,1,1,1
1,1,1,1,1,1,1,1,1,1,1,1,1,1
1,1,1,1,1,1,1,1,1,1,1,1,1,1
1,1,1,1,1,1,1,1,1,1,1,1,1,1
1,1,1,1,1,1,1,1,1,1,1,1,1,1
1,1,1,1,1,1,1,1,1,1,1,1,1,1
1,1,1,1,1,1,1,1,1,1,1,1,1,1
1,1,1,1,1,1,1,1,1,1,1,1,1,1
1,1,1,1,1,1,1,1,1,1,1,1,1,1
1,1,1,1,1,1,1,1,1,1,1,1,1,1
endlayer

layer
1,1,1,1,2,2,3,3,2,2,1,1,1,1
1,3,2,3,3,2,2,2,2,3,3,2,3,1
1,2,3,2,3,2,3,3,2,3,2,3,2,1
1,3,2,3,3,2,3,3,2,3,3,2,3,1
2,3,3,3,1,2,2,2,2,1,3,3,3,2
2,2,2,2,2,3,3,3,3,2,2,2,2,2
3,2,3,3,2,3,3,3,3,2,3,3,2,3
3,2,3,3,2,3,3,3,3,2,3,3,2,3
2,2,2,2,2,3,3,3,3,2,2,2,2,2
2,3,3,3,1,2,2,2,2,1,3,3,3,2
1,3,2,3,3,2,3,3,2,3,3,2,3,1
1,2,3,2,3,2,3,3,2,3,2,3,2,1
1,3,2,3,3,2,2,2,2,3,3,2,3,1
1,1,1,1,2,2,3,3,2,2,1,1,1,1
endlayer

layer
1,1,1,1,2,6,5,5,4,2,1,1,1,1
1,0,7,0,8,0,0,0,0,8,0,7,0,1
1,7,7,0,0,0,0,0,0,0,9,7,7,1
1,11,0,0,10,0,0,0,0,10,0,0,0,1
2,6,0,4,2,6,0,0,4,2,6,0,4,2
8,0,0,0,8,12,0,0,0,8,0,0,0,8
15,0,0,0,0,14,0,0,0,0,0,0,0,13
15,0,0,0,0,16,11,0,0,0,0,0,0,13
10,0,0,0,10,17,11,0,0,10,0,0,0,10
2,6,0,4,2,6,0,0,4,2,6,0,4,2
1,0,0,0,8,0,0,0,0,8,18,0,0,1
1,7,7,0,0,0,0,0,0,0,0,7,7,1
1,0,7,0,10,0,0,0,0,10,0,7,0,1
1,1,1,1,2,6,19,19,4,2,1,1,1,1
endlayer

layer
1,1,1,1,2,7,21,20,7,2,1,1,1,1
1,22,7,0,7,0,0,0,0,7,0,7,22,1
1,7,0,0,0,0,0,0,0,0,0,0,7,1
1,0,0,0,7,0,0,0,0,7,0,0,0,1
2,7,0,7,2,7,0,0,7,2,7,0,7,2
7,0,0,0,7,0,0,0,0,7,0,0,0,7
20,0,0,0,0,0,0,0,0,0,0,0,0,21
21,0,0,0,0,12,0,0,0,0,0,0,0,20
7,0,0,0,7,14,16,0,0,7,0,0,0,7
2,7,0,7,2,7,0,0,7,2,7,0,7,2
1,0,0,0,7,0,0,0,0,7,0,0,0,1
1,7,0,0,0,0,0,0,0,0,0,0,7,1
1,23,7,0,7,0,0,0,0,7,0,7,23,1
1,1,1,1,2,7,20,21,7,2,1,1,1,1
endlayer

layer
1,1,1,1,2,25,0,0,24,2,1,1,1,1
1,0,7,0,26,11,0,0,0,26,11,7,0,1
1,7,7,0,0,0,0,0,0,0,0,7,7,1
1,0,0,0,27,0,0,0,0,27,0,0,11,1
2,25,11,24,2,25,0,0,24,2,25,11,24,2
26,0,0,0,26,11,0,0,0,26,0,0,0,26
0,0,0,0,0,0,0,0,0,0,0,0,0,0
0,0,0,0,11,0,0,0,0,0,0,0,0,0
27,0,0,0,27,0,12,14,16,27,0,0,0,27
2,25,11,24,2,25,0,0,24,2,25,11,24,2
1,0,0,0,26,0,0,0,0,26,0,0,0,1
1,7,7,0,0,0,0,0,0,0,0,7,7,1
1,0,7,0,27,0,0,0,0,27,0,7,0,1
1,1,1,1,2,25,0,0,24,2,1,1,1,1
endlayer

layer
2,2,2,2,2,2,2,2,2,2,2,2,2,2
2,1,1,1,2,1,1,1,1,2,1,1,1,2
2,1,1,1,2,1,1,1,1,2,1,1,1,2
2,1,1,1,2,1,1,1,1,2,1,1,1,2
2,2,2,2,2,2,2,2,2,2,2,2,2,2
2,1,1,1,2,0,0,0,0,2,1,1,1,2
2,1,1,1,2,0,0,0,16,2,1,1,1,2
2,1,1,1,2,0,0,0,14,2,1,1,1,2
2,1,1,1,2,0,0,0,12,2,1,1,1,2
2,2,2,2,2,2,2,2,2,2,2,2,2,2
2,1,1,1,2,1,1,1,1,2,1,1,1,2
2,1,1,1,2,1,1,1,1,2,1,1,1,2
2,1,1,1,2,1,1,1,1,2,1,1,1,2
2,2,2,2,2,2,2,2,2,2,2,2,2,2
endlayer

