# Obsidian Cell Dungeon: Stairwell
# Created by Ruins mod version 14.7 Ingame Parser
# authoring Player: Jordan_Greywolf
# MC 1.7.10; 8 Apr 2015
# Updated to MC 1.11: 12 Jan 2017
# Note: Place in \templateparser folder.

weight=1
embed_into_distance=0
acceptable_target_blocks=
unacceptable_target_blocks=flowing_water,water,flowing_lava,lava
dimensions=6,8,8
allowable_overhang=0
max_leveling=0
leveling_buffer=0
preserve_water=0
preserve_lava=0

rule1=0,100,minecraft:double_stone_slab-0
rule2=0,100,minecraft:obsidian-0
rule3=0,100,minecraft:stonebrick,minecraft:stonebrick-1,minecraft:stonebrick-2
rule4=0,100,minecraft:stone_slab-8
rule5=0,100,minecraft:stone_slab-0
rule6=0,100,minecraft:stone_brick_stairs-3
rule7=0,100,minecraft:stone_brick_stairs-2
rule8=0,100,minecraft:stone_brick_stairs-1
rule9=0,100,minecraft:stone_brick_stairs-0
rule10=0,100,minecraft:stone_brick_stairs-7
rule11=0,100,minecraft:stone_brick_stairs-6
rule12=0,100,minecraft:stone_brick_stairs-5
rule13=0,100,minecraft:stone_brick_stairs-4

layer
1,2,2,2,2,2,2,1
2,3,3,3,3,3,3,2
2,3,0,0,4,1,3,2
2,3,0,0,0,5,3,2
2,3,0,0,0,0,3,2
2,3,0,0,0,0,3,2
2,3,3,3,3,3,3,2
1,2,2,2,2,2,2,1
endlayer

layer
1,2,2,2,2,2,2,1
2,1,7,0,0,6,1,2
2,8,4,1,5,0,8,2
2,0,0,0,0,0,0,2
2,0,0,0,0,0,0,2
2,9,0,0,0,0,9,2
2,1,7,0,0,6,1,2
1,2,2,2,2,2,2,1
endlayer

layer
1,2,2,2,2,2,2,1
2,1,11,0,0,10,1,2
2,12,5,0,0,0,12,2
2,0,1,0,0,0,0,2
2,0,4,0,0,0,0,2
2,13,0,0,0,0,13,2
2,1,11,0,0,10,1,2
1,2,2,2,2,2,2,1
endlayer

layer
1,2,2,2,2,2,2,1
2,1,7,0,0,6,1,2
2,8,0,0,0,0,8,2
2,0,0,0,0,0,0,2
2,0,5,0,0,0,0,2
2,9,1,4,0,0,9,2
2,1,7,0,0,6,1,2
1,2,2,2,2,2,2,1
endlayer

layer
1,2,2,2,2,2,2,1
2,1,11,0,0,10,1,2
2,12,0,0,0,0,12,2
2,0,0,0,0,0,0,2
2,0,0,0,0,0,0,2
2,13,0,5,1,4,13,2
2,1,11,0,0,10,1,2
1,2,2,2,2,2,2,1
endlayer

layer
1,2,2,2,2,2,2,1
2,1,3,3,3,3,1,2
2,3,0,0,0,0,3,2
2,3,0,0,0,4,3,2
2,3,0,0,0,1,3,2
2,3,0,0,0,5,3,2
2,1,3,3,3,3,1,2
1,2,2,2,2,2,2,1
endlayer

