# Obsidian Cell Dungeon: North/South/East/West Intersection
# Created by Ruins mod version 14.7 Ingame Parser
# authoring Player: Jordan_Greywolf
# MC 1.7.10; 8 Apr 2015
# Updated to MC 1.11: 12 Jan 2017
# Note: Place in \templateparser folder.

weight=1
embed_into_distance=0
acceptable_target_blocks=
unacceptable_target_blocks=flowing_water,water,flowing_lava,lava
dimensions=6,14,14
allowable_overhang=0
max_leveling=0
leveling_buffer=0
preserve_water=0
preserve_lava=0

rule1=0,100,minecraft:obsidian-0
rule2=0,100,minecraft:stonebrick-3
rule3=0,100,minecraft:stonebrick,minecraft:stonebrick-1,minecraft:stonebrick-2
rule4=0,100,minecraft:stone_brick_stairs-3
rule5=0,100,minecraft:stone_brick_stairs-2
rule6=0,100,Skull:0:7-1
rule7=0,100,minecraft:flower_pot-0
rule8=0,100,minecraft:web-0
rule9=0,100,minecraft:iron_door-2
rule10=0,100,minecraft:stone_brick_stairs-1
rule11=0,100,minecraft:redstone_wire-0
rule12=0,100,minecraft:stone_brick_stairs-0
rule13=0,100,Skull:0:10-1
rule14=0,100,minecraft:iron_door-0
rule15=0,100,Skull:0:6-1
rule16=0,100,Skull:0:12-1
rule17=0,100,minecraft:iron_bars-0
rule18=0,100,minecraft:tripwire_hook-3
rule19=0,100,minecraft:iron_door-8
rule20=0,100,minecraft:lever-1
rule21=0,100,minecraft:lever-2
rule22=0,100,minecraft:tripwire_hook-1
rule23=0,100,minecraft:stone_brick_stairs-7
rule24=0,100,minecraft:stone_brick_stairs-6
rule25=0,100,minecraft:stone_brick_stairs-5
rule26=0,100,minecraft:stone_brick_stairs-4

layer
1,1,1,1,1,1,1,1,1,1,1,1,1,1
1,1,1,1,1,1,1,1,1,1,1,1,1,1
1,1,1,1,1,1,1,1,1,1,1,1,1,1
1,1,1,1,1,1,1,1,1,1,1,1,1,1
1,1,1,1,1,1,1,1,1,1,1,1,1,1
1,1,1,1,1,1,1,1,1,1,1,1,1,1
1,1,1,1,1,1,1,1,1,1,1,1,1,1
1,1,1,1,1,1,1,1,1,1,1,1,1,1
1,1,1,1,1,1,1,1,1,1,1,1,1,1
1,1,1,1,1,1,1,1,1,1,1,1,1,1
1,1,1,1,1,1,1,1,1,1,1,1,1,1
1,1,1,1,1,1,1,1,1,1,1,1,1,1
1,1,1,1,1,1,1,1,1,1,1,1,1,1
1,1,1,1,1,1,1,1,1,1,1,1,1,1
endlayer

layer
1,1,1,1,2,2,3,3,2,2,1,1,1,1
1,3,2,3,1,2,2,2,2,1,3,2,3,1
1,2,3,2,1,2,3,3,2,1,2,3,2,1
1,3,2,3,1,2,3,3,2,1,3,2,3,1
2,1,3,1,1,2,2,2,2,1,1,3,1,2
2,2,2,2,2,3,3,3,3,2,2,2,2,2
3,2,3,3,2,3,3,3,3,2,3,3,2,3
3,2,3,3,2,3,3,3,3,2,3,3,2,3
2,2,2,2,2,3,3,3,3,2,2,2,2,2
2,1,3,1,1,2,2,2,2,1,1,3,1,2
1,3,2,3,1,2,3,3,2,1,3,2,3,1
1,2,3,2,1,2,3,3,2,1,2,3,2,1
1,3,2,3,1,2,2,2,2,1,3,2,3,1
1,1,1,1,2,2,3,3,2,2,1,1,1,1
endlayer

layer
1,1,1,1,2,5,0,0,4,2,1,1,1,1
1,0,0,0,1,0,0,0,6,1,0,0,0,1
1,0,0,0,1,0,0,0,0,1,0,7,0,1
1,8,0,7,1,0,0,0,0,1,0,0,0,1
2,1,9,1,2,5,0,0,4,2,1,9,1,2
10,0,0,0,10,0,0,0,0,10,0,0,0,10
0,0,0,0,0,0,11,0,0,0,0,0,0,0
0,0,0,0,0,0,0,0,0,0,0,0,0,0
12,0,0,0,12,0,0,0,13,12,0,0,0,12
2,1,14,1,2,5,0,0,4,2,1,14,1,2
1,0,0,0,1,0,0,0,15,1,0,0,0,1
1,0,0,7,1,0,0,0,0,1,0,16,0,1
1,0,0,0,1,0,0,0,8,1,0,0,0,1
1,1,1,1,2,5,0,0,4,2,1,1,1,1
endlayer

layer
1,1,1,1,2,17,0,0,17,2,1,1,1,1
1,0,18,18,1,0,0,0,0,1,0,18,18,1
1,0,0,0,1,0,0,0,0,1,0,0,0,1
1,0,0,0,1,0,0,0,0,1,0,0,0,1
2,1,19,1,2,17,0,0,17,2,1,19,1,2
17,0,0,20,17,0,0,0,0,17,0,0,20,17
0,0,0,0,0,0,0,0,0,0,0,0,0,0
0,0,0,0,0,0,0,0,0,0,0,0,0,0
17,21,0,0,17,0,0,0,0,17,21,0,0,17
2,1,19,1,2,17,0,0,17,2,1,19,1,2
1,0,0,0,1,0,0,0,0,1,0,0,0,1
1,0,0,0,1,0,0,0,0,1,0,0,0,1
1,22,22,0,1,0,0,0,0,1,22,22,0,1
1,1,1,1,2,17,0,0,17,2,1,1,1,1
endlayer

layer
1,1,1,1,2,24,0,0,23,2,1,1,1,1
1,0,0,0,1,0,0,0,8,1,8,0,8,1
1,0,0,0,1,0,0,0,0,1,0,0,0,1
1,8,8,8,1,8,0,0,0,1,0,8,0,1
2,1,1,1,2,24,0,0,23,2,1,1,1,2
25,0,0,8,25,8,0,0,8,25,8,0,0,25
0,0,0,0,0,0,0,0,0,0,0,0,0,0
0,0,0,0,0,0,0,0,0,0,0,0,0,0
26,8,0,0,26,8,0,0,8,26,0,0,8,26
2,1,1,1,2,24,0,0,23,2,1,1,1,2
1,0,0,0,1,0,0,0,8,1,0,8,0,1
1,0,0,0,1,0,0,0,0,1,0,0,0,1
1,0,0,0,1,8,0,0,0,1,0,0,0,1
1,1,1,1,2,24,0,0,23,2,1,1,1,1
endlayer

layer
2,2,2,2,2,2,2,2,2,2,2,2,2,2
2,1,1,1,2,1,1,1,1,2,1,1,1,2
2,1,1,1,2,1,1,1,1,2,1,1,1,2
2,1,1,1,2,1,1,1,1,2,1,1,1,2
2,2,2,2,2,2,2,2,2,2,2,2,2,2
2,1,1,1,2,1,1,1,1,2,1,1,1,2
2,1,1,1,2,1,1,1,1,2,1,1,1,2
2,1,1,1,2,1,1,1,1,2,1,1,1,2
2,1,1,1,2,1,1,1,1,2,1,1,1,2
2,2,2,2,2,2,2,2,2,2,2,2,2,2
2,1,1,1,2,1,1,1,1,2,1,1,1,2
2,1,1,1,2,1,1,1,1,2,1,1,1,2
2,1,1,1,2,1,1,1,1,2,1,1,1,2
2,2,2,2,2,2,2,2,2,2,2,2,2,2
endlayer

