# Sunken Tower
# Based on SunkenQuartzShrine -- 16 Apr 2014 / 13 Oct 2014
# MC 1.7.10; 27 Jan 2015
# Created by Ruins mod version 12.3 Ingame Parser
# authoring Player: Jordan_Greywolf
# Special Instructions: Place this in the \templateparser
#   folder.  Not meant to be in standard biome folders.
# Updated to MC 1.8: 5 Mar 2016
# Updated to MC 1.11: 12 Jan 2017
# Updated to MC 1.12: 22 Jun 2017

biomesToSpawnIn=deep ocean,kelp forest,ocean,ocean oil field,oceanic abyss,coral reef

weight=1
embed_into_distance=4
acceptable_target_blocks=water,flowing_water,ice
dimensions=24,11,11
allowable_overhang=999
max_cut_in=0
cut_in_buffer=0
max_leveling=0
leveling_buffer=0
preserve_water=0
preserve_lava=0
preserve_plants=0

rule1=0,100,preserveBlock
rule2=0,100,minecraft:quartz_block-0
rule3=0,100,minecraft:sandstone-2
rule4=0,100,minecraft:glowstone
rule5=0,100,minecraft:vine-2
rule6=0,100,minecraft:vine-4
rule7=0,100,minecraft:vine-1
rule8=0,100,minecraft:vine-8
rule9=0,100,minecraft:stained_glass-3
rule10=0,100,minecraft:quartz_block-2
rule11=0,100,minecraft:quartz_block-1
rule12=0,100,minecraft:quartz_stairs-0
rule13=0,100,minecraft:stone_slab-7
rule14=0,100,minecraft:quartz_stairs-2
rule15=0,100,minecraft:quartz_stairs-3
rule16=0,100,minecraft:quartz_stairs-1
rule17=0,100,minecraft:glowstone
rule18=0,100,minecraft:water-1

rule19=0,100,CommandBlock:RUINSTRIGGER /summon skeleton ~0 ~0 ~0 {HandItems:[{Count:1,id:stained_glass,Damage:3,tag:{ench:[{id:19,lvl:2}]}},{}],ArmorItems:[{Count:8,id:fish,Damage:2},{Count:8,id:fish,Damage:1},{Count:8,id:fish},{Count:1,id:stained_glass,Damage:3,tag:{ench:[{id:5,lvl:50},{id:8,lvl:50}],display:{Name:Water Anomaly}}}],CustomName:"Water Guardian",Attributes:[{Name:generic.attackDamage,Base:6},{Name:generic.knockbackResistance,Base:1}],HandDropChances:[0.0F,0.0F],ArmorDropChances:[1.0F,1.0F,1.0F,0.0F],ActiveEffects:[{Id:12,Amplifier:1,Duration:999999,Ambient:1},{Id:14,Amplifier:1,Duration:999999,Ambient:1},{Id:13,Amplifier:1,Duration:999999,Ambient:1}],Silent:1,PersistenceRequired:1}:@

rule20=0,100,CommandBlock:RUINSTRIGGER /gamerule commandBlockOutput false:@

rule21=0,100,ChestGenHook:chests/simple_dungeon:5

layer
1,1,1,1,2,2,2,1,1,1,1
1,1,2,2,2,2,2,2,2,1,1
1,2,2,2,3,3,3,2,2,2,1
1,2,2,3,3,3,3,3,2,2,1
2,2,3,3,3,3,3,3,3,2,2
2,2,3,3,3,20,3,3,3,2,2
2,2,3,3,3,3,3,3,3,2,2
1,2,2,3,3,3,3,3,2,2,1
1,2,2,2,3,3,3,2,2,2,1
1,1,2,2,2,2,2,2,2,1,1
1,1,1,1,2,2,2,1,1,1,1
endlayer

layer
1,1,1,1,2,2,2,1,1,1,1
1,1,2,2,18,18,18,2,2,1,1
1,2,18,18,2,2,2,18,18,2,1
1,2,18,2,4,4,4,2,18,2,1
2,18,2,4,4,4,4,4,2,18,2
2,18,2,4,4,4,4,4,2,18,2
2,18,2,4,4,4,4,4,2,18,2
1,2,18,2,4,4,4,2,18,2,1
1,2,18,18,2,2,2,18,18,2,1
1,1,2,2,18,18,18,2,2,1,1
1,1,1,1,2,2,2,1,1,1,1
endlayer

layer
1,1,1,1,2,2,2,1,1,1,1
1,1,2,2,18,18,18,2,2,1,1
1,2,18,18,2,2,2,18,18,2,1
1,2,18,2,0,0,0,2,18,2,1
2,18,2,0,0,0,0,0,2,18,2
2,18,2,0,19,21,19,0,2,18,2
2,18,2,0,0,0,0,0,2,18,2
1,2,18,2,0,0,0,2,18,2,1
1,2,18,18,2,2,2,18,18,2,1
1,1,2,2,18,18,18,2,2,1,1
1,1,1,1,2,2,2,1,1,1,1
endlayer

layer
1,1,1,1,2,2,2,1,1,1,1
1,1,2,2,18,0,18,2,2,1,1
1,2,18,0,0,0,0,0,18,2,1
1,2,0,0,0,0,0,0,0,2,1
2,18,0,0,0,0,0,0,0,18,2
2,0,0,0,0,19,0,0,0,0,2
2,18,0,0,0,0,0,0,0,18,2
1,2,0,0,0,0,0,0,0,2,1
1,2,18,0,0,0,0,0,18,2,1
1,1,2,2,18,0,18,2,2,1,1
1,1,1,1,2,2,2,1,1,1,1
endlayer

layer
1,1,1,1,2,2,2,1,1,1,1
1,1,2,2,18,5,18,2,2,1,1
1,2,18,5,0,0,0,5,18,2,1
1,2,7,0,0,0,0,0,6,2,1
2,18,0,0,0,0,0,0,0,18,2
2,7,0,0,0,0,0,0,0,6,2
2,18,0,0,0,0,0,0,0,18,2
1,2,7,0,0,0,0,0,6,2,1
1,2,18,8,0,0,0,8,18,2,1
1,1,2,2,18,8,18,2,2,1,1
1,1,1,1,2,2,2,1,1,1,1
endlayer

layer
1,1,1,1,1,10,1,1,1,1,1
1,1,1,10,18,5,18,10,1,1,1
1,1,18,5,0,0,0,5,18,1,1
1,10,7,0,0,0,0,0,6,10,1
1,18,0,0,0,0,0,0,0,18,1
10,7,0,0,0,0,0,0,0,6,10
1,18,0,0,0,0,0,0,0,18,1
1,10,7,0,0,0,0,0,6,10,1
1,1,18,8,0,0,0,8,18,1,1
1,1,1,10,18,8,18,10,1,1,1
1,1,1,1,1,10,1,1,1,1,1
endlayer

layer
1,1,1,1,1,10,1,1,1,1,1
1,1,1,10,18,5,18,10,1,1,1
1,1,0,5,0,0,0,5,18,1,1
1,10,7,0,0,0,0,0,6,10,1
1,18,0,0,0,0,0,0,0,18,1
10,7,0,0,0,0,0,0,0,6,10
1,18,0,0,0,0,0,0,0,18,1
1,10,7,0,0,0,0,0,6,10,1
1,1,18,8,0,0,0,8,18,1,1
1,1,1,10,18,8,18,10,1,1,1
1,1,1,1,1,10,1,1,1,1,1
endlayer

layer
1,1,1,1,1,10,1,1,1,1,1
1,1,1,10,9,5,9,10,1,1,1
1,1,9,5,0,0,0,5,9,1,1
1,10,7,0,0,0,0,0,6,10,1
1,9,0,0,0,0,0,0,0,9,1
10,7,0,0,0,0,0,0,0,6,10
1,9,0,0,0,0,0,0,0,9,1
1,10,7,0,0,0,0,0,6,10,1
1,1,9,8,0,0,0,8,9,1,1
1,1,1,10,9,8,9,10,1,1,1
1,1,1,1,1,10,1,1,1,1,1
endlayer

layer
1,1,1,1,1,10,1,1,1,1,1
1,1,1,10,9,5,9,10,1,1,1
1,1,9,5,0,0,0,5,9,1,1
1,10,7,0,0,0,0,0,6,10,1
1,9,0,0,0,0,0,0,0,9,1
10,7,0,0,0,0,0,0,0,6,10
1,9,0,0,0,0,0,0,0,9,1
1,10,7,0,0,0,0,0,6,10,1
1,1,9,8,0,0,0,8,9,1,1
1,1,1,10,9,8,9,10,1,1,1
1,1,1,1,1,10,1,1,1,1,1
endlayer

layer
1,1,1,1,1,10,1,1,1,1,1
1,1,1,10,9,5,9,10,1,1,1
1,1,9,5,0,0,0,5,9,1,1
1,10,7,0,0,0,0,0,6,10,1
1,9,0,0,0,0,0,0,0,9,1
10,7,0,0,0,0,0,0,0,6,10
1,9,0,0,0,0,0,0,0,9,1
1,10,7,0,0,0,0,0,6,10,1
1,1,9,8,0,0,0,8,9,1,1
1,1,1,10,9,8,9,10,1,1,1
1,1,1,1,1,10,1,1,1,1,1
endlayer

layer
1,1,1,1,1,10,1,1,1,1,1
1,1,1,10,9,5,9,10,1,1,1
1,1,9,5,0,0,0,5,9,1,1
1,10,7,0,0,0,0,0,6,10,1
1,9,0,0,0,0,0,0,0,9,1
10,7,0,0,0,0,0,0,0,6,10
1,9,0,0,0,0,0,0,0,9,1
1,10,7,0,0,0,0,0,6,10,1
1,1,9,8,0,0,0,8,9,1,1
1,1,1,10,9,8,9,10,1,1,1
1,1,1,1,1,10,1,1,1,1,1
endlayer

layer
1,1,1,1,1,10,1,1,1,1,1
1,1,1,10,9,5,9,10,1,1,1
1,1,9,5,0,0,0,5,9,1,1
1,10,7,0,0,0,0,0,6,10,1
1,9,0,0,0,0,0,0,0,9,1
10,7,0,0,0,0,0,0,0,6,10
1,9,0,0,0,0,0,0,0,9,1
1,10,7,0,0,0,0,0,6,10,1
1,1,9,8,0,0,0,8,9,1,1
1,1,1,10,9,8,9,10,1,1,1
1,1,1,1,1,10,1,1,1,1,1
endlayer

layer
1,1,1,1,1,10,1,1,1,1,1
1,1,1,10,9,5,9,10,1,1,1
1,1,9,5,0,0,0,5,9,1,1
1,10,7,0,0,0,0,0,6,10,1
1,9,0,0,0,0,0,0,0,9,1
10,7,0,0,0,0,0,0,0,6,10
1,9,0,0,0,0,0,0,0,9,1
1,10,7,0,0,0,0,0,6,10,1
1,1,9,8,0,0,0,8,9,1,1
1,1,1,10,9,8,9,10,1,1,1
1,1,1,1,1,10,1,1,1,1,1
endlayer

layer
1,1,1,1,1,10,1,1,1,1,1
1,1,1,10,9,5,9,10,1,1,1
1,1,9,5,0,0,0,5,9,1,1
1,10,7,0,0,0,0,0,6,10,1
1,9,0,0,0,0,0,0,0,9,1
10,7,0,0,0,0,0,0,0,6,10
1,9,0,0,0,0,0,0,0,9,1
1,10,7,0,0,0,0,0,6,10,1
1,1,9,8,0,0,0,8,9,1,1
1,1,1,10,9,8,9,10,1,1,1
1,1,1,1,1,10,1,1,1,1,1
endlayer

layer
1,1,1,1,1,10,1,1,1,1,1
1,1,1,10,9,5,9,10,1,1,1
1,1,9,5,0,0,0,5,9,1,1
1,10,7,0,0,0,0,0,6,10,1
1,9,0,0,0,0,0,0,0,9,1
10,7,0,0,0,0,0,0,0,6,10
1,9,0,0,0,0,0,0,0,9,1
1,10,7,0,0,0,0,0,6,10,1
1,1,9,8,0,0,0,8,9,1,1
1,1,1,10,9,8,9,10,1,1,1
1,1,1,1,1,10,1,1,1,1,1
endlayer

layer
1,1,1,1,1,10,1,1,1,1,1
1,1,1,10,9,5,9,10,1,1,1
1,1,9,5,0,0,0,5,9,1,1
1,10,7,0,0,0,0,0,6,10,1
1,9,0,0,0,0,0,0,0,9,1
10,7,0,0,0,0,0,0,0,6,10
1,9,0,0,0,0,0,0,0,9,1
1,10,7,0,0,0,0,0,6,10,1
1,1,9,8,0,0,0,8,9,1,1
1,1,1,10,9,8,9,10,1,1,1
1,1,1,1,1,10,1,1,1,1,1
endlayer

layer
1,1,1,1,1,10,1,1,1,1,1
1,1,1,10,9,5,9,10,1,1,1
1,1,9,5,0,0,0,5,9,1,1
1,10,7,0,0,0,0,0,6,10,1
1,9,0,0,0,0,0,0,0,9,1
10,7,0,0,0,0,0,0,0,6,10
1,9,0,0,0,0,0,0,0,9,1
1,10,7,0,0,0,0,0,6,10,1
1,1,9,8,0,0,0,8,9,1,1
1,1,1,10,9,8,9,10,1,1,1
1,1,1,1,1,10,1,1,1,1,1
endlayer

layer
1,1,1,1,1,11,1,1,1,1,1
1,1,1,11,9,5,9,11,1,1,1
1,1,9,5,0,0,0,5,9,1,1
1,11,7,0,0,0,0,0,6,11,1
1,9,0,0,0,0,0,0,0,9,1
11,7,0,0,0,0,0,0,0,6,11
1,9,0,0,0,0,0,0,0,9,1
1,11,7,0,0,0,0,0,6,11,1
1,1,9,8,0,0,0,8,9,1,1
1,1,1,11,9,8,9,11,1,1,1
1,1,1,1,1,11,1,1,1,1,1
endlayer

layer
1,1,1,1,2,2,2,1,1,1,1
1,1,2,2,2,5,2,2,2,1,1
1,2,2,0,0,0,0,0,2,2,1
1,2,0,0,0,0,0,0,0,2,1
2,2,0,0,0,0,0,0,0,2,2
2,0,0,0,0,0,0,0,0,0,2
2,2,0,0,0,0,0,0,0,2,2
1,2,0,0,0,0,0,0,0,2,1
1,2,2,0,0,0,0,0,2,2,1
1,1,2,2,2,0,2,2,2,1,1
1,1,1,1,2,2,2,1,1,1,1
endlayer

layer
1,1,1,1,12,2,12,1,1,1,1
1,1,13,2,2,2,2,2,13,1,1
1,13,2,0,0,0,0,0,2,13,1
1,2,0,0,0,0,0,0,0,2,1
15,2,0,0,0,0,0,0,0,2,14
2,2,0,0,0,0,0,0,0,2,2
15,2,0,0,0,0,0,0,0,2,14
1,2,0,0,0,0,0,0,0,2,1
1,13,2,0,0,0,0,0,2,13,1
1,1,13,2,2,2,2,2,13,1,1
1,1,1,1,16,2,16,1,1,1,1
endlayer

layer
1,1,1,1,1,1,1,1,1,1,1
1,1,1,2,2,2,2,2,1,1,1
1,1,2,0,0,0,0,0,2,1,1
1,2,0,0,0,0,0,0,0,2,1
1,2,0,0,0,0,0,0,0,2,1
1,2,0,0,0,0,0,0,0,2,1
1,2,0,0,0,0,0,0,0,2,1
1,2,0,0,0,0,0,0,0,2,1
1,1,2,0,0,0,0,0,2,1,1
1,1,1,2,2,2,2,2,1,1,1
1,1,1,1,1,1,1,1,1,1,1
endlayer

layer
1,1,1,1,1,1,1,1,1,1,1
1,1,1,1,1,12,1,1,1,1,1
1,1,1,2,2,2,2,2,1,1,1
1,1,2,0,0,0,0,0,2,1,1
1,1,2,0,0,0,0,0,2,1,1
1,15,2,0,0,0,0,0,2,14,1
1,1,2,0,0,0,0,0,2,1,1
1,1,2,0,0,0,0,0,2,1,1
1,1,1,2,2,2,2,2,1,1,1
1,1,1,1,1,16,1,1,1,1,1
1,1,1,1,1,1,1,1,1,1,1
endlayer

layer
1,1,1,1,1,1,1,1,1,1,1
1,1,1,1,1,1,1,1,1,1,1
1,1,1,1,1,13,1,1,1,1,1
1,1,1,13,2,2,2,13,1,1,1
1,1,1,2,2,2,2,2,1,1,1
1,1,13,2,2,17,2,2,13,1,1
1,1,1,2,2,2,2,2,1,1,1
1,1,1,13,2,2,2,13,1,1,1
1,1,1,1,1,13,1,1,1,1,1
1,1,1,1,1,1,1,1,1,1,1
1,1,1,1,1,1,1,1,1,1,1
endlayer

layer
1,1,1,1,1,1,1,1,1,1,1
1,1,1,1,1,1,1,1,1,1,1
1,1,1,1,1,1,1,1,1,1,1
1,1,1,1,1,1,1,1,1,1,1
1,1,1,1,13,2,13,1,1,1,1
1,1,1,1,2,17,2,1,1,1,1
1,1,1,1,13,2,13,1,1,1,1
1,1,1,1,1,1,1,1,1,1,1
1,1,1,1,1,1,1,1,1,1,1
1,1,1,1,1,1,1,1,1,1,1
1,1,1,1,1,1,1,1,1,1,1
endlayer



