# Sky Islet - Main
# Created by Ruins mod version 16.8 Ingame Parser
# authoring Player: Jordan_Greywolf
# Created for MC 1.12.1: 9 Sep 2017
# Last Updated: 8 Dec 2018
# Special thanks to BOYSLITTLE and QuarterAnimal for bug report and teBlock fix.

weight=1
embed_into_distance=19

unacceptable_target_blocks=flowing_water,water,flowing_lava,lava,command_block

dimensions=19,17,17
allowable_overhang=0
max_leveling=12
leveling_buffer=-1
preserve_water=0
preserve_lava=0
preserve_plants=1

rule1=0,100,preserveBlock

# Irregular Stone Edging
rule2=0,100,minecraft:stone-0,3*preserveBlock

# Main Stone Body
rule3=0,100,8*minecraft:stone-0,minecraft:sand,minecraft:gravel,minecraft:clay,minecraft:concrete_powder-8

# Hidden Ore Pocket
rule4=0,100,minecraft:emerald_ore-0,minecraft:gold_ore-0,minecraft:lapis_ore-0

# Irregular Dirt Edging
rule5=0,100,minecraft:grass,2*preserveBlock

rule6=0,100,minecraft:dirt-0

# Hidden Clay Pocket
rule7=0,100,minecraft:clay-0

# Self-Triggering Command Blocks
rule8=0,100,CommandBlock:RUINSTRIGGER /testruin TP_SkyIslet2 ~-6 ~4 ~-4:@,CommandBlock:RUINSTRIGGER /testruin TP_SkyIslet2 ~-8 ~4 ~4:@,CommandBlock:RUINSTRIGGER /testruin TP_SkyIslet2 ~-10 ~3 ~-3:@,CommandBlock:RUINSTRIGGER /testruin TP_SkyIslet2 ~-7 ~3 ~2:@,CommandBlock:RUINSTRIGGER /testruin TP_SkyIslet2 ~-13 ~4 ~1:@

rule9=0,100,CommandBlock:RUINSTRIGGER /testruin TP_SkyIslet2 ~0 ~4 ~-10:@,CommandBlock:RUINSTRIGGER /testruin TP_SkyIslet2 ~-8 ~4 ~-6:@,CommandBlock:RUINSTRIGGER /testruin TP_SkyIslet2 ~4 ~4 ~-8:@,CommandBlock:RUINSTRIGGER /testruin TP_SkyIslet2 ~-4 ~3 ~-5:@,CommandBlock:RUINSTRIGGER /testruin TP_SkyIslet2 ~3 ~3 ~-10:@

rule10=0,100,CommandBlock:RUINSTRIGGER /testruin TP_Tree_GreatGnarledOak ~0 ~4 ~0:@,CommandBlock:RUINSTRIGGER /testruin TP_SkyIslet2 ~0 ~6 ~0:@,CommandBlock:RUINSTRIGGER /testruin TP_CrystalCavern_Adventure ~0 ~12 ~0:@,CommandBlock:RUINSTRIGGER /testruin TP_Cave_WaterHollow_Adventure ~0 ~12 ~0:@,CommandBlock:RUINSTRIGGER /testruin TP_Cave_LavaHollow_Adventure ~0 ~12 ~0:@,CommandBlock:RUINSTRIGGER /testruin TP_ForestPool ~0 ~4 ~0:@,CommandBlock:RUINSTRIGGER /testruin TP_Decor_Garden ~0 ~4 ~0:@

rule11=0,100,CommandBlock:RUINSTRIGGER /testruin TP_SkyIslet2 ~0 ~4 ~10:@,CommandBlock:RUINSTRIGGER /testruin TP_SkyIslet2 ~-4 ~4 ~8:@,CommandBlock:RUINSTRIGGER /testruin TP_SkyIslet2 ~3 ~4 ~7:@,CommandBlock:RUINSTRIGGER /testruin TP_SkyIslet2 ~-3 ~3 ~5:@,CommandBlock:RUINSTRIGGER /testruin TP_SkyIslet2 ~5 ~3 ~9:@

rule12=0,100,CommandBlock:RUINSTRIGGER /testruin TP_SkyIslet2 ~8 ~4 ~-4:@,CommandBlock:RUINSTRIGGER /testruin TP_SkyIslet2 ~4 ~4 ~4:@,CommandBlock:RUINSTRIGGER /testruin TP_SkyIslet2 ~6 ~3 ~-6:@,CommandBlock:RUINSTRIGGER /testruin TP_SkyIslet2 ~10 ~3 ~4:@,CommandBlock:RUINSTRIGGER /testruin TP_SkyIslet2 ~12 ~4 ~-1:@

# Regular Grass
rule13=0,100,minecraft:grass-0

# Tallgrass/Ferns/Bushes/
rule14=0,100,2*minecraft:tallgrass-2,2*minecraft:tallgrass-1,2*preserveBlock,minecraft:leaves-4

# Foliage Feature (updated to use teBlock for randomization)
rule15=0,100,minecraft:red_flower-0,minecraft:sapling-0,minecraft:tallgrass-2,minecraft:tallgrass-1,teBlock;command_block;{Command:"RUINSTRIGGER /testruin TP_Tree_GnarledOak ~0 ~-2 ~0"},teBlock;command_block;{Command:"RUINSTRIGGER /testruin TP_Tree_GnarledOak ~0 ~-1 ~0 2"},teBlock;command_block;{Command:"RUINSTRIGGER /testruin TP_Obsidian_Geode ~0 ~15 ~0 2"}

layer
1,1,1,1,1,1,1,1,1,1,1,1,1,1,1,1,1
1,1,1,1,1,1,1,1,1,1,1,1,1,1,1,1,1
1,1,1,1,1,1,1,1,1,1,1,1,1,1,1,1,1
1,1,1,1,1,1,1,1,1,1,1,1,1,1,1,1,1
1,1,1,1,1,1,1,1,1,1,1,1,1,1,1,1,1
1,1,1,1,1,1,1,1,1,1,1,1,1,1,1,1,1
1,1,1,1,1,1,1,1,1,1,1,1,1,1,1,1,1
1,1,1,1,1,1,1,1,1,1,1,1,1,1,1,1,1
1,1,1,1,1,1,1,1,2,1,1,1,1,1,1,1,1
1,1,1,1,1,1,1,1,1,1,1,1,1,1,1,1,1
1,1,1,1,1,1,1,1,1,1,1,1,1,1,1,1,1
1,1,1,1,1,1,1,1,1,1,1,1,1,1,1,1,1
1,1,1,1,1,1,1,1,1,1,1,1,1,1,1,1,1
1,1,1,1,1,1,1,1,1,1,1,1,1,1,1,1,1
1,1,1,1,1,1,1,1,1,1,1,1,1,1,1,1,1
1,1,1,1,1,1,1,1,1,1,1,1,1,1,1,1,1
1,1,1,1,1,1,1,1,1,1,1,1,1,1,1,1,1
endlayer

layer
1,1,1,1,1,1,1,1,1,1,1,1,1,1,1,1,1
1,1,1,1,1,1,1,1,1,1,1,1,1,1,1,1,1
1,1,1,1,1,1,1,1,1,1,1,1,1,1,1,1,1
1,1,1,1,1,1,1,1,1,1,1,1,1,1,1,1,1
1,1,1,1,1,1,1,1,1,1,1,1,1,1,1,1,1
1,1,1,1,1,1,1,1,1,1,1,1,1,1,1,1,1
1,1,1,1,1,1,1,1,1,1,1,1,1,1,1,1,1
1,1,1,1,1,1,1,1,1,1,1,1,1,1,1,1,1
1,1,1,1,1,1,1,1,3,1,1,1,1,1,1,1,1
1,1,1,1,1,1,1,1,1,1,1,1,1,1,1,1,1
1,1,1,1,1,1,1,1,1,1,1,1,1,1,1,1,1
1,1,1,1,1,1,1,1,1,1,1,1,1,1,1,1,1
1,1,1,1,1,1,1,1,1,1,1,1,1,1,1,1,1
1,1,1,1,1,1,1,1,1,1,1,1,1,1,1,1,1
1,1,1,1,1,1,1,1,1,1,1,1,1,1,1,1,1
1,1,1,1,1,1,1,1,1,1,1,1,1,1,1,1,1
1,1,1,1,1,1,1,1,1,1,1,1,1,1,1,1,1
endlayer

layer
1,1,1,1,1,1,1,1,1,1,1,1,1,1,1,1,1
1,1,1,1,1,1,1,1,1,1,1,1,1,1,1,1,1
1,1,1,1,1,1,1,1,1,1,1,1,1,1,1,1,1
1,1,1,1,1,1,1,1,1,1,1,1,1,1,1,1,1
1,1,1,1,1,1,1,1,1,1,1,1,1,1,1,1,1
1,1,1,1,1,1,1,1,1,1,1,1,1,1,1,1,1
1,1,1,1,1,1,1,1,1,1,1,1,1,1,1,1,1
1,1,1,1,1,1,1,1,1,1,1,1,1,1,1,1,1
1,1,1,1,1,1,1,2,3,1,1,1,1,1,1,1,1
1,1,1,1,1,1,1,1,1,1,1,1,1,1,1,1,1
1,1,1,1,1,1,1,1,1,1,1,1,1,1,1,1,1
1,1,1,1,1,1,1,1,1,1,1,1,1,1,1,1,1
1,1,1,1,1,1,1,1,1,1,1,1,1,1,1,1,1
1,1,1,1,1,1,1,1,1,1,1,1,1,1,1,1,1
1,1,1,1,1,1,1,1,1,1,1,1,1,1,1,1,1
1,1,1,1,1,1,1,1,1,1,1,1,1,1,1,1,1
1,1,1,1,1,1,1,1,1,1,1,1,1,1,1,1,1
endlayer

layer
1,1,1,1,1,1,1,1,1,1,1,1,1,1,1,1,1
1,1,1,1,1,1,1,1,1,1,1,1,1,1,1,1,1
1,1,1,1,1,1,1,1,1,1,1,1,1,1,1,1,1
1,1,1,1,1,1,1,1,1,1,1,1,1,1,1,1,1
1,1,1,1,1,1,1,1,1,1,1,1,1,1,1,1,1
1,1,1,1,1,1,1,1,1,1,1,1,1,1,1,1,1
1,1,1,1,1,1,1,1,1,1,1,1,1,1,1,1,1
1,1,1,1,1,1,1,1,2,1,1,1,1,1,1,1,1
1,1,1,1,1,1,1,3,3,1,1,1,1,1,1,1,1
1,1,1,1,1,1,1,1,1,1,1,1,1,1,1,1,1
1,1,1,1,1,1,1,1,1,1,1,1,1,1,1,1,1
1,1,1,1,1,1,1,1,1,1,1,1,1,1,1,1,1
1,1,1,1,1,1,1,1,1,1,1,1,1,1,1,1,1
1,1,1,1,1,1,1,1,1,1,1,1,1,1,1,1,1
1,1,1,1,1,1,1,1,1,1,1,1,1,1,1,1,1
1,1,1,1,1,1,1,1,1,1,1,1,1,1,1,1,1
1,1,1,1,1,1,1,1,1,1,1,1,1,1,1,1,1
endlayer

layer
1,1,1,1,1,1,1,1,1,1,1,1,1,1,1,1,1
1,1,1,1,1,1,1,1,1,1,1,1,1,1,1,1,1
1,1,1,1,1,1,1,1,1,1,1,1,1,1,1,1,1
1,1,1,1,1,1,1,1,1,1,1,1,1,1,1,1,1
1,1,1,1,1,1,1,1,1,1,1,1,1,1,1,1,1
1,1,1,1,1,1,1,1,1,1,1,1,1,1,1,1,1
1,1,1,1,1,1,1,1,1,1,1,1,1,1,1,1,1
1,1,1,1,1,1,1,1,3,1,1,1,1,1,1,1,1
1,1,1,1,1,1,1,3,3,2,1,1,1,1,1,1,1
1,1,1,1,1,1,1,1,1,1,1,1,1,1,1,1,1
1,1,1,1,1,1,1,1,1,1,1,1,1,1,1,1,1
1,1,1,1,1,1,1,1,1,1,1,1,1,1,1,1,1
1,1,1,1,1,1,1,1,1,1,1,1,1,1,1,1,1
1,1,1,1,1,1,1,1,1,1,1,1,1,1,1,1,1
1,1,1,1,1,1,1,1,1,1,1,1,1,1,1,1,1
1,1,1,1,1,1,1,1,1,1,1,1,1,1,1,1,1
1,1,1,1,1,1,1,1,1,1,1,1,1,1,1,1,1
endlayer

layer
1,1,1,1,1,1,1,1,1,1,1,1,1,1,1,1,1
1,1,1,1,1,1,1,1,1,1,1,1,1,1,1,1,1
1,1,1,1,1,1,1,1,1,1,1,1,1,1,1,1,1
1,1,1,1,1,1,1,1,1,1,1,1,1,1,1,1,1
1,1,1,1,1,1,1,1,1,1,1,1,1,1,1,1,1
1,1,1,1,1,1,1,1,1,1,1,1,1,1,1,1,1
1,1,1,1,1,1,1,1,1,1,1,1,1,1,1,1,1
1,1,1,1,1,1,1,1,3,1,1,1,1,1,1,1,1
1,1,1,1,1,1,1,3,3,3,1,1,1,1,1,1,1
1,1,1,1,1,1,1,1,2,1,1,1,1,1,1,1,1
1,1,1,1,1,1,1,1,1,1,1,1,1,1,1,1,1
1,1,1,1,1,1,1,1,1,1,1,1,1,1,1,1,1
1,1,1,1,1,1,1,1,1,1,1,1,1,1,1,1,1
1,1,1,1,1,1,1,1,1,1,1,1,1,1,1,1,1
1,1,1,1,1,1,1,1,1,1,1,1,1,1,1,1,1
1,1,1,1,1,1,1,1,1,1,1,1,1,1,1,1,1
1,1,1,1,1,1,1,1,1,1,1,1,1,1,1,1,1
endlayer

layer
1,1,1,1,1,1,1,1,1,1,1,1,1,1,1,1,1
1,1,1,1,1,1,1,1,1,1,1,1,1,1,1,1,1
1,1,1,1,1,1,1,1,1,1,1,1,1,1,1,1,1
1,1,1,1,1,1,1,1,1,1,1,1,1,1,1,1,1
1,1,1,1,1,1,1,1,1,1,1,1,1,1,1,1,1
1,1,1,1,1,1,1,1,1,1,1,1,1,1,1,1,1
1,1,1,1,1,1,1,1,1,1,1,1,1,1,1,1,1
1,1,1,1,1,1,1,1,3,1,1,1,1,1,1,1,1
1,1,1,1,1,1,1,3,3,3,1,1,1,1,1,1,1
1,1,1,1,1,1,1,1,3,1,1,1,1,1,1,1,1
1,1,1,1,1,1,1,1,1,1,1,1,1,1,1,1,1
1,1,1,1,1,1,1,1,1,1,1,1,1,1,1,1,1
1,1,1,1,1,1,1,1,1,1,1,1,1,1,1,1,1
1,1,1,1,1,1,1,1,1,1,1,1,1,1,1,1,1
1,1,1,1,1,1,1,1,1,1,1,1,1,1,1,1,1
1,1,1,1,1,1,1,1,1,1,1,1,1,1,1,1,1
1,1,1,1,1,1,1,1,1,1,1,1,1,1,1,1,1
endlayer

layer
1,1,1,1,1,1,1,1,1,1,1,1,1,1,1,1,1
1,1,1,1,1,1,1,1,1,1,1,1,1,1,1,1,1
1,1,1,1,1,1,1,1,1,1,1,1,1,1,1,1,1
1,1,1,1,1,1,1,1,1,1,1,1,1,1,1,1,1
1,1,1,1,1,1,1,1,1,1,1,1,1,1,1,1,1
1,1,1,1,1,1,1,1,1,1,1,1,1,1,1,1,1
1,1,1,1,1,1,1,2,2,2,1,1,1,1,1,1,1
1,1,1,1,1,1,2,3,3,3,2,1,1,1,1,1,1
1,1,1,1,1,1,2,3,4,3,2,1,1,1,1,1,1
1,1,1,1,1,1,2,3,3,3,2,1,1,1,1,1,1
1,1,1,1,1,1,1,2,2,2,1,1,1,1,1,1,1
1,1,1,1,1,1,1,1,1,1,1,1,1,1,1,1,1
1,1,1,1,1,1,1,1,1,1,1,1,1,1,1,1,1
1,1,1,1,1,1,1,1,1,1,1,1,1,1,1,1,1
1,1,1,1,1,1,1,1,1,1,1,1,1,1,1,1,1
1,1,1,1,1,1,1,1,1,1,1,1,1,1,1,1,1
1,1,1,1,1,1,1,1,1,1,1,1,1,1,1,1,1
endlayer

layer
1,1,1,1,1,1,1,1,1,1,1,1,1,1,1,1,1
1,1,1,1,1,1,1,1,1,1,1,1,1,1,1,1,1
1,1,1,1,1,1,1,1,1,1,1,1,1,1,1,1,1
1,1,1,1,1,1,1,1,1,1,1,1,1,1,1,1,1
1,1,1,1,1,1,1,1,1,1,1,1,1,1,1,1,1
1,1,1,1,1,1,1,1,1,1,1,1,1,1,1,1,1
1,1,1,1,1,1,1,3,3,3,1,1,1,1,1,1,1
1,1,1,1,1,1,3,3,3,3,3,1,1,1,1,1,1
1,1,1,1,1,1,3,3,4,3,3,1,1,1,1,1,1
1,1,1,1,1,1,3,3,3,3,3,1,1,1,1,1,1
1,1,1,1,1,1,1,3,3,3,1,1,1,1,1,1,1
1,1,1,1,1,1,1,1,1,1,1,1,1,1,1,1,1
1,1,1,1,1,1,1,1,1,1,1,1,1,1,1,1,1
1,1,1,1,1,1,1,1,1,1,1,1,1,1,1,1,1
1,1,1,1,1,1,1,1,1,1,1,1,1,1,1,1,1
1,1,1,1,1,1,1,1,1,1,1,1,1,1,1,1,1
1,1,1,1,1,1,1,1,1,1,1,1,1,1,1,1,1
endlayer

layer
1,1,1,1,1,1,1,1,1,1,1,1,1,1,1,1,1
1,1,1,1,1,1,1,1,1,1,1,1,1,1,1,1,1
1,1,1,1,1,1,1,1,1,1,1,1,1,1,1,1,1
1,1,1,1,1,1,1,1,1,1,1,1,1,1,1,1,1
1,1,1,1,1,1,1,1,1,1,1,1,1,1,1,1,1
1,1,1,1,1,1,1,1,2,1,1,1,1,1,1,1,1
1,1,1,1,1,1,2,3,3,3,2,1,1,1,1,1,1
1,1,1,1,1,1,3,3,4,3,3,1,1,1,1,1,1
1,1,1,1,1,2,3,4,4,4,3,2,1,1,1,1,1
1,1,1,1,1,1,3,3,4,3,3,1,1,1,1,1,1
1,1,1,1,1,1,2,3,3,3,2,1,1,1,1,1,1
1,1,1,1,1,1,1,1,2,1,1,1,1,1,1,1,1
1,1,1,1,1,1,1,1,1,1,1,1,1,1,1,1,1
1,1,1,1,1,1,1,1,1,1,1,1,1,1,1,1,1
1,1,1,1,1,1,1,1,1,1,1,1,1,1,1,1,1
1,1,1,1,1,1,1,1,1,1,1,1,1,1,1,1,1
1,1,1,1,1,1,1,1,1,1,1,1,1,1,1,1,1
endlayer

layer
1,1,1,1,1,1,1,1,1,1,1,1,1,1,1,1,1
1,1,1,1,1,1,1,1,1,1,1,1,1,1,1,1,1
1,1,1,1,1,1,1,1,1,1,1,1,1,1,1,1,1
1,1,1,1,1,1,1,1,1,1,1,1,1,1,1,1,1
1,1,1,1,1,1,1,1,1,1,1,1,1,1,1,1,1
1,1,1,1,1,1,1,2,3,2,1,1,1,1,1,1,1
1,1,1,1,1,1,3,3,3,3,3,1,1,1,1,1,1
1,1,1,1,1,2,3,3,3,3,3,2,1,1,1,1,1
1,1,1,1,1,3,3,3,4,3,3,3,1,1,1,1,1
1,1,1,1,1,2,3,3,3,3,3,2,1,1,1,1,1
1,1,1,1,1,1,3,3,3,3,3,1,1,1,1,1,1
1,1,1,1,1,1,1,2,3,2,1,1,1,1,1,1,1
1,1,1,1,1,1,1,1,1,1,1,1,1,1,1,1,1
1,1,1,1,1,1,1,1,1,1,1,1,1,1,1,1,1
1,1,1,1,1,1,1,1,1,1,1,1,1,1,1,1,1
1,1,1,1,1,1,1,1,1,1,1,1,1,1,1,1,1
1,1,1,1,1,1,1,1,1,1,1,1,1,1,1,1,1
endlayer

layer
1,1,1,1,1,1,1,1,1,1,1,1,1,1,1,1,1
1,1,1,1,1,1,1,1,1,1,1,1,1,1,1,1,1
1,1,1,1,1,1,1,1,1,1,1,1,1,1,1,1,1
1,1,1,1,1,1,1,1,1,1,1,1,1,1,1,1,1
1,1,1,1,1,1,1,2,2,2,1,1,1,1,1,1,1
1,1,1,1,1,1,2,3,3,3,2,1,1,1,1,1,1
1,1,1,1,1,2,3,3,3,3,3,2,1,1,1,1,1
1,1,1,1,2,3,3,3,3,3,3,3,2,1,1,1,1
1,1,1,1,2,3,3,3,3,3,3,3,2,1,1,1,1
1,1,1,1,2,3,3,3,3,3,3,3,2,1,1,1,1
1,1,1,1,1,2,3,3,3,3,3,2,1,1,1,1,1
1,1,1,1,1,1,2,3,3,3,2,1,1,1,1,1,1
1,1,1,1,1,1,1,2,2,2,1,1,1,1,1,1,1
1,1,1,1,1,1,1,1,1,1,1,1,1,1,1,1,1
1,1,1,1,1,1,1,1,1,1,1,1,1,1,1,1,1
1,1,1,1,1,1,1,1,1,1,1,1,1,1,1,1,1
1,1,1,1,1,1,1,1,1,1,1,1,1,1,1,1,1
endlayer

layer
1,1,1,1,1,1,1,1,1,1,1,1,1,1,1,1,1
1,1,1,1,1,1,1,1,1,1,1,1,1,1,1,1,1
1,1,1,1,1,1,1,1,1,1,1,1,1,1,1,1,1
1,1,1,1,1,1,1,2,2,2,1,1,1,1,1,1,1
1,1,1,1,1,1,2,3,3,3,2,1,1,1,1,1,1
1,1,1,1,1,2,3,3,3,3,3,2,1,1,1,1,1
1,1,1,1,2,3,3,3,3,3,3,3,2,1,1,1,1
1,1,1,2,3,3,3,3,3,3,3,3,3,2,1,1,1
1,1,1,2,3,3,3,3,3,3,3,3,3,2,1,1,1
1,1,1,2,3,3,3,3,3,3,3,3,3,2,1,1,1
1,1,1,1,2,3,3,3,3,3,3,3,2,1,1,1,1
1,1,1,1,1,2,3,3,3,3,3,2,1,1,1,1,1
1,1,1,1,1,1,2,3,3,3,2,1,1,1,1,1,1
1,1,1,1,1,1,1,2,2,2,1,1,1,1,1,1,1
1,1,1,1,1,1,1,1,1,1,1,1,1,1,1,1,1
1,1,1,1,1,1,1,1,1,1,1,1,1,1,1,1,1
1,1,1,1,1,1,1,1,1,1,1,1,1,1,1,1,1
endlayer

layer
1,1,1,1,1,1,1,1,1,1,1,1,1,1,1,1,1
1,1,1,1,1,1,1,1,1,1,1,1,1,1,1,1,1
1,1,1,1,1,1,1,2,2,2,1,1,1,1,1,1,1
1,1,1,1,1,2,3,3,3,3,3,2,1,1,1,1,1
1,1,1,1,2,3,3,3,3,3,3,3,2,1,1,1,1
1,1,1,2,3,3,3,3,3,3,3,3,3,2,1,1,1
1,1,1,3,3,3,3,3,3,3,3,3,3,3,1,1,1
1,1,2,3,3,3,3,3,3,3,3,3,3,3,2,1,1
1,1,2,3,3,3,3,3,3,3,3,3,3,3,2,1,1
1,1,2,3,3,3,3,3,3,3,3,3,3,3,2,1,1
1,1,1,3,3,3,3,3,3,3,3,3,3,3,1,1,1
1,1,1,2,3,3,3,3,3,3,3,3,3,2,1,1,1
1,1,1,1,2,3,3,3,3,3,3,3,2,1,1,1,1
1,1,1,1,1,2,3,3,3,3,3,2,1,1,1,1,1
1,1,1,1,1,1,1,2,2,2,1,1,1,1,1,1,1
1,1,1,1,1,1,1,1,1,1,1,1,1,1,1,1,1
1,1,1,1,1,1,1,1,1,1,1,1,1,1,1,1,1
endlayer

layer
1,1,1,1,1,1,1,1,1,1,1,1,1,1,1,1,1
1,1,1,1,1,1,1,5,5,5,1,1,1,1,1,1,1
1,1,1,1,1,5,5,6,6,6,5,5,1,1,1,1,1
1,1,1,1,5,6,6,6,6,6,6,6,5,1,1,1,1
1,1,1,5,6,6,6,6,6,6,6,6,6,5,1,1,1
1,1,5,6,6,6,6,6,6,6,6,6,6,6,5,1,1
1,1,5,6,6,6,6,6,7,6,6,6,6,6,5,1,1
1,5,6,6,6,6,6,7,8,7,6,6,6,6,6,5,1
1,5,6,6,6,6,7,11,10,9,7,6,6,6,6,5,1
1,5,6,6,6,6,6,7,12,7,6,6,6,6,6,5,1
1,1,5,6,6,6,6,6,7,6,6,6,6,6,5,1,1
1,1,5,6,6,6,6,6,6,6,6,6,6,6,5,1,1
1,1,1,5,6,6,6,6,6,6,6,6,6,5,1,1,1
1,1,1,1,5,6,6,6,6,6,6,6,5,1,1,1,1
1,1,1,1,1,5,5,6,6,6,5,5,1,1,1,1,1
1,1,1,1,1,1,1,5,5,5,1,1,1,1,1,1,1
1,1,1,1,1,1,1,1,1,1,1,1,1,1,1,1,1
endlayer

layer
1,1,1,1,1,1,1,5,5,5,1,1,1,1,1,1,1
1,1,1,1,1,1,5,13,13,13,5,5,1,1,1,1,1
1,1,1,1,5,13,13,6,6,6,13,13,5,1,1,1,1
1,1,1,5,13,6,6,6,6,6,6,6,13,5,1,1,1
1,1,5,13,6,6,6,6,6,6,6,6,6,13,5,1,1
1,5,13,6,6,6,6,6,6,6,6,6,6,6,13,5,1
1,5,13,6,6,6,6,6,6,6,6,6,6,6,13,5,1
5,13,6,6,6,6,6,6,7,6,6,6,6,6,6,13,5
5,13,6,6,6,6,6,7,7,7,6,6,6,6,6,13,5
5,13,6,6,6,6,6,6,7,6,6,6,6,6,6,13,5
1,5,13,6,6,6,6,6,6,6,6,6,6,6,13,5,1
1,5,13,6,6,6,6,6,6,6,6,6,6,6,13,5,1
1,1,5,13,6,6,6,6,6,6,6,6,6,13,5,1,1
1,1,1,5,13,6,6,6,6,6,6,6,13,5,1,1,1
1,1,1,1,5,13,13,6,6,6,13,13,5,1,1,1,1
1,1,1,1,1,5,5,13,13,13,5,5,1,1,1,1,1
1,1,1,1,1,1,1,5,5,5,1,1,1,1,1,1,1
endlayer

layer
1,1,1,1,1,1,1,1,14,14,1,1,1,1,1,1,1
1,1,1,1,1,1,14,14,14,1,14,1,1,1,1,1,1
1,1,1,1,1,14,14,13,13,13,14,14,14,1,1,1,1
1,1,1,14,14,13,13,13,13,13,13,13,14,14,1,1,1
1,1,14,1,13,13,13,6,6,6,13,13,13,14,1,1,1
1,14,14,13,13,13,6,6,6,6,6,13,13,13,14,14,1
1,14,14,13,13,6,6,6,6,6,6,6,13,13,14,14,1
14,14,13,13,6,6,6,6,6,6,6,6,6,13,13,14,14
14,14,13,13,6,6,6,6,6,6,6,6,6,13,13,14,14
14,14,13,13,6,6,6,6,6,6,6,6,6,13,13,1,14
1,14,14,13,13,6,6,6,6,6,6,6,13,13,14,14,1
1,14,14,13,13,13,6,6,6,6,6,13,13,13,14,14,1
1,1,14,14,13,13,13,6,6,6,13,13,13,14,14,1,1
1,1,1,14,14,13,13,13,13,13,13,13,14,14,1,1,1
1,1,1,1,14,14,14,13,13,13,14,14,14,1,1,1,1
1,1,1,1,1,14,14,14,14,1,1,14,1,1,1,1,1
1,1,1,1,1,1,1,14,1,14,1,1,1,1,1,1,1
endlayer

layer
1,1,1,1,1,1,1,1,1,1,1,1,1,1,1,1,1
1,1,1,1,1,1,1,1,1,1,1,1,1,1,1,1,1
1,1,1,1,1,1,1,14,14,14,1,1,1,1,1,1,1
1,1,1,1,1,1,14,14,15,14,14,14,1,1,1,1,1
1,1,1,1,14,14,14,13,13,13,14,14,15,1,1,1,1
1,1,1,14,14,1,13,13,13,13,13,14,14,14,1,1,1
1,1,1,14,1,13,13,13,13,13,13,13,14,14,1,1,1
1,1,14,14,13,13,13,13,13,13,13,13,13,14,14,1,1
1,1,14,14,13,13,13,13,13,13,13,13,13,14,14,1,1
1,1,14,14,13,13,13,13,13,13,13,13,13,14,14,1,1
1,1,1,14,14,13,13,13,13,13,13,13,14,14,1,1,1
1,1,1,14,15,14,13,13,13,13,13,14,1,14,1,1,1
1,1,1,1,14,14,14,13,13,13,14,14,14,1,1,1,1
1,1,1,1,1,14,14,14,14,14,14,15,1,1,1,1,1
1,1,1,1,1,1,1,14,14,14,1,1,1,1,1,1,1
1,1,1,1,1,1,1,1,1,1,1,1,1,1,1,1,1
1,1,1,1,1,1,1,1,1,1,1,1,1,1,1,1,1
endlayer

layer
1,1,1,1,1,1,1,1,1,1,1,1,1,1,1,1,1
1,1,1,1,1,1,1,1,1,1,1,1,1,1,1,1,1
1,1,1,1,1,1,1,1,1,1,1,1,1,1,1,1,1
1,1,1,1,1,1,1,1,1,1,1,1,1,1,1,1,1
1,1,1,1,1,1,1,14,14,14,1,1,1,1,1,1,1
1,1,1,1,1,1,14,14,14,14,14,1,1,1,1,1,1
1,1,1,1,1,14,14,14,14,14,14,14,1,1,1,1,1
1,1,1,1,14,15,14,14,14,14,14,15,14,1,1,1,1
1,1,1,1,14,14,14,14,14,14,14,14,14,1,1,1,1
1,1,1,1,14,14,14,14,14,14,14,14,14,1,1,1,1
1,1,1,1,1,14,14,14,14,14,14,14,1,1,1,1,1
1,1,1,1,1,1,14,14,15,14,14,1,1,1,1,1,1
1,1,1,1,1,1,1,14,14,14,1,1,1,1,1,1,1
1,1,1,1,1,1,1,1,1,1,1,1,1,1,1,1,1
1,1,1,1,1,1,1,1,1,1,1,1,1,1,1,1,1
1,1,1,1,1,1,1,1,1,1,1,1,1,1,1,1,1
1,1,1,1,1,1,1,1,1,1,1,1,1,1,1,1,1
endlayer

