# Sky Islet #2 (Support Fragment)
# Created by Ruins mod version 16.8 Ingame Parser
# authoring Player: Jordan_Greywolf
# Created for MC 1.12.1: 9 Sep 2017
# Last Updated: 8 Dec 2018
# Special thanks to BOYSLITTLE and QuarterAnimal for error report and fix.

weight=1
embed_into_distance=16
acceptable_target_blocks=
unacceptable_target_blocks=flowing_water,water,flowing_lava,lava,command_block

dimensions=16,7,7
allowable_overhang=0
max_leveling=0
leveling_buffer=-1
preserve_water=0
preserve_lava=0

rule1=0,100,preserveBlock

# Irregular Stone Edge
rule2=0,100,minecraft:stone-0,preserveBlock,preserveBlock,preserveBlock

# Main Stone Body
rule3=0,100,8*minecraft:stone-0,minecraft:clay

# Irregular Dirt Edge
rule4=0,100,minecraft:dirt,preserveBlock,preserveBlock

# Main Dirt Body
rule5=0,100,minecraft:dirt-0

# Irregular Grass Edge
rule6=0,100,minecraft:grass,preserveBlock

rule7=0,100,minecraft:grass-0

# (Placeholder for random foliage if this is a stand-alone island feature)
rule8=0,100,preserveBlock

# Random Special Feature (note: teBlock used because Command Block structure doesn't mix with non-CB blocks for randomization)
rule9=0,100,teBlock;command_block;{Command:"RUINSTRIGGER /testruin TP_Tree_GnarledOak ~0 ~0 ~0 2"},minecraft:sapling-0,minecraft:grass,minecraft:leaves-4,preserveBlock,preserveBlock,preserveBlock

layer
1,1,1,1,1,1,1
1,1,1,1,1,1,1
1,1,1,1,1,1,1
1,1,1,2,1,1,1
1,1,1,1,1,1,1
1,1,1,1,1,1,1
1,1,1,1,1,1,1
endlayer

layer
1,1,1,1,1,1,1
1,1,1,1,1,1,1
1,1,1,1,1,1,1
1,1,1,3,1,1,1
1,1,1,1,1,1,1
1,1,1,1,1,1,1
1,1,1,1,1,1,1
endlayer

layer
1,1,1,1,1,1,1
1,1,1,1,1,1,1
1,1,1,1,1,1,1
1,1,2,3,1,1,1
1,1,1,2,1,1,1
1,1,1,1,1,1,1
1,1,1,1,1,1,1
endlayer

layer
1,1,1,1,1,1,1
1,1,1,1,1,1,1
1,1,1,2,1,1,1
1,1,3,3,2,1,1
1,1,1,3,1,1,1
1,1,1,1,1,1,1
1,1,1,1,1,1,1
endlayer

layer
1,1,1,1,1,1,1
1,1,1,1,1,1,1
1,1,1,3,1,1,1
1,1,3,3,3,1,1
1,1,1,3,1,1,1
1,1,1,1,1,1,1
1,1,1,1,1,1,1
endlayer

layer
1,1,1,1,1,1,1
1,1,1,1,1,1,1
1,1,1,3,1,1,1
1,1,3,3,3,1,1
1,1,1,3,1,1,1
1,1,1,1,1,1,1
1,1,1,1,1,1,1
endlayer

layer
1,1,1,1,1,1,1
1,1,1,1,1,1,1
1,1,1,3,1,1,1
1,1,3,3,3,1,1
1,1,1,3,1,1,1
1,1,1,1,1,1,1
1,1,1,1,1,1,1
endlayer

layer
1,1,1,1,1,1,1
1,1,1,1,1,1,1
1,1,1,3,1,1,1
1,1,3,3,3,1,1
1,1,1,3,2,1,1
1,1,1,1,1,1,1
1,1,1,1,1,1,1
endlayer

layer
1,1,1,1,1,1,1
1,1,1,1,1,1,1
1,1,1,3,1,1,1
1,1,3,3,3,1,1
1,1,1,3,3,1,1
1,1,1,1,1,1,1
1,1,1,1,1,1,1
endlayer

layer
1,1,1,1,1,1,1
1,1,1,1,1,1,1
1,1,1,3,1,1,1
1,1,3,3,3,1,1
1,1,1,3,3,1,1
1,1,1,1,1,1,1
1,1,1,1,1,1,1
endlayer

layer
1,1,1,1,1,1,1
1,1,1,1,1,1,1
1,1,2,3,1,1,1
1,1,3,3,3,1,1
1,1,1,3,3,1,1
1,1,1,1,1,1,1
1,1,1,1,1,1,1
endlayer

layer
1,1,1,1,1,1,1
1,1,1,2,1,1,1
1,2,3,3,2,1,1
1,2,3,3,3,2,1
1,1,2,3,3,1,1
1,1,1,2,2,1,1
1,1,1,1,1,1,1
endlayer

layer
1,1,4,4,4,1,1
1,4,5,5,5,4,1
4,5,5,5,5,5,4
4,5,5,5,5,5,4
4,5,5,5,5,5,4
1,4,5,5,5,4,1
1,1,4,4,4,1,1
endlayer

layer
1,6,7,7,7,6,1
6,7,5,5,5,7,6
7,5,5,5,5,5,7
7,5,5,5,5,5,7
7,5,5,5,5,5,7
6,7,5,5,5,7,6
1,6,7,7,7,6,1
endlayer

layer
1,8,8,8,8,8,1
8,8,7,7,7,8,8
8,7,7,7,7,7,8
8,7,7,7,7,7,8
8,7,7,7,7,7,8
8,8,7,7,7,8,8
1,8,8,8,8,8,1
endlayer

layer
1,1,1,1,1,1,1
1,1,8,9,8,1,1
1,8,8,8,8,8,1
1,9,8,8,8,9,1
1,8,8,8,8,8,1
1,1,8,9,8,1,1
1,1,1,1,1,1,1
endlayer

