# Sandstone Dungeon Room - Fountain
# Created by Ruins mod version 14.6 Ingame Parser
# authoring Player: Jordan_Greywolf
# MC 1.7.10; 3 Jan 2015
# Updated to MC 1.11: 12 Jan 2017 / Updated 11 May 2017
# Updated to MC 1.12: 22 Jun 2017

# Thanks to Syndaryl for bug reporting.


weight=1
embed_into_distance=0
acceptable_target_blocks=
unacceptable_target_blocks=flowing_water,water,flowing_lava,lava
dimensions=11,13,13
allowable_overhang=0
max_leveling=0
leveling_buffer=0
preserve_water=0
preserve_lava=0

rule1=0,100,minecraft:sandstone-2
rule2=0,100,minecraft:sandstone-0
rule3=0,100,minecraft:stained_hardened_clay-1
rule4=0,100,minecraft:stained_hardened_clay-0
rule5=0,100,minecraft:sandstone_stairs-0
rule6=0,100,minecraft:sandstone_stairs-2
rule7=0,100,minecraft:water-0
rule8=0,100,minecraft:sandstone_stairs-3
rule9=0,100,minecraft:sandstone-1
rule10=0,100,minecraft:sandstone_stairs-1
rule11=0,100,minecraft:skull,minecraft:skull-1,minecraft:skull-2,minecraft:skull-3,minecraft:skull-4,minecraft:web
rule12=0,100,minecraft:web
rule13=0,100,minecraft:waterlily-0
rule14=0,100,minecraft:web
rule15=0,100,minecraft:sandstone_stairs-5
rule16=0,100,minecraft:sandstone_stairs-7
rule17=0,100,minecraft:sandstone_stairs-6
rule18=0,100,minecraft:sandstone_stairs-4
rule19=0,100,preserveBlock
rule20=0,100,CommandBlock:RUINSTRIGGER /setblock ~0 ~-1 ~0 mob_spawner 0 replace {SpawnData:{id:cave_spider,CustomName:"Tomb Scarab",ActiveEffects:[{Id:14,Amplifier:1,Duration:999999,Ambient:1}]}}:@,CommandBlock:RUINSTRIGGER /testruin TP_SandItem_Lava ~0 ~-7 ~0:@,CommandBlock:RUINSTRIGGER /testruin TP_SandItem_Fountain ~0 ~-7 ~0:@

layer
1,1,1,1,1,1,1,1,1,1,1,1,1
1,2,2,2,2,2,2,2,2,2,2,2,1
1,2,2,2,2,3,4,3,2,2,2,2,1
1,2,2,2,2,2,2,2,2,2,2,2,1
1,2,2,2,2,5,5,5,2,2,2,2,1
1,2,3,2,8,7,7,7,6,2,3,2,1
1,2,4,2,8,7,7,7,6,2,4,2,1
1,2,3,2,8,7,7,7,6,2,3,2,1
2,2,2,2,2,10,10,10,2,2,2,2,1
2,2,2,2,2,2,2,2,2,2,2,2,1
2,2,2,2,2,3,4,3,2,2,2,2,1
2,2,2,2,2,2,2,2,2,2,2,2,1
1,2,2,2,2,1,1,1,2,2,2,2,1
endlayer

layer
1,2,2,2,2,1,0,1,2,2,2,2,1
2,14,0,0,0,12,0,12,0,0,0,11,2
2,0,8,5,5,0,0,0,8,5,5,0,2
2,0,8,2,6,0,0,0,8,2,6,0,2
2,0,10,10,6,0,0,0,10,10,6,0,2
1,11,0,0,0,13,0,13,0,0,0,12,1
0,0,0,0,0,0,0,0,0,0,0,0,0
1,0,0,0,0,0,0,13,0,0,0,11,1
2,0,8,5,5,0,0,0,8,5,5,0,2
2,12,8,2,6,0,0,0,8,2,6,0,2
2,0,10,10,6,0,0,0,10,10,6,0,2
2,11,0,0,0,0,0,0,0,0,0,12,2
1,2,2,2,2,1,0,1,2,2,2,2,1
endlayer

layer
1,2,9,10,9,1,0,1,9,10,9,2,1
2,0,0,12,0,0,0,0,0,0,0,12,2
9,0,0,0,0,0,0,0,0,0,0,0,9
6,0,0,9,0,0,0,0,0,9,0,0,8
9,0,0,0,0,0,0,0,0,0,0,0,9
1,0,0,0,0,0,0,0,0,0,0,0,1
0,0,0,0,0,0,0,0,0,0,0,0,0
1,0,0,0,0,0,0,0,0,0,0,0,1
9,0,0,0,0,0,0,0,0,0,0,0,9
6,0,12,9,0,0,0,0,0,9,0,0,8
9,0,0,0,0,0,0,0,0,0,0,0,9
2,0,0,0,0,0,0,0,0,0,0,0,2
1,2,9,5,9,1,0,1,9,5,9,2,1
endlayer

layer
1,2,9,15,9,1,12,1,9,15,9,2,1
2,0,0,0,0,0,0,0,0,0,0,12,2
9,0,0,12,0,0,0,0,0,0,0,0,9
17,0,12,2,0,0,0,0,0,2,0,0,16
9,0,0,0,0,0,0,0,0,0,0,0,9
1,0,0,0,0,0,0,0,0,0,0,0,1
12,0,0,0,0,0,0,0,0,0,0,0,12
1,0,0,0,0,0,0,0,0,0,0,0,1
9,0,0,0,0,0,0,0,0,0,0,0,9
17,0,0,2,0,0,0,0,0,2,0,0,16
9,0,0,0,0,0,0,0,0,0,0,0,9
2,0,0,0,0,0,0,0,0,0,0,0,2
1,2,9,18,9,1,12,1,9,18,9,2,1
endlayer

layer
1,2,2,2,2,1,1,1,2,2,2,2,1
2,0,0,0,0,12,0,0,0,0,0,12,2
2,0,0,0,0,0,0,0,0,0,0,0,2
2,0,12,9,0,0,0,0,0,9,12,12,2
2,12,0,0,0,0,0,0,0,0,0,0,2
1,0,0,0,0,0,0,0,0,0,0,0,1
1,0,0,0,0,0,0,0,0,0,0,12,1
1,0,0,0,0,0,0,0,0,0,0,0,1
2,12,0,0,0,0,0,0,0,0,0,0,2
2,0,0,9,0,0,0,0,0,9,12,12,2
2,0,0,0,0,0,0,0,0,0,0,0,2
2,0,0,12,12,0,0,12,0,0,0,0,2
1,2,2,2,2,1,1,1,2,2,2,2,1
endlayer

layer
1,1,1,1,1,1,1,1,1,1,1,1,1
1,17,15,15,15,15,15,15,15,15,15,15,1
1,17,16,18,18,12,0,12,16,18,18,16,1
1,17,16,1,17,0,0,0,16,1,17,16,1
1,17,15,15,17,0,0,0,15,15,17,16,1
1,17,0,0,0,0,0,0,0,0,0,16,1
1,17,0,0,0,0,0,0,0,0,12,16,1
1,17,0,0,0,0,0,0,0,0,0,16,1
1,17,16,18,18,12,0,0,16,18,18,16,1
1,17,16,1,17,0,0,0,16,1,17,16,1
1,17,15,15,17,0,0,0,15,15,17,16,1
1,17,18,18,18,18,18,18,18,18,18,16,1
1,1,1,1,1,1,1,1,1,1,1,1,1
endlayer

layer
19,19,19,19,19,1,1,1,19,19,19,19,19
19,1,1,1,1,1,1,1,1,1,1,1,19
19,1,1,1,1,15,15,15,1,1,1,1,19
19,1,1,1,1,12,0,0,1,1,1,1,19
19,1,1,1,1,0,0,0,1,1,1,1,19
1,1,17,0,12,0,0,0,0,0,16,1,1
1,1,17,0,0,0,0,0,0,0,16,1,1
1,1,17,12,0,0,0,0,0,0,16,1,1
19,1,1,1,1,0,0,0,1,1,1,1,19
19,1,1,1,1,12,0,0,1,1,1,1,19
19,1,1,1,1,18,18,18,1,1,1,1,19
19,1,1,1,1,1,1,1,1,1,1,1,19
19,19,19,19,19,1,1,1,19,19,19,19,19
endlayer

layer
19,19,19,19,19,1,1,1,19,19,19,19,19
19,19,19,19,19,1,1,1,19,19,19,19,19
19,19,1,1,1,1,1,1,1,1,1,19,19
19,19,1,1,1,15,15,15,1,1,1,19,19
19,19,1,1,1,0,0,0,1,1,1,19,19
1,1,1,17,0,0,0,0,0,16,1,1,1
1,1,1,17,0,0,0,0,12,16,1,1,1
1,1,1,17,12,0,0,0,0,16,1,1,1
19,19,1,1,1,0,12,12,1,1,1,19,19
19,19,1,1,1,18,18,18,1,1,1,19,19
19,19,1,1,1,1,1,1,1,1,1,19,19
19,19,19,19,19,1,1,1,19,19,19,19,19
19,19,19,19,19,1,1,1,19,19,19,19,19
endlayer

layer
19,19,19,19,19,19,1,19,19,19,19,19,19
19,19,19,19,19,19,1,19,19,19,19,19,19
19,19,19,19,19,19,1,19,19,19,19,19,19
19,19,19,1,1,1,1,1,1,1,19,19,19
19,19,19,1,1,15,15,15,1,1,19,19,19
19,19,19,1,17,12,0,0,16,1,19,19,19
1,1,1,1,17,0,20,0,16,1,1,1,1
19,19,19,1,17,12,0,12,16,1,19,19,19
19,19,19,1,1,18,18,18,1,1,19,19,19
19,19,19,1,1,1,1,1,1,1,19,19,19
19,19,19,19,19,19,1,19,19,19,19,19,19
19,19,19,19,19,19,1,19,19,19,19,19,19
19,19,19,19,19,19,1,19,19,19,19,19,19
endlayer

layer
19,19,19,19,19,19,19,19,19,19,19,19,19
19,19,19,19,19,19,19,19,19,19,19,19,19
19,19,19,19,19,19,19,19,19,19,19,19,19
19,19,19,19,19,19,19,19,19,19,19,19,19
19,19,19,19,1,1,1,1,1,19,19,19,19
19,19,19,19,1,17,15,16,1,19,19,19,19
19,19,19,19,1,17,2,16,1,19,19,19,19
19,19,19,19,1,18,18,16,1,19,19,19,19
19,19,19,19,1,1,1,1,1,19,19,19,19
19,19,19,19,19,19,19,19,19,19,19,19,19
19,19,19,19,19,19,19,19,19,19,19,19,19
19,19,19,19,19,19,19,19,19,19,19,19,19
19,19,19,19,19,19,19,19,19,19,19,19,19
endlayer

layer
19,19,19,19,19,19,19,19,19,19,19,19,19
19,19,19,19,19,19,19,19,19,19,19,19,19
19,19,19,19,19,19,19,19,19,19,19,19,19
19,19,19,19,19,19,19,19,19,19,19,19,19
19,19,19,19,19,19,19,19,19,19,19,19,19
19,19,19,19,19,1,1,1,19,19,19,19,19
19,19,19,19,19,1,1,1,19,19,19,19,19
19,19,19,19,19,1,1,1,19,19,19,19,19
19,19,19,19,19,19,19,19,19,19,19,19,19
19,19,19,19,19,19,19,19,19,19,19,19,19
19,19,19,19,19,19,19,19,19,19,19,19,19
19,19,19,19,19,19,19,19,19,19,19,19,19
19,19,19,19,19,19,19,19,19,19,19,19,19
endlayer

