# Sunken Dungeon Entry
# Created by Ruins mod version 15.1 Ingame Parser
# authoring Player: Jordan_Greywolf
# Updated to MC 1.8: 5 Mar 2016
# Updated to MC 1.9: 24 Apr 2016
# Updated to MC 1.11: 12 Jan 2017
# Updated to MC 1.12: 22 Jun 2017

weight=1
embed_into_distance=7
acceptable_target_blocks=
unacceptable_target_blocks=cloud,Natura:Cloud
dimensions=20,13,13
allowable_overhang=0
max_leveling=0
leveling_buffer=-1
preserve_water=0
preserve_lava=0

# Stone Brick
rule1=0,100,minecraft:stonebrick,minecraft:stonebrick-1,minecraft:stonebrick-1,minecraft:stonebrick-2

# Water/Earth Fill
rule2=0,100,preserveBlock

# Colored Tile Flooring
rule3=0,100,minecraft:stained_hardened_clay-11
rule4=0,100,minecraft:stained_hardened_clay-9

# Chiseled Stone Brick
rule5=0,100,minecraft:stonebrick-3

# Pool Edge
rule6=0,100,minecraft:stone_brick_stairs-1
rule7=0,100,minecraft:stone_brick_stairs-3
rule8=0,100,minecraft:stone_brick_stairs-2
rule9=0,100,minecraft:stone_brick_stairs-0

# Window
rule10=0,100,minecraft:glass_pane-0

# Defender
rule11=0,100,CommandBlock:RUINSTRIGGER /summon Skeleton ~0 ~0 ~0 {HandItems:[{Count:1,id:stained_glass,Damage:3,tag:{ench:[{id:19,lvl:2}]}},{}],ArmorItems:[{Count:8,id:fish,Damage:2},{Count:8,id:fish,Damage:1},{Count:8,id:fish},{Count:1,id:stained_glass,Damage:3,tag:{ench:[{id:5,lvl:50},{id:8,lvl:50}],display:{Name:"Water Anomaly"}}}],CustomName:"Water Guardian",Attributes:[{Name:generic.attackDamage,Base:6},{Name:generic.knockbackResistance,Base:1}],HandDropChances:[0.0F,0.0F],ArmorDropChances:[1.0F,1.0F,1.0F,0.0F],ActiveEffects:[{Id:12,Amplifier:1,Duration:999999,Ambient:1},{Id:14,Amplifier:1,Duration:999999,Ambient:1},{Id:13,Amplifier:1,Duration:999999,Ambient:1}],Silent:1,PersistenceRequired:1}:@

#
rule12=0,100,CommandBlock:RUINSTRIGGER /testruin TP_SunkenDungeon_PassW ~-7 ~-3 ~0

# Sconce
rule13=0,100,minecraft:cobblestone_wall-1,minecraft:cobblestone_wall

rule14=0,100,CommandBlock:RUINSTRIGGER /testruin TP_SunkenDungeon_PassN ~0 ~-3 ~-7
rule15=0,100,CommandBlock:RUINSTRIGGER /testruin TP_SunkenDungeon_PassS ~0 ~-3 ~7
rule16=0,100,CommandBlock:RUINSTRIGGER /testruin TP_SunkenDungeon_PassE ~7 ~-3 ~0

# Torches
rule17=1,100,minecraft:redstone_torch-5

# Vine Starters
rule18=0,100,minecraft:vine-2
rule19=0,100,minecraft:vine-1
rule20=0,100,minecraft:vine-4
rule21=0,100,minecraft:vine-8

# Glass Block Roof
rule22=0,100,minecraft:glass-0

# Stone Brick Supports
rule23=0,100,minecraft:stone_brick_stairs-5
rule24=0,100,minecraft:stone_brick_stairs-7
rule25=0,100,minecraft:stone_brick_stairs-6
rule26=0,100,minecraft:stone_brick_stairs-4

# Stone Brick
rule27=0,100,minecraft:stonebrick,minecraft:stonebrick-1,minecraft:stonebrick-1,minecraft:stonebrick-2

# Silence Rule
rule28=0,100,CommandBlock:RUINSTRIGGER /gamerule commandBlockOutput false:@

# Still Water
rule29=0,100,minecraft:water

layer
1,1,1,1,1,1,1,1,1,1,1,1,1
1,2,2,2,1,2,2,2,1,2,2,2,1
1,2,2,2,1,2,2,2,1,2,2,2,1
1,2,2,2,1,2,2,2,1,2,2,2,1
1,1,1,1,1,1,1,1,1,1,1,1,1
1,2,2,2,1,2,2,2,1,2,2,2,1
1,2,2,2,1,2,28,2,1,2,2,2,1
1,2,2,2,1,2,2,2,1,2,2,2,1
1,1,1,1,1,1,1,1,1,1,1,1,1
1,2,2,2,1,2,2,2,1,2,2,2,1
1,2,2,2,1,2,2,2,1,2,2,2,1
1,2,2,2,1,2,2,2,1,2,2,2,1
1,1,1,1,1,1,1,1,1,1,1,1,1
endlayer

layer
1,2,2,2,1,2,2,2,1,2,2,2,1
2,2,2,2,2,2,2,2,2,2,2,2,2
2,2,2,2,2,2,2,2,2,2,2,2,2
2,2,2,2,2,2,2,2,2,2,2,2,2
1,2,2,2,1,2,2,2,1,2,2,2,1
2,2,2,2,2,2,2,2,2,2,2,2,2
2,2,2,2,2,2,2,2,2,2,2,2,2
2,2,2,2,2,2,2,2,2,2,2,2,2
1,2,2,2,1,2,2,2,1,2,2,2,1
2,2,2,2,2,2,2,2,2,2,2,2,2
2,2,2,2,2,2,2,2,2,2,2,2,2
2,2,2,2,2,2,2,2,2,2,2,2,2
1,2,2,2,1,2,2,2,1,2,2,2,1
endlayer

layer
1,2,2,2,1,2,2,2,1,2,2,2,1
2,2,2,2,2,2,2,2,2,2,2,2,2
2,2,2,2,2,2,2,2,2,2,2,2,2
2,2,2,2,2,2,2,2,2,2,2,2,2
1,2,2,2,1,2,2,2,1,2,2,2,1
2,2,2,2,2,2,2,2,2,2,2,2,2
2,2,2,2,2,2,2,2,2,2,2,2,2
2,2,2,2,2,2,2,2,2,2,2,2,2
1,2,2,2,1,2,2,2,1,2,2,2,1
2,2,2,2,2,2,2,2,2,2,2,2,2
2,2,2,2,2,2,2,2,2,2,2,2,2
2,2,2,2,2,2,2,2,2,2,2,2,2
1,2,2,2,1,2,2,2,1,2,2,2,1
endlayer

layer
1,2,2,2,1,2,2,2,1,2,2,2,1
2,2,2,2,2,2,2,2,2,2,2,2,2
2,2,2,2,2,2,2,2,2,2,2,2,2
2,2,2,2,2,2,2,2,2,2,2,2,2
1,2,2,2,1,2,2,2,1,2,2,2,1
2,2,2,2,2,2,2,2,2,2,2,2,2
2,2,2,2,2,2,2,2,2,2,2,2,2
2,2,2,2,2,2,2,2,2,2,2,2,2
1,2,2,2,1,2,2,2,1,2,2,2,1
2,2,2,2,2,2,2,2,2,2,2,2,2
2,2,2,2,2,2,2,2,2,2,2,2,2
2,2,2,2,2,2,2,2,2,2,2,2,2
1,2,2,2,1,2,2,2,1,2,2,2,1
endlayer

layer
1,2,2,2,1,2,2,2,1,2,2,2,1
2,2,2,2,2,2,2,2,2,2,2,2,2
2,2,2,2,2,2,2,2,2,2,2,2,2
2,2,2,2,2,2,2,2,2,2,2,2,2
1,2,2,2,1,2,2,2,1,2,2,2,1
2,2,2,2,2,2,2,2,2,2,2,2,2
2,2,2,2,2,2,2,2,2,2,2,2,2
2,2,2,2,2,2,2,2,2,2,2,2,2
1,2,2,2,1,2,2,2,1,2,2,2,1
2,2,2,2,2,2,2,2,2,2,2,2,2
2,2,2,2,2,2,2,2,2,2,2,2,2
2,2,2,2,2,2,2,2,2,2,2,2,2
1,2,2,2,1,2,2,2,1,2,2,2,1
endlayer

layer
1,2,2,2,1,2,2,2,1,2,2,2,1
2,2,2,2,2,2,2,2,2,2,2,2,2
2,2,2,2,2,2,2,2,2,2,2,2,2
2,2,2,2,2,2,2,2,2,2,2,2,2
1,2,2,2,1,2,2,2,1,2,2,2,1
2,2,2,2,2,2,2,2,2,2,2,2,2
2,2,2,2,2,2,2,2,2,2,2,2,2
2,2,2,2,2,2,2,2,2,2,2,2,2
1,2,2,2,1,2,2,2,1,2,2,2,1
2,2,2,2,2,2,2,2,2,2,2,2,2
2,2,2,2,2,2,2,2,2,2,2,2,2
2,2,2,2,2,2,2,2,2,2,2,2,2
1,2,2,2,1,2,2,2,1,2,2,2,1
endlayer


layer
1,2,2,2,1,2,2,2,1,2,2,2,1
2,2,2,2,2,2,2,2,2,2,2,2,2
2,2,2,2,2,2,2,2,2,2,2,2,2
2,2,2,2,2,2,2,2,2,2,2,2,2
1,2,2,2,1,2,2,2,1,2,2,2,1
2,2,2,2,2,2,2,2,2,2,2,2,2
2,2,2,2,2,2,2,2,2,2,2,2,2
2,2,2,2,2,2,2,2,2,2,2,2,2
1,2,2,2,1,2,2,2,1,2,2,2,1
2,2,2,2,2,2,2,2,2,2,2,2,2
2,2,2,2,2,2,2,2,2,2,2,2,2
2,2,2,2,2,2,2,2,2,2,2,2,2
1,2,2,2,1,2,2,2,1,2,2,2,1
endlayer

layer
1,1,2,1,1,1,2,1,1,1,2,1,1
1,2,2,2,2,2,2,2,2,2,2,2,1
2,2,2,2,2,2,2,2,2,2,2,2,2
1,2,2,2,1,2,2,2,2,2,2,2,1
1,1,2,1,1,1,2,1,1,1,2,1,1
1,2,2,2,1,29,29,29,1,2,2,2,1
2,2,2,2,2,29,29,29,2,2,2,2,2
1,2,2,2,1,29,29,29,1,2,2,2,1
1,1,2,1,1,1,2,1,1,1,2,1,1
1,2,2,2,1,2,2,2,1,2,2,2,1
2,2,2,2,2,2,2,2,2,2,2,2,2
1,2,2,2,1,2,2,2,1,2,2,2,1
1,1,2,1,1,1,2,1,1,1,2,1,1
endlayer


layer
1,1,1,1,1,1,1,1,1,1,1,1,1
1,3,4,3,1,3,4,3,1,3,4,3,1
1,4,4,4,1,4,4,4,1,4,4,4,1
1,3,4,3,1,3,4,3,1,3,4,3,1
1,1,1,1,5,6,6,6,5,1,1,1,1
1,3,4,3,8,0,0,0,7,3,4,3,1
1,4,4,4,8,0,29,0,7,4,4,4,1
1,3,4,3,8,0,0,0,7,3,4,3,1
1,1,1,1,5,9,9,9,5,1,1,1,1
1,3,4,3,1,3,4,3,1,3,4,3,1
1,4,4,4,1,4,4,4,1,4,4,4,1
1,3,4,3,1,3,4,3,1,3,4,3,1
1,1,1,1,1,1,1,1,1,1,1,1,1
endlayer

layer
1,10,10,10,1,10,10,10,1,10,10,10,1
10,11,0,0,0,0,12,0,0,0,0,11,10
10,0,0,0,0,0,0,0,0,0,0,0,10
10,0,0,0,0,0,0,0,0,0,0,0,10
1,0,0,0,13,0,0,0,13,0,0,0,1
10,0,0,0,0,0,0,0,0,0,0,0,10
10,15,0,0,0,0,29,0,0,0,0,14,10
10,0,0,0,0,0,0,0,0,0,0,0,10
1,0,0,0,13,0,0,0,13,0,0,0,1
10,0,0,0,0,0,0,0,0,0,0,0,10
10,0,0,0,0,0,0,0,0,0,0,0,10
10,11,0,0,0,0,16,0,0,0,0,11,10
1,10,10,10,1,10,10,10,1,10,10,10,1
endlayer

layer
1,10,10,10,1,10,10,10,1,10,10,10,1
10,0,0,0,0,0,0,0,0,0,0,0,10
10,0,0,0,0,0,0,0,0,0,0,0,10
10,0,0,0,0,0,0,0,0,0,0,0,10
1,0,0,0,17,0,0,0,17,0,0,0,1
10,0,0,0,0,0,0,0,0,0,0,0,10
10,0,0,0,0,0,29,0,0,0,0,0,10
10,0,0,0,0,0,0,0,0,0,0,0,10
1,0,0,0,17,0,0,0,17,0,0,0,1
10,0,0,0,0,0,0,0,0,0,0,0,10
10,0,0,0,0,0,0,0,0,0,0,0,10
10,0,0,0,0,0,0,0,0,0,0,0,10
1,10,10,10,1,10,10,10,1,10,10,10,1
endlayer

layer
1,10,10,10,1,10,10,10,1,10,10,10,1
10,0,0,0,13,0,0,0,13,0,0,0,10
10,0,0,0,0,0,0,0,0,0,0,0,10
10,0,0,0,0,0,0,0,0,0,0,0,10
1,13,0,0,0,0,0,0,0,0,0,13,1
10,0,0,0,0,0,0,0,0,0,0,0,10
10,0,0,0,0,0,29,0,0,0,0,0,10
10,0,0,0,0,0,0,0,0,0,0,0,10
1,13,0,0,0,0,0,0,0,0,0,13,1
10,0,0,0,0,0,0,0,0,0,0,0,10
10,0,0,0,0,0,0,0,0,0,0,0,10
10,0,0,0,13,0,0,0,13,0,0,0,10
1,10,10,10,1,10,10,10,1,10,10,10,1
endlayer

layer
1,1,10,1,1,1,10,1,1,1,10,1,1
1,0,0,0,17,0,0,0,17,0,0,0,1
10,0,0,0,0,0,0,0,0,0,0,0,10
1,0,0,0,0,0,0,0,0,0,0,0,1
1,17,0,0,0,0,0,0,0,0,0,17,1
1,0,0,0,0,0,0,0,0,0,0,0,1
10,0,0,0,0,0,29,0,0,0,0,0,10
1,0,0,0,0,0,0,0,0,0,0,0,1
1,17,0,0,0,0,0,0,0,0,0,17,1
1,0,0,0,0,0,0,0,0,0,0,0,1
10,0,0,0,0,0,0,0,0,0,0,0,10
1,0,0,0,17,0,0,0,17,0,0,0,1
1,1,10,1,1,1,10,1,1,1,10,1,1
endlayer

layer
1,1,10,1,1,1,10,1,1,1,10,1,1
1,19,0,18,0,18,0,18,0,18,0,18,1
10,0,0,0,0,0,0,0,0,0,0,0,10
1,19,0,0,0,0,0,0,0,0,0,20,1
1,0,0,0,0,0,0,0,0,0,0,0,1
1,19,0,0,0,0,0,0,0,0,0,20,1
10,0,0,0,0,0,29,0,0,0,0,0,10
1,19,0,0,0,0,0,0,0,0,0,20,1
1,0,0,0,0,0,0,0,0,0,0,0,1
1,19,0,0,0,0,0,0,0,0,0,20,1
10,0,0,0,0,0,0,0,0,0,0,0,10
1,21,0,21,0,21,0,21,0,21,0,20,1
1,1,10,1,1,1,10,1,1,1,10,1,1
endlayer

layer
1,1,1,1,1,1,1,1,1,1,1,1,1
1,22,22,1,1,22,22,22,1,1,22,22,1
1,22,1,22,23,0,0,0,23,22,1,22,1
1,1,22,0,0,0,0,0,0,0,22,1,1
1,1,25,0,0,0,0,0,0,0,24,1,1
1,22,0,0,0,0,0,0,0,0,0,22,1
1,22,0,0,0,0,29,0,0,0,0,22,1
1,22,0,0,0,0,0,0,0,0,0,22,1
1,1,25,0,0,0,0,0,0,0,24,1,1
1,1,22,0,0,0,0,0,0,0,22,1,1
1,22,1,22,26,0,0,0,26,22,1,22,1
1,22,22,1,1,22,22,22,1,1,22,22,1
1,1,1,1,1,1,1,1,1,1,1,1,1
endlayer

layer
2,2,2,2,2,2,2,2,2,2,2,2,2
2,2,2,2,2,22,22,22,2,2,2,2,2
2,2,2,22,27,19,0,0,27,22,2,2,2
2,2,22,0,18,0,0,0,18,0,22,2,2
2,2,27,19,0,0,0,0,0,20,27,2,2
2,22,0,0,0,0,0,0,0,0,0,22,2
2,22,0,0,0,0,29,0,0,0,0,22,2
2,22,0,0,0,0,0,0,0,0,0,22,2
2,2,27,19,0,0,0,0,0,20,27,2,2
2,2,22,0,21,0,0,0,21,0,22,2,2
2,2,2,22,27,0,0,0,27,22,2,2,2
2,2,2,2,2,22,22,22,2,2,2,2,2
2,2,2,2,2,2,2,2,2,2,2,2,2
endlayer

layer
2,2,2,2,2,2,2,2,2,2,2,2,2
2,2,2,2,2,2,2,2,2,2,2,2,2
2,2,2,2,27,22,22,22,27,2,2,2,2
2,2,2,22,23,0,0,0,23,22,2,2,2
2,2,27,25,0,0,0,0,0,24,27,2,2
2,2,22,0,0,0,0,0,0,0,22,2,2
2,2,22,0,0,0,29,0,0,0,22,2,2
2,2,22,0,0,0,0,0,0,0,22,2,2
2,2,27,25,0,0,0,0,0,24,27,2,2
2,2,2,22,26,0,0,0,26,22,2,2,2
2,2,2,2,27,22,22,22,27,2,2,2,2
2,2,2,2,2,2,2,2,2,2,2,2,2
2,2,2,2,2,2,2,2,2,2,2,2,2
endlayer

layer
2,2,2,2,2,2,2,2,2,2,2,2,2
2,2,2,2,2,2,2,2,2,2,2,2,2
2,2,2,2,2,2,22,2,2,2,2,2,2
2,2,2,2,27,22,0,22,27,2,2,2,2
2,2,2,27,18,0,0,0,20,27,2,2,2
2,2,2,22,0,0,0,0,0,22,2,2,2
2,2,22,0,0,0,29,0,0,0,22,2,2
2,2,2,22,0,0,0,0,0,22,2,2,2
2,2,2,27,19,0,0,0,21,27,2,2,2
2,2,2,2,27,22,0,22,27,2,2,2,2
2,2,2,2,2,2,22,2,2,2,2,2,2
2,2,2,2,2,2,2,2,2,2,2,2,2
2,2,2,2,2,2,2,2,2,2,2,2,2
endlayer

layer
2,2,2,2,2,2,2,2,2,2,2,2,2
2,2,2,2,2,2,2,2,2,2,2,2,2
2,2,2,2,2,2,2,2,2,2,2,2,2
2,2,2,2,2,22,22,22,2,2,2,2,2
2,2,2,2,27,27,27,27,27,2,2,2,2
2,2,2,22,27,19,18,18,27,22,2,2,2
2,2,2,22,27,19,29,20,27,22,2,2,2
2,2,2,22,27,21,21,20,27,22,2,2,2
2,2,2,2,27,27,27,27,27,2,2,2,2
2,2,2,2,2,22,22,22,2,2,2,2,2
2,2,2,2,2,2,2,2,2,2,2,2,2
2,2,2,2,2,2,2,2,2,2,2,2,2
2,2,2,2,2,2,2,2,2,2,2,2,2
endlayer

layer
2,2,2,2,2,2,2,2,2,2,2,2,2
2,2,2,2,2,2,2,2,2,2,2,2,2
2,2,2,2,2,2,2,2,2,2,2,2,2
2,2,2,2,2,2,2,2,2,2,2,2,2
2,2,2,2,2,2,2,2,2,2,2,2,2
2,2,2,2,2,22,22,22,2,2,2,2,2
2,2,2,2,2,22,0,22,2,2,2,2,2
2,2,2,2,2,22,22,22,2,2,2,2,2
2,2,2,2,2,2,2,2,2,2,2,2,2
2,2,2,2,2,2,2,2,2,2,2,2,2
2,2,2,2,2,2,2,2,2,2,2,2,2
2,2,2,2,2,2,2,2,2,2,2,2,2
2,2,2,2,2,2,2,2,2,2,2,2,2
endlayer

