# Snow Tower Dungeon Segment
# Created by Ruins mod version 15.1 Ingame Parser
# authoring Player: Jordan_Greywolf
# Note: Place this in \templateparser folder.
# Last Updated 7 Jan 2016
# Updated to MC 1.8: 5 Mar 2016
# Updated to MC 1.9: 24 Apr 2016
# Updated to MC 1.11: 12 Jan 2017
# Updated to MC 1.12: 22 Jun 2017

weight=1
embed_into_distance=0
acceptable_target_blocks=
unacceptable_target_blocks=flowing_water,water,flowing_lava,lava
dimensions=15,23,23
allowable_overhang=0
max_leveling=-1
leveling_buffer=0
preserve_water=0
preserve_lava=0

rule1=0,100,preserveBlock
rule2=0,100,minecraft:snow-0
rule3=0,100,minecraft:ice-0
rule4=0,100,minecraft:packed_ice-0
rule5=0,100,minecraft:stone_slab-7
rule6=0,100,minecraft:double_stone_slab-7
rule7=0,100,minecraft:stone_slab-15
rule8=0,100,minecraft:water-0
rule9=0,100,minecraft:glowstone-0,minecraft:packed_ice-0
rule10=0,100,ChestGenHook:chests/simple_dungeon:3-4,ChestGenHook:chests/spawn_bonus_chest:6-4,ChestGenHook:chests/jungle_temple:4-4
rule11=0,100,ChestGenHook:chests/simple_dungeon:3-2,ChestGenHook:chests/spawn_bonus_chest:6-2,ChestGenHook:chests/jungle_temple:4-2
rule12=0,100,ChestGenHook:chests/simple_dungeon:3-3,ChestGenHook:chests/spawn_bonus_chest:6-3,ChestGenHook:chests/jungle_temple:4-3
rule13=0,100,ChestGenHook:chests/simple_dungeon:3-5,ChestGenHook:chests/spawn_bonus_chest:6-5,ChestGenHook:chests/jungle_temple:4-5

rule14=0,100,CommandBlock:RUINSTRIGGER /setblock ~0 ~1 ~0 mob_spawner 0 replace {SpawnData:{id:Skeleton,HandItems:[{Count:1,id:diamond_pickaxe,tag:{display:{Name:"Ice Pick"}}},{}],ArmorItems:[{Count:1,id:diamond_boots,tag:{display:{Name:"Frozen Boots"}}},{Count:1,id:diamond_leggings,tag:{display:{Name:"Ice Greaves"}}},{Count:1,id:diamond_chestplate,tag:{display:{Name:"Ice Armor"}}},{Count:1,id:ice}],HandDropChances:[0.0F,0.0F],ArmorDropChance:[0.0F,0.0F,0.0F,0.5F]}}:@


layer
1,1,1,1,1,1,1,1,2,2,2,2,2,2,2,1,1,1,1,1,1,1,1
1,1,1,1,1,1,2,2,3,3,3,3,3,3,3,2,2,1,1,1,1,1,1
1,1,1,1,2,2,3,3,3,3,3,4,3,3,3,3,3,2,2,1,1,1,1
1,1,1,2,3,3,3,3,3,3,4,4,4,3,3,3,3,3,3,2,1,1,1
1,1,2,3,3,4,3,3,3,3,3,4,3,3,3,3,3,4,3,3,2,1,1
1,1,2,3,4,4,4,3,3,3,3,3,3,3,3,3,4,4,4,3,2,1,1
1,2,3,3,3,4,3,3,3,3,3,3,3,3,3,3,3,4,3,3,3,2,1
1,2,3,3,3,3,3,3,3,3,3,3,3,3,3,3,3,3,3,3,3,2,1
2,3,3,3,3,3,3,3,3,3,4,4,4,3,3,3,3,3,3,3,3,3,2
2,3,3,3,3,3,3,3,3,4,4,4,4,4,3,3,3,3,3,3,3,3,2
2,3,3,4,3,3,3,3,4,4,4,4,4,4,4,3,3,3,3,4,3,3,2
2,3,4,4,4,3,3,3,4,4,4,4,4,4,4,3,3,3,4,4,4,3,2
2,3,3,4,3,3,3,3,4,4,4,4,4,4,4,3,3,3,3,4,3,3,2
2,3,3,3,3,3,3,3,3,4,4,4,4,4,3,3,3,3,3,3,3,3,2
2,3,3,3,3,3,3,3,3,3,4,4,4,3,3,3,3,3,3,3,3,3,2
1,2,3,3,3,3,3,3,3,3,3,3,3,3,3,3,3,3,3,3,3,2,1
1,2,3,3,3,4,3,3,3,3,3,3,3,3,3,3,3,4,3,3,3,2,1
1,1,2,3,4,4,4,3,3,3,3,3,3,3,3,3,4,4,4,3,2,1,1
1,1,2,3,3,4,3,3,3,3,3,4,3,3,3,3,3,4,0,3,2,1,1
1,1,1,2,3,3,3,3,3,3,4,4,4,3,3,3,0,0,0,2,1,1,1
1,1,1,1,2,2,3,3,3,3,3,4,3,3,6,5,0,2,2,1,1,1,1
1,1,1,1,1,1,2,2,3,3,3,3,3,3,7,2,2,1,1,1,1,1,1
1,1,1,1,1,1,1,1,2,2,2,2,2,2,2,1,1,1,1,1,1,1,1
endlayer

layer
1,1,1,1,1,1,1,1,2,2,3,3,3,2,2,1,1,1,1,1,1,1,1
1,1,1,1,1,1,2,2,0,0,0,0,0,0,0,2,2,1,1,1,1,1,1
1,1,1,1,2,2,0,0,0,0,0,4,0,0,0,0,0,2,2,1,1,1,1
1,1,1,2,0,0,0,0,0,0,4,4,4,0,0,0,0,0,0,2,1,1,1
1,1,2,0,0,4,0,0,0,0,0,4,0,0,0,0,0,4,0,0,2,1,1
1,1,2,0,4,4,4,0,0,0,0,0,0,0,0,0,4,4,4,0,2,1,1
1,2,0,0,0,4,0,0,0,0,0,0,0,0,0,0,0,4,0,0,0,2,1
1,2,7,0,0,0,0,0,0,0,0,0,0,0,0,0,0,0,0,0,0,2,1
2,5,6,0,0,0,0,0,0,0,3,3,3,0,0,0,0,0,0,0,0,0,2
2,0,0,0,0,0,0,0,0,3,3,14,3,3,0,0,0,0,0,0,0,0,2
3,0,0,4,0,0,0,0,3,3,8,8,8,3,3,0,0,0,0,4,0,0,3
3,0,4,4,4,0,0,0,3,14,8,9,8,14,3,0,0,0,4,4,4,0,3
3,0,0,4,0,0,0,0,3,3,8,8,8,3,3,0,0,0,0,4,0,0,3
2,0,0,0,0,0,0,0,0,3,3,14,3,3,0,0,0,0,0,0,0,0,2
2,0,0,0,0,0,0,0,0,0,3,3,3,0,0,0,0,0,0,0,0,0,2
1,2,0,0,0,0,0,0,0,0,0,0,0,0,0,0,0,0,0,0,0,2,1
1,2,0,0,0,4,0,0,0,0,0,0,0,0,0,0,0,4,0,0,0,2,1
1,1,2,0,4,4,4,0,0,0,0,0,0,0,0,0,4,4,4,0,2,1,1
1,1,2,0,0,4,0,0,0,0,0,4,0,0,0,0,0,4,0,0,2,1,1
1,1,1,2,0,0,0,0,0,0,4,4,4,0,0,0,0,0,0,2,1,1,1
1,1,1,1,2,2,0,0,0,0,0,4,0,0,0,0,0,2,2,1,1,1,1
1,1,1,1,1,1,2,2,0,0,0,0,0,0,0,2,2,1,1,1,1,1,1
1,1,1,1,1,1,1,1,2,2,3,3,3,2,2,1,1,1,1,1,1,1,1
endlayer

layer
1,1,1,1,1,1,1,1,2,2,3,3,3,2,2,1,1,1,1,1,1,1,1
1,1,1,1,1,1,2,2,0,0,0,0,0,0,0,2,2,1,1,1,1,1,1
1,1,1,1,2,2,0,0,0,0,0,10,0,0,0,0,0,2,2,1,1,1,1
1,1,1,2,0,0,0,0,0,0,0,4,0,0,0,0,0,0,0,2,1,1,1
1,1,2,0,0,0,0,0,0,0,0,0,0,0,0,0,0,0,0,0,2,1,1
1,1,2,0,0,4,0,0,0,0,0,0,0,0,0,0,0,4,0,0,2,1,1
1,2,6,7,0,0,0,0,0,0,0,0,0,0,0,0,0,0,0,0,0,2,1
1,2,5,0,0,0,0,0,0,0,0,0,0,0,0,0,0,0,0,0,0,2,1
2,0,0,0,0,0,0,0,0,0,3,3,3,0,0,0,0,0,0,0,0,0,2
2,0,0,0,0,0,0,0,0,3,3,8,3,3,0,0,0,0,0,0,0,0,2
3,0,0,0,0,0,0,0,3,3,8,8,8,3,3,0,0,0,0,0,0,0,3
3,0,12,4,0,0,0,0,3,8,8,9,8,8,3,0,0,0,0,4,11,0,3
3,0,0,0,0,0,0,0,3,3,8,8,8,3,3,0,0,0,0,0,0,0,3
2,0,0,0,0,0,0,0,0,3,3,8,3,3,0,0,0,0,0,0,0,0,2
2,0,0,0,0,0,0,0,0,0,3,3,3,0,0,0,0,0,0,0,0,0,2
1,2,0,0,0,0,0,0,0,0,0,0,0,0,0,0,0,0,0,0,0,2,1
1,2,0,0,0,0,0,0,0,0,0,0,0,0,0,0,0,0,0,0,0,2,1
1,1,2,0,0,4,0,0,0,0,0,0,0,0,0,0,0,4,0,0,2,1,1
1,1,2,0,0,0,0,0,0,0,0,0,0,0,0,0,0,0,0,0,2,1,1
1,1,1,2,0,0,0,0,0,0,0,4,0,0,0,0,0,0,0,2,1,1,1
1,1,1,1,2,2,0,0,0,0,0,13,0,0,0,0,0,2,2,1,1,1,1
1,1,1,1,1,1,2,2,0,0,0,0,0,0,0,2,2,1,1,1,1,1,1
1,1,1,1,1,1,1,1,2,2,3,3,3,2,2,1,1,1,1,1,1,1,1
endlayer

layer
1,1,1,1,1,1,1,1,2,2,4,3,4,2,2,1,1,1,1,1,1,1,1
1,1,1,1,1,1,2,2,0,0,0,0,0,0,0,2,2,1,1,1,1,1,1
1,1,1,1,2,2,0,0,0,0,0,0,0,0,0,0,0,2,2,1,1,1,1
1,1,1,2,0,0,0,0,0,0,0,4,0,0,0,0,0,0,0,2,1,1,1
1,1,2,7,0,0,0,0,0,0,0,0,0,0,0,0,0,0,0,0,2,1,1
1,1,2,6,0,4,0,0,0,0,0,0,0,0,0,0,0,4,0,0,2,1,1
1,2,0,5,0,0,0,0,0,0,0,0,0,0,0,0,0,0,0,0,0,2,1
1,2,0,0,0,0,0,0,0,0,0,0,0,0,0,0,0,0,0,0,0,2,1
2,0,0,0,0,0,0,0,0,0,3,3,3,0,0,0,0,0,0,0,0,0,2
2,0,0,0,0,0,0,0,0,3,3,8,3,3,0,0,0,0,0,0,0,0,2
4,0,0,0,0,0,0,0,3,3,8,8,8,3,3,0,0,0,0,0,0,0,4
3,0,0,4,0,0,0,0,3,8,8,9,8,8,3,0,0,0,0,4,0,0,3
4,0,0,0,0,0,0,0,3,3,8,8,8,3,3,0,0,0,0,0,0,0,4
2,0,0,0,0,0,0,0,0,3,3,8,3,3,0,0,0,0,0,0,0,0,2
2,0,0,0,0,0,0,0,0,0,3,3,3,0,0,0,0,0,0,0,0,0,2
1,2,0,0,0,0,0,0,0,0,0,0,0,0,0,0,0,0,0,0,0,2,1
1,2,0,0,0,0,0,0,0,0,0,0,0,0,0,0,0,0,0,0,0,2,1
1,1,2,0,0,4,0,0,0,0,0,0,0,0,0,0,0,4,0,0,2,1,1
1,1,2,0,0,0,0,0,0,0,0,0,0,0,0,0,0,0,0,0,2,1,1
1,1,1,2,0,0,0,0,0,0,0,4,0,0,0,0,0,0,0,2,1,1,1
1,1,1,1,2,2,0,0,0,0,0,0,0,0,0,0,0,2,2,1,1,1,1
1,1,1,1,1,1,2,2,0,0,0,0,0,0,0,2,2,1,1,1,1,1,1
1,1,1,1,1,1,1,1,2,2,4,3,4,2,2,1,1,1,1,1,1,1,1
endlayer

layer
1,1,1,1,1,1,1,1,2,2,4,3,4,2,2,1,1,1,1,1,1,1,1
1,1,1,1,1,1,2,2,0,0,0,0,0,0,0,2,2,1,1,1,1,1,1
1,1,1,1,2,2,0,0,0,0,0,0,0,0,0,0,0,2,2,1,1,1,1
1,1,1,2,7,0,0,0,0,0,0,4,0,0,0,0,0,0,0,2,1,1,1
1,1,2,5,6,0,0,0,0,0,0,0,0,0,0,0,0,0,0,0,2,1,1
1,1,2,0,0,4,0,0,0,0,0,0,0,0,0,0,0,4,0,0,2,1,1
1,2,0,0,0,0,0,0,0,0,0,0,0,0,0,0,0,0,0,0,0,2,1
1,2,0,0,0,0,0,0,0,0,0,0,0,0,0,0,0,0,0,0,0,2,1
2,0,0,0,0,0,0,0,0,0,3,3,3,0,0,0,0,0,0,0,0,0,2
2,0,0,0,0,0,0,0,0,3,3,8,3,3,0,0,0,0,0,0,0,0,2
4,0,0,0,0,0,0,0,3,3,8,8,8,3,3,0,0,0,0,0,0,0,4
3,0,0,4,0,0,0,0,3,8,8,9,8,8,3,0,0,0,0,4,0,0,3
4,0,0,0,0,0,0,0,3,3,8,8,8,3,3,0,0,0,0,0,0,0,4
2,0,0,0,0,0,0,0,0,3,3,8,3,3,0,0,0,0,0,0,0,0,2
2,0,0,0,0,0,0,0,0,0,3,3,3,0,0,0,0,0,0,0,0,0,2
1,2,0,0,0,0,0,0,0,0,0,0,0,0,0,0,0,0,0,0,0,2,1
1,2,0,0,0,0,0,0,0,0,0,0,0,0,0,0,0,0,0,0,0,2,1
1,1,2,0,0,4,0,0,0,0,0,0,0,0,0,0,0,4,0,0,2,1,1
1,1,2,0,0,0,0,0,0,0,0,0,0,0,0,0,0,0,0,0,2,1,1
1,1,1,2,0,0,0,0,0,0,0,4,0,0,0,0,0,0,0,2,1,1,1
1,1,1,1,2,2,0,0,0,0,0,0,0,0,0,0,0,2,2,1,1,1,1
1,1,1,1,1,1,2,2,0,0,0,0,0,0,0,2,2,1,1,1,1,1,1
1,1,1,1,1,1,1,1,2,2,4,3,4,2,2,1,1,1,1,1,1,1,1
endlayer

layer
1,1,1,1,1,1,1,1,2,2,2,4,2,2,2,1,1,1,1,1,1,1,1
1,1,1,1,1,1,2,2,0,0,0,0,0,0,0,2,2,1,1,1,1,1,1
1,1,1,1,2,2,0,0,0,0,0,4,0,0,0,0,0,2,2,1,1,1,1
1,1,1,2,5,6,7,0,0,0,4,4,4,0,0,0,0,0,0,2,1,1,1
1,1,2,0,0,4,0,0,0,0,0,4,0,0,0,0,0,4,0,0,2,1,1
1,1,2,0,4,4,4,0,0,0,0,0,0,0,0,0,4,4,4,0,2,1,1
1,2,0,0,0,4,0,0,0,0,0,0,0,0,0,0,0,4,0,0,0,2,1
1,2,0,0,0,0,0,0,0,0,0,0,0,0,0,0,0,0,0,0,0,2,1
2,0,0,0,0,0,0,0,0,0,3,3,3,0,0,0,0,0,0,0,0,0,2
2,0,0,0,0,0,0,0,0,3,3,8,3,3,0,0,0,0,0,0,0,0,2
2,0,0,4,0,0,0,0,3,3,8,8,8,3,3,0,0,0,0,4,0,0,2
4,0,4,4,4,0,0,0,3,8,8,9,8,8,3,0,0,0,4,4,4,0,4
2,0,0,4,0,0,0,0,3,3,8,8,8,3,3,0,0,0,0,4,0,0,2
2,0,0,0,0,0,0,0,0,3,3,8,3,3,0,0,0,0,0,0,0,0,2
2,0,0,0,0,0,0,0,0,0,3,3,3,0,0,0,0,0,0,0,0,0,2
1,2,0,0,0,0,0,0,0,0,0,0,0,0,0,0,0,0,0,0,0,2,1
1,2,0,0,0,4,0,0,0,0,0,0,0,0,0,0,0,4,0,0,0,2,1
1,1,2,0,4,4,4,0,0,0,0,0,0,0,0,0,4,4,4,0,2,1,1
1,1,2,0,0,4,0,0,0,0,0,4,0,0,0,0,0,4,0,0,2,1,1
1,1,1,2,0,0,0,0,0,0,4,4,4,0,0,0,0,0,0,2,1,1,1
1,1,1,1,2,2,0,0,0,0,0,4,0,0,0,0,0,2,2,1,1,1,1
1,1,1,1,1,1,2,2,0,0,0,0,0,0,0,2,2,1,1,1,1,1,1
1,1,1,1,1,1,1,1,2,2,2,4,2,2,2,1,1,1,1,1,1,1,1
endlayer

layer
1,1,1,1,1,1,1,1,2,2,2,2,2,2,2,1,1,1,1,1,1,1,1
1,1,1,1,1,1,2,2,0,0,0,0,0,0,0,2,2,1,1,1,1,1,1
1,1,1,1,2,2,6,7,0,0,0,4,0,0,0,0,0,2,2,1,1,1,1
1,1,1,2,0,0,5,0,0,0,4,4,4,0,0,0,0,0,0,2,1,1,1
1,1,2,0,0,4,0,0,0,0,0,4,0,0,0,0,0,4,0,0,2,1,1
1,1,2,0,4,4,4,0,0,0,0,0,0,0,0,0,4,4,4,0,2,1,1
1,2,0,0,0,4,0,0,0,0,0,0,0,0,0,0,0,4,0,0,0,2,1
1,2,0,0,0,0,0,0,0,0,0,0,0,0,0,0,0,0,0,0,0,2,1
2,0,0,0,0,0,0,0,0,0,3,3,3,0,0,0,0,0,0,0,0,0,2
2,0,0,0,0,0,0,0,0,3,3,8,3,3,0,0,0,0,0,0,0,0,2
2,0,0,4,0,0,0,0,3,3,8,8,8,3,3,0,0,0,0,4,0,0,2
2,0,4,4,4,0,0,0,3,8,8,9,8,8,3,0,0,0,4,4,4,0,2
2,0,0,4,0,0,0,0,3,3,8,8,8,3,3,0,0,0,0,4,0,0,2
2,0,0,0,0,0,0,0,0,3,3,8,3,3,0,0,0,0,0,0,0,0,2
2,0,0,0,0,0,0,0,0,0,3,3,3,0,0,0,0,0,0,0,0,0,2
1,2,0,0,0,0,0,0,0,0,0,0,0,0,0,0,0,0,0,0,0,2,1
1,2,0,0,0,4,0,0,0,0,0,0,0,0,0,0,0,4,0,0,0,2,1
1,1,2,0,4,4,4,0,0,0,0,0,0,0,0,0,4,4,4,0,2,1,1
1,1,2,0,0,4,0,0,0,0,0,4,0,0,0,0,0,4,0,0,2,1,1
1,1,1,2,0,0,0,0,0,0,4,4,4,0,0,0,0,0,0,2,1,1,1
1,1,1,1,2,2,0,0,0,0,0,4,0,0,0,0,0,2,2,1,1,1,1
1,1,1,1,1,1,2,2,0,0,0,0,0,0,0,2,2,1,1,1,1,1,1
1,1,1,1,1,1,1,1,2,2,2,2,2,2,2,1,1,1,1,1,1,1,1
endlayer

layer
1,1,1,1,1,1,1,1,2,2,2,2,2,2,2,1,1,1,1,1,1,1,1
1,1,1,1,1,1,2,2,7,3,3,3,3,3,3,2,2,1,1,1,1,1,1
1,1,1,1,2,2,0,5,6,3,3,4,3,3,3,3,3,2,2,1,1,1,1
1,1,1,2,0,0,0,3,3,3,4,4,4,3,3,3,3,3,3,2,1,1,1
1,1,2,3,0,4,3,3,3,3,3,4,3,3,3,3,3,4,3,3,2,1,1
1,1,2,3,4,4,4,3,3,3,3,3,3,3,3,3,4,4,4,3,2,1,1
1,2,3,3,3,4,3,3,3,3,3,3,3,3,3,3,3,4,3,3,3,2,1
1,2,3,3,3,3,3,3,3,3,3,3,3,3,3,3,3,3,3,3,3,2,1
2,3,3,3,3,3,3,3,3,3,4,4,4,3,3,3,3,3,3,3,3,3,2
2,3,3,3,3,3,3,3,3,4,4,4,4,4,3,3,3,3,3,3,3,3,2
2,3,3,4,3,3,3,3,4,4,4,4,4,4,4,3,3,3,3,4,3,3,2
2,3,4,4,4,3,3,3,4,4,4,4,4,4,4,3,3,3,4,4,4,3,2
2,3,3,4,3,3,3,3,4,4,4,4,4,4,4,3,3,3,3,4,3,3,2
2,3,3,3,3,3,3,3,3,4,4,4,4,4,3,3,3,3,3,3,3,3,2
2,3,3,3,3,3,3,3,3,3,4,4,4,3,3,3,3,3,3,3,3,3,2
1,2,3,3,3,3,3,3,3,3,3,3,3,3,3,3,3,3,3,3,3,2,1
1,2,3,3,3,4,3,3,3,3,3,3,3,3,3,3,3,4,3,3,3,2,1
1,1,2,3,4,4,4,3,3,3,3,3,3,3,3,3,4,4,4,3,2,1,1
1,1,2,3,3,4,3,3,3,3,3,4,3,3,3,3,3,4,3,3,2,1,1
1,1,1,2,3,3,3,3,3,3,4,4,4,3,3,3,3,3,3,2,1,1,1
1,1,1,1,2,2,3,3,3,3,3,4,3,3,3,3,3,2,2,1,1,1,1
1,1,1,1,1,1,2,2,3,3,3,3,3,3,3,2,2,1,1,1,1,1,1
1,1,1,1,1,1,1,1,2,2,2,2,2,2,2,1,1,1,1,1,1,1,1
endlayer

layer
1,1,1,1,1,1,1,1,2,2,3,3,3,2,2,1,1,1,1,1,1,1,1
1,1,1,1,1,1,2,2,0,0,0,0,0,0,0,2,2,1,1,1,1,1,1
1,1,1,1,2,2,0,0,0,0,0,4,0,0,0,0,0,2,2,1,1,1,1
1,1,1,2,0,0,0,0,0,0,4,4,4,0,0,0,0,0,0,2,1,1,1
1,1,2,0,0,4,0,0,0,0,0,4,0,0,0,0,0,4,0,0,2,1,1
1,1,2,0,4,4,4,0,0,0,0,0,0,0,0,0,4,4,4,0,2,1,1
1,2,0,0,0,4,0,0,0,0,0,0,0,0,0,0,0,4,0,0,0,2,1
1,2,0,0,0,0,0,0,0,0,0,0,0,0,0,0,0,0,0,0,0,2,1
2,0,0,0,0,0,0,0,0,0,3,3,3,0,0,0,0,0,0,0,0,0,2
2,0,0,0,0,0,0,0,0,3,3,14,3,3,0,0,0,0,0,0,0,0,2
3,0,0,4,0,0,0,0,3,3,8,8,8,3,3,0,0,0,0,4,0,0,3
3,0,4,4,4,0,0,0,3,14,8,9,8,14,3,0,0,0,4,4,4,0,3
3,0,0,4,0,0,0,0,3,3,8,8,8,3,3,0,0,0,0,4,0,0,3
2,0,0,0,0,0,0,0,0,3,3,14,3,3,0,0,0,0,0,0,0,0,2
2,0,0,0,0,0,0,0,0,0,3,3,3,0,0,0,0,0,0,0,6,5,2
1,2,0,0,0,0,0,0,0,0,0,0,0,0,0,0,0,0,0,0,7,2,1
1,2,0,0,0,4,0,0,0,0,0,0,0,0,0,0,0,4,0,0,0,2,1
1,1,2,0,4,4,4,0,0,0,0,0,0,0,0,0,4,4,4,0,2,1,1
1,1,2,0,0,4,0,0,0,0,0,4,0,0,0,0,0,4,0,0,2,1,1
1,1,1,2,0,0,0,0,0,0,4,4,4,0,0,0,0,0,0,2,1,1,1
1,1,1,1,2,2,0,0,0,0,0,4,0,0,0,0,0,2,2,1,1,1,1
1,1,1,1,1,1,2,2,0,0,0,0,0,0,0,2,2,1,1,1,1,1,1
1,1,1,1,1,1,1,1,2,2,3,3,3,2,2,1,1,1,1,1,1,1,1
endlayer

layer
1,1,1,1,1,1,1,1,2,2,3,3,3,2,2,1,1,1,1,1,1,1,1
1,1,1,1,1,1,2,2,0,0,0,0,0,0,0,2,2,1,1,1,1,1,1
1,1,1,1,2,2,0,0,0,0,0,10,0,0,0,0,0,2,2,1,1,1,1
1,1,1,2,0,0,0,0,0,0,0,4,0,0,0,0,0,0,0,2,1,1,1
1,1,2,0,0,0,0,0,0,0,0,0,0,0,0,0,0,0,0,0,2,1,1
1,1,2,0,0,4,0,0,0,0,0,0,0,0,0,0,0,4,0,0,2,1,1
1,2,0,0,0,0,0,0,0,0,0,0,0,0,0,0,0,0,0,0,0,2,1
1,2,0,0,0,0,0,0,0,0,0,0,0,0,0,0,0,0,0,0,0,2,1
2,0,0,0,0,0,0,0,0,0,3,3,3,0,0,0,0,0,0,0,0,0,2
2,0,0,0,0,0,0,0,0,3,3,8,3,3,0,0,0,0,0,0,0,0,2
3,0,0,0,0,0,0,0,3,3,8,8,8,3,3,0,0,0,0,0,0,0,3
3,0,12,4,0,0,0,0,3,8,8,9,8,8,3,0,0,0,0,4,11,0,3
3,0,0,0,0,0,0,0,3,3,8,8,8,3,3,0,0,0,0,0,0,0,3
2,0,0,0,0,0,0,0,0,3,3,8,3,3,0,0,0,0,0,0,0,0,2
2,0,0,0,0,0,0,0,0,0,3,3,3,0,0,0,0,0,0,0,0,0,2
1,2,0,0,0,0,0,0,0,0,0,0,0,0,0,0,0,0,0,0,5,2,1
1,2,0,0,0,0,0,0,0,0,0,0,0,0,0,0,0,0,0,7,6,2,1
1,1,2,0,0,4,0,0,0,0,0,0,0,0,0,0,0,4,0,0,2,1,1
1,1,2,0,0,0,0,0,0,0,0,0,0,0,0,0,0,0,0,0,2,1,1
1,1,1,2,0,0,0,0,0,0,0,4,0,0,0,0,0,0,0,2,1,1,1
1,1,1,1,2,2,0,0,0,0,0,13,0,0,0,0,0,2,2,1,1,1,1
1,1,1,1,1,1,2,2,0,0,0,0,0,0,0,2,2,1,1,1,1,1,1
1,1,1,1,1,1,1,1,2,2,3,3,3,2,2,1,1,1,1,1,1,1,1
endlayer

layer
1,1,1,1,1,1,1,1,2,2,4,3,4,2,2,1,1,1,1,1,1,1,1
1,1,1,1,1,1,2,2,0,0,0,0,0,0,0,2,2,1,1,1,1,1,1
1,1,1,1,2,2,0,0,0,0,0,0,0,0,0,0,0,2,2,1,1,1,1
1,1,1,2,0,0,0,0,0,0,0,4,0,0,0,0,0,0,0,2,1,1,1
1,1,2,0,0,0,0,0,0,0,0,0,0,0,0,0,0,0,0,0,2,1,1
1,1,2,0,0,4,0,0,0,0,0,0,0,0,0,0,0,4,0,0,2,1,1
1,2,0,0,0,0,0,0,0,0,0,0,0,0,0,0,0,0,0,0,0,2,1
1,2,0,0,0,0,0,0,0,0,0,0,0,0,0,0,0,0,0,0,0,2,1
2,0,0,0,0,0,0,0,0,0,3,3,3,0,0,0,0,0,0,0,0,0,2
2,0,0,0,0,0,0,0,0,3,3,8,3,3,0,0,0,0,0,0,0,0,2
4,0,0,0,0,0,0,0,3,3,8,8,8,3,3,0,0,0,0,0,0,0,4
3,0,0,4,0,0,0,0,3,8,8,9,8,8,3,0,0,0,0,4,0,0,3
4,0,0,0,0,0,0,0,3,3,8,8,8,3,3,0,0,0,0,0,0,0,4
2,0,0,0,0,0,0,0,0,3,3,8,3,3,0,0,0,0,0,0,0,0,2
2,0,0,0,0,0,0,0,0,0,3,3,3,0,0,0,0,0,0,0,0,0,2
1,2,0,0,0,0,0,0,0,0,0,0,0,0,0,0,0,0,0,0,0,2,1
1,2,0,0,0,0,0,0,0,0,0,0,0,0,0,0,0,0,0,5,0,2,1
1,1,2,0,0,4,0,0,0,0,0,0,0,0,0,0,0,4,0,6,2,1,1
1,1,2,0,0,0,0,0,0,0,0,0,0,0,0,0,0,0,0,7,2,1,1
1,1,1,2,0,0,0,0,0,0,0,4,0,0,0,0,0,0,0,2,1,1,1
1,1,1,1,2,2,0,0,0,0,0,0,0,0,0,0,0,2,2,1,1,1,1
1,1,1,1,1,1,2,2,0,0,0,0,0,0,0,2,2,1,1,1,1,1,1
1,1,1,1,1,1,1,1,2,2,4,3,4,2,2,1,1,1,1,1,1,1,1
endlayer

layer
1,1,1,1,1,1,1,1,2,2,4,3,4,2,2,1,1,1,1,1,1,1,1
1,1,1,1,1,1,2,2,0,0,0,0,0,0,0,2,2,1,1,1,1,1,1
1,1,1,1,2,2,0,0,0,0,0,0,0,0,0,0,0,2,2,1,1,1,1
1,1,1,2,0,0,0,0,0,0,0,4,0,0,0,0,0,0,0,2,1,1,1
1,1,2,0,0,0,0,0,0,0,0,0,0,0,0,0,0,0,0,0,2,1,1
1,1,2,0,0,4,0,0,0,0,0,0,0,0,0,0,0,4,0,0,2,1,1
1,2,0,0,0,0,0,0,0,0,0,0,0,0,0,0,0,0,0,0,0,2,1
1,2,0,0,0,0,0,0,0,0,0,0,0,0,0,0,0,0,0,0,0,2,1
2,0,0,0,0,0,0,0,0,0,3,3,3,0,0,0,0,0,0,0,0,0,2
2,0,0,0,0,0,0,0,0,3,3,8,3,3,0,0,0,0,0,0,0,0,2
4,0,0,0,0,0,0,0,3,3,8,8,8,3,3,0,0,0,0,0,0,0,4
3,0,0,4,0,0,0,0,3,8,8,9,8,8,3,0,0,0,0,4,0,0,3
4,0,0,0,0,0,0,0,3,3,8,8,8,3,3,0,0,0,0,0,0,0,4
2,0,0,0,0,0,0,0,0,3,3,8,3,3,0,0,0,0,0,0,0,0,2
2,0,0,0,0,0,0,0,0,0,3,3,3,0,0,0,0,0,0,0,0,0,2
1,2,0,0,0,0,0,0,0,0,0,0,0,0,0,0,0,0,0,0,0,2,1
1,2,0,0,0,0,0,0,0,0,0,0,0,0,0,0,0,0,0,0,0,2,1
1,1,2,0,0,4,0,0,0,0,0,0,0,0,0,0,0,4,0,0,2,1,1
1,1,2,0,0,0,0,0,0,0,0,0,0,0,0,0,0,0,6,5,2,1,1
1,1,1,2,0,0,0,0,0,0,0,4,0,0,0,0,0,0,7,2,1,1,1
1,1,1,1,2,2,0,0,0,0,0,0,0,0,0,0,0,2,2,1,1,1,1
1,1,1,1,1,1,2,2,0,0,0,0,0,0,0,2,2,1,1,1,1,1,1
1,1,1,1,1,1,1,1,2,2,4,3,4,2,2,1,1,1,1,1,1,1,1
endlayer

layer
1,1,1,1,1,1,1,1,2,2,2,4,2,2,2,1,1,1,1,1,1,1,1
1,1,1,1,1,1,2,2,0,0,0,0,0,0,0,2,2,1,1,1,1,1,1
1,1,1,1,2,2,0,0,0,0,0,4,0,0,0,0,0,2,2,1,1,1,1
1,1,1,2,0,0,0,0,0,0,4,4,4,0,0,0,0,0,0,2,1,1,1
1,1,2,0,0,4,0,0,0,0,0,4,0,0,0,0,0,4,0,0,2,1,1
1,1,2,0,4,4,4,0,0,0,0,0,0,0,0,0,4,4,4,0,2,1,1
1,2,0,0,0,4,0,0,0,0,0,0,0,0,0,0,0,4,0,0,0,2,1
1,2,0,0,0,0,0,0,0,0,0,0,0,0,0,0,0,0,0,0,0,2,1
2,0,0,0,0,0,0,0,0,0,3,3,3,0,0,0,0,0,0,0,0,0,2
2,0,0,0,0,0,0,0,0,3,3,8,3,3,0,0,0,0,0,0,0,0,2
2,0,0,4,0,0,0,0,3,3,8,8,8,3,3,0,0,0,0,4,0,0,2
4,0,4,4,4,0,0,0,3,8,8,9,8,8,3,0,0,0,4,4,4,0,4
2,0,0,4,0,0,0,0,3,3,8,8,8,3,3,0,0,0,0,4,0,0,2
2,0,0,0,0,0,0,0,0,3,3,8,3,3,0,0,0,0,0,0,0,0,2
2,0,0,0,0,0,0,0,0,0,3,3,3,0,0,0,0,0,0,0,0,0,2
1,2,0,0,0,0,0,0,0,0,0,0,0,0,0,0,0,0,0,0,0,2,1
1,2,0,0,0,4,0,0,0,0,0,0,0,0,0,0,0,4,0,0,0,2,1
1,1,2,0,4,4,4,0,0,0,0,0,0,0,0,0,4,4,4,0,2,1,1
1,1,2,0,0,4,0,0,0,0,0,4,0,0,0,0,0,4,0,0,2,1,1
1,1,1,2,0,0,0,0,0,0,4,4,4,0,0,0,7,6,5,2,1,1,1
1,1,1,1,2,2,0,0,0,0,0,4,0,0,0,0,0,2,2,1,1,1,1
1,1,1,1,1,1,2,2,0,0,0,0,0,0,0,2,2,1,1,1,1,1,1
1,1,1,1,1,1,1,1,2,2,2,4,2,2,2,1,1,1,1,1,1,1,1
endlayer

layer
1,1,1,1,1,1,1,1,2,2,2,2,2,2,2,1,1,1,1,1,1,1,1
1,1,1,1,1,1,2,2,0,0,0,0,0,0,0,2,2,1,1,1,1,1,1
1,1,1,1,2,2,0,0,0,0,0,4,0,0,0,0,0,2,2,1,1,1,1
1,1,1,2,0,0,0,0,0,0,4,4,4,0,0,0,0,0,0,2,1,1,1
1,1,2,0,0,4,0,0,0,0,0,4,0,0,0,0,0,4,0,0,2,1,1
1,1,2,0,4,4,4,0,0,0,0,0,0,0,0,0,4,4,4,0,2,1,1
1,2,0,0,0,4,0,0,0,0,0,0,0,0,0,0,0,4,0,0,0,2,1
1,2,0,0,0,0,0,0,0,0,0,0,0,0,0,0,0,0,0,0,0,2,1
2,0,0,0,0,0,0,0,0,0,3,3,3,0,0,0,0,0,0,0,0,0,2
2,0,0,0,0,0,0,0,0,3,3,8,3,3,0,0,0,0,0,0,0,0,2
2,0,0,4,0,0,0,0,3,3,8,8,8,3,3,0,0,0,0,4,0,0,2
2,0,4,4,4,0,0,0,3,8,8,9,8,8,3,0,0,0,4,4,4,0,2
2,0,0,4,0,0,0,0,3,3,8,8,8,3,3,0,0,0,0,4,0,0,2
2,0,0,0,0,0,0,0,0,3,3,8,3,3,0,0,0,0,0,0,0,0,2
2,0,0,0,0,0,0,0,0,0,3,3,3,0,0,0,0,0,0,0,0,0,2
1,2,0,0,0,0,0,0,0,0,0,0,0,0,0,0,0,0,0,0,0,2,1
1,2,0,0,0,4,0,0,0,0,0,0,0,0,0,0,0,4,0,0,0,2,1
1,1,2,0,4,4,4,0,0,0,0,0,0,0,0,0,4,4,4,0,2,1,1
1,1,2,0,0,4,0,0,0,0,0,4,0,0,0,0,0,4,0,0,2,1,1
1,1,1,2,0,0,0,0,0,0,4,4,4,0,0,0,5,0,0,2,1,1,1
1,1,1,1,2,2,0,0,0,0,0,4,0,0,0,7,6,2,2,1,1,1,1
1,1,1,1,1,1,2,2,0,0,0,0,0,0,0,2,2,1,1,1,1,1,1
1,1,1,1,1,1,1,1,2,2,2,2,2,2,2,1,1,1,1,1,1,1,1
endlayer

layer
1,1,1,1,1,1,1,1,2,2,2,2,2,2,2,1,1,1,1,1,1,1,1
1,1,1,1,1,1,2,2,3,3,3,3,3,3,3,2,2,1,1,1,1,1,1
1,1,1,1,2,2,3,3,3,3,3,4,3,3,3,3,3,2,2,1,1,1,1
1,1,1,2,3,3,3,3,3,3,4,4,4,3,3,3,3,3,3,2,1,1,1
1,1,2,3,3,4,3,3,3,3,3,4,3,3,3,3,3,4,3,3,2,1,1
1,1,2,3,4,4,4,3,3,3,3,3,3,3,3,3,4,4,4,3,2,1,1
1,2,3,3,3,4,3,3,3,3,3,3,3,3,3,3,3,4,3,3,3,2,1
1,2,3,3,3,3,3,3,3,3,3,3,3,3,3,3,3,3,3,3,3,2,1
2,3,3,3,3,3,3,3,3,3,4,4,4,3,3,3,3,3,3,3,3,3,2
2,3,3,3,3,3,3,3,3,4,4,4,4,4,3,3,3,3,3,3,3,3,2
2,3,3,4,3,3,3,3,4,4,4,4,4,4,4,3,3,3,3,4,3,3,2
2,3,4,4,4,3,3,3,4,4,4,4,4,4,4,3,3,3,4,4,4,3,2
2,3,3,4,3,3,3,3,4,4,4,4,4,4,4,3,3,3,3,4,3,3,2
2,3,3,3,3,3,3,3,3,4,4,4,4,4,3,3,3,3,3,3,3,3,2
2,3,3,3,3,3,3,3,3,3,4,4,4,3,3,3,3,3,3,3,3,3,2
1,2,3,3,3,3,3,3,3,3,3,3,3,3,3,3,3,3,3,3,3,2,1
1,2,3,3,3,4,3,3,3,3,3,3,3,3,3,3,3,4,3,3,3,2,1
1,1,2,3,4,4,4,3,3,3,3,3,3,3,3,3,4,4,4,3,2,1,1
1,1,2,3,3,4,3,3,3,3,3,4,3,3,3,3,3,4,0,3,2,1,1
1,1,1,2,3,3,3,3,3,3,4,4,4,3,3,3,0,0,0,2,1,1,1
1,1,1,1,2,2,3,3,3,3,3,4,3,3,6,5,0,2,2,1,1,1,1
1,1,1,1,1,1,2,2,3,3,3,3,3,3,7,2,2,1,1,1,1,1,1
1,1,1,1,1,1,1,1,2,2,2,2,2,2,2,1,1,1,1,1,1,1,1
endlayer

