# Sandstone Dungeon Room - N/S Corridor (Trapped)
# Created by Ruins mod version 14.6 Ingame Parser
# authoring Player: Jordan_Greywolf
# MC 1.7.10; 3 Jan 2015
# Updated to MC 1.11: 12 Jan 2017


weight=1
embed_into_distance=0
acceptable_target_blocks=
unacceptable_target_blocks=flowing_water,water,flowing_lava,lava
dimensions=11,13,13
allowable_overhang=0
max_leveling=0
leveling_buffer=0
preserve_water=0
preserve_lava=0

rule1=0,100,minecraft:sandstone-2
rule2=0,100,minecraft:sandstone-0
rule3=0,100,minecraft:sandstone-1
rule4=0,100,minecraft:stained_hardened_clay-1
rule5=0,100,minecraft:stained_hardened_clay-11
rule6=0,100,minecraft:stained_hardened_clay-0
rule7=1,100,minecraft:redstone_torch-5
rule8=0,100,minecraft:sandstone_stairs-0
rule9=0,100,minecraft:tripwire_hook-7
rule10=0,100,minecraft:sandstone_stairs-1
rule11=0,100,minecraft:tripwire-4
rule12=0,100,minecraft:web-0,minecraft:web-0
rule13=0,100,minecraft:tripwire_hook-5
rule14=0,100,Skull:0:12-1
rule15=0,100,IInventory;minecraft:dispenser;minecraft:arrow#16#0#0-5
rule16=0,100,minecraft:sandstone_stairs-5
rule17=0,100,minecraft:sandstone_stairs-4
rule18=0,100,IInventory;minecraft:dispenser;minecraft:arrow#16#0#0-4
rule19=0,100,Skull:0:4-1
rule20=0,100,minecraft:sandstone_stairs-7
rule21=0,100,minecraft:sandstone_stairs-6
rule22=0,100,preserveBlock

layer
1,1,1,1,1,1,1,1,1,1,1,1,1
1,2,2,2,2,2,2,2,2,2,2,2,1
1,2,2,2,2,1,1,1,2,2,2,2,1
1,2,2,2,2,2,2,2,2,2,2,2,1
1,2,2,2,2,3,3,3,2,2,2,2,1
1,2,4,2,5,2,4,2,5,2,4,2,1
1,2,6,2,6,2,6,2,6,2,6,2,1
1,2,4,2,5,2,4,2,5,2,4,2,1
2,2,2,2,2,3,3,3,2,2,2,2,1
2,2,2,2,2,2,2,2,2,2,2,2,1
2,2,2,2,2,1,1,1,2,2,2,2,1
2,2,2,2,2,2,2,2,2,2,2,2,1
1,2,2,2,2,1,1,1,2,2,2,2,1
endlayer

layer
1,2,2,2,2,1,7,1,2,2,2,2,1
2,1,1,1,1,1,8,1,1,1,1,1,2
2,1,1,1,1,1,1,1,1,1,1,1,2
2,1,1,2,1,1,1,1,1,2,1,1,2
2,9,10,9,10,9,10,9,10,9,10,9,2
1,11,0,11,0,11,0,11,0,11,0,11,1
12,11,0,11,0,11,0,11,0,11,0,11,12
1,11,0,11,0,11,0,11,0,11,0,11,1
2,13,8,13,8,13,8,13,8,13,8,13,2
2,1,1,2,1,1,1,1,1,2,1,1,2
2,1,1,1,1,1,1,1,1,1,1,1,2
2,1,1,1,1,1,10,1,1,1,1,1,2
1,2,2,2,2,1,7,1,2,2,2,2,1
endlayer

layer
1,2,3,3,3,1,0,1,3,3,3,2,1
2,1,1,1,1,3,14,3,1,1,1,1,2
3,1,1,1,1,1,3,1,1,1,1,1,3
1,15,1,15,1,15,1,15,1,15,1,15,1
3,0,16,0,16,0,16,0,16,0,16,0,3
1,0,0,0,0,0,0,0,0,0,0,0,1
12,0,0,0,0,0,0,0,0,0,0,0,12
1,0,0,0,0,0,0,0,0,0,0,0,1
3,0,17,0,17,0,17,0,17,0,17,0,3
1,18,1,18,1,18,1,18,1,18,1,18,1
3,1,1,1,1,1,3,1,1,1,1,1,3
2,1,1,1,1,3,19,3,1,1,1,1,2
1,2,3,3,3,1,0,1,3,3,3,2,1
endlayer

layer
1,2,3,3,3,1,0,1,3,3,3,2,1
2,1,1,1,1,1,17,1,1,1,1,1,2
3,1,1,1,1,1,1,1,1,1,1,1,3
1,3,1,3,1,3,1,3,1,3,1,3,1
3,0,19,0,19,0,19,0,19,0,19,0,3
1,0,0,0,0,0,0,0,0,0,0,0,1
12,0,0,0,0,0,0,0,0,0,0,0,12
1,0,0,0,0,0,0,0,0,0,0,0,1
3,0,14,0,14,0,14,0,14,0,14,0,3
1,3,1,3,1,3,1,3,1,3,1,3,1
3,1,1,1,1,1,1,1,1,1,1,1,3
2,1,1,1,1,1,16,1,1,1,1,1,2
1,2,3,3,3,1,0,1,3,3,3,2,1
endlayer

layer
1,2,2,2,2,1,1,1,2,2,2,2,1
2,1,1,1,1,1,1,1,1,1,1,1,2
2,1,1,1,1,1,1,1,1,1,1,1,2
1,3,1,3,1,3,1,3,1,3,1,3,1
2,12,0,0,0,0,0,0,0,0,0,12,2
1,0,0,0,0,0,0,0,0,0,0,0,1
1,0,0,0,0,0,0,0,0,0,0,0,1
1,0,0,0,0,0,0,0,0,0,0,0,1
2,12,0,0,0,0,0,0,0,0,0,12,2
1,3,1,3,1,3,1,3,1,3,1,3,1
2,1,1,1,1,1,1,1,1,1,1,1,2
2,1,1,1,1,1,1,1,1,1,1,1,2
1,2,2,2,2,1,1,1,2,2,2,2,1
endlayer

layer
1,1,1,1,1,1,1,1,1,1,1,1,1
1,1,1,1,1,1,1,1,1,1,1,1,1
1,1,1,1,1,1,1,1,1,1,1,1,1
1,1,1,1,1,1,1,1,1,1,1,1,1
1,21,20,16,21,0,0,0,20,16,21,20,1
1,21,0,0,0,0,0,0,0,0,12,20,1
1,21,0,0,0,0,0,0,0,0,0,20,1
1,21,0,0,0,0,0,0,0,0,12,20,1
1,21,20,17,21,0,0,0,20,17,21,20,1
1,1,1,1,1,1,1,1,1,1,1,1,1
1,1,1,1,1,1,1,1,1,1,1,1,1
1,1,1,1,1,1,1,1,1,1,1,1,1
1,1,1,1,1,1,1,1,1,1,1,1,1
endlayer

layer
22,22,22,22,22,1,1,1,22,22,22,22,22
22,1,1,1,1,1,1,1,1,1,1,1,22
22,1,1,1,1,1,1,1,1,1,1,1,22
22,1,1,1,1,1,1,1,1,1,1,1,22
22,1,1,1,1,0,0,0,1,1,1,1,22
1,1,21,0,12,0,0,0,0,0,20,1,1
1,1,21,0,0,0,0,0,0,0,20,1,1
1,1,21,12,0,0,0,0,0,0,20,1,1
22,1,1,1,1,0,0,0,1,1,1,1,22
22,1,1,1,1,1,1,1,1,1,1,1,22
22,1,1,1,1,3,3,3,1,1,1,1,22
22,1,1,1,1,1,1,1,1,1,1,1,22
22,22,22,22,22,1,1,1,22,22,22,22,22
endlayer

layer
22,22,22,22,22,1,1,1,22,22,22,22,22
22,22,22,22,22,1,1,1,22,22,22,22,22
22,22,1,1,1,1,1,1,1,1,1,22,22
22,22,1,1,1,1,1,1,1,1,1,22,22
22,22,1,1,1,12,0,12,1,1,1,22,22
1,1,1,21,0,0,0,0,0,20,1,1,1
1,1,1,21,0,0,0,0,12,20,1,1,1
1,1,1,21,12,0,0,0,0,20,1,1,1
22,22,1,1,1,12,0,12,1,1,1,22,22
22,22,1,1,1,1,1,1,1,1,1,22,22
22,22,1,1,1,1,1,1,1,1,1,22,22
22,22,22,22,22,1,1,1,22,22,22,22,22
22,22,22,22,22,1,1,1,22,22,22,22,22
endlayer

layer
22,22,22,22,22,22,1,22,22,22,22,22,22
22,22,22,22,22,22,1,22,22,22,22,22,22
22,22,22,22,22,22,1,22,22,22,22,22,22
22,22,22,1,1,1,1,1,1,1,22,22,22
22,22,22,1,1,16,16,16,1,1,22,22,22
22,22,22,1,21,12,0,0,20,1,22,22,22
1,1,1,1,21,0,0,0,20,1,1,1,1
22,22,22,1,21,12,0,12,20,1,22,22,22
22,22,22,1,1,17,17,17,1,1,22,22,22
22,22,22,1,1,1,1,1,1,1,22,22,22
22,22,22,22,22,22,1,22,22,22,22,22,22
22,22,22,22,22,22,1,22,22,22,22,22,22
22,22,22,22,22,22,1,22,22,22,22,22,22
endlayer

layer
22,22,22,22,22,22,22,22,22,22,22,22,22
22,22,22,22,22,22,22,22,22,22,22,22,22
22,22,22,22,22,22,22,22,22,22,22,22,22
22,22,22,22,22,22,22,22,22,22,22,22,22
22,22,22,22,1,1,1,1,1,22,22,22,22
22,22,22,22,1,21,16,20,1,22,22,22,22
22,22,22,22,1,21,2,20,1,22,22,22,22
22,22,22,22,1,17,17,20,1,22,22,22,22
22,22,22,22,1,1,1,1,1,22,22,22,22
22,22,22,22,22,22,22,22,22,22,22,22,22
22,22,22,22,22,22,22,22,22,22,22,22,22
22,22,22,22,22,22,22,22,22,22,22,22,22
22,22,22,22,22,22,22,22,22,22,22,22,22
endlayer

layer
22,22,22,22,22,22,22,22,22,22,22,22,22
22,22,22,22,22,22,22,22,22,22,22,22,22
22,22,22,22,22,22,22,22,22,22,22,22,22
22,22,22,22,22,22,22,22,22,22,22,22,22
22,22,22,22,22,22,22,22,22,22,22,22,22
22,22,22,22,22,1,1,1,22,22,22,22,22
22,22,22,22,22,1,1,1,22,22,22,22,22
22,22,22,22,22,1,1,1,22,22,22,22,22
22,22,22,22,22,22,22,22,22,22,22,22,22
22,22,22,22,22,22,22,22,22,22,22,22,22
22,22,22,22,22,22,22,22,22,22,22,22,22
22,22,22,22,22,22,22,22,22,22,22,22,22
22,22,22,22,22,22,22,22,22,22,22,22,22
endlayer

