# Sandstone Dungeon Room - Ladder
# Created by Ruins mod version 14.6 Ingame Parser
# authoring Player: Jordan_Greywolf
# MC 1.7.10; 3 Jan 2015
# Updated to MC 1.11: 12 Jan 2017


weight=1
embed_into_distance=0
acceptable_target_blocks=
unacceptable_target_blocks=
dimensions=15,13,13
allowable_overhang=0
max_leveling=0
leveling_buffer=0
preserve_water=0
preserve_lava=0

rule1=0,100,minecraft:sandstone-2
rule2=0,100,minecraft:sandstone-0
rule3=0,100,minecraft:stained_hardened_clay-1
rule4=0,100,minecraft:stained_hardened_clay-0
rule5=0,100,minecraft:stained_hardened_clay-11
rule6=0,100,minecraft:sandstone_stairs-0
rule7=0,100,minecraft:sandstone_stairs-3
rule8=0,100,minecraft:sandstone_stairs-2
rule9=0,100,minecraft:sandstone_stairs-1
rule10=0,100,minecraft:sandstone-1
rule11=0,100,minecraft:ladder-5
rule12=0,100,Skull:0:4-1
rule13=0,100,Skull:0:8-1
rule14=0,100,Skull:0:0-1
rule15=0,100,Skull:0:12-1
rule16=0,100,minecraft:sandstone_stairs-5
rule17=0,100,minecraft:sandstone_stairs-6
rule18=0,100,minecraft:sandstone_stairs-7
rule19=0,100,minecraft:sandstone_stairs-4
rule20=0,100,preserveBlock

layer
1,1,1,1,1,1,1,1,1,1,1,1,1
1,2,2,2,2,2,2,2,2,2,2,2,1
1,2,2,2,2,3,4,3,2,2,2,2,1
1,2,2,2,2,2,2,2,2,2,2,2,1
1,2,2,2,2,5,4,5,2,2,2,2,1
1,2,3,2,5,1,1,1,5,2,3,2,1
1,2,4,2,4,1,4,1,4,2,4,2,1
1,2,3,2,5,1,1,1,5,2,3,2,1
2,2,2,2,2,5,4,5,2,2,2,2,1
2,2,2,2,2,2,2,2,2,2,2,2,1
2,2,2,2,2,3,4,3,2,2,2,2,1
2,2,2,2,2,2,2,2,2,2,2,2,1
1,2,2,2,2,1,1,1,2,2,2,2,1
endlayer

layer
1,2,2,2,2,1,0,1,2,2,2,2,1
2,0,0,0,0,0,0,0,0,0,0,0,2
2,0,7,6,6,0,0,0,7,6,6,0,2
2,0,7,2,8,0,0,0,7,2,8,0,2
2,0,9,9,8,0,0,0,9,9,8,0,2
1,0,0,0,0,0,1,0,0,0,0,0,1
0,0,0,0,0,0,0,0,0,0,0,0,0
1,0,0,0,0,0,0,0,0,0,0,0,1
2,0,7,6,6,0,0,0,7,6,6,0,2
2,0,7,2,8,0,0,0,7,2,8,0,2
2,0,9,9,8,0,0,0,9,9,8,0,2
2,0,0,0,0,0,0,0,0,0,0,0,2
1,2,2,2,2,1,0,1,2,2,2,2,1
endlayer

layer
1,2,10,9,10,1,0,1,10,9,10,2,1
2,0,0,0,0,0,0,0,0,0,0,0,2
10,0,0,0,0,0,0,0,0,0,0,0,10
8,0,0,10,0,0,0,0,0,10,0,0,7
10,0,0,0,0,0,0,0,0,0,0,0,10
1,0,0,0,0,0,1,0,0,0,0,0,1
0,0,0,0,0,0,11,0,0,0,0,0,0
1,0,0,0,0,0,0,0,0,0,0,0,1
10,0,0,0,0,0,0,0,0,0,0,0,10
8,0,0,10,0,0,0,0,0,10,0,0,7
10,0,0,0,0,0,0,0,0,0,0,0,10
2,0,0,0,0,0,0,0,0,0,0,0,2
1,2,10,6,10,1,0,1,10,6,10,2,1
endlayer

layer
1,2,10,12,10,1,0,1,10,12,10,2,1
2,0,0,0,0,0,0,0,0,0,0,0,2
10,0,0,0,0,0,0,0,0,0,0,0,10
14,0,0,2,0,0,0,0,0,2,0,0,13
10,0,0,0,0,0,0,0,0,0,0,0,10
1,0,0,0,0,0,1,0,0,0,0,0,1
0,0,0,0,0,0,11,0,0,0,0,0,0
1,0,0,0,0,0,0,0,0,0,0,0,1
10,0,0,0,0,0,0,0,0,0,0,0,10
14,0,0,2,0,0,0,0,0,2,0,0,13
10,0,0,0,0,0,0,0,0,0,0,0,10
2,0,0,0,0,0,0,0,0,0,0,0,2
1,2,10,15,10,1,0,1,10,15,10,2,1
endlayer

layer
1,2,2,2,2,1,1,1,2,2,2,2,1
2,0,0,0,0,0,0,0,0,0,0,0,2
2,0,0,0,0,0,0,0,0,0,0,0,2
2,0,0,10,0,0,0,0,0,10,0,0,2
2,0,0,0,0,0,0,0,0,0,0,0,2
1,0,0,0,0,0,1,0,0,0,0,0,1
1,0,0,0,0,0,11,0,0,0,0,0,1
1,0,0,0,0,0,0,0,0,0,0,0,1
2,0,0,0,0,0,0,0,0,0,0,0,2
2,0,0,10,0,0,0,0,0,10,0,0,2
2,0,0,0,0,0,0,0,0,0,0,0,2
2,0,0,0,0,0,0,0,0,0,0,0,2
1,2,2,2,2,1,1,1,2,2,2,2,1
endlayer

layer
1,1,1,1,1,1,1,1,1,1,1,1,1
1,17,16,16,16,16,16,16,16,16,16,16,1
1,17,18,19,19,0,0,0,0,0,0,18,1
1,17,18,1,17,0,0,0,0,1,0,18,1
1,17,16,16,17,0,0,0,0,0,0,18,1
1,17,0,0,0,0,1,0,0,0,0,18,1
1,17,0,0,0,0,11,0,0,0,0,18,1
1,17,0,0,0,0,0,0,0,0,0,18,1
1,17,0,0,0,0,0,0,0,0,0,18,1
1,17,0,1,0,0,0,0,0,1,0,18,1
1,17,0,0,0,0,0,0,0,0,0,18,1
1,17,19,19,19,19,19,19,19,19,19,18,1
1,1,1,1,1,1,1,1,1,1,1,1,1
endlayer

layer
1,1,1,1,1,1,1,1,1,1,1,1,1
1,17,16,16,16,16,16,16,16,16,16,16,1
1,17,18,19,19,0,0,0,18,19,19,18,1
1,17,18,1,17,0,0,0,18,1,17,18,1
1,17,16,16,17,0,0,0,16,16,17,18,1
1,17,0,0,0,0,1,0,0,0,0,18,1
1,17,0,0,0,0,11,0,0,0,0,18,1
1,17,0,0,0,0,0,0,0,0,0,18,1
1,17,18,19,19,0,0,0,18,19,19,18,1
1,17,18,1,17,0,0,0,18,1,17,18,1
1,17,16,16,17,0,0,0,16,16,17,18,1
1,17,19,19,19,19,19,19,19,19,19,18,1
1,1,1,1,1,1,1,1,1,1,1,1,1
endlayer

layer
20,20,20,20,20,1,1,1,20,20,20,20,20
20,1,1,1,1,1,1,1,1,1,1,1,20
20,1,1,1,1,0,0,0,1,1,1,1,20
20,1,1,1,1,0,0,0,1,1,1,1,20
20,1,1,1,1,0,0,0,1,1,1,1,20
1,1,0,0,0,0,1,0,0,0,0,1,1
1,1,0,0,0,0,11,0,0,0,0,1,1
1,1,0,0,0,0,0,0,0,0,0,1,1
20,1,1,1,1,0,0,0,1,1,1,1,20
20,1,1,1,1,0,0,0,1,1,1,1,20
20,1,1,1,1,0,0,0,1,1,1,1,20
20,1,1,1,1,1,1,1,1,1,1,1,20
20,20,20,20,20,1,1,1,20,20,20,20,20
endlayer

layer
20,20,20,20,20,1,1,1,20,20,20,20,20
20,1,1,1,1,1,1,1,1,1,1,1,20
20,1,1,1,1,16,16,16,1,1,1,1,20
20,1,1,1,1,0,0,0,1,1,1,1,20
20,1,1,1,1,0,0,0,1,1,1,1,20
1,1,17,0,0,0,1,0,0,0,18,1,1
1,1,17,0,0,0,11,0,0,0,18,1,1
1,1,17,0,0,0,0,0,0,0,18,1,1
20,1,1,1,1,0,0,0,1,1,1,1,20
20,1,1,1,1,0,0,0,1,1,1,1,20
20,1,1,1,1,19,19,19,1,1,1,1,20
20,1,1,1,1,1,1,1,1,1,1,1,20
20,20,20,20,20,1,1,1,20,20,20,20,20
endlayer

layer
20,20,20,20,20,1,1,1,20,20,20,20,20
20,20,20,20,20,1,1,1,20,20,20,20,20
20,20,1,1,1,1,1,1,1,1,1,20,20
20,20,1,1,1,0,0,0,1,1,1,20,20
20,20,1,1,1,0,0,0,1,1,1,20,20
1,1,1,0,0,0,1,0,0,0,1,1,1
1,1,1,0,0,0,11,0,0,0,1,1,1
1,1,1,0,0,0,0,0,0,0,1,1,1
20,20,1,1,1,0,0,0,1,1,1,20,20
20,20,1,1,1,0,0,0,1,1,1,20,20
20,20,1,1,1,1,1,1,1,1,1,20,20
20,20,20,20,20,1,1,1,20,20,20,20,20
20,20,20,20,20,1,1,1,20,20,20,20,20
endlayer

layer
20,20,20,20,20,1,1,1,20,20,20,20,20
20,20,20,20,20,1,1,1,20,20,20,20,20
20,20,1,1,1,1,1,1,1,1,1,20,20
20,20,1,1,1,16,16,16,1,1,1,20,20
20,20,1,1,1,0,0,0,1,1,1,20,20
1,1,1,17,0,0,1,0,0,18,1,1,1
1,1,1,17,0,0,11,0,0,18,1,1,1
1,1,1,17,0,0,0,0,0,18,1,1,1
20,20,1,1,1,0,0,0,1,1,1,20,20
20,20,1,1,1,19,19,19,1,1,1,20,20
20,20,1,1,1,1,1,1,1,1,1,20,20
20,20,20,20,20,1,1,1,20,20,20,20,20
20,20,20,20,20,1,1,1,20,20,20,20,20
endlayer

layer
20,20,20,20,20,20,1,20,20,20,20,20,20
20,20,20,20,20,20,1,20,20,20,20,20,20
20,20,20,20,20,20,1,20,20,20,20,20,20
20,20,20,1,1,1,1,1,1,1,20,20,20
20,20,20,1,1,0,0,0,1,1,20,20,20
20,20,20,1,0,0,1,0,0,1,20,20,20
1,1,1,1,0,0,11,0,0,1,1,1,1
20,20,20,1,0,0,0,0,0,1,20,20,20
20,20,20,1,1,0,0,0,1,1,20,20,20
20,20,20,1,1,1,1,1,1,1,20,20,20
20,20,20,20,20,20,1,20,20,20,20,20,20
20,20,20,20,20,20,1,20,20,20,20,20,20
20,20,20,20,20,20,1,20,20,20,20,20,20
endlayer

layer
20,20,20,20,20,20,1,20,20,20,20,20,20
20,20,20,20,20,20,1,20,20,20,20,20,20
20,20,20,20,20,20,1,20,20,20,20,20,20
20,20,20,1,1,1,1,1,1,1,20,20,20
20,20,20,1,1,16,16,16,1,1,20,20,20
20,20,20,1,17,0,1,0,18,1,20,20,20
1,1,1,1,17,0,11,0,18,1,1,1,1
20,20,20,1,17,0,0,0,18,1,20,20,20
20,20,20,1,1,19,19,19,1,1,20,20,20
20,20,20,1,1,1,1,1,1,1,20,20,20
20,20,20,20,20,20,1,20,20,20,20,20,20
20,20,20,20,20,20,1,20,20,20,20,20,20
20,20,20,20,20,20,1,20,20,20,20,20,20
endlayer

layer
20,20,20,20,20,20,20,20,20,20,20,20,20
20,20,20,20,20,20,20,20,20,20,20,20,20
20,20,20,20,20,20,20,20,20,20,20,20,20
20,20,20,10,10,10,10,10,10,10,20,20,20
20,20,20,10,1,1,1,1,1,10,20,20,20
20,20,20,10,1,16,1,16,1,10,20,20,20
20,20,20,10,1,17,11,18,1,10,20,20,20
20,20,20,10,1,19,19,18,1,10,20,20,20
20,20,20,10,1,1,1,1,1,10,20,20,20
20,20,20,10,10,10,10,10,10,10,20,20,20
20,20,20,20,20,20,20,20,20,20,20,20,20
20,20,20,20,20,20,20,20,20,20,20,20,20
20,20,20,20,20,20,20,20,20,20,20,20,20
endlayer

layer
20,20,20,20,20,20,20,20,20,20,20,20,20
20,20,20,20,20,20,20,20,20,20,20,20,20
20,20,20,20,20,20,20,20,20,20,20,20,20
20,20,20,10,10,10,10,10,10,10,20,20,20
20,20,20,10,3,5,4,5,3,10,20,20,20
20,20,20,10,5,1,10,1,5,10,20,20,20
20,20,20,10,4,10,11,10,4,10,20,20,20
20,20,20,10,5,1,10,1,5,10,20,20,20
20,20,20,10,3,5,4,5,3,10,20,20,20
20,20,20,10,10,10,10,10,10,10,20,20,20
20,20,20,20,20,20,20,20,20,20,20,20,20
20,20,20,20,20,20,20,20,20,20,20,20,20
20,20,20,20,20,20,20,20,20,20,20,20,20
endlayer

