# Sandstone Dungeon Room - N/S Corridor
# Created by Ruins mod version 14.6 Ingame Parser
# authoring Player: Jordan_Greywolf
# MC 1.7.10; 3 Jan 2015
# Updated to MC 1.11: 12 Jan 2017


weight=1
embed_into_distance=0
acceptable_target_blocks=
unacceptable_target_blocks=
dimensions=11,13,13
allowable_overhang=0
max_leveling=0
leveling_buffer=0
preserve_water=0
preserve_lava=0

rule1=0,100,minecraft:sandstone-2
rule2=0,100,minecraft:sandstone-0
rule3=0,100,minecraft:sandstone-1
rule4=0,100,minecraft:stained_hardened_clay-1
rule5=0,100,minecraft:stained_hardened_clay-11
rule6=0,100,minecraft:stained_hardened_clay-0
rule7=1,100,minecraft:redstone_torch-5
rule8=0,100,minecraft:sandstone_stairs-0
rule9=0,100,minecraft:sandstone_stairs-1
rule10=0,100,Skull:0:12-1
rule11=0,100,minecraft:sandstone_stairs-5
rule12=0,100,minecraft:sandstone_stairs-4
rule13=0,100,Skull:0:4-1
rule14=0,100,minecraft:web-0
rule15=0,100,minecraft:sandstone_stairs-7
rule16=0,100,minecraft:sandstone_stairs-6
rule17=0,100,preserveBlock

layer
1,1,1,1,1,1,1,1,1,1,1,1,1
1,2,2,2,2,2,2,2,2,2,2,2,1
1,2,2,2,2,1,1,1,2,2,2,2,1
1,2,2,2,2,2,2,2,2,2,2,2,1
1,2,2,2,2,3,3,3,2,2,2,2,1
1,2,4,2,5,2,4,2,5,2,4,2,1
1,2,6,2,6,2,6,2,6,2,6,2,1
1,2,4,2,5,2,4,2,5,2,4,2,1
2,2,2,2,2,3,3,3,2,2,2,2,1
2,2,2,2,2,2,2,2,2,2,2,2,1
2,2,2,2,2,1,1,1,2,2,2,2,1
2,2,2,2,2,2,2,2,2,2,2,2,1
1,2,2,2,2,1,1,1,2,2,2,2,1
endlayer

layer
1,2,2,2,2,1,7,1,2,2,2,2,1
2,1,1,1,1,1,8,1,1,1,1,1,2
2,1,1,1,1,1,1,1,1,1,1,1,2
2,1,1,2,1,1,1,1,1,2,1,1,2
2,9,9,9,9,9,9,9,9,9,9,9,2
1,0,0,0,0,0,0,0,0,0,0,0,1
0,0,0,0,0,0,0,0,0,0,0,0,0
1,0,0,0,0,0,0,0,0,0,0,0,1
2,8,8,8,8,8,8,8,8,8,8,8,2
2,1,1,2,1,1,1,1,1,2,1,1,2
2,1,1,1,1,1,1,1,1,1,1,1,2
2,1,1,1,1,1,9,1,1,1,1,1,2
1,2,2,2,2,1,7,1,2,2,2,2,1
endlayer

layer
1,2,3,3,3,1,0,1,3,3,3,2,1
2,1,1,1,1,3,10,3,1,1,1,1,2
3,1,1,1,1,1,3,1,1,1,1,1,3
1,3,1,3,1,3,1,3,1,3,1,3,1
3,0,11,0,11,0,11,0,11,0,11,0,3
1,0,0,0,0,0,0,0,0,0,0,0,1
0,0,0,0,0,0,0,0,0,0,0,0,0
1,0,0,0,0,0,0,0,0,0,0,0,1
3,0,12,0,12,0,12,0,12,0,12,0,3
1,3,1,3,1,3,1,3,1,3,1,3,1
3,1,1,1,1,1,3,1,1,1,1,1,3
2,1,1,1,1,3,13,3,1,1,1,1,2
1,2,3,3,3,1,0,1,3,3,3,2,1
endlayer

layer
1,2,3,3,3,1,0,1,3,3,3,2,1
2,1,1,1,1,1,12,1,1,1,1,1,2
3,1,1,1,1,1,1,1,1,1,1,1,3
1,3,1,3,1,3,1,3,1,3,1,3,1
3,0,13,0,13,0,13,0,13,0,13,0,3
1,0,0,0,0,0,0,0,0,0,0,0,1
0,0,0,0,0,0,0,0,0,0,0,0,0
1,0,0,0,0,0,0,0,0,0,0,0,1
3,0,10,0,10,0,10,0,10,0,10,0,3
1,3,1,3,1,3,1,3,1,3,1,3,1
3,1,1,1,1,1,1,1,1,1,1,1,3
2,1,1,1,1,1,11,1,1,1,1,1,2
1,2,3,3,3,1,0,1,3,3,3,2,1
endlayer

layer
1,2,2,2,2,1,1,1,2,2,2,2,1
2,1,1,1,1,1,1,1,1,1,1,1,2
2,1,1,1,1,1,1,1,1,1,1,1,2
1,3,1,3,1,3,1,3,1,3,1,3,1
2,14,0,0,0,0,0,0,0,0,0,14,2
1,0,0,0,0,0,0,0,0,0,0,0,1
1,0,0,0,0,0,0,0,0,0,0,0,1
1,0,0,0,0,0,0,0,0,0,0,0,1
2,14,0,0,0,0,0,0,0,0,0,14,2
1,3,1,3,1,3,1,3,1,3,1,3,1
2,1,1,1,1,1,1,1,1,1,1,1,2
2,1,1,1,1,1,1,1,1,1,1,1,2
1,2,2,2,2,1,1,1,2,2,2,2,1
endlayer

layer
1,1,1,1,1,1,1,1,1,1,1,1,1
1,1,1,1,1,1,1,1,1,1,1,1,1
1,1,1,1,1,1,1,1,1,1,1,1,1
1,1,1,1,1,1,1,1,1,1,1,1,1
1,16,15,11,16,0,0,0,15,11,16,15,1
1,16,0,0,0,0,0,0,0,0,14,15,1
1,16,0,0,0,0,0,0,0,0,0,15,1
1,16,0,0,0,0,0,0,0,0,14,15,1
1,16,15,12,16,0,0,0,15,12,16,15,1
1,1,1,1,1,1,1,1,1,1,1,1,1
1,1,1,1,1,1,1,1,1,1,1,1,1
1,1,1,1,1,1,1,1,1,1,1,1,1
1,1,1,1,1,1,1,1,1,1,1,1,1
endlayer

layer
17,17,17,17,17,1,1,1,17,17,17,17,17
17,1,1,1,1,1,1,1,1,1,1,1,17
17,1,1,1,1,1,1,1,1,1,1,1,17
17,1,1,1,1,1,1,1,1,1,1,1,17
17,1,1,1,1,0,0,0,1,1,1,1,17
1,1,16,0,14,0,0,0,0,0,15,1,1
1,1,16,0,0,0,0,0,0,0,15,1,1
1,1,16,14,0,0,0,0,0,0,15,1,1
17,1,1,1,1,0,0,0,1,1,1,1,17
17,1,1,1,1,1,1,1,1,1,1,1,17
17,1,1,1,1,3,3,3,1,1,1,1,17
17,1,1,1,1,1,1,1,1,1,1,1,17
17,17,17,17,17,1,1,1,17,17,17,17,17
endlayer

layer
17,17,17,17,17,1,1,1,17,17,17,17,17
17,17,17,17,17,1,1,1,17,17,17,17,17
17,17,1,1,1,1,1,1,1,1,1,17,17
17,17,1,1,1,1,1,1,1,1,1,17,17
17,17,1,1,1,14,0,14,1,1,1,17,17
1,1,1,16,0,0,0,0,0,15,1,1,1
1,1,1,16,0,0,0,0,14,15,1,1,1
1,1,1,16,14,0,0,0,0,15,1,1,1
17,17,1,1,1,14,0,14,1,1,1,17,17
17,17,1,1,1,1,1,1,1,1,1,17,17
17,17,1,1,1,1,1,1,1,1,1,17,17
17,17,17,17,17,1,1,1,17,17,17,17,17
17,17,17,17,17,1,1,1,17,17,17,17,17
endlayer

layer
17,17,17,17,17,17,1,17,17,17,17,17,17
17,17,17,17,17,17,1,17,17,17,17,17,17
17,17,17,17,17,17,1,17,17,17,17,17,17
17,17,17,1,1,1,1,1,1,1,17,17,17
17,17,17,1,1,11,11,11,1,1,17,17,17
17,17,17,1,16,14,0,0,15,1,17,17,17
1,1,1,1,16,0,0,0,15,1,1,1,1
17,17,17,1,16,14,0,14,15,1,17,17,17
17,17,17,1,1,12,12,12,1,1,17,17,17
17,17,17,1,1,1,1,1,1,1,17,17,17
17,17,17,17,17,17,1,17,17,17,17,17,17
17,17,17,17,17,17,1,17,17,17,17,17,17
17,17,17,17,17,17,1,17,17,17,17,17,17
endlayer

layer
17,17,17,17,17,17,17,17,17,17,17,17,17
17,17,17,17,17,17,17,17,17,17,17,17,17
17,17,17,17,17,17,17,17,17,17,17,17,17
17,17,17,17,17,17,17,17,17,17,17,17,17
17,17,17,17,1,1,1,1,1,17,17,17,17
17,17,17,17,1,16,11,15,1,17,17,17,17
17,17,17,17,1,16,2,15,1,17,17,17,17
17,17,17,17,1,12,12,15,1,17,17,17,17
17,17,17,17,1,1,1,1,1,17,17,17,17
17,17,17,17,17,17,17,17,17,17,17,17,17
17,17,17,17,17,17,17,17,17,17,17,17,17
17,17,17,17,17,17,17,17,17,17,17,17,17
17,17,17,17,17,17,17,17,17,17,17,17,17
endlayer

layer
17,17,17,17,17,17,17,17,17,17,17,17,17
17,17,17,17,17,17,17,17,17,17,17,17,17
17,17,17,17,17,17,17,17,17,17,17,17,17
17,17,17,17,17,17,17,17,17,17,17,17,17
17,17,17,17,17,17,17,17,17,17,17,17,17
17,17,17,17,17,1,1,1,17,17,17,17,17
17,17,17,17,17,1,1,1,17,17,17,17,17
17,17,17,17,17,1,1,1,17,17,17,17,17
17,17,17,17,17,17,17,17,17,17,17,17,17
17,17,17,17,17,17,17,17,17,17,17,17,17
17,17,17,17,17,17,17,17,17,17,17,17,17
17,17,17,17,17,17,17,17,17,17,17,17,17
17,17,17,17,17,17,17,17,17,17,17,17,17
endlayer

