# Sunken Dungeon Chamber (N)
# Created by Ruins mod version 15.1 Ingame Parser
# authoring Player: Jordan_Greywolf
# Updated to MC 1.8: 5 Mar 2016
# Updated to MC 1.9: 24 Apr 2016
# Updated to MC 1.11: 12 Jan 2017
# Updated to MC 1.12: 22 Jun 2017

weight=1
embed_into_distance=6

unacceptable_target_blocks=flowing_lava,lava,cloud,Natura:Cloud

dimensions=15,13,13
allowable_overhang=0
max_leveling=0
leveling_buffer=-1
preserve_water=0
preserve_lava=0

rule1=0,100,minecraft:stonebrick-1,minecraft:stonebrick-1,minecraft:stonebrick,minecraft:stonebrick-2

rule2=0,100,preserveBlock

rule3=0,100,minecraft:stained_hardened_clay-11
rule4=0,100,minecraft:stained_hardened_clay-9

rule5=0,100,minecraft:stonebrick-3

rule6=0,100,minecraft:glass_pane-0

# West
rule7=0,100,CommandBlock:RUINSTRIGGER /testruin TP_SunkenDungeon_PassW ~-7 ~-1 ~0:@,CommandBlock:RUINSTRIGGER /testruin TP_Decor_ChestVault ~-3 ~2 ~0:@

rule8=0,100,CommandBlock:RUINSTRIGGER /summon Skeleton ~0 ~0 ~0 {HandItems:[{Count:1,id:stained_glass,Damage:3,tag:{ench:[{id:19,lvl:2}]}},{}],ArmorItems:[{Count:8,id:fish,Damage:2},{Count:8,id:fish,Damage:1},{Count:8,id:fish},{Count:1,id:stained_glass,Damage:3,tag:{ench:[{id:5,lvl:50},{id:8,lvl:50}],display:{Name:"Water Anomaly"}}}],CustomName:"Water Guardian",Attributes:[{Name:generic.attackDamage,Base:6},{Name:generic.knockbackResistance,Base:1}],HandDropChances:[0.0F,0.0F],ArmorDropChances:[1.0F,1.0F,1.0F,0.0F],ActiveEffects:[{Id:12,Amplifier:1,Duration:999999,Ambient:1},{Id:14,Amplifier:1,Duration:999999,Ambient:1},{Id:13,Amplifier:1,Duration:999999,Ambient:1}],Silent:1,PersistenceRequired:1}:@

rule9=0,100,minecraft:cobblestone_wall-1,minecraft:cobblestone_wall

# North
rule10=0,100,CommandBlock:RUINSTRIGGER /testruin TP_SunkenDungeon_PassN ~0 ~-1 ~-7:@,CommandBlock:RUINSTRIGGER /testruin TP_Decor_ChestVault ~0 ~2 ~-3:@

rule11=0,100,CommandBlock:RUINSTRIGGER /testruin TP_Decor_Fountain ~0 ~2 ~0:@,CommandBlock:RUINSTRIGGER /testruin TP_Decor_Garden ~0 ~2 ~0:@,CommandBlock:RUINSTRIGGER /testruin TP_Decor_LavaVault ~0 ~2 ~0:@,CommandBlock:RUINSTRIGGER /testruin TP_Decor_MonsterVault ~0 ~2 ~0:@,CommandBlock:RUINSTRIGGER /testruin TP_Decor_SkullStatue ~0 ~2 ~0:@,CommandBlock:RUINSTRIGGER /testruin TP_Decor_SkullVault ~0 ~2 ~0:@,CommandBlock:RUINSTRIGGER /testruin TP_Decor_WaterVault ~0 ~2 ~0:@,CommandBlock:RUINSTRIGGER /testruin TP_Decor_BookVault ~0 ~2 ~0:@

# South
rule12=0,100,preserveBlock

# East
rule13=0,100,CommandBlock:RUINSTRIGGER /testruin TP_SunkenDungeon_PassE ~7 ~-1 ~0:@,CommandBlock:RUINSTRIGGER /testruin TP_Decor_ChestVault ~3 ~2 ~0:@

rule14=1,100,minecraft:redstone_torch-5
rule15=0,100,minecraft:vine-1
rule16=0,100,minecraft:vine-8
rule17=0,100,minecraft:vine-2
rule18=0,100,minecraft:stone_brick_stairs-5
rule19=0,100,minecraft:vine-4
rule20=0,100,minecraft:stone_brick_stairs-7
rule21=0,100,minecraft:stone_brick_stairs-6
rule22=0,100,minecraft:stone_brick_stairs-4
rule23=0,100,minecraft:stained_glass-11
rule24=0,100,minecraft:stained_glass-9

layer
1,1,1,1,1,1,1,1,1,1,1,1,1
1,2,2,2,1,2,2,2,1,2,2,2,1
1,2,2,2,1,2,2,2,1,2,2,2,1
1,2,2,2,1,2,2,2,1,2,2,2,1
1,1,1,1,1,1,1,1,1,1,1,1,1
1,2,2,2,1,2,2,2,1,2,2,2,1
1,2,2,2,1,2,12,2,1,2,2,2,1
1,2,2,2,1,2,2,2,1,2,2,2,1
1,1,1,1,1,1,1,1,1,1,1,1,1
1,2,2,2,1,2,2,2,1,2,2,2,1
1,2,2,2,1,2,2,2,1,2,2,2,1
1,2,2,2,1,2,2,2,1,2,2,2,1
1,1,1,1,1,1,1,1,1,1,1,1,1
endlayer

layer
1,2,2,2,1,2,2,2,1,2,2,2,1
2,2,2,2,2,2,2,2,2,2,2,2,2
2,2,2,2,2,2,2,2,2,2,2,2,2
2,2,2,2,2,2,2,2,2,2,2,2,2
1,2,2,2,1,2,2,2,1,2,2,2,1
2,2,2,2,2,2,2,2,2,2,2,2,2
2,2,2,2,2,2,2,2,2,2,2,2,2
2,2,2,2,2,2,2,2,2,2,2,2,2
1,2,2,2,1,2,2,2,1,2,2,2,1
2,2,2,2,2,2,2,2,2,2,2,2,2
2,2,2,2,2,2,2,2,2,2,2,2,2
2,2,2,2,2,2,2,2,2,2,2,2,2
1,2,2,2,1,2,2,2,1,2,2,2,1
endlayer

layer
1,2,2,2,1,2,2,2,1,2,2,2,1
2,2,2,2,2,2,2,2,2,2,2,2,2
2,2,2,2,2,2,2,2,2,2,2,2,2
2,2,2,2,2,2,2,2,2,2,2,2,2
1,2,2,2,1,2,2,2,1,2,2,2,1
2,2,2,2,2,2,2,2,2,2,2,2,2
2,2,2,2,2,2,2,2,2,2,2,2,2
2,2,2,2,2,2,2,2,2,2,2,2,2
1,2,2,2,1,2,2,2,1,2,2,2,1
2,2,2,2,2,2,2,2,2,2,2,2,2
2,2,2,2,2,2,2,2,2,2,2,2,2
2,2,2,2,2,2,2,2,2,2,2,2,2
1,2,2,2,1,2,2,2,1,2,2,2,1
endlayer

layer
1,2,2,2,1,2,2,2,1,2,2,2,1
2,2,2,2,2,2,2,2,2,2,2,2,2
2,2,2,2,2,2,2,2,2,2,2,2,2
2,2,2,2,2,2,2,2,2,2,2,2,2
1,2,2,2,1,2,2,2,1,2,2,2,1
2,2,2,2,2,2,2,2,2,2,2,2,2
2,2,2,2,2,2,2,2,2,2,2,2,2
2,2,2,2,2,2,2,2,2,2,2,2,2
1,2,2,2,1,2,2,2,1,2,2,2,1
2,2,2,2,2,2,2,2,2,2,2,2,2
2,2,2,2,2,2,2,2,2,2,2,2,2
2,2,2,2,2,2,2,2,2,2,2,2,2
1,2,2,2,1,2,2,2,1,2,2,2,1
endlayer

layer
1,2,2,2,1,2,2,2,1,2,2,2,1
2,2,2,2,2,2,2,2,2,2,2,2,2
2,2,2,2,2,2,2,2,2,2,2,2,2
2,2,2,2,2,2,2,2,2,2,2,2,2
1,2,2,2,1,2,2,2,1,2,2,2,1
2,2,2,2,2,2,2,2,2,2,2,2,2
2,2,2,2,2,2,2,2,2,2,2,2,2
2,2,2,2,2,2,2,2,2,2,2,2,2
1,2,2,2,1,2,2,2,1,2,2,2,1
2,2,2,2,2,2,2,2,2,2,2,2,2
2,2,2,2,2,2,2,2,2,2,2,2,2
2,2,2,2,2,2,2,2,2,2,2,2,2
1,2,2,2,1,2,2,2,1,2,2,2,1
endlayer

layer
1,2,2,2,1,2,2,2,1,2,2,2,1
2,2,2,2,2,2,2,2,2,2,2,2,2
2,2,2,2,2,2,2,2,2,2,2,2,2
2,2,2,2,2,2,2,2,2,2,2,2,2
1,2,2,2,1,2,2,2,1,2,2,2,1
2,2,2,2,2,2,2,2,2,2,2,2,2
2,2,2,2,2,2,2,2,2,2,2,2,2
2,2,2,2,2,2,2,2,2,2,2,2,2
1,2,2,2,1,2,2,2,1,2,2,2,1
2,2,2,2,2,2,2,2,2,2,2,2,2
2,2,2,2,2,2,2,2,2,2,2,2,2
2,2,2,2,2,2,2,2,2,2,2,2,2
1,2,2,2,1,2,2,2,1,2,2,2,1
endlayer

layer
1,2,2,2,1,2,2,2,1,2,2,2,1
2,2,2,2,2,2,2,2,2,2,2,2,2
2,2,2,2,2,2,2,2,2,2,2,2,2
2,2,2,2,2,2,2,2,2,2,2,2,2
1,2,2,2,1,2,2,2,1,2,2,2,1
2,2,2,2,2,2,2,2,2,2,2,2,2
2,2,2,2,2,2,2,2,2,2,2,2,2
2,2,2,2,2,2,2,2,2,2,2,2,2
1,2,2,2,1,2,2,2,1,2,2,2,1
2,2,2,2,2,2,2,2,2,2,2,2,2
2,2,2,2,2,2,2,2,2,2,2,2,2
2,2,2,2,2,2,2,2,2,2,2,2,2
1,2,2,2,1,2,2,2,1,2,2,2,1
endlayer


layer
1,1,2,1,1,1,2,1,1,1,2,1,1
1,2,2,2,2,2,7,2,2,2,2,2,1
2,2,2,2,2,2,2,2,2,2,2,2,2
1,2,2,2,1,2,2,2,1,2,2,2,1
1,1,2,1,1,1,2,1,1,1,2,1,1
1,2,2,2,1,2,2,2,1,2,2,2,1
2,2,2,2,2,2,11,2,2,2,2,10,2
1,2,2,2,1,2,2,2,1,2,2,2,1
1,1,2,1,1,1,2,1,1,1,2,1,1
1,2,2,2,1,2,2,2,1,2,2,2,1
2,2,2,2,2,2,2,2,2,2,2,2,2
1,2,2,2,1,2,13,2,1,2,2,2,1
1,1,2,1,1,1,2,1,1,1,2,1,1
endlayer


layer
1,1,1,1,1,1,1,1,1,1,1,1,1
1,3,4,3,1,3,4,3,1,3,4,3,1
1,4,4,4,1,4,4,4,1,4,4,4,1
1,3,4,3,1,3,4,3,1,3,4,3,1
1,1,1,1,5,1,1,1,5,1,1,1,1
1,3,4,3,1,3,4,3,1,3,4,3,1
1,4,4,4,1,4,4,4,1,4,4,4,1
1,3,4,3,1,3,4,3,1,3,4,3,1
1,1,1,1,5,1,1,1,5,1,1,1,1
1,3,4,3,1,3,4,3,1,3,4,3,1
1,4,4,4,1,4,4,4,1,4,4,4,1
1,3,4,3,1,3,4,3,1,3,4,3,1
1,1,1,1,1,1,1,1,1,1,1,1,1
endlayer

layer
1,6,6,6,1,6,6,6,1,6,6,6,1
6,0,0,0,0,0,0,0,0,0,0,0,6
6,0,8,0,0,0,0,0,0,0,8,0,6
6,0,0,0,0,0,0,0,0,0,0,0,6
1,0,0,0,9,0,0,0,9,0,0,0,1
9,0,0,0,0,0,0,0,0,0,0,0,6
0,0,0,0,0,0,0,0,0,0,0,0,6
9,0,0,0,0,0,0,0,0,0,0,0,6
1,0,0,0,9,0,0,0,9,0,0,0,1
6,0,0,0,0,0,0,0,0,0,0,0,6
6,0,8,0,0,0,0,0,0,0,8,0,6
6,0,0,0,0,0,0,0,0,0,0,0,6
1,6,6,6,1,6,6,6,1,6,6,6,1
endlayer

layer
1,6,6,6,1,6,6,6,1,6,6,6,1
6,0,0,0,0,0,0,0,0,0,0,0,6
6,0,0,0,0,0,0,0,0,0,0,0,6
6,0,0,0,0,0,0,0,0,0,0,0,6
1,0,0,0,14,0,0,0,14,0,0,0,1
9,0,0,0,0,0,0,0,0,0,0,0,6
0,0,0,0,0,0,0,0,0,0,0,0,6
9,0,0,0,0,0,0,0,0,0,0,0,6
1,0,0,0,14,0,0,0,14,0,0,0,1
6,0,0,0,0,0,0,0,0,0,0,0,6
6,0,0,0,0,0,0,0,0,0,0,0,6
6,0,0,0,0,0,0,0,0,0,0,0,6
1,6,6,6,1,6,6,6,1,6,6,6,1
endlayer

layer
1,6,6,6,1,6,6,6,1,6,6,6,1
6,0,0,0,9,0,0,0,9,0,0,0,6
6,0,0,0,0,0,0,0,0,0,0,0,6
6,0,0,0,0,0,0,0,0,0,0,0,6
1,9,0,0,0,0,0,0,0,0,0,9,1
9,0,0,0,0,0,0,0,0,0,0,0,6
0,0,0,0,0,0,0,0,0,0,0,0,6
9,0,0,0,0,0,0,0,0,0,0,0,6
1,9,0,0,0,0,0,0,0,0,0,9,1
6,0,0,0,0,0,0,0,0,0,0,0,6
6,0,0,0,0,0,0,0,0,0,0,0,6
6,0,0,0,9,0,0,0,9,0,0,0,6
1,6,6,6,1,6,6,6,1,6,6,6,1
endlayer

layer
1,1,6,1,1,1,6,1,1,1,6,1,1
1,0,0,0,14,0,0,0,14,0,0,0,1
6,0,0,0,0,0,0,0,0,0,0,0,6
1,0,0,0,0,0,0,0,0,0,0,0,1
1,14,0,0,0,0,0,0,0,0,0,14,1
1,0,0,0,0,0,0,0,0,0,0,0,1
1,0,0,0,0,0,0,0,0,0,0,0,6
1,0,0,0,0,0,0,0,0,0,0,0,1
1,14,0,0,0,0,0,0,0,0,0,14,1
1,15,0,0,0,0,0,0,0,0,0,0,1
6,0,0,0,0,0,0,0,0,0,0,0,6
1,0,0,0,14,0,0,0,14,16,0,0,1
1,1,6,1,1,1,6,1,1,1,6,1,1
endlayer

layer
1,1,6,1,1,1,6,1,1,1,6,1,1
1,15,0,17,18,17,0,17,18,17,0,17,1
6,0,0,0,0,0,0,0,0,0,0,0,6
1,15,0,0,0,0,0,0,0,0,0,19,1
1,21,0,0,0,0,0,0,0,0,0,20,1
1,15,0,0,0,0,0,0,0,0,0,19,1
6,0,0,0,0,0,0,0,0,0,0,0,6
1,15,0,0,0,0,0,0,0,0,0,19,1
1,21,0,0,0,0,0,0,0,0,0,20,1
1,15,0,0,0,0,0,0,0,0,0,19,1
6,0,0,0,0,0,0,0,0,0,0,0,6
1,16,0,16,22,16,0,16,22,16,0,19,1
1,1,6,1,1,1,6,1,1,1,6,1,1
endlayer

layer
1,1,1,1,1,1,1,1,1,1,1,1,1
1,23,24,23,1,23,24,23,1,23,24,23,1
1,24,24,24,1,24,24,24,1,24,24,24,1
1,23,24,23,1,23,24,23,1,23,24,23,1
1,1,1,1,5,1,1,1,5,1,1,1,1
1,23,24,23,1,23,24,23,1,23,24,23,1
1,24,24,24,1,24,24,24,1,24,24,24,1
1,23,24,23,1,23,24,23,1,23,24,23,1
1,1,1,1,5,1,1,1,5,1,1,1,1
1,23,24,23,1,23,24,23,1,23,24,23,1
1,24,24,24,1,24,24,24,1,24,24,24,1
1,23,24,23,1,23,24,23,1,23,24,23,1
1,1,1,1,1,1,1,1,1,1,1,1,1
endlayer

