# Sandstone Dungeon Room - Chest
# Created by Ruins mod version 14.6 Ingame Parser
# authoring Player: Jordan_Greywolf
# MC 1.7.10; 3 Jan 2015
# Updated 27 Apr 2015
# Updated to MC 1.9: 24 Apr 2016
# Updated to MC 1.11: 12 Jan 2017 / Updated 11 May 2017
# Updated to MC 1.12: 22 Jun 2017

# Thanks to Syndaryl for bug reporting.

weight=1
embed_into_distance=0
acceptable_target_blocks=
unacceptable_target_blocks=flowing_water,water,flowing_lava,lava
dimensions=11,13,13
allowable_overhang=0
max_leveling=0
leveling_buffer=0
preserve_water=0
preserve_lava=0

rule1=0,100,minecraft:sandstone-2
rule2=0,100,minecraft:sandstone-0
rule3=0,100,minecraft:stained_hardened_clay-1
rule4=0,100,minecraft:stained_hardened_clay-0
rule5=0,100,minecraft:stained_hardened_clay-11
rule6=0,100,CommandBlock:/effect @p[r=3] 9 30:@,CommandBlock:/effect @p[r=3] 15 30:@,CommandBlock:/effect @p[r=3] 17 10:@,CommandBlock:/effect @p[r=3] 18 30:@
rule7=0,100,minecraft:skull,minecraft:skull-1,minecraft:skull-2,minecraft:skull-3,minecraft:skull-4,minecraft:skull-5,minecraft:web-0
rule8=0,100,minecraft:web-0
rule9=0,100,minecraft:sandstone_stairs-0
rule10=0,100,minecraft:sandstone_stairs-3
rule11=0,100,minecraft:sandstone_stairs-2
rule12=0,100,minecraft:sandstone_stairs-1
rule13=0,100,minecraft:sandstone-1

rule14=0,100,IInventory;minecraft:trapped_chest;minecraft:golden_hoe#1#0#0+minecraft:rotten_flesh#2#0#1+minecraft:arrow#4#0#2+minecraft:bone#4#0#3+minecraft:glass_bottle#1#0#4-3,IInventory;minecraft:trapped_chest;minecraft:golden_sword#1#0#0+minecraft:rotten_flesh#2#0#1+minecraft:splash_potion#{Potion:"minecraft:strong_regeneration"}#0#2+minecraft:bone#4#0#3+minecraft:splash_potion#{Potion:"minecraft:strong_healing"}#0#4-3,ChestGenHook:chests/desert_pyramid:3-3,IInventory;minecraft:trapped_chest;minecraft:gold_ingot#3#0#0-3,IInventory;minecraft:trapped_chest;minecraft:diamond#1#0#0-3,IInventory;minecraft:trapped_chest;minecraft:arrow#16#0#0-3

rule15=0,100,minecraft:sandstone_stairs-5
rule16=0,100,minecraft:sandstone_stairs-7
rule17=0,100,minecraft:sandstone_stairs-6
rule18=0,100,minecraft:sandstone_stairs-4
rule19=0,100,preserveBlock

rule20=0,100,CommandBlock:RUINSTRIGGER /setblock ~0 ~-1 ~0 mob_spawner 0 replace {SpawnData:{id:cave_spider,CustomName:"Tomb Scarab",ActiveEffects:[{Id:14,Amplifier:1,Duration:999999,Ambient:1}]}}:@,CommandBlock:RUINSTRIGGER /testruin TP_SandItem_Ankh ~0 ~-7 ~0:@,CommandBlock:RUINSTRIGGER /testruin TP_SandItem_Pool ~0 ~-7 ~0:@,CommandBlock:RUINSTRIGGER /testruin TP_SandItem_Sarcophagus ~0 ~-7 ~0:@,CommandBlock:RUINSTRIGGER /testruin TP_SandItem_Fountain ~0 ~-7 ~0:@
rule21=0,100,minecraft:wooden_pressure_plate

layer
1,1,1,1,1,1,1,1,1,1,1,1,1
1,2,2,2,2,2,2,2,2,2,2,2,1
1,2,2,2,2,3,4,3,2,2,2,2,1
1,2,2,2,2,2,2,2,2,2,2,2,1
1,2,2,2,2,5,4,5,2,2,2,2,1
1,2,3,2,5,2,2,2,5,2,3,2,1
1,2,4,2,4,2,6,2,4,2,4,2,1
1,2,3,2,5,2,2,2,5,2,3,2,1
2,2,2,2,2,5,4,5,2,2,2,2,1
2,2,2,2,2,2,2,2,2,2,2,2,1
2,2,2,2,2,3,4,3,2,2,2,2,1
2,2,2,2,2,2,2,2,2,2,2,2,1
1,2,2,2,2,1,1,1,2,2,2,2,1
endlayer

layer
1,2,2,2,2,1,0,1,2,2,2,2,1
2,7,0,0,0,8,0,8,0,0,0,0,2
2,0,10,9,9,0,0,0,10,9,9,0,2
2,0,10,2,11,0,0,0,10,2,11,0,2
2,0,12,12,11,0,0,0,12,12,11,0,2
1,7,0,0,0,7,9,8,0,0,0,8,1
0,0,0,0,0,10,13,11,0,0,0,0,0
1,8,0,0,0,8,12,7,0,0,0,7,1
2,0,10,9,9,0,0,0,10,9,9,0,2
2,8,10,2,11,0,0,0,10,2,11,0,2
2,0,12,12,11,0,0,0,12,12,11,0,2
2,0,0,0,0,0,0,0,0,0,0,7,2
1,2,2,2,2,1,0,1,2,2,2,2,1
endlayer

layer
1,2,13,12,13,1,8,1,13,12,13,2,1
2,0,0,8,0,0,0,0,0,0,0,0,2
13,8,0,0,0,0,0,0,0,0,0,0,13
11,0,0,13,0,0,0,0,0,13,0,0,10
13,0,0,0,0,0,0,0,0,0,0,0,13
1,0,0,0,0,0,8,0,0,0,0,0,1
8,0,0,0,0,0,14,0,0,0,0,0,8
1,0,0,0,0,0,0,0,0,0,0,0,1
13,0,0,0,0,0,0,0,0,0,0,0,13
11,0,8,13,0,0,0,0,0,13,0,0,10
13,0,0,0,0,0,0,0,0,0,0,0,13
2,0,0,0,0,0,0,0,0,0,0,0,2
1,2,13,9,13,1,8,1,13,9,13,2,1
endlayer

layer
1,2,13,15,13,1,0,1,13,15,13,2,1
2,0,0,0,0,0,0,0,0,0,0,8,2
13,0,0,8,0,0,0,0,0,0,0,0,13
17,0,8,2,0,0,0,0,0,2,0,0,16
13,0,0,0,0,0,0,0,0,0,0,0,13
1,0,0,0,0,0,0,0,0,0,0,0,1
0,0,0,0,0,0,0,0,0,0,0,0,0
1,0,0,0,0,0,0,0,0,0,0,0,1
13,0,0,0,0,0,0,0,0,0,0,0,13
17,0,0,2,0,0,0,0,0,2,0,0,16
13,0,0,0,0,0,0,0,0,0,0,0,13
2,0,0,0,0,0,0,0,0,0,0,0,2
1,2,13,18,13,1,0,1,13,18,13,2,1
endlayer

layer
1,2,2,2,2,1,1,1,2,2,2,2,1
2,0,0,0,0,8,0,0,0,0,0,8,2
2,0,0,0,0,0,0,0,0,0,0,0,2
2,0,8,13,0,0,0,0,0,13,8,8,2
2,8,0,0,0,0,0,0,0,0,0,0,2
1,0,0,0,0,0,0,0,0,0,0,0,1
1,0,0,0,0,0,0,0,0,0,0,8,1
1,0,0,0,0,0,0,0,0,0,0,0,1
2,8,0,0,0,0,0,0,0,0,0,0,2
2,0,0,13,0,0,0,0,0,13,8,8,2
2,0,0,0,0,0,0,0,0,0,0,0,2
2,0,0,8,8,0,0,8,0,0,0,0,2
1,2,2,2,2,1,1,1,2,2,2,2,1
endlayer

layer
1,1,1,1,1,1,1,1,1,1,1,1,1
1,17,15,15,15,15,15,15,15,15,15,15,1
1,17,16,18,18,8,0,8,16,18,18,16,1
1,17,16,1,17,0,0,0,16,1,17,16,1
1,17,15,15,17,0,0,0,15,15,17,16,1
1,17,8,0,0,0,0,0,0,0,0,16,1
1,17,0,0,0,0,0,0,0,0,8,16,1
1,17,0,0,0,0,0,0,0,0,0,16,1
1,17,16,18,18,8,0,0,16,18,18,16,1
1,17,16,1,17,0,0,0,16,1,17,16,1
1,17,15,15,17,0,0,0,15,15,17,16,1
1,17,18,18,18,18,18,18,18,18,18,16,1
1,1,1,1,1,1,1,1,1,1,1,1,1
endlayer

layer
19,19,19,19,19,1,1,1,19,19,19,19,19
19,1,1,1,1,1,1,1,1,1,1,1,19
19,1,1,1,1,15,15,15,1,1,1,1,19
19,1,1,1,1,8,0,0,1,1,1,1,19
19,1,1,1,1,0,0,0,1,1,1,1,19
1,1,17,0,8,0,0,0,0,0,16,1,1
1,1,17,0,0,0,0,0,0,0,16,1,1
1,1,17,8,0,0,0,0,0,0,16,1,1
19,1,1,1,1,0,0,0,1,1,1,1,19
19,1,1,1,1,8,0,0,1,1,1,1,19
19,1,1,1,1,18,18,18,1,1,1,1,19
19,1,1,1,1,1,1,1,1,1,1,1,19
19,19,19,19,19,1,1,1,19,19,19,19,19
endlayer

layer
19,19,19,19,19,1,1,1,19,19,19,19,19
19,19,19,19,19,1,1,1,19,19,19,19,19
19,19,1,1,1,1,1,1,1,1,1,19,19
19,19,1,1,1,15,15,15,1,1,1,19,19
19,19,1,1,1,8,0,0,1,1,1,19,19
1,1,1,17,0,0,0,0,0,16,1,1,1
1,1,1,17,0,0,0,0,8,16,1,1,1
1,1,1,17,8,0,0,0,0,16,1,1,1
19,19,1,1,1,0,8,8,1,1,1,19,19
19,19,1,1,1,18,18,18,1,1,1,19,19
19,19,1,1,1,1,1,1,1,1,1,19,19
19,19,19,19,19,1,1,1,19,19,19,19,19
19,19,19,19,19,1,1,1,19,19,19,19,19
endlayer

layer
19,19,19,19,19,19,1,19,19,19,19,19,19
19,19,19,19,19,19,1,19,19,19,19,19,19
19,19,19,19,19,19,1,19,19,19,19,19,19
19,19,19,1,1,1,1,1,1,1,19,19,19
19,19,19,1,1,15,15,15,1,1,19,19,19
19,19,19,1,17,8,0,0,16,1,19,19,19
1,1,1,1,17,0,20,0,16,1,1,1,1
19,19,19,1,17,8,0,8,16,1,19,19,19
19,19,19,1,1,18,18,18,1,1,19,19,19
19,19,19,1,1,1,1,1,1,1,19,19,19
19,19,19,19,19,19,1,19,19,19,19,19,19
19,19,19,19,19,19,1,19,19,19,19,19,19
19,19,19,19,19,19,1,19,19,19,19,19,19
endlayer

layer
19,19,19,19,19,19,19,19,19,19,19,19,19
19,19,19,19,19,19,19,19,19,19,19,19,19
19,19,19,19,19,19,19,19,19,19,19,19,19
19,19,19,19,19,19,19,19,19,19,19,19,19
19,19,19,19,1,1,1,1,1,19,19,19,19
19,19,19,19,1,17,15,16,1,19,19,19,19
19,19,19,19,1,17,2,16,1,19,19,19,19
19,19,19,19,1,18,18,16,1,19,19,19,19
19,19,19,19,1,1,1,1,1,19,19,19,19
19,19,19,19,19,19,19,19,19,19,19,19,19
19,19,19,19,19,19,19,19,19,19,19,19,19
19,19,19,19,19,19,19,19,19,19,19,19,19
19,19,19,19,19,19,19,19,19,19,19,19,19
endlayer

layer
19,19,19,19,19,19,19,19,19,19,19,19,19
19,19,19,19,19,19,19,19,19,19,19,19,19
19,19,19,19,19,19,19,19,19,19,19,19,19
19,19,19,19,19,19,19,19,19,19,19,19,19
19,19,19,19,19,19,19,19,19,19,19,19,19
19,19,19,19,19,1,1,1,19,19,19,19,19
19,19,19,19,19,1,1,1,19,19,19,19,19
19,19,19,19,19,1,1,1,19,19,19,19,19
19,19,19,19,19,19,19,19,19,19,19,19,19
19,19,19,19,19,19,19,19,19,19,19,19,19
19,19,19,19,19,19,19,19,19,19,19,19,19
19,19,19,19,19,19,19,19,19,19,19,19,19
19,19,19,19,19,19,19,19,19,19,19,19,19
endlayer


