# Sandstone Dungeon Room - Open Area
# Created by Ruins mod version 14.6 Ingame Parser
# authoring Player: Jordan_Greywolf
# MC 1.7.10; 3 Jan 2014
# Updated to MC 1.11: 12 Jan 2017


weight=1
embed_into_distance=0
acceptable_target_blocks=
unacceptable_target_blocks=flowing_water,water,flowing_lava,lava
dimensions=14,13,13
allowable_overhang=0
max_leveling=0
leveling_buffer=0
preserve_water=0
preserve_lava=0

rule1=0,100,minecraft:sandstone-2
rule2=0,100,minecraft:sandstone-0
rule3=0,100,minecraft:stained_hardened_clay-1
rule4=0,100,minecraft:stained_hardened_clay-0
rule5=0,100,minecraft:stained_hardened_clay-11
rule6=0,100,minecraft:sand-0
rule7=0,100,minecraft:web-0
rule8=2,100,minecraft:torch-1
rule9=2,100,minecraft:torch-3
rule10=2,100,minecraft:torch-4
rule11=2,100,minecraft:torch-2
rule12=0,100,minecraft:sandstone-1
rule13=0,100,minecraft:sandstone_stairs-1
rule14=0,100,minecraft:sandstone_stairs-3
rule15=0,100,minecraft:sandstone_stairs-2
rule16=0,100,minecraft:sandstone_stairs-0
rule17=0,100,minecraft:sandstone_stairs-5
rule18=0,100,minecraft:sandstone_stairs-7
rule19=0,100,minecraft:sandstone_stairs-6
rule20=0,100,minecraft:sandstone_stairs-4
rule21=0,100,preserveBlock
rule22=0,100,CommandBlock:RUINSTRIGGER /testruin TP_SandItem_Sarcophagus ~0 ~-10 ~0:@,CommandBlock:RUINSTRIGGER /testruin TP_SandItem_Ankh ~0 ~-10 ~0:@,CommandBlock:RUINSTRIGGER /testruin TP_SandItem_Lion ~0 ~-10 ~0:@,CommandBlock:RUINSTRIGGER /testruin TP_SandItem_Statue ~0 ~-10 ~0:@,CommandBlock:RUINSTRIGGER /testruin TP_SandItem_LevelDown ~0 ~-10 ~0:@

layer
1,1,1,1,1,1,1,1,1,1,1,1,1
1,2,2,2,2,2,2,2,2,2,2,2,1
1,2,3,3,4,3,4,3,4,3,3,2,1
1,2,3,5,2,2,2,2,2,5,3,2,1
1,2,4,2,4,5,4,5,4,2,4,2,1
1,2,3,2,5,2,2,2,5,2,3,2,1
1,2,4,2,4,2,5,2,4,2,4,2,1
1,2,3,2,5,2,2,2,5,2,3,2,1
2,2,4,2,4,5,4,5,4,2,4,2,1
2,2,3,5,2,2,2,2,2,5,3,2,1
2,2,3,3,4,3,4,3,4,3,3,2,1
2,2,2,2,2,2,2,2,2,2,2,2,1
1,2,2,2,2,1,1,1,2,2,2,2,1
endlayer

layer
1,2,2,2,2,1,6,1,2,2,2,2,1
2,7,7,8,0,6,6,6,0,8,7,7,2
2,7,0,0,0,0,6,0,0,0,0,7,2
2,10,0,0,0,0,0,0,0,0,0,9,2
2,0,0,0,0,0,0,0,0,0,0,0,2
1,6,0,0,0,0,0,0,0,0,0,6,1
6,6,6,0,0,0,0,0,0,0,6,6,6
1,6,0,0,0,0,0,0,0,0,0,6,1
2,0,0,0,0,0,0,0,0,0,0,0,2
2,10,0,0,0,0,0,0,0,0,0,9,2
2,7,0,0,0,0,6,0,0,0,0,7,2
2,7,7,11,0,6,6,6,0,11,7,7,2
1,2,2,2,2,1,6,1,2,2,2,2,1
endlayer

layer
1,2,12,13,12,1,6,1,12,13,12,2,1
2,7,0,7,0,0,6,0,0,0,0,7,2
12,0,0,0,0,0,0,0,0,0,0,0,12
15,0,0,0,0,0,0,0,0,0,0,0,14
12,0,0,0,0,0,0,0,0,0,0,0,12
1,0,0,0,0,0,0,0,0,0,0,0,1
6,6,0,0,0,0,0,0,0,0,0,6,6
1,0,0,0,0,0,0,0,0,0,0,0,1
12,0,0,0,0,0,0,0,0,0,0,0,12
15,0,0,0,0,0,0,0,0,0,0,0,14
12,0,0,0,0,0,0,0,0,0,0,0,12
2,7,0,0,0,0,6,0,0,0,0,7,2
1,2,12,16,12,1,6,1,12,16,12,2,1
endlayer

layer
1,2,12,17,12,1,6,1,12,17,12,2,1
2,0,0,0,0,0,0,0,0,0,0,7,2
12,0,0,0,0,0,0,0,0,0,0,0,12
19,0,0,0,0,0,0,0,0,0,0,0,18
12,0,0,0,0,0,0,0,0,0,0,0,12
1,0,0,0,0,0,0,0,0,0,0,0,1
6,0,0,0,0,0,0,0,0,0,0,0,6
1,0,0,0,0,0,0,0,0,0,0,0,1
12,0,0,0,0,0,0,0,0,0,0,0,12
19,0,0,0,0,0,0,0,0,0,0,0,18
12,0,0,0,0,0,0,0,0,0,0,0,12
2,0,0,0,0,0,0,0,0,0,0,0,2
1,2,12,20,12,1,6,1,12,20,12,2,1
endlayer

layer
1,2,2,2,2,2,2,2,2,2,2,2,1
2,0,0,0,0,0,0,0,0,0,0,0,2
2,0,0,0,0,0,0,0,0,0,0,0,2
2,0,0,0,0,0,0,0,0,0,0,0,2
2,0,0,0,0,0,0,0,0,0,0,0,2
2,0,0,0,0,0,0,0,0,0,0,0,2
2,0,0,0,0,0,0,0,0,0,0,0,2
2,0,0,0,0,0,0,0,0,0,0,0,2
2,0,0,0,0,0,0,0,0,0,0,0,2
2,0,0,0,0,0,0,0,0,0,0,0,2
2,0,0,0,0,0,0,0,0,0,0,0,2
2,0,0,0,0,0,0,0,0,0,0,0,2
1,2,2,2,2,2,2,2,2,2,2,2,1
endlayer

layer
1,2,2,2,2,2,2,2,2,2,2,2,1
2,0,0,0,0,0,0,0,0,0,0,0,2
2,0,0,0,0,0,0,0,0,0,0,0,2
2,0,0,0,0,0,0,0,0,0,0,0,2
2,0,0,0,0,0,0,0,0,0,0,0,2
2,0,0,0,0,0,0,0,0,0,0,0,2
2,0,0,0,0,0,0,0,0,0,0,0,2
2,0,0,0,0,0,0,0,0,0,0,0,2
2,0,0,0,0,0,0,0,0,0,0,0,2
2,0,0,0,0,0,0,0,0,0,0,0,2
2,0,0,0,0,0,0,0,0,0,0,0,2
2,0,0,0,0,0,0,0,0,0,0,0,2
1,2,2,2,2,2,2,2,2,2,2,2,1
endlayer


layer
1,2,2,2,2,2,2,2,2,2,2,2,1
2,0,0,0,0,0,0,0,0,0,0,0,2
2,0,0,0,0,0,0,0,0,0,0,0,2
2,0,0,0,0,0,0,0,0,0,0,0,2
2,0,0,0,0,0,0,0,0,0,0,0,2
2,0,0,0,0,0,0,0,0,0,0,0,2
2,0,0,0,0,0,0,0,0,0,0,0,2
2,0,0,0,0,0,0,0,0,0,0,0,2
2,0,0,0,0,0,0,0,0,0,0,0,2
2,0,0,0,0,0,0,0,0,0,0,0,2
2,0,0,0,0,0,0,0,0,0,0,0,2
2,0,0,0,0,0,0,0,0,0,0,0,2
1,2,2,2,2,2,2,2,2,2,2,2,1
endlayer

layer
1,2,2,2,2,1,1,1,2,2,2,2,1
2,7,0,0,0,7,0,0,0,0,0,7,2
2,0,0,0,0,0,0,0,0,0,0,0,2
2,0,0,0,0,0,0,0,0,0,0,0,2
2,7,0,0,0,0,0,0,0,0,0,0,2
1,0,0,0,0,0,0,0,0,0,0,0,1
1,0,0,0,0,0,0,0,0,0,0,7,1
1,0,0,0,0,0,0,0,0,0,0,0,1
2,0,0,0,0,0,0,0,0,0,0,0,2
2,0,0,0,0,0,0,0,0,0,0,7,2
2,0,0,0,0,0,0,0,0,0,0,0,2
2,7,0,7,7,0,0,7,0,0,0,7,2
1,2,2,2,2,1,1,1,2,2,2,2,1
endlayer

layer
1,1,1,1,1,1,1,1,1,1,1,1,1
1,19,17,17,17,17,17,17,17,17,17,17,1
1,19,0,0,0,0,0,0,0,0,0,18,1
1,19,0,0,0,0,0,0,0,0,0,18,1
1,19,0,0,0,0,0,0,0,0,0,18,1
1,19,0,0,0,0,0,0,0,0,0,18,1
1,19,0,0,0,0,0,0,0,0,7,18,1
1,19,0,0,0,0,0,0,0,0,0,18,1
1,19,0,0,0,0,0,0,0,0,0,18,1
1,19,0,0,0,0,0,0,0,0,0,18,1
1,19,0,0,0,0,0,0,0,0,0,18,1
1,19,20,20,20,20,20,20,20,20,20,18,1
1,1,1,1,1,1,1,1,1,1,1,1,1
endlayer

layer
21,21,21,21,21,1,1,1,21,21,21,21,21
21,1,1,1,1,1,1,1,1,1,1,1,21
21,1,17,17,17,17,17,17,17,17,18,1,21
21,1,19,0,0,0,0,0,0,7,18,1,21
21,1,19,0,0,0,0,0,0,0,18,1,21
1,1,19,0,0,0,0,0,0,0,18,1,1
1,1,19,0,0,0,0,0,0,0,18,1,1
1,1,19,0,0,0,0,0,0,0,18,1,1
21,1,19,0,0,0,0,0,0,0,18,1,21
21,1,19,0,0,0,0,0,0,0,18,1,21
21,1,19,20,20,20,20,20,16,16,20,1,21
21,1,1,1,1,1,1,1,1,1,1,1,21
21,21,21,21,21,1,1,1,21,21,21,21,21
endlayer

layer
21,21,21,21,21,1,1,1,21,21,21,21,21
21,21,21,21,21,1,1,1,21,21,21,21,21
21,21,1,1,1,1,1,1,1,1,1,21,21
21,21,1,17,17,17,17,17,17,18,1,21,21
21,21,1,19,0,0,0,0,7,18,1,21,21
1,1,1,19,0,0,0,0,0,18,1,1,1
1,1,1,19,0,0,0,0,0,18,1,1,1
1,1,1,19,7,0,0,0,0,18,1,1,1
21,21,1,19,0,0,7,0,0,18,1,21,21
21,21,1,19,20,20,20,20,20,20,1,21,21
21,21,1,1,1,1,1,1,1,1,1,21,21
21,21,21,21,21,1,1,1,21,21,21,21,21
21,21,21,21,21,1,1,1,21,21,21,21,21
endlayer

layer
21,21,21,21,21,21,1,21,21,21,21,21,21
21,21,21,21,21,21,1,21,21,21,21,21,21
21,21,21,21,21,21,1,21,21,21,21,21,21
21,21,21,1,1,1,1,1,1,1,21,21,21
21,21,21,1,19,17,17,17,18,1,21,21,21
21,21,21,1,19,7,0,0,18,1,21,21,21
1,1,1,1,19,0,22,0,18,1,1,1,1
21,21,21,1,19,7,0,7,18,1,21,21,21
21,21,21,1,19,20,20,20,20,1,21,21,21
21,21,21,1,1,1,1,1,1,1,21,21,21
21,21,21,21,21,21,1,21,21,21,21,21,21
21,21,21,21,21,21,1,21,21,21,21,21,21
21,21,21,21,21,21,1,21,21,21,21,21,21
endlayer

layer
21,21,21,21,21,21,21,21,21,21,21,21,21
21,21,21,21,21,21,21,21,21,21,21,21,21
21,21,21,21,21,21,21,21,21,21,21,21,21
21,21,21,21,21,21,21,21,21,21,21,21,21
21,21,21,21,1,1,1,1,1,21,21,21,21
21,21,21,21,1,19,17,18,1,21,21,21,21
21,21,21,21,1,19,2,18,1,21,21,21,21
21,21,21,21,1,20,20,18,1,21,21,21,21
21,21,21,21,1,1,1,1,1,21,21,21,21
21,21,21,21,21,21,21,21,21,21,21,21,21
21,21,21,21,21,21,21,21,21,21,21,21,21
21,21,21,21,21,21,21,21,21,21,21,21,21
21,21,21,21,21,21,21,21,21,21,21,21,21
endlayer

layer
21,21,21,21,21,21,21,21,21,21,21,21,21
21,21,21,21,21,21,21,21,21,21,21,21,21
21,21,21,21,21,21,21,21,21,21,21,21,21
21,21,21,21,21,21,21,21,21,21,21,21,21
21,21,21,21,21,21,21,21,21,21,21,21,21
21,21,21,21,21,1,1,1,21,21,21,21,21
21,21,21,21,21,1,1,1,21,21,21,21,21
21,21,21,21,21,1,1,1,21,21,21,21,21
21,21,21,21,21,21,21,21,21,21,21,21,21
21,21,21,21,21,21,21,21,21,21,21,21,21
21,21,21,21,21,21,21,21,21,21,21,21,21
21,21,21,21,21,21,21,21,21,21,21,21,21
21,21,21,21,21,21,21,21,21,21,21,21,21
endlayer

