
# Tree of Chandeliers
# 9 Mar 2014; updated to MC 1.7.10, 10 Oct 2014
# Created by Ruins mod version 12.3 Ingame Parser
# authoring Player: Jordan_Greywolf
# Last Updated: 27 Apr 2015
# \templateparser version

biomesToSpawnIn=boreal forest,enchanted forest,extreme hills,extreme hills edge,flower field,flower forest,forest,foresthills,fungi forest,garden,lighted forest,magical forest,mystic grove,oak savanna,ominous woods,orchard,plains,roofed forest,roofed forest m,sacred springs,sunflower plains,taiga,taigahills,taiga m,thinned mystic grove,twilight clearing,wonderous woods

weight=1
embed_into_distance=4

unacceptable_target_blocks=lava,flowing_lava,cloud,Natura:Cloud,slime_dirt,slime_grass,slime_congealed,command_block

dimensions=22,14,23
allowable_overhang=300
max_cut_in=0
cut_in_buffer=0
max_leveling=0
leveling_buffer=0
preserve_water=0
preserve_lava=0
preserve_plants=1

rule1=0,100,preserveBlock
rule2=0,100,minecraft:log-0
rule3=0,100,minecraft:flowing_water
rule4=0,100,minecraft:flowing_water
rule5=0,100,minecraft:flowing_water
rule6=0,100,minecraft:dirt-0
rule7=0,100,minecraft:log-12
rule8=0,100,minecraft:flowing_water
rule9=0,100,minecraft:grass-0
rule10=0,100,minecraft:tallgrass-1,minecraft:tallgrass-2,minecraft:red_flower,minecraft:yellow_flower,minecraft:red_flower-1,minecraft:red_flower-2
rule11=0,100,minecraft:fence-0
rule12=1,100,minecraft:torch-5
rule13=0,100,minecraft:leaves-4

layer
1,1,1,1,1,1,1,1,1,1,1,1,1,1,1,1,1,1,1,1,1,1,1
1,1,1,1,1,1,1,1,1,1,1,1,1,1,1,1,1,1,1,1,1,1,1
1,1,1,1,1,1,1,1,1,1,1,1,1,1,1,1,1,1,1,1,1,1,1
1,1,1,1,1,1,1,1,1,1,1,1,1,2,1,1,1,1,1,1,1,1,1
1,1,1,1,1,1,1,1,1,1,1,1,1,1,3,4,3,1,1,1,1,1,1
1,1,1,1,1,1,1,1,1,1,1,1,1,1,4,5,4,1,1,1,1,1,1
1,1,1,1,1,1,1,1,1,1,2,1,1,1,3,3,3,1,1,1,1,1,1
1,1,1,1,1,1,1,1,1,1,1,1,1,2,6,1,1,1,1,1,1,1,1
1,1,1,1,1,1,1,1,1,1,1,1,6,6,6,1,1,1,1,1,1,1,1
1,1,1,1,1,1,1,1,1,1,1,1,1,1,1,1,1,1,1,1,1,1,1
1,1,1,1,1,1,1,1,1,1,1,1,1,1,1,2,1,1,1,1,1,1,1
1,1,1,1,1,1,1,1,1,1,1,1,1,1,1,1,1,1,1,1,1,1,1
1,1,1,1,1,1,1,1,1,1,1,1,1,1,1,1,1,1,1,1,1,1,1
1,1,1,1,1,1,1,1,1,1,1,1,1,1,1,1,1,1,1,1,1,1,1
endlayer

layer
1,1,1,1,1,1,1,1,1,1,1,1,1,1,1,1,1,1,1,1,1,1,1
1,1,1,1,1,1,1,1,1,1,1,1,1,1,1,1,1,1,1,1,1,1,1
1,1,1,1,1,1,1,1,1,1,1,1,1,1,1,1,1,1,1,1,1,1,1
1,1,1,1,1,1,1,1,1,1,1,1,1,2,1,1,1,1,1,1,1,1,1
1,1,1,1,1,1,1,1,1,1,1,1,1,1,0,4,0,1,1,1,1,1,1
1,1,1,1,1,1,1,1,1,1,1,1,1,1,3,5,4,1,1,1,1,1,1
1,1,1,1,1,1,1,1,1,1,2,1,6,6,6,1,0,1,1,1,1,1,1
1,1,1,1,1,1,1,1,1,1,1,6,6,2,6,6,1,2,1,1,1,1,1
1,1,1,1,1,1,1,1,2,1,6,6,6,6,6,6,1,1,1,1,1,1,1
1,1,1,1,1,1,1,1,1,1,1,1,6,6,6,1,1,1,1,1,1,1,1
1,1,1,1,1,1,1,1,1,1,1,1,1,1,1,2,1,1,1,1,1,1,1
1,1,1,1,1,1,1,1,1,1,2,1,1,1,1,1,1,1,1,1,1,1,1
1,1,1,1,1,1,1,1,1,1,1,1,1,1,1,1,1,1,1,1,1,1,1
1,1,1,1,1,1,1,1,1,1,1,1,1,1,1,1,1,1,1,1,1,1,1
endlayer

layer
1,1,1,1,1,1,1,1,1,1,1,1,1,1,1,1,1,1,1,1,1,1,1
1,1,1,1,1,1,1,1,1,1,1,1,1,1,1,1,1,1,1,1,1,1,1
1,1,1,1,1,1,1,1,1,1,1,1,1,1,1,1,1,1,1,1,1,1,1
1,1,1,1,1,1,1,1,1,1,1,1,1,2,1,1,1,1,1,1,1,1,1
1,1,1,1,1,1,1,1,1,1,1,1,1,1,1,3,0,1,1,1,1,1,1
1,1,1,1,1,1,1,1,1,1,1,1,1,6,1,5,3,1,1,1,1,1,1
1,1,1,1,1,1,1,1,1,1,2,6,6,6,6,6,1,1,1,1,1,1,1
1,1,1,1,1,1,1,1,1,1,6,6,6,2,6,6,6,2,1,1,1,1,1
1,1,1,1,1,1,1,1,2,6,6,6,6,6,6,6,1,1,1,1,1,1,1
1,1,1,1,1,1,1,1,1,1,2,6,6,6,6,1,1,1,1,1,1,1,1
1,1,1,1,1,1,1,1,1,1,1,1,1,1,1,2,1,1,1,1,1,1,1
1,1,1,1,1,1,1,1,1,1,2,1,1,1,1,1,1,1,1,1,1,1,1
1,1,1,1,1,1,1,1,1,1,1,1,1,1,1,1,1,1,1,1,1,1,1
1,1,1,1,1,1,1,1,1,1,1,1,1,1,1,1,1,1,1,1,1,1,1
endlayer

layer
1,1,1,1,1,1,1,1,1,1,1,1,1,1,1,1,1,1,1,1,1,1,1
1,1,1,1,1,1,1,1,1,1,1,1,1,1,1,1,1,1,1,1,1,1,1
1,1,1,1,1,1,1,1,1,1,1,1,1,1,1,1,1,1,1,1,1,1,1
1,1,1,1,1,1,1,1,1,1,1,1,1,7,1,1,1,1,1,1,1,1,1
1,1,1,1,1,1,1,1,1,1,1,1,1,1,1,1,1,1,1,1,1,1,1
1,1,1,1,1,1,1,1,1,1,1,1,9,6,9,8,1,1,1,1,1,1,1
1,1,1,1,1,1,1,1,1,9,2,6,6,6,6,9,1,1,1,1,1,1,1
1,1,1,1,1,1,1,1,1,6,6,6,6,2,6,6,6,7,1,1,1,1,1
1,1,1,1,1,1,1,1,7,6,7,7,6,6,6,6,9,1,1,1,1,1,1
1,1,1,1,1,1,1,1,1,1,2,7,6,6,6,6,1,1,1,1,1,1,1
1,1,1,1,1,1,1,1,1,1,1,6,9,6,9,7,1,1,1,1,1,1,1
1,1,1,1,1,1,1,1,1,1,7,1,1,1,1,1,1,1,1,1,1,1,1
1,1,1,1,1,1,1,1,1,1,1,1,1,1,1,1,1,1,1,1,1,1,1
1,1,1,1,1,1,1,1,1,1,1,1,1,1,1,1,1,1,1,1,1,1,1
endlayer

layer
1,1,1,1,1,1,1,1,1,0,0,0,1,1,1,1,1,1,1,1,1,1,1
1,1,1,1,1,1,1,1,0,0,0,0,0,0,0,1,1,1,1,1,1,1,1
1,1,1,1,1,1,1,0,0,0,0,0,0,0,0,0,1,1,1,1,1,1,1
1,1,1,1,1,0,0,0,0,0,0,0,0,0,0,0,0,1,1,1,1,1,1
1,1,1,0,0,0,0,0,0,0,0,0,0,7,0,0,0,0,0,0,1,1,1
1,0,0,0,0,0,0,0,0,0,0,0,10,6,10,0,0,0,0,0,0,1,1
0,0,0,0,0,0,0,0,0,10,7,7,6,6,2,10,0,0,0,0,0,0,1
1,0,0,0,0,0,0,0,0,9,7,7,5,2,6,6,7,0,0,0,0,0,0
1,0,0,0,0,0,0,0,0,7,8,8,8,6,6,9,10,0,0,0,0,0,1
1,1,0,0,0,0,0,0,0,0,7,8,7,9,9,7,0,0,0,0,0,1,1
1,1,0,0,0,0,0,0,0,0,0,7,10,9,10,0,0,0,0,1,1,1,1
1,1,1,0,0,0,0,0,0,0,0,0,0,0,0,0,0,1,1,1,1,1,1
1,1,1,1,0,0,0,0,1,1,0,0,0,0,0,1,1,1,1,1,1,1,1
1,1,1,1,1,0,0,1,1,1,1,1,0,1,1,1,1,1,1,1,1,1,1
endlayer

layer
1,1,1,1,1,1,1,1,0,0,0,0,0,0,0,1,1,1,1,1,1,1,1
1,1,1,1,1,0,0,0,0,0,0,0,0,0,0,0,0,1,1,1,1,1,1
1,1,1,1,0,0,0,0,0,0,0,0,0,0,0,0,0,0,1,1,1,1,1
1,0,0,0,0,0,0,0,0,0,0,0,0,0,0,0,0,0,0,1,1,1,1
1,0,0,0,0,0,0,0,0,0,0,0,0,0,0,0,0,0,0,0,0,1,1
0,0,0,0,0,0,0,0,0,0,0,0,0,7,0,0,0,0,0,0,0,0,0
0,0,0,0,0,0,0,0,0,0,0,7,2,2,2,0,0,0,0,0,0,0,0
0,0,0,0,0,0,0,0,0,10,0,7,8,2,2,7,0,0,0,0,0,0,0
0,0,0,0,0,0,0,0,0,0,0,0,3,2,2,10,0,0,0,0,0,0,0
0,0,0,0,0,0,0,0,0,0,0,0,7,10,10,0,0,0,0,0,0,0,1
1,0,0,0,0,11,0,0,0,0,0,0,0,10,0,0,0,0,0,0,0,0,1
1,1,0,0,11,11,11,0,0,0,0,0,0,0,0,0,0,0,0,0,1,1,1
1,1,0,0,0,11,0,0,0,0,0,0,0,0,0,0,0,0,1,1,1,1,1
1,1,1,1,0,0,0,0,1,1,0,0,0,0,0,0,1,1,1,1,1,1,1
endlayer

layer
1,1,1,1,0,0,0,0,0,0,0,0,0,0,0,0,0,0,0,1,1,1,1
1,1,1,0,0,0,0,0,0,0,0,0,0,0,0,0,0,0,0,0,1,1,1
0,0,0,0,0,0,0,0,0,0,0,0,0,0,0,0,0,0,0,0,0,1,1
0,0,0,0,0,0,0,0,0,0,0,0,0,0,0,0,0,0,0,0,0,0,1
0,0,0,0,0,0,0,0,0,0,0,0,0,0,0,0,0,0,0,0,0,0,0
0,0,0,0,0,0,0,0,0,0,0,0,0,7,0,0,0,0,0,0,0,0,0
0,0,0,0,0,0,0,0,0,0,0,0,2,2,2,0,0,0,0,0,0,0,0
0,0,0,0,0,0,0,0,0,0,0,7,2,2,2,7,0,0,0,0,0,0,0
0,0,0,0,0,0,0,0,0,0,0,0,2,2,2,0,0,0,0,0,0,0,0
0,0,0,0,0,0,0,0,0,0,0,0,0,0,0,0,0,0,0,0,0,0,0
0,0,0,0,0,12,0,0,0,0,0,0,0,0,0,0,0,0,0,0,0,0,0
1,0,0,0,12,11,12,0,0,0,0,0,0,0,0,0,0,0,0,0,0,0,1
1,0,0,0,0,12,0,0,0,0,0,0,0,0,0,0,0,0,0,0,0,1,1
1,1,1,0,0,0,0,0,0,0,0,0,0,0,0,0,0,0,1,1,1,1,1
endlayer

layer
1,1,0,0,0,0,0,0,0,0,0,0,0,0,0,0,0,0,0,0,1,1,1
0,0,0,0,0,0,0,0,0,0,0,0,0,0,0,0,0,0,0,0,0,1,1
0,0,0,0,0,0,0,0,0,0,0,0,0,0,0,0,0,0,0,0,0,0,0
0,0,0,0,0,0,0,0,0,0,0,0,0,0,0,0,0,0,0,0,0,0,0
0,0,0,0,0,0,0,0,0,0,0,0,0,0,0,0,0,0,0,0,0,0,0
0,0,0,0,0,0,0,0,0,0,0,0,0,0,0,0,0,0,0,0,0,0,0
0,0,0,0,0,0,0,0,0,0,0,0,2,2,2,0,0,0,0,0,0,0,0
0,0,0,0,0,0,0,0,0,0,0,0,2,2,2,0,0,0,0,0,0,0,0
0,0,0,0,0,0,0,0,0,0,0,0,2,2,2,0,0,0,0,0,0,0,0
0,0,0,0,0,0,0,0,0,0,0,0,0,0,0,0,0,0,0,0,0,0,0
0,0,0,0,0,0,0,0,0,0,0,0,0,0,0,0,0,0,0,0,0,0,0
0,0,0,0,0,11,0,0,0,0,0,0,0,0,0,0,0,0,0,0,0,0,0
1,0,0,0,0,0,0,0,0,0,0,0,0,0,0,0,0,0,0,0,0,0,1
1,1,0,0,0,0,0,0,0,0,0,0,0,0,0,0,0,0,0,1,1,1,1
endlayer

layer
1,0,0,0,0,0,0,0,0,0,0,0,0,0,0,0,0,0,0,0,0,1,1
0,0,0,0,0,0,0,0,0,0,0,0,0,0,0,0,0,0,0,0,0,0,0
0,0,0,0,0,0,0,0,0,0,0,0,0,0,0,0,0,0,11,0,0,0,0
0,0,0,0,0,0,0,0,0,0,0,0,0,0,0,0,0,11,11,11,0,0,0
0,0,0,0,0,0,0,0,0,0,0,0,0,0,0,0,0,0,11,0,0,0,0
0,0,0,0,0,0,0,0,0,0,0,0,0,0,0,0,0,0,0,0,0,0,0
0,0,0,0,0,0,0,0,0,0,0,0,2,2,2,0,0,0,0,0,0,0,0
0,0,0,0,0,0,0,0,0,0,0,0,2,2,2,0,0,0,0,0,0,0,0
0,0,0,0,0,0,0,0,0,0,0,0,2,2,2,0,0,0,0,0,0,0,0
0,0,0,0,0,0,0,0,0,0,0,0,0,0,0,0,0,0,0,0,0,0,0
0,0,0,0,0,0,0,0,0,0,0,0,0,0,0,0,0,0,0,0,0,0,0
0,0,0,0,0,11,0,0,0,0,0,0,0,0,0,0,0,0,0,0,0,0,0
0,0,0,0,0,0,0,0,0,0,0,0,0,0,0,0,0,0,0,0,0,0,0
1,0,0,0,0,0,0,0,0,0,0,0,0,0,0,0,0,0,0,0,0,1,1
endlayer

layer
0,0,0,0,0,0,0,0,0,0,0,0,0,0,0,0,0,0,0,0,0,0,0
0,0,0,0,0,0,0,0,0,0,0,0,0,0,0,0,0,0,0,0,0,0,0
0,0,0,0,0,0,0,0,0,0,0,0,0,0,0,0,0,0,12,0,0,0,0
0,0,0,0,0,0,0,0,0,0,0,0,0,0,0,0,0,12,11,12,0,0,0
0,0,11,0,0,0,0,0,0,0,0,0,0,0,0,0,0,0,12,0,0,0,0
0,11,11,11,0,0,0,0,0,0,0,0,0,0,0,0,0,0,0,0,0,0,0
0,0,11,0,0,0,0,0,0,0,0,0,2,2,2,0,0,0,0,0,0,0,0
0,0,0,0,0,0,0,0,0,0,0,0,2,2,2,0,0,0,0,0,0,0,0
0,0,0,0,0,0,0,0,0,0,0,7,2,2,2,0,0,0,0,0,0,0,0
0,0,0,0,0,0,0,0,0,0,0,0,0,0,0,0,0,0,0,0,0,0,0
0,0,0,0,0,0,0,0,0,0,11,0,0,0,0,0,0,0,0,0,0,0,0
0,0,0,0,0,11,0,0,0,11,11,11,0,0,0,0,0,0,0,0,0,0,0
0,0,0,0,0,0,0,0,0,0,11,0,0,0,0,0,0,0,0,0,0,0,0
0,0,0,0,0,0,0,0,0,0,0,0,0,0,0,0,0,0,0,0,0,0,0
endlayer

layer
0,0,0,0,0,0,0,0,0,0,0,0,0,0,0,0,0,0,0,0,0,0,0
0,0,0,0,0,0,0,0,0,0,0,0,0,0,0,0,0,0,0,0,0,0,0
0,0,0,0,0,0,0,0,0,0,0,0,0,0,0,0,0,0,0,0,0,0,0
0,0,0,0,0,0,0,0,0,0,0,0,0,0,0,0,0,0,11,0,0,0,0
0,0,12,0,0,0,0,0,0,0,0,0,0,0,0,0,0,0,0,0,0,0,0
0,12,11,12,0,0,0,0,0,0,0,0,7,0,0,0,0,0,0,0,0,0,0
0,0,12,0,0,0,0,0,0,0,0,0,2,2,2,7,0,0,0,0,0,0,0
0,0,0,0,0,0,0,0,0,0,0,0,2,2,2,0,0,0,0,0,0,0,0
0,0,0,0,0,0,0,0,0,0,7,7,2,2,2,0,0,0,0,0,0,0,0
0,0,0,0,0,0,0,0,0,0,0,7,7,0,7,13,13,0,0,0,0,0,0
0,0,0,0,0,0,0,13,13,0,12,0,0,0,13,13,13,13,0,0,0,0,0
0,0,0,0,0,11,0,0,0,12,11,12,0,0,0,13,13,0,0,0,0,0,0
0,0,0,0,0,0,0,0,0,0,12,0,0,0,0,0,0,0,0,0,0,0,0
0,0,0,0,0,0,0,0,0,0,0,0,0,0,0,0,0,0,0,0,0,0,0
endlayer

layer
0,0,0,0,0,0,0,0,0,0,0,0,0,0,0,0,0,0,0,0,0,0,0
0,0,0,0,0,0,0,0,0,0,0,0,0,0,0,0,0,0,0,0,0,0,0
0,0,0,0,0,0,0,0,0,0,0,0,0,0,0,0,0,0,0,0,0,0,0
0,0,0,0,0,0,13,0,0,0,0,0,0,0,0,13,0,0,11,0,0,0,0
0,0,0,0,0,13,13,13,0,0,0,0,7,0,13,13,13,0,0,0,0,0,0
0,0,11,0,0,13,13,13,0,0,0,0,7,13,13,7,13,0,0,0,0,0,0
0,0,0,0,0,0,13,0,7,0,0,13,7,7,7,7,0,0,0,0,0,0,0
0,0,0,0,0,0,0,0,0,7,13,13,7,7,7,13,13,0,0,0,0,0,0
0,0,0,0,0,0,0,0,0,13,7,7,7,7,7,13,13,0,0,0,0,0,0
0,0,0,0,0,0,0,13,13,7,7,7,13,13,7,13,13,13,0,0,0,0,0
0,0,0,0,0,0,13,13,13,0,0,7,13,13,13,7,7,13,13,0,0,0,0
0,0,0,0,0,11,0,13,13,0,11,0,0,0,13,13,13,13,0,0,0,0,0
0,0,0,0,0,0,0,0,0,0,0,0,0,0,0,13,13,0,0,0,0,0,0
0,0,0,0,0,0,0,0,0,0,0,0,0,0,0,0,0,0,0,0,0,0,0
endlayer

layer
0,0,0,0,0,0,0,0,0,0,0,13,0,0,0,0,0,0,0,0,0,0,0
0,0,0,0,0,0,0,0,0,0,13,13,13,0,0,0,0,0,0,0,0,0,0
0,0,0,0,0,0,13,0,0,13,13,7,13,13,0,0,0,0,0,0,0,0,0
0,0,0,0,0,13,13,13,13,13,13,13,7,0,0,0,0,0,11,0,0,0,0
0,0,13,13,13,13,7,13,13,0,0,13,0,0,13,13,13,0,0,0,0,0,0
0,13,11,13,13,13,7,13,13,0,0,7,7,0,13,7,13,13,0,0,0,0,0
0,0,13,13,13,13,13,7,0,0,0,0,7,0,0,0,13,0,0,0,0,0,0
0,0,0,0,0,0,13,0,0,0,0,0,0,0,0,0,0,0,0,0,0,0,0
0,0,0,0,0,0,0,13,13,0,0,0,0,0,0,0,0,0,0,0,0,0,0
0,0,0,0,0,0,13,13,13,13,13,0,0,0,7,13,13,0,0,0,0,0,0
0,0,0,0,0,13,7,7,7,13,13,13,0,0,13,13,13,13,0,0,0,0,0
0,0,0,0,13,11,13,13,13,13,7,13,13,0,0,13,13,0,0,0,0,0,0
0,0,0,0,0,13,0,13,13,13,13,13,0,0,0,0,0,0,0,0,0,0,0
0,0,0,0,0,0,0,0,0,0,13,0,0,0,0,0,0,0,0,0,0,0,0
endlayer

layer
0,0,0,0,0,0,0,0,0,0,0,0,0,0,0,0,0,0,0,0,0,0,0
0,0,0,0,0,0,0,0,0,0,0,13,0,0,0,0,0,0,0,0,0,0,0
0,0,0,0,0,0,0,0,0,0,13,13,13,0,0,0,0,13,13,0,0,0,0
0,0,13,13,13,13,0,0,0,13,13,13,0,0,0,0,13,13,11,13,0,0,0
0,13,13,13,13,13,13,0,13,13,7,7,0,0,0,0,7,7,13,0,0,0,0
13,13,7,7,7,7,13,13,0,0,0,7,0,0,0,0,0,0,0,0,0,0,0
0,13,13,13,13,13,13,0,0,0,0,0,0,0,0,0,0,0,0,0,0,0,0
0,0,13,13,13,13,0,0,0,0,0,0,0,0,0,0,0,0,0,0,0,0,0
0,0,0,0,0,0,0,0,0,0,0,0,0,0,0,0,0,0,0,0,0,0,0
0,0,0,0,0,13,0,13,13,0,0,0,0,0,0,7,0,0,0,0,0,0,0
0,0,0,0,13,13,13,13,13,13,13,0,0,0,0,0,0,0,0,0,0,0,0
0,0,0,13,13,7,13,13,13,13,13,13,0,0,0,0,0,0,0,0,0,0,0
0,0,0,0,13,13,13,0,0,0,13,0,0,0,0,0,0,0,0,0,0,0,0
0,0,0,0,0,13,0,0,0,0,0,0,0,0,0,0,0,0,0,0,0,0,0
endlayer

layer
0,0,0,0,0,0,0,0,0,0,0,0,0,0,0,0,0,0,0,0,0,0,0
0,0,0,0,0,0,0,0,0,0,0,0,0,0,0,0,0,13,13,0,0,0,0
0,0,0,0,0,0,0,0,0,0,13,0,0,0,0,0,13,13,13,13,0,0,0
0,0,0,0,0,0,0,0,0,13,13,13,0,0,0,13,13,7,7,13,13,0,0
0,0,13,13,13,13,0,0,0,13,7,13,0,11,0,0,13,13,13,13,0,0,0
0,13,13,13,13,13,13,0,0,0,13,0,11,11,11,0,0,13,13,0,0,0,0
0,0,13,13,13,13,0,0,0,0,0,0,0,11,0,0,0,0,0,0,0,0,0
0,0,0,0,0,0,0,0,0,0,0,0,0,0,0,0,0,0,0,0,0,0,0
0,0,0,0,0,0,0,0,0,0,0,0,0,0,0,0,0,0,0,0,0,0,0
0,0,0,0,0,0,0,0,0,0,0,0,0,0,0,7,0,0,0,0,0,0,0
0,0,0,0,0,13,0,13,13,0,0,0,0,0,0,0,0,0,0,0,0,0,0
0,0,0,0,13,13,13,0,0,0,0,0,0,0,0,0,0,0,0,0,0,0,0
0,0,0,0,0,13,0,0,0,0,0,0,0,0,0,0,0,0,0,0,0,0,0
0,0,0,0,0,0,0,0,0,0,0,0,0,0,0,0,0,0,0,0,0,0,0
endlayer

layer
0,0,0,0,0,0,0,0,0,0,0,0,0,0,0,0,0,0,0,0,0,0,0
0,0,0,0,0,0,0,0,0,0,13,0,0,0,0,0,0,0,0,0,0,0,0
0,0,0,0,0,0,0,0,0,13,13,13,0,0,0,0,0,13,13,0,0,0,0
0,0,0,0,0,0,0,0,13,13,7,13,13,0,0,0,13,13,13,13,0,0,0
0,0,0,0,0,0,0,0,13,13,7,13,13,12,0,0,0,13,13,0,0,0,0
0,0,0,0,0,0,0,0,0,13,13,13,12,11,12,0,0,0,0,0,0,0,0
0,0,0,0,0,0,0,0,0,0,13,0,0,12,0,0,0,0,0,0,0,0,0
0,0,0,0,0,0,0,0,0,0,0,0,13,13,0,13,13,0,0,0,0,0,0
0,0,0,0,0,0,0,0,0,0,0,0,13,13,7,13,13,0,0,0,0,0,0
0,0,0,0,0,0,0,0,0,0,0,0,0,13,13,13,0,0,0,0,0,0,0
0,0,0,0,0,0,0,0,0,0,0,0,0,0,13,7,13,0,0,0,0,0,0
0,0,0,0,0,0,0,0,0,0,0,0,0,0,0,0,0,0,0,0,0,0,0
0,0,0,0,0,0,0,0,0,0,0,0,0,0,0,0,0,0,0,0,0,0,0
0,0,0,0,0,0,0,0,0,0,0,0,0,0,0,0,0,0,0,0,0,0,0
endlayer

layer
0,0,0,0,0,0,0,0,0,0,0,0,0,0,0,0,0,0,0,0,0,0,0
0,0,0,0,0,0,0,0,0,0,0,0,0,0,0,0,0,0,0,0,0,0,0
0,0,0,0,0,0,0,0,0,0,13,0,0,0,0,0,0,0,0,0,0,0,0
0,0,0,0,0,0,0,0,0,7,13,13,0,0,0,0,0,0,0,0,0,0,0
0,0,0,0,0,0,0,0,0,13,13,13,0,0,0,0,0,0,0,0,0,0,0
0,0,0,0,0,0,0,0,0,0,13,0,0,11,0,0,0,0,0,0,0,0,0
0,0,0,0,0,0,0,0,0,0,0,0,0,0,13,0,0,0,0,0,0,0,0
0,0,0,0,0,0,0,0,0,0,0,0,0,13,7,13,0,0,0,0,0,0,0
0,0,0,0,0,0,0,0,0,0,0,0,0,13,13,13,0,0,0,0,0,0,0
0,0,0,0,0,0,0,0,0,0,0,0,0,0,13,13,13,0,0,0,0,0,0
0,0,0,0,0,0,0,0,0,0,0,0,0,13,13,7,13,13,0,0,0,0,0
0,0,0,0,0,0,0,0,0,0,0,0,0,0,13,13,13,0,0,0,0,0,0
0,0,0,0,0,0,0,0,0,0,0,0,0,0,0,13,0,0,0,0,0,0,0
0,0,0,0,0,0,0,0,0,0,0,0,0,0,0,0,0,0,0,0,0,0,0
endlayer

layer
0,0,0,0,0,0,0,0,0,0,0,0,0,0,0,0,0,0,0,0,0,0,0
0,0,0,0,0,0,0,0,0,0,0,0,0,0,0,0,0,0,0,0,0,0,0
0,0,0,0,0,0,0,0,13,0,0,0,0,0,0,0,0,0,0,0,0,0,0
0,0,0,0,0,0,0,13,13,7,0,0,0,0,0,0,0,0,0,0,0,0,0
0,0,0,0,0,0,0,0,13,0,0,0,0,13,0,0,0,0,0,0,0,0,0
0,0,0,0,0,0,0,0,0,0,0,0,13,11,13,0,0,0,0,0,0,0,0
0,0,0,0,0,0,0,0,0,0,0,0,13,13,13,0,0,0,0,0,0,0,0
0,0,0,0,0,0,0,0,0,0,0,0,0,13,7,0,0,0,0,0,0,0,0
0,0,0,0,0,0,0,0,0,0,0,0,0,0,0,0,13,0,0,0,0,0,0
0,0,0,0,0,0,0,0,0,0,0,0,0,0,0,13,13,13,0,0,0,0,0
0,0,0,0,0,0,0,0,0,0,0,0,0,0,13,13,7,13,13,0,0,0,0
0,0,0,0,0,0,0,0,0,0,0,0,0,0,0,13,13,13,0,0,0,0,0
0,0,0,0,0,0,0,0,0,0,0,0,0,0,0,0,13,0,0,0,0,0,0
0,0,0,0,0,0,0,0,0,0,0,0,0,0,0,0,0,0,0,0,0,0,0
endlayer

layer
0,0,0,0,0,0,0,0,0,0,0,0,0,0,0,0,0,0,0,0,0,0,0
0,0,0,0,0,0,0,0,13,0,0,0,0,0,0,0,0,0,0,0,0,0,0
0,0,0,0,0,0,0,13,13,13,0,0,0,0,0,0,0,0,0,0,0,0,0
0,0,0,0,0,0,13,13,7,13,13,0,0,13,0,0,0,0,0,0,0,0,0
0,0,0,0,0,0,0,13,13,13,0,0,13,13,13,0,0,0,0,0,0,0,0
0,0,0,0,0,0,0,0,13,0,0,13,13,7,13,13,0,0,0,0,0,0,0
0,0,0,0,0,0,0,0,0,0,0,13,13,7,13,13,0,0,0,0,0,0,0
0,0,0,0,0,0,0,0,0,0,0,0,13,13,13,0,0,0,0,0,0,0,0
0,0,0,0,0,0,0,0,0,0,0,0,0,13,0,0,0,0,0,0,0,0,0
0,0,0,0,0,0,0,0,0,0,0,0,0,0,0,0,13,0,0,0,0,0,0
0,0,0,0,0,0,0,0,0,0,0,0,0,0,0,13,13,13,0,0,0,0,0
0,0,0,0,0,0,0,0,0,0,0,0,0,0,13,13,7,13,13,0,0,0,0
0,0,0,0,0,0,0,0,0,0,0,0,0,0,0,13,13,13,0,0,0,0,0
0,0,0,0,0,0,0,0,0,0,0,0,0,0,0,0,13,0,0,0,0,0,0
endlayer

layer
0,0,0,0,0,0,0,0,0,0,0,0,0,0,0,0,0,0,0,0,0,0,0
0,0,0,0,0,0,0,0,0,0,0,0,0,0,0,0,0,0,0,0,0,0,0
0,0,0,0,0,0,0,0,13,0,0,0,0,0,0,0,0,0,0,0,0,0,0
0,0,0,0,0,0,0,13,13,13,0,0,0,0,0,0,0,0,0,0,0,0,0
0,0,0,0,0,0,0,0,13,0,0,0,0,13,0,0,0,0,0,0,0,0,0
0,0,0,0,0,0,0,0,0,0,0,0,13,13,13,0,0,0,0,0,0,0,0
0,0,0,0,0,0,0,0,0,0,0,0,13,13,13,0,0,0,0,0,0,0,0
0,0,0,0,0,0,0,0,0,0,0,0,0,13,0,0,0,0,0,0,0,0,0
0,0,0,0,0,0,0,0,0,0,0,0,0,0,0,0,0,0,0,0,0,0,0
0,0,0,0,0,0,0,0,0,0,0,0,0,0,0,0,13,0,0,0,0,0,0
0,0,0,0,0,0,0,0,0,0,0,0,0,0,0,13,13,13,0,0,0,0,0
0,0,0,0,0,0,0,0,0,0,0,0,0,0,13,13,7,13,13,0,0,0,0
0,0,0,0,0,0,0,0,0,0,0,0,0,0,0,13,13,13,0,0,0,0,0
0,0,0,0,0,0,0,0,0,0,0,0,0,0,0,0,13,0,0,0,0,0,0
endlayer

layer
0,0,0,0,0,0,0,0,0,0,0,0,0,0,0,0,0,0,0,0,0,0,0
0,0,0,0,0,0,0,0,0,0,0,0,0,0,0,0,0,0,0,0,0,0,0
0,0,0,0,0,0,0,0,0,0,0,0,0,0,0,0,0,0,0,0,0,0,0
0,0,0,0,0,0,0,0,0,0,0,0,0,0,0,0,0,0,0,0,0,0,0
0,0,0,0,0,0,0,0,0,0,0,0,0,0,0,0,0,0,0,0,0,0,0
0,0,0,0,0,0,0,0,0,0,0,0,0,0,0,0,0,0,0,0,0,0,0
0,0,0,0,0,0,0,0,0,0,0,0,0,0,0,0,0,0,0,0,0,0,0
0,0,0,0,0,0,0,0,0,0,0,0,0,0,0,0,0,0,0,0,0,0,0
0,0,0,0,0,0,0,0,0,0,0,0,0,0,0,0,0,0,0,0,0,0,0
0,0,0,0,0,0,0,0,0,0,0,0,0,0,0,0,0,0,0,0,0,0,0
0,0,0,0,0,0,0,0,0,0,0,0,0,0,0,0,13,0,0,0,0,0,0
0,0,0,0,0,0,0,0,0,0,0,0,0,0,0,13,13,13,0,0,0,0,0
0,0,0,0,0,0,0,0,0,0,0,0,0,0,0,0,13,0,0,0,0,0,0
0,0,0,0,0,0,0,0,0,0,0,0,0,0,0,0,0,0,0,0,0,0,0
endlayer

layer
0,0,0,0,0,0,0,0,0,0,0,0,0,0,0,0,0,0,0,0,0,0,0
0,0,0,0,0,0,0,0,0,0,0,0,0,0,0,0,0,0,0,0,0,0,0
0,0,0,0,0,0,0,0,0,0,0,0,0,0,0,0,0,0,0,0,0,0,0
0,0,0,0,0,0,0,0,0,0,0,0,0,0,0,0,0,0,0,0,0,0,0
0,0,0,0,0,0,0,0,0,0,0,0,0,0,0,0,0,0,0,0,0,0,0
0,0,0,0,0,0,0,0,0,0,0,0,0,0,0,0,0,0,0,0,0,0,0
0,0,0,0,0,0,0,0,0,0,0,0,0,0,0,0,0,0,0,0,0,0,0
0,0,0,0,0,0,0,0,0,0,0,0,0,0,0,0,0,0,0,0,0,0,0
0,0,0,0,0,0,0,0,0,0,0,0,0,0,0,0,0,0,0,0,0,0,0
0,0,0,0,0,0,0,0,0,0,0,0,0,0,0,0,0,0,0,0,0,0,0
0,0,0,0,0,0,0,0,0,0,0,0,0,0,0,0,0,0,0,0,0,0,0
0,0,0,0,0,0,0,0,0,0,0,0,0,0,0,0,13,0,0,0,0,0,0
0,0,0,0,0,0,0,0,0,0,0,0,0,0,0,0,0,0,0,0,0,0,0
0,0,0,0,0,0,0,0,0,0,0,0,0,0,0,0,0,0,0,0,0,0,0
endlayer

