
# TreeGnarled (Oak)
# 11 Mar 2014; updated to MC 1.7.10, 10 Oct 2014
# Created by Ruins mod version 12.3 Ingame Parser
# authoring Player: Jordan_Greywolf
# Last Updated: 2 Dec 2017
# \templateparser version

biomesToSpawnIn=autumn hills,autumn woods,boreal forest,cold taiga,cold taiga hills,cold taiga m,enchanted forest,extreme hills,extreme hills edge,extreme hills m,extreme hills+,extreme hills+ m,flower forest,forest,foresthills,magical forest,mega taiga,mega taiga hills,mystic grove,oak savanna,plains,roofed forest,roofed forest m,taiga,taiga m,taigahills,thinned mystic grove,thinned timber,tundra,twilight clearing,twilight forest,wonderous woods,woodland,woodlands

weight=1
embed_into_distance=4

unacceptable_target_blocks=lava,flowing_lava,cloud,Natura:Cloud,slime_dirt,slime_grass,slime_congealed,command_block

dimensions=12,13,13
allowable_overhang=50
max_cut_in=0
cut_in_buffer=0
max_leveling=0
leveling_buffer=-1
preserve_water=0
preserve_lava=0
preserve_plants=1

rule1=0,100,preserveBlock
rule2=0,100,minecraft:log-12
rule3=0,100,minecraft:leaves-4

layer
1,1,1,1,1,1,1,1,1,1,1,1,1
1,1,1,1,1,1,1,1,1,1,1,1,1
1,1,1,1,1,1,1,1,1,1,1,1,1
1,1,1,2,1,1,1,1,1,1,1,1,1
1,1,1,1,1,1,1,1,1,1,1,1,1
1,1,1,1,1,1,1,1,1,1,1,1,1
1,1,1,1,1,1,1,1,1,1,1,1,1
1,1,1,1,1,1,1,1,1,1,1,1,1
1,1,1,1,1,1,1,1,1,1,1,1,1
1,1,2,1,1,1,1,1,2,1,1,1,1
1,1,1,1,1,1,1,1,1,1,1,1,1
1,1,1,1,1,1,1,1,1,1,1,1,1
1,1,1,1,1,1,1,1,1,1,1,1,1
endlayer

layer
1,1,1,1,1,1,1,1,1,1,1,1,1
1,1,1,1,1,1,1,1,1,1,1,1,1
1,1,1,1,1,1,1,1,1,1,1,1,1
1,1,1,2,1,1,1,1,1,1,1,1,1
1,1,1,1,2,1,1,1,1,2,1,1,1
1,1,1,1,1,1,2,1,1,1,1,1,1
1,1,1,1,1,1,1,1,1,1,1,1,1
1,1,1,1,1,1,1,1,1,1,1,1,1
1,1,1,2,1,1,1,2,1,1,1,1,1
1,1,2,1,1,1,1,1,2,1,1,1,1
1,1,1,1,1,1,1,1,1,1,1,1,1
1,1,1,1,1,1,1,1,1,1,1,1,1
1,1,1,1,1,1,1,1,1,1,1,1,1
endlayer

layer
1,1,1,1,1,1,1,1,1,1,1,1,1
1,1,1,1,1,1,1,1,1,1,1,1,1
1,1,1,1,1,1,1,1,1,1,1,1,1
1,1,1,1,1,1,1,1,1,1,1,1,1
1,1,1,1,2,1,1,1,2,1,1,1,1
1,1,1,1,2,1,2,1,1,1,1,1,1
1,1,1,1,2,1,1,1,1,1,1,1,1
1,1,1,1,1,1,1,2,1,1,1,1,1
1,1,1,2,1,1,1,2,1,1,1,1,1
1,1,1,1,1,1,1,1,1,1,1,1,1
1,1,1,1,1,1,1,1,1,1,1,1,1
1,1,1,1,1,1,1,1,1,1,1,1,1
1,1,1,1,1,1,1,1,1,1,1,1,1
endlayer

layer
1,1,1,1,1,1,1,1,1,1,1,1,1
1,1,1,1,1,1,1,1,1,1,1,1,1
1,1,1,1,1,1,1,1,1,1,1,1,1
1,1,1,1,1,1,1,1,1,1,1,1,1
1,1,1,1,1,1,2,2,2,1,1,1,1
1,1,1,1,2,2,2,2,1,1,1,1,1
1,1,1,1,2,2,2,2,1,1,1,1,1
1,1,1,1,2,1,2,2,1,1,1,1,1
1,1,1,2,1,1,1,2,1,1,1,1,1
1,1,1,1,1,1,1,1,1,1,1,1,1
1,1,1,1,1,1,1,1,1,1,1,1,1
1,1,1,1,1,1,1,1,1,1,1,1,1
1,1,1,1,1,1,1,1,1,1,1,1,1
endlayer

layer
1,1,1,1,1,1,1,1,1,1,1,1,1
1,1,1,1,1,1,1,1,1,1,1,1,1
1,1,1,1,1,1,1,1,1,1,1,1,1
1,1,1,1,1,1,1,1,3,1,1,1,1
1,1,1,1,1,1,2,1,2,3,1,1,1
1,1,1,1,2,2,1,2,2,1,1,1,1
1,1,1,1,2,2,1,2,1,1,1,1,1
1,1,1,1,2,2,1,2,1,1,1,1,1
1,1,1,1,1,1,1,1,1,1,1,1,1
1,1,1,1,1,1,1,1,1,1,1,1,1
1,1,1,1,1,1,1,1,1,1,1,1,1
1,1,1,1,1,1,1,1,1,1,1,1,1
1,1,1,1,1,1,1,1,1,1,1,1,1
endlayer

layer
1,1,1,1,1,1,1,1,1,1,1,1,1
1,1,1,1,1,1,1,1,1,1,1,1,1
1,1,1,1,1,1,1,1,1,1,1,1,1
1,1,1,1,1,1,1,3,3,3,1,1,1
1,1,1,1,1,1,2,3,3,3,1,1,1
1,1,1,1,1,2,1,2,2,3,1,1,1
1,1,1,1,2,2,1,2,1,1,1,1,1
1,1,1,1,2,1,1,1,1,1,1,1,1
1,1,1,1,1,1,1,1,1,1,1,1,1
1,1,1,1,1,1,1,1,1,1,1,1,1
1,1,1,1,1,1,1,1,1,1,1,1,1
1,1,1,1,1,1,1,1,1,1,1,1,1
1,1,1,1,1,1,1,1,1,1,1,1,1
endlayer

layer
1,1,1,1,1,1,1,1,1,1,1,1,1
1,1,1,1,1,1,1,1,1,1,1,1,1
1,1,1,1,1,1,1,1,1,1,1,1,1
1,1,1,1,1,1,1,1,3,1,1,1,1
1,1,1,1,1,2,2,3,3,3,1,1,1
1,1,1,1,1,2,2,2,3,1,1,1,1
1,1,1,1,2,2,2,2,1,1,1,1,1
1,1,1,1,2,1,1,1,1,1,1,1,1
1,1,1,1,1,1,1,1,1,1,1,1,1
1,1,1,1,1,1,1,1,1,1,1,1,1
1,1,1,1,1,1,1,1,1,1,1,1,1
1,1,1,1,1,1,1,1,1,1,1,1,1
1,1,1,1,1,1,1,1,1,1,1,1,1
endlayer

layer
1,1,1,1,1,1,1,1,1,1,1,1,1
1,1,1,1,1,1,1,1,1,1,1,1,1
1,1,1,1,1,1,1,1,1,1,1,1,1
1,1,1,1,1,1,1,1,1,1,1,1,1
1,1,1,1,1,2,2,1,1,1,1,1,1
1,1,1,1,1,2,2,2,1,1,1,1,1
1,1,1,1,1,2,2,2,1,1,1,1,1
1,1,1,1,2,1,1,1,2,1,1,1,1
1,1,1,1,1,1,1,1,1,1,1,1,1
1,1,1,1,1,1,1,1,1,1,1,1,1
1,1,1,1,1,1,1,1,1,1,1,1,1
1,1,1,1,1,1,1,1,1,1,1,1,1
1,1,1,1,1,1,1,1,1,1,1,1,1
endlayer

layer
1,1,1,1,1,1,1,1,1,1,1,1,1
1,1,1,1,1,1,1,1,1,1,1,1,1
1,1,1,1,1,1,1,1,1,3,1,1,1
1,1,1,3,3,1,3,1,1,3,1,1,1
1,1,3,3,3,2,2,1,2,1,1,1,1
1,1,1,3,3,2,2,2,1,1,1,1,1
1,1,1,1,1,1,2,1,1,1,1,1,1
1,1,3,1,2,1,1,1,2,1,1,1,1
1,3,3,2,1,1,1,1,1,2,1,1,1
1,1,3,1,1,1,1,1,3,3,3,1,1
1,1,1,1,1,1,1,1,3,3,3,1,1
1,1,1,1,1,1,1,1,1,3,1,1,1
1,1,1,1,1,1,1,1,1,1,1,1,1
endlayer

layer
1,1,1,1,1,1,1,1,1,3,1,1,1
1,1,1,1,1,1,1,1,3,3,3,1,1
1,1,1,3,3,3,1,3,3,2,3,3,1
1,1,3,3,3,3,3,3,3,2,3,3,1
1,3,3,2,2,2,3,3,2,3,3,1,1
1,1,3,3,3,3,3,3,3,3,1,1,1
1,1,3,3,3,3,1,1,3,3,1,1,1
1,3,3,3,3,1,1,1,3,3,3,1,1
3,3,2,2,3,3,1,3,3,2,3,3,1
1,3,3,3,3,1,1,3,3,2,3,3,1
1,1,3,3,1,1,1,3,3,2,3,3,1
1,1,1,1,1,1,1,1,3,3,3,1,1
1,1,1,1,1,1,1,1,1,3,1,1,1
endlayer

layer
1,1,1,1,1,1,1,1,1,1,1,1,1
1,1,1,1,1,1,1,1,1,3,1,1,1
1,1,1,1,1,1,1,1,3,3,3,1,1
1,1,1,3,3,3,1,1,3,3,3,1,1
1,1,3,3,3,3,3,3,3,3,1,1,1
1,1,1,3,3,3,1,1,3,1,1,1,1
1,1,1,1,1,1,1,1,1,1,1,1,1
1,1,3,3,1,1,1,1,1,3,1,1,1
1,3,3,3,3,1,1,1,3,3,3,1,1
1,3,3,2,3,3,1,1,3,3,3,1,1
1,1,3,3,3,1,1,1,3,3,3,1,1
1,1,1,3,1,1,1,1,1,3,1,1,1
1,1,1,1,1,1,1,1,1,1,1,1,1
endlayer

layer
1,1,1,1,1,1,1,1,1,1,1,1,1
1,1,1,1,1,1,1,1,1,1,1,1,1
1,1,1,1,1,1,1,1,1,1,1,1,1
1,1,1,1,1,1,1,1,1,1,1,1,1
1,1,1,1,1,1,1,1,1,1,1,1,1
1,1,1,1,1,1,1,1,1,1,1,1,1
1,1,1,1,1,1,1,1,1,1,1,1,1
1,1,1,1,1,1,1,1,1,1,1,1,1
1,1,1,3,1,1,1,1,1,1,1,1,1
1,1,3,3,3,1,1,1,1,1,1,1,1
1,1,1,3,1,1,1,1,1,1,1,1,1
1,1,1,1,1,1,1,1,1,1,1,1,1
1,1,1,1,1,1,1,1,1,1,1,1,1
endlayer

