
# Underground_Fountain (based on Menhir_Fountain)
# Created by Ruins mod version 12.3 Ingame Parser
# authoring Player: Jordan_Greywolf
# Last Updated: 27 Apr 2015

biomesToSpawnIn=extreme hills

weight=1
embed_into_distance=30

unacceptable_target_blocks=water,flowing_water,lava,flowing_lava,cloud,Natura:Cloud

dimensions=7,13,13
allowable_overhang=0
max_cut_in=0
cut_in_buffer=0
max_leveling=0
leveling_buffer=0
preserve_water=0
preserve_lava=0
preserve_plants=1

rule1=0,100,preserveBlock

# Pave Stones (and dirt/gravel)
rule2=0,100,minecraft:stone-0,minecraft:grass-0,minecraft:gravel-0

# Decorative Circle
rule3=0,100,minecraft:stonebrick-3

# Fountain
rule4=0,100,minecraft:water-0

# Column
rule5=1,100,minecraft:cobblestone-0,minecraft:mossy_cobblestone-0

# Keystone
rule6=0,100,minecraft:mossy_cobblestone-0,minecraft:cobblestone-0,minecraft:gravel-0

layer
1,1,1,1,1,2,2,2,1,1,1,1,1
1,1,1,2,2,2,2,2,2,2,1,1,1
1,1,2,2,2,3,3,3,2,2,2,1,1
1,2,2,2,3,4,4,4,3,2,2,2,1
1,2,2,3,4,4,4,4,4,3,2,2,1
2,2,3,4,4,4,4,4,4,4,3,2,2
2,2,3,4,4,4,2,4,4,4,3,2,2
2,2,3,4,4,4,4,4,4,4,3,2,2
1,2,2,3,4,4,4,4,4,3,2,2,1
1,2,2,2,3,4,4,4,3,2,2,2,1
1,1,2,2,2,3,3,3,2,2,2,1,1
1,1,1,2,2,2,2,2,2,2,1,1,1
1,1,1,1,1,2,2,2,1,1,1,1,1
endlayer


layer
1,1,1,1,1,2,2,2,1,1,1,1,1
1,1,1,2,2,2,2,2,2,2,1,1,1
1,1,2,2,2,3,3,3,2,2,2,1,1
1,2,2,2,3,4,4,4,3,2,2,2,1
1,2,2,3,4,4,4,4,4,3,2,2,1
2,2,3,4,4,4,4,4,4,4,3,2,2
2,2,3,4,4,4,2,4,4,4,3,2,2
2,2,3,4,4,4,4,4,4,4,3,2,2
1,2,2,3,4,4,4,4,4,3,2,2,1
1,2,2,2,3,4,4,4,3,2,2,2,1
1,1,2,2,2,3,3,3,2,2,2,1,1
1,1,1,2,2,2,2,2,2,2,1,1,1
1,1,1,1,1,2,2,2,1,1,1,1,1
endlayer

layer
1,1,1,1,1,5,1,5,1,1,1,1,1
1,1,1,5,1,0,1,0,1,5,1,1,1
1,1,1,1,0,0,0,0,0,1,1,1,1
1,5,1,0,0,0,0,0,0,0,1,5,1
1,1,0,0,0,0,4,0,0,0,0,1,1
5,0,0,0,0,0,0,0,0,0,0,0,5
1,1,0,0,4,0,2,0,4,0,0,1,1
5,0,0,0,0,0,0,0,0,0,0,0,5
1,1,0,0,0,0,4,0,0,0,0,1,1
1,5,1,0,0,0,0,0,0,0,1,5,1
1,1,1,1,0,0,0,0,0,1,1,1,1
1,1,1,5,1,0,1,0,1,5,1,1,1
1,1,1,1,1,5,1,5,1,1,1,1,1
endlayer

layer
1,1,1,1,1,5,1,5,1,1,1,1,1
1,1,1,5,0,0,0,0,0,5,1,1,1
1,1,1,0,0,0,0,0,0,0,1,1,1
1,5,0,0,0,0,0,0,0,0,0,5,1
1,0,0,0,0,0,4,0,0,0,0,0,1
5,0,0,0,0,0,0,0,0,0,0,0,5
1,0,0,0,4,0,2,0,4,0,0,0,1
5,0,0,0,0,0,0,0,0,0,0,0,5
1,0,0,0,0,0,4,0,0,0,0,0,1
1,5,0,0,0,0,0,0,0,0,0,5,1
1,1,1,0,0,0,0,0,0,0,1,1,1
1,1,1,5,0,0,0,0,0,5,1,1,1
1,1,1,1,1,5,1,5,1,1,1,1,1
endlayer

layer
1,1,1,1,1,5,6,5,1,1,1,1,1
1,1,1,5,0,0,0,0,0,5,1,1,1
1,1,6,0,0,0,0,0,0,0,6,1,1
1,5,0,0,0,0,0,0,0,0,0,5,1
1,0,0,0,0,0,4,0,0,0,0,0,1
5,0,0,0,0,0,0,0,0,0,0,0,5
6,0,0,0,4,0,2,0,4,0,0,0,6
5,0,0,0,0,0,0,0,0,0,0,0,5
1,0,0,0,0,0,4,0,0,0,0,0,1
1,5,0,0,0,0,0,0,0,0,0,5,1
1,1,6,0,0,0,0,0,0,0,6,1,1
1,1,1,5,0,0,0,0,0,5,1,1,1
1,1,1,1,1,5,6,5,1,1,1,1,1
endlayer

layer
1,1,1,1,1,1,1,1,1,1,1,1,1
1,1,1,1,1,0,0,0,1,1,1,1,1
1,1,1,1,0,0,0,0,0,1,1,1,1
1,1,1,0,0,0,0,0,0,0,1,1,1
1,1,0,0,0,0,4,0,0,0,0,1,1
1,0,0,0,0,0,0,0,0,0,0,0,1
1,0,0,0,4,0,4,0,4,0,0,0,1
1,0,0,0,0,0,0,0,0,0,0,0,1
1,1,0,0,0,0,4,0,0,0,0,1,1
1,1,1,0,0,0,0,0,0,0,1,1,1
1,1,1,1,0,0,0,0,0,1,1,1,1
1,1,1,1,1,0,0,0,1,1,1,1,1
1,1,1,1,1,1,1,1,1,1,1,1,1
endlayer

layer
1,1,1,1,1,1,1,1,1,1,1,1,1
1,1,1,1,1,1,1,1,1,1,1,1,1
1,1,1,1,1,0,0,0,1,1,1,1,1
1,1,1,1,0,0,0,0,0,1,1,1,1
1,1,1,0,0,0,0,0,0,0,1,1,1
1,1,0,0,0,0,4,0,0,0,0,1,1
1,1,0,0,0,4,0,4,0,0,0,1,1
1,1,0,0,0,0,4,0,0,0,0,1,1
1,1,1,0,0,0,0,0,0,0,1,1,1
1,1,1,1,0,0,0,0,0,1,1,1,1
1,1,1,1,1,0,0,0,1,1,1,1,1
1,1,1,1,1,1,1,1,1,1,1,1,1
1,1,1,1,1,1,1,1,1,1,1,1,1
endlayer

