# Vault 4-Way
# MC 1.7.10; 12 Nov 2014
# Created by Ruins mod version 14.2 Ingame Parser
# authoring Player: Jordan_Greywolf
# Special Instructions: Place in /templateparser folder.

weight=1
embed_into_distance=0
acceptable_target_blocks=
unacceptable_target_blocks=
dimensions=6,16,16
allowable_overhang=9999
max_leveling=0
leveling_buffer=0
preserve_water=0
preserve_lava=0
preserve_plants=1

# Randomized Stone Brick Walls
rule1=0,100,minecraft:stonebrick,minecraft:stonebrick-1,minecraft:stonebrick-2,minecraft:monster_egg-4

# Mossy Cobblestone Floor
rule2=0,100,minecraft:mossy_cobblestone-0

# Randomized Skulls
rule3=0,100,minecraft:skull,minecraft:skull-1,minecraft:skull-2,minecraft:skull-3

rule4=0,100,minecraft:web-0
rule5=0,100,minecraft:vine-4
rule6=0,100,minecraft:stone_brick_stairs-0
rule7=0,100,minecraft:stone_brick_stairs-3
rule8=0,100,minecraft:stone_brick_stairs-2
rule9=0,100,minecraft:stone_brick_stairs-1
rule10=0,100,minecraft:cobblestone_wall,minecraft:cobblestone_wall-1
rule11=0,100,minecraft:vine-1
rule12=0,100,minecraft:stone_brick_stairs-5
rule13=0,100,minecraft:stone_brick_stairs-7
rule14=0,100,minecraft:stone_brick_stairs-6
rule15=0,100,minecraft:stone_brick_stairs-4
rule16=0,100,minecraft:vine-2
rule17=0,100,minecraft:vine-8
rule18=0,100,minecraft:vine-0
rule19=0,100,preserveBlock

# Chiseled Stone
rule20=0,100,minecraft:stonebrick-3

layer
1,1,1,1,1,1,1,2,2,1,1,1,1,1,1,1
1,2,2,2,1,1,2,2,2,2,1,1,2,2,2,1
1,2,2,2,1,1,2,2,2,2,1,1,2,2,2,1
1,2,2,2,1,1,1,2,2,1,1,1,2,2,2,1
1,1,1,1,1,1,2,2,2,2,1,1,1,1,1,1
1,1,1,1,1,1,2,2,2,2,1,1,1,1,1,1
1,2,2,1,2,2,2,2,2,2,2,2,1,2,2,1
2,2,2,2,2,2,2,1,1,2,2,2,2,2,2,2
2,2,2,2,2,2,2,1,1,2,2,2,2,2,2,2
1,2,2,1,2,2,2,2,2,2,2,2,1,2,2,1
1,1,1,1,1,1,2,2,2,2,1,1,1,1,1,1
1,1,1,1,1,1,2,2,2,2,1,1,1,1,1,1
1,2,2,2,1,1,1,2,2,1,1,1,2,2,2,1
1,2,2,2,1,1,2,2,2,2,1,1,2,2,2,1
1,2,2,2,1,1,2,2,2,2,1,1,2,2,2,1
1,1,1,1,1,1,1,2,2,1,1,1,1,1,1,1
endlayer

layer
1,1,1,1,1,1,1,0,0,1,1,1,1,1,1,1
1,3,4,3,1,1,4,0,0,3,1,1,3,4,3,1
1,4,0,4,1,1,4,0,0,4,1,1,4,0,4,1
1,3,4,3,1,1,1,0,0,1,1,1,3,4,3,1
1,1,1,1,1,1,4,0,4,4,1,1,1,1,1,1
1,1,1,1,1,1,0,0,0,5,1,1,1,1,1,1
1,0,0,1,0,0,0,0,0,0,0,4,1,0,0,1
0,0,0,4,0,0,0,7,6,0,0,0,0,0,0,4
4,0,0,0,0,0,0,9,8,0,0,0,0,0,0,0
1,0,0,1,3,0,0,0,0,0,0,0,1,4,3,1
1,1,1,1,1,1,0,0,0,0,1,1,1,1,1,1
1,1,1,1,1,1,4,4,0,4,1,1,1,1,1,1
1,3,4,3,1,1,1,0,0,1,1,1,3,0,3,1
1,4,0,4,1,1,4,0,0,4,1,1,0,0,4,1
1,3,4,3,1,1,3,0,0,0,1,1,3,4,3,1
1,1,1,1,1,1,1,0,0,1,1,1,1,1,1,1
endlayer

layer
1,9,9,9,1,1,10,0,0,10,1,1,9,9,9,1
8,4,0,0,7,8,0,0,0,0,7,8,4,0,4,7
8,0,0,0,7,8,0,0,0,0,7,8,0,0,0,7
8,4,0,4,7,1,10,0,0,10,1,8,4,0,4,7
1,6,6,6,1,8,0,0,0,0,7,1,6,6,6,1
1,9,9,1,9,8,0,0,0,5,7,9,1,9,9,1
10,0,0,10,0,0,0,0,0,5,0,0,10,0,0,10
0,0,0,0,0,0,0,10,10,0,0,0,0,0,0,0
0,0,0,0,0,0,0,10,10,0,0,0,0,0,0,0
10,0,0,10,0,0,11,0,0,0,0,0,10,11,0,10
1,6,6,1,6,8,0,0,0,0,7,6,1,6,6,1
1,9,9,9,1,8,4,4,0,0,7,1,9,9,9,1
8,0,0,0,7,1,10,0,0,10,1,8,4,0,4,7
8,0,0,0,7,8,0,0,0,0,7,8,0,0,0,7
8,0,0,0,7,8,0,0,0,0,7,8,4,0,4,7
1,6,6,6,1,1,10,0,0,10,1,1,6,6,6,1
endlayer

layer
1,12,12,12,1,1,14,0,4,13,1,1,12,12,12,1
14,0,0,0,13,14,0,0,0,0,13,14,4,0,0,13
14,0,0,0,13,14,0,0,0,0,13,14,4,0,0,13
14,0,0,4,13,1,14,0,0,13,1,14,4,0,0,13
1,15,15,15,1,14,16,0,0,16,13,1,15,15,15,1
1,12,12,1,12,14,11,0,0,5,13,12,1,12,12,1
12,11,0,12,16,0,11,0,0,5,16,0,12,0,16,12
0,0,0,0,0,0,0,3,3,0,0,0,0,0,0,0
0,0,0,0,0,0,0,3,3,0,0,0,0,0,0,4
15,0,0,15,0,17,11,0,0,5,17,0,15,11,0,15
1,15,15,1,15,14,11,0,0,5,13,15,1,15,15,1
1,12,12,12,1,14,17,0,0,0,13,1,12,12,12,1
14,0,0,0,13,1,14,4,4,13,1,14,4,0,0,13
14,0,0,0,13,14,0,0,0,0,13,14,0,0,0,13
14,0,0,0,13,14,0,0,0,0,13,14,0,4,4,13
1,15,15,15,1,1,14,0,0,13,1,1,15,15,15,1
endlayer

layer
1,1,1,1,1,1,1,14,13,1,1,1,1,1,1,1
1,4,0,4,1,1,14,0,4,13,1,1,4,0,4,1
1,0,0,0,1,1,14,4,0,13,1,1,0,0,0,1
1,4,4,0,1,1,1,14,13,1,1,1,0,0,4,1
1,1,1,1,1,1,16,0,0,16,1,1,1,1,1,1
1,1,1,1,1,1,11,0,0,5,1,1,1,1,1,1
1,11,0,1,16,16,18,0,0,18,16,16,1,0,16,1
12,4,0,12,4,0,0,0,0,4,0,4,12,0,0,12
15,0,0,15,0,0,0,4,0,4,0,0,15,0,0,15
1,4,4,1,17,17,18,0,0,18,17,17,1,11,0,1
1,1,1,1,1,1,11,0,0,5,1,1,1,1,1,1
1,1,1,1,1,1,17,0,0,17,1,1,1,1,1,1
1,4,0,4,1,1,1,14,13,1,1,1,0,0,4,1
1,0,0,0,1,1,14,0,4,13,1,1,0,0,0,1
1,4,0,4,1,1,14,4,0,13,1,1,0,0,4,1
1,1,1,1,1,1,1,14,13,1,1,1,1,1,1,1
endlayer

layer
19,1,1,1,19,19,1,1,1,1,19,19,1,1,1,19
1,1,1,1,1,19,1,20,20,1,19,1,1,1,1,1
1,1,20,1,1,19,1,20,20,1,19,1,1,20,1,1
1,1,1,1,1,19,1,1,1,1,19,1,1,1,1,1
19,1,1,1,19,19,1,20,20,1,19,19,1,1,1,19
19,19,19,19,19,19,1,20,20,1,19,19,19,19,19,19
1,1,1,1,1,1,1,1,1,1,1,1,1,1,1,1
1,20,20,1,20,20,1,20,20,1,20,20,1,20,20,1
1,20,20,1,20,20,1,20,20,1,20,20,1,20,20,1
1,1,1,1,1,1,1,1,1,1,1,1,1,1,1,1
19,19,19,19,19,19,1,20,20,1,19,19,19,19,19,19
19,1,1,1,19,19,1,20,20,1,19,19,1,1,1,19
1,1,1,1,1,19,1,1,1,1,19,1,1,1,1,1
1,1,20,1,1,19,1,20,20,1,19,1,1,20,1,1
1,1,1,1,1,19,1,20,20,1,19,1,1,1,1,1
19,1,1,1,19,19,1,1,1,1,19,19,1,1,1,19
endlayer

