# Vault Shrine
# MC 1.7.10; 12 Nov 2014
# Created by Ruins mod version 14.2 Ingame Parser
# authoring Player: Jordan_Greywolf
# Special Instructions: Place in /templateparser folder
# Updated to MC 1.8: 5 Mar 2016
# Updated to MC 1.9: 24 Apr 2016
# Updated to MC 1.11: 12 Jan 2017
# Updated to MC 1.12: 22 Jun 2017

weight=1
embed_into_distance=0
acceptable_target_blocks=
unacceptable_target_blocks=
dimensions=11,16,16
allowable_overhang=0
max_leveling=0
leveling_buffer=0
preserve_water=0
preserve_lava=0
preserve_plants=1

# Chiseled Stone
rule1=0,100,minecraft:stonebrick-3

# Randomized Stone Brick
rule2=0,100,minecraft:stonebrick,minecraft:stonebrick-1,minecraft:stonebrick-2,minecraft:monster_egg-4

rule3=0,100,preserveBlock

# Mossy Cobblestone Floor
rule4=0,100,minecraft:mossy_cobblestone-0

rule5=0,100,minecraft:double_stone_slab-0
rule6=0,100,minecraft:stone_brick_stairs-1

# Cobblestone Statue Body
rule7=0,100,minecraft:cobblestone-0

rule8=0,100,minecraft:stone_stairs-3
rule9=0,100,minecraft:web-0
rule10=0,100,minecraft:vine-2
rule11=0,100,minecraft:stone_stairs-2
rule12=0,100,minecraft:stone_slab-3
rule13=0,100,minecraft:stone_stairs-1
rule14=0,100,minecraft:vine-4
rule15=0,100,minecraft:vine-1
rule16=0,100,minecraft:stone_brick_stairs-2
rule17=0,100,minecraft:stone_brick_stairs-0
rule18=0,100,minecraft:stone_brick_stairs-3

# Randomized Skull
rule19=0,100,minecraft:skull,minecraft:skull-1,minecraft:skull-2,minecraft:skull-3,minecraft:skull-4,minecraft:skull-5

rule20=0,100,ChestGenHook:chests/simple_dungeon:3-3
rule21=0,100,minecraft:wooden_door-3
rule22=0,100,minecraft:stone_stairs-0
rule23=0,100,minecraft:vine-8
rule24=0,100,ChestGenHook:chests/simple_dungeon:3-5
rule25=0,100,minecraft:glowstone-0
rule26=0,100,ChestGenHook:chests/simple_dungeon:3-2

# Randomized Stained Glass
rule27=0,100,minecraft:stained_glass-1,minecraft:stained_glass-2,minecraft:stained_glass-3,minecraft:stained_glass-4,minecraft:stained_glass-5,minecraft:stained_glass-6,minecraft:stained_glass-9,minecraft:stained_glass-10,minecraft:stained_glass-11,minecraft:stained_glass-12,minecraft:stained_glass-13,minecraft:stained_glass-14

# Randomized Cobblestone Wall
rule28=0,100,minecraft:cobblestone_wall-0,minecraft:cobblestone_wall-1

rule29=0,100,minecraft:stone_brick_stairs-6
rule30=0,100,minecraft:stone_brick_stairs-4
rule31=0,100,minecraft:stone_brick_stairs-7
rule32=0,100,minecraft:wooden_door-8
rule33=0,100,minecraft:wooden_door-9
rule34=0,100,minecraft:stone_brick_stairs-5
rule35=0,100,minecraft:vine-12
rule36=0,100,ChestGenHook:chests/simple_dungeon:3-4

# Restless Spirit Mob Spawner
rule37=0,100,CommandBlock:RUINSTRIGGER /setblock ~0 ~-1 ~0 mob_spawner 0 replace {SpawnData:{ArmorItems:[{},{},{},{Count:1,id:skull,Damage:1}],ActiveEffects:[{Id:14,Amplifier:1,Duration:999999}],Silent:1,id:zombie}}:@

rule38=1,100,minecraft:redstone_torch-5

# Barrow Champion Summon
rule39=0,100,CommandBlock:RUINSTRIGGER /summon Skeleton ~0 ~0 ~0 {HandItems:[{Count:1,id:golden_sword,tag:{display:{Name:"Cursed Warblade"},ench:[{id:48,lvl:8},{id:49,lvl:2},{id:50,lvl:2}]}},{Count:1,id:shield}],ArmorItems:[{Count:1,id:golden_boots},{Count:1,id:golden_leggings},{Count:1,id:golden_chestplate},{Count:1,id:golden_helmet}],CustomName:"Barrow Champion",Health:100.0f,Attributes:[{Name:generic.movementSpeed,Base:0.5}],HandDropChances:[0.5F,0.5F],ArmorDropChances:[0.3F,0.3F,0.3F,0.3F],ActiveEffects:[{Id:12,Amplifier:1,Duration:999999,Ambient:1},{Id:3,Amplifier:1,Duration:999999,Ambient:1},{Id:21,Amplifier:1,Duration:999999,Ambient:1},{Id:14,Amplifier:1,Duration:999999,Ambient:1},{Id:11,Amplifier:1,Duration:999999,Ambient:1},{Id:1,Amplifier:1,Duration:999999,Ambient:1},{Id:5,Amplifier:1,Duration:999999.Ambient:1}],PersistenceRequired:1}:@

# Barrow Archer Summon
rule40=0,100,CommandBlock:RUINSTRIGGER /summon Skeleton ~0 ~0 ~0 {HandItems:[{Count:1,id:bow,tag:{display:{Name:"Cursed Warbow"},ench:[{id:19,lvl:8},{id:20,lvl:2},{id:19,lvl:5}]}},{Count:8,id:arrow}],ArmorItems:[{Count:1,id:golden_boots},{Count:1,id:golden_leggings},{Count:1,id:golden_chestplate},{Count:1,id:golden_helmet}],CustomName:"Barrow Archer",Health:100.0f,Attributes:[{Name:generic.movementSpeed,Base:0.5}],HandDropChances:[0.5F,0.5F],ArmorDropChances:[0.2F,0.2F,0.2F,0.2F],ActiveEffects:[{Id:12,Amplifier:1,Duration:999999,Ambient:1},{Id:3,Amplifier:1,Duration:999999,Ambient:1},{Id:21,Amplifier:1,Duration:999999,Ambient:1},{Id:14,Amplifier:1,Duration:999999,Ambient:1},{Id:11,Amplifier:1,Duration:999999,Ambient:1},{Id:1,Amplifier:1,Duration:999999,Ambient:1},{Id:5,Amplifier:1,Duration:999999.Ambient:1}],PersistenceRequired:1}:@

rule41=0,100,minecraft:stone_stairs-7
rule42=0,100,minecraft:stone_stairs-6
rule43=0,100,minecraft:stone_stairs-5
rule44=0,100,minecraft:stone_slab-11
rule45=0,100,minecraft:stone_stairs-4
rule46=0,100,minecraft:stone_slab-13

layer
1,2,2,1,3,2,2,4,4,2,2,3,1,2,2,1
2,2,2,2,3,2,4,4,4,4,2,3,2,2,2,2
2,2,2,2,3,2,4,4,4,4,2,3,2,2,2,2
1,2,2,1,2,2,2,4,4,2,2,2,1,2,2,1
2,4,4,2,4,4,4,4,4,4,4,4,2,3,3,3
2,4,4,2,4,4,4,4,4,4,4,4,2,2,2,2
2,4,4,2,4,4,2,2,2,2,2,4,2,4,4,2
4,4,4,4,4,4,2,2,2,2,2,4,4,4,4,4
4,4,4,4,4,4,2,2,2,2,2,4,4,4,4,4
2,4,4,2,4,4,2,2,2,2,2,4,2,4,4,2
2,4,4,2,4,4,4,4,4,4,4,4,2,2,2,2
2,4,4,2,4,4,4,4,4,4,4,4,2,3,3,3
1,2,2,1,2,2,2,4,4,2,2,2,1,2,2,1
2,2,2,2,3,2,4,4,4,4,2,3,2,2,2,2
2,2,2,2,3,2,4,4,4,4,2,3,2,2,2,2
1,2,2,1,3,2,2,4,4,2,2,3,1,2,2,1
endlayer

layer
5,4,4,5,3,2,2,2,2,2,2,3,5,4,4,5
4,4,4,4,3,2,2,2,2,2,2,3,4,4,4,4
4,4,4,4,3,2,2,2,2,2,2,3,4,4,4,4
5,4,4,5,2,2,2,6,6,2,2,2,5,4,4,5
2,12,12,2,7,11,10,0,10,9,8,7,2,3,3,3
2,15,14,2,13,0,0,0,0,0,0,13,2,2,2,2
2,15,14,2,0,0,17,17,17,17,16,9,2,2,2,2
21,0,0,0,0,0,18,19,20,19,16,14,18,2,2,2
21,0,0,0,15,0,18,19,20,19,16,14,18,2,2,2
2,15,14,2,0,0,6,6,6,6,16,0,2,2,2,2
2,15,14,2,22,9,0,0,0,0,0,22,2,2,2,2
2,12,12,2,7,11,0,23,23,0,8,7,2,3,3,3
5,4,4,5,2,2,2,17,17,2,2,2,5,4,4,5
4,4,4,4,3,2,2,2,2,2,2,3,4,4,4,4
4,4,4,4,3,2,2,2,2,2,2,3,4,4,4,4
5,4,4,5,3,2,2,2,2,2,2,3,5,4,4,5
endlayer

layer
5,24,24,5,3,2,2,2,2,2,2,3,5,0,0,5
26,0,0,0,14,2,25,25,25,25,2,0,0,0,0,0
26,0,0,23,14,2,27,27,27,27,2,0,0,0,0,0
5,15,14,5,2,2,28,0,0,28,2,2,5,0,0,5
2,15,14,2,7,10,10,0,10,10,10,7,2,0,0,3
2,15,14,2,10,0,0,0,0,0,0,10,2,2,2,2
28,0,0,28,0,0,31,30,30,30,29,14,28,27,25,2
32,0,0,0,0,0,31,1,1,1,29,14,0,27,25,2
33,0,0,0,15,0,31,1,1,1,29,14,0,27,25,2
28,0,0,28,0,0,31,34,34,34,29,14,28,27,25,2
2,15,14,2,15,0,0,0,0,0,0,35,2,2,2,2
2,15,14,2,7,15,0,23,23,0,14,7,2,0,0,3
5,15,14,5,2,2,28,0,0,28,2,2,5,0,0,5
26,0,0,10,10,2,27,27,27,27,2,0,0,0,0,0
26,0,0,0,14,2,25,25,25,25,2,0,0,0,0,0
5,36,36,5,3,2,2,2,2,2,2,3,5,0,0,5
endlayer

layer
5,0,0,5,3,2,2,2,2,2,2,3,5,0,0,5
0,0,0,37,14,2,25,25,25,25,2,0,0,0,0,0
23,0,0,23,14,2,27,27,27,27,2,0,0,0,0,0
5,15,14,5,2,2,28,0,0,28,2,2,5,0,0,5
2,15,14,2,7,10,10,0,10,10,10,7,2,0,0,3
2,15,14,2,10,0,0,0,0,0,0,10,2,2,2,2
34,0,0,28,0,0,38,0,0,0,38,14,28,27,25,2
28,0,0,0,0,0,10,0,0,39,0,14,0,27,25,2
28,0,0,0,15,0,23,0,0,40,0,14,0,27,25,2
30,0,0,28,0,0,38,15,0,0,38,14,28,27,25,2
2,15,14,2,15,0,0,0,0,0,0,14,2,2,2,2
2,15,14,2,7,15,0,23,23,0,14,7,2,0,0,3
5,15,14,5,2,2,28,0,0,28,2,2,5,0,0,5
10,0,0,10,10,2,27,27,27,27,2,0,0,0,0,0
0,0,0,37,14,2,25,25,25,25,2,0,0,0,0,0
5,0,0,5,3,2,2,2,2,2,2,3,5,0,0,5
endlayer

layer
5,29,31,5,3,2,2,2,2,2,2,3,5,29,31,5
34,0,0,34,14,2,25,25,25,25,2,0,34,0,0,34
30,0,0,30,14,2,27,27,27,27,2,0,30,0,0,30
5,29,31,5,2,2,28,0,0,28,2,2,5,29,31,5
2,15,14,2,7,42,10,10,10,10,41,7,2,0,0,3
2,29,31,2,43,44,0,0,0,0,44,43,2,2,2,2
2,9,0,28,0,0,0,0,14,0,0,14,28,27,25,2
34,0,0,0,15,0,10,0,0,10,0,14,0,27,25,2
30,0,0,0,15,0,23,0,0,0,0,14,0,27,25,2
2,9,0,28,0,0,0,15,14,0,0,14,28,27,25,2
2,29,31,2,45,44,0,0,0,0,44,45,2,2,2,2
2,15,14,2,7,42,0,23,23,23,41,7,2,0,0,3
5,29,31,5,2,2,28,0,0,28,2,2,5,29,31,5
34,0,0,34,10,2,27,27,27,27,2,0,34,0,0,34
30,0,0,30,14,2,25,25,25,25,2,0,30,0,0,30
5,29,31,5,3,2,2,2,2,2,2,3,5,29,31,5
endlayer

layer
5,2,2,5,3,3,2,2,2,2,3,3,5,2,2,5
2,34,31,2,3,2,25,25,25,25,2,3,2,34,31,2
2,29,30,2,3,2,27,27,27,27,2,3,2,29,30,2
5,2,2,5,2,2,29,0,0,31,2,2,5,2,2,5
2,2,2,2,7,11,10,10,10,10,8,7,2,3,3,3
2,2,2,2,13,38,0,0,0,0,38,13,2,2,2,3
2,34,34,34,0,0,0,15,14,0,0,14,34,27,25,2
2,29,0,9,15,0,10,0,0,10,0,14,0,27,25,2
2,29,9,0,15,0,23,0,0,0,0,14,0,27,25,2
2,30,30,30,0,0,0,15,14,0,0,14,30,27,25,2
2,2,2,2,22,38,0,0,0,0,38,22,2,2,2,3
2,2,2,2,7,11,23,23,23,23,8,7,2,3,3,3
5,2,2,5,2,2,29,0,0,31,2,2,5,2,2,5
2,34,31,2,3,2,27,27,27,27,2,3,2,34,31,2
2,29,30,2,3,2,25,25,25,25,2,3,2,29,30,2
5,2,2,5,3,3,2,2,2,2,3,3,5,2,2,5
endlayer

layer
5,3,3,5,3,3,3,3,3,3,3,3,5,3,3,5
3,3,3,3,3,3,2,2,2,2,3,3,3,3,3,3
3,3,3,3,3,3,2,2,2,2,3,3,3,3,3,3
5,3,3,5,2,2,2,2,2,2,2,2,5,3,3,5
3,3,3,2,1,0,10,10,10,10,0,1,2,3,3,3
3,3,3,2,0,0,0,0,0,0,0,0,2,3,3,3
3,3,3,2,9,0,0,15,14,0,0,14,2,2,2,3
3,2,2,2,15,0,10,0,0,10,0,14,2,2,2,3
3,2,2,2,15,0,23,0,0,0,0,14,2,2,2,3
3,3,3,2,9,0,0,15,14,0,0,14,2,2,2,3
3,3,3,2,0,0,0,0,0,0,0,0,2,3,3,3
3,3,3,2,1,0,23,23,23,23,0,1,2,3,3,3
5,3,3,5,2,2,2,2,2,2,2,2,5,3,3,5
3,3,3,3,3,3,2,2,2,2,3,3,3,3,3,3
3,3,3,3,3,3,2,2,2,2,3,3,3,3,3,3
5,3,3,5,3,3,3,3,3,3,3,3,5,3,3,5
endlayer

layer
1,3,3,1,3,3,3,3,3,3,3,3,1,3,3,1
3,3,3,3,3,3,3,3,3,3,3,3,3,3,3,3
3,3,3,3,3,3,3,3,3,3,3,3,3,3,3,3
1,3,3,1,2,2,2,2,2,2,2,2,1,3,3,1
3,3,3,2,2,2,34,10,10,34,2,2,2,3,3,3
3,3,3,2,2,46,9,0,0,0,46,2,2,3,3,3
3,3,3,2,29,0,0,15,14,0,9,31,2,3,3,3
3,3,3,2,15,0,10,0,0,10,0,14,2,3,3,3
3,3,3,2,15,0,23,0,0,23,0,14,2,3,3,3
3,3,3,2,29,0,0,15,14,0,0,31,2,3,3,3
3,3,3,2,2,46,0,0,0,0,46,2,2,3,3,3
3,3,3,2,2,2,30,23,23,30,2,2,2,3,3,3
1,3,3,1,2,2,2,2,2,2,2,2,1,3,3,1
3,3,3,3,3,3,3,3,3,3,3,3,3,3,3,3
3,3,3,3,3,3,3,3,3,3,3,3,3,3,3,3
1,3,3,1,3,3,3,3,3,3,3,3,1,3,3,1
endlayer

layer
3,3,3,3,3,3,3,3,3,3,3,3,3,3,3,3
3,3,3,3,3,3,3,3,3,3,3,3,3,3,3,3
3,3,3,3,3,3,3,3,3,3,3,3,3,3,3,3
3,3,3,3,3,3,3,3,3,3,3,3,3,3,3,3
3,3,3,3,3,3,2,34,34,2,3,3,3,3,3,3
3,3,3,3,3,2,34,9,9,34,2,3,3,3,3,3
3,3,3,3,2,29,0,15,14,9,31,2,3,3,3,3
3,3,3,3,29,9,10,0,0,10,0,31,3,3,3,3
3,3,3,3,29,0,23,0,0,23,0,31,3,3,3,3
3,3,3,3,2,29,0,15,14,0,31,2,3,3,3,3
3,3,3,3,3,2,30,0,9,30,2,3,3,3,3,3
3,3,3,3,3,3,2,30,30,2,3,3,3,3,3,3
3,3,3,3,3,3,3,3,3,3,3,3,3,3,3,3
3,3,3,3,3,3,3,3,3,3,3,3,3,3,3,3
3,3,3,3,3,3,3,3,3,3,3,3,3,3,3,3
3,3,3,3,3,3,3,3,3,3,3,3,3,3,3,3
endlayer

layer
3,3,3,3,3,3,3,3,3,3,3,3,3,3,3,3
3,3,3,3,3,3,3,3,3,3,3,3,3,3,3,3
3,3,3,3,3,3,3,3,3,3,3,3,3,3,3,3
3,3,3,3,3,3,3,3,3,3,3,3,3,3,3,3
3,3,3,3,3,3,3,3,3,3,3,3,3,3,3,3
3,3,3,3,3,3,2,34,34,2,3,3,3,3,3,3
3,3,3,3,3,2,2,15,14,2,2,3,3,3,3,3
3,3,3,3,3,29,10,0,0,10,31,3,3,3,3,3
3,3,3,3,3,29,23,0,0,23,31,3,3,3,3,3
3,3,3,3,3,2,2,15,14,2,2,3,3,3,3,3
3,3,3,3,3,3,2,30,30,2,3,3,3,3,3,3
3,3,3,3,3,3,3,3,3,3,3,3,3,3,3,3
3,3,3,3,3,3,3,3,3,3,3,3,3,3,3,3
3,3,3,3,3,3,3,3,3,3,3,3,3,3,3,3
3,3,3,3,3,3,3,3,3,3,3,3,3,3,3,3
3,3,3,3,3,3,3,3,3,3,3,3,3,3,3,3
endlayer

layer
3,3,3,3,3,3,3,3,3,3,3,3,3,3,3,3
3,3,3,3,3,3,3,3,3,3,3,3,3,3,3,3
3,3,3,3,3,3,3,3,3,3,3,3,3,3,3,3
3,3,3,3,3,3,3,3,3,3,3,3,3,3,3,3
3,3,3,3,3,3,3,3,3,3,3,3,3,3,3,3
3,3,3,3,3,3,3,3,3,3,3,3,3,3,3,3
3,3,3,3,3,3,2,2,2,2,3,3,3,3,3,3
3,3,3,3,3,3,2,0,0,2,3,3,3,3,3,3
3,3,3,3,3,3,2,0,0,2,3,3,3,3,3,3
3,3,3,3,3,3,2,2,2,2,3,3,3,3,3,3
3,3,3,3,3,3,3,3,3,3,3,3,3,3,3,3
3,3,3,3,3,3,3,3,3,3,3,3,3,3,3,3
3,3,3,3,3,3,3,3,3,3,3,3,3,3,3,3
3,3,3,3,3,3,3,3,3,3,3,3,3,3,3,3
3,3,3,3,3,3,3,3,3,3,3,3,3,3,3,3
3,3,3,3,3,3,3,3,3,3,3,3,3,3,3,3
endlayer

