# Vault Skull Hall
# MC 1.7.10; 12 Nov 2014
# Created by Ruins mod version 14.2 Ingame Parser
# authoring Player: Jordan_Greywolf
# Special Instructions: Place in /templateparser folder.

weight=1
embed_into_distance=0
acceptable_target_blocks=
unacceptable_target_blocks=
dimensions=6,16,8
allowable_overhang=9999
max_leveling=0
leveling_buffer=0
preserve_water=0
preserve_lava=0
preserve_plants=1

# Randomized Stone Brick
rule1=0,100,minecraft:stonebrick,minecraft:stonebrick-1,minecraft:stonebrick-2,minecraft:monster_egg-4

# Mossy Cobblestone Floor
rule2=0,100,minecraft:mossy_cobblestone-0

rule3=0,100,minecraft:web-0

# Randomized Skulls
rule4=0,100,minecraft:skull,minecraft:skull-1,minecraft:skull-2,minecraft:skull-3
rule5=0,100,minecraft:vine-4
rule6=0,100,minecraft:vine-1
rule7=0,100,minecraft:cobblestone_wall,minecraft:cobblestone_wall-1
rule8=0,100,minecraft:stone_brick_stairs-2
rule9=0,100,minecraft:stone_brick_stairs-3
rule10=0,100,minecraft:vine-2

# Dispensers (decorative only)
rule11=0,100,minecraft:dispenser-3
rule12=0,100,minecraft:dispenser-2

rule13=0,100,minecraft:stone_brick_stairs-7
rule14=0,100,minecraft:stone_brick_stairs-6
rule15=0,100,minecraft:vine-8
rule16=0,100,preserveBlock

# Chiseled Stone
rule17=0,100,minecraft:stonebrick-3

layer
1,1,1,2,2,1,1,1
1,1,2,2,2,2,1,1
1,1,2,2,2,2,1,1
1,1,1,2,2,1,1,1
1,1,2,2,2,2,1,1
1,1,2,2,2,2,1,1
1,1,2,2,2,2,1,1
1,1,2,2,2,2,1,1
1,1,2,2,2,2,1,1
1,1,2,2,2,2,1,1
1,1,2,2,2,2,1,1
1,1,2,2,2,2,1,1
1,1,1,2,2,1,1,1
1,1,2,2,2,2,1,1
1,1,2,2,2,2,1,1
1,1,1,2,2,1,1,1
endlayer

layer
1,1,1,0,0,1,1,1
1,1,3,0,0,0,1,1
1,1,3,0,0,3,1,1
1,1,1,0,0,1,1,1
1,1,3,0,3,3,1,1
1,4,6,0,0,5,4,1
1,4,6,0,0,0,4,1
1,1,3,0,0,3,1,1
1,1,3,3,0,3,1,1
1,4,6,0,0,5,4,1
1,4,6,0,0,5,4,1
1,1,3,3,0,3,1,1
1,1,1,0,0,1,1,1
1,1,3,0,0,3,1,1
1,1,0,0,0,0,1,1
1,1,1,0,0,1,1,1
endlayer

layer
1,1,7,0,0,7,1,1
9,4,0,0,0,0,4,8
9,4,0,0,0,0,4,8
1,1,7,0,0,7,1,1
9,4,6,0,0,10,4,8
1,12,6,0,0,5,11,1
1,12,6,0,0,5,11,1
9,4,0,0,0,0,4,8
9,4,6,0,0,0,4,8
1,12,6,0,0,5,11,1
1,12,6,0,0,5,11,1
9,4,3,3,0,0,4,8
1,1,7,0,0,7,1,1
9,4,0,0,0,0,4,8
9,4,0,0,0,0,4,8
1,1,7,0,0,7,1,1
endlayer

layer
1,1,14,0,3,13,1,1
13,14,0,0,0,0,13,14
13,14,0,0,0,0,13,14
1,1,14,0,0,13,1,1
13,14,6,0,0,10,13,14
1,12,6,0,0,5,11,1
1,12,6,0,0,5,11,1
13,14,0,0,0,0,13,14
13,14,6,0,0,0,13,14
1,12,6,0,0,5,11,1
1,12,6,0,0,5,11,1
13,14,15,0,0,15,13,14
1,1,14,3,3,13,1,1
13,14,0,0,0,0,13,14
13,14,0,0,0,0,13,14
1,1,14,0,0,13,1,1
endlayer

layer
1,1,1,14,13,1,1,1
1,1,14,0,3,13,1,1
1,1,14,3,0,13,1,1
1,1,1,14,13,1,1,1
1,1,6,0,0,10,1,1
1,4,6,0,0,5,4,1
1,4,6,0,0,5,4,1
1,1,3,0,0,3,1,1
1,1,6,3,0,3,1,1
1,4,6,0,0,5,4,1
1,4,6,0,0,5,4,1
1,1,15,0,0,15,1,1
1,1,1,14,13,1,1,1
1,1,14,0,3,13,1,1
1,1,14,3,0,13,1,1
1,1,1,14,13,1,1,1
endlayer

layer
16,16,1,1,1,1,16,16
16,16,1,17,17,1,16,16
16,16,1,17,17,1,16,16
16,16,1,1,1,1,16,16
16,16,1,17,17,1,16,16
1,1,1,17,17,1,1,1
1,1,1,1,1,1,1,1
16,1,1,17,17,1,1,16
16,1,1,17,17,1,1,16
1,1,1,1,1,1,1,1
1,1,1,17,17,1,1,1
16,16,1,17,17,1,16,16
16,16,1,1,1,1,16,16
16,16,1,17,17,1,16,16
16,16,1,17,17,1,16,16
16,16,1,1,1,1,16,16
endlayer

