# Vault 4-Way (Tangled Version)
# MC 1.7.10; 12 Nov 2014
# Updated to MC 1.9: 24 Apr 2016
# Updated to MC 1.11: 12 Jan 2017
# Created by Ruins mod version 14.2 Ingame Parser
# authoring Player: Jordan_Greywolf
# Special Instructions: Place in /templateparser folder.

weight=1
embed_into_distance=0
acceptable_target_blocks=
unacceptable_target_blocks=
dimensions=6,16,16
allowable_overhang=9999
max_leveling=0
leveling_buffer=0
preserve_water=0
preserve_lava=0
preserve_plants=1

# Randomized Stone Brick Walls
rule1=0,100,minecraft:stonebrick,minecraft:stonebrick-1,minecraft:stonebrick-2,minecraft:monster_egg-4

# Mossy Cobblestone Floor
rule2=0,100,minecraft:mossy_cobblestone-0

# Randomized Skull
rule3=0,100,minecraft:skull,minecraft:skull-1,minecraft:skull-2,minecraft:skull-3
rule4=0,100,minecraft:web-0
rule5=0,100,minecraft:vine-4
rule6=0,100,minecraft:vine-1
rule7=0,100,minecraft:vine-2

# Destructive Roots!
rule8=0,100,CommandBlock:RUINSTRIGGER /testruin TP_TangleTree2 ~0 _ ~0:@
rule9=0,100,minecraft:stone_brick_stairs-0

rule10=0,100,minecraft:stone_brick_stairs-3
rule11=0,100,minecraft:stone_brick_stairs-2
rule12=0,100,minecraft:stone_brick_stairs-1
rule13=0,100,minecraft:vine-8
rule14=0,100,minecraft:cobblestone_wall,minecraft:cobblestone_wall-1
rule15=0,100,minecraft:stone_brick_stairs-5
rule16=0,100,minecraft:stone_brick_stairs-7
rule17=0,100,minecraft:stone_brick_stairs-6
rule18=0,100,minecraft:stone_brick_stairs-4
rule19=0,100,minecraft:vine-0
rule20=0,100,preserveBlock

# Chiseled Stone
rule21=0,100,minecraft:stonebrick-3

# Casket
rule22=0,100,ChestGenHook:chests/desert_pyramid:2

# Monster Spawner
rule23=0,100,MobSpawner:Spider

layer
1,1,1,1,1,1,1,2,2,1,1,1,1,1,1,1
1,2,2,2,1,1,2,2,2,2,1,1,2,2,2,1
1,2,22,2,1,1,2,2,2,2,1,1,2,22,2,1
1,2,2,2,1,1,1,2,2,1,1,1,2,2,2,1
1,1,1,1,1,1,2,2,2,2,1,1,1,1,1,1
1,1,1,1,1,1,2,2,2,2,1,1,1,1,1,1
1,2,2,1,2,2,2,2,2,2,2,2,1,2,2,1
2,2,2,2,2,2,2,1,1,2,2,2,2,2,2,2
2,2,2,2,2,2,2,1,1,2,2,2,2,2,2,2
1,2,2,1,2,2,2,2,2,2,2,2,1,2,2,1
1,1,1,1,1,1,2,2,2,2,1,1,1,1,1,1
1,1,1,1,1,1,2,2,2,2,1,1,1,1,1,1
1,2,2,2,1,1,1,2,2,1,1,1,2,2,2,1
1,2,22,2,1,1,2,2,2,2,1,1,2,22,2,1
1,2,2,2,1,1,2,2,2,2,1,1,2,2,2,1
1,1,1,1,1,1,1,2,2,1,1,1,1,1,1,1
endlayer

layer
1,1,1,1,1,1,1,0,0,1,1,1,1,1,1,1
1,3,4,3,1,1,4,0,0,3,1,1,3,4,3,1
1,4,23,4,1,1,4,0,0,4,1,1,4,23,4,1
1,3,4,3,1,1,1,0,0,1,1,1,3,4,3,1
1,1,1,1,1,1,4,0,4,4,1,1,1,1,1,1
1,1,1,1,1,1,6,0,0,5,1,1,1,1,1,1
1,6,0,1,7,7,6,0,8,5,7,4,1,0,7,1
0,0,0,4,0,0,0,10,9,0,0,0,0,0,0,4
4,0,0,0,0,0,0,12,11,0,0,0,0,0,0,0
1,0,0,1,3,13,6,0,0,5,13,13,1,4,3,1
1,1,1,1,1,1,6,0,0,5,1,1,1,1,1,1
1,1,1,1,1,1,4,4,0,4,1,1,1,1,1,1
1,3,4,3,1,1,1,0,0,1,1,1,3,0,3,1
1,4,23,4,1,1,4,0,0,4,1,1,0,23,4,1
1,3,4,3,1,1,3,0,0,0,1,1,3,4,3,1
1,1,1,1,1,1,1,0,0,1,1,1,1,1,1,1
endlayer

layer
1,12,12,12,1,1,14,0,0,14,1,1,12,12,12,1
11,4,0,0,10,11,0,0,0,0,10,11,4,0,4,10
11,0,0,0,10,11,0,0,0,0,10,11,0,0,0,10
11,4,0,4,10,1,14,0,0,14,1,11,4,0,4,10
1,9,9,9,1,11,7,0,0,7,10,1,9,9,9,1
1,12,12,1,12,11,6,0,0,5,10,12,1,12,12,1
14,6,0,14,7,7,6,0,0,5,7,7,14,0,7,14
0,0,0,0,0,0,0,14,14,0,0,0,0,0,0,0
0,0,0,0,0,0,0,14,14,0,0,0,0,0,0,0
14,0,0,14,13,13,6,0,0,5,13,13,14,6,0,14
1,9,9,1,9,11,6,0,0,5,10,9,1,9,9,1
1,12,12,12,1,11,4,4,0,0,10,1,12,12,12,1
11,0,0,0,10,1,14,0,0,14,1,11,4,0,4,10
11,0,0,0,10,11,0,0,0,0,10,11,0,0,0,10
11,0,0,0,10,11,0,0,0,0,10,11,4,0,4,10
1,9,9,9,1,1,14,0,0,14,1,1,9,9,9,1
endlayer

layer
1,15,15,15,1,1,17,0,4,16,1,1,15,15,15,1
17,0,0,0,16,17,0,0,0,0,16,17,4,0,0,16
17,0,0,0,16,17,0,0,0,0,16,17,4,0,0,16
17,0,0,4,16,1,17,0,0,16,1,17,4,0,0,16
1,18,18,18,1,17,7,0,0,7,16,1,18,18,18,1
1,15,15,1,15,17,6,0,0,5,16,15,1,15,15,1
15,6,0,15,7,7,6,0,0,5,7,7,15,0,7,15
0,0,0,0,0,0,0,3,3,0,0,0,0,0,0,0
0,0,0,0,0,0,0,3,3,0,0,0,0,0,0,4
18,0,0,18,13,13,6,0,0,5,13,13,18,6,0,18
1,18,18,1,18,17,6,0,0,5,16,18,1,18,18,1
1,15,15,15,1,17,13,0,0,13,16,1,15,15,15,1
17,0,0,0,16,1,17,4,4,16,1,17,4,0,0,16
17,0,0,0,16,17,0,0,0,0,16,17,0,0,0,16
17,0,0,0,16,17,0,0,0,0,16,17,0,4,4,16
1,18,18,18,1,1,17,0,0,16,1,1,18,18,18,1
endlayer

layer
1,1,1,1,1,1,1,17,16,1,1,1,1,1,1,1
1,4,0,4,1,1,17,0,4,16,1,1,4,0,4,1
1,0,0,0,1,1,17,4,0,16,1,1,0,0,0,1
1,4,4,0,1,1,1,17,16,1,1,1,0,0,4,1
1,1,1,1,1,1,7,0,0,7,1,1,1,1,1,1
1,1,1,1,1,1,6,0,0,5,1,1,1,1,1,1
1,6,0,1,7,7,19,0,0,19,7,7,1,0,7,1
15,4,0,15,4,0,0,0,0,4,0,4,15,0,0,15
18,0,0,18,0,0,0,4,0,4,0,0,18,0,0,18
1,4,4,1,13,13,19,0,0,19,13,13,1,6,0,1
1,1,1,1,1,1,6,0,0,5,1,1,1,1,1,1
1,1,1,1,1,1,13,0,0,13,1,1,1,1,1,1
1,4,0,4,1,1,1,17,16,1,1,1,0,0,4,1
1,0,0,0,1,1,17,0,4,16,1,1,0,0,0,1
1,4,0,4,1,1,17,4,0,16,1,1,0,0,4,1
1,1,1,1,1,1,1,17,16,1,1,1,1,1,1,1
endlayer

layer
20,1,1,1,20,20,1,1,1,1,20,20,1,1,1,20
1,1,1,1,1,20,1,21,21,1,20,1,1,1,1,1
1,1,21,1,1,20,1,21,21,1,20,1,1,21,1,1
1,1,1,1,1,20,1,1,1,1,20,1,1,1,1,1
20,1,1,1,20,20,1,21,21,1,20,20,1,1,1,20
20,20,20,20,20,20,1,21,21,1,20,20,20,20,20,20
1,1,1,1,1,1,1,1,1,1,1,1,1,1,1,1
1,21,21,1,21,21,1,21,21,1,21,21,1,21,21,1
1,21,21,1,21,21,1,21,21,1,21,21,1,21,21,1
1,1,1,1,1,1,1,1,1,1,1,1,1,1,1,1
20,20,20,20,20,20,1,21,21,1,20,20,20,20,20,20
20,1,1,1,20,20,1,21,21,1,20,20,1,1,1,20
1,1,1,1,1,20,1,1,1,1,20,1,1,1,1,1
1,1,21,1,1,20,1,21,21,1,20,1,1,21,1,1
1,1,1,1,1,20,1,21,21,1,20,1,1,1,1,1
20,1,1,1,20,20,1,1,1,1,20,20,1,1,1,20
endlayer

