# Village Fancy Church (bandit version)
# 22 Sep 2014 -- Minecraft 1.7.10
# Updated for MC 1.8: 26 Jul 2015
# Created by Ruins mod version 13.8 Ingame Parser
# authoring Player: Jordan_Greywolf
# Note: Place in \templateparser folder
# Last Updated 31 Oct 2015
# Updated to MC 1.8: 20 Mar 2016
# Updated to MC 1.11: 12 Jan 2017
# Updated to MC 1.12: 22 Jun 2017

# biomesToSpawnIn=plains,savanna,savanna plateau,extreme hills,extreme hills edge,forest,lavender fields,sunflower plains

weight=1
embed_into_distance=5

unacceptable_target_blocks=flowing_lava,lava,cloud,Natura:Cloud,red_mushroom_block,brown_mushroom_block,planks,cobblestone,mossy_cobblestone,iron_bars,glass,redstone_torch,torch,stone_slab,double_stone_slab,oak_stairs,spruce_stairs,birch_stairs,dark_oak_stairs,acacia_stairs,jungle_stairs,slime_congealed,slime_dirt,slime_grass,fence,stone_brick,cobblestone_wall,command_block

dimensions=26,7,11
allowable_overhang=0
max_leveling=5
leveling_buffer=-1
preserve_water=0
preserve_lava=0
preserve_plants=1

rule1=0,100,preserveBlock
rule2=0,100,minecraft:cobblestone-0
rule3=0,100,minecraft:web-0
rule4=0,100,minecraft:ladder-4
rule5=0,100,minecraft:spruce_fence-0
rule6=1,100,minecraft:torch-5
rule7=0,100,minecraft:stonebrick-3
rule8=0,100,minecraft:stone_stairs-3
rule9=0,100,minecraft:spruce_stairs-2
rule10=0,100,minecraft:log-0
rule11=0,100,minecraft:spruce_door-1
rule12=0,100,minecraft:trapdoor-2

# Randomized Stained Glass Window
rule13=0,100,minecraft:stained_glass_pane-0,minecraft:stained_glass_pane-1,minecraft:stained_glass_pane-2,minecraft:stained_glass_pane-3,minecraft:stained_glass_pane-4,minecraft:stained_glass_pane-5,minecraft:stained_glass_pane-6,minecraft:stained_glass_pane-7,minecraft:stained_glass_pane-8,minecraft:stained_glass_pane-9,minecraft:stained_glass_pane-10,minecraft:stained_glass_pane-11,minecraft:stained_glass_pane-12,minecraft:stained_glass_pane-13,minecraft:stained_glass_pane-14,minecraft:stained_glass_pane-15

rule14=0,100,minecraft:oak_stairs-1
rule15=0,100,minecraft:spruce_fence_gate-2

# Villager: Priest
rule16=0,100,CommandBlock:RUINSTRIGGER /summon Villager ~0 ~0 ~0 {Profession:2,Career:1,CustomName:"Village Priest"}:@

rule17=0,100,minecraft:spruce_door-8
rule18=0,100,minecraft:oak_stairs-0
rule19=0,100,minecraft:oak_stairs-5
rule20=0,100,minecraft:wooden_slab-8
rule21=0,100,minecraft:oak_stairs-4
rule22=0,100,minecraft:wooden_slab-0
rule23=0,100,minecraft:fence-0
rule24=0,100,minecraft:cobblestone_wall-0
rule25=0,100,minecraft:noteblock-0
rule26=0,100,minecraft:oak_stairs-2
rule27=0,100,minecraft:oak_stairs-3
rule28=0,100,minecraft:oak_stairs-7
rule29=0,100,minecraft:oak_stairs-6
rule30=0,100,minecraft:planks-0

# Highwayman (Bandit Archer)
rule31=0,100,CommandBlock:RUINSTRIGGER /summon Skeleton ~0 ~0 ~0 {HandItems:[{Count:1,id:bow,tag:{display:{Name:"Bandit Bow"},ench:[{id:48,lvl:3},{id:49,lvl:2}]}},{Count:8,id:tipped_arrow,tag:{Potion:"minecraft:strong_harming"}}],ArmorItems:[{Count:1,id:leather_boots},{Count:1,id:leather_leggings},{Count:1,id:leather_chestplate},{Count:1,id:skull,Damage:3,tag:{SkullOwner:MHF_Villager}}],CustomName:Highwayman,HandDropChances:[1.0F,0.0F],ArmorDropChances:[0.5F,0.5F,0.5F,0.0F],Silent:1,PersistenceRequired:1,Health:15.0f}:@


layer
1,1,1,1,1,1,1,1,1,1,1
1,2,2,2,2,2,2,2,2,2,1
1,2,2,2,2,2,2,2,2,2,1
2,2,2,2,2,2,2,2,2,2,1
1,2,2,2,2,2,2,2,2,2,1
1,2,2,2,2,2,2,2,2,2,1
1,1,1,1,1,1,1,1,1,1,1
endlayer

layer
1,1,1,1,1,1,1,1,1,1,1
1,2,2,2,2,2,2,2,2,2,1
1,2,3,3,0,0,0,3,3,2,1
2,2,0,31,0,0,0,0,31,2,1
1,2,3,3,4,0,0,3,3,2,1
1,2,2,2,2,2,2,2,2,2,1
1,1,1,1,1,1,1,1,1,1,1
endlayer

layer
1,1,1,1,1,1,1,1,1,1,1
1,2,2,2,2,2,2,2,2,2,1
1,2,0,0,0,0,0,0,0,2,1
2,2,0,0,0,0,0,0,0,2,1
1,2,0,0,4,0,0,0,0,2,1
1,2,2,2,2,2,2,2,2,2,1
1,1,1,1,1,1,1,1,1,1,1
endlayer

layer
1,1,1,1,1,1,1,1,1,1,1
1,2,2,2,2,2,2,2,2,2,1
1,2,5,0,0,5,0,0,5,2,1
2,2,0,0,0,0,0,0,0,2,1
1,2,5,0,4,5,0,0,5,2,1
1,2,2,2,2,2,2,2,2,2,1
1,1,1,1,1,1,1,1,1,1,1
endlayer

layer
1,1,1,1,1,1,1,1,1,1,1
1,2,2,2,2,2,2,2,2,2,1
1,2,6,0,3,6,3,0,6,2,1
2,2,3,0,0,0,0,0,3,2,1
1,2,6,0,4,6,3,0,6,2,1
1,2,2,2,2,2,2,2,2,2,1
1,1,1,1,1,1,1,1,1,1,1
endlayer

layer
1,1,1,1,1,1,1,1,1,1,1
1,7,2,2,2,2,2,2,2,7,1
0,2,2,2,2,2,2,2,2,2,1
8,2,2,2,2,2,2,2,2,2,1
0,2,2,2,4,2,2,2,2,2,1
1,7,2,2,2,2,2,2,2,7,1
1,1,1,1,1,1,1,1,1,1,1
endlayer

layer
1,0,1,0,0,0,0,0,1,0,1
0,5,2,2,2,2,2,2,2,5,0
0,2,9,9,0,0,8,2,2,2,1
0,11,0,31,0,5,10,2,2,2,1
0,2,9,9,12,0,8,2,2,2,1
0,5,2,2,2,2,2,2,2,5,0
1,0,1,0,0,0,0,0,1,0,1
endlayer

layer
0,0,0,0,0,0,0,0,0,0,0
0,6,2,13,2,13,2,13,2,6,0
0,2,0,0,0,0,15,0,14,2,0
0,17,0,0,0,6,10,0,16,2,0
0,2,0,0,4,0,15,0,18,2,0
0,6,2,13,2,13,2,13,2,6,0
0,0,0,0,0,0,0,0,0,0,0
endlayer

layer
0,0,0,0,0,0,0,0,0,0,0
0,0,2,13,2,13,2,13,2,0,0
0,2,0,0,0,0,0,0,0,2,0
0,2,0,0,0,0,0,0,0,13,0
0,2,0,0,4,0,0,0,0,2,0
0,0,2,13,2,13,2,13,2,0,0
0,0,0,0,0,0,0,0,0,0,0
endlayer

layer
18,18,18,18,18,18,18,18,18,18,18
0,7,2,2,2,2,2,2,2,7,0
0,2,2,2,2,2,0,0,0,2,0
0,2,2,2,2,2,0,0,0,13,0
0,2,2,2,4,2,0,0,0,2,0
0,7,2,2,2,2,2,2,2,7,0
14,14,14,14,14,14,14,14,14,14,14
endlayer

layer
0,0,0,0,0,0,0,0,0,0,0
18,18,2,2,2,18,18,18,18,18,18
20,2,0,0,0,2,19,19,19,2,19
20,2,0,0,0,2,20,20,20,2,20
20,2,0,0,12,2,21,21,21,2,21
14,14,2,2,2,14,14,14,14,14,14
0,0,0,0,0,0,0,0,0,0,0
endlayer

layer
0,0,0,0,0,0,0,0,0,0,0
0,0,2,13,2,0,0,0,0,0,0
22,2,0,0,0,2,22,22,22,22,22
22,13,0,0,0,13,22,22,22,22,22
22,2,0,0,4,2,22,22,22,22,22
0,0,2,13,2,0,0,0,0,0,0
0,0,0,0,0,0,0,0,0,0,0
endlayer

layer
0,0,0,0,0,0,0,0,0,0,0
0,0,2,13,2,0,0,0,0,0,0
0,2,23,0,23,2,0,0,0,0,0
0,13,0,0,0,13,0,0,0,0,0
0,2,23,0,4,2,0,0,0,0,0
0,0,2,13,2,0,0,0,0,0,0
0,0,0,0,0,0,0,0,0,0,0
endlayer

layer
0,0,0,0,0,0,0,0,0,0,0
0,0,2,2,2,0,0,0,0,0,0
0,2,6,0,6,2,0,0,0,0,0
0,2,0,0,0,2,0,0,0,0,0
0,2,6,0,4,2,0,0,0,0,0
0,0,2,2,2,0,0,0,0,0,0
0,0,0,0,0,0,0,0,0,0,0
endlayer

layer
0,0,0,0,0,0,0,0,0,0,0
0,7,2,2,2,7,0,0,0,0,0
0,2,2,2,2,2,0,0,0,0,0
0,2,2,2,2,2,0,0,0,0,0
0,2,2,2,4,2,0,0,0,0,0
0,7,2,2,2,7,0,0,0,0,0
0,0,0,0,0,0,0,0,0,0,0
endlayer

layer
0,0,0,0,0,0,0,0,0,0,0
0,5,2,24,2,5,0,0,0,0,0
0,2,0,0,0,2,0,0,0,0,0
0,24,0,0,0,24,0,0,0,0,0
0,2,0,0,12,2,0,0,0,0,0
0,5,2,24,2,5,0,0,0,0,0
0,0,0,0,0,0,0,0,0,0,0
endlayer

layer
0,0,0,0,0,0,0,0,0,0,0
0,6,2,6,2,6,0,0,0,0,0
0,2,0,0,0,2,0,0,0,0,0
0,6,0,0,0,6,0,0,0,0,0
0,2,0,0,0,2,0,0,0,0,0
0,6,2,6,2,6,0,0,0,0,0
0,0,0,0,0,0,0,0,0,0,0
endlayer

layer
0,0,0,0,0,0,0,0,0,0,0
0,0,2,0,2,0,0,0,0,0,0
0,2,0,0,0,2,0,0,0,0,0
0,0,0,25,0,0,0,0,0,0,0
0,2,0,0,0,2,0,0,0,0,0
0,0,2,0,2,0,0,0,0,0,0
0,0,0,0,0,0,0,0,0,0,0
endlayer

layer
0,27,18,18,18,26,0,0,0,0,0
18,27,2,2,2,18,18,0,0,0,0
27,2,2,0,2,2,26,0,0,0,0
27,2,0,23,0,2,26,0,0,0,0
27,2,2,0,2,2,26,0,0,0,0
14,14,2,2,2,26,14,0,0,0,0
0,27,14,14,14,26,0,0,0,0,0
endlayer

layer
0,0,0,0,0,0,0,0,0,0,0
0,0,27,18,26,0,0,0,0,0,0
0,18,27,19,18,18,0,0,0,0,0
0,27,29,23,28,26,0,0,0,0,0
0,14,14,21,26,14,0,0,0,0,0
0,0,27,14,26,0,0,0,0,0,0
0,0,0,0,0,0,0,0,0,0,0
endlayer

layer
0,0,0,0,0,0,0,0,0,0,0
0,0,0,0,0,0,0,0,0,0,0
0,0,0,18,0,0,0,0,0,0,0
0,0,27,30,26,0,0,0,0,0,0
0,0,0,14,0,0,0,0,0,0,0
0,0,0,0,0,0,0,0,0,0,0
0,0,0,0,0,0,0,0,0,0,0
endlayer

layer
0,0,0,0,0,0,0,0,0,0,0
0,0,0,0,0,0,0,0,0,0,0
0,0,0,0,0,0,0,0,0,0,0
0,0,0,30,0,0,0,0,0,0,0
0,0,0,0,0,0,0,0,0,0,0
0,0,0,0,0,0,0,0,0,0,0
0,0,0,0,0,0,0,0,0,0,0
endlayer

layer
0,0,0,0,0,0,0,0,0,0,0
0,0,0,0,0,0,0,0,0,0,0
0,0,0,0,0,0,0,0,0,0,0
0,0,0,30,0,0,0,0,0,0,0
0,0,0,0,0,0,0,0,0,0,0
0,0,0,0,0,0,0,0,0,0,0
0,0,0,0,0,0,0,0,0,0,0
endlayer

layer
0,0,0,0,0,0,0,0,0,0,0
0,0,0,0,0,0,0,0,0,0,0
0,0,0,0,0,0,0,0,0,0,0
0,0,0,5,0,0,0,0,0,0,0
0,0,0,0,0,0,0,0,0,0,0
0,0,0,0,0,0,0,0,0,0,0
0,0,0,0,0,0,0,0,0,0,0
endlayer

layer
0,0,0,0,0,0,0,0,0,0,0
0,0,0,0,0,0,0,0,0,0,0
0,0,0,5,0,0,0,0,0,0,0
0,0,0,5,0,0,0,0,0,0,0
0,0,0,5,0,0,0,0,0,0,0
0,0,0,0,0,0,0,0,0,0,0
0,0,0,0,0,0,0,0,0,0,0
endlayer

layer
0,0,0,0,0,0,0,0,0,0,0
0,0,0,0,0,0,0,0,0,0,0
0,0,0,0,0,0,0,0,0,0,0
0,0,0,5,0,0,0,0,0,0,0
0,0,0,0,0,0,0,0,0,0,0
0,0,0,0,0,0,0,0,0,0,0
0,0,0,0,0,0,0,0,0,0,0
endlayer


