# Village Windmill (bandit version)
# Originally Created 19 Mar 2014 for MC 1.7.2
# Updated to MC 1.8: 26 Jul 2015
# Created by Ruins mod version 14.9 Ingame Parser
# authoring Player: Jordan_Greywolf
# Note: Place in \templateparser folder.
# Updated to MC 1.9: 24 May 2016
# Updated to MC 1.11: 12 Jan 2017
# Updated to MC 1.12: 22 Jun 2017

weight=1
embed_into_distance=11

unacceptable_target_blocks=flowing_lava,lava,cloud,Natura:Cloud,red_mushroom_block,brown_mushroom_block,planks,cobblestone,mossy_cobblestone,iron_bars,glass,redstone_torch,torch,stone_slab,double_stone_slab,oak_stairs,spruce_stairs,birch_stairs,dark_oak_stairs,acacia_stairs,jungle_stairs,slime_congealed,slime_dirt,slime_grass,fence,stone_brick,cobblestone_wall,command_block

dimensions=26,13,11
allowable_overhang=0
max_leveling=8
leveling_buffer=-1
preserve_water=0
preserve_lava=0
preserve_plants=1

rule1=0,100,preserveBlock
rule2=0,100,minecraft:grass-0
rule3=0,100,minecraft:cobblestone,minecraft:mossy_cobblestone
rule4=0,100,minecraft:double_stone_slab-0
rule5=0,100,minecraft:stone_slab-0
rule6=0,100,minecraft:fence-0
rule7=0,100,minecraft:spruce_stairs-6
rule8=0,100,minecraft:spruce_stairs-3
rule9=0,100,minecraft:spruce_stairs-4
rule10=1,100,minecraft:torch-5
rule11=0,100,minecraft:spruce_stairs-1
rule12=0,100,preserveBlock
rule13=0,100,minecraft:wooden_slab-9
rule14=0,100,minecraft:spruce_stairs-5
rule15=0,100,minecraft:stone_slab-8
rule16=0,100,minecraft:log-0
rule17=0,100,minecraft:mossy_cobblestone,minecraft:cobblestone
rule18=0,100,minecraft:spruce_stairs-2
rule19=0,100,minecraft:planks-1
rule20=0,100,minecraft:spruce_door-1
rule21=0,100,minecraft:spruce_door-8
rule22=0,100,minecraft:log-8
rule23=0,100,minecraft:log-4
rule24=0,100,minecraft:spruce_stairs-0
rule25=0,100,minecraft:stone_stairs-2
rule26=0,100,minecraft:stone_stairs-0
rule27=0,100,minecraft:stone_stairs-3
rule28=0,100,minecraft:stone_stairs-1
rule29=0,100,minecraft:planks-0
rule30=0,100,minecraft:wooden_slab-1

# Highwayman (Bandit Archer)
rule31=0,100,CommandBlock:RUINSTRIGGER /summon Skeleton ~0 ~0 ~0 {HandItems:[{Count:1,id:bow,tag:{display:{Name:"Bandit Bow"},ench:[{id:48,lvl:3},{id:49,lvl:2}]}},{Count:8,id:tipped_arrow,tag:{Potion:"minecraft:strong_harming"}}],ArmorItems:[{Count:1,id:leather_boots},{Count:1,id:leather_leggings},{Count:1,id:leather_chestplate},{Count:1,id:skull,Damage:3,tag:{SkullOwner:MHF_Villager}}],CustomName:Highwayman,HandDropChances:[1.0F,0.0F],ArmorDropChances:[0.5F,0.5F,0.5F,0.0F],Silent:1,PersistenceRequired:1,Health:15.0f}:@


layer
1,1,2,2,2,2,2,2,2,1,1
1,2,2,2,2,2,2,2,2,2,1
2,2,2,2,2,2,2,2,2,2,2
2,2,3,3,3,3,3,3,3,2,2
2,2,3,3,3,3,3,3,3,2,2
2,2,3,3,3,3,3,3,3,2,2
2,2,3,3,3,3,3,3,3,2,2
2,2,3,3,3,3,3,3,3,2,2
2,2,3,3,3,3,3,3,3,2,2
2,2,3,3,3,3,3,3,3,2,2
2,2,2,2,2,2,2,2,2,2,2
1,2,2,2,2,2,2,2,2,2,1
1,1,2,2,2,2,2,2,2,1,1
endlayer


layer
1,1,2,2,2,2,2,2,2,1,1
1,2,2,2,2,2,2,2,2,2,1
2,2,2,2,2,2,2,2,2,2,2
2,2,3,3,3,3,3,3,3,2,2
2,2,3,0,0,0,0,0,3,2,2
2,2,3,0,0,0,0,0,3,2,2
2,2,3,0,0,0,0,0,3,2,2
2,2,3,0,0,0,0,0,3,2,2
2,2,3,0,0,0,0,0,3,2,2
2,2,3,3,3,3,3,3,3,2,2
2,2,2,2,2,2,2,2,2,2,2
1,2,2,2,2,2,2,2,2,2,1
1,1,2,2,2,2,2,2,2,1,1
endlayer


layer
1,1,2,2,2,2,2,2,2,1,1
1,2,2,2,2,2,2,2,2,2,1
2,2,2,2,2,2,2,2,2,2,2
2,2,3,3,3,3,3,3,3,2,2
2,2,3,0,0,0,0,0,3,2,2
2,2,3,0,0,0,0,0,3,2,2
2,2,3,0,0,0,0,0,3,2,2
2,2,3,0,0,0,0,0,3,2,2
2,2,3,0,0,0,0,0,3,2,2
2,2,3,3,3,3,3,3,3,2,2
2,2,2,2,2,2,2,2,2,2,2
1,2,2,2,2,2,2,2,2,2,1
1,1,2,2,2,2,2,2,2,1,1
endlayer


layer
1,1,2,2,2,2,2,2,2,1,1
1,2,2,2,2,2,2,2,2,2,1
2,2,2,2,2,2,2,2,2,2,2
2,2,3,3,3,3,3,3,3,2,2
2,2,3,0,0,0,0,0,3,2,2
2,2,3,0,0,0,0,0,3,2,2
2,2,3,0,0,0,0,0,3,2,2
2,2,3,0,0,0,0,0,3,2,2
2,2,3,0,0,0,0,0,3,2,2
2,2,3,3,3,3,3,3,3,2,2
2,2,2,2,2,2,2,2,2,2,2
1,2,2,2,2,2,2,2,2,2,1
1,1,2,2,2,2,2,2,2,1,1
endlayer


layer
1,1,2,2,2,2,2,2,2,1,1
1,2,2,2,2,2,2,2,2,2,1
2,2,2,2,2,2,2,2,2,2,2
2,2,3,3,3,3,3,3,3,2,2
2,2,3,0,0,0,0,0,3,2,2
2,2,3,0,0,0,0,0,3,2,2
2,2,3,0,0,0,0,0,3,2,2
2,2,3,0,0,0,0,0,3,2,2
2,2,3,0,0,0,0,0,3,2,2
2,2,3,3,3,3,3,3,3,2,2
2,2,2,2,2,2,2,2,2,2,2
1,2,2,2,2,2,2,2,2,2,1
1,1,2,2,2,2,2,2,2,1,1
endlayer


layer
1,1,2,2,2,2,2,2,2,1,1
1,2,2,2,2,2,2,2,2,2,1
2,2,2,2,2,2,2,2,2,2,2
2,2,3,3,3,3,3,3,3,2,2
2,2,3,0,0,0,0,0,3,2,2
2,2,3,0,0,0,0,0,3,2,2
2,2,3,0,0,0,0,0,3,2,2
2,2,3,0,0,0,0,0,3,2,2
2,2,3,0,0,0,0,0,3,2,2
2,2,3,3,3,3,3,3,3,2,2
2,2,2,2,2,2,2,2,2,2,2
1,2,2,2,2,2,2,2,2,2,1
1,1,2,2,2,2,2,2,2,1,1
endlayer


layer
1,1,2,2,2,2,2,2,2,1,1
1,2,2,2,2,2,2,2,2,2,1
2,2,2,2,2,2,2,2,2,2,2
2,2,3,3,3,3,3,3,3,2,2
2,2,3,4,4,4,4,4,3,2,2
2,2,3,4,4,4,4,4,3,2,2
2,2,3,4,4,4,4,4,3,2,2
2,2,3,4,4,4,4,4,3,2,2
2,2,3,4,4,4,4,4,3,2,2
2,2,3,3,3,3,3,3,3,2,2
2,2,2,2,2,2,2,2,2,2,2
1,2,2,2,2,2,2,2,2,2,1
1,1,2,2,2,2,2,2,2,1,1
endlayer

layer
1,1,1,2,2,2,2,2,1,1,1
1,1,2,2,2,2,2,2,2,1,1
1,2,2,2,2,2,2,2,2,2,1
2,2,3,3,3,3,3,3,3,2,2
2,2,3,0,31,31,0,0,3,2,2
2,2,3,0,5,5,5,0,3,2,2
2,2,3,0,5,6,5,0,3,2,2
2,2,3,0,5,5,5,0,3,2,2
2,2,3,0,0,0,8,7,3,2,2
2,2,3,3,3,3,3,3,3,2,2
1,2,2,2,2,2,2,2,2,2,1
1,1,2,2,2,2,2,2,2,1,1
1,1,1,2,2,2,2,2,1,1,1
endlayer

layer
1,1,1,1,2,2,2,1,1,1,1
1,1,1,2,2,2,2,2,1,1,1
1,1,2,2,2,2,2,2,2,1,1
1,2,3,3,3,3,3,3,3,2,1
2,2,3,6,0,0,0,6,3,2,2
2,2,3,0,0,0,0,0,3,2,2
2,2,3,0,0,6,0,0,3,2,2
2,2,3,0,0,0,0,9,3,2,2
2,2,3,6,0,0,0,8,3,2,2
1,2,3,3,3,3,3,3,3,2,1
1,1,2,2,2,2,2,2,2,1,1
1,1,1,2,2,2,2,2,1,1,1
1,1,1,1,2,2,2,1,1,1,1
endlayer

layer
1,1,1,1,1,1,1,1,1,1,1
1,1,1,1,2,2,2,1,1,1,1
1,1,1,2,2,2,2,2,1,1,1
1,1,3,3,3,3,3,3,3,1,1
1,2,3,10,0,0,0,10,3,2,1
2,2,3,0,0,0,0,0,3,2,2
2,2,3,0,0,6,0,9,3,2,2
2,2,3,0,0,0,0,11,3,2,2
1,2,3,10,0,0,0,0,3,2,1
1,1,3,3,3,3,3,3,3,1,1
1,1,1,2,2,2,2,2,1,1,1
1,1,1,1,2,2,2,1,1,1,1
1,1,1,1,1,1,1,1,1,1,1
endlayer

layer
1,1,1,1,1,1,1,1,1,1,1
1,1,1,1,1,1,1,1,1,1,1
1,1,1,1,12,12,12,1,1,1,1
1,1,3,3,3,3,3,3,3,1,1
1,1,3,13,13,14,13,13,3,1,1
1,12,3,13,15,15,15,13,3,1,1
1,12,3,7,15,6,15,11,3,1,1
1,12,3,13,15,15,15,0,3,1,1
1,1,3,13,13,9,0,0,3,1,1
1,1,3,3,3,3,3,3,3,1,1
1,1,1,1,12,12,12,1,1,1,1
1,1,1,1,1,1,1,1,1,1,1
1,1,1,1,1,1,1,1,1,1,1
endlayer

layer
1,1,1,1,1,1,1,1,1,1,1
1,1,1,1,1,1,1,1,1,1,1
1,1,1,1,0,0,0,1,1,1,1
1,1,16,3,3,3,3,17,16,1,1
1,1,3,0,0,0,0,6,3,1,1
1,0,3,0,19,18,0,0,3,0,1
1,0,17,0,0,6,0,0,20,0,1
1,0,3,0,0,0,0,0,3,0,1
1,1,3,6,0,0,0,0,3,1,1
1,1,16,17,3,3,3,3,16,1,1
1,1,1,1,0,0,0,1,1,1,1
1,1,1,1,1,1,1,1,1,1,1
1,1,1,1,1,1,1,1,1,1,1
endlayer

layer
1,1,1,1,1,1,1,1,1,1,1
1,1,1,0,0,0,0,0,1,1,1
1,1,0,0,0,0,0,0,0,1,1
1,0,16,3,3,3,17,3,16,0,1
0,0,17,0,0,0,0,10,3,0,0
0,0,3,0,18,0,0,0,3,0,0
0,0,3,0,14,6,0,0,21,0,0
0,0,3,0,0,0,0,0,3,0,0
0,0,3,10,0,0,0,0,17,0,0
1,0,16,3,3,3,17,3,16,0,1
1,1,0,0,0,0,0,0,0,1,1
1,1,1,0,0,0,0,0,1,1,1
1,1,1,1,1,1,1,1,1,1,1
endlayer

layer
1,1,1,0,0,0,0,0,1,1,1
1,1,0,0,0,0,0,0,0,1,1
1,0,0,0,0,0,0,0,0,0,1
0,0,16,17,3,3,3,3,16,0,0
0,0,3,16,22,22,22,16,3,0,0
0,0,17,23,0,0,0,23,3,0,6
0,0,17,23,24,6,15,23,3,0,6
0,0,3,23,15,15,15,23,3,0,6
0,0,3,16,22,22,22,16,3,0,0
0,0,16,3,3,3,3,17,16,0,0
1,0,0,0,0,0,0,0,0,0,1
1,1,0,0,0,0,0,0,0,1,1
1,1,1,0,0,0,0,0,1,1,1
endlayer

layer
1,1,0,0,0,0,0,0,0,1,1
1,0,0,0,0,0,0,0,0,0,1
0,0,0,0,0,0,0,0,0,0,0
0,0,27,26,26,26,26,26,25,0,0
0,0,27,16,3,3,3,16,25,0,0
0,0,27,3,0,0,6,3,25,0,6
0,0,27,3,0,6,0,3,25,0,6
0,0,27,3,0,0,0,3,25,0,6
0,0,27,16,3,3,3,16,25,0,0
0,0,28,28,28,28,28,28,28,0,0
0,0,0,0,0,0,0,0,0,0,0
1,0,0,0,0,0,0,0,0,0,1
1,1,0,0,0,0,0,0,0,1,1
endlayer

layer
1,0,0,0,0,0,0,0,0,0,1
0,0,0,0,0,0,0,0,0,0,0
0,0,0,0,0,0,0,0,0,0,0
0,0,0,0,0,0,0,0,0,0,0
0,0,0,16,3,6,3,16,0,0,0
0,0,0,17,0,0,10,3,0,0,6
0,0,0,6,0,6,0,6,0,0,6
0,0,0,3,0,0,0,3,0,0,6
0,0,0,16,3,6,3,16,0,0,0
0,0,0,0,0,0,0,0,0,0,0
0,0,0,0,0,0,0,0,0,0,0
0,0,0,0,0,0,0,0,0,0,0
1,0,0,0,0,0,0,0,0,0,1
endlayer

layer
0,0,0,0,0,0,0,0,0,0,0
0,0,0,0,0,0,0,0,0,0,0
0,0,0,0,0,0,0,0,0,0,0
0,0,0,0,0,0,0,0,0,0,0
0,0,0,16,3,17,3,16,0,0,0
0,0,0,3,16,22,16,3,0,0,6
0,0,0,3,23,6,23,3,0,0,6
0,0,0,3,16,22,16,3,0,0,6
0,0,0,16,3,3,3,16,0,0,0
0,0,0,0,0,0,0,0,0,0,0
0,0,0,0,0,0,0,0,0,0,0
0,0,0,0,0,0,0,0,0,0,0
0,0,0,0,0,0,0,0,0,0,0
endlayer

layer
0,0,0,0,0,0,0,0,0,0,0
0,0,0,0,0,0,0,0,0,0,0
0,0,0,0,0,0,0,0,0,0,0
0,0,0,0,0,0,0,0,0,0,0
0,0,0,27,26,26,26,26,0,0,0
0,0,0,27,16,3,16,25,0,0,6
0,0,0,27,3,6,3,25,0,0,6
0,0,0,27,16,3,16,25,0,0,6
0,0,0,28,28,28,28,25,0,0,0
0,0,0,0,0,0,0,0,0,0,0
0,0,0,0,0,0,0,0,0,0,0
0,0,0,0,0,0,0,0,0,0,0
0,0,0,0,0,0,0,0,0,0,0
endlayer

layer
0,0,0,0,0,0,0,0,0,0,0
0,0,0,0,0,0,0,0,0,0,0
0,0,0,0,0,0,0,0,0,0,0
0,0,0,0,0,0,0,0,0,0,0
0,0,0,0,0,0,0,0,0,0,0
0,0,0,0,16,3,16,0,0,0,0
0,0,0,0,3,6,3,0,0,0,6
0,0,0,0,16,3,16,0,0,0,0
0,0,0,0,0,0,0,0,0,0,6
0,0,0,0,0,0,0,0,0,0,6
0,0,0,0,0,0,0,0,0,0,6
0,0,0,0,0,0,0,0,0,0,6
0,0,0,0,0,0,0,0,0,0,6
endlayer

layer
0,0,0,0,0,0,0,0,0,0,6
0,0,0,0,0,0,0,0,0,0,6
0,0,0,0,0,0,0,0,0,0,6
0,0,0,0,0,0,0,0,0,0,6
0,0,0,0,0,0,0,0,0,0,6
0,0,0,0,16,17,16,0,0,0,6
0,0,0,0,3,6,29,29,29,29,29
0,0,0,0,16,3,16,0,0,0,6
0,0,0,0,0,0,0,0,0,0,6
0,0,0,0,0,0,0,0,0,0,6
0,0,0,0,0,0,0,0,0,0,6
0,0,0,0,0,0,0,0,0,0,6
0,0,0,0,0,0,0,0,0,0,6
endlayer

layer
0,0,0,0,0,0,0,0,0,0,6
0,0,0,0,0,0,0,0,0,0,6
0,0,0,0,0,0,0,0,0,0,6
0,0,0,0,0,0,0,0,0,0,6
0,0,0,0,0,0,0,0,0,0,6
0,0,0,0,24,24,18,0,0,0,0
0,0,0,0,8,19,18,0,0,0,6
0,0,0,0,8,11,11,0,0,0,0
0,0,0,0,0,0,0,0,0,0,0
0,0,0,0,0,0,0,0,0,0,0
0,0,0,0,0,0,0,0,0,0,0
0,0,0,0,0,0,0,0,0,0,0
0,0,0,0,0,0,0,0,0,0,0
endlayer

layer
0,0,0,0,0,0,0,0,0,0,0
0,0,0,0,0,0,0,0,0,0,0
0,0,0,0,0,0,0,0,0,0,0
0,0,0,0,0,0,0,0,0,0,0
0,0,0,0,0,0,0,0,0,0,0
0,0,0,0,0,0,0,0,0,0,6
0,0,0,0,0,30,0,0,0,0,6
0,0,0,0,0,0,0,0,0,0,6
0,0,0,0,0,0,0,0,0,0,0
0,0,0,0,0,0,0,0,0,0,0
0,0,0,0,0,0,0,0,0,0,0
0,0,0,0,0,0,0,0,0,0,0
0,0,0,0,0,0,0,0,0,0,0
endlayer

layer
0,0,0,0,0,0,0,0,0,0,0
0,0,0,0,0,0,0,0,0,0,0
0,0,0,0,0,0,0,0,0,0,0
0,0,0,0,0,0,0,0,0,0,0
0,0,0,0,0,0,0,0,0,0,0
0,0,0,0,0,0,0,0,0,0,6
0,0,0,0,0,0,0,0,0,0,6
0,0,0,0,0,0,0,0,0,0,6
0,0,0,0,0,0,0,0,0,0,0
0,0,0,0,0,0,0,0,0,0,0
0,0,0,0,0,0,0,0,0,0,0
0,0,0,0,0,0,0,0,0,0,0
0,0,0,0,0,0,0,0,0,0,0
endlayer

layer
0,0,0,0,0,0,0,0,0,0,0
0,0,0,0,0,0,0,0,0,0,0
0,0,0,0,0,0,0,0,0,0,0
0,0,0,0,0,0,0,0,0,0,0
0,0,0,0,0,0,0,0,0,0,0
0,0,0,0,0,0,0,0,0,0,6
0,0,0,0,0,0,0,0,0,0,6
0,0,0,0,0,0,0,0,0,0,6
0,0,0,0,0,0,0,0,0,0,0
0,0,0,0,0,0,0,0,0,0,0
0,0,0,0,0,0,0,0,0,0,0
0,0,0,0,0,0,0,0,0,0,0
0,0,0,0,0,0,0,0,0,0,0
endlayer

layer
0,0,0,0,0,0,0,0,0,0,0
0,0,0,0,0,0,0,0,0,0,0
0,0,0,0,0,0,0,0,0,0,0
0,0,0,0,0,0,0,0,0,0,0
0,0,0,0,0,0,0,0,0,0,0
0,0,0,0,0,0,0,0,0,0,6
0,0,0,0,0,0,0,0,0,0,6
0,0,0,0,0,0,0,0,0,0,6
0,0,0,0,0,0,0,0,0,0,0
0,0,0,0,0,0,0,0,0,0,0
0,0,0,0,0,0,0,0,0,0,0
0,0,0,0,0,0,0,0,0,0,0
0,0,0,0,0,0,0,0,0,0,0
endlayer

layer
0,0,0,0,0,0,0,0,0,0,0
0,0,0,0,0,0,0,0,0,0,0
0,0,0,0,0,0,0,0,0,0,0
0,0,0,0,0,0,0,0,0,0,0
0,0,0,0,0,0,0,0,0,0,0
0,0,0,0,0,0,0,0,0,0,6
0,0,0,0,0,0,0,0,0,0,6
0,0,0,0,0,0,0,0,0,0,6
0,0,0,0,0,0,0,0,0,0,0
0,0,0,0,0,0,0,0,0,0,0
0,0,0,0,0,0,0,0,0,0,0
0,0,0,0,0,0,0,0,0,0,0
0,0,0,0,0,0,0,0,0,0,0
endlayer

