# VaultStatues -- Underground "Dungeon" Chamber
# 1 Oct 2014 - Minecraft 1.7.10
# Created by Ruins mod version 13.8 Ingame Parser
# authoring Player: Jordan_Greywolf
# Inspired by "Knight Statue" structures in Twilight Forest
# Last Updated: 27 Apr 2015
# Place in \templateparser folder.  Meant to be called.

biomesToSpawnIn=extreme hills

weight=1
embed_into_distance=20
acceptable_target_blocks=

unacceptable_target_blocks=flowing_water,cloud,Natura:Cloud

dimensions=11,16,16
allowable_overhang=400
max_leveling=0
leveling_buffer=0
preserve_water=0
preserve_lava=0
preserve_plants=1

rule1=0,100,preserveBlock

# Stone Brick (weathered)
rule2=0,100,minecraft:stonebrick-0,minecraft:stonebrick-1,minecraft:stonebrick-2

# Mossy Cobblestone Floor
rule3=0,100,minecraft:mossy_cobblestone-0

# Chiseled Stone Keystones
rule4=0,100,minecraft:stonebrick-3

rule5=0,100,minecraft:stone_brick_stairs-3
rule6=0,100,minecraft:stone_brick_stairs-1
rule7=0,100,minecraft:stone_brick_stairs-2
rule8=0,100,minecraft:stone_brick_stairs-0
rule9=0,100,minecraft:cobblestone_wall-0
rule10=0,100,minecraft:double_stone_slab-0
rule11=0,100,minecraft:cobblestone-0
rule12=0,100,minecraft:stone_stairs-3
rule13=0,100,minecraft:stone_stairs-2
rule14=0,100,minecraft:stone_stairs-1
rule15=0,100,minecraft:stone_stairs-0

# Upright Redstone Torch
rule16=1,100,minecraft:redstone_torch-5

rule17=0,100,minecraft:stone_brick_stairs-7
rule18=0,100,minecraft:stone_brick_stairs-6
rule19=0,100,minecraft:stone_brick_stairs-5
rule20=0,100,minecraft:stone_brick_stairs-4
rule21=0,100,minecraft:stone_stairs-7
rule22=0,100,minecraft:stone_stairs-6
rule23=0,100,minecraft:stone_stairs-5
rule24=0,100,minecraft:stone_slab-11
rule25=0,100,minecraft:stone_stairs-4
rule26=0,100,minecraft:stone_slab-13

layer
1,1,1,1,1,2,2,3,3,2,2,1,1,1,1,1
1,1,1,1,1,2,3,3,3,3,2,1,1,1,1,1
1,1,1,1,1,2,3,3,3,3,2,1,1,1,1,1
1,1,1,4,2,2,2,3,3,2,2,2,4,1,1,1
1,1,1,2,3,3,3,3,3,3,3,3,2,1,1,1
2,2,2,2,3,3,3,3,3,3,3,3,2,2,2,2
2,3,3,2,3,3,6,6,6,5,3,3,2,3,3,2
3,3,3,3,3,3,7,0,0,5,3,3,3,3,3,3
3,3,3,3,3,3,7,0,0,5,3,3,3,3,3,3
2,3,3,2,3,3,7,8,8,8,3,3,2,3,3,2
2,2,2,2,3,3,3,3,3,3,3,3,2,2,2,2
1,1,1,2,3,3,3,3,3,3,3,3,2,1,1,1
1,1,1,4,2,2,2,3,3,2,2,2,4,1,1,1
1,1,1,1,1,2,3,3,3,3,2,1,1,1,1,1
1,1,1,1,1,2,3,3,3,3,2,1,1,1,1,1
1,1,1,1,1,2,2,3,3,2,2,1,1,1,1,1
endlayer

layer
1,1,1,1,1,2,2,0,0,2,2,1,1,1,1,1
1,1,1,1,1,2,9,0,0,9,2,1,1,1,1,1
1,1,1,1,1,2,0,0,0,0,2,1,1,1,1,1
1,1,1,10,2,2,2,0,0,2,2,2,10,1,1,1
1,1,1,2,11,13,0,0,0,0,12,11,2,1,1,1
2,2,2,2,14,0,0,0,0,0,0,14,2,2,2,2
2,9,0,2,0,0,0,0,0,0,0,0,2,0,9,2
0,0,0,0,0,0,0,0,0,0,0,0,0,0,0,0
0,0,0,0,0,0,0,0,0,0,0,0,0,0,0,0
2,9,0,2,0,0,0,0,0,0,0,0,2,0,9,2
2,2,2,2,15,0,0,0,0,0,0,15,2,2,2,2
1,1,1,2,11,13,0,0,0,0,12,11,2,1,1,1
1,1,1,10,2,2,2,0,0,2,2,2,10,1,1,1
1,1,1,1,1,2,0,0,0,0,2,1,1,1,1,1
1,1,1,1,1,2,9,0,0,9,2,1,1,1,1,1
1,1,1,1,1,2,2,0,0,2,2,1,1,1,1,1
endlayer

layer
1,1,1,1,1,2,9,0,0,9,2,1,1,1,1,1
1,1,1,1,1,7,16,0,0,16,5,1,1,1,1,1
1,1,1,1,1,7,0,0,0,0,5,1,1,1,1,1
1,1,1,10,2,2,9,0,0,9,2,2,10,1,1,1
1,1,1,2,11,0,0,0,0,0,0,11,2,1,1,1
2,6,6,2,0,0,0,0,0,0,0,0,2,6,6,2
9,16,0,9,0,0,0,0,0,0,0,0,9,0,16,9
0,0,0,0,0,0,0,0,0,0,0,0,0,0,0,0
0,0,0,0,0,0,0,0,0,0,0,0,0,0,0,0
9,16,0,9,0,0,0,0,0,0,0,0,9,0,16,9
2,8,8,2,0,0,0,0,0,0,0,0,2,8,8,2
1,1,1,2,11,0,0,0,0,0,0,11,2,1,1,1
1,1,1,10,2,2,9,0,0,9,2,2,10,1,1,1
1,1,1,1,1,7,0,0,0,0,5,1,1,1,1,1
1,1,1,1,1,7,16,0,0,16,5,1,1,1,1,1
1,1,1,1,1,2,9,0,0,9,2,1,1,1,1,1
endlayer

layer
1,1,1,1,1,2,18,0,0,17,2,1,1,1,1,1
1,1,1,1,1,18,0,0,0,0,17,1,1,1,1,1
1,1,1,1,1,18,0,0,0,0,17,1,1,1,1,1
1,1,1,10,2,2,9,0,0,9,2,2,10,1,1,1
1,1,1,2,11,0,0,0,0,0,0,11,2,1,1,1
2,19,19,2,0,0,0,0,0,0,0,0,2,19,19,2
19,0,0,9,0,0,0,0,0,0,0,0,9,0,0,19
0,0,0,0,0,0,0,0,0,0,0,0,0,0,0,0
0,0,0,0,0,0,0,0,0,0,0,0,0,0,0,0
20,0,0,9,0,0,0,0,0,0,0,0,9,0,0,20
2,20,20,2,0,0,0,0,0,0,0,0,2,20,20,2
1,1,1,2,11,0,0,0,0,0,0,11,2,1,1,1
1,1,1,10,2,2,9,0,0,9,2,2,10,1,1,1
1,1,1,1,1,18,0,0,0,0,17,1,1,1,1,1
1,1,1,1,1,18,0,0,0,0,17,1,1,1,1,1
1,1,1,1,1,2,18,0,0,17,2,1,1,1,1,1
endlayer

layer
1,1,1,1,1,2,2,18,17,2,2,1,1,1,1,1
1,1,1,1,1,2,0,0,0,0,2,1,1,1,1,1
1,1,1,1,1,2,0,0,0,0,2,1,1,1,1,1
1,1,1,10,2,2,9,0,0,9,2,2,10,1,1,1
1,1,1,2,11,22,0,0,0,0,21,11,2,1,1,1
2,2,2,2,23,24,0,0,0,0,24,23,2,2,2,2
2,0,0,9,0,0,0,0,0,0,0,0,9,0,0,2
19,0,0,0,0,0,0,0,0,0,0,0,0,0,0,19
20,0,0,0,0,0,0,0,0,0,0,0,0,0,0,20
2,0,0,9,0,0,0,0,0,0,0,0,9,0,0,2
2,2,2,2,25,24,0,0,0,0,24,25,2,2,2,2
1,1,1,2,11,22,0,0,0,0,21,11,2,1,1,1
1,1,1,10,2,2,9,0,0,9,2,2,10,1,1,1
1,1,1,1,1,2,0,0,0,0,2,1,1,1,1,1
1,1,1,1,1,2,0,0,0,0,2,1,1,1,1,1
1,1,1,1,1,2,2,18,17,2,2,1,1,1,1,1
endlayer

layer
1,1,1,1,1,1,2,2,2,2,1,1,1,1,1,1
1,1,1,1,1,1,18,19,19,17,1,1,1,1,1,1
1,1,1,1,1,1,18,0,0,17,1,1,1,1,1,1
1,1,1,10,2,2,18,0,0,17,2,2,10,1,1,1
1,1,1,2,11,13,0,0,0,0,12,11,2,1,1,1
1,1,1,2,14,16,0,0,0,0,16,14,2,1,1,1
2,19,19,19,0,0,0,0,0,0,0,0,19,19,19,2
2,18,0,0,0,0,0,0,0,0,0,0,0,0,17,2
2,18,0,0,0,0,0,0,0,0,0,0,0,0,17,2
2,20,20,20,0,0,0,0,0,0,0,0,20,20,20,2
1,1,1,2,15,16,0,0,0,0,16,15,2,1,1,1
1,1,1,2,11,13,0,0,0,0,12,11,2,1,1,1
1,1,1,10,2,2,18,0,0,17,2,2,10,1,1,1
1,1,1,1,1,1,18,0,0,17,1,1,1,1,1,1
1,1,1,1,1,1,18,20,20,17,1,1,1,1,1,1
1,1,1,1,1,1,2,2,2,2,1,1,1,1,1,1
endlayer

layer
1,1,1,1,1,1,1,1,1,1,1,1,1,1,1,1
1,1,1,1,1,1,1,2,2,1,1,1,1,1,1,1
1,1,1,1,1,1,1,2,2,1,1,1,1,1,1,1
1,1,1,10,2,2,2,2,2,2,2,2,10,1,1,1
1,1,1,2,4,0,0,0,0,0,0,4,2,1,1,1
1,1,1,2,0,0,0,0,0,0,0,0,2,1,1,1
1,1,1,2,0,0,0,0,0,0,0,0,2,1,1,1
1,2,2,2,0,0,0,0,0,0,0,0,2,2,2,1
1,2,2,2,0,0,0,0,0,0,0,0,2,2,2,1
1,1,1,2,0,0,0,0,0,0,0,0,2,1,1,1
1,1,1,2,0,0,0,0,0,0,0,0,2,1,1,1
1,1,1,2,4,0,0,0,0,0,0,4,2,1,1,1
1,1,1,10,2,2,2,2,2,2,2,2,10,1,1,1
1,1,1,1,1,1,1,2,2,1,1,1,1,1,1,1
1,1,1,1,1,1,1,2,2,1,1,1,1,1,1,1
1,1,1,1,1,1,1,1,1,1,1,1,1,1,1,1
endlayer

layer
1,1,1,1,1,1,1,1,1,1,1,1,1,1,1,1
1,1,1,1,1,1,1,1,1,1,1,1,1,1,1,1
1,1,1,1,1,1,1,1,1,1,1,1,1,1,1,1
1,1,1,4,2,2,2,2,2,2,2,2,4,1,1,1
1,1,1,2,2,2,19,0,0,19,2,2,2,1,1,1
1,1,1,2,2,26,0,0,0,0,26,2,2,1,1,1
1,1,1,2,18,0,0,0,0,0,0,17,2,1,1,1
1,1,1,2,0,0,0,0,0,0,0,0,2,1,1,1
1,1,1,2,0,0,0,0,0,0,0,0,2,1,1,1
1,1,1,2,18,0,0,0,0,0,0,17,2,1,1,1
1,1,1,2,2,26,0,0,0,0,26,2,2,1,1,1
1,1,1,2,2,2,20,0,0,20,2,2,2,1,1,1
1,1,1,4,2,2,2,2,2,2,2,2,4,1,1,1
1,1,1,1,1,1,1,1,1,1,1,1,1,1,1,1
1,1,1,1,1,1,1,1,1,1,1,1,1,1,1,1
1,1,1,1,1,1,1,1,1,1,1,1,1,1,1,1
endlayer

layer
1,1,1,1,1,1,1,1,1,1,1,1,1,1,1,1
1,1,1,1,1,1,1,1,1,1,1,1,1,1,1,1
1,1,1,1,1,1,1,1,1,1,1,1,1,1,1,1
1,1,1,1,1,1,1,1,1,1,1,1,1,1,1,1
1,1,1,1,1,1,2,19,19,2,1,1,1,1,1,1
1,1,1,1,1,2,19,0,0,19,2,1,1,1,1,1
1,1,1,1,2,18,0,0,0,0,17,2,1,1,1,1
1,1,1,1,18,0,0,0,0,0,0,17,1,1,1,1
1,1,1,1,18,0,0,0,0,0,0,17,1,1,1,1
1,1,1,1,2,18,0,0,0,0,17,2,1,1,1,1
1,1,1,1,1,2,20,0,0,20,2,1,1,1,1,1
1,1,1,1,1,1,2,20,20,2,1,1,1,1,1,1
1,1,1,1,1,1,1,1,1,1,1,1,1,1,1,1
1,1,1,1,1,1,1,1,1,1,1,1,1,1,1,1
1,1,1,1,1,1,1,1,1,1,1,1,1,1,1,1
1,1,1,1,1,1,1,1,1,1,1,1,1,1,1,1
endlayer

layer
1,1,1,1,1,1,1,1,1,1,1,1,1,1,1,1
1,1,1,1,1,1,1,1,1,1,1,1,1,1,1,1
1,1,1,1,1,1,1,1,1,1,1,1,1,1,1,1
1,1,1,1,1,1,1,1,1,1,1,1,1,1,1,1
1,1,1,1,1,1,1,1,1,1,1,1,1,1,1,1
1,1,1,1,1,1,2,19,19,2,1,1,1,1,1,1
1,1,1,1,1,2,2,0,0,2,2,1,1,1,1,1
1,1,1,1,1,18,0,0,0,0,17,1,1,1,1,1
1,1,1,1,1,18,0,0,0,0,17,1,1,1,1,1
1,1,1,1,1,2,2,0,0,2,2,1,1,1,1,1
1,1,1,1,1,1,2,20,20,2,1,1,1,1,1,1
1,1,1,1,1,1,1,1,1,1,1,1,1,1,1,1
1,1,1,1,1,1,1,1,1,1,1,1,1,1,1,1
1,1,1,1,1,1,1,1,1,1,1,1,1,1,1,1
1,1,1,1,1,1,1,1,1,1,1,1,1,1,1,1
1,1,1,1,1,1,1,1,1,1,1,1,1,1,1,1
endlayer

layer
1,1,1,1,1,1,1,1,1,1,1,1,1,1,1,1
1,1,1,1,1,1,1,1,1,1,1,1,1,1,1,1
1,1,1,1,1,1,1,1,1,1,1,1,1,1,1,1
1,1,1,1,1,1,1,1,1,1,1,1,1,1,1,1
1,1,1,1,1,1,1,1,1,1,1,1,1,1,1,1
1,1,1,1,1,1,1,1,1,1,1,1,1,1,1,1
1,1,1,1,1,1,2,2,2,2,1,1,1,1,1,1
1,1,1,1,1,1,2,4,4,2,1,1,1,1,1,1
1,1,1,1,1,1,2,4,4,2,1,1,1,1,1,1
1,1,1,1,1,1,2,2,2,2,1,1,1,1,1,1
1,1,1,1,1,1,1,1,1,1,1,1,1,1,1,1
1,1,1,1,1,1,1,1,1,1,1,1,1,1,1,1
1,1,1,1,1,1,1,1,1,1,1,1,1,1,1,1
1,1,1,1,1,1,1,1,1,1,1,1,1,1,1,1
1,1,1,1,1,1,1,1,1,1,1,1,1,1,1,1
1,1,1,1,1,1,1,1,1,1,1,1,1,1,1,1
endlayer

