# Vault Intersection
# MC 1.7.10; 12 Nov 2014
# Created by Ruins mod version 14.2 Ingame Parser
# authoring Player: Jordan_Greywolf
# Statues inspired by "Goblin Stronghold" in Twilight Forest
# Special Instructions: Place in /templateparser folder

weight=1
embed_into_distance=0
acceptable_target_blocks=
unacceptable_target_blocks=
dimensions=11,16,16
allowable_overhang=9999
max_leveling=0
leveling_buffer=0
preserve_water=0
preserve_lava=0
preserve_plants=1

rule1=0,100,preserveBlock

# Randomized Stone Brick
rule2=0,100,minecraft:stonebrick,minecraft:stonebrick-1,minecraft:stonebrick-2,minecraft:monster_egg-4
rule3=0,100,minecraft:stonebrick,minecraft:stonebrick-1,minecraft:stonebrick-2

# Mossy Cobblestone Floor
rule4=0,100,minecraft:mossy_cobblestone-0

# Chiseled Stone
rule5=0,100,minecraft:stonebrick-3

# Monster Eggs!
rule6=0,100,minecraft:monster_egg-4

rule7=0,100,minecraft:stone_brick_stairs-3
rule8=0,100,minecraft:stone_brick_stairs-1

# Randomized Bone Pit
rule9=0,100,minecraft:skull,minecraft:skull-1,minecraft:skull-2,minecraft:skull-3

rule10=0,100,minecraft:stone_brick_stairs-2
rule11=0,100,minecraft:stone_brick_stairs-0
rule12=0,100,minecraft:cobblestone_wall,minecraft:cobblestone_wall-1
rule13=0,100,minecraft:web-0
rule14=0,100,minecraft:double_stone_slab-0
rule15=0,100,minecraft:vine-1
rule16=0,100,minecraft:cobblestone-0
rule17=0,100,minecraft:stone_stairs-3
rule18=0,100,minecraft:stone_stairs-2
rule19=0,100,minecraft:stone_stairs-1
rule20=0,100,minecraft:vine-8
rule21=0,100,minecraft:stone_stairs-0
rule22=1,100,minecraft:redstone_torch-5
rule23=0,100,minecraft:vine-2
rule24=0,100,minecraft:vine-12
rule25=0,100,minecraft:stone_brick_stairs-7
rule26=0,100,minecraft:stone_brick_stairs-6
rule27=0,100,minecraft:stone_brick_stairs-5
rule28=0,100,minecraft:stone_brick_stairs-4
rule29=0,100,minecraft:vine-4
rule30=0,100,minecraft:vine-3
rule31=0,100,minecraft:stone_stairs-7
rule32=0,100,minecraft:stone_stairs-6
rule33=0,100,minecraft:stone_stairs-5
rule34=0,100,minecraft:stone_slab-11
rule35=0,100,minecraft:stone_stairs-4
rule36=0,100,minecraft:stone_slab-13



layer
1,1,1,1,1,2,3,4,4,3,2,1,1,1,1,1
1,1,1,1,1,3,4,4,4,4,3,1,1,1,1,1
1,1,1,1,1,3,4,4,4,4,2,1,1,1,1,1
1,1,1,5,2,3,6,4,4,6,3,3,5,1,1,1
1,1,1,6,4,4,4,4,4,4,4,4,2,1,1,1
3,6,3,3,4,4,4,4,4,4,4,4,3,3,6,3
6,4,4,2,4,4,8,8,8,7,4,4,3,4,4,3
4,4,4,4,4,4,10,9,9,7,4,4,4,4,4,4
4,4,4,4,4,4,10,9,9,7,4,4,4,4,4,4
6,4,4,3,4,4,10,11,11,11,4,4,6,4,4,3
6,3,2,6,4,4,4,4,4,4,4,4,3,3,6,2
1,1,1,2,4,4,4,4,4,4,4,4,2,1,1,1
1,1,1,5,3,3,3,4,4,6,6,6,5,1,1,1
1,1,1,1,1,6,4,4,4,4,2,1,1,1,1,1
1,1,1,1,1,3,4,4,4,4,6,1,1,1,1,1
1,1,1,1,1,2,2,4,4,3,3,1,1,1,1,1
endlayer

layer
1,1,1,1,1,3,2,0,0,6,3,1,1,1,1,1
1,1,1,1,1,2,12,0,0,12,6,1,1,1,1,1
1,1,1,1,1,3,13,0,0,0,2,1,1,1,1,1
1,1,1,14,3,2,3,15,0,2,6,2,14,1,1,1
1,1,1,3,16,18,0,0,0,13,17,16,6,1,1,1
3,6,2,3,19,0,0,0,0,0,0,19,2,2,6,6
6,12,0,6,0,0,0,0,0,0,0,13,2,0,12,2
0,0,0,0,0,0,0,0,0,0,0,0,0,0,0,0
20,0,0,0,0,0,0,0,0,0,0,0,0,0,0,0
6,12,0,3,0,0,0,0,0,0,0,0,6,0,12,3
2,6,3,2,21,13,0,0,0,0,0,21,2,2,3,2
1,1,1,2,16,18,0,0,0,0,17,16,3,1,1,1
1,1,1,14,2,2,2,13,0,3,2,2,14,1,1,1
1,1,1,1,1,3,0,0,0,0,6,1,1,1,1,1
1,1,1,1,1,3,12,0,0,12,6,1,1,1,1,1
1,1,1,1,1,6,2,0,0,3,6,1,1,1,1,1
endlayer

layer
1,1,1,1,1,3,12,0,0,12,6,1,1,1,1,1
1,1,1,1,1,10,22,0,0,22,7,1,1,1,1,1
1,1,1,1,1,10,0,0,0,0,7,1,1,1,1,1
1,1,1,14,2,2,12,0,0,12,3,3,14,1,1,1
1,1,1,3,16,0,0,0,0,0,0,16,6,1,1,1
6,8,8,2,0,0,0,0,0,0,0,0,2,8,8,6
12,22,0,12,0,0,0,0,0,0,0,0,12,23,22,12
0,0,0,0,0,0,0,0,0,0,0,0,0,0,0,0
0,0,0,0,0,0,0,0,0,0,0,0,0,0,0,0
12,22,0,12,0,0,0,0,0,0,0,0,12,0,22,12
6,11,11,2,15,0,0,0,0,0,0,24,3,11,11,6
1,1,1,3,16,0,0,0,0,0,0,16,3,1,1,1
1,1,1,14,6,3,12,0,0,12,3,2,14,1,1,1
1,1,1,1,1,10,13,0,0,0,7,1,1,1,1,1
1,1,1,1,1,10,22,0,0,22,7,1,1,1,1,1
1,1,1,1,1,2,12,0,0,12,3,1,1,1,1,1
endlayer

layer
1,1,1,1,1,6,26,0,13,25,6,1,1,1,1,1
1,1,1,1,1,26,0,0,0,0,25,1,1,1,1,1
1,1,1,1,1,26,0,0,0,0,25,1,1,1,1,1
1,1,1,14,3,2,12,0,0,12,2,6,14,1,1,1
1,1,1,3,16,0,0,0,0,0,0,16,6,1,1,1
2,27,27,3,0,0,0,0,0,0,0,0,2,27,27,3
27,0,0,12,0,0,0,0,0,0,0,0,12,23,0,27
0,0,0,0,0,0,0,0,0,0,0,0,0,0,0,0
0,0,0,0,0,0,0,0,0,0,0,0,0,0,0,0
28,0,0,12,0,0,0,0,0,0,0,0,12,20,0,28
2,28,28,2,15,0,0,0,0,0,0,29,6,28,28,3
1,1,1,6,16,0,0,0,20,0,0,16,2,1,1,1
1,1,1,14,2,6,12,0,0,12,3,2,14,1,1,1
1,1,1,1,1,26,0,0,0,0,25,1,1,1,1,1
1,1,1,1,1,26,0,0,0,0,25,1,1,1,1,1
1,1,1,1,1,3,26,0,0,25,3,1,1,1,1,1
endlayer

layer
1,1,1,1,1,2,2,26,25,3,3,1,1,1,1,1
1,1,1,1,1,2,30,0,0,13,2,1,1,1,1,1
1,1,1,1,1,3,13,0,0,0,3,1,1,1,1,1
1,1,1,14,3,3,12,0,0,12,6,3,14,1,1,1
1,1,1,2,16,32,0,0,0,0,31,16,2,1,1,1
6,6,2,6,33,34,0,0,0,0,34,33,6,6,6,3
6,13,0,12,0,0,0,0,0,0,0,0,12,23,13,3
27,0,0,0,0,0,0,0,0,0,0,0,0,0,0,27
28,0,0,0,0,0,0,0,0,0,0,0,0,0,0,28
6,13,0,12,0,0,0,0,0,0,0,0,12,20,20,3
2,3,2,3,35,34,0,0,0,0,34,35,2,3,6,3
1,1,1,2,16,32,0,20,20,0,31,16,2,1,1,1
1,1,1,14,6,6,12,0,0,12,3,6,14,1,1,1
1,1,1,1,1,6,0,0,0,0,3,1,1,1,1,1
1,1,1,1,1,3,13,0,0,13,6,1,1,1,1,1
1,1,1,1,1,3,2,26,25,2,6,1,1,1,1,1
endlayer

layer
1,1,1,1,1,1,2,2,2,6,1,1,1,1,1,1
1,1,1,1,1,1,26,27,27,25,1,1,1,1,1,1
1,1,1,1,1,1,26,0,0,25,1,1,1,1,1,1
1,1,1,14,2,3,26,13,0,25,2,2,14,1,1,1
1,1,1,3,16,18,0,0,0,0,17,16,6,1,1,1
1,1,1,3,19,22,0,0,0,0,22,19,6,1,1,1
3,27,27,27,0,0,0,0,0,0,0,0,27,27,27,6
3,26,0,13,0,0,0,0,0,0,0,0,0,0,25,6
3,26,13,0,15,0,0,0,0,0,0,29,0,13,25,2
3,28,28,28,0,0,0,0,0,0,0,0,28,28,28,3
1,1,1,2,21,22,0,0,0,0,22,21,2,1,1,1
1,1,1,6,16,18,0,20,20,0,17,16,6,1,1,1
1,1,1,14,3,3,26,0,13,25,6,2,14,1,1,1
1,1,1,1,1,1,26,0,0,25,1,1,1,1,1,1
1,1,1,1,1,1,26,28,28,25,1,1,1,1,1,1
1,1,1,1,1,1,6,6,3,3,1,1,1,1,1,1
endlayer

layer
1,1,1,1,1,1,1,1,1,1,1,1,1,1,1,1
1,1,1,1,1,1,1,2,2,1,1,1,1,1,1,1
1,1,1,1,1,1,1,6,3,1,1,1,1,1,1,1
1,1,1,14,3,6,2,2,6,6,6,3,14,1,1,1
1,1,1,3,5,0,23,23,23,23,0,5,2,1,1,1
1,1,1,2,0,0,0,0,0,0,0,0,6,1,1,1
1,1,1,2,13,0,0,0,0,0,0,0,6,1,1,1
1,3,2,2,15,0,0,0,0,23,0,29,3,3,6,1
1,6,3,6,15,0,0,0,0,0,0,29,2,3,3,1
1,1,1,2,13,0,0,0,0,0,0,0,3,1,1,1
1,1,1,2,0,0,0,0,0,0,0,0,3,1,1,1
1,1,1,3,5,0,0,20,20,0,0,5,2,1,1,1
1,1,1,14,2,2,3,6,2,3,2,3,14,1,1,1
1,1,1,1,1,1,1,3,3,1,1,1,1,1,1,1
1,1,1,1,1,1,1,3,2,1,1,1,1,1,1,1
1,1,1,1,1,1,1,1,1,1,1,1,1,1,1,1
endlayer

layer
1,1,1,1,1,1,1,1,1,1,1,1,1,1,1,1
1,1,1,1,1,1,1,1,1,1,1,1,1,1,1,1
1,1,1,1,1,1,1,1,1,1,1,1,1,1,1,1
1,1,1,5,6,3,3,3,2,3,6,2,5,1,1,1
1,1,1,2,6,2,27,23,23,27,2,6,2,1,1,1
1,1,1,2,3,36,13,0,0,0,36,2,6,1,1,1
1,1,1,6,26,0,0,0,0,0,13,25,6,1,1,1
1,1,1,2,15,0,23,0,0,23,0,29,3,1,1,1
1,1,1,2,15,0,0,0,0,0,0,29,2,1,1,1
1,1,1,3,26,0,0,0,0,0,0,25,2,1,1,1
1,1,1,2,3,36,0,0,0,0,36,2,6,1,1,1
1,1,1,2,3,2,28,20,20,28,3,3,2,1,1,1
1,1,1,5,2,6,6,3,6,3,2,6,5,1,1,1
1,1,1,1,1,1,1,1,1,1,1,1,1,1,1,1
1,1,1,1,1,1,1,1,1,1,1,1,1,1,1,1
1,1,1,1,1,1,1,1,1,1,1,1,1,1,1,1
endlayer

layer
1,1,1,1,1,1,1,1,1,1,1,1,1,1,1,1
1,1,1,1,1,1,1,1,1,1,1,1,1,1,1,1
1,1,1,1,1,1,1,1,1,1,1,1,1,1,1,1
1,1,1,1,1,1,1,1,1,1,1,1,1,1,1,1
1,1,1,1,1,1,3,27,27,2,1,1,1,1,1,1
1,1,1,1,1,2,27,13,13,27,2,1,1,1,1,1
1,1,1,1,6,26,0,0,0,13,25,3,1,1,1,1
1,1,1,1,26,13,23,0,0,23,0,25,1,1,1,1
1,1,1,1,26,0,20,0,0,0,0,25,1,1,1,1
1,1,1,1,6,26,0,0,0,0,25,6,0,1,1,1
1,1,1,1,1,6,28,0,13,28,2,1,1,1,1,1
1,1,1,1,1,1,2,28,28,6,1,1,1,1,1,1
1,1,1,1,1,1,1,1,1,1,1,1,1,1,1,1
1,1,1,1,1,1,1,1,1,1,1,1,1,1,1,1
1,1,1,1,1,1,1,1,1,1,1,1,1,1,1,1
1,1,1,1,1,1,1,1,1,1,1,1,1,1,1,1
endlayer

layer
1,1,1,1,1,1,1,1,1,1,1,1,1,1,1,1
1,1,1,1,1,1,1,1,1,1,1,1,1,1,1,1
1,1,1,1,1,1,1,1,1,1,1,1,1,1,1,1
1,1,1,1,1,1,1,1,1,1,1,1,1,1,1,1
1,1,1,1,1,1,1,1,1,1,1,1,1,1,1,1
1,1,1,1,1,1,2,27,27,2,1,1,1,1,1,1
1,1,1,1,1,3,3,15,13,2,2,1,1,1,1,1
1,1,1,1,1,26,23,0,0,23,25,1,1,1,1,1
1,1,1,1,1,26,21,0,0,13,25,1,1,1,1,1
1,1,1,1,1,6,6,15,29,3,3,1,1,1,1,1
1,1,1,1,1,1,2,28,28,2,1,1,1,1,1,1
1,1,1,1,1,1,1,1,1,1,1,1,1,1,1,1
1,1,1,1,1,1,1,1,1,1,1,1,1,1,1,1
1,1,1,1,1,1,1,1,1,1,1,1,1,1,1,1
1,1,1,1,1,1,1,1,1,1,1,1,1,1,1,1
1,1,1,1,1,1,1,1,1,1,1,1,1,1,1,1
endlayer

layer
1,1,1,1,1,1,1,1,1,1,1,1,1,1,1,1
1,1,1,1,1,1,1,1,1,1,1,1,1,1,1,1
1,1,1,1,1,1,1,1,1,1,1,1,1,1,1,1
1,1,1,1,1,1,1,1,1,1,1,1,1,1,1,1
1,1,1,1,1,1,1,1,1,1,1,1,1,1,1,1
1,1,1,1,1,1,1,1,1,1,1,1,1,1,1,1
1,1,1,1,1,1,6,6,6,3,1,1,1,1,1,1
1,1,1,1,1,1,2,5,5,3,1,1,1,1,1,1
1,1,1,1,1,1,6,5,5,2,1,1,1,1,1,1
1,1,1,1,1,1,6,6,3,2,1,1,1,1,1,1
1,1,1,1,1,1,1,1,1,1,1,1,1,1,1,1
1,1,1,1,1,1,1,1,1,1,1,1,1,1,1,1
1,1,1,1,1,1,1,1,1,1,1,1,1,1,1,1
1,1,1,1,1,1,1,1,1,1,1,1,1,1,1,1
1,1,1,1,1,1,1,1,1,1,1,1,1,1,1,1
1,1,1,1,1,1,1,1,1,1,1,1,1,1,1,1
endlayer


