# Vault Arrow Hall
# MC 1.7.10; 12 Nov 2014
# Updated to MC 1.9: 24 Apr 2016
# Created by Ruins mod version 14.2 Ingame Parser
# authoring Player: Jordan_Greywolf
# Special Instructions: Place in /templateparser folder.

weight=1
embed_into_distance=0
acceptable_target_blocks=
unacceptable_target_blocks=
dimensions=6,16,8
allowable_overhang=9999
max_leveling=0
leveling_buffer=0
preserve_water=0
preserve_lava=0
preserve_plants=1

# Randomized Stone Brick Walls
rule1=0,100,minecraft:stonebrick-1,minecraft:stonebrick,minecraft:stonebrick-2,minecraft:monster_egg-4

# Mossy Cobblestone Floor
rule2=0,100,minecraft:mossy_cobblestone-0

rule3=0,100,minecraft:web-0
rule4=0,100,minecraft:tripwire_hook-4
rule5=0,100,minecraft:tripwire-4
rule6=0,100,minecraft:tripwire_hook-6
rule7=0,100,minecraft:tripwire-0

rule8=0,100,minecraft:cobblestone_wall-0,minecraft:cobblestone_wall-1

rule9=0,100,minecraft:stone_brick_stairs-2
rule10=0,100,minecraft:stone_brick_stairs-3
rule11=0,100,IInventory;minecraft:dispenser;minecraft:arrow#16#0#0-3
rule12=0,100,minecraft:vine-4
rule13=0,100,minecraft:vine-1
rule14=0,100,IInventory;minecraft:dispenser;minecraft:arrow#16#0#0-2
rule15=0,100,minecraft:stone_brick_stairs-7
rule16=0,100,minecraft:stone_brick_stairs-6
rule17=0,100,minecraft:vine-2

# Empty Dispensers (decorative only)
rule18=0,100,minecraft:dispenser-3
rule19=0,100,minecraft:dispenser-2
rule20=0,100,minecraft:dispenser-3
rule21=0,100,minecraft:dispenser-2

rule22=0,100,minecraft:vine-8
rule23=0,100,preserveBlock

# Chiseled Stone
rule24=0,100,minecraft:stonebrick-3

layer
1,1,1,2,2,1,1,1
1,1,2,2,2,2,1,1
1,1,2,2,2,2,1,1
1,1,1,2,2,1,1,1
1,1,2,2,2,2,1,1
1,1,2,2,2,2,1,1
1,1,2,2,2,2,1,1
1,1,2,2,2,2,1,1
1,1,2,2,2,2,1,1
1,1,2,2,2,2,1,1
1,1,2,2,2,2,1,1
1,1,2,2,2,2,1,1
1,1,1,2,2,1,1,1
1,1,2,2,2,2,1,1
1,1,2,2,2,2,1,1
1,1,1,2,2,1,1,1
endlayer

layer
1,1,1,0,0,1,1,1
1,1,3,0,0,0,1,1
1,1,3,0,0,3,1,1
1,1,1,0,0,1,1,1
1,1,3,0,3,3,1,1
1,6,5,5,5,5,4,1
1,6,7,5,5,5,4,1
1,1,3,0,0,3,1,1
1,1,3,3,0,3,1,1
1,6,5,5,5,7,4,1
1,6,5,5,5,7,4,1
1,1,3,3,0,3,1,1
1,1,1,0,0,1,1,1
1,1,3,0,0,3,1,1
1,1,0,0,0,0,1,1
1,1,1,0,0,1,1,1
endlayer

layer
1,1,8,0,0,8,1,1
10,9,0,0,0,0,10,9
10,9,0,0,0,0,10,9
1,1,8,0,0,8,1,1
10,9,0,0,0,0,10,9
1,14,13,0,0,12,11,1
1,14,13,0,0,12,11,1
10,9,0,0,0,0,10,9
10,9,0,0,0,0,10,9
1,14,13,0,0,12,11,1
1,14,13,0,0,12,11,1
10,9,3,3,0,0,10,9
1,1,8,0,0,8,1,1
10,9,0,0,0,0,10,9
10,9,0,0,0,0,10,9
1,1,8,0,0,8,1,1
endlayer

layer
1,1,16,0,3,15,1,1
15,16,0,0,0,0,15,16
15,16,0,0,0,0,15,16
1,1,16,0,0,15,1,1
15,16,17,0,0,0,15,16
1,19,13,0,0,12,18,1
1,19,13,0,0,12,18,1
15,16,0,0,0,0,15,16
15,16,0,0,0,0,15,16
1,21,13,0,0,12,20,1
1,21,13,0,0,12,20,1
15,16,22,0,0,0,15,16
1,1,16,3,3,15,1,1
15,16,0,0,0,0,15,16
15,16,0,0,0,0,15,16
1,1,16,0,0,15,1,1
endlayer

layer
1,1,1,16,15,1,1,1
1,1,16,0,3,15,1,1
1,1,16,3,0,15,1,1
1,1,1,16,15,1,1,1
1,1,17,0,0,17,1,1
1,1,13,0,0,12,1,1
1,1,13,0,0,12,1,1
1,1,3,0,0,3,1,1
1,1,3,3,0,3,1,1
1,1,13,0,0,12,1,1
1,1,13,0,0,12,1,1
1,1,22,0,0,22,1,1
1,1,1,16,15,1,1,1
1,1,16,0,3,15,1,1
1,1,16,3,0,15,1,1
1,1,1,16,15,1,1,1
endlayer

layer
23,23,1,1,1,1,23,23
23,23,1,24,24,1,23,23
23,23,1,24,24,1,23,23
23,23,1,1,1,1,23,23
23,23,1,24,24,1,23,23
1,1,1,24,24,1,1,1
1,1,1,1,1,1,1,1
23,1,1,24,24,1,1,1
23,1,1,24,24,1,1,1
1,1,1,1,1,1,1,1
1,1,1,24,24,1,1,1
23,23,1,24,24,1,23,23
23,23,1,1,1,1,23,23
23,23,1,24,24,1,23,23
23,23,1,24,24,1,23,23
23,23,1,1,1,1,23,23
endlayer

