# Village Plot
# Created by Ruins mod version 14.9 Ingame Parser
# authoring Player: Jordan_Greywolf
# Created for MC 1.8: 26 Jul 2015
# Note: Place in \templateparser folder.
# Last Updated 31 Oct 2015

weight=1
embed_into_distance=4

unacceptable_target_blocks=flowing_lava,lava,cloud,Natura:Cloud,red_mushroom_block,brown_mushroom_block,planks,cobblestone,mossy_cobblestone,iron_bars,glass,redstone_torch,torch,stone_slab,double_stone_slab,oak_stairs,spruce_stairs,birch_stairs,dark_oak_stairs,acacia_stairs,jungle_stairs,slime_congealed,slime_dirt,slime_grass,fence,stone_brick,cobblestone_wall,command_block

dimensions=8,9,13
allowable_overhang=0
max_leveling=3
leveling_buffer=-1
preserve_water=0
preserve_lava=0

rule1=0,100,minecraft:dirt-0
rule2=0,100,minecraft:log-0
rule3=0,100,minecraft:farmland-7,minecraft:farmland-1,minecraft:farmland-5,minecraft:farmland-3
rule4=0,100,minecraft:water-0
rule5=0,100,preserveBlock
rule6=0,100,minecraft:carrots-7,minecraft:carrots-4,minecraft:carrots-1
rule7=0,100,minecraft:potatoes-7,minecraft:potatoes-4,minecraft:potatoes-1
rule8=0,100,CommandBlock:RUINSTRIGGER /summon cow ~0 ~1 ~0:@
rule9=0,100,minecraft:wooden_slab-0
rule10=0,100,minecraft:fence-0
rule11=0,100,minecraft:wool-7,minecraft:wool-14,minecraft:wool,minecraft:wool-1,minecraft:wool-11,minecraft:wool-15,minecraft:wool-12
rule12=0,100,minecraft:lit_pumpkin-2
rule13=0,100,minecraft:lit_pumpkin-0

layer
1,1,1,1,1,1,1,1,1,1,1,1,1
1,1,1,1,1,1,1,1,1,1,1,1,1
1,1,1,1,1,1,1,1,1,1,1,1,1
1,1,1,1,1,1,1,1,1,1,1,1,1
1,1,1,1,1,1,1,1,1,1,1,1,1
1,1,1,1,1,1,1,1,1,1,1,1,1
1,1,1,1,1,1,1,1,1,1,1,1,1
1,1,1,1,1,1,1,1,1,1,1,1,1
1,1,1,1,1,1,1,1,1,1,1,1,1
endlayer

layer
1,1,1,1,1,1,1,1,1,1,1,1,1
1,1,1,1,1,1,1,1,1,1,1,1,1
1,1,1,1,1,1,1,1,1,1,1,1,1
1,1,1,1,1,1,1,1,1,1,1,1,1
1,1,1,1,1,1,1,1,1,1,1,1,1
1,1,1,1,1,1,1,1,1,1,1,1,1
1,1,1,1,1,1,1,1,1,1,1,1,1
1,1,1,1,1,1,1,1,1,1,1,1,1
1,1,1,1,1,1,1,1,1,1,1,1,1
endlayer

layer
1,1,1,1,1,1,1,1,1,1,1,1,1
1,1,1,1,1,1,1,1,1,1,1,1,1
1,1,1,1,1,1,1,1,1,1,1,1,1
1,1,1,1,1,1,1,1,1,1,1,1,1
1,1,1,1,1,1,1,1,1,1,1,1,1
1,1,1,1,1,1,1,1,1,1,1,1,1
1,1,1,1,1,1,1,1,1,1,1,1,1
1,1,1,1,1,1,1,1,1,1,1,1,1
1,1,1,1,1,1,1,1,1,1,1,1,1
endlayer

layer
1,1,1,1,1,1,1,1,1,1,1,1,1
1,1,1,1,1,1,1,1,1,1,1,1,1
1,1,1,1,1,1,1,1,1,1,1,1,1
1,1,1,1,1,1,1,1,1,1,1,1,1
1,1,1,1,1,1,1,1,1,1,1,1,1
1,1,1,1,1,1,1,1,1,1,1,1,1
1,1,1,1,1,1,1,1,1,1,1,1,1
1,1,1,1,1,1,1,1,1,1,1,1,1
1,1,1,1,1,1,1,1,1,1,1,1,1
endlayer


layer
2,2,2,2,2,2,2,2,2,2,2,2,2
2,3,3,2,3,3,2,3,3,2,3,3,2
2,3,3,2,3,3,2,3,3,2,3,3,2
2,3,3,4,3,3,4,3,3,4,3,3,2
2,3,3,2,3,3,4,3,3,2,3,3,2
2,3,3,4,3,3,4,3,3,4,3,3,2
2,3,3,2,3,3,2,3,3,2,3,3,2
2,3,3,2,3,3,2,3,3,2,3,3,2
2,2,2,2,2,2,2,2,2,2,2,2,2
endlayer

layer
5,5,5,5,0,0,5,0,0,5,5,5,5
5,6,6,0,7,7,0,7,7,0,6,6,5
5,6,6,0,7,7,8,7,7,0,6,6,5
5,6,6,9,7,7,9,7,7,9,6,6,5
0,6,6,10,7,7,9,7,7,10,6,6,0
5,6,6,9,7,7,9,7,7,9,6,6,5
5,6,6,0,7,7,8,7,7,0,6,6,5
5,6,6,0,7,7,0,7,7,0,6,6,5
5,5,5,5,0,0,5,0,0,5,5,5,5
endlayer

layer
5,5,0,0,0,0,0,0,0,0,0,5,5
5,0,0,0,0,0,0,0,0,0,0,0,5
0,0,0,0,0,0,0,0,0,0,0,0,0
0,0,0,10,0,0,0,0,0,10,0,0,0
0,0,0,11,0,0,0,0,0,11,0,0,0
0,0,0,10,0,0,0,0,0,10,0,0,0
0,0,0,0,0,0,0,0,0,0,0,0,0
5,0,0,0,0,0,0,0,0,0,0,0,5
5,5,0,0,0,0,0,0,0,0,0,5,5
endlayer

layer
5,0,0,0,0,0,0,0,0,0,0,0,5
0,0,0,0,0,0,0,0,0,0,0,0,0
0,0,0,0,0,0,0,0,0,0,0,0,0
0,0,0,0,0,0,0,0,0,0,0,0,0
0,0,0,13,0,0,0,0,0,12,0,0,0
0,0,0,0,0,0,0,0,0,0,0,0,0
0,0,0,0,0,0,0,0,0,0,0,0,0
0,0,0,0,0,0,0,0,0,0,0,0,0
5,0,0,0,0,0,0,0,0,0,0,0,5
endlayer

