# Village Horse Barn (bandit version)
# Original Version: 27 Sep 2014
# Updated to MC 1.8: 26 Jul 2015
# Created by Ruins mod version 14.9 Ingame Parser
# authoring Player: Jordan_Greywolf
# Note: Place in \templateparser folder.
# Updated to MC 1.8: 20 Mar 2016
# Updated to MC 1.9: 29 Apr 2016
# Updated to MC 1.11: 12 Jan 2017
# Updated to MC 1.12: 22 Jun 2017

# biomesToSpawnIn=birch forest,brushland,chaparral,field,flower field,forest,foresthills,field,flower forest,lavender fields,majestic meadow,meadow,meadow forest,pasture,pasture meadow,plains,prairie,sublime shrubland,sunflower plains,thick shrubland,thinned pasture

preventRotation=1


weight=1
embed_into_distance=5

unacceptable_target_blocks=flowing_lava,lava,cloud,Natura:Cloud,red_mushroom_block,brown_mushroom_block,planks,cobblestone,mossy_cobblestone,iron_bars,glass,redstone_torch,torch,stone_slab,double_stone_slab,oak_stairs,spruce_stairs,birch_stairs,dark_oak_stairs,acacia_stairs,jungle_stairs,slime_congealed,slime_dirt,slime_grass,fence,stone_brick,cobblestone_wall,command_block

dimensions=16,20,20
allowable_overhang=0
max_leveling=4
leveling_buffer=-1
preserve_water=0
preserve_lava=0

rule1=0,100,preserveBlock
rule2=0,100,minecraft:dirt-0
rule3=0,100,minecraft:mossy_cobblestone-0,minecraft:cobblestone
rule4=0,100,minecraft:stone-0
rule5=0,100,minecraft:double_stone_slab-0
rule6=0,100,minecraft:water-0
rule7=0,100,minecraft:hay_block-0
rule8=0,100,minecraft:web-0

# Villager: Stablehand
rule9=0,100,CommandBlock:RUINSTRIGGER /summon Villager ~0 ~0 ~0 {Profession:0,Career:1,CareerLevel:6,CustomName:Stablehand,Offers:{Recipes:[{buy:{id:emerald,Count:10},sell:{id:saddle,Count:1}},{buy:{id:emerald,Count:1},sell:{id:lead,Count:1}},{buy:{id:leather,Count:12},sell:{id:emerald,Count:1}},{buy:{id:carrot,Count:32},sell:{id:emerald,Count:1}},{buy:{id:apple,Count:20},sell:{id:emerald,Count:1}},{buy:{id:golden_horse_armor,Count:1},sell:{id:emerald,Count:1}},{buy:{id:diamond_horse_armor,Count:1},sell:{id:emerald,Count:1}}]}}:@

rule10=0,100,minecraft:cobblestone-0
rule11=0,100,minecraft:spruce_stairs-4
rule12=0,100,minecraft:spruce_stairs-3
rule13=0,100,minecraft:spruce_fence-0
rule14=0,100,minecraft:spruce_stairs-1
rule15=0,100,minecraft:stonebrick-3
rule16=1,100,minecraft:torch-5
rule17=0,100,minecraft:grass-0
rule18=0,100,minecraft:planks-1
rule19=0,100,minecraft:planks-0
rule20=0,100,minecraft:oak_stairs-0
rule21=0,100,minecraft:cobblestone_wall-1,minecraft:cobblestone_wall-0
rule22=0,100,minecraft:oak_stairs-2
rule23=0,100,minecraft:oak_stairs-3
rule24=0,100,minecraft:tallgrass-1,minecraft:red_flower,minecraft:yellow_flower,minecraft:red_flower-1,minecraft:red_flower-2
rule25=0,100,minecraft:oak_stairs-1
rule26=0,100,minecraft:spruce_fence_gate-0
rule27=0,100,minecraft:spruce_door-2

# Horse
rule28=0,100,CommandBlock:RUINSTRIGGER /summon horse ~0 ~0 ~0 {AbsorptionAmount:5,Health:100.0f,Attributes:[{Name:generic.movementSpeed,Base:0.4}],PersistenceRequired:1}:@

rule29=0,100,minecraft:wooden_pressure_plate-0
rule30=0,100,minecraft:spruce_door-0
rule31=0,100,minecraft:spruce_fence_gate-3
rule32=0,100,minecraft:spruce_fence_gate-1
rule33=0,100,minecraft:spruce_door-1
rule34=0,100,minecraft:spruce_door-3
rule35=0,100,minecraft:log-0
rule36=0,100,minecraft:ladder-4
rule37=0,100,minecraft:spruce_door-9
rule38=0,100,minecraft:spruce_door-8
rule39=0,100,minecraft:wooden_slab-0
rule40=0,100,minecraft:oak_stairs-4
rule41=0,100,minecraft:log-8
rule42=0,100,minecraft:log-4
rule43=0,100,minecraft:wooden_slab-9
rule44=0,100,minecraft:oak_stairs-5
rule45=0,100,minecraft:wooden_slab-8
rule46=0,100,minecraft:oak_stairs-6
rule47=0,100,minecraft:oak_stairs-7

# Highwayman (Bandit Archer)
rule48=0,100,CommandBlock:RUINSTRIGGER /summon Skeleton ~0 ~0 ~0 {HandItems:[{Count:1,id:bow,tag:{display:{Name:"Bandit Bow"},ench:[{id:48,lvl:3},{id:49,lvl:2}]}},{Count:8,id:tipped_arrow,tag:{Potion:"minecraft:strong_harming"}}],ArmorItems:[{Count:1,id:leather_boots},{Count:1,id:leather_leggings},{Count:1,id:leather_chestplate},{Count:1,id:skull,Damage:3,tag:{SkullOwner:MHF_Villager}}],CustomName:Highwayman,HandDropChances:[1.0F,0.0F],ArmorDropChances:[0.5F,0.5F,0.5F,0.0F],Silent:1,PersistenceRequired:1,Health:15.0f}:@


layer
1,1,1,2,3,3,3,3,3,3,3,3,3,3,3,3,2,2,1,1
1,1,2,2,3,4,4,4,4,4,4,4,4,4,4,3,2,2,2,1
1,1,2,2,3,4,4,4,4,4,4,4,4,4,4,3,2,2,2,1
1,2,2,2,3,4,4,4,4,4,4,4,4,4,4,3,2,2,2,1
1,2,2,2,3,4,4,4,4,4,4,4,4,4,4,3,2,2,2,1
1,2,2,2,3,4,4,4,4,4,4,4,4,4,4,3,2,2,2,2
2,2,2,2,3,3,3,3,3,3,3,3,3,3,3,3,2,2,2,2
2,2,2,2,4,4,4,4,4,4,4,4,4,4,4,3,2,2,2,2
2,2,2,2,3,4,4,4,4,4,4,4,4,4,4,3,2,2,2,2
2,2,2,2,3,4,4,4,4,4,4,4,4,4,4,3,2,2,2,2
2,2,2,2,3,4,4,4,4,4,4,4,4,4,4,3,2,2,2,2
2,2,2,2,3,4,4,4,4,4,4,4,4,4,4,3,2,2,2,2
2,2,2,2,3,4,4,4,4,4,4,4,4,4,4,3,2,2,2,2
1,2,2,2,3,3,3,4,4,4,4,4,4,4,4,3,2,2,2,1
1,2,2,2,3,3,3,4,4,4,4,4,4,4,4,3,2,2,2,1
1,2,2,2,3,3,3,3,3,3,3,3,3,3,3,3,2,2,2,1
1,2,2,2,2,2,2,2,2,2,2,2,2,2,2,2,2,2,1,1
1,1,2,2,2,2,2,2,2,2,2,2,2,2,2,2,2,2,1,1
1,1,2,2,2,2,2,2,2,2,2,2,2,2,2,2,2,2,1,1
1,1,1,2,2,2,2,2,2,2,2,2,2,2,2,2,2,1,1,1
endlayer

layer
1,1,1,2,5,3,3,3,3,3,3,3,3,3,3,5,2,1,1,1
1,1,1,2,3,2,2,2,2,2,2,2,2,3,6,3,2,2,1,1
1,1,2,2,3,2,2,2,2,2,2,2,2,3,6,3,2,2,1,1
1,1,2,2,3,2,2,2,2,2,2,2,2,3,3,3,2,2,1,1
1,1,2,2,3,2,2,2,2,2,2,2,2,2,2,3,2,2,1,1
1,2,2,2,3,7,2,2,2,2,2,2,2,2,7,3,2,2,2,1
1,2,2,2,3,3,3,3,3,3,3,3,3,3,3,3,2,2,2,2
1,2,2,2,3,7,9,0,7,7,7,8,8,8,8,3,2,2,2,2
2,2,2,2,3,7,0,0,0,0,0,0,0,0,0,3,2,2,2,2
2,2,2,2,3,7,0,0,3,0,0,3,0,0,8,3,2,2,2,2
2,2,2,2,10,7,7,0,0,48,0,0,0,0,0,3,2,2,2,2
1,2,2,2,10,7,0,0,0,0,0,0,0,0,8,3,2,2,2,1
1,2,2,2,3,7,8,0,3,0,0,3,0,0,0,3,2,2,2,1
1,2,2,2,3,7,7,8,0,0,0,0,0,0,11,3,2,2,1,1
1,1,2,2,3,7,7,7,8,0,0,8,0,0,12,3,2,2,1,1
1,1,2,2,3,3,3,3,3,3,3,3,3,3,3,3,2,1,1,1
1,1,2,2,2,2,2,2,2,2,2,2,2,2,2,2,2,1,1,1
1,1,2,2,2,2,2,2,2,2,2,2,2,2,2,2,1,1,1,1
1,1,1,2,2,2,2,2,2,2,2,2,2,2,2,2,1,1,1,1
1,1,1,1,1,1,2,2,2,2,2,2,2,1,1,1,1,1,1,1
endlayer

layer
1,1,1,1,5,3,3,3,3,3,3,3,3,3,3,5,1,1,1,1
1,1,1,2,3,2,2,2,2,2,2,2,2,3,6,3,2,1,1,1
1,1,1,2,3,2,2,2,2,2,2,2,2,3,6,3,2,1,1,1
1,1,2,2,3,2,2,2,2,2,2,2,2,3,3,3,2,1,1,1
1,1,2,2,3,2,2,2,2,2,2,2,2,2,2,3,2,2,1,1
1,1,2,2,3,2,2,2,2,6,6,2,2,2,2,3,2,2,1,1
1,1,2,2,3,3,3,3,3,3,3,3,3,3,3,3,2,2,2,1
1,2,2,2,3,0,0,0,13,0,0,13,0,0,8,3,2,2,2,1
1,2,2,2,3,0,0,0,0,0,0,0,0,0,0,3,2,2,2,1
2,2,2,2,3,8,0,0,3,0,0,3,0,0,0,3,2,2,2,1
1,2,2,2,3,8,0,0,0,0,0,0,0,0,0,3,2,2,2,1
1,2,2,2,3,8,0,0,0,0,0,0,0,0,8,3,2,2,2,1
1,1,2,2,3,8,0,0,3,0,0,3,0,0,11,3,2,2,1,1
1,1,2,2,3,7,8,0,0,0,0,0,0,0,14,3,2,1,1,1
1,1,2,2,3,7,7,8,13,0,0,13,0,0,0,3,2,1,1,1
1,1,2,2,3,3,3,3,3,3,3,3,3,3,3,3,2,1,1,1
1,1,1,2,2,2,2,2,2,2,2,2,2,2,2,2,1,1,1,1
1,1,1,2,2,2,2,2,2,2,2,2,2,2,2,1,1,1,1,1
1,1,1,1,1,1,2,2,2,2,2,2,2,2,1,1,1,1,1,1
1,1,1,1,1,1,1,1,2,2,2,1,1,1,1,1,1,1,1,1
endlayer

layer
1,1,1,1,5,3,3,3,3,3,3,3,3,3,3,5,1,1,1,1
1,1,1,2,3,2,2,2,2,2,2,2,2,3,6,3,1,1,1,1
1,1,1,2,3,2,2,2,2,2,2,2,2,3,6,3,1,1,1,1
1,1,1,2,3,2,2,2,2,2,2,2,2,3,3,3,1,1,1,1
1,1,2,2,3,2,2,2,2,2,2,2,2,2,2,3,2,1,1,1
1,1,2,2,3,2,2,2,2,15,2,2,2,2,2,3,2,1,1,1
1,1,2,2,3,3,3,3,3,3,3,3,3,3,3,3,2,2,1,1
1,1,2,2,3,0,0,0,16,8,0,16,0,0,8,3,2,2,1,1
1,2,2,2,3,0,0,0,8,0,0,8,0,0,8,3,2,2,1,1
1,2,2,2,3,8,0,8,3,8,8,3,8,0,0,3,2,2,2,1
1,2,2,2,3,8,0,0,0,0,0,0,0,0,8,3,2,2,2,1
1,1,2,2,3,8,0,0,0,8,0,0,0,0,11,3,2,2,1,1
1,1,2,2,3,8,0,0,3,0,0,3,0,0,14,3,2,1,1,1
1,1,2,2,3,8,0,0,0,0,0,0,0,0,0,3,2,1,1,1
1,1,2,2,3,7,8,0,16,0,0,16,0,0,0,3,2,1,1,1
1,1,1,2,3,3,3,3,3,3,3,3,3,3,3,3,2,1,1,1
1,1,1,2,2,2,2,2,2,2,2,2,2,2,2,2,1,1,1,1
1,1,1,1,1,2,2,2,2,2,2,2,2,2,1,1,1,1,1,1
1,1,1,1,1,1,1,2,2,2,2,1,1,1,1,1,1,1,1,1
1,1,1,1,1,1,1,1,1,1,1,1,1,1,1,1,1,1,1,1
endlayer

layer
1,1,1,1,5,3,3,3,3,3,3,3,3,3,3,5,1,1,1,1
1,1,1,1,3,17,17,17,17,17,17,17,17,3,6,3,1,1,1,1
1,1,1,17,3,17,17,17,17,17,17,17,17,3,6,3,1,1,1,1
1,1,1,17,3,17,17,17,17,17,17,17,17,3,3,3,1,1,1,1
1,1,1,17,3,17,17,17,17,17,17,17,17,17,17,3,1,1,1,1
1,1,17,17,3,17,17,17,17,17,17,17,17,17,17,3,17,1,1,1
1,1,17,17,3,3,3,3,3,3,3,3,3,3,3,3,17,1,1,1
1,1,17,17,3,18,18,18,18,18,18,18,18,18,18,3,17,1,1,1
1,1,17,17,3,18,18,18,18,18,18,18,18,18,18,3,17,1,1,1
1,17,17,17,3,18,18,18,3,18,18,3,18,18,18,3,17,17,1,1
1,17,17,5,5,18,18,18,18,18,18,18,18,18,18,5,5,17,1,1
1,1,17,5,5,18,18,18,18,18,18,18,18,18,14,5,5,1,1,1
1,1,17,17,3,18,18,18,18,18,18,18,18,18,0,3,17,1,1,1
1,1,17,17,3,18,18,18,18,18,18,18,18,18,0,3,17,1,1,1
1,1,1,17,3,18,18,18,18,18,18,18,18,18,0,3,17,1,1,1
1,1,1,17,6,3,3,3,3,3,3,3,3,3,3,6,17,1,1,1
1,1,1,1,17,17,17,17,17,17,17,17,17,17,17,17,1,1,1,1
1,1,1,1,1,1,17,17,17,17,17,17,17,1,1,1,1,1,1,1
1,1,1,1,1,1,1,1,1,17,1,1,1,1,1,1,1,1,1,1
1,1,1,1,1,1,1,1,1,1,1,1,1,1,1,1,1,1,1,1
endlayer

layer
1,1,1,1,3,21,21,21,21,21,21,21,21,19,20,19,1,1,1,1
1,1,1,0,21,24,24,24,24,24,24,24,24,23,6,22,0,1,1,1
1,1,0,24,21,24,24,24,24,24,24,24,24,23,6,22,0,1,1,1
1,1,0,24,21,24,24,24,24,24,24,24,24,19,25,19,0,1,1,1
1,1,0,24,21,24,24,24,24,24,24,24,24,24,24,21,0,0,1,1
1,0,24,24,21,24,24,0,21,24,24,21,24,24,24,26,24,0,1,1
1,0,24,24,3,0,0,0,3,27,27,3,0,0,0,3,24,0,1,1
1,0,24,24,3,0,28,0,3,29,29,3,0,28,0,3,24,0,1,1
0,0,24,24,3,0,0,0,3,30,30,3,0,0,0,3,24,0,1,1
0,24,24,21,3,13,32,13,3,0,0,3,13,31,13,3,21,24,0,1
0,24,24,0,34,0,0,0,48,0,0,48,0,0,0,33,0,24,0,1
0,0,24,0,34,0,0,0,0,0,0,0,0,0,0,33,0,0,0,1
1,0,24,21,3,13,31,13,35,13,13,35,0,13,0,3,21,0,1,1
1,0,24,24,3,0,0,0,13,7,7,0,0,13,0,3,24,0,1,1
1,1,0,24,3,0,0,0,13,7,7,0,36,13,0,3,24,0,1,1
1,1,0,24,3,3,3,3,3,3,3,3,3,3,3,3,24,0,1,1
1,1,0,0,24,24,24,24,24,24,24,24,24,24,24,24,0,1,1,1
1,1,1,0,0,0,24,24,24,24,24,24,24,0,0,0,1,1,1,1
1,1,1,1,1,0,0,0,0,24,0,0,0,1,1,1,1,1,1,1
1,1,1,1,1,1,1,1,1,0,1,1,1,1,1,1,1,1,1,1
endlayer

layer
1,1,1,0,3,0,0,16,0,0,0,0,16,13,0,13,0,1,1,1
1,1,0,0,0,0,0,0,0,0,0,0,0,0,0,0,0,0,1,1
1,0,0,0,0,0,0,0,0,0,0,0,0,0,0,0,0,0,0,1
0,0,0,0,0,0,0,0,0,0,0,0,0,13,0,13,0,0,0,1
0,0,0,0,16,0,0,0,0,0,0,0,0,0,0,16,0,0,0,1
0,0,0,0,0,0,0,0,16,0,0,16,0,0,0,0,0,0,0,1
0,0,0,0,35,0,0,0,35,38,37,35,0,0,0,35,0,0,0,1
0,0,0,0,19,0,0,0,13,0,0,13,0,0,0,19,0,0,0,1
0,0,0,0,13,0,0,0,13,37,38,13,0,0,0,13,0,0,0,0
0,0,0,16,35,16,0,0,35,0,0,35,0,0,16,35,16,0,0,0
0,0,0,0,38,0,0,0,0,0,0,0,0,0,0,37,0,0,0,0
0,0,0,0,37,0,0,0,0,0,0,0,0,0,0,38,0,0,0,0
0,0,0,16,35,16,0,0,35,0,16,35,0,16,0,35,16,0,0,0
0,0,0,0,13,0,0,0,0,0,0,0,0,0,0,13,0,0,0,1
0,0,0,0,19,0,0,0,0,0,0,0,36,0,0,19,0,0,0,1
1,0,0,0,35,19,13,19,35,13,13,35,19,13,19,35,0,0,0,1
1,0,0,0,0,0,0,0,0,0,0,0,0,0,0,0,0,0,1,1
1,1,0,0,0,0,0,0,0,0,0,0,0,0,0,0,0,1,1,1
1,1,0,0,0,0,0,0,0,0,0,0,0,0,0,0,0,1,1,1
1,1,1,1,0,0,0,0,0,0,0,0,0,1,1,1,1,1,1,1
endlayer

layer
1,1,0,0,3,0,0,0,0,0,0,0,0,39,39,39,0,0,1,1
1,0,0,0,0,0,0,0,0,0,0,0,0,39,40,39,0,0,0,1
0,0,0,0,0,0,0,0,0,0,0,0,0,39,25,39,0,0,0,1
0,0,0,0,0,0,0,0,0,0,0,0,0,39,39,39,0,0,0,0
0,0,0,0,0,0,0,0,0,0,0,0,0,0,0,0,0,0,0,0
0,0,0,0,0,0,0,0,0,0,0,0,0,0,0,0,0,0,0,0
0,0,0,0,35,0,0,0,35,8,8,35,0,0,0,35,0,0,0,0
0,0,0,0,19,0,0,0,13,0,0,13,0,0,0,19,0,0,0,0
0,0,0,0,19,0,0,0,13,0,0,13,0,0,0,19,0,0,0,0
0,0,0,0,35,8,0,8,35,8,8,35,8,0,8,35,0,0,0,0
0,0,0,0,0,0,0,0,8,0,0,0,0,0,0,0,0,0,0,0
0,0,0,0,0,0,0,0,8,0,0,0,0,0,0,0,0,0,0,0
0,0,0,0,35,8,0,8,35,8,0,35,0,0,0,35,0,0,0,0
0,0,0,0,19,0,0,0,0,0,0,0,0,0,0,19,0,0,0,0
0,0,0,0,19,8,0,8,8,0,0,8,36,0,8,19,0,0,0,0
0,0,0,0,35,19,19,19,35,19,19,35,19,19,19,35,0,0,0,0
0,0,0,0,0,0,0,0,0,0,0,0,0,0,0,0,0,0,0,1
0,0,0,0,0,0,0,0,0,0,0,0,0,0,0,0,0,0,1,1
1,0,0,0,0,0,0,0,0,0,0,0,0,0,0,0,0,0,1,1
1,1,0,0,0,0,0,0,0,0,0,0,0,0,0,0,0,1,1,1
endlayer

layer
1,0,0,0,21,0,0,0,0,0,0,0,0,0,0,0,0,0,0,1
0,0,0,0,0,0,0,0,0,0,0,0,0,0,0,0,0,0,0,0
0,0,0,0,0,0,0,0,0,0,0,0,0,0,0,0,0,0,0,0
0,0,0,0,0,0,0,0,0,0,0,0,0,0,0,0,0,0,0,0
0,0,0,0,0,0,0,0,0,0,0,0,0,0,0,0,0,0,0,0
0,0,0,0,0,0,0,0,0,0,0,0,0,0,0,0,0,0,0,0
0,0,0,0,35,41,41,41,35,41,41,35,41,41,41,35,0,0,0,0
0,0,0,0,42,43,43,43,42,43,43,42,43,43,43,42,0,0,0,0
0,0,0,0,42,43,43,43,42,43,43,42,43,43,43,42,0,0,0,0
0,0,0,43,35,41,41,41,35,41,41,35,41,41,41,35,43,0,0,0
0,0,0,43,42,43,42,0,42,0,8,42,0,42,43,42,43,0,0,0
0,0,0,43,42,43,42,8,42,8,0,42,8,42,43,42,43,0,0,0
0,0,0,43,35,41,41,41,7,41,41,7,41,41,41,35,43,0,0,0
0,0,0,0,42,43,43,43,42,43,43,42,43,43,43,42,0,0,0,0
0,0,0,0,42,43,43,43,42,43,43,42,36,43,43,42,0,0,0,0
0,0,0,0,35,41,41,41,35,41,41,35,41,41,41,35,0,0,0,0
0,0,0,0,0,0,0,0,0,0,0,0,0,0,0,0,0,0,0,0
0,0,0,0,0,0,0,0,0,0,0,0,0,0,0,0,0,0,0,1
0,0,0,0,0,0,0,0,0,0,0,0,0,0,0,0,0,0,0,1
1,0,0,0,0,0,0,0,0,0,0,0,0,0,0,0,0,0,1,1
endlayer

layer
0,0,0,0,0,0,0,0,0,0,0,0,0,0,0,0,0,0,0,0
0,0,0,0,0,0,0,0,0,0,0,0,0,0,0,0,0,0,0,0
0,0,0,0,0,0,0,0,0,0,0,0,0,0,0,0,0,0,0,0
0,0,0,0,0,0,0,0,0,0,0,0,0,0,0,0,0,0,0,0
0,0,0,0,0,0,0,0,0,0,0,0,0,0,0,0,0,0,0,0
0,0,0,20,20,20,20,20,20,20,20,20,20,20,20,20,20,0,0,0
0,0,0,19,19,19,19,19,19,19,19,19,19,19,19,19,19,0,0,0
0,0,0,0,19,7,7,7,7,7,7,7,7,7,7,19,0,0,0,0
0,0,0,0,19,7,7,0,0,48,0,0,0,7,7,19,0,0,0,0
0,0,0,0,35,13,0,0,35,13,13,35,0,0,13,35,0,0,0,0
0,0,0,0,0,0,0,0,0,0,0,0,0,0,0,0,0,0,0,0
0,0,0,0,0,0,0,0,0,0,0,0,0,0,0,0,0,0,0,0
0,0,0,0,35,13,0,0,35,13,13,35,0,0,13,35,0,0,0,0
0,0,0,0,19,7,7,0,0,0,48,0,0,7,7,19,0,0,0,0
0,0,0,0,19,7,7,7,7,7,7,7,0,7,7,19,0,0,0,0
0,0,0,19,19,19,19,19,19,19,19,19,19,19,19,19,19,0,0,0
0,0,0,25,25,25,25,25,25,25,25,25,25,25,25,25,25,0,0,0
0,0,0,0,0,0,0,0,0,0,0,0,0,0,0,0,0,0,0,0
0,0,0,0,0,0,0,0,0,0,0,0,0,0,0,0,0,0,0,1
0,0,0,0,0,0,0,0,0,0,0,0,0,0,0,0,0,0,0,1
endlayer

layer
0,0,0,0,0,0,0,0,0,0,0,0,0,0,0,0,0,0,0,0
0,0,0,0,0,0,0,0,0,0,0,0,0,0,0,0,0,0,0,0
0,0,0,0,0,0,0,0,0,0,0,0,0,0,0,0,0,0,0,0
0,0,0,0,0,0,0,0,0,0,0,0,0,0,0,0,0,0,0,0
0,0,0,0,0,0,0,0,0,0,0,0,0,0,0,0,0,0,0,0
0,0,0,0,0,0,0,0,0,0,0,0,0,0,0,0,0,0,0,0
0,0,0,19,19,19,19,19,19,19,19,19,19,19,19,19,19,0,0,0
0,0,0,0,19,7,7,7,7,7,7,7,7,7,7,19,0,0,0,0
0,0,0,0,19,7,0,0,0,0,0,0,0,0,7,19,0,0,0,0
0,0,0,0,35,16,0,0,35,0,16,35,0,0,16,35,0,0,0,0
0,0,0,0,0,0,0,0,8,0,0,8,0,0,0,0,0,0,0,0
0,0,0,0,0,0,0,0,8,0,0,8,0,0,0,0,0,0,0,0
0,0,0,0,35,16,0,0,35,16,0,35,0,0,16,35,0,0,0,0
0,0,0,0,19,7,0,0,0,0,0,0,0,0,7,19,0,0,0,0
0,0,0,0,19,7,7,7,7,7,7,7,0,7,7,19,0,0,0,0
0,0,0,19,19,19,19,19,19,19,19,19,19,19,19,19,19,0,0,0
0,0,0,0,0,0,0,0,0,0,0,0,0,0,0,0,0,0,0,0
0,0,0,0,0,0,0,0,0,0,0,0,0,0,0,0,0,0,0,0
0,0,0,0,0,0,0,0,0,0,0,0,0,0,0,0,0,0,0,0
0,0,0,0,0,0,0,0,0,0,0,0,0,0,0,0,0,0,0,1
endlayer

layer
0,0,0,0,0,0,0,0,0,0,0,0,0,0,0,0,0,0,0,0
0,0,0,0,0,0,0,0,0,0,0,0,0,0,0,0,0,0,0,0
0,0,0,0,0,0,0,0,0,0,0,0,0,0,0,0,0,0,0,0
0,0,0,0,0,0,0,0,0,0,0,0,0,0,0,0,0,0,0,0
0,0,0,0,0,0,0,0,0,0,0,0,0,0,0,0,0,0,0,0
0,0,0,0,0,0,0,0,0,0,0,0,0,0,0,0,0,0,0,0
0,0,0,20,20,20,20,20,20,20,20,20,20,20,20,20,20,0,0,0
0,0,0,44,42,44,44,44,42,44,44,42,44,44,44,42,44,0,0,0
0,0,0,0,42,8,0,0,42,0,0,42,0,0,0,42,0,0,0,0
0,0,0,0,35,0,0,0,35,0,0,35,0,0,0,35,0,0,0,0
0,0,0,0,42,0,0,0,42,0,0,42,0,0,0,42,0,0,0,0
0,0,0,0,42,0,0,0,42,0,0,42,0,0,0,42,0,0,0,0
0,0,0,0,35,0,0,0,35,0,0,35,0,0,0,35,0,0,0,0
0,0,0,0,42,8,0,0,42,0,8,42,0,0,0,42,0,0,0,0
0,0,0,40,42,40,40,40,42,40,40,42,40,40,40,42,40,0,0,0
0,0,0,25,25,25,25,25,25,25,25,25,25,25,25,25,25,0,0,0
0,0,0,0,0,0,0,0,0,0,0,0,0,0,0,0,0,0,0,0
0,0,0,0,0,0,0,0,0,0,0,0,0,0,0,0,0,0,0,0
0,0,0,0,0,0,0,0,0,0,0,0,0,0,0,0,0,0,0,0
0,0,0,0,0,0,0,0,0,0,0,0,0,0,0,0,0,0,0,0
endlayer

layer
0,0,0,0,0,0,0,0,0,0,0,0,0,0,0,0,0,0,0,0
0,0,0,0,0,0,0,0,0,0,0,0,0,0,0,0,0,0,0,0
0,0,0,0,0,0,0,0,0,0,0,0,0,0,0,0,0,0,0,0
0,0,0,0,0,0,0,0,0,0,0,0,0,0,0,0,0,0,0,0
0,0,0,0,0,0,0,0,0,0,0,0,0,0,0,0,0,0,0,0
0,0,0,0,0,0,0,0,0,0,0,0,0,0,0,0,0,0,0,0
0,0,0,0,0,0,0,0,0,0,0,0,0,0,0,0,0,0,0,0
0,0,0,20,20,20,20,20,20,20,20,20,20,20,20,20,20,0,0,0
0,0,0,44,19,44,44,44,44,44,44,44,44,44,44,19,44,0,0,0
0,0,0,0,35,8,0,0,35,8,8,35,8,0,8,35,0,0,0,0
0,0,0,0,8,0,0,0,8,0,0,8,0,0,0,8,0,0,0,0
0,0,0,0,0,0,0,0,8,0,0,8,0,0,0,8,0,0,0,0
0,0,0,0,35,0,0,0,35,8,8,35,0,8,8,35,0,0,0,0
0,0,0,40,19,40,40,40,40,40,40,40,40,40,40,19,40,0,0,0
0,0,0,25,25,25,25,25,25,25,25,25,25,25,25,25,25,0,0,0
0,0,0,0,0,0,0,0,0,0,0,0,0,0,0,0,0,0,0,0
0,0,0,0,0,0,0,0,0,0,0,0,0,0,0,0,0,0,0,0
0,0,0,0,0,0,0,0,0,0,0,0,0,0,0,0,0,0,0,0
0,0,0,0,0,0,0,0,0,0,0,0,0,0,0,0,0,0,0,0
0,0,0,0,0,0,0,0,0,0,0,0,0,0,0,0,0,0,0,0
endlayer

layer
0,0,0,0,0,0,0,0,0,0,0,0,0,0,0,0,0,0,0,0
0,0,0,0,0,0,0,0,0,0,0,0,0,0,0,0,0,0,0,0
0,0,0,0,0,0,0,0,0,0,0,0,0,0,0,0,0,0,0,0
0,0,0,0,0,0,0,0,0,0,0,0,0,0,0,0,0,0,0,0
0,0,0,0,0,0,0,0,0,0,0,0,0,0,0,0,0,0,0,0
0,0,0,0,0,0,0,0,0,0,0,0,0,0,0,0,0,0,0,0
0,0,0,0,0,0,0,0,0,0,0,0,0,0,0,0,0,0,0,0
0,0,0,0,0,0,0,0,0,0,0,0,0,0,0,0,0,0,0,0
0,0,0,39,39,39,39,39,39,39,39,39,39,39,39,39,39,0,0,0
0,0,0,19,19,19,19,19,19,19,19,19,19,19,19,19,19,0,0,0
0,0,0,45,45,45,45,45,45,0,0,45,45,45,45,45,45,0,0,0
0,0,0,45,45,45,45,45,45,0,0,45,45,45,45,45,45,0,0,0
0,0,0,19,19,19,19,19,19,19,19,19,19,19,19,19,19,0,0,0
0,0,0,39,39,39,39,39,39,39,39,39,39,39,39,39,39,0,0,0
0,0,0,0,0,0,0,0,0,0,0,0,0,0,0,0,0,0,0,0
0,0,0,0,0,0,0,0,0,0,0,0,0,0,0,0,0,0,0,0
0,0,0,0,0,0,0,0,0,0,0,0,0,0,0,0,0,0,0,0
0,0,0,0,0,0,0,0,0,0,0,0,0,0,0,0,0,0,0,0
0,0,0,0,0,0,0,0,0,0,0,0,0,0,0,0,0,0,0,0
0,0,0,0,0,0,0,0,0,0,0,0,0,0,0,0,0,0,0,0
endlayer

layer
0,0,0,0,0,0,0,0,0,0,0,0,0,0,0,0,0,0,0,0
0,0,0,0,0,0,0,0,0,0,0,0,0,0,0,0,0,0,0,0
0,0,0,0,0,0,0,0,0,0,0,0,0,0,0,0,0,0,0,0
0,0,0,0,0,0,0,0,0,0,0,0,0,0,0,0,0,0,0,0
0,0,0,0,0,0,0,0,0,0,0,0,0,0,0,0,0,0,0,0
0,0,0,0,0,0,0,0,0,0,0,0,0,0,0,0,0,0,0,0
0,0,0,0,0,0,0,0,0,0,0,0,0,0,0,0,0,0,0,0
0,0,0,0,0,0,0,0,0,0,0,0,0,0,0,0,0,0,0,0
0,0,0,0,0,0,0,0,0,0,0,0,0,0,0,0,0,0,0,0
0,0,0,0,0,0,0,0,13,13,13,13,0,0,0,0,0,0,0,0
0,0,0,19,39,39,39,39,39,0,0,39,39,39,39,39,19,0,0,0
0,0,0,19,39,39,39,39,39,0,0,39,39,39,39,39,19,0,0,0
0,0,0,0,0,0,0,0,13,13,13,13,0,0,0,0,0,0,0,0
0,0,0,0,0,0,0,0,0,0,0,0,0,0,0,0,0,0,0,0
0,0,0,0,0,0,0,0,0,0,0,0,0,0,0,0,0,0,0,0
0,0,0,0,0,0,0,0,0,0,0,0,0,0,0,0,0,0,0,0
0,0,0,0,0,0,0,0,0,0,0,0,0,0,0,0,0,0,0,0
0,0,0,0,0,0,0,0,0,0,0,0,0,0,0,0,0,0,0,0
0,0,0,0,0,0,0,0,0,0,0,0,0,0,0,0,0,0,0,0
0,0,0,0,0,0,0,0,0,0,0,0,0,0,0,0,0,0,0,0
endlayer

layer
0,0,0,0,0,0,0,0,0,0,0,0,0,0,0,0,0,0,0,0
0,0,0,0,0,0,0,0,0,0,0,0,0,0,0,0,0,0,0,0
0,0,0,0,0,0,0,0,0,0,0,0,0,0,0,0,0,0,0,0
0,0,0,0,0,0,0,0,0,0,0,0,0,0,0,0,0,0,0,0
0,0,0,0,0,0,0,0,0,0,0,0,0,0,0,0,0,0,0,0
0,0,0,0,0,0,0,0,0,0,0,0,0,0,0,0,0,0,0,0
0,0,0,0,0,0,0,0,0,0,0,0,0,0,0,0,0,0,0,0
0,0,0,0,0,0,0,0,0,0,0,0,0,0,0,0,0,0,0,0
0,0,0,0,0,0,0,0,0,0,0,0,0,0,0,0,0,0,0,0
0,0,0,0,0,0,0,0,39,39,39,39,0,0,0,0,0,0,0,0
0,0,47,22,0,0,0,0,39,19,19,39,0,0,0,0,23,46,0,0
0,0,47,22,0,0,0,0,39,19,19,39,0,0,0,0,23,46,0,0
0,0,0,0,0,0,0,0,39,39,39,39,0,0,0,0,0,0,0,0
0,0,0,0,0,0,0,0,0,0,0,0,0,0,0,0,0,0,0,0
0,0,0,0,0,0,0,0,0,0,0,0,0,0,0,0,0,0,0,0
0,0,0,0,0,0,0,0,0,0,0,0,0,0,0,0,0,0,0,0
0,0,0,0,0,0,0,0,0,0,0,0,0,0,0,0,0,0,0,0
0,0,0,0,0,0,0,0,0,0,0,0,0,0,0,0,0,0,0,0
0,0,0,0,0,0,0,0,0,0,0,0,0,0,0,0,0,0,0,0
0,0,0,0,0,0,0,0,0,0,0,0,0,0,0,0,0,0,0,0
endlayer

