# Vault Fountain
# MC 1.7.10; 12 Nov 2014
# Created by Ruins mod version 14.2 Ingame Parser
# authoring Player: Jordan_Greywolf
# Special Instructions: Place in /templateparser folder

weight=1
embed_into_distance=0
acceptable_target_blocks=
unacceptable_target_blocks=
dimensions=11,16,16
allowable_overhang=0
max_leveling=0
leveling_buffer=0
preserve_water=0
preserve_lava=0
preserve_plants=1

rule1=0,100,minecraft:stonebrick-3
rule2=0,100,minecraft:stonebrick,minecraft:stonebrick-1,minecraft:stonebrick-2,minecraft:monster_egg-4
rule3=0,100,minecraft:mossy_cobblestone-0
rule4=0,100,minecraft:water-0
rule5=0,100,minecraft:double_stone_slab-0
rule6=0,100,minecraft:vine-4
rule7=0,100,minecraft:vine-1
rule8=0,100,minecraft:skull,minecraft:skull-1,minecraft:skull-2,minecraft:skull-3,minecraft:skull-4,minecraft:skull-5
rule9=0,100,minecraft:vine-2
rule10=0,100,minecraft:vine-8
rule11=0,100,minecraft:cobblestone-0
rule12=0,100,minecraft:stone_stairs-3
rule13=0,100,minecraft:web-0
rule14=0,100,minecraft:stone_stairs-2
rule15=0,100,minecraft:stone_stairs-1
rule16=0,100,minecraft:stone_slab-5
rule17=0,100,minecraft:cobblestone_wall-0
rule18=0,100,minecraft:water-8
rule19=0,100,minecraft:stone_stairs-0
rule20=1,100,minecraft:redstone_torch-5
rule21=0,100,minecraft:vine-12
rule22=0,100,minecraft:vine-9
rule23=0,100,minecraft:stone_brick_stairs-5
rule24=0,100,minecraft:stone_brick_stairs-7
rule25=0,100,minecraft:stone_brick_stairs-6
rule26=0,100,minecraft:stone_brick_stairs-4
rule27=0,100,minecraft:stone_stairs-7
rule28=0,100,minecraft:stone_stairs-6
rule29=0,100,minecraft:stone_stairs-5
rule30=0,100,minecraft:stone_slab-11
rule31=0,100,minecraft:stone_stairs-4
rule32=0,100,preserveBlock
rule33=0,100,minecraft:stone_slab-13

layer
1,2,2,1,2,2,2,3,3,2,2,2,1,2,2,1
2,3,3,3,3,3,3,3,3,3,3,3,3,3,3,2
2,3,3,3,3,3,3,3,3,3,3,3,3,3,3,2
1,3,3,1,2,2,2,3,3,2,2,2,1,3,3,1
2,3,3,2,3,3,3,3,3,3,3,3,2,3,3,2
2,3,3,2,3,3,2,2,2,2,3,3,2,3,3,2
2,3,3,2,3,2,2,4,4,2,2,3,2,3,3,2
3,3,3,3,3,2,4,4,4,4,2,3,3,3,3,3
3,3,3,3,3,2,4,4,4,4,2,3,3,3,3,3
2,3,3,2,3,2,2,4,4,2,2,3,2,3,3,2
2,3,3,2,3,3,2,2,2,2,3,3,2,3,3,2
2,3,3,2,3,3,3,3,3,3,3,3,2,3,3,2
1,3,3,1,2,2,2,3,3,2,2,2,1,3,3,1
2,3,3,3,3,3,3,3,3,3,3,3,3,3,3,2
2,3,3,3,3,3,3,3,3,3,3,3,3,3,3,2
1,2,2,1,2,2,2,3,3,2,2,2,1,2,2,1
endlayer

layer
5,2,2,5,2,2,2,7,6,2,2,2,5,2,2,5
2,8,9,0,0,0,9,0,0,0,0,0,0,9,8,2
2,7,0,10,10,10,10,0,0,10,10,10,10,0,6,2
5,0,6,5,2,2,2,7,0,2,2,2,5,7,0,5
2,0,6,2,11,14,9,0,0,13,12,11,2,0,0,2
2,0,6,2,15,0,16,16,16,16,0,15,2,7,0,2
2,7,0,2,0,16,17,0,0,17,16,13,2,7,0,2
9,0,0,0,0,16,0,18,18,0,16,0,9,0,0,9
10,0,0,10,0,16,0,18,18,0,16,0,0,0,0,10
2,7,6,2,0,16,17,0,0,17,16,0,2,7,0,2
2,0,6,2,19,0,16,16,16,16,0,19,2,0,0,2
2,0,0,2,11,14,0,0,0,0,12,11,2,0,6,2
5,0,6,5,2,2,2,13,0,2,2,2,5,0,0,5
2,7,0,9,0,0,9,0,0,0,0,9,0,0,6,2
2,8,10,0,0,0,0,0,0,0,10,10,0,0,0,2
5,2,2,5,2,2,2,7,6,2,2,2,5,2,2,5
endlayer

layer
5,8,8,5,8,2,17,0,0,17,2,8,5,8,8,5
8,0,0,9,0,9,0,0,0,0,9,0,9,0,0,8
8,0,0,0,10,10,0,0,0,0,10,10,0,0,0,8
5,7,0,17,2,2,17,0,0,17,2,2,17,0,0,5
8,0,6,2,11,0,0,0,0,0,0,11,2,7,0,8
2,7,6,2,9,0,0,0,0,0,0,0,2,7,6,2
17,0,0,17,0,0,20,0,0,20,0,0,17,0,0,17
0,0,0,0,0,0,0,18,18,0,0,0,0,0,0,0
0,0,0,0,0,0,0,18,18,0,0,6,0,0,0,0
17,0,0,17,0,0,20,0,0,20,0,0,17,0,0,17
2,7,6,2,22,0,0,0,0,0,0,21,2,7,0,2
8,7,6,2,11,0,0,10,10,0,0,11,2,7,0,8
5,0,0,17,2,2,17,0,0,17,2,2,17,0,0,5
8,0,0,0,9,9,0,0,0,0,0,9,0,0,0,8
8,10,0,0,0,0,0,0,0,0,10,0,0,0,0,8
5,8,8,5,8,2,17,0,0,17,2,8,5,8,8,5
endlayer

layer
5,23,23,5,23,2,25,0,13,24,2,23,5,23,23,5
25,7,0,9,0,9,0,0,0,0,9,9,9,0,0,24
25,0,0,0,10,10,0,0,0,0,10,10,0,0,0,24
5,7,0,17,2,2,17,0,0,17,2,2,17,0,6,5
25,0,6,2,11,9,0,0,9,0,0,11,2,7,6,24
2,7,6,2,9,0,0,0,0,0,0,0,2,7,6,2
23,0,0,17,0,0,0,0,0,0,0,0,17,0,6,23
0,0,0,0,0,0,0,18,18,0,0,0,0,0,0,0
0,0,0,0,0,0,0,18,18,0,0,6,0,0,0,0
26,0,0,17,0,0,0,0,0,0,0,0,17,0,0,26
2,7,6,2,7,0,0,0,0,0,0,6,2,7,6,2
25,7,6,2,11,10,0,10,10,0,10,11,2,7,6,24
5,7,0,17,2,2,17,0,0,17,2,2,17,0,6,5
25,0,0,0,9,9,0,0,0,0,9,9,0,0,0,24
25,10,10,10,0,10,0,0,0,0,10,0,10,10,0,24
5,26,26,5,26,2,25,0,0,24,2,26,5,26,26,5
endlayer

layer
5,2,2,5,2,2,2,25,24,2,2,2,5,2,2,5
2,7,9,23,9,23,9,0,0,13,23,9,23,9,6,2
2,7,0,26,10,26,13,0,0,0,26,10,26,0,6,2
5,25,24,5,2,2,17,0,0,17,2,2,5,25,24,5
2,7,6,2,11,28,0,9,9,0,27,11,2,7,6,2
2,25,24,2,29,30,0,0,0,0,30,29,2,25,24,2
2,13,0,17,0,0,0,0,0,0,0,0,17,0,6,2
23,0,0,0,0,0,0,18,18,0,0,6,0,0,0,23
26,0,0,0,0,0,0,18,18,0,0,6,0,0,0,26
2,7,0,17,0,0,0,0,0,0,0,0,17,0,6,2
2,25,24,2,31,30,0,0,0,0,30,31,2,25,24,2
2,7,6,2,11,28,0,10,10,0,27,11,2,7,6,2
5,25,24,5,2,2,17,0,0,17,2,2,5,25,24,5
2,7,0,23,9,23,0,0,0,0,23,9,23,0,6,2
2,10,10,26,10,26,13,0,0,10,26,10,26,10,6,2
5,2,2,5,2,2,2,25,24,2,2,2,5,2,2,5
endlayer

layer
5,2,2,5,32,32,2,2,2,2,32,0,5,2,2,5
2,23,24,2,2,2,25,23,23,24,2,2,2,23,24,2
2,25,26,2,2,2,25,0,0,24,2,2,2,25,26,2
5,2,2,5,2,2,25,13,0,24,2,2,5,2,2,5
32,2,2,2,11,14,9,9,9,9,12,11,2,2,2,32
32,2,2,2,15,20,0,0,0,0,20,15,2,2,2,32
2,23,23,23,0,0,0,0,0,0,0,0,23,23,23,2
2,25,0,13,0,0,0,18,18,0,0,6,0,0,24,2
2,25,13,0,7,0,0,18,18,0,0,6,0,13,24,2
2,26,26,26,0,0,0,0,0,0,0,0,26,26,26,2
32,2,2,2,19,20,0,0,0,0,20,19,2,2,2,32
32,2,2,2,11,14,0,10,10,0,12,11,2,2,2,32
5,2,2,5,2,2,25,0,13,24,2,2,5,2,2,5
2,23,24,2,2,2,25,0,0,24,2,2,2,25,23,2
2,25,26,2,2,2,25,26,26,24,2,2,2,26,24,2
5,2,2,5,32,32,2,2,2,2,32,32,5,2,2,5
endlayer

layer
5,32,32,5,32,32,32,32,32,32,32,32,5,32,32,5
32,2,2,32,32,32,32,2,2,32,32,32,32,2,2,32
32,2,2,32,32,32,32,2,2,32,32,32,32,2,2,32
5,32,32,5,2,2,2,2,2,2,2,2,5,32,32,5
32,32,32,2,1,0,9,9,9,9,0,1,2,32,32,32
32,32,32,2,0,0,0,0,0,0,0,0,2,32,32,32
32,32,32,2,13,0,0,0,0,0,0,0,2,32,32,32
32,2,2,2,7,0,9,18,18,9,0,6,2,2,2,32
32,2,2,2,7,0,10,18,18,0,0,6,2,2,2,32
32,32,32,2,13,0,0,0,0,0,0,0,2,32,32,32
32,32,32,2,0,0,0,0,0,0,0,0,2,32,32,32
32,32,32,2,1,0,0,10,10,0,0,1,2,32,32,32
5,32,32,5,2,2,2,2,2,2,2,2,5,32,32,5
32,2,2,32,32,32,32,2,2,32,32,32,32,2,2,32
32,2,2,32,32,32,32,2,2,32,32,32,32,2,2,32
5,32,32,5,32,32,32,32,32,32,32,32,5,32,32,5
endlayer

layer
1,32,32,1,32,32,32,32,32,32,32,32,1,32,32,1
32,32,32,32,32,32,32,32,32,32,32,32,32,32,32,32
32,32,32,32,32,32,32,32,32,32,32,32,32,32,32,32
1,32,32,1,2,2,2,2,2,2,2,2,1,32,32,1
32,32,32,2,2,2,23,9,9,23,2,2,2,32,32,32
32,32,32,2,2,33,13,0,0,0,33,2,2,32,32,32
32,32,32,2,25,0,0,0,0,0,13,24,2,32,32,32
32,32,32,2,7,0,9,18,18,9,0,6,2,32,32,32
32,32,32,2,7,0,10,18,18,0,0,6,2,32,32,32
32,32,32,2,25,0,0,0,6,0,0,24,2,32,32,32
32,32,32,2,2,33,0,0,0,0,33,2,2,32,32,32
32,32,32,2,2,2,26,10,10,26,2,2,2,32,32,32
1,32,32,1,2,2,2,2,2,2,2,2,1,32,32,1
32,32,32,32,32,32,32,32,32,32,32,32,32,32,32,32
32,32,32,32,32,32,32,32,32,32,32,32,32,32,32,32
1,32,32,1,32,32,32,32,32,32,32,32,1,32,32,1
endlayer

layer
32,32,32,32,32,32,32,32,32,32,32,32,32,32,32,32
32,32,32,32,32,32,32,32,32,32,32,32,32,32,32,32
32,32,32,32,32,32,32,32,32,32,32,32,32,32,32,32
32,32,32,32,32,32,32,32,32,32,32,32,32,32,32,32
32,32,32,32,32,32,2,23,23,2,32,32,32,32,32,32
32,32,32,32,32,2,23,13,13,23,2,32,32,32,32,32
32,32,32,32,2,25,0,7,0,13,24,2,32,32,32,32
32,32,32,32,25,13,9,18,18,9,0,24,32,32,32,32
32,32,32,32,25,0,10,18,18,0,0,24,32,32,32,32
32,32,32,32,2,25,0,7,6,0,24,2,32,32,32,32
32,32,32,32,32,2,26,0,13,26,2,32,32,32,32,32
32,32,32,32,32,32,2,26,26,2,32,32,32,32,32,32
32,32,32,32,32,32,32,32,32,32,32,32,32,32,32,32
32,32,32,32,32,32,32,32,32,32,32,32,32,32,32,32
32,32,32,32,32,32,32,32,32,32,32,32,32,32,32,32
32,32,32,32,32,32,32,32,32,32,32,32,32,32,32,32
endlayer

layer
32,32,32,32,32,32,32,32,32,32,32,32,32,32,32,32
32,32,32,32,32,32,32,32,32,32,32,32,32,32,32,32
32,32,32,32,32,32,32,32,32,32,32,32,32,32,32,32
32,32,32,32,32,32,32,32,32,32,32,32,32,32,32,32
32,32,32,32,32,32,32,32,32,32,32,32,32,32,32,32
32,32,32,32,32,32,2,23,23,2,32,32,32,32,32,32
32,32,32,32,32,2,2,7,13,2,2,32,32,32,32,32
32,32,32,32,32,25,9,18,18,9,24,32,32,32,32,32
32,32,32,32,32,25,10,18,18,13,24,32,32,32,32,32
32,32,32,32,32,2,2,7,6,2,2,32,32,32,32,32
32,32,32,32,32,32,2,26,26,2,32,32,32,32,32,32
32,32,32,32,32,32,32,32,32,32,32,32,32,32,32,32
32,32,32,32,32,32,32,32,32,32,32,32,32,32,32,32
32,32,32,32,32,32,32,32,32,32,32,32,32,32,32,32
32,32,32,32,32,32,32,32,32,32,32,32,32,32,32,32
32,32,32,32,32,32,32,32,32,32,32,32,32,32,32,32
endlayer

layer
32,32,32,32,32,32,32,32,32,32,32,32,32,32,32,32
32,32,32,32,32,32,32,32,32,32,32,32,32,32,32,32
32,32,32,32,32,32,32,32,32,32,32,32,32,32,32,32
32,32,32,32,32,32,32,32,32,32,32,32,32,32,32,32
32,32,32,32,32,32,32,32,32,32,32,32,32,32,32,32
32,32,32,32,32,32,32,32,32,32,32,32,32,32,32,32
32,32,32,32,32,32,2,2,2,2,32,32,32,32,32,32
32,32,32,32,32,32,2,4,4,2,32,32,32,32,32,32
32,32,32,32,32,32,2,4,4,2,32,32,32,32,32,32
32,32,32,32,32,32,2,2,2,2,32,32,32,32,32,32
32,32,32,32,32,32,32,32,32,32,32,32,32,32,32,32
32,32,32,32,32,32,32,32,32,32,32,32,32,32,32,32
32,32,32,32,32,32,32,32,32,32,32,32,32,32,32,32
32,32,32,32,32,32,32,32,32,32,32,32,32,32,32,32
32,32,32,32,32,32,32,32,32,32,32,32,32,32,32,32
32,32,32,32,32,32,32,32,32,32,32,32,32,32,32,32
endlayer

