# Village Butcher (bandit version)
# Created by Ruins mod version 14.9 Ingame Parser
# Created for MC 1.8: 26 Jul 2015
# authoring Player: Jordan_Greywolf
# Note: Put in \templateparser folder.
# Converted to MC 1.8: 20 Mar 2016
# Converted to MC 1.11: 12 Jan 2017
# Converted to MC 1.12: 22 Jun 2017


weight=1
embed_into_distance=5
acceptable_target_blocks=

unacceptable_target_blocks=flowing_lava,lava,cloud,Natura:Cloud,red_mushroom_block,brown_mushroom_block,planks,cobblestone,mossy_cobblestone,iron_bars,glass,redstone_torch,torch,stone_slab,double_stone_slab,oak_stairs,spruce_stairs,birch_stairs,dark_oak_stairs,acacia_stairs,jungle_stairs,slime_congealed,slime_dirt,slime_grass,fence,stone_brick,cobblestone_wall,command_block

dimensions=18,8,11
allowable_overhang=0
max_leveling=3
leveling_buffer=0
preserve_water=0
preserve_lava=0
preserve_plants=1

rule1=0,100,minecraft:log-0
rule2=0,100,minecraft:dirt-1
rule3=0,100,minecraft:stonebrick-3
rule4=0,100,minecraft:grass-0
rule5=0,100,minecraft:cobblestone-0
rule6=0,100,minecraft:water-0
rule7=0,100,minecraft:double_stone_slab-0
rule8=0,100,minecraft:fence-0
rule9=0,100,minecraft:red_flower-0,minecraft:yellow_flower,minecraft:red_flower-1,minecraft:red_flower-2

rule10=0,100,CommandBlock:RUINSTRIGGER /summon Pig ~0 ~0 ~0:@
rule11=0,100,minecraft:ladder-2
rule12=0,100,minecraft:stone_slab-0
rule13=1,100,minecraft:torch-5
rule14=0,100,CommandBlock:RUINSTRIGGER /summon Villager ~0 ~0 ~0 {CustomName:Butcher,Profession:4,Career:1}:@
rule15=0,100,minecraft:fence_gate-1
rule16=0,100,minecraft:crafting_table-0
rule17=0,100,minecraft:oak_stairs-0
rule18=0,100,minecraft:wooden_door-2
rule19=0,100,minecraft:glass_pane-0
rule20=0,100,minecraft:ladder-3
rule21=0,100,minecraft:wooden_door-8
rule22=2,100,WallSign:--*--:Village:Butcher:--*---5
rule23=0,100,minecraft:log-8
rule24=0,100,minecraft:spruce_stairs-3
rule25=0,100,minecraft:log-4
rule26=0,100,minecraft:wooden_slab-8
rule27=0,100,minecraft:planks-0
rule28=0,100,minecraft:wooden_door-1
rule29=0,100,minecraft:wooden_slab-9
rule30=0,100,minecraft:spruce_stairs-2
rule31=0,100,minecraft:oak_stairs-7
rule32=0,100,minecraft:oak_stairs-6
rule33=0,100,minecraft:planks-1
rule34=0,100,minecraft:spruce_stairs-7
rule35=0,100,minecraft:spruce_stairs-6
rule36=0,100,minecraft:spruce_stairs-1
rule37=0,100,minecraft:wooden_slab-1
rule38=0,100,minecraft:spruce_stairs-0

# Highwayman (Bandit Archer)
rule39=0,100,CommandBlock:RUINSTRIGGER /summon Skeleton ~0 ~0 ~0 {HandItems:[{Count:1,id:bow,tag:{display:{Name:"Bandit Bow"},ench:[{id:48,lvl:3},{id:49,lvl:2}]}},{Count:8,id:tipped_arrow,tag:{Potion:"minecraft:strong_harming"}}],ArmorItems:[{Count:1,id:leather_boots},{Count:1,id:leather_leggings},{Count:1,id:leather_chestplate},{Count:1,id:skull,Damage:3,tag:{SkullOwner:MHF_Villager}}],CustomName:Highwayman,HandDropChances:[1.0F,0.0F],ArmorDropChances:[0.5F,0.5F,0.5F,0.0F],Silent:1,PersistenceRequired:1,Health:15.0f}:@


layer
4,4,4,4,4,4,4,2,2,2,2
4,5,5,5,5,5,2,2,2,2,2
4,5,1,1,1,5,2,2,2,2,2
4,5,1,1,1,5,2,2,2,2,2
4,5,1,1,1,5,2,2,2,2,2
4,5,1,1,1,5,2,2,2,2,2
4,5,5,5,5,5,2,2,2,2,2
4,4,5,5,5,4,4,2,2,2,2
endlayer

layer
4,4,4,4,4,4,4,2,2,2,2
4,5,5,5,5,5,2,2,2,2,2
4,5,0,0,0,5,2,2,2,2,2
4,5,0,0,0,5,2,2,2,2,2
4,5,0,0,0,5,2,2,2,2,2
4,5,0,0,0,5,2,2,2,2,2
4,5,5,5,5,5,2,2,2,2,2
4,4,5,5,5,4,4,2,2,2,2
endlayer

layer
4,4,4,4,4,4,4,2,2,2,2
4,5,5,5,5,5,2,2,2,2,2
4,5,0,0,0,5,2,2,2,2,2
4,5,0,0,0,5,2,2,2,2,2
4,5,0,0,0,5,2,2,2,2,2
4,5,0,0,0,5,2,2,2,2,2
4,5,5,5,5,5,2,2,2,2,2
4,4,5,5,5,4,4,2,2,2,2
endlayer


layer
4,4,4,4,4,4,4,2,2,2,2
4,5,5,5,5,5,2,2,2,2,2
4,5,0,0,0,5,2,2,2,2,2
4,5,0,0,0,5,2,2,2,2,2
4,5,0,0,0,5,2,2,2,2,2
4,5,0,0,0,5,2,2,2,2,2
4,5,5,5,5,5,2,2,2,2,2
4,4,5,5,5,4,4,2,2,2,2
endlayer


layer
3,4,4,4,4,4,3,2,2,2,1
4,5,5,5,5,5,2,2,2,2,2
4,5,0,0,0,5,2,2,2,2,2
4,5,0,0,0,5,2,2,2,2,2
4,5,0,0,0,5,6,2,2,2,2
4,5,0,0,0,5,6,2,2,2,2
4,5,5,5,5,5,6,2,2,2,2
3,4,7,3,7,4,3,2,2,2,1
endlayer

layer
7,9,9,9,9,9,7,8,8,8,1
9,5,5,5,5,5,11,0,0,10,8
9,5,1,1,1,5,0,0,0,0,8
9,5,1,1,1,5,0,0,0,0,8
9,5,1,1,1,5,0,0,0,0,8
9,5,1,1,1,5,0,0,0,0,8
9,5,5,5,5,5,0,0,0,10,8
7,9,0,12,0,9,7,8,8,8,1
endlayer

layer
7,0,0,0,0,0,7,13,0,0,1
0,5,5,5,5,5,11,0,0,0,13
0,5,14,14,0,5,0,0,0,0,0
0,5,16,15,8,5,0,0,0,0,0
0,5,39,39,0,5,0,0,0,0,0
0,5,17,0,17,5,0,0,0,0,0
0,5,5,18,5,5,0,0,0,0,13
7,0,0,0,0,0,7,13,0,0,1
endlayer

layer
7,0,0,0,0,0,7,0,0,0,1
0,5,5,19,5,5,11,0,0,0,0
0,5,0,0,20,5,0,0,0,0,0
0,19,0,0,13,19,0,0,0,0,0
0,19,0,0,0,19,0,0,0,0,0
0,5,17,0,17,5,0,0,0,0,0
0,5,5,21,5,5,0,0,0,0,0
7,0,0,0,22,0,7,0,0,0,1
endlayer

layer
24,1,23,23,23,1,23,23,23,23,1
24,25,27,27,27,25,11,26,26,26,25
24,25,27,27,20,25,26,26,26,26,25
24,25,27,27,27,25,26,26,26,26,25
24,25,27,27,27,25,26,26,26,26,25
24,25,27,27,27,25,26,26,26,26,25
24,25,27,27,27,25,26,26,26,26,25
24,1,23,23,23,1,23,23,23,23,1
endlayer

layer
0,1,27,27,27,1,8,8,8,8,8
0,27,0,0,0,27,0,0,0,0,8
0,27,0,0,0,27,0,0,0,0,8
0,27,0,0,0,27,0,0,0,0,8
0,27,0,0,8,27,0,0,0,0,8
0,27,0,0,0,28,0,0,0,0,8
0,27,29,29,29,27,0,0,0,0,8
0,1,27,27,27,1,8,8,8,8,8
endlayer

layer
0,1,27,19,27,1,13,0,0,0,13
0,27,0,0,0,27,0,0,0,0,0
0,19,0,0,0,19,0,0,0,0,0
0,27,0,0,0,19,0,0,0,0,0
0,27,0,0,13,27,0,0,0,0,0
0,19,0,0,0,21,0,0,0,0,0
0,27,0,0,0,27,0,0,0,0,0
0,1,27,19,27,1,13,0,0,0,13
endlayer

layer
0,1,27,27,27,1,0,0,0,0,0
0,27,0,0,0,27,0,0,0,0,0
0,27,0,0,0,27,0,0,0,0,0
0,27,0,0,0,27,0,0,0,0,0
0,27,0,0,0,27,0,0,0,0,0
0,27,0,0,0,27,0,0,0,0,0
0,27,0,0,0,27,0,0,0,0,0
0,1,27,27,27,1,0,0,0,0,0
endlayer

layer
24,1,23,23,23,1,30,0,0,0,0
24,25,32,26,31,25,30,0,0,0,0
24,25,0,0,0,25,30,0,0,0,0
24,25,0,0,0,25,30,0,0,0,0
24,25,0,0,0,25,30,0,0,0,0
24,25,0,0,0,25,30,0,0,0,0
24,25,32,26,31,25,30,0,0,0,0
24,1,23,23,23,1,30,0,0,0,0
endlayer

layer
0,33,0,0,0,33,0,0,0,0,0
0,33,27,19,27,33,0,0,0,0,0
0,33,0,0,0,33,0,0,0,0,0
0,33,0,0,0,33,0,0,0,0,0
0,33,0,0,0,33,0,0,0,0,0
0,33,0,0,0,33,0,0,0,0,0
0,33,27,19,27,33,0,0,0,0,0
0,33,0,0,0,33,0,0,0,0,0
endlayer

layer
0,24,35,0,34,30,0,0,0,0,0
0,24,27,19,27,30,0,0,0,0,0
0,24,35,0,34,30,0,0,0,0,0
0,24,35,0,34,30,0,0,0,0,0
0,24,35,0,34,30,0,0,0,0,0
0,24,35,0,34,30,0,0,0,0,0
0,24,27,19,27,30,0,0,0,0,0
0,24,35,0,34,30,0,0,0,0,0
endlayer

layer
0,0,24,29,30,0,0,0,0,0,0
0,0,24,27,30,0,0,0,0,0,0
0,0,24,29,30,0,0,0,0,0,0
0,0,24,29,30,0,0,0,0,0,0
0,0,24,29,30,0,0,0,0,0,0
0,0,24,29,30,0,0,0,0,0,0
0,0,24,27,30,0,0,0,0,0,0
0,0,24,29,30,0,0,0,0,0,0
endlayer

layer
0,0,0,33,0,0,0,0,0,0,0
0,0,0,36,0,0,0,0,0,0,0
0,0,0,37,0,0,0,0,0,0,0
0,0,0,37,0,0,0,0,0,0,0
0,0,0,37,0,0,0,0,0,0,0
0,0,0,37,0,0,0,0,0,0,0
0,0,0,38,0,0,0,0,0,0,0
0,0,0,33,0,0,0,0,0,0,0
endlayer

layer
0,0,0,36,0,0,0,0,0,0,0
0,0,0,0,0,0,0,0,0,0,0
0,0,0,0,0,0,0,0,0,0,0
0,0,0,0,0,0,0,0,0,0,0
0,0,0,0,0,0,0,0,0,0,0
0,0,0,0,0,0,0,0,0,0,0
0,0,0,0,0,0,0,0,0,0,0
0,0,0,38,0,0,0,0,0,0,0
endlayer

