# Village Tannery Shoppe (bandit version)
# MC 1.7.10; 21 Oct 2014
# Updated to MC 1.8: 26 Jul 2015
# Created by Ruins mod version 13.8 Ingame Parser
# authoring Player: Jordan_Greywolf
# Note: Place in \templateparser folder.
# Updated to MC 1.8: 25 Mar 2016
# Updated to MC 1.9: 29 Apr 2016
# Updated to MC 1.10: 10 Jan 2017
# Updated to MC 1.11: 11 Jan 2017
# Updated to MC 1.12: 22 Jun 2017

# Special Thanks to Syndaryl for villager trade corrections!

# biomesToSpawnIn=brushland,chaparral,field,grassland,healthland,lavender fields,orchard,origin valley,plains,silkglades,sunflower plains

# uniqueMinDistance=2000

weight=1
embed_into_distance=0
acceptable_target_blocks=

unacceptable_target_blocks=flowing_lava,lava,cloud,Natura:Cloud,red_mushroom_block,brown_mushroom_block,planks,cobblestone,mossy_cobblestone,iron_bars,glass,redstone_torch,torch,stone_slab,double_stone_slab,oak_stairs,spruce_stairs,birch_stairs,dark_oak_stairs,acacia_stairs,jungle_stairs,slime_congealed,slime_dirt,slime_grass,fence,stone_brick,cobblestone_wall,command_block

dimensions=15,11,13
allowable_overhang=0
max_leveling=3
leveling_buffer=1
preserve_water=0
preserve_lava=0
preserve_plants=1

rule1=0,100,minecraft:leaves-6
rule2=0,100,minecraft:stonebrick-0,minecraft:stonebrick-0,minecraft:stonebrick-2
rule3=0,100,minecraft:netherrack-0
rule4=0,100,minecraft:stained_hardened_clay-15
rule5=0,100,minecraft:stained_hardened_clay-14
rule6=0,100,minecraft:stone_brick_stairs-1
rule7=0,100,minecraft:stained_hardened_clay-4
rule8=0,100,minecraft:fire-15

# Villager: Leatherworker
rule9=0,100,CommandBlock:RUINSTRIGGER /summon Villager ~0 ~0 ~0 {Profession:4,Career:2,CustomName:Leatherworker,Offers:{Recipes:[{buy:{id:emerald,Count:1},sell:{id:leather_chestplate,Count:1}},{buy:{id:emerald,Count:8},sell:{id:leather_boots,Count:1,tag:{ench:[{id:0,lvl:5},{id:2,lvl:24}],display:{Name:”Boots of the Zephyr”}}}},{buy:{id:emerald,Count:12},sell:{id:leather_leggings,Count:1,tag:{ench:[{id:0,lvl:5},{id:1,lvl:24}],display:{Name:”Pants of the Liar Liar”}}}},{buy:{id:emerald,Count:10},sell:{id:saddle,Count:1}},{buy:{id:emerald,Count:10},sell:{id:leather_helmet,Count:1,tag:{ench:[{id:0,lvl:5},{id:5,lvl:32}],display:{Name:”Cowl of the Sailor”}}}},{buy:{id:emerald,Count:16},sell:{id:minecraft:leather_chestplate,Count:1,tag:{ench:[{id:0,lvl:10},{id:3,lvl:10}],display:{Name:”Tunic of the Miner”}}}}]}}:@

rule10=0,100,IInventory;minecraft:lit_furnace;minecraft:coal#4#1#1-5
rule11=0,100,minecraft:iron_bars-0

# Villager: Tanner
rule12=0,100,CommandBlock:RUINSTRIGGER /summon Villager ~0 ~0 ~0 {Profession:4,Career:2,CustomName:Tanner,Offers:{Recipes:[{buy:{id:saddle,Count:1},sell:{id:leather,Count:1}},{buy:{id:rotten_flesh,Count:64},sell:{id:leather,Count:32}},{buy:{id:item_frame,Count:24},sell:{id:leather,Count:16}},{buy:{id:enchanted_book,Count:1},sell:{id:leather,Count:1}},{buy:{id:leather_helmet,Count:1},sell:{id:leather,Count:2}},{buy:{id:leather_chestplate,Count:1},sell:{id:leather,Count:4}},{buy:{id:leather_leggings,Count:1},sell:{id:leather,Count:3}},{buy:{id:leather_boots,Count:1},sell:{id:leather,Count:1}},{buy:{id:book,Count:12},sell:{id:leather,Count:12}},{buy:{id:leather,Count:64},sell:{id:emerald,Count:1}}]}}:@

rule13=0,100,minecraft:spruce_stairs-7
rule14=0,100,minecraft:wooden_slab-9
rule15=0,100,minecraft:spruce_stairs-6
rule16=0,100,minecraft:crafting_table-0
rule17=0,100,minecraft:fence_gate-3
rule18=0,100,minecraft:spruce_stairs-0
rule19=0,100,minecraft:wooden_slab-1
rule20=0,100,minecraft:spruce_stairs-2
rule21=0,100,minecraft:spruce_stairs-5

# Randomized Flower Pots
rule22=0,100,teBlock;minecraft:flower_pot;{Item:"minecraft:red_flower",x:0,y:0,z:0,Data:0,id:"flower_pot"}-0,teBlock;minecraft:flower_pot;{Item:"minecraft:yellow_flower",x:0,y:0,z:0,Data:0,id:"flower_pot"}-0,teBlock;minecraft:flower_pot;{Item:"minecraft:red_flower",x:0,y:0,z:0,Data:1,id:"flower_pot"}-0,teBlock;minecraft:flower_pot;{Item:"minecraft:red_flower",x:0,y:0,z:0,Data:2,id:"flower_pot"}-0,teBlock;minecraft:flower_pot;{Item:"minecraft:tallgrass",x:0,y:0,z:0,Data:2,id:"flower_pot"}-0,teBlock;minecraft:flower_pot;{Item:"minecraft:sapling",x:0,y:0,z:0,Data:3,id:"flower_pot"}-0,teBlock;minecraft:flower_pot;{Item:"minecraft:sapling",x:0,y:0,z:0,Data:0,id:"flower_pot"}-0,teBlock;minecraft:flower_pot;{Item:"minecraft:sapling",x:0,y:0,z:0,Data:1,id:"flower_pot"}-0,teBlock;minecraft:flower_pot;{Item:"minecraft:cactus",x:0,y:0,z:0,Data:0,id:"flower_pot"}-0,teBlock;minecraft:flower_pot;{Item:"minecraft:red_mushroom",x:0,y:0,z:0,Data:0,id:"flower_pot"}-0

rule23=1,100,minecraft:wooden_door-2
rule24=0,100,minecraft:nether_brick_fence-0
rule25=0,100,minecraft:stained_glass_pane-4
rule26=0,100,minecraft:planks-1
rule27=0,100,minecraft:fence-0
rule28=1,100,minecraft:wooden_door-8
rule29=1,100,minecraft:torch-5
rule30=0,100,minecraft:stone_brick_stairs-5
rule31=0,100,minecraft:noteblock-0
rule32=2,100,WallSign:Ye Olde:Tannery &:Leather:Shoppe-5
rule33=0,100,minecraft:log-9
rule34=0,100,minecraft:spruce_stairs-3
rule35=0,100,minecraft:log-5
rule36=0,100,minecraft:stained_hardened_clay-0
rule37=0,100,minecraft:stained_hardened_clay-8
rule38=0,100,minecraft:wool-12
rule39=0,100,minecraft:planks-5
rule40=0,100,minecraft:log-1
rule41=0,100,minecraft:spruce_stairs-1
rule42=0,100,minecraft:stone_brick_stairs-6
rule43=0,100,minecraft:stone_brick_stairs-7
rule44=0,100,minecraft:cobblestone_wall-0

# Highwayman (Bandit Archer)
rule45=0,100,CommandBlock:RUINSTRIGGER /summon Skeleton ~0 ~0 ~0 {HandItems:[{Count:1,id:bow,tag:{display:{Name:"Bandit Bow"},ench:[{id:48,lvl:3},{id:49,lvl:2}]}},{Count:8,id:tipped_arrow,tag:{Potion:"minecraft:strong_harming"}}],ArmorItems:[{Count:1,id:leather_boots},{Count:1,id:leather_leggings},{Count:1,id:leather_chestplate},{Count:1,id:skull,Damage:3,tag:{SkullOwner:MHF_Villager}}],CustomName:Highwayman,HandDropChances:[1.0F,0.0F],ArmorDropChances:[0.5F,0.5F,0.5F,0.0F],Silent:1,PersistenceRequired:1,Health:15.0f}:@



layer
1,1,1,1,1,2,2,2,1,1,1,1,1
1,2,2,2,2,2,3,2,2,2,2,2,1
1,2,4,5,4,2,2,2,4,5,4,2,1
1,2,5,4,5,4,5,4,5,4,5,2,1
1,2,4,5,4,5,4,5,4,5,4,2,1
1,2,5,4,5,4,5,4,5,4,5,2,1
1,2,4,5,4,5,4,5,4,5,4,2,1
1,2,5,4,5,4,5,4,5,4,5,2,1
1,2,4,5,4,5,4,5,4,5,4,2,1
1,2,2,2,2,2,2,2,2,2,2,2,1
1,1,1,1,1,2,6,2,1,1,1,1,1
endlayer

layer
0,0,0,0,0,2,2,2,0,0,0,0,0
0,2,2,7,7,2,8,2,7,7,2,2,0
0,7,12,0,0,10,11,10,0,0,9,7,0
0,7,0,0,0,0,0,0,0,0,0,7,0
0,7,15,14,13,16,17,16,15,14,13,7,0
0,7,0,0,0,45,0,45,0,0,0,7,0
0,7,20,0,19,0,0,0,0,0,18,7,0
0,7,20,0,19,0,0,0,0,0,21,7,0
0,7,22,0,0,0,0,0,0,0,22,7,0
0,2,2,7,7,7,23,7,7,7,2,2,0
0,0,0,0,0,24,0,24,0,0,0,0,0
endlayer

layer
0,0,0,0,0,2,2,2,0,0,0,0,0
0,2,7,7,25,2,0,2,25,7,7,2,0
0,2,0,0,0,0,0,0,0,0,0,2,0
0,7,0,0,0,0,0,0,0,0,0,7,0
0,25,0,0,0,0,0,0,0,0,0,25,0
0,7,0,0,0,0,0,0,0,0,0,7,0
0,25,0,0,0,0,0,0,0,0,0,25,0
0,7,0,0,0,0,0,0,0,0,18,7,0
0,2,0,0,0,27,0,27,0,0,26,2,0
0,2,7,7,25,7,28,7,25,7,7,2,0
0,0,0,0,0,29,0,29,0,0,0,0,0
endlayer

layer
0,0,0,0,0,2,2,2,0,0,0,0,0
0,2,2,7,25,2,0,2,25,7,2,2,0
0,7,0,0,0,30,30,30,0,0,0,7,0
0,7,0,0,0,0,0,0,0,0,0,7,0
0,25,27,27,27,27,27,27,27,27,27,25,0
0,7,0,0,0,0,0,0,0,0,0,7,0
0,25,0,0,0,0,0,0,0,0,0,25,0
0,7,0,0,0,0,0,0,0,0,0,7,0
0,7,0,0,0,29,0,29,0,13,18,7,0
0,2,2,7,25,7,31,7,25,7,2,2,0
0,0,0,0,0,0,32,0,0,0,0,0,0
endlayer

layer
0,24,0,24,0,2,2,2,0,24,0,24,0
24,2,7,7,7,2,0,2,7,7,7,2,24
0,2,0,0,0,2,2,2,0,0,0,2,0
24,7,0,0,0,0,0,0,0,0,0,7,24
0,7,27,0,0,0,0,0,0,0,27,7,0
24,7,0,0,0,0,0,0,0,0,0,7,24
0,7,0,0,0,0,0,0,0,0,0,7,0
24,7,0,0,0,0,0,0,0,0,0,7,24
0,2,0,0,0,0,0,0,13,20,0,2,0
24,2,7,7,7,7,7,7,7,7,7,2,24
0,24,0,24,0,24,0,24,0,24,0,24,0
endlayer

layer
34,26,33,33,33,2,2,2,33,33,33,26,20
34,35,36,36,36,2,3,2,36,36,36,35,20
34,35,36,36,36,2,2,2,36,36,36,35,20
34,35,36,36,36,36,36,36,36,36,36,35,20
34,35,36,36,36,36,36,36,36,36,36,35,20
34,35,36,36,36,36,36,36,36,36,36,35,20
34,35,36,36,36,36,36,36,36,36,36,35,20
34,35,36,36,36,36,36,36,36,36,0,35,20
34,35,36,36,36,36,36,36,20,0,0,35,20
34,35,36,36,36,36,36,36,36,36,36,35,20
34,26,33,33,33,33,33,33,33,33,33,26,20
endlayer

layer
0,26,37,37,37,2,2,2,37,37,37,26,0
0,26,0,0,0,2,8,2,0,0,0,26,0
0,26,0,0,0,11,11,11,0,0,0,26,0
0,26,0,0,0,0,0,0,0,0,0,26,0
0,26,0,0,38,18,18,18,38,0,0,26,0
0,25,0,0,0,0,0,0,0,0,0,25,0
0,26,0,0,0,45,0,45,0,0,0,26,0
0,26,0,0,0,0,0,0,0,0,0,26,0
0,26,0,0,0,0,0,0,0,0,0,26,0
0,26,22,0,0,0,0,0,0,0,22,26,0
0,26,37,25,37,39,40,39,37,25,37,26,0
endlayer

layer
0,34,26,37,39,2,2,2,39,37,26,20,0
0,34,15,0,0,2,0,2,0,0,13,20,0
0,34,15,0,0,0,0,0,0,0,13,20,0
0,34,15,0,0,0,0,0,0,0,13,20,0
0,26,15,0,0,0,0,0,0,0,13,26,0
0,25,0,0,0,0,0,0,0,0,0,25,0
0,26,15,0,0,0,0,0,0,0,13,26,0
0,34,15,0,0,0,0,0,0,0,13,20,0
0,34,15,0,0,0,0,0,0,0,13,20,0
0,34,15,0,0,0,0,0,0,0,13,20,0
0,34,26,25,39,37,40,37,39,25,26,20,0
endlayer

layer
0,0,26,39,37,2,2,2,37,39,26,0,0
0,0,26,0,0,2,0,2,0,0,26,0,0
0,0,26,0,0,30,30,30,0,0,26,0,0
0,0,26,0,0,0,0,0,0,0,26,0,0
0,18,26,0,0,0,0,0,0,0,26,18,0
0,13,0,0,0,0,27,0,0,0,0,15,0
0,41,26,0,0,27,27,27,0,0,26,41,0
0,0,26,0,0,0,27,0,0,0,26,0,0
0,0,26,0,0,0,0,0,0,0,26,0,0
0,0,26,0,0,0,0,0,0,0,26,0,0
0,0,26,39,37,37,40,37,37,39,26,0,0
endlayer

layer
0,0,34,26,37,2,2,2,37,26,20,0,0
0,0,34,15,43,2,0,2,42,13,20,0,0
0,0,34,15,0,22,6,22,0,13,20,0,0
0,0,34,15,0,0,0,0,0,13,20,0,0
0,0,34,15,0,0,0,0,0,13,20,0,0
0,19,34,15,0,0,29,0,0,13,20,19,0
0,0,34,15,0,29,27,29,0,13,20,0,0
0,0,34,15,0,0,29,0,0,13,20,0,0
0,0,34,15,0,0,0,0,0,13,20,0,0
0,0,34,15,0,0,0,0,0,13,20,0,0
0,0,34,26,37,37,40,37,37,26,20,0,0
endlayer

layer
0,0,0,34,26,2,2,2,26,20,0,0,0
0,0,0,34,2,2,2,2,2,20,0,0,0
0,0,0,34,2,30,30,30,2,20,0,0,0
0,0,0,34,15,0,0,0,13,20,0,0,0
0,0,0,34,15,0,0,0,13,20,0,0,0
0,0,0,34,15,0,0,0,13,20,0,0,0
0,0,0,34,15,0,27,0,13,20,0,0,0
0,0,0,34,15,0,0,0,13,20,0,0,0
0,0,0,34,15,0,0,0,13,20,0,0,0
0,0,0,34,15,0,0,0,13,20,0,0,0
0,0,0,34,26,37,40,37,26,20,0,0,0
endlayer

layer
0,0,0,0,19,34,2,20,19,0,0,0,0
0,0,0,0,19,34,2,20,19,0,0,0,0
0,0,0,0,19,34,26,20,19,0,0,0,0
0,0,0,0,19,34,26,20,19,0,0,0,0
0,0,0,0,19,34,26,20,19,0,0,0,0
0,0,0,0,19,34,26,20,19,0,0,0,0
0,0,0,0,19,34,26,20,19,0,0,0,0
0,0,0,0,19,34,26,20,19,0,0,0,0
0,0,0,0,19,34,26,20,19,0,0,0,0
0,0,0,0,19,34,26,20,19,0,0,0,0
0,0,0,0,19,34,26,20,19,0,0,0,0
endlayer

layer
0,0,0,0,0,0,2,0,0,0,0,0,0
0,0,0,0,0,0,6,0,0,0,0,0,0
0,0,0,0,0,0,24,0,0,0,0,0,0
0,0,0,0,0,0,24,0,0,0,0,0,0
0,0,0,0,0,0,24,0,0,0,0,0,0
0,0,0,0,0,0,24,0,0,0,0,0,0
0,0,0,0,0,0,24,0,0,0,0,0,0
0,0,0,0,0,0,24,0,0,0,0,0,0
0,0,0,0,0,0,24,0,0,0,0,0,0
0,0,0,0,0,0,18,0,0,0,0,0,0
0,0,0,0,0,0,26,0,0,0,0,0,0
endlayer

layer
0,0,0,0,0,0,2,0,0,0,0,0,0
0,0,0,0,0,0,0,0,0,0,0,0,0
0,0,0,0,0,0,0,0,0,0,0,0,0
0,0,0,0,0,0,0,0,0,0,0,0,0
0,0,0,0,0,0,0,0,0,0,0,0,0
0,0,0,0,0,0,0,0,0,0,0,0,0
0,0,0,0,0,0,0,0,0,0,0,0,0
0,0,0,0,0,0,0,0,0,0,0,0,0
0,0,0,0,0,0,0,0,0,0,0,0,0
0,0,0,0,0,0,0,0,0,0,0,0,0
0,0,0,0,0,0,26,0,0,0,0,0,0
endlayer

layer
0,0,0,0,0,0,44,0,0,0,0,0,0
0,0,0,0,0,0,0,0,0,0,0,0,0
0,0,0,0,0,0,0,0,0,0,0,0,0
0,0,0,0,0,0,0,0,0,0,0,0,0
0,0,0,0,0,0,0,0,0,0,0,0,0
0,0,0,0,0,0,0,0,0,0,0,0,0
0,0,0,0,0,0,0,0,0,0,0,0,0
0,0,0,0,0,0,0,0,0,0,0,0,0
0,0,0,0,0,0,0,0,0,0,0,0,0
0,0,0,0,0,0,0,0,0,0,0,0,0
0,0,0,0,0,0,18,0,0,0,0,0,0
endlayer

