# War Tower A
# MC 1.7.10; 31 Oct 2014
# Created by Ruins mod version 14.0 Ingame Parser
# authoring Player: Jordan_Greywolf
# Updated to MC 1.8: 20 Mar 2016
# Updated to MC 1.9: 24 Apr 2016
# Updated to MC 1.11: 12 Jan 2017
# Updated to MC 1.12: 22 Jun 2017

weight=1
embed_into_distance=0
acceptable_target_blocks=
unacceptable_target_blocks=
dimensions=16,23,23
allowable_overhang=0
max_leveling=0
leveling_buffer=0
preserve_water=0
preserve_lava=0
preserve_plants=1

rule1=0,100,minecraft:obsidian-0
rule2=0,100,minecraft:quartz_block-1
rule3=0,100,minecraft:stonebrick-3
rule4=0,100,minecraft:stone_slab-7
rule5=0,100,minecraft:stone_slab-0
rule6=0,100,minecraft:double_stone_slab-7
rule7=0,100,minecraft:stone_slab-8
rule8=0,100,minecraft:dirt-2
rule9=0,100,minecraft:nether_brick_fence-0
rule10=0,100,minecraft:log-12
rule11=0,100,minecraft:nether_brick_fence-0
rule12=0,100,minecraft:leaves-4
rule13=1,100,minecraft:redstone_torch-5
rule14=0,100,minecraft:double_stone_slab-0
rule15=0,100,MobSpawner:Zombie
rule16=0,100,ChestGenHook:chests/simple_dungeon:3-5
rule17=0,100,IInventory;minecraft:trapped_chest;minecraft:clay#16#0#1-4
rule18=0,100,ChestGenHook:chests/spawn_bonus_chest:6-3
rule19=0,100,ChestGenHook:chests/jungle_temple:3-2
rule20=0,100,CommandBlock:/testruin TP_WarTower1B ~0 ~0 ~0:@
rule21=0,100,ChestGenHook:chests/desert_pyramid:2-4

# Earth Guardian
rule22=0,100,CommandBlock:RUINSTRIGGER /summon Skeleton ~0 ~0 ~0 {HandItems:[{Count:1,id:diamond_shovel,tag:{display:{Name:"Earth Sledge"},ench:[{id:16,lvl:5},{id:33,lvl:1},{id:19,lvl:5}]}},{}],ArmorItems:[{Count:1,id:leather_boots},{Count:1,id:leather_leggings},{Count:1,id:leather_chestplate},{Count:1,id:dropper,tag:{display:{Name:"Earth Head"},ench:[{id:5,lvl:10},{id:0,lvl:5}]}}],CustomName:"Earth Guardian",Health:65.0f,Attributes:[{Name:generic.knockbackResistance,Base:1.0},{Name:generic.movementSpeed,Base:0.3}],HandDropChances:[1.0F,0.0F],ArmorDropChances:[0.0F,0.0F,0.0F,0.2F],ActiveEffects:[{Id:10,Amplifier:1,Duration:999999,Ambient:1},{Id:5,Amplifier:1,Duration:999999,Ambient:1}],Silent:1,PersistenceRequired:1}:@



layer
0,0,0,0,0,0,0,0,1,1,1,1,1,1,1,0,0,0,0,0,0,0,0
0,0,0,0,0,0,1,1,1,1,4,5,4,1,1,1,1,0,0,0,0,0,0
0,0,0,0,1,1,1,1,1,1,5,4,5,1,1,1,1,1,1,0,0,0,0
0,0,0,1,1,1,1,1,1,5,0,0,0,0,1,1,1,1,1,1,0,0,0
0,0,1,1,1,1,1,0,7,6,0,0,0,0,0,0,1,1,1,1,1,0,0
0,0,1,1,1,1,0,0,0,0,0,0,0,0,0,0,0,1,1,1,1,0,0
0,1,1,1,1,0,5,4,5,0,0,0,0,0,5,4,5,0,1,1,1,1,0
0,1,1,1,0,0,4,8,4,0,0,0,0,0,4,8,4,0,0,1,1,1,0
1,1,1,1,0,0,5,4,5,0,0,0,0,0,5,4,5,0,7,1,1,1,1
1,1,1,0,0,0,0,0,0,0,0,0,0,0,0,0,0,0,6,5,1,1,1
1,4,5,0,0,0,0,0,0,0,5,0,5,0,0,0,0,0,0,0,5,4,1
1,5,4,0,0,0,0,0,0,0,0,0,0,0,0,0,0,0,0,0,4,5,1
1,4,5,0,0,0,0,0,0,0,5,0,5,0,0,0,0,0,0,0,5,4,1
1,1,1,5,6,0,0,0,0,0,0,0,0,0,0,0,0,0,0,0,1,1,1
1,1,1,1,7,0,5,4,5,0,0,0,0,0,5,4,5,0,0,1,1,1,1
0,1,1,1,0,0,4,8,4,0,0,0,0,0,4,8,4,0,0,1,1,1,0
0,1,1,1,1,0,5,4,5,0,0,0,0,0,5,4,5,0,1,1,1,1,0
0,0,1,1,1,1,0,0,0,0,0,0,0,0,0,0,0,1,1,1,1,0,0
0,0,1,1,1,1,1,0,0,0,0,0,0,6,7,0,1,1,1,1,1,0,0
0,0,0,1,1,1,1,1,1,0,0,0,0,5,1,1,1,1,1,1,0,0,0
0,0,0,0,1,1,1,1,1,1,5,4,5,1,1,1,1,1,1,0,0,0,0
0,0,0,0,0,0,1,1,1,1,4,5,4,1,1,1,1,0,0,0,0,0,0
0,0,0,0,0,0,0,0,1,1,1,1,1,1,1,0,0,0,0,0,0,0,0
endlayer

layer
0,0,0,0,0,0,0,0,0,9,9,9,9,9,0,0,0,0,0,0,0,0,0
0,0,0,0,0,0,0,0,0,1,0,0,0,1,0,0,0,0,0,0,0,0,0
0,0,0,0,0,0,0,0,1,1,0,0,0,1,1,0,0,0,0,0,0,0,0
0,0,0,0,0,0,1,1,1,0,0,0,0,0,1,1,1,0,0,0,0,0,0
0,0,0,0,1,1,1,6,5,0,0,0,0,0,0,0,1,1,1,0,0,0,0
0,0,0,0,1,1,0,7,0,0,0,0,0,0,0,0,0,1,1,0,0,0,0
0,0,0,1,1,0,0,0,0,0,0,0,0,0,0,0,0,0,1,1,0,0,0
0,0,0,1,0,0,0,10,0,0,0,0,0,0,0,10,0,7,6,1,0,0,0
0,0,1,1,0,0,0,0,0,0,0,0,0,0,0,0,0,0,5,1,1,0,0
9,1,1,0,0,0,0,0,0,0,0,0,0,0,0,0,0,0,0,0,1,1,9
9,0,0,0,0,0,0,0,0,0,0,0,0,0,0,0,0,0,0,0,0,0,9
9,0,0,0,0,0,0,0,0,0,0,0,0,0,0,0,0,0,0,0,0,0,9
9,0,0,0,0,0,0,0,0,0,0,0,0,0,0,0,0,0,0,0,0,0,9
9,1,1,0,0,0,0,0,0,0,0,0,0,0,0,0,0,0,0,0,1,1,9
0,0,1,1,5,0,0,0,0,0,0,0,0,0,0,0,0,0,0,1,1,0,0
0,0,0,1,6,7,0,10,0,0,0,0,0,0,0,10,0,0,0,1,0,0,0
0,0,0,1,1,0,0,0,0,0,0,0,0,0,0,0,0,0,1,1,0,0,0
0,0,0,0,1,1,0,0,0,0,0,0,0,0,0,7,0,1,1,0,0,0,0
0,0,0,0,1,1,1,0,0,0,0,0,0,0,5,6,1,1,1,0,0,0,0
0,0,0,0,0,0,1,1,1,0,0,0,0,0,1,1,1,0,0,0,0,0,0
0,0,0,0,0,0,0,0,1,1,0,0,0,1,1,0,0,0,0,0,0,0,0
0,0,0,0,0,0,0,0,0,1,0,0,0,1,0,0,0,0,0,0,0,0,0
0,0,0,0,0,0,0,0,0,9,9,9,9,9,0,0,0,0,0,0,0,0,0
endlayer

layer
0,0,0,0,0,0,0,0,0,9,0,0,0,9,0,0,0,0,0,0,0,0,0
0,0,0,0,0,0,0,0,0,1,0,0,0,1,0,0,0,0,0,0,0,0,0
0,0,0,0,0,0,0,0,1,1,0,0,0,1,1,0,0,0,0,0,0,0,0
0,0,0,0,0,0,1,1,1,0,0,0,0,0,1,1,1,0,0,0,0,0,0
0,0,0,0,1,1,1,0,0,0,0,0,0,0,0,11,1,1,1,0,0,0,0
0,0,0,0,1,1,6,5,0,0,0,0,0,0,0,0,0,1,1,0,0,0,0
0,0,0,1,1,0,7,12,12,0,0,0,0,0,12,12,7,6,1,1,0,0,0
0,0,0,1,11,0,12,10,12,0,0,0,0,0,10,10,12,5,0,1,0,0,0
0,0,1,1,0,0,12,10,12,0,0,0,0,0,12,12,12,0,0,1,1,0,0
9,1,1,0,0,0,0,0,0,0,0,0,0,0,0,0,0,0,0,0,1,1,9
0,0,0,0,0,0,0,0,0,0,0,0,0,0,0,0,0,0,0,0,0,0,0
0,0,0,0,0,0,0,0,0,0,0,0,0,0,0,0,0,0,0,0,0,0,0
0,0,0,0,0,0,0,0,0,0,0,0,0,0,0,0,0,0,0,0,0,0,0
9,1,1,0,0,0,0,0,0,0,0,0,0,0,0,0,0,0,0,0,1,1,9
0,0,1,1,0,0,12,12,12,0,0,0,0,0,12,10,12,0,0,1,1,0,0
0,0,0,1,0,5,12,10,10,0,0,0,0,0,12,10,12,0,11,1,0,0,0
0,0,0,1,1,6,7,12,12,0,0,0,0,0,12,12,7,0,1,1,0,0,0
0,0,0,0,1,1,0,0,0,0,0,0,0,0,0,5,6,1,1,0,0,0,0
0,0,0,0,1,1,1,11,0,0,0,0,0,0,0,0,1,1,1,0,0,0,0
0,0,0,0,0,0,1,1,1,0,0,0,0,0,1,1,1,0,0,0,0,0,0
0,0,0,0,0,0,0,0,1,1,0,0,0,1,1,0,0,0,0,0,0,0,0
0,0,0,0,0,0,0,0,0,1,0,0,0,1,0,0,0,0,0,0,0,0,0
0,0,0,0,0,0,0,0,0,9,0,0,0,9,0,0,0,0,0,0,0,0,0
endlayer

layer
0,0,0,0,0,0,0,0,0,13,0,0,0,13,0,0,0,0,0,0,0,0,0
0,0,0,0,0,0,0,0,0,1,0,0,0,1,0,0,0,0,0,0,0,0,0
0,0,0,0,0,0,0,0,1,1,0,0,0,1,1,0,0,0,0,0,0,0,0
0,0,0,0,0,0,1,1,1,0,0,0,0,0,1,1,1,0,0,0,0,0,0
0,0,0,0,1,1,1,0,0,0,0,0,0,0,0,13,1,1,1,0,0,0,0
0,0,0,0,1,1,0,0,0,0,0,0,0,0,0,7,6,1,1,0,0,0,0
0,0,0,1,1,6,5,0,0,0,0,0,0,0,0,0,5,0,1,1,0,0,0
0,0,0,1,13,7,0,12,0,0,0,0,0,0,10,12,0,0,0,1,0,0,0
0,0,1,1,0,0,0,10,10,0,0,0,0,0,10,0,0,0,0,1,1,0,0
13,1,1,0,0,0,0,0,0,0,0,0,0,0,0,0,0,0,0,0,1,1,13
0,0,0,0,0,0,0,0,0,0,0,0,0,0,0,0,0,0,0,0,0,0,0
0,0,0,0,0,0,0,0,0,0,0,0,0,0,0,0,0,0,0,0,0,0,0
0,0,0,0,0,0,0,0,0,0,0,0,0,0,0,0,0,0,0,0,0,0,0
13,1,1,0,0,0,0,0,0,0,0,0,0,0,0,0,0,0,0,0,1,1,13
0,0,1,1,0,0,0,0,10,0,0,0,0,0,10,10,0,0,0,1,1,0,0
0,0,0,1,0,0,0,12,10,0,0,0,0,0,0,12,0,7,13,1,0,0,0
0,0,0,1,1,0,5,0,0,0,0,0,0,0,0,0,5,6,1,1,0,0,0
0,0,0,0,1,1,6,7,0,0,0,0,0,0,0,0,0,1,1,0,0,0,0
0,0,0,0,1,1,1,13,0,0,0,0,0,0,0,0,1,1,1,0,0,0,0
0,0,0,0,0,0,1,1,1,0,0,0,0,0,1,1,1,0,0,0,0,0,0
0,0,0,0,0,0,0,0,1,1,0,0,0,1,1,0,0,0,0,0,0,0,0
0,0,0,0,0,0,0,0,0,1,0,0,0,1,0,0,0,0,0,0,0,0,0
0,0,0,0,0,0,0,0,0,13,0,0,0,13,0,0,0,0,0,0,0,0,0
endlayer

layer
0,0,0,0,0,0,0,0,0,0,0,0,0,0,0,0,0,0,0,0,0,0,0
0,0,0,0,0,0,0,0,0,1,0,0,0,1,0,0,0,0,0,0,0,0,0
0,0,0,0,0,0,0,0,1,1,0,0,0,1,1,0,0,0,0,0,0,0,0
0,0,0,0,0,0,1,1,1,0,0,0,0,0,1,1,1,0,0,0,0,0,0
0,0,0,0,1,1,1,0,0,0,0,0,0,0,7,6,1,1,1,0,0,0,0
0,0,0,0,1,1,0,0,0,0,0,0,0,0,0,5,0,1,1,0,0,0,0
0,0,0,1,1,0,0,0,0,0,0,0,0,0,0,0,0,0,1,1,0,0,0
0,0,0,1,6,5,0,0,0,0,0,0,0,0,0,0,0,0,0,1,0,0,0
0,0,1,1,7,0,0,0,10,0,0,0,0,10,10,0,0,0,0,1,1,0,0
0,1,1,0,0,0,0,0,10,0,0,0,0,0,0,0,0,0,0,0,1,1,0
0,0,0,0,0,0,0,0,0,0,0,0,0,0,0,0,0,0,0,0,0,0,0
0,0,0,0,0,0,0,0,0,0,0,10,0,0,0,0,0,0,0,0,0,0,0
0,0,0,0,0,0,0,0,0,0,0,0,0,0,0,0,0,0,0,0,0,0,0
0,1,1,0,0,0,0,0,0,0,0,0,0,0,10,0,0,0,0,0,1,1,0
0,0,1,1,0,0,0,0,10,10,0,0,0,0,10,0,0,0,7,1,1,0,0
0,0,0,1,0,0,0,0,0,0,0,0,0,0,0,0,0,5,6,1,0,0,0
0,0,0,1,1,0,0,0,0,0,0,0,0,0,0,0,0,0,1,1,0,0,0
0,0,0,0,1,1,0,5,0,0,0,0,0,0,0,0,0,1,1,0,0,0,0
0,0,0,0,1,1,1,6,7,0,0,0,0,0,0,0,1,1,1,0,0,0,0
0,0,0,0,0,0,1,1,1,0,0,0,0,0,1,1,1,0,0,0,0,0,0
0,0,0,0,0,0,0,0,1,1,0,0,0,1,1,0,0,0,0,0,0,0,0
0,0,0,0,0,0,0,0,0,1,0,0,0,1,0,0,0,0,0,0,0,0,0
0,0,0,0,0,0,0,0,0,0,0,0,0,0,0,0,0,0,0,0,0,0,0
endlayer

layer
0,0,0,0,0,0,0,0,0,0,0,0,0,0,0,0,0,0,0,0,0,0,0
0,0,0,0,0,0,0,0,0,1,1,0,1,1,0,0,0,0,0,0,0,0,0
0,0,0,0,0,0,0,0,1,1,0,0,0,1,1,0,0,0,0,0,0,0,0
0,0,0,0,0,0,1,1,1,0,0,0,0,7,1,1,1,0,0,0,0,0,0
0,0,0,0,1,1,1,0,0,0,0,0,0,6,5,0,1,1,1,0,0,0,0
0,0,0,0,1,1,0,0,0,0,0,0,0,0,0,0,0,1,1,0,0,0,0
0,0,0,1,1,0,0,0,0,0,0,0,0,0,0,0,0,0,1,1,0,0,0
0,0,0,1,0,0,0,0,0,0,0,0,12,12,12,0,0,0,0,1,0,0,0
0,0,1,1,5,0,0,12,12,12,0,0,12,10,12,0,0,0,0,1,1,0,0
0,1,1,7,6,0,0,12,10,10,0,0,12,10,12,0,0,0,0,0,1,1,0
0,1,0,0,0,0,0,12,12,12,12,12,12,0,0,0,0,0,0,0,0,1,0
0,0,0,0,0,0,0,0,0,0,12,10,12,0,0,0,0,0,0,0,0,0,0
0,1,0,0,0,0,0,0,0,0,12,12,12,12,12,12,0,0,0,0,0,1,0
0,1,1,0,0,0,0,0,12,10,12,0,0,10,10,12,0,0,6,7,1,1,0
0,0,1,1,0,0,0,0,12,10,12,0,0,12,12,12,0,0,5,1,1,0,0
0,0,0,1,0,0,0,0,12,12,12,0,0,0,0,0,0,0,0,1,0,0,0
0,0,0,1,1,0,0,0,0,0,0,0,0,0,0,0,0,0,1,1,0,0,0
0,0,0,0,1,1,0,0,0,0,0,0,0,0,0,0,0,1,1,0,0,0,0
0,0,0,0,1,1,1,0,5,6,0,0,0,0,0,0,1,1,1,0,0,0,0
0,0,0,0,0,0,1,1,1,7,0,0,0,0,1,1,1,0,0,0,0,0,0
0,0,0,0,0,0,0,0,1,1,0,0,0,1,1,0,0,0,0,0,0,0,0
0,0,0,0,0,0,0,0,0,1,1,0,1,1,0,0,0,0,0,0,0,0,0
0,0,0,0,0,0,0,0,0,0,0,0,0,0,0,0,0,0,0,0,0,0,0
endlayer

layer
0,0,0,0,0,0,0,0,1,1,1,1,1,1,1,0,0,0,0,0,0,0,0
0,0,0,0,0,0,1,1,1,1,1,1,1,1,1,1,1,0,0,0,0,0,0
0,0,0,0,1,1,1,1,1,1,1,1,1,1,1,1,1,1,1,0,0,0,0
0,0,0,1,1,1,1,1,1,7,6,14,6,5,1,1,1,1,1,1,0,0,0
0,0,1,1,1,1,1,0,0,0,0,2,0,0,0,0,1,1,1,1,1,0,0
0,0,1,1,1,1,0,0,0,0,0,3,0,0,0,0,0,1,1,1,1,0,0
0,1,1,1,1,0,0,0,0,0,0,2,0,0,0,0,0,0,1,1,1,1,0
0,1,1,1,0,0,0,0,0,0,0,3,0,0,0,0,0,0,0,1,1,1,0
1,1,1,1,0,0,0,0,0,0,0,2,0,12,0,0,0,0,0,1,1,1,1
1,1,1,5,0,0,0,0,12,10,10,3,0,10,0,0,0,0,0,7,1,1,1
1,1,1,6,0,0,0,0,0,0,12,10,12,10,0,0,0,0,0,6,1,1,1
1,1,1,14,2,3,2,3,2,3,10,10,10,3,2,3,2,3,2,14,1,1,1
1,1,1,6,0,0,0,0,0,10,12,10,12,0,0,0,0,0,0,6,1,1,1
1,1,1,7,0,0,0,0,0,10,0,3,10,10,12,0,0,0,0,5,1,1,1
1,1,1,1,0,0,0,0,0,12,0,2,0,0,0,0,0,0,0,1,1,1,1
0,1,1,1,0,0,0,0,0,0,0,3,0,0,0,0,0,0,0,1,1,1,0
0,1,1,1,1,0,0,0,0,0,0,2,0,0,0,0,0,0,1,1,1,1,0
0,0,1,1,1,1,0,0,0,0,0,3,0,0,0,0,0,1,1,1,1,0,0
0,0,1,1,1,1,1,0,0,0,0,2,0,0,0,0,1,1,1,1,1,0,0
0,0,0,1,1,1,1,1,1,5,6,14,6,7,1,1,1,1,1,1,0,0,0
0,0,0,0,1,1,1,1,1,1,1,1,1,1,1,1,1,1,1,0,0,0,0
0,0,0,0,0,0,1,1,1,1,1,1,1,1,1,1,1,0,0,0,0,0,0
0,0,0,0,0,0,0,0,1,1,1,1,1,1,1,0,0,0,0,0,0,0,0
endlayer

layer
0,0,0,0,0,0,0,0,1,1,1,1,1,1,1,0,0,0,0,0,0,0,0
0,0,0,0,0,0,1,1,1,1,4,5,4,1,1,1,1,0,0,0,0,0,0
0,0,0,0,1,1,1,1,1,1,5,4,5,1,1,1,1,1,1,0,0,0,0
0,0,0,1,1,1,1,1,1,5,0,0,0,0,1,1,1,1,1,1,0,0,0
0,0,1,1,1,1,1,0,7,6,0,0,0,0,0,0,1,1,1,1,1,0,0
0,0,1,1,1,1,0,0,0,0,0,0,0,0,0,0,0,1,1,1,1,0,0
0,1,1,1,1,0,0,0,0,0,0,0,0,0,0,0,0,0,1,1,1,1,0
0,1,1,1,0,0,0,0,0,0,0,0,0,0,0,0,0,0,0,1,1,1,0
1,1,1,1,0,0,0,0,0,0,0,0,0,0,0,0,0,0,7,1,1,1,1
1,1,1,0,0,0,0,0,0,0,10,0,0,0,0,0,0,0,6,5,1,1,1
1,4,5,0,0,0,0,0,0,0,3,0,3,10,0,0,0,0,0,0,5,4,1
1,5,4,0,0,0,0,0,0,0,0,0,0,0,0,0,0,0,0,0,4,5,1
1,4,5,0,0,0,0,0,0,10,3,0,3,0,0,0,0,0,0,0,5,4,1
1,1,1,5,6,0,0,0,0,0,0,0,10,0,0,0,0,0,0,0,1,1,1
1,1,1,1,7,0,0,0,0,0,0,0,0,0,0,0,0,0,0,1,1,1,1
0,1,1,1,0,0,0,0,0,0,0,0,0,0,0,0,0,0,0,1,1,1,0
0,1,1,1,1,0,0,0,0,0,0,0,0,0,0,0,0,0,1,1,1,1,0
0,0,1,1,1,1,0,0,0,0,0,0,0,0,0,0,0,1,1,1,1,0,0
0,0,1,1,1,1,1,0,0,0,0,0,0,6,7,0,1,1,1,1,1,0,0
0,0,0,1,1,1,1,1,1,0,0,0,0,5,1,1,1,1,1,1,0,0,0
0,0,0,0,1,1,1,1,1,1,5,4,5,1,1,1,1,1,1,0,0,0,0
0,0,0,0,0,0,1,1,1,1,4,5,4,1,1,1,1,0,0,0,0,0,0
0,0,0,0,0,0,0,0,1,1,1,1,1,1,1,0,0,0,0,0,0,0,0
endlayer

layer
0,0,0,0,0,0,0,0,0,9,9,9,9,9,0,0,0,0,0,0,0,0,0
0,0,0,0,0,0,0,0,0,1,0,0,0,1,0,0,0,0,0,0,0,0,0
0,0,0,0,0,0,0,0,1,1,0,0,0,1,1,0,0,0,0,0,0,0,0
0,0,0,0,0,0,1,1,1,0,0,0,0,0,1,1,1,0,0,0,0,0,0
0,0,0,0,1,1,1,6,5,0,0,0,0,0,0,0,1,1,1,0,0,0,0
0,0,0,0,1,1,0,7,0,0,0,0,0,0,0,0,0,1,1,0,0,0,0
0,0,0,1,1,0,0,0,0,0,0,0,0,0,0,0,0,0,1,1,0,0,0
0,0,0,1,0,0,0,0,0,0,0,0,0,0,0,0,0,7,6,1,0,0,0
0,0,1,1,0,0,0,0,0,0,0,0,0,0,0,0,0,0,5,1,1,0,0
9,1,1,0,0,0,0,0,0,10,10,0,0,10,0,0,0,0,0,0,1,1,9
9,0,0,0,0,0,0,0,0,0,3,0,3,10,0,0,0,0,0,0,0,0,9
9,0,0,0,0,0,0,0,0,0,0,0,0,0,0,0,0,0,0,0,0,0,9
9,0,0,0,0,0,0,0,0,10,3,0,3,0,0,0,0,0,0,0,0,0,9
9,1,1,0,0,0,0,0,0,10,0,0,10,10,0,0,0,0,0,0,1,1,9
0,0,1,1,5,0,0,0,0,0,0,0,0,0,0,0,0,0,0,1,1,0,0
0,0,0,1,6,7,0,0,0,0,0,0,0,0,0,0,0,0,0,1,0,0,0
0,0,0,1,1,0,0,0,0,0,0,0,0,0,0,0,0,0,1,1,0,0,0
0,0,0,0,1,1,0,0,0,0,0,0,0,0,0,7,0,1,1,0,0,0,0
0,0,0,0,1,1,1,0,0,0,0,0,0,0,5,6,1,1,1,0,0,0,0
0,0,0,0,0,0,1,1,1,0,0,0,0,0,1,1,1,0,0,0,0,0,0
0,0,0,0,0,0,0,0,1,1,0,0,0,1,1,0,0,0,0,0,0,0,0
0,0,0,0,0,0,0,0,0,1,0,0,0,1,0,0,0,0,0,0,0,0,0
0,0,0,0,0,0,0,0,0,9,9,9,9,9,0,0,0,0,0,0,0,0,0
endlayer

layer
0,0,0,0,0,0,0,0,0,9,0,0,0,9,0,0,0,0,0,0,0,0,0
0,0,0,0,0,0,0,0,0,1,0,0,0,1,0,0,0,0,0,0,0,0,0
0,0,0,0,0,0,0,0,1,1,0,0,0,1,1,0,0,0,0,0,0,0,0
0,0,0,0,0,0,1,1,1,0,0,0,0,0,1,1,1,0,0,0,0,0,0
0,0,0,0,1,1,1,0,0,0,0,0,0,0,0,11,1,1,1,0,0,0,0
0,0,0,0,1,1,6,5,0,0,0,0,0,0,0,0,0,1,1,0,0,0,0
0,0,0,1,1,0,7,0,0,0,0,0,0,0,0,0,7,6,1,1,0,0,0
0,0,0,1,11,0,0,0,0,0,0,0,0,0,0,0,0,5,0,1,0,0,0
0,0,1,1,0,0,0,0,10,0,0,0,0,12,10,0,0,0,0,1,1,0,0
9,1,1,0,0,0,0,0,12,12,10,10,12,12,0,0,0,0,0,0,1,1,9
0,0,0,0,0,0,0,0,0,12,3,7,3,10,0,0,0,0,0,0,0,0,0
0,0,0,0,0,0,0,0,0,10,7,0,7,10,0,0,0,0,0,0,0,0,0
0,0,0,0,0,0,0,0,0,10,3,7,3,12,0,0,0,0,0,0,0,0,0
9,1,1,0,0,0,0,0,0,12,12,10,10,12,12,0,0,0,0,0,1,1,9
0,0,1,1,0,0,0,0,10,12,0,0,0,0,10,0,0,0,0,1,1,0,0
0,0,0,1,0,5,0,0,0,0,0,0,0,0,0,0,0,0,11,1,0,0,0
0,0,0,1,1,6,7,0,0,0,0,0,0,0,0,0,7,0,1,1,0,0,0
0,0,0,0,1,1,0,0,0,0,0,0,0,0,0,5,6,1,1,0,0,0,0
0,0,0,0,1,1,1,11,0,0,0,0,0,0,0,0,1,1,1,0,0,0,0
0,0,0,0,0,0,1,1,1,0,0,0,0,0,1,1,1,0,0,0,0,0,0
0,0,0,0,0,0,0,0,1,1,0,0,0,1,1,0,0,0,0,0,0,0,0
0,0,0,0,0,0,0,0,0,1,0,0,0,1,0,0,0,0,0,0,0,0,0
0,0,0,0,0,0,0,0,0,9,0,0,0,9,0,0,0,0,0,0,0,0,0
endlayer

layer
0,0,0,0,0,0,0,0,0,13,0,0,0,13,0,0,0,0,0,0,0,0,0
0,0,0,0,0,0,0,0,0,1,0,0,0,1,0,0,0,0,0,0,0,0,0
0,0,0,0,0,0,0,0,1,1,0,0,0,1,1,0,0,0,0,0,0,0,0
0,0,0,0,0,0,1,1,1,0,0,0,0,0,1,1,1,0,0,0,0,0,0
0,0,0,0,1,1,1,0,0,0,0,0,0,0,0,13,1,1,1,0,0,0,0
0,0,0,0,1,1,0,0,0,0,0,0,0,0,0,7,6,1,1,0,0,0,0
0,0,0,1,1,6,5,0,0,0,0,0,0,0,0,0,5,0,1,1,0,0,0
0,0,0,1,13,7,0,0,0,0,0,0,0,0,10,0,0,0,0,1,0,0,0
0,0,1,1,0,0,0,10,10,0,0,0,0,0,10,0,0,0,0,1,1,0,0
13,1,1,0,0,0,0,0,0,0,0,9,0,0,0,0,0,0,0,0,1,1,13
0,0,0,0,0,0,0,0,0,0,9,9,9,0,0,0,0,0,0,0,0,0,0
0,0,0,0,0,0,0,0,0,9,9,15,9,9,0,0,0,0,0,0,0,0,0
0,0,0,0,0,0,0,0,0,0,9,9,9,0,0,0,0,0,0,0,0,0,0
13,1,1,0,0,0,0,0,0,0,0,9,0,0,0,0,0,0,0,0,1,1,13
0,0,1,1,0,0,0,0,10,0,0,0,0,0,10,10,0,0,0,1,1,0,0
0,0,0,1,0,0,0,0,10,0,0,0,0,0,0,0,0,7,13,1,0,0,0
0,0,0,1,1,0,5,0,0,0,0,0,0,0,0,0,5,6,1,1,0,0,0
0,0,0,0,1,1,6,7,0,0,0,0,0,0,0,0,0,1,1,0,0,0,0
0,0,0,0,1,1,1,13,0,0,0,0,0,0,0,0,1,1,1,0,0,0,0
0,0,0,0,0,0,1,1,1,0,0,0,0,0,1,1,1,0,0,0,0,0,0
0,0,0,0,0,0,0,0,1,1,0,0,0,1,1,0,0,0,0,0,0,0,0
0,0,0,0,0,0,0,0,0,1,0,0,0,1,0,0,0,0,0,0,0,0,0
0,0,0,0,0,0,0,0,0,13,0,0,0,13,0,0,0,0,0,0,0,0,0
endlayer

layer
0,0,0,0,0,0,0,0,0,0,0,0,0,0,0,0,0,0,0,0,0,0,0
0,0,0,0,0,0,0,0,0,1,0,0,0,1,0,0,0,0,0,0,0,0,0
0,0,0,0,0,0,0,0,1,1,0,0,0,1,1,0,0,0,0,0,0,0,0
0,0,0,0,0,0,1,1,1,0,0,0,0,0,1,1,1,0,0,0,0,0,0
0,0,0,0,1,1,1,0,0,0,0,0,0,0,7,6,1,1,1,0,0,0,0
0,0,0,0,1,1,0,0,0,0,0,0,0,0,0,5,0,1,1,0,0,0,0
0,0,0,1,1,0,0,0,0,0,0,0,0,0,12,0,0,0,1,1,0,0,0
0,0,0,1,6,5,0,12,0,0,0,0,0,12,10,12,0,0,0,1,0,0,0
0,0,1,1,7,0,12,10,12,0,0,0,0,0,12,0,0,0,0,1,1,0,0
0,1,1,0,0,0,0,12,0,0,0,13,0,0,0,0,0,0,0,0,1,1,0
0,0,0,0,0,0,0,0,0,0,13,9,13,0,0,0,0,0,0,0,0,0,0
0,0,0,0,0,0,0,0,0,13,9,9,9,13,0,0,0,0,0,0,0,0,0
0,0,0,0,0,0,0,0,0,0,13,9,13,0,0,0,0,0,0,0,0,0,0
0,1,1,0,0,0,0,0,0,0,0,13,0,0,0,12,0,0,0,0,1,1,0
0,0,1,1,0,0,0,0,12,0,0,0,0,0,12,10,12,0,7,1,1,0,0
0,0,0,1,0,0,0,12,10,12,0,0,0,0,0,12,0,5,6,1,0,0,0
0,0,0,1,1,0,0,0,12,0,0,0,0,0,0,0,0,0,1,1,0,0,0
0,0,0,0,1,1,0,5,0,0,0,0,0,0,0,0,0,1,1,0,0,0,0
0,0,0,0,1,1,1,6,7,0,0,0,0,0,0,0,1,1,1,0,0,0,0
0,0,0,0,0,0,1,1,1,0,0,0,0,0,1,1,1,0,0,0,0,0,0
0,0,0,0,0,0,0,0,1,1,0,0,0,1,1,0,0,0,0,0,0,0,0
0,0,0,0,0,0,0,0,0,1,0,0,0,1,0,0,0,0,0,0,0,0,0
0,0,0,0,0,0,0,0,0,0,0,0,0,0,0,0,0,0,0,0,0,0,0
endlayer

layer
0,0,0,0,0,0,0,0,0,0,0,0,0,0,0,0,0,0,0,0,0,0,0
0,0,0,0,0,0,0,0,0,1,1,0,1,1,0,0,0,0,0,0,0,0,0
0,0,0,0,0,0,0,0,1,1,0,0,0,1,1,0,0,0,0,0,0,0,0
0,0,0,0,0,0,1,1,1,0,0,0,0,7,1,1,1,0,0,0,0,0,0
0,0,0,0,1,1,1,0,0,0,0,0,0,6,5,0,1,1,1,0,0,0,0
0,0,0,0,1,1,0,0,0,0,0,0,0,0,0,0,0,1,1,0,0,0,0
0,0,0,1,1,0,0,0,0,0,0,0,0,12,12,12,0,0,1,1,0,0,0
0,0,0,1,0,0,12,12,12,0,0,0,0,12,10,12,0,0,0,1,0,0,0
0,0,1,1,5,0,12,10,12,0,0,0,0,12,12,12,0,0,0,1,1,0,0
0,1,1,7,6,0,12,12,12,0,0,0,0,0,0,0,0,0,0,0,1,1,0
0,1,0,0,0,0,0,0,0,0,0,0,0,0,0,0,0,0,0,0,0,1,0
0,0,0,0,0,0,0,0,0,0,0,9,0,0,0,0,0,0,0,0,0,0,0
0,1,0,0,0,0,0,0,0,0,0,0,0,0,0,0,0,0,0,0,0,1,0
0,1,1,0,0,0,0,0,0,0,0,0,0,0,12,12,12,0,6,7,1,1,0
0,0,1,1,0,0,0,12,12,12,0,0,0,0,12,10,12,0,5,1,1,0,0
0,0,0,1,0,0,0,12,10,12,0,0,0,0,12,12,12,0,0,1,0,0,0
0,0,0,1,1,0,0,12,12,12,0,0,0,0,0,0,0,0,1,1,0,0,0
0,0,0,0,1,1,0,0,0,0,0,0,0,0,0,0,0,1,1,0,0,0,0
0,0,0,0,1,1,1,0,5,6,0,0,0,0,0,0,1,1,1,0,0,0,0
0,0,0,0,0,0,1,1,1,7,0,0,0,0,1,1,1,0,0,0,0,0,0
0,0,0,0,0,0,0,0,1,1,0,0,0,1,1,0,0,0,0,0,0,0,0
0,0,0,0,0,0,0,0,0,1,1,0,1,1,0,0,0,0,0,0,0,0,0
0,0,0,0,0,0,0,0,0,0,0,0,0,0,0,0,0,0,0,0,0,0,0
endlayer

layer
0,0,0,0,0,0,0,0,1,1,1,1,1,1,1,0,0,0,0,0,0,0,0
0,0,0,0,0,0,1,1,1,1,1,1,1,1,1,1,1,0,0,0,0,0,0
0,0,0,0,1,1,1,1,1,1,1,1,1,1,1,1,1,1,1,0,0,0,0
0,0,0,1,1,1,1,1,1,3,2,3,2,5,1,1,1,1,1,1,0,0,0
0,0,1,1,1,1,1,2,3,2,3,2,3,0,0,0,1,1,1,1,1,0,0
0,0,1,1,1,1,0,3,2,3,2,3,2,3,2,0,0,1,1,1,1,0,0
0,1,1,1,1,0,0,2,3,2,3,2,3,2,3,2,3,2,1,1,1,1,0
0,1,1,1,0,0,2,3,2,3,2,3,2,3,2,3,2,3,2,1,1,1,0
1,1,1,1,0,2,3,2,3,2,3,2,3,2,3,2,3,2,3,1,1,1,1
1,1,1,5,0,3,2,3,2,3,2,3,2,3,2,3,2,3,2,3,1,1,1
1,1,1,2,3,2,3,2,3,2,3,2,3,2,3,2,3,2,3,2,1,1,1
1,1,1,3,2,3,2,3,2,3,2,3,2,3,2,3,2,3,2,3,1,1,1
1,1,1,2,3,2,3,2,3,2,3,2,3,2,3,2,3,2,3,2,1,1,1
1,1,1,3,2,3,2,3,2,3,2,3,2,3,2,3,2,3,0,5,1,1,1
1,1,1,1,3,2,3,2,3,2,3,2,3,2,3,2,3,2,0,1,1,1,1
0,1,1,1,2,3,2,3,2,3,2,3,2,3,2,3,2,0,0,1,1,1,0
0,1,1,1,1,0,0,2,3,2,3,2,3,2,3,2,0,0,1,1,1,1,0
0,0,1,1,1,1,0,0,2,3,2,3,2,3,2,3,0,1,1,1,1,0,0
0,0,1,1,1,1,1,0,0,0,3,2,3,2,3,2,1,1,1,1,1,0,0
0,0,0,1,1,1,1,1,1,5,2,3,2,3,1,1,1,1,1,1,0,0,0
0,0,0,0,1,1,1,1,1,1,1,1,1,1,1,1,1,1,1,0,0,0,0
0,0,0,0,0,0,1,1,1,1,1,1,1,1,1,1,1,0,0,0,0,0,0
0,0,0,0,0,0,0,0,1,1,1,1,1,1,1,0,0,0,0,0,0,0,0
endlayer

layer
0,0,0,0,0,0,0,0,0,0,0,0,0,0,0,0,0,0,0,0,0,0,0
0,0,0,0,0,0,0,0,0,1,1,1,1,1,0,0,0,0,0,0,0,0,0
0,0,0,0,0,0,0,0,1,0,0,16,0,0,1,0,0,0,0,0,0,0,0
0,0,0,0,0,0,1,1,0,0,0,0,0,0,0,1,1,0,0,0,0,0,0
0,0,0,0,1,1,0,0,0,0,0,0,0,0,0,0,0,1,1,0,0,0,0
0,0,0,0,1,0,0,0,0,0,0,0,0,0,0,0,0,0,1,0,0,0,0
0,0,0,1,0,0,0,0,0,0,0,0,0,0,0,0,0,0,0,1,0,0,0
0,0,0,1,0,0,0,0,0,0,0,0,0,0,0,0,0,0,0,1,0,0,0
0,0,1,0,0,0,0,0,0,0,0,0,0,0,0,0,0,0,0,0,1,0,0
0,1,0,0,0,0,0,0,0,0,0,0,0,0,0,0,0,0,0,0,0,1,0
0,1,0,0,0,0,0,0,0,0,5,17,5,0,0,0,0,0,0,0,0,1,0
0,1,19,0,0,0,0,0,0,0,18,20,19,0,0,0,0,0,0,0,18,1,0
0,1,0,0,0,0,0,0,0,0,5,16,5,0,0,0,0,0,0,0,0,1,0
0,1,0,0,0,0,0,0,0,0,0,0,0,0,0,0,0,0,0,0,0,1,0
0,0,1,0,0,0,0,0,0,0,0,0,0,0,0,0,0,0,0,0,1,0,0
0,0,0,1,0,0,0,0,0,0,0,0,0,0,0,0,0,0,0,1,0,0,0
0,0,0,1,0,0,0,0,0,0,0,0,0,0,0,0,0,0,0,1,0,0,0
0,0,0,0,1,0,0,0,0,0,0,0,0,0,0,0,0,0,1,0,0,0,0
0,0,0,0,1,1,0,0,0,0,0,0,0,0,0,0,0,1,1,0,0,0,0
0,0,0,0,0,0,1,1,0,0,0,0,0,0,0,1,1,0,0,0,0,0,0
0,0,0,0,0,0,0,0,1,0,0,21,0,0,1,0,0,0,0,0,0,0,0
0,0,0,0,0,0,0,0,0,1,1,1,1,1,0,0,0,0,0,0,0,0,0
0,0,0,0,0,0,0,0,0,0,0,0,0,0,0,0,0,0,0,0,0,0,0
endlayer

layer
0,0,0,0,0,0,0,0,0,0,0,0,0,0,0,0,0,0,0,0,0,0,0
0,0,0,0,0,0,0,0,0,1,0,0,0,1,0,0,0,0,0,0,0,0,0
0,0,0,0,0,0,0,0,0,0,0,0,0,0,0,0,0,0,0,0,0,0,0
0,0,0,0,0,0,1,0,0,0,0,0,0,0,0,0,1,0,0,0,0,0,0
0,0,0,0,1,0,0,0,0,0,0,0,0,0,0,0,0,0,1,0,0,0,0
0,0,0,0,0,0,0,0,0,0,0,0,0,0,0,0,0,0,0,0,0,0,0
0,0,0,1,0,0,0,0,0,0,0,0,0,0,0,0,0,0,0,1,0,0,0
0,0,0,0,0,0,0,0,0,0,0,0,0,0,0,0,0,0,0,0,0,0,0
0,0,0,0,0,0,0,0,0,0,0,0,0,0,0,0,0,0,0,0,0,0,0
0,1,0,0,0,0,0,0,0,0,0,0,0,0,0,0,0,0,0,0,0,1,0
0,0,0,0,0,0,0,0,0,0,0,0,0,0,0,0,0,0,0,0,0,0,0
0,0,0,0,0,0,0,0,0,0,0,22,0,0,0,0,0,0,0,0,0,0,0
0,0,0,0,0,0,0,0,0,0,0,0,0,0,0,0,0,0,0,0,0,0,0
0,1,0,0,0,0,0,0,0,0,0,0,0,0,0,0,0,0,0,0,0,1,0
0,0,0,0,0,0,0,0,0,0,0,0,0,0,0,0,0,0,0,0,0,0,0
0,0,0,0,0,0,0,0,0,0,0,0,0,0,0,0,0,0,0,0,0,0,0
0,0,0,1,0,0,0,0,0,0,0,0,0,0,0,0,0,0,0,1,0,0,0
0,0,0,0,0,0,0,0,0,0,0,0,0,0,0,0,0,0,0,0,0,0,0
0,0,0,0,1,0,0,0,0,0,0,0,0,0,0,0,0,0,1,0,0,0,0
0,0,0,0,0,0,1,0,0,0,0,0,0,0,0,0,1,0,0,0,0,0,0
0,0,0,0,0,0,0,0,0,0,0,0,0,0,0,0,0,0,0,0,0,0,0
0,0,0,0,0,0,0,0,0,1,0,0,0,1,0,0,0,0,0,0,0,0,0
0,0,0,0,0,0,0,0,0,0,0,0,0,0,0,0,0,0,0,0,0,0,0
endlayer

