# War Tower D
# MC 1.7.10; 31 Oct 2014
# Created by Ruins mod version 14.0 Ingame Parser
# authoring Player: Jordan_Greywolf
# Updated to MC 1.8: 20 Mar 2016
# Updated to MC 1.9: 24 Apr 2016
# Updated to MC 1.11: 12 Jan 2017
# Updated to MC 1.12: 22 Jun 2017

weight=1
embed_into_distance=0
acceptable_target_blocks=
unacceptable_target_blocks=
dimensions=16,23,23
allowable_overhang=0
max_leveling=0
leveling_buffer=0
preserve_water=0
preserve_lava=0
preserve_plants=1

rule1=0,100,minecraft:obsidian-0
rule2=0,100,minecraft:quartz_block-1
rule3=0,100,minecraft:stonebrick-3
rule4=0,100,minecraft:stone_slab-7
rule5=0,100,minecraft:stone_slab-0
rule6=0,100,minecraft:double_stone_slab-7
rule7=0,100,minecraft:stone_slab-8
rule8=0,100,CommandBlock:RUINSTRIGGER /summon fireball ~0 ~2 ~0 {direction:[0.0,0.0,0.0],ExplosionPower:3}:@
rule9=0,100,minecraft:lava-8
rule10=0,100,minecraft:lava-2
rule11=0,100,minecraft:lava-4
rule12=0,100,minecraft:nether_brick_fence-0
rule13=1,100,minecraft:redstone_torch-5
rule14=0,100,minecraft:netherrack-0
rule15=0,100,minecraft:double_stone_slab-0
rule16=0,100,MobSpawner:LavaSlime
rule17=0,100,minecraft:fire-15
rule18=0,100,minecraft:fire-14
rule19=0,100,minecraft:fire-9
rule20=0,100,MobSpawner:Blaze
rule21=0,100,minecraft:lava-0
rule22=0,100,ChestGenHook:chests/simple_dungeon:4-5

rule23=0,100,IInventory;minecraft:trapped_chest;minecraft:gunpowder#8#0#0+minecraft:magma_cream#1#0#1+minecraft:tnt#8#0#3+minecraft:firework_charge#1#0#4+minecraft:coal#8#0#6+minecraft:blaze_rod#1#0#7+minecraft:enchanted_book#{StoredEnchantments:[{lvl:2,id:20}]}#0#11+minecraft:gunpowder#8#0#13+minecraft:fire_charge#1#0#14+minecraft:enchanted_book#{StoredEnchantments:[{lvl:4,id:1}]}#0#16+minecraft:lava_bucket#1#0#18+minecraft:lingering_potion#{Potion:"minecraft:fire_resistance"}#0#21+minecraft:flint_and_steel#1#0#24-4

rule24=0,100,ChestGenHook:chests/desert_pyramid:5-3
rule25=0,100,ChestGenHook:chests/simple_dungeon:4-2
rule26=0,100,CommandBlock:/testruin TP_WarTower1Top ~0 ~0 ~0:@
rule27=0,100,ChestGenHook:dungeonChest:3-4

rule28=0,100,CommandBlock:RUINSTRIGGER /summon Skeleton ~0 ~1 ~0 {HandItems:[{Count:1,id:blaze_rod,tag:{display:{Name:"Inferno Staff"},ench:[{id:20,lvl:2},{id:16,lvl:5}]}},{}],ArmorItems:[{Count:1,id:leather_boots,tag:{display:{color:9843760}}},{Count:1,id:leather_leggings,tag:{display:{color:9843760}}},{Count:1,id:leather_chestplate,tag:{display:{color:9843760}}},{Count:1,id:redstone_block,tag:{ench:[{id:0,lvl:5},{id:3,lvl:4},{id:1,lvl:4},{id:7,lvl:3}]}}],CustomName:"Fire Guardian",Health:50.0f,Attributes:[{Name:generic.movementSpeed,Base:0.5}],HandDropChances:[0.9F,0.0F],ArmorDropChances:[0.0F,0.0F,0.0F,0.0F],ActiveEffects:[{Id:12,Amplifier:1,Duration:999999},{Id:21,Amplifier:1,Duration:999999},{Id:10,Amplifier:1,Duration:999999},{Id:11,Amplifier:1,Duration:999999},{Id:1,Amplifier:1,Duration:999999},{Id:5,Amplifier:1,Duration:999999}],Silent:1,PersistenceRequired:1,SkeletonType:1}:@

rule29=0,100,CommandBlock:RUINSTRIGGER /summon magma_cube ~0 ~0 ~0 {Size:15,PersistenceRequired:1}:@

layer
0,0,0,0,0,0,0,0,1,1,1,1,1,1,1,0,0,0,0,0,0,0,0
0,0,0,0,0,0,1,1,1,1,4,5,4,1,1,1,1,0,0,0,0,0,0
0,0,0,0,1,1,1,1,1,1,5,4,5,1,1,1,1,1,1,0,0,0,0
0,0,0,1,1,1,1,1,1,5,0,0,0,0,1,1,1,1,1,1,0,0,0
0,0,1,1,1,1,1,0,7,6,0,0,0,0,0,0,1,1,1,1,1,0,0
0,0,1,1,1,1,0,0,0,0,0,8,0,0,0,0,0,1,1,1,1,0,0
0,1,1,1,1,0,0,4,5,0,0,0,0,0,5,4,0,0,1,1,1,1,0
0,1,1,1,0,0,4,9,10,5,0,0,0,5,10,9,4,0,0,1,1,1,0
1,1,1,1,0,0,5,10,11,4,0,0,0,4,11,10,5,0,7,1,1,1,1
1,1,1,0,0,0,0,5,4,0,0,0,0,0,4,5,0,0,6,5,1,1,1
1,4,5,0,0,0,0,0,0,0,5,0,5,0,0,0,0,0,0,0,5,4,1
1,5,4,0,0,8,0,0,0,0,0,8,0,0,0,0,0,8,0,0,4,5,1
1,4,5,0,0,0,0,0,0,0,5,0,5,0,0,0,0,0,0,0,5,4,1
1,1,1,5,6,0,0,5,4,0,0,0,0,0,4,5,0,0,0,0,1,1,1
1,1,1,1,7,0,5,10,11,4,0,0,0,4,11,10,5,0,0,1,1,1,1
0,1,1,1,0,0,4,9,10,5,0,0,0,5,10,9,4,0,0,1,1,1,0
0,1,1,1,1,0,0,4,5,0,0,0,0,0,5,4,0,0,1,1,1,1,0
0,0,1,1,1,1,0,0,0,0,0,8,0,0,0,0,0,1,1,1,1,0,0
0,0,1,1,1,1,1,0,0,0,0,0,0,6,7,0,1,1,1,1,1,0,0
0,0,0,1,1,1,1,1,1,0,0,0,0,5,1,1,1,1,1,1,0,0,0
0,0,0,0,1,1,1,1,1,1,5,4,5,1,1,1,1,1,1,0,0,0,0
0,0,0,0,0,0,1,1,1,1,4,5,4,1,1,1,1,0,0,0,0,0,0
0,0,0,0,0,0,0,0,1,1,1,1,1,1,1,0,0,0,0,0,0,0,0
endlayer

layer
0,0,0,0,0,0,0,0,0,12,12,12,12,12,0,0,0,0,0,0,0,0,0
0,0,0,0,0,0,0,0,0,1,0,0,0,1,0,0,0,0,0,0,0,0,0
0,0,0,0,0,0,0,0,1,1,0,0,0,1,1,0,0,0,0,0,0,0,0
0,0,0,0,0,0,1,1,1,0,0,0,0,0,1,1,1,0,0,0,0,0,0
0,0,0,0,1,1,1,6,5,0,0,0,0,0,0,0,1,1,1,0,0,0,0
0,0,0,0,1,1,0,7,0,0,0,0,0,0,0,0,0,1,1,0,0,0,0
0,0,0,1,1,0,0,0,0,0,0,0,0,0,0,0,0,0,1,1,0,0,0
0,0,0,1,0,0,0,9,0,0,0,0,0,0,0,9,0,7,6,1,0,0,0
0,0,1,1,0,0,0,0,0,0,0,0,0,0,0,0,0,0,5,1,1,0,0
12,1,1,0,0,0,0,0,0,0,0,0,0,0,0,0,0,0,0,0,1,1,12
12,0,0,0,0,0,0,0,0,0,0,0,0,0,0,0,0,0,0,0,0,0,12
12,0,0,0,0,0,0,0,0,0,0,0,0,0,0,0,0,0,0,0,0,0,12
12,0,0,0,0,0,0,0,0,0,0,0,0,0,0,0,0,0,0,0,0,0,12
12,1,1,0,0,0,0,0,0,0,0,0,0,0,0,0,0,0,0,0,1,1,12
0,0,1,1,5,0,0,0,0,0,0,0,0,0,0,0,0,0,0,1,1,0,0
0,0,0,1,6,7,0,9,0,0,0,0,0,0,0,9,0,0,0,1,0,0,0
0,0,0,1,1,0,0,0,0,0,0,0,0,0,0,0,0,0,1,1,0,0,0
0,0,0,0,1,1,0,0,0,0,0,0,0,0,0,7,0,1,1,0,0,0,0
0,0,0,0,1,1,1,0,0,0,0,0,0,0,5,6,1,1,1,0,0,0,0
0,0,0,0,0,0,1,1,1,0,0,0,0,0,1,1,1,0,0,0,0,0,0
0,0,0,0,0,0,0,0,1,1,0,0,0,1,1,0,0,0,0,0,0,0,0
0,0,0,0,0,0,0,0,0,1,0,0,0,1,0,0,0,0,0,0,0,0,0
0,0,0,0,0,0,0,0,0,12,12,12,12,12,0,0,0,0,0,0,0,0,0
endlayer

layer
0,0,0,0,0,0,0,0,0,12,0,0,0,12,0,0,0,0,0,0,0,0,0
0,0,0,0,0,0,0,0,0,1,0,0,0,1,0,0,0,0,0,0,0,0,0
0,0,0,0,0,0,0,0,1,1,0,0,0,1,1,0,0,0,0,0,0,0,0
0,0,0,0,0,0,1,1,1,0,0,0,0,0,1,1,1,0,0,0,0,0,0
0,0,0,0,1,1,1,0,0,0,0,0,0,0,0,12,1,1,1,0,0,0,0
0,0,0,0,1,1,6,5,0,0,0,0,0,0,0,0,0,1,1,0,0,0,0
0,0,0,1,1,0,7,0,0,0,0,0,0,0,0,0,7,6,1,1,0,0,0
0,0,0,1,12,0,0,9,0,0,0,0,0,0,0,9,0,5,0,1,0,0,0
0,0,1,1,0,0,0,0,0,0,0,0,0,0,0,0,0,0,0,1,1,0,0
12,1,1,0,0,0,0,0,0,0,0,0,0,0,0,0,0,0,0,0,1,1,12
0,0,0,0,0,0,0,0,0,0,0,0,0,0,0,0,0,0,0,0,0,0,0
0,0,0,0,0,0,0,0,0,0,0,0,0,0,0,0,0,0,0,0,0,0,0
0,0,0,0,0,0,0,0,0,0,0,0,0,0,0,0,0,0,0,0,0,0,0
12,1,1,0,0,0,0,0,0,0,0,0,0,0,0,0,0,0,0,0,1,1,12
0,0,1,1,0,0,0,0,0,0,0,0,0,0,0,0,0,0,0,1,1,0,0
0,0,0,1,0,5,0,9,0,0,0,0,0,0,0,9,0,0,12,1,0,0,0
0,0,0,1,1,6,7,0,0,0,0,0,0,0,0,0,7,0,1,1,0,0,0
0,0,0,0,1,1,0,0,0,0,0,0,0,0,0,5,6,1,1,0,0,0,0
0,0,0,0,1,1,1,12,0,0,0,0,0,0,0,0,1,1,1,0,0,0,0
0,0,0,0,0,0,1,1,1,0,0,0,0,0,1,1,1,0,0,0,0,0,0
0,0,0,0,0,0,0,0,1,1,0,0,0,1,1,0,0,0,0,0,0,0,0
0,0,0,0,0,0,0,0,0,1,0,0,0,1,0,0,0,0,0,0,0,0,0
0,0,0,0,0,0,0,0,0,12,0,0,0,12,0,0,0,0,0,0,0,0,0
endlayer

layer
0,0,0,0,0,0,0,0,0,13,0,0,0,13,0,0,0,0,0,0,0,0,0
0,0,0,0,0,0,0,0,0,1,0,0,0,1,0,0,0,0,0,0,0,0,0
0,0,0,0,0,0,0,0,1,1,0,0,0,1,1,0,0,0,0,0,0,0,0
0,0,0,0,0,0,1,1,1,0,0,0,0,0,1,1,1,0,0,0,0,0,0
0,0,0,0,1,1,1,0,0,0,0,0,0,0,0,13,1,1,1,0,0,0,0
0,0,0,0,1,1,0,0,0,0,0,0,0,0,0,7,6,1,1,0,0,0,0
0,0,0,1,1,6,5,0,0,0,0,0,0,0,0,0,5,0,1,1,0,0,0
0,0,0,1,13,7,0,9,0,0,0,0,0,0,0,9,0,0,0,1,0,0,0
0,0,1,1,0,0,0,0,0,0,0,0,0,0,0,0,0,0,0,1,1,0,0
13,1,1,0,0,0,0,0,0,0,0,0,0,0,0,0,0,0,0,0,1,1,13
0,0,0,0,0,0,0,0,0,0,0,0,0,0,0,0,0,0,0,0,0,0,0
0,0,0,0,0,0,0,0,0,0,0,0,0,0,0,0,0,0,0,0,0,0,0
0,0,0,0,0,0,0,0,0,0,0,0,0,0,0,0,0,0,0,0,0,0,0
13,1,1,0,0,0,0,0,0,0,0,0,0,0,0,0,0,0,0,0,1,1,13
0,0,1,1,0,0,0,0,0,0,0,0,0,0,0,0,0,0,0,1,1,0,0
0,0,0,1,0,0,0,9,0,0,0,0,0,0,0,9,0,7,13,1,0,0,0
0,0,0,1,1,0,5,0,0,0,0,0,0,0,0,0,5,6,1,1,0,0,0
0,0,0,0,1,1,6,7,0,0,0,0,0,0,0,0,0,1,1,0,0,0,0
0,0,0,0,1,1,1,13,0,0,0,0,0,0,0,0,1,1,1,0,0,0,0
0,0,0,0,0,0,1,1,1,0,0,0,0,0,1,1,1,0,0,0,0,0,0
0,0,0,0,0,0,0,0,1,1,0,0,0,1,1,0,0,0,0,0,0,0,0
0,0,0,0,0,0,0,0,0,1,0,0,0,1,0,0,0,0,0,0,0,0,0
0,0,0,0,0,0,0,0,0,13,0,0,0,13,0,0,0,0,0,0,0,0,0
endlayer

layer
0,0,0,0,0,0,0,0,0,0,0,0,0,0,0,0,0,0,0,0,0,0,0
0,0,0,0,0,0,0,0,0,1,0,0,0,1,0,0,0,0,0,0,0,0,0
0,0,0,0,0,0,0,0,1,1,0,0,0,1,1,0,0,0,0,0,0,0,0
0,0,0,0,0,0,1,1,1,0,0,0,0,0,1,1,1,0,0,0,0,0,0
0,0,0,0,1,1,1,0,0,0,0,0,0,0,7,6,1,1,1,0,0,0,0
0,0,0,0,1,1,0,0,0,0,0,0,0,0,0,5,0,1,1,0,0,0,0
0,0,0,1,1,0,0,0,0,0,0,0,0,0,0,0,0,0,1,1,0,0,0
0,0,0,1,6,5,0,9,0,0,0,0,0,0,0,9,0,0,0,1,0,0,0
0,0,1,1,7,0,0,0,0,0,0,0,0,0,0,0,0,0,0,1,1,0,0
0,1,1,0,0,0,0,0,0,0,0,0,0,0,0,0,0,0,0,0,1,1,0
0,0,0,0,0,0,0,0,0,0,0,0,0,0,0,0,0,0,0,0,0,0,0
0,0,0,0,0,0,0,0,0,0,0,14,0,0,0,0,0,0,0,0,0,0,0
0,0,0,0,0,0,0,0,0,0,0,0,0,0,0,0,0,0,0,0,0,0,0
0,1,1,0,0,0,0,0,0,0,0,0,0,0,0,0,0,0,0,0,1,1,0
0,0,1,1,0,0,0,0,0,0,0,0,0,0,0,0,0,0,7,1,1,0,0
0,0,0,1,0,0,0,9,0,0,0,0,0,0,0,9,0,5,6,1,0,0,0
0,0,0,1,1,0,0,0,0,0,0,0,0,0,0,0,0,0,1,1,0,0,0
0,0,0,0,1,1,0,5,0,0,0,0,0,0,0,0,0,1,1,0,0,0,0
0,0,0,0,1,1,1,6,7,0,0,0,0,0,0,0,1,1,1,0,0,0,0
0,0,0,0,0,0,1,1,1,0,0,0,0,0,1,1,1,0,0,0,0,0,0
0,0,0,0,0,0,0,0,1,1,0,0,0,1,1,0,0,0,0,0,0,0,0
0,0,0,0,0,0,0,0,0,1,0,0,0,1,0,0,0,0,0,0,0,0,0
0,0,0,0,0,0,0,0,0,0,0,0,0,0,0,0,0,0,0,0,0,0,0
endlayer

layer
0,0,0,0,0,0,0,0,0,0,0,0,0,0,0,0,0,0,0,0,0,0,0
0,0,0,0,0,0,0,0,0,1,1,0,1,1,0,0,0,0,0,0,0,0,0
0,0,0,0,0,0,0,0,1,1,0,0,0,1,1,0,0,0,0,0,0,0,0
0,0,0,0,0,0,1,1,1,0,0,0,0,7,1,1,1,0,0,0,0,0,0
0,0,0,0,1,1,1,0,0,0,0,0,0,6,5,0,1,1,1,0,0,0,0
0,0,0,0,1,1,0,0,0,0,0,0,0,0,0,0,0,1,1,0,0,0,0
0,0,0,1,1,0,0,0,0,0,0,0,0,0,0,0,0,0,1,1,0,0,0
0,0,0,1,0,0,0,9,0,0,0,0,0,0,0,9,0,0,0,1,0,0,0
0,0,1,1,5,0,0,0,0,0,0,0,0,0,0,0,0,0,0,1,1,0,0
0,1,1,7,6,0,0,0,0,0,0,0,0,0,0,0,0,0,0,0,1,1,0
0,1,0,0,0,0,0,0,0,0,8,14,8,0,0,0,0,0,0,0,0,1,0
0,0,0,0,0,0,0,0,0,0,14,14,14,0,0,0,0,0,0,0,0,0,0
0,1,0,0,0,0,0,0,0,0,8,14,8,0,0,0,0,0,0,0,0,1,0
0,1,1,0,0,0,0,0,0,0,0,0,0,0,0,0,0,0,6,7,1,1,0
0,0,1,1,0,0,0,0,0,0,0,0,0,0,0,0,0,0,5,1,1,0,0
0,0,0,1,0,0,0,9,0,0,0,0,0,0,0,9,0,0,0,1,0,0,0
0,0,0,1,1,0,0,0,0,0,0,0,0,0,0,0,0,0,1,1,0,0,0
0,0,0,0,1,1,0,0,0,0,0,0,0,0,0,0,0,1,1,0,0,0,0
0,0,0,0,1,1,1,0,5,6,0,0,0,0,0,0,1,1,1,0,0,0,0
0,0,0,0,0,0,1,1,1,7,0,0,0,0,1,1,1,0,0,0,0,0,0
0,0,0,0,0,0,0,0,1,1,0,0,0,1,1,0,0,0,0,0,0,0,0
0,0,0,0,0,0,0,0,0,1,1,0,1,1,0,0,0,0,0,0,0,0,0
0,0,0,0,0,0,0,0,0,0,0,0,0,0,0,0,0,0,0,0,0,0,0
endlayer

layer
0,0,0,0,0,0,0,0,1,1,1,1,1,1,1,0,0,0,0,0,0,0,0
0,0,0,0,0,0,1,1,1,1,1,1,1,1,1,1,1,0,0,0,0,0,0
0,0,0,0,1,1,1,1,1,1,1,1,1,1,1,1,1,1,1,0,0,0,0
0,0,0,1,1,1,1,1,1,7,6,15,6,5,1,1,1,1,1,1,0,0,0
0,0,1,1,1,1,1,0,0,0,14,14,14,0,0,0,1,1,1,1,1,0,0
0,0,1,1,1,1,0,0,0,0,0,14,0,0,0,0,0,1,1,1,1,0,0
0,1,1,1,1,0,0,0,0,0,14,14,14,0,0,0,0,0,1,1,1,1,0
0,1,1,1,0,0,0,9,0,0,0,14,0,0,0,9,0,0,0,1,1,1,0
1,1,1,1,0,0,0,0,0,0,14,14,14,0,0,0,0,0,0,1,1,1,1
1,1,1,5,0,0,0,0,0,0,0,14,0,0,0,0,0,0,0,7,1,1,1
1,1,1,6,14,0,14,0,14,0,14,14,14,0,14,0,14,0,14,6,1,1,1
1,1,1,15,14,14,14,14,14,14,14,16,14,14,14,14,14,14,14,15,1,1,1
1,1,1,6,14,0,14,0,14,0,14,14,14,0,14,0,14,0,14,6,1,1,1
1,1,1,7,0,0,0,0,0,0,0,14,0,0,0,0,0,0,0,5,1,1,1
1,1,1,1,0,0,0,0,0,0,14,14,14,0,0,0,0,0,0,1,1,1,1
0,1,1,1,0,0,0,9,0,0,0,14,0,0,0,9,0,0,0,1,1,1,0
0,1,1,1,1,0,0,0,0,0,14,14,14,0,0,0,0,0,1,1,1,1,0
0,0,1,1,1,1,0,0,0,0,0,14,0,0,0,0,0,1,1,1,1,0,0
0,0,1,1,1,1,1,0,0,0,14,14,14,0,0,0,1,1,1,1,1,0,0
0,0,0,1,1,1,1,1,1,5,6,15,6,7,1,1,1,1,1,1,0,0,0
0,0,0,0,1,1,1,1,1,1,1,1,1,1,1,1,1,1,1,0,0,0,0
0,0,0,0,0,0,1,1,1,1,1,1,1,1,1,1,1,0,0,0,0,0,0
0,0,0,0,0,0,0,0,1,1,1,1,1,1,1,0,0,0,0,0,0,0,0
endlayer

layer
0,0,0,0,0,0,0,0,1,1,1,1,1,1,1,0,0,0,0,0,0,0,0
0,0,0,0,0,0,1,1,1,1,4,5,4,1,1,1,1,0,0,0,0,0,0
0,0,0,0,1,1,1,1,1,1,5,4,5,1,1,1,1,1,1,0,0,0,0
0,0,0,1,1,1,1,1,1,5,0,0,0,0,1,1,1,1,1,1,0,0,0
0,0,1,1,1,1,1,0,7,6,0,17,0,0,0,0,1,1,1,1,1,0,0
0,0,1,1,1,1,0,0,0,0,0,0,0,0,0,0,0,1,1,1,1,0,0
0,1,1,1,1,0,0,0,0,0,0,18,0,0,0,0,0,0,1,1,1,1,0
0,1,1,1,0,0,0,9,0,0,0,0,0,0,0,9,0,0,0,1,1,1,0
1,1,1,1,0,0,0,0,0,0,0,17,0,0,0,0,0,0,7,1,1,1,1
1,1,1,0,0,0,0,0,0,0,0,0,0,0,0,0,0,0,6,5,1,1,1
1,4,5,0,0,0,0,0,0,0,0,17,0,0,0,0,0,0,0,0,5,4,1
1,5,4,0,19,0,19,0,17,0,17,0,17,0,17,0,17,0,17,0,4,5,1
1,4,5,0,0,0,0,0,0,0,0,17,0,0,0,0,0,0,0,0,5,4,1
1,1,1,5,6,0,0,0,0,0,0,0,0,0,0,0,0,0,0,0,1,1,1
1,1,1,1,7,0,0,0,0,0,0,17,0,0,0,0,0,0,0,1,1,1,1
0,1,1,1,0,0,0,9,0,0,0,0,0,0,0,9,0,0,0,1,1,1,0
0,1,1,1,1,0,0,0,0,0,0,17,0,0,0,0,0,0,1,1,1,1,0
0,0,1,1,1,1,0,0,0,0,0,0,0,0,0,0,0,1,1,1,1,0,0
0,0,1,1,1,1,1,0,0,0,0,17,0,6,7,0,1,1,1,1,1,0,0
0,0,0,1,1,1,1,1,1,0,0,0,0,5,1,1,1,1,1,1,0,0,0
0,0,0,0,1,1,1,1,1,1,5,4,5,1,1,1,1,1,1,0,0,0,0
0,0,0,0,0,0,1,1,1,1,4,5,4,1,1,1,1,0,0,0,0,0,0
0,0,0,0,0,0,0,0,1,1,1,1,1,1,1,0,0,0,0,0,0,0,0
endlayer

layer
0,0,0,0,0,0,0,0,0,12,12,12,12,12,0,0,0,0,0,0,0,0,0
0,0,0,0,0,0,0,0,0,1,0,0,0,1,0,0,0,0,0,0,0,0,0
0,0,0,0,0,0,0,0,1,1,0,0,0,1,1,0,0,0,0,0,0,0,0
0,0,0,0,0,0,1,1,1,0,0,0,0,0,1,1,1,0,0,0,0,0,0
0,0,0,0,1,1,1,6,5,0,0,0,0,0,0,0,1,1,1,0,0,0,0
0,0,0,0,1,1,0,7,0,0,0,0,0,0,0,0,0,1,1,0,0,0,0
0,0,0,1,1,0,0,0,0,0,0,0,0,0,0,0,0,0,1,1,0,0,0
0,0,0,1,0,0,0,9,0,0,0,0,0,0,0,9,0,7,6,1,0,0,0
0,0,1,1,0,0,0,0,0,0,0,0,0,0,0,0,0,0,5,1,1,0,0
12,1,1,0,0,0,0,0,0,0,0,0,0,0,0,0,0,0,0,0,1,1,12
12,0,0,0,0,0,0,0,0,0,0,0,0,0,0,0,0,0,0,0,0,0,12
12,0,0,0,0,0,0,0,0,0,0,0,0,0,0,0,0,0,0,0,0,0,12
12,0,0,0,0,0,0,0,0,0,0,0,0,0,0,0,0,0,0,0,0,0,12
12,1,1,0,0,0,0,0,0,0,0,0,0,0,0,0,0,0,0,0,1,1,12
0,0,1,1,5,0,0,0,0,0,0,0,0,0,0,0,0,0,0,1,1,0,0
0,0,0,1,6,7,0,9,0,0,0,0,0,0,0,9,0,0,0,1,0,0,0
0,0,0,1,1,0,0,0,0,0,0,0,0,0,0,0,0,0,1,1,0,0,0
0,0,0,0,1,1,0,0,0,0,0,0,0,0,0,7,0,1,1,0,0,0,0
0,0,0,0,1,1,1,0,0,0,0,0,0,0,5,6,1,1,1,0,0,0,0
0,0,0,0,0,0,1,1,1,0,0,0,0,0,1,1,1,0,0,0,0,0,0
0,0,0,0,0,0,0,0,1,1,0,0,0,1,1,0,0,0,0,0,0,0,0
0,0,0,0,0,0,0,0,0,1,0,0,0,1,0,0,0,0,0,0,0,0,0
0,0,0,0,0,0,0,0,0,12,12,12,12,12,0,0,0,0,0,0,0,0,0
endlayer

layer
0,0,0,0,0,0,0,0,0,12,0,0,0,12,0,0,0,0,0,0,0,0,0
0,0,0,0,0,0,0,0,0,1,0,0,0,1,0,0,0,0,0,0,0,0,0
0,0,0,0,0,0,0,0,1,1,0,0,0,1,1,0,0,0,0,0,0,0,0
0,0,0,0,0,0,1,1,1,0,0,0,0,0,1,1,1,0,0,0,0,0,0
0,0,0,0,1,1,1,0,0,0,0,0,0,0,0,12,1,1,1,0,0,0,0
0,0,0,0,1,1,6,5,0,0,0,0,0,0,0,0,0,1,1,0,0,0,0
0,0,0,1,1,0,7,0,0,0,0,0,0,0,0,0,7,6,1,1,0,0,0
0,0,0,1,12,0,0,9,0,0,0,0,0,0,0,9,0,5,0,1,0,0,0
0,0,1,1,0,0,0,0,0,0,0,0,0,0,0,0,0,0,0,1,1,0,0
12,1,1,0,0,0,0,0,0,0,0,0,0,0,0,0,0,0,0,0,1,1,12
0,0,0,0,0,0,0,0,0,0,0,0,0,0,0,0,0,0,0,0,0,0,0
0,0,0,0,0,0,0,0,0,0,0,0,0,0,0,0,0,0,0,0,0,0,0
0,0,0,0,0,0,0,0,0,0,0,0,0,0,0,0,0,0,0,0,0,0,0
12,1,1,0,0,0,0,0,0,0,0,0,0,0,0,0,0,0,0,0,1,1,12
0,0,1,1,0,0,0,0,0,0,0,0,0,0,0,0,0,0,0,1,1,0,0
0,0,0,1,0,5,0,9,0,0,0,0,0,0,0,9,0,0,12,1,0,0,0
0,0,0,1,1,6,7,0,0,0,0,0,0,0,0,0,7,0,1,1,0,0,0
0,0,0,0,1,1,0,0,0,0,0,0,0,0,0,5,6,1,1,0,0,0,0
0,0,0,0,1,1,1,12,0,0,0,0,0,0,0,0,1,1,1,0,0,0,0
0,0,0,0,0,0,1,1,1,0,0,0,0,0,1,1,1,0,0,0,0,0,0
0,0,0,0,0,0,0,0,1,1,0,0,0,1,1,0,0,0,0,0,0,0,0
0,0,0,0,0,0,0,0,0,1,0,0,0,1,0,0,0,0,0,0,0,0,0
0,0,0,0,0,0,0,0,0,12,0,0,0,12,0,0,0,0,0,0,0,0,0
endlayer

layer
0,0,0,0,0,0,0,0,0,13,0,0,0,13,0,0,0,0,0,0,0,0,0
0,0,0,0,0,0,0,0,0,1,0,0,0,1,0,0,0,0,0,0,0,0,0
0,0,0,0,0,0,0,0,1,1,0,0,0,1,1,0,0,0,0,0,0,0,0
0,0,0,0,0,0,1,1,1,0,0,0,0,0,1,1,1,0,0,0,0,0,0
0,0,0,0,1,1,1,0,0,0,0,0,0,0,0,13,1,1,1,0,0,0,0
0,0,0,0,1,1,0,0,0,0,0,0,0,0,0,7,6,1,1,0,0,0,0
0,0,0,1,1,6,5,0,0,0,0,0,0,0,0,0,5,0,1,1,0,0,0
0,0,0,1,13,7,0,9,0,0,0,0,0,0,0,9,0,0,0,1,0,0,0
0,0,1,1,0,0,0,0,0,0,0,0,0,0,0,0,0,0,0,1,1,0,0
13,1,1,0,0,0,0,0,0,0,0,12,0,0,0,0,0,0,0,0,1,1,13
0,0,0,0,0,0,0,0,0,0,12,12,12,0,0,0,0,0,0,0,0,0,0
0,0,0,0,0,0,0,0,0,12,12,20,12,12,0,0,0,0,0,0,0,0,0
0,0,0,0,0,0,0,0,0,0,12,12,12,0,0,0,0,0,0,0,0,0,0
13,1,1,0,0,0,0,0,0,0,0,12,0,0,0,0,0,0,0,0,1,1,13
0,0,1,1,0,0,0,0,0,0,0,0,0,0,0,0,0,0,0,1,1,0,0
0,0,0,1,0,0,0,9,0,0,0,0,0,0,0,9,0,7,13,1,0,0,0
0,0,0,1,1,0,5,0,0,0,0,0,0,0,0,0,5,6,1,1,0,0,0
0,0,0,0,1,1,6,7,0,0,0,0,0,0,0,0,0,1,1,0,0,0,0
0,0,0,0,1,1,1,13,0,0,0,0,0,0,0,0,1,1,1,0,0,0,0
0,0,0,0,0,0,1,1,1,0,0,0,0,0,1,1,1,0,0,0,0,0,0
0,0,0,0,0,0,0,0,1,1,0,0,0,1,1,0,0,0,0,0,0,0,0
0,0,0,0,0,0,0,0,0,1,0,0,0,1,0,0,0,0,0,0,0,0,0
0,0,0,0,0,0,0,0,0,13,0,0,0,13,0,0,0,0,0,0,0,0,0
endlayer

layer
0,0,0,0,0,0,0,0,0,0,0,0,0,0,0,0,0,0,0,0,0,0,0
0,0,0,0,0,0,0,0,0,1,0,0,0,1,0,0,0,0,0,0,0,0,0
0,0,0,0,0,0,0,0,1,1,0,0,0,1,1,0,0,0,0,0,0,0,0
0,0,0,0,0,0,1,1,1,0,0,0,0,0,1,1,1,0,0,0,0,0,0
0,0,0,0,1,1,1,0,0,0,0,0,0,0,7,6,1,1,1,0,0,0,0
0,0,0,0,1,1,0,0,0,0,0,0,0,0,0,5,0,1,1,0,0,0,0
0,0,0,1,1,0,0,0,0,0,0,0,0,0,0,0,0,0,1,1,0,0,0
0,0,0,1,6,5,0,9,0,0,0,0,0,0,0,9,0,0,0,1,0,0,0
0,0,1,1,7,0,0,0,0,0,0,0,0,0,0,0,0,0,0,1,1,0,0
0,1,1,0,0,0,0,0,0,0,0,13,0,0,0,0,0,0,0,0,1,1,0
0,0,0,0,0,0,0,0,0,0,13,12,13,0,0,0,0,0,0,0,0,0,0
0,0,0,0,0,0,0,0,0,13,12,12,12,13,0,0,0,0,0,0,0,0,0
0,0,0,0,0,0,0,0,0,0,13,12,13,0,0,0,0,0,0,0,0,0,0
0,1,1,0,0,0,0,0,0,0,0,13,0,0,0,0,0,0,0,0,1,1,0
0,0,1,1,0,0,0,0,0,0,0,0,0,0,0,0,0,0,7,1,1,0,0
0,0,0,1,0,0,0,9,0,0,0,0,0,0,0,9,0,5,6,1,0,0,0
0,0,0,1,1,0,0,0,0,0,0,0,0,0,0,0,0,0,1,1,0,0,0
0,0,0,0,1,1,0,5,0,0,0,0,0,0,0,0,0,1,1,0,0,0,0
0,0,0,0,1,1,1,6,7,0,0,0,0,0,0,0,1,1,1,0,0,0,0
0,0,0,0,0,0,1,1,1,0,0,0,0,0,1,1,1,0,0,0,0,0,0
0,0,0,0,0,0,0,0,1,1,0,0,0,1,1,0,0,0,0,0,0,0,0
0,0,0,0,0,0,0,0,0,1,0,0,0,1,0,0,0,0,0,0,0,0,0
0,0,0,0,0,0,0,0,0,0,0,0,0,0,0,0,0,0,0,0,0,0,0
endlayer

layer
0,0,0,0,0,0,0,0,0,0,0,0,0,0,0,0,0,0,0,0,0,0,0
0,0,0,0,0,0,0,0,0,1,1,0,1,1,0,0,0,0,0,0,0,0,0
0,0,0,0,0,0,0,0,1,1,0,0,0,1,1,0,0,0,0,0,0,0,0
0,0,0,0,0,0,1,1,1,0,0,0,0,7,1,1,1,0,0,0,0,0,0
0,0,0,0,1,1,1,0,0,0,0,0,0,6,5,0,1,1,1,0,0,0,0
0,0,0,0,1,1,0,0,0,0,0,0,0,0,0,0,0,1,1,0,0,0,0
0,0,0,1,1,0,0,14,0,0,0,0,0,0,0,14,0,0,1,1,0,0,0
0,0,0,1,0,0,14,21,14,0,0,0,0,0,14,21,14,0,0,1,0,0,0
0,0,1,1,5,0,0,14,0,0,0,0,0,0,0,14,0,0,0,1,1,0,0
0,1,1,7,6,0,0,0,0,0,0,0,0,0,0,0,0,0,0,0,1,1,0
0,1,0,0,0,0,0,0,0,0,0,0,0,0,0,0,0,0,0,0,0,1,0
0,0,0,0,0,0,0,0,0,0,0,12,0,0,0,0,0,0,0,0,0,0,0
0,1,0,0,0,0,0,0,0,0,0,0,0,0,0,0,0,0,0,0,0,1,0
0,1,1,0,0,0,0,0,0,0,0,0,0,0,0,0,0,0,6,7,1,1,0
0,0,1,1,0,0,0,14,0,0,0,0,0,0,0,14,0,0,5,1,1,0,0
0,0,0,1,0,0,14,21,14,0,0,0,0,0,14,21,14,0,0,1,0,0,0
0,0,0,1,1,0,0,14,0,0,0,0,0,0,0,14,0,0,1,1,0,0,0
0,0,0,0,1,1,0,0,0,0,0,0,0,0,0,0,0,1,1,0,0,0,0
0,0,0,0,1,1,1,0,5,6,0,0,0,0,0,0,1,1,1,0,0,0,0
0,0,0,0,0,0,1,1,1,7,0,0,0,0,1,1,1,0,0,0,0,0,0
0,0,0,0,0,0,0,0,1,1,0,0,0,1,1,0,0,0,0,0,0,0,0
0,0,0,0,0,0,0,0,0,1,1,0,1,1,0,0,0,0,0,0,0,0,0
0,0,0,0,0,0,0,0,0,0,0,0,0,0,0,0,0,0,0,0,0,0,0
endlayer

layer
0,0,0,0,0,0,0,0,1,1,1,1,1,1,1,0,0,0,0,0,0,0,0
0,0,0,0,0,0,1,1,1,1,1,1,1,1,1,1,1,0,0,0,0,0,0
0,0,0,0,1,1,1,1,1,1,1,1,1,1,1,1,1,1,1,0,0,0,0
0,0,0,1,1,1,1,1,1,3,2,3,2,5,1,1,1,1,1,1,0,0,0
0,0,1,1,1,1,1,2,3,2,3,2,3,0,0,0,1,1,1,1,1,0,0
0,0,1,1,1,1,0,3,2,3,2,3,2,3,2,0,0,1,1,1,1,0,0
0,1,1,1,1,0,0,2,3,2,3,2,3,2,3,2,3,2,1,1,1,1,0
0,1,1,1,0,0,2,3,2,3,2,3,2,3,2,3,2,3,2,1,1,1,0
1,1,1,1,0,2,3,2,3,2,3,2,3,2,3,2,3,2,3,1,1,1,1
1,1,1,5,0,3,2,3,2,3,2,3,2,3,2,3,2,3,2,3,1,1,1
1,1,1,2,3,2,3,2,3,2,3,2,3,2,3,2,3,2,3,2,1,1,1
1,1,1,3,2,3,2,3,2,3,2,3,2,3,2,3,2,3,2,3,1,1,1
1,1,1,2,3,2,3,2,3,2,3,2,3,2,3,2,3,2,3,2,1,1,1
1,1,1,3,2,3,2,3,2,3,2,3,2,3,2,3,2,3,0,5,1,1,1
1,1,1,1,3,2,3,2,3,2,3,2,3,2,3,2,3,2,0,1,1,1,1
0,1,1,1,2,3,2,3,2,3,2,3,2,3,2,3,2,0,0,1,1,1,0
0,1,1,1,1,0,0,2,3,2,3,2,3,2,3,2,0,0,1,1,1,1,0
0,0,1,1,1,1,0,0,2,3,2,3,2,3,2,3,0,1,1,1,1,0,0
0,0,1,1,1,1,1,0,0,0,3,2,3,2,3,2,1,1,1,1,1,0,0
0,0,0,1,1,1,1,1,1,5,2,3,2,3,1,1,1,1,1,1,0,0,0
0,0,0,0,1,1,1,1,1,1,1,1,1,1,1,1,1,1,1,0,0,0,0
0,0,0,0,0,0,1,1,1,1,1,1,1,1,1,1,1,0,0,0,0,0,0
0,0,0,0,0,0,0,0,1,1,1,1,1,1,1,0,0,0,0,0,0,0,0
endlayer

layer
0,0,0,0,0,0,0,0,0,0,0,0,0,0,0,0,0,0,0,0,0,0,0
0,0,0,0,0,0,0,0,0,1,1,1,1,1,0,0,0,0,0,0,0,0,0
0,0,0,0,0,0,0,0,1,0,0,22,0,0,1,0,0,0,0,0,0,0,0
0,0,0,0,0,0,1,1,0,0,0,0,0,0,0,1,1,0,0,0,0,0,0
0,0,0,0,1,1,0,0,0,0,0,0,0,0,0,0,0,1,1,0,0,0,0
0,0,0,0,1,0,0,0,0,0,0,8,0,0,0,0,0,0,1,0,0,0,0
0,0,0,1,0,0,0,0,0,0,0,0,0,0,0,0,0,0,0,1,0,0,0
0,0,0,1,0,0,0,0,4,0,0,0,0,0,4,0,0,0,0,1,0,0,0
0,0,1,0,0,0,0,4,21,4,0,0,0,4,21,4,0,0,0,0,1,0,0
0,1,0,0,0,0,0,0,4,0,0,0,0,0,4,0,0,0,0,0,0,1,0
0,1,0,0,0,0,0,0,0,0,5,23,5,0,0,0,0,0,0,0,0,1,0
0,1,25,0,0,8,0,0,0,0,24,26,25,0,0,0,0,8,0,0,24,1,0
0,1,0,0,0,0,0,0,0,0,5,22,5,0,0,0,0,0,0,0,0,1,0
0,1,0,0,0,0,0,0,4,0,0,0,0,0,4,0,0,0,0,0,0,1,0
0,0,1,0,0,0,0,4,21,4,0,0,0,4,21,4,0,0,0,0,1,0,0
0,0,0,1,0,0,0,0,4,0,0,0,0,0,4,0,0,0,0,1,0,0,0
0,0,0,1,0,0,0,0,0,0,0,0,0,0,0,0,0,0,0,1,0,0,0
0,0,0,0,1,0,0,0,0,0,0,8,0,0,0,0,0,0,1,0,0,0,0
0,0,0,0,1,1,0,0,0,0,0,0,0,0,0,0,0,1,1,0,0,0,0
0,0,0,0,0,0,1,1,0,0,0,0,0,0,0,1,1,0,0,0,0,0,0
0,0,0,0,0,0,0,0,1,0,0,27,0,0,1,0,0,0,0,0,0,0,0
0,0,0,0,0,0,0,0,0,1,1,1,1,1,0,0,0,0,0,0,0,0,0
0,0,0,0,0,0,0,0,0,0,0,0,0,0,0,0,0,0,0,0,0,0,0
endlayer

layer
0,0,0,0,0,0,0,0,0,0,0,0,0,0,0,0,0,0,0,0,0,0,0
0,0,0,0,0,0,0,0,0,1,0,0,0,1,0,0,0,0,0,0,0,0,0
0,0,0,0,0,0,0,0,0,0,0,0,0,0,0,0,0,0,0,0,0,0,0
0,0,0,0,0,0,1,0,0,0,0,0,0,0,0,0,1,0,0,0,0,0,0
0,0,0,0,1,0,0,0,0,0,0,0,0,0,0,0,0,0,1,0,0,0,0
0,0,0,0,0,0,0,0,0,0,0,0,0,0,0,0,0,0,0,0,0,0,0
0,0,0,1,0,0,0,0,0,0,0,0,0,0,0,0,0,0,0,1,0,0,0
0,0,0,0,0,0,0,0,0,0,0,0,0,0,0,0,0,0,0,0,0,0,0
0,0,0,0,0,0,0,0,0,0,0,0,0,0,0,0,0,0,0,0,0,0,0
0,1,0,0,0,0,0,0,0,0,0,0,0,0,0,0,0,0,0,0,0,1,0
0,0,0,0,0,0,0,0,0,0,0,0,0,0,0,0,0,0,0,0,0,0,0
0,0,0,0,0,0,0,0,0,0,29,28,0,0,0,0,0,0,0,0,0,0,0
0,0,0,0,0,0,0,0,0,0,0,0,0,0,0,0,0,0,0,0,0,0,0
0,1,0,0,0,0,0,0,0,0,0,0,0,0,0,0,0,0,0,0,0,1,0
0,0,0,0,0,0,0,0,0,0,0,0,0,0,0,0,0,0,0,0,0,0,0
0,0,0,0,0,0,0,0,0,0,0,0,0,0,0,0,0,0,0,0,0,0,0
0,0,0,1,0,0,0,0,0,0,0,0,0,0,0,0,0,0,0,1,0,0,0
0,0,0,0,0,0,0,0,0,0,0,0,0,0,0,0,0,0,0,0,0,0,0
0,0,0,0,1,0,0,0,0,0,0,0,0,0,0,0,0,0,1,0,0,0,0
0,0,0,0,0,0,1,0,0,0,0,0,0,0,0,0,1,0,0,0,0,0,0
0,0,0,0,0,0,0,0,0,0,0,0,0,0,0,0,0,0,0,0,0,0,0
0,0,0,0,0,0,0,0,0,1,0,0,0,1,0,0,0,0,0,0,0,0,0
0,0,0,0,0,0,0,0,0,0,0,0,0,0,0,0,0,0,0,0,0,0,0
endlayer


