# War Tower Top #1
# MC 1.7.10; 9 Nov 2014
# Created by Ruins mod version 14.2 Ingame Parser
# authoring Player: Jordan_Greywolf
# Special Instructions: Place in /templateparser folder.
# Updated to MC 1.8: 20 Mar 2016
# Updated to MC 1.9: 28 Apr 2016
# Updated to MC 1.11: 12 Jan 2017
# Updated to MC 1.12: 22 Jun 2017

weight=1
embed_into_distance=0
acceptable_target_blocks=
unacceptable_target_blocks=flowing_water,water
dimensions=42,23,23
allowable_overhang=9999
max_leveling=0
leveling_buffer=0
preserve_water=0
preserve_lava=0
preserve_plants=1

rule1=0,100,minecraft:obsidian-0
rule2=0,100,minecraft:quartz_block-1
rule3=0,100,minecraft:stonebrick-3
rule4=0,100,minecraft:stone_slab-7
rule5=0,100,minecraft:stone_slab-0
rule6=0,100,minecraft:double_stone_slab-7
rule7=0,100,minecraft:stone_slab-8
rule8=0,100,minecraft:nether_brick_fence-0
rule9=1,100,minecraft:redstone_torch-5
rule10=0,100,minecraft:double_stone_slab-0
rule11=0,100,minecraft:nether_brick_stairs-1
rule12=0,100,minecraft:nether_brick_stairs-7
rule13=0,100,minecraft:stone_slab-14
rule14=0,100,minecraft:nether_brick_stairs-6
rule15=0,100,minecraft:carpet-0

# Flesh Golem Spawner
rule16=0,100,CommandBlock:RUINSTRIGGER /setblock ~0 ~1 ~0 mob_spawner 0 replace {SpawnCount:1,SpawnRange:4,maxNearbyEntities:4,Delay:20,MinSpawnDelay:60,MaxSpawnDelay:120,EntityId:zombie_pigman,SpawnData:{id:zombie_pigman,HandItems:[{Count:1,id:iron_sword,tag:{display:{Name:"Tainted Sword"},ench:[{id:19,lvl:2},{id:16,lvl:5}]}},{Count:1,id:shield}],ArmorItems:[{},{},{Count:1,id:leather_chestplate,tag:{display:{Name:"Stitched Leather",color:0}}},{Count:1,id:stained_glass}],CustomName:"Flesh Golem",HandDropChances:[0.1F,0.1F],ArmorDropChances:[0.0F,0.0F,0.1F,0.1F],Attributes:[{Name:zombie.spawnReinforcements,Base:1}],Silent:1,CanBreakDoors:1,IsVillager:1,Anger:32767}}:@

rule17=0,100,minecraft:nether_brick_stairs-2
rule18=0,100,minecraft:nether_brick_stairs-0
rule19=0,100,minecraft:nether_brick_stairs-3
rule20=0,100,minecraft:nether_brick-0

rule21=0,100,ChestGenHook:chests/stronghold_library:5-5

rule22=0,100,IInventory;minecraft:trapped_chest;minecraft:arrow#16#0#0+minecraft:writable_book#1#0#1-5

rule23=0,100,minecraft:bookshelf-0
rule24=0,100,minecraft:ladder-5

rule25=0,100,CommandBlock:RUINSTRIGGER /summon ocelot ~0 ~0 ~0 {CustomName:"Sorcerer's Familiar",Health:250.0f,ActiveEffects:[{Id:12,Amplifier:1,Duration:999999,Ambient:1},{Id:10,Amplifier:1,Duration:999999,Ambient:1},{Id:13,Amplifier:1,Duration:999999,Ambient:1}],PersistenceRequired:1,Silent:1,CatType:1}:@

rule26=0,100,ChestGenHook:chests/simple_dungeon:5-3
rule27=0,100,ChestGenHook:chests/simple_dungeon:5-2
rule28=0,100,IInventory;minecraft:trapped_chest;minecraft:painting#8#0#0+minecraft:item_frame#8#0#1-3
rule29=0,100,minecraft:ladder-3

# Flesh Golem
rule30=0,100,CommandBlock:RUINSTRIGGER /summon zombie_pigman ~0 ~0 ~0 {HandItems:[{Count:1,id:golden_sword,tag:{display:{Name:"Bone Blade"},ench:[{id:20,lvl:2},{id:19,lvl:2},{id:16,lvl:5}]}},{Count:1,id:shield}],ArmorItems:[{Count:1,id:leather_boots,tag:{display:{Name:"Stitched Boots",color:0}}},{Count:1,id:chainmail_leggings,tag:{display:{Name:"Rusty Leggings"}}},{Count:1,id:leather_chestplate,tag:{display:{Name:"Stitched Leather",color:0}}},{Count:1,id:skull,Damage:3,tag:{SkullOwner:MHF_Herobrine}}],CustomName:"Patchwork Golem",Attributes:[{Name:generic.knockbackResistance,Base:1}],HandDropChances:[0.5F,0.5F],ArmorDropChances:[0.1F,0.1F,0.1F,0.1F],ActiveEffects:[{Id:21,Amplifier:1,Duration:999999},{Id:11,Amplifier:1,Duration:999999},{Id:5,Amplifier:1,Duration:999999}],Silent:1,PersistenceRequired:1,CanBreakDoors:1,IsVillager:1,Anger:32767}:@

rule31=0,100,minecraft:enchanting_table-0
rule32=0,100,minecraft:ladder-2

rule33=0,100,IInventory;minecraft:trapped_chest;minecraft:emerald#1#0#0+minecraft:glowstone#2#0#1-2

# Evil Sorcerer
rule34=0,100,CommandBlock:RUINSTRIGGER /summon witch ~0 ~0 ~0 {HandItems:[{Count:1,id:emerald},{Count:1,id:writable_book,tag:{display:{Name:"Dark Tome"},ench:[{id:20,lvl:2},{id:19,lvl:2}]}}],ArmorItems:[{Count:1,id:leather_boots,tag:{display:{Name:"Dark Sandals"}}},{Count:1,id:leather_leggings,tag:{display:{Name:"Dark Leggings"}}},{Count:1,id:leather_chestplate,tag:{display:{Name:"Dark Robes"}}},{Count:1,id:skull,Damage:3,tag:{SkullOwner:MHF_Herobrine}}],CustomName:"Evil Sorcerer",Health:100.0f,Attributes:[{Name:generic.knockbackResistance,Base:1}],HandDropChances:[1.0F,1.0F],ArmorDropChances:[1.0F,1.0F,1.0F,0.0F],ActiveEffects:[{Id:12,Amplifier:1,Duration:999999,Ambient:1},{Id:3,Amplifier:1,Duration:999999,Ambient:1},{Id:21,Amplifier:1,Duration:999999,Ambient:1},{Id:8,Amplifier:1,Duration:999999,Ambient:1},{Id:11,Amplifier:1,Duration:999999,Ambient:1},{Id:5,Amplifier:1,Duration:999999,Ambient:1},{Id:13,Amplifier:1,Duration:999999,Ambient:1}],Silent:1,PersistenceRequired:1}:@
rule35=0,100,minecraft:ladder-4

rule36=0,100,ChestGenHook:chests/simple_dungeon:5-4

rule37=0,100,IInventory;minecraft:trapped_chest;minecraft:splash_potion#{Potion:"minecraft:strong_leaping"}#0#0+minecraft:potion#{Potion:"minecraft:strong_leaping"}#0#1+minecraft:enchanted_book#{StoredEnchantments:[{lvl:4,id:0}]}#0#3+minecraft:splash_potion#{Potion:"minecraft:long_weakness"}#0#5+minecraft:enchanted_book#{StoredEnchantments:[{lvl:4,id:1}]}#0#7+minecraft:enchanted_book#{StoredEnchantments:[{lvl:4,id:3}]}#0#9+minecraft:splash_potion#{Potion:"minecraft:strong_healing"}#0#10+minecraft:splash_potion#{Potion:"minecraft:strong_healing"}#0#11+minecraft:splash_potion#{Potion:"minecraft:slowness"}#0#12+minecraft:enchanted_book#{StoredEnchantments:[{lvl:1,id:70}]}#0#13+minecraft:lingering_potion#{Potion:"minecraft:strong_healing"}#0#14+minecraft:splash_potion#{Potion:"minecraft:strong_healing"}#0#15+minecraft:lingering_potion#{Potion:"minecraft:strong_regeneration"}#0#16+minecraft:splash_potion#{Potion:"minecraft:long_invisibility"}#0#18+minecraft:splash_potion#{Potion:"minecraft:long_water_breathing"}#0#19+minecraft:potion#{Potion:"minecraft:strong_healing"}#0#21+minecraft:splash_potion#{Potion:"minecraft:strong_swiftness"}#0#22+minecraft:splash_potion#{Potion:"minecraft:long_strength"}#0#23+minecraft:enchanted_book#{StoredEnchantments:[{lvl:1,id:33}]}#0#24+minecraft:enchanted_book#{StoredEnchantments:[{lvl:5,id:48}]}#0#26-4

rule38=0,100,minecraft:nether_brick_stairs-5
rule39=0,100,minecraft:nether_brick_stairs-4
rule40=0,100,minecraft:netherrack-0
rule41=0,100,minecraft:fire-15
rule42=0,100,minecraft:glowstone-0
rule43=0,100,minecraft:stone_slab-6
rule44=0,100,CommandBlock:RUINSTRIGGER /summon fireball ~0 ~1 ~0 {direction:[0.0,0.0,0.0],ExplosionPower:5,PersistenceRequired:1}:@

layer
0,0,0,0,0,0,0,0,1,1,1,1,1,1,1,0,0,0,0,0,0,0,0
0,0,0,0,0,0,1,1,1,1,4,5,4,1,1,1,1,0,0,0,0,0,0
0,0,0,0,1,1,1,1,1,1,5,4,5,1,1,1,1,1,1,0,0,0,0
0,0,0,1,1,1,1,1,1,5,0,0,0,0,1,1,1,1,1,1,0,0,0
0,0,1,1,1,1,1,0,7,6,0,0,0,0,0,0,1,1,1,1,1,0,0
0,0,1,1,1,1,0,0,0,0,0,0,0,0,0,0,0,1,1,1,1,0,0
0,1,1,1,1,0,0,0,0,0,0,0,0,0,0,0,0,0,1,1,1,1,0
0,1,1,1,0,0,0,0,0,0,0,0,0,0,0,0,0,0,0,1,1,1,0
1,1,1,1,0,0,0,0,0,0,0,0,0,0,0,0,0,0,7,1,1,1,1
1,1,1,0,0,0,0,0,0,0,0,0,0,0,0,0,0,0,6,5,1,1,1
1,4,5,0,0,0,0,0,0,0,5,0,5,0,0,0,0,0,0,0,5,4,1
1,5,4,0,0,0,0,0,0,0,0,0,0,0,0,0,0,0,0,0,4,5,1
1,4,5,0,0,0,0,0,0,0,5,0,5,0,0,0,0,0,0,0,5,4,1
1,1,1,5,6,0,0,0,0,0,0,0,0,0,0,0,0,0,0,0,1,1,1
1,1,1,1,7,0,0,0,0,0,0,0,0,0,0,0,0,0,0,1,1,1,1
0,1,1,1,0,0,0,0,0,0,0,0,0,0,0,0,0,0,0,1,1,1,0
0,1,1,1,1,0,0,0,0,0,0,0,0,0,0,0,0,0,1,1,1,1,0
0,0,1,1,1,1,0,0,0,0,0,0,0,0,0,0,0,1,1,1,1,0,0
0,0,1,1,1,1,1,0,0,0,0,0,0,6,7,0,1,1,1,1,1,0,0
0,0,0,1,1,1,1,1,1,0,0,0,0,5,1,1,1,1,1,1,0,0,0
0,0,0,0,1,1,1,1,1,1,5,4,5,1,1,1,1,1,1,0,0,0,0
0,0,0,0,0,0,1,1,1,1,4,5,4,1,1,1,1,0,0,0,0,0,0
0,0,0,0,0,0,0,0,1,1,1,1,1,1,1,0,0,0,0,0,0,0,0
endlayer

layer
0,0,0,0,0,0,0,0,0,8,8,8,8,8,0,0,0,0,0,0,0,0,0
0,0,0,0,0,0,0,0,0,1,0,0,0,1,0,0,0,0,0,0,0,0,0
0,0,0,0,0,0,0,0,1,1,0,0,0,1,1,0,0,0,0,0,0,0,0
0,0,0,0,0,0,1,1,1,0,0,0,0,0,1,1,1,0,0,0,0,0,0
0,0,0,0,1,1,1,6,5,0,0,0,0,0,0,0,1,1,1,0,0,0,0
0,0,0,0,1,1,0,7,0,0,0,0,0,0,0,0,0,1,1,0,0,0,0
0,0,0,1,1,0,0,0,0,0,0,0,0,0,0,0,0,0,1,1,0,0,0
0,0,0,1,0,0,0,0,0,0,0,0,0,0,0,0,0,7,6,1,0,0,0
0,0,1,1,0,0,0,0,0,0,0,0,0,0,0,0,0,0,5,1,1,0,0
8,1,1,0,0,0,0,0,0,0,0,0,0,0,0,0,0,0,0,0,1,1,8
8,0,0,0,0,0,0,0,0,0,0,0,0,0,0,0,0,0,0,0,0,0,8
8,0,0,0,0,0,0,0,0,0,0,0,0,0,0,0,0,0,0,0,0,0,8
8,0,0,0,0,0,0,0,0,0,0,0,0,0,0,0,0,0,0,0,0,0,8
8,1,1,0,0,0,0,0,0,0,0,0,0,0,0,0,0,0,0,0,1,1,8
0,0,1,1,5,0,0,0,0,0,0,0,0,0,0,0,0,0,0,1,1,0,0
0,0,0,1,6,7,0,0,0,0,0,0,0,0,0,0,0,0,0,1,0,0,0
0,0,0,1,1,0,0,0,0,0,0,0,0,0,0,0,0,0,1,1,0,0,0
0,0,0,0,1,1,0,0,0,0,0,0,0,0,0,7,0,1,1,0,0,0,0
0,0,0,0,1,1,1,0,0,0,0,0,0,0,5,6,1,1,1,0,0,0,0
0,0,0,0,0,0,1,1,1,0,0,0,0,0,1,1,1,0,0,0,0,0,0
0,0,0,0,0,0,0,0,1,1,0,0,0,1,1,0,0,0,0,0,0,0,0
0,0,0,0,0,0,0,0,0,1,0,0,0,1,0,0,0,0,0,0,0,0,0
0,0,0,0,0,0,0,0,0,8,8,8,8,8,0,0,0,0,0,0,0,0,0
endlayer

layer
0,0,0,0,0,0,0,0,0,8,0,0,0,8,0,0,0,0,0,0,0,0,0
0,0,0,0,0,0,0,0,0,1,0,0,0,1,0,0,0,0,0,0,0,0,0
0,0,0,0,0,0,0,0,1,1,0,0,0,1,1,0,0,0,0,0,0,0,0
0,0,0,0,0,0,1,1,1,0,0,0,0,0,1,1,1,0,0,0,0,0,0
0,0,0,0,1,1,1,0,0,0,0,0,0,0,0,8,1,1,1,0,0,0,0
0,0,0,0,1,1,6,5,0,0,0,0,0,0,0,0,0,1,1,0,0,0,0
0,0,0,1,1,0,7,0,0,0,0,0,0,0,0,0,7,6,1,1,0,0,0
0,0,0,1,8,0,0,0,0,0,0,0,0,0,0,0,0,5,0,1,0,0,0
0,0,1,1,0,0,0,0,0,0,0,0,0,0,0,0,0,0,0,1,1,0,0
8,1,1,0,0,0,0,0,0,0,0,0,0,0,0,0,0,0,0,0,1,1,8
0,0,0,0,0,0,0,0,0,0,0,0,0,0,0,0,0,0,0,0,0,0,0
0,0,0,0,0,0,0,0,0,0,0,0,0,0,0,0,0,0,0,0,0,0,0
0,0,0,0,0,0,0,0,0,0,0,0,0,0,0,0,0,0,0,0,0,0,0
8,1,1,0,0,0,0,0,0,0,0,0,0,0,0,0,0,0,0,0,1,1,8
0,0,1,1,0,0,0,0,0,0,0,0,0,0,0,0,0,0,0,1,1,0,0
0,0,0,1,0,5,0,0,0,0,0,0,0,0,0,0,0,0,8,1,0,0,0
0,0,0,1,1,6,7,0,0,0,0,0,0,0,0,0,7,0,1,1,0,0,0
0,0,0,0,1,1,0,0,0,0,0,0,0,0,0,5,6,1,1,0,0,0,0
0,0,0,0,1,1,1,8,0,0,0,0,0,0,0,0,1,1,1,0,0,0,0
0,0,0,0,0,0,1,1,1,0,0,0,0,0,1,1,1,0,0,0,0,0,0
0,0,0,0,0,0,0,0,1,1,0,0,0,1,1,0,0,0,0,0,0,0,0
0,0,0,0,0,0,0,0,0,1,0,0,0,1,0,0,0,0,0,0,0,0,0
0,0,0,0,0,0,0,0,0,8,0,0,0,8,0,0,0,0,0,0,0,0,0
endlayer

layer
0,0,0,0,0,0,0,0,0,9,0,0,0,9,0,0,0,0,0,0,0,0,0
0,0,0,0,0,0,0,0,0,1,0,0,0,1,0,0,0,0,0,0,0,0,0
0,0,0,0,0,0,0,0,1,1,0,0,0,1,1,0,0,0,0,0,0,0,0
0,0,0,0,0,0,1,1,1,0,0,0,0,0,1,1,1,0,0,0,0,0,0
0,0,0,0,1,1,1,0,0,0,0,0,0,0,0,9,1,1,1,0,0,0,0
0,0,0,0,1,1,0,0,0,0,0,0,0,0,0,7,6,1,1,0,0,0,0
0,0,0,1,1,6,5,0,0,0,0,0,0,0,0,0,5,0,1,1,0,0,0
0,0,0,1,9,7,0,0,0,0,0,0,0,0,0,0,0,0,0,1,0,0,0
0,0,1,1,0,0,0,0,0,0,0,0,0,0,0,0,0,0,0,1,1,0,0
9,1,1,0,0,0,0,0,0,0,0,0,0,0,0,0,0,0,0,0,1,1,9
0,0,0,0,0,0,0,0,0,0,0,0,0,0,0,0,0,0,0,0,0,0,0
0,0,0,0,0,0,0,0,0,0,0,0,0,0,0,0,0,0,0,0,0,0,0
0,0,0,0,0,0,0,0,0,0,0,0,0,0,0,0,0,0,0,0,0,0,0
9,1,1,0,0,0,0,0,0,0,0,0,0,0,0,0,0,0,0,0,1,1,9
0,0,1,1,0,0,0,0,0,0,0,0,0,0,0,0,0,0,0,1,1,0,0
0,0,0,1,0,0,0,0,0,0,0,0,0,0,0,0,0,7,9,1,0,0,0
0,0,0,1,1,0,5,0,0,0,0,0,0,0,0,0,5,6,1,1,0,0,0
0,0,0,0,1,1,6,7,0,0,0,0,0,0,0,0,0,1,1,0,0,0,0
0,0,0,0,1,1,1,9,0,0,0,0,0,0,0,0,1,1,1,0,0,0,0
0,0,0,0,0,0,1,1,1,0,0,0,0,0,1,1,1,0,0,0,0,0,0
0,0,0,0,0,0,0,0,1,1,0,0,0,1,1,0,0,0,0,0,0,0,0
0,0,0,0,0,0,0,0,0,1,0,0,0,1,0,0,0,0,0,0,0,0,0
0,0,0,0,0,0,0,0,0,9,0,0,0,9,0,0,0,0,0,0,0,0,0
endlayer

layer
0,0,0,0,0,0,0,0,0,0,0,0,0,0,0,0,0,0,0,0,0,0,0
0,0,0,0,0,0,0,0,0,1,0,0,0,1,0,0,0,0,0,0,0,0,0
0,0,0,0,0,0,0,0,1,1,0,0,0,1,1,0,0,0,0,0,0,0,0
0,0,0,0,0,0,1,1,1,0,0,0,0,0,1,1,1,0,0,0,0,0,0
0,0,0,0,1,1,1,0,0,0,0,0,0,0,7,6,1,1,1,0,0,0,0
0,0,0,0,1,1,0,0,0,0,0,0,0,0,0,5,0,1,1,0,0,0,0
0,0,0,1,1,0,0,0,0,0,0,0,0,0,0,0,0,0,1,1,0,0,0
0,0,0,1,6,5,0,0,0,0,0,0,0,0,0,0,0,0,0,1,0,0,0
0,0,1,1,7,0,0,0,0,0,0,0,0,0,0,0,0,0,0,1,1,0,0
0,1,1,0,0,0,0,0,0,0,0,0,0,0,0,0,0,0,0,0,1,1,0
0,0,0,0,0,0,0,0,0,0,0,8,0,0,0,0,0,0,0,0,0,0,0
0,0,0,0,0,0,0,0,0,0,8,8,8,0,0,0,0,0,0,0,0,0,0
0,0,0,0,0,0,0,0,0,0,0,8,0,0,0,0,0,0,0,0,0,0,0
0,1,1,0,0,0,0,0,0,0,0,0,0,0,0,0,0,0,0,0,1,1,0
0,0,1,1,0,0,0,0,0,0,0,0,0,0,0,0,0,0,7,1,1,0,0
0,0,0,1,0,0,0,0,0,0,0,0,0,0,0,0,0,5,6,1,0,0,0
0,0,0,1,1,0,0,0,0,0,0,0,0,0,0,0,0,0,1,1,0,0,0
0,0,0,0,1,1,0,5,0,0,0,0,0,0,0,0,0,1,1,0,0,0,0
0,0,0,0,1,1,1,6,7,0,0,0,0,0,0,0,1,1,1,0,0,0,0
0,0,0,0,0,0,1,1,1,0,0,0,0,0,1,1,1,0,0,0,0,0,0
0,0,0,0,0,0,0,0,1,1,0,0,0,1,1,0,0,0,0,0,0,0,0
0,0,0,0,0,0,0,0,0,1,0,0,0,1,0,0,0,0,0,0,0,0,0
0,0,0,0,0,0,0,0,0,0,0,0,0,0,0,0,0,0,0,0,0,0,0
endlayer

layer
0,0,0,0,0,0,0,0,0,0,0,0,0,0,0,0,0,0,0,0,0,0,0
0,0,0,0,0,0,0,0,0,1,1,0,1,1,0,0,0,0,0,0,0,0,0
0,0,0,0,0,0,0,0,1,1,0,0,0,1,1,0,0,0,0,0,0,0,0
0,0,0,0,0,0,1,1,1,0,0,0,0,7,1,1,1,0,0,0,0,0,0
0,0,0,0,1,1,1,0,0,0,0,0,0,6,5,0,1,1,1,0,0,0,0
0,0,0,0,1,1,0,0,0,0,0,0,0,0,0,0,0,1,1,0,0,0,0
0,0,0,1,1,0,0,0,0,0,0,0,0,0,0,0,0,0,1,1,0,0,0
0,0,0,1,0,0,0,0,0,0,0,0,0,0,0,0,0,0,0,1,0,0,0
0,0,1,1,5,0,0,0,8,0,0,0,0,0,8,0,0,0,0,1,1,0,0
0,1,1,7,6,0,0,0,0,0,0,0,0,0,0,0,0,0,0,0,1,1,0
0,1,0,0,0,0,0,0,0,0,0,9,0,0,0,0,0,0,0,0,0,1,0
0,0,0,0,0,0,0,0,0,0,9,8,9,0,0,0,0,0,0,0,0,0,0
0,1,0,0,0,0,0,0,0,0,0,9,0,0,0,0,0,0,0,0,0,1,0
0,1,1,0,0,0,0,0,0,0,0,0,0,0,0,0,0,0,6,7,1,1,0
0,0,1,1,0,0,0,0,8,0,0,0,0,0,8,0,0,0,5,1,1,0,0
0,0,0,1,0,0,0,0,0,0,0,0,0,0,0,0,0,0,0,1,0,0,0
0,0,0,1,1,0,0,0,0,0,0,0,0,0,0,0,0,0,1,1,0,0,0
0,0,0,0,1,1,0,0,0,0,0,0,0,0,0,0,0,1,1,0,0,0,0
0,0,0,0,1,1,1,0,5,6,0,0,0,0,0,0,1,1,1,0,0,0,0
0,0,0,0,0,0,1,1,1,7,0,0,0,0,1,1,1,0,0,0,0,0,0
0,0,0,0,0,0,0,0,1,1,0,0,0,1,1,0,0,0,0,0,0,0,0
0,0,0,0,0,0,0,0,0,1,1,0,1,1,0,0,0,0,0,0,0,0,0
0,0,0,0,0,0,0,0,0,0,0,0,0,0,0,0,0,0,0,0,0,0,0
endlayer

layer
0,0,0,0,0,0,0,0,1,1,1,1,1,1,1,0,0,0,0,0,0,0,0
0,0,0,0,0,0,1,1,1,1,1,1,1,1,1,1,1,0,0,0,0,0,0
0,0,0,0,1,1,1,1,1,1,1,1,1,1,1,1,1,1,1,0,0,0,0
0,0,0,1,1,1,1,1,1,7,6,10,6,5,1,1,1,1,1,1,0,0,0
0,0,1,1,1,1,1,0,0,0,0,2,0,0,0,0,1,1,1,1,1,0,0
0,0,1,1,1,1,0,0,0,0,0,3,0,0,0,0,0,1,1,1,1,0,0
0,1,1,1,1,0,0,0,0,0,0,2,0,0,0,0,0,0,1,1,1,1,0
0,1,1,1,0,0,0,0,0,0,0,3,0,0,0,0,0,0,0,1,1,1,0
1,1,1,1,0,0,0,0,8,2,3,2,3,2,8,0,0,0,0,1,1,1,1
1,1,1,5,0,0,0,0,2,3,2,3,2,3,2,0,0,0,0,7,1,1,1
1,1,1,6,0,0,0,0,3,2,3,2,3,2,3,0,0,0,0,6,1,1,1
1,1,1,10,2,3,2,3,2,3,2,3,2,3,2,3,2,3,2,10,1,1,1
1,1,1,6,0,0,0,0,3,2,3,2,3,2,3,0,0,0,0,6,1,1,1
1,1,1,7,0,0,0,0,2,3,2,3,2,3,2,0,0,0,0,5,1,1,1
1,1,1,1,0,0,0,0,8,2,3,2,3,2,8,0,0,0,0,1,1,1,1
0,1,1,1,0,0,0,0,0,0,0,3,0,0,0,0,0,0,0,1,1,1,0
0,1,1,1,1,0,0,0,0,0,0,2,0,0,0,0,0,0,1,1,1,1,0
0,0,1,1,1,1,0,0,0,0,0,3,0,0,0,0,0,1,1,1,1,0,0
0,0,1,1,1,1,1,0,0,0,0,2,0,0,0,0,1,1,1,1,1,0,0
0,0,0,1,1,1,1,1,1,5,6,10,6,7,1,1,1,1,1,1,0,0,0
0,0,0,0,1,1,1,1,1,1,1,1,1,1,1,1,1,1,1,0,0,0,0
0,0,0,0,0,0,1,1,1,1,1,1,1,1,1,1,1,0,0,0,0,0,0
0,0,0,0,0,0,0,0,1,1,1,1,1,1,1,0,0,0,0,0,0,0,0
endlayer

layer
0,0,0,0,0,0,0,0,1,1,1,1,1,1,1,0,0,0,0,0,0,0,0
0,0,0,0,0,0,1,1,1,1,4,5,4,1,1,1,1,0,0,0,0,0,0
0,0,0,0,1,1,1,1,1,1,5,4,5,1,1,1,1,1,1,0,0,0,0
0,0,0,1,1,1,1,1,1,5,0,0,0,0,1,1,1,1,1,1,0,0,0
0,0,1,1,1,1,1,0,7,6,0,0,0,0,0,0,1,1,1,1,1,0,0
0,0,1,1,1,1,0,0,0,0,0,0,0,0,0,0,0,1,1,1,1,0,0
0,1,1,1,1,0,0,0,0,0,0,0,0,0,0,0,0,0,1,1,1,1,0
0,1,1,1,0,0,0,0,0,0,0,0,0,0,0,0,0,0,0,1,1,1,0
1,1,1,1,0,0,0,0,8,8,0,0,0,8,8,0,0,0,7,1,1,1,1
1,1,1,0,0,0,0,0,8,0,0,0,0,0,8,0,0,0,6,5,1,1,1
1,4,5,0,0,0,0,0,0,0,0,11,0,0,0,0,0,0,0,0,5,4,1
1,5,4,0,0,0,0,0,0,0,14,13,12,0,0,0,0,0,0,0,4,5,1
1,4,5,0,0,0,0,0,0,0,0,0,0,0,0,0,0,0,0,0,5,4,1
1,1,1,5,6,0,0,0,8,0,0,0,0,0,8,0,0,0,0,0,1,1,1
1,1,1,1,7,0,0,0,8,8,0,0,0,8,8,0,0,0,0,1,1,1,1
0,1,1,1,0,0,0,0,0,0,0,0,0,0,0,0,0,0,0,1,1,1,0
0,1,1,1,1,0,0,0,0,0,0,0,0,0,0,0,0,0,1,1,1,1,0
0,0,1,1,1,1,0,0,0,0,0,0,0,0,0,0,0,1,1,1,1,0,0
0,0,1,1,1,1,1,0,0,0,0,0,0,6,7,0,1,1,1,1,1,0,0
0,0,0,1,1,1,1,1,1,0,0,0,0,5,1,1,1,1,1,1,0,0,0
0,0,0,0,1,1,1,1,1,1,5,4,5,1,1,1,1,1,1,0,0,0,0
0,0,0,0,0,0,1,1,1,1,4,5,4,1,1,1,1,0,0,0,0,0,0
0,0,0,0,0,0,0,0,1,1,1,1,1,1,1,0,0,0,0,0,0,0,0
endlayer

layer
0,0,0,0,0,0,0,0,0,8,8,8,8,8,0,0,0,0,0,0,0,0,0
0,0,0,0,0,0,0,0,0,1,0,0,0,1,0,0,0,0,0,0,0,0,0
0,0,0,0,0,0,0,0,1,1,0,0,0,1,1,0,0,0,0,0,0,0,0
0,0,0,0,0,0,1,1,1,0,0,0,0,0,1,1,1,0,0,0,0,0,0
0,0,0,0,1,1,1,6,5,0,0,0,0,0,0,0,1,1,1,0,0,0,0
0,0,0,0,1,1,0,7,0,0,0,0,0,0,0,0,0,1,1,0,0,0,0
0,0,0,1,1,0,0,0,0,0,0,0,0,0,0,0,0,0,1,1,0,0,0
0,0,0,1,0,0,0,0,0,0,0,0,0,0,0,0,0,7,6,1,0,0,0
0,0,1,1,0,0,0,0,9,15,0,0,0,15,9,0,0,0,5,1,1,0,0
8,1,1,0,0,0,0,0,15,0,0,0,0,0,15,0,0,0,0,0,1,1,8
8,0,0,0,0,0,0,0,0,0,0,0,0,0,0,0,0,0,0,0,0,0,8
8,0,0,0,0,0,0,0,0,0,9,15,0,0,0,0,0,0,0,0,0,0,8
8,0,0,0,0,0,0,0,0,0,0,0,0,0,0,0,0,0,0,0,0,0,8
8,1,1,0,0,0,0,0,15,0,0,0,0,0,15,0,0,0,0,0,1,1,8
0,0,1,1,5,0,0,0,9,15,0,0,0,15,9,0,0,0,0,1,1,0,0
0,0,0,1,6,7,0,0,0,0,0,0,0,0,0,0,0,0,0,1,0,0,0
0,0,0,1,1,0,0,0,0,0,0,0,0,0,0,0,0,0,1,1,0,0,0
0,0,0,0,1,1,0,0,0,0,0,0,0,0,0,7,0,1,1,0,0,0,0
0,0,0,0,1,1,1,0,0,0,0,0,0,0,5,6,1,1,1,0,0,0,0
0,0,0,0,0,0,1,1,1,0,0,0,0,0,1,1,1,0,0,0,0,0,0
0,0,0,0,0,0,0,0,1,1,0,0,0,1,1,0,0,0,0,0,0,0,0
0,0,0,0,0,0,0,0,0,1,0,0,0,1,0,0,0,0,0,0,0,0,0
0,0,0,0,0,0,0,0,0,8,8,8,8,8,0,0,0,0,0,0,0,0,0
endlayer

layer
0,0,0,0,0,0,0,0,0,8,0,0,0,8,0,0,0,0,0,0,0,0,0
0,0,0,0,0,0,0,0,0,1,0,0,0,1,0,0,0,0,0,0,0,0,0
0,0,0,0,0,0,0,0,1,1,0,0,0,1,1,0,0,0,0,0,0,0,0
0,0,0,0,0,0,1,1,1,0,0,0,0,0,1,1,1,0,0,0,0,0,0
0,0,0,0,1,1,1,0,0,0,0,0,0,0,0,8,1,1,1,0,0,0,0
0,0,0,0,1,1,6,5,0,0,0,0,0,0,0,0,0,1,1,0,0,0,0
0,0,0,1,1,0,7,0,0,0,0,0,0,0,0,0,7,6,1,1,0,0,0
0,0,0,1,8,0,0,0,0,0,0,0,0,0,0,0,0,5,0,1,0,0,0
0,0,1,1,0,0,0,0,0,0,0,0,0,0,0,0,0,0,0,1,1,0,0
8,1,1,0,0,0,0,0,0,0,0,0,0,0,0,0,0,0,0,0,1,1,8
0,0,0,0,0,0,0,0,0,0,0,0,0,0,0,0,0,0,0,0,0,0,0
0,0,0,0,0,0,0,0,0,0,0,16,0,0,0,0,0,0,0,0,0,0,0
0,0,0,0,0,0,0,0,0,0,0,0,0,0,0,0,0,0,0,0,0,0,0
8,1,1,0,0,0,0,0,0,0,0,0,0,0,0,0,0,0,0,0,1,1,8
0,0,1,1,0,0,0,0,0,0,0,0,0,0,0,0,0,0,0,1,1,0,0
0,0,0,1,0,5,0,0,0,0,0,0,0,0,0,0,0,0,8,1,0,0,0
0,0,0,1,1,6,7,0,0,0,0,0,0,0,0,0,7,0,1,1,0,0,0
0,0,0,0,1,1,0,0,0,0,0,0,0,0,0,5,6,1,1,0,0,0,0
0,0,0,0,1,1,1,8,0,0,0,0,0,0,0,0,1,1,1,0,0,0,0
0,0,0,0,0,0,1,1,1,0,0,0,0,0,1,1,1,0,0,0,0,0,0
0,0,0,0,0,0,0,0,1,1,0,0,0,1,1,0,0,0,0,0,0,0,0
0,0,0,0,0,0,0,0,0,1,0,0,0,1,0,0,0,0,0,0,0,0,0
0,0,0,0,0,0,0,0,0,8,0,0,0,8,0,0,0,0,0,0,0,0,0
endlayer

layer
0,0,0,0,0,0,0,0,0,9,0,0,0,9,0,0,0,0,0,0,0,0,0
0,0,0,0,0,0,0,0,0,1,0,0,0,1,0,0,0,0,0,0,0,0,0
0,0,0,0,0,0,0,0,1,1,0,0,0,1,1,0,0,0,0,0,0,0,0
0,0,0,0,0,0,1,1,1,0,0,0,0,0,1,1,1,0,0,0,0,0,0
0,0,0,0,1,1,1,0,0,0,0,0,0,0,0,9,1,1,1,0,0,0,0
0,0,0,0,1,1,0,0,0,0,0,0,0,0,0,7,6,1,1,0,0,0,0
0,0,0,1,1,6,5,0,0,0,0,0,0,0,0,0,5,0,1,1,0,0,0
0,0,0,1,9,7,0,0,0,0,0,0,0,0,0,0,0,0,0,1,0,0,0
0,0,1,1,0,0,0,0,0,0,0,0,0,0,0,0,0,0,0,1,1,0,0
9,1,1,0,0,0,0,0,0,0,0,8,0,0,0,0,0,0,0,0,1,1,9
0,0,0,0,0,0,0,0,0,0,8,8,8,0,0,0,0,0,0,0,0,0,0
0,0,0,0,0,0,0,0,0,8,8,2,8,8,0,0,0,0,0,0,0,0,0
0,0,0,0,0,0,0,0,0,0,8,8,8,0,0,0,0,0,0,0,0,0,0
9,1,1,0,0,0,0,0,0,0,0,8,0,0,0,0,0,0,0,0,1,1,9
0,0,1,1,0,0,0,0,0,0,0,0,0,0,0,0,0,0,0,1,1,0,0
0,0,0,1,0,0,0,0,0,0,0,0,0,0,0,0,0,7,9,1,0,0,0
0,0,0,1,1,0,5,0,0,0,0,0,0,0,0,0,5,6,1,1,0,0,0
0,0,0,0,1,1,6,7,0,0,0,0,0,0,0,0,0,1,1,0,0,0,0
0,0,0,0,1,1,1,9,0,0,0,0,0,0,0,0,1,1,1,0,0,0,0
0,0,0,0,0,0,1,1,1,0,0,0,0,0,1,1,1,0,0,0,0,0,0
0,0,0,0,0,0,0,0,1,1,0,0,0,1,1,0,0,0,0,0,0,0,0
0,0,0,0,0,0,0,0,0,1,0,0,0,1,0,0,0,0,0,0,0,0,0
0,0,0,0,0,0,0,0,0,9,0,0,0,9,0,0,0,0,0,0,0,0,0
endlayer

layer
0,0,0,0,0,0,0,0,0,0,0,0,0,0,0,0,0,0,0,0,0,0,0
0,0,0,0,0,0,0,0,0,1,0,0,0,1,0,0,0,0,0,0,0,0,0
0,0,0,0,0,0,0,0,1,1,0,0,0,1,1,0,0,0,0,0,0,0,0
0,0,0,0,0,0,1,1,1,0,0,0,0,0,1,1,1,0,0,0,0,0,0
0,0,0,0,1,1,1,0,0,0,0,0,0,0,7,6,1,1,1,0,0,0,0
0,0,0,0,1,1,0,0,0,0,0,0,0,0,0,5,0,1,1,0,0,0,0
0,0,0,1,1,0,0,0,0,0,0,0,0,0,0,0,0,0,1,1,0,0,0
0,0,0,1,6,5,0,0,0,0,0,0,0,0,0,0,0,0,0,1,0,0,0
0,0,1,1,7,0,0,0,0,0,0,0,0,0,0,0,0,0,0,1,1,0,0
0,1,1,0,0,0,0,0,0,0,0,9,0,0,0,0,0,0,0,0,1,1,0
0,0,0,0,0,0,0,0,0,0,9,8,9,0,0,0,0,0,0,0,0,0,0
0,0,0,0,0,0,0,0,0,9,8,8,8,9,0,0,0,0,0,0,0,0,0
0,0,0,0,0,0,0,0,0,0,9,8,9,0,0,0,0,0,0,0,0,0,0
0,1,1,0,0,0,0,0,0,0,0,9,0,0,0,0,0,0,0,0,1,1,0
0,0,1,1,0,0,0,0,0,0,0,0,0,0,0,0,0,0,7,1,1,0,0
0,0,0,1,0,0,0,0,0,0,0,0,0,0,0,0,0,5,6,1,0,0,0
0,0,0,1,1,0,0,0,0,0,0,0,0,0,0,0,0,0,1,1,0,0,0
0,0,0,0,1,1,0,5,0,0,0,0,0,0,0,0,0,1,1,0,0,0,0
0,0,0,0,1,1,1,6,7,0,0,0,0,0,0,0,1,1,1,0,0,0,0
0,0,0,0,0,0,1,1,1,0,0,0,0,0,1,1,1,0,0,0,0,0,0
0,0,0,0,0,0,0,0,1,1,0,0,0,1,1,0,0,0,0,0,0,0,0
0,0,0,0,0,0,0,0,0,1,0,0,0,1,0,0,0,0,0,0,0,0,0
0,0,0,0,0,0,0,0,0,0,0,0,0,0,0,0,0,0,0,0,0,0,0
endlayer

layer
0,0,0,0,0,0,0,0,0,0,0,0,0,0,0,0,0,0,0,0,0,0,0
0,0,0,0,0,0,0,0,0,1,1,0,1,1,0,0,0,0,0,0,0,0,0
0,0,0,0,0,0,0,0,1,1,0,0,0,1,1,0,0,0,0,0,0,0,0
0,0,0,0,0,0,1,1,1,0,0,0,0,7,1,1,1,0,0,0,0,0,0
0,0,0,0,1,1,1,0,0,0,0,0,0,6,5,0,1,1,1,0,0,0,0
0,0,0,0,1,1,0,0,0,0,0,0,0,0,0,0,0,1,1,0,0,0,0
0,0,0,1,1,0,0,0,0,0,0,0,0,0,0,0,0,0,1,1,0,0,0
0,0,0,1,0,0,0,0,0,0,0,0,0,0,0,0,0,0,0,1,0,0,0
0,0,1,1,5,0,0,0,0,0,0,0,0,0,0,0,0,0,0,1,1,0,0
0,1,1,7,6,0,0,0,0,0,0,0,0,0,0,0,0,0,0,0,1,1,0
0,1,0,0,0,0,0,0,0,0,0,0,0,0,0,0,0,0,0,0,0,1,0
0,0,0,0,0,0,0,0,0,0,0,8,0,0,0,0,0,0,0,0,0,0,0
0,1,0,0,0,0,0,0,0,0,0,0,0,0,0,0,0,0,0,0,0,1,0
0,1,1,0,0,0,0,0,0,0,0,0,0,0,0,0,0,0,6,7,1,1,0
0,0,1,1,0,0,0,0,0,0,0,0,0,0,0,0,0,0,5,1,1,0,0
0,0,0,1,0,0,0,0,0,0,0,0,0,0,0,0,0,0,0,1,0,0,0
0,0,0,1,1,0,0,0,0,0,0,0,0,0,0,0,0,0,1,1,0,0,0
0,0,0,0,1,1,0,0,0,0,0,0,0,0,0,0,0,1,1,0,0,0,0
0,0,0,0,1,1,1,0,5,6,0,0,0,0,0,0,1,1,1,0,0,0,0
0,0,0,0,0,0,1,1,1,7,0,0,0,0,1,1,1,0,0,0,0,0,0
0,0,0,0,0,0,0,0,1,1,0,0,0,1,1,0,0,0,0,0,0,0,0
0,0,0,0,0,0,0,0,0,1,1,0,1,1,0,0,0,0,0,0,0,0,0
0,0,0,0,0,0,0,0,0,0,0,0,0,0,0,0,0,0,0,0,0,0,0
endlayer

layer
0,0,0,0,0,19,18,18,1,1,1,1,1,1,1,18,18,17,0,0,0,0,0
0,0,0,19,18,18,1,1,1,1,1,1,1,1,1,1,1,18,18,17,0,0,0
0,0,19,18,1,1,1,1,1,1,1,1,1,1,1,1,1,1,1,18,17,0,0
0,18,19,1,1,1,1,1,1,3,2,3,2,5,1,1,1,1,1,1,18,18,0
0,19,1,1,1,1,1,2,3,2,3,2,3,0,0,0,1,1,1,1,1,17,0
18,19,1,1,1,1,0,3,2,3,2,3,2,3,2,0,0,1,1,1,1,17,18
19,1,1,1,1,0,0,2,3,2,3,2,3,2,3,2,3,2,1,1,1,1,17
19,1,1,1,0,0,2,3,2,3,2,3,2,3,2,3,2,3,2,1,1,1,18
1,1,1,1,0,2,3,2,3,2,3,2,3,2,3,2,3,2,3,1,1,1,1
1,1,1,5,0,3,2,3,2,3,2,3,2,3,2,3,2,3,2,3,1,1,1
1,1,1,2,3,2,3,2,3,2,3,2,3,2,3,2,3,2,3,2,1,1,1
1,1,1,3,2,3,2,3,2,3,2,3,2,3,2,3,2,3,2,3,1,1,1
1,1,1,2,3,2,3,2,3,2,3,2,3,2,3,2,3,2,3,2,1,1,1
1,1,1,3,2,3,2,3,2,3,2,3,2,3,2,3,2,3,0,5,1,1,1
1,1,1,1,3,2,3,2,3,2,3,2,3,2,3,2,3,2,0,1,1,1,1
11,1,1,1,2,3,2,3,2,3,2,3,2,3,2,3,2,0,0,1,1,1,17
19,1,1,1,1,0,0,2,3,2,3,2,3,2,3,2,0,0,1,1,1,1,17
11,11,1,1,1,1,0,0,2,3,2,3,2,3,2,3,0,1,1,1,1,17,11
0,19,1,1,1,1,1,0,0,0,3,2,3,2,3,2,1,1,1,1,1,17,0
0,11,11,1,1,1,1,1,1,5,2,3,2,3,1,1,1,1,1,1,17,11,0
0,0,19,11,1,1,1,1,1,1,1,1,1,1,1,1,1,1,1,17,11,0,0
0,0,0,19,11,11,1,1,1,1,1,1,1,1,1,1,1,17,11,17,0,0,0
0,0,0,0,0,19,11,11,1,1,1,1,1,1,1,17,11,17,0,0,0,0,0
endlayer

layer
0,0,0,0,0,0,0,0,19,18,18,18,18,18,18,0,0,0,0,0,0,0,0
0,0,0,0,0,0,18,18,19,1,1,1,1,1,17,18,18,0,0,0,0,0,0
0,0,0,0,19,18,19,20,1,0,21,22,21,0,1,20,17,18,18,0,0,0,0
0,0,0,19,18,20,1,1,0,0,0,0,0,0,0,1,1,20,17,18,0,0,0
0,0,19,18,1,1,0,0,0,0,0,0,0,0,0,0,0,1,1,17,18,0,0
0,0,19,20,1,0,0,0,0,19,23,23,23,17,0,0,0,0,1,20,17,0,0
0,19,18,1,0,0,0,0,0,0,0,24,0,0,0,0,0,0,0,1,17,18,0
0,19,20,1,0,0,0,0,0,0,0,0,0,0,0,0,0,0,0,1,20,17,0
19,18,1,0,0,0,0,0,0,18,0,25,0,18,0,0,0,0,0,0,1,17,18
19,1,0,0,0,18,0,0,19,23,17,0,19,23,17,0,0,18,0,0,0,1,17
19,1,27,0,0,23,0,0,0,11,0,0,0,11,0,0,0,23,0,0,26,1,17
19,1,33,0,0,23,32,0,30,0,0,31,0,0,30,0,29,23,0,0,28,1,17
19,1,27,0,0,23,0,0,0,18,0,0,0,18,0,0,0,23,0,0,26,1,17
19,1,0,0,0,11,0,0,19,23,17,0,19,23,17,0,0,11,0,0,0,1,17
19,11,1,0,0,0,0,0,0,11,0,34,0,11,0,0,0,0,0,0,1,11,17
0,19,20,1,0,0,0,0,0,0,0,0,0,0,0,0,0,0,0,1,20,17,0
0,19,11,1,0,0,0,0,0,0,0,35,0,0,0,0,0,0,0,1,11,17,0
0,0,19,20,1,0,0,0,0,19,23,23,23,17,0,0,0,0,1,20,17,0,0
0,0,11,11,1,1,0,0,0,0,0,0,0,0,0,0,0,1,1,11,17,0,0
0,0,0,19,11,20,1,1,0,0,0,0,0,0,0,1,1,20,11,17,0,0,0
0,0,0,0,19,11,19,20,1,0,36,37,36,0,1,20,11,11,17,0,0,0,0
0,0,0,0,0,0,19,11,19,1,1,1,1,1,11,11,17,0,0,0,0,0,0
0,0,0,0,0,0,0,0,11,11,11,11,11,11,17,0,0,0,0,0,0,0,0
endlayer

layer
0,0,0,0,0,0,0,0,0,0,0,0,0,0,0,0,0,0,0,0,0,0,0
0,0,0,0,0,0,0,0,0,20,20,20,20,20,0,0,0,0,0,0,0,0,0
0,0,0,0,0,0,0,20,20,38,0,0,0,38,20,20,0,0,0,0,0,0,0
0,0,0,0,0,20,20,20,0,0,0,0,0,0,0,20,20,20,0,0,0,0,0
0,0,0,0,20,20,0,0,0,0,0,0,0,0,0,0,0,20,20,0,0,0,0
0,0,0,20,20,0,0,0,0,8,23,23,23,8,0,0,0,0,20,20,0,0,0
0,0,0,20,0,0,0,0,0,0,0,24,0,0,0,0,0,0,0,20,0,0,0
0,0,20,20,0,0,0,0,0,0,0,0,0,0,0,0,0,0,0,20,20,0,0
0,0,20,0,0,0,0,0,0,8,0,0,0,8,0,0,0,0,0,0,20,0,0
0,20,14,0,0,8,0,0,8,23,8,0,8,23,8,0,0,8,0,0,12,20,0
0,20,0,0,0,23,0,0,0,8,0,0,0,8,0,0,0,23,0,0,0,20,0
0,20,0,0,0,23,32,0,0,0,0,44,0,0,0,0,29,23,0,0,0,20,0
0,20,0,0,0,23,0,0,0,8,0,0,0,8,0,0,0,23,0,0,0,20,0
0,20,14,0,0,8,0,0,8,23,8,0,8,23,8,0,0,8,0,0,12,20,0
0,0,20,0,0,0,0,0,0,8,0,0,0,8,0,0,0,0,0,0,20,0,0
0,0,20,20,0,0,0,0,0,0,0,0,0,0,0,0,0,0,0,20,20,0,0
0,0,0,20,0,0,0,0,0,0,0,35,0,0,0,0,0,0,0,20,0,0,0
0,0,0,20,20,0,0,0,0,8,23,23,23,8,0,0,0,0,20,20,0,0,0
0,0,0,0,20,20,0,0,0,0,0,0,0,0,0,0,0,20,20,0,0,0,0
0,0,0,0,0,20,20,20,0,0,0,0,0,0,0,20,20,20,0,0,0,0,0
0,0,0,0,0,0,0,20,20,39,0,0,0,39,20,20,0,0,0,0,0,0,0
0,0,0,0,0,0,0,0,0,20,20,20,20,20,0,0,0,0,0,0,0,0,0
0,0,0,0,0,0,0,0,0,0,0,0,0,0,0,0,0,0,0,0,0,0,0
endlayer

layer
0,0,0,0,0,0,0,0,0,0,0,0,0,0,0,0,0,0,0,0,0,0,0
0,0,0,0,0,0,0,0,0,19,18,18,18,17,0,0,0,0,0,0,0,0,0
0,0,0,0,0,0,0,19,18,18,38,38,38,18,18,17,0,0,0,0,0,0,0
0,0,0,0,0,18,18,19,38,38,13,0,13,38,38,18,18,17,0,0,0,0,0
0,0,0,0,18,19,38,38,13,0,0,0,0,0,13,38,38,18,17,0,0,0,0
0,0,0,18,19,20,13,0,0,8,23,23,23,8,0,0,13,20,18,17,0,0,0
0,0,0,19,14,13,0,0,0,0,0,24,0,0,0,0,0,13,12,17,0,0,0
0,0,18,19,14,0,0,0,0,0,0,0,0,0,0,0,0,0,12,18,17,0,0
0,0,19,14,13,0,0,0,0,8,0,0,0,8,0,0,0,0,13,12,17,0,0
0,19,18,14,0,8,0,0,8,23,8,0,8,23,8,0,0,8,0,12,18,17,0
0,19,14,13,0,23,0,0,0,8,0,0,0,8,0,0,0,23,0,13,12,17,0
0,19,14,0,0,23,32,0,0,0,0,0,0,0,0,0,29,23,0,0,12,17,0
0,19,14,13,0,23,0,0,0,8,0,0,0,8,0,0,0,23,0,13,12,17,0
0,19,11,14,0,8,0,0,8,23,8,0,8,23,8,0,0,8,0,12,17,11,0
0,0,19,14,13,0,0,0,0,8,0,0,0,8,0,0,0,0,13,12,17,0,0
0,0,19,11,14,0,0,0,0,0,0,0,0,0,0,0,0,0,12,17,11,0,0
0,0,0,19,14,13,0,0,0,0,0,35,0,0,0,0,0,13,12,17,0,0,0
0,0,0,19,11,20,13,0,0,8,23,23,23,8,0,0,13,20,17,11,0,0,0
0,0,0,0,19,11,39,39,13,0,0,0,0,0,13,39,39,17,11,0,0,0,0
0,0,0,0,0,19,11,11,39,39,13,0,13,39,39,17,11,11,0,0,0,0,0
0,0,0,0,0,0,0,19,11,11,39,39,39,17,11,11,0,0,0,0,0,0,0
0,0,0,0,0,0,0,0,0,19,11,11,11,11,0,0,0,0,0,0,0,0,0
0,0,0,0,0,0,0,0,0,0,0,0,0,0,0,0,0,0,0,0,0,0,0
endlayer

layer
0,0,0,0,0,0,0,0,0,0,0,0,0,0,0,0,0,0,0,0,0,0,0
0,0,0,0,0,0,0,0,0,0,0,0,0,0,0,0,0,0,0,0,0,0,0
0,0,0,0,0,0,0,0,0,0,18,18,18,0,0,0,0,0,0,0,0,0,0
0,0,0,0,0,0,0,0,20,20,20,38,20,20,20,0,0,0,0,0,0,0,0
0,0,0,0,0,0,20,20,20,0,0,0,0,0,20,20,20,0,0,0,0,0,0
0,0,0,0,0,20,20,0,0,8,23,23,23,8,0,0,20,20,0,0,0,0,0
0,0,0,0,20,20,0,0,0,0,8,24,8,0,0,0,0,20,20,0,0,0,0
0,0,0,0,20,0,0,0,0,0,0,0,0,0,0,0,0,0,20,0,0,0,0
0,0,0,20,20,0,0,0,0,39,0,0,0,39,0,0,0,0,20,20,0,0,0
0,0,0,20,0,8,0,0,12,40,14,13,12,40,14,0,0,8,0,20,0,0,0
0,0,19,20,0,23,8,0,0,38,0,0,0,38,0,0,8,23,0,20,17,0,0
0,0,19,14,0,23,32,0,0,13,0,0,0,13,0,0,29,23,0,12,17,0,0
0,0,19,20,0,23,8,0,0,39,0,0,0,39,0,0,8,23,0,20,17,0,0
0,0,0,20,0,8,0,0,12,40,14,13,12,40,14,0,0,8,0,20,0,0,0
0,0,0,20,20,0,0,0,0,38,0,0,0,38,0,0,0,0,20,20,0,0,0
0,0,0,0,20,0,0,0,0,0,0,0,0,0,0,0,0,0,20,0,0,0,0
0,0,0,0,20,20,0,0,0,0,8,35,8,0,0,0,0,20,20,0,0,0,0
0,0,0,0,0,20,20,0,0,8,23,23,23,8,0,0,20,20,0,0,0,0,0
0,0,0,0,0,0,20,20,20,0,0,0,0,0,20,20,20,0,0,0,0,0,0
0,0,0,0,0,0,0,0,20,20,20,39,20,20,20,0,0,0,0,0,0,0,0
0,0,0,0,0,0,0,0,0,0,11,11,11,0,0,0,0,0,0,0,0,0,0
0,0,0,0,0,0,0,0,0,0,0,0,0,0,0,0,0,0,0,0,0,0,0
0,0,0,0,0,0,0,0,0,0,0,0,0,0,0,0,0,0,0,0,0,0,0
endlayer

layer
0,0,0,0,0,0,0,0,0,0,0,0,0,0,0,0,0,0,0,0,0,0,0
0,0,0,0,0,0,0,0,0,0,0,0,0,0,0,0,0,0,0,0,0,0,0
0,0,0,0,0,0,0,0,0,0,0,0,0,0,0,0,0,0,0,0,0,0,0
0,0,0,0,0,0,0,0,18,18,18,18,18,18,17,0,0,0,0,0,0,0,0
0,0,0,0,0,0,18,18,19,38,38,38,38,38,18,18,17,0,0,0,0,0,0
0,0,0,0,0,18,19,38,38,8,23,23,23,8,38,38,18,17,0,0,0,0,0
0,0,0,0,18,19,13,0,0,0,9,24,9,0,0,0,13,18,17,0,0,0,0
0,0,0,0,19,14,0,0,0,0,0,0,0,0,0,0,0,12,17,0,0,0,0
0,0,0,18,19,14,0,0,8,8,8,0,8,8,8,0,0,12,18,17,0,0,0
0,0,0,19,14,8,0,0,8,41,8,8,8,41,8,0,0,8,12,17,0,0,0
0,0,0,19,14,23,9,0,8,8,0,0,0,8,8,0,9,23,12,17,0,0,0
0,0,0,19,14,23,32,0,0,8,0,8,0,8,0,0,29,23,12,17,0,0,0
0,0,0,19,14,23,9,0,8,8,0,0,0,8,8,0,9,23,12,17,0,0,0
0,0,0,19,14,8,0,0,8,41,8,8,8,41,8,0,0,8,12,17,0,0,0
0,0,0,19,11,14,0,0,8,8,8,0,8,8,8,0,0,12,17,11,0,0,0
0,0,0,0,19,14,0,0,0,0,0,0,0,0,0,0,0,12,17,0,0,0,0
0,0,0,0,19,11,13,0,0,0,9,35,9,0,0,0,13,17,11,0,0,0,0
0,0,0,0,0,19,11,39,39,8,23,23,23,8,39,39,17,11,0,0,0,0,0
0,0,0,0,0,0,19,11,11,39,39,39,39,39,11,11,11,0,0,0,0,0,0
0,0,0,0,0,0,0,0,19,11,11,11,11,11,17,0,0,0,0,0,0,0,0
0,0,0,0,0,0,0,0,0,0,0,0,0,0,0,0,0,0,0,0,0,0,0
0,0,0,0,0,0,0,0,0,0,0,0,0,0,0,0,0,0,0,0,0,0,0
0,0,0,0,0,0,0,0,0,0,0,0,0,0,0,0,0,0,0,0,0,0,0
endlayer

layer
0,0,0,0,0,0,0,0,0,0,0,0,0,0,0,0,0,0,0,0,0,0,0
0,0,0,0,0,0,0,0,0,0,0,0,0,0,0,0,0,0,0,0,0,0,0
0,0,0,0,0,0,0,0,0,0,0,0,0,0,0,0,0,0,0,0,0,0,0
0,0,0,0,0,0,0,0,0,0,0,0,0,0,0,0,0,0,0,0,0,0,0
0,0,0,0,0,0,0,0,0,20,20,20,20,20,0,0,0,0,0,0,0,0,0
0,0,0,0,0,0,0,20,20,20,23,23,23,20,20,20,0,0,0,0,0,0,0
0,0,0,0,0,0,20,38,0,0,0,24,0,0,0,38,20,0,0,0,0,0,0
0,0,0,0,0,20,14,0,0,0,0,0,0,0,0,0,12,20,0,0,0,0,0
0,0,0,0,0,20,0,0,0,0,0,0,0,0,0,0,0,20,0,0,0,0,0
0,0,0,0,20,20,0,0,0,0,0,0,0,0,0,0,0,20,20,0,0,0,0
0,0,0,0,20,23,0,0,0,0,0,8,0,0,0,0,0,23,20,0,0,0,0
0,0,0,0,20,23,32,0,0,0,8,8,8,0,0,0,29,23,20,0,0,0,0
0,0,0,0,20,23,0,0,0,0,0,8,0,0,0,0,0,23,20,0,0,0,0
0,0,0,0,20,20,0,0,0,0,0,0,0,0,0,0,0,20,20,0,0,0,0
0,0,0,0,0,20,0,0,0,0,0,0,0,0,0,0,0,20,0,0,0,0,0
0,0,0,0,0,20,14,0,0,0,0,0,0,0,0,0,12,20,0,0,0,0,0
0,0,0,0,0,0,20,39,0,0,0,35,0,0,0,39,20,0,0,0,0,0,0
0,0,0,0,0,0,0,20,20,20,23,23,23,20,20,20,0,0,0,0,0,0,0
0,0,0,0,0,0,0,0,0,20,20,20,20,20,0,0,0,0,0,0,0,0,0
0,0,0,0,0,0,0,0,0,0,0,0,0,0,0,0,0,0,0,0,0,0,0
0,0,0,0,0,0,0,0,0,0,0,0,0,0,0,0,0,0,0,0,0,0,0
0,0,0,0,0,0,0,0,0,0,0,0,0,0,0,0,0,0,0,0,0,0,0
0,0,0,0,0,0,0,0,0,0,0,0,0,0,0,0,0,0,0,0,0,0,0
endlayer

layer
0,0,0,0,0,0,0,0,0,0,0,0,0,0,0,0,0,0,0,0,0,0,0
0,0,0,0,0,0,0,0,0,0,0,0,0,0,0,0,0,0,0,0,0,0,0
0,0,0,0,0,0,0,0,0,0,0,0,0,0,0,0,0,0,0,0,0,0,0
0,0,0,0,0,0,0,0,0,0,0,0,0,0,0,0,0,0,0,0,0,0,0
0,0,0,0,0,0,0,0,0,18,18,18,18,17,0,0,0,0,0,0,0,0,0
0,0,0,0,0,0,0,19,18,19,38,38,38,18,18,17,0,0,0,0,0,0,0
0,0,0,0,0,0,18,18,38,38,13,0,13,38,38,18,17,0,0,0,0,0,0
0,0,0,0,0,18,19,13,13,0,0,0,0,0,13,13,17,18,0,0,0,0,0
0,0,0,0,0,19,14,13,0,0,0,0,0,0,0,13,12,17,0,0,0,0,0
0,0,0,0,18,19,14,0,0,0,0,0,0,0,0,0,12,18,17,0,0,0,0
0,0,0,0,19,14,13,0,0,0,0,8,0,0,0,0,13,12,17,0,0,0,0
0,0,0,0,19,14,0,0,0,0,8,9,8,0,0,0,0,12,17,0,0,0,0
0,0,0,0,19,14,13,0,0,0,0,8,0,0,0,0,13,12,17,0,0,0,0
0,0,0,0,11,11,14,0,0,0,0,0,0,0,0,0,12,11,11,0,0,0,0
0,0,0,0,0,19,14,13,0,0,0,0,0,0,0,13,12,17,0,0,0,0,0
0,0,0,0,0,11,19,13,13,0,0,0,0,0,13,13,17,11,0,0,0,0,0
0,0,0,0,0,0,19,11,39,39,13,0,13,39,39,11,11,0,0,0,0,0,0
0,0,0,0,0,0,0,19,11,11,39,39,39,11,11,17,0,0,0,0,0,0,0
0,0,0,0,0,0,0,0,0,19,11,11,11,17,0,0,0,0,0,0,0,0,0
0,0,0,0,0,0,0,0,0,0,0,0,0,0,0,0,0,0,0,0,0,0,0
0,0,0,0,0,0,0,0,0,0,0,0,0,0,0,0,0,0,0,0,0,0,0
0,0,0,0,0,0,0,0,0,0,0,0,0,0,0,0,0,0,0,0,0,0,0
0,0,0,0,0,0,0,0,0,0,0,0,0,0,0,0,0,0,0,0,0,0,0
endlayer

layer
0,0,0,0,0,0,0,0,0,0,0,0,0,0,0,0,0,0,0,0,0,0,0
0,0,0,0,0,0,0,0,0,0,0,0,0,0,0,0,0,0,0,0,0,0,0
0,0,0,0,0,0,0,0,0,0,0,0,0,0,0,0,0,0,0,0,0,0,0
0,0,0,0,0,0,0,0,0,0,0,0,0,0,0,0,0,0,0,0,0,0,0
0,0,0,0,0,0,0,0,0,0,0,0,0,0,0,0,0,0,0,0,0,0,0
0,0,0,0,0,0,0,0,0,0,18,18,18,0,0,0,0,0,0,0,0,0,0
0,0,0,0,0,0,0,0,18,20,20,38,20,20,18,0,0,0,0,0,0,0,0
0,0,0,0,0,0,0,20,20,13,0,0,0,13,20,20,0,0,0,0,0,0,0
0,0,0,0,0,0,19,20,0,0,0,0,0,0,0,20,17,0,0,0,0,0,0
0,0,0,0,0,0,20,13,0,8,8,8,8,8,0,13,20,0,0,0,0,0,0
0,0,0,0,0,19,20,0,0,8,0,8,0,8,0,0,20,17,0,0,0,0,0
0,0,0,0,0,19,14,0,0,8,8,8,8,8,0,0,12,17,0,0,0,0,0
0,0,0,0,0,19,20,0,0,8,0,8,0,8,0,0,20,17,0,0,0,0,0
0,0,0,0,0,0,20,13,0,8,8,8,8,8,0,13,20,0,0,0,0,0,0
0,0,0,0,0,0,19,20,0,0,0,0,0,0,0,20,17,0,0,0,0,0,0
0,0,0,0,0,0,0,20,20,13,0,0,0,13,20,20,0,0,0,0,0,0,0
0,0,0,0,0,0,0,0,11,20,20,39,20,20,11,0,0,0,0,0,0,0,0
0,0,0,0,0,0,0,0,0,0,11,11,11,0,0,0,0,0,0,0,0,0,0
0,0,0,0,0,0,0,0,0,0,0,0,0,0,0,0,0,0,0,0,0,0,0
0,0,0,0,0,0,0,0,0,0,0,0,0,0,0,0,0,0,0,0,0,0,0
0,0,0,0,0,0,0,0,0,0,0,0,0,0,0,0,0,0,0,0,0,0,0
0,0,0,0,0,0,0,0,0,0,0,0,0,0,0,0,0,0,0,0,0,0,0
0,0,0,0,0,0,0,0,0,0,0,0,0,0,0,0,0,0,0,0,0,0,0
endlayer

layer
0,0,0,0,0,0,0,0,0,0,0,0,0,0,0,0,0,0,0,0,0,0,0
0,0,0,0,0,0,0,0,0,0,0,0,0,0,0,0,0,0,0,0,0,0,0
0,0,0,0,0,0,0,0,0,0,0,0,0,0,0,0,0,0,0,0,0,0,0
0,0,0,0,0,0,0,0,0,0,0,0,0,0,0,0,0,0,0,0,0,0,0
0,0,0,0,0,0,0,0,0,0,0,0,0,0,0,0,0,0,0,0,0,0,0
0,0,0,0,0,0,0,0,0,0,0,0,0,0,0,0,0,0,0,0,0,0,0
0,0,0,0,0,0,0,0,0,19,18,18,18,18,0,0,0,0,0,0,0,0,0
0,0,0,0,0,0,0,19,18,18,38,38,38,17,18,18,0,0,0,0,0,0,0
0,0,0,0,0,0,0,19,20,38,14,0,12,38,20,17,0,0,0,0,0,0,0
0,0,0,0,0,0,19,18,14,9,0,9,0,9,12,17,18,0,0,0,0,0,0
0,0,0,0,0,0,19,14,38,0,8,8,8,0,38,12,17,0,0,0,0,0,0
0,0,0,0,0,0,19,14,0,9,8,42,8,9,0,12,17,0,0,0,0,0,0
0,0,0,0,0,0,19,14,39,0,8,8,8,0,39,12,17,0,0,0,0,0,0
0,0,0,0,0,0,11,19,14,9,0,9,0,9,12,11,17,0,0,0,0,0,0
0,0,0,0,0,0,0,19,20,39,14,0,12,39,20,17,0,0,0,0,0,0,0
0,0,0,0,0,0,0,11,11,19,39,39,39,11,11,17,0,0,0,0,0,0,0
0,0,0,0,0,0,0,0,0,11,11,11,11,17,0,0,0,0,0,0,0,0,0
0,0,0,0,0,0,0,0,0,0,0,0,0,0,0,0,0,0,0,0,0,0,0
0,0,0,0,0,0,0,0,0,0,0,0,0,0,0,0,0,0,0,0,0,0,0
0,0,0,0,0,0,0,0,0,0,0,0,0,0,0,0,0,0,0,0,0,0,0
0,0,0,0,0,0,0,0,0,0,0,0,0,0,0,0,0,0,0,0,0,0,0
0,0,0,0,0,0,0,0,0,0,0,0,0,0,0,0,0,0,0,0,0,0,0
0,0,0,0,0,0,0,0,0,0,0,0,0,0,0,0,0,0,0,0,0,0,0
endlayer

layer
0,0,0,0,0,0,0,0,0,0,0,0,0,0,0,0,0,0,0,0,0,0,0
0,0,0,0,0,0,0,0,0,0,0,0,0,0,0,0,0,0,0,0,0,0,0
0,0,0,0,0,0,0,0,0,0,0,0,0,0,0,0,0,0,0,0,0,0,0
0,0,0,0,0,0,0,0,0,0,0,0,0,0,0,0,0,0,0,0,0,0,0
0,0,0,0,0,0,0,0,0,0,0,0,0,0,0,0,0,0,0,0,0,0,0
0,0,0,0,0,0,0,0,0,0,0,0,0,0,0,0,0,0,0,0,0,0,0
0,0,0,0,0,0,0,0,0,0,0,0,0,0,0,0,0,0,0,0,0,0,0
0,0,0,0,0,0,0,0,0,0,20,20,20,0,0,0,0,0,0,0,0,0,0
0,0,0,0,0,0,0,0,20,20,20,0,20,20,20,0,0,0,0,0,0,0,0
0,0,0,0,0,0,0,0,20,0,0,0,0,0,20,0,0,0,0,0,0,0,0
0,0,0,0,0,0,0,20,20,0,9,8,9,0,20,20,0,0,0,0,0,0,0
0,0,0,0,0,0,0,20,0,0,8,8,8,0,0,20,0,0,0,0,0,0,0
0,0,0,0,0,0,0,20,20,0,9,8,9,0,20,20,0,0,0,0,0,0,0
0,0,0,0,0,0,0,0,20,0,0,0,0,0,20,0,0,0,0,0,0,0,0
0,0,0,0,0,0,0,0,20,20,20,0,20,20,20,0,0,0,0,0,0,0,0
0,0,0,0,0,0,0,0,0,0,20,20,20,0,0,0,0,0,0,0,0,0,0
0,0,0,0,0,0,0,0,0,0,0,0,0,0,0,0,0,0,0,0,0,0,0
0,0,0,0,0,0,0,0,0,0,0,0,0,0,0,0,0,0,0,0,0,0,0
0,0,0,0,0,0,0,0,0,0,0,0,0,0,0,0,0,0,0,0,0,0,0
0,0,0,0,0,0,0,0,0,0,0,0,0,0,0,0,0,0,0,0,0,0,0
0,0,0,0,0,0,0,0,0,0,0,0,0,0,0,0,0,0,0,0,0,0,0
0,0,0,0,0,0,0,0,0,0,0,0,0,0,0,0,0,0,0,0,0,0,0
0,0,0,0,0,0,0,0,0,0,0,0,0,0,0,0,0,0,0,0,0,0,0
endlayer

layer
0,0,0,0,0,0,0,0,0,0,0,0,0,0,0,0,0,0,0,0,0,0,0
0,0,0,0,0,0,0,0,0,0,0,0,0,0,0,0,0,0,0,0,0,0,0
0,0,0,0,0,0,0,0,0,0,0,0,0,0,0,0,0,0,0,0,0,0,0
0,0,0,0,0,0,0,0,0,0,0,0,0,0,0,0,0,0,0,0,0,0,0
0,0,0,0,0,0,0,0,0,0,0,0,0,0,0,0,0,0,0,0,0,0,0
0,0,0,0,0,0,0,0,0,0,0,0,0,0,0,0,0,0,0,0,0,0,0
0,0,0,0,0,0,0,0,0,0,0,0,0,0,0,0,0,0,0,0,0,0,0
0,0,0,0,0,0,0,0,0,0,20,20,20,0,0,0,0,0,0,0,0,0,0
0,0,0,0,0,0,0,0,43,20,20,0,20,20,43,0,0,0,0,0,0,0,0
0,0,0,0,0,0,0,0,20,0,0,0,0,0,20,0,0,0,0,0,0,0,0
0,0,0,0,0,0,0,20,20,0,0,9,0,0,20,20,0,0,0,0,0,0,0
0,0,0,0,0,0,0,20,0,0,9,8,9,0,0,20,0,0,0,0,0,0,0
0,0,0,0,0,0,0,20,20,0,0,9,0,0,20,20,0,0,0,0,0,0,0
0,0,0,0,0,0,0,0,20,0,0,0,0,0,20,0,0,0,0,0,0,0,0
0,0,0,0,0,0,0,0,43,20,20,0,20,20,43,0,0,0,0,0,0,0,0
0,0,0,0,0,0,0,0,0,0,20,20,20,0,0,0,0,0,0,0,0,0,0
0,0,0,0,0,0,0,0,0,0,0,0,0,0,0,0,0,0,0,0,0,0,0
0,0,0,0,0,0,0,0,0,0,0,0,0,0,0,0,0,0,0,0,0,0,0
0,0,0,0,0,0,0,0,0,0,0,0,0,0,0,0,0,0,0,0,0,0,0
0,0,0,0,0,0,0,0,0,0,0,0,0,0,0,0,0,0,0,0,0,0,0
0,0,0,0,0,0,0,0,0,0,0,0,0,0,0,0,0,0,0,0,0,0,0
0,0,0,0,0,0,0,0,0,0,0,0,0,0,0,0,0,0,0,0,0,0,0
0,0,0,0,0,0,0,0,0,0,0,0,0,0,0,0,0,0,0,0,0,0,0
endlayer

layer
0,0,0,0,0,0,0,0,0,0,0,0,0,0,0,0,0,0,0,0,0,0,0
0,0,0,0,0,0,0,0,0,0,0,0,0,0,0,0,0,0,0,0,0,0,0
0,0,0,0,0,0,0,0,0,0,0,0,0,0,0,0,0,0,0,0,0,0,0
0,0,0,0,0,0,0,0,0,0,0,0,0,0,0,0,0,0,0,0,0,0,0
0,0,0,0,0,0,0,0,0,0,0,0,0,0,0,0,0,0,0,0,0,0,0
0,0,0,0,0,0,0,0,0,0,0,0,0,0,0,0,0,0,0,0,0,0,0
0,0,0,0,0,0,0,0,0,0,0,0,0,0,0,0,0,0,0,0,0,0,0
0,0,0,0,0,0,0,0,0,0,19,18,17,0,0,0,0,0,0,0,0,0,0
0,0,0,0,0,0,0,0,0,19,18,38,18,17,0,0,0,0,0,0,0,0,0
0,0,0,0,0,0,0,0,18,20,38,13,38,20,18,0,0,0,0,0,0,0,0
0,0,0,0,0,0,0,18,19,14,0,0,0,12,17,18,0,0,0,0,0,0,0
0,0,0,0,0,0,0,19,14,13,0,8,0,13,12,17,0,0,0,0,0,0,0
0,0,0,0,0,0,0,11,19,14,0,0,0,12,17,11,0,0,0,0,0,0,0
0,0,0,0,0,0,0,0,11,20,39,13,39,20,11,0,0,0,0,0,0,0,0
0,0,0,0,0,0,0,0,0,19,11,39,11,17,0,0,0,0,0,0,0,0,0
0,0,0,0,0,0,0,0,0,0,19,11,17,0,0,0,0,0,0,0,0,0,0
0,0,0,0,0,0,0,0,0,0,0,0,0,0,0,0,0,0,0,0,0,0,0
0,0,0,0,0,0,0,0,0,0,0,0,0,0,0,0,0,0,0,0,0,0,0
0,0,0,0,0,0,0,0,0,0,0,0,0,0,0,0,0,0,0,0,0,0,0
0,0,0,0,0,0,0,0,0,0,0,0,0,0,0,0,0,0,0,0,0,0,0
0,0,0,0,0,0,0,0,0,0,0,0,0,0,0,0,0,0,0,0,0,0,0
0,0,0,0,0,0,0,0,0,0,0,0,0,0,0,0,0,0,0,0,0,0,0
0,0,0,0,0,0,0,0,0,0,0,0,0,0,0,0,0,0,0,0,0,0,0
endlayer

layer
0,0,0,0,0,0,0,0,0,0,0,0,0,0,0,0,0,0,0,0,0,0,0
0,0,0,0,0,0,0,0,0,0,0,0,0,0,0,0,0,0,0,0,0,0,0
0,0,0,0,0,0,0,0,0,0,0,0,0,0,0,0,0,0,0,0,0,0,0
0,0,0,0,0,0,0,0,0,0,0,0,0,0,0,0,0,0,0,0,0,0,0
0,0,0,0,0,0,0,0,0,0,0,0,0,0,0,0,0,0,0,0,0,0,0
0,0,0,0,0,0,0,0,0,0,0,0,0,0,0,0,0,0,0,0,0,0,0
0,0,0,0,0,0,0,0,0,0,0,0,0,0,0,0,0,0,0,0,0,0,0
0,0,0,0,0,0,0,0,0,0,0,0,0,0,0,0,0,0,0,0,0,0,0
0,0,0,0,0,0,0,0,0,0,0,18,0,0,0,0,0,0,0,0,0,0,0
0,0,0,0,0,0,0,0,0,43,20,20,20,43,0,0,0,0,0,0,0,0,0
0,0,0,0,0,0,0,0,0,20,0,0,0,20,0,0,0,0,0,0,0,0,0
0,0,0,0,0,0,0,0,19,20,0,8,0,20,17,0,0,0,0,0,0,0,0
0,0,0,0,0,0,0,0,0,20,0,0,0,20,0,0,0,0,0,0,0,0,0
0,0,0,0,0,0,0,0,0,43,20,20,20,43,0,0,0,0,0,0,0,0,0
0,0,0,0,0,0,0,0,0,0,0,11,0,0,0,0,0,0,0,0,0,0,0
0,0,0,0,0,0,0,0,0,0,0,0,0,0,0,0,0,0,0,0,0,0,0
0,0,0,0,0,0,0,0,0,0,0,0,0,0,0,0,0,0,0,0,0,0,0
0,0,0,0,0,0,0,0,0,0,0,0,0,0,0,0,0,0,0,0,0,0,0
0,0,0,0,0,0,0,0,0,0,0,0,0,0,0,0,0,0,0,0,0,0,0
0,0,0,0,0,0,0,0,0,0,0,0,0,0,0,0,0,0,0,0,0,0,0
0,0,0,0,0,0,0,0,0,0,0,0,0,0,0,0,0,0,0,0,0,0,0
0,0,0,0,0,0,0,0,0,0,0,0,0,0,0,0,0,0,0,0,0,0,0
0,0,0,0,0,0,0,0,0,0,0,0,0,0,0,0,0,0,0,0,0,0,0
endlayer

layer
0,0,0,0,0,0,0,0,0,0,0,0,0,0,0,0,0,0,0,0,0,0,0
0,0,0,0,0,0,0,0,0,0,0,0,0,0,0,0,0,0,0,0,0,0,0
0,0,0,0,0,0,0,0,0,0,0,0,0,0,0,0,0,0,0,0,0,0,0
0,0,0,0,0,0,0,0,0,0,0,0,0,0,0,0,0,0,0,0,0,0,0
0,0,0,0,0,0,0,0,0,0,0,0,0,0,0,0,0,0,0,0,0,0,0
0,0,0,0,0,0,0,0,0,0,0,0,0,0,0,0,0,0,0,0,0,0,0
0,0,0,0,0,0,0,0,0,0,0,0,0,0,0,0,0,0,0,0,0,0,0
0,0,0,0,0,0,0,0,0,0,0,0,0,0,0,0,0,0,0,0,0,0,0
0,0,0,0,0,0,0,0,0,0,0,0,0,0,0,0,0,0,0,0,0,0,0
0,0,0,0,0,0,0,0,0,0,18,20,18,0,0,0,0,0,0,0,0,0,0
0,0,0,0,0,0,0,0,0,19,20,38,20,17,0,0,0,0,0,0,0,0,0
0,0,0,0,0,0,0,0,0,20,14,8,12,20,0,0,0,0,0,0,0,0,0
0,0,0,0,0,0,0,0,0,19,20,39,20,17,0,0,0,0,0,0,0,0,0
0,0,0,0,0,0,0,0,0,0,11,20,11,0,0,0,0,0,0,0,0,0,0
0,0,0,0,0,0,0,0,0,0,0,0,0,0,0,0,0,0,0,0,0,0,0
0,0,0,0,0,0,0,0,0,0,0,0,0,0,0,0,0,0,0,0,0,0,0
0,0,0,0,0,0,0,0,0,0,0,0,0,0,0,0,0,0,0,0,0,0,0
0,0,0,0,0,0,0,0,0,0,0,0,0,0,0,0,0,0,0,0,0,0,0
0,0,0,0,0,0,0,0,0,0,0,0,0,0,0,0,0,0,0,0,0,0,0
0,0,0,0,0,0,0,0,0,0,0,0,0,0,0,0,0,0,0,0,0,0,0
0,0,0,0,0,0,0,0,0,0,0,0,0,0,0,0,0,0,0,0,0,0,0
0,0,0,0,0,0,0,0,0,0,0,0,0,0,0,0,0,0,0,0,0,0,0
0,0,0,0,0,0,0,0,0,0,0,0,0,0,0,0,0,0,0,0,0,0,0
endlayer

layer
0,0,0,0,0,0,0,0,0,0,0,0,0,0,0,0,0,0,0,0,0,0,0
0,0,0,0,0,0,0,0,0,0,0,0,0,0,0,0,0,0,0,0,0,0,0
0,0,0,0,0,0,0,0,0,0,0,0,0,0,0,0,0,0,0,0,0,0,0
0,0,0,0,0,0,0,0,0,0,0,0,0,0,0,0,0,0,0,0,0,0,0
0,0,0,0,0,0,0,0,0,0,0,0,0,0,0,0,0,0,0,0,0,0,0
0,0,0,0,0,0,0,0,0,0,0,0,0,0,0,0,0,0,0,0,0,0,0
0,0,0,0,0,0,0,0,0,0,0,0,0,0,0,0,0,0,0,0,0,0,0
0,0,0,0,0,0,0,0,0,0,0,0,0,0,0,0,0,0,0,0,0,0,0
0,0,0,0,0,0,0,0,0,0,0,0,0,0,0,0,0,0,0,0,0,0,0
0,0,0,0,0,0,0,0,0,0,0,18,0,0,0,0,0,0,0,0,0,0,0
0,0,0,0,0,0,0,0,0,0,20,20,20,0,0,0,0,0,0,0,0,0,0
0,0,0,0,0,0,0,0,0,19,20,8,20,17,0,0,0,0,0,0,0,0,0
0,0,0,0,0,0,0,0,0,0,20,20,20,0,0,0,0,0,0,0,0,0,0
0,0,0,0,0,0,0,0,0,0,0,11,0,0,0,0,0,0,0,0,0,0,0
0,0,0,0,0,0,0,0,0,0,0,0,0,0,0,0,0,0,0,0,0,0,0
0,0,0,0,0,0,0,0,0,0,0,0,0,0,0,0,0,0,0,0,0,0,0
0,0,0,0,0,0,0,0,0,0,0,0,0,0,0,0,0,0,0,0,0,0,0
0,0,0,0,0,0,0,0,0,0,0,0,0,0,0,0,0,0,0,0,0,0,0
0,0,0,0,0,0,0,0,0,0,0,0,0,0,0,0,0,0,0,0,0,0,0
0,0,0,0,0,0,0,0,0,0,0,0,0,0,0,0,0,0,0,0,0,0,0
0,0,0,0,0,0,0,0,0,0,0,0,0,0,0,0,0,0,0,0,0,0,0
0,0,0,0,0,0,0,0,0,0,0,0,0,0,0,0,0,0,0,0,0,0,0
0,0,0,0,0,0,0,0,0,0,0,0,0,0,0,0,0,0,0,0,0,0,0
endlayer

layer
0,0,0,0,0,0,0,0,0,0,0,0,0,0,0,0,0,0,0,0,0,0,0
0,0,0,0,0,0,0,0,0,0,0,0,0,0,0,0,0,0,0,0,0,0,0
0,0,0,0,0,0,0,0,0,0,0,0,0,0,0,0,0,0,0,0,0,0,0
0,0,0,0,0,0,0,0,0,0,0,0,0,0,0,0,0,0,0,0,0,0,0
0,0,0,0,0,0,0,0,0,0,0,0,0,0,0,0,0,0,0,0,0,0,0
0,0,0,0,0,0,0,0,0,0,0,0,0,0,0,0,0,0,0,0,0,0,0
0,0,0,0,0,0,0,0,0,0,0,0,0,0,0,0,0,0,0,0,0,0,0
0,0,0,0,0,0,0,0,0,0,0,0,0,0,0,0,0,0,0,0,0,0,0
0,0,0,0,0,0,0,0,0,0,0,0,0,0,0,0,0,0,0,0,0,0,0
0,0,0,0,0,0,0,0,0,0,0,0,0,0,0,0,0,0,0,0,0,0,0
0,0,0,0,0,0,0,0,0,0,20,20,20,0,0,0,0,0,0,0,0,0,0
0,0,0,0,0,0,0,0,0,0,20,8,20,0,0,0,0,0,0,0,0,0,0
0,0,0,0,0,0,0,0,0,0,20,20,20,0,0,0,0,0,0,0,0,0,0
0,0,0,0,0,0,0,0,0,0,0,0,0,0,0,0,0,0,0,0,0,0,0
0,0,0,0,0,0,0,0,0,0,0,0,0,0,0,0,0,0,0,0,0,0,0
0,0,0,0,0,0,0,0,0,0,0,0,0,0,0,0,0,0,0,0,0,0,0
0,0,0,0,0,0,0,0,0,0,0,0,0,0,0,0,0,0,0,0,0,0,0
0,0,0,0,0,0,0,0,0,0,0,0,0,0,0,0,0,0,0,0,0,0,0
0,0,0,0,0,0,0,0,0,0,0,0,0,0,0,0,0,0,0,0,0,0,0
0,0,0,0,0,0,0,0,0,0,0,0,0,0,0,0,0,0,0,0,0,0,0
0,0,0,0,0,0,0,0,0,0,0,0,0,0,0,0,0,0,0,0,0,0,0
0,0,0,0,0,0,0,0,0,0,0,0,0,0,0,0,0,0,0,0,0,0,0
0,0,0,0,0,0,0,0,0,0,0,0,0,0,0,0,0,0,0,0,0,0,0
endlayer

layer
0,0,0,0,0,0,0,0,0,0,0,0,0,0,0,0,0,0,0,0,0,0,0
0,0,0,0,0,0,0,0,0,0,0,0,0,0,0,0,0,0,0,0,0,0,0
0,0,0,0,0,0,0,0,0,0,0,0,0,0,0,0,0,0,0,0,0,0,0
0,0,0,0,0,0,0,0,0,0,0,0,0,0,0,0,0,0,0,0,0,0,0
0,0,0,0,0,0,0,0,0,0,0,0,0,0,0,0,0,0,0,0,0,0,0
0,0,0,0,0,0,0,0,0,0,0,0,0,0,0,0,0,0,0,0,0,0,0
0,0,0,0,0,0,0,0,0,0,0,0,0,0,0,0,0,0,0,0,0,0,0
0,0,0,0,0,0,0,0,0,0,0,0,0,0,0,0,0,0,0,0,0,0,0
0,0,0,0,0,0,0,0,0,0,0,0,0,0,0,0,0,0,0,0,0,0,0
0,0,0,0,0,0,0,0,0,0,0,0,0,0,0,0,0,0,0,0,0,0,0
0,0,0,0,0,0,0,0,0,0,43,20,43,0,0,0,0,0,0,0,0,0,0
0,0,0,0,0,0,0,0,0,0,20,8,20,0,0,0,0,0,0,0,0,0,0
0,0,0,0,0,0,0,0,0,0,43,20,43,0,0,0,0,0,0,0,0,0,0
0,0,0,0,0,0,0,0,0,0,0,0,0,0,0,0,0,0,0,0,0,0,0
0,0,0,0,0,0,0,0,0,0,0,0,0,0,0,0,0,0,0,0,0,0,0
0,0,0,0,0,0,0,0,0,0,0,0,0,0,0,0,0,0,0,0,0,0,0
0,0,0,0,0,0,0,0,0,0,0,0,0,0,0,0,0,0,0,0,0,0,0
0,0,0,0,0,0,0,0,0,0,0,0,0,0,0,0,0,0,0,0,0,0,0
0,0,0,0,0,0,0,0,0,0,0,0,0,0,0,0,0,0,0,0,0,0,0
0,0,0,0,0,0,0,0,0,0,0,0,0,0,0,0,0,0,0,0,0,0,0
0,0,0,0,0,0,0,0,0,0,0,0,0,0,0,0,0,0,0,0,0,0,0
0,0,0,0,0,0,0,0,0,0,0,0,0,0,0,0,0,0,0,0,0,0,0
0,0,0,0,0,0,0,0,0,0,0,0,0,0,0,0,0,0,0,0,0,0,0
endlayer

layer
0,0,0,0,0,0,0,0,0,0,0,0,0,0,0,0,0,0,0,0,0,0,0
0,0,0,0,0,0,0,0,0,0,0,0,0,0,0,0,0,0,0,0,0,0,0
0,0,0,0,0,0,0,0,0,0,0,0,0,0,0,0,0,0,0,0,0,0,0
0,0,0,0,0,0,0,0,0,0,0,0,0,0,0,0,0,0,0,0,0,0,0
0,0,0,0,0,0,0,0,0,0,0,0,0,0,0,0,0,0,0,0,0,0,0
0,0,0,0,0,0,0,0,0,0,0,0,0,0,0,0,0,0,0,0,0,0,0
0,0,0,0,0,0,0,0,0,0,0,0,0,0,0,0,0,0,0,0,0,0,0
0,0,0,0,0,0,0,0,0,0,0,0,0,0,0,0,0,0,0,0,0,0,0
0,0,0,0,0,0,0,0,0,0,0,0,0,0,0,0,0,0,0,0,0,0,0
0,0,0,0,0,0,0,0,0,0,0,0,0,0,0,0,0,0,0,0,0,0,0
0,0,0,0,0,0,0,0,0,0,0,20,0,0,0,0,0,0,0,0,0,0,0
0,0,0,0,0,0,0,0,0,0,20,8,20,0,0,0,0,0,0,0,0,0,0
0,0,0,0,0,0,0,0,0,0,0,20,0,0,0,0,0,0,0,0,0,0,0
0,0,0,0,0,0,0,0,0,0,0,0,0,0,0,0,0,0,0,0,0,0,0
0,0,0,0,0,0,0,0,0,0,0,0,0,0,0,0,0,0,0,0,0,0,0
0,0,0,0,0,0,0,0,0,0,0,0,0,0,0,0,0,0,0,0,0,0,0
0,0,0,0,0,0,0,0,0,0,0,0,0,0,0,0,0,0,0,0,0,0,0
0,0,0,0,0,0,0,0,0,0,0,0,0,0,0,0,0,0,0,0,0,0,0
0,0,0,0,0,0,0,0,0,0,0,0,0,0,0,0,0,0,0,0,0,0,0
0,0,0,0,0,0,0,0,0,0,0,0,0,0,0,0,0,0,0,0,0,0,0
0,0,0,0,0,0,0,0,0,0,0,0,0,0,0,0,0,0,0,0,0,0,0
0,0,0,0,0,0,0,0,0,0,0,0,0,0,0,0,0,0,0,0,0,0,0
0,0,0,0,0,0,0,0,0,0,0,0,0,0,0,0,0,0,0,0,0,0,0
endlayer

layer
0,0,0,0,0,0,0,0,0,0,0,0,0,0,0,0,0,0,0,0,0,0,0
0,0,0,0,0,0,0,0,0,0,0,0,0,0,0,0,0,0,0,0,0,0,0
0,0,0,0,0,0,0,0,0,0,0,0,0,0,0,0,0,0,0,0,0,0,0
0,0,0,0,0,0,0,0,0,0,0,0,0,0,0,0,0,0,0,0,0,0,0
0,0,0,0,0,0,0,0,0,0,0,0,0,0,0,0,0,0,0,0,0,0,0
0,0,0,0,0,0,0,0,0,0,0,0,0,0,0,0,0,0,0,0,0,0,0
0,0,0,0,0,0,0,0,0,0,0,0,0,0,0,0,0,0,0,0,0,0,0
0,0,0,0,0,0,0,0,0,0,0,0,0,0,0,0,0,0,0,0,0,0,0
0,0,0,0,0,0,0,0,0,0,0,0,0,0,0,0,0,0,0,0,0,0,0
0,0,0,0,0,0,0,0,0,0,0,0,0,0,0,0,0,0,0,0,0,0,0
0,0,0,0,0,0,0,0,0,0,0,18,0,0,0,0,0,0,0,0,0,0,0
0,0,0,0,0,0,0,0,0,0,19,20,17,0,0,0,0,0,0,0,0,0,0
0,0,0,0,0,0,0,0,0,0,0,11,0,0,0,0,0,0,0,0,0,0,0
0,0,0,0,0,0,0,0,0,0,0,0,0,0,0,0,0,0,0,0,0,0,0
0,0,0,0,0,0,0,0,0,0,0,0,0,0,0,0,0,0,0,0,0,0,0
0,0,0,0,0,0,0,0,0,0,0,0,0,0,0,0,0,0,0,0,0,0,0
0,0,0,0,0,0,0,0,0,0,0,0,0,0,0,0,0,0,0,0,0,0,0
0,0,0,0,0,0,0,0,0,0,0,0,0,0,0,0,0,0,0,0,0,0,0
0,0,0,0,0,0,0,0,0,0,0,0,0,0,0,0,0,0,0,0,0,0,0
0,0,0,0,0,0,0,0,0,0,0,0,0,0,0,0,0,0,0,0,0,0,0
0,0,0,0,0,0,0,0,0,0,0,0,0,0,0,0,0,0,0,0,0,0,0
0,0,0,0,0,0,0,0,0,0,0,0,0,0,0,0,0,0,0,0,0,0,0
0,0,0,0,0,0,0,0,0,0,0,0,0,0,0,0,0,0,0,0,0,0,0
endlayer

layer
0,0,0,0,0,0,0,0,0,0,0,0,0,0,0,0,0,0,0,0,0,0,0
0,0,0,0,0,0,0,0,0,0,0,0,0,0,0,0,0,0,0,0,0,0,0
0,0,0,0,0,0,0,0,0,0,0,0,0,0,0,0,0,0,0,0,0,0,0
0,0,0,0,0,0,0,0,0,0,0,0,0,0,0,0,0,0,0,0,0,0,0
0,0,0,0,0,0,0,0,0,0,0,0,0,0,0,0,0,0,0,0,0,0,0
0,0,0,0,0,0,0,0,0,0,0,0,0,0,0,0,0,0,0,0,0,0,0
0,0,0,0,0,0,0,0,0,0,0,0,0,0,0,0,0,0,0,0,0,0,0
0,0,0,0,0,0,0,0,0,0,0,0,0,0,0,0,0,0,0,0,0,0,0
0,0,0,0,0,0,0,0,0,0,0,0,0,0,0,0,0,0,0,0,0,0,0
0,0,0,0,0,0,0,0,0,0,0,0,0,0,0,0,0,0,0,0,0,0,0
0,0,0,0,0,0,0,0,0,0,0,0,0,0,0,0,0,0,0,0,0,0,0
0,0,0,0,0,0,0,0,0,0,0,20,0,0,0,0,0,0,0,0,0,0,0
0,0,0,0,0,0,0,0,0,0,0,0,0,0,0,0,0,0,0,0,0,0,0
0,0,0,0,0,0,0,0,0,0,0,0,0,0,0,0,0,0,0,0,0,0,0
0,0,0,0,0,0,0,0,0,0,0,0,0,0,0,0,0,0,0,0,0,0,0
0,0,0,0,0,0,0,0,0,0,0,0,0,0,0,0,0,0,0,0,0,0,0
0,0,0,0,0,0,0,0,0,0,0,0,0,0,0,0,0,0,0,0,0,0,0
0,0,0,0,0,0,0,0,0,0,0,0,0,0,0,0,0,0,0,0,0,0,0
0,0,0,0,0,0,0,0,0,0,0,0,0,0,0,0,0,0,0,0,0,0,0
0,0,0,0,0,0,0,0,0,0,0,0,0,0,0,0,0,0,0,0,0,0,0
0,0,0,0,0,0,0,0,0,0,0,0,0,0,0,0,0,0,0,0,0,0,0
0,0,0,0,0,0,0,0,0,0,0,0,0,0,0,0,0,0,0,0,0,0,0
0,0,0,0,0,0,0,0,0,0,0,0,0,0,0,0,0,0,0,0,0,0,0
endlayer

layer
0,0,0,0,0,0,0,0,0,0,0,0,0,0,0,0,0,0,0,0,0,0,0
0,0,0,0,0,0,0,0,0,0,0,0,0,0,0,0,0,0,0,0,0,0,0
0,0,0,0,0,0,0,0,0,0,0,0,0,0,0,0,0,0,0,0,0,0,0
0,0,0,0,0,0,0,0,0,0,0,0,0,0,0,0,0,0,0,0,0,0,0
0,0,0,0,0,0,0,0,0,0,0,0,0,0,0,0,0,0,0,0,0,0,0
0,0,0,0,0,0,0,0,0,0,0,0,0,0,0,0,0,0,0,0,0,0,0
0,0,0,0,0,0,0,0,0,0,0,0,0,0,0,0,0,0,0,0,0,0,0
0,0,0,0,0,0,0,0,0,0,0,0,0,0,0,0,0,0,0,0,0,0,0
0,0,0,0,0,0,0,0,0,0,0,0,0,0,0,0,0,0,0,0,0,0,0
0,0,0,0,0,0,0,0,0,0,0,0,0,0,0,0,0,0,0,0,0,0,0
0,0,0,0,0,0,0,0,0,0,0,0,0,0,0,0,0,0,0,0,0,0,0
0,0,0,0,0,0,0,0,0,0,0,20,0,0,0,0,0,0,0,0,0,0,0
0,0,0,0,0,0,0,0,0,0,0,0,0,0,0,0,0,0,0,0,0,0,0
0,0,0,0,0,0,0,0,0,0,0,0,0,0,0,0,0,0,0,0,0,0,0
0,0,0,0,0,0,0,0,0,0,0,0,0,0,0,0,0,0,0,0,0,0,0
0,0,0,0,0,0,0,0,0,0,0,0,0,0,0,0,0,0,0,0,0,0,0
0,0,0,0,0,0,0,0,0,0,0,0,0,0,0,0,0,0,0,0,0,0,0
0,0,0,0,0,0,0,0,0,0,0,0,0,0,0,0,0,0,0,0,0,0,0
0,0,0,0,0,0,0,0,0,0,0,0,0,0,0,0,0,0,0,0,0,0,0
0,0,0,0,0,0,0,0,0,0,0,0,0,0,0,0,0,0,0,0,0,0,0
0,0,0,0,0,0,0,0,0,0,0,0,0,0,0,0,0,0,0,0,0,0,0
0,0,0,0,0,0,0,0,0,0,0,0,0,0,0,0,0,0,0,0,0,0,0
0,0,0,0,0,0,0,0,0,0,0,0,0,0,0,0,0,0,0,0,0,0,0
endlayer

layer
0,0,0,0,0,0,0,0,0,0,0,0,0,0,0,0,0,0,0,0,0,0,0
0,0,0,0,0,0,0,0,0,0,0,0,0,0,0,0,0,0,0,0,0,0,0
0,0,0,0,0,0,0,0,0,0,0,0,0,0,0,0,0,0,0,0,0,0,0
0,0,0,0,0,0,0,0,0,0,0,0,0,0,0,0,0,0,0,0,0,0,0
0,0,0,0,0,0,0,0,0,0,0,0,0,0,0,0,0,0,0,0,0,0,0
0,0,0,0,0,0,0,0,0,0,0,0,0,0,0,0,0,0,0,0,0,0,0
0,0,0,0,0,0,0,0,0,0,0,0,0,0,0,0,0,0,0,0,0,0,0
0,0,0,0,0,0,0,0,0,0,0,0,0,0,0,0,0,0,0,0,0,0,0
0,0,0,0,0,0,0,0,0,0,0,0,0,0,0,0,0,0,0,0,0,0,0
0,0,0,0,0,0,0,0,0,0,0,0,0,0,0,0,0,0,0,0,0,0,0
0,0,0,0,0,0,0,0,0,0,0,0,0,0,0,0,0,0,0,0,0,0,0
0,0,0,0,0,0,0,0,0,0,0,20,0,0,0,0,0,0,0,0,0,0,0
0,0,0,0,0,0,0,0,0,0,0,0,0,0,0,0,0,0,0,0,0,0,0
0,0,0,0,0,0,0,0,0,0,0,0,0,0,0,0,0,0,0,0,0,0,0
0,0,0,0,0,0,0,0,0,0,0,0,0,0,0,0,0,0,0,0,0,0,0
0,0,0,0,0,0,0,0,0,0,0,0,0,0,0,0,0,0,0,0,0,0,0
0,0,0,0,0,0,0,0,0,0,0,0,0,0,0,0,0,0,0,0,0,0,0
0,0,0,0,0,0,0,0,0,0,0,0,0,0,0,0,0,0,0,0,0,0,0
0,0,0,0,0,0,0,0,0,0,0,0,0,0,0,0,0,0,0,0,0,0,0
0,0,0,0,0,0,0,0,0,0,0,0,0,0,0,0,0,0,0,0,0,0,0
0,0,0,0,0,0,0,0,0,0,0,0,0,0,0,0,0,0,0,0,0,0,0
0,0,0,0,0,0,0,0,0,0,0,0,0,0,0,0,0,0,0,0,0,0,0
0,0,0,0,0,0,0,0,0,0,0,0,0,0,0,0,0,0,0,0,0,0,0
endlayer

layer
0,0,0,0,0,0,0,0,0,0,0,0,0,0,0,0,0,0,0,0,0,0,0
0,0,0,0,0,0,0,0,0,0,0,0,0,0,0,0,0,0,0,0,0,0,0
0,0,0,0,0,0,0,0,0,0,0,0,0,0,0,0,0,0,0,0,0,0,0
0,0,0,0,0,0,0,0,0,0,0,0,0,0,0,0,0,0,0,0,0,0,0
0,0,0,0,0,0,0,0,0,0,0,0,0,0,0,0,0,0,0,0,0,0,0
0,0,0,0,0,0,0,0,0,0,0,0,0,0,0,0,0,0,0,0,0,0,0
0,0,0,0,0,0,0,0,0,0,0,0,0,0,0,0,0,0,0,0,0,0,0
0,0,0,0,0,0,0,0,0,0,0,0,0,0,0,0,0,0,0,0,0,0,0
0,0,0,0,0,0,0,0,0,0,0,0,0,0,0,0,0,0,0,0,0,0,0
0,0,0,0,0,0,0,0,0,0,0,0,0,0,0,0,0,0,0,0,0,0,0
0,0,0,0,0,0,0,0,0,0,0,0,0,0,0,0,0,0,0,0,0,0,0
0,0,0,0,0,0,0,0,0,0,0,20,0,0,0,0,0,0,0,0,0,0,0
0,0,0,0,0,0,0,0,0,0,0,0,0,0,0,0,0,0,0,0,0,0,0
0,0,0,0,0,0,0,0,0,0,0,0,0,0,0,0,0,0,0,0,0,0,0
0,0,0,0,0,0,0,0,0,0,0,0,0,0,0,0,0,0,0,0,0,0,0
0,0,0,0,0,0,0,0,0,0,0,0,0,0,0,0,0,0,0,0,0,0,0
0,0,0,0,0,0,0,0,0,0,0,0,0,0,0,0,0,0,0,0,0,0,0
0,0,0,0,0,0,0,0,0,0,0,0,0,0,0,0,0,0,0,0,0,0,0
0,0,0,0,0,0,0,0,0,0,0,0,0,0,0,0,0,0,0,0,0,0,0
0,0,0,0,0,0,0,0,0,0,0,0,0,0,0,0,0,0,0,0,0,0,0
0,0,0,0,0,0,0,0,0,0,0,0,0,0,0,0,0,0,0,0,0,0,0
0,0,0,0,0,0,0,0,0,0,0,0,0,0,0,0,0,0,0,0,0,0,0
0,0,0,0,0,0,0,0,0,0,0,0,0,0,0,0,0,0,0,0,0,0,0
endlayer

layer
0,0,0,0,0,0,0,0,0,0,0,0,0,0,0,0,0,0,0,0,0,0,0
0,0,0,0,0,0,0,0,0,0,0,0,0,0,0,0,0,0,0,0,0,0,0
0,0,0,0,0,0,0,0,0,0,0,0,0,0,0,0,0,0,0,0,0,0,0
0,0,0,0,0,0,0,0,0,0,0,0,0,0,0,0,0,0,0,0,0,0,0
0,0,0,0,0,0,0,0,0,0,0,0,0,0,0,0,0,0,0,0,0,0,0
0,0,0,0,0,0,0,0,0,0,0,0,0,0,0,0,0,0,0,0,0,0,0
0,0,0,0,0,0,0,0,0,0,0,0,0,0,0,0,0,0,0,0,0,0,0
0,0,0,0,0,0,0,0,0,0,0,0,0,0,0,0,0,0,0,0,0,0,0
0,0,0,0,0,0,0,0,0,0,0,0,0,0,0,0,0,0,0,0,0,0,0
0,0,0,0,0,0,0,0,0,0,0,0,0,0,0,0,0,0,0,0,0,0,0
0,0,0,0,0,0,0,0,0,0,0,0,0,0,0,0,0,0,0,0,0,0,0
0,0,0,0,0,0,0,0,0,0,0,8,0,0,0,0,0,0,0,0,0,0,0
0,0,0,0,0,0,0,0,0,0,0,0,0,0,0,0,0,0,0,0,0,0,0
0,0,0,0,0,0,0,0,0,0,0,0,0,0,0,0,0,0,0,0,0,0,0
0,0,0,0,0,0,0,0,0,0,0,0,0,0,0,0,0,0,0,0,0,0,0
0,0,0,0,0,0,0,0,0,0,0,0,0,0,0,0,0,0,0,0,0,0,0
0,0,0,0,0,0,0,0,0,0,0,0,0,0,0,0,0,0,0,0,0,0,0
0,0,0,0,0,0,0,0,0,0,0,0,0,0,0,0,0,0,0,0,0,0,0
0,0,0,0,0,0,0,0,0,0,0,0,0,0,0,0,0,0,0,0,0,0,0
0,0,0,0,0,0,0,0,0,0,0,0,0,0,0,0,0,0,0,0,0,0,0
0,0,0,0,0,0,0,0,0,0,0,0,0,0,0,0,0,0,0,0,0,0,0
0,0,0,0,0,0,0,0,0,0,0,0,0,0,0,0,0,0,0,0,0,0,0
0,0,0,0,0,0,0,0,0,0,0,0,0,0,0,0,0,0,0,0,0,0,0
endlayer

layer
0,0,0,0,0,0,0,0,0,0,0,0,0,0,0,0,0,0,0,0,0,0,0
0,0,0,0,0,0,0,0,0,0,0,0,0,0,0,0,0,0,0,0,0,0,0
0,0,0,0,0,0,0,0,0,0,0,0,0,0,0,0,0,0,0,0,0,0,0
0,0,0,0,0,0,0,0,0,0,0,0,0,0,0,0,0,0,0,0,0,0,0
0,0,0,0,0,0,0,0,0,0,0,0,0,0,0,0,0,0,0,0,0,0,0
0,0,0,0,0,0,0,0,0,0,0,0,0,0,0,0,0,0,0,0,0,0,0
0,0,0,0,0,0,0,0,0,0,0,0,0,0,0,0,0,0,0,0,0,0,0
0,0,0,0,0,0,0,0,0,0,0,0,0,0,0,0,0,0,0,0,0,0,0
0,0,0,0,0,0,0,0,0,0,0,0,0,0,0,0,0,0,0,0,0,0,0
0,0,0,0,0,0,0,0,0,0,0,0,0,0,0,0,0,0,0,0,0,0,0
0,0,0,0,0,0,0,0,0,0,0,0,0,0,0,0,0,0,0,0,0,0,0
0,0,0,0,0,0,0,0,0,0,0,8,0,0,0,0,0,0,0,0,0,0,0
0,0,0,0,0,0,0,0,0,0,0,0,0,0,0,0,0,0,0,0,0,0,0
0,0,0,0,0,0,0,0,0,0,0,0,0,0,0,0,0,0,0,0,0,0,0
0,0,0,0,0,0,0,0,0,0,0,0,0,0,0,0,0,0,0,0,0,0,0
0,0,0,0,0,0,0,0,0,0,0,0,0,0,0,0,0,0,0,0,0,0,0
0,0,0,0,0,0,0,0,0,0,0,0,0,0,0,0,0,0,0,0,0,0,0
0,0,0,0,0,0,0,0,0,0,0,0,0,0,0,0,0,0,0,0,0,0,0
0,0,0,0,0,0,0,0,0,0,0,0,0,0,0,0,0,0,0,0,0,0,0
0,0,0,0,0,0,0,0,0,0,0,0,0,0,0,0,0,0,0,0,0,0,0
0,0,0,0,0,0,0,0,0,0,0,0,0,0,0,0,0,0,0,0,0,0,0
0,0,0,0,0,0,0,0,0,0,0,0,0,0,0,0,0,0,0,0,0,0,0
0,0,0,0,0,0,0,0,0,0,0,0,0,0,0,0,0,0,0,0,0,0,0
endlayer

layer
0,0,0,0,0,0,0,0,0,0,0,0,0,0,0,0,0,0,0,0,0,0,0
0,0,0,0,0,0,0,0,0,0,0,0,0,0,0,0,0,0,0,0,0,0,0
0,0,0,0,0,0,0,0,0,0,0,0,0,0,0,0,0,0,0,0,0,0,0
0,0,0,0,0,0,0,0,0,0,0,0,0,0,0,0,0,0,0,0,0,0,0
0,0,0,0,0,0,0,0,0,0,0,0,0,0,0,0,0,0,0,0,0,0,0
0,0,0,0,0,0,0,0,0,0,0,0,0,0,0,0,0,0,0,0,0,0,0
0,0,0,0,0,0,0,0,0,0,0,0,0,0,0,0,0,0,0,0,0,0,0
0,0,0,0,0,0,0,0,0,0,0,0,0,0,0,0,0,0,0,0,0,0,0
0,0,0,0,0,0,0,0,0,0,0,0,0,0,0,0,0,0,0,0,0,0,0
0,0,0,0,0,0,0,0,0,0,0,0,0,0,0,0,0,0,0,0,0,0,0
0,0,0,0,0,0,0,0,0,0,0,0,0,0,0,0,0,0,0,0,0,0,0
0,0,0,0,0,0,0,0,0,0,0,8,0,0,0,0,0,0,0,0,0,0,0
0,0,0,0,0,0,0,0,0,0,0,0,0,0,0,0,0,0,0,0,0,0,0
0,0,0,0,0,0,0,0,0,0,0,0,0,0,0,0,0,0,0,0,0,0,0
0,0,0,0,0,0,0,0,0,0,0,0,0,0,0,0,0,0,0,0,0,0,0
0,0,0,0,0,0,0,0,0,0,0,0,0,0,0,0,0,0,0,0,0,0,0
0,0,0,0,0,0,0,0,0,0,0,0,0,0,0,0,0,0,0,0,0,0,0
0,0,0,0,0,0,0,0,0,0,0,0,0,0,0,0,0,0,0,0,0,0,0
0,0,0,0,0,0,0,0,0,0,0,0,0,0,0,0,0,0,0,0,0,0,0
0,0,0,0,0,0,0,0,0,0,0,0,0,0,0,0,0,0,0,0,0,0,0
0,0,0,0,0,0,0,0,0,0,0,0,0,0,0,0,0,0,0,0,0,0,0
0,0,0,0,0,0,0,0,0,0,0,0,0,0,0,0,0,0,0,0,0,0,0
0,0,0,0,0,0,0,0,0,0,0,0,0,0,0,0,0,0,0,0,0,0,0
endlayer

layer
0,0,0,0,0,0,0,0,0,0,0,0,0,0,0,0,0,0,0,0,0,0,0
0,0,0,0,0,0,0,0,0,0,0,0,0,0,0,0,0,0,0,0,0,0,0
0,0,0,0,0,0,0,0,0,0,0,0,0,0,0,0,0,0,0,0,0,0,0
0,0,0,0,0,0,0,0,0,0,0,0,0,0,0,0,0,0,0,0,0,0,0
0,0,0,0,0,0,0,0,0,0,0,0,0,0,0,0,0,0,0,0,0,0,0
0,0,0,0,0,0,0,0,0,0,0,0,0,0,0,0,0,0,0,0,0,0,0
0,0,0,0,0,0,0,0,0,0,0,0,0,0,0,0,0,0,0,0,0,0,0
0,0,0,0,0,0,0,0,0,0,0,0,0,0,0,0,0,0,0,0,0,0,0
0,0,0,0,0,0,0,0,0,0,0,0,0,0,0,0,0,0,0,0,0,0,0
0,0,0,0,0,0,0,0,0,0,0,0,0,0,0,0,0,0,0,0,0,0,0
0,0,0,0,0,0,0,0,0,0,0,0,0,0,0,0,0,0,0,0,0,0,0
0,0,0,0,0,0,0,0,0,0,0,8,0,0,0,0,0,0,0,0,0,0,0
0,0,0,0,0,0,0,0,0,0,0,0,0,0,0,0,0,0,0,0,0,0,0
0,0,0,0,0,0,0,0,0,0,0,0,0,0,0,0,0,0,0,0,0,0,0
0,0,0,0,0,0,0,0,0,0,0,0,0,0,0,0,0,0,0,0,0,0,0
0,0,0,0,0,0,0,0,0,0,0,0,0,0,0,0,0,0,0,0,0,0,0
0,0,0,0,0,0,0,0,0,0,0,0,0,0,0,0,0,0,0,0,0,0,0
0,0,0,0,0,0,0,0,0,0,0,0,0,0,0,0,0,0,0,0,0,0,0
0,0,0,0,0,0,0,0,0,0,0,0,0,0,0,0,0,0,0,0,0,0,0
0,0,0,0,0,0,0,0,0,0,0,0,0,0,0,0,0,0,0,0,0,0,0
0,0,0,0,0,0,0,0,0,0,0,0,0,0,0,0,0,0,0,0,0,0,0
0,0,0,0,0,0,0,0,0,0,0,0,0,0,0,0,0,0,0,0,0,0,0
0,0,0,0,0,0,0,0,0,0,0,0,0,0,0,0,0,0,0,0,0,0,0
endlayer

layer
0,0,0,0,0,0,0,0,0,0,0,0,0,0,0,0,0,0,0,0,0,0,0
0,0,0,0,0,0,0,0,0,0,0,0,0,0,0,0,0,0,0,0,0,0,0
0,0,0,0,0,0,0,0,0,0,0,0,0,0,0,0,0,0,0,0,0,0,0
0,0,0,0,0,0,0,0,0,0,0,0,0,0,0,0,0,0,0,0,0,0,0
0,0,0,0,0,0,0,0,0,0,0,0,0,0,0,0,0,0,0,0,0,0,0
0,0,0,0,0,0,0,0,0,0,0,0,0,0,0,0,0,0,0,0,0,0,0
0,0,0,0,0,0,0,0,0,0,0,0,0,0,0,0,0,0,0,0,0,0,0
0,0,0,0,0,0,0,0,0,0,0,0,0,0,0,0,0,0,0,0,0,0,0
0,0,0,0,0,0,0,0,0,0,0,0,0,0,0,0,0,0,0,0,0,0,0
0,0,0,0,0,0,0,0,0,0,0,0,0,0,0,0,0,0,0,0,0,0,0
0,0,0,0,0,0,0,0,0,0,0,0,0,0,0,0,0,0,0,0,0,0,0
0,0,0,0,0,0,0,0,0,0,0,9,0,0,0,0,0,0,0,0,0,0,0
0,0,0,0,0,0,0,0,0,0,0,0,0,0,0,0,0,0,0,0,0,0,0
0,0,0,0,0,0,0,0,0,0,0,0,0,0,0,0,0,0,0,0,0,0,0
0,0,0,0,0,0,0,0,0,0,0,0,0,0,0,0,0,0,0,0,0,0,0
0,0,0,0,0,0,0,0,0,0,0,0,0,0,0,0,0,0,0,0,0,0,0
0,0,0,0,0,0,0,0,0,0,0,0,0,0,0,0,0,0,0,0,0,0,0
0,0,0,0,0,0,0,0,0,0,0,0,0,0,0,0,0,0,0,0,0,0,0
0,0,0,0,0,0,0,0,0,0,0,0,0,0,0,0,0,0,0,0,0,0,0
0,0,0,0,0,0,0,0,0,0,0,0,0,0,0,0,0,0,0,0,0,0,0
0,0,0,0,0,0,0,0,0,0,0,0,0,0,0,0,0,0,0,0,0,0,0
0,0,0,0,0,0,0,0,0,0,0,0,0,0,0,0,0,0,0,0,0,0,0
0,0,0,0,0,0,0,0,0,0,0,0,0,0,0,0,0,0,0,0,0,0,0
endlayer

