# Water Dungeon Hall -- 9 Jan 2016 (MC 1.7.10)
# Created by Ruins mod version 15.1 Ingame Parser
# authoring Player: Jordan_Greywolf
# Note: Place in \templateparser folder.
# Updated to MC 1.9: 26 Apr 2016

weight=1
embed_into_distance=2
acceptable_target_blocks=
unacceptable_target_blocks=flowing_water,water,flowing_lava,lava
dimensions=9,7,13
allowable_overhang=0
max_leveling=0
leveling_buffer=0
preserve_water=0
preserve_lava=0

rule1=0,100,minecraft:mossy_cobblestone-0,minecraft:cobblestone
rule2=0,100,minecraft:water-0
rule3=0,100,minecraft:stonebrick-0,minecraft:stonebrick-0,minecraft:stonebrick-1,minecraft:stonebrick-2
rule4=0,100,minecraft:water-9
rule5=0,100,minecraft:stone_brick_stairs-7
rule6=0,100,minecraft:stone_brick_stairs-6
rule7=0,100,minecraft:stone_brick_stairs-4
rule8=0,100,minecraft:stone_brick_stairs-5
rule9=0,100,minecraft:stone_brick_stairs-1
rule10=0,100,minecraft:cobblestone_wall-1,minecraft:cobblestone_wall
rule11=0,100,ChestGenHook:chests/simple_dungeon:3-5,ChestGenHook:chests/spawn_bonus_chest:6-5
rule12=0,100,ChestGenHook:chests/simple_dungeon:3-4,ChestGenHook:chests/spawn_bonus_chest:6-4
rule13=0,100,minecraft:stone_brick_stairs-0
rule14=0,100,MobSpawner:Skeleton,MobSpawner:Spider
rule15=0,100,minecraft:water-1
rule16=0,100,minecraft:stonebrick-3
rule17=0,100,minecraft:stone_slab-13

layer
1,1,1,1,1,1,1,1,1,1,1,1,1
1,2,2,2,2,2,2,2,2,2,2,2,1
1,2,2,2,2,2,2,2,2,2,2,2,1
1,2,1,2,1,2,1,2,1,2,1,2,1
1,2,2,2,2,2,2,2,2,2,2,2,1
1,2,2,2,2,2,2,2,2,2,2,2,1
1,1,1,1,1,1,1,1,1,1,1,1,1
endlayer

layer
3,3,3,3,3,3,3,3,3,3,3,3,3
3,0,0,4,4,0,0,0,4,4,0,0,3
3,0,0,0,0,0,0,0,0,0,0,0,3
3,0,1,0,1,0,1,0,1,0,1,0,3
3,0,0,0,0,0,0,0,0,0,0,0,3
3,0,0,4,4,0,0,0,4,4,0,0,3
3,3,3,3,3,3,3,3,3,3,3,3,3
endlayer

layer
3,3,3,3,3,3,3,3,3,3,3,3,3
3,1,6,4,4,5,1,6,4,4,5,1,3
3,1,7,7,7,7,1,7,7,7,7,1,3
3,1,1,1,1,1,1,1,1,1,1,1,3
3,1,8,8,8,8,1,8,8,8,8,1,3
3,1,6,4,4,5,1,6,4,4,5,1,3
3,3,3,3,3,3,3,3,3,3,3,3,3
endlayer

layer
3,3,3,9,9,3,9,3,9,9,3,3,3
3,0,10,4,4,10,11,10,4,4,10,0,3
0,0,10,10,10,10,0,10,10,10,10,0,0
0,0,0,0,0,0,0,0,0,0,0,0,0
0,0,10,10,10,10,0,10,10,10,10,0,0
3,0,10,4,4,10,12,10,4,4,10,0,3
3,3,3,13,13,3,13,3,13,13,3,3,3
endlayer

layer
3,3,3,2,2,3,14,3,2,2,3,3,3
3,0,0,15,15,0,0,0,15,15,0,0,3
0,0,0,0,0,0,0,0,0,0,0,0,0
0,0,0,0,0,0,0,0,0,0,0,0,0
0,0,0,0,0,0,0,0,0,0,0,0,0
3,0,0,15,15,0,0,0,15,15,0,0,3
3,3,3,2,2,3,14,3,2,2,3,3,3
endlayer

layer
3,3,3,8,8,3,8,3,8,8,3,3,3
3,0,0,0,0,0,0,0,0,0,0,0,3
0,0,0,0,0,0,0,0,0,0,0,0,0
0,0,0,0,0,0,0,0,0,0,0,0,0
0,0,0,0,0,0,0,0,0,0,0,0,0
3,0,0,0,0,0,0,0,0,0,0,0,3
3,3,3,7,7,3,7,3,7,7,3,3,3
endlayer

layer
3,3,3,3,3,3,3,3,3,3,3,3,3
3,8,16,8,8,16,0,16,8,8,16,8,3
0,0,0,0,0,0,0,0,0,0,0,0,0
0,0,0,0,0,0,0,0,0,0,0,0,0
0,0,0,0,0,0,0,0,0,0,0,0,0
3,7,16,7,7,16,0,16,7,7,16,7,3
3,3,3,3,3,3,3,3,3,3,3,3,3
endlayer

layer
3,3,3,3,3,3,3,3,3,3,3,3,3
3,3,3,3,3,3,0,3,3,3,3,3,3
0,0,0,0,0,0,0,0,0,0,0,0,0
0,0,0,0,0,0,0,0,0,0,0,0,0
0,0,0,0,0,0,0,0,0,0,0,0,0
3,3,3,3,3,3,0,3,3,3,3,3,3
3,3,3,3,3,3,3,3,3,3,3,3,3
endlayer

layer
3,3,3,3,3,3,3,3,3,3,3,3,3
3,3,3,3,3,3,8,3,3,3,3,3,3
3,8,8,8,5,3,17,3,8,8,8,5,3
3,6,17,17,5,3,17,3,6,17,17,5,3
3,6,7,7,7,3,17,3,6,7,7,7,3
3,3,3,3,3,3,7,3,3,3,3,3,3
3,3,3,3,3,3,3,3,3,3,3,3,3
endlayer

