# Water Dungeon Chamber - North/South Intersection
# 9 Jan 2016 (MC 1.7.10)
# Created by Ruins mod version 15.1 Ingame Parser
# authoring Player: Jordan_Greywolf
# Note: Place in \templateparser folder.
# Updated to MC 1.8: 20 Mar 2016
# Updated to MC 1.9: 26 Apr 2016
# Updated to MC 1.11: 12 Jan 2017
# Updated to MC 1.12: 22 Jun 2017

weight=1
embed_into_distance=2
acceptable_target_blocks=
unacceptable_target_blocks=flowing_water,water,flowing_lava,lava
dimensions=16,13,13
allowable_overhang=0
max_leveling=0
leveling_buffer=0
preserve_water=0
preserve_lava=0

rule1=0,100,minecraft:mossy_cobblestone-0,minecraft:mossy_cobblestone-0,minecraft:cobblestone-0
rule2=0,100,minecraft:stonebrick-0,minecraft:stonebrick-0,minecraft:stonebrick-1,minecraft:stonebrick-2

rule3=0,100,minecraft:water-0
rule4=0,100,minecraft:water-8
rule5=0,100,minecraft:water-9
rule6=0,100,minecraft:stone_slab-13
rule7=0,100,minecraft:iron_bars-0
rule8=0,100,minecraft:stone_brick_stairs-6
rule9=0,100,minecraft:stone_brick_stairs-7
rule10=0,100,minecraft:stone_brick_stairs-5
rule11=0,100,minecraft:stone_slab-5
rule12=0,100,minecraft:stonebrick-3
rule13=0,100,minecraft:stone_brick_stairs-0
rule14=0,100,minecraft:stone_brick_stairs-4

rule15=0,100,MobSpawner:Cave_Spider,MobSpawner:Skeleton

rule16=0,100,minecraft:stone_brick_stairs-2
rule17=0,100,minecraft:stone_brick_stairs-3
rule18=0,100,minecraft:stone_brick_stairs-1
rule19=0,100,CommandBlock:RUINSTRIGGER /testruin TP_WaterHall ~-7 ~-2 ~0 1:@
rule20=0,100,minecraft:cobblestone_wall-1
rule21=0,100,ChestGenHook:chests/simple_dungeon:2-5
rule22=0,100,ChestGenHook:chests/simple_dungeon:2-2
rule23=0,100,minecraft:mossy_cobblestone

rule24=0,100,CommandBlock:RUINSTRIGGER /summon Zombie ~0 ~1 ~0 {ArmorItems:[{Count:1,id:chainmail_boots,tag:{ench:[{id:7,lvl:3}]}},{Count:1,id:chainmail_leggings,tag:{ench:[{id:7,lvl:3}]}},{Count:1,id:chainmail_chestplate,tag:{ench:[{id:7,lvl:3}]}},{Count:1,id:chainmail_helmet,tag:{ench:[{id:7,lvl:3}]}}],CustomName:"Vile Spirit",Health:50.0f,Attributes:[{Name:generic.attackDamage,Base:6}],ActiveEffects:[{Id:12,Amplifier:1,Duration:999999},{Id:3,Amplifier:1,Duration:999999},{Id:14,Amplifier:1,Duration:999999},{Id:8,Amplifier:1,Duration:999999},{Id:10,Amplifier:1,Duration:999999}],Silent:1,PersistenceRequired:1}:@

rule25=0,100,minecraft:mossy_cobblestone
rule26=0,100,ChestGenHook:chests/simple_dungeon:2-3
rule27=0,100,ChestGenHook:chests/simple_dungeon:2-4
rule28=0,100,CommandBlock:RUINSTRIGGER /testruin TP_WaterHall ~7 ~-2 ~0 1:@
rule29=0,100,CommandBlock:RUINSTRIGGER /testruin TP_WaterCorner ~-20 ~-4 ~0:@
rule30=0,100,minecraft:water-1
rule31=0,100,minecraft:mossy_cobblestone
rule32=0,100,minecraft:mossy_cobblestone
rule33=0,100,CommandBlock:RUINSTRIGGER /testruin TP_WaterCorner ~20 ~-4 ~0:@
rule34=0,100,minecraft:grass-0
rule35=0,100,minecraft:red_flower-4
rule36=0,100,minecraft:glowstone-0

layer
23,25,31,32,1,1,1,1,1,1,1,1,1
1,1,1,1,1,1,1,1,1,1,1,1,1
1,1,1,1,1,1,1,1,1,1,1,1,1
1,1,1,1,1,1,1,1,1,1,1,1,1
1,1,1,1,1,1,1,1,1,1,1,1,1
1,1,1,1,1,1,1,1,1,1,1,1,1
1,1,1,1,1,1,1,1,1,1,1,1,1
1,1,1,1,1,1,1,1,1,1,1,1,1
1,1,1,1,1,1,1,1,1,1,1,1,1
1,1,1,1,1,1,1,1,1,1,1,1,1
1,1,1,1,1,1,1,1,1,1,1,1,1
1,1,1,1,1,1,1,1,1,1,1,1,1
1,1,1,1,1,1,1,1,1,1,1,1,1
endlayer

layer
2,2,2,2,2,2,2,2,2,2,2,2,2
2,3,3,3,3,2,2,2,3,3,3,3,2
2,3,3,3,3,3,3,3,3,3,3,3,2
2,3,3,3,3,3,3,3,3,3,3,3,2
2,3,3,3,3,3,3,3,3,3,3,3,2
2,2,3,3,3,3,3,3,3,3,3,2,2
2,2,3,3,3,3,3,3,3,3,3,2,2
2,2,3,3,3,3,3,3,3,3,3,2,2
2,3,3,3,3,3,3,3,3,3,3,3,2
2,3,3,3,3,3,3,3,3,3,3,3,2
2,3,3,3,3,3,3,3,3,3,3,3,2
2,3,3,3,3,2,2,2,3,3,3,3,2
2,2,2,2,2,2,2,2,2,2,2,2,2
endlayer

layer
2,2,2,2,2,2,2,2,2,2,2,2,2
2,4,5,0,0,2,2,2,0,0,5,4,2
2,5,0,0,0,6,6,6,0,0,0,5,2
2,0,0,0,0,0,0,0,0,0,0,0,2
2,0,0,0,0,0,0,0,0,0,0,0,2
2,2,6,0,0,0,0,0,0,0,6,2,2
2,2,6,0,0,0,0,0,0,0,6,2,2
2,2,6,0,0,0,0,0,0,0,6,2,2
2,0,0,0,0,0,0,0,0,0,0,0,2
2,0,0,0,0,0,0,0,0,0,0,0,2
2,5,0,0,0,6,6,6,0,0,0,5,2
2,4,5,0,0,2,2,2,0,0,5,4,2
2,2,2,2,2,2,2,2,2,2,2,2,2
endlayer

layer
2,2,2,2,2,7,7,7,2,2,2,2,2
2,4,5,0,9,0,0,0,8,0,5,4,2
2,5,0,0,10,11,11,11,10,0,0,5,2
2,0,0,12,2,13,13,13,2,12,0,0,2
2,14,8,2,6,2,15,2,6,2,9,14,2
7,0,11,17,2,12,2,12,2,16,11,0,7
7,0,11,17,15,2,2,2,15,16,11,0,7
7,0,11,17,2,12,2,12,2,16,11,0,7
2,10,8,2,6,2,15,2,6,6,9,10,2
2,0,0,12,2,18,18,18,2,12,0,0,2
2,5,0,0,14,11,11,11,14,0,0,5,2
2,4,5,0,9,0,0,0,8,0,5,4,2
2,2,2,2,2,7,7,7,2,2,2,2,2
endlayer

layer
2,2,2,2,2,7,19,7,2,2,2,2,2
2,4,5,0,20,0,0,0,20,0,5,4,2
2,5,0,0,20,0,0,0,20,0,0,5,2
2,0,0,20,20,0,0,0,20,20,0,0,2
2,20,20,20,22,0,0,0,21,20,20,20,2
7,0,0,0,0,0,0,0,0,0,0,0,7
0,0,0,0,0,0,24,0,0,0,0,0,0
7,0,0,0,0,0,0,0,0,0,0,0,7
2,20,20,20,27,0,0,0,26,20,20,20,2
2,0,0,20,20,0,0,0,20,20,0,0,2
2,5,0,0,20,0,0,0,20,0,0,5,2
2,4,5,0,20,0,0,0,20,0,5,4,2
2,2,2,2,2,7,28,7,2,2,2,2,2
endlayer

layer
2,2,18,2,2,7,7,7,2,2,18,2,2
2,4,5,0,0,0,0,0,0,0,5,4,2
16,5,0,0,0,0,0,0,0,0,0,5,17
2,0,0,20,0,0,0,0,0,20,0,0,2
2,0,0,20,0,0,0,0,0,0,0,0,2
7,0,0,0,0,0,0,0,0,0,0,0,7
7,0,0,0,0,0,0,0,0,0,0,0,7
7,0,0,0,0,0,0,0,0,0,0,0,7
2,0,0,0,0,0,0,0,0,0,0,0,2
2,0,0,20,0,0,0,0,0,20,0,0,2
16,5,0,0,0,0,0,0,0,0,0,5,17
2,4,5,0,0,0,0,0,0,0,5,4,2
2,2,13,2,2,7,7,7,2,2,13,2,2
endlayer

layer
2,2,3,2,2,7,29,7,2,2,3,2,2
2,4,30,0,0,0,0,0,0,0,30,4,2
3,30,0,0,0,0,0,0,0,0,0,30,3
2,0,0,20,0,0,0,0,0,20,0,0,2
2,0,0,0,0,0,0,0,0,0,0,0,2
7,0,0,0,0,0,0,0,0,0,0,0,7
0,0,0,0,0,0,0,0,0,0,0,0,0
7,0,0,0,0,0,0,0,0,0,0,0,7
2,0,0,0,0,0,0,0,0,0,0,0,2
2,0,0,20,0,0,0,0,0,20,0,0,2
3,30,0,0,0,0,0,0,0,0,0,30,3
2,4,30,0,0,0,0,0,0,0,30,4,2
2,2,3,2,2,7,33,7,2,2,3,2,2
endlayer

layer
2,2,10,2,2,7,7,7,2,2,10,2,2
2,4,0,0,0,0,0,0,0,0,0,4,2
8,0,0,0,0,0,0,0,0,0,0,0,9
2,0,0,20,0,0,0,0,0,20,0,0,2
2,0,0,0,0,0,0,0,0,0,0,0,2
7,0,0,0,0,0,0,0,0,0,0,0,7
7,0,0,0,0,0,0,0,0,0,0,0,7
7,0,0,0,0,0,0,0,0,0,0,0,7
2,0,0,0,0,0,0,0,0,0,0,0,2
2,0,0,20,0,0,0,0,0,20,0,0,2
8,0,0,0,0,0,0,0,0,0,0,0,9
2,4,0,0,0,0,0,0,0,0,0,4,2
2,2,14,2,2,7,7,7,2,2,14,2,2
endlayer

layer
2,2,2,2,12,2,2,2,12,2,2,2,2
2,4,2,8,0,0,0,0,0,9,2,4,2
2,2,2,8,0,0,0,0,0,9,2,2,2
2,10,10,12,0,0,0,0,0,12,10,10,2
12,0,0,0,0,0,0,0,0,0,0,0,12
2,0,0,0,0,0,0,0,0,0,0,0,2
2,0,0,0,0,0,0,0,0,0,0,0,2
2,0,0,0,0,0,0,0,0,0,0,0,2
12,0,0,0,0,0,0,0,0,0,0,0,12
2,14,14,12,0,0,0,0,0,12,14,14,2
2,2,2,8,0,0,0,0,0,9,2,2,2
2,4,2,8,0,0,0,0,0,9,2,4,2
2,2,2,2,12,2,2,2,12,2,2,2,2
endlayer

layer
2,2,2,2,2,2,2,2,2,2,2,2,2
2,3,3,2,8,0,0,0,9,2,3,3,2
2,3,3,2,8,0,0,0,9,2,3,3,2
2,2,2,2,8,0,0,0,9,2,2,2,2
2,10,10,10,12,0,0,0,12,10,10,10,2
2,0,0,0,0,0,0,0,0,0,0,0,2
2,0,0,0,0,0,0,0,0,0,0,0,2
2,0,0,0,0,0,0,0,0,0,0,0,2
2,14,14,14,12,0,0,0,12,14,14,14,2
2,2,2,2,8,0,0,0,9,2,2,2,2
2,3,3,2,8,0,0,0,9,2,3,3,2
2,3,3,2,8,0,0,0,9,2,3,3,2
2,2,2,2,2,2,2,2,2,2,2,2,2
endlayer

layer
2,2,2,2,2,2,2,2,2,2,2,2,2
2,3,3,34,34,8,10,9,34,34,3,3,2
2,3,3,34,34,8,0,9,34,34,3,3,2
2,34,34,34,34,8,0,9,34,34,34,34,2
2,34,34,34,34,8,0,9,34,34,34,34,2
2,10,10,10,10,12,10,12,10,10,10,10,2
2,8,0,0,0,8,0,9,0,0,0,9,2
2,14,14,14,14,12,14,12,14,14,14,14,2
2,34,34,34,34,8,0,9,34,34,34,34,2
2,34,34,34,34,8,0,9,34,34,34,34,2
2,3,3,34,34,8,0,9,34,34,3,3,2
2,3,3,34,34,8,14,9,34,34,3,3,2
2,2,2,2,2,2,2,2,2,2,2,2,2
endlayer

layer
2,18,2,2,2,2,2,2,2,2,2,18,2
16,5,0,35,35,20,20,20,35,35,0,5,17
2,0,0,35,35,20,0,20,35,35,0,0,2
2,35,35,35,35,20,0,20,35,35,35,35,2
2,35,35,35,35,20,0,20,35,35,35,35,2
2,20,20,20,20,20,20,20,20,20,20,20,2
2,20,0,0,0,20,0,20,0,0,0,20,2
2,20,20,20,20,20,20,20,20,20,20,20,2
2,35,35,35,35,20,0,20,35,35,35,35,2
2,35,35,35,35,20,0,20,35,35,35,35,2
2,0,0,35,35,20,0,20,35,35,0,0,2
16,5,0,35,35,20,20,20,35,35,0,5,17
2,13,2,2,2,2,2,2,2,2,2,13,2
endlayer

layer
36,3,2,18,18,2,12,2,18,18,2,3,36
3,30,0,0,0,0,0,0,0,0,0,30,3
2,0,0,0,0,0,0,0,0,0,0,0,2
16,0,0,0,0,0,0,0,0,0,0,0,17
16,0,0,0,0,0,0,0,0,0,0,0,17
2,0,0,0,0,20,0,20,0,0,0,0,2
12,0,0,0,0,0,0,0,0,0,0,0,12
2,0,0,0,0,20,0,20,0,0,0,0,2
16,0,0,0,0,0,0,0,0,0,0,0,17
16,0,0,0,0,0,0,0,0,0,0,0,17
2,0,0,0,0,0,0,0,0,0,0,0,2
3,30,0,0,0,0,0,0,0,0,0,30,3
36,3,2,13,13,2,12,2,13,13,2,3,36
endlayer

layer
2,10,2,10,10,2,12,2,10,10,2,10,2
8,0,0,0,0,0,0,0,0,0,0,0,9
2,0,0,0,0,0,0,0,0,0,0,0,2
8,0,0,0,0,0,0,0,0,0,0,0,9
8,0,0,0,0,0,0,0,0,0,0,0,9
2,0,0,0,0,20,0,20,0,0,0,0,2
12,0,0,0,0,0,0,0,0,0,0,0,12
2,0,0,0,0,20,0,20,0,0,0,0,2
8,0,0,0,0,0,0,0,0,0,0,0,9
8,0,0,0,0,0,0,0,0,0,0,0,9
2,0,0,0,0,0,0,0,0,0,0,0,2
8,0,0,0,0,0,0,0,0,0,0,0,9
2,14,2,14,14,2,12,2,14,14,2,14,2
endlayer

layer
2,2,2,2,2,2,2,2,2,2,2,2,2
2,0,0,0,0,0,0,0,0,0,0,0,2
2,0,0,0,0,0,0,0,0,0,0,0,2
2,0,0,0,0,0,0,0,0,0,0,0,2
2,0,0,0,0,0,0,0,0,0,0,0,2
2,0,0,0,0,12,0,12,0,0,0,0,2
2,0,0,0,0,0,0,0,0,0,0,0,2
2,0,0,0,0,12,0,12,0,0,0,0,2
2,0,0,0,0,0,0,0,0,0,0,0,2
2,0,0,0,0,0,0,0,0,0,0,0,2
2,0,0,0,0,0,0,0,0,0,0,0,2
2,0,0,0,0,0,0,0,0,0,0,0,2
2,2,2,2,2,2,2,2,2,2,2,2,2
endlayer

layer
2,2,2,2,2,2,2,2,2,2,2,2,2
2,10,10,10,9,2,10,2,10,10,10,9,2
2,8,0,0,9,2,6,2,8,0,0,9,2
2,8,0,0,9,2,6,2,8,0,0,9,2
2,8,14,14,14,2,14,2,14,14,14,9,2
2,2,2,2,2,2,2,2,2,2,2,2,2
2,8,6,6,9,2,12,2,8,6,6,9,2
2,2,2,2,2,2,2,2,2,2,2,2,2
2,10,10,10,9,2,10,2,10,10,10,9,2
2,8,0,0,9,2,6,2,8,0,0,9,2
2,8,0,0,9,2,6,2,8,0,0,9,2
2,8,14,14,14,2,14,2,8,14,14,14,2
2,2,2,2,2,2,2,2,2,2,2,2,2
endlayer

