# Water Dungeon Entry -- 9 Jan 2016 (MC 1.7.10)
# Created by Ruins mod version 15.1 Ingame Parser
# authoring Player: Jordan_Greywolf
# Note: Place in \templateparser folder.

weight=1
embed_into_distance=2
acceptable_target_blocks=
unacceptable_target_blocks=flowing_water,water,flowing_lava,lava
dimensions=16,13,13
allowable_overhang=0
max_leveling=0
leveling_buffer=0
preserve_water=0
preserve_lava=0

rule1=0,100,minecraft:mossy_cobblestone-0,minecraft:mossy_cobblestone-0,minecraft:cobblestone-0

rule2=0,100,minecraft:stonebrick-0,minecraft:stonebrick-0,minecraft:stonebrick-1,minecraft:stonebrick-2

rule3=0,100,minecraft:water-0
rule4=0,100,minecraft:water-8
rule5=0,100,minecraft:water-9
rule6=0,100,minecraft:iron_bars-0
rule7=0,100,minecraft:stone_brick_stairs-6
rule8=0,100,minecraft:stone_brick_stairs-0
rule9=0,100,minecraft:stone_brick_stairs-7
rule10=0,100,minecraft:stone_brick_stairs-5
rule11=0,100,minecraft:stone_slab-13
rule12=0,100,minecraft:stone_brick_stairs-4
rule13=0,100,minecraft:glowstone-0
rule14=0,100,minecraft:stone_brick_stairs-2
rule15=0,100,minecraft:stone_brick_stairs-3
rule16=0,100,minecraft:stone_brick_stairs-1

rule17=0,100,CommandBlock:RUINSTRIGGER /testruin TP_WaterHall ~-7 ~-2 ~0 1:@

rule18=0,100,minecraft:stonebrick-3
rule19=0,100,minecraft:stained_glass-2
rule20=0,100,minecraft:stained_glass-11
rule21=0,100,minecraft:stained_glass-14
rule22=0,100,minecraft:stained_glass-1

rule23=0,100,CommandBlock:RUINSTRIGGER /testruin TP_WaterHall ~0 ~-2 ~-7:@

rule24=0,100,CommandBlock:/tp @p[r=3] ~0 ~50 ~0:@

rule25=0,100,CommandBlock:RUINSTRIGGER /testruin TP_WaterHall ~0 ~-2 ~7:@
rule26=0,100,CommandBlock:RUINSTRIGGER /testruin TP_WaterHall ~7 ~-2 ~0 1:@

rule27=0,100,minecraft:cobblestone_wall-1,minecraft:cobblestone_wall-0

rule28=2,100,minecraft:stone_button-2
rule29=2,100,minecraft:stone_button-4
rule30=2,100,minecraft:stone_button-3
rule31=2,100,minecraft:stone_button-1

rule32=0,100,CommandBlock:RUINSTRIGGER /testruin TP_WaterEWChamber ~-20 ~-4 ~0:@

rule33=0,100,minecraft:water-1

rule34=0,100,CommandBlock:RUINSTRIGGER /testruin TP_WaterNSChamber ~0 ~-4 ~-20:@
rule35=0,100,CommandBlock:RUINSTRIGGER /testruin TP_WaterNSChamber ~0 ~-4 ~20:@
rule36=0,100,CommandBlock:RUINSTRIGGER /testruin TP_WaterEWChamber ~20 ~-4 ~0:@

rule37=0,100,minecraft:grass-0

rule38=0,100,minecraft:red_flower-4,minecraft:red_flower-0,minecraft:red_flower-1,minecraft:red_flower-2

layer
1,1,1,1,1,1,1,1,1,1,1,1,1
1,1,1,1,1,1,1,1,1,1,1,1,1
1,1,1,1,1,1,1,1,1,1,1,1,1
1,1,1,1,1,1,1,1,1,1,1,1,1
1,1,1,1,1,1,1,1,1,1,1,1,1
1,1,1,1,1,1,1,1,1,1,1,1,1
1,1,1,1,1,1,1,1,1,1,1,1,1
1,1,1,1,1,1,1,1,1,1,1,1,1
1,1,1,1,1,1,1,1,1,1,1,1,1
1,1,1,1,1,1,1,1,1,1,1,1,1
1,1,1,1,1,1,1,1,1,1,1,1,1
1,1,1,1,1,1,1,1,1,1,1,1,1
1,1,1,1,1,1,1,1,1,1,1,1,1
endlayer

layer
2,2,2,2,2,2,2,2,2,2,2,2,2
2,3,3,3,3,2,2,2,3,3,3,3,2
2,3,3,3,3,3,3,3,3,3,3,3,2
2,3,3,3,3,3,3,3,3,3,3,3,2
2,3,3,3,3,3,3,3,3,3,3,3,2
2,2,3,3,3,3,3,3,3,3,3,2,2
2,2,3,3,3,3,3,3,3,3,3,2,2
2,2,3,3,3,3,3,3,3,3,3,2,2
2,3,3,3,3,3,3,3,3,3,3,3,2
2,3,3,3,3,3,3,3,3,3,3,3,2
2,3,3,3,3,3,3,3,3,3,3,3,2
2,3,3,3,3,2,2,2,3,3,3,3,2
2,2,2,2,2,2,2,2,2,2,2,2,2
endlayer

layer
2,2,2,2,2,2,2,2,2,2,2,2,2
2,4,5,0,0,2,2,2,0,0,5,4,2
2,5,0,0,0,0,0,0,0,0,0,5,2
2,0,0,0,0,0,0,0,0,0,0,0,2
2,0,0,0,0,0,0,0,0,0,0,0,2
2,2,0,0,0,0,0,0,0,0,0,2,2
2,2,0,0,0,0,0,0,0,0,0,2,2
2,2,0,0,0,0,0,0,0,0,0,2,2
2,0,0,0,0,0,0,0,0,0,0,0,2
2,0,0,0,0,0,0,0,0,0,0,0,2
2,5,0,0,0,0,0,0,0,0,0,5,2
2,4,5,0,0,2,2,2,0,0,5,4,2
2,2,2,2,2,2,2,2,2,2,2,2,2
endlayer

layer
2,2,2,2,2,6,6,6,2,2,2,2,2
2,4,5,0,9,8,8,8,7,0,5,4,2
2,5,0,0,10,10,10,10,10,0,0,5,2
2,0,0,0,0,11,11,11,0,0,0,0,2
2,12,7,0,11,2,13,2,11,0,9,12,2
6,15,7,11,2,2,2,2,2,11,9,14,6
6,15,7,11,13,2,2,2,13,11,9,14,6
6,15,7,11,2,2,2,2,2,11,9,14,6
2,10,7,0,11,2,13,2,11,11,9,10,2
2,0,0,0,0,11,11,11,0,0,0,0,2
2,5,0,0,12,12,12,12,12,0,0,5,2
2,4,5,0,9,16,16,16,7,0,5,4,2
2,2,2,2,2,6,6,6,2,2,2,2,2
endlayer

layer
2,2,2,2,2,6,17,6,2,2,2,2,2
2,4,5,0,2,0,0,0,2,0,5,4,2
2,5,0,0,2,8,8,8,2,0,0,5,2
2,0,0,2,2,2,18,2,2,2,0,0,2
2,2,2,2,18,19,20,19,18,2,2,2,2
6,0,15,2,19,21,22,21,19,2,14,0,6
25,0,15,18,20,22,24,22,20,18,14,0,23
6,0,15,2,19,21,22,21,19,2,14,0,6
2,2,2,2,18,19,20,19,18,2,2,2,2
2,0,0,2,2,2,18,2,2,2,0,0,2
2,5,0,0,2,16,16,16,2,0,0,5,2
2,4,5,0,2,0,0,0,2,0,5,4,2
2,2,2,2,2,6,26,6,2,2,2,2,2
endlayer

layer
2,2,16,2,2,6,6,6,2,2,16,2,2
2,4,5,0,27,0,0,0,27,0,5,4,2
14,5,0,0,27,0,0,0,27,0,0,5,15
2,0,0,27,27,0,0,0,27,27,0,0,2
2,27,27,27,0,0,0,0,0,27,27,27,2
6,0,0,0,0,0,28,0,0,0,0,0,6
6,0,0,0,0,30,18,29,0,0,0,0,6
6,0,0,0,0,0,31,0,0,0,0,0,6
2,27,27,27,0,0,0,0,0,27,27,27,2
2,0,0,27,27,0,0,0,27,27,0,0,2
14,5,0,0,27,0,0,0,27,0,0,5,15
2,4,5,0,27,0,0,0,27,0,5,4,2
2,2,8,2,2,6,6,6,2,2,8,2,2
endlayer

layer
2,2,3,2,2,6,32,6,2,2,3,2,2
2,4,33,0,0,0,0,0,0,0,33,4,2
3,33,0,0,0,0,0,0,0,0,0,33,3
2,0,0,27,0,0,0,0,0,27,0,0,2
2,0,0,0,0,0,0,0,0,0,0,0,2
6,0,0,0,0,0,0,0,0,0,0,0,6
35,0,0,0,0,0,0,0,0,0,0,0,34
6,0,0,0,0,0,0,0,0,0,0,0,6
2,0,0,0,0,0,0,0,0,0,0,0,2
2,0,0,27,0,0,0,0,0,27,0,0,2
3,33,0,0,0,0,0,0,0,0,0,33,3
2,4,33,0,0,0,0,0,0,0,33,4,2
2,2,3,2,2,6,36,6,2,2,3,2,2
endlayer

layer
2,2,10,2,2,6,6,6,2,2,10,2,2
2,4,0,0,0,0,0,0,0,0,0,4,2
7,0,0,0,0,0,0,0,0,0,0,0,9
2,0,0,27,0,0,0,0,0,27,0,0,2
2,0,0,0,0,0,0,0,0,0,0,0,2
6,0,0,0,0,0,0,0,0,0,0,0,6
6,0,0,0,0,0,0,0,0,0,0,0,6
6,0,0,0,0,0,0,0,0,0,0,0,6
2,0,0,0,0,0,0,0,0,0,0,0,2
2,0,0,27,0,0,0,0,0,27,0,0,2
7,0,0,0,0,0,0,0,0,0,0,0,9
2,4,0,0,0,0,0,0,0,0,0,4,2
2,2,12,2,2,6,6,6,2,2,12,2,2
endlayer

layer
2,2,2,2,18,2,2,2,18,2,2,2,2
2,4,2,7,0,0,0,0,0,9,2,4,2
2,2,2,7,0,0,0,0,0,9,2,2,2
2,10,10,18,0,0,0,0,0,18,10,10,2
18,0,0,0,0,0,0,0,0,0,0,0,18
2,0,0,0,0,0,0,0,0,0,0,0,2
2,0,0,0,0,0,0,0,0,0,0,0,2
2,0,0,0,0,0,0,0,0,0,0,0,2
18,0,0,0,0,0,0,0,0,0,0,0,18
2,12,12,18,0,0,0,0,0,18,12,12,2
2,2,2,7,0,0,0,0,0,9,2,2,2
2,4,2,7,0,0,0,0,0,9,2,4,2
2,2,2,2,18,2,2,2,18,2,2,2,2
endlayer

layer
2,2,2,2,2,2,2,2,2,2,2,2,2
2,3,3,2,7,0,0,0,9,2,3,3,2
2,3,3,2,7,0,0,0,9,2,3,3,2
2,2,2,2,7,0,0,0,9,2,2,2,2
2,10,10,10,18,0,0,0,18,10,10,10,2
2,0,0,0,0,0,0,0,0,0,0,0,2
2,0,0,0,0,0,0,0,0,0,0,0,2
2,0,0,0,0,0,0,0,0,0,0,0,2
2,12,12,12,18,0,0,0,18,12,12,12,2
2,2,2,2,7,0,0,0,9,2,2,2,2
2,3,3,2,7,0,0,0,9,2,3,3,2
2,3,3,2,7,0,0,0,9,2,3,3,2
2,2,2,2,2,2,2,2,2,2,2,2,2
endlayer

layer
2,2,2,2,2,2,2,2,2,2,2,2,2
2,3,3,37,37,7,10,9,37,37,3,3,2
2,3,3,37,37,7,0,9,37,37,3,3,2
2,37,37,37,37,7,0,9,37,37,37,37,2
2,37,37,37,37,7,0,9,37,37,37,37,2
2,10,10,10,10,18,10,18,10,10,10,10,2
2,7,0,0,0,7,0,9,0,0,0,9,2
2,12,12,12,12,18,12,18,12,12,12,12,2
2,37,37,37,37,7,0,9,37,37,37,37,2
2,37,37,37,37,7,0,9,37,37,37,37,2
2,3,3,37,37,7,0,9,37,37,3,3,2
2,3,3,37,37,7,12,9,37,37,3,3,2
2,2,2,2,2,2,2,2,2,2,2,2,2
endlayer

layer
2,16,2,2,2,2,2,2,2,2,2,16,2
14,5,0,38,38,27,27,27,38,38,0,5,15
2,0,0,38,38,27,0,27,38,38,0,0,2
2,38,38,38,38,27,0,27,38,38,38,38,2
2,38,38,38,38,27,0,27,38,38,38,38,2
2,27,27,27,27,27,27,27,27,27,27,27,2
2,27,0,0,0,27,0,27,0,0,0,27,2
2,27,27,27,27,27,27,27,27,27,27,27,2
2,38,38,38,38,27,0,27,38,38,38,38,2
2,38,38,38,38,27,0,27,38,38,38,38,2
2,0,0,38,38,27,0,27,38,38,0,0,2
14,5,0,38,38,27,27,27,38,38,0,5,15
2,8,2,2,2,2,2,2,2,2,2,8,2
endlayer

layer
13,3,2,16,16,2,18,2,16,16,2,3,13
3,33,0,0,0,0,0,0,0,0,0,33,3
2,0,0,0,0,0,0,0,0,0,0,0,2
14,0,0,0,0,0,0,0,0,0,0,0,15
14,0,0,0,0,0,0,0,0,0,0,0,15
2,0,0,0,0,27,0,27,0,0,0,0,2
18,0,0,0,0,0,0,0,0,0,0,0,18
2,0,0,0,0,27,0,27,0,0,0,0,2
14,0,0,0,0,0,0,0,0,0,0,0,15
14,0,0,0,0,0,0,0,0,0,0,0,15
2,0,0,0,0,0,0,0,0,0,0,0,2
3,33,0,0,0,0,0,0,0,0,0,33,3
13,3,2,8,8,2,18,2,8,8,2,3,13
endlayer

layer
2,10,2,10,10,2,18,2,10,10,2,10,2
7,0,0,0,0,0,0,0,0,0,0,0,9
2,0,0,0,0,0,0,0,0,0,0,0,2
7,0,0,0,0,0,0,0,0,0,0,0,9
7,0,0,0,0,0,0,0,0,0,0,0,9
2,0,0,0,0,27,0,27,0,0,0,0,2
18,0,0,0,0,0,0,0,0,0,0,0,18
2,0,0,0,0,27,0,27,0,0,0,0,2
7,0,0,0,0,0,0,0,0,0,0,0,9
7,0,0,0,0,0,0,0,0,0,0,0,9
2,0,0,0,0,0,0,0,0,0,0,0,2
7,0,0,0,0,0,0,0,0,0,0,0,9
2,12,2,12,12,2,18,2,12,12,2,12,2
endlayer

layer
2,2,2,2,2,2,2,2,2,2,2,2,2
2,0,0,0,0,0,0,0,0,0,0,0,2
2,0,0,0,0,0,0,0,0,0,0,0,2
2,0,0,0,0,0,0,0,0,0,0,0,2
2,0,0,0,0,0,0,0,0,0,0,0,2
2,0,0,0,0,13,0,13,0,0,0,0,2
2,0,0,0,0,0,0,0,0,0,0,0,2
2,0,0,0,0,13,0,13,0,0,0,0,2
2,0,0,0,0,0,0,0,0,0,0,0,2
2,0,0,0,0,0,0,0,0,0,0,0,2
2,0,0,0,0,0,0,0,0,0,0,0,2
2,0,0,0,0,0,0,0,0,0,0,0,2
2,2,2,2,2,2,2,2,2,2,2,2,2
endlayer

layer
2,2,2,2,2,2,2,2,2,2,2,2,2
2,10,10,10,9,2,10,2,10,10,10,9,2
2,7,0,0,9,2,11,2,7,0,0,9,2
2,7,0,0,9,2,11,2,7,0,0,9,2
2,7,12,12,12,2,12,2,12,12,12,9,2
2,2,2,2,2,2,2,2,2,2,2,2,2
2,7,11,11,9,2,18,2,7,11,11,9,2
2,2,2,2,2,2,2,2,2,2,2,2,2
2,10,10,10,9,2,10,2,10,10,10,9,2
2,7,0,0,9,2,11,2,7,0,0,9,2
2,7,0,0,9,2,11,2,7,0,0,9,2
2,7,12,12,12,2,12,2,7,12,12,12,2
2,2,2,2,2,2,2,2,2,2,2,2,2
endlayer

