# War Tower B
# MC 1.7.10; 31 Oct 2014
# Created by Ruins mod version 14.0 Ingame Parser
# authoring Player: Jordan_Greywolf
# Updated to MC 1.8: 20 Mar 2016
# Updated to MC 1.9: 28 Apr 2016
# Updated to MC 1.11: 12 Jan 2017
# Updated to MC 1.12: 22 Jun 2017

weight=1
embed_into_distance=0
acceptable_target_blocks=
unacceptable_target_blocks=
dimensions=16,23,23
allowable_overhang=0
max_leveling=0
leveling_buffer=0
preserve_water=0
preserve_lava=0
preserve_plants=1

rule1=0,100,minecraft:obsidian-0
rule2=0,100,minecraft:quartz_block-1
rule3=0,100,minecraft:stonebrick-3
rule4=0,100,minecraft:stone_slab-7
rule5=0,100,minecraft:stone_slab-0
rule6=0,100,minecraft:double_stone_slab-7
rule7=0,100,minecraft:stone_slab-8
rule8=0,100,minecraft:water-8
rule9=0,100,minecraft:water-1
rule10=0,100,minecraft:water-2
rule11=0,100,minecraft:nether_brick_fence-0
rule12=0,100,minecraft:cobblestone_wall-0
rule13=1,100,minecraft:redstone_torch-5
rule14=0,100,minecraft:ice-0
rule15=0,100,minecraft:packed_ice-0
rule16=0,100,minecraft:double_stone_slab-0
rule17=0,100,minecraft:water-9
rule18=0,100,CommandBlock:RUINSTRIGGER /summon Slime ~0 9 ~0 {Size:15,AbsorptionAmount:10,PersistenceRequired:1}:@
rule19=0,100,minecraft:water-0
rule20=0,100,MobSpawner:Spider
rule21=0,100,ChestGenHook:chests/simple_dungeon:3-5

rule22=0,100,IInventory;minecraft:trapped_chest;minecraft:enchanted_book#{StoredEnchantments:[{lvl:1,id:6}]}#0#2+minecraft:lingering_potion#{Potion:"minecraft:long_water_breathing"}#0#5+minecraft:splash_potion#{Potion:"minecraft:long_water_breathing"}#0#12+minecraft:enchanted_book#{StoredEnchantments:[{lvl:3,id:62}]}#0#15+minecraft:potion#{Potion:"minecraft:long_water_breathing"}#0#17+minecraft:water_bucket#1#0#19+minecraft:potion#{Potion:"minecraft:water"}#0#23-4

rule23=0,100,ChestGenHook:chests/village_blacksmith:3-3
rule24=0,100,ChestGenHook:chests/desert_pyramid:3-2
rule25=0,100,CommandBlock:/testruin TP_WarTower1C ~0 ~0 ~0:@
rule26=0,100,ChestGenHook:chests/simple_dungeon:3-4

# Ice Guardian
rule27=0,100,CommandBlock:RUINSTRIGGER /summon skeleton ~0 ~2 ~0 {HandItems:[{Count:1,id:diamond_pickaxe,tag:{display:{Name:"Ice Pick"},ench:[{id:16,lvl:10},{id:19,lvl:10}]}},{}],ArmorItems:[{Count:1,id:diamond_boots,tag:{display:{Name:"Frozen Boots"},ench:[{id:2,lvl:10},{id:3,lvl:5}],AttributeModifiers:[{AttributeName:"generic.knockbackResistance",Name:"Knockback Resistance",Amount:1.0,Operation:0,UUIDLeast:894654,UUIDMost:2872}]}},{Count:1,id:diamond_leggings,tag:{display:{Name:"Ice Greaves"},ench:[{id:3,lvl:5}]}},{Count:1,id:diamond_chestplate,tag:{display:{Name:"Ice Armor"},ench:[{id:0,lvl:1},{id:4,lvl:5}]}},{Count:1,id:ice,tag:{display:{Name:"Enchanted Ice Block"},ench:[{id:5,lvl:10},{id:0,lvl:1}]}}],CustomName:"Ice Guardian",Health:50.0f,Attributes:[{Name:generic.movementSpeed,Base:0.3}],HandDropChances:[1.0F,0.0F],ArmorDropChances:[0.1F,0.1F,0.1F,1.0F],ActiveEffects:[{Id:5,Amplifier:1,Duration:999999}],Silent:1,PersistenceRequired:1}:@


layer
0,0,0,0,0,0,0,0,1,1,1,1,1,1,1,0,0,0,0,0,0,0,0
0,0,0,0,0,0,1,1,1,1,4,5,4,1,1,1,1,0,0,0,0,0,0
0,0,0,0,1,1,1,1,1,1,5,4,5,1,1,1,1,1,1,0,0,0,0
0,0,0,1,1,1,1,1,1,5,0,0,0,0,1,1,1,1,1,1,0,0,0
0,0,1,1,1,1,1,0,7,6,0,0,0,0,0,0,1,1,1,1,1,0,0
0,0,1,1,1,1,0,0,0,0,0,0,0,0,0,0,0,1,1,1,1,0,0
0,1,1,1,1,0,0,4,5,0,0,0,0,0,5,4,0,0,1,1,1,1,0
0,1,1,1,0,0,4,8,9,5,0,0,0,5,9,8,4,0,0,1,1,1,0
1,1,1,1,0,0,5,9,10,4,0,0,0,4,10,9,5,0,7,1,1,1,1
1,1,1,0,0,0,0,5,4,0,0,0,0,0,4,5,0,0,6,5,1,1,1
1,4,5,0,0,0,0,0,0,0,5,4,5,0,0,0,0,0,0,0,5,4,1
1,5,4,0,0,0,0,0,0,0,4,8,4,0,0,0,0,0,0,0,4,5,1
1,4,5,0,0,0,0,0,0,0,5,4,5,0,0,0,0,0,0,0,5,4,1
1,1,1,5,6,0,0,5,4,0,0,0,0,0,4,5,0,0,0,0,1,1,1
1,1,1,1,7,0,5,9,10,4,0,0,0,4,10,9,5,0,0,1,1,1,1
0,1,1,1,0,0,4,8,9,5,0,0,0,5,9,8,4,0,0,1,1,1,0
0,1,1,1,1,0,0,4,5,0,0,0,0,0,5,4,0,0,1,1,1,1,0
0,0,1,1,1,1,0,0,0,0,0,0,0,0,0,0,0,1,1,1,1,0,0
0,0,1,1,1,1,1,0,0,0,0,0,0,6,7,0,1,1,1,1,1,0,0
0,0,0,1,1,1,1,1,1,0,0,0,0,5,1,1,1,1,1,1,0,0,0
0,0,0,0,1,1,1,1,1,1,5,4,5,1,1,1,1,1,1,0,0,0,0
0,0,0,0,0,0,1,1,1,1,4,5,4,1,1,1,1,0,0,0,0,0,0
0,0,0,0,0,0,0,0,1,1,1,1,1,1,1,0,0,0,0,0,0,0,0
endlayer

layer
0,0,0,0,0,0,0,0,0,11,11,11,11,11,0,0,0,0,0,0,0,0,0
0,0,0,0,0,0,0,0,0,1,0,0,0,1,0,0,0,0,0,0,0,0,0
0,0,0,0,0,0,0,0,1,1,0,0,0,1,1,0,0,0,0,0,0,0,0
0,0,0,0,0,0,1,1,1,0,0,0,0,0,1,1,1,0,0,0,0,0,0
0,0,0,0,1,1,1,6,5,0,0,0,0,0,0,0,1,1,1,0,0,0,0
0,0,0,0,1,1,0,7,0,0,0,0,0,0,0,0,0,1,1,0,0,0,0
0,0,0,1,1,0,0,0,0,0,0,0,0,0,0,0,0,0,1,1,0,0,0
0,0,0,1,0,0,0,8,0,0,0,0,0,0,0,8,0,7,6,1,0,0,0
0,0,1,1,0,0,0,0,0,0,0,0,0,0,0,0,0,0,5,1,1,0,0
11,1,1,0,0,0,0,0,0,0,0,0,0,0,0,0,0,0,0,0,1,1,11
11,0,0,0,0,0,0,0,0,0,0,0,0,0,0,0,0,0,0,0,0,0,11
11,0,0,0,0,0,0,0,0,0,0,0,0,0,0,0,0,0,0,0,0,0,11
11,0,0,0,0,0,0,0,0,0,0,0,0,0,0,0,0,0,0,0,0,0,11
11,1,1,0,0,0,0,0,0,0,0,0,0,0,0,0,0,0,0,0,1,1,11
0,0,1,1,5,0,0,0,0,0,0,0,0,0,0,0,0,0,0,1,1,0,0
0,0,0,1,6,7,0,8,0,0,0,0,0,0,0,8,0,0,0,1,0,0,0
0,0,0,1,1,0,0,0,0,0,0,0,0,0,0,0,0,0,1,1,0,0,0
0,0,0,0,1,1,0,0,0,0,0,0,0,0,0,7,0,1,1,0,0,0,0
0,0,0,0,1,1,1,0,0,0,0,0,0,0,5,6,1,1,1,0,0,0,0
0,0,0,0,0,0,1,1,1,0,0,0,0,0,1,1,1,0,0,0,0,0,0
0,0,0,0,0,0,0,0,1,1,0,0,0,1,1,0,0,0,0,0,0,0,0
0,0,0,0,0,0,0,0,0,1,0,0,0,1,0,0,0,0,0,0,0,0,0
0,0,0,0,0,0,0,0,0,11,11,11,11,11,0,0,0,0,0,0,0,0,0
endlayer

layer
0,0,0,0,0,0,0,0,0,11,0,0,0,11,0,0,0,0,0,0,0,0,0
0,0,0,0,0,0,0,0,0,1,0,0,0,1,0,0,0,0,0,0,0,0,0
0,0,0,0,0,0,0,0,1,1,0,0,0,1,1,0,0,0,0,0,0,0,0
0,0,0,0,0,0,1,1,1,0,0,0,0,0,1,1,1,0,0,0,0,0,0
0,0,0,0,1,1,1,0,0,0,0,0,0,0,0,12,1,1,1,0,0,0,0
0,0,0,0,1,1,6,5,0,0,0,0,0,0,0,0,0,1,1,0,0,0,0
0,0,0,1,1,0,7,0,0,0,0,0,0,0,0,0,7,6,1,1,0,0,0
0,0,0,1,12,0,0,8,0,0,0,0,0,0,0,8,0,5,0,1,0,0,0
0,0,1,1,0,0,0,0,0,0,0,0,0,0,0,0,0,0,0,1,1,0,0
11,1,1,0,0,0,0,0,0,0,0,0,0,0,0,0,0,0,0,0,1,1,11
0,0,0,0,0,0,0,0,0,0,0,0,0,0,0,0,0,0,0,0,0,0,0
0,0,0,0,0,0,0,0,0,0,0,0,0,0,0,0,0,0,0,0,0,0,0
0,0,0,0,0,0,0,0,0,0,0,0,0,0,0,0,0,0,0,0,0,0,0
11,1,1,0,0,0,0,0,0,0,0,0,0,0,0,0,0,0,0,0,1,1,11
0,0,1,1,0,0,0,0,0,0,0,0,0,0,0,0,0,0,0,1,1,0,0
0,0,0,1,0,5,0,8,0,0,0,0,0,0,0,8,0,0,12,1,0,0,0
0,0,0,1,1,6,7,0,0,0,0,0,0,0,0,0,7,0,1,1,0,0,0
0,0,0,0,1,1,0,0,0,0,0,0,0,0,0,5,6,1,1,0,0,0,0
0,0,0,0,1,1,1,12,0,0,0,0,0,0,0,0,1,1,1,0,0,0,0
0,0,0,0,0,0,1,1,1,0,0,0,0,0,1,1,1,0,0,0,0,0,0
0,0,0,0,0,0,0,0,1,1,0,0,0,1,1,0,0,0,0,0,0,0,0
0,0,0,0,0,0,0,0,0,1,0,0,0,1,0,0,0,0,0,0,0,0,0
0,0,0,0,0,0,0,0,0,11,0,0,0,11,0,0,0,0,0,0,0,0,0
endlayer

layer
0,0,0,0,0,0,0,0,0,13,0,0,0,13,0,0,0,0,0,0,0,0,0
0,0,0,0,0,0,0,0,0,1,0,0,0,1,0,0,0,0,0,0,0,0,0
0,0,0,0,0,0,0,0,1,1,0,0,0,1,1,0,0,0,0,0,0,0,0
0,0,0,0,0,0,1,1,1,0,0,0,0,0,1,1,1,0,0,0,0,0,0
0,0,0,0,1,1,1,0,0,0,0,0,0,0,0,13,1,1,1,0,0,0,0
0,0,0,0,1,1,0,0,0,0,0,0,0,0,0,7,6,1,1,0,0,0,0
0,0,0,1,1,6,5,0,0,0,0,0,0,0,0,0,5,0,1,1,0,0,0
0,0,0,1,13,7,0,8,0,0,0,0,0,0,0,8,0,0,0,1,0,0,0
0,0,1,1,0,0,0,0,0,0,0,0,0,0,0,0,0,0,0,1,1,0,0
13,1,1,0,0,0,0,0,0,0,0,0,0,0,0,0,0,0,0,0,1,1,13
0,0,0,0,0,0,0,0,0,0,0,0,0,0,0,0,0,0,0,0,0,0,0
0,0,0,0,0,0,0,0,0,0,0,0,0,0,0,0,0,0,0,0,0,0,0
0,0,0,0,0,0,0,0,0,0,0,0,0,0,0,0,0,0,0,0,0,0,0
13,1,1,0,0,0,0,0,0,0,0,0,0,0,0,0,0,0,0,0,1,1,13
0,0,1,1,0,0,0,0,0,0,0,0,0,0,0,0,0,0,0,1,1,0,0
0,0,0,1,0,0,0,8,0,0,0,0,0,0,0,8,0,7,13,1,0,0,0
0,0,0,1,1,0,5,0,0,0,0,0,0,0,0,0,5,6,1,1,0,0,0
0,0,0,0,1,1,6,7,0,0,0,0,0,0,0,0,0,1,1,0,0,0,0
0,0,0,0,1,1,1,13,0,0,0,0,0,0,0,0,1,1,1,0,0,0,0
0,0,0,0,0,0,1,1,1,0,0,0,0,0,1,1,1,0,0,0,0,0,0
0,0,0,0,0,0,0,0,1,1,0,0,0,1,1,0,0,0,0,0,0,0,0
0,0,0,0,0,0,0,0,0,1,0,0,0,1,0,0,0,0,0,0,0,0,0
0,0,0,0,0,0,0,0,0,13,0,0,0,13,0,0,0,0,0,0,0,0,0
endlayer

layer
0,0,0,0,0,0,0,0,0,0,0,0,0,0,0,0,0,0,0,0,0,0,0
0,0,0,0,0,0,0,0,0,1,0,0,0,1,0,0,0,0,0,0,0,0,0
0,0,0,0,0,0,0,0,1,1,0,0,0,1,1,0,0,0,0,0,0,0,0
0,0,0,0,0,0,1,1,1,0,0,0,0,0,1,1,1,0,0,0,0,0,0
0,0,0,0,1,1,1,0,0,0,0,14,0,0,7,6,1,1,1,0,0,0,0
0,0,0,0,1,1,0,0,0,0,0,0,0,0,0,5,0,1,1,0,0,0,0
0,0,0,1,1,0,0,0,0,0,0,0,0,0,0,0,0,0,1,1,0,0,0
0,0,0,1,6,5,0,8,0,0,0,0,0,0,0,8,0,0,0,1,0,0,0
0,0,1,1,7,0,0,0,0,0,0,0,0,0,0,0,0,0,0,1,1,0,0
0,1,1,0,0,0,0,0,0,14,0,0,0,14,0,0,0,0,0,0,1,1,0
0,0,0,0,0,0,0,0,0,0,0,0,0,0,0,0,0,0,0,0,0,0,0
0,0,0,0,14,0,0,0,0,0,0,14,0,0,0,0,0,0,14,0,0,0,0
0,0,0,0,0,0,0,0,0,0,0,0,0,0,0,0,0,0,0,0,0,0,0
0,1,1,0,0,0,0,0,0,14,0,0,0,14,0,0,0,0,0,0,1,1,0
0,0,1,1,0,0,0,0,0,0,0,0,0,0,0,0,0,0,7,1,1,0,0
0,0,0,1,0,0,0,8,0,0,0,0,0,0,0,8,0,5,6,1,0,0,0
0,0,0,1,1,0,0,0,0,0,0,0,0,0,0,0,0,0,1,1,0,0,0
0,0,0,0,1,1,0,5,0,0,0,0,0,0,0,0,0,1,1,0,0,0,0
0,0,0,0,1,1,1,6,7,0,0,14,0,0,0,0,1,1,1,0,0,0,0
0,0,0,0,0,0,1,1,1,0,0,0,0,0,1,1,1,0,0,0,0,0,0
0,0,0,0,0,0,0,0,1,1,0,0,0,1,1,0,0,0,0,0,0,0,0
0,0,0,0,0,0,0,0,0,1,0,0,0,1,0,0,0,0,0,0,0,0,0
0,0,0,0,0,0,0,0,0,0,0,0,0,0,0,0,0,0,0,0,0,0,0
endlayer

layer
0,0,0,0,0,0,0,0,0,0,0,0,0,0,0,0,0,0,0,0,0,0,0
0,0,0,0,0,0,0,0,0,1,1,0,1,1,0,0,0,0,0,0,0,0,0
0,0,0,0,0,0,0,0,1,1,0,0,0,1,1,0,0,0,0,0,0,0,0
0,0,0,0,0,0,1,1,1,0,0,14,0,7,1,1,1,0,0,0,0,0,0
0,0,0,0,1,1,1,0,0,0,0,14,0,6,5,0,1,1,1,0,0,0,0
0,0,0,0,1,1,0,0,0,0,0,0,0,0,0,0,0,1,1,0,0,0,0
0,0,0,1,1,0,0,0,0,0,0,0,0,0,0,0,0,0,1,1,0,0,0
0,0,0,1,0,0,0,8,0,0,0,0,0,0,0,8,0,0,0,1,0,0,0
0,0,1,1,5,0,0,0,0,0,0,0,0,0,0,0,0,0,0,1,1,0,0
0,1,1,7,6,0,0,0,0,14,0,0,0,14,0,0,0,0,0,0,1,1,0
0,1,0,0,0,0,0,0,0,0,0,14,0,0,0,0,0,0,0,0,0,1,0
0,0,0,14,14,0,0,0,0,0,14,15,14,0,0,0,0,0,14,14,0,0,0
0,1,0,0,0,0,0,0,0,0,0,14,0,0,0,0,0,0,0,0,0,1,0
0,1,1,0,0,0,0,0,0,14,0,0,0,14,0,0,0,0,6,7,1,1,0
0,0,1,1,0,0,0,0,0,0,0,0,0,0,0,0,0,0,5,1,1,0,0
0,0,0,1,0,0,0,8,0,0,0,0,0,0,0,8,0,0,0,1,0,0,0
0,0,0,1,1,0,0,0,0,0,0,0,0,0,0,0,0,0,1,1,0,0,0
0,0,0,0,1,1,0,0,0,0,0,0,0,0,0,0,0,1,1,0,0,0,0
0,0,0,0,1,1,1,0,5,6,0,14,0,0,0,0,1,1,1,0,0,0,0
0,0,0,0,0,0,1,1,1,7,0,14,0,0,1,1,1,0,0,0,0,0,0
0,0,0,0,0,0,0,0,1,1,0,0,0,1,1,0,0,0,0,0,0,0,0
0,0,0,0,0,0,0,0,0,1,1,0,1,1,0,0,0,0,0,0,0,0,0
0,0,0,0,0,0,0,0,0,0,0,0,0,0,0,0,0,0,0,0,0,0,0
endlayer

layer
0,0,0,0,0,0,0,0,1,1,1,1,1,1,1,0,0,0,0,0,0,0,0
0,0,0,0,0,0,1,1,1,1,1,1,1,1,1,1,1,0,0,0,0,0,0
0,0,0,0,1,1,1,1,1,1,1,1,1,1,1,1,1,1,1,0,0,0,0
0,0,0,1,1,1,1,1,1,7,6,16,6,5,1,1,1,1,1,1,0,0,0
0,0,1,1,1,1,1,0,0,0,0,14,0,0,0,0,1,1,1,1,1,0,0
0,0,1,1,1,1,0,0,0,0,0,14,0,0,0,0,0,1,1,1,1,0,0
0,1,1,1,1,0,0,0,0,0,0,14,0,0,0,0,0,0,1,1,1,1,0
0,1,1,1,0,0,0,8,0,0,14,14,14,0,0,8,0,0,0,1,1,1,0
1,1,1,1,0,0,0,0,0,14,14,14,14,14,0,0,0,0,0,1,1,1,1
1,1,1,5,0,0,0,0,14,14,15,14,15,14,14,0,0,0,0,7,1,1,1
1,1,1,6,0,0,0,14,14,15,14,17,14,15,14,14,0,0,0,6,1,1,1
1,1,1,16,14,14,14,14,14,14,17,18,17,14,14,14,14,14,14,16,1,1,1
1,1,1,6,0,0,0,14,14,15,14,17,14,15,14,14,0,0,0,6,1,1,1
1,1,1,7,0,0,0,0,14,14,15,14,15,14,14,0,0,0,0,5,1,1,1
1,1,1,1,0,0,0,0,0,14,14,14,14,14,0,0,0,0,0,1,1,1,1
0,1,1,1,0,0,0,8,0,0,14,14,14,0,0,8,0,0,0,1,1,1,0
0,1,1,1,1,0,0,0,0,0,0,14,0,0,0,0,0,0,1,1,1,1,0
0,0,1,1,1,1,0,0,0,0,0,14,0,0,0,0,0,1,1,1,1,0,0
0,0,1,1,1,1,1,0,0,0,0,14,0,0,0,0,1,1,1,1,1,0,0
0,0,0,1,1,1,1,1,1,5,6,16,6,7,1,1,1,1,1,1,0,0,0
0,0,0,0,1,1,1,1,1,1,1,1,1,1,1,1,1,1,1,0,0,0,0
0,0,0,0,0,0,1,1,1,1,1,1,1,1,1,1,1,0,0,0,0,0,0
0,0,0,0,0,0,0,0,1,1,1,1,1,1,1,0,0,0,0,0,0,0,0
endlayer

layer
0,0,0,0,0,0,0,0,1,1,1,1,1,1,1,0,0,0,0,0,0,0,0
0,0,0,0,0,0,1,1,1,1,4,5,4,1,1,1,1,0,0,0,0,0,0
0,0,0,0,1,1,1,1,1,1,5,4,5,1,1,1,1,1,1,0,0,0,0
0,0,0,1,1,1,1,1,1,5,0,0,0,0,1,1,1,1,1,1,0,0,0
0,0,1,1,1,1,1,0,7,6,0,0,0,0,0,0,1,1,1,1,1,0,0
0,0,1,1,1,1,0,0,0,0,0,0,0,0,0,0,0,1,1,1,1,0,0
0,1,1,1,1,0,0,0,0,0,0,0,0,0,0,0,0,0,1,1,1,1,0
0,1,1,1,0,0,0,8,0,0,0,0,0,0,0,8,0,0,0,1,1,1,0
1,1,1,1,0,0,0,0,0,0,0,0,0,0,0,0,0,0,7,1,1,1,1
1,1,1,0,0,0,0,0,0,0,15,0,15,0,0,0,0,0,6,5,1,1,1
1,4,5,0,0,0,0,0,0,15,0,17,0,15,0,0,0,0,0,0,5,4,1
1,5,4,0,0,0,0,0,0,0,17,8,17,0,0,0,0,0,0,0,4,5,1
1,4,5,0,0,0,0,0,0,15,0,17,0,15,0,0,0,0,0,0,5,4,1
1,1,1,5,6,0,0,0,0,0,15,0,15,0,0,0,0,0,0,0,1,1,1
1,1,1,1,7,0,0,0,0,0,0,0,0,0,0,0,0,0,0,1,1,1,1
0,1,1,1,0,0,0,8,0,0,0,0,0,0,0,8,0,0,0,1,1,1,0
0,1,1,1,1,0,0,0,0,0,0,0,0,0,0,0,0,0,1,1,1,1,0
0,0,1,1,1,1,0,0,0,0,0,0,0,0,0,0,0,1,1,1,1,0,0
0,0,1,1,1,1,1,0,0,0,0,0,0,6,7,0,1,1,1,1,1,0,0
0,0,0,1,1,1,1,1,1,0,0,0,0,5,1,1,1,1,1,1,0,0,0
0,0,0,0,1,1,1,1,1,1,5,4,5,1,1,1,1,1,1,0,0,0,0
0,0,0,0,0,0,1,1,1,1,4,5,4,1,1,1,1,0,0,0,0,0,0
0,0,0,0,0,0,0,0,1,1,1,1,1,1,1,0,0,0,0,0,0,0,0
endlayer

layer
0,0,0,0,0,0,0,0,0,11,11,11,11,11,0,0,0,0,0,0,0,0,0
0,0,0,0,0,0,0,0,0,1,0,0,0,1,0,0,0,0,0,0,0,0,0
0,0,0,0,0,0,0,0,1,1,0,0,0,1,1,0,0,0,0,0,0,0,0
0,0,0,0,0,0,1,1,1,0,0,0,0,0,1,1,1,0,0,0,0,0,0
0,0,0,0,1,1,1,6,5,0,0,0,0,0,0,0,1,1,1,0,0,0,0
0,0,0,0,1,1,0,7,0,0,0,0,0,0,0,0,0,1,1,0,0,0,0
0,0,0,1,1,0,0,0,0,0,0,0,0,0,0,0,0,0,1,1,0,0,0
0,0,0,1,0,0,0,8,0,0,0,0,0,0,0,8,0,7,6,1,0,0,0
0,0,1,1,0,0,0,0,0,0,0,0,0,0,0,0,0,0,5,1,1,0,0
11,1,1,0,0,0,0,0,0,0,0,0,0,0,0,0,0,0,0,0,1,1,11
11,0,0,0,0,0,0,0,0,0,0,17,0,0,0,0,0,0,0,0,0,0,11
11,0,0,0,0,0,0,0,0,0,17,8,17,0,0,0,0,0,0,0,0,0,11
11,0,0,0,0,0,0,0,0,0,0,17,0,0,0,0,0,0,0,0,0,0,11
11,1,1,0,0,0,0,0,0,0,0,0,0,0,0,0,0,0,0,0,1,1,11
0,0,1,1,5,0,0,0,0,0,0,0,0,0,0,0,0,0,0,1,1,0,0
0,0,0,1,6,7,0,8,0,0,0,0,0,0,0,8,0,0,0,1,0,0,0
0,0,0,1,1,0,0,0,0,0,0,0,0,0,0,0,0,0,1,1,0,0,0
0,0,0,0,1,1,0,0,0,0,0,0,0,0,0,7,0,1,1,0,0,0,0
0,0,0,0,1,1,1,0,0,0,0,0,0,0,5,6,1,1,1,0,0,0,0
0,0,0,0,0,0,1,1,1,0,0,0,0,0,1,1,1,0,0,0,0,0,0
0,0,0,0,0,0,0,0,1,1,0,0,0,1,1,0,0,0,0,0,0,0,0
0,0,0,0,0,0,0,0,0,1,0,0,0,1,0,0,0,0,0,0,0,0,0
0,0,0,0,0,0,0,0,0,11,11,11,11,11,0,0,0,0,0,0,0,0,0
endlayer

layer
0,0,0,0,0,0,0,0,0,11,0,0,0,11,0,0,0,0,0,0,0,0,0
0,0,0,0,0,0,0,0,0,1,0,0,0,1,0,0,0,0,0,0,0,0,0
0,0,0,0,0,0,0,0,1,1,0,0,0,1,1,0,0,0,0,0,0,0,0
0,0,0,0,0,0,1,1,1,0,0,0,0,0,1,1,1,0,0,0,0,0,0
0,0,0,0,1,1,1,0,0,0,0,0,0,0,0,11,1,1,1,0,0,0,0
0,0,0,0,1,1,6,5,0,0,0,0,0,0,0,0,0,1,1,0,0,0,0
0,0,0,1,1,0,7,0,0,0,0,0,0,0,0,0,7,6,1,1,0,0,0
0,0,0,1,11,0,0,8,0,0,0,0,0,0,0,8,0,5,0,1,0,0,0
0,0,1,1,0,0,0,0,0,0,0,0,0,0,0,0,0,0,0,1,1,0,0
11,1,1,0,0,0,0,0,0,0,0,0,0,0,0,0,0,0,0,0,1,1,11
0,0,0,0,0,0,0,0,0,0,0,9,0,0,0,0,0,0,0,0,0,0,0
0,0,0,0,0,0,0,0,0,0,9,19,9,0,0,0,0,0,0,0,0,0,0
0,0,0,0,0,0,0,0,0,0,0,9,0,0,0,0,0,0,0,0,0,0,0
11,1,1,0,0,0,0,0,0,0,0,0,0,0,0,0,0,0,0,0,1,1,11
0,0,1,1,0,0,0,0,0,0,0,0,0,0,0,0,0,0,0,1,1,0,0
0,0,0,1,0,5,0,8,0,0,0,0,0,0,0,8,0,0,11,1,0,0,0
0,0,0,1,1,6,7,0,0,0,0,0,0,0,0,0,7,0,1,1,0,0,0
0,0,0,0,1,1,0,0,0,0,0,0,0,0,0,5,6,1,1,0,0,0,0
0,0,0,0,1,1,1,11,0,0,0,0,0,0,0,0,1,1,1,0,0,0,0
0,0,0,0,0,0,1,1,1,0,0,0,0,0,1,1,1,0,0,0,0,0,0
0,0,0,0,0,0,0,0,1,1,0,0,0,1,1,0,0,0,0,0,0,0,0
0,0,0,0,0,0,0,0,0,1,0,0,0,1,0,0,0,0,0,0,0,0,0
0,0,0,0,0,0,0,0,0,11,0,0,0,11,0,0,0,0,0,0,0,0,0
endlayer

layer
0,0,0,0,0,0,0,0,0,13,0,0,0,13,0,0,0,0,0,0,0,0,0
0,0,0,0,0,0,0,0,0,1,0,0,0,1,0,0,0,0,0,0,0,0,0
0,0,0,0,0,0,0,0,1,1,0,0,0,1,1,0,0,0,0,0,0,0,0
0,0,0,0,0,0,1,1,1,0,0,0,0,0,1,1,1,0,0,0,0,0,0
0,0,0,0,1,1,1,0,0,0,0,0,0,0,0,13,1,1,1,0,0,0,0
0,0,0,0,1,1,0,0,0,0,0,0,0,0,0,7,6,1,1,0,0,0,0
0,0,0,1,1,6,5,0,0,0,0,0,0,0,0,0,5,0,1,1,0,0,0
0,0,0,1,13,7,0,8,0,0,0,0,0,0,0,8,0,0,0,1,0,0,0
0,0,1,1,0,0,0,0,0,0,0,0,0,0,0,0,0,0,0,1,1,0,0
13,1,1,0,0,0,0,0,0,14,0,11,0,14,0,0,0,0,0,0,1,1,13
0,0,0,0,0,0,0,0,0,0,11,11,11,0,0,0,0,0,0,0,0,0,0
0,0,0,0,0,0,0,0,0,11,11,20,11,11,0,0,0,0,0,0,0,0,0
0,0,0,0,0,0,0,0,0,0,11,11,11,0,0,0,0,0,0,0,0,0,0
13,1,1,0,0,0,0,0,0,14,0,11,0,14,0,0,0,0,0,0,1,1,13
0,0,1,1,0,0,0,0,0,0,0,0,0,0,0,0,0,0,0,1,1,0,0
0,0,0,1,0,0,0,8,0,0,0,0,0,0,0,8,0,7,13,1,0,0,0
0,0,0,1,1,0,5,0,0,0,0,0,0,0,0,0,5,6,1,1,0,0,0
0,0,0,0,1,1,6,7,0,0,0,0,0,0,0,0,0,1,1,0,0,0,0
0,0,0,0,1,1,1,13,0,0,0,0,0,0,0,0,1,1,1,0,0,0,0
0,0,0,0,0,0,1,1,1,0,0,0,0,0,1,1,1,0,0,0,0,0,0
0,0,0,0,0,0,0,0,1,1,0,0,0,1,1,0,0,0,0,0,0,0,0
0,0,0,0,0,0,0,0,0,1,0,0,0,1,0,0,0,0,0,0,0,0,0
0,0,0,0,0,0,0,0,0,13,0,0,0,13,0,0,0,0,0,0,0,0,0
endlayer

layer
0,0,0,0,0,0,0,0,0,0,0,0,0,0,0,0,0,0,0,0,0,0,0
0,0,0,0,0,0,0,0,0,1,0,0,0,1,0,0,0,0,0,0,0,0,0
0,0,0,0,0,0,0,0,1,1,0,0,0,1,1,0,0,0,0,0,0,0,0
0,0,0,0,0,0,1,1,1,0,0,0,0,0,1,1,1,0,0,0,0,0,0
0,0,0,0,1,1,1,0,0,0,0,0,0,0,7,6,1,1,1,0,0,0,0
0,0,0,0,1,1,0,0,0,0,0,0,0,0,0,5,0,1,1,0,0,0,0
0,0,0,1,1,0,0,0,0,0,14,0,14,0,0,0,0,0,1,1,0,0,0
0,0,0,1,6,5,0,8,0,0,0,0,0,0,0,8,0,0,0,1,0,0,0
0,0,1,1,7,0,0,0,0,0,0,0,0,0,0,0,0,0,0,1,1,0,0
0,1,1,0,0,0,0,0,0,15,0,13,0,15,0,0,0,0,0,0,1,1,0
0,0,0,0,0,0,14,0,0,0,13,11,13,0,0,0,14,0,0,0,0,0,0
0,0,0,0,0,0,0,0,0,13,11,11,11,13,0,0,0,0,0,0,0,0,0
0,0,0,0,0,0,14,0,0,0,13,11,13,0,0,0,14,0,0,0,0,0,0
0,1,1,0,0,0,0,0,0,15,0,13,0,15,0,0,0,0,0,0,1,1,0
0,0,1,1,0,0,0,0,0,0,0,0,0,0,0,0,0,0,7,1,1,0,0
0,0,0,1,0,0,0,8,0,0,0,0,0,0,0,8,0,5,6,1,0,0,0
0,0,0,1,1,0,0,0,0,0,14,0,14,0,0,0,0,0,1,1,0,0,0
0,0,0,0,1,1,0,5,0,0,0,0,0,0,0,0,0,1,1,0,0,0,0
0,0,0,0,1,1,1,6,7,0,0,0,0,0,0,0,1,1,1,0,0,0,0
0,0,0,0,0,0,1,1,1,0,0,0,0,0,1,1,1,0,0,0,0,0,0
0,0,0,0,0,0,0,0,1,1,0,0,0,1,1,0,0,0,0,0,0,0,0
0,0,0,0,0,0,0,0,0,1,0,0,0,1,0,0,0,0,0,0,0,0,0
0,0,0,0,0,0,0,0,0,0,0,0,0,0,0,0,0,0,0,0,0,0,0
endlayer

layer
0,0,0,0,0,0,0,0,0,0,0,0,0,0,0,0,0,0,0,0,0,0,0
0,0,0,0,0,0,0,0,0,1,1,0,1,1,0,0,0,0,0,0,0,0,0
0,0,0,0,0,0,0,0,1,1,0,0,0,1,1,0,0,0,0,0,0,0,0
0,0,0,0,0,0,1,1,1,0,0,14,0,7,1,1,1,0,0,0,0,0,0
0,0,0,0,1,1,1,0,0,0,0,0,0,6,5,0,1,1,1,0,0,0,0
0,0,0,0,1,1,0,0,0,0,0,14,0,0,0,0,0,1,1,0,0,0,0
0,0,0,1,1,0,0,15,0,0,14,0,14,0,0,15,0,0,1,1,0,0,0
0,0,0,1,0,0,15,19,15,0,0,14,0,0,15,19,15,0,0,1,0,0,0
0,0,1,1,5,0,0,15,0,0,0,15,0,0,0,15,0,0,0,1,1,0,0
0,1,1,7,6,0,0,0,0,15,0,0,0,15,0,0,0,0,0,0,1,1,0
0,1,0,0,0,0,14,0,0,0,0,0,0,0,0,0,14,0,0,0,0,1,0
0,0,0,14,0,14,0,14,15,0,0,11,0,0,15,14,0,14,0,14,0,0,0
0,1,0,0,0,0,14,0,0,0,0,0,0,0,0,0,14,0,0,0,0,1,0
0,1,1,0,0,0,0,0,0,15,0,0,0,15,0,0,0,0,6,7,1,1,0
0,0,1,1,0,0,0,15,0,0,0,15,0,0,0,15,0,0,5,1,1,0,0
0,0,0,1,0,0,15,19,15,0,0,14,0,0,15,19,15,0,0,1,0,0,0
0,0,0,1,1,0,0,15,0,0,14,0,14,0,0,15,0,0,1,1,0,0,0
0,0,0,0,1,1,0,0,0,0,0,14,0,0,0,0,0,1,1,0,0,0,0
0,0,0,0,1,1,1,0,5,6,0,0,0,0,0,0,1,1,1,0,0,0,0
0,0,0,0,0,0,1,1,1,7,0,14,0,0,1,1,1,0,0,0,0,0,0
0,0,0,0,0,0,0,0,1,1,0,0,0,1,1,0,0,0,0,0,0,0,0
0,0,0,0,0,0,0,0,0,1,1,0,1,1,0,0,0,0,0,0,0,0,0
0,0,0,0,0,0,0,0,0,0,0,0,0,0,0,0,0,0,0,0,0,0,0
endlayer

layer
0,0,0,0,0,0,0,0,1,1,1,1,1,1,1,0,0,0,0,0,0,0,0
0,0,0,0,0,0,1,1,1,1,1,1,1,1,1,1,1,0,0,0,0,0,0
0,0,0,0,1,1,1,1,1,1,1,1,1,1,1,1,1,1,1,0,0,0,0
0,0,0,1,1,1,1,1,1,3,2,3,2,5,1,1,1,1,1,1,0,0,0
0,0,1,1,1,1,1,2,3,2,3,2,3,0,0,0,1,1,1,1,1,0,0
0,0,1,1,1,1,0,3,2,3,2,3,2,3,2,0,0,1,1,1,1,0,0
0,1,1,1,1,0,0,2,3,2,3,2,3,2,3,2,3,2,1,1,1,1,0
0,1,1,1,0,0,2,3,2,3,2,3,2,3,2,3,2,3,2,1,1,1,0
1,1,1,1,0,2,3,2,3,2,3,2,3,2,3,2,3,2,3,1,1,1,1
1,1,1,5,0,3,2,3,2,3,2,3,2,3,2,3,2,3,2,3,1,1,1
1,1,1,2,3,2,3,2,3,2,3,2,3,2,3,2,3,2,3,2,1,1,1
1,1,1,3,2,3,2,3,2,3,2,3,2,3,2,3,2,3,2,3,1,1,1
1,1,1,2,3,2,3,2,3,2,3,2,3,2,3,2,3,2,3,2,1,1,1
1,1,1,3,2,3,2,3,2,3,2,3,2,3,2,3,2,3,0,5,1,1,1
1,1,1,1,3,2,3,2,3,2,3,2,3,2,3,2,3,2,0,1,1,1,1
0,1,1,1,2,3,2,3,2,3,2,3,2,3,2,3,2,0,0,1,1,1,0
0,1,1,1,1,0,0,2,3,2,3,2,3,2,3,2,0,0,1,1,1,1,0
0,0,1,1,1,1,0,0,2,3,2,3,2,3,2,3,0,1,1,1,1,0,0
0,0,1,1,1,1,1,0,0,0,3,2,3,2,3,2,1,1,1,1,1,0,0
0,0,0,1,1,1,1,1,1,5,2,3,2,3,1,1,1,1,1,1,0,0,0
0,0,0,0,1,1,1,1,1,1,1,1,1,1,1,1,1,1,1,0,0,0,0
0,0,0,0,0,0,1,1,1,1,1,1,1,1,1,1,1,0,0,0,0,0,0
0,0,0,0,0,0,0,0,1,1,1,1,1,1,1,0,0,0,0,0,0,0,0
endlayer

layer
0,0,0,0,0,0,0,0,0,0,0,0,0,0,0,0,0,0,0,0,0,0,0
0,0,0,0,0,0,0,0,0,1,1,1,1,1,0,0,0,0,0,0,0,0,0
0,0,0,0,0,0,0,0,1,0,0,21,0,0,1,0,0,0,0,0,0,0,0
0,0,0,0,0,0,1,1,0,0,0,0,0,0,0,1,1,0,0,0,0,0,0
0,0,0,0,1,1,0,0,0,0,0,0,0,0,0,0,0,1,1,0,0,0,0
0,0,0,0,1,0,0,0,0,0,0,5,0,0,0,0,0,0,1,0,0,0,0
0,0,0,1,0,0,0,0,0,0,5,19,5,0,0,0,0,0,0,1,0,0,0
0,0,0,1,0,0,0,0,0,0,0,5,0,0,0,0,0,0,0,1,0,0,0
0,0,1,0,0,0,0,0,0,0,0,0,0,0,0,0,0,0,0,0,1,0,0
0,1,0,0,0,0,0,0,0,0,0,0,0,0,0,0,0,0,0,0,0,1,0
0,1,0,0,0,0,5,0,0,0,5,22,5,0,0,0,5,0,0,0,0,1,0
0,1,24,0,0,5,19,5,0,0,23,25,24,0,0,5,19,5,0,0,23,1,0
0,1,0,0,0,0,5,0,0,0,5,21,5,0,0,0,5,0,0,0,0,1,0
0,1,0,0,0,0,0,0,0,0,0,0,0,0,0,0,0,0,0,0,0,1,0
0,0,1,0,0,0,0,0,0,0,0,0,0,0,0,0,0,0,0,0,1,0,0
0,0,0,1,0,0,0,0,0,0,0,5,0,0,0,0,0,0,0,1,0,0,0
0,0,0,1,0,0,0,0,0,0,5,19,5,0,0,0,0,0,0,1,0,0,0
0,0,0,0,1,0,0,0,0,0,0,5,0,0,0,0,0,0,1,0,0,0,0
0,0,0,0,1,1,0,0,0,0,0,0,0,0,0,0,0,1,1,0,0,0,0
0,0,0,0,0,0,1,1,0,0,0,0,0,0,0,1,1,0,0,0,0,0,0
0,0,0,0,0,0,0,0,1,0,0,26,0,0,1,0,0,0,0,0,0,0,0
0,0,0,0,0,0,0,0,0,1,1,1,1,1,0,0,0,0,0,0,0,0,0
0,0,0,0,0,0,0,0,0,0,0,0,0,0,0,0,0,0,0,0,0,0,0
endlayer

layer
0,0,0,0,0,0,0,0,0,0,0,0,0,0,0,0,0,0,0,0,0,0,0
0,0,0,0,0,0,0,0,0,1,0,0,0,1,0,0,0,0,0,0,0,0,0
0,0,0,0,0,0,0,0,0,0,0,0,0,0,0,0,0,0,0,0,0,0,0
0,0,0,0,0,0,1,0,0,0,0,0,0,0,0,0,1,0,0,0,0,0,0
0,0,0,0,1,0,0,0,0,0,0,0,0,0,0,0,0,0,1,0,0,0,0
0,0,0,0,0,0,0,0,0,0,0,0,0,0,0,0,0,0,0,0,0,0,0
0,0,0,1,0,0,0,0,0,0,0,0,0,0,0,0,0,0,0,1,0,0,0
0,0,0,0,0,0,0,0,0,0,0,0,0,0,0,0,0,0,0,0,0,0,0
0,0,0,0,0,0,0,0,0,0,0,0,0,0,0,0,0,0,0,0,0,0,0
0,1,0,0,0,0,0,0,0,0,0,0,0,0,0,0,0,0,0,0,0,1,0
0,0,0,0,0,0,0,0,0,0,0,0,0,0,0,0,0,0,0,0,0,0,0
0,0,0,0,0,0,0,0,0,0,0,27,0,0,0,0,0,0,0,0,0,0,0
0,0,0,0,0,0,0,0,0,0,0,0,0,0,0,0,0,0,0,0,0,0,0
0,1,0,0,0,0,0,0,0,0,0,0,0,0,0,0,0,0,0,0,0,1,0
0,0,0,0,0,0,0,0,0,0,0,0,0,0,0,0,0,0,0,0,0,0,0
0,0,0,0,0,0,0,0,0,0,0,0,0,0,0,0,0,0,0,0,0,0,0
0,0,0,1,0,0,0,0,0,0,0,0,0,0,0,0,0,0,0,1,0,0,0
0,0,0,0,0,0,0,0,0,0,0,0,0,0,0,0,0,0,0,0,0,0,0
0,0,0,0,1,0,0,0,0,0,0,0,0,0,0,0,0,0,1,0,0,0,0
0,0,0,0,0,0,1,0,0,0,0,0,0,0,0,0,1,0,0,0,0,0,0
0,0,0,0,0,0,0,0,0,0,0,0,0,0,0,0,0,0,0,0,0,0,0
0,0,0,0,0,0,0,0,0,1,0,0,0,1,0,0,0,0,0,0,0,0,0
0,0,0,0,0,0,0,0,0,0,0,0,0,0,0,0,0,0,0,0,0,0,0
endlayer

