# Sky Islet
# MC 1.7.10; 4 Dec 2014
# Created by Ruins mod version 14.4 Ingame Parser
# authoring Player: Jordan_Greywolf
# Special Instructions: Place in \templateparser folder.

weight=1
embed_into_distance=8
random_height_offset=-3,3
acceptable_target_blocks=
unacceptable_target_blocks=
dimensions=21,7,7
allowable_overhang=99999
max_leveling=0
leveling_buffer=0
preserve_water=0
preserve_lava=0
preserve_plants=1

rule1=0,100,minecraft:glowstone-0
rule2=0,100,minecraft:stone-0
rule3=0,100,minecraft:dirt-0
rule4=0,100,CommandBlock:RUINSTRIGGER /testruin TPSky_Shard ~-6 ~0 ~-6:@,CommandBlock:RUINSTRIGGER /testruin TPSky_Shard ~-5 ~0 ~-8:@,CommandBlock:RUINSTRIGGER /testruin TPSky_Shard ~-10 ~0 ~-4:@
rule5=0,100,minecraft:grass-0
rule6=0,100,CommandBlock:RUINSTRIGGER /testruin TPSky_Shard ~-6 ~0 ~6:@,CommandBlock:RUINSTRIGGER /testruin TPSky_Shard ~-4 ~0 ~9:@,CommandBlock:RUINSTRIGGER /testruin TPSky_Shard ~-9 ~0 ~4:@
rule7=0,100,CommandBlock:RUINSTRIGGER /testruin TPSky_Shard ~6 ~0 ~-6:@,CommandBlock:RUINSTRIGGER /testruin TPSky_Shard ~8 ~0 ~-5:@,CommandBlock:RUINSTRIGGER /testruin TPSky_Shard ~5 ~0 ~-8:@
rule8=0,100,CommandBlock:RUINSTRIGGER /testruin TPSky_Shard ~6 ~0 ~6:@,CommandBlock:RUINSTRIGGER /testruin TPSky_Shard ~7 ~0 ~5:@,CommandBlock:RUINSTRIGGER /testruin TPSky_Shard ~5 ~0 ~9:@
rule9=0,100,minecraft:vine-8
rule10=0,100,minecraft:vine-4
rule11=0,100,minecraft:vine-1
rule12=0,100,minecraft:vine-2
rule13=0,100,CommandBlock:RUINSTRIGGER /testruin TP_TangleTree ~0 ~3 ~0:@,CommandBlock:RUINSTRIGGER /testruin TPSky_QuartzColumn ~0 ~4 ~0:@,CommandBlock:RUINSTRIGGER /setblock glowstone ~0 ~4 ~0:@,CommandBlock:RUINSTRIGGER /testruin TPSky_QuartzColumn ~0 ~1 ~0:@,CommandBlock:RUINSTRIGGER /testruin TPSky_Islet ~0 ~10 ~0:@
rule14=0,100,preserveBlock

layer
14,14,14,14,14,14,14
14,14,14,14,14,14,14
14,14,14,14,14,14,14
14,14,14,1,14,14,14
14,14,14,14,14,14,14
14,14,14,14,14,14,14
14,14,14,14,14,14,14
endlayer

layer
14,14,14,14,14,14,14
14,14,14,14,14,14,14
14,14,14,14,14,14,14
14,14,14,1,14,14,14
14,14,14,14,14,14,14
14,14,14,14,14,14,14
14,14,14,14,14,14,14
endlayer

layer
14,14,14,14,14,14,14
14,14,14,14,14,14,14
14,14,14,14,14,14,14
14,14,14,2,14,14,14
14,14,14,14,14,14,14
14,14,14,14,14,14,14
14,14,14,14,14,14,14
endlayer

layer
14,14,14,14,14,14,14
14,14,14,14,14,14,14
14,14,14,14,14,14,14
14,14,14,2,14,14,14
14,14,14,14,14,14,14
14,14,14,14,14,14,14
14,14,14,14,14,14,14
endlayer

layer
14,14,14,14,14,14,14
14,14,14,14,14,14,14
14,14,14,14,14,14,14
14,14,14,2,14,14,14
14,14,14,2,14,14,14
14,14,14,14,14,14,14
14,14,14,14,14,14,14
endlayer

layer
14,14,14,14,14,14,14
14,14,14,14,14,14,14
14,14,14,2,14,14,14
14,14,14,2,14,14,14
14,14,14,2,14,14,14
14,14,14,14,14,14,14
14,14,14,14,14,14,14
endlayer

layer
14,14,14,14,14,14,14
14,14,14,14,14,14,14
14,14,14,2,14,14,14
14,14,14,2,2,14,14
14,14,14,2,14,14,14
14,14,14,14,14,14,14
14,14,14,14,14,14,14
endlayer

layer
14,14,14,14,14,14,14
14,14,14,14,14,14,14
14,14,14,2,14,14,14
14,14,2,2,2,14,14
14,14,14,2,14,14,14
14,14,14,14,14,14,14
14,14,14,14,14,14,14
endlayer

layer
14,14,14,14,14,14,14
14,14,14,14,14,14,14
14,14,14,2,14,14,14
14,14,2,2,2,14,14
14,14,14,2,14,14,14
14,14,14,14,14,14,14
14,14,14,14,14,14,14
endlayer

layer
14,14,14,14,14,14,14
14,14,14,14,14,14,14
14,14,2,2,2,14,14
14,14,2,2,2,14,14
14,14,14,2,14,14,14
14,14,14,2,14,14,14
14,14,14,14,14,14,14
endlayer

layer
14,14,14,14,14,14,14
14,14,14,14,14,14,14
14,14,2,2,2,14,14
14,14,2,2,2,2,14
14,14,2,2,2,14,14
14,14,14,2,14,14,14
14,14,14,14,14,14,14
endlayer

layer
14,14,14,14,14,14,14
14,14,2,2,14,14,14
14,2,2,2,2,14,14
14,2,2,2,2,2,3
14,14,2,2,2,14,14
14,14,14,2,14,14,14
14,14,14,14,14,14,14
endlayer

layer
14,14,14,3,14,14,14
14,3,2,2,2,3,14
14,2,2,2,2,2,14
3,2,2,2,2,2,3
14,2,2,2,2,2,14
14,3,2,2,2,14,14
14,14,3,3,14,14,14
endlayer

layer
14,6,5,5,5,4,14
14,5,5,2,5,5,14
5,5,2,2,2,5,5
5,2,2,2,2,2,5
5,5,2,2,2,5,5
14,5,5,2,5,5,7
14,8,5,5,5,14,14
endlayer

layer
14,14,14,9,14,14,14
14,14,9,2,9,14,14
14,10,2,2,5,9,14
10,5,2,2,2,5,11
14,10,5,2,5,11,14
14,14,12,5,12,14,14
14,14,14,12,14,14,14
endlayer

layer
14,14,14,9,14,14,14
14,14,14,5,11,14,14
14,14,5,2,9,14,14
14,10,2,2,2,11,14
14,14,12,2,14,14,14
14,14,14,12,14,14,14
14,14,14,14,14,14,14
endlayer

layer
14,14,14,14,14,14,14
14,14,14,14,14,14,14
14,14,9,5,11,14,14
14,10,2,13,2,11,14
14,14,12,5,12,14,14
14,14,14,14,14,14,14
14,14,14,14,14,14,14
endlayer

layer
14,14,14,14,14,14,14
14,14,14,14,14,14,14
14,14,14,9,9,14,14
14,10,5,2,5,11,14
14,14,12,12,12,14,14
14,14,14,14,14,14,14
14,14,14,14,14,14,14
endlayer

layer
14,14,14,14,14,14,14
14,14,14,14,14,14,14
14,14,14,9,14,14,14
14,14,14,2,14,14,14
14,14,14,12,14,14,14
14,14,14,14,14,14,14
14,14,14,14,14,14,14
endlayer

layer
14,14,14,14,14,14,14
14,14,14,14,14,14,14
14,14,14,9,14,14,14
14,14,10,2,11,14,14
14,14,14,14,14,14,14
14,14,14,14,14,14,14
14,14,14,14,14,14,14
endlayer

layer
14,14,14,14,14,14,14
14,14,14,14,14,14,14
14,14,14,14,14,14,14
14,14,14,3,14,14,14
14,14,14,14,14,14,14
14,14,14,14,14,14,14
14,14,14,14,14,14,14
endlayer


