# Sky Quartz Portal Temple
# MC 1.7.10; 4 Dec 2014
# Created by Ruins mod version 14.4 Ingame Parser
# authoring Player: Jordan_Greywolf
# Special Instructions: Place in \templateparser folder.

weight=1
embed_into_distance=0
acceptable_target_blocks=
unacceptable_target_blocks=
dimensions=21,17,17
allowable_overhang=99999
max_leveling=0
leveling_buffer=0
preserve_water=0
preserve_lava=0
preserve_plants=1

rule1=0,100,minecraft:glowstone-0
rule2=0,100,minecraft:stone-0
rule3=0,100,minecraft:iron_ore-0,minecraft:coal_ore,minecraft:redstone_ore,minecraft:gold_ore,minecraft:emerald_ore
rule4=0,100,minecraft:dirt-0
rule5=0,100,minecraft:grass-0
rule6=0,100,minecraft:quartz_block-1
rule7=0,100,minecraft:quartz_block-0
rule8=0,100,CommandBlock:RUINSTRIGGER /testruin TPSky_Islet ~-8 ~0 ~0:@,CommandBlock:RUINSTRIGGER /testruin TPSky_Islet ~-5 ~1 ~2:@
rule9=0,100,minecraft:tallgrass-1,minecraft:tallgrass-1,minecraft:red_flower
rule10=0,100,minecraft:double_plant-4
rule11=0,100,minecraft:double_plant-4
rule12=0,100,minecraft:water-0
rule13=0,100,CommandBlock:RUINSTRIGGER /testruin TPSky_Islet ~0 ~0 ~-8:@,CommandBlock:RUINSTRIGGER /testruin TPSky_Islet ~-1 ~-2 ~-5:@
rule14=0,100,CommandBlock:/tp @p ~0 ~-140 ~0:@
rule15=0,100,CommandBlock:RUINSTRIGGER /testruin TPSky_Islet ~0 ~0 ~8:@,CommandBlock:RUINSTRIGGER /testruin TPSky_Islet ~2 ~3 ~6:@
rule16=0,100,CommandBlock:RUINSTRIGGER /testruin TPSky_Islet ~8 ~0 ~0:@,CommandBlock:RUINSTRIGGER /testruin TPSky_Islet ~6 ~0 ~3:@
rule17=0,100,minecraft:double_plant-12
rule18=0,100,minecraft:double_plant-12
rule19=0,100,minecraft:stone_slab-7
rule20=0,100,minecraft:quartz_block-2
rule21=2,100,minecraft:stone_button-4
rule22=0,100,minecraft:double_plant-12
rule23=0,100,minecraft:double_plant-12
rule24=0,100,minecraft:vine-8
rule25=0,100,minecraft:vine-1
rule26=0,100,minecraft:vine-4
rule27=0,100,minecraft:vine-2
rule28=0,100,minecraft:quartz_stairs-4
rule29=0,100,minecraft:quartz_stairs-6
rule30=0,100,minecraft:netherrack-0
rule31=0,100,minecraft:quartz_stairs-7
rule32=0,100,minecraft:quartz_stairs-5
rule33=0,100,minecraft:fire-15
rule34=0,100,minecraft:double_stone_slab-7
rule35=0,100,minecraft:stone_slab-15
rule36=0,100,minecraft:quartz_stairs-0
rule37=0,100,minecraft:quartz_stairs-2
rule38=0,100,minecraft:quartz_stairs-3
rule39=0,100,minecraft:quartz_stairs-1

layer
0,0,0,0,0,0,0,0,0,0,0,0,0,0,0,0,0
0,0,0,0,0,0,0,0,0,0,0,0,0,0,0,0,0
0,0,0,0,0,0,0,0,0,0,0,0,0,0,0,0,0
0,0,0,0,0,0,0,0,0,0,0,0,0,0,0,0,0
0,0,0,0,0,0,0,0,0,0,0,0,0,0,0,0,0
0,0,0,0,0,0,0,0,0,0,0,0,0,0,0,0,0
0,0,0,0,0,0,0,0,0,0,0,0,0,0,0,0,0
0,0,0,0,0,0,0,0,0,0,0,0,0,0,0,0,0
0,0,0,0,0,0,0,0,1,0,0,0,0,0,0,0,0
0,0,0,0,0,0,0,0,0,0,0,0,0,0,0,0,0
0,0,0,0,0,0,0,0,0,0,0,0,0,0,0,0,0
0,0,0,0,0,0,0,0,0,0,0,0,0,0,0,0,0
0,0,0,0,0,0,0,0,0,0,0,0,0,0,0,0,0
0,0,0,0,0,0,0,0,0,0,0,0,0,0,0,0,0
0,0,0,0,0,0,0,0,0,0,0,0,0,0,0,0,0
0,0,0,0,0,0,0,0,0,0,0,0,0,0,0,0,0
0,0,0,0,0,0,0,0,0,0,0,0,0,0,0,0,0
endlayer

layer
0,0,0,0,0,0,0,0,0,0,0,0,0,0,0,0,0
0,0,0,0,0,0,0,0,0,0,0,0,0,0,0,0,0
0,0,0,0,0,0,0,0,0,0,0,0,0,0,0,0,0
0,0,0,0,0,0,0,0,0,0,0,0,0,0,0,0,0
0,0,0,0,0,0,0,0,0,0,0,0,0,0,0,0,0
0,0,0,0,0,0,0,0,0,0,0,0,0,0,0,0,0
0,0,0,0,0,0,0,0,0,0,0,0,0,0,0,0,0
0,0,0,0,0,0,0,0,0,0,0,0,0,0,0,0,0
0,0,0,0,0,0,0,0,1,0,0,0,0,0,0,0,0
0,0,0,0,0,0,0,0,0,0,0,0,0,0,0,0,0
0,0,0,0,0,0,0,0,0,0,0,0,0,0,0,0,0
0,0,0,0,0,0,0,0,0,0,0,0,0,0,0,0,0
0,0,0,0,0,0,0,0,0,0,0,0,0,0,0,0,0
0,0,0,0,0,0,0,0,0,0,0,0,0,0,0,0,0
0,0,0,0,0,0,0,0,0,0,0,0,0,0,0,0,0
0,0,0,0,0,0,0,0,0,0,0,0,0,0,0,0,0
0,0,0,0,0,0,0,0,0,0,0,0,0,0,0,0,0
endlayer

layer
0,0,0,0,0,0,0,0,0,0,0,0,0,0,0,0,0
0,0,0,0,0,0,0,0,0,0,0,0,0,0,0,0,0
0,0,0,0,0,0,0,0,0,0,0,0,0,0,0,0,0
0,0,0,0,0,0,0,0,0,0,0,0,0,0,0,0,0
0,0,0,0,0,0,0,0,0,0,0,0,0,0,0,0,0
0,0,0,0,0,0,0,0,0,0,0,0,0,0,0,0,0
0,0,0,0,0,0,0,0,0,0,0,0,0,0,0,0,0
0,0,0,0,0,0,0,0,0,0,0,0,0,0,0,0,0
0,0,0,0,0,0,0,0,2,0,0,0,0,0,0,0,0
0,0,0,0,0,0,0,0,0,0,0,0,0,0,0,0,0
0,0,0,0,0,0,0,0,0,0,0,0,0,0,0,0,0
0,0,0,0,0,0,0,0,0,0,0,0,0,0,0,0,0
0,0,0,0,0,0,0,0,0,0,0,0,0,0,0,0,0
0,0,0,0,0,0,0,0,0,0,0,0,0,0,0,0,0
0,0,0,0,0,0,0,0,0,0,0,0,0,0,0,0,0
0,0,0,0,0,0,0,0,0,0,0,0,0,0,0,0,0
0,0,0,0,0,0,0,0,0,0,0,0,0,0,0,0,0
endlayer

layer
0,0,0,0,0,0,0,0,0,0,0,0,0,0,0,0,0
0,0,0,0,0,0,0,0,0,0,0,0,0,0,0,0,0
0,0,0,0,0,0,0,0,0,0,0,0,0,0,0,0,0
0,0,0,0,0,0,0,0,0,0,0,0,0,0,0,0,0
0,0,0,0,0,0,0,0,0,0,0,0,0,0,0,0,0
0,0,0,0,0,0,0,0,0,0,0,0,0,0,0,0,0
0,0,0,0,0,0,0,0,0,0,0,0,0,0,0,0,0
0,0,0,0,0,0,0,0,0,0,0,0,0,0,0,0,0
0,0,0,0,0,0,0,0,3,2,0,0,0,0,0,0,0
0,0,0,0,0,0,0,0,0,0,0,0,0,0,0,0,0
0,0,0,0,0,0,0,0,0,0,0,0,0,0,0,0,0
0,0,0,0,0,0,0,0,0,0,0,0,0,0,0,0,0
0,0,0,0,0,0,0,0,0,0,0,0,0,0,0,0,0
0,0,0,0,0,0,0,0,0,0,0,0,0,0,0,0,0
0,0,0,0,0,0,0,0,0,0,0,0,0,0,0,0,0
0,0,0,0,0,0,0,0,0,0,0,0,0,0,0,0,0
0,0,0,0,0,0,0,0,0,0,0,0,0,0,0,0,0
endlayer

layer
0,0,0,0,0,0,0,0,0,0,0,0,0,0,0,0,0
0,0,0,0,0,0,0,0,0,0,0,0,0,0,0,0,0
0,0,0,0,0,0,0,0,0,0,0,0,0,0,0,0,0
0,0,0,0,0,0,0,0,0,0,0,0,0,0,0,0,0
0,0,0,0,0,0,0,0,0,0,0,0,0,0,0,0,0
0,0,0,0,0,0,0,0,0,0,0,0,0,0,0,0,0
0,0,0,0,0,0,0,0,0,0,0,0,0,0,0,0,0
0,0,0,0,0,0,0,0,0,0,0,0,0,0,0,0,0
0,0,0,0,0,0,0,0,2,2,0,0,0,0,0,0,0
0,0,0,0,0,0,0,0,2,0,0,0,0,0,0,0,0
0,0,0,0,0,0,0,0,0,0,0,0,0,0,0,0,0
0,0,0,0,0,0,0,0,0,0,0,0,0,0,0,0,0
0,0,0,0,0,0,0,0,0,0,0,0,0,0,0,0,0
0,0,0,0,0,0,0,0,0,0,0,0,0,0,0,0,0
0,0,0,0,0,0,0,0,0,0,0,0,0,0,0,0,0
0,0,0,0,0,0,0,0,0,0,0,0,0,0,0,0,0
0,0,0,0,0,0,0,0,0,0,0,0,0,0,0,0,0
endlayer

layer
0,0,0,0,0,0,0,0,0,0,0,0,0,0,0,0,0
0,0,0,0,0,0,0,0,0,0,0,0,0,0,0,0,0
0,0,0,0,0,0,0,0,0,0,0,0,0,0,0,0,0
0,0,0,0,0,0,0,0,0,0,0,0,0,0,0,0,0
0,0,0,0,0,0,0,0,0,0,0,0,0,0,0,0,0
0,0,0,0,0,0,0,0,0,0,0,0,0,0,0,0,0
0,0,0,0,0,0,0,0,0,0,0,0,0,0,0,0,0
0,0,0,0,0,0,0,0,0,0,0,0,0,0,0,0,0
0,0,0,0,0,0,0,2,2,3,0,0,0,0,0,0,0
0,0,0,0,0,0,0,0,2,0,0,0,0,0,0,0,0
0,0,0,0,0,0,0,0,0,0,0,0,0,0,0,0,0
0,0,0,0,0,0,0,0,0,0,0,0,0,0,0,0,0
0,0,0,0,0,0,0,0,0,0,0,0,0,0,0,0,0
0,0,0,0,0,0,0,0,0,0,0,0,0,0,0,0,0
0,0,0,0,0,0,0,0,0,0,0,0,0,0,0,0,0
0,0,0,0,0,0,0,0,0,0,0,0,0,0,0,0,0
0,0,0,0,0,0,0,0,0,0,0,0,0,0,0,0,0
endlayer

layer
0,0,0,0,0,0,0,0,0,0,0,0,0,0,0,0,0
0,0,0,0,0,0,0,0,0,0,0,0,0,0,0,0,0
0,0,0,0,0,0,0,0,0,0,0,0,0,0,0,0,0
0,0,0,0,0,0,0,0,0,0,0,0,0,0,0,0,0
0,0,0,0,0,0,0,0,0,0,0,0,0,0,0,0,0
0,0,0,0,0,0,0,0,0,0,0,0,0,0,0,0,0
0,0,0,0,0,0,0,0,0,0,0,0,0,0,0,0,0
0,0,0,0,0,0,0,0,4,0,0,0,0,0,0,0,0
0,0,0,0,0,0,0,3,2,2,0,0,0,0,0,0,0
0,0,0,0,0,0,0,0,2,0,0,0,0,0,0,0,0
0,0,0,0,0,0,0,0,0,0,0,0,0,0,0,0,0
0,0,0,0,0,0,0,0,0,0,0,0,0,0,0,0,0
0,0,0,0,0,0,0,0,0,0,0,0,0,0,0,0,0
0,0,0,0,0,0,0,0,0,0,0,0,0,0,0,0,0
0,0,0,0,0,0,0,0,0,0,0,0,0,0,0,0,0
0,0,0,0,0,0,0,0,0,0,0,0,0,0,0,0,0
0,0,0,0,0,0,0,0,0,0,0,0,0,0,0,0,0
endlayer

layer
0,0,0,0,0,0,0,0,0,0,0,0,0,0,0,0,0
0,0,0,0,0,0,0,0,0,0,0,0,0,0,0,0,0
0,0,0,0,0,0,0,0,0,0,0,0,0,0,0,0,0
0,0,0,0,0,0,0,0,0,0,0,0,0,0,0,0,0
0,0,0,0,0,0,0,0,0,0,0,0,0,0,0,0,0
0,0,0,0,0,0,0,0,0,0,0,0,0,0,0,0,0
0,0,0,0,0,0,0,0,0,0,0,0,0,0,0,0,0
0,0,0,0,0,0,0,0,2,0,0,0,0,0,0,0,0
0,0,0,0,0,0,0,2,2,2,0,0,0,0,0,0,0
0,0,0,0,0,0,0,0,2,0,0,0,0,0,0,0,0
0,0,0,0,0,0,0,0,0,0,0,0,0,0,0,0,0
0,0,0,0,0,0,0,0,0,0,0,0,0,0,0,0,0
0,0,0,0,0,0,0,0,0,0,0,0,0,0,0,0,0
0,0,0,0,0,0,0,0,0,0,0,0,0,0,0,0,0
0,0,0,0,0,0,0,0,0,0,0,0,0,0,0,0,0
0,0,0,0,0,0,0,0,0,0,0,0,0,0,0,0,0
0,0,0,0,0,0,0,0,0,0,0,0,0,0,0,0,0
endlayer

layer
0,0,0,0,0,0,0,0,0,0,0,0,0,0,0,0,0
0,0,0,0,0,0,0,0,0,0,0,0,0,0,0,0,0
0,0,0,0,0,0,0,0,0,0,0,0,0,0,0,0,0
0,0,0,0,0,0,0,0,0,0,0,0,0,0,0,0,0
0,0,0,0,0,0,0,0,0,0,0,0,0,0,0,0,0
0,0,0,0,0,0,0,0,0,0,0,0,0,0,0,0,0
0,0,0,0,0,0,0,0,0,0,0,0,0,0,0,0,0
0,0,0,0,0,0,0,0,2,0,0,0,0,0,0,0,0
0,0,0,0,0,0,0,2,2,2,4,0,0,0,0,0,0
0,0,0,0,0,0,0,4,2,0,0,0,0,0,0,0,0
0,0,0,0,0,0,0,0,2,0,0,0,0,0,0,0,0
0,0,0,0,0,0,0,0,0,0,0,0,0,0,0,0,0
0,0,0,0,0,0,0,0,0,0,0,0,0,0,0,0,0
0,0,0,0,0,0,0,0,0,0,0,0,0,0,0,0,0
0,0,0,0,0,0,0,0,0,0,0,0,0,0,0,0,0
0,0,0,0,0,0,0,0,0,0,0,0,0,0,0,0,0
0,0,0,0,0,0,0,0,0,0,0,0,0,0,0,0,0
endlayer

layer
0,0,0,0,0,0,0,0,0,0,0,0,0,0,0,0,0
0,0,0,0,0,0,0,0,0,0,0,0,0,0,0,0,0
0,0,0,0,0,0,0,0,0,0,0,0,0,0,0,0,0
0,0,0,0,0,0,0,0,0,0,0,0,0,0,0,0,0
0,0,0,0,0,0,0,0,0,0,0,0,0,0,0,0,0
0,0,0,0,0,0,0,0,0,0,0,0,0,0,0,0,0
0,0,0,0,0,0,0,0,0,0,0,0,0,0,0,0,0
0,0,0,0,0,0,0,2,2,4,0,0,0,0,0,0,0
0,0,0,0,0,0,0,2,2,2,4,0,0,0,0,0,0
0,0,0,0,0,0,0,4,2,2,0,0,0,0,0,0,0
0,0,0,4,0,0,0,4,2,0,0,0,4,0,0,0,0
0,0,0,0,0,0,0,0,0,0,0,0,0,0,0,0,0
0,0,0,0,0,0,0,0,0,0,0,0,0,0,0,0,0
0,0,0,0,0,0,0,0,0,0,0,0,0,0,0,0,0
0,0,0,0,0,0,0,0,0,0,0,0,0,0,0,0,0
0,0,0,0,0,0,0,0,0,0,0,0,0,0,0,0,0
0,0,0,0,0,0,0,0,0,0,0,0,0,0,0,0,0
endlayer

layer
0,0,0,0,0,0,0,0,0,0,0,0,0,0,0,0,0
0,0,0,0,0,0,0,0,0,0,0,0,0,0,0,0,0
0,0,0,0,0,0,0,0,4,0,0,0,0,0,0,0,0
0,0,0,0,0,0,0,0,0,0,0,0,4,0,0,0,0
0,0,0,0,4,0,0,0,2,0,0,0,0,4,0,0,0
0,0,0,0,0,2,0,0,0,0,0,2,0,0,0,0,0
0,0,0,0,4,0,0,0,2,0,0,4,0,0,0,0,0
0,0,4,0,0,0,4,2,2,2,0,0,2,0,0,0,0
0,0,0,0,2,0,2,2,2,2,2,0,0,0,0,0,0
0,0,0,0,0,0,0,2,2,2,0,0,2,0,4,0,0
0,0,0,4,0,0,0,4,2,0,0,0,4,0,0,0,0
0,0,0,0,0,0,4,0,0,0,2,0,0,0,0,0,0
0,0,0,0,0,0,0,0,2,0,0,0,0,0,0,0,0
0,0,0,0,0,0,0,0,0,0,0,0,0,4,0,0,0
0,0,0,0,0,0,0,0,0,0,0,0,0,0,0,0,0
0,0,0,0,0,0,0,0,0,0,0,0,0,0,0,0,0
0,0,0,0,0,0,0,0,0,0,0,0,0,0,0,0,0
endlayer

layer
0,0,0,0,0,0,0,0,0,0,0,0,0,0,0,0,0
0,0,0,0,0,0,0,0,0,0,0,0,0,0,0,0,0
0,0,0,0,0,0,0,0,4,4,0,0,0,0,0,0,0
0,0,0,4,4,0,4,0,0,0,0,4,4,0,0,0,0
0,0,0,0,4,0,0,0,2,0,0,0,4,4,0,0,0
0,0,0,0,0,2,2,0,0,2,0,2,4,0,0,0,0
0,0,0,4,4,4,4,2,2,2,2,4,4,0,0,0,0
0,0,4,0,0,0,2,2,2,2,2,2,2,0,4,0,0
0,0,0,0,2,2,2,2,2,2,2,4,4,0,0,0,0
0,0,0,0,0,2,2,2,2,2,2,0,2,0,4,0,0
0,0,0,4,0,4,4,2,2,2,4,4,4,4,0,0,0
0,0,0,0,4,0,4,4,2,0,2,0,4,0,0,0,0
0,0,0,0,0,0,0,0,2,0,0,4,0,4,0,0,0
0,0,0,0,0,0,4,0,0,0,0,0,0,4,0,0,0
0,0,0,0,0,0,0,0,0,0,4,0,0,0,0,0,0
0,0,0,0,0,0,0,4,0,0,0,0,0,0,0,0,0
0,0,0,0,0,0,0,0,0,0,0,0,0,0,0,0,0
endlayer

layer
0,0,0,0,0,0,0,5,4,5,0,0,0,0,0,0,0
0,0,0,0,0,5,5,5,5,5,5,5,5,0,0,0,0
0,0,0,5,5,5,4,4,4,4,4,5,5,5,0,0,0
0,0,5,5,4,4,4,2,2,2,4,4,4,5,5,0,0
0,0,5,4,4,2,2,2,2,2,2,2,4,4,5,0,0
0,5,5,4,2,2,2,2,2,2,2,2,2,4,5,5,0
0,5,4,4,2,2,2,2,2,2,2,2,2,4,4,5,0
5,5,4,2,2,2,2,6,6,6,2,2,2,2,4,5,5
4,5,4,2,2,2,2,6,7,6,2,2,2,2,4,5,4
5,5,4,2,2,2,2,6,6,6,2,2,2,2,4,5,5
0,5,4,4,2,2,2,2,2,2,2,2,2,4,4,5,0
0,5,5,4,2,2,2,2,2,2,2,2,4,4,5,5,0
0,0,5,4,4,2,2,2,2,2,2,4,4,4,5,0,0
0,0,5,5,4,4,4,2,2,2,4,4,4,5,5,0,0
0,0,0,5,5,5,4,4,4,4,4,5,5,5,0,0,0
0,0,0,0,0,5,5,5,5,5,5,5,0,0,0,0,0
0,0,0,0,0,0,0,5,4,5,0,0,0,0,0,0,0
endlayer

layer
0,0,0,0,0,0,0,0,8,0,0,0,0,0,0,0,0
0,0,0,0,0,9,10,9,9,0,0,0,0,0,0,0,0
0,0,0,0,0,11,5,5,5,5,5,9,0,0,0,0,0
0,0,0,11,5,5,5,5,5,5,5,5,5,9,0,0,0
0,0,0,5,5,5,5,5,5,5,5,5,5,5,9,0,0
0,0,10,5,5,5,5,7,7,7,5,5,5,5,9,9,0
0,0,5,5,5,5,7,7,7,7,7,5,5,5,5,0,0
0,9,5,5,5,7,7,12,12,12,7,7,5,5,5,9,0
15,9,5,5,5,7,7,12,14,12,7,7,5,5,5,9,13
0,11,5,5,5,7,7,12,12,12,7,7,5,5,5,0,0
0,0,5,5,5,5,7,7,7,7,7,5,5,5,5,0,0
0,9,10,5,5,5,5,7,7,7,5,5,5,5,9,11,0
0,0,9,5,5,5,5,5,5,5,5,5,5,5,9,0,0
0,0,0,9,5,5,5,5,5,5,5,5,5,10,0,0,0
0,0,0,11,0,9,5,5,5,5,5,0,0,9,0,0,0
0,0,0,0,0,0,0,9,9,9,11,0,0,0,0,0,0
0,0,0,0,0,0,0,0,16,0,0,0,0,0,0,0,0
endlayer

layer
0,0,0,0,0,0,0,0,0,0,0,0,0,0,0,0,0
0,0,0,0,0,0,17,0,0,0,0,0,0,0,0,0,0
0,0,0,0,0,18,9,0,0,11,9,0,0,0,0,0,0
0,0,0,17,0,0,9,0,9,0,9,0,0,0,0,0,0
0,0,0,0,0,9,0,19,19,19,0,9,9,9,0,0,0
0,0,18,0,9,10,19,20,19,20,19,10,0,9,0,0,0
0,0,0,9,11,19,19,0,0,0,19,19,0,9,0,0,0
0,0,9,0,19,20,0,0,0,0,0,20,19,0,11,0,0
0,0,0,9,19,19,0,0,20,21,0,19,19,9,9,0,0
0,22,0,9,19,20,0,0,0,0,0,20,19,0,9,0,0
0,0,0,9,0,19,19,0,0,0,19,19,9,0,0,0,0
0,0,17,9,0,10,19,20,19,20,19,10,0,9,0,23,0
0,0,0,9,0,9,9,19,19,19,0,9,9,0,0,0,0
0,0,0,0,9,11,9,0,9,9,0,0,0,22,0,0,0
0,0,0,22,0,0,9,9,9,9,0,0,0,0,0,0,0
0,0,0,0,0,0,0,0,0,0,23,0,0,0,0,0,0
0,0,0,0,0,0,0,0,0,0,0,0,0,0,0,0,0
endlayer

layer
0,0,0,0,0,0,0,0,0,0,0,0,0,0,0,0,0
0,0,0,0,0,0,0,0,0,0,0,0,0,0,0,0,0
0,0,0,0,0,0,0,0,0,17,0,0,0,0,0,0,0
0,0,0,0,0,0,0,0,0,0,0,0,0,0,0,0,0
0,0,0,0,0,0,0,0,0,24,0,0,0,0,0,0,0
0,0,0,0,0,23,0,20,26,20,25,17,0,0,0,0,0
0,0,0,0,18,24,0,0,0,0,0,24,0,0,0,0,0
0,0,0,0,26,20,0,0,0,0,0,20,25,0,22,0,0
0,0,0,0,0,24,0,0,6,0,0,27,0,0,0,0,0
0,0,0,0,26,20,0,0,0,0,0,20,25,0,0,0,0
0,0,0,0,0,27,0,0,0,0,0,27,0,0,0,0,0
0,0,0,0,0,23,0,20,25,20,0,18,0,0,0,0,0
0,0,0,0,0,0,0,27,0,27,0,0,0,0,0,0,0
0,0,0,0,0,22,0,0,0,0,0,0,0,0,0,0,0
0,0,0,0,0,0,0,0,0,0,0,0,0,0,0,0,0
0,0,0,0,0,0,0,0,0,0,0,0,0,0,0,0,0
0,0,0,0,0,0,0,0,0,0,0,0,0,0,0,0,0
endlayer

layer
0,0,0,0,0,0,0,0,0,0,0,0,0,0,0,0,0
0,0,0,0,0,0,0,0,0,0,0,0,0,0,0,0,0
0,0,0,0,0,0,0,0,0,0,0,0,0,0,0,0,0
0,0,0,0,0,0,0,0,0,0,0,0,0,0,0,0,0
0,0,0,0,0,0,0,24,0,24,0,0,0,0,0,0,0
0,0,0,0,0,0,26,20,26,20,25,0,0,0,0,0,0
0,0,0,0,0,24,0,0,0,0,0,24,0,0,0,0,0
0,0,0,0,26,20,0,0,28,0,0,20,25,0,0,0,0
0,0,0,0,0,24,0,31,30,29,0,27,0,0,0,0,0
0,0,0,0,26,20,0,0,32,0,0,20,25,0,0,0,0
0,0,0,0,0,27,0,0,0,0,0,27,0,0,0,0,0
0,0,0,0,0,0,26,20,25,20,25,0,0,0,0,0,0
0,0,0,0,0,0,0,27,0,27,0,0,0,0,0,0,0
0,0,0,0,0,0,0,0,0,0,0,0,0,0,0,0,0
0,0,0,0,0,0,0,0,0,0,0,0,0,0,0,0,0
0,0,0,0,0,0,0,0,0,0,0,0,0,0,0,0,0
0,0,0,0,0,0,0,0,0,0,0,0,0,0,0,0,0
endlayer

layer
0,0,0,0,0,0,0,0,0,0,0,0,0,0,0,0,0
0,0,0,0,0,0,0,0,0,0,0,0,0,0,0,0,0
0,0,0,0,0,0,0,0,0,0,0,0,0,0,0,0,0
0,0,0,0,0,0,0,0,0,0,0,0,0,0,0,0,0
0,0,0,0,0,0,0,24,0,24,0,0,0,0,0,0,0
0,0,0,0,0,0,26,6,26,6,25,0,0,0,0,0,0
0,0,0,0,0,24,0,0,0,0,0,24,0,0,0,0,0
0,0,0,0,26,6,0,0,0,0,0,6,25,0,0,0,0
0,0,0,0,0,24,0,0,33,0,0,27,0,0,0,0,0
0,0,0,0,26,6,0,0,0,0,0,6,25,0,0,0,0
0,0,0,0,0,27,0,0,0,0,0,27,0,0,0,0,0
0,0,0,0,0,0,26,6,25,6,25,0,0,0,0,0,0
0,0,0,0,0,0,0,27,0,27,0,0,0,0,0,0,0
0,0,0,0,0,0,0,0,0,0,0,0,0,0,0,0,0
0,0,0,0,0,0,0,0,0,0,0,0,0,0,0,0,0
0,0,0,0,0,0,0,0,0,0,0,0,0,0,0,0,0
0,0,0,0,0,0,0,0,0,0,0,0,0,0,0,0,0
endlayer

layer
0,0,0,0,0,0,0,0,0,0,0,0,0,0,0,0,0
0,0,0,0,0,0,0,0,0,0,0,0,0,0,0,0,0
0,0,0,0,0,0,0,0,0,0,0,0,0,0,0,0,0
0,0,0,0,0,0,0,0,0,0,0,0,0,0,0,0,0
0,0,0,0,0,0,0,34,34,34,0,0,0,0,0,0,0
0,0,0,0,0,0,34,7,7,7,34,0,0,0,0,0,0
0,0,0,0,0,34,7,35,35,35,7,34,0,0,0,0,0
0,0,0,0,34,7,35,35,35,35,35,7,34,0,0,0,0
0,0,0,0,34,7,35,35,0,35,35,7,34,0,0,0,0
0,0,0,0,34,7,35,35,35,35,35,7,34,0,0,0,0
0,0,0,0,0,34,7,35,35,35,7,34,0,0,0,0,0
0,0,0,0,0,0,34,7,7,7,34,0,0,0,0,0,0
0,0,0,0,0,0,0,34,34,34,0,0,0,0,0,0,0
0,0,0,0,0,0,0,0,0,0,0,0,0,0,0,0,0
0,0,0,0,0,0,0,0,0,0,0,0,0,0,0,0,0
0,0,0,0,0,0,0,0,0,0,0,0,0,0,0,0,0
0,0,0,0,0,0,0,0,0,0,0,0,0,0,0,0,0
endlayer

layer
0,0,0,0,0,0,0,0,0,0,0,0,0,0,0,0,0
0,0,0,0,0,0,0,0,0,0,0,0,0,0,0,0,0
0,0,0,0,0,0,0,0,0,0,0,0,0,0,0,0,0
0,0,0,0,0,0,0,0,0,0,0,0,0,0,0,0,0
0,0,0,0,0,0,0,0,0,0,0,0,0,0,0,0,0
0,0,0,0,0,0,0,19,36,19,0,0,0,0,0,0,0
0,0,0,0,0,0,19,34,34,34,19,0,0,0,0,0,0
0,0,0,0,0,19,34,34,34,34,34,19,0,0,0,0,0
0,0,0,0,0,38,34,34,34,34,34,37,0,0,0,0,0
0,0,0,0,0,19,34,34,34,34,34,19,0,0,0,0,0
0,0,0,0,0,0,19,34,34,34,19,0,0,0,0,0,0
0,0,0,0,0,0,0,19,39,19,0,0,0,0,0,0,0
0,0,0,0,0,0,0,0,0,0,0,0,0,0,0,0,0
0,0,0,0,0,0,0,0,0,0,0,0,0,0,0,0,0
0,0,0,0,0,0,0,0,0,0,0,0,0,0,0,0,0
0,0,0,0,0,0,0,0,0,0,0,0,0,0,0,0,0
0,0,0,0,0,0,0,0,0,0,0,0,0,0,0,0,0
endlayer

layer
0,0,0,0,0,0,0,0,0,0,0,0,0,0,0,0,0
0,0,0,0,0,0,0,0,0,0,0,0,0,0,0,0,0
0,0,0,0,0,0,0,0,0,0,0,0,0,0,0,0,0
0,0,0,0,0,0,0,0,0,0,0,0,0,0,0,0,0
0,0,0,0,0,0,0,0,0,0,0,0,0,0,0,0,0
0,0,0,0,0,0,0,0,0,0,0,0,0,0,0,0,0
0,0,0,0,0,0,0,0,0,0,0,0,0,0,0,0,0
0,0,0,0,0,0,0,0,0,0,0,0,0,0,0,0,0
0,0,0,0,0,0,0,0,19,0,0,0,0,0,0,0,0
0,0,0,0,0,0,0,0,0,0,0,0,0,0,0,0,0
0,0,0,0,0,0,0,0,0,0,0,0,0,0,0,0,0
0,0,0,0,0,0,0,0,0,0,0,0,0,0,0,0,0
0,0,0,0,0,0,0,0,0,0,0,0,0,0,0,0,0
0,0,0,0,0,0,0,0,0,0,0,0,0,0,0,0,0
0,0,0,0,0,0,0,0,0,0,0,0,0,0,0,0,0
0,0,0,0,0,0,0,0,0,0,0,0,0,0,0,0,0
0,0,0,0,0,0,0,0,0,0,0,0,0,0,0,0,0
endlayer

