# Boglight Lair
# Created by Ruins mod version 14.6 Ingame Parser
# authoring Player: Jordan_Greywolf
# MC 1.7.10; 4 Jan 2015
# Note: Uses CommandBlocks & RUINSTRIGGER for custom monster spawns.

# Updated to MC 1.8: 5 Mar 2016
# Updated to MC 1.9: 29 Apr 2016
# Updated to MC 1.11: 13 Jan 2017
# Verified for MC 1.12: 23 Jun 2017
# Updated to MC 1.12.1: 10 Sep 2017

uniqueMinDistance=1000

biomesToSpawnIn=bog,mire,swamp,swampland,swamplands,swampland m,dead swamp,dead_swamp,lush swamp,lush_swamp,green swampland,green_swamp,quagmire,ominous woods,thick ominous woods,haunted forest,sludgepit,tainted land,tainted lands,tainted land,eerie,eldritch,fen,bayou,moor,land of lakes,land_of_lakes,mutated_swampland

weight=1
embed_into_distance=21
acceptable_target_blocks=

unacceptable_target_blocks=flowing_lava,lava,cloud,Natura:Cloud,slime_congealed,slime_dirt,slime_grass,command_block,planks,planks2,concrete,cobblestone,stonebrick,brick_block,glass,torch,oak_stairs,stone_stairs,brick_stairs,stone_brick_stairs,nether_brick_stairs,sandstone_stairs,spruce_stairs,birch_stairs,jungle_stairs,quartz_stairs,acacia_stairs,dark_oak_stairs,cobblestone_wall,stone_slab,double_stone_slab,stone_slab2,wooden_slab,double_wooden_slab,nether_brick,fence

dimensions=30,16,22
allowable_overhang=0
max_leveling=6
leveling_buffer=-1
preserve_water=0
preserve_lava=0
preserve_plants=1

rule1=0,100,preserveBlock
rule2=0,100,minecraft:stone-0
rule3=0,100,minecraft:obsidian-0
rule4=0,100,minecraft:water-3
rule5=0,100,minecraft:water-1
rule6=0,100,minecraft:water-9
rule7=0,100,minecraft:water-2
rule8=0,100,minecraft:water-0
rule9=0,100,minecraft:mossy_cobblestone-0
rule10=0,100,minecraft:mycelium-0
rule11=0,100,minecraft:water-13
rule12=0,100,minecraft:water-10
rule13=0,100,minecraft:dirt-0
rule14=0,100,minecraft:grass-0
rule15=0,100,minecraft:emerald_ore,minecraft:gold_ore
rule16=0,100,minecraft:lava-2
rule17=0,100,minecraft:lava-0
rule18=0,100,minecraft:lava-6
rule19=0,100,minecraft:lava-4
rule20=0,100,minecraft:lava-10
rule21=0,100,minecraft:red_mushroom,minecraft:brown_mushroom
rule22=0,100,minecraft:vine-4
rule23=0,100,minecraft:water-6
rule24=0,100,minecraft:water-5
rule25=0,100,ChestGenHook:chests/simple_dungeon:5-2
rule26=0,100,minecraft:vine-9
rule27=0,100,CommandBlock:RUINSTRIGGER /gamerule commandBlockOutput false:@
rule28=0,100,minecraft:water-4
rule29=0,100,minecraft:vine-1
rule30=0,100,minecraft:water-7
rule31=0,100,minecraft:vine-2
rule32=0,100,minecraft:vine-8
rule33=0,100,minecraft:red_mushroom_block-10
rule34=0,100,minecraft:red_mushroom_block-1
rule35=0,100,minecraft:red_mushroom_block-4
rule36=0,100,minecraft:red_mushroom_block-7
rule37=0,100,minecraft:red_mushroom_block-2
rule38=0,100,minecraft:red_mushroom_block-8
rule39=0,100,minecraft:red_mushroom_block-3
rule40=0,100,minecraft:red_mushroom_block-9
rule41=0,100,minecraft:red_mushroom_block-6
rule42=0,100,minecraft:brown_mushroom_block-10
rule43=0,100,minecraft:water-8
rule44=0,100,minecraft:lava-12
rule45=0,100,minecraft:red_mushroom_block-5
rule46=0,100,minecraft:vine-3

rule47=0,100,CommandBlock:RUINSTRIGGER /setblock ~0 ~1 ~0 mob_spawner 0 replace {EntityId:cave_spider,SpawnData:{id:cave_spider,CustomName:"Baby Boglight Spider"}}:@

rule48=0,100,minecraft:brown_mushroom_block-1
rule49=0,100,minecraft:brown_mushroom_block-4
rule50=0,100,minecraft:brown_mushroom_block-7
rule51=0,100,minecraft:brown_mushroom_block-5
rule52=0,100,minecraft:brown_mushroom_block-2
rule53=0,100,minecraft:brown_mushroom_block-8
rule54=0,100,minecraft:brown_mushroom_block-3
rule55=0,100,minecraft:brown_mushroom_block-9
rule56=0,100,minecraft:brown_mushroom_block-6
rule57=0,100,minecraft:web-0

rule58=0,100,CommandBlock:RUINSTRIGGER /summon spider ~0 ~0 ~0 {CustomName:"Boglight Spider",Health:100.0f,Attributes:[{Name:generic.movementSpeed,Base:0.3}],HandItems:[{id:spider_eye,Count:1,tag:{display:{Name:"Boglight Scepter"},AttributeModifiers:[{AttributeName:"generic.maxHealth",Name:"Health",Amount:10,Operation:0,UUIDLeast:894670,UUIDMost:2872}],ench:[{id:19,lvl:1},{id:20,lvl:3},{id:16,lvl:3}]}},{id:web,Count:6}],PersistenceRequired:1,DropChances:[2.0F,1.0F],ActiveEffects:[{Id:12,Amplifier:1,Duration:999999,Ambient:1},{Id:8,Amplifier:1,Duration:999999,Ambient:1},{Id:10,Amplifier:1,Duration:999999,Ambient:1},{Id:11,Amplifier:1,Duration:999999},{Id:13,Amplifier:1,Duration:999999,Ambient:1}]}:@

rule59=0,100,minecraft:log2-12

rule60=0,100,CommandBlock:RUINSTRIGGER /summon bat ~0 ~1 ~0 {PersistenceRequired:1,Silent:1,ActiveEffects:[{Id:14,Amplifier:0,Duration:999999,Ambient:1}],Passengers:[{id:fireball,direction:[0.0,0.0,0.0],ExplosionPower:5,PersistenceRequired:1}]}:@

rule61=0,100,minecraft:vine-6
rule62=0,100,minecraft:vine-10
rule63=0,100,minecraft:vine-13
rule64=0,100,minecraft:log2-12
rule65=0,100,minecraft:vine-0
rule66=0,100,minecraft:vine-5
rule67=0,100,minecraft:vine-15
rule68=0,100,minecraft:red_flower-1
rule69=0,100,minecraft:tallgrass-1,minecraft:tallgrass-0,minecraft:tallgrass-2
rule70=0,100,minecraft:double_plant-2
rule71=0,100,minecraft:waterlily-0
rule72=0,100,minecraft:double_plant-8
rule73=0,100,minecraft:double_plant-11
rule74=0,100,minecraft:vine-12
rule75=0,100,minecraft:double_plant-9
rule76=0,100,minecraft:double_plant-10

layer
1,1,1,1,1,1,2,2,2,2,3,3,2,2,2,2,2,1,1,1,1,1
1,1,1,1,2,2,2,2,3,3,3,3,3,2,2,2,2,2,2,1,1,1
1,1,1,2,2,2,2,2,3,3,3,3,3,3,2,2,2,2,2,2,1,1
1,1,2,2,4,2,2,3,3,3,3,3,3,3,2,2,2,2,2,2,1,1
1,2,6,5,7,4,2,2,3,3,3,3,3,2,2,2,2,6,5,2,2,1
1,2,2,6,5,7,2,2,3,3,3,3,3,2,2,2,8,8,2,2,2,1
2,2,2,6,5,2,2,3,3,3,3,3,2,2,2,2,8,8,9,2,2,2
2,2,2,2,11,2,3,3,3,3,3,3,3,2,2,2,2,10,10,2,2,2
2,6,5,2,2,2,3,3,3,3,3,3,3,2,5,2,2,2,2,2,2,2
2,2,5,12,2,2,2,3,3,3,3,3,9,9,8,8,8,2,2,2,1,1
2,6,6,2,2,2,2,2,3,2,9,9,8,8,8,8,8,8,2,1,1,1
2,2,13,2,2,2,2,2,2,2,8,8,8,8,8,9,8,9,2,1,1,1
1,2,2,2,2,2,2,2,8,8,8,8,8,8,9,2,2,2,2,1,1,1
1,1,2,2,2,2,2,12,5,5,13,14,8,9,2,2,2,2,2,1,1,1
1,1,1,2,2,2,2,2,6,13,2,2,2,2,2,2,2,1,1,1,1,1
1,1,1,1,1,1,1,2,2,2,2,2,2,2,1,1,1,1,1,1,1,1
endlayer

layer
1,1,1,1,1,2,2,2,2,3,3,3,3,2,2,2,5,2,1,1,1,1
1,1,1,2,15,2,2,2,3,3,3,3,3,2,2,2,6,10,2,1,1,1
1,1,1,2,0,0,2,3,3,17,17,16,3,3,2,2,2,8,13,2,1,1
1,1,2,0,0,0,3,3,20,16,16,19,18,3,2,2,2,6,14,14,2,1
1,2,6,0,0,0,2,3,3,17,16,16,3,2,2,13,13,5,0,14,2,1
2,13,13,6,0,0,2,2,3,3,17,17,3,2,10,13,0,0,0,9,9,2
2,13,6,5,22,2,2,3,19,16,17,3,3,2,10,10,0,0,9,21,14,2
2,6,25,0,24,23,3,19,16,17,16,19,3,2,2,10,10,21,21,0,13,2
8,5,0,0,28,24,3,16,17,16,19,3,3,0,13,10,10,27,26,0,13,2
2,29,0,7,4,28,24,3,16,3,3,3,9,0,0,0,0,13,10,9,2,2
1,6,6,5,2,2,0,24,3,30,0,0,0,0,0,0,0,0,9,2,1,1
2,2,13,6,2,2,0,28,24,23,30,0,0,0,31,0,0,0,9,2,1,1
1,2,13,13,6,5,2,4,28,24,0,0,0,0,0,9,13,13,13,2,1,1
1,1,2,13,13,6,5,7,0,0,13,0,0,0,13,13,13,2,2,1,1,1
1,1,2,2,2,13,13,0,5,10,10,13,13,13,13,2,2,1,1,1,1,1
1,1,1,1,1,2,2,2,8,8,2,2,2,2,2,1,1,1,1,1,1,1
endlayer

layer
1,1,1,1,1,2,2,2,2,3,3,3,3,2,2,2,0,0,2,1,1,1
1,1,1,2,2,2,2,2,3,0,0,0,3,3,2,8,5,0,2,1,1,1
1,1,2,2,2,3,3,3,0,0,0,0,0,3,2,2,2,0,14,9,1,1
1,2,0,0,0,15,3,20,16,0,0,0,0,0,0,2,8,5,0,0,2,1
2,13,5,0,0,3,3,3,0,0,0,0,0,3,10,13,13,0,0,0,9,1
2,13,6,5,0,0,0,0,0,0,0,0,0,3,0,13,0,0,0,0,21,2
2,6,5,0,22,2,3,0,0,0,0,0,0,3,21,21,0,0,0,0,0,2
2,5,0,0,0,0,3,0,0,0,0,0,0,0,0,21,21,0,0,0,0,2
0,0,0,0,0,0,3,0,0,0,0,0,3,0,33,21,0,32,0,0,0,2
2,29,0,29,0,0,0,3,0,0,0,3,0,0,0,0,0,14,29,0,13,2
2,6,5,0,2,0,0,0,3,0,0,0,0,0,0,0,29,0,0,13,2,2
2,13,6,5,0,2,0,0,13,13,0,0,0,0,31,0,0,0,9,13,2,1
2,13,6,6,5,0,13,0,0,10,10,0,0,0,0,0,13,13,13,2,1,1
1,2,13,13,6,5,0,0,0,10,14,0,0,0,0,21,13,2,2,1,1,1
1,1,2,2,13,6,0,0,0,21,21,14,14,13,13,13,2,1,2,1,1,1
1,1,1,1,2,2,2,2,0,0,2,2,2,2,2,2,1,1,1,1,1,1
endlayer

layer
1,1,1,1,2,2,1,1,2,3,3,3,3,2,2,0,0,0,2,1,1,1
1,1,2,2,2,2,2,2,3,0,0,0,0,0,13,0,0,0,2,2,1,1
1,2,2,2,2,3,3,3,0,0,0,0,0,0,13,2,2,0,0,0,2,1
2,2,0,2,3,15,20,16,0,0,0,0,0,0,0,0,0,0,0,0,2,1
2,13,0,0,3,3,3,0,0,0,0,0,0,0,0,10,13,0,0,0,21,2
2,13,6,0,0,2,0,0,0,0,0,0,0,3,0,10,0,0,0,0,0,2
2,6,0,0,0,0,0,0,0,0,0,0,0,36,35,34,0,0,0,0,0,2
2,0,0,0,0,22,3,0,0,0,0,0,36,0,0,0,34,0,0,0,0,2
2,0,29,0,0,0,0,0,0,0,0,0,38,0,33,0,37,0,0,0,0,2
2,29,0,29,32,0,0,0,0,0,0,0,40,0,0,0,39,29,0,0,21,2
2,6,0,0,2,0,0,0,10,13,0,0,0,40,41,39,29,0,0,0,13,2
2,13,6,0,0,2,0,0,10,10,0,0,0,0,31,0,0,0,21,0,10,2
2,13,6,5,0,0,0,0,0,21,21,0,0,0,0,0,0,0,0,13,2,1
2,2,13,6,5,0,0,0,0,21,0,0,0,0,0,0,0,14,13,2,1,1
1,1,2,13,6,5,0,0,0,0,0,0,0,14,0,0,14,2,2,1,1,1
1,1,1,2,2,2,2,2,2,0,2,2,2,2,2,2,2,2,1,1,1,1
endlayer

layer
1,1,1,2,2,1,1,1,2,2,2,2,2,2,2,0,0,0,2,2,1,1
1,1,2,2,2,2,2,3,0,3,2,2,2,2,13,0,0,2,2,2,1,1
1,2,2,2,2,3,0,0,0,0,3,2,2,0,10,0,2,0,0,2,2,1
2,13,0,2,3,20,16,0,0,0,0,3,2,10,0,10,0,0,0,0,2,1
2,13,0,2,3,3,3,0,0,0,0,0,2,0,0,0,42,0,0,0,0,2
2,6,5,0,2,3,0,0,0,0,0,0,2,2,0,0,0,0,0,0,0,2
2,5,0,0,0,0,0,0,0,0,0,0,0,36,35,34,0,0,0,0,0,2
2,0,0,0,0,22,13,0,0,0,0,0,36,0,0,0,34,0,0,0,0,2
2,13,29,0,0,0,0,0,0,0,0,0,38,0,33,0,37,0,0,0,0,2
2,29,0,29,32,0,0,0,0,0,0,0,40,0,0,0,39,29,0,0,0,2
2,5,0,0,2,0,0,0,21,42,0,0,0,40,41,39,29,0,0,0,0,2
2,6,5,0,0,10,0,0,21,21,0,0,0,0,31,0,0,0,0,0,21,2
2,13,6,0,0,0,0,0,0,0,0,0,0,0,0,0,0,0,0,21,2,1
2,2,13,6,0,0,0,0,0,0,0,0,0,0,0,0,0,21,0,10,2,1
1,1,2,13,6,0,0,0,0,0,0,0,0,0,0,0,0,13,13,2,1,1
1,1,1,2,2,2,2,2,2,2,2,2,2,2,2,2,2,2,2,2,1,1
endlayer

layer
1,1,2,2,2,1,1,1,2,2,1,1,1,2,2,2,0,2,2,2,1,1
1,2,2,2,2,3,2,2,0,2,1,1,1,2,14,0,0,2,2,2,2,1
2,2,2,2,3,0,0,0,0,0,2,2,2,0,0,0,0,0,2,2,2,1
2,43,2,2,3,16,0,0,0,0,0,0,0,0,0,0,0,0,0,2,2,2
2,6,2,3,3,20,3,0,0,0,0,0,0,0,0,0,42,0,0,0,0,2
2,5,0,2,3,3,0,0,0,0,0,0,0,0,0,0,0,0,0,0,0,2
2,0,0,0,0,0,0,0,0,0,0,0,0,36,35,34,0,0,0,0,0,2
2,13,0,0,0,22,13,13,0,0,0,0,36,0,0,0,34,0,0,0,0,2
2,13,29,0,0,0,13,0,0,0,0,0,38,0,33,0,37,0,0,0,0,2
2,0,0,29,32,0,0,0,0,0,0,0,40,0,0,0,39,29,0,0,0,2
2,0,0,29,2,0,0,0,0,42,0,0,0,40,41,39,29,0,0,0,0,2
2,5,0,0,0,21,0,0,0,0,0,0,0,0,31,22,0,0,0,0,0,2
2,12,5,0,0,0,0,0,0,0,0,0,0,0,0,0,0,0,0,0,13,2
2,13,12,5,0,0,0,0,0,0,0,0,0,0,0,0,0,0,0,21,2,1
1,2,13,12,5,0,0,0,0,0,0,0,0,0,0,0,0,0,0,13,2,1
1,1,2,2,2,2,2,2,2,2,2,2,2,2,2,2,2,2,2,2,1,1
endlayer

layer
1,1,2,2,2,1,1,2,2,2,0,1,0,2,2,2,0,2,2,2,2,1
2,2,2,2,2,2,2,2,0,13,0,0,0,14,0,0,0,13,13,13,2,1
2,2,2,3,3,0,0,0,0,0,14,14,14,0,0,0,0,0,13,13,2,1
2,8,2,3,3,0,0,0,0,0,0,0,0,0,0,0,0,0,0,2,2,2
2,5,2,3,44,16,10,0,0,0,0,0,0,0,0,0,42,0,0,0,2,2
2,0,2,3,3,13,10,0,0,0,0,0,0,0,0,0,0,0,0,0,0,2
2,0,0,0,3,10,10,10,0,0,0,0,0,0,0,0,0,0,0,0,0,2
2,13,0,0,0,10,10,13,13,13,0,0,0,36,35,34,0,0,0,0,0,2
1,2,29,0,0,10,13,13,13,0,0,0,0,38,45,37,0,0,0,0,0,2
1,2,0,29,32,0,0,0,0,0,0,0,0,40,41,39,46,0,0,0,0,2
2,0,0,26,15,0,0,0,0,42,0,0,0,0,0,0,0,0,0,0,2,2
2,0,0,0,0,0,0,0,0,0,0,0,0,32,32,22,0,0,0,0,2,2
2,12,0,0,32,0,0,0,0,0,0,0,0,0,0,32,0,0,0,0,0,2
2,13,12,0,0,0,0,0,0,0,0,0,0,0,0,0,0,0,0,0,13,2
2,2,13,12,0,0,0,0,0,0,0,13,2,2,0,0,0,0,0,13,2,1
1,1,2,2,2,2,2,2,2,2,2,2,2,2,2,2,2,2,2,2,1,1
endlayer

layer
1,2,2,2,1,1,1,2,2,2,0,1,0,2,2,2,2,2,2,2,2,1
2,2,2,2,2,2,15,2,0,14,0,0,0,0,50,49,49,49,48,47,2,1
2,2,2,3,3,0,0,0,0,0,0,0,0,50,51,51,51,51,51,48,13,2
2,2,2,3,0,0,0,0,0,0,0,0,0,53,51,51,51,51,51,52,13,2
2,0,2,3,44,0,0,0,0,0,0,0,0,53,51,51,51,51,51,52,2,2
2,0,2,3,0,10,0,0,0,0,0,0,0,53,51,51,51,51,51,52,2,2
2,0,0,0,3,0,0,0,0,0,0,0,0,55,51,51,51,51,51,54,0,2
1,2,0,0,0,0,0,50,49,49,49,48,0,0,55,56,56,56,54,2,0,2
1,2,29,0,0,0,50,51,51,51,51,51,48,0,0,31,0,0,0,0,0,2
1,2,0,29,0,0,53,51,51,51,51,51,52,29,0,0,31,0,0,0,0,2
1,2,0,26,0,0,53,51,51,51,51,51,52,0,46,0,0,0,0,0,2,2
1,2,14,14,0,0,53,51,51,51,51,51,52,32,32,22,0,29,9,9,2,2
2,7,0,0,32,0,55,51,51,51,51,51,54,0,0,32,0,9,9,9,9,2
2,5,7,0,0,0,0,55,56,56,56,54,2,2,0,0,0,9,9,9,9,2
2,8,5,7,0,0,0,0,0,0,0,2,2,9,2,0,0,0,9,9,2,2
1,2,2,2,2,2,2,2,2,2,2,2,1,1,2,2,2,2,2,2,1,1
endlayer

layer
1,2,2,2,1,1,1,2,2,2,0,0,0,2,2,9,9,9,2,2,2,1
2,2,2,2,2,2,2,2,0,0,0,0,0,0,31,0,0,0,0,0,13,2
2,2,2,2,0,0,0,0,0,0,0,0,0,57,31,0,58,0,0,0,57,2
2,2,2,3,0,0,0,0,0,0,0,0,59,29,0,0,0,0,0,0,10,2
2,0,2,3,44,0,0,0,0,0,0,0,0,0,0,0,57,0,60,22,13,2
2,0,2,3,0,0,0,0,0,0,0,0,0,0,0,26,0,0,0,9,2,2
1,2,0,0,0,0,0,0,0,0,0,0,0,57,22,13,32,2,2,2,2,2
1,2,0,0,0,0,0,0,0,22,13,29,32,0,22,0,0,2,2,2,2,1
1,2,29,0,0,0,0,0,0,0,31,0,0,0,22,0,0,0,2,2,0,2
1,2,0,29,0,0,0,0,0,0,0,22,0,32,0,0,31,0,0,0,47,2
1,2,0,29,0,0,0,0,0,0,0,0,0,0,46,0,0,29,0,0,13,2
1,2,0,32,0,0,0,0,0,0,0,0,0,32,32,22,0,29,9,9,2,2
1,2,9,9,32,0,0,60,32,0,32,0,32,0,0,32,0,9,9,9,9,2
2,0,9,9,9,0,0,0,0,32,0,2,2,2,2,2,0,9,9,9,9,2
2,0,9,9,2,2,2,0,2,0,2,2,8,8,9,9,13,0,9,9,13,2
1,2,1,1,1,1,1,2,2,2,2,1,5,1,1,9,2,2,2,2,2,1
endlayer

layer
2,2,2,2,1,1,1,1,2,2,2,0,2,2,2,2,9,9,2,2,2,1
2,2,2,2,2,2,2,2,13,0,0,0,0,0,31,0,0,57,2,2,2,2
2,2,2,2,0,0,0,0,13,0,0,0,0,0,31,0,0,0,57,0,57,2
2,2,2,3,3,0,0,0,0,0,0,0,59,29,0,0,0,0,0,0,0,2
2,2,2,3,44,0,0,0,0,0,0,0,0,0,0,0,0,0,0,0,0,2
2,0,0,0,0,0,0,0,0,0,0,0,0,0,31,29,0,57,0,0,2,2
2,0,0,0,0,0,0,0,0,0,0,0,0,0,0,32,32,2,2,2,2,1
1,2,0,0,0,0,0,0,0,22,13,29,32,0,22,14,14,2,2,2,2,2
1,2,29,0,0,0,0,0,0,0,31,0,0,0,22,13,13,13,2,2,13,2
1,9,9,29,0,0,0,0,0,0,0,22,0,32,14,13,31,29,13,13,0,2
1,9,9,29,0,0,0,0,0,0,0,0,22,0,46,61,0,29,0,13,14,2
1,2,0,32,0,0,0,0,0,0,0,0,0,32,26,22,0,29,32,61,13,2
1,2,9,9,32,32,32,32,32,0,32,0,32,13,13,32,0,32,9,9,31,2
1,2,9,9,9,0,0,0,0,32,0,13,14,14,2,2,2,13,9,9,29,2
2,2,9,9,2,2,2,2,2,2,13,14,0,0,32,0,9,14,0,26,13,2
2,1,1,1,1,1,1,2,1,2,0,0,0,0,0,0,2,2,2,2,2,1
endlayer

layer
2,2,2,1,1,1,1,1,2,2,2,2,2,2,2,2,2,1,1,1,1,2
2,2,2,2,2,2,2,2,13,13,0,0,0,0,31,0,0,9,2,1,1,2
2,2,2,2,2,2,0,13,13,0,0,0,0,0,31,0,0,0,57,2,2,2
2,3,3,3,3,0,0,0,13,0,0,0,59,29,0,0,0,0,0,0,2,2
2,3,3,3,44,0,0,0,0,0,0,0,0,29,0,0,0,0,0,57,2,2
2,0,3,3,3,0,0,0,0,0,0,0,0,0,31,29,0,0,0,2,1,1
2,0,0,0,0,0,0,0,0,0,0,0,0,0,0,0,0,0,57,2,1,1
1,2,0,0,0,0,0,0,0,22,13,29,32,0,0,32,32,0,10,13,2,2
1,2,0,0,0,0,0,0,0,0,31,0,29,0,22,14,14,29,0,0,13,2
1,9,9,29,0,0,0,0,0,0,0,22,0,32,0,0,13,29,0,0,0,2
1,9,9,29,0,0,0,0,0,0,0,0,22,0,29,22,13,29,0,0,32,2
1,2,0,57,0,0,0,0,0,0,32,0,0,13,26,22,0,29,0,22,13,2
1,2,0,0,32,32,32,32,32,0,32,0,0,13,14,0,13,26,0,0,31,2
1,2,9,2,2,2,15,13,13,32,13,14,29,62,14,13,13,14,29,0,0,2
2,2,2,2,1,1,1,2,13,14,14,0,0,0,32,0,2,8,14,29,0,2
2,2,1,1,1,1,1,1,2,2,0,0,1,1,0,1,2,8,2,2,2,2
endlayer

layer
2,2,1,1,1,1,1,1,2,2,2,2,2,1,1,2,2,1,1,1,1,1
2,2,2,2,2,1,2,2,13,14,13,0,2,2,2,0,0,2,2,1,1,1
2,2,3,2,2,2,2,13,13,13,0,0,0,0,31,0,0,57,0,2,1,1
2,3,3,3,0,0,0,13,13,0,0,0,59,29,0,0,0,0,0,0,2,1
2,3,20,16,19,0,0,0,0,0,0,0,59,29,0,29,0,0,0,57,2,2
2,3,3,3,0,0,0,0,13,0,0,0,0,0,31,29,0,0,0,2,1,1
2,0,0,0,0,0,0,0,0,0,14,0,0,0,0,0,0,0,0,13,2,1
1,2,0,0,0,0,0,0,22,13,13,29,32,0,0,0,0,0,21,13,2,2
1,2,0,0,0,0,0,0,0,0,31,0,29,29,0,32,32,0,0,0,13,2
1,2,0,0,0,0,0,0,0,0,0,22,0,26,13,14,14,29,0,0,0,2
1,2,0,57,0,0,0,0,0,0,0,0,22,13,29,22,13,29,0,0,32,2
1,15,0,57,0,0,0,0,0,0,32,29,0,14,29,22,14,29,0,22,13,2
1,2,47,0,57,0,32,32,14,0,32,0,0,14,29,14,14,29,0,0,31,2
1,2,2,2,2,2,15,15,14,31,13,26,32,62,22,14,14,29,0,0,0,2
2,2,2,1,1,1,1,2,2,0,0,0,0,0,32,13,14,29,0,0,0,2
2,2,1,1,1,1,1,1,1,2,2,0,0,1,0,1,2,0,2,2,2,2
endlayer

layer
2,2,1,1,1,1,1,2,2,2,2,2,2,1,1,1,2,2,2,1,1,1
2,2,3,1,2,1,2,2,2,0,0,0,2,2,2,2,57,13,10,2,1,1
2,3,3,3,2,2,2,14,14,14,0,0,0,0,31,0,57,57,0,21,2,1
2,3,20,3,0,0,14,14,14,14,0,0,32,0,0,0,0,0,0,0,57,2
3,17,16,0,0,0,0,13,0,57,0,59,59,29,0,29,0,0,0,0,57,2
2,3,0,0,0,0,0,0,13,0,0,0,0,0,31,29,0,0,0,21,2,2
2,0,0,0,0,0,0,0,0,0,0,0,0,0,0,29,0,0,0,0,13,2
1,2,0,0,0,0,0,0,22,59,13,13,32,0,0,0,0,0,0,57,13,2
1,2,0,0,0,0,0,0,59,59,13,0,29,29,0,0,32,0,0,0,0,2
1,2,0,0,0,0,0,59,59,0,0,22,0,26,0,0,0,0,0,0,0,2
1,2,0,57,0,0,0,0,0,31,31,61,22,59,29,0,0,0,0,0,0,2
1,2,0,57,0,0,57,0,0,0,32,29,14,32,0,0,0,0,0,0,21,2
1,2,0,0,13,0,14,14,63,0,13,13,14,0,0,0,0,0,0,0,0,2
1,2,2,2,2,2,2,13,0,31,14,26,32,32,0,0,0,0,0,0,2,1
1,2,1,1,1,1,1,2,2,0,0,0,0,0,32,14,0,0,0,0,2,2
2,2,1,1,1,1,1,1,1,2,2,2,1,0,0,2,2,2,2,2,2,2
endlayer

layer
2,3,3,3,1,1,2,2,2,2,2,1,1,1,1,1,1,2,2,2,1,1
2,3,3,3,2,2,2,0,0,0,0,2,2,2,2,2,2,13,21,13,2,1
2,3,20,3,3,0,0,0,0,0,0,0,0,0,0,0,13,0,0,0,57,2
2,3,16,0,0,0,0,0,0,0,0,0,0,0,0,0,0,0,0,0,2,1
3,0,0,0,0,0,0,14,57,0,0,32,0,0,0,29,0,0,0,0,2,1
2,0,0,0,0,0,0,14,14,0,0,59,0,0,31,29,0,0,0,0,2,1
1,2,0,0,0,0,0,0,14,57,0,59,0,0,0,29,0,0,0,0,2,1
1,2,0,0,0,0,0,0,0,0,59,14,32,0,31,0,0,0,0,0,13,2
1,2,0,0,0,0,0,0,0,22,14,13,29,29,0,0,32,0,0,0,0,2
1,2,13,0,0,0,0,31,0,0,0,22,59,26,0,0,0,0,0,0,0,2
1,2,13,57,0,0,0,0,0,31,31,61,59,59,29,0,0,0,0,0,0,2
1,2,13,13,57,57,0,0,0,57,13,29,31,32,0,0,0,0,0,0,0,2
1,2,13,14,14,13,29,0,63,14,14,14,29,0,0,0,0,0,0,0,2,1
1,2,2,2,2,2,2,0,0,31,29,32,32,32,0,0,0,0,0,0,2,1
2,2,2,1,1,1,1,2,2,0,0,9,9,0,32,0,0,0,57,2,1,1
2,2,1,1,1,1,1,1,1,2,2,2,1,0,0,2,2,2,2,2,1,1
endlayer

layer
2,3,3,3,1,1,2,2,2,2,1,1,1,1,1,1,2,2,2,2,2,1
2,3,20,3,2,2,2,0,0,0,9,2,2,2,2,2,13,0,0,21,13,2
2,3,16,3,0,0,0,0,0,0,0,0,0,10,0,10,0,0,0,0,2,1
2,3,0,0,0,0,0,0,0,0,0,0,0,10,10,0,0,0,0,0,2,1
2,0,0,0,0,0,0,0,0,0,0,0,22,10,10,29,0,0,0,0,2,1
2,2,0,0,0,0,0,0,0,0,0,57,0,10,31,29,0,0,0,0,2,1
1,2,0,0,0,0,0,0,0,0,0,0,0,57,0,29,0,57,0,0,2,1
1,2,0,0,0,0,0,0,0,0,0,0,32,0,31,0,0,0,0,0,2,1
1,2,0,0,0,0,22,0,29,32,32,14,13,29,0,0,32,0,0,0,57,2
1,2,0,0,0,0,0,31,0,0,0,14,59,29,0,0,0,0,0,0,0,2
1,15,0,0,0,0,0,0,0,31,31,31,31,0,0,0,0,0,0,0,0,2
1,2,0,0,0,0,0,0,0,0,14,29,0,32,0,0,0,0,0,0,0,2
1,2,0,0,0,0,0,0,26,31,31,0,0,0,0,0,0,0,0,0,2,1
1,2,0,0,2,2,2,2,9,9,29,0,32,32,0,0,0,0,57,2,1,1
2,2,2,2,1,1,1,1,2,2,0,22,9,2,32,0,0,57,0,2,1,1
2,2,2,2,1,1,1,1,1,1,2,2,2,1,2,2,2,2,2,1,1,1
endlayer

layer
3,3,2,2,2,2,2,2,2,1,1,1,1,1,1,2,2,2,2,2,2,2
3,17,20,3,2,2,0,0,13,2,9,2,2,2,2,21,21,0,0,0,2,1
3,3,0,0,0,0,0,0,0,0,0,0,0,0,0,0,0,0,0,0,2,1
2,3,0,0,0,0,0,0,0,0,0,0,0,0,21,0,0,0,0,0,2,1
2,0,0,0,0,0,0,0,0,0,0,57,0,0,57,0,0,0,0,0,2,1
2,0,0,0,0,0,0,0,0,0,0,57,0,57,64,29,0,0,0,0,2,1
2,0,0,0,0,0,0,0,0,0,0,59,0,0,10,29,0,57,0,0,2,1
1,2,0,0,0,0,0,0,0,0,0,31,32,0,31,0,0,0,0,0,2,1
1,2,0,0,0,0,22,64,29,32,32,0,59,29,0,0,32,0,0,0,2,1
1,2,0,0,0,0,0,31,0,64,0,0,31,0,0,0,0,0,0,0,57,2
1,15,0,0,0,0,0,0,0,31,31,0,0,0,0,0,0,0,0,0,0,2
1,15,0,0,0,0,0,0,0,0,0,29,0,32,0,0,0,0,0,0,2,1
1,2,0,0,0,0,0,0,26,31,31,0,0,64,29,0,0,0,0,0,2,1
1,2,0,0,0,15,2,2,2,29,32,0,0,0,0,0,0,0,0,57,2,1
2,13,13,0,2,1,1,1,1,9,2,0,0,0,32,0,57,2,57,2,2,1
2,2,2,2,1,1,1,1,1,1,1,2,2,2,2,2,2,2,2,2,2,2
endlayer

layer
3,2,2,2,2,2,2,2,2,2,2,1,1,1,2,2,2,2,2,2,2,2
3,17,16,0,0,0,0,13,13,0,57,2,2,2,0,0,0,0,0,0,0,2
3,3,0,0,0,0,0,0,0,0,0,0,0,0,0,0,0,0,0,0,2,1
2,0,0,0,0,0,0,0,0,0,0,0,0,0,0,0,0,0,0,0,2,1
2,0,0,0,0,0,0,0,0,0,64,57,0,0,0,0,0,13,0,0,2,1
2,0,0,13,13,13,13,0,0,0,64,13,0,0,64,29,0,0,0,0,2,1
2,2,13,13,13,13,13,0,0,0,0,59,0,0,0,65,0,57,0,0,2,1
1,2,13,13,13,13,13,0,0,0,0,66,32,0,31,0,0,0,0,0,57,2
1,2,13,13,13,13,13,64,29,32,32,0,59,29,0,0,32,0,0,0,2,1
1,2,0,13,13,13,13,31,0,64,64,0,31,0,0,0,64,57,0,0,2,1
1,2,0,0,0,0,0,0,0,31,31,0,0,0,0,0,64,0,0,0,0,2
1,2,0,0,0,13,0,0,0,64,64,29,0,32,0,0,0,0,0,0,2,1
1,2,13,0,13,13,13,13,29,31,31,0,0,64,29,0,0,0,0,57,2,1
1,2,0,0,13,13,13,13,13,29,32,0,0,0,0,0,0,0,0,2,2,1
2,2,13,0,2,2,2,2,2,2,9,0,0,0,32,57,0,0,2,2,2,2
2,2,2,2,2,1,1,1,1,1,1,2,2,2,2,2,2,2,2,2,2,2
endlayer

layer
2,2,2,2,2,2,2,2,2,2,2,2,1,2,2,2,2,2,2,2,2,2
2,0,2,2,13,13,13,13,13,13,57,13,2,0,0,0,0,0,0,0,2,2
2,3,0,13,13,13,13,13,13,13,57,0,0,0,0,0,0,13,0,0,0,2
2,13,13,13,13,13,13,13,13,13,0,0,0,0,0,0,13,13,0,0,0,2
2,13,13,13,13,13,13,13,0,0,13,13,13,13,13,13,13,13,0,0,2,1
2,13,13,13,8,8,8,13,13,0,64,64,13,64,64,13,13,13,13,13,2,1
2,13,13,8,8,8,8,13,13,13,64,64,13,13,13,64,13,13,13,13,13,2
2,13,13,13,8,8,8,13,0,13,13,67,0,64,31,0,0,0,13,13,57,2
2,13,13,8,13,8,8,64,64,13,64,13,64,13,13,0,22,13,13,0,0,2
1,2,13,13,13,13,13,13,0,13,64,13,13,13,13,64,64,0,57,13,2,1
1,2,13,13,13,13,13,13,0,13,64,13,13,64,13,0,0,0,0,57,2,1
2,13,13,13,13,13,13,13,13,13,64,13,13,64,13,0,13,0,13,13,2,1
2,13,13,13,13,13,13,13,13,13,13,13,13,64,13,0,13,0,13,2,2,2
2,0,0,13,13,13,13,13,13,13,0,13,13,0,13,0,13,0,2,2,2,2
2,2,2,13,13,2,2,2,2,2,0,2,0,0,0,2,2,2,2,2,2,2
2,2,2,2,2,2,1,1,1,1,2,2,2,2,2,2,2,2,2,2,2,2
endlayer

layer
2,2,2,2,2,2,2,2,2,2,2,2,2,2,2,2,2,2,2,2,2,2
2,2,2,2,2,2,2,13,13,13,13,13,13,13,13,2,2,2,2,2,2,2
2,2,2,2,2,2,13,8,8,13,13,13,13,0,0,2,13,13,2,2,2,2
2,2,2,13,13,13,8,8,13,13,13,13,13,13,13,13,13,13,13,2,2,2
2,2,14,13,14,13,8,8,13,13,8,8,8,8,8,13,8,13,13,13,2,2
2,2,14,14,8,8,8,8,13,13,8,64,8,8,13,8,8,8,13,13,13,2
2,13,8,8,8,8,8,8,13,8,8,64,5,5,64,64,8,8,13,13,13,2
2,13,8,8,8,8,8,8,64,13,13,67,13,64,13,13,13,13,13,13,13,2
2,14,8,8,13,8,8,8,64,8,64,13,64,8,8,13,13,13,13,13,2,2
2,13,13,8,8,8,8,8,13,8,8,8,8,64,8,64,13,13,13,13,2,2
2,2,13,8,8,8,8,8,13,8,64,8,13,64,13,13,13,13,13,2,2,2
2,2,13,13,8,13,8,8,13,8,8,8,64,64,8,13,13,13,13,13,2,2
2,2,2,13,13,13,8,13,13,8,8,8,8,8,8,13,13,13,13,2,2,2
2,2,2,2,13,13,13,13,13,13,13,5,13,0,13,13,13,13,2,2,2,2
2,2,2,2,2,13,13,13,13,13,13,13,13,0,2,2,2,2,2,2,2,2
2,2,2,2,2,2,2,2,2,2,2,2,2,2,2,2,2,2,2,2,2,2
endlayer

layer
13,13,13,13,13,13,13,13,13,13,13,13,13,13,13,13,13,13,13,13,13,13
13,13,14,13,13,13,14,8,8,13,13,13,13,14,13,13,13,13,13,13,13,13
13,13,14,13,13,13,8,8,8,14,13,13,14,14,14,8,8,8,13,13,13,13
13,13,14,8,8,8,8,8,8,13,13,13,13,13,13,8,8,13,13,13,13,13
13,14,8,8,8,13,8,8,8,13,13,13,14,14,13,8,8,13,13,13,13,13
13,13,8,8,8,8,8,8,8,13,13,64,13,13,13,8,8,8,8,8,13,13
13,8,8,8,8,8,8,8,13,64,64,64,13,64,64,8,8,8,13,13,14,13
13,8,8,8,8,8,8,8,64,64,13,67,13,64,13,8,8,8,8,14,14,13
13,8,8,8,13,8,8,8,13,13,64,64,64,64,13,8,8,8,8,14,13,13
13,14,8,8,8,8,8,8,8,13,13,64,13,64,13,64,8,8,8,13,13,13
13,14,8,8,8,8,8,8,8,13,64,64,64,13,8,8,8,8,13,13,13,13
13,13,8,8,8,13,8,8,8,13,13,13,64,13,13,13,8,13,13,14,13,13
13,13,13,13,8,8,8,8,8,13,13,13,13,13,13,13,8,14,14,13,13,13
13,13,13,13,8,8,8,8,8,13,13,13,13,13,13,13,14,13,14,13,13,13
13,13,13,13,14,8,8,13,13,13,13,13,13,13,14,13,13,14,13,13,13,13
13,13,14,13,13,13,13,13,13,13,13,14,13,13,13,13,13,13,13,13,13,13
endlayer

layer
13,13,14,14,14,14,14,14,13,13,14,14,14,14,13,13,14,14,14,13,13,13
13,14,8,14,8,14,8,8,8,14,14,14,13,8,14,8,8,14,8,14,13,13
13,14,8,8,8,8,8,8,8,8,14,14,8,8,8,8,8,8,8,8,13,13
14,14,8,8,8,8,8,8,8,8,8,14,14,8,8,8,8,8,8,8,14,14
14,8,8,8,8,14,8,8,8,8,10,10,8,8,8,8,8,8,8,8,8,14
14,8,8,8,8,8,8,8,8,10,64,64,64,8,8,8,8,8,8,8,14,13
14,8,8,8,8,8,8,8,10,64,64,64,64,64,8,8,8,8,8,8,8,14
14,8,8,8,8,8,8,8,64,64,64,61,64,64,13,8,8,8,8,8,8,14
13,8,8,8,14,8,8,8,10,64,64,64,64,64,8,8,8,8,8,8,14,13
13,8,8,8,8,8,8,8,8,64,64,64,64,64,8,8,8,8,8,8,14,13
14,8,8,8,8,8,8,8,8,10,64,14,14,14,8,8,8,8,8,14,14,13
14,14,8,8,8,14,8,8,8,8,8,8,14,14,8,8,8,8,8,8,14,14
14,14,14,8,8,8,8,8,8,8,8,8,13,10,10,8,8,8,8,14,13,13
14,14,8,8,8,8,8,8,8,8,8,8,8,8,10,10,8,8,8,14,14,13
13,14,14,14,8,8,8,8,8,8,8,14,14,8,8,14,14,8,14,14,13,13
14,13,0,14,14,14,13,13,14,14,13,0,13,14,14,13,13,14,14,13,14,13
endlayer

layer
14,14,0,69,0,0,68,69,14,14,0,0,69,0,14,14,68,0,0,14,14,13
14,0,0,70,0,69,0,0,0,0,0,0,14,0,0,0,0,69,0,70,14,14
14,68,0,0,0,0,0,0,0,0,0,69,0,0,0,0,0,0,0,0,14,13
69,0,0,0,0,0,0,0,0,0,0,0,70,0,0,0,0,0,71,0,68,0
69,0,0,0,0,70,0,0,0,0,21,21,0,0,71,0,0,0,0,0,0,69
0,0,71,0,0,0,71,0,0,21,64,64,64,0,0,0,0,0,0,0,0,14
68,0,0,0,0,0,0,0,21,64,10,31,22,64,0,0,0,71,0,0,0,70
0,0,0,0,0,0,0,0,22,64,29,66,64,64,0,0,0,0,0,0,0,0
14,0,0,0,70,0,0,0,21,64,0,10,0,64,0,0,0,0,71,0,69,14
14,0,0,0,0,0,71,0,0,31,64,64,64,31,0,0,0,0,0,0,0,14
0,0,0,0,0,0,0,0,0,21,31,69,31,69,0,0,71,0,0,68,0,14
69,0,0,71,0,70,0,0,0,0,0,0,0,0,0,71,0,0,0,0,69,69
0,68,0,0,0,0,0,0,0,0,71,0,10,21,21,0,0,0,0,0,14,14
70,0,0,0,0,0,0,71,0,0,0,0,0,0,21,21,0,0,71,0,69,14
14,69,70,68,0,0,0,0,0,0,0,69,0,0,0,70,0,0,68,70,14,14
69,14,0,0,69,0,14,14,70,0,14,0,14,0,69,14,14,0,0,14,68,14
endlayer

layer
70,0,0,0,0,0,0,0,0,70,0,0,0,0,0,70,0,0,0,69,0,14
0,0,0,73,0,0,0,0,0,0,0,0,68,0,0,0,0,0,0,72,0,0
0,0,0,0,0,0,0,0,0,0,0,0,0,0,0,0,0,0,0,0,0,14
0,0,0,0,0,0,0,0,0,0,0,0,72,0,0,0,0,0,0,0,0,0
0,0,0,0,0,73,0,0,0,0,0,32,0,0,0,0,0,0,0,0,0,0
0,0,0,0,0,0,0,0,0,74,64,64,64,0,0,0,0,0,0,0,0,0
0,0,0,0,0,0,0,0,0,64,21,31,22,64,0,0,0,0,0,0,0,72
0,0,0,0,0,0,0,0,22,64,29,29,22,64,0,0,0,0,0,0,0,0
68,0,0,0,75,0,0,0,0,64,64,21,64,64,0,0,0,0,0,0,0,0
0,0,0,0,0,0,0,0,0,31,64,64,64,31,0,0,0,0,0,0,0,0
0,0,0,0,0,0,0,0,0,0,31,0,31,0,0,0,0,0,0,0,0,69
0,0,0,0,0,72,0,0,0,0,0,0,0,0,0,0,0,0,0,0,0,0
0,0,0,0,0,0,0,0,0,0,0,0,21,0,0,0,0,0,0,0,0,70
76,0,0,0,0,0,0,0,0,0,0,0,0,0,0,0,0,0,0,0,0,0
0,0,75,0,0,0,0,0,0,0,0,0,0,0,0,75,0,0,0,75,0,68
0,0,0,0,0,0,68,0,76,0,69,0,70,0,0,0,70,0,0,0,0,0
endlayer

layer
73,0,0,0,0,0,0,0,0,72,0,0,0,0,0,72,0,0,0,0,0,70
0,0,0,0,0,0,0,0,0,0,0,0,0,0,0,0,0,0,0,0,0,0
0,0,0,0,0,0,0,0,0,0,0,0,0,0,0,0,0,0,0,0,0,69
0,0,0,0,0,0,0,0,0,0,0,0,0,0,0,0,0,0,0,0,0,0
0,0,0,0,0,0,0,0,0,0,0,0,0,0,0,0,0,0,0,0,0,0
0,0,0,0,0,0,0,0,0,32,0,64,64,0,0,0,0,0,0,0,0,0
0,0,0,0,0,0,0,0,0,64,64,31,22,64,0,0,0,0,0,0,0,0
0,0,0,0,0,0,0,0,22,64,29,29,61,64,0,0,0,0,0,0,0,0
0,0,0,0,0,0,0,0,0,31,64,74,64,31,0,0,0,0,0,0,0,0
0,0,0,0,0,0,0,0,0,0,31,64,64,0,0,0,0,0,0,0,0,0
0,0,0,0,0,0,0,0,0,0,0,57,0,0,0,0,0,0,0,0,0,0
0,0,0,0,0,0,0,0,0,0,0,0,0,0,0,0,0,0,0,0,0,0
0,0,0,0,0,0,0,0,0,0,0,0,0,0,0,0,0,0,0,0,0,72
0,0,0,0,0,0,0,0,0,0,0,0,0,0,0,0,0,0,0,0,0,0
0,0,0,0,0,0,0,0,0,0,0,0,0,0,0,0,0,0,0,0,0,0
0,0,0,0,0,0,0,0,0,0,0,0,75,0,0,0,75,0,0,0,0,0
endlayer

layer
0,0,0,0,0,0,0,0,0,0,0,0,0,0,0,0,0,0,0,0,0,72
0,0,0,0,0,0,0,0,0,0,0,0,0,0,0,0,0,0,0,0,0,0
0,0,0,0,0,0,0,0,0,0,0,0,0,0,0,57,0,0,0,0,0,0
0,0,0,0,0,0,0,0,0,0,0,0,0,0,0,0,0,0,0,0,0,0
0,0,0,0,0,0,0,0,0,0,0,0,0,0,0,0,0,0,0,0,0,0
0,0,0,0,0,0,0,0,0,0,0,64,0,0,0,0,0,0,0,0,0,0
0,0,0,0,0,0,0,0,0,32,64,31,64,0,0,0,0,0,0,0,0,0
0,0,0,0,0,0,57,0,0,64,29,29,61,64,0,0,0,0,0,0,0,0
0,0,0,0,0,0,0,0,0,31,64,74,64,31,0,0,0,0,0,0,0,0
0,0,0,0,0,0,0,0,0,0,0,64,64,0,0,0,0,0,0,0,0,0
0,0,0,0,0,0,0,0,0,0,0,57,0,0,0,0,0,0,0,0,0,0
0,0,0,0,0,0,0,0,0,0,0,0,0,0,0,0,0,0,0,0,0,0
0,0,0,0,0,0,0,0,0,0,0,0,0,0,0,0,0,0,0,0,0,0
0,0,0,0,0,0,0,0,0,0,0,0,0,0,0,0,0,0,0,0,0,0
0,0,0,0,0,0,0,0,0,0,0,0,0,0,0,0,0,0,0,0,0,0
0,0,0,0,0,0,0,0,0,0,0,0,0,0,0,0,0,0,0,0,0,0
endlayer

layer
0,0,0,0,0,0,0,0,0,0,0,0,0,0,0,0,0,0,0,0,0,0
0,0,0,0,0,0,0,0,0,0,0,0,0,0,0,0,0,0,0,0,0,0
0,0,0,0,0,0,0,0,0,0,0,0,0,0,0,57,0,0,0,0,0,0
0,0,0,0,0,0,0,0,0,0,0,0,0,0,57,0,0,0,0,0,0,0
0,0,0,0,0,0,0,0,0,0,0,0,0,0,0,0,0,0,0,0,0,0
0,0,0,0,0,0,0,0,0,0,57,64,0,0,0,0,0,0,0,0,0,0
0,0,0,0,0,0,0,0,0,32,64,31,64,0,0,0,0,0,0,0,0,0
0,0,0,0,0,0,57,57,0,64,29,29,61,64,57,0,0,0,0,0,0,0
0,0,0,0,0,0,0,0,0,31,64,74,64,31,0,0,0,0,0,0,0,0
0,0,0,0,0,0,0,0,0,0,0,64,57,0,0,0,0,0,0,0,0,0
0,0,0,0,0,0,0,0,0,0,0,57,0,0,0,0,0,0,0,0,0,0
0,0,0,0,0,0,0,0,0,0,0,0,0,0,0,0,0,0,0,0,0,0
0,0,0,0,0,0,0,0,0,0,0,0,0,0,0,0,0,0,0,0,0,0
0,0,0,0,0,0,0,0,0,0,0,0,0,0,0,0,0,0,0,0,0,0
0,0,0,0,0,0,0,0,0,0,0,0,0,0,0,0,0,0,0,0,0,0
0,0,0,0,0,0,0,0,0,0,0,0,0,0,0,0,0,0,0,0,0,0
endlayer

layer
0,0,0,0,0,0,0,0,0,0,0,0,0,0,0,0,0,0,0,0,0,0
0,0,0,0,0,0,0,0,0,0,0,0,0,0,0,0,0,0,0,0,0,0
0,0,0,0,0,0,0,0,0,0,57,0,0,0,0,57,0,0,0,0,0,0
0,0,0,0,0,0,0,0,0,0,0,0,0,0,57,0,0,0,0,0,0,0
0,0,0,0,0,0,0,0,0,0,0,0,0,0,0,0,0,0,0,0,0,0
0,0,0,0,0,0,0,0,0,0,57,64,0,0,57,0,0,0,0,0,0,0
0,0,0,0,0,0,0,0,0,32,64,31,64,64,64,0,0,0,0,0,0,0
0,0,0,0,0,0,57,57,64,64,0,29,61,64,57,0,0,0,0,0,0,0
0,0,0,0,0,0,0,0,0,31,64,22,64,31,0,0,0,0,0,0,0,0
0,0,0,0,0,0,0,0,0,0,0,0,0,0,0,0,0,0,0,0,0,0
0,0,0,0,0,0,0,0,0,0,0,0,0,0,0,0,0,0,0,0,0,0
0,0,0,0,0,0,0,0,0,0,0,0,0,0,0,0,0,0,0,0,0,0
0,0,0,0,0,0,0,0,0,0,0,0,0,0,0,0,0,0,0,0,0,0
0,0,0,0,0,0,0,0,0,0,0,0,0,0,0,0,0,0,0,0,0,0
0,0,0,0,0,0,0,0,0,0,0,0,0,0,0,0,0,0,0,0,0,0
0,0,0,0,0,0,0,0,0,0,0,0,0,0,0,0,0,0,0,0,0,0
endlayer

layer
0,0,0,0,0,0,0,0,0,0,0,0,0,0,0,0,0,0,0,0,0,0
0,0,0,0,0,0,0,0,0,0,0,0,0,0,0,0,0,0,0,0,0,0
0,0,0,0,0,0,0,0,0,0,57,0,0,0,0,64,0,0,0,0,0,0
0,0,0,0,0,0,0,0,0,0,0,0,0,0,64,64,0,0,0,0,0,0
0,0,0,0,0,0,0,0,0,0,64,0,0,0,64,0,0,0,0,0,0,0
0,0,0,0,0,0,0,0,0,0,64,64,0,0,64,0,0,0,0,0,0,0
0,0,0,0,0,0,0,0,0,0,64,31,64,0,64,0,0,0,0,0,0,0
0,0,0,0,0,0,57,64,64,22,64,29,31,0,0,0,0,0,0,0,0,0
0,0,0,0,0,0,0,0,0,0,0,0,0,0,0,0,0,0,0,0,0,0
0,0,0,0,0,0,0,0,0,0,0,0,0,0,0,0,0,0,0,0,0,0
0,0,0,0,0,0,0,0,0,0,0,0,0,0,0,0,0,0,0,0,0,0
0,0,0,0,0,0,0,0,0,0,0,0,0,0,0,0,0,0,0,0,0,0
0,0,0,0,0,0,0,0,0,0,0,0,0,0,0,0,0,0,0,0,0,0
0,0,0,0,0,0,0,0,0,0,0,0,0,0,0,0,0,0,0,0,0,0
0,0,0,0,0,0,0,0,0,0,0,0,0,0,0,0,0,0,0,0,0,0
0,0,0,0,0,0,0,0,0,0,0,0,0,0,0,0,0,0,0,0,0,0
endlayer

layer
0,0,0,0,0,0,0,0,0,0,0,0,0,0,0,0,0,0,0,0,0,0
0,0,0,0,0,0,0,0,0,0,0,0,0,0,0,0,0,0,0,0,0,0
0,0,0,0,0,0,0,0,0,0,57,0,0,0,0,0,0,0,0,0,0,0
0,0,0,0,0,0,0,0,0,0,64,0,0,0,0,0,0,0,0,0,0,0
0,0,0,0,0,0,0,0,0,0,64,0,0,0,0,0,0,0,0,0,0,0
0,0,0,0,0,0,0,0,0,0,0,0,0,0,0,0,0,0,0,0,0,0
0,0,0,0,0,0,0,0,0,0,0,0,60,0,0,0,0,0,0,0,0,0
0,0,0,0,0,0,57,64,0,0,0,0,0,0,0,0,0,0,0,0,0,0
0,0,0,0,0,0,0,0,0,0,0,0,0,0,0,0,0,0,0,0,0,0
0,0,0,0,0,0,0,0,0,0,0,0,0,0,0,0,0,0,0,0,0,0
0,0,0,0,0,0,0,0,0,0,0,0,0,0,0,0,0,0,0,0,0,0
0,0,0,0,0,0,0,0,0,0,0,0,0,0,0,0,0,0,0,0,0,0
0,0,0,0,0,0,0,0,0,0,0,0,0,0,0,0,0,0,0,0,0,0
0,0,0,0,0,0,0,0,0,0,0,0,0,0,0,0,0,0,0,0,0,0
0,0,0,0,0,0,0,0,0,0,0,0,0,0,0,0,0,0,0,0,0,0
0,0,0,0,0,0,0,0,0,0,0,0,0,0,0,0,0,0,0,0,0,0
endlayer

layer
0,0,0,0,0,0,0,0,0,0,0,0,0,0,0,0,0,0,0,0,0,0
0,0,0,0,0,0,0,0,0,0,0,0,0,0,0,0,0,0,0,0,0,0
0,0,0,0,0,0,0,0,0,0,64,0,0,0,0,0,0,0,0,0,0,0
0,0,0,0,0,0,0,0,0,0,64,0,0,0,0,0,0,0,0,0,0,0
0,0,0,0,0,0,0,0,0,0,0,0,0,0,0,0,0,0,0,0,0,0
0,0,0,0,0,0,0,0,0,0,0,0,0,0,0,0,0,0,0,0,0,0
0,0,0,0,0,0,0,0,0,0,0,0,0,0,0,0,0,0,0,0,0,0
0,0,0,0,0,0,57,64,0,0,0,0,0,0,0,0,0,0,0,0,0,0
0,0,0,0,0,0,0,0,0,0,0,0,0,0,0,0,0,0,0,0,0,0
0,0,0,0,0,0,0,0,0,0,0,0,0,0,0,0,0,0,0,0,0,0
0,0,0,0,0,0,0,0,0,0,0,0,0,0,0,0,0,0,0,0,0,0
0,0,0,0,0,0,0,0,0,0,0,0,0,0,0,0,0,0,0,0,0,0
0,0,0,0,0,0,0,0,0,0,0,0,0,0,0,0,0,0,0,0,0,0
0,0,0,0,0,0,0,0,0,0,0,0,0,0,0,0,0,0,0,0,0,0
0,0,0,0,0,0,0,0,0,0,0,0,0,0,0,0,0,0,0,0,0,0
0,0,0,0,0,0,0,0,0,0,0,0,0,0,0,0,0,0,0,0,0,0
endlayer

