# Dead Tree
# Created by Ruins mod version 14.6 Ingame Parser
# authoring Player: Jordan_Greywolf
# MC 1.7.10; 4 Jan 2015
# Last Updated: 29 Oct 2015
# Updated to MC 1.11: 13 Jan 2017
# Verified for MC 1.12: 23 Jun 2017
# Updated to MC 1.12.1: 10 Sep 2017

biomesToSpawnIn=swamp,swampland,swampland m,bog,mire,quagmire,wasteland,badlands,green swampland,green_swamp,lush swamp,lush_swamp,dead swamp,dead_swamp,ominous woods,thick ominous woods,eerie,dead forest,dead_forest,deadlands,dead woods,deadwood,thicket,fen,moor,bayou,eldritch,eerie,tainted land,tainted_land,silkglades,mutated_swampland

weight=1
embed_into_distance=6
acceptable_target_blocks=

unacceptable_target_blocks=flowing_lava,lava,cloud,Natura:Cloud,slime_congealed,slime_dirt,slime_grass,command_block,planks,planks2,concrete,cobblestone,stonebrick,brick_block,glass,torch,oak_stairs,stone_stairs,brick_stairs,stone_brick_stairs,nether_brick_stairs,sandstone_stairs,spruce_stairs,birch_stairs,jungle_stairs,quartz_stairs,acacia_stairs,dark_oak_stairs,cobblestone_wall,stone_slab,double_stone_slab,stone_slab2,wooden_slab,double_wooden_slab,nether_brick,fence

dimensions=15,9,10
allowable_overhang=0
max_leveling=6
leveling_buffer=-1
preserve_water=0
preserve_lava=0
preserve_plants=1

rule1=0,100,minecraft:log2-12
rule2=0,100,preserveBlock

layer
2,2,2,2,2,2,2,2,2,2
2,2,2,1,2,2,2,2,2,2
2,2,2,2,2,2,2,2,2,2
2,2,2,2,2,2,2,2,2,2
2,2,2,2,2,2,2,2,2,2
2,2,1,2,2,2,2,2,2,2
2,2,2,2,2,2,2,2,2,2
2,2,2,2,2,2,2,2,2,2
2,2,2,2,2,2,1,2,2,2
endlayer

layer
2,2,2,2,2,2,2,2,2,2
2,2,2,1,2,2,2,2,2,2
2,2,2,2,2,2,2,2,2,2
2,2,2,2,2,2,2,2,2,2
2,2,2,2,2,2,2,2,2,2
2,2,1,1,2,2,2,2,2,1
2,2,2,2,2,2,2,2,2,1
2,2,2,2,2,2,2,2,2,2
2,2,2,2,2,2,1,2,2,2
endlayer

layer
2,2,2,2,2,2,2,2,2,2
2,2,2,1,2,2,2,2,2,2
2,2,2,1,1,2,2,2,1,2
2,2,2,2,2,2,1,2,2,2
2,2,2,1,2,2,2,2,2,2
2,2,2,1,2,2,2,2,1,1
2,2,2,2,2,2,2,2,2,2
2,2,2,2,2,2,1,2,2,2
2,2,2,2,2,2,1,2,2,2
endlayer

layer
2,2,2,2,2,2,2,2,2,2
2,2,2,2,2,2,2,2,2,2
2,2,2,2,1,2,2,1,1,2
2,2,2,2,2,2,1,2,2,2
2,2,2,1,2,2,2,2,2,2
2,2,2,2,2,2,2,2,1,2
2,2,2,2,2,2,2,2,2,2
2,2,2,2,2,1,1,2,2,2
2,2,2,2,2,2,2,2,2,2
endlayer

layer
2,2,2,2,2,2,2,2,2,2
2,2,2,2,2,2,2,2,2,2
2,2,2,2,1,2,2,1,2,2
2,2,2,2,2,2,1,2,2,2
2,2,2,1,1,0,1,2,2,2
2,2,2,2,1,2,2,2,1,2
2,2,2,2,1,1,2,2,2,2
2,2,2,2,2,1,2,2,2,2
2,2,2,2,2,2,2,2,2,2
endlayer

layer
2,2,2,2,2,2,2,2,2,2
2,2,2,2,2,2,2,2,2,2
2,2,2,2,1,1,1,1,2,2
2,2,2,1,1,1,1,1,2,2
2,2,2,1,1,0,1,1,2,2
2,2,2,1,1,1,1,1,1,2
2,2,2,2,1,1,1,1,2,2
2,2,2,2,2,1,2,2,2,2
2,2,2,2,2,2,2,2,2,2
endlayer

layer
2,2,2,2,2,2,2,2,2,2
2,2,2,2,2,2,2,2,2,2
2,2,2,2,1,1,1,2,2,2
2,2,2,1,0,1,0,1,2,2
2,2,2,1,0,0,0,1,2,2
2,2,2,1,0,0,0,1,2,2
2,2,2,2,1,1,1,2,2,2
2,2,2,2,2,2,2,2,2,2
2,2,2,2,2,2,2,2,2,2
endlayer

layer
2,2,2,2,2,2,2,2,2,2
2,2,2,2,2,2,2,2,2,2
2,2,2,2,1,1,1,2,2,2
2,2,2,1,0,1,1,1,2,2
2,2,2,1,0,0,0,1,2,2
2,2,2,1,0,0,1,1,2,2
2,2,2,2,1,1,1,2,2,2
2,2,2,2,2,2,2,2,2,2
2,2,2,2,2,2,2,2,2,2
endlayer

layer
2,2,2,2,2,2,2,2,2,2
2,2,2,2,2,2,2,2,2,2
2,2,2,2,1,1,2,2,2,2
2,2,2,1,0,0,1,1,2,2
2,2,2,1,0,0,0,1,2,2
2,2,2,2,1,0,1,2,2,2
2,2,2,2,1,1,2,2,2,2
2,2,2,2,2,2,2,2,2,2
2,2,2,2,2,2,2,2,2,2
endlayer

layer
2,2,2,2,2,2,2,2,2,2
2,2,2,2,2,2,2,2,2,2
2,2,2,2,2,1,2,2,2,2
2,2,2,2,1,0,1,1,2,2
2,2,2,1,0,0,0,1,2,2
2,2,2,2,1,0,1,2,2,2
2,2,2,2,2,1,2,2,2,2
2,2,2,2,2,2,2,2,2,2
2,2,2,2,2,2,2,2,2,2
endlayer

layer
2,2,2,2,2,2,2,2,2,2
2,2,2,2,2,2,2,2,2,2
2,2,2,2,2,1,2,2,2,2
2,2,2,2,1,0,1,2,2,2
2,2,2,1,0,0,0,1,2,2
2,2,2,2,1,0,1,2,2,2
2,2,2,2,2,1,2,2,2,2
2,2,2,2,2,2,2,2,2,2
2,2,2,2,2,2,2,2,2,2
endlayer

layer
2,2,2,2,2,2,2,2,2,2
2,2,2,2,1,2,2,2,2,2
2,2,2,2,1,1,2,2,2,2
2,2,2,2,1,0,1,2,2,2
2,2,2,1,0,0,0,2,2,2
2,2,2,2,1,0,1,2,2,2
2,2,2,2,2,1,2,2,2,2
2,2,2,2,2,1,2,2,2,2
2,2,2,2,2,2,2,2,2,2
endlayer

layer
1,1,2,2,2,2,2,2,2,2
2,1,1,1,1,2,2,2,2,2
2,2,2,2,2,2,2,2,2,2
2,2,2,2,1,2,2,2,2,2
2,2,2,1,0,0,2,2,2,2
2,2,1,1,1,1,2,2,2,2
2,2,2,2,2,2,2,2,2,2
2,2,2,2,2,1,2,2,2,2
2,2,2,2,2,1,2,2,2,2
endlayer

layer
2,2,2,2,2,2,2,2,2,2
2,2,2,2,2,2,2,2,2,2
2,2,2,2,2,2,2,2,2,2
2,2,2,2,2,2,2,2,2,2
2,2,2,2,2,2,2,2,2,2
2,1,1,2,2,2,2,2,2,2
2,2,2,2,2,2,2,2,2,2
2,2,2,2,2,2,2,2,2,2
2,2,2,2,2,1,2,2,2,2
endlayer

layer
2,2,2,2,2,2,2,2,2,2
2,2,2,2,2,2,2,2,2,2
2,2,2,2,2,2,2,2,2,2
2,2,2,2,2,2,2,2,2,2
2,2,2,2,2,2,2,2,2,2
1,1,2,2,2,2,2,2,2,2
2,2,2,2,2,2,2,2,2,2
2,2,2,2,2,2,2,2,2,2
2,2,2,2,2,1,2,2,2,2
endlayer


