# Necromancer Hut
# MC 1.7.10; 24 Dec 2014
# Created by Ruins mod version 14.4 Ingame Parser
# authoring Player: Jordan_Greywolf

# Updated for MC 1.8: 5 Mar 2016
# Updated for MC 1.9: 29 Apr 2016
# Updated to MC 1.11: 13 Jan 2017
# Last Updated: 11 May 2017
# Verified for MC 1.12: 23 Jun 2017
# Updated to MC 1.12.1: 10 Sep 2017

# Thanks to MentalMouse42 for help with bug fixes.

weight=1
embed_into_distance=7
acceptable_target_blocks=

unacceptable_target_blocks=flowing_lava,lava,cloud,Natura:Cloud,slime_congealed,slime_dirt,slime_grass,command_block,planks,planks2,concrete,cobblestone,stonebrick,brick_block,glass,torch,oak_stairs,stone_stairs,brick_stairs,stone_brick_stairs,nether_brick_stairs,sandstone_stairs,spruce_stairs,birch_stairs,jungle_stairs,quartz_stairs,acacia_stairs,dark_oak_stairs,cobblestone_wall,stone_slab,double_stone_slab,stone_slab2,wooden_slab,double_wooden_slab,nether_brick,fence

dimensions=22,10,9
allowable_overhang=9999
max_leveling=7
leveling_buffer=-1
preserve_water=0
preserve_lava=0
preserve_plants=1

uniqueMinDistance=1000

biomesToSpawnIn=bayou,bog,crag,dead forest,dead_forest,dead swamp,dead_swamp,eerie,fen,fire swamp,fire_swamp,lush swamp,lush_swamp,mangrove,marsh,mire,moor,ominous woods,quagmire,sludgepit,swamp,swampland,swamplands,tainted land,thick ominous woods,wasteland,wetland,eldritch,rwg_jungle,rwg_tropical,mutated_swampland

rule1=0,100,preserveBlock
rule2=0,100,minecraft:ladder-4
rule3=0,100,minecraft:log-1
rule4=0,100,minecraft:planks-1
rule5=0,100,minecraft:dark_oak_fence-0

rule6=0,100,CommandBlock:RUINSTRIGGER /summon skeleton ~0 ~0 ~0 {HandItems:[{Count:1,id:bow,tag:{display:{Name:"Ribcage Bow",Lore:["Fashioned from reanimated ribs!"]},ench:[{id:49,lvl:12},{id:34,lvl:2}]}},{Count:8,id:tipped_arrow,tag:{Potion:"minecraft:strong_harming"}}],ArmorItems:[{Count:1,id:leather_boots},{Count:1,id:leather_leggings},{Count:1,id:leather_chestplate},{Count:1,id:lit_pumpkin,Count:1}],CustomName:"Bone Golem",HandDropChances:[0.5F,0.5F],ArmorDropChances:[0.3F,0.3F,0.3F,0.5F],ActiveEffects:[{Id:12,Amplifier:1,Duration:999999,Ambient:1},{Id:11,Amplifier:1,Duration:999999,Ambient:1}],PersistenceRequired:1}:@

rule7=0,100,minecraft:dark_oak_fence_gate-1
rule8=0,100,minecraft:dark_oak_door-2

rule9=0,100,IInventory;minecraft:chest;minecraft:bone#2#0#0+minecraft:arrow#32#0#1+minecraft:skull#1#3#2+minecraft:skull#1#4#3+minecraft:skull#2#2#4+minecraft:splash_potion#{Potion:"minecraft:strong_regeneration"}#0#5+minecraft:splash_potion#{Potion:"minecraft:strong_healing"}#0#6+minecraft:splash_potion#{Potion:"minecraft:long_weakness"}#0#7-3

# Villager: Necromancer
rule10=0,100,CommandBlock:RUINSTRIGGER /summon villager ~0 ~0 ~0 {Profession:2,Career:1,CareerLevel:6,CustomName:Necromancer,Offers:{Recipes:[{buy:{id:rotten_flesh,Count:16},sell:{id:leather,Count:12}},{buy:{id:bone,Count:32},sell:{id:emerald,Count:1}},{buy:{id:spider_eye,Count:32},sell:{id:emerald,Count:1}},{buy:{id:spawn_egg,Count:16},sell:{id:emerald,Count:1}},{buy:{id:emerald,Count:20},sell:{id:spawn_egg,Count:1,tag:{EntityTag:{id:Villager,Health:60.0f},display:{Name:"Reanimated Villager"}}}},{buy:{id:emerald,Count:1},sell:{id:spawn_egg,Count:4,tag:{EntityTag:{id:Zombie,IsVillager:1,Health:50.0f,ArmorItems:[{},{},{},{id:skull,Damage:3,tag:{SkullOwner:MHF_Villager}}]},display:{Name:"Failed Experiment"}}}},{buy:{id:emerald,Count:32},sell:{id:spawn_egg,Count:1,tag:{EntityTag:{id:Sheep,CustomName:"jeb_",Health:60.0f},display:{Name:"Chromatic Sheep"}}}},{buy:{id:emerald,Count:32},sell:{id:spawn_egg,Count:1,tag:{EntityTag:{id:Rabbit,RabbitType:99,CustomName:"Vorpal Bunny",Health:50.0f},display:{Name:"Vorpal Bunny"}}}},{buy:{id:emerald,Count:20},sell:{id:spawn_egg,Count:1,tag:{EntityTag:{id:Skeleton_Horse,Tame:1,PersistenceRequired:1,Health:100.0f},display:{Name:"Reanimated Steed"}}}},{buy:{id:emerald,Count:24},buyB:{id:iron_shovel,Count:1},sell:{id:iron_shovel,Count:1,tag:{display:{Name:"Gravedigger"},ench:[{id:33,lvl:1},{id:16,lvl:5},{id:34,lvl:5}]}}}]}}:@

rule11=0,100,IInventory;minecraft:lit_furnace;minecraft:coal#2#1#1-3

rule12=0,100,CommandBlock:RUINSTRIGGER /gamerule commandBlockOutput false:@

rule13=1,100,minecraft:torch-5
rule14=0,100,minecraft:skull,minecraft:skull-1,minecraft:skull-2,minecraft:skull-3,minecraft:skull-4
rule15=0,100,minecraft:dark_oak_door-8
rule16=0,100,minecraft:cobblestone_wall-0
rule17=0,100,minecraft:spruce_stairs-6
rule18=0,100,minecraft:spruce_stairs-4
rule19=0,100,minecraft:spruce_stairs-7
rule20=0,100,minecraft:log-9
rule21=0,100,minecraft:log-5
rule22=0,100,minecraft:spruce_stairs-5
rule23=0,100,minecraft:tripwire_hook-0
rule24=0,100,minecraft:crafting_table-0
rule25=0,100,minecraft:redstone_wire-0
rule26=2,100,minecraft:torch-1
rule27=2,100,minecraft:torch-2
rule28=0,100,minecraft:spruce_stairs-2
rule29=0,100,minecraft:spruce_stairs-0
rule30=0,100,minecraft:spruce_stairs-3
rule31=0,100,minecraft:spruce_stairs-1
rule32=0,100,minecraft:wooden_slab-1

layer
1,1,1,1,1,1,1,1,1
1,1,1,1,3,1,1,1,1
1,1,1,1,1,1,1,1,1
1,3,1,1,1,1,1,3,1
1,1,1,1,1,1,1,1,1
1,1,1,1,1,1,1,1,1
1,1,1,1,1,1,1,1,1
1,1,1,1,1,1,1,1,1
1,3,1,1,1,1,1,3,1
1,1,1,1,1,1,1,1,1
endlayer

layer
1,1,1,1,1,1,1,1,1
1,1,1,1,3,1,1,1,1
1,1,1,1,1,1,1,1,1
1,3,1,1,1,1,1,3,1
1,1,1,1,1,1,1,1,1
1,1,1,1,1,1,1,1,1
1,1,1,1,1,1,1,1,1
1,1,1,1,1,1,1,1,1
1,3,1,1,1,1,1,3,1
1,1,1,1,1,1,1,1,1
endlayer

layer
1,1,1,1,1,1,1,1,1
1,1,1,1,3,1,1,1,1
1,1,1,1,1,1,1,1,1
1,3,1,1,1,1,1,3,1
1,1,1,1,1,1,1,1,1
1,1,1,1,1,1,1,1,1
1,1,1,1,1,1,1,1,1
1,1,1,1,1,1,1,1,1
1,3,1,1,1,1,1,3,1
1,1,1,1,1,1,1,1,1
endlayer

layer
1,1,1,1,1,1,1,1,1
1,1,1,1,3,1,1,1,1
1,1,1,1,1,1,1,1,1
1,3,1,1,1,1,1,3,1
1,1,1,1,1,1,1,1,1
1,1,1,1,1,1,1,1,1
1,1,1,1,1,1,1,1,1
1,1,1,1,1,1,1,1,1
1,3,1,1,1,1,1,3,1
1,1,1,1,1,1,1,1,1
endlayer

layer
1,1,1,1,1,1,1,1,1
1,1,1,1,3,1,1,1,1
1,1,1,1,1,1,1,1,1
1,3,1,1,1,1,1,3,1
1,1,1,1,1,1,1,1,1
1,1,1,1,1,1,1,1,1
1,1,1,1,1,1,1,1,1
1,1,1,1,1,1,1,1,1
1,3,1,1,1,1,1,3,1
1,1,1,1,1,1,1,1,1
endlayer

layer
1,1,1,1,1,1,1,1,1
1,1,1,1,3,1,1,1,1
1,1,1,1,1,1,1,1,1
1,3,1,1,1,1,1,3,1
1,1,1,1,1,1,1,1,1
1,1,1,1,1,1,1,1,1
1,1,1,1,1,1,1,1,1
1,1,1,1,1,1,1,1,1
1,3,1,1,1,1,1,3,1
1,1,1,1,1,1,1,1,1
endlayer

layer
1,1,1,1,1,1,1,1,1
1,1,1,1,3,1,1,1,1
1,1,1,1,1,1,1,1,1
1,3,1,1,1,1,1,3,1
1,1,1,1,1,1,1,1,1
1,1,1,1,1,1,1,1,1
1,1,1,1,1,1,1,1,1
1,1,1,1,1,1,1,1,1
1,3,1,1,1,1,1,3,1
1,1,1,1,1,1,1,1,1
endlayer

layer
1,1,1,1,1,1,1,1,1
1,1,1,1,3,1,1,1,1
1,1,1,1,1,1,1,1,1
1,3,1,1,1,1,1,3,1
1,1,1,1,1,1,1,1,1
1,1,1,1,1,1,1,1,1
1,1,1,1,1,1,1,1,1
1,1,1,1,1,1,1,1,1
1,3,1,1,1,1,1,3,1
1,1,1,1,1,1,1,1,1
endlayer

layer
1,1,1,1,2,1,1,1,1
1,1,1,1,3,1,1,1,1
1,1,1,1,1,1,1,1,1
1,3,1,1,1,1,1,3,1
1,1,1,1,1,1,1,1,1
1,1,1,1,1,1,1,1,1
1,1,1,1,1,1,1,1,1
1,1,1,1,1,1,1,1,1
1,3,1,1,1,1,1,3,1
1,1,1,1,1,1,1,1,1
endlayer

layer
1,1,1,1,2,1,1,1,1
1,1,1,1,3,1,1,1,1
1,1,1,1,1,1,1,1,1
1,3,1,1,1,1,1,3,1
1,1,1,1,1,1,1,1,1
1,1,1,1,1,1,1,1,1
1,1,1,1,1,1,1,1,1
1,1,1,1,1,1,1,1,1
1,3,1,1,1,1,1,3,1
1,1,1,1,1,1,1,1,1
endlayer


layer
4,4,4,4,2,4,4,4,4
4,4,4,4,4,4,4,4,4
4,4,4,4,4,4,4,4,4
4,3,4,4,4,4,4,3,4
4,4,4,4,4,4,4,4,4
4,4,4,4,4,4,4,4,4
4,4,4,4,4,4,4,4,4
4,4,4,4,4,4,4,4,4
4,3,4,4,4,4,4,3,4
4,4,4,4,4,4,4,4,4
endlayer

layer
5,5,5,5,0,5,5,5,5
5,6,0,5,7,5,0,6,5
5,0,0,0,0,0,0,0,5
5,3,4,4,4,8,4,3,5
5,4,10,0,0,0,9,4,5
5,4,0,0,0,0,0,4,5
5,4,0,0,0,0,0,4,5
5,4,12,0,0,0,11,4,5
5,3,4,4,4,4,4,3,5
5,5,5,5,5,5,5,5,5
endlayer

layer
13,0,0,14,0,14,0,0,13
0,0,0,13,0,13,0,0,0
0,0,0,0,0,0,0,0,0
14,3,4,5,4,15,4,3,14
0,4,0,0,0,0,0,4,0
0,5,0,0,0,0,0,5,0
0,5,0,0,0,0,0,5,0
0,4,2,0,0,0,16,4,0
14,3,4,5,4,5,4,3,14
13,14,0,0,0,0,0,16,13
endlayer

layer
0,0,0,0,0,0,0,0,0
0,0,0,0,0,0,0,0,0
0,0,0,0,0,0,0,0,0
0,3,4,4,4,4,4,3,0
0,4,0,0,0,0,0,4,0
0,4,0,0,0,0,0,4,0
0,4,0,0,0,0,0,4,0
0,4,2,0,0,0,13,4,0
0,3,4,4,4,4,4,3,0
0,0,0,0,0,0,0,16,0
endlayer

layer
0,0,0,0,0,0,0,0,0
0,0,0,0,0,0,0,0,0
0,0,19,18,18,18,17,0,0
0,3,20,20,20,20,20,3,0
18,21,4,4,4,4,4,21,18
19,21,4,4,4,4,4,21,17
19,21,4,4,4,4,4,21,17
22,21,2,4,4,4,4,21,22
0,3,20,20,20,20,20,3,0
0,0,19,22,22,22,17,16,0
endlayer

layer
0,0,0,0,0,0,0,0,0
0,0,0,0,0,0,0,0,0
0,0,5,5,5,5,5,0,0
0,3,4,4,4,4,4,3,0
5,4,0,0,17,19,23,4,5
5,4,0,0,0,0,0,4,5
5,4,0,0,0,0,14,4,5
5,4,0,0,0,0,24,4,5
0,3,4,4,4,4,4,3,0
0,0,5,5,5,5,5,16,0
endlayer

layer
0,0,0,0,0,0,0,0,0
0,0,0,0,0,0,0,0,0
0,0,13,0,14,0,13,0,0
0,3,4,5,4,5,4,3,0
13,4,0,0,25,14,23,4,13
0,5,0,0,0,0,0,5,0
0,5,0,0,0,0,0,5,0
13,4,0,0,0,0,25,4,13
0,3,4,5,4,5,4,3,0
0,0,13,0,14,0,13,16,0
endlayer

layer
0,0,0,0,0,0,0,0,0
0,0,0,0,0,0,0,0,0
0,0,0,0,0,0,0,0,0
0,3,4,4,4,4,4,3,0
0,4,0,0,26,0,0,4,0
0,4,0,0,0,0,0,4,0
0,4,0,0,0,0,0,4,0
0,4,0,0,27,0,0,4,0
0,3,4,4,4,4,4,3,0
0,0,0,0,0,0,0,16,0
endlayer

layer
0,0,0,0,0,0,0,0,0
0,0,0,0,0,0,0,0,0
30,29,29,29,29,29,29,29,28
30,3,20,20,20,20,20,3,28
30,21,0,0,0,0,0,21,28
30,21,0,0,0,0,0,21,28
30,21,0,0,0,0,0,21,28
30,21,0,0,0,0,0,21,28
30,3,20,20,20,20,20,3,28
30,31,31,31,31,31,31,16,28
endlayer

layer
0,0,0,0,0,0,0,0,0
0,0,0,0,0,0,0,0,0
14,0,0,0,0,0,0,0,14
0,29,29,29,29,29,29,29,0
0,22,22,22,22,22,22,22,0
0,5,0,0,0,0,0,5,0
0,5,0,0,0,0,0,5,0
0,18,18,18,18,18,18,18,0
0,31,31,31,31,31,31,31,0
14,0,0,0,0,0,0,16,14
endlayer

layer
0,0,0,0,0,0,0,0,0
0,0,0,0,0,0,0,0,0
0,0,0,0,0,0,0,0,0
0,0,0,0,0,0,0,0,0
0,29,29,29,29,29,29,29,0
0,22,22,22,22,22,22,22,0
0,18,18,18,18,18,18,18,0
0,31,31,31,31,31,31,31,0
0,0,0,0,0,0,0,0,0
0,0,0,0,0,0,0,16,0
endlayer

layer
0,0,0,0,0,0,0,0,0
0,0,0,0,0,0,0,0,0
0,0,0,0,0,0,0,0,0
0,0,0,0,0,0,0,0,0
0,0,0,0,0,0,0,0,0
0,28,32,32,32,32,32,30,0
0,28,32,32,32,32,32,30,0
0,0,0,0,0,0,0,0,0
0,0,0,0,0,0,0,0,0
0,0,0,0,0,0,0,16,0
endlayer

