
# Witch Hut (2 Apr 2014; MC 1.5.*)
# Updated to MC 1.7.10, 10 Oct 2014
# authoring Player: Jordan_Greywolf (based on Vanilla Witch Hut)
# Last Updated: 14 Nov 2015
# Updated to MC 1.8: 5 Mar 2016
# Updated to MC 1.9: 30 Apr 2016
# Updated to MC 1.11: 13 Jan 2017
# Verified for MC 1.12: 23 Jun 2017
# Updated to MC 1.12.1: 10 Sep 2017

biomesToSpawnIn=bayou,bog,dead swamp,dead_swamp,dreadlands,fen,fire swamp,green swampland,green_swamp,lush swamp,lush_swamp,marsh,ominous woods,quagmire,sludgepit,swamp,swampland,swampland m,wetlands,rwg_riveroasis,mutated_swampland

weight=1
embed_into_distance=10


unacceptable_target_blocks=lava,flowing_lava,cloud,Natura:Cloud,slime_congealed,slime_dirt,slime_grass,command_block,planks,planks2,concrete,cobblestone,stonebrick,brick_block,glass,torch,oak_stairs,stone_stairs,brick_stairs,stone_brick_stairs,nether_brick_stairs,sandstone_stairs,spruce_stairs,birch_stairs,jungle_stairs,quartz_stairs,acacia_stairs,dark_oak_stairs,cobblestone_wall,stone_slab,double_stone_slab,stone_slab2,wooden_slab,double_wooden_slab,nether_brick,fence

dimensions=16,10,7
allowable_overhang=0
max_cut_in=0
cut_in_buffer=0
max_leveling=5
leveling_buffer=-1
preserve_water=0
preserve_lava=0
preserve_plants=1

# Terrain Blending
rule01=0,100,preserveBlock

# Log/Wood (Oak - U/D)
rule02=0,100,minecraft:log-0

# Spruce Plank
rule03=0,100,minecraft:planks-1

# Fence
rule04=0,100,minecraft:fence

# Crafting Table (Workbench)
rule05=0,100,minecraft:crafting_table

# flower_pot (random content)
rule06=0,100,teBlock;minecraft:flower_pot;{Item:"minecraft:red_mushroom",x:0,y:0,z:0,Data:0,id:"flower_pot"}-0,teBlock;minecraft:flower_pot;{Item:"minecraft:tallgrass",x:0,y:0,z:0,Data:0,id:"flower_pot"}-0,teBlock;minecraft:flower_pot;{Item:"minecraft:brown_mushroom",x:0,y:0,z:0,Data:0,id:"flower_pot"}-0,teBlock;minecraft:flower_pot;{Item:"minecraft:cactus",x:0,y:0,z:0,Data:0,id:"flower_pot"}-0

# Cauldron
rule07=0,100,minecraft:cauldron-1

# Spruce Stairs
rule08=0,100,minecraft:spruce_stairs-0
rule09=0,100,minecraft:spruce_stairs-1
rule10=0,100,minecraft:spruce_stairs-2
rule11=0,100,minecraft:spruce_stairs-3

# Ladder
rule12=2,100,minecraft:ladder-4

# Witch Spawner
rule13=0,100,CommandBlock:RUINSTRIGGER /summon witch ~0 ~0 ~0 {HandItems:[{},{Count:1,id:wooden_shovel,tag:{display:{Name:"Witch Broom"},ench:[{id:20,lvl:2},{id:19,lvl:5},{id:33,lvl:1},{id:34,lvl:3}]}},{},{},{},{}],CustomName:Bog Witch,AbsorptionAmount:5,Health:50.0f,HandDropChances:[1.0F,1.0F],PersistenceRequired:1}:@

# Chest
rule14=0,100,ChestGenHook:chests/simple_dungeon:3

#
# Layout
# 

# Supports (-10)
layer
01,01,01,01,01,01,01
01,01,01,01,01,01,01
01,01,01,01,01,01,01
01,02,01,01,01,02,01
01,01,01,01,01,01,01
01,01,01,01,01,01,01
01,01,01,01,01,01,01
01,01,01,01,01,01,01
01,02,01,01,01,02,01
01,01,01,01,01,01,01
endlayer


# Supports (-9)
layer
01,01,01,01,01,01,01
01,01,01,01,01,01,01
01,01,01,01,01,01,01
01,02,01,01,01,02,01
01,01,01,01,01,01,01
01,01,01,01,01,01,01
01,01,01,01,01,01,01
01,01,01,01,01,01,01
01,02,01,01,01,02,01
01,01,01,01,01,01,01
endlayer


# Supports (-8)
layer
01,01,01,01,01,01,01
01,01,01,01,01,01,01
01,01,01,01,01,01,01
01,02,01,01,01,02,01
01,01,01,01,01,01,01
01,01,01,01,01,01,01
01,01,01,01,01,01,01
01,01,01,01,01,01,01
01,02,01,01,01,02,01
01,01,01,01,01,01,01
endlayer


# Supports (-7)
layer
01,01,01,01,01,01,01
01,01,01,01,01,01,01
01,01,01,01,01,01,01
01,02,01,01,01,02,01
01,01,01,01,01,01,01
01,01,01,01,01,01,01
01,01,01,01,01,01,01
01,01,01,01,01,01,01
01,02,01,01,01,02,01
01,01,01,01,01,01,01
endlayer


# Supports (-6)
layer
01,01,01,01,01,01,01
01,01,01,01,01,01,01
01,01,01,01,01,01,01
01,02,01,01,01,02,01
01,01,01,01,01,01,01
01,01,01,01,01,01,01
01,01,01,01,01,01,01
01,01,01,01,01,01,01
01,02,01,01,01,02,01
01,01,01,01,01,01,01
endlayer

# Supports (-5)
layer
01,01,01,01,01,01,01
01,01,01,01,01,01,01
01,01,01,01,01,01,01
01,02,01,01,01,02,01
01,01,01,01,01,01,01
01,01,01,01,01,01,01
01,01,01,01,01,01,01
01,01,01,01,01,01,01
01,02,01,01,01,02,01
01,01,01,01,01,01,01
endlayer


# Supports (-4)
layer
01,01,01,01,01,01,01
01,01,01,01,01,01,01
01,01,01,01,01,01,01
01,02,01,01,01,02,01
01,01,01,01,01,01,01
01,01,01,01,01,01,01
01,01,01,01,01,01,01
01,01,01,01,01,01,01
01,02,01,01,01,02,01
01,01,01,01,01,01,01
endlayer


# Supports (-3)
layer
01,01,01,01,01,01,01
01,01,01,01,01,01,01
01,01,01,01,01,01,01
01,02,01,01,01,02,01
01,01,01,01,01,01,01
01,01,01,01,01,01,01
01,01,01,01,01,01,01
01,01,01,01,01,01,01
01,02,01,01,01,02,01
01,01,01,01,01,01,01
endlayer


# Supports (-2)
layer
01,01,01,01,01,01,01
01,01,01,01,01,01,01
01,01,01,01,01,01,01
01,02,01,01,01,02,01
01,01,01,01,01,01,01
01,01,01,01,01,01,01
01,01,01,01,01,01,01
01,01,01,01,01,01,01
01,02,01,01,01,02,01
01,01,01,01,01,01,01
endlayer


# Supports (-1)
layer
01,01,01,01,01,01,01
01,01,01,01,01,01,01
01,01,01,01,01,01,01
01,02,01,01,01,02,01
01,01,01,01,01,01,01
01,01,01,01,01,01,01
01,01,01,01,01,01,01
01,01,01,01,01,01,01
01,02,01,01,01,02,01
01,01,01,01,01,01,01
endlayer

# Supports (+1)
layer
01,01,01,12,01,01,01
01,01,01,03,01,01,01
01,01,01,01,01,01,01
01,02,01,01,01,02,01
01,01,01,01,01,01,01
01,01,01,01,01,01,01
01,01,01,01,01,01,01
01,01,01,01,01,01,01
01,02,01,01,01,02,01
01,01,01,01,01,01,01
endlayer

# Supports (+2)
layer
01,01,00,12,00,01,01
01,01,00,03,00,01,01
01,00,00,00,00,00,01
00,02,00,00,00,02,00
00,00,00,00,00,00,00
00,00,00,00,00,00,00
00,00,00,00,00,00,00
00,00,00,00,00,00,00
01,02,00,00,00,02,01
01,01,00,00,00,01,01
endlayer

# Floor (+3)
layer
01,00,00,12,00,00,01
00,00,03,03,03,00,00
00,03,03,03,03,03,00
00,02,03,03,03,02,00
00,03,03,03,03,03,00
00,03,03,03,03,03,00
00,03,03,03,03,03,00
00,03,03,03,03,03,00
00,02,03,03,03,02,00
01,00,00,00,00,00,01
endlayer

# Lower Interior (+4)
layer
00,00,00,00,00,00,00
00,00,00,00,00,00,00
00,04,00,00,00,04,00
00,02,03,03,00,02,00
00,03,00,00,00,03,00
00,03,00,13,00,03,00
00,03,00,00,00,03,00
00,03,07,05,14,03,00
00,02,03,03,03,02,00
00,00,00,00,00,00,00
endlayer

# Upper Interior (+5)
layer
00,00,00,00,00,00,00
00,00,00,00,00,00,00
00,00,00,00,00,00,00
00,02,00,03,00,02,00
00,03,00,00,00,03,00
00,00,00,00,00,00,00
00,00,00,00,00,06,00
00,03,00,00,00,03,00
00,02,03,04,03,02,00
00,00,00,00,00,00,00
endlayer

# Roof (+6)
layer
00,00,00,00,00,00,00
00,00,00,00,00,00,00
08,08,08,08,08,08,08
11,03,03,03,03,03,10
11,03,03,03,03,03,10
11,03,03,03,03,03,10
11,03,03,03,03,03,10
11,03,03,03,03,03,10
11,03,03,03,03,03,10
09,09,09,09,09,09,09
endlayer



