# Ziggurat Island
# Originally 9 Apr 2014; updated to MC 1.7.10, 13 Oct 2014
# Updated with Command Blocks, 12 Jan 2015
# Created by Ruins mod version 14.7 Ingame Parser
# authoring Player: Jordan_Greywolf

# Updated to MC 1.8: 5 Mar 2016
# Updated to MC 1.9: 30 Apr 2016
# Updated to MC 1.11: 13 Jan 2017
# Verified for MC 1.12: 23 Jun 2017
# Updated to MC 1.12.1: 10 Sep 2017

biomesToSpawnIn=bayou,beach,bog,gravel beach,gravel_beach,forested island,jungle,stone beach,stone_beach,swampland,marsh,swampland m,dead swamp,dead_swamp,lush swamp,lush_swamp,tropical jungle,jungle m,jungle extreme,extreme jungle,jungle m,tropics,tropical rainforest,tropical_rainforest,tropical_island,mutated_swampland

uniqueMinDistance=1000

weight=1
embed_into_distance=18

acceptable_target_blocks=stone,dirt,grass,sand,gravel,water,flowing_water,clay,sandstone

unacceptable_target_blocks=
dimensions=50,36,36
allowable_overhang=500
max_leveling=7
leveling_buffer=-1
preserve_water=0
preserve_lava=0
preserve_plants=1

rule1=0,100,preserveBlock
rule2=0,100,minecraft:grass-0
rule3=0,100,minecraft:dirt-0
rule4=0,100,minecraft:stone-0

# Rare Ore
rule5=0,100,minecraft:gold_ore,minecraft:diamond_ore,minecraft:emerald_ore,minecraft:gold_ore,minecraft:emerald_ore
rule6=0,100,minecraft:vine-2
rule7=0,100,minecraft:vine-1
rule8=0,100,minecraft:vine-4
rule9=0,100,minecraft:vine-8
rule10=0,100,minecraft:vine-12
rule11=0,100,minecraft:vine-5
rule12=0,100,minecraft:vine-3
rule13=0,100,minecraft:vine-0
rule14=0,100,minecraft:vine-10
rule15=0,100,minecraft:vine-9
rule16=0,100,minecraft:vine-14
rule17=0,100,minecraft:vine-6
rule18=0,100,minecraft:vine-13
rule19=0,100,MobSpawner:Cave_Spider
rule20=0,100,CommandBlock:/effect @p[r=3] 9:@,CommandBlock:/effect @p[r=3] 15:@,CommandBlock:/effect @p[r=3] 17:@
rule21=0,100,minecraft:stonebrick-3,minecraft:stonebrick-3,minecraft:stonebrick-3,minecraft:stonebrick-3,minecraft:monster_egg-5
rule22=0,100,minecraft:stonebrick-0,minecraft:stonebrick-0,minecraft:stonebrick-0,minecraft:stonebrick-0,minecraft:monster_egg-2
rule23=0,100,minecraft:stonebrick-2,minecraft:stonebrick-2,minecraft:stonebrick-2,minecraft:stonebrick-2,minecraft:monster_egg-4
rule24=0,100,minecraft:stonebrick-1,minecraft:stonebrick-1,minecraft:stonebrick-1,minecraft:stonebrick-1,minecraft:monster_egg-3
rule25=0,100,minecraft:vine-7
rule26=0,100,minecraft:water-11
rule27=0,100,minecraft:stone_slab-5
rule28=0,100,minecraft:stone_slab-13
rule29=0,100,minecraft:log-15
rule30=0,100,minecraft:stone_pressure_plate-0
rule31=0,100,minecraft:redstone_wire-0
rule32=0,100,minecraft:water-0
rule33=0,100,minecraft:tripwire_hook-4
rule34=0,100,minecraft:tripwire-4
rule35=0,100,minecraft:tripwire_hook-6
rule36=0,100,ChestGenHook:chests/jungle_temple:3-4
rule37=0,100,minecraft:water-13
rule38=0,100,minecraft:water-1
rule39=0,100,minecraft:tripwire_hook-7
rule40=0,100,minecraft:water-2
rule41=0,100,ChestGenHook:chests/jungle_temple:3-2
rule42=0,100,minecraft:water-3
rule43=0,100,ChestGenHook:chests/jungle_temple:3-3
rule44=0,100,minecraft:tripwire_hook-5
rule45=0,100,ChestGenHook:chests/jungle_temple:3-5
rule46=0,100,minecraft:cobblestone_wall-1
rule47=0,100,minecraft:stone_brick_stairs-4
rule48=0,100,minecraft:stone_brick_stairs-6
rule49=0,100,minecraft:stone_brick_stairs-7
rule50=0,100,minecraft:stone_brick_stairs-5
rule51=1,100,minecraft:redstone_torch-5
rule52=2,100,WallSign:null:null:null:null-3
rule53=2,100,WallSign:null:null:null:null-2
rule54=2,100,WallSign:null:null:null:null-5
rule55=0,100,minecraft:lava-0
rule56=2,100,WallSign:null:null:null:null-4
rule57=0,100,minecraft:tallgrass-1,minecraft:tallgrass-1,minecraft:tallgrass-2
rule58=0,100,minecraft:leaves-7
rule59=0,100,minecraft:stone_brick_stairs-0
rule60=0,100,minecraft:stone_brick_stairs-1
rule61=0,100,minecraft:stone_brick_stairs-2
rule62=0,100,minecraft:stone_brick_stairs-3
rule63=0,100,minecraft:cocoa-11
rule64=0,100,minecraft:cocoa-10
rule65=0,100,minecraft:water-4
rule66=0,100,minecraft:water-5
rule67=0,100,minecraft:cocoa-8
rule68=0,100,minecraft:cocoa-9
rule69=0,100,Skull:0:9-1

layer
1,1,1,1,1,1,1,1,1,1,3,3,1,1,2,3,3,3,2,3,2,1,1,1,1,1,3,1,1,2,1,1,1,1,1,1
1,1,1,1,1,1,1,1,1,3,3,3,3,4,4,4,4,4,4,4,3,1,1,1,3,4,4,4,3,3,2,3,1,1,1,1
1,1,1,1,1,1,1,2,4,4,4,4,4,4,4,4,4,4,4,4,4,4,3,4,4,4,4,4,4,4,4,4,2,1,1,1
1,1,1,1,1,1,3,4,4,4,4,4,4,4,4,4,4,4,4,4,4,4,4,4,4,4,4,4,4,4,4,4,4,3,1,1
1,1,1,1,1,2,4,4,4,4,4,4,4,4,4,4,4,4,4,4,4,4,4,4,4,4,4,4,4,4,4,4,4,4,1,1
1,1,1,1,2,4,4,4,4,4,4,4,4,4,4,4,4,4,4,4,4,4,4,4,4,4,4,4,4,4,4,4,4,4,1,1
1,1,1,2,4,4,4,4,4,4,4,4,4,4,4,4,4,4,4,4,4,4,4,4,4,4,4,4,4,4,4,4,4,4,1,1
1,1,1,2,4,4,4,4,4,4,4,4,4,4,4,4,4,4,4,4,4,4,4,4,4,4,4,4,4,4,4,4,4,4,1,1
1,1,1,4,4,4,4,4,4,4,4,4,4,4,4,4,4,4,4,4,4,4,4,4,4,4,4,4,4,4,4,4,4,4,1,1
1,1,2,4,4,4,4,4,4,4,4,4,4,4,4,4,4,4,4,4,4,4,4,4,4,4,4,4,4,4,4,4,4,4,1,1
1,2,4,4,4,4,4,4,4,4,4,4,4,4,4,4,4,4,4,4,4,4,4,4,4,4,4,4,4,4,4,4,4,3,1,1
1,4,4,4,4,4,4,4,4,4,4,4,4,4,4,4,4,4,4,4,4,4,4,4,4,4,4,4,4,4,4,4,4,3,1,1
1,2,2,4,4,4,4,4,4,4,4,4,4,5,4,4,4,4,4,4,4,4,4,4,4,4,4,4,4,4,4,4,4,4,4,3
1,1,1,4,4,4,4,4,4,4,4,4,4,4,4,4,4,4,4,4,4,4,4,4,4,4,4,4,4,4,4,4,4,4,4,3
1,1,1,2,4,4,4,4,4,4,4,4,4,4,4,4,4,4,4,4,4,4,4,4,4,4,4,4,4,4,4,4,4,4,4,3
1,1,1,4,4,4,4,4,4,4,4,4,4,4,4,4,4,4,4,4,4,4,4,4,4,4,4,4,4,4,4,4,4,4,4,1
1,1,1,1,3,4,4,4,4,4,4,4,4,4,4,4,4,4,4,4,4,4,4,4,4,4,4,4,4,4,4,4,4,4,3,1
1,1,1,1,4,4,4,4,4,4,4,4,4,4,4,4,4,4,4,4,4,4,4,4,4,4,4,4,4,4,4,4,4,4,3,1
1,1,1,2,4,4,4,4,4,4,4,4,4,4,4,4,4,4,4,4,4,4,4,4,4,4,4,4,4,4,4,4,4,4,2,1
1,1,1,2,4,4,4,4,4,4,4,4,4,4,4,4,4,4,4,4,4,4,4,4,4,4,4,4,4,4,4,4,4,4,1,1
1,1,2,4,4,4,4,4,4,4,4,4,4,4,4,4,4,4,4,4,4,4,4,4,4,4,4,4,4,4,4,4,4,3,1,1
1,2,4,4,4,4,4,4,4,4,4,4,4,4,4,4,4,4,4,4,4,4,4,4,4,4,4,4,4,4,4,4,4,3,1,1
2,4,4,4,4,4,4,4,4,4,4,4,4,4,4,4,4,4,4,4,4,4,4,4,4,4,4,4,4,4,4,4,4,3,1,1
2,4,4,4,4,4,4,4,0,4,4,4,4,4,4,4,4,4,4,4,4,4,4,4,4,4,4,4,4,4,4,4,4,3,1,1
1,1,4,4,4,4,4,4,4,4,4,4,4,4,4,4,4,4,4,4,4,4,4,4,4,4,4,4,4,4,4,4,4,3,1,1
1,1,2,4,4,4,4,4,4,4,4,4,4,4,4,4,5,4,4,4,4,4,4,4,4,4,4,4,4,4,4,4,4,3,3,1
1,1,1,3,4,4,4,4,4,4,4,4,4,4,4,4,4,4,4,4,4,4,4,4,4,4,4,4,4,4,4,4,4,3,1,1
1,1,1,2,4,4,4,4,4,4,4,4,4,4,4,4,4,4,4,4,4,4,4,4,4,4,4,4,4,4,4,4,4,3,1,1
1,1,1,1,2,4,4,4,4,4,4,4,4,4,4,4,4,4,4,4,4,4,4,4,4,4,4,4,4,4,4,4,3,3,1,1
1,1,1,1,1,2,4,4,4,4,4,4,4,4,4,4,4,4,4,4,4,4,4,4,4,4,4,4,4,4,3,3,3,1,1,1
1,1,1,1,1,1,3,4,4,4,4,4,4,4,4,4,4,4,4,4,4,4,4,4,4,4,4,4,4,3,3,3,1,1,1,1
1,1,1,1,1,1,1,1,3,4,3,1,4,4,4,4,4,4,4,4,4,4,4,4,4,4,4,4,4,3,3,1,1,1,1,1
1,1,1,1,1,1,1,1,1,3,1,1,1,4,4,4,3,4,4,4,4,4,3,4,4,4,4,4,3,1,1,1,1,1,1,1
1,1,1,1,1,1,1,1,1,1,1,1,1,1,1,3,1,1,1,3,4,2,1,3,4,4,4,3,1,1,1,1,1,1,1,1
1,1,1,1,1,1,1,1,1,1,1,1,1,1,1,1,1,1,1,1,3,1,1,1,2,4,2,1,1,1,1,1,1,1,1,1
1,1,1,1,1,1,1,1,1,1,1,1,1,1,1,1,1,1,1,1,1,1,1,1,1,3,1,1,1,1,1,1,1,1,1,1
endlayer

layer
1,1,1,1,1,1,1,1,1,1,1,1,1,1,1,3,3,3,1,2,1,1,1,1,1,1,2,1,1,1,1,1,1,1,1,1
1,1,1,1,1,1,1,1,1,1,3,3,3,4,4,4,4,4,4,4,3,1,1,1,2,3,4,3,2,3,1,2,1,1,1,1
1,1,1,1,1,1,1,1,3,4,4,4,4,4,4,4,4,4,4,4,4,3,3,3,4,4,4,4,4,4,4,3,1,1,1,1
1,1,1,1,1,1,3,4,4,4,4,4,4,4,4,4,4,4,4,4,4,4,4,4,4,4,4,4,4,4,4,4,4,2,1,1
1,1,1,1,1,1,4,4,4,4,4,4,4,4,4,4,4,4,4,4,4,4,4,4,4,4,4,4,4,4,4,4,4,4,1,1
1,1,1,1,1,4,4,4,4,4,4,4,4,7,6,4,4,4,4,4,4,4,4,4,4,4,4,4,4,4,4,4,4,4,1,1
1,1,1,1,3,4,4,4,4,4,4,4,4,0,0,4,4,4,4,4,4,4,4,4,4,4,4,4,4,4,4,4,4,4,1,1
1,1,1,1,4,4,4,4,4,4,4,4,4,4,0,4,4,4,4,4,4,4,4,4,4,4,4,4,4,4,4,4,4,4,1,1
1,1,1,2,4,4,4,4,4,4,4,4,4,4,7,0,0,0,0,0,4,4,4,4,4,4,4,4,4,4,4,4,4,4,1,1
1,1,1,4,4,4,4,4,4,4,4,4,4,0,0,0,0,0,0,0,0,0,6,6,6,0,4,4,4,4,4,4,4,4,1,1
1,1,3,4,4,4,4,4,4,4,4,4,4,4,0,0,4,4,4,4,0,0,0,8,4,4,4,4,4,4,4,4,4,3,1,1
1,3,4,4,4,4,4,4,4,4,4,4,4,4,7,0,0,4,4,4,4,4,0,0,0,0,4,4,4,4,4,4,4,3,1,1
1,1,1,4,4,4,4,4,4,4,4,4,0,6,4,9,9,4,4,4,4,4,4,0,0,0,0,4,4,4,4,4,4,4,4,1
1,1,1,3,4,4,4,4,4,4,4,4,4,0,4,4,4,4,4,4,4,4,4,4,4,9,0,4,4,4,4,4,4,4,4,3
1,1,1,1,4,4,4,4,4,4,4,4,4,4,4,4,4,4,4,4,4,4,4,4,4,4,0,0,4,4,4,4,4,4,4,1
1,1,1,2,4,4,4,4,4,4,4,4,4,4,4,4,4,4,4,4,4,4,4,4,4,4,4,0,6,0,4,4,4,4,4,1
1,1,1,1,2,4,4,4,4,4,4,4,4,4,4,4,4,4,4,4,4,4,4,4,4,4,4,0,4,4,4,4,4,4,3,1
1,1,1,1,3,4,4,4,4,4,4,4,4,4,4,4,4,4,4,4,4,4,4,4,4,4,4,0,0,4,4,4,4,4,3,1
1,1,1,1,4,4,4,4,4,4,4,4,4,4,4,4,4,0,4,4,4,4,4,4,4,4,4,8,4,4,4,4,4,4,1,1
1,1,1,1,4,4,4,4,4,4,4,4,4,4,4,0,0,0,4,4,4,4,4,0,0,0,0,10,4,4,4,4,4,4,1,1
1,1,1,4,4,4,4,4,4,4,4,4,4,0,0,0,4,4,4,4,4,4,0,0,9,4,11,4,4,4,4,4,4,3,1,1
1,1,4,4,4,4,4,4,4,4,4,4,4,0,7,4,4,4,4,4,4,0,0,0,4,4,0,0,4,4,4,4,4,3,1,1
1,4,4,4,4,4,4,4,4,4,4,4,0,0,4,4,4,4,4,4,0,0,0,4,4,4,0,8,4,4,4,4,4,3,1,1
1,3,4,4,4,4,4,4,4,4,4,4,4,0,4,4,4,4,4,0,0,0,4,4,4,4,9,8,4,4,4,4,4,3,1,1
1,1,4,4,4,4,4,4,4,4,4,0,7,0,0,0,7,0,0,0,0,4,4,4,4,4,4,4,4,4,4,4,4,3,1,1
1,1,1,4,4,4,4,4,4,4,4,4,4,4,4,0,9,9,9,4,4,4,4,4,4,4,4,4,4,4,4,4,4,3,1,1
1,1,1,2,4,4,4,4,4,4,4,4,4,4,4,4,4,4,4,4,4,4,4,4,4,4,4,4,4,4,4,4,4,3,1,1
1,1,1,1,4,4,4,4,4,4,4,4,4,4,4,4,4,4,4,4,4,4,4,4,4,4,4,4,4,4,4,4,4,3,1,1
1,1,1,1,1,4,4,4,4,4,4,4,4,4,4,4,4,4,4,4,4,4,4,4,4,4,4,4,4,4,4,4,3,3,1,1
1,1,1,1,1,1,4,4,4,4,4,4,4,4,4,4,4,4,4,4,4,4,4,4,4,4,4,4,4,4,3,3,3,1,1,1
1,1,1,1,1,1,2,4,4,4,4,4,4,4,4,4,4,4,4,4,4,4,4,4,4,4,4,4,4,3,3,3,1,1,1,1
1,1,1,1,1,1,1,1,3,4,2,1,4,4,4,4,4,4,4,4,4,4,4,4,4,4,4,4,3,3,3,1,1,1,1,1
1,1,1,1,1,1,1,1,1,2,1,1,1,3,4,4,3,3,4,4,4,4,2,4,4,4,4,4,3,1,1,1,1,1,1,1
1,1,1,1,1,1,1,1,1,1,1,1,1,1,1,3,1,1,1,3,4,1,1,2,4,4,4,2,1,1,1,1,1,1,1,1
1,1,1,1,1,1,1,1,1,1,1,1,1,1,1,1,1,1,1,1,2,1,1,1,1,3,1,1,1,1,1,1,1,1,1,1
1,1,1,1,1,1,1,1,1,1,1,1,1,1,1,1,1,1,1,1,1,1,1,1,1,2,1,1,1,1,1,1,1,1,1,1
endlayer

layer
1,1,1,1,1,1,1,1,1,1,1,1,1,1,1,3,3,2,1,1,1,1,1,1,1,1,1,1,1,1,1,1,1,1,1,1
1,1,1,1,1,1,1,1,1,1,1,1,3,4,4,4,4,4,4,4,2,1,1,1,1,3,4,2,1,2,1,1,1,1,1,1
1,1,1,1,1,1,1,1,3,4,4,1,4,4,4,4,4,4,4,4,3,3,2,3,4,4,4,4,4,4,2,2,1,1,1,1
1,1,1,1,1,1,3,4,4,4,4,4,4,4,4,4,4,4,4,4,4,4,4,4,4,4,4,4,4,4,4,4,4,1,1,1
1,1,1,1,1,1,4,4,4,4,4,4,4,4,0,4,4,4,4,4,4,4,4,4,4,4,4,4,4,4,4,4,4,4,1,1
1,1,1,1,1,3,4,4,4,4,4,4,4,7,0,4,4,4,4,4,4,4,4,4,4,4,4,4,4,4,4,4,4,4,1,1
1,1,1,1,2,4,4,4,4,4,4,4,4,0,0,0,0,4,4,4,4,4,4,4,4,0,0,0,4,4,4,4,4,4,1,1
1,1,1,1,4,4,4,4,4,4,4,4,4,7,0,0,0,0,0,0,0,4,4,4,5,0,0,4,4,4,4,4,4,4,1,1
1,1,1,1,4,4,4,4,4,4,4,4,0,0,0,0,0,0,0,0,0,0,4,0,0,0,0,4,4,4,4,4,4,4,1,1
1,1,1,4,4,4,4,4,4,4,4,4,0,0,0,0,0,0,0,0,0,0,6,0,0,8,4,4,4,4,4,4,4,4,1,1
1,1,2,4,4,4,4,4,4,4,4,4,4,4,0,0,0,0,0,0,0,0,0,0,0,0,0,4,4,4,4,4,4,3,1,1
1,3,4,4,4,4,4,4,4,4,4,4,4,4,12,0,0,0,0,4,0,0,0,0,0,0,0,0,4,4,4,4,4,3,1,1
1,1,1,3,4,4,4,4,4,4,4,4,0,6,0,8,0,0,4,4,0,4,0,0,0,0,0,8,4,4,4,4,4,4,4,1
1,1,1,2,4,4,4,4,4,4,4,0,0,0,0,0,0,4,4,4,4,4,4,0,0,0,0,0,0,0,4,4,4,4,4,3
1,1,1,1,4,4,4,4,4,4,4,4,4,0,0,4,4,4,4,4,4,4,4,0,0,0,0,0,0,0,4,4,4,4,4,1
1,1,1,1,4,4,4,4,4,4,4,4,4,4,4,4,4,4,4,4,4,4,4,4,7,13,0,0,6,0,0,0,0,4,4,1
1,1,1,1,1,4,4,4,4,4,4,4,4,4,4,4,4,4,0,4,4,4,4,4,4,0,0,9,8,0,4,4,4,4,3,1
1,1,1,1,2,4,4,4,4,4,4,4,4,4,4,6,0,5,4,4,4,4,4,4,4,4,0,0,0,0,4,4,4,4,3,1
1,1,1,1,3,4,4,4,4,4,4,4,4,4,0,0,0,0,4,4,4,4,0,0,0,0,0,0,0,4,4,4,4,4,1,1
1,1,1,1,4,4,4,4,4,4,4,4,4,7,0,0,0,0,4,4,4,0,0,6,0,0,0,0,0,4,4,4,4,4,1,1
1,1,1,4,4,4,4,4,4,4,4,4,0,0,0,6,0,0,4,0,0,0,0,0,9,0,0,0,0,5,4,4,4,3,1,1
1,1,4,4,4,4,4,4,4,4,4,0,0,0,7,0,0,4,0,0,0,0,0,0,4,0,0,0,0,4,4,4,4,3,1,1
1,3,4,4,4,4,4,4,4,4,4,0,0,0,0,0,4,5,4,0,0,0,0,0,4,0,0,0,0,4,4,4,4,3,1,1
1,2,4,4,4,4,4,4,4,4,4,0,0,0,0,0,0,0,0,0,0,0,0,4,4,0,0,8,0,4,4,4,4,3,1,1
1,1,3,4,4,4,4,4,4,4,9,13,7,0,0,0,7,0,0,0,0,0,0,4,4,0,0,0,0,4,4,4,4,3,1,1
1,1,1,3,4,4,4,4,4,4,4,7,0,0,0,0,9,9,0,0,0,0,4,4,4,4,0,4,0,14,4,4,4,3,1,1
1,1,1,1,4,4,4,4,4,4,4,4,4,4,0,0,0,0,0,0,5,4,4,4,4,4,4,4,7,4,4,4,4,3,1,1
1,1,1,1,3,4,4,4,4,4,4,4,4,4,4,4,0,0,0,0,4,4,4,4,4,4,4,4,4,4,4,4,4,3,1,1
1,1,1,1,1,4,4,4,4,4,4,4,4,4,4,4,4,4,4,4,4,4,4,4,4,4,4,4,4,4,4,4,3,3,1,1
1,1,1,1,1,1,4,4,4,4,4,4,4,4,4,4,4,4,4,4,4,4,4,4,4,4,4,4,4,4,3,3,3,1,1,1
1,1,1,1,1,1,1,4,4,4,4,4,4,4,4,4,4,4,4,4,4,4,4,4,4,4,4,4,4,3,3,3,1,1,1,1
1,1,1,1,1,1,1,1,2,4,1,1,3,4,4,4,4,4,4,4,4,4,3,4,4,4,4,4,3,3,3,1,1,1,1,1
1,1,1,1,1,1,1,1,1,1,1,1,1,3,4,4,3,3,3,4,4,3,1,4,4,4,4,3,3,1,1,1,1,1,1,1
1,1,1,1,1,1,1,1,1,1,1,1,1,1,1,3,1,1,1,2,4,1,1,1,3,4,4,1,1,1,1,1,1,1,1,1
1,1,1,1,1,1,1,1,1,1,1,1,1,1,1,1,1,1,1,1,1,1,1,1,1,3,1,1,1,1,1,1,1,1,1,1
1,1,1,1,1,1,1,1,1,1,1,1,1,1,1,1,1,1,1,1,1,1,1,1,1,1,1,1,1,1,1,1,1,1,1,1
endlayer

layer
1,1,1,1,1,1,1,1,1,1,1,1,1,1,1,2,2,1,1,1,1,1,1,1,1,1,1,1,1,1,1,1,1,1,1,1
1,1,1,1,1,1,1,1,1,1,1,1,3,4,4,4,4,4,4,2,1,1,1,1,1,2,3,1,1,1,1,1,1,1,1,1
1,1,1,1,1,1,1,1,3,3,4,1,4,4,4,4,4,4,4,4,3,3,1,3,4,4,4,4,4,3,1,1,1,1,1,1
1,1,1,1,1,1,2,3,4,4,4,1,4,4,4,4,4,4,4,4,4,4,4,4,4,4,4,4,4,4,4,4,3,1,1,1
1,1,1,1,1,1,4,4,4,4,4,4,4,4,4,4,4,4,4,4,4,4,4,4,4,4,4,4,4,4,4,4,4,4,1,1
1,1,1,1,1,2,4,4,4,4,4,4,4,0,6,4,4,4,4,4,4,4,4,4,4,4,4,4,4,4,4,4,4,4,1,1
1,1,1,1,1,4,4,4,4,4,4,4,4,7,13,4,4,4,4,4,4,4,4,4,4,4,4,4,4,4,4,4,4,4,1,1
1,1,1,1,3,4,4,4,4,4,4,4,4,4,4,4,4,4,4,4,4,4,4,4,4,4,4,6,8,4,4,4,4,4,1,1
1,1,1,1,4,4,4,4,4,4,4,4,4,4,4,4,4,4,4,4,4,4,4,4,4,4,4,7,8,4,4,4,4,4,1,1
1,1,1,2,4,4,4,4,4,4,4,4,4,4,4,4,4,4,4,4,4,4,4,4,4,4,4,7,9,4,4,4,4,4,1,1
1,1,1,4,4,4,4,4,4,4,4,4,4,4,4,4,4,4,4,4,4,4,4,4,4,4,4,4,4,4,4,4,4,3,1,1
1,2,3,4,4,4,4,4,4,4,4,4,4,7,6,4,4,4,4,4,4,4,4,4,4,4,4,4,4,4,4,4,4,1,1,1
1,1,1,2,4,4,4,4,4,4,4,4,4,0,9,8,4,4,4,4,4,4,4,4,4,4,4,4,4,4,4,4,4,4,4,1
1,1,1,1,4,4,4,4,4,4,4,4,4,4,4,4,4,4,4,4,4,4,4,4,4,4,4,4,4,4,4,4,4,4,4,3
1,1,1,1,4,4,4,4,4,4,4,4,4,4,4,4,4,4,4,4,4,4,4,4,4,4,4,7,4,4,4,4,4,4,4,1
1,1,1,1,3,4,4,4,4,4,4,4,4,4,4,4,4,5,4,4,4,4,4,4,4,4,4,0,6,0,0,0,0,4,4,1
1,1,1,1,1,4,4,4,4,4,4,4,4,4,4,4,4,5,4,4,4,4,4,4,4,4,4,9,8,4,4,4,4,4,3,1
1,1,1,1,1,4,4,4,4,4,4,4,4,4,4,4,4,4,4,4,4,4,4,4,4,4,4,4,4,4,4,4,4,4,2,1
1,1,1,1,2,4,4,4,4,4,4,4,4,4,4,4,4,4,4,4,4,4,0,4,4,4,4,6,0,4,4,4,4,4,1,1
1,1,1,1,4,4,4,4,4,4,4,4,4,4,4,4,4,4,4,4,4,0,0,6,0,0,6,0,0,4,4,4,4,4,1,1
1,1,1,4,4,4,4,4,4,4,4,4,4,4,0,6,6,4,4,4,4,0,0,0,4,4,4,4,4,4,4,4,4,3,1,1
1,1,3,4,4,4,4,4,4,4,0,4,4,4,7,9,0,4,4,4,4,4,4,4,4,6,6,4,4,4,4,4,4,3,1,1
1,3,4,4,4,4,4,4,4,4,4,4,4,4,4,4,4,4,4,4,4,4,4,4,4,0,0,0,4,4,4,4,4,3,1,1
1,1,3,4,4,4,4,4,4,4,4,4,4,4,4,4,4,4,4,4,4,4,4,4,4,0,0,8,4,4,4,4,4,3,1,1
1,1,2,3,4,4,4,4,4,4,4,4,7,13,4,4,7,13,8,4,4,4,4,4,4,4,4,0,0,4,4,4,4,3,1,1
1,1,1,3,4,4,4,4,4,4,4,4,4,5,4,4,9,9,0,4,4,4,4,4,4,4,4,4,7,14,4,4,4,3,1,1
1,1,1,1,3,4,4,4,4,4,4,4,4,4,4,4,4,4,4,4,4,4,4,4,4,4,4,4,7,4,4,4,4,3,1,1
1,1,1,1,3,4,4,4,4,4,4,4,4,4,4,4,4,4,4,4,4,4,4,4,4,4,4,4,4,4,4,4,4,3,1,1
1,1,1,1,1,3,4,4,4,4,4,4,4,4,4,4,4,4,4,4,4,4,4,4,4,4,4,4,4,4,4,3,3,2,1,1
1,1,1,1,1,1,4,4,4,4,4,4,4,4,4,4,4,4,4,4,4,4,4,4,4,4,4,4,4,4,3,3,3,1,1,1
1,1,1,1,1,1,1,4,4,4,4,4,4,4,4,4,4,4,4,4,4,4,4,4,4,4,4,4,3,3,3,2,1,1,1,1
1,1,1,1,1,1,1,1,1,4,1,1,3,4,4,4,4,4,4,4,4,3,3,4,4,4,4,4,3,3,2,1,1,1,1,1
1,1,1,1,1,1,1,1,1,1,1,1,1,3,3,4,1,3,3,4,4,3,1,4,4,4,4,3,2,1,1,1,1,1,1,1
1,1,1,1,1,1,1,1,1,1,1,1,1,1,1,1,1,1,1,1,3,1,1,1,3,4,3,1,1,1,1,1,1,1,1,1
1,1,1,1,1,1,1,1,1,1,1,1,1,1,1,1,1,1,1,1,1,1,1,1,1,3,1,1,1,1,1,1,1,1,1,1
1,1,1,1,1,1,1,1,1,1,1,1,1,1,1,1,1,1,1,1,1,1,1,1,1,1,1,1,1,1,1,1,1,1,1,1
endlayer

layer
1,1,1,1,1,1,1,1,1,1,1,1,1,1,1,1,1,1,1,1,1,1,1,1,1,1,1,1,1,1,1,1,1,1,1,1
1,1,1,1,1,1,1,1,1,1,1,1,1,4,4,4,4,4,3,1,1,1,1,1,1,1,2,1,1,1,1,1,1,1,1,1
1,1,1,1,1,1,1,1,2,3,3,1,4,4,4,4,4,4,4,3,3,2,1,2,4,4,4,4,3,2,1,1,1,1,1,1
1,1,1,1,1,1,1,3,4,4,4,1,1,4,4,4,4,4,4,4,4,4,3,4,4,4,4,4,4,4,4,3,2,1,1,1
1,1,1,1,1,1,4,4,4,4,4,1,1,4,4,4,4,4,4,4,4,4,4,4,4,4,4,4,4,4,4,4,4,4,1,1
1,1,1,1,1,1,4,4,4,4,4,4,4,5,4,4,4,4,4,4,4,4,4,4,4,4,4,4,0,0,0,4,4,4,1,1
1,1,1,1,1,3,4,4,4,4,4,4,4,4,4,4,4,4,4,4,4,4,4,4,4,4,4,0,0,0,9,4,4,4,1,1
1,1,1,1,2,4,4,4,4,4,4,4,4,4,4,4,4,4,4,4,4,4,4,4,4,4,4,0,0,8,4,4,4,4,1,1
1,1,1,1,3,4,4,4,4,4,4,4,4,4,4,4,4,4,4,4,4,4,4,4,4,4,0,0,0,0,4,4,4,4,1,1
1,1,1,1,4,4,4,4,4,4,4,4,4,4,4,4,4,4,4,4,4,4,4,4,4,4,7,0,9,4,4,4,4,4,1,1
1,1,1,2,4,4,4,4,4,4,4,4,4,12,0,8,4,4,4,4,4,4,4,4,4,4,4,7,4,4,4,4,4,1,1,1
1,1,2,4,4,4,4,4,4,4,4,4,4,7,0,0,0,4,4,4,4,4,4,4,4,4,4,4,4,4,4,4,4,1,1,1
1,1,1,1,4,4,4,4,4,4,4,4,4,4,9,0,0,6,6,0,8,4,4,4,4,4,4,4,4,4,4,4,4,4,4,1
1,1,1,1,4,4,4,4,4,4,4,4,4,4,4,4,15,8,4,0,0,4,4,4,4,4,4,4,4,4,4,4,4,4,4,1
1,1,1,1,3,4,4,4,4,4,4,4,4,4,4,4,4,4,0,0,0,4,4,4,4,4,4,4,4,4,4,4,4,4,4,1
1,1,1,1,2,4,4,4,4,4,4,4,4,4,4,4,4,0,0,0,4,4,4,4,4,4,4,4,4,4,4,6,0,1,4,1
1,1,1,1,1,1,1,1,1,4,4,4,4,4,4,4,0,0,0,9,4,4,4,4,4,4,4,4,4,4,4,4,4,4,3,1
1,1,1,1,1,4,4,4,4,4,4,4,4,4,4,7,0,0,0,4,4,4,4,4,4,4,4,4,4,4,4,4,4,4,1,1
1,1,1,1,1,4,4,4,4,4,4,4,4,4,4,0,8,4,4,4,4,4,4,4,4,4,4,4,4,4,4,4,4,4,1,1
1,1,1,1,2,4,4,4,4,4,4,4,4,4,4,4,8,4,4,4,4,4,4,4,4,4,4,4,4,4,4,4,4,4,1,1
1,1,1,2,4,4,4,4,4,4,4,4,4,4,4,4,4,4,4,4,4,4,4,4,4,4,4,4,4,4,4,4,4,3,1,1
1,1,2,4,4,4,4,4,4,4,4,4,4,4,4,4,4,4,4,4,4,4,4,4,4,4,4,4,4,4,4,4,4,3,1,1
1,2,3,4,4,4,4,4,4,4,4,4,4,4,4,4,4,4,4,4,4,4,4,4,4,4,4,4,4,4,4,4,4,3,1,1
1,1,2,4,4,4,4,4,4,4,4,4,4,4,4,4,4,4,4,4,4,4,4,4,4,4,4,0,4,4,4,4,4,3,1,1
1,1,1,3,4,4,4,4,4,4,4,4,4,4,4,4,4,4,4,4,4,4,4,4,4,4,4,0,0,4,4,4,4,3,1,1
1,1,1,2,3,4,4,4,4,4,4,4,4,4,4,4,4,4,4,4,4,4,4,4,4,4,4,0,0,9,4,4,4,3,1,1
1,1,1,1,3,4,4,4,4,4,4,4,4,4,4,4,4,4,4,4,4,4,4,4,4,4,4,4,15,4,4,4,4,3,1,1
1,1,1,1,3,4,4,4,4,4,4,4,4,4,4,4,4,4,4,4,4,4,4,4,4,4,4,4,4,4,4,4,4,3,1,1
1,1,1,1,1,3,4,4,4,4,4,4,4,4,4,4,4,4,4,4,4,4,4,4,4,4,4,4,4,4,4,3,3,1,1,1
1,1,1,1,1,1,3,4,4,4,4,4,4,4,4,4,4,4,4,4,4,4,4,4,4,4,4,4,4,4,3,3,2,1,1,1
1,1,1,1,1,1,1,4,4,4,4,3,4,4,4,4,4,4,4,4,4,3,4,4,4,4,4,4,3,3,2,1,1,1,1,1
1,1,1,1,1,1,1,1,1,3,1,1,3,4,4,4,4,4,4,4,4,3,3,4,4,4,4,3,3,2,1,1,1,1,1,1
1,1,1,1,1,1,1,1,1,1,1,1,1,3,2,3,1,3,3,3,4,3,1,3,4,4,4,3,1,1,1,1,1,1,1,1
1,1,1,1,1,1,1,1,1,1,1,1,1,1,1,1,1,1,1,1,3,1,1,1,3,4,2,1,1,1,1,1,1,1,1,1
1,1,1,1,1,1,1,1,1,1,1,1,1,1,1,1,1,1,1,1,1,1,1,1,1,2,1,1,1,1,1,1,1,1,1,1
1,1,1,1,1,1,1,1,1,1,1,1,1,1,1,1,1,1,1,1,1,1,1,1,1,1,1,1,1,1,1,1,1,1,1,1
endlayer

layer
1,1,1,1,1,1,1,1,1,1,1,1,1,1,1,1,1,1,1,1,1,1,1,1,1,1,1,1,1,1,1,1,1,1,1,1
1,1,1,1,1,1,1,1,1,1,1,1,1,4,4,4,4,4,2,1,1,1,1,1,1,1,1,1,1,1,1,1,1,1,1,1
1,1,1,1,1,1,1,1,1,2,3,4,4,4,4,4,4,4,4,3,2,1,1,1,4,4,4,4,2,1,1,1,1,1,1,1
1,1,1,1,1,1,1,3,3,4,4,1,1,4,4,4,4,4,4,4,4,4,3,4,4,4,4,4,4,4,3,2,1,1,1,1
1,1,1,1,1,1,4,4,4,4,4,1,1,1,4,4,4,4,4,4,4,4,4,4,4,4,4,4,4,5,4,4,4,3,1,1
1,1,1,1,1,1,4,4,4,4,4,1,1,1,1,1,4,4,4,4,4,4,4,4,4,4,4,4,0,0,0,4,4,4,1,1
1,1,1,1,1,3,4,4,4,4,4,4,1,1,1,1,4,4,4,4,4,4,4,4,4,4,4,0,0,0,0,0,4,4,1,1
1,1,1,1,1,4,4,4,4,4,4,4,4,1,1,1,4,4,4,4,4,4,4,4,4,4,4,0,0,9,9,4,4,4,1,1
1,1,1,1,3,4,4,4,4,4,4,4,4,4,4,4,4,4,4,4,4,4,4,4,4,4,0,0,0,4,4,4,4,4,1,1
1,1,1,1,3,4,4,4,4,4,4,4,6,4,4,4,4,4,4,4,4,4,4,4,4,0,0,0,0,4,4,4,4,4,1,1
1,1,1,1,3,4,4,4,4,4,4,7,0,6,0,8,4,4,4,4,4,4,4,4,0,0,0,0,4,4,4,4,4,1,1,1
1,1,1,3,4,4,4,4,4,4,0,0,0,0,0,0,0,0,6,0,4,4,4,4,7,0,0,4,4,4,4,4,4,1,1,1
1,1,1,1,3,4,4,4,4,4,7,0,4,4,0,0,0,0,0,0,8,4,4,4,4,7,9,4,4,4,4,4,4,4,4,1
1,1,1,1,4,4,4,4,4,4,4,4,4,4,4,7,9,8,4,0,0,0,4,4,4,4,4,4,4,4,4,4,4,4,4,1
1,1,1,1,3,4,4,4,1,1,4,4,4,4,4,4,4,4,0,0,0,8,4,4,4,4,4,4,4,4,4,4,4,4,4,1
1,1,1,1,1,4,4,4,1,1,1,1,4,4,4,4,4,0,0,0,9,0,4,4,4,4,4,4,4,4,4,4,4,1,1,1
1,1,1,1,1,1,1,1,1,1,1,1,4,4,4,4,0,0,0,9,4,4,4,4,4,4,4,4,4,4,4,4,4,4,2,1
1,1,1,1,1,4,4,5,4,4,4,4,4,4,4,7,0,0,0,4,4,4,4,4,4,4,4,4,4,4,4,4,4,4,1,1
1,1,1,1,1,4,4,3,4,4,4,4,4,4,4,0,0,8,5,4,4,4,4,4,4,4,4,4,4,4,4,4,4,4,1,1
1,1,1,1,1,4,4,4,4,4,4,4,4,4,4,0,0,10,4,4,4,4,4,4,4,4,4,4,4,4,4,4,4,4,1,1
1,1,1,1,4,4,4,4,4,4,4,4,4,4,4,4,4,4,4,4,4,4,4,4,4,4,4,4,4,4,4,4,4,3,1,1
1,1,1,2,4,4,4,4,4,4,4,4,4,4,4,4,4,4,4,4,4,4,4,4,4,4,4,4,4,4,4,4,4,3,1,1
1,1,2,4,4,4,4,4,4,4,4,4,4,4,4,4,4,4,4,4,4,4,4,4,4,4,4,4,4,4,4,4,4,3,1,1
1,1,1,3,4,4,4,4,4,4,4,4,4,4,4,4,4,4,4,4,4,4,4,4,4,4,4,4,4,4,4,4,4,3,1,1
1,1,1,3,4,4,4,4,4,4,4,4,4,4,4,4,4,4,4,4,4,4,4,4,4,4,4,0,0,4,4,4,4,3,1,1
1,1,1,1,3,4,4,4,4,4,4,4,4,4,4,4,4,4,4,4,4,4,4,4,4,4,4,0,7,6,4,4,4,3,1,1
1,1,1,1,3,4,0,4,4,4,4,4,4,4,4,4,4,4,4,4,4,4,4,4,4,4,4,4,15,8,4,4,4,3,1,1
1,1,1,1,2,4,4,4,4,4,4,4,4,4,4,4,4,4,4,4,4,4,4,4,4,4,4,4,4,4,4,4,3,3,1,1
1,1,1,1,1,2,4,4,4,4,4,4,4,4,4,4,4,4,4,4,4,4,4,4,4,4,4,4,4,4,3,3,3,1,1,1
1,1,1,1,1,1,3,4,4,4,4,4,4,4,4,4,4,4,4,4,4,4,4,4,4,4,4,4,4,4,3,3,1,1,1,1
1,1,1,1,1,1,1,4,4,4,4,3,4,4,4,4,4,4,4,4,4,3,4,4,4,4,4,4,3,3,1,1,1,1,1,1
1,1,1,1,1,1,1,1,1,2,1,1,2,4,4,4,4,4,4,4,4,3,2,4,4,4,4,3,2,1,1,1,1,1,1,1
1,1,1,1,1,1,1,1,1,1,1,1,1,2,1,2,1,3,2,3,2,2,1,3,4,4,4,2,1,1,1,1,1,1,1,1
1,1,1,1,1,1,1,1,1,1,1,1,1,1,1,1,1,1,1,1,2,1,1,1,2,3,1,1,1,1,1,1,1,1,1,1
1,1,1,1,1,1,1,1,1,1,1,1,1,1,1,1,1,1,1,1,1,1,1,1,1,1,1,1,1,1,1,1,1,1,1,1
1,1,1,1,1,1,1,1,1,1,1,1,1,1,1,1,1,1,1,1,1,1,1,1,1,1,1,1,1,1,1,1,1,1,1,1
endlayer

layer
1,1,1,1,1,1,1,1,1,1,1,1,1,1,1,1,1,1,1,1,1,1,1,1,1,1,1,1,1,1,1,1,1,1,1,1
1,1,1,1,1,1,1,1,1,1,1,1,1,4,4,4,4,4,1,1,1,1,1,1,1,1,1,1,1,1,1,1,1,1,1,1
1,1,1,1,1,1,1,1,1,1,2,3,4,4,4,4,4,4,4,2,1,1,1,1,4,4,4,4,1,1,1,1,1,1,1,1
1,1,1,1,1,1,1,2,3,4,4,4,0,4,4,4,4,4,4,4,4,3,3,2,4,4,4,4,4,3,3,1,1,1,1,1
1,1,1,1,1,1,4,4,4,4,4,0,1,0,4,4,4,4,4,4,4,4,4,4,4,4,4,4,4,4,4,4,3,1,1,1
1,1,1,1,1,1,4,4,4,4,4,0,0,0,0,0,4,4,4,4,4,4,4,4,4,4,4,4,4,0,0,4,4,1,1,1
1,1,1,1,1,3,4,4,4,4,4,0,0,0,0,0,0,4,4,4,4,4,4,4,4,4,4,4,0,0,0,0,4,4,1,1
1,1,1,1,1,4,4,4,4,4,4,4,0,0,0,0,0,4,4,4,4,4,4,4,4,4,4,4,0,0,0,0,4,4,1,1
1,1,1,1,3,4,4,4,4,4,4,4,5,0,0,9,8,4,4,4,4,4,4,4,4,4,0,0,4,9,0,5,4,4,1,1
1,1,1,1,2,4,4,4,4,4,4,4,6,4,4,4,4,4,4,4,4,4,4,4,4,0,0,0,4,4,4,4,4,3,1,1
1,1,1,1,3,4,4,4,4,4,4,7,0,6,0,8,4,4,4,4,4,4,4,4,0,0,0,0,4,4,4,4,4,1,1,1
1,1,1,3,3,4,4,4,6,0,0,0,0,0,0,0,8,4,4,4,4,4,4,0,0,0,0,5,4,4,4,4,4,1,1,1
1,1,1,1,3,4,4,6,0,0,0,0,5,4,4,0,8,4,4,0,8,4,4,0,0,0,0,4,4,4,4,4,4,4,3,1
1,1,1,1,4,7,0,0,0,9,0,4,4,4,4,7,4,4,4,0,0,4,4,7,9,0,4,4,4,4,4,4,4,4,4,1
1,1,1,1,2,4,4,4,0,0,4,6,4,4,4,4,4,4,4,0,0,4,4,4,4,4,4,4,4,4,4,4,4,4,4,1
1,1,1,1,1,4,4,4,0,0,9,8,4,4,4,4,4,4,4,0,9,0,4,4,4,4,4,4,4,4,4,4,4,4,3,1
1,1,1,1,1,2,4,0,7,9,0,10,4,4,4,4,4,4,4,4,4,4,4,4,4,4,4,4,4,4,4,4,4,4,1,1
1,1,1,1,1,2,4,4,4,4,4,9,4,4,4,4,0,0,4,8,4,4,4,4,4,4,4,4,4,4,4,4,4,4,1,1
1,1,1,1,1,4,4,0,4,4,4,4,4,4,4,4,0,0,0,0,4,4,4,4,4,4,4,4,4,4,4,4,4,4,1,1
1,1,1,1,1,4,4,4,4,4,4,4,4,4,4,4,0,9,0,0,0,4,4,4,4,4,4,4,4,4,4,4,4,3,1,1
1,1,1,1,3,4,4,4,4,4,4,4,4,4,4,4,4,4,4,4,0,4,4,4,4,4,4,4,4,4,4,4,4,3,1,1
1,1,1,1,4,4,4,4,4,4,4,4,4,4,4,4,4,4,4,4,0,0,4,4,4,4,4,4,4,4,4,4,4,3,1,1
1,1,1,3,4,4,4,4,4,4,4,4,4,4,4,4,4,4,4,4,4,9,4,4,4,4,4,4,4,4,4,4,4,2,1,1
1,1,1,2,4,4,4,4,4,4,4,4,4,4,4,4,4,4,4,4,4,4,4,4,4,4,4,4,4,4,4,4,3,2,1,1
1,1,1,2,4,4,4,4,4,4,4,4,4,4,4,4,4,4,4,4,4,4,4,4,4,4,4,4,4,4,4,4,4,3,1,1
1,1,1,1,2,4,4,4,4,4,4,4,4,4,4,4,4,4,4,4,4,4,4,4,4,4,4,4,15,4,4,4,4,3,1,1
1,1,1,1,2,4,4,4,4,4,4,4,4,4,4,4,4,4,4,4,4,4,4,4,4,4,4,4,9,8,4,4,4,3,1,1
1,1,1,1,1,4,4,4,4,4,4,4,4,4,4,4,4,4,4,4,4,4,4,4,4,4,4,4,4,4,4,4,3,3,1,1
1,1,1,1,1,1,3,4,4,4,4,4,4,4,4,4,4,4,4,4,4,4,4,4,4,4,4,4,4,4,3,3,3,1,1,1
1,1,1,1,1,1,3,4,4,4,4,4,4,4,4,4,4,4,4,4,4,4,4,4,4,4,4,4,4,3,3,3,1,1,1,1
1,1,1,1,1,1,1,2,4,4,4,3,3,4,4,4,4,4,4,4,4,3,3,4,4,4,4,3,3,2,1,1,1,1,1,1
1,1,1,1,1,1,1,1,1,1,1,1,1,3,4,4,4,4,4,4,3,2,1,4,4,4,4,3,1,1,1,1,1,1,1,1
1,1,1,1,1,1,1,1,1,1,1,1,1,1,1,1,1,2,1,2,1,1,1,2,4,4,3,1,1,1,1,1,1,1,1,1
1,1,1,1,1,1,1,1,1,1,1,1,1,1,1,1,1,1,1,1,1,1,1,1,1,3,1,1,1,1,1,1,1,1,1,1
1,1,1,1,1,1,1,1,1,1,1,1,1,1,1,1,1,1,1,1,1,1,1,1,1,1,1,1,1,1,1,1,1,1,1,1
1,1,1,1,1,1,1,1,1,1,1,1,1,1,1,1,1,1,1,1,1,1,1,1,1,1,1,1,1,1,1,1,1,1,1,1
endlayer

layer
1,1,1,1,1,1,1,1,1,1,1,1,1,1,1,1,1,1,1,1,1,1,1,1,1,1,1,1,1,1,1,1,1,1,1,1
1,1,1,1,1,1,1,1,1,1,1,1,1,3,4,4,4,2,1,1,1,1,1,1,1,1,1,1,1,1,1,1,1,1,1,1
1,1,1,1,1,1,1,1,1,1,1,2,2,4,4,4,4,4,2,1,1,1,1,1,2,4,4,2,1,1,1,1,1,1,1,1
1,1,1,1,1,1,1,1,3,4,4,4,4,4,4,4,4,4,4,4,4,3,2,1,4,4,4,4,3,3,2,1,1,1,1,1
1,1,1,1,1,1,4,4,4,4,4,4,1,4,4,4,4,4,4,4,4,4,4,4,4,4,4,4,4,4,4,3,3,1,1,1
1,1,1,1,1,1,4,4,4,4,4,4,0,0,4,4,4,4,4,4,4,4,4,4,4,4,4,4,4,4,4,4,3,1,1,1
1,1,1,1,1,2,4,4,4,4,5,0,0,0,0,0,0,4,4,4,4,4,4,4,4,4,4,4,4,0,0,4,4,1,1,1
1,1,1,1,1,4,4,4,4,4,4,4,0,0,0,6,0,4,4,4,4,4,4,4,4,4,4,4,4,0,0,4,4,4,1,1
1,1,1,1,2,4,4,4,4,4,4,4,0,0,0,0,0,0,4,4,4,4,4,4,4,4,4,4,7,0,0,4,4,4,1,1
1,1,1,1,1,4,4,4,4,4,4,4,4,4,4,0,0,8,4,4,4,4,4,4,4,4,4,4,9,9,4,4,4,3,1,1
1,1,1,1,2,4,4,4,4,4,4,4,4,4,4,4,9,9,4,4,4,4,4,4,4,0,0,4,4,4,4,4,3,1,1,1
1,1,1,2,3,4,4,4,6,0,0,0,0,4,4,4,4,4,4,4,4,4,4,0,0,0,0,4,4,4,4,4,4,1,1,1
1,1,1,1,2,4,7,6,0,7,0,0,4,4,4,4,4,4,5,4,4,4,4,0,0,0,4,4,4,4,4,4,4,4,2,1
1,1,1,1,5,7,0,0,0,9,9,4,4,4,4,4,4,4,4,4,4,4,7,0,9,0,4,4,4,4,4,4,4,4,4,1
1,1,1,1,1,4,4,9,0,0,4,6,4,4,4,4,4,4,4,4,4,7,8,0,4,4,4,4,4,4,5,4,4,4,4,1
1,1,1,1,1,2,4,4,0,0,9,8,4,4,4,4,4,4,4,4,4,4,4,4,4,4,4,4,4,4,4,4,4,4,2,1
1,1,1,1,1,1,2,4,7,9,4,9,4,4,4,4,4,4,4,4,6,4,4,4,4,4,4,4,4,4,4,4,4,4,1,1
1,1,1,1,1,1,2,4,4,4,4,5,4,4,4,4,4,4,4,0,0,4,4,4,4,4,4,4,4,4,4,4,4,4,1,1
1,1,1,1,1,2,2,3,4,4,4,4,4,4,4,4,0,0,0,0,0,4,4,4,4,4,4,4,4,4,4,4,4,3,1,1
1,1,1,1,1,4,4,4,4,4,4,4,4,4,4,4,0,9,0,0,0,4,4,4,4,4,4,4,4,4,4,4,4,2,1,1
1,1,1,1,2,4,4,4,4,4,4,4,4,4,4,4,4,4,4,0,0,0,4,4,4,4,4,4,4,4,4,4,4,3,1,1
1,1,1,1,2,4,4,4,4,4,4,4,4,4,4,4,4,4,4,0,0,0,0,4,4,4,4,4,4,4,4,4,3,2,1,1
1,1,1,2,4,4,4,4,4,4,4,4,4,4,4,4,4,4,4,0,0,0,16,4,4,4,4,4,4,4,4,4,4,1,1,1
1,1,1,1,4,4,4,4,4,4,4,4,4,4,4,4,4,4,4,4,4,9,4,4,4,4,4,4,4,4,4,4,3,1,1,1
1,1,1,1,2,4,4,4,4,4,4,4,4,4,4,4,4,4,4,4,4,4,4,4,4,4,4,4,4,4,4,4,4,3,1,1
1,1,1,1,1,4,4,4,4,4,4,4,4,4,4,4,4,4,4,4,4,4,4,4,4,4,4,4,9,6,4,4,4,3,1,1
1,1,1,1,1,4,4,4,4,4,4,4,4,4,4,4,4,4,4,4,4,4,4,4,4,4,4,4,0,8,4,4,3,3,1,1
1,1,1,1,1,2,4,4,4,4,4,4,4,4,4,4,4,4,4,4,4,4,4,4,4,4,4,4,4,4,4,4,3,3,1,1
1,1,1,1,1,1,2,4,4,4,4,4,4,4,4,4,4,4,4,4,4,4,4,4,4,4,4,4,4,4,3,3,3,1,1,1
1,1,1,1,1,1,2,3,4,4,4,4,4,4,4,4,4,4,4,4,4,4,4,4,4,4,4,4,4,3,3,3,1,1,1,1
1,1,1,1,1,1,1,1,2,4,3,2,3,4,4,4,4,4,4,4,4,2,2,4,4,4,4,2,2,1,1,1,1,1,1,1
1,1,1,1,1,1,1,1,1,1,1,1,1,3,3,4,4,4,4,4,2,1,1,3,4,4,4,2,1,1,1,1,1,1,1,1
1,1,1,1,1,1,1,1,1,1,1,1,1,1,1,1,1,1,1,1,1,1,1,1,3,4,2,1,1,1,1,1,1,1,1,1
1,1,1,1,1,1,1,1,1,1,1,1,1,1,1,1,1,1,1,1,1,1,1,1,1,2,1,1,1,1,1,1,1,1,1,1
1,1,1,1,1,1,1,1,1,1,1,1,1,1,1,1,1,1,1,1,1,1,1,1,1,1,1,1,1,1,1,1,1,1,1,1
1,1,1,1,1,1,1,1,1,1,1,1,1,1,1,1,1,1,1,1,1,1,1,1,1,1,1,1,1,1,1,1,1,1,1,1
endlayer

layer
1,1,1,1,1,1,1,1,1,1,1,1,1,1,1,1,1,1,1,1,1,1,1,1,1,1,1,1,1,1,1,1,1,1,1,1
1,1,1,1,1,1,1,1,1,1,1,1,1,2,2,3,2,1,1,1,1,1,1,1,1,1,1,1,1,1,1,1,1,1,1,1
1,1,1,1,1,1,1,1,1,1,1,1,1,2,3,3,3,2,1,1,1,1,1,1,1,2,3,1,1,1,1,1,1,1,1,1
1,1,1,1,1,1,1,1,2,2,2,2,1,3,4,4,3,2,3,3,3,3,1,1,2,3,3,3,3,2,1,1,1,1,1,1
1,1,1,1,1,1,2,3,3,3,3,3,0,4,4,4,4,4,3,3,4,4,4,3,3,4,4,3,3,3,3,3,3,1,1,1
1,1,1,1,1,1,2,3,3,3,4,4,5,4,4,4,4,4,4,4,4,4,4,4,4,4,4,4,4,4,3,3,3,1,1,1
1,1,1,1,1,1,3,3,3,4,4,4,4,7,0,4,4,4,4,4,4,4,4,4,4,4,4,4,4,4,4,3,3,1,1,1
1,1,1,1,1,2,3,3,3,4,4,4,4,7,0,6,6,0,4,4,4,4,4,4,4,4,4,4,4,0,4,3,3,3,1,1
1,1,1,1,1,3,3,3,3,4,4,4,4,4,9,7,0,0,4,4,4,4,4,4,4,4,4,7,0,0,4,3,3,3,1,1
1,1,1,1,1,3,3,3,3,4,4,4,4,4,4,0,0,0,0,4,4,4,4,4,4,4,9,0,0,9,4,3,3,3,1,1
1,1,1,1,1,3,3,3,3,4,4,4,4,4,4,0,0,0,0,4,4,4,4,4,4,4,4,9,0,4,4,3,3,1,1,1
1,1,1,1,2,3,3,3,4,4,4,4,4,4,4,4,0,0,0,0,4,4,4,4,4,4,4,4,4,4,4,3,3,1,1,1
1,1,1,1,1,3,4,4,4,7,4,4,4,4,4,4,4,0,0,0,0,4,4,0,0,4,4,4,4,4,4,3,3,3,1,1
1,1,1,1,2,4,4,4,5,9,9,4,4,4,4,4,4,4,0,0,0,0,0,0,0,4,4,4,4,4,1,1,1,2,1,1
1,1,1,1,1,2,3,4,4,4,4,4,4,4,4,4,4,4,4,0,0,0,8,0,4,4,4,4,1,1,1,1,1,3,3,1
1,1,1,1,1,1,3,3,4,4,4,4,4,4,4,4,4,4,4,4,0,8,4,4,4,4,4,4,1,1,4,3,3,3,1,1
1,1,1,1,1,1,1,3,4,4,4,4,4,4,4,4,4,4,4,0,9,0,4,4,4,4,4,4,4,4,4,3,3,2,1,1
1,1,1,1,1,1,1,3,4,4,4,4,4,4,4,4,4,4,4,0,0,4,4,4,4,4,4,4,4,4,4,3,3,2,1,1
1,1,1,1,1,1,1,3,3,4,4,4,4,4,4,4,4,4,4,0,0,4,4,4,4,4,4,4,4,4,4,3,3,2,1,1
1,1,1,1,1,2,3,3,3,4,4,4,4,4,4,4,4,4,4,4,4,4,4,4,4,4,4,4,4,4,4,3,3,1,1,1
1,1,1,1,1,3,3,3,3,4,4,4,4,4,4,4,4,4,4,0,0,0,4,4,4,4,4,4,4,4,4,3,3,2,1,1
1,1,1,1,1,2,3,3,3,4,4,4,4,4,4,4,4,4,4,4,0,17,4,4,4,4,4,4,4,4,4,3,3,1,1,1
1,1,1,1,2,3,3,3,3,4,4,4,4,4,4,4,4,4,4,0,0,0,16,4,4,4,4,4,4,4,4,3,3,1,1,1
1,1,1,1,2,3,3,3,4,4,4,4,4,4,4,4,4,4,4,4,0,0,4,4,4,4,4,4,4,4,4,3,3,1,1,1
1,1,1,1,1,3,3,3,3,4,4,4,4,4,4,4,4,4,4,4,4,18,4,4,4,4,4,4,4,4,4,3,3,3,1,1
1,1,1,1,1,3,3,3,3,4,4,4,4,4,4,4,4,4,4,4,4,4,4,4,4,4,4,4,9,6,5,3,3,3,1,1
1,1,1,1,1,2,3,3,3,4,4,4,4,4,4,4,4,4,4,4,4,4,4,4,4,4,4,4,4,8,4,3,3,1,1,1
1,1,1,1,1,1,3,3,3,4,4,4,4,4,4,4,4,4,4,4,4,4,4,4,4,4,4,4,4,5,4,3,3,1,1,1
1,1,1,1,1,1,1,3,3,3,3,3,3,4,4,4,4,4,4,4,4,4,3,4,4,4,3,3,3,3,3,3,3,1,1,1
1,1,1,1,1,1,1,3,3,3,3,3,3,3,3,4,4,4,4,3,3,3,3,3,3,3,3,3,3,3,3,3,1,1,1,1
1,1,1,1,1,1,1,1,1,3,3,1,3,3,3,3,4,3,3,3,3,1,1,3,3,3,3,1,1,1,1,1,1,1,1,1
1,1,1,1,1,1,1,1,1,1,1,1,1,3,3,3,3,3,3,3,1,1,1,2,3,3,3,1,1,1,1,1,1,1,1,1
1,1,1,1,1,1,1,1,1,1,1,1,1,1,1,1,1,1,1,1,1,1,1,1,2,2,1,1,1,1,1,1,1,1,1,1
1,1,1,1,1,1,1,1,1,1,1,1,1,1,1,1,1,1,1,1,1,1,1,1,1,1,1,1,1,1,1,1,1,1,1,1
1,1,1,1,1,1,1,1,1,1,1,1,1,1,1,1,1,1,1,1,1,1,1,1,1,1,1,1,1,1,1,1,1,1,1,1
1,1,1,1,1,1,1,1,1,1,1,1,1,1,1,1,1,1,1,1,1,1,1,1,1,1,1,1,1,1,1,1,1,1,1,1
endlayer

layer
1,1,1,1,1,1,1,1,1,1,1,1,1,1,1,1,1,1,1,1,1,1,1,1,1,1,1,1,1,1,1,1,1,1,1,1
1,1,1,1,1,1,1,1,1,1,1,1,1,1,1,2,1,1,1,1,1,1,1,1,1,1,1,1,1,1,1,1,1,1,1,1
1,1,1,1,1,1,1,1,1,1,1,1,1,1,2,3,2,1,1,1,1,1,1,1,1,1,2,1,1,1,1,1,1,1,1,1
1,1,1,1,1,1,1,1,1,1,1,1,2,3,3,3,3,1,2,3,3,3,1,1,1,3,3,3,2,1,1,1,1,1,1,1
1,1,1,1,1,1,1,3,3,3,3,3,3,3,3,3,3,3,3,3,3,3,3,3,3,3,3,3,3,3,3,3,3,1,1,1
1,1,1,1,1,1,1,3,3,3,3,3,3,3,3,3,3,3,3,3,3,4,4,4,4,4,4,4,4,3,3,3,3,1,1,1
1,1,1,1,1,1,2,3,3,4,4,4,4,4,4,4,4,4,4,4,4,4,4,4,4,4,4,4,4,4,4,3,3,1,1,1
1,1,1,1,1,1,3,3,3,4,4,4,4,4,4,4,4,0,4,4,4,4,4,4,4,4,4,4,4,0,4,3,3,3,1,1
1,1,1,1,1,2,3,3,3,4,4,4,4,4,4,7,6,0,0,4,4,4,4,4,4,4,0,0,0,0,4,3,3,3,1,1
1,1,1,1,1,2,3,3,3,4,4,4,4,4,4,0,0,0,0,4,4,4,4,4,4,4,0,0,0,0,4,3,3,3,1,1
1,1,1,1,1,2,3,3,3,4,4,4,4,4,4,0,0,0,0,0,4,4,4,4,4,5,0,9,0,4,4,3,3,1,1,1
1,1,1,1,1,2,3,3,3,4,4,4,4,4,4,4,0,7,0,0,4,4,4,4,4,4,0,4,4,4,4,3,3,1,1,1
1,1,1,1,1,2,3,3,3,4,4,4,4,4,4,4,0,0,0,0,0,4,4,4,4,4,0,0,0,4,4,3,3,3,1,1
1,1,1,1,1,3,3,3,3,4,4,4,4,4,4,4,0,7,0,0,0,0,0,4,4,4,0,0,0,0,0,0,1,1,1,1
1,1,1,1,1,1,3,3,3,4,4,4,4,4,4,4,4,4,0,0,0,0,8,4,4,4,4,0,0,0,0,0,0,3,2,1
1,1,1,1,1,1,3,3,4,4,4,4,4,4,4,4,4,4,4,0,0,0,9,8,4,4,4,0,0,0,4,3,3,2,1,1
1,1,1,1,1,1,1,3,3,4,4,4,4,4,4,4,4,4,4,0,9,0,4,4,4,4,4,4,0,19,4,3,3,1,1,1
1,1,1,1,1,1,1,3,3,4,4,4,4,4,4,4,4,4,4,0,0,0,4,4,4,4,4,4,4,4,4,3,3,1,1,1
1,1,1,1,1,1,1,3,3,4,4,4,4,4,4,4,4,4,4,4,4,4,4,4,4,4,4,4,4,4,4,3,3,1,1,1
1,1,1,1,1,1,2,3,3,4,4,4,4,4,4,4,4,4,4,4,4,4,4,4,4,4,4,4,4,4,4,3,3,1,1,1
1,1,1,1,1,2,3,3,3,4,4,4,4,4,4,4,4,4,4,4,4,4,4,4,4,4,4,4,4,4,4,3,3,1,1,1
1,1,1,1,1,1,3,3,3,4,4,4,4,4,4,4,4,4,4,4,4,17,4,4,4,4,4,4,4,4,4,3,3,1,1,1
1,1,1,1,1,2,3,3,3,4,4,4,4,4,4,4,4,4,4,4,0,0,17,4,4,4,4,4,4,4,4,3,3,1,1,1
1,1,1,1,1,3,3,3,4,4,4,4,4,4,4,4,4,4,4,4,0,0,0,4,4,4,4,4,4,4,4,3,3,1,1,1
1,1,1,1,1,2,3,3,3,4,4,4,4,4,4,4,4,4,4,4,0,0,0,0,0,4,4,4,4,4,4,3,3,3,1,1
1,1,1,1,1,3,3,3,3,4,4,4,4,4,4,4,4,4,4,4,4,0,0,0,0,0,4,4,4,4,4,3,3,1,1,1
1,1,1,1,1,1,3,3,3,4,4,4,4,4,4,4,4,4,4,4,4,4,4,4,4,4,4,4,7,4,4,3,3,1,1,1
1,1,1,1,1,1,3,3,3,4,4,4,4,4,4,4,4,4,4,4,4,4,4,4,4,4,4,4,4,4,4,3,3,1,1,1
1,1,1,1,1,1,1,3,3,3,3,3,3,3,3,4,4,4,4,4,4,4,3,3,3,3,3,3,3,3,3,3,3,1,1,1
1,1,1,1,1,1,1,3,3,3,3,3,3,3,3,3,3,3,3,3,3,3,3,3,3,3,3,3,3,3,3,3,1,1,1,1
1,1,1,1,1,1,1,1,1,3,3,1,2,3,3,3,3,3,3,3,2,1,1,2,3,3,3,1,1,1,1,1,1,1,1,1
1,1,1,1,1,1,1,1,1,1,1,1,1,2,2,3,3,3,3,2,1,1,1,1,2,3,3,1,1,1,1,1,1,1,1,1
1,1,1,1,1,1,1,1,1,1,1,1,1,1,1,1,1,1,1,1,1,1,1,1,1,1,1,1,1,1,1,1,1,1,1,1
1,1,1,1,1,1,1,1,1,1,1,1,1,1,1,1,1,1,1,1,1,1,1,1,1,1,1,1,1,1,1,1,1,1,1,1
1,1,1,1,1,1,1,1,1,1,1,1,1,1,1,1,1,1,1,1,1,1,1,1,1,1,1,1,1,1,1,1,1,1,1,1
1,1,1,1,1,1,1,1,1,1,1,1,1,1,1,1,1,1,1,1,1,1,1,1,1,1,1,1,1,1,1,1,1,1,1,1
endlayer

layer
1,1,1,1,1,1,1,1,1,1,1,1,1,1,1,1,1,1,1,1,1,1,1,1,1,1,1,1,1,1,1,1,1,1,1,1
1,1,1,1,1,1,1,1,1,1,1,1,1,1,1,1,1,1,1,1,1,1,1,1,1,1,1,1,1,1,1,1,1,1,1,1
1,1,1,1,1,1,1,1,1,1,1,1,1,1,1,2,1,1,1,1,1,1,1,1,1,1,1,1,1,1,1,1,1,1,1,1
1,1,1,1,1,1,1,1,1,1,1,1,1,2,3,3,2,1,1,3,1,1,1,1,1,3,3,2,1,1,1,1,1,1,1,1
1,1,1,1,1,1,1,2,2,2,2,2,2,2,3,3,3,3,3,3,3,3,3,3,3,3,3,3,3,3,3,3,3,1,1,1
1,1,1,1,1,1,1,3,3,3,3,3,3,3,3,3,3,3,3,3,3,3,3,3,4,3,3,3,3,3,3,3,3,1,1,1
1,1,1,1,1,1,1,3,3,4,4,4,4,4,4,4,4,4,4,4,4,4,4,4,4,4,4,4,4,4,4,3,3,1,1,1
1,1,1,1,1,1,2,3,3,4,4,4,4,4,4,4,4,4,4,4,4,4,4,4,4,4,4,4,4,4,4,3,3,3,1,1
1,1,1,1,1,1,3,3,3,4,4,4,4,4,4,7,0,4,4,4,4,4,4,4,4,4,0,0,4,4,4,3,3,3,1,1
1,1,1,1,1,1,2,3,3,4,4,4,4,4,4,0,0,0,4,4,4,4,4,4,4,0,0,0,0,4,4,3,3,1,1,1
1,1,1,1,1,1,3,3,3,4,4,4,4,4,4,4,0,0,4,4,4,4,4,4,4,0,0,0,4,4,4,3,3,1,1,1
1,1,1,1,1,1,3,3,3,4,4,4,4,4,4,4,4,7,0,4,4,4,4,4,4,0,0,0,4,4,4,3,3,1,1,1
1,1,1,1,1,1,3,3,3,4,4,4,4,4,4,4,4,0,0,0,4,4,4,4,4,4,0,0,0,4,4,3,3,3,1,1
1,1,1,1,1,3,3,3,3,4,4,4,4,4,4,4,4,7,0,0,0,4,4,4,4,4,0,0,0,0,0,0,0,3,1,1
1,1,1,1,1,1,3,3,3,4,4,4,4,4,4,4,4,4,0,0,0,0,0,8,4,4,4,0,0,0,0,0,0,2,1,1
1,1,1,1,1,1,3,3,4,4,4,4,4,4,4,4,4,4,4,4,7,0,0,8,4,4,4,0,0,4,4,3,3,1,1,1
1,1,1,1,1,1,1,3,3,4,4,4,4,4,4,4,4,4,4,4,9,0,13,4,4,4,4,4,0,4,4,3,3,1,1,1
1,1,1,1,1,1,1,3,3,4,4,4,4,4,4,4,4,4,4,4,4,4,4,4,4,4,4,4,4,4,4,3,3,1,1,1
1,1,1,1,1,1,1,3,3,4,4,4,4,4,4,4,4,4,4,4,4,4,4,4,4,4,4,4,4,4,4,3,3,1,1,1
1,1,1,1,1,1,1,3,3,4,4,4,4,4,4,4,4,4,4,4,4,4,4,4,4,4,4,4,4,4,4,3,3,1,1,1
1,1,1,1,1,1,2,3,3,4,4,4,4,4,4,4,4,4,4,4,4,4,4,4,4,4,4,4,4,4,4,3,3,1,1,1
1,1,1,1,1,1,2,3,3,4,4,4,4,4,4,4,4,4,4,4,4,4,4,4,4,4,4,4,4,4,4,3,3,1,1,1
1,1,1,1,1,1,3,3,3,4,4,4,4,4,4,4,4,4,4,4,4,0,4,4,4,4,4,4,4,4,4,3,3,1,1,1
1,1,1,1,1,2,3,3,3,4,4,4,4,4,4,4,4,4,4,4,0,0,0,0,4,4,4,4,4,4,4,3,3,1,1,1
1,1,1,1,1,1,3,3,3,4,4,4,4,4,4,4,4,4,4,4,0,0,0,0,0,4,4,4,4,4,4,3,3,1,1,1
1,1,1,1,1,3,3,3,3,4,4,4,4,4,4,4,4,4,4,4,4,0,0,0,0,0,0,6,6,8,4,3,3,1,1,1
1,1,1,1,1,1,3,3,3,4,4,4,4,4,4,4,4,4,4,4,4,4,19,4,4,4,4,4,7,4,4,3,3,1,1,1
1,1,1,1,1,1,3,3,3,4,4,4,4,4,4,4,4,4,4,4,4,4,4,4,4,4,4,4,4,4,4,3,3,1,1,1
1,1,1,1,1,1,1,3,3,3,3,3,3,3,3,3,4,3,3,3,3,3,3,3,3,3,3,3,3,3,3,3,3,1,1,1
1,1,1,1,1,1,1,3,3,3,3,3,3,3,3,3,3,3,3,3,3,3,3,3,3,3,3,3,3,3,3,3,1,1,1,1
1,1,1,1,1,1,1,1,1,3,1,1,1,3,3,3,3,3,3,2,1,1,1,1,2,3,3,1,1,1,1,1,1,1,1,1
1,1,1,1,1,1,1,1,1,1,1,1,1,1,1,2,3,3,2,1,1,1,1,1,1,2,2,1,1,1,1,1,1,1,1,1
1,1,1,1,1,1,1,1,1,1,1,1,1,1,1,1,1,1,1,1,1,1,1,1,1,1,1,1,1,1,1,1,1,1,1,1
1,1,1,1,1,1,1,1,1,1,1,1,1,1,1,1,1,1,1,1,1,1,1,1,1,1,1,1,1,1,1,1,1,1,1,1
1,1,1,1,1,1,1,1,1,1,1,1,1,1,1,1,1,1,1,1,1,1,1,1,1,1,1,1,1,1,1,1,1,1,1,1
1,1,1,1,1,1,1,1,1,1,1,1,1,1,1,1,1,1,1,1,1,1,1,1,1,1,1,1,1,1,1,1,1,1,1,1
endlayer

layer
1,1,1,1,1,1,1,1,1,1,1,1,1,1,1,1,1,1,1,1,1,1,1,1,1,1,1,1,1,1,1,1,1,1,1,1
1,1,1,1,1,1,1,1,1,1,1,1,1,1,1,1,1,1,1,1,1,1,1,1,1,1,1,1,1,1,1,1,1,1,1,1
1,1,1,1,1,1,1,1,1,1,1,1,1,1,1,1,1,1,1,1,1,1,1,1,1,1,1,1,1,1,1,1,1,1,1,1
1,1,1,1,1,1,1,1,1,1,1,1,1,1,2,3,1,1,1,3,1,1,1,1,1,2,2,1,1,1,1,1,1,1,1,1
1,1,1,1,1,1,1,1,1,1,1,1,1,1,3,3,3,3,3,3,3,3,3,3,3,3,3,3,3,3,3,3,3,1,1,1
1,1,1,1,1,1,1,3,3,3,3,3,3,3,3,3,3,3,3,3,3,3,3,3,3,3,3,3,3,3,3,3,3,1,1,1
1,1,1,1,1,1,1,3,3,4,4,4,4,4,4,4,4,4,4,4,4,4,4,4,4,4,4,4,4,4,4,3,3,1,1,1
1,1,1,1,1,1,1,3,3,4,4,4,4,4,4,4,4,4,20,21,21,20,4,4,4,4,4,4,4,4,4,3,3,3,1,1
1,1,1,1,1,1,2,3,3,4,4,4,4,4,4,4,4,4,4,4,4,4,4,4,4,4,4,4,4,4,4,3,3,1,1,1
1,1,1,1,1,1,1,3,3,4,4,4,4,4,4,4,4,4,4,4,4,4,4,4,4,4,4,4,4,4,4,3,3,1,1,1
1,1,1,1,1,1,3,3,3,4,4,4,4,4,4,4,4,4,4,4,4,4,4,4,4,4,4,4,4,4,4,3,3,1,1,1
1,1,1,1,1,1,3,3,3,4,4,4,4,4,4,4,4,4,4,4,4,4,4,4,4,4,4,4,4,4,4,3,3,1,1,1
1,1,1,1,1,1,3,3,3,4,4,4,4,4,4,4,4,5,4,4,4,4,4,4,4,4,4,4,4,4,4,3,3,2,1,1
1,1,1,1,1,2,3,3,3,4,4,4,4,4,4,4,4,4,4,4,4,4,4,4,4,4,4,4,4,4,4,3,3,3,1,1
1,1,1,1,1,1,3,3,3,4,4,4,4,4,4,4,4,4,4,4,4,0,0,17,4,4,4,4,4,4,4,3,3,1,1,1
1,1,1,1,1,1,2,3,3,4,20,4,4,4,4,4,4,4,4,4,4,4,0,8,4,4,4,4,4,20,4,3,3,1,1,1
1,1,1,1,1,1,1,3,3,4,21,4,4,4,4,4,4,4,4,4,4,4,4,4,4,4,4,4,4,21,4,3,3,1,1,1
1,1,1,1,1,1,1,3,3,4,21,4,4,4,4,4,4,4,4,4,4,4,4,4,4,4,4,4,4,21,4,3,3,1,1,1
1,1,1,1,1,1,1,3,3,4,20,4,4,4,4,4,4,4,4,4,4,4,4,4,4,4,4,4,4,20,4,3,3,1,1,1
1,1,1,1,1,1,1,3,3,4,4,4,4,4,4,4,4,4,4,4,4,4,4,4,4,4,4,4,4,4,4,3,3,1,1,1
1,1,1,1,1,1,1,3,3,4,4,4,4,4,4,4,4,4,4,4,4,4,4,4,4,4,4,4,4,4,4,3,3,1,1,1
1,1,1,1,1,1,1,3,3,4,4,4,4,4,4,4,4,4,4,4,4,4,4,4,4,4,4,4,4,4,4,3,3,1,1,1
1,1,1,1,1,1,2,3,3,4,4,4,4,4,4,4,4,4,4,4,4,4,4,4,4,4,4,4,4,4,4,3,3,1,1,1
1,1,1,1,1,1,2,3,3,4,4,4,4,4,4,4,4,4,4,4,4,4,22,4,4,4,4,4,4,4,4,3,3,1,1,1
1,1,1,1,1,1,3,3,3,4,4,4,4,4,4,4,4,4,4,4,4,4,0,0,0,0,4,4,4,4,4,3,3,1,1,1
1,1,1,1,1,2,3,3,3,4,4,4,4,4,4,4,4,4,4,4,4,4,5,0,0,0,0,6,6,8,4,3,3,1,1,1
1,1,1,1,1,1,3,3,3,4,4,4,4,4,4,4,4,4,20,21,21,20,4,4,4,4,4,4,0,10,4,3,3,1,1,1
1,1,1,1,1,1,2,3,3,4,4,4,4,4,4,4,4,4,4,4,4,4,4,4,4,4,4,4,4,4,4,3,3,1,1,1
1,1,1,1,1,1,1,3,3,3,3,3,3,3,3,3,3,3,3,3,3,3,3,3,3,3,3,3,3,3,3,3,3,1,1,1
1,1,1,1,1,1,1,3,3,3,3,3,3,3,3,3,3,3,3,3,3,3,3,3,3,3,3,3,3,3,3,3,1,1,1,1
1,1,1,1,1,1,1,1,1,1,1,1,1,3,3,2,3,3,3,1,1,1,1,1,1,2,3,1,1,1,1,1,1,1,1,1
1,1,1,1,1,1,1,1,1,1,1,1,1,1,1,1,2,3,1,1,1,1,1,1,1,1,1,1,1,1,1,1,1,1,1,1
1,1,1,1,1,1,1,1,1,1,1,1,1,1,1,1,1,1,1,1,1,1,1,1,1,1,1,1,1,1,1,1,1,1,1,1
1,1,1,1,1,1,1,1,1,1,1,1,1,1,1,1,1,1,1,1,1,1,1,1,1,1,1,1,1,1,1,1,1,1,1,1
1,1,1,1,1,1,1,1,1,1,1,1,1,1,1,1,1,1,1,1,1,1,1,1,1,1,1,1,1,1,1,1,1,1,1,1
1,1,1,1,1,1,1,1,1,1,1,1,1,1,1,1,1,1,1,1,1,1,1,1,1,1,1,1,1,1,1,1,1,1,1,1
endlayer

layer
1,1,1,1,1,1,1,1,1,1,1,1,1,1,1,1,1,1,1,1,1,1,1,1,1,1,1,1,1,1,1,1,1,1,1,1
1,1,1,1,1,1,1,1,1,1,1,1,1,1,1,1,1,1,1,1,1,1,1,1,1,1,1,1,1,1,1,1,1,1,1,1
1,1,1,1,1,1,1,1,1,1,1,1,1,1,1,1,1,1,1,1,1,1,1,1,1,1,1,1,1,1,1,1,1,1,1,1
1,1,1,1,1,1,1,1,1,1,1,1,1,1,1,3,1,1,1,1,1,1,1,1,1,1,1,1,1,1,1,1,1,1,1,1
1,1,1,1,1,1,1,1,1,1,1,1,1,1,3,3,3,3,3,3,3,3,3,3,3,3,3,3,3,3,3,3,3,1,1,1
1,1,1,1,1,1,1,3,3,3,3,3,3,3,3,3,3,3,3,3,3,3,3,3,3,3,3,3,3,3,3,3,3,1,1,1
1,1,1,1,1,1,1,3,3,22,22,23,23,23,23,22,23,22,24,22,22,22,24,22,22,24,22,24,24,23,23,3,3,1,1,1
1,1,1,1,1,1,1,3,3,23,22,23,22,22,23,23,22,23,22,22,22,22,23,22,24,22,24,24,22,23,24,3,3,1,1,1
1,1,1,1,1,1,1,3,3,22,22,22,23,22,24,23,22,22,24,24,23,22,22,22,23,23,22,24,22,22,22,3,3,1,1,1
1,1,1,1,1,1,1,3,3,22,23,22,24,23,23,22,24,22,23,22,23,23,22,24,22,24,23,23,22,22,23,3,3,1,1,1
1,1,1,1,1,1,2,3,3,24,24,23,22,22,24,22,24,20,22,22,22,22,20,22,23,23,22,22,23,23,24,3,3,1,1,1
1,1,1,1,1,1,3,3,3,23,22,24,24,22,22,24,23,24,23,24,23,23,22,24,23,23,23,24,24,23,23,3,3,1,1,1
1,1,1,1,1,1,3,3,3,22,23,22,22,23,22,23,23,5,24,23,23,24,24,22,22,23,23,24,24,23,23,3,3,1,1,1
1,1,1,1,1,1,3,3,3,24,24,22,22,24,22,23,23,23,22,24,22,24,23,24,23,24,24,24,24,22,24,3,3,2,1,1
1,1,1,1,1,1,3,3,3,24,23,23,22,20,24,22,23,24,23,24,24,22,23,25,23,24,20,23,23,22,24,3,3,1,1,1
1,1,1,1,1,1,1,3,3,24,22,23,24,22,23,24,24,24,24,23,24,24,24,22,23,23,22,24,23,22,23,3,3,1,1,1
1,1,1,1,1,1,1,3,3,22,22,23,23,22,22,23,24,24,24,26,26,23,23,23,22,23,22,24,22,22,24,3,3,1,1,1
1,1,1,1,1,1,1,3,3,22,22,22,24,22,22,24,22,23,22,26,26,23,22,22,24,23,22,24,23,22,23,3,3,1,1,1
1,1,1,1,1,1,1,3,3,22,22,22,24,22,22,24,22,23,24,24,24,24,22,24,22,23,22,22,23,22,23,3,3,1,1,1
1,1,1,1,1,1,1,3,3,22,24,23,23,20,23,23,22,24,24,22,23,24,22,23,23,22,20,22,22,22,23,3,3,1,1,1
1,1,1,1,1,1,1,3,3,24,23,24,22,23,24,24,23,22,24,24,24,24,22,22,23,23,22,24,22,27,24,3,3,1,1,1
1,1,1,1,1,1,1,3,3,23,23,22,23,22,24,22,23,23,22,23,23,24,22,23,23,24,22,23,27,22,23,3,3,1,1,1
1,1,1,1,1,1,1,3,3,23,22,24,22,24,23,22,24,24,23,22,24,24,22,22,24,23,24,23,24,24,22,3,3,1,1,1
1,1,1,1,1,1,1,3,3,24,22,24,22,22,24,22,23,20,22,22,22,22,20,22,24,24,24,24,22,23,23,3,3,1,1,1
1,1,1,1,1,1,3,3,3,23,23,22,23,23,23,23,22,23,22,22,23,24,24,22,24,22,22,24,23,27,23,3,3,1,1,1
1,1,1,1,1,1,3,3,3,24,22,23,24,22,24,23,24,24,23,22,23,22,22,27,23,23,24,27,28,8,24,3,3,1,1,1
1,1,1,1,1,1,3,3,3,24,24,24,22,24,24,24,24,22,22,22,22,22,22,22,22,27,23,23,27,9,24,3,3,1,1,1
1,1,1,1,1,1,1,3,3,22,22,23,22,22,24,23,23,24,22,23,24,23,23,24,24,23,24,23,22,22,24,3,3,1,1,1
1,1,1,1,1,1,1,3,3,3,3,3,3,3,3,3,3,3,3,3,3,3,3,3,3,3,3,3,3,3,3,3,3,1,1,1
1,1,1,1,1,1,1,3,3,3,3,3,3,3,3,3,3,3,3,3,3,3,3,3,3,3,3,3,3,3,3,3,1,1,1,1
1,1,1,1,1,1,1,1,1,1,1,1,1,2,3,1,2,3,2,1,1,1,1,1,1,1,2,1,1,1,1,1,1,1,1,1
1,1,1,1,1,1,1,1,1,1,1,1,1,1,1,1,1,2,1,1,1,1,1,1,1,1,1,1,1,1,1,1,1,1,1,1
1,1,1,1,1,1,1,1,1,1,1,1,1,1,1,1,1,1,1,1,1,1,1,1,1,1,1,1,1,1,1,1,1,1,1,1
1,1,1,1,1,1,1,1,1,1,1,1,1,1,1,1,1,1,1,1,1,1,1,1,1,1,1,1,1,1,1,1,1,1,1,1
1,1,1,1,1,1,1,1,1,1,1,1,1,1,1,1,1,1,1,1,1,1,1,1,1,1,1,1,1,1,1,1,1,1,1,1
1,1,1,1,1,1,1,1,1,1,1,1,1,1,1,1,1,1,1,1,1,1,1,1,1,1,1,1,1,1,1,1,1,1,1,1
endlayer

layer
1,1,1,1,1,1,1,1,1,1,1,1,1,1,1,1,1,1,1,1,1,1,1,1,1,1,1,1,1,1,1,1,1,1,1,1
1,1,1,1,1,1,1,1,1,1,1,1,1,1,1,1,1,1,1,1,1,1,1,1,1,1,1,1,1,1,1,1,1,1,1,1
1,1,1,1,1,1,1,1,1,1,1,1,1,1,1,1,1,1,1,1,1,1,1,1,1,1,1,1,1,1,1,1,1,1,1,1
1,1,1,1,1,1,1,1,1,1,1,1,1,1,1,29,1,1,1,1,1,1,1,1,1,1,1,1,1,1,1,1,1,1,1,1
1,1,1,1,1,1,1,1,1,1,1,1,1,1,2,3,3,3,3,3,3,3,3,3,3,3,3,3,3,3,3,3,2,1,1,1
1,1,1,1,1,1,1,2,22,22,22,22,22,22,22,22,22,22,22,22,22,22,22,22,22,22,22,22,22,22,22,22,3,1,1,1
1,1,1,1,1,1,1,2,22,22,22,23,24,23,24,23,24,24,22,23,24,22,22,22,22,23,22,23,24,23,23,22,3,1,1,1
1,1,1,1,1,1,1,2,22,24,0,0,0,0,0,0,6,6,30,0,0,30,0,0,0,0,0,0,0,0,23,22,3,1,1,1
1,1,1,1,1,1,1,2,22,22,0,0,0,0,0,0,0,0,0,0,31,0,0,0,0,0,9,0,0,0,23,22,3,1,1,1
1,1,1,1,1,1,1,3,22,24,0,0,22,23,22,24,23,27,23,31,0,24,27,22,23,24,22,24,0,8,24,22,3,1,1,1
1,1,1,1,1,1,1,3,22,24,0,0,23,32,32,32,22,23,35,34,34,33,22,22,32,32,32,23,0,0,24,22,3,1,1,1
1,1,1,1,1,1,2,3,22,24,0,0,24,32,19,32,22,24,22,36,36,23,24,22,32,19,32,22,0,0,23,22,3,1,1,1
1,1,1,1,1,1,3,3,22,22,0,0,22,32,32,32,22,22,22,24,24,23,27,22,32,32,32,23,0,0,22,22,3,1,1,1
1,1,1,1,1,1,2,3,22,22,0,0,23,22,22,22,22,22,23,37,37,23,22,22,22,22,22,22,0,0,22,22,3,1,1,1
1,1,1,1,1,1,2,3,22,24,0,0,27,24,24,22,22,22,24,38,38,23,27,8,22,23,22,27,0,0,22,22,3,1,1,1
1,1,1,1,1,1,1,3,22,22,30,0,23,39,22,22,23,22,23,40,40,24,22,27,24,23,39,22,0,30,22,22,3,1,1,1
1,1,1,1,1,1,1,3,22,23,0,0,31,34,43,22,37,38,40,42,42,40,38,37,23,41,34,31,0,0,24,22,3,1,1,1
1,1,1,1,1,1,1,3,22,24,0,0,0,34,43,22,37,38,40,42,42,40,38,37,24,41,34,0,0,0,24,22,3,1,1,1
1,1,1,1,1,1,1,3,22,22,30,0,22,44,22,22,23,22,24,40,40,22,23,24,23,22,44,24,0,30,22,22,3,1,1,1
1,1,1,1,1,1,1,3,22,23,0,31,27,24,24,22,22,22,23,38,38,22,22,22,22,22,23,27,0,0,22,22,3,1,1,1
1,1,1,1,1,1,1,3,22,22,7,0,24,22,22,22,22,22,23,37,37,24,22,22,22,22,22,24,0,0,24,22,3,1,1,1
1,1,1,1,1,1,1,3,22,24,0,0,22,32,32,32,22,22,22,23,22,22,22,22,32,32,32,23,0,0,23,22,3,1,1,1
1,1,1,1,1,1,1,3,22,22,0,0,22,32,19,32,22,24,23,45,45,23,23,22,32,19,32,23,0,0,24,22,3,1,1,1
1,1,1,1,1,1,1,3,22,22,0,0,23,32,32,32,22,23,35,34,34,33,22,22,32,32,32,22,0,0,22,22,3,1,1,1
1,1,1,1,1,1,2,3,22,23,0,0,23,23,22,23,24,27,22,31,8,24,27,22,22,22,24,27,0,8,24,22,3,1,1,1
1,1,1,1,1,1,3,3,22,23,0,0,0,0,0,0,0,31,0,6,0,6,0,0,0,0,0,0,0,8,24,22,3,1,1,1
1,1,1,1,1,1,2,3,22,24,0,0,9,9,0,0,0,0,30,0,0,30,0,0,0,0,0,0,9,10,24,22,3,1,1,1
1,1,1,1,1,1,1,3,22,23,22,23,24,23,24,22,24,23,22,22,23,22,24,24,22,23,22,22,22,24,22,22,3,1,1,1
1,1,1,1,1,1,1,3,22,22,22,22,22,22,22,22,22,22,22,22,22,22,22,22,22,22,22,22,22,22,22,22,2,1,1,1
1,1,1,1,1,1,1,2,3,3,3,3,3,3,3,3,3,3,3,3,3,3,3,3,3,3,3,3,3,3,3,3,1,1,1,1
1,1,1,1,1,1,1,1,1,1,1,1,1,1,2,1,1,2,1,1,1,1,1,1,1,1,1,1,1,1,1,1,1,1,1,1
1,1,1,1,1,1,1,1,1,1,1,1,1,1,1,1,1,1,1,1,1,1,1,1,1,1,1,1,1,1,1,1,1,1,1,1
1,1,1,1,1,1,1,1,1,1,1,1,1,1,1,1,1,1,1,1,1,1,1,1,1,1,1,1,1,1,1,1,1,1,1,1
1,1,1,1,1,1,1,1,1,1,1,1,1,1,1,1,1,1,1,1,1,1,1,1,1,1,1,1,1,1,1,1,1,1,1,1
1,1,1,1,1,1,1,1,1,1,1,1,1,1,1,1,1,1,1,1,1,1,1,1,1,1,1,1,1,1,1,1,1,1,1,1
1,1,1,1,1,1,1,1,1,1,1,1,1,1,1,1,1,1,1,1,1,1,1,1,1,1,1,1,1,1,1,1,1,1,1,1
endlayer

layer
1,1,1,1,1,1,1,1,1,1,1,1,1,1,1,1,1,1,1,1,1,1,1,1,1,1,1,1,1,1,1,1,1,1,1,1
1,1,1,1,1,1,1,1,1,1,1,1,1,1,1,1,1,1,1,1,1,1,1,1,1,1,1,1,1,1,1,1,1,1,1,1
1,1,1,1,1,1,1,1,1,1,1,1,1,1,1,1,1,1,1,1,1,1,1,1,1,1,1,1,1,1,1,1,1,1,1,1
1,1,1,1,1,1,1,1,1,1,1,1,1,1,1,29,1,1,1,1,1,1,1,1,1,1,1,1,1,1,1,1,1,1,1,1
1,1,1,1,1,1,1,1,1,1,1,1,1,1,1,2,3,3,3,3,3,3,3,3,2,3,2,3,3,3,3,2,1,1,1,1
1,1,1,1,1,1,1,1,3,3,3,3,3,2,3,3,3,3,3,3,3,3,3,3,3,3,3,3,3,3,3,3,3,1,1,1
1,1,1,1,1,1,1,1,3,23,23,21,23,21,21,21,21,21,23,22,22,24,21,21,21,21,21,23,21,24,23,3,3,1,1,1
1,1,1,1,1,1,1,1,2,24,0,0,0,0,0,0,6,0,0,0,0,0,0,0,0,0,0,0,6,0,22,3,3,1,1,1
1,1,1,1,1,1,1,1,3,21,0,0,0,0,0,0,0,0,0,0,9,0,0,0,0,0,0,0,0,0,21,3,3,1,1,1
1,1,1,1,1,1,1,2,3,23,0,0,46,46,46,46,46,8,24,0,0,22,7,46,46,46,46,46,0,8,24,3,3,1,1,1
1,1,1,1,1,1,1,3,3,21,0,0,46,0,38,0,46,0,21,0,0,21,0,46,0,38,0,46,0,0,21,3,3,1,1,1
1,1,1,1,1,1,1,3,3,21,0,0,46,38,32,38,46,0,22,0,0,24,0,46,38,32,38,46,0,8,21,3,2,1,1,1
1,1,1,1,1,1,2,3,3,21,0,0,46,0,38,0,46,0,0,21,21,46,0,46,0,38,0,46,0,8,21,3,3,1,1,1
1,1,1,1,1,1,1,3,3,21,0,0,46,46,46,46,46,0,0,37,37,0,0,46,46,46,46,46,0,0,21,3,3,1,1,1
1,1,1,1,1,1,1,3,3,21,0,0,9,9,0,0,0,27,46,0,0,46,0,0,0,0,0,9,0,9,21,3,3,1,1,1
1,1,1,1,1,1,1,3,3,23,0,0,24,21,24,0,0,46,24,47,47,24,46,0,46,22,21,24,0,0,24,3,3,1,1,1
1,1,1,1,1,1,1,3,3,23,0,0,0,0,0,21,37,0,49,24,24,48,0,37,21,0,0,0,0,0,22,3,3,1,1,1
1,1,1,1,1,1,1,3,3,24,0,0,0,0,0,21,37,0,49,24,24,48,0,37,21,0,0,0,0,8,23,3,3,1,1,1
1,1,1,1,1,1,1,3,3,24,0,0,22,21,22,0,0,46,24,50,50,23,46,0,46,22,21,23,0,0,24,3,3,1,1,1
1,1,1,1,1,1,1,3,3,21,0,0,6,0,6,0,0,27,46,0,0,46,27,0,0,0,0,6,0,0,21,3,3,1,1,1
1,1,1,1,1,1,1,3,3,21,7,0,46,46,46,46,46,0,0,37,37,0,0,46,46,46,46,46,0,0,21,3,3,1,1,1
1,1,1,1,1,1,1,3,3,21,0,0,46,0,38,0,46,0,0,21,21,46,0,46,0,38,0,46,0,0,21,3,3,1,1,1
1,1,1,1,1,1,1,3,3,21,0,0,46,38,32,38,46,0,23,0,0,22,0,46,38,32,38,46,0,0,21,3,3,1,1,1
1,1,1,1,1,1,1,3,3,21,0,0,46,0,38,0,46,0,21,0,0,21,0,46,0,38,0,46,0,0,21,3,2,1,1,1
1,1,1,1,1,1,1,3,3,22,0,0,46,46,46,46,46,0,22,7,8,22,7,46,46,46,46,0,0,8,23,3,3,1,1,1
1,1,1,1,1,1,3,3,3,21,0,0,0,0,0,0,0,0,0,6,6,0,0,0,0,0,0,0,0,8,21,3,3,1,1,1
1,1,1,1,1,1,1,3,3,22,0,0,9,9,0,0,0,0,0,9,0,0,0,9,0,0,0,9,0,0,24,3,2,1,1,1
1,1,1,1,1,1,1,3,3,23,24,21,22,21,21,21,21,21,24,23,23,23,21,21,21,21,21,23,21,23,24,3,2,1,1,1
1,1,1,1,1,1,1,3,3,3,3,3,3,3,3,3,3,3,3,3,3,3,3,3,3,3,3,3,3,3,3,3,1,1,1,1
1,1,1,1,1,1,1,1,3,3,3,3,3,3,3,3,3,3,3,3,3,3,3,3,3,3,3,3,3,3,3,2,1,1,1,1
1,1,1,1,1,1,1,1,1,1,1,1,1,1,1,1,1,1,1,1,1,1,1,1,1,1,1,1,1,1,1,1,1,1,1,1
1,1,1,1,1,1,1,1,1,1,1,1,1,1,1,1,1,1,1,1,1,1,1,1,1,1,1,1,1,1,1,1,1,1,1,1
1,1,1,1,1,1,1,1,1,1,1,1,1,1,1,1,1,1,1,1,1,1,1,1,1,1,1,1,1,1,1,1,1,1,1,1
1,1,1,1,1,1,1,1,1,1,1,1,1,1,1,1,1,1,1,1,1,1,1,1,1,1,1,1,1,1,1,1,1,1,1,1
1,1,1,1,1,1,1,1,1,1,1,1,1,1,1,1,1,1,1,1,1,1,1,1,1,1,1,1,1,1,1,1,1,1,1,1
1,1,1,1,1,1,1,1,1,1,1,1,1,1,1,1,1,1,1,1,1,1,1,1,1,1,1,1,1,1,1,1,1,1,1,1
endlayer

layer
1,1,1,1,1,1,1,1,1,1,1,1,1,1,1,1,1,1,1,1,1,1,1,1,1,1,1,1,1,1,1,1,1,1,1,1
1,1,1,1,1,1,1,1,1,1,1,1,1,1,1,1,1,1,1,1,1,1,1,1,1,1,1,1,1,1,1,1,1,1,1,1
1,1,1,1,1,1,1,1,1,1,1,1,1,1,1,1,1,1,1,1,1,1,1,1,1,1,1,1,1,1,1,1,1,1,1,1
1,1,1,1,1,1,1,1,1,1,1,1,1,1,1,29,1,1,1,1,1,1,1,1,1,1,1,1,1,1,1,1,1,1,1,1
1,1,1,1,1,1,1,1,1,1,1,1,1,1,1,1,2,3,2,2,3,3,3,2,1,2,1,2,3,3,3,1,1,1,1,1
1,1,1,1,1,1,1,1,29,29,2,2,2,1,2,3,3,3,3,3,3,3,3,3,3,3,3,3,3,3,3,3,2,1,1,1
1,1,1,1,1,1,1,1,2,22,23,21,23,21,24,24,23,21,22,23,23,22,21,23,24,23,21,22,21,22,24,3,3,1,1,1
1,1,1,1,1,1,1,1,1,23,0,0,0,0,0,0,6,0,0,6,0,0,0,0,0,6,0,0,6,0,22,3,2,1,1,1
1,1,1,1,1,1,1,1,2,21,0,0,0,0,0,0,0,0,0,9,9,0,0,0,0,0,0,0,0,0,21,3,3,1,1,1
1,1,1,1,1,1,1,1,3,22,7,0,51,0,0,0,51,8,24,23,22,23,7,51,0,0,0,51,0,8,24,3,2,1,1,1
1,1,1,1,1,1,1,2,3,21,0,0,0,0,0,0,0,0,22,53,52,24,7,0,0,0,0,0,0,0,21,3,2,1,1,1
1,1,1,1,1,1,1,3,3,23,0,0,0,0,0,0,0,0,22,53,52,23,7,0,0,0,0,0,0,8,24,3,1,1,1,1
1,1,1,1,1,1,1,3,3,24,0,0,0,0,0,0,0,0,0,23,24,51,0,0,0,0,0,0,0,8,22,3,2,1,1,1
1,1,1,1,1,1,1,3,3,24,0,0,51,0,0,0,51,0,0,37,37,0,0,51,0,0,0,51,0,0,23,3,3,1,1,1
1,1,1,1,1,1,1,3,3,21,0,0,9,0,0,0,0,0,51,0,0,51,0,0,0,0,0,9,0,9,21,3,3,1,1,1
1,1,1,1,1,1,1,3,3,23,0,8,23,22,23,0,0,51,24,24,24,23,51,0,51,23,24,23,0,0,24,3,3,1,1,1
1,1,1,1,1,1,1,3,3,23,0,8,22,54,54,23,37,0,24,55,55,24,0,37,22,54,54,22,7,0,22,3,3,1,1,1
1,1,1,1,1,1,1,3,3,23,0,8,22,56,56,24,37,0,24,55,55,24,0,37,23,56,56,22,0,8,22,3,3,1,1,1
1,1,1,1,1,1,1,3,3,23,0,0,24,23,23,0,0,51,23,24,24,22,51,0,51,23,22,23,0,0,23,3,3,1,1,1
1,1,1,1,1,1,1,3,3,21,0,0,6,0,6,0,0,0,51,0,0,51,0,0,0,0,0,6,0,0,21,3,3,1,1,1
1,1,1,1,1,1,1,3,3,23,7,0,51,0,0,0,51,0,0,37,37,0,0,51,0,0,0,51,0,0,22,3,3,1,1,1
1,1,1,1,1,1,1,2,3,22,0,0,0,0,0,0,0,0,0,24,24,51,0,0,0,0,0,0,0,0,22,3,3,1,1,1
1,1,1,1,1,1,1,3,3,24,0,0,0,0,0,0,0,0,22,53,52,22,0,0,0,0,0,0,0,8,23,3,3,1,1,1
1,1,1,1,1,1,1,3,3,21,0,0,0,0,0,0,0,0,22,53,52,23,0,0,0,0,0,0,0,8,21,3,1,1,1,1
1,1,1,1,1,1,1,3,3,22,0,0,51,0,0,0,51,8,24,23,23,24,7,51,0,0,0,0,0,0,22,3,2,1,1,1
1,1,1,1,1,1,2,3,3,21,0,0,0,0,0,0,0,0,0,6,6,0,0,0,0,0,0,0,0,8,21,3,3,1,1,1
1,1,1,1,1,1,1,2,3,22,0,0,0,9,0,0,0,0,0,9,0,0,0,9,0,9,0,9,0,0,22,3,1,1,1,1
1,1,1,1,1,1,1,2,3,24,22,21,22,21,23,23,24,21,22,24,24,23,21,24,22,22,21,23,21,22,24,3,1,1,1,1
1,1,1,1,1,1,1,2,3,3,3,3,3,3,3,3,3,3,3,3,3,3,3,3,3,3,3,3,3,3,3,3,1,1,1,1
1,1,1,1,1,1,1,1,2,3,3,3,3,2,3,3,3,3,3,3,3,2,3,3,3,2,2,3,3,2,2,1,1,1,1,1
1,1,1,1,1,1,1,1,1,1,1,1,1,1,1,1,1,1,1,1,1,1,1,1,1,1,1,1,1,1,1,1,1,1,1,1
1,1,1,1,1,1,1,1,1,1,1,1,1,1,1,1,1,1,1,1,1,1,1,1,1,1,1,1,1,1,1,1,1,1,1,1
1,1,1,1,1,1,1,1,1,1,1,1,1,1,1,1,1,1,1,1,1,1,1,1,1,1,1,1,1,1,1,1,1,1,1,1
1,1,1,1,1,1,1,1,1,1,1,1,1,1,1,1,1,1,1,1,1,1,1,1,1,1,1,1,1,1,1,1,1,1,1,1
1,1,1,1,1,1,1,1,1,1,1,1,1,1,1,1,1,1,1,1,1,1,1,1,1,1,1,1,1,1,1,1,1,1,1,1
1,1,1,1,1,1,1,1,1,1,1,1,1,1,1,1,1,1,1,1,1,1,1,1,1,1,1,1,1,1,1,1,1,1,1,1
endlayer

layer
1,1,1,1,1,1,1,1,1,1,1,1,1,1,1,1,1,1,1,1,1,1,1,1,1,1,1,1,1,1,1,1,1,1,1,1
1,1,1,1,1,1,1,1,1,1,1,1,1,1,1,1,1,1,1,1,1,1,1,1,1,1,1,1,1,1,1,1,1,1,1,1
1,1,1,1,1,1,1,1,1,1,1,1,1,1,1,1,1,1,1,1,1,1,1,1,1,1,1,1,1,1,1,1,1,1,1,1
1,1,1,1,1,1,1,1,1,1,1,1,1,1,1,29,1,1,1,1,1,1,1,1,1,1,1,1,1,1,1,1,1,1,1,1
1,1,1,1,1,1,1,1,1,1,1,1,1,1,1,1,1,2,1,1,2,3,2,1,1,1,1,1,3,3,2,1,1,1,1,1
1,1,1,1,1,1,1,1,29,29,1,1,1,1,1,3,3,3,3,3,3,3,3,3,3,2,3,3,3,3,3,3,1,1,1,1
1,1,1,1,1,1,1,1,1,24,24,21,23,21,21,21,23,21,24,22,24,24,21,22,21,21,21,23,21,22,24,3,2,1,1,1
1,1,1,1,1,1,1,1,1,23,7,0,6,0,0,0,6,0,0,6,0,0,0,0,0,6,0,0,0,0,24,3,1,1,1,1
1,1,1,1,1,1,1,1,1,21,0,0,0,0,0,0,0,0,0,9,9,0,0,0,0,0,0,0,0,0,21,3,2,1,1,1
1,1,1,1,1,1,1,1,2,23,0,0,0,0,0,0,0,8,24,24,22,24,0,0,0,0,0,0,0,8,23,3,1,1,1,1
1,1,1,1,1,1,1,1,3,21,0,0,0,0,0,0,0,8,24,55,55,24,7,0,0,0,0,0,0,0,21,3,1,1,1,1
1,1,1,1,1,1,1,3,3,21,0,0,0,0,0,0,0,0,23,55,55,22,7,0,0,0,0,0,0,8,21,3,1,1,1,1
1,1,1,1,1,1,1,3,3,21,0,0,0,0,0,0,0,0,0,24,23,0,0,0,0,0,0,0,0,0,21,3,1,1,1,1
1,1,1,1,1,1,1,2,3,22,0,0,0,0,0,0,0,0,0,37,37,0,0,0,0,0,0,0,0,0,24,3,2,1,1,1
1,1,1,1,1,1,1,3,3,21,0,0,9,0,0,0,0,0,9,0,0,9,0,0,0,0,0,9,9,9,21,3,3,1,1,1
1,1,1,1,1,1,1,2,3,22,0,8,24,24,23,0,0,8,22,0,0,24,7,0,0,23,23,23,0,0,24,3,3,1,1,1
1,1,1,1,1,1,1,3,3,24,0,8,24,55,55,22,37,0,0,0,0,0,0,37,24,55,55,22,7,0,22,3,3,1,1,1
1,1,1,1,1,1,1,3,3,24,7,8,24,55,55,23,37,0,0,0,0,0,0,37,23,55,55,23,7,8,23,3,3,1,1,1
1,1,1,1,1,1,1,2,3,23,0,0,22,22,22,6,0,8,23,0,0,22,7,0,0,24,23,23,0,0,23,3,3,1,1,1
1,1,1,1,1,1,1,3,3,21,6,0,6,0,6,0,0,0,6,0,0,6,0,0,0,0,0,6,0,0,21,3,3,1,1,1
1,1,1,1,1,1,1,3,3,22,7,0,0,0,0,0,0,0,0,37,37,0,0,0,0,0,0,0,0,0,22,3,3,1,1,1
1,1,1,1,1,1,1,1,3,21,0,0,0,0,0,0,0,0,0,22,23,0,0,0,0,0,0,0,0,0,21,3,2,1,1,1
1,1,1,1,1,1,1,2,3,21,0,0,0,0,0,0,0,0,24,55,55,23,0,0,0,0,8,0,0,8,21,3,2,1,1,1
1,1,1,1,1,1,1,3,3,21,0,0,0,0,0,0,0,0,23,55,55,24,0,0,0,0,0,0,0,8,21,3,1,1,1,1
1,1,1,1,1,1,1,3,3,22,0,0,0,0,0,0,0,8,22,23,22,23,7,0,0,0,0,0,0,0,23,3,1,1,1,1
1,1,1,1,1,1,1,2,3,21,0,0,0,0,0,0,0,0,0,6,6,6,0,0,0,0,0,0,0,8,21,3,3,1,1,1
1,1,1,1,1,1,1,1,3,24,0,0,0,9,0,0,0,0,0,9,0,0,0,9,0,9,0,9,0,0,23,3,1,1,1,1
1,1,1,1,1,1,1,1,3,24,24,21,22,21,21,21,22,21,23,23,23,22,21,24,21,21,21,23,21,23,24,3,1,1,1,1
1,1,1,1,1,1,1,1,3,3,3,3,3,3,3,3,3,3,3,3,3,3,3,3,3,3,3,3,3,3,3,3,1,1,1,1
1,1,1,1,1,1,1,1,1,2,3,2,2,1,2,3,2,2,2,3,2,1,2,3,2,1,1,2,3,1,1,1,1,1,1,1
1,1,1,1,1,1,1,1,1,1,1,1,1,1,1,1,1,1,1,1,1,1,1,1,1,1,1,1,1,1,1,1,1,1,1,1
1,1,1,1,1,1,1,1,1,1,1,1,1,1,1,1,1,1,1,1,1,1,1,1,1,1,1,1,1,1,1,1,1,1,1,1
1,1,1,1,1,1,1,1,1,1,1,1,1,1,1,1,1,1,1,1,1,1,1,1,1,1,1,1,1,1,1,1,1,1,1,1
1,1,1,1,1,1,1,1,1,1,1,1,1,1,1,1,1,1,1,1,1,1,1,1,1,1,1,1,1,1,1,1,1,1,1,1
1,1,1,1,1,1,1,1,1,1,1,1,1,1,1,1,1,1,1,1,1,1,1,1,1,1,1,1,1,1,1,1,1,1,1,1
1,1,1,1,1,1,1,1,1,1,1,1,1,1,1,1,1,1,1,1,1,1,1,1,1,1,1,1,1,1,1,1,1,1,1,1
endlayer

layer
1,1,1,1,1,1,1,1,1,1,1,1,1,1,1,1,1,1,1,1,1,1,1,1,1,1,1,1,1,1,1,1,1,1,1,1
1,1,1,1,1,1,1,1,1,1,1,1,1,1,1,1,1,1,1,1,1,1,1,1,1,1,1,1,1,1,1,1,1,1,1,1
1,1,1,1,1,1,1,1,1,1,1,1,1,1,1,1,1,1,1,1,1,1,1,1,1,1,1,1,1,1,1,1,1,1,1,1
1,1,1,1,1,1,1,1,1,1,1,1,1,1,1,29,1,1,1,1,1,1,1,1,1,1,1,1,1,1,1,1,1,1,1,1
1,1,1,1,1,1,1,1,29,29,1,1,1,1,1,1,1,1,1,1,1,3,1,1,1,1,1,1,3,3,1,1,1,1,1,1
1,1,1,1,1,1,1,1,29,29,1,1,1,1,1,2,3,3,3,3,3,3,3,3,3,1,2,3,3,3,3,3,1,1,1,1
1,1,1,1,1,1,1,1,1,23,22,21,22,24,22,21,23,21,23,23,24,22,21,22,21,23,24,23,21,22,23,3,1,1,1,1
1,1,1,1,1,1,1,1,1,23,0,0,6,0,0,0,6,0,0,6,0,0,0,6,0,6,0,6,0,8,22,2,1,1,1,1
1,1,1,1,1,1,1,1,1,21,0,0,0,0,0,0,0,0,0,9,9,0,0,0,0,0,0,0,0,0,21,3,1,1,1,1
1,1,1,1,1,1,1,1,1,23,0,0,0,0,0,0,0,8,24,24,24,24,0,0,0,0,0,0,0,0,22,3,1,1,1,1
1,1,1,1,1,1,1,1,3,23,0,0,0,0,0,0,0,0,23,0,0,24,0,0,0,0,0,0,0,0,22,3,1,1,1,1
1,1,1,1,1,1,1,2,3,22,7,0,0,0,0,0,0,0,23,0,0,22,7,0,0,0,0,0,0,8,24,3,1,1,1,1
1,1,1,1,1,1,1,3,3,21,0,0,0,0,0,0,0,0,0,22,23,0,0,0,0,0,0,0,0,0,21,3,1,1,1,1
1,1,1,1,1,1,1,1,3,23,0,0,0,0,0,0,0,0,0,37,37,0,0,0,0,0,0,0,0,0,22,3,1,1,1,1
1,1,1,1,1,1,1,2,3,21,9,0,9,0,9,0,0,0,9,0,0,9,0,0,0,0,0,9,9,9,21,3,3,1,1,1
1,1,1,1,1,1,1,1,3,24,0,0,24,22,24,0,0,8,22,0,0,24,7,0,0,24,23,22,7,8,24,3,2,1,1,1
1,1,1,1,1,1,1,3,3,23,0,8,23,0,0,24,37,0,0,0,0,0,0,37,22,0,0,22,0,0,22,3,2,1,1,1
1,1,1,1,1,1,1,3,3,24,0,8,22,0,0,22,37,0,0,0,0,0,0,37,24,0,0,22,7,8,24,3,2,1,1,1
1,1,1,1,1,1,1,1,3,23,0,0,22,22,22,6,0,8,23,0,0,23,0,0,0,22,24,23,0,0,24,3,2,1,1,1
1,1,1,1,1,1,1,2,3,21,6,0,6,0,6,0,0,0,6,0,0,6,0,0,0,0,0,6,6,0,21,3,3,1,1,1
1,1,1,1,1,1,1,2,3,24,7,0,0,0,0,0,0,0,0,37,37,0,0,0,0,0,0,0,0,8,22,3,2,1,1,1
1,1,1,1,1,1,1,1,3,21,0,0,0,0,0,0,0,0,0,22,23,0,0,0,0,0,0,0,0,0,21,3,1,1,1,1
1,1,1,1,1,1,1,1,3,23,0,0,0,0,0,0,0,0,22,0,0,22,7,0,0,0,8,0,0,8,24,3,1,1,1,1
1,1,1,1,1,1,1,3,3,23,0,0,0,0,0,0,0,0,22,0,0,23,0,0,0,0,0,0,0,0,24,3,1,1,1,1
1,1,1,1,1,1,1,3,3,24,0,0,0,0,0,0,0,8,24,22,24,22,7,0,0,0,0,0,0,0,22,3,1,1,1,1
1,1,1,1,1,1,1,1,3,21,0,0,0,0,0,0,0,0,0,6,0,0,0,0,0,0,0,0,0,8,21,3,3,1,1,1
1,1,1,1,1,1,1,1,3,24,0,0,0,9,0,0,0,8,0,9,0,0,0,9,0,9,9,9,0,0,23,3,1,1,1,1
1,1,1,1,1,1,1,1,2,22,22,21,22,22,23,21,22,21,22,23,22,22,21,24,21,22,22,24,21,24,24,2,1,1,1,1
1,1,1,1,1,1,1,1,2,3,3,3,3,3,3,3,3,3,3,3,3,3,3,3,3,3,3,3,3,3,3,2,1,1,1,1
1,1,1,1,1,1,1,1,1,1,2,1,1,1,1,3,1,1,1,3,1,1,1,2,1,1,1,1,3,1,1,1,1,1,1,1
1,1,1,1,1,1,1,1,1,1,1,1,1,1,1,1,1,1,1,1,1,1,1,1,1,1,1,1,1,1,1,1,1,1,1,1
1,1,1,1,1,1,1,1,1,1,1,1,1,1,1,1,1,1,1,1,1,1,1,1,1,1,1,1,1,1,1,1,1,1,1,1
1,1,1,1,1,1,1,1,1,1,1,1,1,1,1,1,1,1,1,1,1,1,1,1,1,1,1,1,1,1,1,1,1,1,1,1
1,1,1,1,1,1,1,1,1,1,1,1,1,1,1,1,1,1,1,1,1,1,1,1,1,1,1,1,1,1,1,1,1,1,1,1
1,1,1,1,1,1,1,1,1,1,1,1,1,1,1,1,1,1,1,1,1,1,1,1,1,1,1,1,1,1,1,1,1,1,1,1
1,1,1,1,1,1,1,1,1,1,1,1,1,1,1,1,1,1,1,1,1,1,1,1,1,1,1,1,1,1,1,1,1,1,1,1
endlayer

layer
0,0,0,0,0,0,0,0,0,0,0,0,0,0,0,0,0,0,0,0,0,0,0,0,0,0,0,0,0,0,0,0,0,0,0,0
0,0,0,0,0,0,0,0,0,0,0,0,0,0,0,0,0,0,0,0,0,0,0,0,0,0,0,0,0,0,0,0,0,0,0,0
0,0,0,0,0,0,0,0,0,0,0,0,0,0,0,9,0,0,0,0,0,0,0,0,0,0,0,0,0,0,0,0,0,0,0,0
0,0,0,0,0,0,0,0,9,9,0,0,0,0,8,29,0,0,0,0,0,9,0,0,0,0,0,0,9,9,0,0,0,0,0,0
0,0,0,0,0,0,0,8,29,29,7,0,0,0,0,0,0,0,0,9,9,3,15,9,9,0,0,8,3,3,7,9,0,0,0,0
0,0,0,0,0,0,0,8,29,29,15,9,9,9,9,8,2,3,2,3,3,3,2,2,3,7,57,2,3,3,2,29,7,0,0,0
0,0,0,0,0,0,0,0,17,23,22,21,21,21,21,21,22,21,24,23,22,22,21,23,21,21,21,21,21,23,22,2,7,0,0,0
0,0,0,0,0,0,0,0,8,22,0,0,6,0,0,0,6,0,0,0,0,6,7,6,0,6,0,6,0,8,22,57,0,0,0,0
0,0,0,0,0,0,0,0,8,21,0,0,0,0,0,0,0,8,0,0,9,0,7,0,0,0,0,0,0,0,21,2,0,0,0,0
0,0,0,0,0,0,0,0,8,21,0,0,0,0,0,0,0,8,23,23,23,24,0,0,0,0,0,0,0,0,21,3,7,0,0,0
0,0,0,0,0,0,0,0,2,21,0,0,0,0,0,0,0,0,0,24,23,6,0,0,0,0,0,0,0,0,21,2,7,0,0,0
0,0,0,0,0,0,0,57,3,21,0,0,0,0,0,0,0,0,0,24,23,0,0,0,0,0,0,0,0,8,21,2,0,0,0,0
0,0,0,0,0,0,0,2,3,21,0,0,0,0,0,0,0,0,0,22,22,0,0,0,0,0,0,0,0,0,21,2,0,0,0,0
0,0,0,0,0,0,0,8,3,22,7,0,0,0,0,0,0,0,0,37,37,0,0,0,0,0,0,0,0,0,23,3,7,0,0,0
0,0,0,0,0,0,0,57,3,21,9,9,9,0,0,0,0,0,9,0,0,9,0,0,0,0,0,9,9,9,21,3,2,0,0,0
0,0,0,0,0,0,0,8,3,22,0,0,22,9,0,9,0,8,22,0,0,23,7,0,0,0,0,24,7,0,23,3,57,0,0,0
0,0,0,0,0,0,0,2,3,22,0,0,23,22,24,23,37,0,0,0,0,0,0,37,24,22,24,24,0,0,23,3,57,0,0,0
0,0,0,0,0,0,0,2,3,24,0,8,24,22,22,24,37,0,0,0,0,9,0,37,24,23,22,24,7,8,24,3,57,0,0,0
0,0,0,0,0,0,0,8,3,23,0,0,24,0,0,6,0,8,24,0,0,24,0,0,0,0,0,24,7,0,24,3,57,0,0,0
0,0,0,0,0,0,0,57,3,21,6,6,6,0,0,0,0,0,6,0,0,6,0,0,0,0,0,6,6,0,21,3,29,7,0,0
0,0,0,0,0,0,0,57,2,22,7,0,0,0,0,0,0,0,0,37,37,0,0,0,0,0,0,0,0,0,22,3,57,0,0,0
0,0,0,0,0,0,0,0,2,21,0,0,0,0,0,0,0,0,0,23,22,0,0,0,0,0,0,0,0,0,21,3,7,0,0,0
0,0,0,0,0,0,0,9,2,21,0,0,0,0,0,0,0,0,8,23,22,0,0,0,0,0,8,0,0,8,21,2,0,0,0,0
0,0,0,0,0,0,8,3,3,21,0,0,0,0,0,0,0,0,8,23,23,0,0,0,0,0,0,0,0,0,21,2,0,0,0,0
0,0,0,0,0,0,8,3,3,21,7,0,0,0,0,0,0,8,24,22,23,23,7,0,0,0,0,0,0,0,21,2,9,0,0,0
0,0,0,0,0,0,0,6,3,21,0,0,0,0,0,0,0,0,0,0,0,0,0,0,0,0,0,0,0,0,21,2,29,7,0,0
0,0,0,0,0,0,0,0,2,22,0,0,0,0,0,0,9,8,0,9,9,0,0,0,0,9,0,9,0,0,24,2,12,0,0,0
0,0,0,0,0,0,0,0,57,22,24,21,21,21,21,21,24,21,23,24,22,23,21,22,21,21,21,21,21,23,23,57,0,0,0,0
0,0,0,0,0,0,0,0,57,3,3,3,2,3,3,3,3,2,3,3,3,3,3,2,3,3,2,3,3,2,2,57,0,0,0,0
0,0,0,0,0,0,0,0,0,6,57,6,0,6,6,29,6,0,6,29,6,6,6,57,6,6,0,6,29,0,6,0,0,0,0,0
0,0,0,0,0,0,0,0,0,0,0,0,0,0,0,6,0,0,0,6,0,0,0,0,0,0,0,0,6,0,0,0,0,0,0,0
0,0,0,0,0,0,0,0,0,0,0,0,0,0,0,0,0,0,0,0,0,0,0,0,0,0,0,0,0,0,0,0,0,0,0,0
0,0,0,0,0,0,0,0,0,0,0,0,0,0,0,0,0,0,0,0,0,0,0,0,0,0,0,0,0,0,0,0,0,0,0,0
0,0,0,0,0,0,0,0,0,0,0,0,0,0,0,0,0,0,0,0,0,0,0,0,0,0,0,0,0,0,0,0,0,0,0,0
0,0,0,0,0,0,0,0,0,0,0,0,0,0,0,0,0,0,0,0,0,0,0,0,0,0,0,0,0,0,0,0,0,0,0,0
0,0,0,0,0,0,0,0,0,0,0,0,0,0,0,0,0,0,0,0,0,0,0,0,0,0,0,0,0,0,0,0,0,0,0,0
endlayer

layer
0,0,0,0,0,0,0,0,0,0,0,0,0,0,0,0,0,0,0,0,0,0,0,0,0,0,0,0,0,0,0,0,0,0,0,0
0,0,0,0,0,0,0,0,0,0,0,0,0,0,0,0,0,0,0,0,0,0,0,0,0,0,0,0,0,0,0,0,0,0,0,0
0,0,0,0,0,0,0,0,0,0,0,0,0,0,0,9,0,0,0,0,0,0,0,0,0,0,0,0,0,0,0,0,0,0,0,0
0,0,0,0,0,0,0,0,9,9,0,0,0,0,8,29,0,0,0,0,0,9,0,0,0,0,0,0,9,9,0,0,0,0,0,0
0,0,0,0,0,0,0,8,29,29,7,0,0,0,0,0,0,0,0,9,9,29,7,0,9,0,0,8,3,3,7,9,0,0,0,0
0,0,0,0,0,0,0,8,29,29,15,9,9,9,9,0,8,29,57,2,2,2,57,57,3,7,0,57,3,3,57,29,7,0,0,0
0,0,0,0,0,0,0,0,17,22,24,23,23,22,22,24,23,24,22,23,24,24,24,24,24,24,24,23,23,23,23,57,0,0,0,0
0,0,0,0,0,0,0,0,8,24,0,0,6,0,0,0,6,8,22,28,28,22,7,0,0,6,0,0,0,8,22,7,0,0,0,0
0,0,0,0,0,0,0,0,8,24,0,0,0,0,0,0,0,8,22,28,28,22,7,0,0,0,0,0,0,0,23,57,0,0,0,0
0,0,0,0,0,0,0,0,8,24,7,0,0,0,0,0,0,8,23,22,22,23,7,0,0,0,0,0,0,8,23,3,7,0,0,0
0,0,0,0,0,0,0,0,57,23,0,0,0,0,7,0,0,0,0,0,0,6,0,6,0,0,0,0,0,0,24,57,0,0,0,0
0,0,0,0,0,0,0,0,2,23,0,0,0,0,0,0,0,0,0,0,0,0,0,0,0,0,6,0,0,8,24,7,0,0,0,0
0,0,0,0,0,0,0,57,3,23,0,0,0,0,0,0,0,0,0,0,0,0,0,0,0,0,0,0,0,0,23,57,0,0,0,0
0,0,0,0,0,0,0,8,3,23,0,0,0,0,0,0,0,0,0,37,37,0,0,0,0,0,0,0,0,0,22,2,7,0,0,0
0,0,0,0,0,0,0,0,2,23,9,9,9,0,0,0,0,0,9,0,0,9,0,0,0,0,0,9,9,9,22,3,57,0,0,0
0,0,0,0,0,0,0,8,2,24,22,22,23,0,0,0,0,8,22,0,0,24,7,0,0,0,0,23,22,22,22,2,7,0,0,0
0,0,0,0,0,0,0,57,2,23,28,28,23,0,0,0,37,0,0,0,0,0,0,37,0,0,0,23,28,28,23,2,0,0,0,0
0,0,0,0,0,0,0,57,2,22,28,28,23,0,0,0,37,0,0,0,0,9,0,37,0,0,0,23,28,28,24,2,7,0,0,0
0,0,0,0,0,0,0,8,2,24,22,22,24,0,0,0,0,8,22,0,0,22,0,0,0,0,0,23,22,22,23,2,0,0,0,0
0,0,0,0,0,0,0,0,2,23,6,6,6,0,0,0,0,0,6,0,0,6,0,0,0,0,0,6,6,6,24,2,29,7,0,0
0,0,0,0,0,0,0,0,57,22,0,0,0,0,0,0,0,0,0,37,37,0,0,0,0,0,0,0,0,0,23,2,58,0,0,0
0,0,0,0,0,0,0,0,57,23,0,0,0,7,0,0,0,0,0,0,0,0,0,0,0,0,0,0,0,0,22,3,7,0,0,0
0,0,0,0,0,0,0,9,57,22,7,0,0,7,0,0,0,0,0,0,0,0,0,0,0,0,8,0,0,8,22,57,0,0,0,0
0,0,0,0,0,0,8,3,3,22,0,0,0,0,0,9,0,0,0,0,0,0,0,0,0,0,0,0,0,0,22,57,0,0,0,0
0,0,0,0,0,0,8,3,3,23,0,0,0,0,0,0,13,8,24,24,22,24,7,0,0,0,0,0,0,0,22,57,9,0,0,0
0,0,0,0,0,0,0,6,2,22,0,0,0,0,0,0,0,8,22,28,28,22,7,0,0,0,0,0,0,0,24,57,29,7,0,0
0,0,0,0,0,0,0,0,57,24,0,9,0,0,0,0,9,8,22,28,28,22,7,0,0,9,0,0,0,0,22,57,6,0,0,0
0,0,0,0,0,0,0,0,8,23,24,22,24,22,24,22,23,24,23,24,23,24,22,23,22,22,22,24,22,22,24,7,0,0,0,0
0,0,0,0,0,0,0,0,0,29,2,2,57,2,2,2,2,57,2,2,2,2,2,57,2,3,58,2,2,58,58,0,0,0,0,0
0,0,0,0,0,0,0,0,0,6,6,6,0,6,6,29,6,0,6,29,6,6,6,0,6,6,58,58,29,58,58,0,0,0,0,0
0,0,0,0,0,0,0,0,0,0,0,0,0,0,0,6,0,0,0,6,0,0,0,0,0,0,58,58,58,58,58,0,0,0,0,0
0,0,0,0,0,0,0,0,0,0,0,0,0,0,0,0,0,0,0,0,0,0,0,0,0,0,0,58,58,58,58,0,0,0,0,0
0,0,0,0,0,0,0,0,0,0,0,0,0,0,0,0,0,0,0,0,0,0,0,0,0,0,0,0,0,0,0,0,0,0,0,0
0,0,0,0,0,0,0,0,0,0,0,0,0,0,0,0,0,0,0,0,0,0,0,0,0,0,0,0,0,0,0,0,0,0,0,0
0,0,0,0,0,0,0,0,0,0,0,0,0,0,0,0,0,0,0,0,0,0,0,0,0,0,0,0,0,0,0,0,0,0,0,0
0,0,0,0,0,0,0,0,0,0,0,0,0,0,0,0,0,0,0,0,0,0,0,0,0,0,0,0,0,0,0,0,0,0,0,0
endlayer

layer
0,0,0,0,0,0,0,0,0,0,0,0,0,0,0,0,0,0,0,0,0,0,0,0,0,0,0,0,0,0,0,0,0,0,0,0
0,0,0,0,0,0,0,0,0,0,0,0,0,58,58,58,58,58,0,0,0,0,0,0,0,0,0,0,0,0,0,0,0,0,0,0
0,0,0,0,0,0,0,0,0,0,0,0,0,58,58,58,58,58,0,0,0,0,0,0,0,0,0,0,0,0,0,0,0,0,0,0
0,0,0,0,0,0,0,0,9,9,0,0,0,58,58,29,58,58,0,0,0,9,0,0,0,0,0,0,9,9,0,0,0,0,0,0
0,0,0,0,0,0,0,8,29,29,7,0,0,58,58,58,58,58,0,0,0,29,7,0,9,0,0,8,29,29,7,9,0,0,0,0
0,0,0,0,0,0,0,8,29,29,7,0,0,58,58,58,58,29,15,57,57,57,0,0,29,7,0,8,29,29,7,29,7,0,0,0
0,0,0,0,0,0,0,0,6,6,0,9,0,9,0,0,0,0,21,59,59,21,0,9,0,0,9,0,6,6,0,6,0,0,0,0
0,0,0,0,0,0,0,0,0,0,24,22,23,23,23,22,22,24,24,23,24,24,24,24,22,22,22,24,22,22,0,0,0,0,0,0
0,0,0,0,0,0,0,0,0,8,22,23,24,24,24,24,22,22,23,23,24,22,22,22,23,23,23,22,23,22,7,0,0,0,0,0
0,0,0,0,0,0,0,0,0,0,23,24,23,23,24,24,23,23,22,24,23,23,24,23,23,23,24,23,23,23,0,29,7,0,0,0
0,0,0,0,0,0,0,0,0,0,23,22,22,22,7,6,6,0,0,60,60,0,0,6,0,0,23,23,24,23,0,0,0,0,0,0
0,0,0,0,0,0,0,0,57,9,22,22,22,0,0,0,0,0,0,60,60,0,0,0,0,0,6,22,24,23,7,0,0,0,0,0
0,0,0,0,0,0,0,8,3,3,24,23,22,7,0,0,0,0,0,60,60,0,0,0,0,0,0,24,22,23,0,0,0,0,0,0
0,0,0,0,0,0,0,8,3,3,23,23,22,0,0,0,0,0,0,37,37,0,0,0,0,0,8,22,22,22,7,9,0,0,0,0
0,0,0,0,0,0,0,0,57,6,24,24,22,0,0,0,0,0,9,0,0,9,0,0,0,0,0,24,22,22,0,29,7,0,0,0
0,0,0,0,0,0,0,0,57,21,24,24,22,0,0,0,0,8,22,0,0,22,0,0,0,0,0,23,24,23,21,57,0,0,0,0
0,0,0,0,0,0,0,0,57,62,23,22,23,61,61,61,37,0,0,0,0,0,0,37,62,62,62,24,24,22,61,57,0,0,0,0
0,0,0,0,0,0,0,0,57,62,22,22,22,61,61,61,37,0,0,0,0,9,0,37,62,62,62,23,24,22,61,57,0,0,0,0
0,0,0,0,0,0,0,0,57,21,24,22,23,0,0,0,0,8,24,7,0,24,0,0,0,0,0,22,23,23,21,57,58,0,0,0
0,0,0,0,0,0,0,0,57,0,22,24,24,0,0,0,0,0,6,0,0,6,0,0,0,0,0,23,22,22,0,58,29,58,0,0
0,0,0,0,0,0,0,0,0,0,22,23,22,0,0,0,0,0,0,37,37,0,0,0,0,0,8,24,23,23,58,58,58,0,0,0
0,0,0,0,0,0,0,0,0,8,24,23,23,7,0,0,0,0,0,59,59,0,0,0,0,0,0,22,24,23,58,29,7,0,0,0
0,0,0,0,0,0,0,9,9,0,22,23,23,7,0,0,0,0,0,59,59,0,0,0,0,0,8,24,23,22,58,58,0,0,0,0
0,0,0,0,0,0,8,29,29,7,24,23,22,24,0,9,0,0,0,59,59,0,0,9,0,9,23,24,22,23,0,0,0,0,0,0
0,0,0,0,0,0,8,29,29,7,24,24,23,24,24,23,23,23,22,22,23,23,23,23,24,23,24,23,23,23,0,0,9,0,0,0
0,0,0,0,0,0,0,6,57,0,22,24,23,22,24,24,22,23,24,22,22,23,23,23,22,22,22,23,22,23,0,8,29,7,0,0
0,0,0,0,0,0,0,0,0,8,24,22,22,23,23,22,23,23,22,23,24,24,22,23,22,23,24,22,24,22,0,0,6,0,0,0
0,0,0,0,0,0,0,0,0,58,58,0,0,0,0,0,0,0,21,60,60,21,0,6,58,58,0,58,58,58,58,0,0,0,0,0
0,0,0,0,0,0,0,0,58,29,57,57,0,57,57,57,57,0,57,57,57,57,57,0,57,29,58,58,58,58,58,0,0,0,0,0
0,0,0,0,0,0,0,0,0,58,0,0,0,0,0,29,0,0,0,29,0,0,0,0,0,6,58,58,29,58,58,0,0,0,0,0
0,0,0,0,0,0,0,0,0,0,0,0,0,0,0,6,0,0,0,6,0,0,0,0,0,0,58,58,58,58,58,0,0,0,0,0
0,0,0,0,0,0,0,0,0,0,0,0,0,0,0,13,0,0,0,0,0,0,0,0,0,0,0,58,58,58,0,0,0,0,0,0
0,0,0,0,0,0,0,0,0,0,0,0,0,0,0,0,0,0,0,0,0,0,0,0,0,0,0,0,0,0,0,0,0,0,0,0
0,0,0,0,0,0,0,0,0,0,0,0,0,0,0,0,0,0,0,0,0,0,0,0,0,0,0,0,0,0,0,0,0,0,0,0
0,0,0,0,0,0,0,0,0,0,0,0,0,0,0,0,0,0,0,0,0,0,0,0,0,0,0,0,0,0,0,0,0,0,0,0
0,0,0,0,0,0,0,0,0,0,0,0,0,0,0,0,0,0,0,0,0,0,0,0,0,0,0,0,0,0,0,0,0,0,0,0
endlayer

layer
0,0,0,0,0,0,0,0,0,0,0,0,0,0,0,0,0,0,0,0,0,0,0,0,0,0,0,0,0,0,0,0,0,0,0,0
0,0,0,0,0,0,0,0,0,0,0,0,0,0,58,58,58,58,0,0,0,0,0,0,0,0,0,0,0,0,0,0,0,0,0,0
0,0,0,0,0,0,0,0,0,0,0,0,0,58,58,58,58,58,0,0,0,0,0,0,0,0,0,0,0,0,0,0,0,0,0,0
0,0,0,0,0,0,0,0,9,63,0,0,0,58,58,29,58,58,0,0,0,9,0,0,0,0,0,0,9,9,0,0,0,0,0,0
0,0,0,0,0,0,0,8,29,29,7,0,0,58,58,58,58,58,0,0,64,29,7,0,9,0,0,8,29,29,7,58,0,0,0,0
0,0,0,0,0,0,0,8,29,29,7,0,0,58,58,58,58,29,7,0,0,0,0,0,29,7,0,8,29,29,7,29,58,0,0,0
0,0,0,0,0,0,0,0,6,6,0,0,0,0,0,0,0,0,9,0,0,0,0,0,0,0,0,0,6,6,0,6,0,0,0,0
0,0,0,0,0,0,0,0,0,0,0,0,9,9,0,9,0,8,21,59,59,21,0,9,0,9,0,0,0,0,58,58,58,0,0,0
0,0,0,0,0,0,0,0,0,0,0,22,24,24,24,24,23,23,24,32,32,24,24,23,23,22,23,22,24,58,58,58,58,58,0,0
0,0,0,0,0,0,0,0,0,0,0,23,24,22,24,23,24,23,21,38,38,21,24,23,24,23,22,22,22,58,58,29,58,58,0,0
0,0,0,0,0,0,0,0,0,0,0,23,22,24,0,0,6,0,46,40,40,46,0,6,0,0,22,22,24,58,58,58,58,58,0,0
0,0,0,0,0,0,0,0,9,9,0,24,23,0,0,0,0,0,46,42,42,46,0,0,0,0,6,23,23,58,58,58,58,58,0,0
0,0,0,0,0,0,0,8,29,29,7,24,22,7,0,0,0,0,46,65,65,46,0,0,0,0,0,24,23,0,0,0,0,0,0,0
0,0,0,0,0,0,0,8,29,29,7,22,22,0,0,0,0,0,0,66,66,0,0,0,0,0,8,22,24,0,0,9,0,0,0,0
0,0,0,0,0,0,0,0,6,6,0,22,24,0,0,0,0,0,9,0,0,9,0,0,0,0,0,24,22,0,0,29,7,0,0,0
0,0,0,0,0,0,0,0,0,0,21,23,21,46,46,46,0,8,22,0,0,23,7,0,46,46,46,21,22,21,7,0,0,0,0,0
0,0,0,0,0,0,0,0,0,0,62,32,38,40,42,65,66,0,0,0,0,0,0,66,65,42,40,38,32,61,0,0,0,0,0,0
0,0,0,0,0,0,0,0,0,0,62,32,38,40,42,65,66,0,0,0,0,0,0,66,65,42,40,38,32,61,0,0,0,0,0,0
0,0,0,0,0,0,0,0,0,0,21,24,21,46,46,46,0,8,24,7,0,23,0,0,46,46,46,21,24,21,7,0,9,0,0,0
0,0,0,0,0,0,0,0,0,0,6,24,23,0,0,0,0,0,6,0,0,6,0,0,0,0,0,23,24,7,0,0,29,67,0,0
0,0,0,0,0,0,0,0,0,0,8,23,24,0,0,0,0,0,0,66,66,0,0,0,0,0,8,24,23,7,0,0,6,0,0,0
0,0,0,0,0,0,0,0,0,0,0,22,23,7,0,0,0,0,46,65,65,46,0,0,0,0,0,24,22,0,58,29,7,0,0,0
0,0,0,0,0,0,0,9,9,0,0,24,24,0,0,0,0,0,46,42,42,46,0,0,0,0,8,24,24,0,0,58,0,0,0,0
0,0,0,0,0,0,8,29,29,7,0,24,22,24,0,0,0,0,46,40,40,46,0,9,0,9,22,24,23,0,0,0,0,0,0,0
0,0,0,0,0,0,8,29,29,7,0,23,24,24,24,22,24,22,21,38,38,21,22,22,24,22,23,22,22,0,0,0,58,0,0,0
0,0,0,0,0,0,0,6,6,0,0,22,24,22,22,23,22,23,24,32,32,24,24,22,23,22,24,24,24,0,0,8,29,7,0,0
0,0,0,0,0,0,0,0,0,58,0,0,0,0,0,0,0,0,21,60,60,21,0,0,0,58,0,0,0,0,0,0,6,0,0,0
0,0,0,0,0,0,0,0,0,58,58,0,0,0,58,58,58,58,58,58,58,58,0,0,58,58,58,0,0,0,0,0,0,0,0,0
0,0,0,0,0,0,0,0,58,29,58,0,0,58,58,58,58,58,58,58,58,58,0,0,8,29,7,58,58,0,0,0,0,0,0,0
0,0,0,0,0,0,0,0,0,6,0,0,0,58,58,29,58,58,58,29,58,58,0,0,0,6,0,58,29,58,0,0,0,0,0,0
0,0,0,0,0,0,0,0,0,0,0,0,0,58,58,58,58,58,58,58,58,58,0,0,0,0,0,58,58,58,0,0,0,0,0,0
0,0,0,0,0,0,0,0,0,0,0,0,0,58,58,58,58,58,58,58,58,0,0,0,0,0,0,0,0,0,0,0,0,0,0,0
0,0,0,0,0,0,0,0,0,0,0,0,0,0,0,0,0,0,0,0,0,0,0,0,0,0,0,0,0,0,0,0,0,0,0,0
0,0,0,0,0,0,0,0,0,0,0,0,0,0,0,0,0,0,0,0,0,0,0,0,0,0,0,0,0,0,0,0,0,0,0,0
0,0,0,0,0,0,0,0,0,0,0,0,0,0,0,0,0,0,0,0,0,0,0,0,0,0,0,0,0,0,0,0,0,0,0,0
0,0,0,0,0,0,0,0,0,0,0,0,0,0,0,0,0,0,0,0,0,0,0,0,0,0,0,0,0,0,0,0,0,0,0,0
endlayer

layer
0,0,0,0,0,0,0,0,0,0,0,0,0,0,0,0,0,0,0,0,0,0,0,0,0,0,0,0,0,0,0,0,0,0,0,0
0,0,0,0,0,0,0,0,0,0,0,0,0,0,0,0,0,0,0,0,0,0,0,0,0,0,0,0,0,0,0,0,0,0,0,0
0,0,0,0,0,0,0,0,0,0,0,0,0,0,0,58,58,0,0,0,0,0,0,0,0,0,0,0,0,0,0,0,0,0,0,0
0,0,0,0,0,0,0,0,9,9,0,0,0,0,58,29,58,0,0,0,0,9,0,0,0,0,0,0,9,63,0,0,0,0,0,0
0,0,0,0,0,0,0,64,29,29,7,0,0,0,58,58,58,0,0,0,0,29,7,0,9,0,0,8,29,29,7,9,0,0,0,0
0,0,0,0,0,0,0,8,29,29,7,0,0,0,0,0,0,29,0,0,0,0,0,0,29,58,0,8,29,29,7,29,67,0,0,0
0,0,0,0,0,0,0,0,6,6,0,0,0,0,0,0,0,0,0,0,0,0,0,0,0,0,0,0,6,6,0,6,0,0,0,0
0,0,0,0,0,0,0,0,0,0,0,0,0,0,0,0,0,0,0,0,0,0,0,0,0,0,0,0,0,58,58,58,58,0,0,0
0,0,0,0,0,0,0,0,0,0,0,0,0,0,9,0,0,0,21,59,59,21,0,0,9,0,0,0,0,58,58,58,58,58,0,0
0,0,0,0,0,0,0,0,0,0,0,0,22,23,24,23,23,23,23,24,24,22,23,24,23,22,24,23,0,58,58,29,58,58,0,0
0,0,0,0,0,0,0,0,0,0,0,0,24,23,0,0,0,0,0,50,50,0,0,0,0,8,24,24,0,58,58,58,58,58,0,0
0,0,0,0,0,0,0,0,9,9,0,8,24,0,0,0,0,0,0,50,50,0,0,0,6,0,6,24,0,0,58,58,58,0,0,0
0,0,0,0,0,0,0,8,29,29,7,0,22,0,0,0,0,0,51,50,50,51,0,0,0,0,0,23,0,0,0,0,0,0,0,0
0,0,0,0,0,0,0,8,29,29,7,8,23,0,0,0,0,0,0,0,0,0,0,0,0,8,8,22,0,0,0,9,0,0,0,0
0,0,0,0,0,0,0,0,6,6,0,0,23,0,0,0,0,0,9,0,0,9,0,0,0,0,0,24,0,0,0,29,7,0,0,0
0,0,0,0,0,0,0,0,0,0,0,21,24,0,0,51,0,8,23,22,22,24,0,0,51,0,0,24,21,0,0,58,0,0,0,0
0,0,0,0,0,0,0,0,0,0,0,62,22,48,48,48,0,0,22,53,54,22,0,0,49,49,49,24,61,0,0,0,0,0,0,0
0,0,0,0,0,0,0,0,0,0,0,62,24,48,48,48,0,8,22,56,52,22,0,0,49,49,49,23,61,0,0,0,0,0,0,0
0,0,0,0,0,0,0,0,0,0,8,21,24,0,0,51,0,8,22,22,22,22,0,0,51,0,0,22,21,0,0,0,9,0,0,0
0,0,0,0,0,0,0,0,0,0,0,0,22,0,0,0,0,0,6,0,0,6,0,0,0,0,0,23,0,0,0,64,29,7,0,0
0,0,0,0,0,0,0,0,0,0,0,0,24,0,0,0,0,0,0,0,0,0,0,0,0,0,0,22,0,0,0,58,6,0,0,0
0,0,0,0,0,0,0,0,0,0,0,0,24,7,0,0,0,0,51,47,47,51,0,0,0,0,0,24,0,0,64,29,67,0,0,0
0,0,0,0,0,0,0,63,9,0,0,8,22,0,0,0,0,0,0,47,47,0,0,0,0,0,0,22,0,0,0,0,0,0,0,0
0,0,0,0,0,0,8,29,29,7,0,0,24,24,0,0,9,0,0,47,47,0,9,0,9,8,24,24,7,0,0,0,0,0,0,0
0,0,0,0,0,0,8,29,29,7,0,0,22,23,23,24,24,23,24,22,23,23,24,24,22,23,23,23,0,0,0,0,9,0,0,0
0,0,0,0,0,0,0,6,6,0,0,0,0,6,0,0,0,8,21,60,60,21,0,0,0,0,0,0,0,0,0,58,29,7,0,0
0,0,0,0,0,0,0,0,0,0,0,0,0,0,0,0,0,0,0,0,0,0,0,0,0,0,0,0,0,0,0,0,68,0,0,0
0,0,0,0,0,0,0,0,0,58,0,0,0,58,58,58,58,58,58,58,58,0,0,0,0,58,0,0,0,0,0,0,0,0,0,0
0,0,0,0,0,0,0,0,58,29,0,0,0,58,58,58,58,58,58,58,58,58,0,0,8,29,7,0,58,0,0,0,0,0,0,0
0,0,0,0,0,0,0,0,0,6,0,0,0,58,58,29,58,58,58,29,58,58,0,0,0,6,0,58,58,58,0,0,0,0,0,0
0,0,0,0,0,0,0,0,0,0,0,0,0,58,58,58,58,58,58,58,58,58,0,0,0,0,0,0,58,0,0,0,0,0,0,0
0,0,0,0,0,0,0,0,0,0,0,0,0,0,58,58,58,58,58,58,58,0,0,0,0,0,0,0,0,0,0,0,0,0,0,0
0,0,0,0,0,0,0,0,0,0,0,0,0,0,0,0,0,0,0,0,0,0,0,0,0,0,0,0,0,0,0,0,0,0,0,0
0,0,0,0,0,0,0,0,0,0,0,0,0,0,0,0,0,0,0,0,0,0,0,0,0,0,0,0,0,0,0,0,0,0,0,0
0,0,0,0,0,0,0,0,0,0,0,0,0,0,0,0,0,0,0,0,0,0,0,0,0,0,0,0,0,0,0,0,0,0,0,0
0,0,0,0,0,0,0,0,0,0,0,0,0,0,0,0,0,0,0,0,0,0,0,0,0,0,0,0,0,0,0,0,0,0,0,0
endlayer

layer
0,0,0,0,0,0,0,0,0,0,0,0,0,0,0,0,0,0,0,0,0,0,0,0,0,0,0,0,0,0,0,0,0,0,0,0
0,0,0,0,0,0,0,0,0,0,0,0,0,0,0,0,0,0,0,0,0,0,0,0,0,0,0,0,0,0,0,0,0,0,0,0
0,0,0,0,0,0,0,0,0,0,0,0,0,0,0,58,0,0,0,0,0,0,0,0,0,0,0,0,0,0,0,0,0,0,0,0
0,0,0,0,0,0,0,0,9,9,0,0,0,0,58,58,58,58,58,58,0,0,58,58,58,58,0,0,9,9,0,0,0,0,0,0
0,0,0,0,0,0,0,8,29,29,7,0,0,0,0,58,58,58,58,58,0,29,58,58,58,58,0,8,29,29,7,9,0,0,0,0
0,0,0,0,0,0,0,8,29,29,7,0,0,0,0,58,58,29,58,58,0,68,58,58,29,58,0,8,29,29,7,29,0,0,0,0
0,0,0,0,0,0,0,0,6,68,0,0,0,0,0,58,58,58,58,58,0,0,58,58,58,58,0,0,6,6,0,68,0,0,0,0
0,0,0,0,0,0,0,0,0,0,0,0,0,0,0,0,58,58,58,0,0,0,58,58,58,58,0,0,0,0,0,0,0,0,0,0
0,0,0,0,0,0,0,0,0,0,0,0,0,0,0,0,0,0,0,0,0,0,0,0,0,0,0,0,0,0,0,58,0,0,0,0
0,0,0,0,0,0,0,0,0,0,0,0,0,0,0,9,9,0,21,59,59,21,0,0,0,9,0,0,0,0,58,29,58,0,0,0
0,0,0,0,0,0,0,0,0,0,0,0,8,23,22,22,22,23,23,21,21,22,22,23,24,22,24,0,0,0,58,58,58,0,0,0
0,0,0,0,0,0,0,0,9,9,0,0,0,22,24,7,0,6,0,0,0,0,0,0,6,23,22,0,0,0,0,0,0,0,0,0
0,0,0,0,0,0,0,8,29,29,7,0,0,22,0,0,0,0,0,0,6,0,0,0,0,0,22,0,0,0,0,0,0,0,0,0
0,0,0,0,0,0,0,8,29,29,7,0,8,24,7,0,0,0,0,0,0,0,0,0,0,8,23,7,0,0,0,63,0,0,0,0
0,0,0,0,0,0,0,0,6,6,0,0,9,24,0,0,0,0,9,9,0,9,0,0,0,0,23,0,0,0,64,29,7,0,0,0
0,0,0,0,0,0,0,0,0,0,0,8,21,22,0,0,0,8,23,24,24,23,0,0,0,8,24,21,0,0,0,0,0,0,0,0
0,0,0,0,0,0,0,0,0,0,0,0,62,21,0,0,0,0,24,32,32,24,7,0,0,0,21,61,0,0,0,0,0,0,0,0
0,0,0,0,0,0,0,0,0,0,0,0,62,21,0,0,0,0,24,32,32,24,7,0,0,0,21,61,0,0,0,0,0,0,0,0
0,0,0,0,0,0,0,0,0,0,0,0,21,23,0,0,0,8,22,24,24,23,0,0,8,0,23,21,0,0,0,0,9,0,0,0
0,0,0,0,0,0,0,0,0,0,0,0,0,22,0,0,0,0,6,0,0,6,0,0,0,0,23,6,0,0,0,0,29,7,0,0
0,0,0,0,0,0,0,0,0,0,0,0,0,24,0,0,0,0,0,0,0,0,0,0,0,0,22,0,0,0,0,0,6,0,0,0
0,0,0,0,0,0,0,0,0,0,0,0,0,24,0,0,0,0,0,0,0,0,0,0,0,8,22,7,0,0,0,29,7,0,0,0
0,0,0,0,0,0,0,9,9,0,0,0,0,24,24,0,0,0,0,0,0,0,0,0,9,23,22,0,0,0,0,0,0,0,0,0
0,0,0,0,0,0,8,29,29,7,0,0,8,22,22,24,24,23,22,21,21,22,24,22,24,23,22,7,0,0,0,0,0,0,0,0
0,0,0,0,0,0,8,29,29,7,0,0,0,0,0,6,0,0,21,60,60,21,0,6,0,0,0,0,0,0,0,0,9,0,0,0
0,0,0,0,0,0,0,6,6,0,0,0,0,0,0,0,0,0,0,0,0,6,0,0,0,0,0,0,0,0,0,64,29,7,0,0
0,0,0,0,0,0,0,58,58,58,58,58,0,0,0,0,0,0,0,0,0,0,0,0,0,0,0,0,0,0,0,0,6,0,0,0
0,0,0,0,0,0,0,58,58,58,58,58,0,0,0,0,0,0,0,0,0,0,0,0,0,0,0,0,0,0,0,0,0,0,0,0
0,0,0,0,0,0,0,58,58,29,58,58,0,0,58,58,58,0,58,58,0,0,0,0,8,29,67,0,0,0,0,0,0,0,0,0
0,0,0,0,0,0,0,58,58,58,58,58,0,0,58,29,58,0,58,29,58,0,0,0,0,6,0,0,0,0,0,0,0,0,0,0
0,0,0,0,0,0,0,58,58,58,58,0,0,0,0,58,58,0,0,58,0,0,0,0,0,0,0,0,0,0,0,0,0,0,0,0
0,0,0,0,0,0,0,0,0,0,0,0,0,0,0,0,0,0,0,0,0,0,0,0,0,0,0,0,0,0,0,0,0,0,0,0
0,0,0,0,0,0,0,0,0,0,0,0,0,0,0,0,0,0,0,0,0,0,0,0,0,0,0,0,0,0,0,0,0,0,0,0
0,0,0,0,0,0,0,0,0,0,0,0,0,0,0,0,0,0,0,0,0,0,0,0,0,0,0,0,0,0,0,0,0,0,0,0
0,0,0,0,0,0,0,0,0,0,0,0,0,0,0,0,0,0,0,0,0,0,0,0,0,0,0,0,0,0,0,0,0,0,0,0
0,0,0,0,0,0,0,0,0,0,0,0,0,0,0,0,0,0,0,0,0,0,0,0,0,0,0,0,0,0,0,0,0,0,0,0
endlayer

layer
0,0,0,0,0,0,0,0,0,0,0,0,0,0,0,0,0,0,0,0,0,0,0,0,0,0,0,0,0,0,0,0,0,0,0,0
0,0,0,0,0,0,0,0,0,0,0,0,0,0,0,0,0,0,0,0,0,0,0,0,0,0,0,0,0,0,0,0,0,0,0,0
0,0,0,0,0,0,0,0,0,0,0,0,0,0,0,0,0,0,0,0,0,0,0,0,0,0,0,0,0,0,0,0,0,0,0,0
0,0,0,0,0,0,0,0,9,9,0,0,0,0,0,0,58,58,58,0,0,63,58,58,58,58,58,0,9,9,0,0,0,0,0,0
0,0,0,0,0,0,0,8,29,29,7,0,0,0,0,58,58,58,58,58,0,29,58,58,58,58,58,8,29,29,7,9,0,0,0,0
0,0,0,0,0,0,0,8,29,29,7,0,0,0,0,58,58,29,58,58,0,0,58,58,29,58,58,8,29,29,7,29,0,0,0,0
0,0,0,0,0,0,0,0,6,6,0,0,0,0,0,58,58,58,58,58,0,0,58,58,58,58,58,0,6,6,0,0,0,0,0,0
0,0,0,0,0,0,0,0,0,0,0,0,0,0,0,58,58,58,58,0,0,0,0,58,58,58,0,0,0,0,0,0,0,0,0,0
0,0,0,0,0,0,0,0,0,0,0,0,0,0,0,0,0,0,0,0,0,0,0,0,0,0,0,0,0,0,0,58,0,0,0,0
0,0,0,0,0,0,0,0,0,0,0,0,0,0,0,0,0,0,0,0,0,0,0,0,0,0,0,0,0,0,58,58,58,0,0,0
0,0,0,0,0,0,0,0,0,0,0,0,0,0,9,0,9,0,21,59,59,21,0,9,0,0,0,0,0,0,0,58,0,0,0,0
0,0,0,0,0,0,0,0,9,9,0,0,0,0,22,24,23,22,23,24,23,23,22,23,24,22,7,0,0,0,0,0,0,0,0,0
0,0,0,0,0,0,0,8,29,29,7,0,0,8,24,22,0,6,0,0,6,0,0,0,22,22,0,0,0,0,0,0,0,0,0,0
0,0,0,0,0,0,0,8,29,29,7,0,0,0,24,6,0,0,6,0,0,0,0,0,0,23,0,0,0,0,0,0,0,0,0,0
0,0,0,0,0,0,0,0,68,6,0,0,0,8,24,0,0,0,9,0,0,9,0,0,8,23,0,0,0,0,0,29,7,13,0,0
0,0,0,0,0,0,0,0,0,0,0,0,0,21,22,0,0,8,23,0,0,22,0,0,0,22,21,7,0,0,0,0,0,0,0,0
0,0,0,0,0,0,0,0,0,0,0,0,0,62,22,7,0,0,0,0,0,0,0,0,0,22,61,0,0,0,0,0,0,0,0,0
0,0,0,0,0,0,0,0,0,0,0,0,0,62,24,0,0,0,0,0,0,0,0,0,0,23,61,0,0,0,0,0,0,0,0,0
0,0,0,0,0,0,0,0,0,0,0,0,8,21,22,7,0,8,23,0,0,22,0,0,8,23,21,0,0,0,0,0,9,0,0,0
0,0,0,0,0,0,0,0,0,0,0,0,0,0,22,0,0,0,6,0,0,6,0,0,0,24,0,0,0,0,0,0,29,7,0,0
0,0,0,0,0,0,0,0,0,0,0,0,0,8,23,0,0,0,0,0,0,0,0,0,0,23,7,0,0,0,0,0,6,13,0,0
0,0,0,0,0,0,0,0,0,0,0,0,0,0,23,22,7,0,0,0,0,9,0,9,24,23,0,0,0,0,0,29,0,0,0,0
0,0,0,0,0,0,0,9,9,0,0,0,0,0,23,24,23,23,22,23,24,23,22,23,24,23,0,0,0,0,0,0,0,0,0,0
0,0,0,0,0,0,8,29,29,7,0,0,0,0,0,0,0,6,21,60,60,21,0,0,0,6,0,0,0,0,0,0,0,0,0,0
0,0,0,0,0,0,8,29,29,7,0,0,0,0,0,0,0,0,6,0,0,0,0,0,0,0,0,0,0,0,0,0,58,0,0,0
0,0,0,0,0,0,0,6,6,0,0,0,0,0,0,0,0,0,0,0,0,0,0,0,0,0,0,0,0,0,0,8,29,67,0,0
0,0,0,0,0,0,0,0,58,58,58,58,0,0,0,0,0,0,0,0,0,0,0,0,0,0,0,0,0,0,0,0,6,0,0,0
0,0,0,0,0,0,0,58,58,58,58,58,0,0,0,0,0,0,0,0,0,0,0,0,0,0,0,0,0,0,0,0,13,0,0,0
0,0,0,0,0,0,0,58,58,29,58,58,0,0,0,58,0,0,0,58,0,0,0,0,0,29,0,0,0,0,0,0,0,0,0,0
0,0,0,0,0,0,0,58,58,58,58,58,0,0,58,58,58,0,58,58,58,0,0,0,0,0,0,0,0,0,0,0,0,0,0,0
0,0,0,0,0,0,0,58,58,58,58,58,0,0,0,58,0,0,0,58,0,0,0,0,0,0,0,0,0,0,0,0,0,0,0,0
0,0,0,0,0,0,0,0,0,0,0,0,0,0,0,0,0,0,0,0,0,0,0,0,0,0,0,0,0,0,0,0,0,0,0,0
0,0,0,0,0,0,0,0,0,0,0,0,0,0,0,0,0,0,0,0,0,0,0,0,0,0,0,0,0,0,0,0,0,0,0,0
0,0,0,0,0,0,0,0,0,0,0,0,0,0,0,0,0,0,0,0,0,0,0,0,0,0,0,0,0,0,0,0,0,0,0,0
0,0,0,0,0,0,0,0,0,0,0,0,0,0,0,0,0,0,0,0,0,0,0,0,0,0,0,0,0,0,0,0,0,0,0,0
0,0,0,0,0,0,0,0,0,0,0,0,0,0,0,0,0,0,0,0,0,0,0,0,0,0,0,0,0,0,0,0,0,0,0,0
endlayer

layer
0,0,0,0,0,0,0,0,0,0,0,0,0,0,0,0,0,0,0,0,0,0,0,0,0,0,0,0,0,0,0,0,0,0,0,0
0,0,0,0,0,0,0,0,0,0,0,0,0,0,0,0,0,0,0,0,0,0,0,0,0,0,0,0,0,0,0,0,0,0,0,0
0,0,0,0,0,0,0,0,0,0,0,0,0,0,0,0,0,0,0,0,0,0,0,0,0,0,0,0,0,0,0,0,0,0,0,0
0,0,0,0,0,0,0,0,9,9,0,0,0,0,0,0,0,0,0,0,0,0,0,0,0,0,0,0,9,9,0,0,0,0,0,0
0,0,0,0,0,0,0,8,29,29,7,0,0,0,0,0,58,58,0,0,0,29,0,0,58,0,0,8,29,29,7,63,0,0,0,0
0,0,0,0,0,0,0,8,29,29,7,0,0,0,0,0,58,29,58,0,0,0,0,58,29,58,0,8,29,29,7,29,0,0,0,0
0,0,0,0,0,0,0,0,6,6,0,0,0,0,0,0,58,58,0,0,0,0,0,58,58,58,0,0,6,6,0,0,0,0,0,0
0,0,0,0,0,0,0,0,0,0,0,0,0,0,0,0,0,0,0,0,0,0,0,0,0,0,0,0,0,0,0,0,0,0,0,0
0,0,0,0,0,0,0,0,0,0,0,0,0,0,0,0,0,0,0,0,0,0,0,0,0,0,0,0,0,0,0,0,0,0,0,0
0,0,0,0,0,0,0,0,0,0,0,0,0,0,0,0,0,0,0,0,0,0,0,0,0,0,0,0,0,0,0,0,0,0,0,0
0,0,0,0,0,0,0,0,0,0,0,0,0,0,0,0,0,0,9,0,0,0,0,0,0,0,0,0,0,0,0,0,0,0,0,0
0,0,0,0,0,0,0,0,9,9,0,0,0,0,0,0,9,0,21,59,59,21,0,0,9,0,0,0,0,0,0,0,0,0,0,0
0,0,0,0,0,0,0,8,29,29,7,0,0,0,0,23,23,24,22,23,24,22,24,23,22,0,0,0,0,0,58,58,58,0,0,0
0,0,0,0,0,0,0,8,29,29,7,0,0,0,8,23,22,0,6,0,0,0,6,24,22,7,0,0,0,58,58,58,58,58,0,0
0,0,0,0,0,0,0,0,6,6,0,0,0,0,8,22,0,0,9,0,0,9,0,6,24,0,0,0,0,58,58,29,58,58,0,0
0,0,0,0,0,0,0,0,0,0,0,0,0,8,21,22,7,8,24,0,0,22,0,0,23,21,7,0,0,58,58,58,58,58,0,0
0,0,0,0,0,0,0,0,0,0,0,0,0,0,62,24,0,0,0,0,0,0,0,8,23,61,0,0,0,0,58,58,58,58,0,0
0,0,0,0,0,0,0,0,0,0,0,0,0,0,62,23,0,0,0,0,0,0,0,0,23,61,0,0,0,0,0,58,58,58,0,0
0,0,0,0,0,0,0,0,0,0,0,0,0,0,21,22,0,8,23,0,0,22,0,0,23,21,0,0,0,0,58,58,58,58,58,0
0,0,0,0,0,0,0,0,0,0,0,0,0,0,6,24,0,0,6,0,0,6,0,0,24,6,0,0,0,0,58,58,29,58,58,0
0,0,0,0,0,0,0,0,0,0,0,0,0,0,0,23,23,0,9,0,9,0,8,23,24,0,0,0,0,0,58,58,58,58,58,0
0,0,0,0,0,0,0,0,0,0,0,0,0,0,0,22,23,24,23,23,23,24,24,23,22,7,0,0,0,0,0,29,58,58,0,0
0,0,0,0,0,0,0,9,9,0,0,0,0,0,0,6,0,0,21,60,60,21,7,6,0,0,0,0,0,0,0,0,0,0,0,0
0,0,0,0,0,0,8,29,29,7,0,0,0,0,0,0,0,0,6,0,0,0,0,0,0,0,0,0,0,0,0,58,58,58,0,0
0,0,0,0,0,0,8,29,29,7,0,0,0,0,0,0,0,0,0,0,0,0,0,0,0,0,0,0,0,0,58,58,58,58,58,0
0,0,0,0,0,0,0,6,6,0,0,0,0,0,0,0,0,0,0,0,0,0,0,0,0,0,0,0,0,0,58,58,29,58,58,0
0,0,0,0,0,0,0,0,0,0,0,0,0,0,0,0,0,0,0,0,0,0,0,58,58,58,58,0,0,0,58,58,58,58,58,0
0,0,0,0,0,0,0,0,58,58,58,0,0,0,0,0,0,0,0,0,0,0,0,58,58,58,58,58,0,0,0,58,58,58,58,0
0,0,0,0,0,0,0,0,58,29,58,0,0,0,0,0,0,0,0,0,0,0,0,58,58,29,58,58,0,0,0,0,0,0,0,0
0,0,0,0,0,0,0,0,58,58,58,0,0,0,0,0,0,0,0,0,0,0,0,58,58,58,58,58,0,0,0,0,0,0,0,0
0,0,0,0,0,0,0,0,0,0,0,0,0,0,0,0,0,0,0,0,0,0,0,58,58,58,58,0,0,0,0,0,0,0,0,0
0,0,0,0,0,0,0,0,0,0,0,0,0,0,0,0,0,0,0,0,0,0,0,0,0,0,0,0,0,0,0,0,0,0,0,0
0,0,0,0,0,0,0,0,0,0,0,0,0,0,0,0,0,0,0,0,0,0,0,0,0,0,0,0,0,0,0,0,0,0,0,0
0,0,0,0,0,0,0,0,0,0,0,0,0,0,0,0,0,0,0,0,0,0,0,0,0,0,0,0,0,0,0,0,0,0,0,0
0,0,0,0,0,0,0,0,0,0,0,0,0,0,0,0,0,0,0,0,0,0,0,0,0,0,0,0,0,0,0,0,0,0,0,0
0,0,0,0,0,0,0,0,0,0,0,0,0,0,0,0,0,0,0,0,0,0,0,0,0,0,0,0,0,0,0,0,0,0,0,0
endlayer

layer
0,0,0,0,0,0,0,0,0,0,0,0,0,0,0,0,0,0,0,0,0,0,0,0,0,0,0,0,0,0,0,0,0,0,0,0
0,0,0,0,0,0,0,0,0,0,0,0,0,0,0,0,0,0,0,0,0,0,0,0,0,0,0,0,0,0,0,0,0,0,0,0
0,0,0,0,0,0,0,0,0,0,0,0,0,0,0,0,0,0,0,0,0,0,0,0,0,0,0,0,0,0,0,0,0,0,0,0
0,0,0,0,0,0,0,0,9,9,0,0,0,0,0,0,0,0,0,0,0,0,0,0,0,0,0,0,9,9,58,58,58,58,0,0
0,0,0,0,0,0,0,8,29,29,7,0,0,0,0,0,0,58,0,0,0,29,0,0,58,0,0,64,29,29,7,58,58,58,0,0
0,0,0,0,0,0,0,8,29,29,7,0,0,0,0,0,58,58,58,0,0,0,0,58,58,58,0,8,29,29,58,29,58,58,0,0
0,0,0,0,0,0,0,0,6,6,0,0,0,0,0,0,0,58,0,0,0,0,0,0,58,0,0,0,6,6,58,58,58,58,0,0
0,0,0,0,0,0,0,0,0,0,0,0,0,0,0,0,0,0,0,0,0,0,0,0,0,0,0,0,0,58,58,58,58,58,0,0
0,0,0,0,0,0,0,0,0,0,0,0,0,0,0,0,0,0,0,0,0,0,0,0,0,0,0,0,0,0,0,0,0,0,0,0
0,0,0,0,0,0,0,0,0,0,0,0,0,0,0,0,0,0,0,0,0,0,0,0,0,0,0,0,0,0,0,0,0,0,0,0
0,0,0,0,0,0,0,0,0,0,0,0,0,0,0,0,0,0,0,0,0,0,0,0,0,0,0,0,0,0,0,0,0,0,0,0
0,0,0,0,0,0,0,0,9,9,0,0,0,0,0,0,0,0,0,0,0,9,0,0,0,0,0,0,0,0,0,0,0,0,0,0
0,0,0,0,0,0,0,8,29,29,7,0,0,0,0,0,0,8,21,59,59,21,7,0,0,0,0,0,0,58,58,58,58,0,0,0
0,0,0,0,0,0,0,8,29,29,7,0,0,0,0,8,24,22,24,24,22,23,22,24,0,0,0,0,0,58,58,58,58,58,0,0
0,0,0,0,0,0,0,0,6,6,0,0,0,0,0,0,23,23,9,0,0,9,23,23,0,0,0,0,0,58,58,29,58,58,0,0
0,0,0,0,0,0,0,0,0,0,0,0,0,0,0,21,24,8,22,24,24,22,0,22,21,0,0,0,0,58,58,58,58,58,0,0
0,0,0,0,0,0,0,0,0,0,0,0,0,0,0,62,24,0,24,54,52,24,0,24,61,0,0,0,0,58,58,58,58,0,0,0
0,0,0,0,0,0,0,0,0,0,0,0,0,0,0,62,23,8,24,53,56,24,0,24,61,0,0,0,0,0,0,58,58,58,58,0
0,0,0,0,0,0,0,0,0,0,0,0,0,0,0,21,23,0,22,24,24,22,0,24,21,7,0,0,0,0,58,58,58,58,58,0
0,0,0,0,0,0,0,0,0,0,0,0,0,0,0,0,24,23,6,0,0,6,23,23,0,0,0,0,0,0,58,58,29,58,58,0
0,0,0,0,0,0,0,0,0,0,0,0,0,0,0,8,22,24,23,22,22,22,22,23,7,0,0,0,0,58,58,58,58,58,58,0
0,0,0,0,0,0,0,0,0,0,0,0,0,0,0,0,0,0,21,60,60,21,0,0,0,0,0,0,0,58,58,29,58,58,58,0
0,0,0,0,0,0,0,9,9,0,0,0,0,0,0,0,0,0,0,0,0,0,0,0,0,0,0,0,0,58,58,58,58,58,0,0
0,0,0,0,0,0,8,29,29,67,0,0,0,0,0,0,0,0,0,0,0,0,0,0,0,0,0,0,0,0,58,58,58,58,58,0
0,0,0,0,0,0,8,29,29,7,0,0,0,0,0,0,0,0,0,0,0,0,0,0,0,0,0,0,0,0,58,58,58,58,58,0
0,0,0,0,0,0,0,6,6,0,0,0,0,0,0,0,0,0,0,0,0,0,0,0,0,0,0,0,0,0,58,58,29,58,58,0
0,0,0,0,0,0,0,0,0,0,0,0,0,0,0,0,0,0,0,0,0,0,0,0,58,58,58,58,0,0,58,58,58,58,58,0
0,0,0,0,0,0,0,0,0,58,0,0,0,0,0,0,0,0,0,0,0,0,0,58,58,58,58,58,0,0,0,58,58,58,58,0
0,0,0,0,0,0,0,0,58,58,58,0,0,0,0,0,0,0,0,0,0,0,0,58,58,29,58,58,0,0,0,0,0,0,0,0
0,0,0,0,0,0,0,0,0,58,0,0,0,0,0,0,0,0,0,0,0,0,0,58,58,58,58,58,0,0,0,0,0,0,0,0
0,0,0,0,0,0,0,0,0,0,0,0,0,0,0,0,0,0,0,0,0,0,0,0,58,58,58,0,0,0,0,0,0,0,0,0
0,0,0,0,0,0,0,0,0,0,0,0,0,0,0,0,0,0,0,0,0,0,0,0,0,0,0,0,0,0,0,0,0,0,0,0
0,0,0,0,0,0,0,0,0,0,0,0,0,0,0,0,0,0,0,0,0,0,0,0,0,0,0,0,0,0,0,0,0,0,0,0
0,0,0,0,0,0,0,0,0,0,0,0,0,0,0,0,0,0,0,0,0,0,0,0,0,0,0,0,0,0,0,0,0,0,0,0
0,0,0,0,0,0,0,0,0,0,0,0,0,0,0,0,0,0,0,0,0,0,0,0,0,0,0,0,0,0,0,0,0,0,0,0
0,0,0,0,0,0,0,0,0,0,0,0,0,0,0,0,0,0,0,0,0,0,0,0,0,0,0,0,0,0,0,0,0,0,0,0
endlayer

layer
0,0,0,0,0,0,0,0,0,0,0,0,0,0,0,0,0,0,0,0,0,0,0,0,0,0,0,0,0,0,0,0,0,0,0,0
0,0,0,0,0,0,0,0,0,0,0,0,0,0,0,0,0,0,0,0,0,0,0,0,0,0,0,0,0,0,0,0,0,0,0,0
0,0,0,0,0,0,0,0,0,0,0,0,0,0,0,0,0,0,0,0,58,58,58,58,0,0,0,0,0,0,0,0,0,0,0,0
0,0,0,0,0,0,0,0,9,9,0,0,0,0,0,0,0,0,0,58,58,58,58,58,0,0,0,0,9,9,58,58,58,0,0,0
0,0,0,0,0,0,0,8,29,29,7,0,0,0,0,0,0,0,0,58,58,29,58,58,0,0,0,8,29,29,7,58,58,58,0,0
0,0,0,0,0,0,0,8,29,29,67,0,0,0,0,0,0,0,0,58,58,58,58,58,0,0,0,8,29,29,7,29,58,58,0,0
0,0,0,0,0,0,0,0,6,6,0,0,0,0,0,0,0,0,0,0,58,58,58,0,0,0,0,0,6,6,58,58,58,58,0,0
0,0,0,0,0,0,0,0,0,0,0,0,0,0,0,0,0,0,0,0,0,0,0,0,0,0,0,0,0,0,58,58,58,58,0,0
0,0,0,0,0,0,0,0,0,0,0,0,0,0,0,0,0,0,0,0,0,0,0,0,0,0,0,0,0,0,0,0,0,0,0,0
0,0,0,0,0,0,0,0,0,0,0,0,0,0,0,0,0,0,0,0,0,0,0,0,0,0,0,0,0,0,0,0,0,0,0,0
0,0,0,0,0,0,0,0,0,0,0,0,0,0,0,0,0,0,0,0,0,0,0,0,0,0,0,0,0,0,0,0,0,0,0,0
0,0,0,0,0,0,0,0,9,9,0,0,0,0,0,0,0,0,0,0,0,0,0,0,0,0,0,0,0,0,0,0,0,0,0,0
0,0,0,0,0,0,0,64,29,29,7,0,0,0,0,0,0,0,9,0,0,9,0,0,0,0,0,0,0,0,0,0,0,0,0,0
0,0,0,0,0,0,0,8,29,29,7,0,0,0,0,0,0,0,21,59,59,21,0,0,0,0,0,0,0,0,58,58,0,0,0,0
0,0,0,0,0,0,0,0,6,6,0,0,0,0,0,0,0,23,22,22,22,24,22,7,0,0,0,0,0,0,58,29,58,0,0,0
0,0,0,0,0,0,0,0,0,0,0,0,0,0,0,0,21,23,24,24,23,24,22,21,0,0,0,0,0,0,0,58,0,0,0,0
0,0,0,0,0,0,0,0,0,0,0,0,0,0,0,0,62,22,23,32,32,24,23,61,0,0,0,0,0,0,0,0,0,0,0,0
0,0,0,0,0,0,0,0,0,0,0,0,0,0,0,0,62,23,23,32,32,22,24,61,0,0,0,0,0,0,0,0,0,0,0,0
0,0,0,0,0,0,0,0,0,0,0,0,0,0,0,0,21,22,23,24,24,22,24,21,0,0,0,0,0,0,0,0,58,58,0,0
0,0,0,0,0,0,0,0,0,0,0,0,0,0,0,0,8,22,24,22,23,23,24,0,0,0,0,0,0,0,58,58,29,58,0,0
0,0,0,0,0,0,0,0,0,0,0,0,0,0,0,0,0,6,21,60,60,21,0,0,0,0,0,0,0,58,58,58,58,58,0,0
0,0,0,0,0,0,0,0,0,0,0,0,0,0,0,0,0,0,0,0,0,6,0,0,0,0,0,0,0,58,58,29,58,58,0,0
0,0,0,0,0,0,0,9,9,0,0,0,0,0,0,0,0,0,0,0,0,0,0,0,0,0,0,0,0,58,58,58,58,58,0,0
0,0,0,0,0,0,64,29,29,7,0,0,0,0,0,0,0,0,0,0,0,0,0,0,0,0,0,0,0,58,58,58,58,0,0,0
0,0,0,0,0,0,8,29,29,7,0,0,0,0,0,0,0,0,0,0,0,0,0,0,0,0,0,0,0,0,0,58,58,0,0,0
0,0,0,0,0,0,0,6,6,0,0,0,0,0,0,0,0,0,0,0,0,0,0,0,0,0,0,0,0,0,0,58,29,58,0,0
0,0,0,0,0,0,0,0,0,0,0,0,0,0,0,0,0,0,0,0,0,0,0,0,0,0,0,0,0,0,0,0,58,0,0,0
0,0,0,0,0,0,0,0,0,0,0,0,0,0,0,0,0,0,0,0,0,0,0,0,58,58,0,0,0,0,0,0,0,0,0,0
0,0,0,0,0,0,0,0,0,0,0,0,0,0,0,0,0,0,0,0,0,0,0,0,58,29,58,0,0,0,0,0,0,0,0,0
0,0,0,0,0,0,0,0,0,0,0,0,0,0,0,0,0,0,0,0,0,0,0,0,0,58,0,0,0,0,0,0,0,0,0,0
0,0,0,0,0,0,0,0,0,0,0,0,0,0,0,0,0,0,0,0,0,0,0,0,0,0,0,0,0,0,0,0,0,0,0,0
0,0,0,0,0,0,0,0,0,0,0,0,0,0,0,0,0,0,0,0,0,0,0,0,0,0,0,0,0,0,0,0,0,0,0,0
0,0,0,0,0,0,0,0,0,0,0,0,0,0,0,0,0,0,0,0,0,0,0,0,0,0,0,0,0,0,0,0,0,0,0,0
0,0,0,0,0,0,0,0,0,0,0,0,0,0,0,0,0,0,0,0,0,0,0,0,0,0,0,0,0,0,0,0,0,0,0,0
0,0,0,0,0,0,0,0,0,0,0,0,0,0,0,0,0,0,0,0,0,0,0,0,0,0,0,0,0,0,0,0,0,0,0,0
0,0,0,0,0,0,0,0,0,0,0,0,0,0,0,0,0,0,0,0,0,0,0,0,0,0,0,0,0,0,0,0,0,0,0,0
endlayer

layer
0,0,0,0,0,0,0,0,0,0,0,0,0,0,0,0,0,0,0,0,0,0,0,0,0,0,0,0,0,0,0,0,0,0,0,0
0,0,0,0,0,0,0,0,0,0,0,0,0,0,0,0,0,0,0,0,0,0,0,0,0,0,0,0,0,0,0,0,0,0,0,0
0,0,0,0,0,0,0,0,0,0,0,0,0,0,0,0,0,0,0,58,58,58,58,0,0,0,0,0,0,0,0,0,0,0,0,0
0,0,0,0,0,0,0,0,9,9,0,0,0,0,0,0,0,0,0,58,58,58,58,58,0,0,0,0,9,9,0,0,0,0,0,0
0,0,0,0,0,0,0,8,29,29,7,0,0,0,0,0,0,0,0,58,58,29,58,58,0,0,0,8,29,29,58,58,0,0,0,0
0,0,0,0,0,0,0,8,29,29,7,0,0,0,0,0,0,0,0,58,58,58,58,58,0,0,0,8,29,29,7,29,58,0,0,0
0,0,0,0,0,0,0,0,0,6,0,0,0,0,0,0,0,0,0,0,58,58,58,0,0,0,0,0,6,6,58,58,58,0,0,0
0,0,0,0,0,0,0,0,0,0,0,0,0,0,0,0,0,0,0,0,0,0,0,0,0,0,0,0,0,0,0,0,0,0,0,0
0,0,0,0,0,0,0,0,0,0,0,0,0,0,0,0,0,0,0,0,0,0,0,0,0,0,0,0,0,0,0,0,0,0,0,0
0,0,0,0,0,0,0,0,0,0,0,0,0,0,0,0,0,0,0,0,0,0,0,0,0,0,0,0,0,0,0,0,0,0,0,0
0,0,0,0,0,0,0,0,0,0,0,0,0,0,0,0,0,0,0,0,0,0,0,0,0,0,0,0,0,0,0,0,0,0,0,0
0,0,0,0,0,0,0,0,9,9,0,0,0,0,0,0,0,0,0,0,0,0,0,0,0,0,0,0,0,0,0,0,0,0,0,0
0,0,0,0,0,0,0,8,29,29,7,0,0,0,0,0,0,0,0,0,0,0,0,0,0,0,0,0,0,0,0,0,0,0,0,0
0,0,0,0,0,0,0,8,29,29,7,0,0,0,0,0,0,0,0,0,0,0,0,0,0,0,0,0,0,0,0,58,0,0,0,0
0,0,0,0,0,0,0,0,6,6,0,0,0,0,0,0,0,0,9,0,69,9,0,0,0,0,0,0,0,0,58,58,58,0,0,0
0,0,0,0,0,0,0,0,0,0,0,0,0,0,0,0,0,8,24,0,31,22,7,0,0,0,0,0,0,0,0,58,0,0,0,0
0,0,0,0,0,0,0,0,0,0,0,0,0,0,0,0,0,31,0,0,0,0,31,0,0,0,0,0,0,0,0,0,0,0,0,0
0,0,0,0,0,0,0,0,0,0,0,0,0,0,0,0,0,0,31,0,0,0,0,0,0,0,0,0,0,0,0,0,0,0,0,0
0,0,0,0,0,0,0,0,0,0,0,0,0,0,0,0,0,69,23,0,0,23,0,0,0,0,0,0,0,0,0,0,58,0,0,0
0,0,0,0,0,0,0,0,0,0,0,0,0,0,0,0,0,0,6,31,0,6,0,0,0,0,0,0,0,0,0,58,58,58,0,0
0,0,0,0,0,0,0,0,0,0,0,0,0,0,0,0,0,0,0,0,0,0,0,0,0,0,0,0,0,0,0,58,58,0,0,0
0,0,0,0,0,0,0,0,0,0,0,0,0,0,0,0,0,0,0,0,0,0,0,0,0,0,0,0,0,0,58,29,58,0,0,0
0,0,0,0,0,0,0,9,9,0,0,0,0,0,0,0,0,0,0,0,0,0,0,0,0,0,0,0,0,0,0,58,58,0,0,0
0,0,0,0,0,0,8,29,29,7,0,0,0,0,0,0,0,0,0,0,0,0,0,0,0,0,0,0,0,0,0,0,0,0,0,0
0,0,0,0,0,0,8,29,29,7,0,0,0,0,0,0,0,0,0,0,0,0,0,0,0,0,0,0,0,0,0,0,58,0,0,0
0,0,0,0,0,0,0,6,6,0,0,0,0,0,0,0,0,0,0,0,0,0,0,0,0,0,0,0,0,0,0,58,58,58,0,0
0,0,0,0,0,0,0,0,0,0,0,0,0,0,0,0,0,0,0,0,0,0,0,0,0,0,0,0,0,0,0,0,58,0,0,0
0,0,0,0,0,0,0,0,0,0,0,0,0,0,0,0,0,0,0,0,0,0,0,0,0,58,0,0,0,0,0,0,0,0,0,0
0,0,0,0,0,0,0,0,0,0,0,0,0,0,0,0,0,0,0,0,0,0,0,0,58,58,58,0,0,0,0,0,0,0,0,0
0,0,0,0,0,0,0,0,0,0,0,0,0,0,0,0,0,0,0,0,0,0,0,0,0,58,0,0,0,0,0,0,0,0,0,0
0,0,0,0,0,0,0,0,0,0,0,0,0,0,0,0,0,0,0,0,0,0,0,0,0,0,0,0,0,0,0,0,0,0,0,0
0,0,0,0,0,0,0,0,0,0,0,0,0,0,0,0,0,0,0,0,0,0,0,0,0,0,0,0,0,0,0,0,0,0,0,0
0,0,0,0,0,0,0,0,0,0,0,0,0,0,0,0,0,0,0,0,0,0,0,0,0,0,0,0,0,0,0,0,0,0,0,0
0,0,0,0,0,0,0,0,0,0,0,0,0,0,0,0,0,0,0,0,0,0,0,0,0,0,0,0,0,0,0,0,0,0,0,0
0,0,0,0,0,0,0,0,0,0,0,0,0,0,0,0,0,0,0,0,0,0,0,0,0,0,0,0,0,0,0,0,0,0,0,0
0,0,0,0,0,0,0,0,0,0,0,0,0,0,0,0,0,0,0,0,0,0,0,0,0,0,0,0,0,0,0,0,0,0,0,0
endlayer

layer
0,0,0,0,0,0,0,0,0,0,0,0,0,0,0,0,0,0,0,0,0,0,0,0,0,0,0,0,0,0,0,0,0,0,0,0
0,0,0,0,0,0,0,0,0,0,0,0,0,0,0,0,0,0,0,0,0,0,0,0,0,0,0,0,0,0,0,0,0,0,0,0
0,0,0,0,0,0,0,0,0,0,0,0,0,0,0,0,0,0,0,0,0,0,0,0,0,0,0,0,0,0,0,0,0,0,0,0
0,0,0,0,0,0,0,0,63,9,0,0,0,0,0,0,0,0,0,0,58,58,0,0,0,0,0,0,9,9,0,0,0,0,0,0
0,0,0,0,0,0,0,0,29,29,7,0,0,0,0,0,0,0,0,0,58,29,58,0,0,0,0,8,29,29,7,58,0,0,0,0
0,0,0,0,0,0,0,8,29,29,7,0,0,0,0,0,0,0,0,0,58,58,0,0,0,0,0,8,29,29,7,58,58,0,0,0
0,0,0,0,0,0,0,0,68,6,0,0,0,0,0,0,0,0,0,0,0,0,0,0,0,0,0,0,6,68,0,58,0,0,0,0
0,0,0,0,0,0,0,0,0,0,0,0,0,0,0,0,0,0,0,0,0,0,0,0,0,0,0,0,0,0,0,0,0,0,0,0
0,0,0,0,0,0,0,0,0,0,0,0,0,0,0,0,0,0,0,0,0,0,0,0,0,0,0,0,0,0,0,0,0,0,0,0
0,0,0,0,0,0,0,0,0,0,0,0,0,0,0,0,0,0,0,0,0,0,0,0,0,0,0,0,0,0,0,0,0,0,0,0
0,0,0,0,0,0,0,0,0,0,0,0,0,0,0,0,0,0,0,0,0,0,0,0,0,0,0,0,0,0,0,0,0,0,0,0
0,0,0,0,0,0,0,0,9,9,0,0,0,0,0,0,0,0,0,0,0,0,0,0,0,0,0,0,0,0,0,0,0,0,0,0
0,0,0,0,0,0,0,8,29,29,7,0,0,0,0,0,0,0,0,0,0,0,0,0,0,0,0,0,0,0,0,0,0,0,0,0
0,0,0,0,0,0,0,8,29,29,7,0,0,0,0,0,0,0,0,0,0,0,0,0,0,0,0,0,0,0,0,0,0,0,0,0
0,0,0,0,0,0,0,0,6,6,0,0,0,0,0,0,0,0,9,0,0,9,0,0,0,0,0,0,0,0,0,0,0,0,0,0
0,0,0,0,0,0,0,0,0,0,0,0,0,0,0,0,0,8,21,0,0,21,7,0,0,0,0,0,0,0,0,0,0,0,0,0
0,0,0,0,0,0,0,0,0,0,0,0,0,0,0,0,0,0,0,0,0,0,0,0,0,0,0,0,0,0,0,0,0,0,0,0
0,0,0,0,0,0,0,0,0,0,0,0,0,0,0,0,0,0,0,0,0,0,0,0,0,0,0,0,0,0,0,0,0,0,0,0
0,0,0,0,0,0,0,0,0,0,0,0,0,0,0,0,0,8,21,0,0,21,0,0,0,0,0,0,0,0,0,0,0,0,0,0
0,0,0,0,0,0,0,0,0,0,0,0,0,0,0,0,0,0,6,0,0,6,0,0,0,0,0,0,0,0,0,0,0,0,0,0
0,0,0,0,0,0,0,0,0,0,0,0,0,0,0,0,0,0,0,0,0,0,0,0,0,0,0,0,0,0,0,58,0,0,0,0
0,0,0,0,0,0,0,0,0,0,0,0,0,0,0,0,0,0,0,0,0,0,0,0,0,0,0,0,0,0,58,58,58,0,0,0
0,0,0,0,0,0,0,9,9,0,0,0,0,0,0,0,0,0,0,0,0,0,0,0,0,0,0,0,0,0,0,58,0,0,0,0
0,0,0,0,0,0,8,29,29,7,0,0,0,0,0,0,0,0,0,0,0,0,0,0,0,0,0,0,0,0,0,0,0,0,0,0
0,0,0,0,0,0,8,29,29,7,0,0,0,0,0,0,0,0,0,0,0,0,0,0,0,0,0,0,0,0,0,0,0,0,0,0
0,0,0,0,0,0,0,6,68,0,0,0,0,0,0,0,0,0,0,0,0,0,0,0,0,0,0,0,0,0,0,0,0,0,0,0
0,0,0,0,0,0,0,0,0,0,0,0,0,0,0,0,0,0,0,0,0,0,0,0,0,0,0,0,0,0,0,0,0,0,0,0
0,0,0,0,0,0,0,0,0,0,0,0,0,0,0,0,0,0,0,0,0,0,0,0,0,0,0,0,0,0,0,0,0,0,0,0
0,0,0,0,0,0,0,0,0,0,0,0,0,0,0,0,0,0,0,0,0,0,0,0,0,0,0,0,0,0,0,0,0,0,0,0
0,0,0,0,0,0,0,0,0,0,0,0,0,0,0,0,0,0,0,0,0,0,0,0,0,0,0,0,0,0,0,0,0,0,0,0
0,0,0,0,0,0,0,0,0,0,0,0,0,0,0,0,0,0,0,0,0,0,0,0,0,0,0,0,0,0,0,0,0,0,0,0
0,0,0,0,0,0,0,0,0,0,0,0,0,0,0,0,0,0,0,0,0,0,0,0,0,0,0,0,0,0,0,0,0,0,0,0
0,0,0,0,0,0,0,0,0,0,0,0,0,0,0,0,0,0,0,0,0,0,0,0,0,0,0,0,0,0,0,0,0,0,0,0
0,0,0,0,0,0,0,0,0,0,0,0,0,0,0,0,0,0,0,0,0,0,0,0,0,0,0,0,0,0,0,0,0,0,0,0
0,0,0,0,0,0,0,0,0,0,0,0,0,0,0,0,0,0,0,0,0,0,0,0,0,0,0,0,0,0,0,0,0,0,0,0
0,0,0,0,0,0,0,0,0,0,0,0,0,0,0,0,0,0,0,0,0,0,0,0,0,0,0,0,0,0,0,0,0,0,0,0
endlayer

layer
0,0,0,0,0,0,0,0,0,0,0,0,0,0,0,0,0,0,0,0,0,0,0,0,0,0,0,0,0,0,0,0,0,0,0,0
0,0,0,0,0,0,0,0,0,0,0,0,0,0,0,0,0,0,0,0,0,0,0,0,0,0,0,0,0,0,0,0,0,0,0,0
0,0,0,0,0,0,0,0,0,0,0,0,0,0,0,0,0,0,0,0,0,0,0,0,0,0,0,0,0,0,0,0,0,0,0,0
0,0,0,0,0,0,0,0,0,29,0,0,0,0,0,0,0,0,0,0,0,58,0,0,0,0,0,0,9,9,0,0,0,0,0,0
0,0,0,0,0,0,0,0,29,29,7,0,0,0,0,0,0,0,0,0,58,58,58,0,0,0,0,8,29,29,7,0,0,0,0,0
0,0,0,0,0,0,0,8,29,29,7,0,0,0,0,0,0,0,0,0,0,58,0,0,0,0,0,8,29,29,7,0,0,0,0,0
0,0,0,0,0,0,0,0,6,6,0,0,0,0,0,0,0,0,0,0,0,0,0,0,0,0,0,0,6,6,0,0,0,0,0,0
0,0,0,0,0,0,0,0,0,0,0,0,0,0,0,0,0,0,0,0,0,0,0,0,0,0,0,0,0,0,0,0,0,0,0,0
0,0,0,0,0,0,0,0,0,0,0,0,0,0,0,0,0,0,0,0,0,0,0,0,0,0,0,0,0,0,0,0,0,0,0,0
0,0,0,0,0,0,0,0,0,0,0,0,0,0,0,0,0,0,0,0,0,0,0,0,0,0,0,0,0,0,0,0,0,0,0,0
0,0,0,0,0,0,0,0,0,0,0,0,0,0,0,0,0,0,0,0,0,0,0,0,0,0,0,0,0,0,0,0,0,0,0,0
0,0,0,0,0,0,0,0,9,9,0,0,0,0,0,0,0,0,0,0,0,0,0,0,0,0,0,0,0,0,0,0,0,0,0,0
0,0,0,0,0,0,0,8,29,29,7,0,0,0,0,0,0,0,0,0,0,0,0,0,0,0,0,0,0,0,0,0,0,0,0,0
0,0,0,0,0,0,0,8,29,29,7,0,0,0,0,0,0,0,0,0,0,0,0,0,0,0,0,0,0,0,0,0,0,0,0,0
0,0,0,0,0,0,0,0,6,0,0,0,0,0,0,0,0,0,0,0,0,0,0,0,0,0,0,0,0,0,0,0,0,0,0,0
0,0,0,0,0,0,0,0,0,0,0,0,0,0,0,0,0,0,59,59,59,61,0,0,0,0,0,0,0,0,0,0,0,0,0,0
0,0,0,0,0,0,0,0,0,0,0,0,0,0,0,0,0,0,62,28,28,61,0,0,0,0,0,0,0,0,0,0,0,0,0,0
0,0,0,0,0,0,0,0,0,0,0,0,0,0,0,0,0,0,62,28,28,61,0,0,0,0,0,0,0,0,0,0,0,0,0,0
0,0,0,0,0,0,0,0,0,0,0,0,0,0,0,0,0,0,62,60,60,60,0,0,0,0,0,0,0,0,0,0,0,0,0,0
0,0,0,0,0,0,0,0,0,0,0,0,0,0,0,0,0,0,0,0,0,0,0,0,0,0,0,0,0,0,0,0,0,0,0,0
0,0,0,0,0,0,0,0,0,0,0,0,0,0,0,0,0,0,0,0,0,0,0,0,0,0,0,0,0,0,0,0,0,0,0,0
0,0,0,0,0,0,0,0,0,0,0,0,0,0,0,0,0,0,0,0,0,0,0,0,0,0,0,0,0,0,0,0,0,0,0,0
0,0,0,0,0,0,0,9,9,0,0,0,0,0,0,0,0,0,0,0,0,0,0,0,0,0,0,0,0,0,0,0,0,0,0,0
0,0,0,0,0,0,8,29,29,7,0,0,0,0,0,0,0,0,0,0,0,0,0,0,0,0,0,0,0,0,0,0,0,0,0,0
0,0,0,0,0,0,8,29,29,7,0,0,0,0,0,0,0,0,0,0,0,0,0,0,0,0,0,0,0,0,0,0,0,0,0,0
0,0,0,0,0,0,0,6,6,0,0,0,0,0,0,0,0,0,0,0,0,0,0,0,0,0,0,0,0,0,0,0,0,0,0,0
0,0,0,0,0,0,0,0,0,0,0,0,0,0,0,0,0,0,0,0,0,0,0,0,0,0,0,0,0,0,0,0,0,0,0,0
0,0,0,0,0,0,0,0,0,0,0,0,0,0,0,0,0,0,0,0,0,0,0,0,0,0,0,0,0,0,0,0,0,0,0,0
0,0,0,0,0,0,0,0,0,0,0,0,0,0,0,0,0,0,0,0,0,0,0,0,0,0,0,0,0,0,0,0,0,0,0,0
0,0,0,0,0,0,0,0,0,0,0,0,0,0,0,0,0,0,0,0,0,0,0,0,0,0,0,0,0,0,0,0,0,0,0,0
0,0,0,0,0,0,0,0,0,0,0,0,0,0,0,0,0,0,0,0,0,0,0,0,0,0,0,0,0,0,0,0,0,0,0,0
0,0,0,0,0,0,0,0,0,0,0,0,0,0,0,0,0,0,0,0,0,0,0,0,0,0,0,0,0,0,0,0,0,0,0,0
0,0,0,0,0,0,0,0,0,0,0,0,0,0,0,0,0,0,0,0,0,0,0,0,0,0,0,0,0,0,0,0,0,0,0,0
0,0,0,0,0,0,0,0,0,0,0,0,0,0,0,0,0,0,0,0,0,0,0,0,0,0,0,0,0,0,0,0,0,0,0,0
0,0,0,0,0,0,0,0,0,0,0,0,0,0,0,0,0,0,0,0,0,0,0,0,0,0,0,0,0,0,0,0,0,0,0,0
0,0,0,0,0,0,0,0,0,0,0,0,0,0,0,0,0,0,0,0,0,0,0,0,0,0,0,0,0,0,0,0,0,0,0,0
endlayer

layer
0,0,0,0,0,0,0,0,0,58,0,0,0,0,0,0,0,0,0,0,0,0,0,0,0,0,0,0,0,0,0,0,0,0,0,0
0,0,0,0,0,0,0,0,58,58,58,0,0,0,0,0,0,0,0,0,0,0,0,0,0,0,0,0,0,0,0,0,0,0,0,0
0,0,0,0,0,0,0,58,58,29,58,58,0,0,0,0,0,0,0,0,0,0,0,0,0,0,0,0,0,0,0,0,0,0,0,0
0,0,0,0,0,0,0,0,58,58,58,0,0,0,0,0,0,0,0,0,0,0,0,0,0,0,0,0,9,9,0,0,0,0,0,0
0,0,0,0,0,0,0,0,29,29,7,0,0,0,0,0,0,0,0,0,0,0,0,0,0,0,0,8,29,29,7,0,0,0,0,0
0,0,0,0,0,0,0,8,29,29,0,0,0,0,0,0,0,0,0,0,0,0,0,0,0,0,0,8,29,29,7,0,0,0,0,0
0,0,0,0,0,0,0,0,6,6,0,0,0,0,0,0,0,0,0,0,0,0,0,0,0,0,0,29,6,6,0,0,0,0,0,0
0,0,0,0,0,0,0,0,0,0,0,0,0,0,0,0,0,0,0,0,0,0,0,0,0,0,0,0,0,0,0,0,0,0,0,0
0,0,0,0,0,0,0,0,0,0,0,0,0,0,0,0,0,0,0,0,0,0,0,0,0,0,0,0,0,0,0,0,0,0,0,0
0,0,0,0,0,0,0,0,0,0,0,0,0,0,0,0,0,0,0,0,0,0,0,0,0,0,0,0,0,0,0,0,0,0,0,0
0,0,0,0,0,0,0,0,0,0,0,0,0,0,0,0,0,0,0,0,0,0,0,0,0,0,0,0,0,0,0,0,0,0,0,0
0,0,0,0,0,0,0,0,9,9,0,0,0,0,0,0,0,0,0,0,0,0,0,0,0,0,0,0,0,0,0,0,0,0,0,0
0,0,0,0,0,0,0,8,29,29,7,0,0,0,0,0,0,0,0,0,0,0,0,0,0,0,0,0,0,0,0,0,0,0,0,0
0,0,0,0,0,0,0,8,29,29,7,0,0,0,0,0,0,0,0,0,0,0,0,0,0,0,0,0,0,0,0,0,0,0,0,0
0,0,0,0,0,0,0,0,6,68,0,0,0,0,0,0,0,0,0,0,0,0,0,0,0,0,0,0,0,0,0,0,0,0,0,0
0,0,0,0,0,0,0,0,0,0,0,0,0,0,0,0,0,0,49,47,47,47,0,0,0,0,0,0,0,0,0,0,0,0,0,0
0,0,0,0,0,0,0,0,0,0,0,0,0,0,0,0,0,0,49,21,21,48,0,0,0,0,0,0,0,0,0,0,0,0,0,0
0,0,0,0,0,0,0,0,0,0,0,0,0,0,0,0,0,0,49,21,21,48,0,0,0,0,0,0,0,0,0,0,0,0,0,0
0,0,0,0,0,0,0,0,0,0,0,0,0,0,0,0,0,0,50,50,50,50,0,0,0,0,0,0,0,0,0,0,0,0,0,0
0,0,0,0,0,0,0,0,0,0,0,0,0,0,0,0,0,0,0,0,0,0,0,0,0,0,0,0,0,0,0,0,0,0,0,0
0,0,0,0,0,0,0,0,0,0,0,0,0,0,0,0,0,0,0,0,0,0,0,0,0,0,0,0,0,0,0,0,0,0,0,0
0,0,0,0,0,0,0,0,0,0,0,0,0,0,0,0,0,0,0,0,0,0,0,0,0,0,0,0,0,0,0,0,0,0,0,0
0,0,0,0,0,0,0,9,9,0,0,0,0,0,0,0,0,0,0,0,0,0,0,0,0,0,0,0,0,0,0,0,0,0,0,0
0,0,0,0,0,0,8,29,29,7,0,0,0,0,0,0,0,0,0,0,0,0,0,0,0,0,0,0,0,0,0,0,0,0,0,0
0,0,0,0,0,0,8,29,29,7,0,0,0,0,0,0,0,0,0,0,0,0,0,0,0,0,0,0,0,0,0,0,0,0,0,0
0,0,0,0,0,0,0,6,6,0,0,0,0,0,0,0,0,0,0,0,0,0,0,0,0,0,0,0,0,0,0,0,0,0,0,0
0,0,0,0,0,0,0,0,0,0,0,0,0,0,0,0,0,0,0,0,0,0,0,0,0,0,0,0,0,0,0,0,0,0,0,0
0,0,0,0,0,0,0,0,0,0,0,0,0,0,0,0,0,0,0,0,0,0,0,0,0,0,0,0,0,0,0,0,0,0,0,0
0,0,0,0,0,0,0,0,0,0,0,0,0,0,0,0,0,0,0,0,0,0,0,0,0,0,0,0,0,0,0,0,0,0,0,0
0,0,0,0,0,0,0,0,0,0,0,0,0,0,0,0,0,0,0,0,0,0,0,0,0,0,0,0,0,0,0,0,0,0,0,0
0,0,0,0,0,0,0,0,0,0,0,0,0,0,0,0,0,0,0,0,0,0,0,0,0,0,0,0,0,0,0,0,0,0,0,0
0,0,0,0,0,0,0,0,0,0,0,0,0,0,0,0,0,0,0,0,0,0,0,0,0,0,0,0,0,0,0,0,0,0,0,0
0,0,0,0,0,0,0,0,0,0,0,0,0,0,0,0,0,0,0,0,0,0,0,0,0,0,0,0,0,0,0,0,0,0,0,0
0,0,0,0,0,0,0,0,0,0,0,0,0,0,0,0,0,0,0,0,0,0,0,0,0,0,0,0,0,0,0,0,0,0,0,0
0,0,0,0,0,0,0,0,0,0,0,0,0,0,0,0,0,0,0,0,0,0,0,0,0,0,0,0,0,0,0,0,0,0,0,0
0,0,0,0,0,0,0,0,0,0,0,0,0,0,0,0,0,0,0,0,0,0,0,0,0,0,0,0,0,0,0,0,0,0,0,0
endlayer

layer
0,0,0,0,0,58,58,58,58,58,58,58,58,0,0,0,0,0,0,0,0,0,0,0,0,0,0,0,0,0,0,0,0,0,0,0
0,0,0,0,58,58,58,58,58,58,58,58,58,58,0,0,0,0,0,0,0,0,0,0,0,0,0,0,0,0,0,0,0,0,0,0
0,0,0,0,58,58,58,58,58,58,58,58,58,58,0,0,0,0,0,0,0,0,0,0,0,0,0,0,0,0,0,0,0,0,0,0
0,0,0,0,58,58,58,58,58,58,58,58,58,58,0,0,0,0,0,0,0,0,0,0,0,0,0,0,9,9,0,0,0,0,0,0
0,0,0,58,58,58,58,58,29,29,58,58,58,58,58,0,0,0,0,0,0,0,0,0,0,0,0,8,29,29,7,0,0,0,0,0
0,0,0,58,58,58,58,58,29,29,58,58,58,58,58,0,0,0,0,0,0,0,0,0,0,0,0,8,29,29,7,0,0,0,0,0
0,0,0,0,58,58,58,58,58,58,58,58,58,58,0,0,0,0,0,0,0,0,0,0,0,0,29,0,6,6,0,0,0,0,0,0
0,0,0,0,58,58,58,58,58,58,58,58,58,58,0,0,0,0,0,0,0,0,0,0,0,29,0,0,0,0,0,0,0,0,0,0
0,0,0,0,58,58,58,58,58,58,58,58,58,58,0,0,0,0,0,0,0,0,0,0,0,0,0,0,0,0,0,0,0,0,0,0
0,0,0,0,0,58,58,58,58,58,58,58,58,0,0,0,0,0,0,0,0,0,0,0,0,0,0,0,0,0,0,0,0,0,0,0
0,0,0,0,0,0,0,0,58,58,0,0,0,0,0,0,0,0,0,0,0,0,0,0,0,0,0,0,0,0,0,0,0,0,0,0
0,0,0,0,0,0,0,0,9,9,0,0,0,0,0,0,0,0,0,0,0,0,0,0,0,0,0,0,0,0,0,0,0,0,0,0
0,0,0,0,0,0,0,8,29,29,7,0,0,0,0,0,0,0,0,0,0,0,0,0,0,0,0,0,0,0,0,0,0,0,0,0
0,0,0,0,0,0,0,8,29,29,7,0,0,0,0,0,0,0,0,0,0,0,0,0,0,0,0,0,0,0,0,0,0,0,0,0
0,0,0,0,0,0,0,0,6,6,0,0,0,0,0,0,0,0,0,0,0,0,0,0,0,0,0,0,0,0,0,0,0,0,0,0
0,0,0,0,0,0,0,0,0,0,0,0,0,0,0,0,0,0,0,0,0,0,0,0,0,0,0,0,0,0,0,0,0,0,0,0
0,0,0,0,0,0,0,0,0,0,0,0,0,0,0,0,0,0,0,0,0,0,0,0,0,0,0,0,0,0,0,0,0,0,0,0
0,0,0,0,0,0,0,0,0,0,0,0,0,0,0,0,0,0,0,0,0,0,0,0,0,0,0,0,0,0,0,0,0,0,0,0
0,0,0,0,0,0,0,0,0,0,0,0,0,0,0,0,0,0,0,0,0,0,0,0,0,0,0,0,0,0,0,0,0,0,0,0
0,0,0,0,0,0,0,0,0,0,0,0,0,0,0,0,0,0,0,0,0,0,0,0,0,0,0,0,0,0,0,0,0,0,0,0
0,0,0,0,0,0,0,0,0,0,0,0,0,0,0,0,0,0,0,0,0,0,0,0,0,0,0,0,0,0,0,0,0,0,0,0
0,0,0,0,0,0,0,0,0,0,0,0,0,0,0,0,0,0,0,0,0,0,0,0,0,0,0,0,0,0,0,0,0,0,0,0
0,0,0,0,0,0,0,9,9,0,0,0,0,0,0,0,0,0,0,0,0,0,0,0,0,0,0,0,0,0,0,0,0,0,0,0
0,0,0,0,0,0,8,29,29,7,0,0,0,0,0,0,0,0,0,0,0,0,0,0,0,0,0,0,0,0,0,0,0,0,0,0
0,0,0,0,0,0,8,29,29,7,0,0,0,0,0,0,0,0,0,0,0,0,0,0,0,0,0,0,0,0,0,0,0,0,0,0
0,0,0,0,0,0,0,6,6,0,0,0,0,0,0,0,0,0,0,0,0,0,0,0,0,0,0,0,0,0,0,0,0,0,0,0
0,0,0,0,0,0,0,0,0,0,0,0,0,0,0,0,0,0,0,0,0,0,0,0,0,0,0,0,0,0,0,0,0,0,0,0
0,0,0,0,0,0,0,0,0,0,0,0,0,0,0,0,0,0,0,0,0,0,0,0,0,0,0,0,0,0,0,0,0,0,0,0
0,0,0,0,0,0,0,0,0,0,0,0,0,0,0,0,0,0,0,0,0,0,0,0,0,0,0,0,0,0,0,0,0,0,0,0
0,0,0,0,0,0,0,0,0,0,0,0,0,0,0,0,0,0,0,0,0,0,0,0,0,0,0,0,0,0,0,0,0,0,0,0
0,0,0,0,0,0,0,0,0,0,0,0,0,0,0,0,0,0,0,0,0,0,0,0,0,0,0,0,0,0,0,0,0,0,0,0
0,0,0,0,0,0,0,0,0,0,0,0,0,0,0,0,0,0,0,0,0,0,0,0,0,0,0,0,0,0,0,0,0,0,0,0
0,0,0,0,0,0,0,0,0,0,0,0,0,0,0,0,0,0,0,0,0,0,0,0,0,0,0,0,0,0,0,0,0,0,0,0
0,0,0,0,0,0,0,0,0,0,0,0,0,0,0,0,0,0,0,0,0,0,0,0,0,0,0,0,0,0,0,0,0,0,0,0
0,0,0,0,0,0,0,0,0,0,0,0,0,0,0,0,0,0,0,0,0,0,0,0,0,0,0,0,0,0,0,0,0,0,0,0
0,0,0,0,0,0,0,0,0,0,0,0,0,0,0,0,0,0,0,0,0,0,0,0,0,0,0,0,0,0,0,0,0,0,0,0
endlayer

layer
0,0,0,0,0,0,0,0,58,58,0,0,0,0,0,0,0,0,0,0,0,0,0,0,0,0,0,0,0,0,0,0,0,0,0,0
0,0,0,0,0,0,58,58,58,58,58,58,0,0,0,0,0,0,0,0,0,0,0,0,0,0,0,0,0,0,0,0,0,0,0,0
0,0,0,0,0,58,58,58,58,58,58,58,58,0,0,0,0,0,0,0,0,0,0,0,0,0,0,0,0,0,0,0,0,0,0,0
0,0,0,0,0,58,58,58,58,58,58,58,58,0,0,0,0,0,0,0,0,0,0,0,0,0,0,0,9,9,0,0,0,0,0,0
0,0,0,0,58,58,58,58,58,29,58,58,58,58,0,0,0,0,0,0,0,0,0,0,0,0,0,8,29,29,67,0,0,0,0,0
0,0,0,0,58,58,58,58,58,58,58,58,58,58,0,0,0,0,0,0,0,0,0,0,0,58,0,8,29,29,7,0,0,0,0,0
0,0,0,0,0,58,58,58,58,58,58,58,58,0,0,0,0,0,0,0,0,0,0,0,58,58,58,0,6,6,0,0,0,0,0,0
0,0,0,0,0,58,58,58,58,58,58,58,58,0,0,0,0,0,0,0,0,0,0,58,58,29,58,58,0,0,0,0,0,0,0,0
0,0,0,0,0,0,58,58,58,58,58,58,0,0,0,0,0,0,0,0,0,0,0,0,58,58,58,0,0,0,0,0,0,0,0,0
0,0,0,0,0,0,0,0,58,58,0,0,0,0,0,0,0,0,0,0,0,0,0,0,0,58,0,0,0,0,0,0,0,0,0,0
0,0,0,0,0,0,0,0,0,0,0,0,0,0,0,0,0,0,0,0,0,0,0,0,0,0,0,0,0,0,0,0,0,0,0,0
0,0,0,0,0,0,0,0,9,9,0,0,0,0,0,0,0,0,0,0,0,0,0,0,0,0,0,0,0,0,0,0,0,0,0,0
0,0,0,0,0,0,0,8,29,29,7,0,0,0,0,0,0,0,0,0,0,0,0,0,0,0,0,0,0,0,0,0,0,0,0,0
0,0,0,0,0,0,0,8,29,29,7,0,0,0,0,0,0,0,0,0,0,0,0,0,0,0,0,0,0,0,0,0,0,0,0,0
0,0,0,0,0,0,0,0,6,6,0,0,0,0,0,0,0,0,0,0,0,0,0,0,0,0,0,0,0,0,0,0,0,0,0,0
0,0,0,0,0,0,0,0,0,0,0,0,0,0,0,0,0,0,0,0,0,0,0,0,0,0,0,0,0,0,0,0,0,0,0,0
0,0,0,0,0,0,0,0,0,0,0,0,0,0,0,0,0,0,0,0,0,0,0,0,0,0,0,0,0,0,0,0,0,0,0,0
0,0,0,0,0,0,0,0,0,0,0,0,0,0,0,0,0,0,0,0,0,0,0,0,0,0,0,0,0,0,0,0,0,0,0,0
0,0,0,0,0,0,0,0,0,0,0,0,0,0,0,0,0,0,0,0,0,0,0,0,0,0,0,0,0,0,0,0,0,0,0,0
0,0,0,0,0,0,0,0,0,0,0,0,0,0,0,0,0,0,0,0,0,0,0,0,0,0,0,0,0,0,0,0,0,0,0,0
0,0,0,0,0,0,0,0,0,0,0,0,0,0,0,0,0,0,0,0,0,0,0,0,0,0,0,0,0,0,0,0,0,0,0,0
0,0,0,0,0,0,0,0,0,0,0,0,0,0,0,0,0,0,0,0,0,0,0,0,0,0,0,0,0,0,0,0,0,0,0,0
0,0,0,0,0,0,0,9,9,0,0,0,0,0,0,0,0,0,0,0,0,0,0,0,0,0,0,0,0,0,0,0,0,0,0,0
0,0,0,0,0,0,8,29,29,67,0,0,0,0,0,0,0,0,0,0,0,0,0,0,0,0,0,0,0,0,0,0,0,0,0,0
0,0,0,0,0,0,8,29,29,7,0,0,0,0,0,0,0,0,0,0,0,0,0,0,0,0,0,0,0,0,0,0,0,0,0,0
0,0,0,0,0,0,0,6,6,0,0,0,0,0,0,0,0,0,0,0,0,0,0,0,0,0,0,0,0,0,0,0,0,0,0,0
0,0,0,0,0,0,0,0,0,0,0,0,0,0,0,0,0,0,0,0,0,0,0,0,0,0,0,0,0,0,0,0,0,0,0,0
0,0,0,0,0,0,0,0,0,0,0,0,0,0,0,0,0,0,0,0,0,0,0,0,0,0,0,0,0,0,0,0,0,0,0,0
0,0,0,0,0,0,0,0,0,0,0,0,0,0,0,0,0,0,0,0,0,0,0,0,0,0,0,0,0,0,0,0,0,0,0,0
0,0,0,0,0,0,0,0,0,0,0,0,0,0,0,0,0,0,0,0,0,0,0,0,0,0,0,0,0,0,0,0,0,0,0,0
0,0,0,0,0,0,0,0,0,0,0,0,0,0,0,0,0,0,0,0,0,0,0,0,0,0,0,0,0,0,0,0,0,0,0,0
0,0,0,0,0,0,0,0,0,0,0,0,0,0,0,0,0,0,0,0,0,0,0,0,0,0,0,0,0,0,0,0,0,0,0,0
0,0,0,0,0,0,0,0,0,0,0,0,0,0,0,0,0,0,0,0,0,0,0,0,0,0,0,0,0,0,0,0,0,0,0,0
0,0,0,0,0,0,0,0,0,0,0,0,0,0,0,0,0,0,0,0,0,0,0,0,0,0,0,0,0,0,0,0,0,0,0,0
0,0,0,0,0,0,0,0,0,0,0,0,0,0,0,0,0,0,0,0,0,0,0,0,0,0,0,0,0,0,0,0,0,0,0,0
0,0,0,0,0,0,0,0,0,0,0,0,0,0,0,0,0,0,0,0,0,0,0,0,0,0,0,0,0,0,0,0,0,0,0,0
endlayer

layer
0,0,0,0,0,0,0,0,0,0,0,0,0,0,0,0,0,0,0,0,0,0,0,0,0,0,0,0,0,0,0,0,0,0,0,0
0,0,0,0,0,0,0,0,58,58,0,0,0,0,0,0,0,0,0,0,0,0,0,0,0,0,0,0,0,0,0,0,0,0,0,0
0,0,0,0,0,0,58,58,58,58,58,58,0,0,0,0,0,0,0,0,0,0,0,0,0,0,0,0,0,0,0,0,0,0,0,0
0,0,0,0,0,0,58,58,58,58,58,58,0,0,0,0,0,0,0,0,0,0,0,0,0,0,0,0,9,9,0,0,0,0,0,0
0,0,0,0,0,58,58,58,58,58,58,58,58,0,0,0,0,0,0,0,0,0,0,0,0,0,0,8,29,29,7,0,0,0,0,0
0,0,0,0,0,58,58,58,58,58,58,58,58,0,0,0,0,0,0,0,0,0,0,0,0,0,0,29,29,29,7,0,0,0,0,0
0,0,0,0,0,0,58,58,58,58,58,58,0,0,0,0,0,0,0,0,0,0,0,0,0,58,0,0,6,6,0,0,0,0,0,0
0,0,0,0,0,0,58,58,58,58,58,58,0,0,0,0,0,0,0,0,0,0,0,0,58,58,58,0,0,0,0,0,0,0,0,0
0,0,0,0,0,0,0,0,58,58,0,0,0,0,0,0,0,0,0,0,0,0,0,0,0,58,0,0,0,0,0,0,0,0,0,0
0,0,0,0,0,0,0,0,0,0,0,0,0,0,0,0,0,0,0,0,0,0,0,0,0,0,0,0,0,0,0,0,0,0,0,0
0,0,0,0,0,0,0,0,0,0,0,0,0,0,0,0,0,0,0,0,0,0,0,0,0,0,0,0,0,0,0,0,0,0,0,0
0,0,0,0,0,0,0,0,9,9,0,0,0,0,0,0,0,0,0,0,0,0,0,0,0,0,0,0,0,0,0,0,0,0,0,0
0,0,0,0,0,0,0,8,29,29,7,0,0,0,0,0,0,0,0,0,0,0,0,0,0,0,0,0,0,0,0,0,0,0,0,0
0,0,0,0,0,0,0,8,29,29,7,0,0,0,0,0,0,0,0,0,0,0,0,0,0,0,0,0,0,0,0,0,0,0,0,0
0,0,0,0,0,0,0,0,6,6,0,0,0,0,0,0,0,0,0,0,0,0,0,0,0,0,0,0,0,0,0,0,0,0,0,0
0,0,0,0,0,0,0,0,0,0,0,0,0,0,0,0,0,0,0,0,0,0,0,0,0,0,0,0,0,0,0,0,0,0,0,0
0,0,0,0,0,0,0,0,0,0,0,0,0,0,0,0,0,0,0,0,0,0,0,0,0,0,0,0,0,0,0,0,0,0,0,0
0,0,0,0,0,0,0,0,0,0,0,0,0,0,0,0,0,0,0,0,0,0,0,0,0,0,0,0,0,0,0,0,0,0,0,0
0,0,0,0,0,0,0,0,0,0,0,0,0,0,0,0,0,0,0,0,0,0,0,0,0,0,0,0,0,0,0,0,0,0,0,0
0,0,0,0,0,0,0,0,0,0,0,0,0,0,0,0,0,0,0,0,0,0,0,0,0,0,0,0,0,0,0,0,0,0,0,0
0,0,0,0,0,0,0,0,0,0,0,0,0,0,0,0,0,0,0,0,0,0,0,0,0,0,0,0,0,0,0,0,0,0,0,0
0,0,0,0,0,0,0,0,0,0,0,0,0,0,0,0,0,0,0,0,0,0,0,0,0,0,0,0,0,0,0,0,0,0,0,0
0,0,0,0,0,0,0,9,0,0,0,0,0,0,0,0,0,0,0,0,0,0,0,0,0,0,0,0,0,0,0,0,0,0,0,0
0,0,0,0,0,0,8,29,29,7,0,0,0,0,0,0,0,0,0,0,0,0,0,0,0,0,0,0,0,0,0,0,0,0,0,0
0,0,0,0,0,0,64,29,29,7,0,0,0,0,0,0,0,0,0,0,0,0,0,0,0,0,0,0,0,0,0,0,0,0,0,0
0,0,0,0,0,0,0,6,6,0,0,0,0,0,0,0,0,0,0,0,0,0,0,0,0,0,0,0,0,0,0,0,0,0,0,0
0,0,0,0,0,0,0,0,0,0,0,0,0,0,0,0,0,0,0,0,0,0,0,0,0,0,0,0,0,0,0,0,0,0,0,0
0,0,0,0,0,0,0,0,0,0,0,0,0,0,0,0,0,0,0,0,0,0,0,0,0,0,0,0,0,0,0,0,0,0,0,0
0,0,0,0,0,0,0,0,0,0,0,0,0,0,0,0,0,0,0,0,0,0,0,0,0,0,0,0,0,0,0,0,0,0,0,0
0,0,0,0,0,0,0,0,0,0,0,0,0,0,0,0,0,0,0,0,0,0,0,0,0,0,0,0,0,0,0,0,0,0,0,0
0,0,0,0,0,0,0,0,0,0,0,0,0,0,0,0,0,0,0,0,0,0,0,0,0,0,0,0,0,0,0,0,0,0,0,0
0,0,0,0,0,0,0,0,0,0,0,0,0,0,0,0,0,0,0,0,0,0,0,0,0,0,0,0,0,0,0,0,0,0,0,0
0,0,0,0,0,0,0,0,0,0,0,0,0,0,0,0,0,0,0,0,0,0,0,0,0,0,0,0,0,0,0,0,0,0,0,0
0,0,0,0,0,0,0,0,0,0,0,0,0,0,0,0,0,0,0,0,0,0,0,0,0,0,0,0,0,0,0,0,0,0,0,0
0,0,0,0,0,0,0,0,0,0,0,0,0,0,0,0,0,0,0,0,0,0,0,0,0,0,0,0,0,0,0,0,0,0,0,0
0,0,0,0,0,0,0,0,0,0,0,0,0,0,0,0,0,0,0,0,0,0,0,0,0,0,0,0,0,0,0,0,0,0,0,0
endlayer

layer
0,0,0,0,0,0,0,0,0,0,0,0,0,0,0,0,0,0,0,0,0,0,0,0,0,0,0,0,0,0,0,0,0,0,0,0
0,0,0,0,0,0,0,0,0,0,0,0,0,0,0,0,0,0,0,0,0,0,0,0,0,0,0,0,0,0,0,0,0,0,0,0
