# GargoyleStone -- Created: 5 May 2014
# Updated to MC 1.8: 21 Jul 2015
# Created by Ruins mod version 12.3 Ingame Parser
# authoring Player: Jordan_Greywolf
# Verified for MC 1.12: 23 Jun 2017
# Updated to MC 1.12.1: 9 Sep 2017

biomesToSpawnIn=extreme hills,extreme hills edge,extreme hills m,extreme hills+,extreme hills+ m,twilight forest,twilight clearing,roofed forest,ominous woods,mystic grove,magical forest,crag,birch_forest_hills,extreme_hills,extreme_hills_with_trees,forest_hills,mutated_birch_forest_hills,mutated_extreme_hills,mutated_extreme_hills_with_trees,mutated_redwood_taiga,mutated_redwood_taiga_hills,mutated_savanna_rock,mutated_taiga_cold,redwood_taiga,redwood_taiga_hills,savanna_rock,smaller_extreme_hills,taiga_cold,taiga_cold_hills,taiga_hills

weight=1
embed_into_distance=0
acceptable_target_blocks=

unacceptable_target_blocks=water,flowing_water,Natura:Cloud,slime_congealed,slime_dirt,slime_grass,command_block

dimensions=13,8,9
allowable_overhang=0
max_cut_in=0
cut_in_buffer=0
max_leveling=8
leveling_buffer=-1
preserve_water=0
preserve_lava=0
preserve_plants=1

rule1=0,100,minecraft:stonebrick,minecraft:stonebrick-1,minecraft:stonebrick-2
rule2=0,100,preserveBlock

layer
2,2,2,2,2,2,2,2,2
2,2,2,2,1,2,2,2,2
2,2,1,1,1,1,1,2,2
2,2,1,1,1,1,1,2,2
2,2,2,2,2,2,2,2,2
2,2,2,2,2,2,2,2,2
2,2,1,2,2,2,1,2,2
2,2,1,2,2,2,1,2,2
endlayer

layer
2,2,2,2,1,2,2,2,2
2,2,2,2,2,2,2,2,2
2,2,1,1,1,1,1,2,2
2,2,2,1,1,1,2,2,2
2,2,2,2,2,2,2,2,2
2,2,1,2,2,2,1,2,2
2,2,1,2,2,2,1,2,2
2,2,2,2,2,2,2,2,2
endlayer

layer
2,2,2,2,1,2,2,2,2
2,2,2,2,2,2,2,2,2
2,2,1,1,1,1,1,2,2
2,2,1,1,1,1,1,2,2
2,2,2,1,1,2,2,2,2
2,2,1,2,2,2,1,2,2
2,2,2,2,2,2,2,2,2
2,2,2,2,2,2,2,2,2
endlayer

layer
2,2,2,2,1,2,2,2,2
2,2,2,2,2,2,2,2,2
2,2,2,2,1,2,2,2,2
2,2,2,1,1,1,2,2,2
2,2,2,1,1,1,2,2,2
2,2,1,1,1,1,1,2,2
2,2,2,2,2,2,2,2,2
2,2,2,2,2,2,2,2,2
endlayer

layer
2,2,2,2,1,2,2,2,2
2,2,2,2,2,2,2,2,2
2,2,2,2,1,2,2,2,2
2,2,2,2,1,2,2,2,2
2,2,2,1,1,1,2,2,2
2,2,2,1,1,1,2,2,2
2,2,2,2,2,2,2,2,2
2,2,2,2,2,2,2,2,2
endlayer

layer
2,2,1,2,1,2,1,2,2
2,2,2,2,2,2,2,2,2
2,2,2,2,1,2,2,2,2
2,2,2,1,1,1,2,2,2
2,2,2,1,1,1,2,2,2
2,2,2,2,1,2,2,2,2
2,2,2,2,2,2,2,2,2
2,2,2,2,2,2,2,2,2
endlayer

layer
1,2,1,2,2,2,1,2,1
2,2,1,2,2,2,1,2,2
2,2,2,2,2,2,2,2,2
2,2,1,1,1,1,1,2,2
2,2,2,2,1,2,2,2,2
2,2,2,2,1,2,2,2,2
2,2,2,1,1,1,2,2,2
2,2,2,2,1,2,2,2,2
endlayer

layer
1,1,1,2,2,2,1,1,1
2,2,1,2,2,2,1,2,2
2,2,1,2,2,2,1,2,2
2,2,1,2,2,2,1,2,2
2,2,2,2,1,2,2,2,2
2,2,2,1,1,1,2,2,2
2,2,2,1,1,1,2,2,2
2,2,2,2,2,2,2,2,2
endlayer

layer
1,1,1,2,2,2,1,1,1
2,2,1,2,2,2,1,2,2
2,2,1,2,2,2,1,2,2
2,2,2,2,2,2,2,2,2
2,2,2,2,2,2,2,2,2
2,2,2,1,2,1,2,2,2
2,2,2,2,2,2,2,2,2
2,2,2,2,2,2,2,2,2
endlayer

layer
1,1,1,2,2,2,1,1,1
2,2,1,2,2,2,1,2,2
2,2,2,2,2,2,2,2,2
2,2,2,2,2,2,2,2,2
2,2,2,2,2,2,2,2,2
2,2,2,2,2,2,2,2,2
2,2,2,2,2,2,2,2,2
2,2,2,2,2,2,2,2,2
endlayer

layer
2,1,1,2,2,2,1,1,2
2,2,1,2,2,2,1,2,2
2,2,2,2,2,2,2,2,2
2,2,2,2,2,2,2,2,2
2,2,2,2,2,2,2,2,2
2,2,2,2,2,2,2,2,2
2,2,2,2,2,2,2,2,2
2,2,2,2,2,2,2,2,2
endlayer

layer
2,2,2,2,2,2,2,2,2
2,1,1,2,2,2,1,1,2
2,2,2,2,2,2,2,2,2
2,2,2,2,2,2,2,2,2
2,2,2,2,2,2,2,2,2
2,2,2,2,2,2,2,2,2
2,2,2,2,2,2,2,2,2
2,2,2,2,2,2,2,2,2
endlayer

layer
2,2,2,2,2,2,2,2,2
2,2,2,2,2,2,2,2,2
2,2,1,2,2,2,1,2,2
2,2,2,2,2,2,2,2,2
2,2,2,2,2,2,2,2,2
2,2,2,2,2,2,2,2,2
2,2,2,2,2,2,2,2,2
2,2,2,2,2,2,2,2,2
endlayer


