# Mine Tower -- created 26 Nov 2015 for MC 1.7.10
# Created by Ruins mod version 15.1 Ingame Parser
# authoring Player: Jordan_Greywolf
# Note: Accompanying "TP_Mine_Tunnel" template goes in
# \templateparser folder.


# Updated to MC 1.9: 26 Apr 2016
# Updated to MC 1.10: 13 Sep 2016
# Updated to MC 1.11: 11 Jan 2017
# Updated to MC 1.12: 23 Jun 2017
# Updated to MC 1.12.1: 9 Sep 2017

# Thanks to GeeTheBlueSky for error reporting.

# Last Updated 8 Dec 2018

preventRotation=1

uniqueMinDistance=2000

biomesToSpawnIn=alps_foothills,apalachia,autumnal_woods,birch forest,birch forest hills,birch forest hills m,birch forest m,boreal forest,boreal_forest,cold taiga,cold taiga hills,cold taiga m,coniferous forest,coniferous_forest,dead forest,dead_forest,dense forest,dreadlands,eden,extreme hills,extreme hills edge,extreme hills m,fen,flower_island,forest,foresthills,frost forest,frost_forest,fungi_forest,highland,jade cliffs,maple woods,maple_woods,mega sprue taiga,mega taiga,mega taiga hills,mountain,oak savannah,oak_savannah,ominous woods,ominous_woods,orchard,origin_island,origin valley,origin_valley,rwg_coldforest,rwg_snowforest,rwg_temperateforest,seasonal forest,seasonal_forest,seasonal forest clearing,shield,silkglades,snowy coniferous forest,spruce woods,steppe,taiga,taiga m,taigahills,twilight_clearing,wildwood,woodland,xeric shrubland,xeric_shrubland,mining biome,miningbiome,mining_biome,extreme_hills,extreme_hills_with_trees,mutated_extreme_hills,mutated_extreme_hills_with_trees,smaller_extreme_hills,stone_beach,birch_forest,birch_forest_hills,mutated_birch_forest,mutated_birch_forest_hills,taiga_cold,taiga_cold_hills,forest_hills

weight=1
embed_into_distance=25
acceptable_target_blocks=

unacceptable_target_blocks=flowing_water,water,flowing_lava,lava,cloud,Natura:Cloud,red_mushroom_block,brown_mushroom_block,slime_congealed,slime_dirt,slime_grass,command_block,planks,planks2,concrete,cobblestone,stonebrick,brick_block,glass,torch,oak_stairs,stone_stairs,brick_stairs,stone_brick_stairs,nether_brick_stairs,sandstone_stairs,spruce_stairs,birch_stairs,jungle_stairs,quartz_stairs,acacia_stairs,dark_oak_stairs,cobblestone_wall,stone_slab,double_stone_slab,stone_slab2,wooden_slab,double_wooden_slab,nether_brick

dimensions=51,14,14
allowable_overhang=0
max_leveling=12
leveling_buffer=-1
preserve_water=0
preserve_lava=0
preserve_plants=1

rule1=0,100,preserveBlock
rule2=0,100,minecraft:log-0
rule3=0,100,minecraft:fence-0
rule4=0,100,minecraft:rail-1

rule5=0,100,minecraft:emerald_ore-0,minecraft:emerald_ore,minecraft:emerald_ore,minecraft:gold_ore,minecraft:gold_ore,minecraft:diamond_ore

rule6=0,100,CommandBlock:RUINSTRIGGER /testruin TP_Mine_Tunnel ~-12 ~0 ~0 3:@

# Undead Miner
rule7=0,100,CommandBlock:RUINSTRIGGER /summon Skeleton ~0 ~0 ~0  {HandItems:[{Count:1,id:iron_pickaxe,tag:{display:{Name:"Webbed Pickaxe"},ench:[{id:33,lvl:1},{id:19,lvl:1},{id:16,lvl:3}]}},{}],ArmorItems:[{Count:1,id:leather_boots},{Count:1,id:leather_leggings},{Count:1,id:leather_chestplate},{Count:1,id:iron_helmet}],HandDropChances:[1.0F,0.0F],ArmorDropChances:[0.0F,0.0F,0.0F,1.0F],ActiveEffects:[{Id:14,Amplifier:1,Duration:999999},{Id:5,Amplifier:1,Duration:999999},{Id:13,Amplifier:1,Duration:999999}],PersistenceRequired:1}:@

rule8=0,100,minecraft:cobblestone-0
rule9=0,100,Skull:0:4-1
rule10=0,100,minecraft:ladder-2
rule11=0,100,minecraft:rail-7
rule12=0,100,minecraft:rail-0
rule13=0,100,minecraft:rail-9
rule14=0,100,CommandBlock:RUINSTRIGGER /testruin TP_Mine_Tunnel ~1 ~0 ~-11:@
rule15=0,100,minecraft:web-0
rule16=0,100,CommandBlock:RUINSTRIGGER /testruin TP_Mine_Tunnel ~0 ~0 ~11 2:@
rule17=0,100,minecraft:mossy_cobblestone-0
rule18=0,100,CommandBlock:RUINSTRIGGER /testruin TP_Mine_Tunnel ~11 ~0 ~1 1:@
rule19=0,100,MobSpawner:Spider,MobSpawner:Skeleton

rule20=0,100,ChestGenHook:chests/simple_dungeon:3-2,ChestGenHook:chests/abandoned_mineshaft:3-2

rule21=0,100,IInventory;minecraft:chest;minecraft:enchanted_book#{StoredEnchantments:[{lvl:3,id:34}]}#0#0+minecraft:enchanted_book#{StoredEnchantments:[{lvl:1,id:33}]}#0#1+minecraft:sapling#6#3#2+minecraft:sapling#6#5#3+minecraft:melon_block#1#0#4+minecraft:rail#12#0#7-4

rule22=0,100,ChestGenHook:chests/abandoned_mineshaft:3-4
rule23=0,100,minecraft:stone-0
rule24=0,100,minecraft:log-8
rule25=0,100,minecraft:log-4
rule26=0,100,minecraft:planks-0
rule27=0,100,minecraft:flowing_lava
rule28=0,100,CommandBlock:RUINSTRIGGER /testruin TP_Mine_Tunnel ~1 ~0 ~-11:@
rule29=0,100,minecraft:mycelium-0
rule30=0,100,minecraft:red_mushroom-0

# Creeper in Mine Cart!
rule31=0,100,CommandBlock:RUINSTRIGGER /summon minecart ~0 ~2 ~0 {Passengers:[{EntityId:creeper,id:creeper,PersistenceRequired:1}]}:@

rule32=0,100,minecraft:flowing_water
rule33=0,100,minecraft:wooden_door-0
rule34=0,100,minecraft:tnt,minecraft:tnt-1

rule35=0,100,IInventory;minecraft:trapped_chest;minecraft:golden_rail#6#0#0+minecraft:tnt#21#0#1+minecraft:tnt_minecart#1#0#2+minecraft:tnt_minecart#1#0#3+minecraft:rail#36#0#4+minecraft:redstone_torch#5#0#5+minecraft:torch#2#0#6+minecraft:water_bucket#1#0#7-4

rule36=2,100,WallSign:DANGER!:* KEEP *:* OUT *:null-4
rule37=0,100,minecraft:wooden_door-8

# Undead Miner Spawner
rule38=0,100,CommandBlock:RUINSTRIGGER /setblock ~0 ~-1 ~0 mob_spawner 0 replace {SpawnCount:1,SpawnRange:4,maxNearbyEntities:6,Delay:20,MinSpawnDelay:60,MaxSpawnDelay:120,EntityId:skeleton,SpawnData:{id:skeleton,HandItems:[{Count:1,id:iron_pickaxe,tag:{display:{Name:"Webbed Pickaxe"},ench:[{id:33,lvl:1},{id:19,lvl:1},{id:16,lvl:3}]}},{}],ArmorItems:[{Count:1,id:leather_boots},{Count:1,id:leather_leggings},{Count:1,id:leather_chestplate},{Count:1,id:tnt}],HandDropChances:[0.5F,0.0F],ArmorDropChances:[0.0F,0.0F,0.0F,0.4F],ActiveEffects:[{Id:14,Amplifier:1,Duration:999999},{Id:5,Amplifier:1,Duration:999999},{Id:13,Amplifier:1,Duration:999999}]}}:@

rule39=0,100,minecraft:iron_bars-0
rule40=0,100,minecraft:red_mushroom_block-10
rule41=0,100,minecraft:red_mushroom_block-7
rule42=0,100,minecraft:red_mushroom_block-8
rule43=0,100,minecraft:red_mushroom_block-9
rule44=0,100,minecraft:red_mushroom_block-3
rule45=0,100,minecraft:red_mushroom_block-6
rule46=0,100,minecraft:red_mushroom_block-1
rule47=0,100,minecraft:red_mushroom_block-4
rule48=0,100,minecraft:red_mushroom_block-2
rule49=0,100,minecraft:red_mushroom_block-5

# Undead Miner
rule50=0,100,CommandBlock:RUINSTRIGGER /summon skeleton ~0 ~0 ~0  {HandItems:[{Count:1,id:iron_pickaxe,tag:{display:{Name:"Webbed Pickaxe"},ench:[{id:33,lvl:1},{id:19,lvl:1},{id:16,lvl:3}]}},{}],ArmorItems:[{Count:1,id:leather_boots},{Count:1,id:leather_leggings},{Count:1,id:leather_chestplate},{Count:1,id:iron_helmet}],HandDropChances:[0.5F,0.0F],ArmorDropChances:[0.0F,0.0F,0.0F,0.4F],ActiveEffects:[{Id:14,Amplifier:1,Duration:999999},{Id:5,Amplifier:1,Duration:999999},{Id:13,Amplifier:1,Duration:999999}],PersistenceRequired:1}:@

rule51=0,100,IInventory;minecraft:furnace;minecraft:coal#3#1#1-2
rule52=0,100,IInventory;minecraft:furnace;minecraft:coal#3#1#1-5
rule53=0,100,minecraft:ladder-4
rule54=0,100,minecraft:brick_block-0
rule55=0,100,minecraft:brick_stairs-0
rule56=0,100,minecraft:brick_stairs-3
rule57=0,100,minecraft:spruce_stairs-2
rule58=0,100,minecraft:spruce_stairs-7
rule59=0,100,minecraft:spruce_stairs-6
rule60=0,100,minecraft:spruce_stairs-3
rule61=0,100,minecraft:spruce_stairs-0
rule62=0,100,minecraft:spruce_stairs-5
rule63=0,100,minecraft:spruce_stairs-4
rule64=0,100,minecraft:spruce_stairs-1
rule65=0,100,minecraft:planks-1
rule66=0,100,minecraft:wooden_slab-1
rule67=0,100,minecraft:wooden_slab-9
rule68=0,100,minecraft:brick_stairs-2
rule69=0,100,minecraft:brick_stairs-1

layer
1,1,1,1,2,3,0,4,3,2,1,1,1,1
1,8,8,8,7,0,6,4,0,0,1,1,5,1
1,8,8,8,0,9,0,4,0,1,1,1,1,1
1,8,8,10,7,0,0,4,0,0,1,1,1,1
2,7,9,7,2,3,0,4,3,2,1,9,0,2
3,0,0,0,3,13,12,11,0,3,0,0,0,3
12,12,12,12,12,11,3,3,15,0,0,0,14,0
0,16,0,0,0,15,3,3,13,12,12,12,12,12
3,0,17,0,3,0,13,12,11,3,0,0,0,3
2,0,17,17,2,3,4,15,3,2,1,0,0,2
17,17,17,17,17,0,4,0,0,15,1,1,1,1
17,17,17,17,17,17,4,0,0,0,1,1,1,1
17,17,17,17,17,15,4,18,0,15,1,1,1,1
17,17,17,17,2,3,4,0,3,2,1,1,1,1
endlayer

layer
1,1,1,1,2,3,0,0,3,2,1,1,5,1
1,8,8,8,0,0,0,0,0,0,1,5,5,5
1,8,8,8,0,0,0,0,0,0,1,1,5,1
1,8,8,10,0,0,0,0,0,0,1,1,1,1
2,0,0,15,2,3,0,0,3,2,0,0,0,2
3,0,0,0,3,0,0,0,0,3,0,0,0,3
0,0,0,0,0,0,0,0,0,0,0,0,0,0
0,0,0,0,0,0,0,0,0,0,0,0,0,0
3,0,0,0,3,0,0,0,0,3,0,0,0,3
2,0,0,0,2,3,0,0,3,2,0,0,0,2
8,20,0,19,0,0,0,0,0,0,1,1,1,1
8,0,0,0,0,0,0,0,0,0,1,1,1,1
8,0,22,21,0,0,0,0,0,0,1,1,1,1
8,8,8,8,2,3,0,0,3,2,1,1,1,1
endlayer

layer
1,1,1,1,2,3,0,0,3,2,1,1,1,1
1,8,8,8,0,0,0,0,0,15,1,1,5,1
1,8,8,8,0,0,0,0,0,1,1,1,1,1
1,8,8,10,0,0,0,0,0,0,1,1,1,1
2,0,0,0,2,3,0,0,3,2,0,0,1,2
3,0,0,0,3,0,0,0,0,3,0,0,0,3
0,0,0,0,0,0,0,0,0,0,0,0,0,0
0,0,0,0,0,0,0,0,0,0,0,0,0,0
3,0,0,0,3,0,0,0,0,3,0,0,0,3
2,0,0,0,2,3,0,0,3,2,0,0,0,2
8,0,0,0,0,0,0,0,0,0,1,1,1,1
8,0,0,0,0,0,0,0,0,0,1,1,1,1
8,0,0,0,0,0,0,0,0,0,1,1,1,1
8,8,8,8,2,3,0,0,3,2,1,1,1,1
endlayer

layer
1,1,1,1,2,3,15,15,3,2,1,1,1,1
1,8,8,8,15,0,0,0,0,1,1,1,1,1
1,8,8,8,0,0,0,0,0,1,1,1,1,1
1,8,8,10,15,0,0,0,0,0,1,1,1,1
2,0,15,15,2,3,0,0,3,2,15,1,1,2
3,0,0,0,3,0,0,0,0,3,0,0,15,3
15,0,0,0,0,0,0,0,0,15,0,0,0,15
15,0,0,0,0,0,0,0,0,15,0,0,0,15
3,15,0,0,3,0,0,0,0,3,0,0,0,3
2,0,0,15,2,3,15,15,3,2,15,0,15,2
8,0,0,0,0,0,0,0,0,15,1,1,1,1
8,0,0,0,0,0,0,0,0,0,1,1,1,1
8,0,0,0,0,0,0,0,0,15,1,1,1,1
8,8,8,8,2,3,15,15,3,2,1,1,1,1
endlayer

layer
1,1,1,1,2,24,24,24,24,2,23,23,1,1
1,8,8,8,25,26,26,26,26,25,23,23,23,1
1,8,8,8,25,26,26,26,26,25,23,5,23,23
1,8,8,10,25,26,26,26,26,25,23,23,23,23
2,24,24,24,2,24,24,24,24,2,24,24,24,2
25,26,26,26,25,26,26,26,26,25,26,26,26,25
25,26,26,26,25,26,3,3,26,25,26,26,26,25
25,26,26,26,25,26,3,3,26,25,26,26,26,25
25,26,26,26,25,26,26,26,26,25,26,26,26,25
2,24,24,24,2,24,24,24,24,2,24,24,24,2
8,17,17,17,25,26,26,26,26,25,1,1,1,1
8,17,17,17,25,26,26,26,26,25,1,1,1,1
8,17,17,17,25,26,26,26,26,25,1,1,1,1
8,8,8,8,2,24,24,24,24,2,1,1,1,1
endlayer

layer
1,1,1,1,2,3,0,4,3,2,23,23,23,1
1,8,8,8,15,0,6,4,0,0,23,27,5,23
1,8,8,8,0,0,0,4,0,5,23,27,27,23
1,8,8,10,15,0,0,4,0,0,23,23,23,23
2,7,7,0,2,3,0,4,3,2,15,9,15,2
3,0,0,0,3,13,12,11,0,3,0,0,0,3
12,12,12,12,12,11,3,3,0,0,0,0,28,15
15,16,0,0,0,0,3,3,13,12,12,12,12,12
3,0,0,0,3,0,13,12,11,3,0,0,0,3
2,15,29,0,2,3,4,0,3,2,0,0,0,2
1,1,29,29,7,0,4,0,0,0,1,1,0,1
1,1,1,1,0,0,4,0,0,0,1,1,1,1
1,1,1,1,15,0,4,18,0,15,1,1,1,1
1,1,1,1,2,3,4,0,3,2,1,1,1,1
endlayer

layer
1,1,1,1,2,3,0,0,3,2,5,23,23,23
1,8,8,8,0,0,0,0,0,0,23,27,27,23
1,8,8,8,0,0,0,0,0,9,23,27,27,5
1,8,8,10,0,0,0,0,0,0,23,23,23,23
2,7,0,0,2,3,0,0,3,2,0,0,0,2
3,0,0,0,3,0,0,0,0,3,0,0,0,3
0,0,0,0,0,0,0,0,0,0,0,0,0,0
0,0,0,0,0,0,0,0,0,0,0,0,0,0
3,0,0,0,3,0,0,0,0,3,0,0,0,3
2,0,0,0,2,3,0,0,3,2,0,0,0,2
1,1,30,0,0,0,0,0,0,0,0,1,1,1
1,1,29,1,0,0,0,0,0,0,1,1,1,1
1,1,29,29,0,0,0,0,0,0,1,1,1,1
1,1,1,1,2,3,0,0,3,2,1,1,1,1
endlayer

layer
1,1,1,1,2,3,0,0,3,2,23,23,5,23
1,8,8,8,0,0,0,0,0,23,23,27,27,23
1,8,8,8,0,0,0,0,0,0,23,27,27,23
1,8,8,10,0,0,0,0,0,0,23,27,23,23
2,0,0,0,2,3,0,0,3,2,0,5,0,2
3,0,0,0,3,0,0,0,0,3,0,0,0,3
0,0,0,0,0,0,0,0,0,0,0,0,0,0
0,0,0,0,0,0,0,0,0,0,0,0,0,0
3,0,0,0,3,0,0,0,0,3,0,0,0,3
2,0,0,0,2,3,0,0,3,2,0,0,0,2
29,29,0,0,0,0,0,0,0,0,0,0,1,1
1,1,0,1,0,0,0,0,0,0,1,1,1,1
1,29,0,0,0,0,0,0,0,0,1,1,1,1
1,1,1,1,2,3,0,0,3,2,1,1,1,1
endlayer

layer
1,1,1,1,2,3,0,15,3,2,23,23,23,1
1,8,8,8,0,0,0,0,15,23,27,27,5,23
1,8,8,8,15,0,0,0,0,5,27,27,27,23
1,8,8,10,15,0,0,0,0,23,27,27,23,5
2,0,0,0,2,3,0,0,3,2,23,23,15,2
3,0,0,0,3,0,0,0,0,3,15,0,0,3
0,31,0,0,0,0,0,0,0,0,0,0,0,15
0,0,0,0,0,0,0,0,0,0,0,0,0,0
3,0,0,0,3,0,0,0,0,3,0,0,15,3
2,0,0,15,2,3,0,0,3,2,15,0,15,2
30,0,23,23,0,0,0,0,0,0,0,1,1,1
1,1,23,23,0,0,0,0,0,0,0,1,1,1
1,0,0,23,15,0,0,0,0,15,1,1,1,1
1,1,1,1,2,3,0,0,3,2,1,1,1,1
endlayer

layer
1,1,1,1,2,24,24,24,24,2,23,23,1,1
1,8,8,8,25,26,26,26,26,25,5,23,23,1
1,8,8,8,25,26,26,26,26,25,23,23,23,23
1,8,8,10,25,26,26,26,26,25,23,23,23,23
2,24,24,24,2,24,24,24,24,2,24,24,24,2
25,26,26,26,25,26,26,26,26,25,26,26,26,25
25,26,26,26,25,26,3,3,26,25,26,26,26,25
25,26,26,26,25,26,3,3,26,25,26,26,26,25
25,26,26,26,25,26,26,26,26,25,26,26,26,25
2,24,24,24,2,24,24,24,24,2,24,24,24,2
1,23,0,29,25,26,26,26,26,25,26,26,26,1
1,23,32,0,25,26,26,26,26,25,26,26,26,1
1,23,23,23,25,26,26,26,26,25,26,26,26,1
1,1,1,1,2,24,24,24,24,2,1,1,1,1
endlayer

layer
1,1,1,1,2,3,0,4,3,2,1,1,1,1
1,8,8,8,0,0,6,4,0,0,1,23,1,1
1,8,8,8,0,0,0,4,0,7,1,23,23,1
1,8,8,10,15,0,0,4,0,0,1,1,29,1
2,15,7,0,2,3,0,4,3,2,0,0,0,2
3,0,0,0,3,13,12,11,15,3,0,0,0,3
12,12,12,12,12,11,3,3,0,0,0,0,28,0
0,16,0,0,0,0,3,3,13,12,12,12,12,12
3,0,0,0,3,15,13,12,11,3,0,0,0,3
2,15,30,0,2,3,4,0,3,2,26,33,26,2
23,29,0,30,0,0,4,0,0,26,0,0,34,1
23,0,0,0,30,0,4,0,0,26,35,34,34,1
23,0,0,29,0,0,4,18,0,26,34,34,34,1
1,22,23,23,2,3,4,0,3,2,1,1,1,1
endlayer

layer
1,1,1,1,2,3,0,0,3,2,29,29,1,1
1,8,8,8,0,0,0,0,0,0,29,29,1,1
1,8,8,8,0,0,0,0,0,0,29,32,29,1
1,8,8,10,0,0,0,0,0,0,1,29,30,1
2,0,0,0,2,3,0,0,3,2,0,0,0,2
3,0,0,0,3,0,0,0,0,3,0,0,0,3
0,0,0,0,0,0,0,0,0,0,0,0,0,0
0,0,0,0,0,0,0,0,0,0,0,0,0,0
3,0,0,0,3,0,0,0,0,3,36,0,0,3
2,0,0,0,2,3,0,0,3,2,26,37,26,2
23,30,0,0,0,0,0,0,0,26,38,0,34,1
23,0,0,0,0,0,0,0,0,39,0,34,34,1
23,0,0,30,0,0,0,0,0,26,34,34,34,1
23,23,23,23,2,3,0,0,3,2,1,1,1,1
endlayer

layer
1,1,1,1,2,3,0,0,3,2,0,30,29,1
1,8,8,8,0,0,0,0,0,0,30,0,40,29
1,8,8,8,0,0,0,0,0,0,0,30,0,1
1,8,8,10,0,0,0,0,0,1,1,0,0,1
2,0,0,0,2,3,0,0,3,2,15,0,0,2
3,0,0,0,3,0,0,0,0,3,0,0,0,3
0,0,0,0,0,0,0,0,0,0,0,0,0,0
0,0,0,0,0,0,0,0,0,0,0,0,0,0
3,0,0,0,3,0,0,0,0,3,0,0,0,3
2,0,0,0,2,3,0,0,3,2,26,39,26,2
23,23,0,0,0,0,0,0,0,26,0,0,34,1
23,0,0,0,0,0,0,0,0,39,0,0,34,1
32,0,0,23,0,0,0,0,0,26,34,34,34,1
23,32,23,23,2,3,0,0,3,2,1,1,1,1
endlayer

layer
1,1,1,1,2,3,0,15,3,2,1,0,0,1
1,8,8,8,15,0,0,0,15,15,0,0,40,0
1,8,8,8,0,0,0,0,0,0,0,0,0,1
1,8,8,10,15,0,0,0,0,1,1,0,0,1
2,15,0,0,2,3,15,0,3,2,1,0,0,2
3,0,0,0,3,0,0,0,0,3,0,0,0,3
0,0,0,0,0,0,0,0,0,0,0,0,0,15
0,0,0,0,0,0,0,0,0,0,0,0,31,0
3,0,0,0,3,0,0,0,0,3,15,0,0,3
2,15,0,15,2,3,0,0,3,2,26,26,26,2
23,23,0,0,0,0,0,0,0,26,0,0,34,1
23,23,0,0,0,0,0,0,0,26,0,0,34,1
23,23,23,23,0,0,0,0,0,26,34,34,34,1
1,23,23,23,2,3,0,0,3,2,1,1,1,1
endlayer

layer
1,1,1,1,2,24,24,24,24,2,1,1,0,1
1,8,8,8,25,26,26,26,26,1,0,0,40,0
1,8,8,8,25,26,26,26,26,1,0,0,0,1
1,8,8,10,25,26,26,26,26,1,1,0,1,1
2,24,24,24,2,24,24,24,24,2,1,0,0,2
25,26,26,26,25,26,26,26,26,25,26,26,26,25
25,26,26,26,25,26,3,3,26,25,26,26,26,25
25,26,26,26,25,26,3,3,26,25,26,26,26,25
25,26,26,26,25,26,26,26,26,25,26,26,26,25
2,24,24,24,2,24,24,24,24,2,24,24,24,2
1,23,23,1,25,26,26,26,26,25,26,26,26,1
1,23,23,23,25,26,26,26,26,25,26,26,26,1
1,23,23,23,25,26,26,26,26,25,26,26,26,1
1,1,1,1,2,24,24,24,24,2,1,1,1,1
endlayer


# Two Floors Down
layer
1,1,1,1,2,3,0,4,3,2,41,1,0,1
1,8,8,8,15,0,0,4,0,15,42,0,40,0
1,8,8,8,7,0,0,4,0,0,43,0,0,0
1,8,8,10,0,0,0,4,0,0,0,43,45,44
2,0,0,0,2,3,0,4,3,2,0,0,15,2
3,0,0,0,3,13,12,11,0,3,0,0,0,3
12,12,12,12,12,11,3,3,0,0,0,0,0,15
0,0,0,0,0,0,3,3,13,12,12,12,12,12
3,15,0,0,3,0,13,12,11,3,0,0,0,3
2,1,0,15,2,3,4,0,3,2,15,0,1,2
1,1,1,1,15,0,4,0,7,1,1,1,1,1
1,23,23,1,0,0,4,0,0,15,1,1,1,1
1,1,23,1,1,0,4,0,0,1,1,1,1,1
1,1,1,1,2,3,4,0,3,2,1,1,1,1
endlayer

layer
1,1,1,1,2,3,0,0,3,2,41,0,0,0
1,8,8,8,0,0,0,0,0,0,42,0,40,0
1,8,8,8,0,0,0,0,0,0,43,0,0,0
1,8,8,10,0,0,0,0,0,0,0,43,45,44
2,0,0,0,2,3,0,0,3,2,0,0,0,2
3,0,0,0,3,0,0,0,0,3,0,0,0,3
0,0,0,0,0,0,0,0,0,0,0,0,0,0
0,0,0,0,0,0,0,0,0,0,0,0,0,0
3,0,0,0,3,0,0,0,0,3,0,0,0,3
2,15,0,0,2,3,0,0,3,2,0,0,0,2
1,1,1,1,0,0,0,0,0,0,1,1,1,1
1,1,23,1,0,0,0,0,0,0,1,1,1,1
1,1,1,1,0,0,0,0,0,0,1,1,1,1
1,1,1,1,2,3,0,0,3,2,1,1,1,1
endlayer

layer
1,1,1,1,2,3,0,0,3,2,41,0,0,0
1,8,8,8,0,0,0,0,0,0,42,0,40,0
1,8,8,8,0,0,0,0,0,0,43,0,0,0
1,8,8,10,0,0,0,0,0,0,0,43,45,44
2,0,0,0,2,3,0,0,3,2,0,0,0,2
3,0,0,0,3,0,0,0,0,3,0,0,0,3
0,0,0,0,0,0,0,0,0,0,0,0,0,0
0,0,0,0,0,0,0,0,0,0,0,0,0,0
3,0,0,0,3,0,0,0,0,3,0,0,0,3
2,0,0,1,2,3,0,0,3,2,0,0,0,2
1,1,1,1,15,0,0,0,0,0,1,1,1,1
1,1,1,1,0,0,0,0,0,0,1,1,1,1
1,1,1,1,0,0,0,0,0,0,1,1,1,1
1,1,1,1,2,3,0,0,3,2,1,1,1,1
endlayer

layer
1,1,1,1,2,3,0,0,3,2,0,41,47,46
1,8,8,8,15,0,0,0,0,15,0,42,49,48
1,8,8,8,0,0,0,0,0,0,0,43,45,44
1,8,8,10,0,0,0,0,0,0,0,0,0,0
2,0,0,0,2,3,0,0,3,2,0,0,0,2
3,0,0,0,3,0,0,0,0,3,0,0,0,3
0,0,0,0,0,0,0,0,0,0,0,0,0,0
15,0,0,0,0,0,0,0,0,0,0,0,0,15
3,15,0,15,3,0,0,0,0,3,0,0,0,3
2,15,0,1,2,3,0,0,3,2,15,0,15,2
1,1,1,1,1,0,0,0,0,15,1,0,1,1
1,1,1,1,0,0,0,0,0,0,1,1,1,1
1,1,1,1,1,15,31,0,0,15,1,1,1,1
1,1,1,1,2,3,0,15,3,2,1,1,1,1
endlayer

layer
1,1,1,1,2,24,24,24,24,2,1,1,1,1
1,8,8,8,25,26,26,26,26,25,1,0,1,1
1,8,8,8,25,26,26,26,26,25,1,0,0,1
1,8,8,10,25,26,26,26,26,25,1,1,0,1
2,24,24,24,2,24,24,24,24,2,24,24,24,2
25,26,26,26,25,26,26,26,26,25,26,26,26,25
25,26,26,26,25,26,3,3,26,25,26,26,26,25
25,26,26,26,25,26,3,3,26,25,26,26,26,25
25,26,26,26,25,26,26,26,26,25,26,26,26,25
2,24,24,24,2,24,24,24,24,2,24,24,24,2
1,1,1,1,25,26,26,26,26,25,1,1,0,1
1,1,1,1,25,26,26,26,26,25,1,1,1,1
1,1,1,1,25,26,26,26,26,25,1,1,1,1
1,1,1,1,2,24,24,24,24,2,1,1,1,1
endlayer

layer
1,1,1,1,2,3,0,4,3,2,1,1,1,1
1,8,8,8,15,0,0,4,0,0,1,1,1,1
1,8,50,8,0,0,0,4,0,0,0,15,1,1
1,8,8,10,0,0,0,4,0,0,1,0,0,1
2,15,0,0,2,3,0,4,3,2,0,0,0,2
3,0,0,0,3,13,12,11,0,3,0,0,0,3
12,12,12,12,12,11,3,3,0,0,0,0,0,15
0,0,0,0,0,0,3,3,13,12,12,12,12,12
3,0,0,0,3,0,13,12,11,3,0,0,0,3
2,0,1,0,2,3,4,0,3,2,0,0,15,2
1,1,1,1,0,0,4,0,0,0,0,1,1,1
1,1,1,1,1,0,4,0,0,0,1,1,1,1
1,1,1,1,0,0,4,0,0,0,1,1,1,1
1,1,1,1,2,3,4,0,3,2,1,1,1,1
endlayer

layer
1,1,1,1,2,3,0,0,3,2,1,1,1,1
1,8,8,8,0,0,0,0,0,0,1,0,1,1
1,8,0,8,0,0,0,0,0,0,0,0,1,1
1,8,8,10,0,0,0,0,0,0,1,0,0,1
2,0,0,0,2,3,0,0,3,2,0,0,0,2
3,0,0,0,3,0,0,0,0,3,0,0,0,3
0,0,0,0,0,0,0,0,0,0,0,0,0,0
0,0,0,0,0,0,0,0,0,0,0,0,0,0
3,0,0,0,3,0,0,0,0,3,0,0,0,3
2,0,0,0,2,3,0,0,3,2,0,0,0,2
1,1,1,1,0,0,0,0,0,0,0,1,1,1
1,1,1,0,0,0,0,0,0,0,0,1,1,1
1,1,1,1,0,0,0,0,0,15,1,1,1,1
1,1,1,1,2,3,0,0,3,2,1,1,1,1
endlayer

layer
1,1,1,1,2,3,0,0,3,2,1,1,1,1
1,8,8,8,15,0,0,0,0,15,1,1,1,1
1,8,0,8,0,0,0,0,0,0,0,1,1,1
1,8,8,10,0,0,0,0,0,15,0,0,1,1
2,0,0,15,2,3,0,0,3,2,0,0,15,2
3,0,0,0,3,0,0,0,0,3,0,0,0,3
0,0,0,0,0,0,0,0,0,0,0,0,0,0
0,0,0,0,0,0,0,0,0,0,0,0,0,0
3,0,0,0,3,0,0,0,0,3,0,0,0,3
2,0,0,0,2,3,0,0,3,2,0,0,15,2
1,1,1,1,15,0,0,0,0,0,0,1,1,1
1,1,1,1,0,0,0,0,0,0,0,1,1,1
1,1,1,1,0,0,0,0,0,0,0,1,1,1
1,1,1,1,2,3,0,0,3,2,1,1,1,1
endlayer

layer
1,1,1,1,2,3,0,0,3,2,1,1,1,1
1,8,8,8,15,0,0,31,0,15,1,1,1,1
1,8,0,8,0,0,0,0,0,0,1,1,1,1
1,8,8,10,0,15,0,0,0,15,15,1,1,1
2,15,0,15,2,3,0,0,3,2,0,15,1,2
3,0,0,0,3,0,0,0,0,3,0,0,15,3
0,0,0,0,0,0,0,0,0,0,0,0,0,15
0,0,0,0,0,0,0,0,0,0,0,0,0,15
3,0,0,0,3,0,0,0,0,3,0,0,0,3
2,15,0,15,2,3,0,0,3,2,0,0,15,2
1,1,1,1,1,15,0,0,0,15,0,0,15,1
1,1,1,1,1,0,0,0,0,0,0,0,1,1
1,1,1,1,15,15,0,0,0,15,0,0,1,1
1,1,1,1,2,3,0,0,3,2,1,1,1,1
endlayer

layer
1,1,1,1,2,24,24,24,24,2,1,1,1,1
1,8,8,8,25,26,26,26,26,25,1,1,1,1
1,8,8,8,25,26,26,26,26,25,1,1,1,1
1,8,8,10,25,26,26,26,26,25,1,1,1,1
2,24,24,24,2,24,24,24,24,2,24,24,24,2
25,26,26,26,25,26,26,26,26,25,26,26,26,25
25,26,26,26,25,26,3,3,26,25,26,26,26,25
25,26,26,26,25,26,3,3,26,25,26,26,26,25
25,26,26,26,25,26,26,26,26,25,26,26,26,25
2,24,24,24,2,24,24,24,24,2,24,24,24,2
1,1,1,1,25,26,26,26,26,25,1,1,1,1
1,1,1,1,25,26,26,26,26,25,1,1,1,1
1,1,1,1,25,26,26,26,26,25,1,1,1,1
1,1,1,1,2,24,24,24,24,2,1,1,1,1
endlayer

layer
1,1,1,1,3,0,0,4,0,3,1,1,1,1
1,8,8,8,2,3,0,4,3,2,1,1,1,1
1,8,0,51,15,0,0,4,0,26,1,1,1,1
1,8,52,10,0,0,0,4,0,26,1,1,1,1
3,2,0,0,2,3,0,4,3,2,26,26,2,3
0,3,0,0,3,13,12,11,0,3,0,0,3,0
12,12,12,12,12,11,3,3,0,0,0,0,0,0
0,0,0,0,0,0,3,3,13,12,12,12,12,12
0,3,0,0,3,0,13,12,11,3,53,0,3,0
3,2,26,26,2,3,4,0,3,2,26,26,2,3
1,1,1,1,26,0,4,0,0,26,1,1,1,1
1,1,1,1,26,15,4,0,0,26,1,1,1,1
1,1,1,1,2,3,4,0,3,2,1,1,1,1
1,1,1,1,3,0,4,0,0,3,1,1,1,1
endlayer

layer
1,1,1,1,3,0,0,0,0,3,1,1,1,1
1,8,8,8,2,3,0,0,3,2,1,1,1,1
1,8,0,51,0,0,0,0,0,26,1,1,1,1
1,8,52,10,0,0,0,0,0,26,1,1,1,1
3,2,0,0,2,3,0,0,3,2,26,26,2,3
0,3,0,0,3,0,0,0,0,3,0,0,3,0
0,0,0,0,0,0,0,0,0,0,0,0,0,0
0,0,0,0,0,0,0,0,0,0,0,0,0,0
0,3,0,0,3,0,0,0,0,3,53,0,3,0
3,2,26,26,2,3,0,0,3,2,26,26,2,3
1,1,1,1,26,0,0,0,0,26,1,1,1,1
1,1,1,1,26,0,0,0,0,26,1,1,1,1
1,1,1,1,2,3,0,0,3,2,1,1,1,1
1,1,1,1,3,0,0,0,0,3,1,1,1,1
endlayer

layer
1,1,1,1,3,0,0,0,0,3,1,1,1,1
1,8,8,8,2,3,0,0,3,2,1,1,1,1
1,8,54,51,0,0,0,0,0,26,1,1,1,1
1,8,52,0,0,0,0,0,0,26,1,1,1,1
3,2,0,0,2,3,0,0,3,2,26,26,2,3
0,3,0,0,3,0,0,0,0,3,0,0,3,0
0,0,0,0,0,0,0,0,0,0,0,0,0,0
0,0,0,0,0,0,0,0,0,0,0,0,0,0
0,3,0,0,3,0,0,0,0,3,53,0,3,0
3,2,26,26,2,3,0,0,3,2,26,26,2,3
1,1,1,1,26,0,0,0,0,26,1,1,1,1
1,1,1,1,26,0,0,0,0,26,1,1,1,1
1,1,1,1,2,3,0,0,3,2,1,1,1,1
1,1,1,1,3,0,0,0,0,3,1,1,1,1
endlayer

layer
1,1,1,1,3,0,0,0,0,3,1,1,1,1
1,56,55,55,2,3,0,0,3,2,1,1,1,1
1,56,54,51,15,0,0,0,15,26,1,1,1,1
1,56,52,0,0,0,0,0,0,26,1,1,1,1
3,2,0,0,2,3,0,0,3,2,26,26,2,3
0,3,0,0,3,0,0,0,15,3,15,15,3,0
0,0,0,0,0,0,0,0,15,15,0,15,0,0
0,0,0,0,0,0,0,0,0,0,0,0,0,0
0,3,0,15,3,0,0,0,0,3,53,15,3,0
3,2,26,26,2,3,0,0,3,2,26,26,2,3
1,1,1,1,26,15,0,0,15,26,1,1,1,1
1,1,1,1,26,0,0,0,0,26,1,1,1,1
1,1,1,1,2,3,0,0,3,2,1,1,1,1
1,1,1,1,3,0,0,0,0,3,1,1,1,1
endlayer

layer
1,1,1,60,59,0,0,0,0,58,57,1,1,1
1,1,1,60,25,3,0,0,3,25,57,1,1,1
1,1,54,54,25,0,0,0,15,25,57,1,1,1
61,61,54,54,25,15,0,0,15,25,57,61,61,61
62,24,24,24,2,24,24,24,24,2,24,24,24,24
0,3,0,0,25,26,26,26,26,25,26,26,25,0
0,0,0,0,25,26,26,26,26,25,26,26,25,0
0,0,0,0,25,26,26,26,26,25,26,26,25,0
0,3,15,15,25,26,26,26,26,25,53,26,25,0
63,24,24,24,2,24,24,24,24,2,24,24,24,24
64,64,64,60,25,15,0,0,15,25,57,64,64,64
1,1,1,60,25,15,0,0,15,25,57,1,1,1
1,1,1,60,25,3,0,0,3,25,57,1,1,1
1,1,1,60,59,0,0,0,0,58,57,1,1,1
endlayer

layer
1,1,1,1,60,59,0,0,58,57,1,1,1,1
1,1,1,1,60,59,0,0,58,57,1,1,1,1
1,1,54,54,60,59,0,0,58,57,1,1,1,1
1,1,54,54,60,59,0,0,58,57,1,1,1,1
61,61,61,61,2,26,3,3,26,2,3,3,2,61
62,62,62,62,26,0,0,0,0,26,0,0,3,0
0,0,0,0,3,0,0,0,0,0,0,0,3,0
0,0,0,0,3,0,0,0,0,0,0,0,3,0
63,63,63,63,26,0,0,0,53,26,0,0,3,0
64,64,64,64,2,26,3,3,26,2,3,3,2,64
1,1,1,1,60,59,0,0,58,57,1,1,1,1
1,1,1,1,60,59,0,0,58,57,1,1,1,1
1,1,1,1,60,59,0,0,58,57,1,1,1,1
1,1,1,1,60,59,15,0,58,57,1,1,1,1
endlayer

layer
1,1,1,1,1,60,59,58,57,1,1,1,1,1
1,1,1,1,1,60,59,58,57,1,1,1,1,1
1,1,54,54,1,60,59,58,57,1,1,1,1,1
1,1,54,54,1,60,59,58,57,1,1,1,1,1
1,1,1,1,2,26,3,3,26,2,0,0,2,1
61,61,61,61,26,0,0,0,0,26,0,0,0,0
62,62,62,62,3,0,0,0,0,0,0,0,0,0
63,63,63,63,3,0,0,0,0,0,0,0,0,0
64,64,64,64,26,0,0,0,53,26,0,0,0,0
1,1,1,1,2,26,3,3,26,2,0,0,2,1
1,1,1,1,1,60,59,58,57,1,1,1,1,1
1,1,1,1,1,60,59,58,57,1,1,1,1,1
1,1,1,1,1,60,59,58,57,1,1,1,1,1
1,1,1,1,1,60,59,58,57,1,1,1,1,1
endlayer

layer
1,1,1,1,1,1,65,65,0,1,1,1,1,1
1,1,1,1,1,1,64,64,0,1,1,1,1,1
1,1,54,54,1,1,66,66,0,1,1,1,1,1
1,1,54,54,1,1,66,66,0,1,1,1,1,1
1,1,1,1,2,24,24,24,24,2,0,0,2,1
1,1,1,1,25,0,0,0,0,25,0,0,0,0
65,57,66,66,25,0,0,0,0,25,0,0,0,0
65,57,66,66,25,0,0,0,0,25,0,0,0,0
1,1,1,1,25,0,0,0,53,25,0,0,0,0
1,1,1,1,2,24,24,24,24,2,0,0,2,1
1,1,1,1,1,1,66,66,1,1,1,1,1,1
1,1,1,1,1,1,66,66,1,1,1,1,1,1
1,1,1,1,1,1,61,61,1,1,1,1,1,1
1,1,1,1,1,1,65,65,1,1,1,1,1,1
endlayer

layer
1,1,1,1,1,1,64,64,1,1,1,1,1,1
1,1,1,1,1,1,1,1,1,1,1,1,1,1
1,1,54,54,1,1,1,1,1,1,1,1,1,1
1,1,54,54,1,1,1,1,1,1,1,1,1,1
1,1,1,1,2,26,3,3,26,2,0,0,2,1
1,1,1,1,26,0,0,0,0,26,0,0,0,0
57,1,1,1,3,0,0,0,0,3,0,0,0,0
57,1,1,1,3,0,0,0,0,3,0,0,0,0
1,1,1,1,26,0,0,0,53,26,0,0,0,0
1,1,1,1,2,26,3,3,26,2,0,0,2,1
1,1,1,1,1,1,1,1,1,1,1,1,1,1
1,1,1,1,1,1,1,1,1,1,1,1,1,1
1,1,1,1,1,1,1,1,1,1,1,1,1,1
1,1,1,1,1,1,61,61,1,1,1,1,1,1
endlayer

layer
1,1,1,1,1,1,1,1,1,1,1,1,1,1
1,1,1,1,1,1,1,1,1,1,1,1,1,1
1,1,54,54,1,1,1,1,1,1,1,1,1,1
1,1,54,54,25,1,1,1,1,25,65,61,61,61
1,1,1,24,2,24,24,24,24,2,24,24,2,62
1,1,1,1,25,0,0,0,0,25,0,0,0,0
1,1,1,1,25,0,0,0,0,25,0,0,0,0
1,1,1,1,25,0,0,0,0,25,0,0,0,0
1,1,1,1,25,0,0,0,53,25,0,0,0,0
1,1,1,24,2,24,24,24,24,2,24,24,2,63
1,1,1,67,25,1,1,1,1,25,65,64,64,64
1,1,1,1,1,1,1,1,1,1,1,1,1,1
1,1,1,1,1,1,1,1,1,1,1,1,1,1
1,1,1,1,1,1,1,1,1,1,1,1,1,1
endlayer

layer
1,1,1,1,1,1,1,1,1,1,1,1,1,1
1,1,1,1,1,1,1,1,1,1,1,1,1,1
1,1,54,54,1,1,1,1,1,1,1,1,1,1
1,1,54,54,24,24,24,24,24,24,2,1,1,1
1,1,1,25,26,65,26,65,26,65,25,61,61,61
1,1,1,25,65,26,65,26,65,26,25,62,62,62
1,1,1,25,26,65,26,65,26,65,25,0,0,0
1,1,1,25,65,26,65,26,65,26,25,0,0,0
1,1,1,25,26,65,26,65,53,65,25,63,63,63
1,1,1,25,65,26,65,26,65,26,25,64,64,64
1,1,1,2,24,24,24,24,24,24,2,1,1,1
1,1,1,1,1,1,1,1,1,1,1,1,1,1
1,1,1,1,1,1,1,1,1,1,1,1,1,1
1,1,1,1,1,1,1,1,1,1,1,1,1,1
endlayer

layer
1,1,1,1,1,1,1,1,1,1,1,1,1,1
1,1,1,1,1,1,1,1,1,1,1,1,1,1
1,1,54,54,3,1,1,1,1,1,1,1,1,1
1,1,54,54,54,3,3,3,3,26,2,1,1,1
1,1,3,54,52,54,0,0,0,0,26,1,1,1
1,1,1,3,0,0,0,0,0,0,3,61,61,61
1,1,1,3,0,0,0,0,7,0,3,62,62,62
1,1,1,3,0,0,0,0,0,0,3,63,63,63
1,1,1,3,0,0,0,0,0,0,3,64,64,64
1,1,1,26,0,0,0,0,0,0,26,1,1,1
1,1,1,2,26,3,3,3,3,26,2,1,1,1
1,1,1,1,1,1,1,1,1,1,1,1,1,1
1,1,1,1,1,1,1,1,1,1,1,1,1,1
1,1,1,1,1,1,1,1,1,1,1,1,1,1
endlayer

layer
1,1,1,1,1,1,1,1,1,1,1,1,1,1
1,1,1,1,1,1,1,1,1,1,1,1,1,1
1,1,54,54,3,1,1,1,1,1,1,1,1,1
1,1,54,54,54,3,3,3,3,26,2,1,1,1
1,1,3,54,52,54,0,0,0,0,26,1,1,1
1,1,1,3,0,0,0,0,0,0,3,1,1,1
1,1,1,3,0,0,0,0,0,0,3,66,60,65
1,1,1,3,0,0,0,0,0,0,3,66,60,65
1,1,1,3,0,0,0,0,0,0,3,1,1,1
1,1,1,26,0,0,0,0,0,0,26,1,1,1
1,1,1,2,26,3,3,3,3,26,2,1,1,1
1,1,1,1,1,1,1,1,1,1,1,1,1,1
1,1,1,1,1,1,1,1,1,1,1,1,1,1
1,1,1,1,1,1,1,1,1,1,1,1,1,1
endlayer

layer
1,1,1,1,1,1,1,1,1,1,1,1,1,1
1,1,1,1,1,1,1,1,1,1,1,1,1,1
1,1,54,54,3,1,1,1,1,1,1,1,1,1
1,1,54,54,54,3,3,3,3,26,2,1,1,1
1,1,3,54,69,68,0,0,0,0,26,1,1,1
1,1,1,3,0,0,0,0,0,0,3,1,1,1
1,1,1,3,0,0,0,0,0,0,3,1,1,60
1,1,1,3,0,0,0,0,0,0,3,1,1,60
1,1,1,3,0,0,0,0,0,0,3,1,1,1
1,1,1,26,0,0,0,0,0,0,26,1,1,1
1,1,1,2,26,3,3,3,3,26,2,1,1,1
1,1,1,1,1,1,1,1,1,1,1,1,1,1
1,1,1,1,1,1,1,1,1,1,1,1,1,1
1,1,1,1,1,1,1,1,1,1,1,1,1,1
endlayer

layer
1,1,1,1,1,1,0,0,0,1,1,1,1,1
1,1,1,1,1,0,0,0,0,0,1,1,1,1
1,1,54,54,3,0,0,0,0,0,1,1,1,1
1,1,54,54,54,3,3,3,3,26,2,0,0,1
1,0,3,54,0,0,0,0,0,0,26,0,0,1
0,0,0,3,0,0,0,0,0,0,3,0,0,0
0,0,0,3,0,0,0,0,0,0,3,0,0,0
0,0,0,3,0,0,0,0,0,0,3,0,0,0
0,0,0,3,0,0,0,0,0,0,3,0,0,0
1,0,0,26,0,0,0,0,0,0,26,0,0,1
1,0,0,2,26,3,3,3,3,26,2,0,0,1
1,1,1,0,0,0,0,0,0,0,0,1,1,1
1,1,1,0,0,0,0,0,0,0,0,1,1,1
1,1,1,1,1,0,0,0,0,1,1,1,1,1
endlayer

layer
1,1,1,0,0,0,0,0,0,0,0,1,1,1
1,1,60,59,0,0,0,0,0,0,58,57,1,1
1,61,54,54,0,0,0,0,0,0,25,61,61,1
0,62,54,54,24,24,24,24,24,24,2,24,62,0
0,0,0,25,0,0,0,0,0,0,25,0,0,0
0,0,0,25,0,0,0,0,0,0,25,0,0,0
0,0,0,25,0,0,0,0,0,0,25,0,0,0
0,0,0,25,0,0,0,0,0,0,25,0,0,0
0,0,0,25,0,0,0,0,0,0,25,0,0,0
0,0,0,25,0,0,0,0,0,0,25,0,0,0
0,63,24,2,24,24,24,24,24,24,2,24,63,0
1,64,60,25,0,0,0,0,0,0,25,57,64,1
1,1,60,59,0,0,0,0,0,0,58,57,1,1
1,1,1,0,0,0,0,0,0,0,0,1,1,1
endlayer

layer
1,1,0,0,0,0,0,0,0,0,0,0,0,1
1,0,0,60,59,0,0,0,0,58,57,0,0,0
0,0,54,60,59,0,0,0,0,58,57,0,0,0
0,61,61,60,26,3,3,3,3,26,61,61,61,0
0,62,62,26,0,0,0,0,0,0,26,62,62,0
0,0,0,3,0,0,0,0,0,0,3,0,0,0
0,0,0,3,0,0,0,0,0,0,3,0,0,0
0,0,0,3,0,0,0,0,0,0,3,0,0,0
0,0,0,3,0,0,0,0,0,0,3,0,0,0
0,63,63,26,0,0,0,0,0,0,26,63,63,0
0,64,64,64,26,3,3,3,3,26,57,64,64,0
0,0,0,60,59,0,0,0,0,58,57,0,0,0
1,0,0,60,59,0,0,0,0,58,57,0,0,1
1,1,0,0,0,0,0,0,0,0,0,0,1,1
endlayer

layer
1,0,0,0,0,0,0,0,0,0,0,0,0,0
0,0,0,0,60,59,0,0,58,57,0,0,0,0
0,0,54,0,60,59,0,0,58,57,0,0,0,0
0,0,0,0,60,59,3,3,58,57,0,0,0,0
0,61,61,61,61,59,0,0,58,61,61,61,61,0
0,62,62,62,62,62,0,0,58,62,62,62,62,0
0,0,0,3,0,0,0,0,0,0,3,0,0,0
0,0,0,3,0,0,0,0,0,0,3,0,0,0
0,63,63,63,63,59,0,0,63,63,63,63,63,0
0,64,64,64,64,59,0,0,58,64,64,64,64,0
0,0,0,0,60,59,3,3,58,57,0,0,0,0
0,0,0,0,60,59,0,0,58,57,0,0,0,0
0,0,0,0,60,59,0,0,58,57,0,0,0,0
1,0,0,0,0,0,0,0,0,0,0,0,0,1
endlayer

layer
0,0,0,0,0,0,0,0,0,0,0,0,0,0
0,0,0,0,0,60,59,58,57,0,0,0,0,0
0,0,54,0,0,60,59,58,57,0,0,0,0,0
0,0,0,0,0,60,59,58,57,0,0,0,0,0
0,0,0,0,0,60,59,58,57,0,0,0,0,0
0,61,61,61,61,65,62,62,65,61,61,61,61,0
0,62,62,62,62,59,0,0,58,62,62,62,62,0
0,63,63,63,63,59,0,0,58,63,63,63,63,0
0,64,64,64,64,65,63,63,65,64,64,64,64,0
0,0,0,0,0,60,59,58,57,0,0,0,0,0
0,0,0,0,0,60,59,58,57,0,0,0,0,0
0,0,0,0,0,60,59,58,57,0,0,0,0,0
0,0,0,0,0,60,59,58,57,0,0,0,0,0
0,0,0,0,0,0,0,0,0,0,0,0,0,0
endlayer

layer
0,0,0,0,0,0,0,0,0,0,0,0,0,0
0,0,0,0,0,0,65,65,0,0,0,0,0,0
0,0,54,0,0,0,64,64,0,0,0,0,0,0
0,0,0,0,0,0,66,66,0,0,0,0,0,0
0,0,0,0,0,0,66,66,0,0,0,0,0,0
0,0,0,0,0,2,26,26,2,0,0,0,0,0
0,65,57,66,66,26,0,0,26,66,66,60,65,0
0,65,57,66,66,26,0,0,26,66,66,60,65,0
0,0,0,0,0,2,26,26,2,0,0,0,0,0
0,0,0,0,0,0,66,66,0,0,0,0,0,0
0,0,0,0,0,0,66,66,0,0,0,0,0,0
0,0,0,0,0,0,61,61,0,0,0,0,0,0
0,0,0,0,0,0,65,65,0,0,0,0,0,0
0,0,0,0,0,0,0,0,0,0,0,0,0,0
endlayer

layer
0,0,0,0,0,0,0,0,0,0,0,0,0,0
0,0,0,0,0,0,64,64,0,0,0,0,0,0
0,0,54,0,0,0,0,0,0,0,0,0,0,0
0,0,0,0,0,0,0,0,0,0,0,0,0,0
0,0,0,0,0,0,0,0,0,0,0,0,0,0
0,0,0,0,0,2,3,3,2,0,0,0,0,0
0,57,0,0,0,3,0,0,3,0,0,0,60,0
0,57,0,0,0,3,0,0,3,0,0,0,60,0
0,0,0,0,0,2,3,3,2,0,0,0,0,0
0,0,0,0,0,0,0,0,0,0,0,0,0,0
0,0,0,0,0,0,0,0,0,0,0,0,0,0
0,0,0,0,0,0,0,0,0,0,0,0,0,0
0,0,0,0,0,0,61,61,0,0,0,0,0,0
0,0,0,0,0,0,0,0,0,0,0,0,0,0
endlayer

layer
0,0,0,0,0,0,0,0,0,0,0,0,0,0
0,0,0,0,0,0,0,0,0,0,0,0,0,0
0,0,54,0,0,0,0,0,0,0,0,0,0,0
0,0,0,0,0,0,0,0,0,0,0,0,0,0
0,0,0,0,0,0,0,0,0,0,0,0,0,0
0,0,0,0,0,2,3,3,2,0,0,0,0,0
0,0,0,0,0,3,0,0,3,0,0,0,0,0
0,0,0,0,0,3,0,0,3,0,0,0,0,0
0,0,0,0,0,2,3,3,2,0,0,0,0,0
0,0,0,0,0,0,0,0,0,0,0,0,0,0
0,0,0,0,0,0,0,0,0,0,0,0,0,0
0,0,0,0,0,0,0,0,0,0,0,0,0,0
0,0,0,0,0,0,0,0,0,0,0,0,0,0
0,0,0,0,0,0,0,0,0,0,0,0,0,0
endlayer

layer
0,0,0,0,0,0,0,0,0,0,0,0,0,0
0,0,0,0,0,0,0,0,0,0,0,0,0,0
0,0,54,0,0,0,0,0,0,0,0,0,0,0
0,0,0,0,60,59,0,0,58,57,0,0,0,0
0,0,0,61,60,25,0,0,25,61,61,0,0,0
0,0,0,62,24,2,26,26,2,24,62,0,0,0
0,0,0,0,0,26,0,0,26,0,0,0,0,0
0,0,0,0,0,26,0,0,26,0,0,0,0,0
0,0,0,63,24,2,26,26,2,24,63,0,0,0
0,0,0,64,64,25,0,0,25,57,64,0,0,0
0,0,0,0,60,59,0,0,58,57,0,0,0,0
0,0,0,0,0,0,0,0,0,0,0,0,0,0
0,0,0,0,0,0,0,0,0,0,0,0,0,0
0,0,0,0,0,0,0,0,0,0,0,0,0,0
endlayer

layer
0,0,0,0,0,0,0,0,0,0,0,0,0,0
0,0,0,0,0,0,0,0,0,0,0,0,0,0
0,0,54,0,0,0,0,0,0,0,0,0,0,0
0,0,0,0,0,60,59,58,57,0,0,0,0,0
0,0,0,0,0,60,59,58,57,0,0,0,0,0
0,0,0,61,61,60,3,3,61,61,61,0,0,0
0,0,0,62,62,3,0,0,3,62,62,0,0,0
0,0,0,63,63,3,0,0,3,63,63,0,0,0
0,0,0,64,64,64,3,3,57,64,64,0,0,0
0,0,0,0,0,60,59,58,57,0,0,0,0,0
0,0,0,0,0,60,59,58,57,0,0,0,0,0
0,0,0,0,0,0,0,0,0,0,0,0,0,0
0,0,0,0,0,0,0,0,0,0,0,0,0,0
0,0,0,0,0,0,0,0,0,0,0,0,0,0
endlayer

layer
0,0,0,0,0,0,0,0,0,0,0,0,0,0
0,0,0,0,0,0,0,0,0,0,0,0,0,0
0,0,54,0,0,0,0,0,0,0,0,0,0,0
0,0,0,0,0,0,64,64,0,0,0,0,0,0
0,0,0,0,0,0,66,66,0,0,0,0,0,0
0,0,0,0,0,0,61,61,0,0,0,0,0,0
0,0,0,57,66,60,62,58,57,66,60,0,0,0
0,0,0,57,66,60,59,63,57,66,60,0,0,0
0,0,0,0,0,0,64,64,0,0,0,0,0,0
0,0,0,0,0,0,66,66,0,0,0,0,0,0
0,0,0,0,0,0,61,61,0,0,0,0,0,0
0,0,0,0,0,0,0,0,0,0,0,0,0,0
0,0,0,0,0,0,0,0,0,0,0,0,0,0
0,0,0,0,0,0,0,0,0,0,0,0,0,0
endlayer

layer
0,0,0,0,0,0,0,0,0,0,0,0,0,0
0,0,0,0,0,0,0,0,0,0,0,0,0,0
0,0,54,0,0,0,0,0,0,0,0,0,0,0
0,0,0,0,0,0,0,0,0,0,0,0,0,0
0,0,0,0,0,0,0,0,0,0,0,0,0,0
0,0,0,0,0,0,0,0,0,0,0,0,0,0
0,0,0,0,0,0,60,61,0,0,0,0,0,0
0,0,0,0,0,0,64,57,0,0,0,0,0,0
0,0,0,0,0,0,0,0,0,0,0,0,0,0
0,0,0,0,0,0,0,0,0,0,0,0,0,0
0,0,0,0,0,0,0,0,0,0,0,0,0,0
0,0,0,0,0,0,0,0,0,0,0,0,0,0
0,0,0,0,0,0,0,0,0,0,0,0,0,0
0,0,0,0,0,0,0,0,0,0,0,0,0,0
endlayer


