# ObsidianGeode
# Created: 9 Oct 2014
# Updated to MC 1.8: 21 Jul 2015
# Created by Ruins mod version 13.8 Ingame Parser
# authoring Player: Jordan_Greywolf
# Last Updated 18 Feb 2016
# Verified for MC 1.12: 23 Jun 2017
# Updated to MC 1.12.1: 9 Sep 2017

biomesToSpawnIn=birch forest hills,cold taiga hills,dark forest,deserthills,extreme hills,extreme hills edge,extreme hills+,extreme hills m,extreme hills+ m,forest,foresthills,junglehills,mega spruce taiga,mega taiga,mesa,mesa plateau,oak savanna,plains,savanna plateau,savanna m,savanna plateau m,taigahills,mining_biome,extreme_hills,extreme_hills_with_trees,mutated_extreme_hills,mutated_extreme_hills_with_trees,smaller_extreme_hills,stone_beach,birch_forest_hills,taiga_cold,taiga_cold_hills,savanna_rock,mutated_savanna_rock,savanna,mutated_savanna,mutated_redwood_taiga,mutated_redwood_taiga_hills,mutated_roofed_forest,redwood_taiga,redwood_taiga_hills,roofed_forest

weight=1
embed_into_distance=25
acceptable_target_blocks=

unacceptable_target_blocks=flowing_lava,lava,Natura:Cloud,slime_congealed,slime_dirt,slime_grass,command_block

dimensions=9,9,9
allowable_overhang=400
max_leveling=20
leveling_buffer=-1
preserve_water=0
preserve_lava=0
preserve_plants=1

rule1=0,100,preserveBlock

# Shell
rule2=0,100,minecraft:obsidian-0

# "Crystal"
rule3=0,100,minecraft:stained_glass-0

rule4=0,100,minecraft:glowstone-0

layer
1,1,1,1,1,1,1,1,1
1,1,1,1,1,1,1,1,1
1,1,1,1,1,1,1,1,1
1,1,1,2,2,2,1,1,1
1,1,1,2,2,2,1,1,1
1,1,1,2,2,2,1,1,1
1,1,1,1,1,1,1,1,1
1,1,1,1,1,1,1,1,1
1,1,1,1,1,1,1,1,1
endlayer

layer
1,1,1,1,1,1,1,1,1
1,1,1,1,2,1,1,1,1
1,1,1,2,2,2,1,1,1
1,1,2,2,3,2,2,1,1
1,2,2,3,3,3,2,2,1
1,1,2,2,3,2,2,1,1
1,1,1,2,2,2,1,1,1
1,1,1,1,2,1,1,1,1
1,1,1,1,1,1,1,1,1
endlayer

layer
1,1,1,1,1,1,1,1,1
1,1,1,2,2,2,1,1,1
1,1,2,3,3,3,2,1,1
1,2,3,3,0,3,3,2,1
1,2,3,0,3,0,3,2,1
1,2,3,3,0,3,3,2,1
1,1,2,3,3,3,2,1,1
1,1,1,2,2,2,1,1,1
1,1,1,1,1,1,1,1,1
endlayer

layer
1,1,1,2,2,2,1,1,1
1,1,2,2,3,2,2,1,1
1,2,3,3,0,3,3,2,1
2,2,3,0,0,0,3,2,2
2,3,0,0,3,0,0,3,2
2,2,3,0,0,0,3,2,2
1,2,3,3,0,3,3,2,1
1,1,2,2,3,2,2,1,1
1,1,1,2,2,2,1,1,1
endlayer

layer
1,1,1,2,2,2,1,1,1
1,2,2,3,3,3,2,2,1
1,2,3,0,3,0,3,2,1
2,3,0,0,3,0,0,3,2
2,3,3,3,4,3,3,3,2
2,3,0,0,3,0,0,3,2
1,2,3,0,3,0,3,2,1
1,2,2,3,3,3,2,2,1
1,1,1,2,2,2,1,1,1
endlayer

layer
1,1,1,2,2,2,1,1,1
1,1,2,2,3,2,2,1,1
1,2,3,3,0,3,3,2,1
2,2,3,0,0,0,3,2,2
2,3,0,0,3,0,0,3,2
2,2,3,0,0,0,3,2,2
1,2,3,3,0,3,3,2,1
1,1,2,2,3,2,2,1,1
1,1,1,2,2,2,1,1,1
endlayer

layer
1,1,1,1,1,1,1,1,1
1,1,1,2,2,2,1,1,1
1,1,2,3,3,3,2,1,1
1,2,3,3,0,3,3,2,1
1,2,3,0,3,0,3,2,1
1,2,3,3,0,3,3,2,1
1,1,2,3,3,3,2,1,1
1,1,1,2,2,2,1,1,1
1,1,1,1,1,1,1,1,1
endlayer

layer
1,1,1,1,1,1,1,1,1
1,1,1,1,2,1,1,1,1
1,1,1,2,2,2,1,1,1
1,1,2,2,3,2,2,1,1
1,2,2,3,3,3,2,2,1
1,1,2,2,3,2,2,1,1
1,1,1,2,2,2,1,1,1
1,1,1,1,2,1,1,1,1
1,1,1,1,1,1,1,1,1
endlayer

layer
1,1,1,1,1,1,1,1,1
1,1,1,1,1,1,1,1,1
1,1,1,1,1,1,1,1,1
1,1,1,2,2,2,1,1,1
1,1,1,2,2,2,1,1,1
1,1,1,2,2,2,1,1,1
1,1,1,1,1,1,1,1,1
1,1,1,1,1,1,1,1,1
1,1,1,1,1,1,1,1,1
endlayer

