# Ruined Guard House
# Created by Ruins mod version 15.6 Ingame Parser
# authoring Player: Jordan_Greywolf
# Created for MC 1.8: 29 May 2016
# Updated for MC 1.9: 29 May 2016
# Verified for MC 1.12: 23 Jun 2017
# Updated to MC 1.12.1: 9 Sep 2017

biomesToSpawnIn=alps,birch forest hills,birch forest hills m,birch forest m,boreal forest,brushland,chaparral,cold desert,cold taiga hills,coniferous forest,crag,dead forest,eerie,eldritch,eucalyptus forest,extreme hills,extreme hills edge,flower forest,grassland,grove,heathland,highland,ice mountains,junglehills,magical forest,mangrove,maple woods,mega taiga hills,mountain,mountain foothills,mystic grove,ominous woods,orchard,overgrown cliffs,redwood taiga hills m,sacred springs,seasonal forest,shield,shrubland,steppe,taigahills,wasteland,woodland,xeric shrubland,birch_forest_hills,extreme_hills,extreme_hills_with_trees,mutated_birch_forest,mutated_birch_forest_hills,mutated_extreme_hills,mutated_extreme_hills_with_trees,mutated_forest,jungle_hills,redwood_taiga,redwood_taiga_hills

weight=1
embed_into_distance=5
acceptable_target_blocks=

unacceptable_target_blocks=cloud,Natura:Cloud,slime_congealed,slime_dirt,slime_grass,command_block

dimensions=18,14,13
allowable_overhang=0
max_leveling=5
leveling_buffer=-1
preserve_water=0
preserve_lava=0
preserve_plants=1

rule1=1,100,minecraft:stonebrick-1,minecraft:stonebrick-1,minecraft:stonebrick-1,minecraft:stonebrick-2
rule2=0,100,minecraft:water-0
rule3=1,100,minecraft:mossy_cobblestone-0
rule4=0,100,minecraft:stonebrick-0,minecraft:stonebrick-0,minecraft:stonebrick-1,minecraft:stonebrick-2
rule5=0,100,preserveBlock
rule6=0,95,minecraft:dark_oak_stairs-1
rule7=0,95,minecraft:dark_oak_stairs-7
rule8=0,100,minecraft:planks-5

rule9=0,100,MobSpawner:Spider,MobSpawner:Skeleton,MobSpawner:Zombie,MobSpawner:Slime

rule10=0,100,IInventory;minecraft:chest;minecraft:log2#16#1#0+minecraft:planks#1#5#2+minecraft:mossy_cobblestone#13#0#4+minecraft:ladder#1#0#6+minecraft:dirt#1#0#8+minecraft:planks#3#0#12+minecraft:stonebrick#12#1#15+minecraft:dark_oak_fence#1#0#18+minecraft:stonebrick#12#2#20+minecraft:log#1#0#23+minecraft:dark_oak_stairs#1#0#25-4

rule11=0,100,ChestGenHook:chests/simple_dungeon:5-4
rule12=0,95,minecraft:dark_oak_stairs-2
rule13=0,100,minecraft:planks-0
rule14=0,95,minecraft:dark_oak_fence-0
rule15=0,95,minecraft:cobblestone_wall-1
rule16=0,100,minecraft:gravel-0,preserveBlock
rule17=1,95,minecraft:stonebrick-2,minecraft:stonebrick-0,minecraft:stonebrick-1
rule18=0,95,minecraft:dark_oak_stairs-0
rule19=0,95,minecraft:stonebrick-3
rule20=0,100,minecraft:log-4
rule21=0,100,minecraft:log-8
rule22=0,100,minecraft:log-0
rule23=0,95,minecraft:log2-9
rule24=0,95,minecraft:log2-5
rule25=1,95,minecraft:log2-1
rule26=0,100,minecraft:wooden_slab-0,minecraft:wooden_slab-5,preserveBlock
rule27=0,100,minecraft:wooden_slab-5,preserveBlock,minecraft:gravel-0

layer
1,1,1,1,1,1,1,1,1,1,1,1,1
1,3,3,3,3,3,3,3,3,3,2,2,1
1,3,4,4,4,4,4,4,3,3,3,2,1
1,3,4,3,3,3,3,4,3,3,3,3,1
1,3,4,3,3,3,3,4,3,3,3,3,1
1,3,4,3,3,3,3,4,3,3,3,3,1
1,3,4,3,3,3,3,3,3,3,3,3,4
1,3,4,3,3,3,3,3,3,3,3,3,4
1,3,4,3,3,3,3,4,3,3,3,3,1
1,3,4,3,3,3,3,4,3,3,3,3,1
1,3,4,3,3,3,3,4,3,3,3,3,1
1,3,4,4,4,4,4,4,3,3,3,2,1
1,3,3,3,3,3,3,3,3,3,2,2,1
1,1,1,1,1,1,1,1,1,1,1,1,1
endlayer

layer
1,1,1,1,1,1,1,1,1,1,1,1,1
1,5,5,5,5,5,5,5,5,5,5,2,1
1,5,4,4,4,4,4,4,5,5,5,5,1
1,5,4,0,0,7,6,4,5,5,5,5,1
1,5,4,0,0,0,0,4,5,5,5,5,1
1,5,4,0,0,0,0,4,5,5,5,5,1
1,5,4,0,0,0,0,8,5,5,5,5,8
1,5,4,0,0,0,0,8,5,5,5,5,8
1,5,4,0,0,0,0,4,5,5,5,5,1
1,5,4,0,0,0,0,4,5,5,5,5,1
1,5,4,9,11,10,9,4,5,5,5,5,1
1,5,4,4,4,4,4,4,5,5,5,5,1
1,5,5,5,5,5,5,5,5,5,5,2,1
1,1,1,1,1,1,1,1,1,1,1,1,1
endlayer

layer
1,1,1,1,1,1,1,1,1,1,1,1,1
1,5,5,5,5,5,5,5,5,5,5,5,1
1,5,4,4,4,4,4,4,5,5,5,5,1
1,5,4,0,7,12,0,4,5,5,5,5,1
1,5,4,0,0,0,0,4,5,5,5,5,1
1,5,4,0,0,0,0,4,5,5,5,5,1
1,5,4,0,0,0,0,8,5,5,5,5,8
1,5,4,0,0,0,0,8,5,5,5,5,8
1,5,4,0,0,0,0,4,5,5,5,5,1
1,5,4,0,0,0,0,4,5,5,5,5,1
1,5,4,0,0,0,0,4,5,5,5,5,1
1,5,4,4,4,4,4,4,5,5,5,5,1
1,5,5,5,5,5,5,5,5,5,5,5,1
1,1,1,1,1,1,1,1,1,1,1,1,1
endlayer

layer
1,1,1,1,1,1,1,1,1,1,1,1,1
1,5,5,5,5,5,5,5,5,5,5,5,1
1,5,4,4,4,4,4,4,5,5,5,5,1
1,5,4,7,12,0,0,4,5,5,5,5,1
1,5,4,0,0,0,0,4,5,5,5,5,1
1,5,4,0,0,0,0,4,5,5,5,5,1
1,5,4,0,0,0,0,4,5,5,5,5,1
1,5,4,0,0,0,0,4,5,5,5,5,1
1,5,4,0,0,0,0,4,5,5,5,5,1
1,5,4,0,0,0,0,4,5,5,5,5,1
1,5,4,0,0,0,0,4,5,5,5,5,1
1,5,4,4,4,4,4,4,5,5,5,5,1
1,5,5,5,5,5,5,5,5,5,5,5,1
1,1,1,1,1,1,1,1,1,1,1,1,1
endlayer

layer
1,1,1,1,1,1,1,1,1,1,1,1,1
1,5,5,5,5,5,5,5,5,5,5,5,1
1,5,4,4,4,4,4,4,5,5,5,5,1
1,5,4,12,0,0,0,4,5,5,5,5,1
1,5,4,13,8,13,8,4,5,5,5,5,1
1,5,4,8,13,8,13,4,5,5,5,5,1
1,5,4,13,8,13,8,4,5,5,5,5,1
1,5,4,8,13,8,13,4,5,5,5,5,1
1,5,4,13,8,13,8,4,5,5,5,5,1
1,5,4,8,13,8,13,4,5,5,5,5,1
1,5,4,13,8,13,8,4,5,5,5,5,1
1,5,4,4,4,4,4,4,5,5,5,5,1
1,5,5,5,5,5,5,5,5,5,5,5,1
1,1,1,1,1,1,1,1,1,1,1,1,1
endlayer

layer
1,1,1,1,1,1,1,1,1,1,1,1,1
1,5,5,5,5,5,5,5,5,5,5,5,1
1,5,4,4,4,4,4,4,5,5,5,5,1
1,5,4,0,0,0,0,4,5,5,5,5,1
1,5,4,0,14,14,14,4,5,5,5,5,1
1,5,4,16,0,0,0,4,15,5,5,5,1
1,5,4,0,0,0,0,5,5,5,5,5,5
1,5,17,16,0,0,0,0,5,5,5,5,5
1,5,4,16,0,0,0,4,15,0,5,5,1
1,5,4,0,0,0,16,4,5,5,5,5,1
1,5,4,11,9,7,18,4,5,5,5,5,1
1,5,4,4,4,4,4,4,5,5,5,5,1
1,5,5,5,5,5,5,5,5,5,5,5,1
1,1,1,1,1,1,1,1,1,1,1,1,1
endlayer

layer
1,17,1,17,17,1,1,17,1,1,1,17,1
1,5,5,5,5,5,5,5,5,5,5,5,17
17,5,4,4,4,17,4,4,5,5,5,5,1
17,5,4,0,0,0,0,4,5,5,5,5,17
17,5,4,0,0,0,0,14,5,5,5,5,17
1,5,4,0,0,0,0,4,5,5,5,5,1
1,5,4,0,0,0,0,0,5,5,5,5,5
17,5,4,16,0,0,0,0,5,5,5,5,5
17,5,4,0,0,0,0,4,5,5,5,5,1
17,5,4,0,0,0,0,14,5,5,5,5,1
1,5,4,0,7,12,0,4,5,5,5,5,1
17,5,4,4,17,4,4,4,5,5,5,5,17
17,5,5,5,5,5,5,5,5,5,5,5,17
1,1,17,17,1,1,17,17,1,1,17,17,1
endlayer

layer
17,17,17,17,17,17,17,17,17,17,17,17,17
17,5,5,5,5,5,5,5,5,5,5,5,17
17,5,4,4,17,4,4,4,5,5,5,5,17
17,5,4,0,0,0,0,4,5,5,5,5,17
17,5,4,0,0,0,0,14,5,5,5,5,17
17,5,17,0,0,0,0,4,5,5,5,5,17
17,5,4,0,0,0,0,19,5,5,5,5,5
17,5,4,0,0,0,0,19,5,5,5,5,5
17,5,4,0,0,0,0,4,5,5,5,5,17
17,5,17,0,0,0,0,14,5,5,5,5,17
17,5,4,7,12,0,0,4,5,5,5,5,17
17,5,4,4,4,4,4,4,5,5,5,5,17
17,5,5,5,5,5,5,5,5,5,5,5,17
17,17,17,17,17,17,17,17,17,17,17,17,17
endlayer

layer
17,0,0,0,0,0,0,0,0,0,0,0,17
0,5,5,5,5,5,5,5,5,5,5,5,0
0,5,4,4,4,4,17,4,5,5,5,5,0
0,5,4,0,0,0,0,4,5,5,5,5,0
0,5,4,0,0,0,0,4,5,5,5,5,0
0,5,4,0,0,0,0,17,5,5,5,5,17
0,5,4,0,0,0,0,4,5,5,5,5,5
0,5,4,0,0,0,0,4,5,5,5,5,5
0,5,4,0,0,0,0,4,5,5,5,5,17
0,5,4,0,0,0,0,4,5,5,5,5,0
0,5,4,12,0,0,0,4,5,5,5,5,0
0,5,4,4,4,4,17,4,5,5,5,5,0
0,5,5,5,5,5,5,5,5,5,5,5,0
17,0,0,0,0,0,0,0,0,0,0,0,17
endlayer

layer
0,0,0,0,0,0,0,0,0,0,0,0,0
0,5,20,5,5,5,5,20,5,5,0,0,0
0,21,4,4,4,4,4,4,21,5,5,0,0
0,5,4,0,0,0,0,4,5,5,5,5,0
0,5,17,0,0,0,0,4,5,5,5,5,0
0,21,4,0,0,0,0,4,21,5,5,5,0
0,5,4,0,0,0,0,4,5,5,5,5,0
0,5,17,0,0,0,0,17,5,5,5,5,0
0,21,4,0,0,0,0,4,21,5,5,5,0
0,5,4,6,0,0,0,4,5,5,5,5,0
0,5,4,0,0,0,0,4,5,5,5,5,0
0,21,4,4,4,4,4,4,21,5,5,0,0
0,5,20,5,5,5,5,20,5,5,0,0,0
0,0,0,0,0,0,0,0,0,0,0,0,0
endlayer

layer
0,0,0,0,0,0,0,0,0,0,0,0,0
0,22,21,21,21,21,23,21,22,0,0,0,0
0,20,13,8,13,8,13,8,24,5,0,0,0
0,24,8,13,8,13,8,13,20,5,5,0,0
0,20,13,8,13,8,13,8,20,5,5,0,0
0,20,8,13,8,13,8,13,20,5,5,5,0
0,20,13,8,13,8,13,8,24,5,5,5,0
0,20,8,13,8,13,8,13,20,5,5,5,0
0,20,13,6,13,8,13,8,20,5,5,5,0
0,20,8,0,8,13,8,13,20,5,5,0,0
0,20,13,0,0,8,13,8,24,5,5,0,0
0,24,8,13,8,13,8,13,24,5,0,0,0
0,22,21,21,21,23,21,21,22,0,0,0,0
0,0,0,0,0,0,0,0,0,0,0,0,0
endlayer

layer
0,0,0,0,0,0,0,0,0,0,0,0,0
0,22,5,25,5,5,25,5,22,0,0,0,0
0,5,16,27,5,27,26,16,5,0,0,0,0
0,5,16,5,5,5,0,16,5,5,0,0,0
0,5,5,0,5,0,27,0,5,5,0,0,0
0,25,27,0,0,0,0,0,25,5,5,0,0
0,5,26,0,5,0,0,5,5,5,5,0,0
0,5,5,0,0,0,5,5,5,5,5,0,0
0,25,0,0,0,0,5,5,25,5,5,0,0
0,5,5,0,0,0,0,5,5,5,0,0,0
0,5,16,0,0,0,26,5,5,5,0,0,0
0,5,16,26,5,5,0,16,5,0,0,0,0
0,22,5,25,5,5,25,5,22,0,0,0,0
0,0,0,0,0,0,0,0,0,0,0,0,0
endlayer

layer
0,0,0,0,0,0,0,0,0,0,0,0,0
0,22,5,25,5,5,25,5,22,0,0,0,0
0,5,5,0,5,0,0,5,5,0,0,0,0
0,5,5,0,0,0,0,0,5,0,0,0,0
0,5,5,0,0,0,0,0,5,0,0,0,0
0,25,0,0,0,0,0,0,25,5,0,0,0
0,5,0,0,0,0,0,0,5,5,0,0,0
0,5,5,0,0,0,0,5,5,5,0,0,0
0,25,0,0,0,0,0,5,25,5,0,0,0
0,5,5,0,0,0,0,0,5,0,0,0,0
0,5,5,0,0,0,0,0,5,0,0,0,0
0,5,5,0,5,5,0,5,5,0,0,0,0
0,22,5,25,5,5,25,5,22,0,0,0,0
0,0,0,0,0,0,0,0,0,0,0,0,0
endlayer

layer
0,0,0,0,0,0,0,0,0,0,0,0,0
0,22,5,25,5,5,25,5,22,0,0,0,0
0,5,5,0,0,0,0,5,5,0,0,0,0
0,5,0,0,0,0,0,0,5,0,0,0,0
0,5,0,0,0,0,0,0,5,0,0,0,0
0,25,0,0,0,0,0,0,25,0,0,0,0
0,5,0,0,0,0,0,0,5,0,0,0,0
0,5,0,0,0,0,0,5,5,0,0,0,0
0,25,0,0,0,0,0,0,25,0,0,0,0
0,5,0,0,0,0,0,0,5,0,0,0,0
0,5,0,0,0,0,0,0,5,0,0,0,0
0,5,5,0,0,0,0,0,5,0,0,0,0
0,22,5,25,5,5,25,5,22,0,0,0,0
0,0,0,0,0,0,0,0,0,0,0,0,0
endlayer

layer
0,0,0,0,0,0,0,0,0,0,0,0,0
0,22,21,21,21,23,23,21,22,0,0,0,0
0,20,0,0,0,0,0,0,20,0,0,0,0
0,20,0,0,0,0,0,0,20,0,0,0,0
0,20,0,0,0,0,0,0,20,0,0,0,0
0,20,0,0,0,0,0,0,20,0,0,0,0
0,24,0,0,0,0,0,0,20,0,0,0,0
0,24,0,0,0,0,0,0,24,0,0,0,0
0,20,0,0,0,0,0,0,24,0,0,0,0
0,20,0,0,0,0,0,0,20,0,0,0,0
0,20,0,0,0,0,0,0,20,0,0,0,0
0,20,0,0,0,0,0,0,20,0,0,0,0
0,22,21,21,23,23,21,21,22,0,0,0,0
0,0,0,0,0,0,0,0,0,0,0,0,0
endlayer

layer
0,0,0,0,0,0,0,0,0,0,0,0,0
0,5,5,25,5,0,25,5,5,0,0,0,0
0,5,0,0,0,0,0,0,5,0,0,0,0
0,5,0,0,0,0,0,0,5,0,0,0,0
0,5,0,0,0,0,0,0,5,0,0,0,0
0,0,0,0,0,0,0,0,5,0,0,0,0
0,0,0,0,0,0,0,0,0,0,0,0,0
0,0,0,0,0,0,0,0,0,0,0,0,0
0,0,0,0,0,0,0,0,0,0,0,0,0
0,5,0,0,0,0,0,0,5,0,0,0,0
0,5,0,0,0,0,0,0,5,0,0,0,0
0,5,0,0,0,0,0,0,5,0,0,0,0
0,5,5,25,0,0,25,5,5,0,0,0,0
0,0,0,0,0,0,0,0,0,0,0,0,0
endlayer

layer
0,0,0,0,0,0,0,0,0,0,0,0,0
0,5,0,25,5,0,25,0,5,0,0,0,0
0,5,0,0,0,0,0,0,5,0,0,0,0
0,5,0,0,0,0,0,0,5,0,0,0,0
0,0,0,0,0,0,0,0,5,0,0,0,0
0,0,0,0,0,0,0,0,0,0,0,0,0
0,0,0,0,0,0,0,0,0,0,0,0,0
0,0,0,0,0,0,0,0,0,0,0,0,0
0,0,0,0,0,0,0,0,0,0,0,0,0
0,0,0,0,0,0,0,0,0,0,0,0,0
0,5,0,0,0,0,0,0,5,0,0,0,0
0,5,0,0,0,0,0,0,5,0,0,0,0
0,5,5,25,0,0,25,0,5,0,0,0,0
0,0,0,0,0,0,0,0,0,0,0,0,0
endlayer

layer
0,0,0,0,0,0,0,0,0,0,0,0,0
0,5,0,25,0,0,25,0,5,0,0,0,0
0,0,0,0,0,0,0,0,5,0,0,0,0
0,0,0,0,0,0,0,0,5,0,0,0,0
0,0,0,0,0,0,0,0,0,0,0,0,0
0,0,0,0,0,0,0,0,0,0,0,0,0
0,0,0,0,0,0,0,0,0,0,0,0,0
0,0,0,0,0,0,0,0,0,0,0,0,0
0,0,0,0,0,0,0,0,0,0,0,0,0
0,0,0,0,0,0,0,0,0,0,0,0,0
0,0,0,0,0,0,0,0,0,0,0,0,0
0,5,0,0,0,0,0,0,5,0,0,0,0
0,5,0,25,0,0,25,0,5,0,0,0,0
0,0,0,0,0,0,0,0,0,0,0,0,0
endlayer

