# SkyShrineQuartz
# Created by Ruins mod version 13.8 Ingame Parser
# authoring Player: Jordan_Greywolf
# Created for MC 1.7.10: 15 Oct 2014
# Updated for MC 1.8: 21 Jul 2015
# Verified for MC 1.12: 23 Jun 2017
# Updated for MC 1.12.1: 9 Sep 2017

# Last Updated: 6 Apr 2018

biomesToSpawnIn=enchanted forest,extreme hills,highlands,deep ocean,mushroomisland,cold_beach,deep_ocean,extreme_hills,forest_hills,frozen_ocean,frozen_river,mutated_extreme_hills,mushroom_island

uniqueMinDistance=2000
spawnMinDistance=2000

weight=1
embed_into_distance=-45

acceptable_target_blocks=stone,grass,dirt,sand,sandstone,water,flowing_water,lava,flowing_lava,bedrock,gravel,clay,mycelium,snow,snow_layer

unacceptable_target_blocks=
dimensions=20,14,14
allowable_overhang=99999
max_leveling=25
leveling_buffer=-1
preserve_water=0
preserve_lava=0
preserve_plants=1

rule1=0,100,minecraft:glowstone-0
rule2=0,100,minecraft:stone-0
rule3=0,100,minecraft:dirt-0
rule4=0,100,preserveBlock
rule5=0,100,minecraft:grass-0
rule6=0,100,minecraft:quartz_block-0
rule7=0,100,minecraft:water-0
rule8=0,100,minecraft:double_plant-2
rule9=0,100,minecraft:tallgrass-1
rule10=0,100,minecraft:double_plant-4
rule11=0,100,minecraft:log-1
rule12=0,100,minecraft:stone_slab-7
rule13=0,100,minecraft:quartz_block-2
rule14=0,100,minecraft:water-9
rule15=0,100,minecraft:leaves-1
rule16=0,100,minecraft:double_plant-8
rule17=0,100,minecraft:double_plant-11
rule18=0,100,minecraft:double_plant-10
rule19=0,100,minecraft:double_plant-9
rule20=0,100,minecraft:quartz_block-1
rule21=0,100,minecraft:water-1
rule22=0,100,minecraft:leaves-9
rule23=0,100,minecraft:double_stone_slab-7
rule24=0,100,minecraft:leaves-5
rule25=0,100,minecraft:quartz_stairs-0
rule26=0,100,minecraft:quartz_stairs-2
rule27=0,100,minecraft:quartz_stairs-3
rule28=0,100,minecraft:quartz_stairs-1

layer
4,4,4,4,4,4,4,4,4,4,4,4,4,4
4,4,4,4,4,4,4,4,4,4,4,4,1,4
4,4,4,4,4,4,4,4,4,4,4,4,4,4
4,4,4,4,4,4,4,4,4,4,4,4,4,4
4,4,4,4,4,4,4,4,4,4,4,4,4,4
4,4,4,4,4,4,4,4,4,4,4,4,4,4
4,4,4,4,4,4,4,4,4,4,4,4,4,4
4,4,4,4,4,1,4,4,4,4,4,4,4,4
4,4,4,4,4,4,4,4,4,4,4,4,4,4
4,4,4,4,4,4,4,4,4,4,4,4,4,4
4,4,4,4,4,4,4,4,4,4,4,4,4,4
4,4,4,4,4,4,4,4,4,4,4,4,4,4
4,4,4,4,4,4,4,4,4,4,4,4,4,4
4,4,4,4,4,4,4,4,4,4,4,4,4,4
endlayer

layer
4,4,4,4,4,4,4,4,4,4,4,4,4,4
4,4,4,4,4,4,4,4,4,4,4,4,2,4
4,4,4,4,4,4,4,4,4,4,4,4,4,4
4,4,4,4,4,4,4,4,4,4,4,4,4,4
4,4,4,4,4,4,4,4,4,4,4,4,4,4
4,4,4,4,4,4,4,4,4,4,4,4,4,4
4,4,1,4,4,4,4,4,4,4,4,4,4,4
4,4,4,4,4,1,4,4,4,4,4,4,4,4
4,4,4,4,4,4,4,4,4,4,4,4,4,4
4,4,4,4,4,4,4,4,4,4,4,4,4,4
4,4,4,4,4,4,4,4,4,4,4,4,4,4
4,4,4,4,4,4,4,4,4,4,4,4,4,4
4,4,4,4,4,4,4,4,4,4,4,4,4,4
4,4,4,4,4,4,4,4,4,4,4,4,4,4
endlayer

layer
4,4,4,4,4,4,4,4,4,4,4,4,4,4
4,4,4,4,4,4,4,4,4,4,4,4,2,4
4,4,4,4,4,4,4,4,4,4,4,4,4,4
4,4,4,4,4,1,4,4,4,4,4,4,4,4
4,4,4,4,4,4,4,4,4,4,4,4,4,4
4,4,4,4,4,4,4,4,4,4,4,4,4,4
4,4,2,4,4,4,4,4,4,4,4,4,4,4
4,4,4,4,4,1,4,4,4,4,4,4,4,4
4,4,4,4,4,4,4,4,4,4,4,4,4,4
4,4,4,4,4,4,4,4,4,4,4,4,4,4
4,4,4,4,4,4,4,4,4,4,4,4,4,4
4,4,4,4,4,4,4,4,4,4,4,4,4,4
4,1,4,4,4,4,4,4,4,4,4,4,4,4
4,4,4,4,4,4,4,4,4,4,4,4,4,4
endlayer

layer
4,4,4,4,4,4,4,4,4,4,4,4,4,4
4,4,4,4,4,4,4,4,4,4,4,4,2,4
4,4,4,4,4,4,4,4,4,4,4,4,4,4
4,4,4,4,4,2,4,4,4,4,4,4,4,4
4,4,4,4,4,4,4,4,4,4,4,4,4,4
4,4,4,4,4,4,4,4,4,4,4,4,4,4
4,4,4,4,4,4,4,4,4,4,4,4,4,4
4,4,4,4,4,2,4,4,4,4,4,4,4,4
4,4,4,4,4,4,4,4,4,4,4,4,4,4
4,4,4,4,4,4,4,4,4,4,4,4,4,4
4,4,4,4,4,4,4,4,4,4,4,4,4,4
4,4,4,4,4,4,4,4,4,4,4,1,4,4
4,2,4,4,4,4,4,4,4,4,4,4,4,4
4,4,4,4,4,4,4,4,4,4,4,4,4,4
endlayer

layer
4,4,4,4,4,4,4,4,4,4,4,4,4,4
4,4,4,4,4,4,4,4,4,4,4,4,4,4
4,4,4,4,4,4,4,4,4,4,4,4,4,4
4,4,4,4,4,2,4,4,4,4,4,4,4,4
4,4,4,4,4,4,4,4,4,4,4,4,4,4
4,4,4,4,4,4,4,4,4,4,4,4,4,4
4,4,4,4,4,4,4,4,4,4,4,4,4,4
4,4,4,4,4,2,2,4,4,4,4,4,4,4
4,4,4,4,4,2,4,4,4,4,4,4,4,4
4,4,4,4,4,4,4,4,4,4,4,4,4,4
4,4,4,4,4,4,4,4,4,4,4,4,4,4
4,4,4,4,4,4,4,4,4,4,4,2,4,4
4,2,4,4,4,4,4,4,4,4,4,4,4,4
4,4,4,4,4,4,4,4,4,4,4,4,4,4
endlayer

layer
4,4,4,4,4,4,4,4,4,4,4,4,4,4
4,4,4,4,4,4,4,4,4,4,4,4,4,4
4,4,4,4,4,4,4,4,4,4,4,4,4,4
4,4,4,4,4,4,4,4,4,4,4,4,4,4
4,4,4,4,4,4,4,4,4,4,4,4,4,4
4,4,4,4,4,4,4,4,4,4,4,4,4,4
4,4,2,4,4,4,4,4,4,4,4,4,4,4
4,4,4,4,2,2,2,4,4,4,4,4,4,4
4,4,4,4,4,2,4,4,4,4,4,4,4,4
4,4,4,4,4,4,4,4,4,4,4,4,4,4
4,4,4,2,4,4,4,4,4,4,4,4,4,4
4,4,4,4,4,4,4,4,4,4,4,2,4,4
4,2,2,4,4,4,4,4,4,4,4,4,4,4
4,4,4,4,4,4,4,4,4,4,4,4,4,4
endlayer

layer
4,4,4,4,4,4,4,4,4,4,4,4,4,4
4,4,4,4,4,4,4,4,4,4,4,4,4,4
4,4,4,4,4,4,2,4,4,4,4,4,4,4
4,4,4,4,4,4,4,4,4,4,4,4,4,4
4,4,4,2,4,4,4,4,4,4,4,4,4,4
4,4,4,4,4,4,4,4,4,4,4,2,4,4
4,4,2,4,4,2,2,4,4,4,4,4,4,4
4,4,4,3,2,2,2,2,4,4,4,4,4,4
4,4,4,4,2,2,4,4,4,4,4,4,4,4
4,4,2,4,4,4,4,4,4,4,4,4,4,4
4,4,4,2,4,4,4,4,2,4,4,4,4,4
4,2,4,4,4,4,4,4,4,4,4,2,2,4
2,2,2,4,4,2,4,4,4,4,4,4,4,4
4,4,2,4,4,4,4,4,4,4,4,4,4,4
endlayer

layer
4,4,4,4,4,4,4,4,4,4,4,4,4,4
4,4,4,4,4,4,4,4,4,4,4,4,4,4
4,4,4,4,4,4,2,2,4,4,4,4,4,4
4,4,4,2,4,4,4,4,4,4,4,4,4,4
4,4,4,2,4,4,4,2,4,4,4,4,4,4
4,4,4,4,4,2,4,4,4,4,2,2,2,4
4,4,2,4,2,2,2,4,4,4,4,4,4,4
4,2,4,2,2,2,2,2,4,4,4,4,4,4
4,4,4,4,2,2,2,4,4,2,4,4,4,4
4,2,2,4,4,2,4,4,4,4,4,4,4,4
4,4,4,2,4,4,4,2,2,4,4,4,4,4
4,4,4,4,4,4,4,4,4,4,4,2,2,4
4,4,4,4,4,2,4,4,4,4,4,2,4,4
4,4,4,4,4,4,4,4,4,4,4,4,4,4
endlayer

layer
4,4,4,4,4,4,4,4,4,4,4,4,4,4
4,4,4,4,4,4,2,4,4,4,4,4,4,4
4,4,4,4,4,2,2,2,4,4,4,4,4,4
4,4,4,2,4,4,2,4,4,4,4,4,4,4
4,4,2,2,4,4,4,2,4,4,4,2,4,4
4,4,4,4,3,2,4,4,4,4,2,2,2,4
4,3,2,2,2,2,2,3,4,2,4,2,4,4
2,2,2,2,2,2,2,2,4,4,4,4,4,4
4,4,3,3,2,2,2,3,4,2,2,4,4,4
4,2,2,3,3,2,3,4,2,4,4,4,4,4
4,4,2,2,2,2,4,2,2,2,4,4,4,4
4,4,4,2,4,4,4,4,2,4,4,4,4,4
4,4,4,4,4,2,2,4,4,4,4,4,4,4
4,4,4,4,4,4,4,4,4,4,4,4,4,4
endlayer

layer
4,4,4,2,2,2,2,4,4,4,4,4,4,4
4,4,2,2,2,2,2,2,2,4,4,4,4,4
4,4,2,2,2,2,2,2,2,2,4,4,4,4
4,2,2,2,2,2,2,2,2,2,2,2,4,4
2,2,2,2,2,2,2,2,2,2,2,2,2,2
2,2,2,2,2,2,2,2,2,2,2,2,2,2
2,2,2,2,2,2,2,2,2,2,2,2,2,4
2,2,2,2,2,2,2,2,2,2,2,2,4,4
2,2,2,2,2,2,2,2,2,2,2,2,4,4
2,2,2,2,2,2,2,2,2,2,2,2,4,4
2,2,2,2,2,2,2,2,2,2,2,4,4,4
4,2,2,2,2,2,2,2,2,2,2,4,4,4
4,4,2,2,2,2,2,2,2,2,4,4,4,4
4,4,4,2,2,2,2,4,4,4,4,4,4,4
endlayer


layer
4,4,4,5,5,5,5,4,4,4,4,4,4,4
4,4,5,5,5,5,5,5,5,4,4,4,4,4
4,4,5,5,5,5,5,5,5,3,4,4,4,4
4,5,5,5,5,5,5,5,5,5,5,5,4,4
5,5,5,6,6,6,5,5,5,5,5,5,5,5
5,5,6,6,6,6,6,5,5,5,5,5,5,5
5,6,6,7,7,7,6,6,5,5,5,5,5,4
6,6,7,7,7,7,7,6,6,5,5,5,4,4
6,6,7,7,6,7,7,6,6,5,5,3,4,4
6,6,7,7,7,7,7,6,6,5,5,5,4,4
5,6,6,7,7,7,6,6,5,5,5,4,4,4
4,5,6,6,6,6,6,5,5,5,5,4,4,4
4,4,5,6,6,6,5,5,5,5,4,4,4,4
4,4,4,5,5,5,5,4,4,4,4,4,4,4
endlayer

layer
0,0,0,0,0,0,8,0,0,0,0,0,0,0
0,0,10,9,8,9,0,0,0,0,0,0,0,0
0,0,9,9,0,0,0,9,0,11,0,0,0,0
0,10,0,9,0,8,0,0,0,9,9,9,0,0
0,0,10,12,12,12,0,9,0,9,0,0,9,10
8,9,12,13,12,13,12,10,0,0,9,9,0,9
9,12,12,0,0,0,12,12,9,10,0,0,8,0
12,13,0,0,14,0,0,13,12,0,0,9,0,0
12,12,0,14,13,14,0,12,12,9,0,11,0,0
12,13,0,0,14,0,0,13,12,9,10,0,0,0
8,12,12,0,0,0,12,12,10,0,0,0,0,0
0,10,12,13,12,13,12,0,9,0,8,0,0,0
0,0,0,12,12,12,9,0,0,9,0,0,0,0
0,0,0,9,0,9,0,0,0,0,0,0,0,0
endlayer

layer
0,0,0,0,0,0,16,0,15,15,15,0,0,0
0,0,18,0,17,0,0,15,15,15,15,15,0,0
0,0,0,0,0,0,0,15,15,11,15,15,0,0
0,18,0,0,0,19,0,15,15,15,15,15,0,0
0,0,19,0,0,0,0,0,15,15,15,0,0,16
19,0,0,13,0,13,0,18,0,0,0,0,0,0
0,0,0,0,0,0,0,0,0,16,0,0,16,0
0,13,0,0,14,0,0,13,0,0,0,0,0,0
0,0,0,14,20,14,0,0,0,0,0,11,0,0
0,13,0,0,14,0,0,13,0,0,16,0,0,0
19,0,0,0,0,0,0,0,17,0,0,0,0,0
0,19,0,13,0,13,0,0,0,0,19,0,0,0
0,0,0,0,0,0,0,0,0,0,0,0,0,0
0,0,0,0,0,0,0,0,0,0,0,0,0,0
endlayer

layer
0,0,0,0,0,0,0,0,0,0,0,0,0,0
0,0,0,0,0,0,0,0,0,15,0,0,0,0
0,0,0,0,0,0,0,0,15,11,15,0,0,0
0,0,0,0,0,0,0,0,0,15,0,0,0,0
0,0,0,0,0,0,0,0,0,0,0,0,0,0
0,0,0,13,0,13,0,0,0,0,0,0,0,0
0,0,0,0,0,0,0,0,0,0,0,0,0,0
0,13,0,0,21,0,0,13,0,0,0,15,0,0
0,0,0,21,7,21,0,0,0,0,15,11,15,0
0,13,0,0,21,0,0,13,0,0,0,15,0,0
0,0,0,0,0,0,0,0,0,0,0,0,0,0
0,0,0,13,0,13,0,0,0,0,0,0,0,0
0,0,0,0,0,0,0,0,0,0,0,0,0,0
0,0,0,0,0,0,0,0,0,0,0,0,0,0
endlayer

layer
0,0,0,0,0,0,0,0,15,15,15,0,0,0
0,0,0,0,0,0,0,15,15,15,15,15,0,0
0,0,0,0,0,0,0,15,15,11,15,15,0,0
0,0,0,0,0,0,0,15,15,15,15,15,0,0
0,0,0,0,0,0,0,0,15,15,15,0,0,0
0,0,0,13,0,13,0,0,0,0,0,0,0,0
0,0,0,0,0,0,0,0,0,0,15,15,15,0
0,13,0,0,0,0,0,13,0,15,15,15,15,15
0,0,0,0,0,0,0,0,0,15,15,11,15,15
0,13,0,0,0,0,0,13,0,15,15,15,15,15
0,0,0,0,0,0,0,0,0,0,15,15,15,0
0,0,0,13,0,13,0,0,0,0,0,0,0,0
0,0,0,0,0,0,0,0,0,0,0,0,0,0
0,0,0,0,0,0,0,0,0,0,0,0,0,0
endlayer

layer
0,0,0,0,0,0,0,0,0,0,0,0,0,0
0,0,0,0,0,0,0,0,0,15,0,0,0,0
0,0,0,0,0,0,0,0,22,11,15,0,0,0
0,0,0,0,0,0,0,0,0,15,0,0,0,0
0,0,0,0,0,0,0,0,0,0,0,0,0,0
0,0,0,20,0,20,0,0,0,0,0,0,0,0
0,0,0,0,0,0,0,0,0,0,0,0,0,0
0,20,0,0,0,0,0,20,0,0,0,15,0,0
0,0,0,0,0,0,0,0,0,0,15,11,15,0
0,20,0,0,0,0,0,20,0,0,0,15,0,0
0,0,0,0,0,0,0,0,0,0,0,0,0,0
0,0,0,20,0,20,0,0,0,0,0,0,0,0
0,0,0,0,0,0,0,0,0,0,0,0,0,0
0,0,0,0,0,0,0,0,0,0,0,0,0,0
endlayer

layer
0,0,0,0,0,0,0,0,0,0,0,0,0,0
0,0,0,0,0,0,0,0,0,0,0,0,0,0
0,0,0,0,0,0,0,0,0,15,0,0,0,0
0,0,0,0,0,0,0,0,0,0,0,0,0,0
0,0,12,12,12,12,12,0,0,0,0,0,0,0
0,12,23,6,6,6,23,12,0,0,0,0,0,0
12,23,6,6,0,6,6,23,12,0,0,24,0,0
12,6,6,0,0,0,6,6,12,0,24,24,24,0
12,6,0,0,0,0,0,6,12,24,24,11,24,24
12,6,6,0,0,0,6,6,12,0,24,24,24,0
12,23,6,6,0,6,6,23,12,0,0,24,0,0
0,12,23,6,6,6,23,12,0,0,0,0,0,0
0,0,12,12,12,12,12,0,0,0,0,0,0,0
0,0,0,0,0,0,0,0,0,0,0,0,0,0
endlayer

layer
0,0,0,0,0,0,0,0,0,0,0,0,0,0
0,0,0,0,0,0,0,0,0,15,0,0,0,0
0,0,0,0,0,0,0,0,15,15,15,0,0,0
0,0,0,0,0,0,0,0,0,15,0,0,0,0
0,0,0,0,0,0,0,0,0,0,0,0,0,0
0,0,0,25,25,25,0,0,0,0,0,0,0,0
0,0,6,6,6,6,6,0,0,0,0,0,0,0
0,27,6,0,0,0,6,26,0,0,0,15,0,0
0,27,6,0,0,0,6,26,0,0,15,11,15,0
0,27,6,0,0,0,6,26,0,0,0,15,0,0
0,0,6,6,6,6,6,0,0,0,0,0,0,0
0,0,0,28,28,28,0,0,0,0,0,0,0,0
0,0,0,0,0,0,0,0,0,0,0,0,0,0
0,0,0,0,0,0,0,0,0,0,0,0,0,0
endlayer

layer
0,0,0,0,0,0,0,0,0,0,0,0,0,0
0,0,0,0,0,0,0,0,0,0,0,0,0,0
0,0,0,0,0,0,0,0,0,0,0,0,0,0
0,0,0,0,0,0,0,0,0,0,0,0,0,0
0,0,0,0,0,0,0,0,0,0,0,0,0,0
0,0,0,0,0,0,0,0,0,0,0,0,0,0
0,0,0,0,12,0,0,0,0,0,0,0,0,0
0,0,0,12,12,12,0,0,0,0,24,24,24,0
0,0,12,12,12,12,12,0,0,0,24,24,24,0
0,0,0,12,12,12,0,0,0,0,24,24,24,0
0,0,0,0,12,0,0,0,0,0,0,0,0,0
0,0,0,0,0,0,0,0,0,0,0,0,0,0
0,0,0,0,0,0,0,0,0,0,0,0,0,0
0,0,0,0,0,0,0,0,0,0,0,0,0,0
endlayer

layer
0,0,0,0,0,0,0,0,0,0,0,0,0,0
0,0,0,0,0,0,0,0,0,0,0,0,0,0
0,0,0,0,0,0,0,0,0,0,0,0,0,0
0,0,0,0,0,0,0,0,0,0,0,0,0,0
0,0,0,0,0,0,0,0,0,0,0,0,0,0
0,0,0,0,0,0,0,0,0,0,0,0,0,0
0,0,0,0,0,0,0,0,0,0,0,0,0,0
0,0,0,0,0,0,0,0,0,0,0,0,0,0
0,0,0,0,0,0,0,0,0,0,0,24,0,0
0,0,0,0,0,0,0,0,0,0,0,0,0,0
0,0,0,0,0,0,0,0,0,0,0,0,0,0
0,0,0,0,0,0,0,0,0,0,0,0,0,0
0,0,0,0,0,0,0,0,0,0,0,0,0,0
0,0,0,0,0,0,0,0,0,0,0,0,0,0
endlayer

