# Clay House
# Created by Ruins mod version 15.6 Ingame Parser
# authoring Player: Jordan_Greywolf

# Created for MC 1.8: 29 May 2016
# Updated to MC 1.12: 23 Jun 2017
# Updated to MC 1.12.1: 10 Sep 2017

biomesToSpawnIn=badlands,mesa,mesa (bryce),mesa plateau,mesa plateau f,mesa plateau f m,mesa plateau m,mesa_rock,mesa_clear_rock,mutated_mesa,mutated_mesa_rock,mutated_mesa_clear_rock

weight=1
embed_into_distance=0
acceptable_target_blocks=

unacceptable_target_blocks=cloud,Natura:Cloud,slime_congealed,slime_dirt,slime_grass,command_block,planks,planks2,concrete,cobblestone,stonebrick,brick_block,glass,torch,oak_stairs,stone_stairs,brick_stairs,stone_brick_stairs,nether_brick_stairs,sandstone_stairs,spruce_stairs,birch_stairs,jungle_stairs,quartz_stairs,acacia_stairs,dark_oak_stairs,cobblestone_wall,stone_slab,double_stone_slab,stone_slab2,wooden_slab,double_wooden_slab,nether_brick,fence

dimensions=8,9,9
allowable_overhang=999
max_leveling=12
leveling_buffer=-1
preserve_water=0
preserve_lava=0
preserve_plants=1

rule1=0,100,preserveBlock
rule2=0,100,minecraft:hardened_clay-0
rule3=0,100,minecraft:stained_hardened_clay-14
rule4=0,100,minecraft:stained_hardened_clay-0
rule5=0,100,minecraft:ladder-2
rule6=0,100,minecraft:log-4
rule7=0,100,minecraft:log-8

layer
1,1,1,1,1,1,1,1,1
1,2,2,2,2,2,2,2,1
1,2,2,2,2,2,2,2,1
1,2,2,2,2,2,2,2,1
1,2,2,2,2,2,2,2,1
1,2,2,2,2,2,2,2,1
1,2,2,2,2,2,2,2,1
1,2,2,2,2,2,2,2,1
1,1,1,1,1,1,1,1,1
endlayer

layer
1,1,1,1,1,1,1,1,1
1,2,2,2,2,2,2,2,1
1,2,3,3,3,3,3,2,1
1,2,3,4,4,4,3,2,1
1,2,3,4,3,4,3,2,1
1,2,3,4,4,4,3,2,1
1,2,3,3,3,3,3,2,1
1,2,2,2,2,2,2,2,1
1,1,1,1,1,1,1,1,1
endlayer

layer
1,1,1,1,1,1,1,1,1
1,2,2,2,1,2,2,2,1
1,2,0,0,0,0,0,2,1
1,2,2,5,0,0,0,2,1
1,1,0,0,0,0,0,1,1
1,2,0,0,0,0,0,2,1
1,2,0,0,0,0,0,2,1
1,2,2,2,1,2,2,2,1
1,1,1,1,1,1,1,1,1
endlayer

layer
1,1,1,1,1,1,1,1,1
1,2,1,2,1,2,1,2,1
1,1,0,0,0,0,0,1,1
1,2,2,5,0,0,0,2,1
1,1,0,0,0,0,0,1,1
1,2,0,0,0,0,0,2,1
1,1,0,0,0,0,0,1,1
1,2,1,2,1,2,1,2,1
1,1,1,1,1,1,1,1,1
endlayer

layer
1,1,1,1,1,1,1,1,1
1,2,2,2,2,2,2,2,1
1,2,0,0,0,0,0,2,1
1,2,2,5,0,0,0,2,1
1,2,0,0,0,0,0,2,1
1,2,0,0,0,0,0,2,1
1,2,0,0,0,0,0,2,1
1,2,2,2,2,2,2,2,1
1,1,1,1,1,1,1,1,1
endlayer

layer
1,1,6,1,1,1,6,1,1
1,2,6,2,2,2,6,2,1
7,7,6,7,7,7,6,7,7
1,2,6,5,0,0,6,2,1
1,2,6,0,0,0,6,2,1
1,2,6,0,0,0,6,2,1
7,7,6,7,7,7,6,7,7
1,2,6,2,2,2,6,2,1
1,1,6,1,1,1,6,1,1
endlayer

layer
1,1,1,1,1,1,1,1,1
1,2,2,2,2,2,2,2,1
1,2,4,4,4,4,4,2,1
1,2,4,5,4,4,4,2,1
1,2,4,4,4,4,4,2,1
1,2,4,4,4,4,4,2,1
1,2,4,4,4,4,4,2,1
1,2,2,2,2,2,2,2,1
1,1,1,1,1,1,1,1,1
endlayer

layer
1,1,1,1,1,1,1,1,1
1,2,2,2,2,2,2,2,1
1,2,0,0,0,0,0,2,1
1,2,0,0,0,0,0,2,1
1,2,0,0,0,0,0,2,1
1,2,0,0,0,0,0,2,1
1,2,0,0,0,0,0,2,1
1,2,2,2,2,2,2,2,1
1,1,1,1,1,1,1,1,1
endlayer

