# Mesa House - created 31 Mar 2018 for MC version 1.12
# Created by Ruins mod version 16.8 Ingame Parser
# authoring Player: Jordan_Greywolf

biomesToSpawnIn=badlands,mesa,mesa (bryce),mesa plateau,mesa plateau f,mesa plateau f m,mesa plateau m,mesa_rock,mesa_clear_rock,mutated_mesa,mutated_mesa_rock,mutated_mesa_clear_rock

weight=1
embed_into_distance=6
acceptable_target_blocks=

acceptable_target_blocks=clay,hardened_clay,stained_hardened_clay

dimensions=12,17,17
allowable_overhang=9999
max_leveling=64
leveling_buffer=-1
preserve_water=0
preserve_lava=0
preserve_plants=1

rule1=0,100,preserveBlock

rule2=0,100,minecraft:hardened_clay-0
rule3=0,100,minecraft:netherrack-0

rule4=0,100,minecraft:emerald_ore-0,minecraft:iron_ore-0,minecraft:gold_ore-0

rule5=0,100,minecraft:stained_hardened_clay-1
rule6=0,100,minecraft:stone_stairs-1
rule7=0,100,minecraft:stone_stairs-2
rule8=0,100,minecraft:stone_stairs-3
rule9=0,100,minecraft:stone_stairs-0

rule10=0,100,MobSpawner:Husk,MobSpawner:Skeleton

rule11=0,100,minecraft:wooden_slab-0
rule12=0,100,minecraft:carpet-9
rule13=0,100,minecraft:log-0
rule14=0,100,minecraft:flower_pot-0
rule15=0,100,minecraft:ladder-2
rule16=0,100,minecraft:log-4
rule17=0,100,minecraft:log-8
rule18=0,100,minecraft:hay_block-0

# 1
layer
1,1,1,1,1,1,1,1,1,1,1,1,1,1,1,1,1
1,2,2,2,2,2,2,2,2,2,2,2,2,2,2,2,1
1,2,2,2,2,2,2,2,2,2,2,2,2,2,2,2,1
1,2,2,2,2,2,2,2,2,2,2,2,2,2,2,2,1
1,2,2,2,2,2,2,2,2,2,2,2,2,2,2,2,1
1,2,2,2,2,2,2,2,2,2,2,2,2,2,2,2,1
1,2,2,2,2,2,2,2,2,2,2,2,2,2,2,2,1
1,2,2,2,2,2,2,2,2,2,2,2,2,2,2,2,1
1,2,2,2,2,2,2,2,3,2,2,2,2,2,2,2,1
1,2,2,2,2,2,2,2,2,2,2,2,2,2,2,2,1
1,2,2,2,2,2,2,2,2,2,2,2,2,2,2,2,1
1,2,2,2,2,2,2,2,2,2,2,2,2,2,2,2,1
1,2,2,2,2,2,2,2,2,2,2,2,2,2,2,2,1
1,2,2,2,2,2,2,2,2,2,2,2,2,2,2,2,1
1,2,2,2,2,2,2,2,2,2,2,2,2,2,2,2,1
1,2,2,2,2,2,2,2,2,2,2,2,2,2,2,2,1
1,1,1,1,1,1,1,1,1,1,1,1,1,1,1,1,1
endlayer

# 2
layer
1,1,1,1,1,1,1,1,1,1,1,1,1,1,1,1,1
1,2,2,2,2,2,2,2,2,2,2,2,2,2,2,2,1
1,2,4,5,5,5,5,5,5,5,5,5,5,5,4,2,1
1,2,5,5,5,5,5,5,5,5,5,5,5,5,5,2,1
1,2,5,5,5,5,5,5,5,5,5,5,5,5,5,2,1
1,2,5,5,5,5,5,5,5,5,5,5,5,5,5,2,1
1,2,5,5,5,5,5,5,5,5,5,5,5,5,5,2,1
1,2,5,5,5,5,5,7,6,6,5,5,5,5,5,2,1
1,2,5,5,5,5,5,7,0,8,5,5,5,5,5,2,1
1,2,5,5,5,5,5,9,9,8,5,5,5,5,5,2,1
1,2,5,5,5,5,5,5,5,5,5,5,5,5,5,2,1
1,2,5,5,5,5,5,5,5,5,5,5,5,5,5,2,1
1,2,5,5,5,5,5,5,5,5,5,5,5,5,5,2,1
1,2,5,5,5,5,5,5,5,5,5,5,5,5,5,2,1
1,2,4,5,5,5,5,5,5,5,5,5,5,5,4,2,1
1,2,2,2,2,2,2,2,2,2,2,2,2,2,2,2,1
1,1,1,1,1,1,1,1,1,1,1,1,1,1,1,1,1
endlayer

# 3
layer
1,1,1,1,1,1,1,1,1,1,1,1,1,1,1,1,1
1,2,2,2,2,2,2,2,1,2,2,2,2,2,2,2,1
1,2,10,0,0,0,0,0,0,0,0,11,11,0,10,2,1
1,2,12,0,0,0,0,0,0,0,0,0,0,0,12,2,1
1,2,12,0,0,0,0,0,0,0,0,0,0,0,12,2,1
1,2,0,0,0,13,0,0,0,0,0,13,0,0,0,2,1
1,2,0,0,0,0,14,0,0,0,0,0,0,0,0,2,1
1,2,0,0,0,0,0,0,0,0,0,0,0,0,0,2,1
1,1,0,0,0,0,0,0,0,0,0,13,15,0,0,1,1
1,2,0,0,0,0,0,0,0,0,0,0,0,0,0,2,1
1,2,0,0,0,0,0,0,14,0,0,0,0,0,0,2,1
1,2,0,0,0,13,0,0,0,0,0,13,0,0,0,2,1
1,2,12,0,0,0,0,0,0,0,0,0,0,0,12,2,1
1,2,12,14,0,0,0,0,0,0,0,0,0,0,12,2,1
1,2,10,0,0,0,11,0,0,0,0,0,0,0,10,2,1
1,2,2,2,2,2,2,2,1,2,2,2,2,2,2,2,1
1,1,1,1,1,1,1,1,1,1,1,1,1,1,1,1,1
endlayer

# 4
layer
1,1,1,1,1,1,1,1,1,1,1,1,1,1,1,1,1
1,2,2,2,2,2,2,2,1,2,2,2,2,2,2,2,1
1,2,0,0,0,0,0,0,0,0,0,0,0,0,0,2,1
1,2,0,0,0,0,0,0,0,0,0,0,0,0,0,2,1
1,2,0,0,0,0,0,0,0,0,0,0,0,0,0,2,1
1,2,0,0,0,13,0,0,0,0,0,13,0,0,0,2,1
1,2,0,0,0,0,0,0,0,0,0,0,0,0,0,2,1
1,2,0,0,0,0,0,0,0,0,0,0,0,0,0,2,1
1,1,0,0,0,0,0,0,0,0,0,13,15,0,0,1,1
1,2,0,0,0,0,0,0,0,0,0,0,0,0,0,2,1
1,2,0,0,0,0,0,0,0,0,0,0,0,0,0,2,1
1,2,0,0,0,13,0,0,0,0,0,13,0,0,0,2,1
1,2,0,0,0,0,0,0,0,0,0,0,0,0,0,2,1
1,2,0,0,0,0,0,0,0,0,0,0,0,0,0,2,1
1,2,0,0,0,0,0,0,0,0,0,0,0,0,0,2,1
1,2,2,2,2,2,2,2,1,2,2,2,2,2,2,2,1
1,1,1,1,1,1,1,1,1,1,1,1,1,1,1,1,1
endlayer

# 5
layer
1,1,1,1,1,1,1,1,1,1,1,1,1,1,1,1,1
1,2,2,2,2,2,2,2,2,2,2,2,2,2,2,2,1
1,2,0,0,0,0,0,0,0,0,0,0,0,0,0,2,1
1,2,0,0,0,0,0,0,0,0,0,0,0,0,0,2,1
1,2,0,0,0,0,0,0,0,0,0,0,0,0,0,2,1
1,2,0,0,0,13,0,0,0,0,0,13,0,0,0,2,1
1,2,0,0,0,0,0,0,0,0,0,0,0,0,0,2,1
1,2,0,0,0,0,0,0,0,0,0,0,0,0,0,2,1
1,2,0,0,0,0,0,0,0,0,0,13,15,0,0,2,1
1,2,0,0,0,0,0,0,0,0,0,0,0,0,0,2,1
1,2,0,0,0,0,0,0,0,0,0,0,0,0,0,2,1
1,2,0,0,0,13,0,0,0,0,0,13,0,0,0,2,1
1,2,0,0,0,0,0,0,0,0,0,0,0,0,0,2,1
1,2,0,0,0,0,0,0,0,0,0,0,0,0,0,2,1
1,2,0,0,0,0,0,0,0,0,0,0,0,0,0,2,1
1,2,2,2,2,2,2,2,2,2,2,2,2,2,2,2,1
1,1,1,1,1,1,1,1,1,1,1,1,1,1,1,1,1
endlayer

# 6
layer
1,1,16,1,1,1,16,1,1,1,16,1,1,1,16,1,1
1,2,2,2,2,2,2,2,2,2,2,2,2,2,2,2,1
17,2,5,5,5,5,5,5,5,5,5,5,5,5,5,2,17
1,2,5,5,5,5,5,5,5,5,5,5,5,5,5,2,1
1,2,5,5,5,5,5,5,5,5,5,5,5,5,5,2,1
1,2,5,5,5,13,5,5,5,5,5,13,5,5,5,2,1
17,2,5,5,5,5,5,5,5,5,5,5,5,5,5,2,17
1,2,5,5,5,5,5,5,5,5,5,5,5,5,5,2,1
1,2,5,5,5,5,5,5,0,5,5,13,15,5,5,2,1
1,2,5,5,5,5,5,5,5,5,5,5,5,5,5,2,1
17,2,5,5,5,5,5,5,5,5,5,5,5,5,5,2,17
1,2,5,5,5,13,5,5,5,5,5,13,5,5,5,2,1
1,2,5,5,5,5,5,5,5,5,5,5,5,5,5,2,1
1,2,5,5,5,5,5,5,5,5,5,5,5,5,5,2,1
17,2,5,5,5,5,5,5,5,5,5,5,5,5,5,2,17
1,2,2,2,2,2,2,2,2,2,2,2,2,2,2,2,1
1,1,16,1,1,1,16,1,1,1,16,1,1,1,16,1,1
endlayer

# 7
layer
1,1,1,1,1,1,1,1,1,1,1,1,1,1,1,1,1
1,2,2,2,2,2,2,2,2,2,2,2,2,2,2,2,1
1,2,0,0,0,0,0,0,0,0,0,0,0,0,0,2,1
1,2,0,0,0,0,0,0,0,0,0,0,0,0,0,2,1
1,2,0,0,0,0,0,0,0,0,0,0,0,0,0,2,1
1,2,0,0,0,2,2,2,2,2,2,2,0,0,0,2,1
1,2,0,0,0,2,0,11,11,0,18,2,0,0,0,2,1
1,2,0,0,0,2,0,0,0,0,14,2,0,0,0,2,1
1,2,0,0,0,0,0,0,0,0,0,2,15,0,0,2,1
1,2,0,0,0,2,0,0,0,0,0,2,0,0,0,2,1
1,2,0,0,0,2,12,12,0,12,12,2,0,0,0,2,1
1,2,0,0,0,2,2,2,2,2,2,2,0,0,0,2,1
1,2,0,0,0,0,0,0,0,0,0,0,0,0,0,2,1
1,2,0,0,0,0,0,0,0,0,0,0,0,0,0,2,1
1,2,0,0,0,0,0,0,0,0,0,0,0,0,0,2,1
1,2,2,2,2,2,2,2,2,2,2,2,2,2,2,2,1
1,1,1,1,1,1,1,1,1,1,1,1,1,1,1,1,1
endlayer

# 8
layer
1,1,1,1,1,1,1,1,1,1,1,1,1,1,1,1,1
1,1,1,1,1,1,1,1,1,1,1,1,1,1,1,1,1
1,1,0,0,0,0,0,0,0,0,0,0,0,0,0,1,1
1,1,0,0,0,0,0,0,0,0,0,0,0,0,0,1,1
1,1,0,0,0,0,0,0,0,0,0,0,0,0,0,1,1
1,1,0,0,0,2,2,2,0,2,2,2,0,0,0,1,1
1,1,0,0,0,2,0,0,0,0,0,2,0,0,0,1,1
1,1,0,0,0,2,0,0,0,0,0,2,0,0,0,1,1
1,1,0,0,0,0,0,0,0,0,0,2,15,0,0,1,1
1,1,0,0,0,2,0,0,0,0,0,2,0,0,0,1,1
1,1,0,0,0,2,0,0,0,0,0,2,0,0,0,1,1
1,1,0,0,0,2,2,2,0,2,2,2,0,0,0,1,1
1,1,0,0,0,0,0,0,0,0,0,0,0,0,0,1,1
1,1,0,0,0,0,0,0,0,0,0,0,0,0,0,1,1
1,1,0,0,0,0,0,0,0,0,0,0,0,0,0,1,1
1,1,1,1,1,1,1,1,1,1,1,1,1,1,1,1,1
1,1,1,1,1,1,1,1,1,1,1,1,1,1,1,1,1
endlayer

# 9
layer
1,1,1,1,1,1,1,1,1,1,1,1,1,1,1,1,1
1,1,1,1,1,1,1,1,1,1,1,1,1,1,1,1,1
1,1,0,0,0,0,0,0,0,0,0,0,0,0,0,1,1
1,1,0,0,0,0,0,0,0,0,0,0,0,0,0,1,1
1,1,0,0,0,0,0,0,0,0,0,0,0,0,0,1,1
1,1,0,0,0,2,2,2,2,2,2,2,0,0,0,1,1
1,1,0,0,0,2,0,0,0,0,0,2,0,0,0,1,1
1,1,0,0,0,2,0,0,0,0,0,2,0,0,0,1,1
1,1,0,0,0,2,0,0,0,0,0,2,15,0,0,1,1
1,1,0,0,0,2,0,0,0,0,0,2,0,0,0,1,1
1,1,0,0,0,2,0,0,0,0,0,2,0,0,0,1,1
1,1,0,0,0,2,2,2,2,2,2,2,0,0,0,1,1
1,1,0,0,0,0,0,0,0,0,0,0,0,0,0,1,1
1,1,0,0,0,0,0,0,0,0,0,0,0,0,0,1,1
1,1,0,0,0,0,0,0,0,0,0,0,0,0,0,1,1
1,1,1,1,1,1,1,1,1,1,1,1,1,1,1,1,1
1,1,1,1,1,1,1,1,1,1,1,1,1,1,1,1,1
endlayer

# 10
layer
1,1,1,1,1,1,1,1,1,1,1,1,1,1,1,1,1
1,1,1,1,1,1,1,1,1,1,1,1,1,1,1,1,1
1,1,0,0,0,0,0,0,0,0,0,0,0,0,0,1,1
1,1,0,0,0,0,0,0,0,0,0,0,0,0,0,1,1
1,1,0,0,0,0,16,0,0,0,16,0,0,0,0,1,1
1,1,0,0,0,2,2,2,2,2,2,2,0,0,0,1,1
1,1,0,0,17,2,5,5,5,5,5,2,17,0,0,1,1
1,1,0,0,0,2,5,5,5,5,5,2,0,0,0,1,1
1,1,0,0,0,2,5,5,5,5,5,2,15,0,0,1,1
1,1,0,0,0,2,5,5,5,5,5,2,0,0,0,1,1
1,1,0,0,17,2,5,5,5,5,5,2,17,0,0,1,1
1,1,0,0,0,2,2,2,2,2,2,2,0,0,0,1,1
1,1,0,0,0,0,16,0,0,0,16,0,0,0,0,1,1
1,1,0,0,0,0,0,0,0,0,0,0,0,0,0,1,1
1,1,0,0,0,0,0,0,0,0,0,0,0,0,0,1,1
1,1,1,1,1,1,1,1,1,1,1,1,1,1,1,1,1
1,1,1,1,1,1,1,1,1,1,1,1,1,1,1,1,1
endlayer

# 11
layer
1,1,1,1,1,1,1,1,1,1,1,1,1,1,1,1,1
1,1,1,1,1,1,1,1,1,1,1,1,1,1,1,1,1
1,1,0,0,0,0,0,0,0,0,0,0,0,0,0,1,1
1,1,0,0,0,0,0,0,0,0,0,0,0,0,0,1,1
1,1,0,0,0,0,0,0,0,0,0,0,0,0,0,1,1
1,1,0,0,0,2,2,2,2,2,2,2,0,0,0,1,1
1,1,0,0,0,2,0,0,0,0,0,2,0,0,0,1,1
1,1,0,0,0,2,0,0,0,0,0,2,0,0,0,1,1
1,1,0,0,0,2,0,0,0,0,0,0,0,0,0,1,1
1,1,0,0,0,2,0,0,0,0,0,2,0,0,0,1,1
1,1,0,0,0,2,0,0,0,0,0,2,0,0,0,1,1
1,1,0,0,0,2,2,2,2,2,2,2,0,0,0,1,1
1,1,0,0,0,0,0,0,0,0,0,0,0,0,0,1,1
1,1,0,0,0,0,0,0,0,0,0,0,0,0,0,1,1
1,1,0,0,0,0,0,0,0,0,0,0,0,0,0,1,1
1,1,1,1,1,1,1,1,1,1,1,1,1,1,1,1,1
1,1,1,1,1,1,1,1,1,1,1,1,1,1,1,1,1
endlayer

# 12
layer
1,1,1,1,1,1,1,1,1,1,1,1,1,1,1,1,1
1,1,1,1,1,1,1,1,1,1,1,1,1,1,1,1,1
1,1,0,0,0,0,0,0,0,0,0,0,0,0,0,1,1
1,1,0,0,0,0,0,0,0,0,0,0,0,0,0,1,1
1,1,0,0,0,0,0,0,0,0,0,0,0,0,0,1,1
1,1,0,0,0,1,1,1,1,1,1,1,0,0,0,1,1
1,1,0,0,0,1,0,0,0,0,0,1,0,0,0,1,1
1,1,0,0,0,1,0,0,0,0,0,1,0,0,0,1,1
1,1,0,0,0,1,0,0,0,0,0,0,0,0,0,1,1
1,1,0,0,0,1,0,0,0,0,0,1,0,0,0,1,1
1,1,0,0,0,1,0,0,0,0,0,1,0,0,0,1,1
1,1,0,0,0,1,1,1,1,1,1,1,0,0,0,1,1
1,1,0,0,0,0,0,0,0,0,0,0,0,0,0,1,1
1,1,0,0,0,0,0,0,0,0,0,0,0,0,0,1,1
1,1,0,0,0,0,0,0,0,0,0,0,0,0,0,1,1
1,1,1,1,1,1,1,1,1,1,1,1,1,1,1,1,1
1,1,1,1,1,1,1,1,1,1,1,1,1,1,1,1,1
endlayer


