# Chisel/Biomes o' Plenty PINK HOUSE
# Created by Ruins mod version 17.1 Ingame Parser
# authoring Player: Jordan_Greywolf

# Made for MC 1.12 with Biomes o' Plenty & Chisel Mod
# Created (MC 1.12): 20 Jul 2018

biomesToSpawnIn=birch_forest,brushland,cherry_blossom_grove,enchanted_forest,flower_field,flower_island,grassland,land_of_lakes,lavender_fields,mutated_plains,oak_savannah,pasture,plains,prairie,seasonal_forest

uniqueMinDistance=2000

weight=1
embed_into_distance=6
acceptable_target_blocks=

unacceptable_target_blocks=lava,flowing_lava,water,flowing_water,cloud,Natura:cloud,red_mushroom_block,brown_mushroom_block,oak_stairs,spruce_stairs,dark_oak_stairs,birch_stairs,jungle_stairs,acacia_stairs,cobblestone,lava,flowing_lava,slime_congealed,slime_dirt,slime_grass,command_block,planks,planks2,concrete,cobblestone,stonebrick,brick_block,glass,torch,oak_stairs,stone_stairs,brick_stairs,stone_brick_stairs,nether_brick_stairs,sandstone_stairs,spruce_stairs,birch_stairs,jungle_stairs,quartz_stairs,acacia_stairs,dark_oak_stairs,cobblestone_wall,stone_slab,double_stone_slab,stone_slab2,wooden_slab,double_wooden_slab,nether_brick

dimensions=27,17,13
allowable_overhang=9
max_leveling=6
leveling_buffer=-1
preserve_water=0
preserve_lava=0

rule1=0,100,preserveBlock

rule2=0,100,chisel:concrete_pink-1,chisel:concrete_pink-2,chisel:concrete_pink1-8

rule3=0,100,minecraft:magenta_glazed_terracotta-0,minecraft:magenta_glazed_terracotta-1,minecraft:magenta_glazed_terracotta-2,minecraft:magenta_glazed_terracotta-3

rule4=0,100,chisel:energizedvoidstone-2
rule5=0,100,chisel:valentines-4
rule6=0,100,minecraft:purpur_stairs-6
rule7=0,100,minecraft:purpur_stairs-3
rule8=0,100,biomesoplenty:mahogany_door_block-0
rule9=0,100,ChestGenHook:chests/simple_dungeon:5-3

rule10=0,100,IInventory;minecraft:chest;minecraft:stained_glass#32#6#0+minecraft:porkchop#8#0#2+minecraft:concrete_powder#32#6#3+minecraft:concrete_powder#32#2#5+minecraft:wool#32#6#7+minecraft:red_flower#6#7#9+minecraft:wool#32#2#10+minecraft:stained_glass#32#6#11+minecraft:stained_glass#32#2#13+minecraft:concrete_powder#32#2#17+minecraft:concrete_powder#32#6#18+minecraft:wool#32#2#21+minecraft:porkchop#8#0#23+minecraft:wool#32#6#24+minecraft:stained_glass#32#2#25+minecraft:red_flower#6#7#26-2


#rule11=0,100,minecraft:wall_banner-4
rule11=0,100,teBlock;minecraft:wall_banner;{x:0,y:0,z:0,id:"minecraft:banner",Base:9}-4

rule12=0,100,CommandBlock:RUINSTRIGGER /setblock ~ ~-1 ~ mob_spawner 0 replace {SpawnCount:6,MaxNearbyEntities:12,RequiredPlayerRange:50,SpawnData:{id:"minecraft:zombie",Silent:1,HandItems:[{id:"minecraft:wool",Damage:6,Count:4},{id:"minecraft:concrete_powder",Damage:6,Count:4}],HandDropChances:[0.5F,0.5F],ArmorItems:[{},{},{},{id:"minecraft:stained_glass",Damage:6,Count:4}],ArmorDropChances:[0F,0F,0F,2F]}}:@

rule13=0,100,biomesoplenty:mahogany_door_block-8
rule14=0,100,chisel:valentines-2

#rule15=0,100,minecraft:wall_banner-3
rule15=0,100,teBlock;minecraft:wall_banner;{x:0,y:0,z:0,id:"minecraft:banner",Base:9}-3

#rule16=0,100,minecraft:wall_banner-2
rule16=0,100,teBlock;minecraft:wall_banner;{x:0,y:0,z:0,id:"minecraft:banner",Base:9}-2

rule17=0,100,minecraft:purpur_slab-8
rule18=0,100,minecraft:pink_glazed_terracotta-0
rule19=0,100,minecraft:pink_glazed_terracotta-3
rule20=0,100,minecraft:pink_glazed_terracotta-2
rule21=0,100,minecraft:pink_glazed_terracotta-1
rule22=0,100,minecraft:double_plant-5
rule23=0,100,minecraft:red_flower-7
rule24=0,100,chisel:valentines-5
rule25=0,100,minecraft:purpur_stairs-2
rule26=0,100,minecraft:purpur_stairs-7
rule27=0,100,chisel:valentines-9
rule28=0,100,biomesoplenty:mahogany_door_block-0
rule29=0,100,minecraft:wool-2
rule30=0,100,minecraft:purpur_stairs-1
rule31=0,100,minecraft:purpur_slab-0
rule32=0,100,minecraft:double_plant-10
rule33=0,100,minecraft:stained_glass_pane-6

# Pink Tulip Flower Pot
rule34=0,100,teBlock;minecraft:flower_pot;{Item:"minecraft:red_flower",x:0
,y:0,z:0,Data:7,id:"minecraft:flower_pot"}-0

rule35=0,100,biomesoplenty:mahogany_door_block-8
#rule36=0,100,minecraft:wall_banner-5
rule36=0,100,teBlock;minecraft:wall_banner;{x:0,y:0,z:0,id:"minecraft:banner",Base:9}-5

rule37=0,100,minecraft:purpur_stairs-4
rule38=0,100,biomesoplenty:wood_slab_0-10
rule39=0,100,minecraft:purpur_stairs-5
rule40=0,100,biomesoplenty:log_0-6
rule41=0,100,biomesoplenty:log_0-10
rule42=0,100,biomesoplenty:log_0-2
rule43=0,100,chisel:wool_pink-0
rule44=0,100,chisel:concrete_pink1-7
rule45=0,100,minecraft:wool-6
rule46=0,100,chisel:carpet_pink-1
rule47=0,100,minecraft:bed-3
rule48=0,100,minecraft:bed-11
rule49=0,100,chisel:concrete_pink-7
rule50=0,100,biomesoplenty:umbran_fence-0
rule51=0,100,chisel:wool_pink-1
rule52=0,100,biomesoplenty:umbran_stairs-2
rule53=0,100,biomesoplenty:planks_0-2
rule54=0,100,biomesoplenty:umbran_stairs-3
rule55=0,100,biomesoplenty:umbran_stairs-7
rule56=0,100,biomesoplenty:umbran_stairs-6
rule57=0,100,biomesoplenty:wood_slab_0-2
rule58=0,100,biomesoplenty:umbran_stairs-1
rule59=0,100,biomesoplenty:umbran_stairs-0

layer
1,1,1,1,1,1,1,1,1,1,1,1,1
1,1,1,1,1,1,1,1,1,1,1,1,1
1,1,1,1,1,1,1,1,1,1,1,1,1
1,1,1,1,1,1,1,1,1,1,1,1,1
1,1,2,2,2,2,2,2,2,2,2,1,1
1,1,2,3,3,3,3,3,3,3,2,1,1
1,1,2,3,3,3,3,3,3,3,2,1,1
1,1,2,3,3,3,3,3,3,3,2,1,1
1,1,2,2,2,2,3,2,2,2,2,1,1
1,1,2,4,4,3,3,3,4,4,2,1,1
1,1,2,3,4,3,3,3,4,3,2,1,1
5,5,2,4,4,3,3,3,4,4,2,5,5
5,5,2,2,2,2,2,2,2,2,2,5,5
5,5,5,5,5,5,5,5,5,5,5,5,5
5,5,5,5,5,5,5,5,5,5,5,5,5
5,5,5,5,5,5,5,5,5,5,5,5,5
1,5,5,5,5,5,5,5,5,5,5,5,1
endlayer

layer
1,1,1,1,1,1,1,1,1,1,1,1,1
1,1,1,1,1,1,1,1,1,1,1,1,1
1,1,1,1,1,1,1,1,1,1,1,1,1
1,1,1,1,1,1,1,1,1,1,1,1,1
1,1,2,2,2,2,2,2,2,2,2,1,1
1,1,2,0,7,6,0,0,0,0,2,1,1
1,1,2,0,0,0,0,0,0,0,2,1,1
1,1,2,0,0,0,0,0,0,0,2,1,1
1,1,2,2,2,2,0,2,2,2,2,1,1
1,1,2,0,0,0,8,0,0,0,2,1,1
1,1,2,10,0,0,0,0,0,9,2,1,1
1,1,2,0,0,0,0,0,0,0,2,1,1
5,5,2,2,2,2,2,2,2,2,2,5,5
5,5,5,5,5,5,5,5,5,5,5,5,5
5,5,5,5,5,5,5,5,5,5,5,5,5
1,5,5,5,5,5,5,5,5,5,5,5,1
1,1,5,5,5,5,5,5,5,5,5,1,1
endlayer

layer
1,1,1,1,1,1,1,1,1,1,1,1,1
1,1,1,1,1,1,1,1,1,1,1,1,1
1,1,1,1,1,1,1,1,1,1,1,1,1
1,1,1,1,1,1,1,1,1,1,1,1,1
1,1,2,2,2,2,2,2,2,2,2,1,1
1,1,2,0,0,7,6,0,0,0,2,1,1
1,1,2,0,0,0,0,0,0,0,2,1,1
1,1,2,0,0,11,0,11,0,0,2,1,1
1,1,2,2,2,2,12,2,2,2,2,1,1
1,1,2,0,0,0,13,0,0,0,2,1,1
1,1,2,0,0,0,0,0,0,0,2,1,1
1,1,2,0,0,0,0,0,0,0,2,1,1
1,1,2,2,2,2,2,2,2,2,2,1,1
1,5,5,5,5,5,5,5,5,5,5,5,1
1,5,5,5,5,5,5,5,5,5,5,5,1
1,1,5,5,5,5,5,5,5,5,5,1,1
1,1,1,5,5,5,5,5,5,5,1,1,1
endlayer

layer
1,1,1,1,1,1,1,1,1,1,1,1,1
1,1,1,1,1,1,1,1,1,1,1,1,1
1,1,1,1,1,1,1,1,1,1,1,1,1
1,1,1,1,1,1,1,1,1,1,1,1,1
1,1,2,2,2,2,2,2,2,2,2,1,1
1,1,2,0,0,0,7,6,0,0,2,1,1
1,1,2,0,0,0,0,0,0,0,2,1,1
1,1,2,0,0,0,0,0,0,0,2,1,1
1,1,2,2,2,2,14,2,2,2,2,1,1
1,1,2,0,0,0,0,0,0,0,2,1,1
1,1,2,16,0,0,0,0,0,15,2,1,1
1,1,2,0,0,0,0,0,0,0,2,1,1
1,1,2,2,2,2,2,2,2,2,2,1,1
1,1,5,5,5,5,5,5,5,5,5,1,1
1,1,5,5,5,5,5,5,5,5,5,1,1
1,1,1,5,5,5,5,5,5,5,1,1,1
1,1,1,1,5,5,5,5,5,1,1,1,1
endlayer

layer
1,1,1,1,1,1,1,1,1,1,1,1,1
1,1,1,1,1,1,1,1,1,1,1,1,1
1,1,1,1,1,1,1,1,1,1,1,1,1
1,1,1,1,1,1,1,1,1,1,1,1,1
1,1,2,2,2,2,2,2,2,2,2,1,1
1,1,2,0,0,0,0,7,6,17,2,1,1
1,1,2,17,17,17,17,17,17,17,2,1,1
1,1,2,17,17,17,17,17,17,17,2,1,1
1,1,2,2,2,2,2,2,2,2,2,1,1
1,1,2,17,17,17,17,17,17,17,2,1,1
1,1,2,17,17,17,17,17,17,17,2,1,1
1,1,2,17,17,17,17,17,17,17,2,1,1
1,1,2,2,2,2,2,2,2,2,2,1,1
1,1,1,5,5,5,5,5,5,5,1,1,1
1,1,1,5,5,5,5,5,5,5,1,1,1
1,1,1,1,5,5,5,5,5,1,1,1,1
1,1,1,1,1,1,1,1,1,1,1,1,1
endlayer

layer
1,1,1,1,1,1,1,1,1,1,1,1,1
1,1,1,1,1,1,1,1,1,1,1,1,1
1,1,1,1,1,1,1,1,1,1,1,1,1
1,1,1,1,1,1,1,1,1,1,1,1,1
1,1,5,5,5,5,5,5,5,5,5,1,1
1,1,5,0,0,0,0,0,7,18,5,1,1
1,1,5,19,20,19,20,19,20,19,5,1,1
1,1,5,18,21,18,21,18,21,18,5,1,1
1,1,5,19,20,19,20,19,20,19,5,1,1
1,1,5,18,21,18,21,18,21,18,5,1,1
1,1,5,19,20,19,20,19,20,19,5,1,1
1,1,5,18,21,18,21,18,21,18,5,1,1
1,1,5,5,5,5,5,5,5,5,5,1,1
1,1,1,1,5,5,5,5,5,1,1,1,1
1,1,1,1,5,5,5,5,5,1,1,1,1
1,1,1,1,1,1,1,1,1,1,1,1,1
1,1,1,1,1,1,1,1,1,1,1,1,1
endlayer

layer
1,1,1,1,1,1,1,1,1,1,1,1,1
1,1,1,1,1,1,1,1,1,1,1,1,1
1,1,1,1,0,0,0,0,0,1,1,1,1
1,1,22,22,23,22,23,22,23,22,22,1,1
1,22,5,24,14,24,14,24,14,24,5,22,1
1,22,24,0,0,0,0,0,0,0,24,22,1
0,23,14,27,0,0,26,25,0,0,14,0,0
0,22,24,24,24,24,24,24,28,24,24,22,0
0,23,14,29,30,30,29,0,0,0,14,23,0
0,22,24,25,0,0,0,0,0,0,24,22,0
0,23,14,25,0,31,0,0,0,0,14,23,0
1,22,24,29,0,0,0,0,0,0,24,22,1
1,22,5,24,14,24,28,24,14,24,5,22,1
1,1,22,22,0,0,0,0,0,22,22,1,1
1,1,1,1,0,0,0,0,0,1,1,1,1
1,1,1,1,1,1,1,1,1,1,1,1,1
1,1,1,1,1,1,1,1,1,1,1,1,1
endlayer

layer
1,1,1,1,1,1,1,1,1,1,1,1,1
1,1,1,0,0,0,0,0,0,0,1,1,1
1,1,0,0,0,0,0,0,0,0,0,1,1
1,0,32,32,0,32,0,32,0,32,32,23,1
0,32,5,24,33,24,33,24,33,24,5,32,0
0,32,24,0,0,0,0,0,0,0,24,32,0
0,0,33,34,0,26,25,0,0,0,33,0,0
0,32,24,24,24,24,24,24,35,24,24,32,0
0,0,33,34,0,0,34,0,0,0,33,0,0
0,32,24,0,0,0,0,0,0,0,24,32,0
0,0,33,0,0,0,0,0,0,0,33,0,0
0,32,24,34,0,0,0,0,0,0,24,32,0
0,32,5,24,33,24,35,24,33,24,5,32,0
1,23,32,32,0,0,0,0,0,32,32,23,1
1,1,0,0,0,0,0,0,0,0,0,1,1
1,1,1,1,0,0,0,0,0,0,1,1,1
1,1,1,1,1,0,0,0,1,1,1,1,1
endlayer

layer
1,1,1,0,0,0,0,0,0,0,1,1,1
1,1,0,0,0,0,0,0,0,0,0,1,1
1,0,0,0,0,0,0,0,0,0,0,0,1
0,0,0,0,0,0,0,0,0,0,0,0,0
0,0,5,24,33,24,33,24,33,24,5,0,0
0,0,24,0,36,0,36,0,36,0,24,0,0
0,0,33,16,26,25,0,0,0,15,33,0,0
0,0,24,24,24,24,24,24,14,24,24,0,0
0,0,33,16,0,0,0,0,0,15,33,0,0
0,0,24,0,0,0,0,0,0,0,24,0,0
0,0,33,16,0,0,0,0,0,15,33,0,0
0,0,24,0,11,0,0,0,11,0,24,0,0
0,0,5,24,33,24,14,24,33,24,5,0,0
0,0,0,0,0,0,0,0,0,0,0,0,0
1,0,0,0,0,0,0,0,0,0,0,0,1
1,1,0,0,0,0,0,0,0,0,0,1,1
1,1,1,0,0,0,0,0,0,0,1,1,1
endlayer

layer
1,1,0,0,0,0,0,0,0,0,0,1,1
1,0,0,0,0,0,0,0,0,0,0,0,1
0,0,0,0,0,0,0,0,0,0,0,0,0
0,0,0,37,0,0,37,0,0,37,0,0,0
0,0,5,24,14,24,14,24,14,24,5,0,0
0,26,24,0,38,0,38,0,38,0,24,6,0
0,0,14,26,25,0,0,0,38,0,14,0,0
0,0,24,24,24,24,24,24,24,24,24,0,0
0,26,14,0,38,0,38,0,38,0,14,6,0
0,0,24,0,38,0,38,0,38,0,24,0,0
0,0,14,0,38,0,38,0,38,0,14,0,0
0,26,24,0,38,0,38,0,38,0,24,6,0
0,0,5,24,14,24,24,24,14,24,5,0,0
0,0,0,39,0,0,39,0,0,39,0,0,0
0,0,0,0,0,0,0,0,0,0,0,0,0
1,0,0,0,0,0,0,0,0,0,0,0,1
1,1,0,0,0,0,0,0,0,0,0,1,1
endlayer

layer
1,0,0,0,0,0,0,0,0,0,0,0,1
0,0,0,0,0,0,0,0,0,0,0,0,0
0,0,0,0,0,0,0,0,0,0,0,0,0
0,40,41,41,41,41,41,41,41,41,41,40,0
0,42,43,43,43,43,43,43,43,43,43,42,0
0,42,43,43,43,43,43,43,43,43,43,42,0
0,42,43,25,0,0,0,0,0,0,43,42,0
0,42,43,43,43,43,43,43,43,43,43,42,0
0,42,43,43,43,43,43,43,43,43,43,42,0
0,42,43,43,43,43,43,43,43,43,43,42,0
0,42,43,43,43,43,43,43,43,43,43,42,0
0,42,43,43,43,43,43,43,43,43,43,42,0
0,42,43,43,43,43,43,43,43,43,43,42,0
0,40,41,41,41,41,41,41,41,41,41,40,0
0,0,0,0,0,0,0,0,0,0,0,0,0
0,0,0,0,0,0,0,0,0,0,0,0,0
1,0,0,0,0,0,0,0,0,0,0,0,1
endlayer

layer
0,0,0,0,0,0,0,0,0,0,0,0,0
0,0,0,0,0,0,0,0,0,0,0,0,0
0,0,0,0,0,0,0,0,0,0,0,0,0
0,40,44,44,40,44,44,44,40,44,44,40,0
0,44,0,0,0,45,17,45,0,0,0,44,0
0,44,0,0,0,0,0,0,0,0,0,44,0
0,40,0,0,0,0,0,0,0,0,0,40,0
0,44,0,0,0,0,0,0,0,0,0,44,0
0,44,0,0,0,0,0,0,0,0,0,44,0
0,44,0,0,0,45,45,45,0,0,0,44,0
0,40,0,0,46,31,47,31,46,0,0,40,0
0,44,0,0,46,31,48,31,46,0,0,44,0
0,44,27,0,0,45,45,45,0,0,27,44,0
0,40,44,44,40,44,44,44,40,44,44,40,0
0,0,0,0,0,0,0,0,0,0,0,0,0
0,0,0,0,0,0,0,0,0,0,0,0,0
0,0,0,0,0,0,0,0,0,0,0,0,0
endlayer

layer
0,0,0,0,0,0,0,0,0,0,0,0,0
0,0,0,0,0,0,0,0,0,0,0,0,0
0,0,0,0,0,0,0,0,0,0,0,0,0
0,40,49,49,40,49,33,49,40,49,49,40,0
0,49,0,0,0,46,46,46,0,0,0,49,0
0,49,0,0,0,0,0,0,0,0,0,49,0
0,40,0,0,0,0,0,0,0,0,0,40,0
0,49,0,0,0,0,0,0,0,0,0,49,0
0,33,0,0,0,0,0,0,0,0,0,33,0
0,49,0,0,0,50,0,50,0,0,0,49,0
0,40,0,0,0,0,0,0,0,0,0,40,0
0,49,0,0,0,0,0,0,0,0,0,49,0
0,49,34,0,0,50,0,50,0,0,34,49,0
0,40,49,49,40,49,33,49,40,49,49,40,0
0,0,0,0,0,0,0,0,0,0,0,0,0
0,0,0,0,0,0,0,0,0,0,0,0,0
0,0,0,0,0,0,0,0,0,0,0,0,0
endlayer

layer
0,0,0,0,0,0,0,0,0,0,0,0,0
0,0,0,0,0,0,0,0,0,0,0,0,0
0,0,0,0,0,0,0,0,0,0,0,0,0
0,40,49,49,40,49,33,49,40,49,49,40,0
0,49,0,0,0,0,36,0,0,0,0,49,0
0,49,0,0,0,0,0,0,0,0,0,49,0
0,40,0,0,0,0,0,0,0,0,0,40,0
0,49,0,0,0,0,0,0,0,0,0,49,0
0,33,16,0,0,11,11,11,0,0,15,33,0
0,49,0,0,15,50,50,50,16,0,0,49,0
0,40,0,0,0,0,0,0,0,0,0,40,0
0,49,0,0,0,0,0,0,0,0,0,49,0
0,49,0,0,15,50,11,50,16,0,0,49,0
0,40,49,49,40,49,33,49,40,49,49,40,0
0,0,0,0,0,0,0,0,0,0,0,0,0
0,0,0,0,0,0,0,0,0,0,0,0,0
0,0,0,0,0,0,0,0,0,0,0,0,0
endlayer

layer
0,0,0,0,0,0,0,0,0,0,0,0,0
0,0,0,0,0,0,0,0,0,0,0,0,0
0,0,0,0,0,0,0,0,0,0,0,0,0
0,40,44,44,40,44,44,44,40,44,44,40,0
0,44,0,0,0,0,0,0,0,0,0,44,0
0,44,0,0,0,0,0,0,0,0,0,44,0
0,40,0,0,0,0,0,0,0,0,0,40,0
0,44,0,0,0,0,0,0,0,0,0,44,0
0,44,0,0,0,0,0,0,0,0,0,44,0
0,44,0,0,0,46,51,46,0,0,0,44,0
0,40,0,0,0,51,51,51,0,0,0,40,0
0,44,0,0,0,51,51,51,0,0,0,44,0
0,44,0,0,0,46,51,46,0,0,0,44,0
0,40,44,44,40,44,44,44,40,44,44,40,0
0,0,0,0,0,0,0,0,0,0,0,0,0
0,0,0,0,0,0,0,0,0,0,0,0,0
0,0,0,0,0,0,0,0,0,0,0,0,0
endlayer

layer
0,0,0,0,0,0,0,0,0,0,0,0,0
0,0,0,0,0,0,0,0,0,0,0,0,0
0,0,0,0,0,0,0,0,0,0,0,0,0
0,40,41,41,40,41,41,41,40,41,41,40,0
0,42,0,0,0,0,0,0,0,0,0,42,0
0,42,0,0,0,0,0,0,0,0,0,42,0
0,40,0,0,0,0,0,0,0,0,0,40,0
0,42,0,0,0,0,0,0,0,0,0,42,0
0,42,0,0,0,0,0,0,0,0,0,42,0
0,42,0,0,0,0,0,0,0,0,0,42,0
0,40,0,0,0,0,46,0,0,0,0,40,0
0,42,0,0,0,0,46,0,0,0,0,42,0
0,42,0,0,0,0,0,0,0,0,0,42,0
0,40,41,41,40,41,41,41,40,41,41,40,0
0,0,0,0,0,0,0,0,0,0,0,0,0
0,0,0,0,0,0,0,0,0,0,0,0,0
0,0,0,0,0,0,0,0,0,0,0,0,0
endlayer

layer
0,0,0,0,0,0,0,0,0,0,0,0,0
0,0,0,0,0,0,0,0,0,0,0,0,0
54,53,0,0,0,0,0,0,0,0,0,53,52
54,53,44,44,40,44,44,44,40,44,44,53,52
54,53,0,0,0,0,0,0,0,0,0,53,52
54,53,0,0,0,0,0,0,0,0,0,53,52
54,53,0,0,0,0,0,0,0,0,0,53,52
54,53,0,0,0,0,0,0,0,0,0,53,52
54,53,0,0,0,0,0,0,0,0,0,53,52
54,53,0,0,0,0,0,0,0,0,0,53,52
54,53,0,0,0,0,0,0,0,0,0,53,52
54,53,0,0,0,0,0,0,0,0,0,53,52
54,53,0,0,0,0,0,0,0,0,0,53,52
54,53,44,44,40,44,44,44,40,44,44,53,52
54,53,0,0,0,0,0,0,0,0,0,53,52
0,0,0,0,0,0,0,0,0,0,0,0,0
0,0,0,0,0,0,0,0,0,0,0,0,0
endlayer

layer
0,0,0,0,0,0,0,0,0,0,0,0,0
0,0,0,0,0,0,0,0,0,0,0,0,0
0,53,0,0,0,0,0,0,0,0,0,53,0
0,53,49,49,40,49,33,49,40,49,49,53,0
0,53,0,0,0,0,0,0,0,0,0,53,0
0,53,0,0,0,0,0,0,0,0,0,53,0
0,53,0,0,0,0,0,0,0,0,0,53,0
0,53,0,0,0,0,0,0,0,0,0,53,0
0,53,0,0,0,0,0,0,0,0,0,53,0
0,53,0,0,0,0,0,0,0,0,0,53,0
0,53,0,0,0,0,0,0,0,0,0,53,0
0,53,0,0,0,0,0,0,0,0,0,53,0
0,53,0,0,0,0,0,0,0,0,0,53,0
0,53,49,49,40,49,33,49,40,49,49,53,0
0,53,0,0,0,0,0,0,0,0,0,53,0
0,0,0,0,0,0,0,0,0,0,0,0,0
0,0,0,0,0,0,0,0,0,0,0,0,0
endlayer

layer
0,0,0,0,0,0,0,0,0,0,0,0,0
0,0,0,0,0,0,0,0,0,0,0,0,0
0,54,56,0,0,0,0,0,0,0,55,52,0
0,54,49,49,40,49,33,49,40,49,49,52,0
0,54,56,0,0,0,36,0,0,0,55,52,0
0,54,56,0,0,0,0,0,0,0,55,52,0
0,54,56,0,0,0,0,0,0,0,55,52,0
0,54,56,0,0,0,0,0,0,0,55,52,0
0,54,56,0,0,0,0,0,0,0,55,52,0
0,54,56,0,0,0,0,0,0,0,55,52,0
0,54,56,0,0,0,0,0,0,0,55,52,0
0,54,56,0,0,0,0,0,0,0,55,52,0
0,54,56,0,0,0,11,0,0,0,55,52,0
0,54,49,49,40,49,33,49,40,49,49,52,0
0,54,56,0,0,0,0,0,0,0,55,52,0
0,0,0,0,0,0,0,0,0,0,0,0,0
0,0,0,0,0,0,0,0,0,0,0,0,0
endlayer

layer
0,0,0,0,0,0,0,0,0,0,0,0,0
0,0,0,0,0,0,0,0,0,0,0,0,0
0,0,54,56,38,0,0,0,38,55,52,0,0
0,0,54,49,40,49,33,49,40,49,52,0,0
0,0,54,56,38,0,36,0,38,55,52,0,0
0,0,54,56,38,0,0,0,38,55,52,0,0
0,0,54,56,38,0,0,0,38,55,52,0,0
0,0,54,56,38,0,0,0,38,55,52,0,0
0,0,54,56,38,0,0,0,38,55,52,0,0
0,0,54,56,38,0,0,0,38,55,52,0,0
0,0,54,56,38,0,0,0,38,55,52,0,0
0,0,54,56,38,0,0,0,38,55,52,0,0
0,0,54,56,38,0,11,0,38,55,52,0,0
0,0,54,49,40,49,33,49,40,49,52,0,0
0,0,54,56,38,0,0,0,38,55,52,0,0
0,0,0,0,0,0,0,0,0,0,0,0,0
0,0,0,0,0,0,0,0,0,0,0,0,0
endlayer

layer
0,0,0,0,0,0,0,0,0,0,0,0,0
0,0,0,0,0,0,0,0,0,0,0,0,0
0,0,0,57,54,56,0,55,52,57,0,0,0
0,0,0,57,54,44,44,44,52,57,0,0,0
0,0,0,57,54,56,0,55,52,57,0,0,0
0,0,0,57,54,56,0,55,52,57,0,0,0
0,0,0,57,54,56,0,55,52,57,0,0,0
0,0,0,57,54,56,0,55,52,57,0,0,0
0,0,0,57,54,56,0,55,52,57,0,0,0
0,0,0,57,54,56,0,55,52,57,0,0,0
0,0,0,57,54,56,0,55,52,57,0,0,0
0,0,0,57,54,56,0,55,52,57,0,0,0
0,0,0,57,54,56,0,55,52,57,0,0,0
0,0,0,57,54,44,44,44,52,57,0,0,0
0,0,0,57,54,56,0,55,52,57,0,0,0
0,0,0,0,0,0,0,0,0,0,0,0,0
0,0,0,0,0,0,0,0,0,0,0,0,0
endlayer

layer
0,0,0,0,0,0,0,0,0,0,0,0,0
0,0,0,0,0,0,0,0,0,0,0,0,0
0,0,0,0,0,57,53,57,0,0,0,0,0
0,0,0,0,0,57,53,57,0,0,0,0,0
0,0,0,0,0,57,53,57,0,0,0,0,0
0,0,0,0,0,57,53,57,0,0,0,0,0
0,0,0,0,0,57,58,57,0,0,0,0,0
0,0,0,0,0,57,57,57,0,0,0,0,0
0,0,0,0,0,57,57,57,0,0,0,0,0
0,0,0,0,0,57,57,57,0,0,0,0,0
0,0,0,0,0,57,59,57,0,0,0,0,0
0,0,0,0,0,57,53,57,0,0,0,0,0
0,0,0,0,0,57,53,57,0,0,0,0,0
0,0,0,0,0,57,53,57,0,0,0,0,0
0,0,0,0,0,57,53,57,0,0,0,0,0
0,0,0,0,0,0,0,0,0,0,0,0,0
0,0,0,0,0,0,0,0,0,0,0,0,0
endlayer

layer
0,0,0,0,0,0,0,0,0,0,0,0,0
0,0,0,0,0,0,0,0,0,0,0,0,0
0,0,0,0,0,0,53,0,0,0,0,0,0
0,0,0,0,0,0,53,0,0,0,0,0,0
0,0,0,0,0,0,58,0,0,0,0,0,0
0,0,0,0,0,0,57,0,0,0,0,0,0
0,0,0,0,0,0,0,0,0,0,0,0,0
0,0,0,0,0,0,0,0,0,0,0,0,0
0,0,0,0,0,0,0,0,0,0,0,0,0
0,0,0,0,0,0,0,0,0,0,0,0,0
0,0,0,0,0,0,0,0,0,0,0,0,0
0,0,0,0,0,0,57,0,0,0,0,0,0
0,0,0,0,0,0,59,0,0,0,0,0,0
0,0,0,0,0,0,53,0,0,0,0,0,0
0,0,0,0,0,0,53,0,0,0,0,0,0
0,0,0,0,0,0,0,0,0,0,0,0,0
0,0,0,0,0,0,0,0,0,0,0,0,0
endlayer

layer
0,0,0,0,0,0,0,0,0,0,0,0,0
0,0,0,0,0,0,0,0,0,0,0,0,0
0,0,0,0,0,0,53,0,0,0,0,0,0
0,0,0,0,0,0,57,0,0,0,0,0,0
0,0,0,0,0,0,0,0,0,0,0,0,0
0,0,0,0,0,0,0,0,0,0,0,0,0
0,0,0,0,0,0,0,0,0,0,0,0,0
0,0,0,0,0,0,0,0,0,0,0,0,0
0,0,0,0,0,0,0,0,0,0,0,0,0
0,0,0,0,0,0,0,0,0,0,0,0,0
0,0,0,0,0,0,0,0,0,0,0,0,0
0,0,0,0,0,0,0,0,0,0,0,0,0
0,0,0,0,0,0,0,0,0,0,0,0,0
0,0,0,0,0,0,57,0,0,0,0,0,0
0,0,0,0,0,0,53,0,0,0,0,0,0
0,0,0,0,0,0,0,0,0,0,0,0,0
0,0,0,0,0,0,0,0,0,0,0,0,0
endlayer

layer
0,0,0,0,0,0,0,0,0,0,0,0,0
0,0,0,0,0,0,57,0,0,0,0,0,0
0,0,0,0,0,0,53,0,0,0,0,0,0
0,0,0,0,0,0,57,0,0,0,0,0,0
0,0,0,0,0,0,0,0,0,0,0,0,0
0,0,0,0,0,0,0,0,0,0,0,0,0
0,0,0,0,0,0,0,0,0,0,0,0,0
0,0,0,0,0,0,0,0,0,0,0,0,0
0,0,0,0,0,0,0,0,0,0,0,0,0
0,0,0,0,0,0,0,0,0,0,0,0,0
0,0,0,0,0,0,0,0,0,0,0,0,0
0,0,0,0,0,0,0,0,0,0,0,0,0
0,0,0,0,0,0,0,0,0,0,0,0,0
0,0,0,0,0,0,57,0,0,0,0,0,0
0,0,0,0,0,0,53,0,0,0,0,0,0
0,0,0,0,0,0,57,0,0,0,0,0,0
0,0,0,0,0,0,0,0,0,0,0,0,0
endlayer

layer
0,0,0,0,0,0,57,0,0,0,0,0,0
0,0,0,0,0,0,59,0,0,0,0,0,0
0,0,0,0,0,0,53,0,0,0,0,0,0
0,0,0,0,0,0,57,0,0,0,0,0,0
0,0,0,0,0,0,0,0,0,0,0,0,0
0,0,0,0,0,0,0,0,0,0,0,0,0
0,0,0,0,0,0,0,0,0,0,0,0,0
0,0,0,0,0,0,0,0,0,0,0,0,0
0,0,0,0,0,0,0,0,0,0,0,0,0
0,0,0,0,0,0,0,0,0,0,0,0,0
0,0,0,0,0,0,0,0,0,0,0,0,0
0,0,0,0,0,0,0,0,0,0,0,0,0
0,0,0,0,0,0,0,0,0,0,0,0,0
0,0,0,0,0,0,57,0,0,0,0,0,0
0,0,0,0,0,0,53,0,0,0,0,0,0
0,0,0,0,0,0,58,0,0,0,0,0,0
0,0,0,0,0,0,57,0,0,0,0,0,0
endlayer

layer
0,0,0,0,0,0,0,0,0,0,0,0,0
0,0,0,0,0,0,0,0,0,0,0,0,0
0,0,0,0,0,0,59,0,0,0,0,0,0
0,0,0,0,0,0,0,0,0,0,0,0,0
0,0,0,0,0,0,0,0,0,0,0,0,0
0,0,0,0,0,0,0,0,0,0,0,0,0
0,0,0,0,0,0,0,0,0,0,0,0,0
0,0,0,0,0,0,0,0,0,0,0,0,0
0,0,0,0,0,0,0,0,0,0,0,0,0
0,0,0,0,0,0,0,0,0,0,0,0,0
0,0,0,0,0,0,0,0,0,0,0,0,0
0,0,0,0,0,0,0,0,0,0,0,0,0
0,0,0,0,0,0,0,0,0,0,0,0,0
0,0,0,0,0,0,0,0,0,0,0,0,0
0,0,0,0,0,0,58,0,0,0,0,0,0
0,0,0,0,0,0,0,0,0,0,0,0,0
0,0,0,0,0,0,0,0,0,0,0,0,0
endlayer

