# Ninja House - BoP/Chisel Version / No CB
# MC 1.7.10, 25 Oct 2014
# Created by Ruins mod version 13.8 Ingame Parser (original)
# Created by Ruins mod version 17.1 Ingame Parser (chisel/BoP)
# Inspired by "Japanese Geisha House" by SasukeUchiha758 (YouTube tutorial)
# authoring Player: Jordan_Greywolf

# IMPORTANT: Do not include unless you have Chisel AND
#    Biomes o' Plenty mods installed.

# Last Updated: 8 Dec 2018  (CB replaced with teBlock)

uniqueMinDistance=500
spawnMinDistance=500

preventRotation=1


biomesToSpawnIn=autumn hills,autumn woods,autumnal_woods,bamboo forest,bamboo_forest,birch forest,birch_forest,cherry blossom grove,cherry_blossom_grove,jade cliffs,jade_cliffs,seasonal forest,seasonal_forest,rwg_coldforest,rwg_snowforest,rwg_temperateforest

weight=1
embed_into_distance=6
acceptable_target_blocks=

unacceptable_target_blocks=flowing_water,water,flowing_lava,lava,cloud,Natura:Cloud,slime_congealed,slime_dirt,slime_grass,command_block,planks,planks2,concrete,cobblestone,stonebrick,brick_block,glass,torch,oak_stairs,stone_stairs,brick_stairs,stone_brick_stairs,nether_brick_stairs,sandstone_stairs,spruce_stairs,birch_stairs,jungle_stairs,quartz_stairs,acacia_stairs,dark_oak_stairs,cobblestone_wall,stone_slab,double_stone_slab,stone_slab2,wooden_slab,double_wooden_slab,nether_brick

dimensions=23,18,15
allowable_overhang=0
max_leveling=5
leveling_buffer=-1
preserve_water=0
preserve_lava=0
preserve_plants=1

rule1=0,100,preserveBlock
rule2=0,100,minecraft:log2-1
rule3=0,100,minecraft:planks-5

# Silence "successfully placed" messages
# rule4=0,100,CommandBlock:RUINSTRIGGER /gamerule commandBlockOutput false:@
rule4=0,100,minecraft:planks-5

rule5=0,100,minecraft:planks-0

# Ninja!

rule6=0,100,teBlock;minecraft:mob_spawner;{SpawnData:{id:Skeleton,Silent:1,CustomName:"Ninja Swordsman", HandItems:[{Count:1,id:stone_sword,tag:{ench:[{id:16,lvl:5}]}},{}],ArmorItems:[{id:leather_boots,Count:1,tag:{display:{Name:"Ninja Foot Wraps",color:0}}},{id:leather_leggings,Count:1,tag:{display:{Name:"Ninja Pants",color:0}}},{id:leather_chestplate,Count:1,tag:{display:{Name:"Ninja Garb",color:0}}},{Count:1,id:wool,Damage:15,tag:{display:{Name:"Ninja Cowl"}}}]},id:"minecraft:mob_spawner"}-0


# Ninja Archer!
rule7=0,100,teBlock;minecraft:mob_spawner;{SpawnData:{id:skeleton,CustomName:"Ninja Archer", HandItems:[{Count:1,id:bow,tag:{ench:[{id:49,lvl:5}]}},{Count:8,id:arrow}],ArmorItems:[{id:leather_boots,Count:1,tag:{display:{Name:"Ninja Foot Wraps",color:0}}},{id:leather_leggings,Count:1,tag:{display:{Name:"Ninja Pants",color:0}}},{id:leather_chestplate,Count:1,tag:{display:{Name:"Ninja Garb",color:0}}},{Count:1,id:wool,Damage:15,tag:{display:{Name:"Ninja Cowl"}}}]},id:"minecraft:mob_spawner"}-0

# Interior areas where we DO NOT want plants intruding
rule8=0,100,minecraft:air

# Bamboo tatami mats
rule9=0,100,biomesoplenty:bamboo_thatching-0
rule10=0,100,minecraft:wooden_slab-5

# House-building materials
rule11=0,100,IInventory;minecraft:chest;biomesoplenty:bamboo_thatching#64#0#0+chisel:paper#64#3#3+minecraft:planks#64#5#7+biomesoplenty:sapling_0#8#2#10+chisel:paper#64#0#11+chisel:paper#64#6#14+minecraft:nether_brick_fence#64#0#21+chisel:paper#64#8#24-3

# Random loot
rule12=0,100,ChestGenHook:chests/simple_dungeon:5-3

rule13=0,100,minecraft:nether_brick_fence-0
rule14=0,100,chisel:paper-0
rule15=0,100,minecraft:grass-0
rule16=0,100,minecraft:trapdoor-13
rule17=0,100,minecraft:trapdoor-12
rule18=0,100,minecraft:trapdoor-15
rule19=0,100,minecraft:wooden_slab-13
rule20=0,100,minecraft:trapdoor-14
rule21=0,100,chisel:paper-6
rule22=0,100,biomesoplenty:bamboo-0
rule23=0,100,minecraft:carpet-0
rule24=0,100,biomesoplenty:leaves_0-6
rule25=0,100,minecraft:dark_oak_stairs-3
rule26=0,100,minecraft:dark_oak_stairs-2
rule27=0,100,minecraft:dark_oak_stairs-1
rule28=0,100,minecraft:log2-9
rule29=0,100,minecraft:log2-5
rule30=0,100,minecraft:dark_oak_stairs-0
rule31=0,100,chisel:paper-3
rule32=0,100,chisel:paper-8
rule33=0,100,minecraft:dark_oak_stairs-7
rule34=0,100,minecraft:dark_oak_stairs-6
rule35=0,100,minecraft:dark_oak_stairs-4
rule36=0,100,minecraft:dark_oak_stairs-5

layer
1,1,1,1,1,1,1,1,1,1,1,1,1,1,1
1,2,3,3,3,3,3,3,3,3,3,3,3,2,1
1,3,3,3,3,3,3,3,3,3,3,3,3,3,1
1,3,3,3,3,3,3,3,3,3,3,3,3,3,1
1,3,3,3,3,3,3,3,3,3,3,3,3,3,1
1,3,3,3,3,3,3,3,3,3,3,3,3,3,1
1,3,3,3,3,3,3,3,3,3,3,3,3,3,1
1,3,3,3,3,3,3,3,3,3,3,3,3,3,1
1,3,3,3,3,3,3,3,3,3,3,3,3,3,1
1,3,3,3,3,3,3,3,3,3,3,3,3,3,1
1,3,3,3,3,3,3,3,3,3,3,3,3,3,1
1,3,3,3,3,3,3,3,3,3,3,3,3,3,1
1,3,3,3,3,3,3,3,3,3,3,3,3,3,1
1,3,3,3,3,3,3,3,3,3,3,3,3,3,1
1,3,3,3,3,3,3,3,3,3,3,3,3,3,1
1,3,3,3,3,3,3,3,3,3,3,3,3,3,1
1,2,3,3,3,3,3,3,3,3,3,3,3,2,1
1,1,1,1,1,1,1,1,1,1,1,1,1,1,1
endlayer

layer
1,1,1,1,1,1,1,1,1,1,1,1,1,1,1
1,2,3,3,3,3,3,3,3,3,3,3,3,2,1
1,3,3,3,3,3,3,3,3,3,3,3,3,3,1
1,3,3,3,3,3,3,3,3,3,3,3,3,3,1
1,3,3,3,3,3,3,3,3,3,3,3,3,3,1
1,3,3,3,3,3,3,3,3,3,3,3,3,3,1
1,3,3,3,3,3,3,3,3,3,3,3,3,3,1
1,3,3,3,3,3,3,3,3,3,3,3,3,3,1
1,3,3,3,3,3,3,3,3,3,3,3,3,3,1
1,3,3,3,3,3,3,3,3,3,3,3,3,3,1
1,3,3,3,3,3,3,3,3,3,3,3,3,3,1
1,3,3,3,3,3,3,3,3,3,3,3,3,3,1
1,3,3,3,3,3,3,3,3,3,3,3,3,3,1
1,3,3,3,3,3,3,3,3,3,3,3,3,3,1
1,3,3,3,3,3,3,3,3,3,3,3,3,3,1
1,3,3,3,3,3,3,3,3,3,3,3,3,3,1
1,2,3,3,3,3,3,3,3,3,3,3,3,2,1
1,1,1,1,1,1,1,1,1,1,1,1,1,1,1
endlayer

layer
1,1,1,1,1,1,1,1,1,1,1,1,1,1,1
1,2,3,3,3,3,3,3,3,3,3,3,3,2,1
1,3,3,3,3,3,3,3,3,3,3,3,3,3,1
1,3,3,3,3,3,3,3,3,3,3,3,3,3,1
1,3,3,3,3,3,3,3,3,3,3,3,3,3,1
1,3,3,3,3,3,3,3,3,3,3,3,3,3,1
1,3,3,3,3,3,3,3,3,3,3,3,3,3,1
1,3,3,3,3,3,3,3,3,3,3,3,3,3,1
1,3,3,3,3,3,3,3,3,3,3,3,3,3,1
1,3,3,3,3,3,3,3,3,3,3,3,3,3,1
1,3,3,3,3,3,3,3,3,3,3,3,3,3,1
1,3,3,3,3,3,3,3,3,3,3,3,3,3,1
1,3,3,3,3,3,3,3,3,3,3,3,3,3,1
1,3,3,3,3,3,3,3,3,3,3,3,3,3,1
1,3,3,3,3,3,3,3,3,3,3,3,3,3,1
1,3,3,3,3,3,3,3,3,3,3,3,3,3,1
1,2,3,3,3,3,3,3,3,3,3,3,3,2,1
1,1,1,1,1,1,1,1,1,1,1,1,1,1,1
endlayer

layer
1,1,1,1,1,1,1,1,1,1,1,1,1,1,1
1,2,3,3,3,3,3,3,3,3,3,3,3,2,1
1,3,3,3,3,3,3,3,3,3,3,3,3,3,1
1,3,3,3,3,3,3,3,3,3,3,3,3,3,1
1,3,3,3,3,3,3,3,3,3,3,3,3,3,1
1,3,3,3,3,3,3,3,3,3,3,3,3,3,1
1,3,3,3,3,3,3,3,3,3,3,3,3,3,1
1,3,3,3,3,3,3,3,3,3,3,3,3,3,1
1,3,3,3,3,3,3,3,3,3,3,3,3,3,1
1,3,3,3,3,3,3,3,3,3,3,3,3,3,1
1,3,3,3,3,3,3,3,3,3,3,3,3,3,1
1,3,3,3,3,3,3,3,3,3,3,3,3,3,1
1,3,3,3,3,3,3,3,3,3,3,3,3,3,1
1,3,3,3,3,3,3,3,3,3,3,3,3,3,1
1,3,3,3,3,3,3,3,3,3,3,3,3,3,1
1,3,3,3,3,3,3,3,3,3,3,3,3,3,1
1,2,3,3,3,3,3,3,3,3,3,3,3,2,1
1,1,1,1,1,1,1,1,1,1,1,1,1,1,1
endlayer

layer
1,1,1,1,1,1,1,1,1,1,1,1,1,1,1
1,2,3,3,3,3,3,3,3,3,3,3,3,2,1
1,3,3,3,3,3,3,3,3,3,3,3,3,3,1
1,3,3,3,3,3,3,3,3,3,3,3,3,3,1
1,3,3,3,3,3,3,3,3,3,3,3,3,3,1
1,3,3,3,3,3,3,3,3,3,3,3,3,3,1
1,3,3,3,3,3,3,3,3,3,3,3,3,3,1
1,3,3,3,3,3,3,3,3,3,3,3,3,3,1
1,3,3,3,3,3,3,3,3,3,3,3,3,3,1
1,3,3,3,3,3,3,3,3,3,3,3,3,3,1
1,3,3,3,3,3,3,3,3,3,3,3,3,3,1
1,3,3,3,3,3,3,3,3,3,3,3,3,3,1
1,3,3,3,3,3,3,3,3,3,3,3,3,3,1
1,3,3,3,3,3,3,3,3,3,3,3,3,3,1
1,3,3,3,3,3,3,3,3,3,3,3,3,3,1
1,3,3,3,3,3,3,3,3,3,3,3,3,3,1
1,2,3,3,3,3,3,3,3,3,3,3,3,2,1
1,1,1,1,1,1,1,1,1,1,1,1,1,1,1
endlayer

layer
1,1,1,1,1,1,1,1,1,1,1,1,1,1,1
1,3,3,3,3,3,3,3,3,3,3,3,3,3,1
1,3,3,3,3,3,3,3,3,3,3,3,3,3,1
1,3,3,3,3,3,3,4,3,3,3,3,3,3,1
1,3,3,3,5,5,5,3,5,5,5,3,3,3,1
1,3,3,3,5,5,5,3,5,5,5,3,3,3,1
1,3,3,3,5,5,5,3,5,5,5,3,3,3,1
1,3,3,3,3,3,3,6,3,3,3,3,3,3,1
1,3,3,3,5,5,5,3,5,5,5,3,3,3,1
1,3,3,3,5,5,5,3,5,5,5,3,3,3,1
1,3,3,3,3,3,3,7,3,3,3,3,3,3,1
1,3,3,3,5,5,5,3,5,5,5,3,3,3,1
1,3,3,3,5,5,5,3,5,5,5,3,3,3,1
1,3,3,3,5,5,5,3,5,5,5,3,3,3,1
1,3,3,3,3,3,3,3,3,3,3,3,3,3,1
1,3,3,3,3,3,3,3,3,3,3,3,3,3,1
1,3,3,3,3,3,3,3,3,3,3,3,3,3,1
1,1,1,1,1,1,1,1,1,1,1,1,1,1,1
endlayer

layer
1,1,1,1,1,8,8,8,8,8,1,1,1,1,1
1,3,3,3,3,3,3,3,3,3,3,3,3,3,1
1,3,3,3,3,3,3,3,3,3,3,3,3,3,1
1,3,3,3,3,3,3,3,3,3,3,3,3,3,1
1,3,3,3,9,9,9,3,9,9,9,3,3,3,1
8,3,3,3,9,9,9,3,9,9,9,3,3,3,8
8,3,3,3,9,9,9,3,9,9,9,3,3,3,8
8,3,3,3,3,3,3,3,3,3,3,3,3,3,8
10,3,3,3,9,9,9,11,9,9,9,3,3,3,10
10,3,3,3,9,9,9,12,9,9,9,3,3,3,10
8,3,3,3,3,3,3,3,3,3,3,3,3,3,8
8,3,3,3,9,9,9,3,9,9,9,3,3,3,8
8,3,3,3,9,9,9,3,9,9,9,3,3,3,8
1,3,3,3,9,9,9,3,9,9,9,3,3,3,1
1,3,3,3,3,3,3,3,3,3,3,3,3,3,1
1,3,3,3,3,3,3,3,3,3,3,3,3,3,1
1,3,3,3,3,3,3,3,3,3,3,3,3,3,1
1,1,1,1,1,8,8,8,8,8,1,1,1,1,1
endlayer

layer
1,1,1,8,8,8,8,8,8,8,8,8,1,1,1
1,13,13,13,13,13,13,13,13,13,13,13,13,13,1
1,13,8,8,8,8,8,8,8,8,8,8,8,13,1
8,13,8,2,14,14,14,2,14,14,14,2,8,13,8
8,13,8,14,15,17,8,8,8,16,15,14,8,13,8
8,13,8,14,18,8,8,8,8,8,18,14,8,13,8
8,13,8,14,8,8,8,8,8,8,8,14,8,13,8
8,13,8,2,8,8,8,3,8,8,8,2,8,13,8
8,8,8,8,8,8,8,19,8,8,8,8,8,8,8
8,8,8,8,8,8,8,19,8,8,8,8,8,8,8
8,13,8,2,8,8,8,3,8,8,8,2,8,13,8
8,13,8,14,8,8,8,8,8,8,8,14,8,13,8
8,13,8,14,20,8,8,8,8,8,20,14,8,13,8
8,13,8,14,15,17,8,8,8,16,15,14,8,13,8
8,13,8,2,14,14,14,2,14,14,14,2,8,13,8
1,13,8,8,8,8,8,8,8,8,8,8,8,13,1
1,13,13,13,13,13,13,13,13,13,13,13,13,13,1
1,1,1,8,8,8,8,8,8,8,8,8,1,1,1
endlayer

layer
1,1,8,8,8,8,8,8,8,8,8,8,8,1,1
1,13,8,8,8,8,8,13,8,8,8,8,8,13,1
8,8,8,8,8,8,8,8,8,8,8,8,8,8,8
8,8,8,2,21,21,21,2,21,21,21,2,8,8,8
8,8,8,21,22,8,8,8,8,8,22,21,8,8,8
8,8,8,21,8,8,8,8,8,8,8,21,8,8,8
8,8,8,21,8,8,8,8,8,8,8,21,8,8,8
8,13,8,2,8,8,8,23,8,8,8,2,8,13,8
8,8,8,8,8,8,8,23,8,8,8,8,8,8,8
8,8,8,8,8,8,8,23,8,8,8,8,8,8,8
8,13,8,2,8,8,8,23,8,8,8,2,8,13,8
8,8,8,21,8,8,8,8,8,8,8,21,8,8,8
8,8,8,21,8,8,8,8,8,8,8,21,8,8,8
8,8,8,21,22,8,8,8,8,8,22,21,8,8,8
8,8,8,2,21,21,21,2,21,21,21,2,8,8,8
8,8,8,8,8,8,8,8,8,8,8,8,8,8,8
1,13,8,8,8,8,8,13,8,8,8,8,8,13,1
1,1,8,8,8,8,8,8,8,8,8,8,8,1,1
endlayer

layer
1,8,8,8,8,8,8,8,8,8,8,8,8,8,1
8,13,8,8,8,8,8,13,8,8,8,8,8,13,8
8,8,8,8,8,8,8,8,8,8,8,8,8,8,8
8,8,8,2,21,21,21,2,21,21,21,2,8,8,8
8,8,8,21,24,8,8,8,8,8,24,21,8,8,8
8,8,8,21,8,8,8,8,8,8,8,21,8,8,8
8,8,8,21,8,8,8,8,8,8,8,21,8,8,8
8,13,8,2,8,8,8,8,8,8,8,2,8,13,8
8,8,8,8,8,8,8,8,8,8,8,8,8,8,8
8,8,8,8,8,8,8,8,8,8,8,8,8,8,8
8,13,8,2,8,8,8,8,8,8,8,2,8,13,8
8,8,8,21,8,8,8,8,8,8,8,21,8,8,8
8,8,8,21,8,8,8,8,8,8,8,21,8,8,8
8,8,8,21,24,8,8,8,8,8,24,21,8,8,8
8,8,8,2,21,21,21,2,21,21,21,2,8,8,8
8,8,8,8,8,8,8,8,8,8,8,8,8,8,8
8,13,8,8,8,8,8,13,8,8,8,8,8,13,8
1,8,8,8,8,8,8,8,8,8,8,8,8,8,1
endlayer

layer
8,19,19,19,19,19,19,19,19,19,19,19,19,19,8
19,13,13,13,13,13,13,13,13,13,13,13,13,13,19
19,13,8,8,8,8,8,8,8,8,8,8,8,13,19
19,13,8,2,14,14,14,2,14,14,14,2,8,13,19
19,13,8,14,8,8,8,8,8,8,8,14,8,13,19
19,13,8,14,8,8,8,8,8,8,8,14,8,13,19
19,13,8,14,8,8,8,8,8,8,8,14,8,13,19
19,13,8,2,8,8,8,8,8,8,8,2,8,13,19
19,13,8,14,8,8,8,8,8,8,8,14,8,13,19
19,13,8,14,8,8,8,8,8,8,8,14,8,13,19
19,13,8,2,8,8,8,8,8,8,8,2,8,13,19
19,13,8,14,8,8,8,8,8,8,8,14,8,13,19
19,13,8,14,8,8,8,8,8,8,8,14,8,13,19
19,13,8,14,8,8,8,8,8,8,8,14,8,13,19
19,13,8,2,14,14,14,2,14,14,14,2,8,13,19
19,13,8,8,8,8,8,8,8,8,8,8,8,13,19
19,13,13,13,13,13,13,13,13,13,13,13,13,13,19
8,19,19,19,19,19,19,19,19,19,19,19,19,19,8
endlayer

layer
3,26,10,8,8,8,8,8,8,8,8,8,10,25,3
27,10,10,10,10,10,10,10,10,10,10,10,10,10,27
10,10,19,19,19,19,19,19,19,19,19,19,19,10,10
8,10,19,2,28,28,28,2,28,28,28,2,19,10,8
8,10,19,29,3,8,8,3,8,8,3,29,19,10,8
8,10,19,29,8,8,8,13,8,8,8,29,19,10,8
8,10,19,29,8,8,8,13,8,8,8,29,19,10,8
8,10,19,2,3,13,13,13,13,13,3,2,19,10,8
8,10,19,29,8,8,8,13,8,8,8,29,19,10,8
8,10,19,29,8,8,8,13,8,8,8,29,19,10,8
8,10,19,2,3,13,13,13,13,13,3,2,19,10,8
8,10,19,29,8,8,8,13,8,8,8,29,19,10,8
8,10,19,29,8,8,8,3,8,8,8,29,19,10,8
8,10,19,29,3,8,8,29,8,8,3,29,19,10,8
8,10,19,2,28,28,28,2,28,28,28,2,19,10,8
10,10,19,19,19,19,19,19,19,19,19,19,19,10,10
30,10,10,10,10,10,10,10,10,10,10,10,10,10,30
3,26,10,8,8,8,8,8,8,8,8,8,10,25,3
endlayer

layer
10,8,8,8,8,8,8,8,8,8,8,8,8,8,10
8,8,8,8,8,8,8,8,8,8,8,8,8,8,8
8,8,8,8,8,8,8,8,8,8,8,8,8,8,8
8,8,8,13,13,13,13,13,13,13,13,13,8,8,8
8,8,8,13,2,28,28,2,28,28,2,13,8,8,8
8,8,8,13,29,8,8,8,8,8,29,13,8,8,8
8,8,8,13,29,8,8,8,8,8,29,13,8,8,8
8,8,8,13,2,8,8,8,8,8,2,13,8,8,8
8,8,8,13,29,8,8,8,8,8,29,13,8,8,8
8,8,8,13,29,8,8,8,8,8,29,13,8,8,8
8,8,8,13,2,8,8,8,8,8,2,13,8,8,8
8,8,8,13,29,8,8,8,8,8,29,13,8,8,8
8,8,8,13,29,8,8,8,8,8,29,13,8,8,8
8,8,8,13,2,28,28,2,28,28,2,13,8,8,8
8,8,8,13,13,13,13,13,13,13,13,13,8,8,8
8,8,8,8,8,8,8,8,8,8,8,8,8,8,8
8,8,8,8,8,8,8,8,8,8,8,8,8,8,8
10,8,8,8,8,8,8,8,8,8,8,8,8,8,10
endlayer

layer
8,8,8,8,8,8,8,8,8,8,8,8,8,8,8
8,8,8,8,8,8,8,8,8,8,8,8,8,8,8
8,8,8,8,8,8,8,8,8,8,8,8,8,8,8
8,8,8,13,8,8,8,8,8,8,8,13,8,8,8
8,8,8,8,2,31,31,2,31,31,2,8,8,8,8
8,8,8,8,31,8,8,8,8,8,31,8,8,8,8
8,8,8,8,31,8,8,8,8,8,31,8,8,8,8
8,8,8,8,2,8,8,8,8,8,2,8,8,8,8
8,8,8,8,31,8,8,8,8,8,8,8,8,8,8
8,8,8,8,31,8,8,8,8,8,8,8,8,8,8
8,8,8,8,2,8,8,8,8,8,2,8,8,8,8
8,8,8,8,31,8,8,8,8,8,31,8,8,8,8
8,8,8,8,31,8,8,8,8,8,31,8,8,8,8
8,8,8,8,2,31,31,2,31,31,2,8,8,8,8
8,8,8,13,8,8,8,8,8,8,8,13,8,8,8
8,8,8,8,8,8,8,8,8,8,8,8,8,8,8
8,8,8,8,8,8,8,8,8,8,8,8,8,8,8
8,8,8,8,8,8,8,8,8,8,8,8,8,8,8
endlayer

layer
8,8,8,8,8,8,8,8,8,8,8,8,8,8,8
8,8,8,8,8,8,8,8,8,8,8,8,8,8,8
8,8,8,8,8,8,8,8,8,8,8,8,8,8,8
8,8,8,13,8,8,8,8,8,8,8,13,8,8,8
8,8,8,8,2,32,32,2,32,32,2,8,8,8,8
8,8,8,8,32,8,8,8,8,8,32,8,8,8,8
8,8,8,8,32,8,8,8,8,8,32,8,8,8,8
8,8,8,8,2,8,8,8,8,8,2,8,8,8,8
8,8,8,8,32,8,8,8,8,8,8,8,8,8,8
8,8,8,8,32,8,8,8,8,8,8,8,8,8,8
8,8,8,8,2,8,8,8,8,8,2,8,8,8,8
8,8,8,8,32,8,8,8,8,8,32,8,8,8,8
8,8,8,8,32,8,8,8,8,8,32,8,8,8,8
8,8,8,8,2,32,32,2,32,32,2,8,8,8,8
8,8,8,13,8,8,8,8,8,8,8,13,8,8,8
8,8,8,8,8,8,8,8,8,8,8,8,8,8,8
8,8,8,8,8,8,8,8,8,8,8,8,8,8,8
8,8,8,8,8,8,8,8,8,8,8,8,8,8,8
endlayer

layer
8,8,8,8,8,8,8,8,8,8,8,8,8,8,8
8,8,8,8,8,8,8,8,8,8,8,8,8,8,8
8,8,8,8,8,8,8,8,8,8,8,8,8,8,8
8,8,8,13,8,8,8,8,8,8,8,13,8,8,8
8,8,8,8,2,31,31,2,31,31,2,8,8,8,8
8,8,8,8,31,8,8,8,8,8,31,8,8,8,8
8,8,8,8,31,8,8,8,8,8,31,8,8,8,8
8,8,8,8,2,8,8,8,8,8,2,8,8,8,8
8,8,8,8,31,8,8,8,8,8,8,8,8,8,8
8,8,8,8,31,8,8,8,8,8,8,8,8,8,8
8,8,8,8,2,8,8,8,8,8,2,8,8,8,8
8,8,8,8,31,8,8,8,8,8,31,8,8,8,8
8,8,8,8,31,8,8,8,8,8,31,8,8,8,8
8,8,8,8,2,31,31,2,31,31,2,8,8,8,8
8,8,8,13,8,8,8,8,8,8,8,13,8,8,8
8,8,8,8,8,8,8,8,8,8,8,8,8,8,8
8,8,8,8,8,8,8,8,8,8,8,8,8,8,8
8,8,8,8,8,8,8,8,8,8,8,8,8,8,8
endlayer

layer
8,8,8,8,8,8,8,8,8,8,8,8,8,8,8
8,8,8,8,8,8,8,8,8,8,8,8,8,8,8
8,8,8,8,8,8,8,8,8,8,8,8,8,8,8
8,8,8,13,8,8,8,8,8,8,8,13,8,8,8
8,8,8,8,2,31,31,2,31,31,2,8,8,8,8
8,8,8,8,31,8,8,8,8,8,31,8,8,8,8
8,8,8,8,31,8,8,8,8,8,31,8,8,8,8
8,8,8,8,2,8,8,8,8,8,2,8,8,8,8
8,8,8,8,31,8,8,8,8,8,8,8,8,8,8
8,8,8,8,31,8,8,8,8,8,8,8,8,8,8
8,8,8,8,2,8,8,8,8,8,2,8,8,8,8
8,8,8,8,31,8,8,8,8,8,31,8,8,8,8
8,8,8,8,31,8,8,8,8,8,31,8,8,8,8
8,8,8,8,2,31,31,2,31,31,2,8,8,8,8
8,8,8,13,8,8,8,8,8,8,8,13,8,8,8
8,8,8,8,8,8,8,8,8,8,8,8,8,8,8
8,8,8,8,8,8,8,8,8,8,8,8,8,8,8
8,8,8,8,8,8,8,8,8,8,8,8,8,8,8
endlayer

layer
8,8,8,8,8,8,8,8,8,8,8,8,8,8,8
8,19,3,10,10,10,10,10,10,10,10,10,3,19,8
8,3,19,19,19,19,19,19,19,19,19,19,19,3,8
8,10,19,13,13,13,13,13,13,13,13,13,19,10,8
8,10,19,13,2,28,28,2,28,28,2,13,19,10,8
8,10,19,13,29,13,8,13,8,13,29,13,19,10,8
8,10,19,13,29,8,8,13,8,8,29,13,19,10,8
8,10,19,13,2,13,13,13,13,13,2,13,19,10,8
8,10,19,13,29,8,8,13,8,8,29,13,19,10,8
8,10,19,13,29,8,8,13,8,8,29,13,19,10,8
8,10,19,13,2,13,13,13,13,13,2,13,19,10,8
8,10,19,13,29,8,8,13,8,8,29,13,19,10,8
8,10,19,13,29,13,8,13,8,13,29,13,19,10,8
8,10,19,13,2,28,28,2,28,28,2,13,19,10,8
8,10,19,13,13,13,13,13,13,13,13,13,19,10,8
8,3,19,19,19,19,19,19,19,19,19,19,19,3,8
8,19,3,10,10,10,10,10,10,10,10,10,3,19,8
8,8,8,8,8,8,8,8,8,8,8,8,8,8,0
endlayer

layer
0,8,8,8,8,8,8,8,8,8,8,8,8,8,0
8,10,8,8,8,8,8,8,8,8,8,8,8,10,8
8,8,8,8,8,8,8,8,8,8,8,8,8,8,8
8,8,8,25,30,30,30,30,30,30,30,30,8,8,8
8,8,8,25,2,28,28,2,28,28,2,26,8,8,8
8,8,8,25,29,2,8,8,8,2,29,26,8,8,8
8,8,8,25,29,8,8,8,8,8,29,26,8,8,8
8,8,8,25,2,8,8,8,8,8,2,26,8,8,8
8,8,8,25,29,8,8,8,8,8,29,26,8,8,8
8,8,8,25,29,8,8,8,8,8,29,26,8,8,8
8,8,8,25,2,8,8,8,8,8,2,26,8,8,8
8,8,8,25,29,8,8,8,8,8,29,26,8,8,8
8,8,8,25,29,2,8,8,8,2,29,26,8,8,8
8,8,8,25,2,28,28,2,28,28,2,26,8,8,8
8,8,8,25,27,27,27,27,27,27,27,26,8,8,8
8,8,8,8,8,8,8,8,8,8,8,8,8,8,0
8,10,8,8,8,8,8,8,8,8,8,8,8,10,0
0,8,8,8,8,8,8,8,8,8,8,8,0,0,0
endlayer

layer
0,8,8,8,8,8,8,8,8,8,8,8,8,0,0
8,8,8,8,8,8,8,8,8,8,8,8,8,8,0
8,8,8,8,8,8,8,8,8,8,8,8,8,8,0
8,8,8,8,8,8,8,8,8,8,8,8,8,8,8
8,8,8,8,25,34,8,8,8,33,26,8,8,8,8
8,8,8,8,25,31,31,8,31,31,26,8,8,8,8
8,8,8,8,25,34,8,8,8,33,26,8,8,8,8
8,8,8,8,25,34,8,8,8,33,26,8,8,8,8
8,8,8,8,25,34,8,8,8,33,26,8,8,8,8
8,8,8,8,25,34,8,8,8,33,26,8,8,8,8
8,8,8,8,25,34,8,8,8,33,26,8,8,8,8
8,8,8,8,25,34,8,8,8,33,26,8,8,8,8
8,8,8,8,25,31,31,8,31,31,26,8,8,8,8
8,8,8,8,25,34,8,8,8,33,26,8,8,8,8
8,8,8,8,8,8,8,8,8,8,8,8,8,8,8
0,8,8,8,8,8,8,8,8,8,8,8,8,8,0
0,0,8,8,8,8,8,8,8,8,8,8,8,0,0
0,0,0,8,8,8,8,8,8,8,8,0,0,0,0
endlayer

layer
0,0,8,8,8,8,8,8,8,8,8,8,0,0,0
0,8,8,8,8,8,8,8,8,8,8,8,8,0,0
8,8,8,8,8,8,8,8,8,8,8,8,8,8,0
8,8,8,8,8,8,8,8,8,8,8,8,8,8,0
8,8,8,8,8,25,34,8,33,26,8,8,8,8,8
8,8,8,8,8,25,31,8,31,26,8,8,8,8,8
8,8,8,8,8,25,34,8,33,26,8,8,8,8,8
8,8,8,8,8,25,34,8,33,26,8,8,8,8,8
8,8,8,8,8,25,34,8,33,26,8,8,8,8,8
8,8,8,8,8,25,34,8,33,26,8,8,8,8,8
8,8,8,8,8,25,34,8,33,26,8,8,8,8,8
8,8,8,8,8,25,34,8,33,26,8,8,8,8,8
8,8,8,8,8,25,31,8,31,26,8,8,8,8,8
8,8,8,8,8,25,34,8,33,26,8,8,8,8,8
0,8,8,8,8,8,8,8,8,8,8,8,8,8,0
0,0,8,8,8,8,8,8,8,8,8,8,8,0,0
0,0,0,8,8,8,8,8,8,8,8,0,0,0,0
0,0,0,0,8,8,8,8,8,8,0,0,0,0,0
endlayer

layer
0,0,0,8,8,8,8,8,8,8,0,0,0,0,0
0,0,8,8,8,8,8,8,8,8,8,8,8,0,0
0,8,8,8,8,8,8,8,8,8,8,8,8,0,0
8,8,8,8,8,8,8,8,8,8,8,8,8,8,0
8,8,8,8,8,8,25,19,26,8,8,8,8,8,0
8,8,8,8,8,8,25,19,26,8,8,8,8,8,8
8,8,8,8,8,8,25,19,26,8,8,8,8,8,8
8,8,8,8,8,8,25,19,26,8,8,8,8,8,8
8,8,8,8,8,8,25,19,26,8,8,8,8,8,8
8,8,8,8,8,8,25,19,26,8,8,8,8,8,8
8,8,8,8,8,8,25,19,26,8,8,8,8,8,8
8,8,8,8,8,8,25,19,26,8,8,8,8,8,8
8,8,8,8,8,8,25,19,26,8,8,8,8,8,8
0,8,8,8,8,8,25,19,26,8,8,8,8,8,0
0,0,8,8,8,8,8,8,8,8,8,8,8,0,0
0,0,0,8,8,8,8,8,8,8,8,8,0,0,0
0,0,0,0,8,8,8,8,8,8,8,0,0,0,0
0,0,0,0,0,8,8,8,8,8,0,0,0,0,0
endlayer

layer
0,0,0,0,0,0,8,8,8,0,0,0,0,0,0
0,0,0,0,8,8,8,8,8,8,8,0,0,0,0
0,0,0,8,8,8,8,8,8,8,8,8,0,0,0
0,0,8,8,8,8,8,35,8,8,8,8,8,0,0
0,8,8,8,8,8,8,3,8,8,8,8,8,0,0
0,8,8,8,8,8,8,27,8,8,8,8,8,8,0
8,8,8,8,8,8,8,10,8,8,8,8,8,8,0
8,8,8,8,8,8,8,10,8,8,8,8,8,8,8
8,8,8,8,8,8,8,10,8,8,8,8,8,8,8
8,8,8,8,8,8,8,10,8,8,8,8,8,8,8
8,8,8,8,8,8,8,10,8,8,8,8,8,8,8
0,8,8,8,8,8,8,10,8,8,8,8,8,8,0
0,8,8,8,8,8,8,30,8,8,8,8,8,8,0
0,0,8,8,8,8,8,3,8,8,8,8,8,0,0
0,0,0,8,8,8,8,36,8,8,8,8,0,0,0
0,0,0,0,8,8,8,8,8,8,8,0,0,0,0
0,0,0,0,0,8,8,8,8,8,0,0,0,0,0
0,0,0,0,0,0,0,8,0,0,0,0,0,0,0
endlayer

