# Adventurers' Inn (Basement Dungeon)
# 25 Apr 2014; updated to MC 1.7.10, 22 Oct 2014

# Created by Ruins mod version 13.8 Ingame Parser
# authoring Player: Jordan_Greywolf
# Note: Place in \templateparser folder.
# Updated to MC 1.8: 20 Mar 2016
# Updated to MC 1.9: 29 Apr 2016
# Dungeon Version: 30 Apr 2016
# Updated to MC 1.11: 12 Jan 2017
# Verified for MC 1.12: 23 Jun 2017
# Updated to MC 1.12.1: 10 Sep 2017

# Last Updated: 9 Jun 2018

biomesToSpawnIn=birch forest,birch_forest,boreal forest,boreal_forest,brushland,chaparral,flower field,flower_field,flower forest,flower_forest,forest,grassland,grove,heathland,lavender fields,lavender_fields,lighted forest,lighted_forest,magical forest,magical_forest,meadow,mountain foothills,mutated_forest,mutated_plains,orchard,plains,sunflower plains,taiga,woodland,pasture,prairie,oak savanna,orchard,origin valley,origin_valley,twilight clearing,twilight_clearing

uniqueMinDistance=1000

preventRotation=1

weight=1
embed_into_distance=19
acceptable_target_blocks=

unacceptable_target_blocks=cloud,Natura:cloud,red_mushroom_block,brown_mushroom_block,oak_stairs,spruce_stairs,dark_oak_stairs,birch_stairs,jungle_stairs,acacia_stairs,cobblestone,lava,flowing_lava,slime_congealed,slime_dirt,slime_grass,command_block,planks,planks2,concrete,cobblestone,stonebrick,brick_block,glass,torch,oak_stairs,stone_stairs,brick_stairs,stone_brick_stairs,nether_brick_stairs,sandstone_stairs,spruce_stairs,birch_stairs,jungle_stairs,quartz_stairs,acacia_stairs,dark_oak_stairs,cobblestone_wall,stone_slab,double_stone_slab,stone_slab2,wooden_slab,double_wooden_slab,nether_brick

dimensions=34,14,14
allowable_overhang=0
max_leveling=7
leveling_buffer=-1
preserve_water=0
preserve_lava=0
preserve_plants=1

rule1=0,100,preserveBlock
rule2=0,100,minecraft:cobblestone-0
rule3=0,100,minecraft:netherrack-0
rule4=0,100,minecraft:mossy_cobblestone-0
rule5=0,100,minecraft:fire-15
rule6=0,100,minecraft:iron_bars-0
rule7=0,100,minecraft:wooden_door-3
rule8=0,100,minecraft:wooden_door-1

rule9=0,100,MobSpawner:Skeleton,MobSpawner:Zombie,MobSpawner:Spider

rule10=0,100,ChestGenHook:chests/simple_dungeon:5-4

rule11=0,100,teBlock;minecraft:flower_pot;{Item:"minecraft:red_flower",x:0,y:0,z:0,Data:4,id:"flower_pot"}-0

rule12=0,100,minecraft:stone_stairs-4
rule13=0,100,minecraft:stone_stairs-1
rule14=0,100,minecraft:wooden_door-2
rule15=0,100,CommandBlock:RUINSTRIGGER /testruin TP_VaultSkullArrowHall ~9 ~-1 ~1:@-5
rule16=0,100,CommandBlock:RUINSTRIGGER /testruin TP_VaultStatues_Adventure ~25 ~19 ~0:@-5
rule17=0,100,minecraft:wooden_door-8
rule18=0,100,minecraft:wooden_door-9
rule19=0,100,CommandBlock:RUINSTRIGGER /testruin TP_VaultArrowHall ~41 ~-2 ~1:@-5
rule20=0,100,CommandBlock:RUINSTRIGGER /testruin TP_VaultShrine ~57 ~-2 ~0 1:@-5
rule21=0,100,minecraft:web-0
rule22=0,100,minecraft:cobblestone_wall-0
rule23=0,100,minecraft:ladder-3
rule24=0,100,IInventory;minecraft:trapped_chest;minecraft:grass#8#0#0+minecraft:painting#2#0#13-3
rule25=0,100,IInventory;minecraft:trapped_chest;minecraft:web#8#0#0+minecraft:coal#2#0#13-2
rule26=1,100,minecraft:torch-5
rule27=0,100,minecraft:grass-0
rule28=0,100,minecraft:farmland-7,minecraft:farmland-4,minecraft:farmland-2
rule29=0,100,minecraft:dirt-0
rule30=0,100,minecraft:water-0
rule31=0,100,minecraft:double_plant-4
rule32=0,100,minecraft:fence-0
rule33=0,100,minecraft:fence_gate-1
rule34=0,100,minecraft:wheat-7,minecraft:wheat-4,minecraft:wheat-2
rule35=0,100,minecraft:melon_block-0
rule36=0,100,minecraft:melon_stem-7,minecraft:melon_stem-4,minecraft:melon_stem-2
rule37=0,100,minecraft:stained_hardened_clay-14
rule38=0,100,minecraft:stained_hardened_clay-15
rule39=0,100,minecraft:leaves-4
rule40=0,100,minecraft:double_plant-10
rule41=0,100,minecraft:log-0
rule42=0,100,minecraft:planks-0

# Villager: Innkeeper
rule43=0,100,CommandBlock:RUINSTRIGGER /summon Villager ~0 ~0 ~0 {Profession:0,Career:1,CareerLevel:6,CustomName:Innkeeper,Offers:{Recipes:[{buy:{id:emerald,Count:1},sell:{id:carrot,Count:16}},{buy:{id:emerald,Count:1},sell:{id:baked_potato,Count:8}},{buy:{id:emerald,Count:1},sell:{id:cooked_porkchop,Count:8}},{buy:{id:emerald,Count:1},sell:{id:cooked_fish,Count:5}},{buy:{id:emerald,Count:1},sell:{id:cooked_chicken,Count:6}},{buy:{id:rotten_flesh,Count:32},sell:{id:emerald,Count:1}},{buy:{id:spider_eye,Count:32},sell:{id:emerald,Count:1}},{buy:{id:bone,Count:32},sell:{id:emerald,Count:1}},{buy:{id:emerald,Count:3},sell:{id:map,Count:1}}]}}:@-0

rule44=0,100,minecraft:crafting_table-0
rule45=0,100,minecraft:spruce_stairs-6
rule46=0,100,minecraft:fence_gate-3
rule47=0,100,IInventory;minecraft:lit_furnace;minecraft:coal#1#1#1-4
rule48=0,100,minecraft:trapdoor-3
rule49=0,100,minecraft:ladder-2
rule50=0,100,minecraft:spruce_stairs-3
rule51=0,100,minecraft:spruce_stairs-2
rule52=0,100,minecraft:stone_pressure_plate-0
rule53=0,100,minecraft:stained_glass_pane-8
rule54=7,100,WallSign:WARNING:Monsters:in:Basement!-3
rule55=7,100,WallSign:* BOUNTY *:offered for:Zombies and:Giant Spiders-5
rule56=7,100,WallSign:***:Inn & Pub      :***:null-5
rule57=7,100,WallSign:***:   Adventurers':***:null-5
rule58=0,100,minecraft:log-4
rule59=0,100,minecraft:spruce_stairs-0
rule60=0,100,minecraft:spruce_stairs-5
rule61=0,100,minecraft:log-8
rule62=0,100,minecraft:planks-2
rule63=0,100,minecraft:trapdoor-14
rule64=0,100,minecraft:trapdoor-12
rule65=0,100,minecraft:glowstone-0
rule66=0,100,minecraft:trapdoor-13
rule67=0,100,minecraft:trapdoor-15
rule68=0,100,minecraft:spruce_stairs-4
rule69=0,100,minecraft:spruce_stairs-1
rule70=0,100,minecraft:planks-1
rule71=0,100,minecraft:stone_stairs-2
rule72=0,100,minecraft:stone_stairs-3
rule73=0,100,minecraft:bed-10
rule74=0,100,minecraft:bed-2
rule75=0,100,minecraft:spruce_stairs-7
rule76=0,100,minecraft:wooden_slab-1
rule77=0,100,minecraft:stone_stairs-6
rule78=0,100,minecraft:stone_stairs-7
rule79=0,100,minecraft:stone_stairs-5
rule80=0,100,minecraft:stone_stairs-0

layer
1,1,1,2,1,2,2,2,2,1,2,1,1,1
1,2,2,2,2,2,3,3,2,2,2,2,2,1
1,2,4,4,2,2,2,2,2,2,4,4,2,1
1,2,4,4,2,4,4,4,4,2,4,4,2,1
1,2,4,4,4,4,4,4,4,4,4,4,2,1
1,2,4,4,2,4,4,4,4,2,4,4,2,1
2,2,2,2,2,4,4,4,4,2,2,2,2,2
1,2,4,4,4,4,4,4,4,4,4,4,2,1
1,2,4,4,4,4,4,4,4,4,4,4,2,1
1,2,4,4,4,4,4,4,4,4,4,4,2,1
1,2,4,4,4,4,4,4,4,4,4,4,2,1
2,2,2,2,2,4,4,4,4,2,2,2,2,2
1,2,1,1,2,2,4,4,2,2,1,1,2,1
2,1,1,1,1,2,4,4,2,1,1,1,1,2
endlayer

layer
1,1,1,2,1,2,2,2,2,1,2,1,1,1
1,2,2,2,2,2,5,5,2,2,2,2,2,1
1,2,0,0,2,2,6,6,2,2,0,0,2,1
1,2,0,0,2,0,0,0,0,2,0,0,2,1
1,2,0,0,8,0,0,0,0,7,0,0,2,1
1,2,9,10,2,0,0,0,0,2,10,9,2,1
2,2,2,2,2,0,0,0,0,2,2,2,2,2
1,2,11,0,0,0,0,0,0,0,0,11,2,1
1,2,0,0,0,0,12,12,0,0,0,0,2,1
1,2,0,0,0,0,13,13,0,0,0,0,2,1
1,2,11,0,0,0,0,0,0,0,0,11,2,1
2,2,2,2,2,0,0,0,0,2,2,2,2,2
1,2,1,1,2,2,14,14,2,2,1,1,2,1
2,1,1,1,1,2,16,15,2,1,1,1,1,2
endlayer

layer
1,1,1,2,1,2,2,2,2,1,2,1,1,1
1,2,2,2,2,2,0,0,2,2,2,2,2,1
1,2,0,0,2,2,6,6,2,2,0,0,2,1
1,2,0,0,2,0,0,0,0,2,0,0,2,1
1,2,0,0,18,0,0,0,0,17,0,0,2,1
1,2,0,0,2,0,0,0,0,2,0,0,2,1
2,2,2,2,2,0,0,0,0,2,2,2,2,2
1,2,0,0,0,0,12,12,0,0,0,0,2,1
1,2,0,0,0,0,13,13,0,0,0,0,2,1
1,2,0,0,0,0,0,0,0,0,0,0,2,1
1,2,0,0,0,0,0,0,0,0,0,0,2,1
2,2,2,2,2,0,0,0,0,2,2,2,2,2
1,2,1,1,2,2,17,18,2,2,1,1,2,1
2,1,1,1,1,2,20,19,2,1,1,1,1,2
endlayer

layer
1,1,1,2,1,2,2,2,2,1,2,1,1,1
1,2,2,2,2,2,0,0,2,2,2,2,2,1
1,2,0,0,2,2,6,6,2,2,0,0,2,1
1,2,0,0,2,0,0,0,0,2,0,0,2,1
1,2,0,0,2,0,0,0,0,2,0,0,2,1
1,2,0,0,2,0,0,0,0,2,0,0,2,1
2,2,2,2,2,0,12,12,0,2,2,2,2,2
1,2,21,0,0,0,13,13,0,0,0,21,2,1
1,2,0,0,0,0,0,0,0,0,0,0,2,1
1,2,0,0,0,0,0,0,0,0,0,0,2,1
1,2,21,0,0,0,0,0,0,0,0,21,2,1
2,2,2,2,2,0,0,0,0,2,2,2,2,2
1,2,1,1,2,2,0,0,2,2,1,1,2,1
2,1,1,1,1,2,12,12,2,1,1,1,1,2
endlayer

layer
1,1,1,2,1,2,2,2,2,1,2,1,1,1
1,2,2,2,2,2,0,0,2,2,2,2,2,1
1,2,0,0,2,2,2,2,2,2,0,0,2,1
1,2,0,0,2,21,0,0,21,2,0,0,2,1
1,2,0,0,2,0,0,0,0,2,0,0,2,1
2,2,0,0,2,0,12,12,0,2,0,0,2,1
2,2,2,2,2,0,13,13,0,2,2,2,2,2
1,2,21,21,0,0,0,0,0,0,21,21,2,1
1,2,21,0,0,0,0,0,0,0,0,0,2,1
1,2,21,0,0,0,0,0,0,0,0,21,2,1
1,2,21,21,0,0,0,0,0,0,21,21,2,1
2,2,2,2,2,21,0,0,21,2,2,2,2,2
1,2,1,1,2,2,12,12,2,2,1,1,2,1
2,1,1,1,1,2,2,2,2,1,1,1,1,2
endlayer

layer
1,1,1,2,1,2,2,2,2,1,2,1,1,1
1,2,2,2,2,2,3,3,2,2,2,2,2,1
1,2,4,4,2,2,2,2,2,2,4,4,2,1
1,2,4,4,2,4,4,4,4,2,4,4,2,1
2,2,4,4,4,4,4,4,4,4,4,4,2,2
2,2,4,4,2,4,13,13,4,2,4,4,2,2
2,2,2,2,2,4,0,0,4,2,2,2,2,2
1,2,4,4,4,4,0,0,4,4,4,4,2,1
1,2,4,4,4,4,0,0,4,4,4,4,2,1
1,2,4,4,4,4,12,12,4,4,4,4,2,1
1,2,4,4,4,4,4,4,4,4,4,4,2,1
2,2,2,2,2,4,4,4,4,2,2,2,2,2
1,2,1,1,2,2,2,2,2,2,1,1,2,1
2,1,1,1,1,2,1,1,2,1,1,1,1,2
endlayer

layer
1,1,1,2,1,2,2,2,2,1,2,1,1,1
1,2,2,2,2,2,5,5,2,2,2,2,2,1
1,2,0,0,2,2,6,6,2,2,0,0,2,1
2,2,0,0,2,0,0,0,0,2,0,0,2,2
2,2,0,0,8,0,0,0,0,7,0,0,2,2
1,2,9,10,2,0,0,0,0,2,10,9,2,1
2,2,2,2,2,0,0,0,0,2,2,2,2,2
1,2,11,0,0,0,0,0,0,0,0,11,2,1
1,2,0,0,0,0,12,12,0,0,0,0,2,1
1,2,0,0,0,0,13,13,0,0,0,0,2,1
1,2,11,0,0,0,0,0,0,0,0,11,2,1
2,2,2,2,2,0,0,0,0,2,2,2,2,2
1,2,1,1,2,2,2,2,2,2,1,1,2,1
2,2,1,1,1,2,1,1,2,1,1,1,2,2
endlayer

layer
1,1,1,2,1,2,2,2,2,1,2,1,1,1
1,2,2,2,2,2,0,0,2,2,2,2,2,1
2,2,0,0,2,2,6,6,2,2,0,0,2,2
2,2,0,0,2,0,0,0,0,2,0,0,2,2
1,2,0,0,17,0,0,0,0,17,0,0,2,1
1,2,0,0,2,0,0,0,0,2,0,0,2,1
2,2,2,2,2,0,0,0,0,2,2,2,2,2
1,2,0,0,0,0,12,12,0,0,0,0,2,1
1,2,0,0,0,0,13,13,0,0,0,0,2,1
1,2,0,0,0,0,0,0,0,0,0,0,2,1
1,2,0,0,0,0,0,0,0,0,0,0,2,1
2,2,2,2,2,0,0,0,0,2,2,2,2,2
1,2,1,1,2,2,2,2,2,2,1,1,2,1
1,2,2,1,1,2,1,1,2,1,1,2,2,1
endlayer

layer
1,1,1,2,1,2,2,2,2,1,2,1,1,1
2,2,2,2,2,2,0,0,2,2,2,2,2,2
2,2,0,0,2,2,6,6,2,2,0,0,2,2
1,2,0,0,2,0,0,0,0,2,0,0,2,1
1,2,0,0,2,0,0,0,0,2,0,0,2,1
1,2,0,0,2,0,0,0,0,2,0,0,2,1
2,2,2,2,2,0,12,12,0,2,2,2,2,2
1,2,21,0,0,0,13,13,0,0,0,21,2,1
1,2,0,0,0,0,0,0,0,0,0,0,2,1
1,2,0,0,0,0,0,0,0,0,0,0,2,1
1,2,21,0,0,0,0,0,0,0,0,21,2,1
2,2,2,2,2,0,0,0,0,2,2,2,2,2
1,2,1,1,2,2,2,2,2,2,1,1,2,1
1,1,2,2,1,2,1,1,2,1,2,2,1,1
endlayer

layer
2,1,1,2,1,2,2,2,2,1,2,1,1,2
2,2,2,2,2,2,0,0,2,2,2,2,2,2
1,2,0,21,2,2,2,2,2,2,0,21,2,1
1,2,0,0,2,21,0,0,21,2,0,0,2,1
1,2,0,0,2,0,0,0,0,2,0,0,2,1
1,2,21,0,2,0,12,12,0,2,21,0,2,1
2,2,2,2,2,0,13,13,0,2,2,2,2,2
1,2,21,21,0,0,0,0,0,0,21,21,2,1
1,2,21,0,0,0,0,0,0,0,0,21,2,1
1,2,21,0,0,0,0,0,0,0,0,21,2,1
1,2,21,21,0,0,0,0,0,0,21,21,2,1
2,2,2,2,2,21,0,0,21,2,2,2,2,2
1,2,1,1,2,2,2,2,2,2,1,1,2,1
1,1,1,2,2,2,1,1,2,2,2,1,1,1
endlayer

layer
1,1,1,2,1,2,2,2,2,1,2,1,1,1
1,2,2,2,2,2,3,3,2,2,2,2,2,1
1,2,4,4,2,2,2,2,2,2,4,4,2,1
1,2,4,4,2,4,4,4,4,2,4,4,2,1
2,2,4,4,4,4,4,4,4,4,4,4,2,2
2,2,4,4,2,4,13,13,4,2,4,4,2,2
2,2,2,2,2,4,0,0,4,2,2,2,2,2
1,2,4,4,4,4,0,0,4,4,4,4,2,1
1,2,4,4,4,4,0,0,4,4,4,4,2,1
1,2,4,4,4,4,12,12,4,4,4,4,2,1
1,2,4,4,4,4,4,4,4,4,4,4,2,1
2,2,2,2,2,4,4,4,4,2,2,2,2,2
1,2,1,1,2,2,2,2,2,2,1,1,2,1
2,1,1,1,1,2,1,1,2,1,1,1,1,2
endlayer

layer
1,1,1,2,1,2,2,2,2,1,2,1,1,1
1,2,2,2,2,2,5,5,2,2,2,2,2,1
1,2,0,0,2,2,6,6,2,2,0,0,2,1
2,2,0,0,2,0,0,0,0,2,0,0,2,2
2,2,0,0,8,0,0,0,0,7,0,0,2,2
1,2,9,10,2,0,0,0,0,2,10,9,2,1
2,2,2,2,2,0,0,0,0,2,2,2,2,2
1,2,11,0,0,0,0,0,0,0,0,11,2,1
1,2,0,0,0,0,12,12,0,0,0,0,2,1
1,2,0,0,0,0,13,13,0,0,0,0,2,1
1,2,11,0,0,0,0,0,0,0,0,11,2,1
2,2,2,2,2,0,0,0,0,2,2,2,2,2
1,2,1,1,2,2,2,2,2,2,1,1,2,1
2,2,1,1,1,2,1,1,2,1,1,1,2,2
endlayer

layer
1,1,1,2,1,2,2,2,2,1,2,1,1,1
1,2,2,2,2,2,0,0,2,2,2,2,2,1
2,2,0,0,2,2,6,6,2,2,0,0,2,2
2,2,0,0,2,0,0,0,0,2,0,0,2,2
1,2,0,0,17,0,0,0,0,17,0,0,2,1
1,2,0,0,2,0,0,0,0,2,0,0,2,1
2,2,2,2,2,0,0,0,0,2,2,2,2,2
1,2,0,0,0,0,12,12,0,0,0,0,2,1
1,2,0,0,0,0,13,13,0,0,0,0,2,1
1,2,0,0,0,0,0,0,0,0,0,0,2,1
1,2,0,0,0,0,0,0,0,0,0,0,2,1
2,2,2,2,2,0,0,0,0,2,2,2,2,2
1,2,1,1,2,2,2,2,2,2,1,1,2,1
1,2,2,1,1,2,1,1,2,1,1,2,2,1
endlayer

layer
1,1,1,2,1,2,2,2,2,1,2,1,1,1
2,2,2,2,2,2,0,0,2,2,2,2,2,2
2,2,0,0,2,2,6,6,2,2,0,0,2,2
1,2,0,0,2,0,0,0,0,2,0,0,2,1
1,2,0,0,2,0,0,0,0,2,0,0,2,1
1,2,0,0,2,0,0,0,0,2,0,0,2,1
2,2,2,2,2,0,12,12,0,2,2,2,2,2
1,2,21,0,0,0,13,13,0,0,0,21,2,1
1,2,0,0,0,0,0,0,0,0,0,0,2,1
1,2,0,0,0,0,0,0,0,0,0,0,2,1
1,2,21,0,0,0,0,0,0,0,0,21,2,1
2,2,2,2,2,0,0,0,0,2,2,2,2,2
1,2,1,1,2,2,2,2,2,2,1,1,2,1
1,1,2,2,1,2,1,1,2,1,2,2,1,1
endlayer

layer
2,1,1,2,1,2,2,2,2,1,2,1,1,2
2,2,2,2,2,2,0,0,2,2,2,2,2,2
1,2,0,21,2,2,2,2,2,2,0,21,2,1
1,2,0,0,2,21,0,0,21,2,0,0,2,1
1,2,0,0,2,0,0,0,0,2,0,0,2,1
1,2,21,0,2,0,12,12,0,2,21,0,2,1
2,2,2,2,2,0,13,13,0,2,2,2,2,2
1,2,21,21,0,0,0,0,0,0,21,21,2,1
1,2,21,0,0,0,0,0,0,0,0,21,2,1
1,2,21,0,0,0,0,0,0,0,0,21,2,1
1,2,21,21,0,0,0,0,0,0,21,21,2,1
2,2,2,2,2,21,0,0,21,2,2,2,2,2
1,2,1,1,2,2,2,2,2,2,1,1,2,1
1,1,1,2,2,2,1,1,2,2,2,1,1,1
endlayer


layer
2,2,1,2,1,2,2,2,2,1,2,1,2,2
1,2,2,2,2,2,3,3,2,2,2,2,2,1
1,2,21,21,2,2,2,2,2,2,21,21,2,1
1,2,0,21,2,4,4,4,4,2,0,21,2,1
1,2,21,0,2,4,4,4,4,2,21,0,2,1
1,2,21,21,2,4,13,13,4,2,21,21,2,1
2,2,2,2,2,4,0,0,4,2,2,2,2,2
1,2,4,4,4,4,0,0,4,4,4,4,2,1
1,2,4,4,4,4,0,0,4,4,4,4,2,1
1,2,4,4,4,4,0,0,4,4,4,4,2,1
1,2,4,4,4,4,0,0,4,4,4,4,2,1
2,2,2,2,2,4,22,22,4,2,2,2,2,2
1,2,1,1,2,2,2,2,2,2,1,1,2,1
1,1,1,1,2,2,1,1,2,2,1,1,1,1
endlayer

layer
1,2,2,2,1,2,2,2,2,1,2,2,2,1
1,2,2,2,2,2,5,5,2,2,2,2,2,1
1,2,2,2,2,2,6,6,2,2,2,2,2,1
1,2,2,2,2,22,0,0,22,2,2,2,2,1
1,2,2,2,2,0,0,0,0,2,2,2,2,1
1,2,2,2,2,0,0,0,0,2,2,2,2,1
2,2,2,2,2,0,0,0,23,2,2,2,2,2
2,2,22,0,0,0,0,0,0,0,0,22,2,2
1,2,25,0,0,0,0,0,0,0,0,24,2,1
1,2,25,0,0,0,0,0,0,0,0,24,2,1
2,2,22,0,11,22,0,0,22,11,0,22,2,2
2,2,2,2,2,22,0,0,22,2,2,2,2,2
1,2,1,1,2,2,2,2,2,2,1,1,2,1
1,1,1,1,1,2,2,2,2,1,1,1,1,1
endlayer

layer
1,1,2,2,2,2,2,2,2,2,2,2,1,1
1,2,2,2,2,2,0,0,2,2,2,2,2,1
1,2,2,2,2,2,6,6,2,2,2,2,2,1
1,2,2,2,2,22,0,0,22,2,2,2,2,1
1,2,2,2,2,0,0,0,0,2,2,2,2,1
1,2,2,2,2,0,0,0,0,2,2,2,2,1
2,2,2,2,2,0,0,0,23,2,2,2,2,2
2,2,22,0,0,0,0,0,0,0,0,22,2,2
2,2,21,0,0,0,0,0,0,0,0,21,2,2
2,2,21,0,0,0,0,0,0,0,0,21,2,2
2,2,22,0,0,26,0,0,26,0,0,22,2,2
2,2,2,2,2,22,0,0,22,2,2,2,2,2
1,2,2,2,2,2,2,2,2,2,2,2,2,1
1,1,1,1,1,1,2,2,1,1,1,1,1,1
endlayer

layer
1,1,1,2,27,2,2,2,2,27,2,1,1,1
1,2,2,2,2,2,0,0,2,2,2,2,2,1
1,2,28,29,2,2,2,2,2,2,28,28,2,1
1,2,28,29,2,2,0,0,2,2,28,28,2,1
1,2,28,29,2,21,0,0,21,2,28,28,2,1
1,2,28,29,2,21,0,0,21,2,28,28,2,1
27,2,30,2,2,0,0,0,23,2,2,30,2,27
27,2,2,0,0,0,0,0,0,21,21,2,2,27
27,2,21,0,0,0,0,0,0,0,0,21,2,27
27,2,21,0,0,0,0,0,0,0,0,21,2,27
27,2,2,21,21,0,0,0,0,21,21,2,2,27
27,2,2,2,2,2,21,21,2,2,2,2,2,27
1,27,27,27,27,2,2,2,2,27,27,27,27,1
1,1,1,1,1,1,1,1,1,1,1,1,1,1
endlayer

layer
1,1,1,1,31,2,2,2,2,31,1,1,1,1
1,32,33,32,2,2,3,3,2,2,32,33,32,1
1,32,36,35,2,2,2,2,2,2,34,34,32,1
1,32,36,35,2,38,37,38,37,2,34,34,32,1
0,32,36,35,2,37,38,37,38,2,34,34,32,0
0,32,36,35,2,38,37,38,37,2,34,34,32,0
31,2,2,2,2,37,38,37,23,2,2,2,2,31
39,2,37,38,37,38,37,38,37,38,37,38,2,39
39,2,38,37,38,37,38,37,38,37,38,37,2,39
39,2,37,38,37,38,37,38,37,38,37,38,2,39
39,2,38,37,38,37,38,37,38,37,38,37,2,39
31,2,2,2,2,2,2,2,2,2,2,2,2,31
1,31,39,39,31,2,1,1,2,31,39,39,31,1
1,1,1,1,0,1,1,1,1,0,1,1,1,1
endlayer

layer
1,1,1,0,40,2,2,2,2,40,0,1,1,1
1,0,0,0,41,2,5,5,2,41,0,0,0,1
1,0,0,0,42,2,6,6,2,42,0,0,0,1
0,0,0,0,42,43,0,0,0,42,0,0,0,0
0,0,0,0,42,0,0,0,0,42,0,0,0,0
0,0,0,0,42,47,46,45,44,42,0,0,0,0
40,41,42,42,41,0,0,0,48,41,42,42,41,40
39,42,49,0,0,0,0,0,0,0,0,23,42,39
39,42,51,32,50,0,0,0,0,51,32,50,42,39
39,42,51,32,50,0,0,0,0,51,32,50,42,39
39,42,11,0,0,0,52,52,0,0,0,11,42,39
40,41,42,42,41,42,14,14,42,41,42,42,41,40
1,40,39,39,40,32,0,0,32,40,39,39,40,1
1,1,1,0,0,0,1,1,0,0,0,1,1,1
endlayer

layer
1,1,0,0,0,2,2,2,2,0,0,0,1,1
1,0,0,0,41,2,0,0,2,41,0,0,0,1
0,0,0,0,42,2,0,0,2,42,0,0,0,0
0,0,0,0,53,0,0,0,0,53,0,0,0,0
0,0,0,0,53,0,0,0,0,53,0,0,0,0
0,0,0,0,42,0,0,0,0,42,0,0,0,0
0,41,53,53,41,0,0,0,54,41,53,53,41,0
0,42,49,0,55,0,0,0,0,0,0,23,42,0
0,53,0,52,0,0,0,0,0,0,52,0,53,0
0,53,0,52,0,0,0,0,0,0,52,0,53,0
0,42,0,0,0,0,0,0,0,0,0,0,42,0
0,41,53,53,41,42,17,18,42,41,53,53,41,0
0,0,0,0,0,26,0,0,26,0,0,0,0,0
1,1,0,0,0,0,0,0,0,0,0,0,1,1
endlayer

layer
1,0,0,0,0,2,2,2,2,0,0,0,0,1
0,0,0,32,41,2,0,0,2,41,32,0,0,0
0,0,0,0,42,2,2,2,2,42,0,0,0,0
0,0,0,0,42,22,0,0,22,42,0,0,0,0
0,0,0,0,42,0,0,0,0,42,0,0,0,0
0,32,0,32,42,32,32,32,32,42,32,0,32,0
0,41,42,42,41,0,0,0,0,41,42,42,41,0
0,42,49,0,0,0,0,0,0,0,0,23,42,0
0,42,0,0,0,0,0,0,0,0,0,0,42,0
0,42,0,0,0,0,0,0,0,0,0,0,42,0
0,42,0,0,0,0,0,0,0,0,0,0,42,0
0,41,42,42,41,42,42,42,42,41,42,42,41,0
0,32,0,0,32,0,57,56,0,32,0,0,32,0
0,0,0,0,0,0,0,0,0,0,0,0,0,0
endlayer

layer
0,0,0,50,0,2,2,2,2,0,51,0,0,0
0,0,0,50,41,2,2,2,2,41,51,0,0,0
0,0,0,50,58,2,2,2,2,58,51,0,0,0
0,0,0,50,58,22,22,22,22,58,51,0,0,0
0,0,0,50,58,0,0,0,0,58,51,0,0,0
59,59,59,59,58,0,0,0,0,58,59,59,59,59
60,41,61,61,41,61,61,61,61,41,61,61,41,60
0,58,49,62,58,0,63,63,0,58,62,23,58,0
0,58,62,62,58,66,65,65,64,58,62,62,58,0
0,58,62,62,58,66,65,65,64,58,62,62,58,0
0,58,62,62,58,0,67,67,0,58,62,62,58,0
68,41,61,61,41,61,61,61,61,41,61,61,41,68
69,69,69,69,69,69,69,69,69,69,69,69,69,69
0,0,0,0,0,0,0,0,0,0,0,0,0,0
endlayer

layer
0,0,0,0,70,72,2,2,71,70,0,0,0,0
0,0,0,0,70,2,2,2,2,70,0,0,0,0
0,0,0,0,70,2,2,2,2,70,0,0,0,0
0,0,0,0,70,0,0,0,0,70,0,0,0,0
0,0,0,0,70,0,0,0,0,70,0,0,0,0
0,0,0,0,70,0,0,0,0,70,0,0,0,0
70,70,70,70,70,32,32,32,32,70,70,70,70,70
32,42,48,11,32,0,0,0,0,32,11,48,42,32
0,53,0,0,32,0,6,6,0,32,0,0,53,0
0,53,0,0,32,0,6,6,0,32,0,0,53,0
32,42,74,73,32,0,0,0,0,32,74,73,42,32
70,70,70,70,70,70,53,53,70,70,70,70,70,70
0,0,0,0,0,32,0,0,32,0,0,0,0,0
0,0,0,0,0,0,0,0,0,0,0,0,0,0
endlayer

layer
0,0,0,0,70,0,2,2,0,70,0,0,0,0
0,0,0,0,70,2,2,2,2,70,0,0,0,0
0,0,0,0,70,2,2,2,2,70,0,0,0,0
0,0,0,0,70,0,0,0,0,70,0,0,0,0
0,0,0,0,70,0,0,0,0,70,0,0,0,0
0,0,0,0,70,0,0,0,0,70,0,0,0,0
70,70,70,70,70,0,0,0,0,70,70,70,70,70
32,42,0,0,0,0,0,0,0,0,0,0,42,32
0,53,0,0,0,0,6,6,0,0,0,0,53,0
0,53,0,0,0,0,6,6,0,0,0,0,53,0
32,42,0,0,26,0,0,0,0,26,0,0,42,32
70,70,70,70,70,70,53,53,70,70,70,70,70,70
0,0,0,0,0,32,0,0,32,0,0,0,0,0
0,0,0,0,0,0,0,0,0,0,0,0,0,0
endlayer

layer
0,0,0,0,50,70,0,0,70,51,0,0,0,0
0,0,0,0,50,70,2,2,70,51,0,0,0,0
0,0,0,0,50,70,2,2,70,51,0,0,0,0
0,0,0,0,50,70,0,0,70,51,0,0,0,0
0,0,0,0,50,70,0,0,70,51,0,0,0,0
0,0,0,0,50,70,0,0,70,51,0,0,0,0
59,59,59,59,59,70,0,0,70,51,59,59,59,59
60,70,70,70,70,70,0,0,70,70,70,70,70,60
0,53,0,0,0,0,6,6,0,0,0,0,53,0
0,53,0,0,0,0,6,6,0,0,0,0,53,0
68,70,70,70,70,70,70,70,70,70,70,70,70,68
69,69,69,69,69,50,70,70,51,69,69,69,69,69
0,0,0,0,0,50,45,75,51,0,0,0,0,0
0,0,0,0,0,0,0,0,0,0,0,0,0,0
endlayer

layer
0,0,0,0,0,50,70,70,51,0,0,0,0,0
0,0,0,0,0,50,2,2,51,0,0,0,0,0
0,0,0,0,0,50,70,70,51,0,0,0,0,0
0,0,0,0,0,50,70,70,51,0,0,0,0,0
0,0,0,0,0,50,70,70,51,0,0,0,0,0
0,0,0,0,0,50,70,70,51,0,0,0,0,0
0,0,0,0,0,50,70,70,51,0,0,0,0,0
59,59,59,59,59,59,70,70,51,59,59,59,59,59
70,70,70,70,70,70,70,70,70,70,70,70,70,70
70,70,70,70,70,70,70,70,70,70,70,70,70,70
69,69,69,69,69,69,69,69,69,69,69,69,69,69
0,0,0,0,0,0,76,76,0,0,0,0,0,0
0,0,0,0,0,0,76,76,0,0,0,0,0,0
0,0,0,0,0,0,0,0,0,0,0,0,0,0
endlayer

layer
0,0,0,0,0,0,70,70,0,0,0,0,0,0
0,0,0,0,0,22,2,2,22,0,0,0,0,0
0,0,0,0,0,0,69,69,0,0,0,0,0,0
0,0,0,0,0,0,76,76,0,0,0,0,0,0
0,0,0,0,0,0,76,76,0,0,0,0,0,0
0,0,0,0,0,0,76,76,0,0,0,0,0,0
0,0,0,0,0,0,76,76,0,0,0,0,0,0
0,0,0,0,0,0,76,76,0,0,0,0,0,0
70,51,76,76,76,76,76,76,76,76,76,76,50,70
70,51,76,76,76,76,76,76,76,76,76,76,50,70
0,0,0,0,0,0,0,0,0,0,0,0,0,0
0,0,0,0,0,0,0,0,0,0,0,0,0,0
0,0,0,0,0,0,0,0,0,0,0,0,0,0
0,0,0,0,0,0,0,0,0,0,0,0,0,0
endlayer

layer
0,0,0,0,0,0,70,70,0,0,0,0,0,0
0,0,0,0,0,22,2,2,22,0,0,0,0,0
0,0,0,0,0,0,0,0,0,0,0,0,0,0
0,0,0,0,0,0,0,0,0,0,0,0,0,0
0,0,0,0,0,0,0,0,0,0,0,0,0,0
0,0,0,0,0,0,0,0,0,0,0,0,0,0
0,0,0,0,0,0,0,0,0,0,0,0,0,0
0,0,0,0,0,0,0,0,0,0,0,0,0,0
70,0,0,0,0,0,0,0,0,0,0,0,0,70
70,0,0,0,0,0,0,0,0,0,0,0,0,70
0,0,0,0,0,0,0,0,0,0,0,0,0,0
0,0,0,0,0,0,0,0,0,0,0,0,0,0
0,0,0,0,0,0,0,0,0,0,0,0,0,0
0,0,0,0,0,0,0,0,0,0,0,0,0,0
endlayer

layer
0,0,0,0,0,0,69,69,0,0,0,0,0,0
0,0,0,0,0,22,2,2,22,0,0,0,0,0
0,0,0,0,0,0,0,0,0,0,0,0,0,0
0,0,0,0,0,0,0,0,0,0,0,0,0,0
0,0,0,0,0,0,0,0,0,0,0,0,0,0
0,0,0,0,0,0,0,0,0,0,0,0,0,0
0,0,0,0,0,0,0,0,0,0,0,0,0,0
0,0,0,0,0,0,0,0,0,0,0,0,0,0
51,0,0,0,0,0,0,0,0,0,0,0,0,50
51,0,0,0,0,0,0,0,0,0,0,0,0,50
0,0,0,0,0,0,0,0,0,0,0,0,0,0
0,0,0,0,0,0,0,0,0,0,0,0,0,0
0,0,0,0,0,0,0,0,0,0,0,0,0,0
0,0,0,0,0,0,0,0,0,0,0,0,0,0
endlayer

layer
0,0,0,0,0,0,0,0,0,0,0,0,0,0
0,0,0,0,0,22,2,2,22,0,0,0,0,0
0,0,0,0,0,0,0,0,0,0,0,0,0,0
0,0,0,0,0,0,0,0,0,0,0,0,0,0
0,0,0,0,0,0,0,0,0,0,0,0,0,0
0,0,0,0,0,0,0,0,0,0,0,0,0,0
0,0,0,0,0,0,0,0,0,0,0,0,0,0
0,0,0,0,0,0,0,0,0,0,0,0,0,0
0,0,0,0,0,0,0,0,0,0,0,0,0,0
0,0,0,0,0,0,0,0,0,0,0,0,0,0
0,0,0,0,0,0,0,0,0,0,0,0,0,0
0,0,0,0,0,0,0,0,0,0,0,0,0,0
0,0,0,0,0,0,0,0,0,0,0,0,0,0
0,0,0,0,0,0,0,0,0,0,0,0,0,0
endlayer

layer
0,0,0,0,0,0,12,12,0,0,0,0,0,0
0,0,0,0,0,78,3,3,77,0,0,0,0,0
0,0,0,0,0,0,79,79,0,0,0,0,0,0
0,0,0,0,0,0,0,0,0,0,0,0,0,0
0,0,0,0,0,0,0,0,0,0,0,0,0,0
0,0,0,0,0,0,0,0,0,0,0,0,0,0
0,0,0,0,0,0,0,0,0,0,0,0,0,0
0,0,0,0,0,0,0,0,0,0,0,0,0,0
0,0,0,0,0,0,0,0,0,0,0,0,0,0
0,0,0,0,0,0,0,0,0,0,0,0,0,0
0,0,0,0,0,0,0,0,0,0,0,0,0,0
0,0,0,0,0,0,0,0,0,0,0,0,0,0
0,0,0,0,0,0,0,0,0,0,0,0,0,0
0,0,0,0,0,0,0,0,0,0,0,0,0,0
endlayer

layer
0,0,0,0,0,0,80,80,0,0,0,0,0,0
0,0,0,0,0,72,5,5,71,0,0,0,0,0
0,0,0,0,0,0,13,13,0,0,0,0,0,0
0,0,0,0,0,0,0,0,0,0,0,0,0,0
0,0,0,0,0,0,0,0,0,0,0,0,0,0
0,0,0,0,0,0,0,0,0,0,0,0,0,0
0,0,0,0,0,0,0,0,0,0,0,0,0,0
0,0,0,0,0,0,0,0,0,0,0,0,0,0
0,0,0,0,0,0,0,0,0,0,0,0,0,0
0,0,0,0,0,0,0,0,0,0,0,0,0,0
0,0,0,0,0,0,0,0,0,0,0,0,0,0
0,0,0,0,0,0,0,0,0,0,0,0,0,0
0,0,0,0,0,0,0,0,0,0,0,0,0,0
0,0,0,0,0,0,0,0,0,0,0,0,0,0
endlayer

