# Andesite Lookout -- 21 Mar 2016
# Created by Ruins mod version 15.5 Ingame Parser
# authoring Player: Jordan_Greywolf
# Note: Created as a test of gate & door rotation in MC 1.8.
# Updated to MC 1.9: 30 Apr 2016
# Updated to MC 1.11: 13 Jan 2017
# Verified for MC 1.12: 23 Jun 2017
# Updated to MC 1.12.1: 10 Sep 2017

# Last Updated: 9 Jun 2018

biomesToSpawnIn=birch forest,birch_forest,birch forest hills,birch_forest_hills,birch forest hills m,birch forest m,boreal forest,boreal_forest,brushland,chaparral,cold taiga,cold taiga hills,cold taiga m,coniferous forest,coniferous_forest,dead forest,dead_forest,extreme hills edge,fen,forest,foresthills,forest_hills,grassland,grove,heathland,highland,ice mountains,ice_mountains,maple woods,maple_woods,mega taiga,mega taiga hills,mountain,mountain foothills,mutated_forest,mutated_taiga,mutated_taiga_hills,ominous woods,ominous_woods,redwood_taiga,redwood_taiga_hills,redwood taiga hills m,steppe,taiga,taiga_cold,taiga_cold_hills,taiga m,taigahills,xeric shrubland,xeric_shrubland

weight=1
embed_into_distance=6
acceptable_target_blocks=

unacceptable_target_blocks=cloud,Natura:Cloud,red_mushroom_block,brown_mushroom_block,slime_congealed,slime_dirt,slime_grass,command_block,planks,planks2,concrete,cobblestone,stonebrick,brick_block,glass,torch,oak_stairs,stone_stairs,brick_stairs,stone_brick_stairs,nether_brick_stairs,sandstone_stairs,spruce_stairs,birch_stairs,jungle_stairs,quartz_stairs,acacia_stairs,dark_oak_stairs,cobblestone_wall,stone_slab,double_stone_slab,stone_slab2,wooden_slab,double_wooden_slab,nether_brick

dimensions=24,9,9
allowable_overhang=0
max_leveling=6
leveling_buffer=0
preserve_water=0
preserve_lava=0
preserve_plants=1

rule1=0,100,preserveBlock
rule2=0,100,minecraft:double_stone_slab-0
rule3=0,100,minecraft:mossy_cobblestone-0
rule4=0,100,minecraft:stone-6
rule5=0,100,minecraft:stonebrick-0,minecraft:stonebrick-0,minecraft:stonebrick-1,minecraft:stonebrick-2
rule6=0,100,MobSpawner:Cave_Spider
rule7=0,100,minecraft:dark_oak_fence_gate-0
rule8=0,100,minecraft:dark_oak_fence-0
rule9=0,100,minecraft:dark_oak_fence_gate-1
rule10=0,100,ChestGenHook:chests/simple_dungeon:5-4
rule11=0,100,IInventory;minecraft:trapped_chest;minecraft:torch#8#0#1+minecraft:stone#8#2#5+minecraft:stone#16#0#7+minecraft:log2#8#1#10+minecraft:stone#16#6#13+minecraft:torch#8#0#20+minecraft:arrow#16#0#24-3
rule12=0,100,minecraft:ladder-2
rule13=0,100,ChestGenHook:chests/simple_dungeon:5-5
rule14=2,100,minecraft:redstone_torch-3
rule15=0,100,minecraft:web-0
rule16=0,100,minecraft:stone_slab-8
rule17=0,100,minecraft:stone_slab-0
rule18=0,100,minecraft:stone-2
rule19=0,100,minecraft:dark_oak_fence_gate-2
rule20=0,100,minecraft:dark_oak_door-2
rule21=0,100,minecraft:dark_oak_door-3
rule22=0,100,minecraft:dark_oak_door-1
rule23=0,100,minecraft:dark_oak_door-0
rule24=0,100,minecraft:dark_oak_door-9
rule25=0,100,minecraft:dark_oak_door-8
rule26=0,100,minecraft:stone_brick_stairs-5
rule27=0,100,minecraft:stone_brick_stairs-7
rule28=0,100,minecraft:stone_brick_stairs-6
rule29=0,100,minecraft:stone_brick_stairs-4
rule30=0,100,minecraft:wooden_slab-5
rule31=0,100,minecraft:dark_oak_stairs-2
rule32=0,100,minecraft:dark_oak_stairs-7
rule33=0,100,minecraft:dark_oak_stairs-6
rule34=0,100,minecraft:dark_oak_stairs-3
rule35=0,100,minecraft:dark_oak_stairs-0
rule36=0,100,minecraft:dark_oak_stairs-5
rule37=0,100,minecraft:dark_oak_stairs-4
rule38=0,100,minecraft:dark_oak_stairs-1
rule39=0,100,minecraft:wooden_slab-13
rule40=0,100,minecraft:planks-5

layer
1,1,1,1,1,1,1,1,1
1,2,2,2,2,2,2,2,1
1,2,3,3,3,3,3,2,1
1,2,3,3,3,3,3,2,1
1,2,3,3,3,3,3,2,1
1,2,3,3,3,3,3,2,1
1,2,3,3,3,3,3,2,1
1,2,2,2,2,2,2,2,1
1,1,1,1,1,1,1,1,1
endlayer

layer
1,1,1,1,1,1,1,1,1
1,4,5,5,5,5,5,4,1
1,5,0,7,0,0,6,5,1
1,5,10,4,8,9,8,5,1
1,5,4,12,0,0,11,5,1
1,5,13,4,8,9,8,5,1
1,5,0,7,0,0,6,5,1
1,4,5,5,5,5,5,4,1
1,1,1,1,1,1,1,1,1
endlayer

layer
1,1,1,1,1,1,1,1,1
1,4,5,5,5,5,5,4,1
1,5,0,0,0,0,0,5,1
1,5,0,4,8,0,8,5,1
1,5,4,12,0,0,14,5,1
1,5,0,4,8,0,8,5,1
1,5,0,0,0,0,0,5,1
1,4,5,5,5,5,5,4,1
1,1,1,1,1,1,1,1,1
endlayer

layer
1,1,1,1,1,1,1,1,1
1,4,5,5,5,5,5,4,1
1,5,15,0,0,0,15,5,1
1,5,0,4,8,8,8,5,1
1,5,4,12,8,0,8,5,1
1,5,0,4,8,8,8,5,1
1,5,15,0,0,0,15,5,1
1,4,5,5,5,5,5,4,1
1,1,1,1,1,1,1,1,1
endlayer

layer
1,1,1,1,1,1,1,1,1
1,4,5,5,5,5,5,4,1
1,5,15,15,0,15,15,5,1
1,5,15,4,16,16,8,5,1
1,5,4,12,16,16,0,5,1
1,5,15,4,16,16,8,5,1
1,5,15,15,0,15,15,5,1
1,4,5,5,5,5,5,4,1
1,1,1,1,1,1,1,1,1
endlayer

layer
1,1,1,1,1,1,1,1,1
1,2,17,17,17,17,17,2,1
1,17,2,2,2,2,2,17,1
1,17,2,18,18,18,2,17,1
1,17,2,12,18,18,2,17,0
1,17,2,18,18,18,2,17,1
1,17,2,2,2,2,2,17,1
1,2,17,17,17,17,17,2,1
1,1,1,1,1,1,1,1,1
endlayer

layer
1,1,1,1,1,1,1,1,1
1,8,1,1,1,1,1,8,1
1,1,4,5,5,5,4,1,1
1,1,5,0,0,0,5,1,1
1,1,5,12,0,0,19,0,0
1,1,5,0,0,0,5,1,1
1,1,4,5,5,5,4,1,1
1,8,1,1,1,1,1,8,1
1,1,1,1,1,1,1,1,1
endlayer

layer
1,1,1,1,1,1,1,1,1
1,8,1,1,1,1,1,8,1
1,1,4,5,8,5,4,1,1
1,1,5,0,0,0,5,1,1
1,1,8,12,0,0,0,0,0
1,1,5,0,0,0,5,1,1
1,1,4,5,8,5,4,1,1
1,8,1,1,1,1,1,8,1
1,1,1,1,1,1,1,1,1
endlayer

layer
1,1,1,1,1,1,1,1,1
1,8,1,1,1,1,1,8,1
1,1,4,5,8,5,4,1,1
1,1,5,0,0,0,5,1,1
1,1,8,12,0,0,8,0,0
1,1,5,0,0,0,5,1,1
1,1,4,5,8,5,4,1,1
1,8,1,1,1,1,1,8,1
1,1,1,1,1,1,1,1,1
endlayer

layer
1,1,1,1,1,1,1,1,1
1,8,1,1,1,1,1,8,1
1,1,4,5,5,5,4,1,1
1,1,5,0,0,0,5,1,1
1,1,5,12,0,0,5,1,0
1,1,5,0,0,0,5,1,1
1,1,4,5,5,5,4,1,1
1,8,1,1,1,1,1,8,1
1,1,1,1,1,1,1,1,1
endlayer

layer
1,1,1,1,1,1,1,1,1
1,2,16,16,16,16,16,2,1
1,16,2,2,2,2,2,16,1
1,16,2,18,18,18,2,16,1
1,16,2,12,18,18,2,16,1
1,16,2,18,18,18,2,16,1
1,16,2,2,2,2,2,16,1
1,2,16,16,16,16,16,2,1
1,1,1,1,1,1,1,1,1
endlayer

layer
1,1,1,1,1,1,1,1,1
1,4,4,8,8,8,4,4,1
1,4,0,0,20,0,0,4,1
1,8,0,4,0,4,0,8,1
1,8,22,0,0,0,21,8,1
1,8,0,4,0,4,0,8,1
1,4,0,0,23,0,0,4,1
1,4,4,8,8,8,4,4,1
1,1,1,1,1,1,1,1,1
endlayer

layer
1,1,1,1,1,1,1,1,1
1,8,4,8,0,8,4,8,1
1,4,0,0,24,0,0,4,1
1,8,0,4,0,4,0,8,1
1,0,25,0,0,0,24,0,1
1,8,0,4,0,4,0,8,1
1,4,0,0,25,0,0,4,1
1,8,4,8,0,8,4,8,1
1,1,1,1,1,1,1,1,1
endlayer

layer
1,1,1,1,1,1,1,1,1
1,4,4,8,8,8,4,4,1
1,4,0,0,0,0,0,4,1
1,8,0,4,26,4,0,8,1
1,8,0,28,0,27,0,8,1
1,8,0,4,29,4,0,8,1
1,4,0,0,0,0,0,4,1
1,4,4,8,8,8,4,4,1
1,1,1,1,1,1,1,1,1
endlayer

layer
30,34,33,1,1,1,32,31,30
35,35,4,4,4,4,4,31,35
36,4,0,0,0,0,0,4,36
1,4,0,4,8,4,0,4,1
1,4,0,8,0,8,0,4,1
1,4,0,4,8,4,0,4,1
37,4,0,0,0,0,0,4,37
38,34,4,4,4,4,4,38,38
30,34,33,1,1,1,32,31,30
endlayer

layer
0,0,34,33,0,32,31,0,0
0,0,34,4,8,4,31,0,0
35,35,34,0,0,0,35,35,35
36,4,0,4,8,4,0,4,36
1,8,0,8,0,8,0,8,1
37,4,0,4,8,4,0,4,37
38,38,38,0,0,0,31,38,38
0,0,34,4,8,4,31,0,0
0,0,34,33,1,32,31,0,0
endlayer

layer
0,0,0,34,39,31,0,0,0
0,0,0,34,39,31,0,0,0
0,0,0,34,39,31,0,0,0
35,35,35,4,8,4,35,35,35
39,39,39,8,0,8,39,39,39
38,38,38,4,8,4,38,38,38
0,0,0,34,39,31,0,0,0
0,0,0,34,39,31,0,0,0
0,0,0,34,39,31,0,0,0
endlayer

layer
0,0,0,0,40,0,0,0,0
0,0,0,0,38,0,0,0,0
0,0,0,0,30,0,0,0,0
0,0,0,4,8,4,0,0,0
40,31,30,8,0,8,30,34,40
0,0,0,4,8,4,0,0,0
0,0,0,0,30,0,0,0,0
0,0,0,0,35,0,0,0,0
0,0,0,0,40,0,0,0,0
endlayer

layer
0,0,0,0,38,0,0,0,0
0,0,0,0,0,0,0,0,0
0,0,0,0,0,0,0,0,0
0,0,0,4,8,4,0,0,0
31,0,0,8,0,8,0,0,34
0,0,0,4,8,4,0,0,0
0,0,0,0,0,0,0,0,0
0,0,0,0,0,0,0,0,0
0,0,0,0,35,0,0,0,0
endlayer

layer
0,0,0,0,0,0,0,0,0
0,0,0,0,0,0,0,0,0
0,0,0,0,0,0,0,0,0
0,0,0,4,8,4,0,0,0
0,0,0,8,0,8,0,0,0
0,0,0,4,8,4,0,0,0
0,0,0,0,0,0,0,0,0
0,0,0,0,0,0,0,0,0
0,0,0,0,0,0,0,0,0
endlayer

layer
0,0,0,0,0,0,0,0,0
0,0,0,0,0,0,0,0,0
0,0,0,34,39,31,0,0,0
0,0,35,40,4,40,35,0,0
0,0,39,4,0,4,39,0,0
0,0,38,40,4,40,38,0,0
0,0,0,34,39,31,0,0,0
0,0,0,0,0,0,0,0,0
0,0,0,0,0,0,0,0,0
endlayer

layer
0,0,0,0,0,0,0,0,0
0,0,0,0,0,0,0,0,0
0,0,0,0,38,0,0,0,0
0,0,0,34,35,35,0,0,0
0,0,31,34,40,31,34,0,0
0,0,0,38,38,31,0,0,0
0,0,0,0,35,0,0,0,0
0,0,0,0,0,0,0,0,0
0,0,0,0,0,0,0,0,0
endlayer

layer
0,0,0,0,0,0,0,0,0
0,0,0,0,0,0,0,0,0
0,0,0,0,0,0,0,0,0
0,0,0,0,0,0,0,0,0
0,0,0,0,40,0,0,0,0
0,0,0,0,0,0,0,0,0
0,0,0,0,0,0,0,0,0
0,0,0,0,0,0,0,0,0
0,0,0,0,0,0,0,0,0
endlayer

layer
0,0,0,0,0,0,0,0,0
0,0,0,0,0,0,0,0,0
0,0,0,0,0,0,0,0,0
0,0,0,0,0,0,0,0,0
0,0,0,0,8,0,0,0,0
0,0,0,0,0,0,0,0,0
0,0,0,0,0,0,0,0,0
0,0,0,0,0,0,0,0,0
0,0,0,0,0,0,0,0,0
endlayer

