# Acacia Roof House -- created 6/3/2017
# Created by Ruins mod version 16.4 Ingame Parser
# authoring Player: Jordan_Greywolf

# Created for MC 1.11.2: 2017 Jun 3
# Verified for MC 1.12: 23 Jun 2017
# Updated to MC 1.12.1: 10 Sep 2017

uniqueMinDistance=2000

biomesToSpawnIn=autumn woods,autumnal_woods,birch forest,birch_forest,bog,deadlands,dead forest,dead_forest,dead swamp,dead_swamp,dreadlands,eerie,eldritch,enchanted forest,enchanted_forest,fen,flower field,flower_field,flower forest,flower_forest,forest,green swamp,green_swampland,quagmire,magical forest,magical_forest,mystic grove,mystic_grove,mutated_forest,mutated_plains,mutated_swampland,ominous woods,ominous_woods,swampland,taiga,tainted land,tainted_land,thinned mystic grove,wasteland,wonderous woods,woodland,woodlands,rwg_coldforest,rwg_snowforest,rwg_temperateforest,witherlands


weight=1
embed_into_distance=8

acceptable_target_blocks=

unacceptable_target_blocks=flowing_water,water,flowing_lava,lava,cloud,Natura:Cloud,bedrock,cobblestone,endstone,red_mushroom_block,brown_mushroom_block,ice,slime_congealed,slime_dirt,slime_grass,command_block,planks,planks2,concrete,cobblestone,stonebrick,brick_block,glass,torch,oak_stairs,stone_stairs,brick_stairs,stone_brick_stairs,nether_brick_stairs,sandstone_stairs,spruce_stairs,birch_stairs,jungle_stairs,quartz_stairs,acacia_stairs,dark_oak_stairs,cobblestone_wall,stone_slab,double_stone_slab,stone_slab2,wooden_slab,double_wooden_slab,nether_brick

dimensions=31,15,13
allowable_overhang=0
max_leveling=6
leveling_buffer=-1
preserve_water=0
preserve_lava=0
preserve_plants=1

rule1=0,100,preserveBlock

rule2=0,100,minecraft:stonebrick-0,minecraft:stonebrick-0,minecraft:stonebrick-1,minecraft:stonebrick-2

rule3=0,100,minecraft:stone-6

rule4=0,100,minecraft:mossy_cobblestone-0,minecraft:cobblestone,minecraft:gravel

rule5=0,100,minecraft:web-0
rule6=0,100,minecraft:tripwire_hook-12
rule7=0,100,minecraft:tripwire-4
rule8=0,100,minecraft:tripwire-4
rule9=0,100,minecraft:tripwire_hook-14

rule10=0,100,ChestGenHook:chests/simple_dungeon:3-4

rule11=0,100,minecraft:ladder-5

rule12=0,100,IInventory;minecraft:dispenser;minecraft:fire_charge#2#0#0+minecraft:fire_charge#2#0#2+minecraft:fire_charge#2#0#4+minecraft:fire_charge#2#0#6+minecraft:fire_charge#2#0#8-11

rule13=0,100,IInventory;minecraft:dispenser;minecraft:fire_charge#2#0#0+minecraft:fire_charge#2#0#2+minecraft:fire_charge#2#0#4+minecraft:fire_charge#2#0#6+minecraft:fire_charge#2#0#8-10

rule14=0,100,minecraft:log-0
rule15=0,100,minecraft:stone_slab-8
rule16=0,100,minecraft:trapdoor-3
rule17=0,100,minecraft:spruce_stairs-4

rule18=0,100,ChestGenHook:chests/simple_dungeon:3-3
rule19=0,100,ChestGenHook:chests/simple_dungeon:3-2

rule20=0,100,minecraft:spruce_stairs-5
rule21=0,100,minecraft:wooden_door-2
rule22=0,100,minecraft:stone_brick_stairs-0
rule23=0,100,minecraft:stone_brick_stairs-2
rule24=0,100,minecraft:stone_brick_stairs-3
rule25=0,100,minecraft:planks-0

rule26=0,100,MobSpawner:Skeleton,MobSpawner:Zombie,MobSpawner:Spider

rule27=0,100,minecraft:wooden_door-8
rule28=0,100,minecraft:fence-0
rule29=0,100,minecraft:log-4
rule30=0,100,minecraft:log-8
rule31=0,100,minecraft:stone_slab-10
rule32=0,100,minecraft:stone_slab-9
rule33=0,100,minecraft:spruce_stairs-1
rule34=0,100,minecraft:spruce_stairs-3
rule35=0,100,minecraft:spruce_stairs-2
rule36=0,100,minecraft:spruce_stairs-6
rule37=0,100,minecraft:spruce_stairs-7
rule38=0,100,minecraft:spruce_stairs-0
rule39=0,100,minecraft:carpet-14
rule40=0,100,minecraft:stone_slab-15
rule41=0,100,minecraft:acacia_stairs-2
rule42=0,100,minecraft:acacia_stairs-7
rule43=0,100,minecraft:acacia_stairs-6
rule44=0,100,minecraft:acacia_stairs-3
rule45=0,100,minecraft:wooden_slab-9
rule46=0,100,minecraft:planks-4
rule47=0,100,Skull:0:12-1
rule48=0,100,minecraft:wooden_slab-12
rule49=0,100,minecraft:wooden_slab-4
rule50=0,100,minecraft:acacia_stairs-0
rule51=0,100,minecraft:acacia_stairs-1
rule52=0,100,minecraft:acacia_stairs-5
rule53=0,100,minecraft:acacia_stairs-4

layer
1,1,1,1,1,1,1,1,1,1,1,1,1
1,1,1,1,1,1,1,1,1,1,1,1,1
1,1,1,1,2,1,1,1,2,1,1,1,1
1,1,3,2,2,2,2,2,2,2,3,1,1
1,1,2,4,4,4,4,4,4,4,2,1,1
1,2,2,4,4,4,4,4,4,4,2,2,1
1,1,2,4,4,4,4,4,4,4,2,1,1
1,1,2,4,4,4,4,4,4,4,2,1,1
1,1,2,4,4,4,4,4,4,4,2,1,1
1,2,2,4,4,4,4,4,4,4,2,2,1
1,1,2,4,4,4,4,4,4,4,2,1,1
1,3,3,3,3,3,3,3,3,3,3,3,1
1,3,3,3,3,3,3,3,3,3,3,3,1
1,1,3,3,3,3,3,3,3,3,3,1,1
1,1,1,3,3,3,3,3,3,3,1,1,1
endlayer

layer
1,1,1,1,1,1,1,1,1,1,1,1,1
1,1,1,1,1,1,1,1,1,1,1,1,1
1,1,1,1,2,1,1,1,2,1,1,1,1
1,1,3,2,2,2,2,2,2,2,3,1,1
1,1,2,2,0,2,5,2,0,2,2,1,1
1,2,2,0,0,0,0,0,0,0,2,2,1
1,1,2,2,0,0,0,0,0,2,2,1,1
1,1,2,0,0,0,0,0,0,0,2,1,1
1,1,2,2,0,0,0,0,0,2,2,1,1
1,2,2,9,8,8,8,8,7,6,2,2,1
1,1,2,2,0,2,10,2,0,2,2,1,1
1,1,3,3,3,3,3,3,3,3,3,1,1
1,1,3,3,3,3,3,3,3,3,3,1,1
1,1,1,3,3,3,3,3,3,3,1,1,1
1,1,1,1,3,3,3,3,3,1,1,1,1
endlayer

layer
1,1,1,1,1,1,1,1,1,1,1,1,1
1,1,1,1,1,1,1,1,1,1,1,1,1
1,1,1,1,2,1,1,1,2,1,1,1,1
1,1,3,2,2,2,2,2,2,2,3,1,1
1,1,2,2,0,2,11,2,0,2,2,1,1
1,2,2,0,0,0,0,0,0,0,2,2,1
1,1,2,2,0,0,0,0,0,2,2,1,1
1,1,2,0,0,0,0,0,0,0,2,1,1
1,1,2,2,0,0,0,0,0,2,2,1,1
1,2,2,13,0,0,0,0,0,12,2,2,1
1,1,2,2,0,2,0,2,0,2,2,1,1
1,1,3,3,3,3,3,3,3,3,3,1,1
1,1,1,3,3,3,3,3,3,3,1,1,1
1,1,1,1,3,3,3,3,3,1,1,1,1
1,1,1,1,1,3,3,3,1,1,1,1,1
endlayer

layer
1,1,1,1,1,1,1,1,1,1,1,1,1
1,1,1,1,1,1,1,1,1,1,1,1,1
1,1,1,1,2,1,1,1,2,1,1,1,1
1,1,3,2,2,2,2,2,2,2,3,1,1
1,1,2,2,0,2,11,2,0,2,2,1,1
1,2,2,0,0,0,0,0,0,0,2,2,1
1,1,2,2,0,0,0,0,0,2,2,1,1
1,1,2,0,0,0,0,0,0,0,2,1,1
1,1,2,2,0,0,0,0,0,2,2,1,1
1,2,2,0,0,0,0,0,0,0,2,2,1
1,1,2,2,0,2,0,2,0,2,2,1,1
1,1,3,3,3,3,3,3,3,3,3,1,1
1,1,1,1,3,3,3,3,3,1,1,1,1
1,1,1,1,1,3,3,3,1,1,1,1,1
1,1,1,1,1,1,1,1,1,1,1,1,1
endlayer

layer
1,1,1,1,1,1,1,1,1,1,1,1,1
1,1,1,1,1,1,1,1,1,1,1,1,1
1,1,1,1,2,1,1,1,2,1,1,1,1
1,1,3,2,2,2,2,2,2,2,3,1,1
1,1,2,2,0,2,11,2,0,2,2,1,1
1,2,2,0,0,0,0,0,0,0,2,2,1
1,1,2,2,0,0,0,0,0,2,2,1,1
1,1,2,0,0,0,0,0,0,0,2,1,1
1,1,2,2,0,0,0,0,0,2,2,1,1
1,2,2,0,0,0,0,0,0,0,2,2,1
1,1,2,2,0,2,0,2,0,2,2,1,1
1,1,3,3,3,3,3,3,3,3,3,1,1
1,1,1,1,3,3,3,3,3,1,1,1,1
1,1,1,1,1,3,3,3,1,1,1,1,1
1,1,1,1,1,1,1,1,1,1,1,1,1
endlayer

layer
1,1,1,1,1,1,1,1,1,1,1,1,1
1,1,1,1,1,1,1,1,1,1,1,1,1
1,1,1,1,2,1,1,1,2,1,1,1,1
1,1,3,2,2,2,2,2,2,2,3,1,1
1,1,2,2,0,2,11,2,0,2,2,1,1
1,2,2,0,0,0,0,0,0,0,2,2,1
1,1,2,2,0,0,0,0,0,2,2,1,1
1,1,2,0,0,0,0,0,0,0,2,1,1
1,1,2,2,0,0,0,0,0,2,2,1,1
1,2,2,0,0,0,0,0,0,0,2,2,1
1,1,2,2,0,2,0,2,0,2,2,1,1
1,1,3,3,3,3,3,3,3,3,3,1,1
1,1,1,1,3,3,3,3,3,1,1,1,1
1,1,1,1,1,3,3,3,1,1,1,1,1
1,1,1,1,1,1,1,1,1,1,1,1,1
endlayer

layer
1,1,1,1,1,1,1,1,1,1,1,1,1
1,1,1,1,1,1,1,1,1,1,1,1,1
1,1,1,1,2,1,1,1,2,1,1,1,1
1,1,3,2,2,2,2,2,2,2,3,1,1
1,1,2,2,0,2,11,2,0,2,2,1,1
1,2,2,0,0,0,0,0,0,0,2,2,1
1,1,2,2,0,0,0,0,0,2,2,1,1
1,1,2,0,0,0,0,0,0,0,2,1,1
1,1,2,2,0,0,0,0,0,2,2,1,1
1,2,2,0,0,0,0,0,0,0,2,2,1
1,1,2,2,0,2,0,2,0,2,2,1,1
1,1,3,3,3,3,3,3,3,3,3,1,1
1,1,1,1,3,3,3,3,3,1,1,1,1
1,1,1,1,1,3,3,3,1,1,1,1,1
1,1,1,1,1,1,1,1,1,1,1,1,1
endlayer


layer
1,1,1,1,1,1,1,1,1,1,1,1,1
1,1,1,1,1,1,1,1,1,1,1,1,1
1,1,1,1,2,1,1,1,2,1,1,1,1
1,1,3,2,2,2,2,2,2,2,3,1,1
1,1,2,14,15,14,11,14,15,14,2,1,1
1,2,2,15,14,15,14,15,14,15,2,2,1
1,1,2,14,15,14,15,14,15,14,2,1,1
1,1,2,15,14,15,14,15,14,15,2,1,1
1,1,2,14,15,14,15,14,15,14,2,1,1
1,2,2,15,14,15,14,15,14,15,2,2,1
1,1,2,14,15,14,15,14,15,14,2,1,1
1,1,3,3,3,3,3,3,2,2,3,1,1
1,1,1,1,1,3,3,3,1,1,1,1,1
1,1,1,1,1,1,1,1,1,1,1,1,1
1,1,1,1,1,1,1,1,1,1,1,1,1
endlayer

layer
1,1,1,1,1,1,1,1,1,1,1,1,1
1,1,1,0,0,0,0,0,0,0,1,1,1
1,1,0,0,2,0,0,0,2,0,0,1,1
1,0,3,2,2,2,2,2,2,2,3,0,1
1,0,2,0,0,0,16,0,0,0,2,0,1
1,2,2,0,0,0,0,0,0,0,2,2,1
1,1,2,17,0,0,0,0,0,17,2,1,1
1,1,2,19,0,0,0,0,0,18,2,1,1
1,1,2,20,0,0,0,0,0,20,2,1,1
1,2,2,0,0,0,0,0,0,0,2,2,1
1,0,2,0,0,0,0,0,0,0,2,0,1
1,0,3,2,2,3,21,3,2,2,3,0,1
1,1,0,0,0,0,0,0,0,0,0,1,1
1,1,1,0,0,0,0,0,0,1,1,1,1
1,1,1,1,1,1,1,1,1,1,1,1,1
endlayer

layer
1,1,1,1,0,0,0,0,0,1,1,1,1
1,1,0,0,0,0,0,0,0,0,0,1,1
1,0,0,0,22,0,0,0,22,0,0,0,1
1,0,3,2,2,2,2,2,2,2,3,0,1
0,0,2,0,0,0,11,0,0,0,2,0,0
0,24,2,0,0,0,0,0,0,0,2,23,0
0,0,2,0,0,0,0,0,0,0,2,0,0
0,0,25,26,0,0,0,0,0,26,25,0,0
0,0,2,0,0,0,0,0,0,0,2,0,0
0,24,2,0,0,0,0,0,0,0,2,23,0
0,0,2,0,0,0,0,0,0,0,2,0,0
1,0,3,2,25,3,27,3,25,2,3,0,1
1,0,0,0,0,0,0,0,0,0,0,0,1
1,1,0,0,0,0,0,0,0,0,0,1,1
1,1,1,1,0,0,0,0,0,1,1,1,1
endlayer

layer
1,1,0,0,0,0,0,0,0,0,0,1,1
1,0,0,0,0,0,0,0,0,0,0,0,1
0,0,0,0,0,0,0,0,0,0,0,0,0
0,0,3,2,2,2,2,2,2,2,3,0,0
0,0,2,28,0,28,11,28,0,28,2,0,0
0,0,2,0,0,0,0,0,0,0,2,0,0
0,0,2,28,0,0,0,0,0,28,2,0,0
0,0,25,0,0,0,0,0,0,0,25,0,0
0,0,2,28,0,0,0,0,0,28,2,0,0
0,0,2,0,0,0,0,0,0,0,2,0,0
0,0,2,28,0,28,0,28,0,28,2,0,0
0,0,3,2,25,3,3,3,25,2,3,0,0
0,0,0,0,0,0,0,0,0,0,0,0,0
1,0,0,0,0,0,0,0,0,0,0,0,1
1,1,0,0,0,0,0,0,0,0,0,1,1
endlayer

layer
1,0,0,0,0,0,0,0,0,0,0,0,1
0,0,0,0,0,0,0,0,0,0,0,0,0
0,0,0,0,0,0,0,0,0,0,0,0,0
0,0,3,2,2,2,2,2,2,2,3,0,0
0,0,2,0,0,0,11,0,0,0,2,0,0
0,0,2,0,0,0,0,0,0,0,2,0,0
0,0,2,0,0,0,0,0,0,0,2,0,0
0,0,2,0,0,0,0,0,0,0,2,0,0
0,0,2,0,0,0,0,0,0,0,2,0,0
0,0,2,0,0,0,0,0,0,0,2,0,0
0,0,2,0,0,0,0,0,0,0,2,0,0
0,0,3,2,2,2,2,2,2,2,3,0,0
0,0,0,0,0,0,0,0,0,0,0,0,0
0,0,0,0,0,0,0,0,0,0,0,0,0
1,0,0,0,0,0,0,0,0,0,0,0,1
endlayer

layer
1,0,0,0,0,0,0,0,0,0,0,0,1
0,0,0,0,0,0,0,0,0,0,0,0,0
0,0,0,0,0,0,0,0,0,0,0,0,0
0,0,3,2,2,2,2,2,2,2,3,0,0
0,0,2,0,0,0,11,0,0,0,2,0,0
0,0,2,0,0,0,0,0,0,0,2,0,0
0,0,2,0,0,0,0,0,0,0,2,0,0
0,0,2,0,0,0,0,0,0,0,2,0,0
0,0,2,0,0,0,0,0,0,0,2,0,0
0,0,2,0,0,0,0,0,0,0,2,0,0
0,0,2,0,0,0,0,0,0,0,2,0,0
0,0,3,2,2,2,2,2,2,2,3,0,0
0,0,0,0,0,0,0,0,0,0,0,0,0
0,0,0,0,0,0,0,0,0,0,0,0,0
1,0,0,0,0,0,0,0,0,0,0,0,1
endlayer



layer
0,0,0,0,0,0,0,0,0,0,0,0,0
0,0,0,0,0,0,0,0,0,0,0,0,0
0,0,0,29,0,0,29,0,0,29,0,0,0
0,0,3,3,3,3,3,3,3,3,3,0,0
0,30,3,15,31,15,11,15,31,15,3,30,0
0,0,3,31,15,31,15,31,15,31,3,0,0
0,0,3,15,31,32,32,32,31,15,3,0,0
0,30,3,31,15,32,15,32,15,31,3,30,0
0,0,3,15,31,32,32,32,31,15,3,0,0
0,0,3,31,15,31,15,31,15,31,3,0,0
0,30,3,15,31,15,31,15,31,15,3,30,0
0,0,3,3,3,3,3,3,3,3,3,0,0
0,0,0,29,0,0,29,0,0,29,0,0,0
0,0,0,0,0,0,0,0,0,0,0,0,0
0,0,0,0,0,0,0,0,0,0,0,0,0
endlayer

layer
0,0,0,0,0,0,0,0,0,0,0,0,0
0,0,0,0,0,0,0,0,0,0,0,0,0
0,14,30,14,30,14,30,14,30,14,30,14,0
0,29,26,0,0,33,33,33,0,0,26,29,0
0,14,0,0,0,0,16,0,0,0,0,14,0
0,29,0,0,0,0,0,0,0,0,0,29,0
0,14,35,0,0,0,17,0,0,0,34,14,0
0,29,19,0,0,37,26,36,0,0,18,29,0
0,14,35,0,0,0,20,0,0,0,34,14,0
0,29,0,0,0,0,0,0,0,0,0,29,0
0,14,0,0,0,0,0,0,0,0,0,14,0
0,29,26,0,0,38,10,38,0,0,26,29,0
0,14,30,14,30,14,30,14,30,14,30,14,0
0,0,0,0,0,0,0,0,0,0,0,0,0
0,0,0,0,0,0,0,0,0,0,0,0,0
endlayer

layer
0,0,0,0,0,0,0,0,0,0,0,0,0
0,0,0,0,0,0,0,0,0,0,0,0,0
0,14,25,14,25,14,25,14,25,14,25,14,0
0,25,0,0,0,0,11,0,0,0,0,25,0
0,14,0,0,0,0,0,0,0,0,0,14,0
0,25,0,0,0,0,0,0,0,0,0,25,0
0,14,0,0,0,0,39,0,0,0,0,14,0
0,25,0,0,0,39,10,39,0,0,0,25,0
0,14,0,0,0,0,39,0,0,0,0,14,0
0,25,0,0,0,0,0,0,0,0,0,25,0
0,14,0,0,0,0,0,0,0,0,0,14,0
0,25,0,0,0,0,0,0,0,0,0,25,0
0,14,25,14,25,14,25,14,25,14,25,14,0
0,0,0,0,0,0,0,0,0,0,0,0,0
0,0,0,0,0,0,0,0,0,0,0,0,0
endlayer

layer
0,0,0,0,0,0,0,0,0,0,0,0,0
0,0,0,0,0,0,0,0,0,0,0,0,0
0,14,25,14,25,14,25,14,25,14,25,14,0
0,25,0,0,0,0,11,0,0,0,0,25,0
0,14,0,0,0,0,0,0,0,0,0,14,0
0,25,0,0,0,0,0,0,0,0,0,25,0
0,14,0,0,0,0,0,0,0,0,0,14,0
0,25,0,0,0,0,0,0,0,0,0,25,0
0,14,0,0,0,0,0,0,0,0,0,14,0
0,25,0,0,0,0,0,0,0,0,0,25,0
0,14,0,0,0,0,0,0,0,0,0,14,0
0,25,0,0,0,0,0,0,0,0,0,25,0
0,14,25,14,25,14,25,14,25,14,25,14,0
0,0,0,0,0,0,0,0,0,0,0,0,0
0,0,0,0,0,0,0,0,0,0,0,0,0
endlayer

layer
0,0,0,0,0,0,0,0,0,0,0,0,0
0,0,0,0,0,0,0,0,0,0,0,0,0
0,14,25,14,25,14,25,14,25,14,25,14,0
0,25,0,0,0,0,11,0,0,0,0,25,0
0,14,0,0,0,0,0,0,0,0,0,14,0
0,25,0,0,0,0,0,0,0,0,0,25,0
0,14,0,0,0,0,0,0,0,0,0,14,0
0,25,0,0,0,0,0,0,0,0,0,25,0
0,14,0,0,0,0,0,0,0,0,0,14,0
0,25,0,0,0,0,0,0,0,0,0,25,0
0,14,0,0,0,0,0,0,0,0,0,14,0
0,25,0,0,0,0,0,0,0,0,0,25,0
0,14,25,14,25,14,25,14,25,14,25,14,0
0,0,0,0,0,0,0,0,0,0,0,0,0
0,0,0,0,0,0,0,0,0,0,0,0,0
endlayer

layer
0,0,0,0,0,0,0,0,0,0,0,0,0
0,0,0,0,0,0,0,0,0,0,0,0,0
0,14,30,14,30,14,30,14,30,14,30,14,0
0,29,40,40,40,40,11,40,40,40,40,29,0
0,14,30,30,30,30,30,30,30,30,30,14,0
0,29,40,40,40,40,40,40,40,40,40,29,0
0,14,30,30,30,30,30,30,30,30,30,14,0
0,29,40,40,40,40,40,40,40,40,40,29,0
0,14,30,30,30,30,30,30,30,30,30,14,0
0,29,40,40,40,40,40,40,40,40,40,29,0
0,14,30,30,30,30,30,30,30,30,30,14,0
0,29,40,40,40,40,40,40,40,40,40,29,0
0,14,30,14,30,14,30,14,30,14,30,14,0
0,0,0,0,0,0,0,0,0,0,0,0,0
0,0,0,0,0,0,0,0,0,0,0,0,0
endlayer

layer
0,0,0,0,0,0,0,0,0,0,0,0,0
44,43,0,0,0,0,0,0,0,0,0,42,41
44,14,25,14,25,14,25,14,25,14,25,14,41
44,25,0,0,0,0,16,0,0,0,0,25,41
44,25,0,0,0,0,0,0,0,0,0,25,41
44,25,28,0,0,0,33,0,0,0,28,25,41
44,25,36,0,0,0,0,0,0,0,37,25,41
44,25,45,0,0,36,45,37,0,0,45,25,41
44,25,36,0,0,0,0,0,0,0,37,25,41
44,25,28,0,0,0,0,0,0,0,28,25,41
44,25,0,0,0,0,0,0,0,0,0,25,41
44,25,0,0,0,37,10,36,0,0,0,25,41
44,14,25,14,25,14,25,14,25,14,25,14,41
44,43,0,0,0,0,0,0,0,0,0,42,41
0,0,0,0,0,0,0,0,0,0,0,0,0
endlayer

layer
0,0,0,0,0,0,0,0,0,0,0,0,0
0,46,0,0,0,0,0,0,0,0,0,46,0
0,46,25,14,25,14,25,14,25,14,25,46,0
0,46,0,0,0,0,0,0,0,0,0,46,0
0,46,0,0,0,0,0,0,0,0,0,46,0
0,46,0,0,0,0,0,0,0,0,0,46,0
0,46,0,0,0,0,0,0,0,0,0,46,0
0,46,39,0,0,0,39,0,0,0,39,46,0
0,46,0,0,0,0,0,0,0,0,0,46,0
0,46,0,0,0,0,0,0,0,0,0,46,0
0,46,0,0,0,0,0,0,0,0,0,46,0
0,46,0,0,0,47,26,47,0,0,0,46,0
0,46,25,14,25,14,25,14,25,14,25,46,0
0,46,0,0,0,0,0,0,0,0,0,46,0
0,0,0,0,0,0,0,0,0,0,0,0,0
endlayer

layer
0,0,0,0,0,0,0,0,0,0,0,0,0
0,44,43,0,0,0,0,0,0,0,42,41,0
0,44,25,14,25,14,30,14,25,14,25,41,0
0,44,43,0,0,0,0,0,0,0,42,41,0
0,44,43,0,0,0,0,0,0,0,42,41,0
0,44,43,0,0,0,0,0,0,0,42,41,0
0,44,43,0,0,0,0,0,0,0,42,41,0
0,44,43,0,0,0,0,0,0,0,42,41,0
0,44,43,0,0,0,0,0,0,0,42,41,0
0,44,43,0,0,0,0,0,0,0,42,41,0
0,44,43,0,0,0,0,0,0,0,42,41,0
0,44,43,0,0,0,0,0,0,0,42,41,0
0,44,25,14,25,14,30,14,25,14,25,41,0
0,44,43,0,0,0,0,0,0,0,42,41,0
0,0,0,0,0,0,0,0,0,0,0,0,0
endlayer

layer
0,0,0,0,0,0,0,0,0,0,0,0,0
0,0,46,0,0,0,0,0,0,0,46,0,0
0,0,46,14,25,14,25,14,25,14,46,0,0
0,0,46,0,0,0,0,0,0,0,46,0,0
0,0,46,0,0,0,0,0,0,0,46,0,0
0,0,46,0,0,0,0,0,0,0,46,0,0
0,0,46,0,0,0,0,0,0,0,46,0,0
0,0,46,0,0,0,0,0,0,0,46,0,0
0,0,46,0,0,0,0,0,0,0,46,0,0
0,0,46,0,0,0,0,0,0,0,46,0,0
0,0,46,0,0,0,0,0,0,0,46,0,0
0,0,46,0,0,0,0,0,0,0,46,0,0
0,0,46,14,25,14,25,14,25,14,46,0,0
0,0,46,0,0,0,0,0,0,0,46,0,0
0,0,0,0,0,0,0,0,0,0,0,0,0
endlayer

layer
0,0,0,0,0,0,0,0,0,0,0,0,0
0,0,44,43,0,0,0,0,0,42,41,0,0
0,0,44,14,30,14,25,14,30,14,41,0,0
0,0,44,43,0,0,0,0,0,42,41,0,0
0,0,44,43,0,0,0,0,0,42,41,0,0
0,0,44,43,0,0,0,0,0,42,41,0,0
0,0,44,43,0,0,0,0,0,42,41,0,0
0,0,44,43,0,0,0,0,0,42,41,0,0
0,0,44,43,0,0,0,0,0,42,41,0,0
0,0,44,43,0,0,0,0,0,42,41,0,0
0,0,44,43,0,0,0,0,0,42,41,0,0
0,0,44,43,0,0,0,0,0,42,41,0,0
0,0,44,14,30,14,25,14,30,14,41,0,0
0,0,44,43,0,0,0,0,0,42,41,0,0
0,0,0,0,0,0,0,0,0,0,0,0,0
endlayer

layer
0,0,0,0,0,0,0,0,0,0,0,0,0
0,0,0,44,43,0,0,0,42,41,0,0,0
0,0,0,44,25,14,30,14,25,41,0,0,0
0,0,0,44,43,0,0,0,42,41,0,0,0
0,0,0,44,43,0,0,0,42,41,0,0,0
0,0,0,44,43,0,0,0,42,41,0,0,0
0,0,0,44,43,0,0,0,42,41,0,0,0
0,0,0,44,43,0,0,0,42,41,0,0,0
0,0,0,44,43,0,0,0,42,41,0,0,0
0,0,0,44,43,0,0,0,42,41,0,0,0
0,0,0,44,43,0,0,0,42,41,0,0,0
0,0,0,44,43,0,0,0,42,41,0,0,0
0,0,0,44,25,14,30,14,25,41,0,0,0
0,0,0,44,43,0,0,0,42,41,0,0,0
0,0,0,0,0,0,0,0,0,0,0,0,0
endlayer

layer
0,0,0,0,0,0,0,0,0,0,0,0,0
0,0,0,0,44,43,48,42,41,0,0,0,0
0,0,0,0,44,14,25,14,41,0,0,0,0
0,0,0,0,44,43,31,42,41,0,0,0,0
0,0,0,0,44,43,31,42,41,0,0,0,0
0,0,0,0,44,43,31,42,41,0,0,0,0
0,0,0,0,44,43,31,42,41,0,0,0,0
0,0,0,0,44,43,31,42,41,0,0,0,0
0,0,0,0,44,43,31,42,41,0,0,0,0
0,0,0,0,44,43,31,42,41,0,0,0,0
0,0,0,0,44,43,31,42,41,0,0,0,0
0,0,0,0,44,43,31,42,41,0,0,0,0
0,0,0,0,44,14,25,14,41,0,0,0,0
0,0,0,0,44,43,48,42,41,0,0,0,0
0,0,0,0,0,0,0,0,0,0,0,0,0
endlayer

layer
0,0,0,0,0,0,0,0,0,0,0,0,0
0,0,0,0,0,49,46,49,0,0,0,0,0
0,0,0,0,0,49,46,49,0,0,0,0,0
0,0,0,0,0,49,50,49,0,0,0,0,0
0,0,0,0,0,49,51,49,0,0,0,0,0
0,0,0,0,0,49,50,49,0,0,0,0,0
0,0,0,0,0,49,51,49,0,0,0,0,0
0,0,0,0,0,49,46,49,0,0,0,0,0
0,0,0,0,0,49,50,49,0,0,0,0,0
0,0,0,0,0,49,51,49,0,0,0,0,0
0,0,0,0,0,49,50,49,0,0,0,0,0
0,0,0,0,0,49,51,49,0,0,0,0,0
0,0,0,0,0,49,46,49,0,0,0,0,0
0,0,0,0,0,49,46,49,0,0,0,0,0
0,0,0,0,0,0,0,0,0,0,0,0,0
endlayer

layer
0,0,0,0,0,0,0,0,0,0,0,0,0
0,0,0,0,0,0,46,0,0,0,0,0,0
0,0,0,0,0,0,52,0,0,0,0,0,0
0,0,0,0,0,0,0,0,0,0,0,0,0
0,0,0,0,0,0,0,0,0,0,0,0,0
0,0,0,0,0,0,0,0,0,0,0,0,0
0,0,0,0,0,0,0,0,0,0,0,0,0
0,0,0,0,0,0,49,0,0,0,0,0,0
0,0,0,0,0,0,0,0,0,0,0,0,0
0,0,0,0,0,0,0,0,0,0,0,0,0
0,0,0,0,0,0,0,0,0,0,0,0,0
0,0,0,0,0,0,0,0,0,0,0,0,0
0,0,0,0,0,0,53,0,0,0,0,0,0
0,0,0,0,0,0,46,0,0,0,0,0,0
0,0,0,0,0,0,0,0,0,0,0,0,0
endlayer

layer
0,0,0,0,0,0,0,0,0,0,0,0,0
0,0,0,0,0,0,46,0,0,0,0,0,0
0,0,0,0,0,0,52,0,0,0,0,0,0
0,0,0,0,0,0,0,0,0,0,0,0,0
0,0,0,0,0,0,0,0,0,0,0,0,0
0,0,0,0,0,0,0,0,0,0,0,0,0
0,0,0,0,0,0,0,0,0,0,0,0,0
0,0,0,0,0,0,0,0,0,0,0,0,0
0,0,0,0,0,0,0,0,0,0,0,0,0
0,0,0,0,0,0,0,0,0,0,0,0,0
0,0,0,0,0,0,0,0,0,0,0,0,0
0,0,0,0,0,0,0,0,0,0,0,0,0
0,0,0,0,0,0,53,0,0,0,0,0,0
0,0,0,0,0,0,46,0,0,0,0,0,0
0,0,0,0,0,0,0,0,0,0,0,0,0
endlayer

layer
0,0,0,0,0,0,49,0,0,0,0,0,0
0,0,0,0,0,0,46,0,0,0,0,0,0
0,0,0,0,0,0,52,0,0,0,0,0,0
0,0,0,0,0,0,0,0,0,0,0,0,0
0,0,0,0,0,0,0,0,0,0,0,0,0
0,0,0,0,0,0,0,0,0,0,0,0,0
0,0,0,0,0,0,0,0,0,0,0,0,0
0,0,0,0,0,0,0,0,0,0,0,0,0
0,0,0,0,0,0,0,0,0,0,0,0,0
0,0,0,0,0,0,0,0,0,0,0,0,0
0,0,0,0,0,0,0,0,0,0,0,0,0
0,0,0,0,0,0,0,0,0,0,0,0,0
0,0,0,0,0,0,53,0,0,0,0,0,0
0,0,0,0,0,0,46,0,0,0,0,0,0
0,0,0,0,0,0,49,0,0,0,0,0,0
endlayer

layer
0,0,0,0,0,0,50,0,0,0,0,0,0
0,0,0,0,0,0,51,0,0,0,0,0,0
0,0,0,0,0,0,48,0,0,0,0,0,0
0,0,0,0,0,0,0,0,0,0,0,0,0
0,0,0,0,0,0,0,0,0,0,0,0,0
0,0,0,0,0,0,0,0,0,0,0,0,0
0,0,0,0,0,0,0,0,0,0,0,0,0
0,0,0,0,0,0,0,0,0,0,0,0,0
0,0,0,0,0,0,0,0,0,0,0,0,0
0,0,0,0,0,0,0,0,0,0,0,0,0
0,0,0,0,0,0,0,0,0,0,0,0,0
0,0,0,0,0,0,0,0,0,0,0,0,0
0,0,0,0,0,0,48,0,0,0,0,0,0
0,0,0,0,0,0,50,0,0,0,0,0,0
0,0,0,0,0,0,51,0,0,0,0,0,0
endlayer

