# Boarded-Up Manor
# Created by Ruins mod version 16.5 Ingame Parser
# authoring Player: Kujaku10
# Created for MC 1.12: 21 Jun 2017
# Updated to MC 1.12.1: 10 Sep 2017

biomesToSpawnIn=biome_degraded,crag,foresthills,forest_hills,alps_foothills,autumn woods,autumn_woods,autumnal_woods,autumn hills,autumn_hills,mining biome,miningbiome,rwg_temperateforest,xeric shrubland,xeric_shrubland,woodland,woodlands

weight=1
embed_into_distance=5
acceptable_target_blocks=

unacceptable_target_blocks=flowing_water,water,flowing_lava,lava,cloud,Natura:Cloud,slime_congealed,slime_dirt,slime_grass,command_block,planks,planks2,concrete,cobblestone,stonebrick,brick_block,glass,torch,oak_stairs,stone_stairs,brick_stairs,stone_brick_stairs,nether_brick_stairs,sandstone_stairs,spruce_stairs,birch_stairs,jungle_stairs,quartz_stairs,acacia_stairs,dark_oak_stairs,cobblestone_wall,stone_slab,double_stone_slab,stone_slab2,wooden_slab,double_wooden_slab,nether_brick

dimensions=28,14,16
allowable_overhang=0
max_leveling=5
leveling_buffer=-1
preserve_water=0
preserve_lava=0
preserve_plants=1

rule1=0,100,preserveBlock

# Polished Andesite
rule2=0,100,minecraft:stone-6

# Stone Brick (underground)
rule3=0,100,minecraft:stonebrick-1,minecraft:stonebrick-1,minecraft:stonebrick,minecraft:stonebrick-2,minecraft:stonebrick-2

rule4=0,100,minecraft:mossy_cobblestone-0

rule5=0,100,minecraft:green_glazed_terracotta-0
rule6=0,100,minecraft:green_glazed_terracotta-3
rule7=0,100,minecraft:green_glazed_terracotta-1
rule8=0,100,minecraft:green_glazed_terracotta-2

rule9=0,100,minecraft:tnt,minecraft:tnt-1

rule10=0,100,ChestGenHook:chests/simple_dungeon:5-5
rule11=0,100,minecraft:gravel-0
rule12=0,100,minecraft:spruce_stairs-0
rule13=0,100,minecraft:spruce_stairs-5
rule14=0,100,minecraft:stone_brick_stairs-2
rule15=0,100,minecraft:stone_brick_stairs-0
rule16=0,100,minecraft:stone_brick_stairs-3

rule17=0,100,MobSpawner:Skeleton,MobSpawner:Spider,MobSpawner:Zombie

# Stone Brick (above ground)
rule18=0,100,minecraft:stonebrick-0,minecraft:stonebrick-0,minecraft:stonebrick-0,minecraft:stonebrick-1,minecraft:stonebrick-2

rule19=0,100,IInventory;minecraft:trapped_chest;minecraft:mossy_cobblestone#4#0#3+minecraft:clay#6#0#5+minecraft:iron_ingot#1#0#9+minecraft:sand#6#0#11+minecraft:sapling#4#1#16+minecraft:coal#4#0#22-4

rule20=0,100,minecraft:stone_slab-8

rule21=0,100,minecraft:blue_glazed_terracotta-0
rule22=0,100,minecraft:blue_glazed_terracotta-3
rule23=0,100,minecraft:blue_glazed_terracotta-1
rule24=0,100,minecraft:blue_glazed_terracotta-2

rule25=0,100,minecraft:netherrack-0
rule26=0,100,minecraft:cobblestone_wall-0
rule27=0,100,minecraft:stonebrick-3
rule28=0,100,minecraft:dark_oak_door-0
rule29=0,100,minecraft:spruce_stairs-4
rule30=0,100,minecraft:spruce_stairs-1
rule31=0,100,minecraft:iron_bars-0
rule32=0,100,minecraft:cobblestone-0
rule33=0,100,minecraft:fire-15
rule34=0,100,minecraft:planks-0
rule35=0,100,minecraft:dark_oak_door-8
rule36=0,100,minecraft:dark_oak_door-9
rule37=0,100,minecraft:stone_brick_stairs-4
rule38=0,100,minecraft:stone_brick_stairs-7
rule39=0,100,minecraft:stone_brick_stairs-6
rule40=0,100,minecraft:nether_brick_stairs-2
rule41=0,100,minecraft:nether_brick_stairs-7
rule42=0,100,minecraft:nether_brick_stairs-6
rule43=0,100,minecraft:nether_brick_stairs-3
rule44=0,100,minecraft:log-5
rule45=0,100,minecraft:red_glazed_terracotta-1
rule46=0,100,minecraft:red_glazed_terracotta-0
rule47=0,100,minecraft:log-9
rule48=0,100,minecraft:red_glazed_terracotta-2
rule49=0,100,minecraft:red_glazed_terracotta-3
rule50=0,100,minecraft:stone_slab-6
rule51=0,100,minecraft:log-1
rule52=0,100,minecraft:oak_stairs-4
rule53=0,100,minecraft:wooden_slab-8
rule54=0,100,minecraft:oak_stairs-1
rule55=0,100,minecraft:oak_stairs-5
rule56=0,100,ChestGenHook:chests/simple_dungeon:3-4
rule57=0,100,minecraft:trapdoor-14
rule58=0,100,minecraft:bone_block-0
rule59=0,100,minecraft:trapdoor-12
rule60=0,100,minecraft:trapdoor-13
rule61=0,100,minecraft:carpet-14
rule62=0,100,minecraft:trapdoor-15
rule63=0,100,minecraft:nether_brick-0
rule64=0,100,ChestGenHook:chests/simple_dungeon:3-3
rule65=0,100,ChestGenHook:chests/simple_dungeon:3-2
rule66=0,100,minecraft:stone_slab-14
rule67=0,100,minecraft:nether_brick_stairs-0
rule68=0,100,minecraft:nether_brick_stairs-1

layer
1,1,1,1,1,1,2,1,1,2,1,1,1,1,1,1
1,2,2,1,2,1,2,3,3,2,1,2,1,2,2,1
1,2,2,1,2,1,3,4,4,3,1,2,1,2,2,1
1,1,2,3,3,3,2,3,3,2,3,3,3,2,1,1
1,1,3,4,4,6,5,6,5,6,5,4,4,3,1,1
1,1,3,4,4,8,7,8,7,8,7,4,4,3,1,1
1,1,3,4,4,6,5,6,5,6,5,4,4,3,1,1
1,1,3,4,4,8,7,8,7,8,7,4,4,3,1,1
1,1,3,4,4,6,4,4,4,4,5,4,4,3,1,1
1,1,3,4,4,8,4,9,9,4,7,4,4,3,1,1
1,1,2,3,3,3,2,3,3,2,3,3,3,2,1,1
1,1,1,1,1,1,3,0,0,3,1,1,1,1,1,1
1,1,1,1,1,1,2,3,3,2,1,1,1,1,1,1
1,1,1,1,1,1,1,1,1,1,1,1,1,1,1,1
endlayer

layer
1,1,1,1,1,1,2,1,1,2,1,1,1,1,1,1
1,1,2,1,2,1,2,3,3,2,1,2,1,2,1,1
1,1,2,1,2,1,3,10,10,3,1,2,1,2,1,1
1,1,2,3,3,3,2,11,11,2,3,3,3,2,1,1
1,1,3,0,0,0,0,0,0,0,0,0,0,3,1,1
1,1,3,0,0,0,0,0,0,0,0,0,12,3,1,1
1,1,3,0,0,0,0,0,0,0,0,0,13,3,1,1
1,1,3,0,0,0,0,0,0,0,0,0,0,3,1,1
1,1,3,0,0,0,16,15,15,14,0,0,0,3,1,1
1,1,3,17,0,0,16,18,18,14,0,0,17,3,1,1
1,1,2,3,3,3,2,3,3,2,3,3,3,2,1,1
1,1,1,1,1,1,3,0,0,3,1,1,1,1,1,1
1,1,1,1,1,1,2,3,3,2,1,1,1,1,1,1
1,1,1,1,1,1,1,1,1,1,1,1,1,1,1,1
endlayer

layer
1,1,1,1,1,1,2,1,1,2,1,1,1,1,1,1
1,1,1,2,2,1,2,3,3,2,1,2,2,1,1,1
1,1,1,2,2,1,3,17,17,3,1,2,2,1,1,1
1,1,2,3,3,3,2,2,2,2,3,3,3,2,1,1
1,1,3,0,0,0,0,0,0,0,0,0,0,3,1,1
1,1,3,0,0,0,0,0,0,0,0,0,0,3,1,1
1,1,3,0,0,0,0,0,0,0,0,0,12,3,1,1
1,1,3,0,0,0,0,0,0,0,0,0,13,3,1,1
1,1,3,0,0,0,0,0,0,0,0,0,0,3,1,1
1,1,3,0,0,0,0,19,19,0,0,0,0,3,1,1
1,1,2,3,3,3,2,3,3,2,3,3,3,2,1,1
1,1,1,1,1,1,3,0,0,3,1,1,1,1,1,1
1,1,1,1,1,1,2,3,3,2,1,1,1,1,1,1
1,1,1,1,1,1,1,1,1,1,1,1,1,1,1,1
endlayer

layer
1,1,1,1,1,1,2,1,1,2,1,1,1,1,1,1
1,1,1,1,2,2,2,3,3,2,1,2,1,1,1,1
1,1,1,1,2,2,3,0,0,3,1,2,1,1,1,1
1,1,2,3,3,3,2,3,3,2,3,3,3,2,1,1
1,1,3,0,0,0,0,0,0,0,0,0,0,3,1,1
1,1,3,0,0,0,0,0,0,0,0,0,0,3,1,1
1,1,3,0,0,0,0,0,0,0,0,0,0,3,1,1
1,1,3,0,0,0,0,0,0,0,0,0,12,3,1,1
1,1,3,0,0,0,0,0,0,0,0,0,13,3,1,1
1,1,3,0,0,0,0,0,0,0,0,0,0,3,1,1
1,1,2,3,3,3,2,3,3,2,3,3,3,2,1,1
1,1,1,1,1,1,3,0,0,3,1,1,1,1,1,1
1,1,1,1,1,1,2,3,3,2,1,1,1,1,1,1
1,1,1,1,1,1,1,1,1,1,1,1,1,1,1,1
endlayer

layer
1,1,1,1,1,2,2,2,2,2,2,1,1,1,1,1
1,1,1,1,1,2,2,3,3,2,2,1,1,1,1,1
1,1,1,1,1,2,3,0,0,3,2,1,1,1,1,1
1,1,2,3,3,3,2,3,3,2,3,3,3,2,1,1
1,1,3,0,0,0,0,0,0,0,0,0,0,3,1,1
1,1,3,0,0,0,0,0,0,0,0,0,0,3,1,1
1,1,3,0,0,0,0,0,0,0,0,0,0,3,1,1
1,1,3,0,0,0,0,0,0,0,0,0,0,3,1,1
1,1,3,0,0,0,0,0,0,0,0,0,12,3,1,1
1,1,3,0,0,0,0,0,0,0,0,0,13,3,1,1
1,1,2,3,3,3,2,3,3,2,3,3,3,2,1,1
1,1,1,1,1,1,3,0,0,3,1,1,1,1,1,1
1,1,1,1,1,1,2,3,3,2,1,1,1,1,1,1
1,1,1,1,1,1,1,1,1,1,1,1,1,1,1,1
endlayer

layer
1,1,1,1,0,1,0,0,0,0,1,0,1,1,1,1
1,1,0,0,0,0,2,15,15,2,0,0,0,0,1,1
1,0,0,0,0,0,16,20,20,14,0,0,0,0,0,1
1,0,2,2,2,2,2,2,2,2,2,2,2,2,0,1
1,0,2,20,2,22,21,22,21,22,21,2,20,2,0,1
1,0,2,20,2,24,23,24,23,24,23,2,20,2,0,1
0,0,2,20,2,22,21,22,21,22,21,2,0,2,0,0
0,0,2,20,2,24,23,24,23,24,23,2,0,2,0,0
1,0,2,20,2,22,21,22,21,22,21,2,0,2,0,1
1,0,2,20,2,24,23,24,23,24,23,2,12,2,0,1
1,0,2,2,2,2,2,2,2,2,2,2,2,2,1,1
1,1,1,1,1,1,2,25,25,2,1,1,1,1,1,1
1,1,1,1,1,1,2,2,2,2,1,1,1,1,1,1
1,1,1,1,1,1,1,1,1,1,1,1,1,1,1,1
endlayer

layer
1,1,1,0,0,0,0,0,0,0,0,0,0,1,1,1
1,0,0,0,0,0,26,0,0,26,0,0,0,0,0,1
1,0,0,0,0,0,0,0,0,0,0,0,0,0,0,1
0,0,2,18,27,18,2,28,28,2,18,27,18,2,0,0
0,0,18,0,0,0,0,0,0,0,0,0,0,18,0,0
0,0,27,0,0,0,0,0,0,0,0,0,0,27,0,0
0,0,18,0,0,0,0,0,0,0,0,0,0,18,0,0
0,0,18,29,0,0,0,0,0,0,0,0,0,18,0,0
0,0,27,30,0,0,0,0,0,0,0,0,0,27,0,0
0,0,18,0,0,0,0,0,0,0,0,0,0,18,0,0
0,0,2,18,27,18,2,31,31,2,18,27,18,2,0,0
1,0,0,0,0,0,32,33,33,32,0,0,0,0,0,1
1,0,0,0,0,0,26,32,32,26,0,0,0,0,0,1
1,1,1,1,1,0,0,0,0,0,0,1,1,1,1,1
endlayer

layer
1,1,0,0,0,0,0,0,0,0,0,0,0,0,1,1
1,0,0,0,0,0,26,0,0,26,0,0,0,0,0,1
0,0,0,0,0,0,0,0,0,0,0,0,0,0,0,0
0,0,2,18,34,18,2,36,35,2,18,34,18,2,0,0
0,0,18,0,0,0,0,0,0,0,0,0,0,18,0,0
0,0,34,0,0,0,0,0,0,0,0,0,0,34,0,0
0,0,18,29,0,0,0,0,0,0,0,0,0,18,0,0
0,0,18,30,0,0,0,0,0,0,0,0,0,18,0,0
0,0,34,0,0,0,0,0,0,0,0,0,0,34,0,0
0,0,18,0,0,0,0,0,0,0,0,0,0,18,0,0
0,0,2,18,34,18,2,31,31,2,18,34,18,2,0,0
0,0,0,0,0,0,32,0,0,32,0,0,0,0,0,0
1,0,0,0,0,0,26,32,32,26,0,0,0,0,0,1
1,1,0,0,0,0,0,0,0,0,0,0,0,0,1,1
endlayer

layer
1,0,0,0,0,0,0,0,0,0,0,0,0,0,0,1
0,0,0,0,0,0,26,0,0,26,0,0,0,0,0,0
0,0,0,0,0,0,0,0,0,0,0,0,0,0,0,0
0,0,2,18,34,18,2,2,2,2,18,34,18,2,0,0
0,0,18,0,0,0,0,0,0,0,0,0,0,18,0,0
0,0,34,29,0,0,0,0,0,0,0,0,0,34,0,0
0,0,18,30,0,0,0,0,0,0,0,0,0,18,0,0
0,0,18,0,0,0,0,0,0,0,0,0,0,18,0,0
0,0,34,0,0,0,0,0,0,0,0,0,0,34,0,0
0,0,18,0,0,0,37,39,38,37,0,0,0,18,0,0
0,0,2,18,34,18,2,39,38,2,18,34,18,2,0,0
0,0,0,0,0,0,32,0,0,32,0,0,0,0,0,0
0,0,0,0,0,0,26,32,32,26,0,0,0,0,0,0
1,0,0,0,0,0,0,0,0,0,0,0,0,0,0,1
endlayer

layer
0,0,0,0,0,0,0,0,0,0,0,0,0,0,0,0
0,0,0,0,0,0,26,0,0,26,0,0,0,0,0,0
0,0,0,0,0,0,0,0,0,0,0,0,0,0,0,0
0,0,2,18,27,18,2,34,34,2,18,27,18,2,0,0
0,0,18,29,0,0,0,0,0,0,0,0,0,18,0,0
0,0,27,30,0,0,0,0,0,0,0,0,0,27,0,0
0,0,18,0,0,0,0,0,0,0,0,0,0,18,0,0
0,0,18,0,0,0,0,0,0,0,0,0,0,18,0,0
0,0,27,0,0,0,0,0,0,0,0,0,0,27,0,0
0,0,18,0,0,0,0,0,0,0,0,0,0,18,0,0
0,0,2,18,27,18,2,18,18,2,18,27,18,2,0,0
0,0,0,0,0,0,32,0,0,32,0,0,0,0,0,0
0,0,0,0,0,0,26,32,32,26,0,0,0,0,0,0
0,0,0,0,0,0,0,0,0,0,0,0,0,0,0,0
endlayer

layer
0,0,0,0,0,43,42,0,0,41,40,0,0,0,0,0
0,0,0,0,0,43,44,0,0,44,40,0,0,0,0,0
0,0,0,0,44,43,44,0,0,44,40,44,0,0,0,0
0,0,2,2,2,2,2,2,2,2,2,2,2,2,0,0
0,0,2,30,2,46,45,46,45,46,45,2,20,2,0,0
0,47,2,0,2,49,48,49,48,49,48,2,20,2,47,0
0,0,2,0,2,46,45,46,45,46,45,2,20,2,0,0
0,0,2,0,2,49,48,49,48,49,48,2,20,2,0,0
0,47,2,20,2,46,45,46,45,46,45,2,20,2,47,0
0,0,2,20,2,49,48,49,48,49,48,2,20,2,0,0
0,0,2,2,2,2,2,2,2,2,2,2,2,2,0,0
0,0,0,0,44,0,2,0,0,2,0,44,0,0,0,0
0,0,0,0,0,0,2,2,2,2,0,0,0,0,0,0
0,0,0,0,0,0,0,0,0,0,0,0,0,0,0,0
endlayer

layer
0,0,0,0,0,0,50,43,40,50,0,0,0,0,0,0
0,0,0,0,0,0,50,43,40,50,0,0,0,0,0,0
0,51,47,47,47,47,47,47,47,47,47,47,47,47,51,0
0,44,0,0,0,0,0,10,10,0,0,0,0,0,44,0
0,44,0,0,0,0,0,0,0,0,0,0,0,0,44,0
0,44,52,0,0,0,0,0,0,0,0,0,0,52,44,0
0,44,53,0,0,0,0,0,0,0,0,0,0,53,44,0
0,44,53,0,0,0,34,54,54,34,0,0,0,53,44,0
0,44,55,0,0,0,0,0,0,0,0,0,0,55,44,0
0,44,0,0,0,0,0,0,0,0,0,0,0,0,44,0
0,44,17,0,0,56,2,31,31,2,56,0,0,17,44,0
0,51,47,47,47,47,32,0,0,32,47,47,47,47,51,0
0,0,0,0,0,0,26,32,32,26,0,0,0,0,0,0
0,0,0,0,0,0,0,0,0,0,0,0,0,0,0,0
endlayer

layer
0,0,0,0,0,0,0,0,0,0,0,0,0,0,0,0
0,0,57,0,57,0,57,0,0,57,0,57,0,57,0,0
0,51,58,34,58,51,58,34,34,58,51,58,34,58,51,0
0,58,0,0,0,0,0,0,0,0,0,0,0,0,58,0
0,58,0,0,0,0,0,0,0,0,0,0,0,0,58,0
60,51,0,0,0,0,0,0,0,0,0,0,0,0,51,59
0,34,61,0,0,0,0,0,0,0,0,0,0,61,34,0
0,34,61,0,0,0,61,0,0,61,0,0,0,61,34,0
60,51,0,0,0,0,0,0,0,0,0,0,0,0,51,59
0,58,0,0,0,0,0,0,0,0,0,0,0,0,58,0
0,58,0,0,0,0,2,31,31,2,0,0,0,0,58,0
0,51,58,34,58,51,32,0,0,32,51,58,34,58,51,0
0,0,62,0,62,0,26,32,32,26,0,62,0,62,0,0
0,0,0,0,0,0,0,0,0,0,0,0,0,0,0,0
endlayer

layer
0,0,0,0,0,0,0,0,0,0,0,0,0,0,0,0
0,0,57,0,57,0,57,0,0,57,0,57,0,57,0,0
0,51,58,34,58,51,58,34,34,58,51,58,34,58,51,0
0,58,0,0,0,0,0,0,0,0,0,0,0,0,58,0
0,58,0,0,0,0,0,0,0,0,0,0,0,0,58,0
60,51,0,0,0,0,0,0,0,0,0,0,0,0,51,59
0,34,0,0,0,0,0,0,0,0,0,0,0,0,34,0
0,34,0,0,0,0,0,0,0,0,0,0,0,0,34,0
60,51,0,0,0,0,0,0,0,0,0,0,0,0,51,59
0,58,0,0,0,0,0,0,0,0,0,0,0,0,58,0
0,58,0,0,0,0,2,2,2,2,0,0,0,0,58,0
0,51,58,34,58,51,32,0,0,32,51,58,34,58,51,0
0,0,62,0,62,0,26,32,32,26,0,62,0,62,0,0
0,0,0,0,0,0,0,0,0,0,0,0,0,0,0,0
endlayer

layer
0,0,0,0,0,0,0,0,0,0,0,0,0,0,0,0
0,0,57,0,57,0,57,0,0,57,0,57,0,57,0,0
0,51,58,34,58,51,58,34,34,58,51,58,34,58,51,0
0,58,0,0,0,0,0,0,0,0,0,0,0,0,58,0
0,58,0,0,0,0,0,0,0,0,0,0,0,0,58,0
60,51,0,0,0,0,0,0,0,0,0,0,0,0,51,59
0,34,0,0,0,0,0,0,0,0,0,0,0,0,34,0
0,34,0,0,0,0,0,0,0,0,0,0,0,0,34,0
60,51,0,0,0,0,0,0,0,0,0,0,0,0,51,59
0,58,0,0,0,0,0,0,0,0,0,0,0,0,58,0
0,58,0,0,0,0,2,27,27,2,0,0,0,0,58,0
0,51,58,34,58,51,32,0,0,32,51,58,34,58,51,0
0,0,62,0,62,0,26,32,32,26,0,62,0,62,0,0
0,0,0,0,0,0,0,0,0,0,0,0,0,0,0,0
endlayer

layer
0,0,0,0,0,0,0,0,0,0,0,0,0,0,0,0
0,0,0,0,0,0,0,0,0,0,0,0,0,0,0,0
0,51,47,47,47,51,47,47,47,47,51,47,47,47,51,0
0,44,0,0,0,44,0,0,0,0,44,0,0,0,44,0
0,44,0,0,0,44,0,0,0,0,44,0,0,0,44,0
0,51,47,47,47,44,0,0,0,0,44,47,47,47,51,0
0,44,0,0,0,44,0,0,0,0,44,0,0,0,44,0
0,44,0,0,0,44,0,0,0,0,44,0,0,0,44,0
0,51,47,47,47,44,0,0,0,0,44,47,47,47,51,0
0,44,0,0,0,44,0,0,0,0,44,0,0,0,44,0
0,44,0,0,0,44,2,2,2,2,44,0,0,0,44,0
0,51,47,47,47,51,2,0,0,2,51,47,47,47,51,0
0,0,0,0,0,0,2,2,2,2,0,0,0,0,0,0
0,0,0,0,0,0,0,0,0,0,0,0,0,0,0,0
endlayer

layer
0,0,0,0,0,0,0,0,0,0,0,0,0,0,0,0
43,42,0,0,0,0,0,0,0,0,0,0,0,0,41,40
43,51,58,58,58,51,58,58,58,58,51,58,58,58,51,40
43,63,0,0,0,0,0,0,0,0,0,0,0,0,63,40
43,63,0,0,0,0,0,0,0,0,0,0,0,0,63,40
43,63,0,0,0,17,0,0,0,0,17,0,0,0,63,40
43,63,0,0,0,0,0,0,0,0,0,0,0,0,63,40
43,63,0,0,0,0,0,0,0,0,0,0,0,0,63,40
43,63,0,0,0,65,0,0,0,0,64,0,0,0,63,40
43,63,0,0,0,0,0,0,0,0,0,0,0,0,63,40
43,63,0,0,0,0,26,32,32,26,0,0,0,0,63,40
43,51,58,58,58,51,32,0,0,32,51,58,58,58,51,40
43,42,0,0,0,0,26,32,32,26,0,0,0,0,41,40
0,0,0,0,0,0,0,0,0,0,0,0,0,0,0,0
endlayer

layer
0,0,0,0,0,0,0,0,0,0,0,0,0,0,0,0
0,63,0,0,0,0,0,0,0,0,0,0,0,0,63,0
0,63,58,58,58,51,58,34,34,58,51,58,58,58,63,0
0,63,0,0,0,0,0,0,0,0,0,0,0,0,63,0
0,63,0,0,0,0,0,0,0,0,0,0,0,0,63,0
0,63,0,0,0,0,0,0,0,0,0,0,0,0,63,0
0,63,0,0,0,0,0,0,0,0,0,0,0,0,63,0
0,63,0,0,0,0,0,0,0,0,0,0,0,0,63,0
0,63,0,0,0,0,0,0,0,0,0,0,0,0,63,0
0,63,0,0,0,0,0,0,0,0,0,0,0,0,63,0
0,63,0,0,0,0,26,32,32,26,0,0,0,0,63,0
0,63,58,58,58,51,32,0,0,32,51,58,58,58,63,0
0,63,0,0,0,0,26,32,32,26,0,0,0,0,63,0
0,0,0,0,0,0,0,0,0,0,0,0,0,0,0,0
endlayer

layer
0,0,0,0,0,0,0,0,0,0,0,0,0,0,0,0
0,43,42,0,0,0,0,0,0,0,0,0,0,41,40,0
0,43,58,58,58,51,58,34,34,58,51,58,58,58,40,0
0,43,42,0,0,0,0,0,0,0,0,0,0,41,40,0
0,43,42,0,0,0,0,0,0,0,0,0,0,41,40,0
0,43,42,0,0,0,0,0,0,0,0,0,0,41,40,0
0,43,42,0,0,0,0,0,0,0,0,0,0,41,40,0
0,43,42,0,0,0,0,0,0,0,0,0,0,41,40,0
0,43,42,0,0,0,0,0,0,0,0,0,0,41,40,0
0,43,42,0,0,0,0,0,0,0,0,0,0,41,40,0
0,43,42,0,0,0,26,32,32,26,0,0,0,41,40,0
0,43,58,58,58,51,32,0,0,32,51,58,58,58,40,0
0,43,42,0,0,0,26,32,32,26,0,0,0,41,40,0
0,0,0,0,0,0,0,0,0,0,0,0,0,0,0,0
endlayer

layer
0,0,0,0,0,0,0,0,0,0,0,0,0,0,0,0
0,0,43,42,0,0,0,0,0,0,0,0,41,40,0,0
0,0,43,58,58,51,58,34,34,58,51,58,58,40,0,0
0,0,43,42,0,0,0,0,0,0,0,0,41,40,0,0
0,0,43,42,0,0,0,0,0,0,0,0,41,40,0,0
0,0,43,42,0,0,0,0,0,0,0,0,41,40,0,0
0,0,43,42,0,0,0,0,0,0,0,0,41,40,0,0
0,0,43,42,0,0,0,0,0,0,0,0,41,40,0,0
0,0,43,42,0,0,0,0,0,0,0,0,41,40,0,0
0,0,43,42,0,0,0,0,0,0,0,0,41,40,0,0
0,0,43,42,0,0,26,32,32,26,0,0,41,40,0,0
0,0,43,58,58,51,32,0,0,32,51,58,58,40,0,0
0,0,43,42,0,0,26,32,32,26,0,0,41,40,0,0
0,0,0,0,0,0,0,0,0,0,0,0,0,0,0,0
endlayer

layer
0,0,0,0,0,0,0,0,0,0,0,0,0,0,0,0
0,0,0,43,42,66,0,0,0,0,66,41,40,0,0,0
0,0,0,43,58,51,58,58,58,58,51,58,40,0,0,0
0,0,0,43,42,66,0,0,0,0,66,41,40,0,0,0
0,0,0,43,42,66,0,0,0,0,66,41,40,0,0,0
0,0,0,43,42,66,0,0,0,0,66,41,40,0,0,0
0,0,0,43,42,66,0,0,0,0,66,41,40,0,0,0
0,0,0,43,42,66,0,0,0,0,66,41,40,0,0,0
0,0,0,43,42,66,0,0,0,0,66,41,40,0,0,0
0,0,0,43,42,66,0,0,0,0,66,41,40,0,0,0
0,0,0,43,42,66,26,32,32,26,66,41,40,0,0,0
0,0,0,43,58,51,32,0,0,32,51,58,40,0,0,0
0,0,0,43,42,66,26,32,32,26,66,41,40,0,0,0
0,0,0,0,0,0,0,0,0,0,0,0,0,0,0,0
endlayer

layer
0,0,0,0,0,0,0,0,0,0,0,0,0,0,0,0
0,0,0,0,50,43,42,66,66,41,40,50,0,0,0,0
0,0,0,0,50,43,58,58,58,58,40,50,0,0,0,0
0,0,0,0,50,43,42,66,66,41,40,50,0,0,0,0
0,0,0,0,50,43,42,66,66,41,40,50,0,0,0,0
0,0,0,0,50,43,42,66,66,41,40,50,0,0,0,0
0,0,0,0,50,43,42,66,66,41,40,50,0,0,0,0
0,0,0,0,50,43,42,66,66,41,40,50,0,0,0,0
0,0,0,0,50,43,42,66,66,41,40,50,0,0,0,0
0,0,0,0,50,43,42,66,66,41,40,50,0,0,0,0
0,0,0,0,50,43,42,66,66,41,40,50,0,0,0,0
0,0,0,0,50,43,32,0,0,32,40,50,0,0,0,0
0,0,0,0,50,43,42,32,32,41,40,50,0,0,0,0
0,0,0,0,0,0,0,0,0,0,0,0,0,0,0,0
endlayer

layer
0,0,0,0,0,0,0,0,0,0,0,0,0,0,0,0
0,0,0,0,0,0,50,63,63,50,0,0,0,0,0,0
0,0,0,0,0,0,50,63,63,50,0,0,0,0,0,0
0,0,0,0,0,0,50,67,67,50,0,0,0,0,0,0
0,0,0,0,0,0,50,68,68,50,0,0,0,0,0,0
0,0,0,0,0,0,50,67,67,50,0,0,0,0,0,0
0,0,0,0,0,0,50,68,68,50,0,0,0,0,0,0
0,0,0,0,0,0,50,67,67,50,0,0,0,0,0,0
0,0,0,0,0,0,50,68,68,50,0,0,0,0,0,0
0,0,0,0,0,0,50,67,67,50,0,0,0,0,0,0
0,0,0,0,0,0,50,68,68,50,0,0,0,0,0,0
0,0,0,0,0,0,50,63,63,50,0,0,0,0,0,0
0,0,0,0,0,0,50,63,63,50,0,0,0,0,0,0
0,0,0,0,0,0,0,0,0,0,0,0,0,0,0,0
endlayer

layer
0,0,0,0,0,0,0,0,0,0,0,0,0,0,0,0
0,0,0,0,0,0,0,63,63,0,0,0,0,0,0,0
0,0,0,0,0,0,0,63,63,0,0,0,0,0,0,0
0,0,0,0,0,0,0,0,0,0,0,0,0,0,0,0
0,0,0,0,0,0,0,0,0,0,0,0,0,0,0,0
0,0,0,0,0,0,0,0,0,0,0,0,0,0,0,0
0,0,0,0,0,0,0,0,0,0,0,0,0,0,0,0
0,0,0,0,0,0,0,0,0,0,0,0,0,0,0,0
0,0,0,0,0,0,0,0,0,0,0,0,0,0,0,0
0,0,0,0,0,0,0,0,0,0,0,0,0,0,0,0
0,0,0,0,0,0,0,0,0,0,0,0,0,0,0,0
0,0,0,0,0,0,0,63,63,0,0,0,0,0,0,0
0,0,0,0,0,0,0,63,63,0,0,0,0,0,0,0
0,0,0,0,0,0,0,0,0,0,0,0,0,0,0,0
endlayer

layer
0,0,0,0,0,0,0,0,0,0,0,0,0,0,0,0
0,0,0,0,0,0,0,63,63,0,0,0,0,0,0,0
0,0,0,0,0,0,0,68,68,0,0,0,0,0,0,0
0,0,0,0,0,0,0,0,0,0,0,0,0,0,0,0
0,0,0,0,0,0,0,0,0,0,0,0,0,0,0,0
0,0,0,0,0,0,0,0,0,0,0,0,0,0,0,0
0,0,0,0,0,0,0,0,0,0,0,0,0,0,0,0
0,0,0,0,0,0,0,0,0,0,0,0,0,0,0,0
0,0,0,0,0,0,0,0,0,0,0,0,0,0,0,0
0,0,0,0,0,0,0,0,0,0,0,0,0,0,0,0
0,0,0,0,0,0,0,0,0,0,0,0,0,0,0,0
0,0,0,0,0,0,0,67,67,0,0,0,0,0,0,0
0,0,0,0,0,0,0,63,63,0,0,0,0,0,0,0
0,0,0,0,0,0,0,0,0,0,0,0,0,0,0,0
endlayer

layer
0,0,0,0,0,0,0,50,50,0,0,0,0,0,0,0
0,0,0,0,0,0,0,63,63,0,0,0,0,0,0,0
0,0,0,0,0,0,0,68,68,0,0,0,0,0,0,0
0,0,0,0,0,0,0,0,0,0,0,0,0,0,0,0
0,0,0,0,0,0,0,0,0,0,0,0,0,0,0,0
0,0,0,0,0,0,0,0,0,0,0,0,0,0,0,0
0,0,0,0,0,0,0,0,0,0,0,0,0,0,0,0
0,0,0,0,0,0,0,0,0,0,0,0,0,0,0,0
0,0,0,0,0,0,0,0,0,0,0,0,0,0,0,0
0,0,0,0,0,0,0,0,0,0,0,0,0,0,0,0
0,0,0,0,0,0,0,0,0,0,0,0,0,0,0,0
0,0,0,0,0,0,0,67,67,0,0,0,0,0,0,0
0,0,0,0,0,0,0,63,63,0,0,0,0,0,0,0
0,0,0,0,0,0,0,50,50,0,0,0,0,0,0,0
endlayer

layer
0,0,0,0,0,0,0,50,50,0,0,0,0,0,0,0
0,0,0,0,0,0,0,67,67,0,0,0,0,0,0,0
0,0,0,0,0,0,0,68,68,0,0,0,0,0,0,0
0,0,0,0,0,0,0,0,0,0,0,0,0,0,0,0
0,0,0,0,0,0,0,0,0,0,0,0,0,0,0,0
0,0,0,0,0,0,0,0,0,0,0,0,0,0,0,0
0,0,0,0,0,0,0,0,0,0,0,0,0,0,0,0
0,0,0,0,0,0,0,0,0,0,0,0,0,0,0,0
0,0,0,0,0,0,0,0,0,0,0,0,0,0,0,0
0,0,0,0,0,0,0,0,0,0,0,0,0,0,0,0
0,0,0,0,0,0,0,0,0,0,0,0,0,0,0,0
0,0,0,0,0,0,0,67,67,0,0,0,0,0,0,0
0,0,0,0,0,0,0,68,68,0,0,0,0,0,0,0
0,0,0,0,0,0,0,50,50,0,0,0,0,0,0,0
endlayer

layer
0,0,0,0,0,0,0,0,0,0,0,0,0,0,0,0
0,0,0,0,0,0,0,0,0,0,0,0,0,0,0,0
0,0,0,0,0,0,0,0,0,0,0,0,0,0,0,0
0,0,0,0,0,0,0,0,0,0,0,0,0,0,0,0
0,0,0,0,0,0,0,0,0,0,0,0,0,0,0,0
0,0,0,0,0,0,0,0,0,0,0,0,0,0,0,0
0,0,0,0,0,0,0,0,0,0,0,0,0,0,0,0
0,0,0,0,0,0,0,0,0,0,0,0,0,0,0,0
0,0,0,0,0,0,0,0,0,0,0,0,0,0,0,0
0,0,0,0,0,0,0,0,0,0,0,0,0,0,0,0
0,0,0,0,0,0,0,0,0,0,0,0,0,0,0,0
0,0,0,0,0,0,0,26,26,0,0,0,0,0,0,0
0,0,0,0,0,0,0,26,26,0,0,0,0,0,0,0
0,0,0,0,0,0,0,0,0,0,0,0,0,0,0,0
endlayer

