# Hunting Lodge (Forest)
# 15 Mar 2014; updated to MC 1.7.10, 11 Oct 2014
# Created by Ruins mod version 13.8 Ingame Parser
# authoring Player: Jordan_Greywolf
# Updated to MC 1.9: 28 Apr 2016
# Last Updated (MC 1.10): 13 Sep 2016
# Updated to MC 1.11: 13 Jan 2017
# Updated to MC 1.12: 23 Jun 2017
# Updated to MC 1.12.1: 10 Sep 2017

biomesToSpawnIn=alps,alps_foothills,alps forest,alpine,apalachia,autumnal_woods,birch forest,birch forest hills,birch forest hills m,birch forest m,birch_forest,birch_forest_hills,boreal forest,boreal_forest,cold taiga,cold taiga hills,cold taiga m,coniferous forest,coniferous_forest,dark forest,dead_forest,deciduous forest,dense forest,enchanted forest,deciduous_forest,extreme hills edge,extreme hills,extreme hills m,extreme hills+,extreme hills+ m,flower forest,frost forest,forest,highlands,highlands center,ice plains,icy hills,magical forest,maple woods,maple_woods,meadow forest,mega spruce taiga,mega taiga,mega taiga hills,mutated_birch_forest,mutated_birch_forest_hills,mutated_forest,mutated_forest_hills,mutated_taiga,oak savanna,oak_savanna,ominous woods,ominous_woods,origin_island,roofed forest,roofed_forest,seasonal forest,seasonal_forest,seasonal forest clearing,seasonal spruce forest,silkglades,snowy forest,snowy_forest,snowy dead forest,snow forest,spruce woods,taiga,taiga_cold,taiga_cold_hills,taiga m,taigahills,taiga_hills,wildwood,wonderous woods,woodland,woodlands,xeric shrubland,xeric_shrubland,rwg_coldforest,rwg_snowforest,rwg_temperateforest,witherlands

uniqueMinDistance=500

weight=1
embed_into_distance=5

preventRotation=1
# Note: Rotation prevented to avoid double-door hinge issue.

acceptable_target_blocks=

unacceptable_target_blocks=flowing_water,water,flowing_lava,lava,cloud,Natura:Cloud,slime_congealed,slime_dirt,slime_grass,command_block,planks,planks2,concrete,cobblestone,stonebrick,brick_block,glass,torch,oak_stairs,stone_stairs,brick_stairs,stone_brick_stairs,nether_brick_stairs,sandstone_stairs,spruce_stairs,birch_stairs,jungle_stairs,quartz_stairs,acacia_stairs,dark_oak_stairs,cobblestone_wall,stone_slab,double_stone_slab,stone_slab2,wooden_slab,double_wooden_slab,nether_brick

dimensions=16,10,19
allowable_overhang=12
max_leveling=5
leveling_buffer=-1
preserve_water=0
preserve_lava=0
preserve_plants=1

rule1=0,100,preserveBlock

rule2=0,100,minecraft:log-1

rule3=0,100,minecraft:cobblestone,minecraft:mossy_cobblestone
rule4=0,100,minecraft:mossy_cobblestone-0

rule5=0,100,minecraft:planks-2
rule6=0,100,minecraft:planks-1
rule7=0,100,minecraft:netherrack-0

rule8=0,100,MobSpawner:Cave_Spider,MobSpawner:Spider

rule9=0,100,minecraft:spruce_stairs-7
rule10=0,100,minecraft:wooden_slab-9
rule11=0,100,minecraft:spruce_stairs-6

rule12=0,100,minecraft:cobblestone_wall-0,minecraft:cobblestone_wall-1

rule13=0,100,minecraft:spruce_stairs-0
rule14=0,100,minecraft:web-0
rule15=0,100,minecraft:fire-15
rule16=0,100,minecraft:iron_bars-0
rule17=0,100,minecraft:carpet-14
rule18=0,100,minecraft:spruce_stairs-2
rule19=0,100,minecraft:spruce_stairs-1
rule20=2,100,minecraft:ladder-4
rule21=0,100,minecraft:stone_stairs-7
rule22=0,100,minecraft:stone_stairs-5
rule23=0,100,minecraft:stone_stairs-4
rule24=0,100,minecraft:stone_stairs-3
rule25=0,100,minecraft:stone_slab-3
rule26=2,100,minecraft:trapdoor-8
rule27=0,100,minecraft:oak_stairs-0
rule28=0,100,minecraft:oak_stairs-2
rule29=0,100,minecraft:bookshelf-0

# Randomized Flower Pot (fern, cactus, sapling)
rule30=0,100,teBlock;minecraft:flower_pot;{Item:"minecraft:tallgrass",x:0,y:0,z:0,Data:2,id:"flower_pot"}-0,teBlock;minecraft:flower_pot;{Item:"minecraft:cactus",x:0,y:0,z:0,Data:0,id:"flower_pot"}-0,teBlock;minecraft:flower_pot;{Item:"minecraft:sapling",x:0,y:0,z:0,Data:1,id:"flower_pot"}-0,teBlock;minecraft:flower_pot;{Item:"minecraft:sapling",x:0,y:0,z:0,Data:1,id:"flower_pot"}-0,teBlock;minecraft:flower_pot;{Item:"minecraft:tallgrass",x:0,y:0,z:0,Data:3,id:"flower_pot"}-0


rule31=0,100,minecraft:oak_stairs-3

rule32=0,100,minecraft:cobblestone_wall,minecraft:cobblestone_wall-1

rule33=0,100,minecraft:fence-0
rule34=1,100,minecraft:wooden_door-3

# Randomized Flower Pot (poppy, dandelion, spruce sapling, oak sapling)
rule35=0,100,teBlock;minecraft:flower_pot;{Item:"minecraft:red_flower",x:0,y:0,z:0,Data:0,id:"flower_pot"}-0,teBlock;minecraft:flower_pot;{Item:"minecraft:yellow_flower",x:0,y:0,z:0,Data:0,id:"flower_pot"}-0,teBlock;minecraft:flower_pot;{Item:"minecraft:sapling",x:0,y:0,z:0,Data:1,id:"flower_pot"}-0,teBlock;minecraft:flower_pot;{Item:"minecraft:sapling",x:0,y:0,z:0,Data:0,id:"flower_pot"}-0,teBlock;minecraft:flower_pot;{Item:"minecraft:tallgrass",x:0,y:0,z:0,Data:2,id:"flower_pot"}-0

rule36=0,100,minecraft:oak_stairs-1
rule37=0,100,minecraft:stone_stairs-0
rule38=1,100,minecraft:redstone_torch-5
rule39=0,100,minecraft:carpet-15

rule40=1,100,minecraft:wooden_door-9
rule41=1,100,minecraft:wooden_door-8

rule42=0,100,minecraft:stone_stairs-1
rule43=0,100,minecraft:log-9
rule44=0,100,minecraft:log-5
rule45=0,100,Skull:0:6-1

rule46=0,100,minecraft:stonebrick-3
rule47=0,100,minecraft:stone_stairs-2

rule48=0,100,ChestGenHook:chests/simple_dungeon:3,ChestGenHook:chests/stronghold_library:3

# ----------------------------------

layer
1,1,1,1,1,1,1,1,1,1,1,1,1,1,1,1,1,1,1
1,1,2,3,3,3,3,3,3,2,3,3,3,3,3,3,2,1,1
1,1,3,2,5,3,5,6,5,3,5,6,5,6,5,2,4,1,1
1,1,4,5,6,3,6,5,6,3,6,5,6,5,6,3,3,3,3
3,3,5,8,5,6,5,6,5,6,5,6,5,6,5,3,3,7,3
3,3,6,8,6,5,6,5,6,5,6,5,6,5,6,3,3,7,3
1,1,4,6,5,3,5,6,5,3,5,6,5,6,5,3,3,3,3
1,1,4,2,6,3,6,5,6,3,6,5,6,5,6,2,4,1,1
1,1,2,3,3,3,3,3,3,2,3,3,3,3,3,4,2,1,1
1,1,1,1,1,1,1,1,1,1,1,1,1,1,1,1,1,1,1
endlayer

layer
1,1,1,1,1,1,1,1,1,1,1,1,1,1,1,1,1,1,1
1,1,2,3,3,3,3,3,3,2,3,3,3,3,3,3,2,1,1
1,1,3,2,0,3,10,10,10,3,48,11,10,9,48,2,3,1,1
1,3,3,14,0,12,0,0,0,12,0,0,13,0,0,12,3,3,3
3,3,18,0,0,0,0,0,0,0,0,0,0,0,17,0,16,15,3
3,3,18,0,0,0,0,0,0,0,0,0,0,0,17,0,16,15,3
1,3,3,14,0,12,0,0,0,12,0,0,19,0,0,12,3,3,3
1,1,3,2,20,3,10,10,10,3,48,11,10,9,48,2,4,1,1
1,1,2,3,3,3,3,3,3,2,3,3,3,3,3,4,2,1,1
1,1,1,1,1,1,1,1,1,1,1,1,1,1,1,1,1,1,1
endlayer

layer
1,1,1,1,1,1,1,1,1,1,1,1,1,1,1,1,1,1,1
1,1,2,3,3,3,3,3,3,2,3,3,3,3,3,3,2,1,1
1,1,3,2,0,3,0,0,0,3,0,0,17,0,0,2,3,1,1
1,3,3,0,0,12,0,0,0,12,0,0,0,0,0,12,3,3,3
3,3,0,0,0,0,0,0,0,0,0,0,0,0,0,0,16,0,3
3,3,0,0,0,0,0,0,0,0,0,0,0,0,0,0,16,0,3
1,3,3,0,0,12,0,0,0,12,0,0,0,0,0,12,3,3,3
1,1,3,2,20,3,0,0,0,3,0,0,17,0,0,2,3,1,1
1,1,2,3,3,3,3,3,3,2,3,3,3,3,3,3,2,1,1
1,1,1,1,1,1,1,1,1,1,1,1,1,1,1,1,1,1,1
endlayer

layer
1,1,1,1,1,1,1,1,1,1,1,1,1,1,1,1,1,1,1
1,1,2,3,3,3,3,3,3,2,3,3,3,3,3,3,2,1,1
1,1,3,2,14,3,14,0,14,3,14,14,0,0,14,2,4,1,1
1,1,3,14,0,22,0,0,0,22,0,0,0,0,0,21,3,3,3
3,3,3,0,0,0,0,0,0,0,0,0,0,0,0,21,3,0,3
3,3,3,0,0,0,0,0,0,0,0,0,0,0,0,21,3,0,3
1,1,3,14,0,23,0,0,0,23,0,0,0,0,0,21,3,3,3
1,1,3,2,20,3,14,0,14,3,14,14,0,0,14,2,4,1,1
1,1,2,3,3,3,3,3,3,2,3,3,3,3,3,3,2,1,1
1,1,1,1,1,1,1,1,1,1,1,1,1,1,1,1,1,1,1
endlayer

layer
1,1,1,1,1,1,1,1,1,1,1,1,1,1,1,1,1,1,1
1,1,2,3,3,3,4,4,4,2,3,3,3,3,3,4,2,1,1
1,1,3,2,5,6,5,6,5,6,5,6,5,6,5,2,4,1,1
1,1,3,5,6,5,6,5,6,5,6,5,6,5,6,4,3,3,3
25,24,3,6,5,6,5,6,5,6,5,6,5,6,5,3,3,7,3
25,24,3,5,6,5,6,5,6,5,6,5,6,5,6,3,4,7,3
1,1,3,6,5,6,5,6,5,6,5,6,5,6,5,4,4,4,3
1,1,3,2,26,5,6,5,6,5,6,5,6,5,6,2,3,1,1
1,1,2,4,4,3,3,3,3,2,3,3,3,3,3,3,2,1,1
1,1,1,1,1,1,1,1,1,1,1,1,1,1,1,1,1,1,1
endlayer

layer
1,1,1,1,1,0,0,0,0,0,0,0,0,0,1,1,1,1,1
1,1,2,27,27,27,27,27,27,2,27,27,27,27,27,27,2,1,1
1,0,31,2,14,14,14,0,0,0,14,0,30,29,29,2,28,0,1
0,0,2,14,0,0,19,0,19,14,19,0,0,0,0,32,3,3,3
0,0,34,0,0,0,33,33,33,33,33,0,0,0,0,8,16,15,3
0,0,34,0,0,0,33,33,33,33,33,0,0,0,0,8,16,15,3
0,0,2,14,0,0,13,0,13,0,13,0,0,0,0,32,3,3,3
1,0,31,2,14,14,14,0,14,0,0,0,35,29,29,2,28,0,1
1,1,2,36,36,36,36,36,36,2,36,36,36,36,36,36,2,1,1
1,1,1,1,1,0,0,0,0,0,0,0,0,0,1,1,1,1,1
endlayer

layer
1,1,1,0,0,0,0,0,0,0,0,0,0,0,0,0,1,1,1
1,0,2,27,27,27,27,27,27,2,27,27,27,27,27,27,2,0,1
0,0,31,2,0,0,0,0,0,0,0,0,0,29,29,2,28,0,0
0,33,2,33,0,0,0,0,0,0,0,0,0,0,0,38,3,3,37
0,0,41,0,0,0,17,39,17,39,17,0,0,0,0,0,16,0,3
0,0,40,0,0,0,17,39,17,39,17,0,0,0,0,0,16,0,3
0,33,2,33,0,0,0,0,0,0,0,0,0,0,0,38,3,3,42
0,0,31,2,14,0,0,0,0,0,0,0,0,29,29,2,28,0,0
1,0,2,36,36,36,36,36,36,2,36,36,36,36,36,36,2,0,1
1,1,1,0,0,0,0,0,0,0,0,0,0,0,0,0,1,1,1
endlayer

layer
1,0,0,0,0,0,0,0,0,0,0,0,0,0,0,0,0,0,1
0,0,2,43,43,43,43,43,43,2,43,43,43,43,43,43,2,0,0
0,0,44,2,0,0,0,0,0,0,0,0,0,0,14,2,44,0,0
0,38,44,38,0,0,0,0,0,0,0,0,0,0,0,0,4,3,23
0,0,44,0,0,0,0,0,0,0,0,0,0,0,0,0,22,0,3
0,0,44,0,0,0,0,0,0,0,0,0,0,0,0,0,23,0,3
0,38,44,38,0,0,0,0,0,0,0,0,0,0,0,0,3,3,22
0,0,44,2,0,0,0,0,0,0,0,0,0,45,14,2,44,0,0
0,0,2,43,43,43,43,43,43,2,43,43,43,43,43,43,2,0,0
1,0,0,0,0,0,0,0,0,0,0,0,0,0,0,0,0,0,1
endlayer

layer
0,0,33,0,0,0,0,0,0,33,0,0,0,0,0,0,33,0,0
0,0,2,27,2,33,33,2,33,2,33,2,33,33,2,27,2,0,0
0,0,31,2,14,0,0,0,0,0,0,0,0,0,14,2,28,0,0
0,0,2,0,0,0,0,0,0,0,0,0,0,0,0,0,46,3,3
0,0,31,0,0,0,0,0,0,0,0,0,0,0,0,0,3,0,3
0,0,31,0,0,0,0,0,0,0,0,0,0,0,0,0,3,0,3
0,0,2,14,0,0,0,0,0,0,0,0,0,0,0,14,46,3,3
0,0,31,2,14,0,0,0,0,0,0,0,0,0,14,2,28,0,0
0,0,2,36,2,33,33,2,33,2,33,2,33,33,2,36,2,0,0
0,0,33,0,0,0,0,0,0,33,0,0,0,0,0,0,33,0,0
endlayer

layer
0,0,13,13,13,13,13,13,13,13,13,13,13,13,13,13,13,0,0
0,33,43,43,43,43,43,43,43,43,43,43,43,43,43,43,43,33,0
0,0,44,2,14,0,0,0,14,14,0,0,14,14,14,2,44,0,0
0,0,2,14,0,0,0,0,0,33,0,0,0,0,0,14,2,3,47
0,0,31,0,0,0,0,0,33,33,33,0,0,0,0,0,3,0,47
0,0,31,0,0,0,0,0,33,33,33,0,0,0,0,0,3,0,47
0,0,2,0,0,0,0,0,0,33,0,0,0,0,0,14,2,3,47
0,0,44,2,14,14,14,14,0,14,14,0,0,0,14,2,44,0,0
0,33,43,43,43,43,43,43,43,43,43,43,43,43,43,43,43,33,0
0,0,19,19,19,19,19,19,19,19,19,19,19,19,19,19,19,0,0
endlayer

layer
0,0,0,0,0,0,0,0,0,0,0,0,0,0,0,0,0,0,0
0,13,13,13,13,13,13,13,13,13,13,13,13,13,13,13,13,13,0
33,43,43,43,43,43,43,43,43,43,43,43,43,43,43,43,43,43,33
0,0,44,14,0,0,14,14,0,38,0,14,14,14,14,14,44,37,0
0,0,31,0,0,0,0,0,38,33,38,0,0,0,0,14,3,3,0
0,0,31,14,0,0,0,0,38,33,38,0,0,0,0,14,3,3,0
0,0,44,14,14,0,14,0,0,38,0,0,0,14,0,14,44,42,0
33,43,43,43,43,43,43,43,43,43,43,43,43,43,43,43,43,43,33
0,19,19,19,19,19,19,19,19,19,19,19,19,19,19,19,19,19,0
0,0,0,0,0,0,0,0,0,0,0,0,0,0,0,0,0,0,0
endlayer

layer
0,0,0,0,0,0,0,0,0,0,0,0,0,0,0,0,0,0,0
0,0,0,0,0,0,0,0,0,0,0,0,0,0,0,0,0,0,0
13,13,13,13,13,13,13,13,13,13,13,13,13,13,13,13,13,13,13
43,43,43,43,43,43,43,43,43,43,43,43,43,43,43,43,43,43,43
0,0,44,14,14,0,0,14,14,33,14,14,0,14,14,14,44,3,0
0,0,44,0,0,0,0,14,0,33,0,0,14,14,14,14,44,3,0
43,43,43,43,43,43,43,43,43,43,43,43,43,43,43,43,43,43,43
19,19,19,19,19,19,19,19,19,19,19,19,19,19,19,19,19,19,19
0,0,0,0,0,0,0,0,0,0,0,0,0,0,0,0,0,0,0
0,0,0,0,0,0,0,0,0,0,0,0,0,0,0,0,0,0,0
endlayer

layer
0,0,0,0,0,0,0,0,0,0,0,0,0,0,0,0,0,0,0
0,0,0,0,0,0,0,0,0,0,0,0,0,0,0,0,0,0,0
0,0,0,0,0,0,0,0,0,0,0,0,0,0,0,0,0,0,0
13,13,13,13,13,13,13,13,13,13,13,13,13,13,13,13,13,13,13
43,43,43,43,43,43,43,43,43,43,43,43,43,43,43,43,43,3,43
43,43,43,43,43,43,43,43,43,43,43,43,43,43,43,43,43,3,43
19,19,19,19,19,19,19,19,19,19,19,19,19,19,19,19,19,19,19
0,0,0,0,0,0,0,0,0,0,0,0,0,0,0,0,0,0,0
0,0,0,0,0,0,0,0,0,0,0,0,0,0,0,0,0,0,0
0,0,0,0,0,0,0,0,0,0,0,0,0,0,0,0,0,0,0
endlayer

layer
0,0,0,0,0,0,0,0,0,0,0,0,0,0,0,0,0,0,0
0,0,0,0,0,0,0,0,0,0,0,0,0,0,0,0,0,0,0
0,0,0,0,0,0,0,0,0,0,0,0,0,0,0,0,0,0,0
0,0,0,0,0,0,0,0,0,0,0,0,0,0,0,0,0,0,0
13,13,13,13,13,13,13,13,13,13,13,13,13,13,13,13,13,4,13
19,19,19,19,19,19,19,19,19,19,19,19,19,19,19,19,19,3,19
0,0,0,0,0,0,0,0,0,0,0,0,0,0,0,0,0,0,0
0,0,0,0,0,0,0,0,0,0,0,0,0,0,0,0,0,0,0
0,0,0,0,0,0,0,0,0,0,0,0,0,0,0,0,0,0,0
0,0,0,0,0,0,0,0,0,0,0,0,0,0,0,0,0,0,0
endlayer

layer
0,0,0,0,0,0,0,0,0,0,0,0,0,0,0,0,0,0,0
0,0,0,0,0,0,0,0,0,0,0,0,0,0,0,0,0,0,0
0,0,0,0,0,0,0,0,0,0,0,0,0,0,0,0,0,0,0
0,0,0,0,0,0,0,0,0,0,0,0,0,0,0,0,0,0,0
0,0,0,0,0,0,0,0,0,0,0,0,0,0,0,0,0,4,0
0,0,0,0,0,0,0,0,0,0,0,0,0,0,0,0,0,4,0
0,0,0,0,0,0,0,0,0,0,0,0,0,0,0,0,0,0,0
0,0,0,0,0,0,0,0,0,0,0,0,0,0,0,0,0,0,0
0,0,0,0,0,0,0,0,0,0,0,0,0,0,0,0,0,0,0
0,0,0,0,0,0,0,0,0,0,0,0,0,0,0,0,0,0,0
endlayer

layer
0,0,0,0,0,0,0,0,0,0,0,0,0,0,0,0,0,0,0
0,0,0,0,0,0,0,0,0,0,0,0,0,0,0,0,0,0,0
0,0,0,0,0,0,0,0,0,0,0,0,0,0,0,0,0,0,0
0,0,0,0,0,0,0,0,0,0,0,0,0,0,0,0,0,0,0
0,0,0,0,0,0,0,0,0,0,0,0,0,0,0,0,0,32,0
0,0,0,0,0,0,0,0,0,0,0,0,0,0,0,0,0,32,0
0,0,0,0,0,0,0,0,0,0,0,0,0,0,0,0,0,0,0
0,0,0,0,0,0,0,0,0,0,0,0,0,0,0,0,0,0,0
0,0,0,0,0,0,0,0,0,0,0,0,0,0,0,0,0,0,0
0,0,0,0,0,0,0,0,0,0,0,0,0,0,0,0,0,0,0
endlayer

