# Ruined Hall
# Created by Ruins mod version 16.4 Ingame Parser
# authoring Player: Jordan_Greywolf
# Created for MC 1.11: 16 Apr 2017
# Updated to MC 1.12: 23 Jun 2017
# Updated to MC 1.12.1: 10 Sep 2017

biomesToSpawnIn=alps_foothills,birch forest,birch_forest,birch forest hills,birch_forest_hills,birch forest hills m,birch forest m,boreal forest,boreal_forest,brushland,chaparral,cold taiga,cold taiga hills,cold taiga m,coniferous forest,coniferous_forest,dead forest,dead_forest,extreme hills edge,forest,foresthills,forest_hills,grassland,grove,heathland,highland,ice mountains,land_of_lakes,maple woods,maple_woods,mega taiga,mega taiga hills,mountain,mountain foothills,mutated_birch_forest,mutated_birch_forest_hills,mutated_forest,mutated_taiga,ominous woods,ominous_woods,origin_island,redwood taiga hills m,smaller_extreme_hills,steppe,taiga,taiga m,taigahills,taiga_hills,xeric shrubland,xeric_shrubland

weight=1
embed_into_distance=13
acceptable_target_blocks=

unacceptable_target_blocks=flowing_water,water,flowing_lava,lava,cloud,slime_congealed,slime_dirt,slime_grass,command_block,planks,planks2,concrete,cobblestone,stonebrick,brick_block,glass,torch,oak_stairs,stone_stairs,brick_stairs,stone_brick_stairs,nether_brick_stairs,sandstone_stairs,spruce_stairs,birch_stairs,jungle_stairs,quartz_stairs,acacia_stairs,dark_oak_stairs,cobblestone_wall,stone_slab,double_stone_slab,stone_slab2,wooden_slab,double_wooden_slab,nether_brick

dimensions=21,5,13
allowable_overhang=0
max_leveling=13
leveling_buffer=-1
preserve_water=0
preserve_lava=0
preserve_plants=1

rule1=0,100,minecraft:double_stone_slab-0
rule2=0,100,minecraft:mossy_cobblestone-0

# Floor (mossy stone brick, etc.)
rule3=0,100,minecraft:stonebrick-1,minecraft:stonebrick-1,minecraft:stonebrick-0

# Chiseled Stone
rule4=0,100,minecraft:stonebrick-3

# Stone Brick Walls
rule5=0,100,minecraft:stonebrick-0,minecraft:stonebrick-0,minecraft:stonebrick-0,minecraft:stonebrick-1,minecraft:stonebrick-2

rule6=0,100,minecraft:cobblestone_wall-0
rule7=0,100,minecraft:web-0
rule8=0,100,minecraft:stone_brick_stairs-3
rule9=0,100,minecraft:stone_brick_stairs-2
rule10=0,100,minecraft:stone-2
rule11=0,100,minecraft:stone-6
rule12=0,100,minecraft:stone_brick_stairs-0
rule13=0,100,minecraft:stone_brick_stairs-5
rule14=0,100,minecraft:stone_brick_stairs-4
rule15=0,100,minecraft:stone_brick_stairs-1
rule16=0,100,minecraft:stone_slab-13
rule17=0,100,minecraft:stone_slab-5

rule18=0,100,preserveBlock

layer
1,2,2,2,1,2,2,2,1,2,2,2,1
2,3,3,3,2,3,3,3,2,3,3,3,2
2,3,4,3,2,3,4,3,2,3,4,3,2
2,3,3,3,2,3,3,3,2,3,3,3,2
1,2,2,2,1,2,2,2,1,2,2,2,1
endlayer

layer
1,5,0,5,1,5,6,5,1,5,0,5,1
5,0,0,0,0,8,7,0,0,0,0,0,5
0,0,0,0,0,0,0,0,0,0,0,0,0
5,0,0,0,0,0,7,9,0,0,0,0,5
1,5,0,5,1,5,6,5,1,5,0,5,1
endlayer

layer
6,5,0,5,1,5,6,5,1,5,0,5,6
5,0,0,0,0,0,8,0,0,0,0,0,5
0,0,0,0,0,0,0,0,0,0,0,0,0
5,0,0,0,0,0,9,0,0,0,0,0,5
6,5,0,5,1,5,6,5,1,5,0,5,6
endlayer

layer
4,5,4,5,4,5,4,5,4,5,4,5,4
5,7,0,0,0,0,0,8,0,0,0,7,5
4,0,0,0,0,0,0,0,0,0,0,0,4
5,7,0,0,0,9,0,0,0,0,0,7,5
4,5,4,5,4,5,4,5,4,5,4,5,4
endlayer

layer
1,1,1,1,1,1,1,1,1,1,1,1,1
1,10,11,10,11,0,0,0,8,10,11,10,1
1,11,10,11,10,11,10,11,10,11,10,11,1
1,10,11,10,9,0,0,0,11,10,11,10,1
1,1,1,1,1,1,1,1,1,1,1,1,1
endlayer

layer
1,5,0,5,1,5,6,5,1,5,0,5,1
5,0,0,0,0,8,7,0,0,0,0,0,5
0,0,0,0,0,0,0,0,0,0,0,0,0
5,0,0,0,0,0,7,9,0,0,0,0,5
1,5,0,5,1,5,6,5,1,5,0,5,1
endlayer

layer
6,5,0,5,1,5,6,5,1,5,0,5,6
5,0,0,0,0,0,8,0,0,0,0,0,5
0,0,0,0,0,0,0,0,0,0,0,0,0
5,0,0,0,0,0,9,0,0,0,0,0,5
6,5,0,5,1,5,6,5,1,5,0,5,6
endlayer

layer
4,5,4,5,4,5,4,5,4,5,4,5,4
5,7,0,0,0,0,0,8,0,0,0,7,5
4,0,0,0,0,0,0,0,0,0,0,0,4
5,7,0,0,0,9,0,0,0,0,0,7,5
4,5,4,5,4,5,4,5,4,5,4,5,4
endlayer

layer
1,1,1,1,1,1,1,1,1,1,1,1,1
1,10,11,10,11,0,0,0,8,10,11,10,1
1,11,10,11,10,11,10,11,10,11,10,11,1
1,10,11,10,9,0,0,0,11,10,11,10,1
1,1,1,1,1,1,1,1,1,1,1,1,1
endlayer


layer
1,5,0,5,1,5,6,5,1,5,0,5,1
5,0,0,0,0,8,7,0,0,0,0,0,5
0,0,0,0,0,0,0,0,0,0,0,0,0
5,0,0,0,0,0,7,9,0,0,0,0,5
1,5,0,5,1,5,6,5,1,5,0,5,1
endlayer

layer
6,5,0,5,1,5,6,5,1,5,0,5,6
5,0,0,0,0,0,8,0,0,0,0,0,5
0,0,0,0,0,0,0,0,0,0,0,0,0
5,0,0,0,0,0,9,0,0,0,0,0,5
6,5,0,5,1,5,6,5,1,5,0,5,6
endlayer

layer
4,5,4,5,4,5,4,5,4,5,4,5,4
5,7,0,0,0,0,0,8,0,0,0,7,5
4,0,0,0,0,0,0,0,0,0,0,0,4
5,7,0,0,0,9,0,0,0,0,0,7,5
4,5,4,5,4,5,4,5,4,5,4,5,4
endlayer

layer
1,1,1,1,1,1,1,1,1,1,1,1,1
1,10,11,10,11,0,0,0,8,10,11,10,1
1,11,10,11,10,11,10,11,10,11,10,11,1
1,10,11,10,9,0,0,0,11,10,11,10,1
1,1,1,1,1,1,1,1,1,1,1,1,1
endlayer

layer
4,18,18,0,4,18,18,18,4,0,18,18,4
18,18,0,0,0,0,18,0,0,0,0,18,18
18,0,0,0,0,0,0,0,0,0,0,0,18
18,18,0,0,0,0,18,0,0,0,0,18,18
4,18,18,0,4,18,18,18,4,0,18,18,4
endlayer

layer
6,18,0,0,6,0,18,0,6,0,0,18,6
18,0,0,0,0,0,0,0,0,0,0,0,18
0,0,0,0,0,0,0,0,0,0,0,0,0
18,0,0,0,0,0,0,0,0,0,0,0,18
6,18,0,0,6,0,18,0,6,0,0,18,6
endlayer

layer
6,0,0,0,6,0,0,0,6,0,0,0,6
0,0,0,0,0,0,0,0,0,0,0,0,0
0,0,0,0,0,0,0,0,0,0,0,0,0
0,0,0,0,0,0,0,0,0,0,0,0,0
6,0,0,0,6,0,0,0,6,0,0,0,6
endlayer

layer
6,0,0,0,6,0,0,0,6,0,0,0,6
0,0,0,0,0,0,0,0,0,0,0,0,0
0,0,0,0,0,0,0,0,0,0,0,0,0
0,0,0,0,0,0,0,0,0,0,0,0,0
6,0,0,0,6,0,0,0,6,0,0,0,6
endlayer

layer
4,0,0,0,4,0,0,0,4,0,0,0,4
0,0,0,0,0,0,0,0,0,0,0,0,0
0,0,0,0,0,0,0,0,0,0,0,0,0
0,0,0,0,0,0,0,0,0,0,0,0,0
4,0,0,0,4,0,0,0,4,0,0,0,4
endlayer

layer
12,0,0,0,12,0,0,0,12,0,0,0,12
13,0,0,0,13,0,0,0,13,0,0,0,13
0,0,0,0,0,0,0,0,0,0,0,0,0
14,0,0,0,14,0,0,0,14,0,0,0,14
15,0,0,0,15,0,0,0,15,0,0,0,15
endlayer

layer
0,0,0,0,0,0,0,0,0,0,0,0,0
12,0,0,0,12,0,0,0,12,0,0,0,12
16,0,0,0,16,0,0,0,16,0,0,0,16
15,0,0,0,15,0,0,0,15,0,0,0,15
0,0,0,0,0,0,0,0,0,0,0,0,0
endlayer

layer
0,0,0,0,0,0,0,0,0,0,0,0,0
0,0,0,0,0,0,0,0,0,0,0,0,0
17,0,0,0,17,0,0,0,17,0,0,0,17
0,0,0,0,0,0,0,0,0,0,0,0,0
0,0,0,0,0,0,0,0,0,0,0,0,0
endlayer

