# SmallQuartzShrine
# 24 Apr 2014; updated to MC 1.7.10, 13 Oct 2014
# Updated to MC 1.8: 22 Jul 2015
# Created by Ruins mod version 12.3 Ingame Parser
# authoring Player: Jordan_Greywolf
# (hacked from "SkyQuartzShrine" top layers)
# Updated to MC 1.11: 13 Jan 2017
# Updated to MC 1.12: 23 Jun 2017
# Updated to MC 1.12.1: 10 Sep 2017

biomesToSpawnIn=birch forest,birch_forest,birch_forest_hills,boreal_forest,coniferous_forest,dead_forest,forest,foresthills,forest_hills,flower forest,mutated_forest,mutated_plains,mutated_roofed_forest,roofed forest,roofed_forest,sunflower plains,mystic grove,mystical_grove,magical forest,lavender fields,lavender_fields,origin_island,origin valley,grove,orchard,rwg_plains,xeric shrubland,xeric_shrubland,mining biome,mining_biome

uniqueMinDistance=2000
spawnMinDistance=1000

weight=1
embed_into_distance=0

unacceptable_target_blocks=lava,flowing_lava,cloud,Natura:Cloud,red_mushroom_block,brown_mushroom_block,slime_congealed,slime_dirt,slime_grass,command_block,planks,planks2,concrete,cobblestone,stonebrick,brick_block,glass,torch,oak_stairs,stone_stairs,brick_stairs,stone_brick_stairs,nether_brick_stairs,sandstone_stairs,spruce_stairs,birch_stairs,jungle_stairs,quartz_stairs,acacia_stairs,dark_oak_stairs,cobblestone_wall,stone_slab,double_stone_slab,stone_slab2,wooden_slab,double_wooden_slab,nether_brick

dimensions=12,11,11
allowable_overhang=0
max_cut_in=0
cut_in_buffer=0
max_leveling=6
leveling_buffer=-1
preserve_water=0
preserve_lava=0
preserve_plants=1

rule1=0,100,minecraft:glowstone-0
rule2=0,0,minecraft:water-7
rule3=0,0,minecraft:water-6
rule4=0,0,minecraft:water-5
rule5=0,0,minecraft:water-9
rule6=0,100,minecraft:water-1
rule7=0,100,minecraft:water-2
rule8=0,0,minecraft:water-3
rule9=0,0,minecraft:water-4
rule10=0,100,minecraft:quartz_block-2
rule11=0,100,minecraft:stone-0
rule12=0,100,minecraft:quartz_block-1
rule13=0,100,minecraft:dirt-0
rule14=0,100,minecraft:water-0
rule15=0,100,minecraft:grass-0
rule16=0,100,minecraft:tallgrass-2,minecraft:tallgrass-1,minecraft:red_flower,minecraft:yellow_flower,minecraft:red_flower-1,minecraft:red_flower-2,minecraft:red_flower-3,minecraft:red_flower-4
rule17=0,100,minecraft:water-11
rule18=0,100,minecraft:quartz_block-0
rule19=0,100,minecraft:water-10
rule20=0,100,minecraft:stone_slab-7
rule21=0,100,preserveBlock

rule22=0,100,minecraft:flowing_water
rule23=0,100,preserveBlock

layer
23,23,23,23,15,15,15,23,23,23,23
2,23,23,15,11,11,11,15,23,23,23
3,23,15,11,11,11,11,11,15,23,23
4,15,11,11,11,11,11,11,11,15,23
15,11,11,13,11,11,11,11,11,11,15
15,11,11,11,11,1,14,19,11,11,15
15,11,11,11,11,11,11,11,11,11,15
5,15,11,11,11,11,11,11,11,15,23
8,23,15,11,11,11,11,11,15,23,23
9,23,23,15,11,11,11,15,23,23,23
23,23,23,23,15,15,15,23,23,23,23
endlayer

layer
23,23,23,23,16,16,16,23,23,23,23
23,23,23,16,20,20,20,16,23,23,23
23,23,16,20,18,18,18,20,16,23,23
23,16,20,18,18,18,18,18,20,16,23
16,20,18,18,15,14,15,18,18,20,16
16,20,18,18,14,14,6,7,18,20,16
16,20,18,18,15,14,15,18,18,20,16
23,16,20,18,18,18,18,18,20,16,23
23,23,16,20,18,18,18,20,16,23,23
23,23,23,16,20,20,20,16,23,23,23
23,23,23,23,16,16,16,23,23,23,23
endlayer


layer
0,0,0,0,0,0,0,0,0,0,0
0,0,0,0,0,0,0,0,0,0,0
0,0,0,0,10,0,10,0,0,0,0
0,0,0,0,0,0,0,0,0,0,0
0,0,10,0,16,0,16,0,10,0,0
0,0,0,0,0,0,0,0,0,0,0
0,0,10,0,16,0,16,0,10,0,0
0,0,0,0,0,0,0,0,0,0,0
0,0,0,0,10,0,10,0,0,0,0
0,0,0,0,0,0,0,0,0,0,0
0,0,0,0,0,0,0,0,0,0,0
endlayer

layer
0,0,0,0,0,0,0,0,0,0,0
0,0,0,0,0,0,0,0,0,0,0
0,0,0,0,10,0,10,0,0,0,0
0,0,0,0,0,0,0,0,0,0,0
0,0,10,0,0,0,0,0,10,0,0
0,0,0,0,0,0,0,0,0,0,0
0,0,10,0,0,0,0,0,10,0,0
0,0,0,0,0,0,0,0,0,0,0
0,0,0,0,10,0,10,0,0,0,0
0,0,0,0,0,0,0,0,0,0,0
0,0,0,0,0,0,0,0,0,0,0
endlayer

layer
0,0,0,0,0,0,0,0,0,0,0
0,0,0,0,0,0,0,0,0,0,0
0,0,0,0,10,0,10,0,0,0,0
0,0,0,0,0,0,0,0,0,0,0
0,0,10,0,0,0,0,0,10,0,0
0,0,0,0,0,0,0,0,0,0,0
0,0,10,0,0,0,0,0,10,0,0
0,0,0,0,0,0,0,0,0,0,0
0,0,0,0,10,0,10,0,0,0,0
0,0,0,0,0,0,0,0,0,0,0
0,0,0,0,0,0,0,0,0,0,0
endlayer

layer
0,0,0,0,0,0,0,0,0,0,0
0,0,0,0,0,0,0,0,0,0,0
0,0,0,0,10,0,10,0,0,0,0
0,0,0,0,0,0,0,0,0,0,0
0,0,10,0,0,0,0,0,10,0,0
0,0,0,0,0,0,0,0,0,0,0
0,0,10,0,0,0,0,0,10,0,0
0,0,0,0,0,0,0,0,0,0,0
0,0,0,0,10,0,10,0,0,0,0
0,0,0,0,0,0,0,0,0,0,0
0,0,0,0,0,0,0,0,0,0,0
endlayer

layer
0,0,0,0,0,0,0,0,0,0,0
0,0,0,0,0,0,0,0,0,0,0
0,0,0,0,12,0,12,0,0,0,0
0,0,0,0,0,0,0,0,0,0,0
0,0,12,0,0,0,0,0,12,0,0
0,0,0,0,0,0,0,0,0,0,0
0,0,12,0,0,0,0,0,12,0,0
0,0,0,0,0,0,0,0,0,0,0
0,0,0,0,12,0,12,0,0,0,0
0,0,0,0,0,0,0,0,0,0,0
0,0,0,0,0,0,0,0,0,0,0
endlayer

layer
0,0,0,0,0,0,0,0,0,0,0
0,0,0,0,18,18,18,0,0,0,0
0,0,0,18,18,18,18,18,0,0,0
0,0,18,18,18,18,18,18,18,0,0
0,18,18,18,0,0,0,18,18,18,0
0,18,18,18,0,0,0,18,18,18,0
0,18,18,18,0,0,0,18,18,18,0
0,0,18,18,18,18,18,18,18,0,0
0,0,0,18,18,18,18,18,0,0,0
0,0,0,0,18,18,18,0,0,0,0
0,0,0,0,0,0,0,0,0,0,0
endlayer

layer
0,0,0,0,0,0,0,0,0,0,0
0,0,0,0,20,20,20,0,0,0,0
0,0,0,20,18,18,18,20,0,0,0
0,0,20,18,0,0,0,18,20,0,0
0,20,18,0,0,0,0,0,18,20,0
0,20,18,0,0,0,0,0,18,20,0
0,20,18,0,0,0,0,0,18,20,0
0,0,20,18,0,0,0,18,20,0,0
0,0,0,20,18,18,18,20,0,0,0
0,0,0,0,20,20,20,0,0,0,0
0,0,0,0,0,0,0,0,0,0,0
endlayer

layer
0,0,0,0,0,0,0,0,0,0,0
0,0,0,0,0,0,0,0,0,0,0
0,0,0,0,20,18,20,0,0,0,0
0,0,0,18,18,18,18,18,0,0,0
0,0,20,18,0,0,0,18,20,0,0
0,0,18,18,0,0,0,18,18,0,0
0,0,20,18,0,0,0,18,20,0,0
0,0,0,18,18,18,18,18,0,0,0
0,0,0,0,20,18,20,0,0,0,0
0,0,0,0,0,0,0,0,0,0,0
0,0,0,0,0,0,0,0,0,0,0
endlayer

layer
0,0,0,0,0,0,0,0,0,0,0
0,0,0,0,0,0,0,0,0,0,0
0,0,0,0,0,0,0,0,0,0,0
0,0,0,20,18,18,18,20,0,0,0
0,0,0,18,18,18,18,18,0,0,0
0,0,0,18,18,1,18,18,0,0,0
0,0,0,18,18,18,18,18,0,0,0
0,0,0,20,18,18,18,20,0,0,0
0,0,0,0,0,0,0,0,0,0,0
0,0,0,0,0,0,0,0,0,0,0
0,0,0,0,0,0,0,0,0,0,0
endlayer

layer
0,0,0,0,0,0,0,0,0,0,0
0,0,0,0,0,0,0,0,0,0,0
0,0,0,0,0,0,0,0,0,0,0
0,0,0,0,0,20,0,0,0,0,0
0,0,0,0,20,18,20,0,0,0,0
0,0,0,20,18,18,18,20,0,0,0
0,0,0,0,20,18,20,0,0,0,0
0,0,0,0,0,20,0,0,0,0,0
0,0,0,0,0,0,0,0,0,0,0
0,0,0,0,0,0,0,0,0,0,0
0,0,0,0,0,0,0,0,0,0,0
endlayer

