# Tower_Obsidian (test structure - 28 Apr 2014)
# Created by Ruins mod version 12.3 Ingame Parser
# authoring Player: Jordan_Greywolf
# Converted to 1.5.2 - 2 Apr 2014
# Originally created for use with Hexxit ModPack

# Updated to MC 1.12: 8 Apr 2018

biomesToSpawnIn=badlands,cold_desert,dead_forest,deadlands,desert,deserthills,extreme hills,extreme hills edge,fire swamp,fire_swamp,hell,mystic_grove,oak_savanna,ominous woods,ominous_woods,origin_island,outback,sacred_springs,savanna,shield,twilight clearing,twilight_clearing,wasteland

weight=1
embed_into_distance=4

unacceptable_target_blocks=flowing_water,water,flowing_lava,lava,cloud,Natura:Cloud,slime_congealed,slime_dirt,slime_grass,command_block,planks,planks2,concrete,cobblestone,stonebrick,brick_block,glass,torch,oak_stairs,stone_stairs,brick_stairs,stone_brick_stairs,nether_brick_stairs,sandstone_stairs,spruce_stairs,birch_stairs,jungle_stairs,quartz_stairs,acacia_stairs,dark_oak_stairs,cobblestone_wall,stone_slab,double_stone_slab,stone_slab2,wooden_slab,double_wooden_slab,nether_brick

uniqueMinDistance=2000
spawnMinDistance=1000

dimensions=45,12,12
allowable_overhang=0
max_cut_in=0
cut_in_buffer=0
max_leveling=18
leveling_buffer=-1
preserve_water=0
preserve_lava=0
preserve_plants=1

# Preserve Terrain
rule1=0,100,preserveBlock

# Obsidian Outer Walls
rule2=0,100,minecraft:obsidian

# Harmful Ground
rule3=0,95,minecraft:magma

# Obsidian Block
rule4=0,100,minecraft:obsidian

# Pressure Plate
rule5=0,100,minecraft:stone_pressure_plate

# Trap
rule6=0,100,CommandBlock:/effect @p[r=5] 9 10:@,CommandBlock:/effect @p[r=5] 15 10:@,CommandBlock:/effect @p[r=5] 17 10:@,CommandBlock:/effect @p[r=5] 18 10:@

# Decorative Block
rule7=0,100,minecraft:quartz_block-2

# Lava
rule8=0,100,minecraft:lava

# Clear Glass
rule9=0,100,minecraft:stained_glass-15

# Red Glass
rule10=0,100,minecraft:stained_glass-14

# Basalt Brick
rule11=0,100,minecraft:brick_block

# Basalt Brick Slab
rule12=0,100,minecraft:stone_slab-4

# Soul Sand
rule13=0,95,minecraft:soul_sand

# Randomized Floor Tiles
rule14=0,100,minecraft:stonebrick,minecraft:stonebrick-1,minecraft:stonebrick-2,minecraft:gravel,minecraft:sand

# Obsidian
rule15=0,100,minecraft:obsidian

# Red Rock
rule16=0,100,minecraft:red_sandstone-2

# Zombie
rule17=0,100,MobSpawner:Zombie

# Skeleton
rule18=0,100,MobSpawner:Skeleton

# Silverfish
rule19=0,100,MobSpawner:Silverfish

# Blaze
rule20=0,100,MobSpawner:Blaze

# Loot!
rule21=0,100,ChestGenHook:chests/simple_dungeon:3

# Obsidian
rule22=0,100,minecraft:obsidian

# Bookshelf
rule23=0,100,minecraft:bookshelf

# Furnaces
rule24=0,100,minecraft:lit_furnace-0,minecraft:lit_furnace-1,minecraft:lit_furnace-2,minecraft:lit_furnace-3

# TNT
rule25=0,100,minecraft:tnt

# -------------

# Lava Pit (-4)
layer
1,1,1,1,2,2,2,2,1,1,1,1
1,1,2,2,8,8,8,8,2,2,1,1
1,2,8,8,8,8,8,8,8,8,2,1
1,2,8,8,8,8,8,8,8,8,2,1
2,8,8,8,8,8,8,8,8,8,8,2
2,8,8,8,8,8,8,8,8,8,8,2
2,8,8,8,8,8,8,8,8,8,8,2
2,8,8,8,8,8,8,8,8,8,8,2
1,2,8,8,8,8,8,8,8,8,2,1
1,2,8,8,8,8,8,8,8,8,2,1
1,1,2,2,8,8,8,8,2,2,1,1
1,1,1,1,2,2,2,2,1,1,1,1
endlayer

# Lava Pit (-3)
layer
1,1,1,1,2,2,2,2,1,1,1,1
1,1,2,2,8,8,8,8,2,2,1,1
1,2,8,8,8,8,8,8,8,8,2,1
1,2,8,8,8,8,8,8,8,8,2,1
2,8,8,8,8,8,8,8,8,8,8,2
2,8,8,8,8,8,8,8,8,8,8,2
2,8,8,8,8,8,8,8,8,8,8,2
2,8,8,8,8,8,8,8,8,8,8,2
1,2,8,8,8,8,8,8,8,8,2,1
1,2,8,8,8,8,8,8,8,8,2,1
1,1,2,2,8,8,8,8,2,2,1,1
1,1,1,1,2,2,2,2,1,1,1,1
endlayer

# Lava Pit (-2)
layer
1,1,1,1,2,2,2,2,1,1,1,1
1,1,2,2,8,8,8,8,2,2,1,1
1,2,8,8,8,8,8,8,8,8,2,1
1,2,8,8,8,8,8,8,8,8,2,1
2,8,8,8,8,8,8,8,8,8,8,2
2,8,8,8,8,8,8,8,8,8,8,2
2,8,8,8,8,8,8,8,8,8,8,2
2,8,8,8,8,8,8,8,8,8,8,2
1,2,8,8,8,8,8,8,8,8,2,1
1,2,8,8,8,8,8,8,8,8,2,1
1,1,2,2,8,8,8,8,2,2,1,1
1,1,1,1,2,2,2,2,1,1,1,1
endlayer

# Base Floor (-1)
layer
01,01,01,01,02,22,22,02,01,01,01,01
01,01,02,02,09,10,09,10,02,02,01,01
01,02,10,09,10,09,10,09,10,09,02,01
01,02,09,10,09,10,09,10,09,10,02,01
02,09,10,09,10,09,10,09,10,09,10,02
22,10,09,10,09,07,07,10,09,10,09,22
22,09,10,09,10,07,07,09,10,09,10,22
02,10,09,10,09,10,09,10,09,10,09,02
01,02,10,09,10,09,10,09,10,09,02,01
01,02,09,10,09,10,09,10,09,10,02,01
01,01,02,02,10,09,10,09,02,02,01,01
01,01,01,01,02,22,22,02,01,01,01,01
endlayer

# Floor Entrance (+1)
layer
01,01,01,01,02,10,10,02,01,01,01,01
01,01,02,02,00,00,00,12,02,02,01,01
01,02,00,00,00,00,00,11,11,00,02,01
01,02,00,00,00,00,00,00,00,00,02,01
02,00,00,00,00,00,00,00,00,00,00,02
10,00,00,00,00,00,00,00,00,00,00,10
10,00,00,00,00,00,00,00,00,00,00,10
02,00,00,00,00,00,00,00,00,00,00,02
01,02,00,00,00,00,00,00,00,00,02,01
01,02,00,00,00,00,00,00,00,00,02,01
01,01,02,02,00,00,00,00,02,02,01,01
01,01,01,01,02,00,00,02,01,01,01,01
endlayer

# Floor Entrance (+2)
layer
01,01,01,01,02,10,10,02,01,01,01,01
01,01,02,02,00,00,00,00,02,02,01,01
01,02,00,00,00,00,00,00,12,11,02,01
01,02,00,00,00,00,00,00,00,11,02,01
02,00,00,00,00,00,00,00,00,00,00,02
10,00,00,00,00,00,00,00,00,00,00,10
10,00,00,00,00,00,00,00,00,00,00,10
02,00,00,00,00,00,00,00,00,00,00,02
01,02,00,00,00,00,00,00,00,00,02,01
01,02,00,00,00,00,00,00,00,00,02,01
01,01,02,02,00,00,00,00,02,02,01,01
01,01,01,01,02,00,00,02,01,01,01,01
endlayer

# Floor Entrance (+3)
layer
01,01,01,01,02,10,10,02,01,01,01,01
01,01,02,02,00,00,00,00,02,02,01,01
01,02,00,00,00,00,00,00,00,00,02,01
01,02,00,00,00,00,00,00,00,12,02,01
02,00,00,00,00,00,00,00,00,11,11,02
10,00,00,00,00,00,00,00,00,00,00,10
10,00,00,00,00,00,00,00,00,00,00,10
02,00,00,00,00,00,00,00,00,00,00,02
01,02,00,00,00,00,00,00,00,00,02,01
01,02,00,00,00,00,00,00,00,00,02,01
01,01,02,02,00,00,00,00,02,02,01,01
01,01,01,01,02,00,00,02,01,01,01,01
endlayer

# 2nd Floor (+4 - Graveyard Soil)
layer
01,01,01,01,02,22,22,02,01,01,01,01
01,01,02,02,03,03,03,03,02,02,01,01
01,02,03,03,03,03,03,00,00,00,02,01
01,02,03,03,03,03,03,03,03,00,02,01
02,03,03,03,03,03,03,03,03,00,12,02
22,03,03,03,03,07,07,03,03,03,03,22
22,03,03,03,03,07,07,03,03,03,03,22
02,03,03,03,03,03,03,03,03,03,03,02
01,02,03,03,03,03,03,03,03,03,02,01
01,02,03,03,03,03,03,03,03,03,02,01
01,01,02,02,03,03,03,03,02,02,01,01
01,01,01,01,02,22,22,02,01,01,01,01
endlayer


# 2nd Floor (+5)
layer
01,01,01,01,02,10,10,02,01,01,01,01
01,01,02,02,00,00,00,00,02,02,01,01
01,02,17,00,00,23,23,00,00,00,02,01
01,02,00,00,00,00,00,00,00,00,02,01
02,00,00,00,00,00,00,00,00,00,00,02
10,00,23,00,00,00,00,00,00,23,00,10
10,00,23,00,00,00,00,00,00,23,00,10
02,00,00,00,00,00,00,00,00,00,00,02
01,02,21,00,00,00,00,00,00,00,02,01
01,02,17,11,11,23,23,00,00,17,02,01
01,01,02,02,12,00,00,00,02,02,01,01
01,01,01,01,02,10,10,02,01,01,01,01
endlayer

# 2nd Floor (+6)
layer
01,01,01,01,02,10,10,02,01,01,01,01
01,01,02,02,00,00,00,00,02,02,01,01
01,02,00,00,00,23,23,00,00,00,02,01
01,02,00,00,00,00,00,00,00,00,02,01
02,00,00,00,00,00,00,00,00,00,00,02
10,00,23,00,00,00,00,00,00,23,00,10
10,00,23,00,00,00,00,00,00,23,00,10
02,00,00,00,00,00,00,00,00,00,00,02
01,02,00,00,00,00,00,00,00,00,02,01
01,02,11,12,00,23,23,00,00,00,02,01
01,01,02,02,00,00,00,00,02,02,01,01
01,01,01,01,02,10,10,02,01,01,01,01
endlayer

# 2nd Floor (+7)
layer
01,01,01,01,02,10,10,02,01,01,01,01
01,01,02,02,00,00,00,00,02,02,01,01
01,02,00,00,00,23,23,00,00,00,02,01
01,02,00,00,00,00,00,00,00,00,02,01
02,00,00,00,00,00,00,00,00,00,00,02
10,00,23,00,00,00,00,00,00,23,00,10
10,00,23,00,00,00,00,00,00,23,00,10
02,11,11,00,00,00,00,00,00,00,00,02
01,02,12,00,00,00,00,00,00,00,02,01
01,02,00,00,00,23,23,00,00,00,02,01
01,01,02,02,00,00,00,00,02,02,01,01
01,01,01,01,02,10,10,02,01,01,01,01
endlayer

# 3rd Floor (+8 - Soul Sand)
layer
01,01,01,01,02,22,22,02,01,01,01,01
01,01,02,02,13,13,13,13,02,02,01,01
01,02,13,13,13,13,13,13,13,13,02,01
01,02,13,13,13,13,13,13,13,13,02,01
02,13,13,13,13,13,13,13,13,13,13,02
22,13,13,13,13,07,07,13,13,13,13,22
22,13,13,13,13,07,07,13,13,13,13,22
02,12,00,13,13,13,13,13,13,13,13,02
01,02,00,13,13,13,13,13,13,13,02,01
01,02,00,00,00,13,13,13,13,13,02,01
01,01,02,02,13,13,13,13,02,02,01,01
01,01,01,01,02,22,22,02,01,01,01,01
endlayer

# 3rd Floor (+9)
layer
01,01,01,01,02,10,10,02,01,01,01,01
01,01,02,02,00,00,00,12,02,02,01,01
01,02,18,00,00,24,24,11,11,18,02,01
01,02,00,00,00,00,00,00,00,21,02,01
02,00,00,00,00,00,00,00,00,00,00,02
10,00,24,00,00,00,00,00,00,24,00,10
10,00,24,00,00,00,00,00,00,24,00,10
02,00,00,00,00,00,00,00,00,00,00,02
01,02,00,00,00,00,00,00,00,00,02,01
01,02,00,00,00,24,24,00,00,18,02,01
01,01,02,02,00,00,00,00,02,02,01,01
01,01,01,01,02,10,10,02,01,01,01,01
endlayer

# 3rd Floor (+10)
layer
01,01,01,01,02,10,10,02,01,01,01,01
01,01,02,02,00,00,00,00,02,02,01,01
01,02,00,00,00,24,24,00,12,11,02,01
01,02,00,00,00,00,00,00,00,00,02,01
02,00,00,00,00,00,00,00,00,00,00,02
10,00,24,00,00,00,00,00,00,24,00,10
10,00,24,00,00,00,00,00,00,24,00,10
02,00,00,00,00,00,00,00,00,00,00,02
01,02,00,00,00,00,00,00,00,00,02,01
01,02,00,00,00,24,24,00,00,00,02,01
01,01,02,02,00,00,00,00,02,02,01,01
01,01,01,01,02,10,10,02,01,01,01,01
endlayer

# 3rd Floor (+11)
layer
01,01,01,01,02,10,10,02,01,01,01,01
01,01,02,02,00,00,00,00,02,02,01,01
01,02,00,00,00,24,24,00,00,00,02,01
01,02,00,00,00,00,00,00,00,12,02,01
02,00,00,00,00,00,00,00,00,11,11,02
10,00,24,00,00,00,00,00,00,24,00,10
10,00,24,00,00,00,00,00,00,24,00,10
02,00,00,00,00,00,00,00,00,00,00,02
01,02,00,00,00,00,00,00,00,00,02,01
01,02,00,00,00,24,24,00,00,00,02,01
01,01,02,02,00,00,00,00,02,02,01,01
01,01,01,01,02,10,10,02,01,01,01,01
endlayer

# 4th Floor (+12 - Brownstone + Hazards)
layer
01,01,01,01,02,22,22,02,01,01,01,01
01,01,02,02,14,14,14,14,02,02,01,01
01,02,14,14,14,04,04,00,00,00,02,01
01,02,14,14,14,14,14,14,14,00,02,01
02,14,14,14,14,14,14,14,14,00,12,02
22,14,04,14,14,07,07,14,14,04,14,22
22,14,04,14,14,07,07,14,14,04,14,22
02,14,14,14,14,14,14,14,14,14,14,02
01,02,14,14,14,14,14,14,14,14,02,01
01,02,14,14,14,04,04,14,14,14,02,01
01,01,02,02,14,14,14,14,02,02,01,01
01,01,01,01,02,22,22,02,01,01,01,01
endlayer

# 4th Floor (+13)
layer
01,01,01,01,02,10,10,02,01,01,01,01
01,01,02,02,00,00,00,00,02,02,01,01
01,02,00,00,00,25,25,00,00,00,02,01
01,02,00,00,00,00,00,00,00,00,02,01
02,00,00,00,00,00,00,00,00,00,00,02
10,00,25,00,00,00,00,00,00,25,00,10
10,00,25,00,00,00,00,00,00,25,00,10
02,00,00,00,00,00,00,00,00,00,00,02
01,02,21,00,00,00,00,00,00,00,02,01
01,02,19,11,11,25,25,00,00,00,02,01
01,01,02,02,12,00,00,00,02,02,01,01
01,01,01,01,02,10,10,02,01,01,01,01
endlayer

# 4th Floor (+14)
layer
01,01,01,01,02,10,10,02,01,01,01,01
01,01,02,02,00,00,00,00,02,02,01,01
01,02,00,00,00,25,25,00,00,00,02,01
01,02,00,00,00,00,00,00,00,00,02,01
02,00,00,00,00,00,00,00,00,00,00,02
10,00,25,00,00,00,00,00,00,25,00,10
10,00,25,00,00,00,00,00,00,25,00,10
02,00,00,00,00,00,00,00,00,00,00,02
01,02,00,00,00,00,00,00,00,00,02,01
01,02,11,12,00,25,25,00,00,00,02,01
01,01,02,02,00,00,00,00,02,02,01,01
01,01,01,01,02,10,10,02,01,01,01,01
endlayer

# 4th Floor (+15)
layer
01,01,01,01,02,10,10,02,01,01,01,01
01,01,02,02,00,00,00,00,02,02,01,01
01,02,00,00,00,25,25,00,00,00,02,01
01,02,00,00,00,00,00,00,00,00,02,01
02,00,00,00,00,00,00,00,00,00,00,02
10,00,25,00,00,00,00,00,00,25,00,10
10,00,25,00,00,00,00,00,00,25,00,10
02,11,11,00,00,00,00,00,00,00,00,02
01,02,12,00,00,00,00,00,00,00,02,01
01,02,00,00,00,25,25,00,00,00,02,01
01,01,02,02,00,00,00,00,02,02,01,01
01,01,01,01,02,10,10,02,01,01,01,01
endlayer

# 5th Floor (+16 - Obsidian / Red Rock)
layer
01,01,01,01,02,22,22,02,01,01,01,01
01,01,02,02,15,16,15,16,02,02,01,01
01,02,16,15,16,15,16,15,16,15,02,01
01,02,15,16,15,16,15,16,15,16,02,01
02,15,16,15,16,15,16,15,16,15,16,02
22,16,15,16,15,07,07,16,15,16,15,22
22,15,16,15,16,07,07,15,16,15,16,22
02,12,00,16,15,16,15,16,15,16,15,02
01,02,00,15,16,15,16,15,16,15,02,01
01,02,00,00,00,16,15,16,15,16,02,01
01,01,02,02,16,15,16,15,02,02,01,01
01,01,01,01,02,22,22,02,01,01,01,01
endlayer

# 5th Floor (+17)
layer
01,01,01,01,02,10,10,02,01,01,01,01
01,01,02,02,00,00,00,12,02,02,01,01
01,02,00,00,00,00,00,11,11,19,02,01
01,02,00,00,00,15,15,00,00,21,02,01
02,00,00,00,15,08,08,15,00,00,00,02
10,00,00,15,08,08,08,08,15,00,00,10
10,00,00,15,08,08,08,08,15,00,00,10
02,00,00,00,15,08,08,15,00,00,00,02
01,02,00,00,00,15,15,00,00,00,02,01
01,02,00,00,00,00,00,00,00,00,02,01
01,01,02,02,00,00,00,00,02,02,01,01
01,01,01,01,02,10,10,02,01,01,01,01
endlayer

# 5th Floor (+18)
layer
01,01,01,01,02,10,10,02,01,01,01,01
01,01,02,02,00,00,00,00,02,02,01,01
01,02,00,00,00,00,00,00,12,11,02,01
01,02,00,00,00,15,15,00,00,00,02,01
02,00,00,00,15,08,08,15,00,00,00,02
10,00,00,15,08,08,08,08,15,00,00,10
10,00,00,15,08,08,08,08,15,00,00,10
02,00,00,00,15,08,08,15,00,00,00,02
01,02,00,00,00,15,15,00,00,00,02,01
01,02,00,00,00,00,00,00,00,00,02,01
01,01,02,02,00,00,00,00,02,02,01,01
01,01,01,01,02,10,10,02,01,01,01,01
endlayer

# 5th Floor (+19)
layer
01,01,01,01,02,10,10,02,01,01,01,01
01,01,02,02,00,00,00,00,02,02,01,01
01,02,00,00,00,00,00,00,00,00,02,01
01,02,00,00,00,15,15,00,00,12,02,01
02,00,00,00,15,06,06,15,00,11,11,02
10,00,00,15,06,06,06,06,15,00,00,10
10,00,00,15,06,06,06,06,15,00,00,10
02,00,00,00,15,06,06,15,00,00,00,02
01,02,00,00,00,15,15,00,00,00,02,01
01,02,00,00,00,00,00,00,00,00,02,01
01,01,02,02,00,00,00,00,02,02,01,01
01,01,01,01,02,10,10,02,01,01,01,01
endlayer

# 6th Floor (+20 - Obsidian)
layer
01,01,01,01,02,22,22,02,01,01,01,01
01,01,02,02,15,15,15,15,02,02,01,01
01,02,15,15,15,15,15,00,00,00,02,01
01,02,15,15,15,15,15,15,15,00,02,01
02,15,15,15,15,15,15,15,15,00,12,02
22,15,15,15,15,07,07,15,15,15,15,22
22,15,15,15,15,07,07,15,15,15,15,22
02,15,15,15,15,15,15,15,15,15,15,02
01,02,15,15,15,15,15,15,15,15,02,01
01,02,15,15,15,15,15,15,15,15,02,01
01,01,02,02,15,15,15,15,02,02,01,01
01,01,01,01,02,22,22,02,01,01,01,01
endlayer

# 6th Floor (+21)
layer
01,01,01,01,02,10,10,02,01,01,01,01
01,01,02,02,00,00,00,00,02,02,01,01
01,02,00,00,00,02,02,00,00,00,02,01
01,02,00,00,00,00,00,00,00,00,02,01
02,00,00,00,00,05,05,00,00,00,00,02
10,00,02,00,05,05,05,05,00,02,00,10
10,00,02,00,05,05,05,05,00,02,00,10
02,00,00,00,00,05,05,00,00,00,00,02
01,02,21,00,00,00,00,00,00,00,02,01
01,02,19,11,11,02,02,00,00,00,02,01
01,01,02,02,12,00,00,00,02,02,01,01
01,01,01,01,02,10,10,02,01,01,01,01
endlayer

# 6th Floor (+22)
layer
01,01,01,01,02,10,10,02,01,01,01,01
01,01,02,02,00,00,00,00,02,02,01,01
01,02,00,00,00,02,02,00,00,00,02,01
01,02,00,00,00,00,00,00,00,00,02,01
02,00,00,00,00,00,00,00,00,00,00,02
10,00,02,00,00,00,00,00,00,02,00,10
10,00,02,00,00,00,00,00,00,02,00,10
02,00,00,00,00,00,00,00,00,00,00,02
01,02,00,00,00,00,00,00,00,00,02,01
01,02,11,12,00,02,02,00,00,00,02,01
01,01,02,02,00,00,00,00,02,02,01,01
01,01,01,01,02,10,10,02,01,01,01,01
endlayer

# 6th Floor (+23)
layer
01,01,01,01,02,10,10,02,01,01,01,01
01,01,02,02,00,00,00,00,02,02,01,01
01,02,00,00,00,02,02,00,00,00,02,01
01,02,00,00,00,00,00,00,00,00,02,01
02,00,00,00,00,00,00,00,00,00,00,02
10,00,02,00,00,00,00,00,00,02,00,10
10,00,02,00,00,00,00,00,00,02,00,10
02,11,11,00,00,00,00,00,00,00,00,02
01,02,12,00,00,00,00,00,00,00,02,01
01,02,00,00,00,02,02,00,00,00,02,01
01,01,02,02,00,00,00,00,02,02,01,01
01,01,01,01,02,10,10,02,01,01,01,01
endlayer

# 7th Floor (+24 - Obsidian / Red Rock)
layer
01,01,01,01,02,22,22,02,01,01,01,01
01,01,02,02,15,16,15,16,02,02,01,01
01,02,16,15,16,15,16,15,16,15,02,01
01,02,15,16,15,16,15,16,15,16,02,01
02,15,16,15,16,15,16,15,16,15,16,02
22,16,15,16,15,07,07,16,15,16,15,22
22,15,16,15,16,07,07,15,16,15,16,22
02,12,00,16,15,16,15,16,15,16,15,02
01,02,00,15,16,15,16,15,16,15,02,01
01,02,00,00,00,16,15,16,15,16,02,01
01,01,02,02,16,15,16,15,02,02,01,01
01,01,01,01,02,22,22,02,01,01,01,01
endlayer

# 7th Floor (+25)
layer
01,01,01,01,02,10,10,02,01,01,01,01
01,01,02,02,00,00,00,00,02,02,01,01
01,02,00,00,00,00,00,00,00,00,02,01
01,02,00,00,00,00,00,00,00,00,02,01
02,00,00,00,00,00,00,00,00,00,00,02
10,00,00,00,00,20,21,00,00,00,00,10
10,00,00,00,00,21,20,00,00,00,00,10
02,00,00,00,00,00,00,00,00,00,00,02
01,02,00,00,00,00,00,00,00,00,02,01
01,02,00,00,00,00,00,00,00,00,02,01
01,01,02,02,00,00,00,00,02,02,01,01
01,01,01,01,02,10,10,02,01,01,01,01
endlayer

# 7th Floor (+26)
layer
01,01,01,01,02,10,10,02,01,01,01,01
01,01,02,02,00,00,00,00,02,02,01,01
01,02,00,00,00,00,00,00,00,00,02,01
01,02,00,00,00,00,00,00,00,00,02,01
02,00,00,00,00,00,00,00,00,00,00,02
10,00,00,00,00,00,00,00,00,00,00,10
10,00,00,00,00,00,00,00,00,00,00,10
02,00,00,00,00,00,00,00,00,00,00,02
01,02,00,00,00,00,00,00,00,00,02,01
01,02,00,00,00,00,00,00,00,00,02,01
01,01,02,02,00,00,00,00,02,02,01,01
01,01,01,01,02,10,10,02,01,01,01,01
endlayer

# 7th Floor (+27)
layer
01,01,01,01,02,10,10,02,01,01,01,01
01,01,02,02,00,00,00,00,02,02,01,01
01,02,00,00,00,00,00,00,00,00,02,01
01,02,00,00,00,00,00,00,00,00,02,01
02,00,00,00,00,00,00,00,00,00,00,02
10,00,00,00,00,00,00,00,00,00,00,10
10,00,00,00,00,00,00,00,00,00,00,10
02,00,00,00,00,00,00,00,00,00,00,02
01,02,00,00,00,00,00,00,00,00,02,01
01,02,00,00,00,00,00,00,00,00,02,01
01,01,02,02,00,00,00,00,02,02,01,01
01,01,01,01,02,10,10,02,01,01,01,01
endlayer

# 7th Floor (+28)
layer
01,01,01,01,02,10,10,02,01,01,01,01
01,01,02,02,00,00,00,00,02,02,01,01
01,02,00,00,00,00,00,00,00,00,02,01
01,02,00,00,00,00,00,00,00,00,02,01
02,00,00,00,00,00,00,00,00,00,00,02
10,00,00,00,00,00,00,00,00,00,00,10
10,00,00,00,00,00,00,00,00,00,00,10
02,00,00,00,00,00,00,00,00,00,00,02
01,02,00,00,00,00,00,00,00,00,02,01
01,02,00,00,00,00,00,00,00,00,02,01
01,01,02,02,00,00,00,00,02,02,01,01
01,01,01,01,02,10,10,02,01,01,01,01
endlayer

# Roof (+29)
layer
00,00,00,00,22,22,22,22,00,00,00,00
00,00,22,22,22,00,00,22,22,22,00,00
00,22,22,00,00,00,00,00,00,22,22,00
00,22,00,00,00,00,00,00,00,00,22,00
22,22,00,00,00,00,00,00,00,00,22,22
22,00,00,00,00,00,00,00,00,00,00,22
22,00,00,00,00,00,00,00,00,00,00,22
22,22,00,00,00,00,00,00,00,00,22,22
00,22,00,00,00,00,00,00,00,00,22,00
00,22,22,00,00,00,00,00,00,22,22,00
00,00,22,22,22,00,00,22,22,22,00,00
00,00,00,00,22,22,22,22,00,00,00,00
endlayer

# Roof (+30)
layer
00,00,00,00,00,00,00,00,00,00,00,00
00,00,00,00,22,22,22,22,00,00,00,00
00,00,22,22,22,00,00,22,22,22,00,00
00,00,22,00,00,00,00,00,00,22,00,00
00,22,22,00,00,00,00,00,00,22,22,00
00,22,00,00,00,00,00,00,00,00,22,00
00,22,00,00,00,00,00,00,00,00,22,00
00,22,22,00,00,00,00,00,00,22,22,00
00,00,22,00,00,00,00,00,00,22,00,00
00,00,22,22,22,00,00,22,22,22,00,00
00,00,00,00,22,22,22,22,00,00,00,00
00,00,00,00,00,00,00,00,00,00,00,00
endlayer

# Roof (+31)
layer
00,00,00,00,00,00,00,00,00,00,00,00
00,00,00,00,00,22,22,00,00,00,00,00
00,00,00,22,22,22,22,22,22,00,00,00
00,00,22,22,00,00,00,00,22,22,00,00
00,00,22,00,00,00,00,00,00,22,00,00
00,22,22,00,00,00,00,00,00,22,22,00
00,22,22,00,00,00,00,00,00,22,22,00
00,00,22,00,00,00,00,00,00,22,00,00
00,00,22,22,00,00,00,00,22,22,00,00
00,00,00,22,22,22,22,22,22,00,00,00
00,00,00,00,00,22,22,00,00,00,00,00
00,00,00,00,00,00,00,00,00,00,00,00
endlayer

# Roof (+32)
layer
00,00,00,00,00,00,00,00,00,00,00,00
00,00,00,00,00,00,00,00,00,00,00,00
00,00,00,00,22,22,22,22,00,00,00,00
00,00,00,22,22,22,22,22,22,00,00,00
00,00,22,22,22,00,00,22,22,22,00,00
00,00,22,22,00,00,00,00,22,22,00,00
00,00,22,22,00,00,00,00,22,22,00,00
00,00,22,22,22,00,00,22,22,22,00,00
00,00,00,22,22,22,22,22,22,00,00,00
00,00,00,00,22,22,22,22,00,00,00,00
00,00,00,00,00,00,00,00,00,00,00,00
00,00,00,00,00,00,00,00,00,00,00,00
endlayer

# Roof (+33)
layer
00,00,00,00,00,00,00,00,00,00,00,00
00,00,00,00,00,00,00,00,00,00,00,00
00,00,00,00,00,22,22,00,00,00,00,00
00,00,00,22,22,22,22,22,22,00,00,00
00,00,00,22,22,00,00,22,22,00,00,00
00,00,22,22,00,00,00,00,22,22,00,00
00,00,22,22,00,00,00,00,22,22,00,00
00,00,00,22,22,00,00,22,22,00,00,00
00,00,00,22,22,22,22,22,22,00,00,00
00,00,00,00,00,22,22,00,00,00,00,00
00,00,00,00,00,00,00,00,00,00,00,00
00,00,00,00,00,00,00,00,00,00,00,00
endlayer

# Roof (+34)
layer
00,00,00,00,00,00,00,00,00,00,00,00
00,00,00,00,00,00,00,00,00,00,00,00
00,00,00,00,00,00,00,00,00,00,00,00
00,00,00,00,22,22,22,22,00,00,00,00
00,00,00,22,22,00,00,22,22,00,00,00
00,00,00,22,00,00,00,00,22,00,00,00
00,00,00,22,00,00,00,00,22,00,00,00
00,00,00,22,22,00,00,22,22,00,00,00
00,00,00,00,22,22,22,22,00,00,00,00
00,00,00,00,00,00,00,00,00,00,00,00
00,00,00,00,00,00,00,00,00,00,00,00
00,00,00,00,00,00,00,00,00,00,00,00
endlayer

# Roof (+35)
layer
00,00,00,00,00,00,00,00,00,00,00,00
00,00,00,00,00,00,00,00,00,00,00,00
00,00,00,00,00,00,00,00,00,00,00,00
00,00,00,00,00,22,22,00,00,00,00,00
00,00,00,00,22,22,22,22,00,00,00,00
00,00,00,22,22,21,21,22,22,00,00,00
00,00,00,22,22,21,21,22,22,00,00,00
00,00,00,00,22,22,22,22,00,00,00,00
00,00,00,00,00,22,22,00,00,00,00,00
00,00,00,00,00,00,00,00,00,00,00,00
00,00,00,00,00,00,00,00,00,00,00,00
00,00,00,00,00,00,00,00,00,00,00,00
endlayer

# Roof (+36)
layer
00,00,00,00,00,00,00,00,00,00,00,00
00,00,00,00,00,00,00,00,00,00,00,00
00,00,00,00,00,00,00,00,00,00,00,00
00,00,00,00,00,00,00,00,00,00,00,00
00,00,00,00,22,22,22,22,00,00,00,00
00,00,00,00,22,00,00,22,00,00,00,00
00,00,00,00,22,00,00,22,00,00,00,00
00,00,00,00,22,22,22,22,00,00,00,00
00,00,00,00,00,00,00,00,00,00,00,00
00,00,00,00,00,00,00,00,00,00,00,00
00,00,00,00,00,00,00,00,00,00,00,00
00,00,00,00,00,00,00,00,00,00,00,00
endlayer

# Roof (+37)
layer
00,00,00,00,00,00,00,00,00,00,00,00
00,00,00,00,00,00,00,00,00,00,00,00
00,00,00,00,00,00,00,00,00,00,00,00
00,00,00,00,00,00,00,00,00,00,00,00
00,00,00,00,00,22,22,00,00,00,00,00
00,00,00,00,22,22,22,22,00,00,00,00
00,00,00,00,22,22,22,22,00,00,00,00
00,00,00,00,00,22,22,00,00,00,00,00
00,00,00,00,00,00,00,00,00,00,00,00
00,00,00,00,00,00,00,00,00,00,00,00
00,00,00,00,00,00,00,00,00,00,00,00
00,00,00,00,00,00,00,00,00,00,00,00
endlayer

# Roof (+38)
layer
00,00,00,00,00,00,00,00,00,00,00,00
00,00,00,00,00,00,00,00,00,00,00,00
00,00,00,00,00,00,00,00,00,00,00,00
00,00,00,00,00,00,00,00,00,00,00,00
00,00,00,00,00,22,22,00,00,00,00,00
00,00,00,00,22,22,22,22,00,00,00,00
00,00,00,00,22,22,22,22,00,00,00,00
00,00,00,00,00,22,22,00,00,00,00,00
00,00,00,00,00,00,00,00,00,00,00,00
00,00,00,00,00,00,00,00,00,00,00,00
00,00,00,00,00,00,00,00,00,00,00,00
00,00,00,00,00,00,00,00,00,00,00,00
endlayer

# Roof (+39)
layer
00,00,00,00,00,00,00,00,00,00,00,00
00,00,00,00,00,00,00,00,00,00,00,00
00,00,00,00,00,00,00,00,00,00,00,00
00,00,00,00,00,00,00,00,00,00,00,00
00,00,00,00,00,00,00,00,00,00,00,00
00,00,00,00,00,22,22,00,00,00,00,00
00,00,00,00,00,22,22,00,00,00,00,00
00,00,00,00,00,00,00,00,00,00,00,00
00,00,00,00,00,00,00,00,00,00,00,00
00,00,00,00,00,00,00,00,00,00,00,00
00,00,00,00,00,00,00,00,00,00,00,00
00,00,00,00,00,00,00,00,00,00,00,00
endlayer

# Roof (+40)
layer
00,00,00,00,00,00,00,00,00,00,00,00
00,00,00,00,00,00,00,00,00,00,00,00
00,00,00,00,00,00,00,00,00,00,00,00
00,00,00,00,00,00,00,00,00,00,00,00
00,00,00,00,00,00,00,00,00,00,00,00
00,00,00,00,00,22,22,00,00,00,00,00
00,00,00,00,00,22,22,00,00,00,00,00
00,00,00,00,00,00,00,00,00,00,00,00
00,00,00,00,00,00,00,00,00,00,00,00
00,00,00,00,00,00,00,00,00,00,00,00
00,00,00,00,00,00,00,00,00,00,00,00
00,00,00,00,00,00,00,00,00,00,00,00
endlayer

# Roof (+41)
layer
00,00,00,00,00,00,00,00,00,00,00,00
00,00,00,00,00,00,00,00,00,00,00,00
00,00,00,00,00,00,00,00,00,00,00,00
00,00,00,00,00,00,00,00,00,00,00,00
00,00,00,00,00,00,00,00,00,00,00,00
00,00,00,00,00,07,07,00,00,00,00,00
00,00,00,00,00,07,07,00,00,00,00,00
00,00,00,00,00,00,00,00,00,00,00,00
00,00,00,00,00,00,00,00,00,00,00,00
00,00,00,00,00,00,00,00,00,00,00,00
00,00,00,00,00,00,00,00,00,00,00,00
00,00,00,00,00,00,00,00,00,00,00,00
endlayer


















