# Village_Tree (19 Mar 2014, 24 Mar 2014 - for MC v. 1.7.2)
# Created by Ruins mod version 12.3 Ingame Parser
# authoring Player: Jordan_Greywolf

# Updated for MC 1.12: 8 Apr 2018

biomesToSpawnIn=autumnal_woods,clearing,dungeon,flower forest,forest,foresthills,forest_hills,green hills,green_hills,magical forest,meadow,mutated_forest,mutated_swampland,mystic grove,mystic_grove,origin_island,rwg_coldforest,rwg_temperateforest,scrubland,shield,shrubland,smaller_extreme_hills,swampland,temperate_rainforest,woodland,woodlands

weight=1
embed_into_distance=5

unacceptable_target_blocks=flowing_water,water,flowing_lava,lava,cloud,Natura:Cloud,slime_congealed,slime_dirt,slime_grass,command_block,planks,planks2,concrete,cobblestone,stonebrick,brick_block,glass,torch,oak_stairs,stone_stairs,brick_stairs,stone_brick_stairs,nether_brick_stairs,sandstone_stairs,spruce_stairs,birch_stairs,jungle_stairs,quartz_stairs,acacia_stairs,dark_oak_stairs,cobblestone_wall,stone_slab,double_stone_slab,stone_slab2,wooden_slab,double_wooden_slab,nether_brick,fence

uniqueMinDistance=2000
spawnMinDistance=250

dimensions=28,24,22
allowable_overhang=999
max_cut_in=0
cut_in_buffer=0
max_leveling=10
leveling_buffer=-1
preserve_water=1
preserve_lava=0
preserve_plants=1

# "Beveled" merger with upward-sloping terrain
rule1=0,100,preserveBlock

# Oak Wood/Log (bark on all sides)
rule2=0,100,minecraft:log-12
rule3=0,100,minecraft:ladder-4

# Jack-o'-Lanterns (no face)
rule4=0,100,minecraft:lit_pumpkin-4

# Oak Leaves (no decay)
rule5=0,100,minecraft:leaves-4

rule6=0,100,minecraft:wooden_slab-8
rule7=0,100,minecraft:planks-0

# Randomized farming ground condition
rule8=0,100,minecraft:farmland-4,minecraft:farmland-1,minecraft:dirt

rule9=0,100,minecraft:water-0
rule10=0,100,minecraft:fence-0
rule11=0,100,minecraft:oak_stairs-2
rule12=0,100,minecraft:wooden_door-2
rule13=0,100,minecraft:oak_stairs-1

# Randomized crops
rule14=0,100,minecraft:carrots-4,minecraft:carrots-1
rule15=0,50,minecraft:pumpkin-4
rule16=0,100,minecraft:pumpkin_stem-7,minecraft:pumpkin_stem-4,minecraft:pumpkin_stem-1

rule17=0,100,minecraft:wooden_door-3
rule18=0,100,minecraft:fence_gate-0
rule19=0,100,minecraft:ladder-3
rule20=0,100,minecraft:oak_stairs-0
rule21=0,100,minecraft:fence_gate-2
rule22=0,100,minecraft:oak_stairs-3
rule23=0,100,minecraft:wooden_door-1
rule24=0,100,minecraft:crafting_table-0,minecraft:lit_furnace-0
rule25=0,100,minecraft:wooden_door-0
rule26=0,100,minecraft:wooden_door-9
rule27=0,100,minecraft:wooden_door-8
rule28=0,100,minecraft:ladder-2
rule29=0,100,minecraft:wheat-4,minecraft:wheat-1
rule30=0,100,minecraft:ladder-5
rule31=0,100,minecraft:wooden_slab-0
rule32=0,100,minecraft:potatoes-4,minecraft:potatoes-1
rule33=0,100,minecraft:dirt-0
rule34=0,100,minecraft:wooden_door-4

# Rooftop saplings
rule35=0,100,minecraft:tallgrass-2,minecraft:sapling-2,minecraft:sapling-1

rule36=0,100,minecraft:bed-10
rule37=0,100,minecraft:bed-2
rule38=0,100,minecraft:bed-3
rule39=0,100,minecraft:bed-11

# Villagers
rule40=0,100,CommandBlock:RUINSTRIGGER /summon Villager ~0 ~0 ~0:@

layer
1,1,1,1,1,1,1,1,1,1,1,1,1,1,1,1,1,1,1,1,1,1
1,1,1,1,1,1,1,1,1,1,1,1,1,1,1,1,1,1,1,1,1,1
1,1,1,1,1,1,1,1,1,1,1,1,1,1,1,1,1,1,1,1,1,1
1,1,1,1,1,1,1,1,1,1,1,1,1,1,1,1,1,1,1,1,1,1
1,1,1,1,1,1,1,1,1,1,1,1,1,1,1,1,1,1,1,1,1,1
1,1,1,1,1,1,1,1,1,1,1,1,1,1,1,1,1,1,1,1,1,1
1,1,1,1,1,1,1,1,1,1,1,1,1,1,1,1,1,1,1,1,1,1
1,1,1,1,1,1,1,1,1,1,1,1,1,1,1,1,1,1,1,1,1,1
1,1,1,1,1,1,1,2,1,1,1,1,1,1,1,1,2,1,1,1,1,1
1,1,1,1,1,1,1,1,1,1,1,1,1,1,1,2,1,1,1,1,1,1
1,1,1,1,1,1,1,1,1,1,1,1,1,1,1,1,1,1,1,1,1,1
1,1,1,1,1,1,1,1,1,1,1,1,1,1,1,1,1,1,1,1,1,1
1,1,1,1,1,1,1,1,1,1,1,2,1,1,1,1,1,1,1,1,1,1
1,1,1,1,1,1,1,1,1,1,1,1,1,1,1,1,2,1,1,1,1,1
1,1,1,1,1,1,1,1,1,1,1,1,1,1,1,1,1,1,1,1,1,1
1,1,1,1,1,1,1,1,1,1,1,1,1,1,2,1,1,1,1,1,1,1
1,1,1,1,1,1,1,1,1,1,1,1,1,1,1,1,1,1,1,1,1,1
1,1,1,1,1,1,1,1,1,1,1,1,1,1,1,1,1,1,1,1,1,1
1,1,1,1,1,1,1,1,1,1,1,1,1,1,1,1,1,1,1,1,1,1
1,1,1,1,1,1,1,1,1,1,1,1,1,1,1,1,1,1,1,1,1,1
1,1,1,1,1,1,1,1,1,1,1,1,1,1,1,1,1,1,1,1,1,1
1,1,1,1,1,1,1,1,1,1,1,1,1,1,1,1,1,1,1,1,1,1
1,1,1,1,1,1,1,1,1,1,1,1,1,1,1,1,1,1,1,1,1,1
1,1,1,1,1,1,1,1,1,1,1,1,1,1,1,1,1,1,1,1,1,1
endlayer

layer
1,1,1,1,1,1,1,1,1,1,1,1,1,1,1,1,1,1,1,1,1,1
1,1,1,1,1,1,1,1,1,1,1,1,1,1,1,1,1,1,1,1,1,1
1,1,1,1,1,1,1,1,1,1,1,1,1,1,1,1,1,1,1,1,1,1
1,1,1,1,1,1,1,1,1,1,1,1,1,1,1,1,1,1,1,1,1,1
1,1,1,1,1,1,1,1,1,1,1,1,1,1,1,1,1,1,1,1,1,1
1,1,1,1,1,1,1,1,1,1,1,1,1,1,1,1,1,1,1,1,1,1
1,1,1,1,1,1,1,1,1,1,1,1,1,1,1,1,1,1,1,1,1,1
1,1,1,1,1,1,1,1,1,1,1,1,1,1,1,1,1,1,1,1,1,1
1,1,1,1,1,1,1,2,1,1,1,1,1,1,1,1,1,1,1,1,1,1
1,1,1,1,1,1,1,1,1,1,1,1,1,1,1,2,1,1,1,1,1,1
1,1,1,1,1,1,1,1,1,1,1,1,1,1,1,1,1,1,1,1,1,1
1,1,1,1,1,1,1,1,1,1,1,1,1,1,1,1,1,1,1,1,1,1
1,1,1,1,1,1,1,1,1,1,1,2,1,1,1,1,1,1,1,1,1,1
1,1,1,1,1,1,1,1,1,1,1,1,1,1,1,2,1,1,1,1,1,1
1,1,1,1,1,1,1,1,2,1,1,1,1,1,1,1,1,1,1,1,1,1
1,1,1,1,1,1,1,1,1,1,1,1,1,1,2,1,1,1,1,1,1,1
1,1,1,1,1,1,1,1,1,1,1,1,1,1,1,1,1,1,1,1,1,1
1,1,1,1,1,1,1,1,1,1,1,1,1,1,1,1,1,1,1,1,1,1
1,1,1,1,1,1,1,1,1,1,1,1,1,1,1,1,1,1,1,1,1,1
1,1,1,1,1,1,1,1,1,1,1,1,1,1,1,1,1,1,1,1,1,1
1,1,1,1,1,1,1,1,1,1,1,1,1,1,1,1,1,1,1,1,1,1
1,1,1,1,1,1,1,1,1,1,1,1,1,1,1,1,1,1,1,1,1,1
1,1,1,1,1,1,1,1,1,1,1,1,1,1,1,1,1,1,1,1,1,1
1,1,1,1,1,1,1,1,1,1,1,1,1,1,1,1,1,1,1,1,1,1
endlayer

layer
1,1,1,1,1,1,1,1,1,1,1,1,1,1,1,1,1,1,1,1,1,1
1,1,1,1,1,1,1,1,1,1,1,1,1,1,1,1,1,1,1,1,1,1
1,1,1,1,1,1,1,1,1,1,1,1,1,1,1,1,1,1,1,1,1,1
1,1,1,1,1,1,1,1,1,1,1,1,1,1,1,1,1,1,1,1,1,1
1,1,1,1,1,1,1,1,1,1,1,1,1,1,1,1,1,1,1,1,1,1
1,1,1,1,1,1,1,1,1,1,1,1,1,1,1,1,1,1,1,1,1,1
1,1,1,1,1,1,1,1,1,1,1,1,1,1,1,1,1,1,1,1,1,1
1,1,1,1,1,1,1,1,1,1,1,1,1,1,1,1,1,1,1,1,1,1
1,1,1,1,1,1,1,1,2,1,1,1,1,1,1,1,1,1,1,1,1,1
1,1,1,1,1,1,1,1,1,2,1,1,1,1,2,1,1,1,1,1,1,1
1,1,1,1,1,1,1,1,1,1,1,1,1,1,1,1,1,1,1,1,1,1
1,1,1,1,1,1,1,1,1,1,1,1,1,1,1,1,1,1,1,1,1,1
1,1,1,1,1,1,1,1,1,1,1,2,1,1,1,2,1,1,1,1,1,1
1,1,1,1,1,1,1,1,1,1,1,1,1,1,1,1,1,1,1,1,1,1
1,1,1,1,1,1,1,1,2,1,1,1,1,2,1,1,1,1,1,1,1,1
1,1,1,1,1,1,1,1,1,1,1,1,1,1,2,1,1,1,1,1,1,1
1,1,1,1,1,1,1,1,1,1,1,1,1,1,1,1,1,1,1,1,1,1
1,1,1,1,1,1,1,1,1,1,1,1,1,1,1,1,1,1,1,1,1,1
1,1,1,1,1,1,1,1,1,1,1,1,1,1,1,1,1,1,1,1,1,1
1,1,1,1,1,1,1,1,1,1,1,1,1,1,1,1,1,1,1,1,1,1
1,1,1,1,1,1,1,1,1,1,1,1,1,1,1,1,1,1,1,1,1,1
1,1,1,1,1,1,1,1,1,1,1,1,1,1,1,1,1,1,1,1,1,1
1,1,1,1,1,1,1,1,1,1,1,1,1,1,1,1,1,1,1,1,1,1
1,1,1,1,1,1,1,1,1,1,1,1,1,1,1,1,1,1,1,1,1,1
endlayer

layer
1,1,1,1,1,1,1,1,1,1,1,1,1,1,1,1,1,1,1,1,1,1
1,1,1,1,1,1,1,1,1,1,1,1,1,1,1,1,1,1,1,1,1,1
1,1,1,1,1,1,1,1,1,1,1,1,1,1,1,1,1,1,1,1,1,1
1,1,1,1,1,1,1,1,1,1,1,1,1,1,1,1,1,1,1,1,1,1
1,1,1,1,1,1,1,1,1,1,1,1,1,1,1,1,1,1,1,1,1,1
1,1,1,1,1,1,1,1,1,1,1,1,1,1,1,1,1,1,1,1,1,1
1,1,1,1,1,1,1,1,1,1,1,1,1,1,1,1,1,1,1,1,1,1
1,1,1,1,1,1,1,1,1,1,1,1,1,1,1,1,1,1,1,1,1,1
1,1,1,1,1,1,1,1,1,1,1,1,1,1,1,1,1,1,1,1,1,1
1,1,1,1,1,1,1,1,1,2,1,1,1,2,1,1,1,1,1,1,1,1
1,1,1,1,1,1,1,1,1,1,2,1,2,1,1,1,1,1,1,1,1,1
1,1,1,1,1,1,1,1,1,1,1,1,1,2,1,1,1,1,1,1,1,1
1,1,1,1,1,1,1,1,1,1,1,2,1,1,2,1,1,1,1,1,1,1
1,1,1,1,1,1,1,1,1,2,1,1,1,1,1,1,1,1,1,1,1,1
1,1,1,1,1,1,1,1,2,1,1,1,1,2,1,1,1,1,1,1,1,1
1,1,1,1,1,1,1,1,1,1,1,1,1,1,1,1,1,1,1,1,1,1
1,1,1,1,1,1,1,1,1,1,1,1,1,1,1,1,1,1,1,1,1,1
1,1,1,1,1,1,1,1,1,1,1,1,1,1,1,1,1,1,1,1,1,1
1,1,1,1,1,1,1,1,1,1,1,1,1,1,1,1,1,1,1,1,1,1
1,1,1,1,1,1,1,1,1,1,1,1,1,1,1,1,1,1,1,1,1,1
1,1,1,1,1,1,1,1,1,1,1,1,1,1,1,1,1,1,1,1,1,1
1,1,1,1,1,1,1,1,1,1,1,1,1,1,1,1,1,1,1,1,1,1
1,1,1,1,1,1,1,1,1,1,1,1,1,1,1,1,1,1,1,1,1,1
1,1,1,1,1,1,1,1,1,1,1,1,1,1,1,1,1,1,1,1,1,1
endlayer

layer
1,1,1,1,1,1,1,1,1,1,1,1,1,1,1,1,1,1,1,1,1,1
1,1,1,1,1,1,1,1,1,1,1,1,1,1,1,1,1,1,1,1,1,1
1,1,1,1,1,1,1,1,1,1,1,1,1,1,1,1,1,1,1,1,1,1
1,1,1,1,1,1,1,1,1,1,1,1,1,1,1,1,1,1,1,1,1,1
1,1,1,1,1,1,1,1,1,1,1,1,1,1,1,1,1,1,1,1,1,1
1,1,1,1,1,1,1,1,1,1,1,1,1,1,1,1,1,1,1,1,1,1
1,1,1,1,1,1,1,1,1,1,1,1,1,1,1,1,1,1,1,1,1,1
1,1,1,1,1,1,1,1,1,1,1,1,1,1,1,1,1,1,1,1,1,1
1,1,1,1,1,1,1,1,1,1,1,1,1,1,1,1,1,1,1,1,1,1
1,1,1,1,1,1,1,1,1,1,1,1,1,1,1,1,1,1,1,1,1,1
1,1,1,1,1,1,1,1,1,1,2,2,2,1,1,1,1,1,1,1,1,1
1,1,1,1,1,1,1,1,1,1,2,2,2,2,1,1,1,1,1,1,1,1
1,1,1,1,1,1,1,1,1,1,1,2,1,1,1,1,1,1,1,1,1,1
1,1,1,1,1,1,1,1,1,2,1,1,2,1,1,1,1,1,1,1,1,1
1,1,1,1,1,1,1,1,1,1,1,1,1,2,1,1,1,1,1,1,1,1
1,1,1,1,1,1,1,1,1,1,1,1,1,1,1,1,1,1,1,1,1,1
1,1,1,1,1,1,1,1,1,1,1,1,1,1,1,1,1,1,1,1,1,1
1,1,1,1,1,1,1,1,1,1,1,1,1,1,1,1,1,1,1,1,1,1
1,1,1,1,1,1,1,1,1,1,1,1,1,1,1,1,1,1,1,1,1,1
1,1,1,1,1,1,1,1,1,1,1,1,1,1,1,1,1,1,1,1,1,1
1,1,1,1,1,1,1,1,1,1,1,1,1,1,1,1,1,1,1,1,1,1
1,1,1,1,1,1,1,1,1,1,1,1,1,1,1,1,1,1,1,1,1,1
1,1,1,1,1,1,1,1,1,1,1,1,1,1,1,1,1,1,1,1,1,1
1,1,1,1,1,1,1,1,1,1,1,1,1,1,1,1,1,1,1,1,1,1
endlayer

layer
1,1,1,1,1,1,1,1,1,1,1,1,1,1,1,1,1,1,1,1,1,1
1,1,1,1,1,1,1,1,1,1,1,1,1,1,1,1,1,1,1,1,1,1
1,1,1,1,1,1,1,1,1,1,1,1,1,1,1,1,1,1,1,1,1,1
1,1,1,1,1,1,1,1,1,1,1,1,1,1,1,1,1,1,1,1,1,1
1,1,1,1,1,1,1,1,1,1,1,1,1,1,1,1,1,1,1,1,1,1
1,1,1,1,1,1,1,1,1,1,1,1,1,1,1,1,1,1,1,1,1,1
1,1,1,1,1,1,1,1,1,1,1,1,1,1,1,1,1,1,1,1,1,1
1,1,1,1,1,1,1,1,1,1,1,1,1,1,1,1,1,1,1,1,1,1
1,1,1,1,1,1,1,1,1,1,1,1,1,1,1,1,1,1,1,1,1,1
1,1,1,1,1,1,1,1,1,0,0,0,0,0,1,1,1,1,1,1,1,1
1,1,1,1,1,1,1,1,0,0,0,0,0,0,0,1,1,1,1,1,1,1
1,1,1,1,1,1,1,1,0,0,2,3,2,0,0,1,1,1,1,1,1,1
1,1,1,1,1,1,1,0,0,0,2,2,2,2,0,1,1,1,1,1,1,1
1,1,1,1,1,1,1,0,0,2,2,2,2,0,0,1,1,1,1,1,1,1
1,1,1,1,1,1,1,0,0,0,0,0,0,0,0,1,1,1,1,1,1,1
1,1,1,1,1,1,1,1,1,0,0,0,0,0,1,1,1,1,1,1,1,1
1,1,1,1,1,1,1,1,1,1,1,1,1,1,1,1,1,1,1,1,1,1
1,1,1,1,1,1,1,1,1,1,1,1,1,1,1,1,1,1,1,1,1,1
1,1,1,1,1,1,1,1,1,1,1,1,1,1,1,1,1,1,1,1,1,1
1,1,1,1,1,1,1,1,1,1,1,1,1,1,1,1,1,1,1,1,1,1
1,1,1,1,1,1,1,1,1,1,1,1,1,1,1,1,1,1,1,1,1,1
1,1,1,1,1,1,1,1,1,1,1,1,1,1,1,1,1,1,1,1,1,1
1,1,1,1,1,1,1,1,1,1,1,1,1,1,1,1,1,1,1,1,1,1
1,1,1,1,1,1,1,1,1,1,1,1,1,1,1,1,1,1,1,1,1,1
endlayer

layer
1,1,1,1,1,1,1,1,1,1,1,1,1,1,1,1,1,1,1,1,1,1
1,1,1,1,1,1,1,1,1,1,1,1,1,1,1,1,1,1,1,1,1,1
1,1,1,1,1,1,1,1,1,1,1,1,1,1,1,1,1,1,1,1,1,1
1,1,1,1,1,1,1,1,1,1,1,1,1,1,1,1,1,1,1,1,1,1
1,1,1,1,1,1,1,1,1,1,1,1,1,1,1,1,1,1,1,1,1,1
1,1,1,1,1,1,1,1,1,1,1,1,1,1,1,1,1,1,1,1,1,1
1,1,1,1,1,1,1,1,1,1,0,0,0,0,1,1,1,1,1,1,1,1
1,1,1,1,1,1,1,1,1,0,0,0,0,0,0,1,1,1,1,1,1,1
1,1,1,1,1,1,1,1,0,0,0,0,0,0,0,1,1,1,1,1,1,1
1,1,1,1,1,1,1,0,0,0,0,0,0,0,0,0,1,1,1,1,1,1
1,1,1,1,1,1,0,0,0,0,0,0,0,0,0,0,0,1,1,1,1,1
1,1,1,1,1,1,0,0,0,0,2,3,2,0,0,0,0,1,1,1,1,1
1,1,1,1,1,1,0,0,0,0,2,2,2,2,0,0,0,1,1,1,1,1
1,1,1,1,1,1,0,0,0,4,2,2,2,0,0,0,0,1,1,1,1,1
1,1,1,1,1,1,0,0,0,0,0,0,0,0,0,0,0,1,1,1,1,1
1,1,1,1,1,1,0,0,0,0,0,0,0,0,0,0,0,1,1,1,1,1
1,1,1,1,1,1,1,1,0,0,0,0,0,0,0,1,1,1,1,1,1,1
1,1,1,1,1,1,1,1,0,0,0,0,0,0,1,1,1,1,1,1,1,1
1,1,1,1,1,1,1,1,1,1,1,1,1,1,1,1,1,1,1,1,1,1
1,1,1,1,1,1,1,1,1,1,1,1,1,1,1,1,1,1,1,1,1,1
1,1,1,1,1,1,1,1,1,1,1,1,1,1,1,1,1,1,1,1,1,1
1,1,1,1,1,1,1,1,1,1,1,1,1,1,1,1,1,1,1,1,1,1
1,1,1,1,1,1,1,1,1,1,1,1,1,1,1,1,1,1,1,1,1,1
1,1,1,1,1,1,1,1,1,1,1,1,1,1,1,1,1,1,1,1,1,1
endlayer

layer
1,1,1,1,1,1,1,1,1,1,1,1,1,1,1,1,1,1,1,1,1,1
1,1,1,1,1,1,1,1,1,1,1,1,1,1,1,1,1,1,1,1,1,1
1,1,1,1,1,1,1,1,1,1,1,1,1,1,1,1,1,1,1,1,1,1
1,1,1,1,1,1,1,1,1,1,1,1,1,1,1,1,1,1,1,1,1,1
1,1,1,1,1,1,1,1,1,0,0,0,0,0,0,1,1,1,1,1,1,1
1,1,1,1,1,1,1,0,0,0,0,0,0,0,0,1,1,1,1,1,1,1
1,1,1,1,1,1,0,0,0,0,0,0,0,0,0,0,1,1,1,1,1,1
1,1,1,1,1,1,0,0,0,0,0,0,0,0,0,0,1,1,1,1,1,1
1,1,1,1,0,0,0,0,0,0,0,0,0,0,0,0,1,1,1,1,1,1
1,1,1,0,0,0,0,0,0,0,0,0,0,0,0,0,0,1,1,1,1,1
1,1,1,0,0,0,0,0,0,0,0,0,0,0,0,0,0,0,1,1,1,1
1,1,1,0,0,0,0,0,0,0,2,3,2,0,0,0,0,0,1,1,1,1
1,1,1,0,0,0,0,0,0,0,2,2,2,4,0,0,0,0,1,1,1,1
1,1,1,0,0,0,0,0,0,0,2,2,2,0,0,0,0,0,1,1,1,1
1,1,1,0,0,0,0,0,0,2,0,0,0,0,0,0,0,0,1,1,1,1
1,1,1,1,0,0,0,0,0,0,0,0,0,0,0,0,0,0,1,1,1,1
1,1,1,1,0,0,0,0,0,0,0,0,0,0,0,0,0,0,1,1,1,1
1,1,1,1,1,1,0,0,0,0,0,0,0,0,0,0,0,1,1,1,1,1
1,1,1,1,1,1,1,0,0,0,0,0,0,0,0,1,1,1,1,1,1,1
1,1,1,1,1,1,1,1,0,0,0,0,0,0,0,1,1,1,1,1,1,1
1,1,1,1,1,1,1,1,1,1,1,1,1,1,1,1,1,1,1,1,1,1
1,1,1,1,1,1,1,1,1,1,1,1,1,1,1,1,1,1,1,1,1,1
1,1,1,1,1,1,1,1,1,1,1,1,1,1,1,1,1,1,1,1,1,1
1,1,1,1,1,1,1,1,1,1,1,1,1,1,1,1,1,1,1,1,1,1
endlayer

layer
1,1,1,1,1,1,1,1,1,1,1,1,1,1,1,1,1,1,1,1,1,1
1,1,1,1,1,1,1,1,1,1,1,1,1,1,1,1,1,1,1,1,1,1
1,1,1,1,1,1,1,1,0,0,0,0,0,0,1,1,1,1,1,1,1,1
1,1,1,1,1,1,1,0,0,0,0,0,0,0,0,0,1,1,1,1,1,1
1,1,1,1,1,1,0,0,0,0,0,0,0,0,0,0,1,1,1,1,1,1
1,1,1,1,1,0,0,0,0,0,0,0,0,0,0,0,0,1,1,1,1,1
1,1,1,1,1,0,0,0,0,0,0,0,0,0,0,0,0,0,1,1,1,1
1,1,1,1,0,0,0,0,0,0,0,0,0,0,0,0,0,0,0,1,1,1
1,1,1,0,0,0,0,0,0,0,0,0,0,0,0,0,0,0,0,1,1,1
1,1,1,0,0,0,0,0,0,0,0,0,0,0,0,0,0,0,0,1,1,1
1,1,1,0,0,0,0,0,0,0,0,0,2,0,0,0,0,0,0,1,1,1
1,1,1,0,0,0,0,0,0,0,2,3,2,0,0,0,0,0,0,0,1,1
1,1,1,0,0,0,0,0,0,2,2,2,2,0,0,0,0,0,0,0,0,1
1,1,1,0,0,0,0,0,0,0,2,2,2,0,0,0,0,0,0,0,0,1
1,1,1,0,0,0,0,0,0,2,0,0,0,0,0,0,0,0,0,0,0,1
1,1,1,0,0,0,0,0,2,2,0,0,0,0,0,0,0,0,0,0,1,1
1,1,1,1,0,0,0,2,2,0,0,0,0,0,0,0,0,0,0,1,1,1
1,1,1,1,0,0,0,0,0,0,0,0,0,0,0,0,0,0,0,1,1,1
1,1,1,1,0,0,0,0,0,0,0,0,0,0,0,0,0,0,1,1,1,1
1,1,1,1,1,1,0,0,0,0,0,0,0,0,0,0,0,0,1,1,1,1
1,1,1,1,1,1,0,0,0,0,0,0,0,0,0,0,0,1,1,1,1,1
1,1,1,1,1,1,1,0,0,0,0,0,0,0,0,0,1,1,1,1,1,1
1,1,1,1,1,1,1,1,1,1,1,1,1,1,1,1,1,1,1,1,1,1
1,1,1,1,1,1,1,1,1,1,1,1,1,1,1,1,1,1,1,1,1,1
endlayer

layer
1,1,1,1,1,1,1,1,1,1,1,0,0,0,1,1,1,1,1,1,1,1
1,1,1,1,1,1,1,0,0,0,0,0,0,0,0,0,1,1,1,1,1,1
1,1,1,1,1,1,0,0,0,0,0,0,0,0,0,0,0,0,1,1,1,1
1,1,1,1,1,0,0,0,0,0,0,0,0,0,0,0,0,0,1,1,1,1
1,1,1,1,0,0,0,0,0,0,0,0,0,0,0,0,0,0,0,1,1,1
1,1,1,0,0,0,0,0,0,0,0,0,0,0,0,0,0,0,0,0,1,1
1,1,0,0,0,0,0,0,0,0,0,0,0,0,0,0,0,0,0,0,1,1
1,1,0,0,0,0,0,0,0,0,0,0,0,0,0,0,0,0,0,0,1,1
1,0,0,0,0,0,0,0,0,0,0,0,0,0,0,0,0,0,0,0,1,1
1,0,0,0,0,0,0,0,0,0,0,0,0,0,0,5,5,0,0,0,1,1
1,0,0,0,0,0,0,0,0,0,0,0,4,2,2,5,5,0,0,0,0,1
1,5,5,5,0,0,0,0,0,0,2,3,2,2,0,0,0,0,0,0,0,1
1,5,5,5,0,0,0,0,2,2,2,2,2,0,0,0,0,0,0,0,0,0
1,5,5,5,0,0,0,0,0,0,2,2,2,0,0,0,0,0,0,0,0,0
1,0,0,0,0,0,0,0,0,0,2,0,0,0,0,0,0,0,0,0,0,0
1,1,0,0,0,0,0,0,0,5,0,0,0,0,0,0,0,0,0,0,0,0
1,1,0,0,0,0,0,5,5,5,5,0,0,0,0,0,0,0,0,0,0,1
1,1,0,0,0,0,0,2,5,5,5,0,0,0,0,0,0,0,0,0,0,1
1,1,1,0,0,0,0,0,5,5,5,5,0,0,0,0,0,0,0,0,0,1
1,1,1,0,0,0,0,0,0,5,5,5,0,0,0,0,0,0,0,0,1,1
1,1,1,1,0,0,0,0,0,5,5,5,0,0,0,0,0,0,0,1,1,1
1,1,1,1,0,0,0,0,0,0,0,0,0,0,0,0,0,0,1,1,1,1
1,1,1,1,1,0,0,0,0,0,0,0,0,0,0,0,0,1,1,1,1,1
1,1,1,1,1,1,1,1,1,0,0,0,0,1,1,1,1,1,1,1,1,1
endlayer

layer
1,1,1,1,1,0,0,0,0,0,0,0,0,0,0,0,0,0,1,1,1,1
1,1,1,1,0,0,0,0,0,0,0,0,0,0,0,0,0,0,0,1,1,1
1,1,1,0,0,0,0,0,0,0,0,0,0,0,0,0,0,0,0,0,1,1
1,1,0,0,0,0,0,0,0,0,0,0,0,0,0,0,0,0,0,0,1,1
1,1,0,0,0,0,0,0,0,0,5,0,0,0,0,0,0,0,0,0,0,1
1,0,0,0,0,0,0,0,0,5,5,5,0,0,0,5,5,0,0,0,0,1
1,0,0,0,0,0,0,0,0,5,5,5,0,0,5,5,5,5,0,0,0,1
1,0,0,0,0,0,0,0,0,0,5,0,0,0,0,5,5,0,0,0,0,1
0,0,0,0,0,0,0,0,0,0,2,0,0,0,0,5,5,0,0,0,0,1
0,0,0,0,0,0,0,0,0,0,2,0,0,0,2,2,5,5,0,0,0,1
0,5,5,5,0,0,0,0,0,0,2,0,0,0,2,5,5,5,0,0,0,0
5,5,5,5,5,0,0,0,0,0,2,3,2,2,0,5,5,0,0,0,0,0
5,5,2,2,5,0,0,2,0,4,2,2,2,2,0,0,0,0,0,0,0,0
5,5,5,5,5,0,0,0,0,2,2,2,2,2,0,0,0,0,0,0,0,0
0,5,5,5,0,0,0,0,0,0,2,0,2,0,0,0,0,0,0,0,0,0
1,0,0,0,0,0,0,5,5,5,2,0,2,0,0,0,0,0,0,0,0,0
1,0,0,0,0,0,0,5,5,5,2,0,0,2,5,0,0,0,0,0,0,0
1,0,0,0,0,5,5,5,5,2,2,0,5,5,5,0,0,0,0,0,0,0
1,0,0,0,0,5,2,2,5,5,5,5,5,5,0,0,0,0,0,0,0,0
1,1,0,0,0,5,5,0,5,5,5,5,5,0,0,0,0,0,0,0,0,1
1,1,0,0,0,5,5,0,5,5,5,5,5,0,0,0,0,0,0,0,0,1
1,1,1,0,0,0,0,0,0,5,5,5,0,0,0,0,0,0,0,0,1,1
1,1,1,0,0,0,0,0,0,0,0,0,0,0,0,0,0,0,0,1,1,1
1,1,1,1,0,0,0,0,0,0,0,0,0,0,0,0,0,0,1,1,1,1
endlayer

layer
1,1,1,1,0,0,0,0,0,0,0,0,0,0,0,0,0,0,0,1,1,1
1,1,1,0,0,0,0,0,0,0,0,0,0,0,0,0,0,0,0,0,1,1
1,1,0,0,0,0,0,0,0,0,0,0,0,0,0,0,0,0,0,0,1,1
1,0,0,0,0,0,0,0,0,0,5,0,0,0,0,0,0,0,0,0,0,1
1,0,0,0,0,0,0,0,0,5,5,5,0,0,0,5,5,0,0,0,0,0
0,0,0,0,0,0,0,0,0,5,2,5,5,0,5,5,5,5,0,0,0,0
0,0,0,0,0,0,0,0,0,5,2,5,5,5,5,5,5,5,5,0,0,0
0,0,0,0,0,0,0,0,0,5,2,5,0,0,5,5,2,5,0,0,0,0
0,0,0,0,0,0,0,0,0,0,2,0,0,6,6,2,6,6,0,0,0,0
0,0,0,6,6,6,6,6,6,0,0,0,0,6,6,6,6,6,0,0,0,0
0,5,5,5,6,6,6,6,6,2,0,0,0,6,6,6,6,6,0,0,0,0
5,5,5,5,2,2,6,6,6,0,2,3,2,6,6,6,6,6,0,0,0,0
5,5,2,5,5,6,2,6,6,0,2,2,2,2,6,6,6,6,0,0,0,0
5,5,5,5,5,2,6,6,6,2,2,2,2,2,0,0,0,5,5,5,0,0
0,5,5,5,2,6,6,6,6,0,0,0,2,2,0,0,5,5,5,5,5,0
0,0,0,6,6,6,6,6,6,5,0,0,0,0,5,0,5,5,5,5,5,5
0,0,0,0,0,5,5,5,5,5,0,0,5,5,5,5,5,5,5,5,5,0
0,0,0,0,5,5,5,0,5,5,0,0,5,2,5,5,5,5,5,5,0,0
0,0,0,0,5,5,2,5,5,5,2,5,5,5,5,5,5,5,0,0,0,0
1,0,0,0,5,2,2,5,5,5,2,5,5,5,5,5,5,0,0,0,0,0
1,0,0,0,5,2,5,5,5,5,2,5,5,0,0,0,0,0,0,0,0,0
1,0,0,0,0,5,5,0,0,5,5,5,0,0,0,0,0,0,0,0,0,1
1,1,0,0,0,0,0,0,0,0,0,0,0,0,0,0,0,0,0,0,1,1
1,1,1,0,0,0,0,0,0,0,0,0,0,0,0,0,0,0,0,1,1,1
endlayer

layer
1,1,1,0,0,0,0,0,0,0,0,0,0,0,0,0,0,0,0,0,1,1
1,1,0,0,0,0,0,0,0,0,0,0,0,0,0,0,0,0,0,0,0,1
1,0,0,0,0,0,0,0,0,0,0,0,0,0,0,0,0,0,0,0,0,1
0,0,0,0,0,0,0,0,0,0,0,0,0,0,0,0,0,0,0,0,0,0
0,0,0,0,0,0,0,0,0,0,5,0,0,0,0,0,0,0,0,0,0,0
0,0,0,0,0,0,0,0,5,5,5,5,7,7,7,7,7,7,0,0,0,0
0,0,0,0,0,0,0,0,5,5,5,5,7,7,7,7,7,7,0,0,0,0
0,0,7,7,7,7,7,7,7,7,7,7,7,7,7,7,2,7,7,0,0,0
7,7,7,7,7,7,7,7,7,7,7,7,7,8,8,8,8,8,7,7,7,0
7,7,7,8,8,8,8,8,8,7,7,7,7,8,8,8,8,8,7,7,7,0
7,7,7,7,7,7,7,7,7,2,7,7,7,8,8,8,8,8,7,7,7,0
7,7,7,8,8,8,8,8,8,7,2,3,2,8,8,8,8,8,7,7,7,0
7,7,9,7,7,7,7,7,7,7,2,2,2,9,8,8,8,8,7,7,7,0
7,7,7,8,8,8,8,8,8,9,2,2,2,2,7,7,7,7,7,7,7,0
7,7,7,7,7,7,7,7,7,7,7,7,2,2,2,5,5,5,5,7,7,5
7,7,7,8,8,8,8,8,8,7,7,7,5,2,2,2,2,2,2,2,5,5
7,7,7,7,7,7,7,7,7,7,7,7,5,5,2,6,5,5,5,5,5,5
0,0,7,7,7,7,7,7,7,7,7,7,5,2,2,2,5,5,5,5,5,0
0,0,0,0,5,7,7,7,7,7,7,7,5,5,2,5,2,5,0,0,0,0
0,0,0,0,5,7,7,7,7,7,7,7,5,5,5,5,5,5,0,0,0,0
0,0,0,0,5,7,7,7,7,7,7,7,5,5,5,5,5,6,0,0,0,0
0,0,0,0,0,5,5,0,0,7,7,7,0,0,0,0,0,0,0,0,0,0
1,0,0,0,0,0,0,0,0,0,0,0,0,0,0,0,0,0,0,0,0,1
1,1,0,0,0,0,0,0,0,0,0,0,0,0,0,0,0,0,0,0,1,1
endlayer

layer
1,1,0,0,0,0,0,0,0,7,7,7,0,0,0,0,0,0,0,0,0,1
1,0,0,0,0,0,0,0,0,7,7,7,0,0,0,0,0,0,0,0,0,0
0,0,0,0,0,0,0,0,0,7,7,7,0,0,0,0,0,0,0,0,0,0
0,0,0,0,0,0,0,0,0,7,7,7,0,0,0,0,0,0,0,0,0,0
0,0,0,0,0,0,0,5,5,7,4,7,0,0,0,0,0,0,5,5,0,0
0,0,0,0,0,0,0,5,5,7,7,7,10,10,10,10,10,2,5,5,5,0
0,0,0,0,0,0,0,5,5,7,7,7,11,0,0,0,0,2,5,5,5,0
0,0,7,10,10,10,4,10,10,7,13,13,7,7,12,12,2,4,7,5,0,0
10,4,7,15,15,15,15,15,15,10,0,0,4,14,14,14,14,14,10,10,10,0
10,0,17,16,16,16,16,16,16,10,0,0,7,14,14,14,14,14,4,13,10,0
10,0,17,0,15,15,15,15,0,18,0,0,0,14,14,14,14,14,17,0,10,0
10,19,7,16,16,16,16,16,16,10,2,3,0,14,14,14,14,14,17,0,10,0
10,0,4,0,15,15,15,15,0,10,2,2,2,4,14,14,14,14,4,0,10,0
10,19,7,16,16,16,16,16,16,4,2,2,2,7,7,4,7,7,7,0,10,0
10,0,17,0,15,15,15,15,0,2,0,0,7,8,8,8,8,8,7,20,7,0
10,0,17,16,16,16,16,16,16,21,0,20,7,8,8,8,8,8,7,7,7,5
10,4,7,15,15,15,15,15,15,10,0,22,7,8,8,8,8,8,7,7,7,0
0,0,7,10,10,10,4,10,10,7,0,22,7,9,8,8,8,8,7,7,7,0
0,0,0,0,5,10,0,0,0,23,0,22,7,8,8,8,8,8,7,7,7,0
0,0,0,0,5,10,24,0,0,23,0,13,7,8,8,8,8,8,7,7,7,0
0,0,0,0,5,10,10,10,10,7,0,0,7,8,8,8,8,8,7,7,7,0
0,0,0,0,0,5,5,0,0,10,10,10,7,7,7,7,7,7,7,7,7,0
0,0,0,0,0,0,0,0,0,0,0,0,0,7,7,7,7,7,7,7,7,0
1,0,0,0,0,0,0,0,0,0,0,0,0,7,7,7,7,7,7,7,7,0
endlayer

layer
1,0,0,0,0,0,0,0,0,10,10,10,0,0,0,0,0,0,0,0,0,0
0,0,0,0,0,0,0,0,0,10,0,10,0,0,0,0,0,0,0,0,0,0
0,0,0,0,0,0,0,0,0,7,25,7,0,0,0,0,0,0,0,0,0,0
0,0,0,0,0,0,0,0,5,10,0,10,0,0,0,0,0,0,0,0,0,0
0,0,0,0,0,0,0,5,5,10,0,10,0,0,0,0,0,5,5,5,5,0
0,0,0,0,0,0,5,5,2,7,0,7,4,0,0,0,0,4,5,5,5,0
0,0,0,0,0,0,5,5,2,10,0,0,0,0,0,0,0,2,2,5,5,0
0,0,7,0,0,0,0,5,2,7,0,0,7,7,27,26,7,10,7,5,5,0
10,10,7,0,0,0,0,0,2,10,0,0,10,0,0,0,0,0,10,10,10,0
0,0,27,0,0,0,0,0,0,0,0,0,7,0,0,0,0,0,7,28,10,0
0,0,26,0,0,0,0,0,0,0,0,0,0,0,0,0,0,0,27,0,10,0
0,19,7,0,0,0,0,0,0,0,2,3,0,0,0,0,0,0,26,0,0,0
0,0,10,0,0,0,0,0,0,0,2,2,10,10,0,0,0,0,7,0,0,0
0,19,7,0,0,0,0,0,0,0,0,0,2,2,10,10,10,10,7,0,10,0
0,0,27,0,0,0,0,0,0,2,0,0,10,29,29,29,29,29,10,0,10,0
0,0,26,0,0,0,0,0,0,0,0,0,7,29,29,29,29,29,4,0,10,0
10,10,7,0,0,0,0,0,0,0,0,0,17,29,29,29,29,29,17,0,10,0
0,0,7,10,10,10,10,10,10,7,0,19,7,4,29,29,29,29,7,0,10,0
0,0,0,0,0,10,0,0,0,26,0,0,17,29,29,29,29,29,17,0,10,0
0,0,0,0,0,10,0,0,0,27,0,0,7,29,29,29,29,29,4,0,10,0
0,0,0,0,0,10,10,10,10,7,0,0,10,29,29,29,29,29,10,0,10,0
0,0,0,0,0,0,0,0,0,0,0,0,7,4,25,7,25,4,7,0,10,0
0,0,0,0,0,0,0,0,0,0,0,0,0,10,0,30,0,0,0,0,10,0
0,0,0,0,0,0,0,0,0,0,0,0,0,10,10,10,10,10,10,10,10,0
endlayer

layer
0,0,0,0,0,0,0,0,0,0,0,0,0,0,0,0,0,0,0,0,0,0
0,0,0,0,0,0,0,0,0,0,0,0,0,0,0,0,0,0,0,0,0,0
0,0,0,0,0,0,0,0,0,7,27,7,0,0,0,0,0,0,0,0,0,0
0,0,0,0,0,0,0,0,0,10,0,10,0,0,0,0,0,0,0,0,0,0
0,0,0,0,0,0,0,0,5,10,0,10,0,0,0,0,0,0,5,5,0,0
0,0,0,0,0,0,0,5,5,7,0,7,10,0,0,0,0,5,5,5,5,0
0,0,10,10,10,10,10,5,5,10,0,0,0,0,0,0,0,5,5,5,5,0
0,10,7,7,7,7,7,7,5,7,0,0,7,7,10,10,7,10,7,5,0,0
0,10,7,7,10,10,10,2,10,7,0,0,10,0,0,0,0,0,10,0,0,0
0,10,7,7,2,10,10,2,10,7,0,0,7,0,0,0,0,0,7,28,0,0
0,10,7,7,10,2,2,2,10,7,0,0,0,0,0,0,0,0,10,0,0,0
0,19,7,7,10,10,10,10,7,7,2,3,0,0,0,0,0,0,10,0,0,0
0,10,7,7,10,10,10,10,10,7,2,2,10,2,0,0,0,0,7,0,0,0
0,19,7,7,10,10,10,10,10,7,5,5,2,2,10,10,10,10,7,0,0,0
0,10,7,7,10,10,10,10,4,2,0,0,10,0,0,0,0,0,10,0,0,0
0,10,7,7,10,10,10,2,2,7,0,0,7,0,0,0,0,0,7,0,0,0
0,10,7,7,10,10,10,7,7,7,0,0,27,0,0,0,0,0,27,0,0,0
0,10,7,7,7,7,7,7,7,7,0,19,7,10,0,0,0,0,7,0,0,0
0,0,10,10,10,7,7,7,7,7,0,0,27,0,0,0,0,0,27,0,0,0
0,0,0,0,10,7,7,7,7,7,0,0,7,0,0,0,0,0,7,0,0,0
0,0,0,0,10,7,7,7,7,7,0,0,10,0,0,0,0,0,10,0,0,0
0,0,0,0,0,10,10,10,10,10,0,0,7,10,27,7,27,10,7,0,0,0
0,0,0,0,0,0,0,0,0,0,0,0,0,0,0,30,0,0,0,0,0,0
0,0,0,0,0,0,0,0,0,0,0,0,0,0,0,0,0,0,0,0,4,0
endlayer

layer
0,0,0,0,0,0,0,0,0,0,0,0,0,0,0,0,0,0,0,0,0,0
0,0,0,0,0,0,0,0,0,10,10,10,0,0,0,0,0,0,0,0,0,0
0,0,0,0,0,0,0,0,10,7,7,7,10,0,0,0,0,0,0,0,0,0
0,0,0,0,0,0,0,0,10,7,7,7,10,0,0,0,0,0,0,0,0,0
0,0,0,0,0,0,0,0,10,7,7,7,10,0,0,0,0,0,0,0,0,0
0,0,0,0,0,0,7,7,7,7,7,7,10,0,0,0,0,0,0,0,0,0
0,0,5,5,5,0,2,7,7,7,4,7,10,10,10,10,10,10,10,10,0,0
0,0,5,5,5,10,2,7,7,7,7,7,7,7,7,7,7,7,7,10,0,0
0,0,5,5,5,0,0,2,0,7,7,10,7,6,6,6,6,6,7,10,0,0
0,0,10,0,2,0,0,0,0,7,7,10,7,6,6,6,6,6,7,28,0,0
0,10,10,0,0,0,0,0,0,7,7,7,7,6,6,6,6,6,7,10,0,0
0,0,0,0,0,0,0,0,7,7,2,3,7,6,6,6,6,6,7,10,0,0
0,10,4,0,0,0,0,0,0,7,2,2,7,2,6,6,6,6,7,10,0,0
0,0,0,0,0,0,0,0,0,7,5,5,0,2,7,7,7,7,7,10,0,0
0,10,10,0,0,0,0,0,0,22,5,5,10,0,0,0,0,0,10,0,0,0
0,0,10,0,0,0,0,2,25,7,0,0,7,0,0,0,0,0,7,0,0,0
0,0,10,0,0,0,2,28,0,10,0,0,10,0,0,0,0,0,10,0,0,0
0,0,10,10,10,10,4,0,0,10,0,19,7,0,0,0,0,0,7,0,0,0
0,0,0,0,0,10,0,0,0,10,0,0,10,0,0,0,0,0,10,0,0,0
0,0,0,0,5,10,0,0,0,10,0,0,7,0,0,0,0,0,7,0,0,0
0,0,0,0,5,10,10,10,10,7,0,0,10,0,0,0,0,0,10,0,0,0
0,0,0,0,0,5,5,0,0,0,0,0,7,10,10,7,10,10,7,0,0,0
0,0,0,0,0,0,0,0,0,0,0,0,0,0,0,30,0,0,0,0,0,0
0,0,0,0,0,0,0,0,0,0,0,0,0,0,0,0,0,0,0,0,0,0
endlayer

layer
0,0,0,0,0,0,0,0,0,0,0,0,0,0,0,0,0,0,0,0,0,0
0,0,0,0,0,0,0,0,0,0,0,0,0,0,0,0,0,0,0,0,0,0
0,0,0,0,0,0,0,0,0,10,10,10,0,0,0,0,0,0,0,0,0,0
0,0,0,0,0,0,0,0,0,10,0,10,0,0,0,0,0,0,0,0,0,0
0,0,0,0,0,0,0,0,0,7,25,7,0,0,0,0,0,0,0,0,0,0
0,0,5,5,5,0,10,10,10,7,0,10,0,0,0,0,0,0,0,0,0,0
0,5,5,5,5,5,10,0,0,17,0,10,0,0,0,0,0,0,0,0,0,0
0,5,5,2,5,5,10,0,19,7,0,7,7,7,7,7,7,7,7,0,0,0
0,5,5,5,2,5,0,0,0,17,0,40,7,8,8,8,8,8,7,10,0,0
0,0,2,2,2,0,0,0,0,17,0,0,7,8,8,8,8,8,7,28,0,0
0,0,0,0,0,0,0,0,0,7,7,0,7,8,8,8,8,8,7,10,0,0
0,0,0,0,0,0,0,0,0,31,2,3,7,8,8,8,8,8,7,0,0,0
0,0,0,0,0,0,0,0,0,0,2,2,7,9,8,8,8,8,7,0,0,0
0,0,0,0,0,0,0,0,0,0,7,7,7,2,2,7,7,7,7,0,0,0
0,0,0,5,5,0,0,0,0,0,22,7,7,10,10,10,10,10,7,10,0,0
0,0,5,5,5,5,0,7,27,7,7,7,7,10,10,10,10,10,7,10,0,0
0,5,5,2,2,2,2,28,0,10,0,0,7,10,10,10,10,7,7,10,0,0
0,0,5,5,5,0,2,0,0,10,0,19,7,10,10,10,10,7,7,10,0,0
0,0,0,5,5,5,2,0,0,10,0,0,7,10,10,10,10,7,7,10,0,0
0,0,0,0,5,2,5,0,0,10,0,0,7,10,10,10,10,10,7,10,0,0
0,0,0,0,5,2,5,5,10,7,0,0,7,10,7,7,7,10,7,10,0,0
0,0,0,0,5,5,5,5,0,0,0,0,7,7,7,7,7,7,7,10,0,0
0,0,0,0,0,0,0,0,0,0,0,0,10,10,10,30,10,10,10,0,0,0
0,0,0,0,0,0,0,0,0,0,0,0,0,0,0,0,0,0,0,0,0,0
endlayer

layer
0,0,0,0,0,0,0,0,0,0,0,0,0,0,0,0,0,0,0,0,0,0
0,0,0,0,0,0,0,0,0,0,0,0,0,0,0,0,0,0,0,0,0,0
0,0,0,0,0,0,0,0,0,0,0,0,0,0,0,0,0,0,0,0,0,0
0,0,0,0,0,0,0,0,0,0,0,0,0,0,0,0,0,0,0,0,0,0
0,0,0,0,0,0,0,0,0,7,27,7,0,0,0,0,0,0,0,0,0,0
0,0,5,5,5,0,0,0,0,7,0,0,0,0,0,0,0,0,0,0,0,0
0,5,5,5,5,5,0,0,0,27,0,0,0,0,0,0,0,0,0,0,0,0
0,5,5,2,5,5,0,0,19,7,0,7,7,10,10,10,10,10,10,0,0,0
0,5,5,5,5,5,0,0,0,27,0,0,23,32,32,32,32,32,7,10,0,0
0,0,5,5,5,0,0,0,0,26,0,0,23,32,32,32,32,32,23,0,0,0
0,0,0,0,0,0,0,0,0,7,0,0,7,32,32,32,32,32,7,10,0,0
0,0,0,0,0,0,0,0,0,0,17,3,23,32,32,32,32,32,10,0,0,0
0,0,0,0,0,0,0,0,0,0,2,7,7,4,32,32,32,32,10,0,0,0
0,0,0,0,0,0,0,0,0,0,10,0,22,10,2,10,10,0,10,0,0,0
0,0,0,0,0,0,0,0,0,0,0,0,0,10,2,0,0,0,10,0,0,0
0,0,0,5,5,0,0,7,4,7,10,10,10,0,2,0,0,0,10,0,0,0
0,0,5,5,5,5,2,28,0,10,0,0,10,0,10,2,5,5,10,0,0,0
0,0,0,5,5,0,0,0,0,10,0,0,0,0,0,5,5,5,10,0,0,0
0,0,0,0,0,5,5,0,0,10,0,0,10,0,10,5,5,5,10,0,0,0
0,0,0,0,5,5,5,5,0,10,0,0,10,0,0,7,0,0,10,0,0,0
0,0,0,0,5,5,5,5,10,7,0,0,10,0,7,10,7,0,10,0,0,0
0,0,0,0,0,5,5,0,0,0,0,0,7,7,7,7,7,7,7,0,0,0
0,0,0,0,0,0,0,0,0,0,0,0,0,0,10,30,10,0,0,0,0,0
0,0,0,0,0,0,0,0,0,0,0,0,0,0,0,0,0,0,0,0,0,0
endlayer

layer
0,0,0,0,0,0,0,0,0,0,0,0,0,0,0,0,0,0,0,0,0,0
0,0,0,0,0,0,0,0,0,0,0,0,0,0,0,0,0,0,0,0,0,0
0,0,0,0,0,0,0,0,0,0,0,0,0,0,0,0,0,0,0,0,0,0
0,0,0,0,0,0,0,0,0,10,10,10,0,0,0,0,0,0,0,0,0,0
0,0,0,0,0,0,0,0,10,7,7,7,10,0,0,0,0,0,0,0,0,0
0,0,5,5,5,0,0,0,10,7,4,7,10,0,0,0,0,0,0,0,0,0
0,5,5,5,5,5,0,0,10,7,7,7,10,0,0,0,0,0,0,0,0,0
0,5,5,5,5,5,0,0,19,7,7,7,4,0,0,0,0,0,4,0,0,0
0,5,5,5,5,5,0,0,10,7,0,0,26,0,0,0,0,0,7,0,0,0
0,0,5,5,5,0,0,0,10,7,0,0,27,0,0,0,0,0,27,0,0,0
0,0,0,0,0,0,0,0,10,7,7,0,7,0,0,0,0,0,7,0,0,0
0,0,0,0,0,0,0,0,0,0,26,3,27,0,0,0,0,0,10,0,0,0
0,0,0,0,0,0,0,0,0,0,2,7,7,10,0,0,0,0,10,5,5,0
0,0,0,0,0,0,0,0,0,2,0,0,0,22,2,2,0,0,4,5,5,0
0,0,0,0,0,0,0,0,0,0,0,0,0,10,10,0,0,0,5,5,5,0
0,0,0,10,7,7,7,7,7,7,0,0,0,0,0,0,0,0,5,0,0,0
0,0,0,10,7,33,2,28,7,7,0,0,0,0,10,2,5,10,5,0,0,0
0,0,0,10,7,7,7,7,7,7,0,0,0,0,0,2,2,2,5,5,0,0
0,0,0,0,10,10,7,7,7,7,0,0,0,0,10,2,5,10,5,0,0,0
0,0,0,0,0,10,7,33,33,7,0,0,0,0,0,4,5,5,10,0,0,0
0,0,0,0,0,10,7,7,7,7,10,10,10,0,0,0,0,0,10,0,0,0
0,0,0,0,0,0,10,10,10,10,0,0,10,10,10,0,10,10,10,0,0,0
0,0,0,0,0,0,0,0,0,0,0,0,0,0,10,0,10,0,0,0,0,0
0,0,0,0,0,0,0,0,0,0,0,0,0,0,0,0,0,0,0,0,0,0
endlayer

layer
0,0,0,0,0,0,0,0,0,0,0,0,0,0,0,0,0,0,0,0,0,0
0,0,0,0,0,0,0,0,0,0,0,0,0,0,0,0,0,0,0,0,0,0
0,0,0,0,0,0,0,0,0,0,0,0,0,0,0,0,0,0,0,0,0,0
0,0,0,0,0,0,0,0,0,0,0,0,0,0,0,0,0,0,0,0,0,0
0,0,0,0,0,0,0,0,0,10,10,10,0,0,0,0,0,0,0,0,0,0
0,0,0,0,0,0,0,0,0,10,0,10,0,0,0,0,0,0,0,0,0,0
0,0,5,5,5,0,0,0,0,7,34,7,7,0,0,0,0,0,0,0,0,0
0,0,5,5,5,0,0,0,0,17,0,0,7,0,0,0,0,0,0,0,0,0
0,0,5,5,5,0,0,0,0,7,20,20,7,0,0,0,0,0,7,0,0,0
0,0,0,0,0,0,0,0,0,7,7,7,7,0,0,0,0,0,10,0,0,0
0,0,0,0,0,0,0,0,10,7,7,7,7,0,0,0,0,0,7,0,0,0
0,0,0,0,0,0,0,0,10,7,7,3,7,0,0,0,0,0,10,5,5,0
0,0,5,5,5,5,0,0,10,7,7,7,7,10,10,10,0,0,10,5,5,5
0,0,5,5,5,5,0,0,0,2,0,0,0,0,22,2,0,0,10,5,5,5
0,0,5,5,5,5,0,0,0,0,0,0,0,10,10,10,0,0,5,5,5,5
0,0,0,0,10,10,10,10,10,10,0,0,0,0,0,0,0,0,5,5,5,0
0,0,0,0,10,35,0,0,0,10,0,0,0,0,10,0,5,10,5,0,0,0
0,0,0,0,10,10,10,0,0,10,0,0,0,0,0,37,36,5,5,5,0,0
0,0,0,0,0,0,10,0,0,10,0,0,0,0,10,0,0,10,5,0,0,0
0,0,0,0,0,0,10,35,35,10,0,0,0,0,0,0,5,5,0,0,0,0
0,0,0,0,0,0,10,10,10,10,0,0,0,0,0,0,0,0,0,0,0,0
0,0,0,0,0,0,0,0,0,0,0,0,0,0,0,0,0,0,0,0,0,0
0,0,0,0,0,0,0,0,0,0,0,0,0,0,0,0,0,0,0,0,0,0
0,0,0,0,0,0,0,0,0,0,0,0,0,0,0,0,0,0,0,0,0,0
endlayer

layer
0,0,0,0,0,0,0,0,0,0,0,0,0,0,0,0,0,0,0,0,0,0
0,0,0,0,0,0,0,0,0,0,0,0,0,0,0,0,0,0,0,0,0,0
0,0,0,0,0,0,0,0,0,0,0,0,0,0,0,0,0,0,0,0,0,0
0,0,0,0,0,0,0,0,0,0,0,0,0,0,0,0,0,0,0,0,0,0
0,0,0,0,0,0,0,0,0,0,0,0,0,0,0,0,0,0,0,0,0,0
0,0,0,0,0,0,0,0,0,0,0,0,0,0,0,0,0,0,0,0,0,0
0,0,0,0,0,0,0,0,0,7,27,7,7,0,0,0,0,0,0,0,0,0
0,0,0,0,0,0,0,0,0,27,0,40,7,0,0,0,0,0,0,0,0,0
0,0,0,0,0,0,0,0,0,7,0,0,10,0,0,0,10,10,7,10,0,0
0,0,0,0,0,0,0,0,0,10,0,0,10,0,0,0,10,7,7,10,0,0
0,0,0,0,0,0,0,0,0,10,38,0,10,0,0,0,7,2,7,7,0,0
0,0,5,5,5,5,0,0,0,10,39,0,10,0,0,0,7,2,7,7,5,0
0,5,5,5,5,5,5,0,0,7,10,10,7,10,10,10,7,2,7,7,5,5
0,5,5,5,5,5,5,2,2,2,0,0,0,0,0,22,2,2,2,2,5,5
0,5,5,5,5,5,5,0,0,2,0,0,0,0,10,10,7,7,7,7,5,5
0,0,5,5,5,5,0,0,0,2,0,0,0,0,0,0,0,0,0,5,5,0
0,0,0,0,0,0,0,0,0,5,0,0,0,0,10,0,5,10,0,0,0,0
0,0,0,0,0,0,4,0,0,5,0,0,0,0,0,0,0,5,5,0,0,0
0,0,0,0,0,0,0,0,0,5,0,0,0,0,10,0,0,10,5,0,0,0
0,0,0,0,0,0,0,0,0,0,0,0,0,0,0,0,5,0,0,0,0,0
0,0,0,0,0,0,0,0,0,0,0,0,0,0,0,0,0,0,0,0,0,0
0,0,0,0,0,0,0,0,0,0,0,0,0,0,0,0,0,0,0,0,0,0
0,0,0,0,0,0,0,0,0,0,0,0,0,0,0,0,0,0,0,0,0,0
0,0,0,0,0,0,0,0,0,0,0,0,0,0,0,0,0,0,0,0,0,0
endlayer

layer
0,0,0,0,0,0,0,0,0,0,0,0,0,0,0,0,0,0,0,0,0,0
0,0,0,0,0,0,0,0,0,0,0,0,0,0,0,0,0,0,0,0,0,0
0,0,0,0,0,0,0,0,0,0,0,0,0,0,0,0,0,0,0,0,0,0
0,0,0,0,0,0,0,0,0,0,0,0,0,0,0,0,0,0,0,0,0,0
0,0,0,0,0,0,0,0,0,0,0,0,0,0,0,0,0,0,0,0,0,0
0,0,0,0,0,0,0,0,0,10,10,10,10,0,0,0,0,0,0,0,0,0
0,0,0,0,0,0,0,0,0,7,7,7,7,0,0,0,0,0,0,0,0,0
0,0,0,0,0,0,0,0,0,4,0,0,7,0,0,0,0,0,0,0,0,0
0,0,0,0,0,0,0,0,0,7,0,0,10,0,0,0,10,10,10,10,0,0
0,0,0,0,0,0,0,0,0,10,0,0,10,0,0,0,10,0,0,10,0,0
0,0,0,0,0,0,0,0,0,10,0,0,10,0,0,0,7,25,25,7,0,0
0,0,5,5,5,5,0,0,0,10,0,0,10,0,0,0,10,0,0,10,5,0
0,5,5,5,2,5,5,0,0,7,10,10,7,0,10,10,7,0,0,4,5,5
0,5,5,2,2,2,2,0,0,2,0,0,0,0,0,0,17,0,0,10,5,5
0,5,5,5,5,5,5,0,0,0,0,0,0,0,0,10,7,10,10,7,5,5
0,0,5,5,5,5,0,0,0,0,0,0,0,0,0,0,0,0,0,5,5,0
0,0,0,0,0,0,0,0,5,2,5,0,0,0,10,10,10,10,0,0,0,0
0,0,0,0,0,0,0,0,5,2,5,0,0,0,10,0,0,10,0,0,0,0
0,0,0,0,0,0,0,0,5,5,5,0,0,0,10,10,10,10,0,0,0,0
0,0,0,0,0,0,0,0,0,5,0,0,0,0,0,0,0,0,0,0,0,0
0,0,0,0,0,0,0,0,0,0,0,0,0,0,0,0,0,0,0,0,0,0
0,0,0,0,0,0,0,0,0,0,0,0,0,0,0,0,0,0,0,0,0,0
0,0,0,0,0,0,0,0,0,0,0,0,0,0,0,0,0,0,0,0,0,0
0,0,0,0,0,0,0,0,0,0,0,0,0,0,0,0,0,0,0,0,0,0
endlayer

layer
0,0,0,0,0,0,0,0,0,0,0,0,0,0,0,0,0,0,0,0,0,0
0,0,0,0,0,0,0,0,0,0,0,0,0,0,0,0,0,0,0,0,0,0
0,0,0,0,0,0,0,0,0,0,0,0,0,0,0,0,0,0,0,0,0,0
0,0,0,0,0,0,0,0,0,0,0,0,0,0,0,0,0,0,0,0,0,0
0,0,0,0,0,0,0,0,0,0,0,0,0,0,0,0,0,0,0,0,0,0
0,0,0,0,0,0,0,0,0,0,0,0,0,0,0,0,0,0,0,0,0,0
0,0,0,0,0,0,0,0,10,7,10,10,7,10,0,0,0,0,0,0,0,0
0,0,0,0,0,0,0,0,10,7,0,0,7,10,0,0,0,0,0,0,0,0
0,0,0,0,0,0,0,0,10,7,0,0,7,10,0,0,0,0,0,0,0,0
0,0,0,0,0,0,0,0,10,7,0,0,7,10,0,0,0,0,0,0,0,0
0,0,0,0,0,0,0,0,10,7,0,0,7,10,0,0,7,26,27,7,0,0
0,0,5,5,5,5,0,0,10,7,0,0,7,10,0,0,10,0,0,10,0,0
0,5,5,5,5,5,5,0,5,7,7,7,7,10,0,0,7,0,0,10,0,0
0,5,5,5,5,5,5,0,5,2,5,0,0,0,0,0,27,0,0,10,0,0
0,5,5,5,5,5,5,0,5,5,5,0,0,0,0,0,7,10,10,7,0,0
0,0,5,5,5,5,0,0,0,0,0,0,0,0,0,0,0,0,0,0,0,0
0,0,0,0,0,0,0,0,0,5,0,0,0,0,31,31,31,31,0,0,0,0
0,0,0,0,0,0,0,0,0,5,0,0,0,0,31,7,7,31,0,0,0,0
0,0,0,0,0,0,0,0,0,5,0,0,0,0,31,31,31,31,0,0,0,0
0,0,0,0,0,0,0,0,0,0,0,0,0,0,0,0,0,0,0,0,0,0
0,0,0,0,0,0,0,0,0,0,0,0,0,0,0,0,0,0,0,0,0,0
0,0,0,0,0,0,0,0,0,0,0,0,0,0,0,0,0,0,0,0,0,0
0,0,0,0,0,0,0,0,0,0,0,0,0,0,0,0,0,0,0,0,0,0
0,0,0,0,0,0,0,0,0,0,0,0,0,0,0,0,0,0,0,0,0,0
endlayer

layer
0,0,0,0,0,0,0,0,0,0,0,0,0,0,0,0,0,0,0,0,0,0
0,0,0,0,0,0,0,0,0,0,0,0,0,0,0,0,0,0,0,0,0,0
0,0,0,0,0,0,0,0,0,0,0,0,0,0,0,0,0,0,0,0,0,0
0,0,0,0,0,0,0,0,0,0,0,0,0,0,0,0,0,0,0,0,0,0
0,0,0,0,0,0,0,0,0,0,0,0,0,0,0,0,0,0,0,0,0,0
0,0,0,0,0,0,0,0,0,0,0,0,0,0,0,0,0,0,0,0,0,0
0,0,0,0,0,0,0,0,0,31,31,31,31,0,0,0,0,0,0,0,0,0
0,0,0,0,0,0,0,0,0,31,7,7,31,0,0,0,0,0,0,0,0,0
0,0,0,0,0,0,0,0,0,31,7,7,31,0,0,0,0,0,0,0,0,0
0,0,0,0,0,0,0,0,0,31,7,7,31,0,0,0,0,0,0,0,0,0
0,0,0,0,0,0,0,0,0,31,7,7,31,0,0,0,7,10,10,7,0,0
0,0,0,0,0,0,0,0,5,31,7,7,31,0,0,0,10,0,0,10,0,0
0,0,5,5,5,5,0,5,5,31,31,31,31,0,0,0,7,0,0,10,0,0
0,0,5,5,5,5,0,5,5,2,5,5,0,0,0,0,10,0,0,10,0,0
0,0,5,5,5,5,0,5,5,5,5,5,0,0,0,0,7,10,10,7,0,0
0,0,0,0,0,0,0,0,5,5,5,0,0,0,0,0,0,0,0,0,0,0
0,0,0,0,0,0,0,0,0,0,0,0,0,0,0,0,0,0,0,0,0,0
0,0,0,0,0,0,0,0,0,0,0,0,0,0,0,22,11,0,0,0,0,0
0,0,0,0,0,0,0,0,0,0,0,0,0,0,0,0,0,0,0,0,0,0
0,0,0,0,0,0,0,0,0,0,0,0,0,0,0,0,0,0,0,0,0,0
0,0,0,0,0,0,0,0,0,0,0,0,0,0,0,0,0,0,0,0,0,0
0,0,0,0,0,0,0,0,0,0,0,0,0,0,0,0,0,0,0,0,0,0
0,0,0,0,0,0,0,0,0,0,0,0,0,0,0,0,0,0,0,0,0,0
0,0,0,0,0,0,0,0,0,0,0,0,0,0,0,0,0,0,0,0,0,0
endlayer

layer
0,0,0,0,0,0,0,0,0,0,0,0,0,0,0,0,0,0,0,0,0,0
0,0,0,0,0,0,0,0,0,0,0,0,0,0,0,0,0,0,0,0,0,0
0,0,0,0,0,0,0,0,0,0,0,0,0,0,0,0,0,0,0,0,0,0
0,0,0,0,0,0,0,0,0,0,0,0,0,0,0,0,0,0,0,0,0,0
0,0,0,0,0,0,0,0,0,0,0,0,0,0,0,0,0,0,0,0,0,0
0,0,0,0,0,0,0,0,0,0,0,0,0,0,0,0,0,0,0,0,0,0
0,0,0,0,0,0,0,0,0,0,0,0,0,0,0,0,0,0,0,0,0,0
0,0,0,0,0,0,0,0,0,0,22,11,0,0,0,0,0,0,0,0,0,0
0,0,0,0,0,0,0,0,0,0,22,11,0,0,0,0,0,0,0,0,0,0
0,0,0,0,0,0,0,0,0,0,22,11,0,0,0,0,10,10,10,10,0,0
0,0,0,0,0,0,0,0,0,0,22,11,0,0,0,10,7,7,7,7,10,0
0,0,0,0,0,0,0,0,5,5,22,11,0,0,0,10,7,40,40,7,10,0
0,0,0,0,0,0,0,5,5,5,5,5,0,0,0,10,7,0,0,7,10,0
0,0,0,0,0,0,0,5,5,2,5,5,0,0,0,10,7,0,0,7,10,0
0,0,0,0,0,0,0,5,5,5,5,5,0,0,0,10,7,7,7,7,10,0
0,0,0,0,0,0,0,0,5,5,5,0,0,0,0,0,10,10,10,10,0,0
0,0,0,0,0,0,0,0,0,0,0,0,0,0,0,0,0,0,0,0,0,0
0,0,0,0,0,0,0,0,0,0,0,0,0,0,0,0,0,0,0,0,0,0
0,0,0,0,0,0,0,0,0,0,0,0,0,0,0,0,0,0,0,0,0,0
0,0,0,0,0,0,0,0,0,0,0,0,0,0,0,0,0,0,0,0,0,0
0,0,0,0,0,0,0,0,0,0,0,0,0,0,0,0,0,0,0,0,0,0
0,0,0,0,0,0,0,0,0,0,0,0,0,0,0,0,0,0,0,0,0,0
0,0,0,0,0,0,0,0,0,0,0,0,0,0,0,0,0,0,0,0,0,0
0,0,0,0,0,0,0,0,0,0,0,0,0,0,0,0,0,0,0,0,0,0
endlayer

layer
0,0,0,0,0,0,0,0,0,0,0,0,0,0,0,0,0,0,0,0,0,0
0,0,0,0,0,0,0,0,0,0,0,0,0,0,0,0,0,0,0,0,0,0
0,0,0,0,0,0,0,0,0,0,0,0,0,0,0,0,0,0,0,0,0,0
0,0,0,0,0,0,0,0,0,0,0,0,0,0,0,0,0,0,0,0,0,0
0,0,0,0,0,0,0,0,0,0,0,0,0,0,0,0,0,0,0,0,0,0
0,0,0,0,0,0,0,0,0,0,0,0,0,0,0,0,0,0,0,0,0,0
0,0,0,0,0,0,0,0,0,0,0,0,0,0,0,0,0,0,0,0,0,0
0,0,0,0,0,0,0,0,0,0,0,0,0,0,0,0,0,0,0,0,0,0
0,0,0,0,0,0,0,0,0,0,0,0,0,0,0,0,0,0,0,0,0,0
0,0,0,0,0,0,0,0,0,0,0,0,0,0,0,0,0,0,0,0,0,0
0,0,0,0,0,0,0,0,0,0,0,0,0,0,0,0,10,10,10,10,0,0
0,0,0,0,0,0,0,0,5,5,5,0,0,0,0,0,10,0,0,10,0,0
0,0,0,0,0,0,0,5,5,5,5,5,0,0,0,0,10,0,0,10,0,0
0,0,0,0,0,0,0,5,5,5,5,5,0,0,0,0,10,0,0,10,0,0
0,0,0,0,0,0,0,5,5,5,5,5,0,0,0,0,10,10,10,10,0,0
0,0,0,0,0,0,0,0,5,5,5,0,0,0,0,0,0,0,0,0,0,0
0,0,0,0,0,0,0,0,0,0,0,0,0,0,0,0,0,0,0,0,0,0
0,0,0,0,0,0,0,0,0,0,0,0,0,0,0,0,0,0,0,0,0,0
0,0,0,0,0,0,0,0,0,0,0,0,0,0,0,0,0,0,0,0,0,0
0,0,0,0,0,0,0,0,0,0,0,0,0,0,0,0,0,0,0,0,0,0
0,0,0,0,0,0,0,0,0,0,0,0,0,0,0,0,0,0,0,0,0,0
0,0,0,0,0,0,0,0,0,0,0,0,0,0,0,0,0,0,0,0,0,0
0,0,0,0,0,0,0,0,0,0,0,0,0,0,0,0,0,0,0,0,0,0
0,0,0,0,0,0,0,0,0,0,0,0,0,0,0,0,0,0,0,0,0,0
endlayer

layer
0,0,0,0,0,0,0,0,0,0,0,0,0,0,0,0,0,0,0,0,0,0
0,0,0,0,0,0,0,0,0,0,0,0,0,0,0,0,0,0,0,0,0,0
0,0,0,0,0,0,0,0,0,0,0,0,0,0,0,0,0,0,0,0,0,0
0,0,0,0,0,0,0,0,0,0,0,0,0,0,0,0,0,0,0,0,0,0
0,0,0,0,0,0,0,0,0,0,0,0,0,0,0,0,0,0,0,0,0,0
0,0,0,0,0,0,0,0,0,0,0,0,0,0,0,0,0,0,0,0,0,0
0,0,0,0,0,0,0,0,0,0,0,0,0,0,0,0,0,0,0,0,0,0
0,0,0,0,0,0,0,0,0,0,0,0,0,0,0,0,0,0,0,0,0,0
0,0,0,0,0,0,0,0,0,0,0,0,0,0,0,0,0,0,0,0,0,0
0,0,0,0,0,0,0,0,0,0,0,0,0,0,0,0,0,0,0,0,0,0
0,0,0,0,0,0,0,0,0,0,0,0,0,0,0,0,31,31,31,31,0,0
0,0,0,0,0,0,0,0,0,0,0,0,0,0,0,0,31,22,11,31,0,0
0,0,0,0,0,0,0,0,5,5,5,0,0,0,0,0,31,22,11,31,0,0
0,0,0,0,0,0,0,0,5,5,5,0,0,0,0,0,31,22,11,31,0,0
0,0,0,0,0,0,0,0,5,5,5,0,0,0,0,0,31,31,31,31,0,0
0,0,0,0,0,0,0,0,0,0,0,0,0,0,0,0,0,0,0,0,0,0
0,0,0,0,0,0,0,0,0,0,0,0,0,0,0,0,0,0,0,0,0,0
0,0,0,0,0,0,0,0,0,0,0,0,0,0,0,0,0,0,0,0,0,0
0,0,0,0,0,0,0,0,0,0,0,0,0,0,0,0,0,0,0,0,0,0
0,0,0,0,0,0,0,0,0,0,0,0,0,0,0,0,0,0,0,0,0,0
0,0,0,0,0,0,0,0,0,0,0,0,0,0,0,0,0,0,0,0,0,0
0,0,0,0,0,0,0,0,0,0,0,0,0,0,0,0,0,0,0,0,0,0
0,0,0,0,0,0,0,0,0,0,0,0,0,0,0,0,0,0,0,0,0,0
0,0,0,0,0,0,0,0,0,0,0,0,0,0,0,0,0,0,0,0,0,0
endlayer