# Wizard Tower 1b -- Courtyard Version
# Originally Crated by Ruins mod version 12.3 Ingame Parser (20 Apr 2014)
# Recreated by Ruins mod version 15.6 Ingame Parser (2 Jun 2016)
# authoring Player: Jordan_Greywolf

# Updated to MC 1.8: 2 Jun 2016
# Updated to MC 1.9 & 1.10: 13 Sep 2016
# Updated to MC 1.11: 13 Jan 2017
# Updated to MC 1.12: 8 Jul 2017

# Last Updated: 8 Dec 2018

# Special thanks to BOYSLITTLE for bug reporting.
# Special thanks to QuarterAnimal for idea to use teBlock for custom Mob Spawners.

uniqueMinDistance=2000

biomesToSpawnIn=dungeon,eerie,eldritch,forest

biomeTypesToSpawnIn=FOREST,SWAMP,MAGICAL,-HILLS,-MOUNTAIN

weight=1
embed_into_distance=5
acceptable_target_blocks=

unacceptable_target_blocks=flowing_water,water,flowing_lava,lava,cloud,slime_congealed,slime_dirt,slime_grass,command_block,planks,planks2,concrete,cobblestone,stonebrick,brick_block,glass,torch,oak_stairs,stone_stairs,brick_stairs,stone_brick_stairs,nether_brick_stairs,sandstone_stairs,spruce_stairs,birch_stairs,jungle_stairs,quartz_stairs,acacia_stairs,dark_oak_stairs,cobblestone_wall,stone_slab,double_stone_slab,stone_slab2,wooden_slab,double_wooden_slab,nether_brick,fence

dimensions=60,21,21
allowable_overhang=0
max_leveling=5
leveling_buffer=0
preserve_water=0
preserve_lava=0
preserve_plants=1

# Base Stone Brick
rule1=0,100,minecraft:stonebrick,minecraft:stonebrick,minecraft:stonebrick-1,minecraft:stonebrick-1,minecraft:stonebrick-2

rule2=0,100,minecraft:nether_brick-0

rule3=0,100,minecraft:cobblestone_wall-1,minecraft:cobblestone_wall

rule4=0,100,ChestGenHook:chests/simple_dungeon:5-5

# Basement Creepy Crawler (Invis Spider) Spawner
rule5=0,100,teBlock;minecraft:mob_spawner;{SpawnData:{HandDropChances:[2.0f,0.0f],Silent:1,id:"minecraft:spider",ActiveEffects:[{Duration:999999,Id:14,Amplifier:1}],HandItems:[{Count:1,id:"web"},{}]},id:"minecraft:mob_spawner"}-0


rule6=0,100,IInventory;minecraft:chest;minecraft:grass#32#0#0+minecraft:web#32#0#8+minecraft:stone#32#0#11+minecraft:nether_brick#32#0#18+minecraft:vine#32#0#26-3
rule7=0,100,IInventory;minecraft:chest;minecraft:torch#32#0#0+minecraft:stained_glass_pane#32#4#8+minecraft:planks#32#1#18+minecraft:mossy_cobblestone#32#0#26-2

rule8=0,100,minecraft:nether_brick_stairs-1
rule9=0,100,ChestGenHook:chests/simple_dungeon:5-4
rule10=0,100,minecraft:dirt-0
rule11=0,100,minecraft:grass-0
rule12=0,100,minecraft:double_stone_slab-0
rule13=0,100,minecraft:water-8
rule14=0,100,minecraft:wool-14

rule15=0,100,minecraft:tallgrass,minecraft:tallgrass-1,minecraft:tallgrass-1,minecraft:tallgrass-1,minecraft:tallgrass-1,minecraft:tallgrass-2,minecraft:tallgrass-2,minecraft:red_flower,minecraft:red_flower-1,minecraft:red_flower-2,minecraft:yellow_flower,minecraft:sapling,minecraft:sapling-1,minecraft:sapling-2,minecraft:sapling-3,minecraft:sapling-4,minecraft:sapling-5

rule16=0,100,minecraft:spruce_door-2
rule17=0,100,minecraft:web-0
rule18=0,100,minecraft:fence-0
rule19=0,100,minecraft:oak_stairs-3
rule20=0,100,minecraft:carpet-14
rule21=0,100,minecraft:oak_stairs-2

# Haunted Armor Spawner
rule22=0,100,teBlock;minecraft:mob_spawner;{SpawnData:{id:Skeleton,AbsorptionAmount:10,HandItems:[{Count:1,id:iron_sword},{Count:1,id:shield}],ArmorItems:[{Count:1,id:iron_boots},{Count:1,id:iron_leggings},{Count:1,id:iron_chestplate},{Count:1,id:iron_helmet}],Silent:1,ActiveEffects:[{Id:14,Amplifier:0,Duration:999999,Ambient:1}]},id:"minecraft:mob_spawner"}-0

rule23=0,100,minecraft:stonebrick-3
rule24=0,100,minecraft:stone_slab-8
rule25=0,100,minecraft:stone_slab-0
rule26=0,100,minecraft:spruce_door-0
rule27=0,100,IInventory;minecraft:chest;minecraft:planks#8#1#11+minecraft:planks#8#1#16-3
rule28=0,100,IInventory;minecraft:chest;minecraft:iron_bars#24#0#2+minecraft:bread#6#0#16+minecraft:carpet#12#14#22-2
rule29=0,100,minecraft:nether_brick_stairs-4
rule30=0,100,minecraft:nether_brick_stairs-6
rule31=0,100,minecraft:nether_brick_stairs-7
rule32=0,100,minecraft:nether_brick_stairs-5
rule33=0,100,minecraft:spruce_door-8
rule34=0,100,minecraft:planks-1
rule35=0,100,minecraft:iron_bars-0
rule36=1,100,minecraft:redstone_torch-5
rule37=0,100,minecraft:nether_brick_stairs-2
rule38=0,100,minecraft:nether_brick_stairs-3
rule39=0,100,IInventory;minecraft:lit_furnace;minecraft:coal#5#1#1+minecraft:cooked_mutton#8#0#2-5
rule40=0,100,minecraft:cauldron-3
rule41=0,100,minecraft:crafting_table-0
rule42=0,100,IInventory;minecraft:chest;minecraft:sugar#6#0#1+minecraft:chicken#2#0#5+minecraft:wheat#6#0#9+minecraft:fish#5#0#12+minecraft:carrot#3#0#17+minecraft:potato#3#0#23-3
rule43=0,100,minecraft:oak_stairs-1
rule44=0,100,minecraft:oak_stairs-0
rule45=0,100,minecraft:nether_brick_stairs-0

# Creepy Crawler (invisible spider)
rule46=0,100,teBlock;minecraft:mob_spawner;{SpawnData:{HandDropChances:[2.0f,0.0f],Silent:1,id:"minecraft:cave_spider",ActiveEffects:[{Duration:999999,Id:14,Amplifier:1}],HandItems:[{Count:1,id:"web"},{}]},id:"minecraft:mob_spawner"}-0

rule47=0,100,minecraft:cake-0

# Creepy Crawler (invisible spider)
rule48=0,100,teBlock;minecraft:mob_spawner;{SpawnData:{HandDropChances:[2.0f,0.0f],Silent:1,id:"minecraft:cave_spider",ActiveEffects:[{Duration:999999,Id:14,Amplifier:1}],HandItems:[{Count:1,id:"web"},{}]},id:"minecraft:mob_spawner"}-0

rule49=0,100,minecraft:hopper-8
rule50=0,100,minecraft:nether_brick_fence-0
rule51=0,100,IInventory;minecraft:chest;minecraft:writable_book#1#0#0+minecraft:dye#6#0#8+minecraft:feather#6#0#14+minecraft:paper#6#0#20-5
rule52=0,100,minecraft:oak_stairs-7
rule53=0,100,minecraft:wooden_slab-8
rule54=0,100,minecraft:oak_stairs-6

rule55=0,100,minecraft:stonebrick,minecraft:stonebrick,minecraft:stonebrick,minecraft:stonebrick-1,minecraft:stonebrick-2

rule56=0,100,minecraft:bookshelf-0
rule57=0,100,ChestGenHook:chests/simple_dungeon:5-3
rule58=0,100,minecraft:bed-10
rule59=0,100,minecraft:bed-2

# Randomized Flower Pot (fern, cactus, sapling)
rule60=0,100,teBlock;minecraft:flower_pot;{Item:"minecraft:tallgrass",x:0,y:0,z:0,Data:2,id:"flower_pot"}-0,teBlock;minecraft:flower_pot;{Item:"minecraft:cactus",x:0,y:0,z:0,Data:0,id:"flower_pot"}-0,teBlock;minecraft:flower_pot;{Item:"minecraft:sapling",x:0,y:0,z:0,Data:1,id:"flower_pot"}-0,teBlock;minecraft:flower_pot;{Item:"minecraft:sapling",x:0,y:0,z:0,Data:1,id:"flower_pot"}-0,teBlock;minecraft:flower_pot;{Item:"minecraft:tallgrass",x:0,y:0,z:0,Data:3,id:"flower_pot"}-0

rule61=0,100,minecraft:oak_stairs-5
rule62=0,100,minecraft:redstone_lamp-0
rule63=0,100,minecraft:hopper-0

# Randomized Command Block trap
rule64=0,100,CommandBlock:/effect @p[r=5] 9 30:@,CommandBlock:/effect @p[r=5] 15 30:@,CommandBlock:/effect @p[r=5] 17 10:@,CommandBlock:/effect @p[r=5] 18 30:@

rule65=0,100,minecraft:stone_pressure_plate-0
rule66=0,100,minecraft:wooden_pressure_plate-0
rule67=0,100,IInventory;minecraft:chest;minecraft:web#5#0#0+minecraft:enchanted_book#{StoredEnchantments:[0:{lvl:1s,id:33s}]}#0#5+minecraft:web#5#0#25-5
rule68=0,100,minecraft:glass_pane-0
rule69=0,100,IInventory;minecraft:trapped_chest;minecraft:iron_bars#16#0#0+minecraft:golden_axe#1#0#4+minecraft:golden_shovel#1#0#6+minecraft:planks#16#1#8+minecraft:golden_apple#1#0#10+minecraft:golden_carrot#1#0#12+minecraft:gold_ore#1#0#18+minecraft:golden_hoe#1#0#23+minecraft:golden_sword#1#0#25+minecraft:web#1#0#26-4
rule70=0,100,minecraft:water-0
rule71=0,100,IInventory;minecraft:chest;minecraft:golden_rail#8#0#3+minecraft:rail#8#0#6+minecraft:iron_bars#2#0#8+minecraft:rail#8#0#10+minecraft:rail#8#0#22+minecraft:rail#8#0#25-5
rule72=0,100,minecraft:rail-6
rule73=0,100,minecraft:golden_rail-0
rule74=0,100,minecraft:rail-9
rule75=0,100,minecraft:golden_rail-1
rule76=0,100,minecraft:rail-7
rule77=0,100,minecraft:rail-8
rule78=0,100,minecraft:tnt-0
rule79=0,100,IInventory;minecraft:dispenser;minecraft:arrow#6#0#0-3
rule80=0,100,minecraft:piston-1
rule81=0,100,minecraft:bed-0
rule82=0,100,minecraft:bed-8
rule83=0,100,ChestGenHook:chests/simple_dungeon:5-2
rule84=0,100,Skull:0:0-0

# Chest at top of tower -- contains assorted spawn eggs.
rule85=0,100,IInventory;minecraft:chest;minecraft:spawn_egg#{EntityTag:{id:"minecraft:mooshroom"}}#0#0+minecraft:spawn_egg#{EntityTag:{id:"minecraft:chicken"}}#0#3+minecraft:spawn_egg#{EntityTag:{id:"minecraft:wolf"}}#0#6+minecraft:spawn_egg#{EntityTag:{id:"minecraft:pig"}}#0#8+minecraft:spawn_egg#{EntityTag:{id:"minecraft:sheep"}}#0#10+minecraft:spawn_egg#{EntityTag:{id:"minecraft:cow"}}#0#14+minecraft:spawn_egg#{EntityTag:{id:"minecraft:mule"}}#0#20+minecraft:spawn_egg#{EntityTag:{id:"minecraft:donkey"}}#0#22+minecraft:spawn_egg#{EntityTag:{id:"minecraft:rabbit"}}#0#25-5

rule86=0,100,minecraft:redstone_wire-13
rule87=0,100,minecraft:redstone_wire-14

# Sorcerer Boss
rule88=0,100,CommandBlock:RUINSTRIGGER /summon witch ~0 ~1 ~0 {HandItems:[{Count:1,id:ender_pearl},{Count:1,id:diamond}],CustomName:Sorcerer,Attributes:[{Name:generic.maxHealth,Base:65}],HandDropChances:[2.0F,2.0F],PersistenceRequired:1}:@

rule89=0,100,minecraft:redstone_wire-15

# Invisible Spider Boss
rule90=0,100,CommandBlock:RUINSTRIGGER /summon spider ~0 ~1 ~0 {HandItems:[{Count:1,id:emerald},{Count:16,id:web}],CustomName:"Creepier Crawler",HandDropChances:[2.0F,2.0F],Attributes:[{Name:generic.maxHealth,Base:50}],ActiveEffects:[{Id:14,Amplifier:1,Duration:999999}],Silent:1,PersistenceRequired:1}:@

rule91=0,100,IInventory;minecraft:chest;minecraft:torch#16#0#0+minecraft:iron_bars#16#0#8+minecraft:enchanted_book#{StoredEnchantments:[0:{lvl:5s,id:18s}]}#0#14+minecraft:arrow#16#0#20-4
rule92=0,100,minecraft:stained_glass-15
rule93=0,100,minecraft:trapdoor-14
rule94=0,100,minecraft:stained_glass-14
rule95=0,100,minecraft:trapdoor-12
rule96=0,100,minecraft:glowstone-0
rule97=0,100,minecraft:trapdoor-13
rule98=0,100,minecraft:stained_glass-11
rule99=0,100,minecraft:trapdoor-15
rule100=0,100,minecraft:stained_glass-0
rule101=0,100,minecraft:stone_slab-6
rule102=0,100,minecraft:stone_slab-14
rule103=0,100,minecraft:double_stone_slab-6

layer
1,1,1,1,1,1,1,1,1,1,1,1,1,1,1,1,1,1,1,1,1
1,2,2,2,2,2,2,2,2,2,2,2,2,2,2,2,2,2,2,2,1
1,2,2,2,2,2,2,2,2,2,2,2,2,2,2,2,2,2,2,2,1
1,2,2,2,2,2,2,2,2,2,2,2,2,2,2,2,2,2,2,2,1
1,2,2,2,2,2,2,2,2,2,2,2,2,2,2,2,2,2,2,2,1
1,2,2,2,2,2,2,2,2,2,2,2,2,2,2,2,2,2,2,2,1
1,2,2,2,2,2,2,2,1,1,1,1,1,2,2,2,2,2,2,2,1
1,2,2,2,2,2,2,1,2,2,2,2,2,1,2,2,2,2,2,2,1
1,2,2,2,2,2,1,2,2,2,2,2,2,2,1,2,2,2,2,2,1
1,2,2,2,2,2,1,2,2,2,2,2,2,2,1,2,2,2,2,2,1
1,2,2,2,2,2,1,2,2,2,2,2,2,2,1,2,2,2,2,2,1
1,2,2,2,2,2,1,2,2,2,2,2,2,2,1,2,2,2,2,2,1
1,2,2,2,2,2,1,2,2,2,2,2,2,2,1,2,2,2,2,2,1
1,2,2,2,2,2,2,1,2,2,2,2,2,1,2,2,2,2,2,2,1
1,2,2,2,2,2,2,2,1,1,1,1,1,2,2,2,2,2,2,2,1
1,2,2,2,2,2,2,2,2,2,2,2,2,2,2,2,2,2,2,2,1
1,2,2,2,2,2,2,2,2,2,2,2,2,2,2,2,2,2,2,2,1
1,2,2,2,2,2,2,2,2,2,2,2,2,2,2,2,2,2,2,2,1
1,2,2,2,2,2,2,2,2,2,2,2,2,2,2,2,2,2,2,2,1
1,2,2,2,2,2,2,2,2,2,2,2,2,2,2,2,2,2,2,2,1
1,1,1,1,1,1,1,1,1,1,1,1,1,1,1,1,1,1,1,1,1
endlayer

layer
1,1,1,1,1,1,1,1,1,1,1,1,1,1,1,1,1,1,1,1,1
1,3,0,0,3,0,0,3,0,4,3,4,0,3,0,0,3,0,0,3,1
1,0,0,0,0,0,0,0,0,0,5,0,0,0,0,0,0,0,0,0,1
1,0,0,0,0,0,0,0,0,0,0,0,0,0,0,0,0,0,0,0,1
1,3,0,0,0,0,0,0,0,0,0,0,0,0,0,0,0,0,0,3,1
1,0,0,0,0,3,0,0,0,0,3,0,0,0,0,3,0,0,0,0,1
1,0,0,0,0,0,0,0,1,0,1,0,1,0,0,0,0,0,0,0,1
1,3,0,0,0,0,0,1,0,0,0,0,0,1,0,0,0,0,0,3,1
1,0,0,0,0,0,1,0,0,0,0,0,0,0,1,0,0,0,0,0,1
1,7,0,0,0,0,0,0,0,0,2,0,0,0,0,0,0,0,0,6,1
1,3,5,0,0,3,1,0,0,0,2,0,0,0,1,3,0,0,5,3,1
1,7,0,0,0,0,0,0,0,0,8,0,0,0,0,0,0,0,0,6,1
1,0,0,0,0,0,1,0,0,0,0,0,0,0,1,0,0,0,0,0,1
1,3,0,0,0,0,0,1,0,0,0,0,0,1,0,0,0,0,0,3,1
1,0,0,0,0,0,0,0,1,0,1,0,1,0,0,0,0,0,0,0,1
1,0,0,0,0,3,0,0,0,0,3,0,0,0,3,0,0,0,0,0,1
1,3,0,0,0,0,0,0,0,0,0,0,0,0,0,0,0,0,0,3,1
1,0,0,0,0,0,0,0,0,0,0,0,0,0,0,0,0,0,0,0,1
1,0,0,0,0,0,0,0,0,0,5,0,0,0,0,0,0,0,0,0,1
1,3,0,0,3,0,0,3,0,9,3,9,0,3,0,0,3,0,0,3,1
1,1,1,1,1,1,1,1,1,1,1,1,1,1,1,1,1,1,1,1,1
endlayer

layer
1,1,1,1,1,1,1,1,1,1,1,1,1,1,1,1,1,1,1,1,1
1,3,0,0,3,0,0,3,0,0,3,0,0,3,0,0,3,0,0,3,1
1,0,0,0,0,0,0,0,0,0,0,0,0,0,0,0,0,0,0,0,1
1,0,0,0,0,0,0,0,0,0,0,0,0,0,0,0,0,0,0,0,1
1,3,0,0,0,0,0,0,0,0,0,0,0,0,0,0,0,0,0,3,1
1,0,0,0,0,3,0,0,0,0,3,0,0,0,0,3,0,0,0,0,1
1,0,0,0,0,0,0,0,1,0,1,0,1,0,0,0,0,0,0,0,1
1,3,0,0,0,0,0,1,0,0,0,0,0,1,0,0,0,0,0,3,1
1,0,0,0,0,0,1,0,0,0,0,0,0,0,1,0,0,0,0,0,1
1,0,0,0,0,0,0,0,0,0,2,0,0,0,0,0,0,0,0,0,1
1,3,0,0,0,3,1,0,0,0,8,0,0,0,1,3,0,0,0,3,1
1,0,0,0,0,0,0,0,0,0,0,0,0,0,0,0,0,0,0,0,1
1,0,0,0,0,0,1,0,0,0,0,0,0,0,1,0,0,0,0,0,1
1,3,0,0,0,0,0,1,0,0,0,0,0,1,0,0,0,0,0,3,1
1,0,0,0,0,0,0,0,1,0,1,0,1,0,0,0,0,0,0,0,1
1,0,0,0,0,3,0,0,0,0,3,0,0,0,3,0,0,0,0,0,1
1,3,0,0,0,0,0,0,0,0,0,0,0,0,0,0,0,0,0,3,1
1,0,0,0,0,0,0,0,0,0,0,0,0,0,0,0,0,0,0,0,1
1,0,0,0,0,0,0,0,0,0,0,0,0,0,0,0,0,0,0,0,1
1,3,0,0,3,0,0,3,0,0,3,0,0,3,0,0,3,0,0,3,1
1,1,1,1,1,1,1,1,1,1,1,1,1,1,1,1,1,1,1,1,1
endlayer

layer
1,1,1,1,1,1,1,1,1,1,1,1,1,1,1,1,1,1,1,1,1
1,10,10,10,10,10,10,10,10,10,10,10,10,10,10,10,10,10,10,10,1
1,10,10,11,11,10,10,10,10,10,10,10,10,10,10,10,11,11,10,10,1
1,10,11,12,12,11,10,10,10,10,10,10,10,10,10,11,12,12,11,10,1
1,10,11,12,12,11,10,10,10,10,10,10,10,10,10,11,12,12,11,10,1
1,10,10,11,11,10,10,10,10,10,10,10,10,10,10,10,11,11,10,10,1
1,10,10,10,10,10,10,10,1,1,1,1,1,10,10,10,10,10,10,10,1
1,10,10,10,10,10,10,1,2,2,2,2,2,1,10,10,10,10,10,10,1
1,10,10,10,10,10,1,2,2,2,2,2,2,2,1,10,10,10,10,10,1
1,10,10,10,10,10,1,2,2,2,8,2,2,2,1,10,10,10,10,10,1
1,10,10,10,10,10,1,2,2,2,0,2,2,2,1,10,10,10,10,10,1
1,10,10,10,10,10,1,2,2,2,0,2,2,2,1,10,10,10,10,10,1
1,10,10,10,10,10,1,2,2,2,0,2,2,2,1,10,10,10,10,10,1
1,10,10,10,10,10,10,1,2,2,2,2,2,1,10,10,10,10,10,10,1
1,10,10,10,10,10,10,10,1,1,1,1,1,10,10,10,10,10,10,10,1
1,10,10,11,11,10,10,10,10,10,10,10,10,10,10,10,11,11,10,10,1
1,10,11,12,12,11,10,10,10,10,10,10,10,10,10,11,12,12,11,10,1
1,10,11,12,12,11,10,10,10,10,10,10,10,10,10,11,12,12,11,10,1
1,10,10,11,11,10,10,10,10,10,10,10,10,10,10,10,11,11,10,10,1
1,10,10,10,10,10,10,10,10,10,10,10,10,10,10,10,10,10,10,10,1
1,1,1,1,1,1,1,1,1,1,1,1,1,1,1,1,1,1,1,1,1
endlayer

layer
1,1,1,1,1,1,1,1,1,1,1,1,1,1,1,1,1,1,1,1,1
1,11,11,11,11,11,11,11,11,11,11,11,11,11,11,11,11,11,11,11,1
1,11,11,13,13,11,11,11,11,11,10,11,11,11,11,11,13,13,11,11,1
1,11,13,13,13,13,11,11,11,11,11,11,11,11,11,13,13,13,13,11,1
1,11,13,13,13,13,11,11,11,11,11,11,11,11,11,13,13,13,13,11,1
1,11,11,13,13,11,11,11,11,11,11,11,11,11,11,11,13,13,11,11,1
1,11,11,11,11,11,11,11,1,1,1,1,1,11,11,11,11,11,11,11,1
1,11,11,11,11,11,11,1,2,2,2,2,2,1,11,11,11,11,11,11,1
1,11,11,11,11,11,1,2,2,2,2,2,2,2,1,11,11,11,11,11,1
1,11,11,11,11,11,1,2,2,2,14,2,2,2,1,11,11,11,11,11,1
1,11,11,11,11,11,1,2,2,2,14,2,2,2,1,11,11,11,11,11,1
1,11,11,11,11,11,1,2,2,2,14,2,2,2,1,11,11,11,11,11,1
1,11,11,11,11,11,1,2,2,2,2,2,2,2,1,11,11,11,11,11,1
1,11,11,11,11,11,11,1,2,2,2,2,2,1,11,11,11,11,11,11,1
1,11,11,11,11,11,11,11,1,1,2,1,1,11,11,11,11,11,11,11,1
1,11,11,13,13,11,11,11,11,2,2,2,11,11,11,11,13,13,11,11,1
1,11,13,13,13,13,11,11,11,2,2,2,11,11,11,13,13,13,13,11,1
1,11,13,13,13,13,11,11,2,2,2,2,2,11,11,13,13,13,13,11,1
1,11,11,13,13,11,11,11,2,2,2,2,2,11,11,11,13,13,11,11,1
1,11,11,11,11,11,11,11,2,2,2,2,2,11,11,11,11,11,11,11,1
1,1,1,1,1,1,1,1,1,1,1,1,1,1,1,1,1,1,1,1,1
endlayer

layer
1,1,1,1,1,1,1,1,1,1,1,1,1,1,1,1,1,1,1,1,1
1,15,15,15,15,15,15,15,15,15,15,15,15,15,15,15,15,15,15,15,1
1,15,15,0,0,15,15,15,15,15,2,15,15,15,15,15,0,0,15,15,1
1,15,0,13,13,0,15,15,15,15,15,15,15,15,15,0,13,13,0,15,1
1,15,0,13,13,0,15,15,15,15,15,15,15,15,15,0,13,13,0,15,1
1,15,15,0,0,15,15,15,15,3,0,3,15,15,15,15,0,0,15,15,1
1,15,15,15,15,15,15,15,1,1,16,1,1,15,15,15,15,15,15,15,1
1,15,15,15,15,15,15,1,0,0,0,0,0,1,15,15,15,15,15,15,1
1,15,15,15,15,15,1,0,18,0,0,0,18,17,1,15,15,15,15,15,1
1,15,15,15,15,3,1,22,21,0,20,0,19,17,1,3,15,15,15,15,1
1,15,15,15,15,3,23,24,21,0,20,0,19,0,23,3,15,15,15,15,1
1,15,15,15,15,3,1,12,21,0,20,0,19,0,1,3,15,15,15,15,1
1,15,15,15,15,15,1,25,0,0,0,0,0,0,1,15,15,15,15,15,1
1,15,15,15,15,15,15,1,0,0,0,0,0,1,15,15,15,15,15,15,1
1,15,15,15,15,15,15,15,1,1,0,1,1,15,15,15,15,15,15,15,1
1,15,15,0,0,15,15,15,15,1,0,1,15,15,15,15,0,0,15,15,1
1,15,0,13,13,0,15,15,15,1,0,1,15,15,15,0,13,13,0,15,1
1,15,0,13,13,0,15,15,1,0,26,0,1,15,15,0,13,13,0,15,1
1,15,15,0,0,15,15,15,23,28,0,27,23,15,15,15,0,0,15,15,1
1,15,15,15,15,15,15,15,1,0,16,17,1,15,15,15,15,15,15,15,1
1,1,1,1,1,1,1,1,1,1,0,1,1,1,1,1,1,1,1,1,1
endlayer

layer
3,3,3,3,3,3,3,3,3,3,3,3,3,3,3,3,3,3,3,3,3
3,0,0,0,0,0,0,0,0,0,29,0,0,0,0,0,0,0,0,0,3
3,0,0,0,0,0,0,0,0,31,2,30,0,0,0,0,0,0,0,0,3
3,0,0,0,0,0,0,0,0,0,32,0,0,0,0,0,0,0,0,0,3
3,0,0,0,0,0,0,0,0,0,0,0,0,0,0,0,0,0,0,0,3
3,0,0,0,0,0,0,0,0,0,0,0,0,0,0,0,0,0,0,0,3
3,0,0,0,0,0,0,0,1,1,33,1,1,0,0,0,0,0,0,0,3
3,0,0,0,0,0,0,1,17,17,17,17,17,1,0,0,0,0,0,0,3
3,0,0,0,0,0,1,24,20,0,0,0,20,17,1,0,0,0,0,0,3
3,0,0,0,0,0,1,12,0,0,0,0,0,0,1,0,0,0,0,0,3
3,0,0,0,0,0,34,25,17,0,0,0,0,0,34,0,0,0,0,0,3
3,0,0,0,0,0,1,0,0,0,0,0,0,0,1,0,0,0,0,0,3
3,0,0,0,0,0,1,0,0,0,0,0,0,0,1,0,0,0,0,0,3
3,0,0,0,0,0,0,1,0,0,0,0,0,1,0,0,0,0,0,0,3
3,0,0,0,0,0,0,0,1,1,0,1,1,0,0,0,0,0,0,0,3
3,0,0,0,0,0,0,0,0,34,0,34,0,0,0,0,0,0,0,0,3
3,0,0,0,0,0,0,0,0,1,0,1,0,0,0,0,0,0,0,0,3
3,0,0,0,0,0,0,0,1,0,33,17,1,0,0,0,0,0,0,0,3
3,0,0,0,0,0,0,0,34,0,0,0,34,0,0,0,0,0,0,0,3
3,0,0,0,0,0,0,0,1,0,33,0,1,0,0,0,0,0,0,0,3
3,3,3,3,3,3,3,3,3,1,0,1,3,3,3,3,3,3,3,3,3
endlayer

layer
0,0,0,0,0,0,0,0,0,0,0,0,0,0,0,0,0,0,0,0,0
0,0,0,0,0,0,0,0,0,0,2,0,0,0,0,0,0,0,0,0,0
0,0,0,0,0,0,0,0,0,2,2,2,0,0,0,0,0,0,0,0,0
0,0,0,0,0,0,0,0,0,0,2,0,0,0,0,0,0,0,0,0,0
0,0,0,0,0,0,0,0,0,0,0,0,0,0,0,0,0,0,0,0,0
0,0,0,0,0,0,0,0,0,0,0,0,0,0,0,0,0,0,0,0,0
0,0,0,0,0,0,0,0,1,1,35,1,1,0,0,0,0,0,0,0,0
0,0,0,0,0,0,0,1,24,17,17,17,17,1,0,0,0,0,0,0,0
0,0,0,0,0,0,1,25,12,0,17,0,0,17,1,0,0,0,0,0,0
0,0,0,0,0,0,1,17,0,17,18,0,0,17,1,0,0,0,0,0,0
0,0,0,0,0,0,34,0,0,18,18,18,0,0,34,0,0,0,0,0,0
0,0,0,0,0,0,1,0,0,0,18,0,0,0,1,0,0,0,0,0,0
0,0,0,0,0,0,1,17,0,0,0,0,0,17,1,0,0,0,0,0,0
0,0,0,0,0,0,0,1,17,0,0,0,17,1,0,0,0,0,0,0,0
0,0,0,0,0,0,0,0,1,1,0,1,1,0,0,0,0,0,0,0,0
0,0,0,0,0,0,0,0,0,34,0,34,0,0,0,0,0,0,0,0,0
0,0,0,0,0,0,0,0,0,1,35,1,0,0,0,0,0,0,0,0,0
0,0,0,0,0,0,0,0,1,17,0,17,1,0,0,0,0,0,0,0,0
0,0,0,0,0,0,0,0,34,0,0,0,34,0,0,0,0,0,0,0,0
0,0,0,0,0,0,0,0,1,17,0,17,1,0,0,0,0,0,0,0,0
0,0,0,0,0,0,0,0,0,1,35,1,0,0,0,0,0,0,0,0,0
endlayer

layer
0,0,0,0,0,0,0,0,0,0,29,0,0,0,0,0,0,0,0,0,0
0,0,0,0,0,0,0,0,0,2,2,2,0,0,0,0,0,0,0,0,0
0,0,0,0,0,0,0,0,31,2,2,2,30,0,0,0,0,0,0,0,0
0,0,0,0,0,0,0,0,0,2,2,2,0,0,0,0,0,0,0,0,0
0,0,0,0,0,0,0,0,0,0,32,0,0,0,0,0,0,0,0,0,0
0,0,0,0,0,0,0,0,0,0,0,0,0,0,0,0,0,0,0,0,0
0,0,0,0,0,0,0,0,1,1,23,1,1,0,0,0,0,0,0,0,0
0,0,0,0,0,0,0,1,25,12,24,17,17,1,0,0,0,0,0,0,0
0,0,0,0,0,0,1,0,0,0,0,0,0,17,1,0,0,0,0,0,0
0,0,0,0,0,0,1,17,0,0,36,0,0,17,1,0,0,0,0,0,0
0,0,0,0,0,0,23,17,17,36,18,36,0,17,23,0,0,0,0,0,0
0,0,0,0,0,0,1,17,0,0,36,0,0,17,1,0,0,0,0,0,0
0,0,0,0,0,0,1,17,0,0,0,0,0,17,1,0,0,0,0,0,0
0,0,0,0,0,0,0,1,17,17,0,17,17,1,0,0,0,0,0,0,0
0,0,0,0,0,0,0,0,1,1,23,1,1,0,0,0,0,0,0,0,0
0,0,0,0,0,0,0,0,0,38,2,37,0,0,0,0,0,0,0,0,0
0,0,0,0,0,0,0,0,0,1,23,1,0,0,0,0,0,0,0,0,0
0,0,0,0,0,0,0,0,1,17,0,17,1,0,0,0,0,0,0,0,0
0,0,0,0,0,0,0,0,23,0,0,0,23,0,0,0,0,0,0,0,0
0,0,0,0,0,0,0,0,1,17,17,17,1,0,0,0,0,0,0,0,0
0,0,0,0,0,0,0,0,0,1,23,1,0,0,0,0,0,0,0,0,0
endlayer

layer
0,0,0,0,0,0,0,0,0,2,2,2,0,0,0,0,0,0,0,0,0
0,0,0,0,0,0,0,0,2,2,2,2,2,0,0,0,0,0,0,0,0
0,0,0,0,0,0,0,0,2,2,2,2,2,0,0,0,0,0,0,0,0
0,0,0,0,0,0,0,0,2,2,2,2,2,0,0,0,0,0,0,0,0
0,0,0,0,0,0,0,0,0,2,2,2,0,0,0,0,0,0,0,0,0
0,0,0,0,0,0,0,0,0,2,2,2,0,0,0,0,0,0,0,0,0
0,0,0,0,0,0,0,0,1,1,2,1,1,0,0,0,0,0,0,0,0
0,0,0,0,0,0,0,1,0,0,25,2,2,1,0,0,0,0,0,0,0
0,0,0,0,0,0,1,0,0,2,2,2,2,2,1,0,0,0,0,0,0
0,0,0,0,0,0,1,0,2,2,2,2,2,2,1,0,0,0,0,0,0
0,0,0,0,0,0,1,2,2,2,2,2,2,2,1,0,0,0,0,0,0
0,0,0,0,0,0,1,2,2,2,2,2,2,2,1,0,0,0,0,0,0
0,0,0,0,0,0,1,2,2,2,2,2,2,2,1,0,0,0,0,0,0
0,0,0,0,0,0,0,1,2,2,2,2,2,1,0,0,0,0,0,0,0
0,0,0,0,0,0,0,0,1,1,1,1,1,0,0,0,0,0,0,0,0
0,0,0,0,0,0,0,0,0,0,0,0,0,0,0,0,0,0,0,0,0
0,0,0,0,0,0,0,0,0,2,2,2,0,0,0,0,0,0,0,0,0
0,0,0,0,0,0,0,0,2,2,0,2,2,0,0,0,0,0,0,0,0
0,0,0,0,0,0,0,0,2,0,46,0,2,0,0,0,0,0,0,0,0
0,0,0,0,0,0,0,0,2,2,17,2,2,0,0,0,0,0,0,0,0
0,0,0,0,0,0,0,0,0,2,2,2,0,0,0,0,0,0,0,0,0
endlayer

layer
0,0,0,0,0,0,0,0,0,1,23,1,0,0,0,0,0,0,0,0,0
0,0,0,0,0,0,0,0,1,41,40,39,1,0,0,0,0,0,0,0,0
0,0,0,0,0,0,0,0,23,17,17,17,23,0,0,0,0,0,0,0,0
0,0,0,0,0,0,0,0,1,48,17,42,1,0,0,0,0,0,0,0,0
0,0,0,0,0,0,0,0,0,1,17,1,0,0,0,0,0,0,0,0,0
0,0,0,0,0,0,0,0,0,35,17,35,0,0,0,0,0,0,0,0,0
0,0,0,0,0,0,0,0,1,1,17,1,1,0,0,0,0,0,0,0,0
0,0,0,0,0,0,0,1,0,0,0,0,0,1,0,0,0,0,0,0,0
0,0,0,0,0,0,1,0,0,0,0,0,0,25,1,0,0,0,0,0,0
0,0,0,0,0,3,1,0,0,0,43,0,0,12,1,3,0,0,0,0,0
0,0,0,0,0,3,23,17,0,21,18,19,0,24,23,3,0,0,2,0,0
0,0,0,0,0,3,1,0,0,0,18,0,0,0,1,3,0,0,0,0,0
0,0,0,0,0,0,1,0,0,21,18,19,0,0,1,0,0,0,0,0,0
0,0,0,0,0,0,0,1,0,0,44,0,0,1,0,0,0,0,0,0,0
0,0,0,0,0,0,0,0,1,1,23,1,1,0,0,0,0,0,0,0,0
0,0,0,0,0,0,0,0,0,3,3,3,0,0,0,0,0,0,0,0,0
0,0,0,0,0,0,0,0,0,0,45,0,0,0,0,0,0,0,0,0,0
0,0,0,0,0,0,0,0,0,2,2,2,0,0,0,0,0,0,0,0,0
0,0,0,0,0,0,0,0,38,2,0,2,37,0,0,0,0,0,0,0,0
0,0,0,0,0,0,0,0,0,2,2,2,0,0,0,0,0,0,0,0,0
0,0,0,0,0,0,0,0,0,0,8,0,0,0,0,0,0,0,0,0,0
endlayer

layer
0,0,0,0,0,0,0,0,0,1,34,1,0,0,0,0,0,0,0,0,0
0,0,0,0,0,0,0,0,1,47,0,17,1,0,0,0,0,0,0,0,0
0,0,0,0,0,0,0,0,34,0,0,0,34,0,0,0,0,0,0,0,0
0,0,0,0,0,0,0,0,1,0,0,17,1,0,0,0,0,0,0,0,0
0,0,0,0,0,0,0,0,0,1,17,1,0,0,0,0,0,0,0,0,0
0,0,0,0,0,0,0,0,0,35,17,35,0,0,0,0,0,0,0,0,0
0,0,0,0,0,0,0,0,1,1,17,1,1,0,0,0,0,0,0,0,0
0,0,0,0,0,0,0,1,17,17,0,0,17,1,0,0,0,0,0,0,0
0,0,0,0,0,0,1,17,0,0,17,0,17,17,1,0,0,0,0,0,0
0,0,0,0,0,0,1,0,0,17,0,0,0,17,1,0,0,0,29,0,0
0,0,0,0,0,0,35,0,0,0,20,0,0,25,35,0,0,31,2,30,0
0,0,0,0,0,0,1,0,0,17,20,0,0,12,1,0,0,0,32,0,0
0,0,0,0,0,0,1,17,0,0,20,0,0,24,1,0,0,0,0,0,0
0,0,0,0,0,0,0,1,17,0,0,0,17,1,0,0,0,0,0,0,0
0,0,0,0,0,0,0,0,1,1,35,1,1,0,0,0,0,0,0,0,0
0,0,0,0,0,0,0,0,0,0,0,0,0,0,0,0,0,0,0,0,0
0,0,0,0,0,0,0,0,0,0,0,0,0,0,0,0,0,0,0,0,0
0,0,0,0,0,0,0,0,0,2,2,2,0,0,0,0,0,0,0,0,0
0,0,0,0,0,0,0,0,0,2,0,2,0,0,0,0,0,0,0,0,0
0,0,0,0,0,0,0,0,0,2,2,2,0,0,0,0,0,0,0,0,0
0,0,0,0,0,0,0,0,0,0,0,0,0,0,0,0,0,0,0,0,0
endlayer

layer
0,0,0,0,0,0,0,0,0,1,34,1,0,0,0,0,0,0,0,0,0
0,0,0,0,0,0,0,0,1,0,0,17,1,0,0,0,0,0,0,0,0
0,0,0,0,0,0,0,0,34,0,0,0,34,0,0,0,0,0,0,0,0
0,0,0,0,0,0,0,0,1,17,0,17,1,0,0,0,0,0,0,0,0
0,0,0,0,0,0,0,0,0,1,17,1,0,0,0,0,0,0,0,0,0
0,0,0,0,0,0,0,0,0,35,17,35,0,0,0,0,0,0,0,0,0
0,0,0,0,0,0,0,0,1,1,17,1,1,0,0,0,0,0,0,0,0
0,0,0,0,0,0,0,1,17,17,17,0,17,1,0,0,0,0,0,0,0
0,0,0,0,0,0,1,17,0,0,0,0,0,17,1,0,0,0,0,0,0
0,0,0,0,0,0,1,17,0,0,18,17,0,0,1,0,0,0,2,0,0
0,0,0,0,0,0,35,17,0,18,18,18,0,0,35,0,0,2,2,2,0
0,0,0,0,0,0,1,17,0,0,18,0,0,0,1,0,0,0,2,0,0
0,0,0,0,0,0,1,17,0,0,0,0,12,25,1,0,0,0,0,0,0
0,0,0,0,0,0,0,1,17,17,0,17,24,1,0,0,0,0,0,0,0
0,0,0,0,0,0,0,0,1,1,35,1,1,0,0,0,0,0,0,0,0
0,0,0,0,0,0,0,0,0,0,0,0,0,0,0,0,0,0,0,0,0
0,0,0,0,0,0,0,0,0,0,0,0,0,0,0,0,0,0,0,0,0
0,0,0,0,0,0,0,0,0,0,45,0,0,0,0,0,0,0,0,0,0
0,0,0,0,0,0,0,0,0,38,2,37,0,0,0,0,0,0,0,0,0
0,0,0,0,0,0,0,0,0,0,8,0,0,0,0,0,0,0,0,0,0
0,0,0,0,0,0,0,0,0,0,0,0,0,0,0,0,0,0,0,0,0
endlayer

layer
0,0,0,0,0,0,0,0,0,1,23,1,0,0,0,0,0,0,0,0,0
0,0,0,0,0,0,0,0,1,17,17,0,1,0,0,0,0,0,0,0,0
0,0,0,0,0,0,0,0,23,17,0,17,23,0,0,0,0,0,0,0,0
0,0,0,0,0,0,0,0,1,17,0,17,1,0,0,0,0,0,0,0,0
0,0,0,0,0,0,0,0,0,1,23,1,0,0,0,0,0,0,0,0,0
0,0,0,0,0,0,0,0,0,38,2,37,0,0,0,0,0,0,0,0,0
0,0,0,0,0,0,0,0,1,1,23,1,1,0,0,0,0,0,0,0,0
0,0,0,0,0,0,0,1,17,17,17,17,17,1,0,0,0,0,0,0,0
0,0,0,0,0,0,1,17,0,17,17,17,17,17,1,0,0,0,29,0,0
0,0,0,0,0,0,1,17,0,17,36,0,17,17,1,0,0,2,2,2,0
0,0,0,0,0,0,23,0,0,36,49,36,0,17,23,0,31,2,2,2,30
0,0,0,0,0,0,1,17,0,0,36,0,0,0,1,0,0,2,2,2,0
0,0,0,0,0,0,1,17,0,0,0,0,0,0,1,0,0,0,32,0,0
0,0,0,0,0,0,0,1,17,17,24,12,25,1,0,0,0,0,0,0,0
0,0,0,0,0,0,0,0,1,1,23,1,1,0,0,0,0,0,0,0,0
0,0,0,0,0,0,0,0,0,0,0,0,0,0,0,0,0,0,0,0,0
0,0,0,0,0,0,0,0,0,0,0,0,0,0,0,0,0,0,0,0,0
0,0,0,0,0,0,0,0,0,0,0,0,0,0,0,0,0,0,0,0,0
0,0,0,0,0,0,0,0,0,0,2,0,0,0,0,0,0,0,0,0,0
0,0,0,0,0,0,0,0,0,0,0,0,0,0,0,0,0,0,0,0,0
0,0,0,0,0,0,0,0,0,0,0,0,0,0,0,0,0,0,0,0,0
endlayer

layer
0,0,0,0,0,0,0,0,0,2,2,2,0,0,0,0,0,0,0,0,0
0,0,0,0,0,0,0,0,2,2,17,2,2,0,0,0,0,0,0,0,0
0,0,0,0,0,0,0,0,2,17,0,17,2,0,0,0,0,0,0,0,0
0,0,0,0,0,0,0,0,2,2,17,2,2,0,0,0,0,0,0,0,0
0,0,0,0,0,0,0,0,0,2,2,2,0,0,0,0,0,0,0,0,0
0,0,0,0,0,0,0,0,0,0,0,0,0,0,0,0,0,0,0,0,0
0,0,0,0,0,0,0,0,1,1,1,1,1,0,0,0,0,0,0,0,0
0,0,0,0,0,0,0,1,2,2,2,2,2,1,0,0,0,0,0,0,0
0,0,0,0,0,0,1,2,2,2,2,2,2,2,1,0,0,2,2,2,0
0,0,0,0,0,0,1,2,2,2,2,2,2,2,1,2,2,2,2,2,2
0,0,0,0,0,0,1,2,2,2,2,2,2,2,2,2,2,2,2,2,2
0,0,0,0,0,0,1,2,2,2,2,2,2,0,1,2,2,2,2,2,2
0,0,0,0,0,0,1,2,2,2,2,2,0,17,1,0,0,2,2,2,0
0,0,0,0,0,0,0,1,2,2,25,0,0,1,0,0,0,0,0,0,0
0,0,0,0,0,0,0,0,1,1,1,1,1,0,0,0,0,0,0,0,0
0,0,0,0,0,0,0,0,0,0,0,0,0,0,0,0,0,0,0,0,0
0,0,0,0,0,0,0,0,0,0,0,0,0,0,0,0,0,0,0,0,0
0,0,0,0,0,0,0,0,0,0,0,0,0,0,0,0,0,0,0,0,0
0,0,0,0,0,0,0,0,0,0,50,0,0,0,0,0,0,0,0,0,0
0,0,0,0,0,0,0,0,0,0,0,0,0,0,0,0,0,0,0,0,0
0,0,0,0,0,0,0,0,0,0,0,0,0,0,0,0,0,0,0,0,0
endlayer

layer
0,0,0,0,0,0,0,0,0,0,45,0,0,0,0,0,0,0,0,0,0
0,0,0,0,0,0,0,0,0,2,2,2,0,0,0,0,0,0,0,0,0
0,0,0,0,0,0,0,0,38,2,17,2,37,0,0,0,0,0,0,0,0
0,0,0,0,0,0,0,0,0,2,2,2,0,0,0,0,0,0,0,0,0
0,0,0,0,0,0,0,0,0,0,8,0,0,0,0,0,0,0,0,0,0
0,0,0,0,0,0,0,0,0,3,3,3,0,0,0,0,0,0,0,0,0
0,0,0,0,0,0,0,0,1,1,23,1,1,0,0,0,0,0,0,0,0
0,0,0,0,0,0,0,1,41,54,53,52,51,1,0,0,0,0,0,0,0
0,0,0,0,0,0,1,0,0,0,44,0,0,56,1,0,0,55,23,55,0
0,0,0,0,0,3,1,22,0,0,0,0,0,43,1,35,55,0,0,57,55
0,0,2,0,0,3,23,24,0,0,17,0,0,0,0,17,17,0,59,58,23
0,0,0,0,0,3,1,12,0,0,0,0,0,0,1,35,55,0,0,18,55
0,0,0,0,0,0,1,25,0,0,0,0,0,17,1,0,0,55,23,55,0
0,0,0,0,0,0,0,1,17,0,0,0,17,1,0,0,0,0,0,0,0
0,0,0,0,0,0,0,0,1,1,23,1,1,0,0,0,0,0,0,0,0
0,0,0,0,0,0,0,0,0,3,3,3,0,0,0,0,0,0,0,0,0
0,0,0,0,0,0,0,0,0,0,0,0,0,0,0,0,0,0,0,0,0
0,0,0,0,0,0,0,0,0,0,0,0,0,0,0,0,0,0,0,0,0
0,0,0,0,0,0,0,0,0,0,36,0,0,0,0,0,0,0,0,0,0
0,0,0,0,0,0,0,0,0,0,0,0,0,0,0,0,0,0,0,0,0
0,0,0,0,0,0,0,0,0,0,0,0,0,0,0,0,0,0,0,0,0
endlayer

layer
0,0,0,0,0,0,0,0,0,0,0,0,0,0,0,0,0,0,0,0,0
0,0,0,0,0,0,0,0,0,2,2,2,0,0,0,0,0,0,0,0,0
0,0,0,0,0,0,0,0,0,2,0,2,0,0,0,0,0,0,0,0,0
0,0,0,0,0,0,0,0,0,2,2,2,0,0,0,0,0,0,0,0,0
0,0,0,0,0,0,0,0,0,0,0,0,0,0,0,0,0,0,0,0,0
0,0,0,0,0,0,0,0,0,0,0,0,0,0,0,0,0,0,0,0,0
0,0,0,0,0,0,0,0,1,1,35,1,1,0,0,0,0,0,0,0,0
0,0,0,0,0,0,0,1,17,17,0,60,17,1,0,0,0,0,0,0,0
0,0,0,0,0,0,1,24,0,0,0,0,0,56,1,0,0,55,34,55,0
0,0,29,0,0,0,1,12,0,0,0,0,0,61,55,35,55,0,0,0,55
0,31,2,30,0,0,35,25,0,0,17,0,0,17,0,17,17,0,0,0,34
0,0,32,0,0,0,1,0,0,0,0,0,0,17,1,35,55,48,0,20,55
0,0,0,0,0,0,1,17,0,0,0,0,0,17,1,0,0,55,34,55,0
0,0,0,0,0,0,0,1,17,0,0,17,17,1,0,0,0,0,0,0,0
0,0,0,0,0,0,0,0,1,1,35,1,1,0,0,0,0,0,0,0,0
0,0,0,0,0,0,0,0,0,0,0,0,0,0,0,0,0,0,0,0,0
0,0,0,0,0,0,0,0,0,0,0,0,0,0,0,0,0,0,0,0,0
0,0,0,0,0,0,0,0,0,0,0,0,0,0,0,0,0,0,0,0,0
0,0,0,0,0,0,0,0,0,0,0,0,0,0,0,0,0,0,0,0,0
0,0,0,0,0,0,0,0,0,0,0,0,0,0,0,0,0,0,0,0,0
0,0,0,0,0,0,0,0,0,0,0,0,0,0,0,0,0,0,0,0,0
endlayer

layer
0,0,0,0,0,0,0,0,0,0,0,0,0,0,0,0,0,0,0,0,0
0,0,0,0,0,0,0,0,0,0,45,0,0,0,0,0,0,0,0,0,0
0,0,0,0,0,0,0,0,0,38,2,37,0,0,0,0,0,0,0,0,0
0,0,0,0,0,0,0,0,0,0,8,0,0,0,0,0,0,0,0,0,0
0,0,0,0,0,0,0,0,0,0,0,0,0,0,0,0,0,0,0,0,0
0,0,0,0,0,0,0,0,0,0,0,0,0,0,0,0,0,0,0,0,0
0,0,0,0,0,0,0,0,1,1,35,1,1,0,0,0,0,0,0,0,0
0,0,0,0,0,0,0,1,24,17,0,17,17,1,0,0,0,0,0,0,0
0,0,0,0,0,0,1,25,12,0,0,0,0,17,1,0,0,55,34,55,0
0,0,2,0,0,0,1,0,0,0,0,0,0,17,1,35,55,17,0,17,55
0,2,2,2,0,0,35,0,0,0,62,0,0,0,35,0,17,0,0,0,34
0,0,2,0,0,0,1,17,0,0,0,0,0,17,1,35,55,17,0,17,55
0,0,0,0,0,0,1,0,0,0,0,0,0,17,1,0,0,55,34,55,0
0,0,0,0,0,0,0,1,0,0,0,17,17,1,0,0,0,0,0,0,0
0,0,0,0,0,0,0,0,1,1,35,1,1,0,0,0,0,0,0,0,0
0,0,0,0,0,0,0,0,0,0,0,0,0,0,0,0,0,0,0,0,0
0,0,0,0,0,0,0,0,0,0,0,0,0,0,0,0,0,0,0,0,0
0,0,0,0,0,0,0,0,0,0,0,0,0,0,0,0,0,0,0,0,0
0,0,0,0,0,0,0,0,0,0,0,0,0,0,0,0,0,0,0,0,0
0,0,0,0,0,0,0,0,0,0,0,0,0,0,0,0,0,0,0,0,0
0,0,0,0,0,0,0,0,0,0,0,0,0,0,0,0,0,0,0,0,0
endlayer

layer
0,0,0,0,0,0,0,0,0,0,0,0,0,0,0,0,0,0,0,0,0
0,0,0,0,0,0,0,0,0,0,0,0,0,0,0,0,0,0,0,0,0
0,0,0,0,0,0,0,0,0,0,2,0,0,0,0,0,0,0,0,0,0
0,0,0,0,0,0,0,0,0,0,0,0,0,0,0,0,0,0,0,0,0
0,0,0,0,0,0,0,0,0,0,0,0,0,0,0,0,0,0,0,0,0
0,0,0,0,0,0,0,0,0,0,0,0,0,0,0,0,0,0,0,0,0
0,0,0,0,0,0,0,0,1,1,23,1,1,0,0,0,0,0,0,0,0
0,0,0,0,0,0,0,1,25,12,24,17,17,1,0,0,0,0,0,0,0
0,0,29,0,0,0,1,0,0,0,0,0,0,17,1,0,0,55,23,55,0
0,2,2,2,0,0,1,0,0,0,0,0,0,0,1,45,55,17,17,17,55
31,2,2,64,30,0,23,17,0,0,63,0,0,17,23,2,23,0,0,0,23
0,2,2,2,0,0,1,17,0,0,0,0,0,17,1,8,55,17,17,17,55
0,0,32,0,0,0,1,17,0,0,17,17,0,17,1,0,0,55,23,55,0
0,0,0,0,0,0,0,1,17,17,17,17,17,1,0,0,0,0,0,0,0
0,0,0,0,0,0,0,0,1,1,23,1,1,0,0,0,0,0,0,0,0
0,0,0,0,0,0,0,0,0,0,0,0,0,0,0,0,0,0,0,0,0
0,0,0,0,0,0,0,0,0,0,0,0,0,0,0,0,0,0,0,0,0
0,0,0,0,0,0,0,0,0,0,0,0,0,0,0,0,0,0,0,0,0
0,0,0,0,0,0,0,0,0,0,0,0,0,0,0,0,0,0,0,0,0
0,0,0,0,0,0,0,0,0,0,0,0,0,0,0,0,0,0,0,0,0
0,0,0,0,0,0,0,0,0,0,0,0,0,0,0,0,0,0,0,0,0
endlayer

layer
0,0,0,0,0,0,0,0,0,0,0,0,0,0,0,0,0,0,0,0,0
0,0,0,0,0,0,0,0,0,0,0,0,0,0,0,0,0,0,0,0,0
0,0,0,0,0,0,0,0,0,0,50,0,0,0,0,0,0,0,0,0,0
0,0,0,0,0,0,0,0,0,0,0,0,0,0,0,0,0,0,0,0,0
0,0,0,0,0,0,0,0,0,0,0,0,0,0,0,0,0,0,0,0,0
0,0,0,0,0,0,0,0,0,0,0,0,0,0,0,0,0,0,0,0,0
0,0,0,0,0,0,0,0,1,1,1,1,1,0,0,0,0,0,0,0,0
0,0,0,0,0,0,0,1,0,0,25,2,2,1,0,0,0,0,0,0,0
0,2,2,2,0,0,1,0,0,2,2,2,2,2,1,0,0,2,2,2,0
2,2,2,2,2,2,1,0,2,2,2,2,2,2,1,0,2,2,17,2,2
2,2,2,2,2,2,2,2,2,2,2,2,2,2,1,0,2,17,0,17,2
2,2,2,2,2,2,1,2,2,2,2,2,2,2,1,0,2,2,17,2,2
0,2,2,2,0,0,1,2,2,2,2,2,2,2,1,0,0,2,2,2,0
0,0,0,0,0,0,0,1,2,2,2,2,2,1,0,0,0,0,0,0,0
0,0,0,0,0,0,0,0,1,1,1,1,1,0,0,0,0,0,0,0,0
0,0,0,0,0,0,0,0,0,0,0,0,0,0,0,0,0,0,0,0,0
0,0,0,0,0,0,0,0,0,0,0,0,0,0,0,0,0,0,0,0,0
0,0,0,0,0,0,0,0,0,0,0,0,0,0,0,0,0,0,0,0,0
0,0,0,0,0,0,0,0,0,0,0,0,0,0,0,0,0,0,0,0,0
0,0,0,0,0,0,0,0,0,0,0,0,0,0,0,0,0,0,0,0,0
0,0,0,0,0,0,0,0,0,0,0,0,0,0,0,0,0,0,0,0,0
endlayer

layer
0,0,0,0,0,0,0,0,0,0,0,0,0,0,0,0,0,0,0,0,0
0,0,0,0,0,0,0,0,0,0,0,0,0,0,0,0,0,0,0,0,0
0,0,0,0,0,0,0,0,0,0,36,0,0,0,0,0,0,0,0,0,0
0,0,0,0,0,0,0,0,0,0,0,0,0,0,0,0,0,0,0,0,0
0,0,0,0,0,0,0,0,0,0,0,0,0,0,0,0,0,0,0,0,0
0,0,0,0,0,0,0,0,0,3,3,3,0,0,0,0,0,0,0,0,0
0,0,0,0,0,0,0,0,1,1,23,1,1,0,0,0,0,0,0,0,0
0,0,0,0,0,0,0,1,0,0,0,0,17,1,0,0,0,0,0,0,0
0,55,23,55,0,0,1,0,0,65,66,65,0,25,1,0,0,0,45,0,0
55,17,0,67,55,35,1,0,65,66,65,66,65,12,1,3,0,2,2,2,0
23,0,0,65,17,17,17,0,66,65,66,65,66,24,23,3,38,2,0,2,37
55,0,17,9,55,35,1,0,65,66,65,66,65,0,1,3,0,2,2,2,0
0,55,23,55,0,0,1,0,0,65,66,65,0,0,1,0,0,0,8,0,0
0,0,0,0,0,0,0,1,0,0,0,0,0,1,0,0,0,0,0,0,0
0,0,0,0,0,0,0,0,1,1,23,1,1,0,0,0,0,0,0,0,0
0,0,0,0,0,0,0,0,0,3,3,3,0,0,0,0,0,0,0,0,0
0,0,0,0,0,0,0,0,0,0,0,0,0,0,0,0,0,0,0,0,0
0,0,0,0,0,0,0,0,0,0,0,0,0,0,0,0,0,0,0,0,0
0,0,0,0,0,0,0,0,0,0,2,0,0,0,0,0,0,0,0,0,0
0,0,0,0,0,0,0,0,0,0,0,0,0,0,0,0,0,0,0,0,0
0,0,0,0,0,0,0,0,0,0,0,0,0,0,0,0,0,0,0,0,0
endlayer

layer
0,0,0,0,0,0,0,0,0,0,0,0,0,0,0,0,0,0,0,0,0
0,0,0,0,0,0,0,0,0,0,0,0,0,0,0,0,0,0,0,0,0
0,0,0,0,0,0,0,0,0,0,0,0,0,0,0,0,0,0,0,0,0
0,0,0,0,0,0,0,0,0,0,0,0,0,0,0,0,0,0,0,0,0
0,0,0,0,0,0,0,0,0,0,0,0,0,0,0,0,0,0,0,0,0
0,0,0,0,0,0,0,0,0,0,0,0,0,0,0,0,0,0,0,0,0
0,0,0,0,0,0,0,0,1,1,35,1,1,0,0,0,0,0,0,0,0
0,0,0,0,0,0,0,1,0,0,0,0,17,1,0,0,0,0,0,0,0
0,55,34,55,0,0,1,0,0,0,0,0,0,0,1,0,0,0,0,0,0
55,17,0,0,55,35,1,0,0,0,0,0,0,17,1,0,0,2,2,2,0
34,48,0,0,17,0,17,0,0,0,0,0,0,25,35,0,0,2,0,2,0
55,17,0,0,55,35,1,0,0,0,0,0,0,12,1,0,0,2,2,2,0
0,55,34,55,0,0,1,0,0,0,0,0,0,24,1,0,0,0,0,0,0
0,0,0,0,0,0,0,1,0,0,0,0,0,1,0,0,0,0,0,0,0
0,0,0,0,0,0,0,0,1,1,35,1,1,0,0,0,0,0,0,0,0
0,0,0,0,0,0,0,0,0,0,0,0,0,0,0,0,0,0,0,0,0
0,0,0,0,0,0,0,0,0,0,0,0,0,0,0,0,0,0,0,0,0
0,0,0,0,0,0,0,0,0,0,29,0,0,0,0,0,0,0,0,0,0
0,0,0,0,0,0,0,0,0,31,2,30,0,0,0,0,0,0,0,0,0
0,0,0,0,0,0,0,0,0,0,32,0,0,0,0,0,0,0,0,0,0
0,0,0,0,0,0,0,0,0,0,0,0,0,0,0,0,0,0,0,0,0
endlayer

layer
0,0,0,0,0,0,0,0,0,0,0,0,0,0,0,0,0,0,0,0,0
0,0,0,0,0,0,0,0,0,0,0,0,0,0,0,0,0,0,0,0,0
0,0,0,0,0,0,0,0,0,0,0,0,0,0,0,0,0,0,0,0,0
0,0,0,0,0,0,0,0,0,0,0,0,0,0,0,0,0,0,0,0,0
0,0,0,0,0,0,0,0,0,0,0,0,0,0,0,0,0,0,0,0,0
0,0,0,0,0,0,0,0,0,0,0,0,0,0,0,0,0,0,0,0,0
0,0,0,0,0,0,0,0,1,1,35,1,1,0,0,0,0,0,0,0,0
0,0,0,0,0,0,0,1,17,0,0,0,17,1,0,0,0,0,0,0,0
0,55,34,55,0,0,1,17,0,0,0,0,17,17,1,0,0,0,0,0,0
55,0,0,0,55,35,1,0,0,0,0,0,17,17,1,0,0,0,45,0,0
34,0,0,0,17,0,17,0,0,0,62,0,0,0,35,0,0,38,2,37,0
55,17,0,0,55,35,1,0,0,0,0,0,0,17,1,0,0,0,8,0,0
0,55,34,55,0,0,1,17,0,0,0,0,12,25,1,0,0,0,0,0,0
0,0,0,0,0,0,0,1,17,0,0,0,24,1,0,0,0,0,0,0,0
0,0,0,0,0,0,0,0,1,1,35,1,1,0,0,0,0,0,0,0,0
0,0,0,0,0,0,0,0,0,0,0,0,0,0,0,0,0,0,0,0,0
0,0,0,0,0,0,0,0,0,0,0,0,0,0,0,0,0,0,0,0,0
0,0,0,0,0,0,0,0,0,0,2,0,0,0,0,0,0,0,0,0,0
0,0,0,0,0,0,0,0,0,2,2,2,0,0,0,0,0,0,0,0,0
0,0,0,0,0,0,0,0,0,0,2,0,0,0,0,0,0,0,0,0,0
0,0,0,0,0,0,0,0,0,0,0,0,0,0,0,0,0,0,0,0,0
endlayer

layer
0,0,0,0,0,0,0,0,0,0,0,0,0,0,0,0,0,0,0,0,0
0,0,0,0,0,0,0,0,0,0,0,0,0,0,0,0,0,0,0,0,0
0,0,0,0,0,0,0,0,0,0,0,0,0,0,0,0,0,0,0,0,0
0,0,0,0,0,0,0,0,0,0,0,0,0,0,0,0,0,0,0,0,0
0,0,0,0,0,0,0,0,0,0,0,0,0,0,0,0,0,0,0,0,0
0,0,0,0,0,0,0,0,0,0,0,0,0,0,0,0,0,0,0,0,0
0,0,0,0,0,0,0,0,1,1,23,1,1,0,0,0,0,0,0,0,0
0,0,0,0,0,0,0,1,17,17,17,17,17,1,0,0,0,0,0,0,0
0,55,55,55,0,0,1,17,0,0,0,0,0,0,1,0,0,0,0,0,0
55,17,0,0,55,45,1,17,0,0,17,0,0,0,1,0,0,0,0,0,0
55,17,0,0,23,2,23,0,0,0,63,0,0,17,23,0,0,0,2,0,0
55,17,0,0,55,8,1,17,0,0,0,0,0,0,1,0,0,0,0,0,0
0,55,55,55,0,0,1,17,0,0,0,0,0,17,1,0,0,0,0,0,0
0,0,0,0,0,0,0,1,17,17,24,12,25,1,0,0,0,0,0,0,0
0,0,0,0,0,0,0,0,1,1,23,1,1,0,0,0,0,0,0,0,0
0,0,0,0,0,0,0,0,0,0,0,0,0,0,0,0,0,0,0,0,0
0,0,0,0,0,0,0,0,0,0,29,0,0,0,0,0,0,0,0,0,0
0,0,0,0,0,0,0,0,0,2,2,2,0,0,0,0,0,0,0,0,0
0,0,0,0,0,0,0,0,31,2,2,2,30,0,0,0,0,0,0,0,0
0,0,0,0,0,0,0,0,0,2,2,2,0,0,0,0,0,0,0,0,0
0,0,0,0,0,0,0,0,0,0,32,0,0,0,0,0,0,0,0,0,0
endlayer

layer
0,0,0,0,0,0,0,0,0,0,0,0,0,0,0,0,0,0,0,0,0
0,0,0,0,0,0,0,0,0,0,0,0,0,0,0,0,0,0,0,0,0
0,0,0,0,0,0,0,0,0,0,0,0,0,0,0,0,0,0,0,0,0
0,0,0,0,0,0,0,0,0,0,0,0,0,0,0,0,0,0,0,0,0
0,0,0,0,0,0,0,0,0,0,0,0,0,0,0,0,0,0,0,0,0
0,0,0,0,0,0,0,0,0,0,0,0,0,0,0,0,0,0,0,0,0
0,0,0,0,0,0,0,0,1,1,1,1,1,0,0,0,0,0,0,0,0
0,0,0,0,0,0,0,1,2,2,2,2,2,1,0,0,0,0,0,0,0
0,2,2,2,0,0,1,2,2,2,2,2,2,2,1,0,0,0,0,0,0
2,2,0,2,2,0,1,2,2,2,2,2,2,2,1,0,0,0,0,0,0
2,0,0,0,2,0,1,2,2,2,2,2,2,2,1,0,0,0,50,0,0
2,2,17,2,2,0,1,2,2,2,2,2,2,17,1,0,0,0,0,0,0
0,2,2,2,0,0,1,2,2,2,2,2,17,17,1,0,0,0,0,0,0
0,0,0,0,0,0,0,1,2,2,25,0,0,1,0,0,0,0,0,0,0
0,0,0,0,0,0,0,0,1,1,2,1,1,0,0,0,0,0,0,0,0
0,0,0,0,0,0,0,0,0,2,2,2,0,0,0,0,0,0,0,0,0
0,0,0,0,0,0,0,0,0,2,2,2,0,0,0,0,0,0,0,0,0
0,0,0,0,0,0,0,0,2,2,2,2,2,0,0,0,0,0,0,0,0
0,0,0,0,0,0,0,0,2,2,64,2,2,0,0,0,0,0,0,0,0
0,0,0,0,0,0,0,0,2,2,2,2,2,0,0,0,0,0,0,0,0
0,0,0,0,0,0,0,0,0,2,2,2,0,0,0,0,0,0,0,0,0
endlayer

layer
0,0,0,0,0,0,0,0,0,0,0,0,0,0,0,0,0,0,0,0,0
0,0,0,0,0,0,0,0,0,0,0,0,0,0,0,0,0,0,0,0,0
0,0,0,0,0,0,0,0,0,0,2,0,0,0,0,0,0,0,0,0,0
0,0,0,0,0,0,0,0,0,0,0,0,0,0,0,0,0,0,0,0,0
0,0,0,0,0,0,0,0,0,0,0,0,0,0,0,0,0,0,0,0,0
0,0,0,0,0,0,0,0,0,3,3,3,0,0,0,0,0,0,0,0,0
0,0,0,0,0,0,0,0,1,1,23,1,1,0,0,0,0,0,0,0,0
0,0,0,0,0,0,0,1,17,0,17,0,17,1,0,0,0,0,0,0,0
0,0,45,0,0,0,1,17,17,0,0,0,0,17,1,0,0,0,0,0,0
0,2,2,2,0,3,1,22,17,68,68,68,0,17,1,3,0,0,0,0,0
38,2,0,2,37,3,23,24,17,68,13,68,0,0,23,3,0,0,36,0,0
0,2,2,2,0,3,1,12,0,68,68,68,0,0,1,3,0,0,0,0,0
0,0,8,0,0,0,1,25,0,0,0,0,0,0,1,0,0,0,0,0,0
0,0,0,0,0,0,0,1,17,0,0,0,0,1,0,0,0,0,0,0,0
0,0,0,0,0,0,0,0,1,1,17,1,1,0,0,0,0,0,0,0,0
0,0,0,0,0,0,0,0,0,35,0,35,0,0,0,0,0,0,0,0,0
0,0,0,0,0,0,0,0,0,1,17,1,0,0,0,0,0,0,0,0,0
0,0,0,0,0,0,0,0,1,0,0,17,1,0,0,0,0,0,0,0,0
0,0,0,0,0,0,0,0,23,0,20,0,23,0,0,0,0,0,0,0,0
0,0,0,0,0,0,0,0,1,44,69,44,1,0,0,0,0,0,0,0,0
0,0,0,0,0,0,0,0,0,1,23,1,0,0,0,0,0,0,0,0,0
endlayer

layer
0,0,0,0,0,0,0,0,0,0,0,0,0,0,0,0,0,0,0,0,0
0,0,0,0,0,0,0,0,0,0,29,0,0,0,0,0,0,0,0,0,0
0,0,0,0,0,0,0,0,0,31,2,30,0,0,0,0,0,0,0,0,0
0,0,0,0,0,0,0,0,0,0,32,0,0,0,0,0,0,0,0,0,0
0,0,0,0,0,0,0,0,0,0,0,0,0,0,0,0,0,0,0,0,0
0,0,0,0,0,0,0,0,0,0,0,0,0,0,0,0,0,0,0,0,0
0,0,0,0,0,0,0,0,1,1,35,1,1,0,0,0,0,0,0,0,0
0,0,0,0,0,0,0,1,17,0,0,0,17,1,0,0,0,0,0,0,0
0,0,0,0,0,0,1,24,17,0,0,0,0,17,1,0,0,0,0,0,0
0,2,2,2,0,0,1,12,17,68,68,68,0,0,1,0,0,0,0,0,0
0,2,0,2,0,0,35,25,0,68,13,68,0,0,35,0,0,0,0,0,0
0,2,2,2,0,0,1,17,0,68,68,68,0,0,1,0,0,0,0,0,0
0,0,0,0,0,0,1,17,0,0,0,0,0,0,1,0,0,0,0,0,0
0,0,0,0,0,0,0,1,17,0,0,0,0,1,0,0,0,0,0,0,0
0,0,0,0,0,0,0,0,1,1,17,1,1,0,0,0,0,0,0,0,0
0,0,0,0,0,0,0,0,0,35,0,35,0,0,0,0,0,0,0,0,0
0,0,0,0,0,0,0,0,0,1,0,1,0,0,0,0,0,0,0,0,0
0,0,0,0,0,0,0,0,1,0,0,17,1,0,0,0,0,0,0,0,0
0,0,0,0,0,0,0,0,34,0,0,0,34,0,0,0,0,0,0,0,0
0,0,0,0,0,0,0,0,1,44,0,44,1,0,0,0,0,0,0,0,0
0,0,0,0,0,0,0,0,0,1,34,1,0,0,0,0,0,0,0,0,0
endlayer

layer
0,0,0,0,0,0,0,0,0,0,0,0,0,0,0,0,0,0,0,0,0
0,0,0,0,0,0,0,0,0,0,2,0,0,0,0,0,0,0,0,0,0
0,0,0,0,0,0,0,0,0,2,2,2,0,0,0,0,0,0,0,0,0
0,0,0,0,0,0,0,0,0,0,2,0,0,0,0,0,0,0,0,0,0
0,0,0,0,0,0,0,0,0,0,0,0,0,0,0,0,0,0,0,0,0
0,0,0,0,0,0,0,0,0,0,0,0,0,0,0,0,0,0,0,0,0
0,0,0,0,0,0,0,0,1,1,35,1,1,0,0,0,0,0,0,0,0
0,0,0,0,0,0,0,1,24,0,0,17,17,1,0,0,0,0,0,0,0
0,0,0,0,0,0,1,25,12,0,0,0,0,17,1,0,0,0,0,0,0
0,0,45,0,0,0,1,17,0,68,68,68,0,0,1,0,0,0,0,0,0
0,38,2,37,0,0,35,0,0,68,13,68,0,0,35,0,0,0,0,0,0
0,0,8,0,0,0,1,17,0,68,68,68,0,0,1,0,0,0,0,0,0
0,0,0,0,0,0,1,17,0,0,0,0,0,17,1,0,0,0,0,0,0
0,0,0,0,0,0,0,1,17,0,0,0,17,1,0,0,0,0,0,0,0
0,0,0,0,0,0,0,0,1,1,17,1,1,0,0,0,0,0,0,0,0
0,0,0,0,0,0,0,0,0,35,17,35,0,0,0,0,0,0,0,0,0
0,0,0,0,0,0,0,0,0,1,17,1,0,0,0,0,0,0,0,0,0
0,0,0,0,0,0,0,0,1,17,0,17,1,0,0,0,0,0,0,0,0
0,0,0,0,0,0,0,0,34,0,0,0,34,0,0,0,0,0,0,0,0
0,0,0,0,0,0,0,0,1,44,0,44,1,0,0,0,0,0,0,0,0
0,0,0,0,0,0,0,0,0,1,34,1,0,0,0,0,0,0,0,0,0
endlayer

layer
0,0,0,0,0,0,0,0,0,0,29,0,0,0,0,0,0,0,0,0,0
0,0,0,0,0,0,0,0,0,2,2,2,0,0,0,0,0,0,0,0,0
0,0,0,0,0,0,0,0,31,2,2,2,30,0,0,0,0,0,0,0,0
0,0,0,0,0,0,0,0,0,2,2,2,0,0,0,0,0,0,0,0,0
0,0,0,0,0,0,0,0,0,0,32,0,0,0,0,0,0,0,0,0,0
0,0,0,0,0,0,0,0,0,0,0,0,0,0,0,0,0,0,0,0,0
0,0,0,0,0,0,0,0,1,1,35,1,1,0,0,0,0,0,0,0,0
0,0,0,0,0,0,0,1,25,12,24,17,17,1,0,0,0,0,0,0,0
0,0,0,0,0,0,1,17,0,0,17,0,0,17,1,0,0,0,0,0,0
0,0,0,0,0,0,1,0,0,68,68,68,0,17,1,0,0,0,0,0,0
0,0,2,0,0,0,23,17,0,68,13,68,0,17,23,0,0,0,0,0,0
0,0,0,0,0,0,1,17,0,68,68,68,0,17,1,0,0,0,0,0,0
0,0,0,0,0,0,1,17,17,0,0,0,0,17,1,0,0,0,0,0,0
0,0,0,0,0,0,0,1,17,17,0,17,17,1,0,0,0,0,0,0,0
0,0,0,0,0,0,0,0,1,1,23,1,1,0,0,0,0,0,0,0,0
0,0,0,0,0,0,0,0,0,38,2,37,0,0,0,0,0,0,0,0,0
0,0,0,0,0,0,0,0,0,1,23,1,0,0,0,0,0,0,0,0,0
0,0,0,0,0,0,0,0,1,17,0,17,1,0,0,0,0,0,0,0,0
0,0,0,0,0,0,0,0,23,0,0,0,23,0,0,0,0,0,0,0,0
0,0,0,0,0,0,0,0,1,44,0,44,1,0,0,0,0,0,0,0,0
0,0,0,0,0,0,0,0,0,1,23,1,0,0,0,0,0,0,0,0,0
endlayer

layer
0,0,0,0,0,0,0,0,0,2,2,2,0,0,0,0,0,0,0,0,0
0,0,0,0,0,0,0,0,2,2,2,2,2,0,0,0,0,0,0,0,0
0,0,0,0,0,0,0,0,2,2,2,2,2,0,0,0,0,0,0,0,0
0,0,0,0,0,0,0,0,2,2,2,2,2,0,0,0,0,0,0,0,0
0,0,0,0,0,0,0,0,0,2,2,2,0,0,0,0,0,0,0,0,0
0,0,0,0,0,0,0,0,0,2,2,2,0,0,0,0,0,0,0,0,0
0,0,0,0,0,0,0,0,1,1,2,1,1,0,0,0,0,0,0,0,0
0,0,0,0,0,0,0,1,17,0,25,2,2,1,0,0,0,0,0,0,0
0,0,0,0,0,0,1,17,0,2,2,2,2,2,1,0,0,0,0,0,0
0,0,0,0,0,0,1,0,2,2,2,2,2,2,1,0,0,0,0,0,0
0,0,50,0,0,0,1,2,2,2,70,2,2,2,1,0,0,0,0,0,0
0,0,0,0,0,0,1,2,2,2,2,2,2,2,1,0,0,0,0,0,0
0,0,0,0,0,0,1,2,2,2,2,2,2,2,1,0,0,0,0,0,0
0,0,0,0,0,0,0,1,2,2,2,2,2,1,0,0,0,0,0,0,0
0,0,0,0,0,0,0,0,1,1,1,1,1,0,0,0,0,0,0,0,0
0,0,0,0,0,0,0,0,0,0,0,0,0,0,0,0,0,0,0,0,0
0,0,0,0,0,0,0,0,0,2,2,2,0,0,0,0,0,0,0,0,0
0,0,0,0,0,0,0,0,2,2,0,2,2,0,0,0,0,0,0,0,0
0,0,0,0,0,0,0,0,2,0,0,0,2,0,0,0,0,0,0,0,0
0,0,0,0,0,0,0,0,2,2,0,2,2,0,0,0,0,0,0,0,0
0,0,0,0,0,0,0,0,0,2,2,2,0,0,0,0,0,0,0,0,0
endlayer

layer
0,0,0,0,0,0,0,0,0,1,23,1,0,0,0,0,0,0,0,0,0
0,0,0,0,0,0,0,0,1,17,71,17,1,0,0,0,0,0,0,0,0
0,0,0,0,0,0,0,0,23,17,0,0,23,0,0,0,0,0,0,0,0
0,0,0,0,0,0,0,0,1,0,0,0,1,0,0,0,0,0,0,0,0
0,0,0,0,0,0,0,0,0,1,17,1,0,0,0,0,0,0,0,0,0
0,0,0,0,0,0,0,0,0,35,17,35,0,0,0,0,0,0,0,0,0
0,0,0,0,0,0,0,0,1,1,17,1,1,0,0,0,0,0,0,0,0
0,0,0,0,0,0,0,1,17,0,17,0,0,1,0,0,0,0,0,0,0
0,0,0,0,0,0,1,17,0,17,0,0,0,25,1,0,0,0,0,0,0
0,0,0,0,0,3,1,0,0,74,73,72,0,12,1,3,0,0,0,0,0
0,0,36,0,0,3,23,0,0,75,63,75,0,24,23,3,0,0,2,0,0
0,0,0,0,0,3,1,0,0,77,73,76,0,17,1,3,0,0,0,0,0
0,0,0,0,0,0,1,17,0,0,0,0,0,17,1,0,0,0,0,0,0
0,0,0,0,0,0,0,1,17,0,0,0,17,1,0,0,0,0,0,0,0
0,0,0,0,0,0,0,0,1,1,23,1,1,0,0,0,0,0,0,0,0
0,0,0,0,0,0,0,0,0,3,3,3,0,0,0,0,0,0,0,0,0
0,0,0,0,0,0,0,0,0,0,45,0,0,0,0,0,0,0,0,0,0
0,0,0,0,0,0,0,0,0,2,2,2,0,0,0,0,0,0,0,0,0
0,0,0,0,0,0,0,0,38,2,0,2,37,0,0,0,0,0,0,0,0
0,0,0,0,0,0,0,0,0,2,2,2,0,0,0,0,0,0,0,0,0
0,0,0,0,0,0,0,0,0,0,8,0,0,0,0,0,0,0,0,0,0
endlayer

layer
0,0,0,0,0,0,0,0,0,1,34,1,0,0,0,0,0,0,0,0,0
0,0,0,0,0,0,0,0,1,0,0,17,1,0,0,0,0,0,0,0,0
0,0,0,0,0,0,0,0,34,0,0,0,34,0,0,0,0,0,0,0,0
0,0,0,0,0,0,0,0,1,48,0,0,1,0,0,0,0,0,0,0,0
0,0,0,0,0,0,0,0,0,1,0,1,0,0,0,0,0,0,0,0,0
0,0,0,0,0,0,0,0,0,35,17,35,0,0,0,0,0,0,0,0,0
0,0,0,0,0,0,0,0,1,1,17,1,1,0,0,0,0,0,0,0,0
0,0,0,0,0,0,0,1,0,0,0,0,17,1,0,0,0,0,0,0,0
0,0,0,0,0,0,1,17,0,0,0,0,0,0,1,0,0,0,0,0,0
0,0,0,0,0,0,1,0,0,0,17,0,0,0,1,0,0,0,29,0,0
0,0,0,0,0,0,35,0,0,0,40,0,0,25,35,0,0,31,2,30,0
0,0,0,0,0,0,1,17,0,0,0,0,0,12,1,0,0,0,32,0,0
0,0,0,0,0,0,1,17,0,0,0,0,17,24,1,0,0,0,0,0,0
0,0,0,0,0,0,0,1,17,0,0,0,17,1,0,0,0,0,0,0,0
0,0,0,0,0,0,0,0,1,1,35,1,1,0,0,0,0,0,0,0,0
0,0,0,0,0,0,0,0,0,0,0,0,0,0,0,0,0,0,0,0,0
0,0,0,0,0,0,0,0,0,0,0,0,0,0,0,0,0,0,0,0,0
0,0,0,0,0,0,0,0,0,2,2,2,0,0,0,0,0,0,0,0,0
0,0,0,0,0,0,0,0,0,2,0,2,0,0,0,0,0,0,0,0,0
0,0,0,0,0,0,0,0,0,2,2,2,0,0,0,0,0,0,0,0,0
0,0,0,0,0,0,0,0,0,0,0,0,0,0,0,0,0,0,0,0,0
endlayer

layer
0,0,0,0,0,0,0,0,0,1,34,1,0,0,0,0,0,0,0,0,0
0,0,0,0,0,0,0,0,1,0,0,17,1,0,0,0,0,0,0,0,0
0,0,0,0,0,0,0,0,34,0,0,0,34,0,0,0,0,0,0,0,0
0,0,0,0,0,0,0,0,1,0,0,0,1,0,0,0,0,0,0,0,0
0,0,0,0,0,0,0,0,0,1,17,1,0,0,0,0,0,0,0,0,0
0,0,0,0,0,0,0,0,0,35,17,35,0,0,0,0,0,0,0,0,0
0,0,0,0,0,0,0,0,1,1,17,1,1,0,0,0,0,0,0,0,0
0,0,0,0,0,0,0,1,17,17,0,0,17,1,0,0,0,0,0,0,0
0,0,0,0,0,0,1,17,0,0,0,0,0,17,1,0,0,0,0,0,0
0,0,0,0,0,0,1,0,0,0,0,0,0,0,1,0,0,0,2,0,0
0,0,0,0,0,0,35,0,0,0,40,0,0,0,35,0,0,2,2,2,0
0,0,0,0,0,0,1,17,0,0,0,0,0,0,1,0,0,0,2,0,0
0,0,0,0,0,0,1,17,0,0,0,0,12,25,1,0,0,0,0,0,0
0,0,0,0,0,0,0,1,17,17,0,17,24,1,0,0,0,0,0,0,0
0,0,0,0,0,0,0,0,1,1,35,1,1,0,0,0,0,0,0,0,0
0,0,0,0,0,0,0,0,0,0,0,0,0,0,0,0,0,0,0,0,0
0,0,0,0,0,0,0,0,0,0,0,0,0,0,0,0,0,0,0,0,0
0,0,0,0,0,0,0,0,0,0,45,0,0,0,0,0,0,0,0,0,0
0,0,0,0,0,0,0,0,0,38,2,37,0,0,0,0,0,0,0,0,0
0,0,0,0,0,0,0,0,0,0,8,0,0,0,0,0,0,0,0,0,0
0,0,0,0,0,0,0,0,0,0,0,0,0,0,0,0,0,0,0,0,0
endlayer

layer
0,0,0,0,0,0,0,0,0,1,23,1,0,0,0,0,0,0,0,0,0
0,0,0,0,0,0,0,0,1,17,17,17,1,0,0,0,0,0,0,0,0
0,0,0,0,0,0,0,0,23,0,0,17,23,0,0,0,0,0,0,0,0
0,0,0,0,0,0,0,0,1,0,0,0,1,0,0,0,0,0,0,0,0
0,0,0,0,0,0,0,0,0,1,23,1,0,0,0,0,0,0,0,0,0
0,0,0,0,0,0,0,0,0,38,2,37,0,0,0,0,0,0,0,0,0
0,0,0,0,0,0,0,0,1,1,23,1,1,0,0,0,0,0,0,0,0
0,0,0,0,0,0,0,1,17,17,0,0,17,1,0,0,0,0,0,0,0
0,0,0,0,0,0,1,17,17,0,0,0,0,17,1,0,0,0,29,0,0
0,0,0,0,0,0,1,17,0,0,35,0,0,0,1,0,0,2,2,2,0
0,0,0,0,0,0,23,17,0,35,40,35,0,0,23,0,31,2,2,2,30
0,0,0,0,0,0,1,17,17,0,35,0,0,0,1,0,0,2,2,2,0
0,0,0,0,0,0,1,17,0,0,0,0,0,17,1,0,0,0,32,0,0
0,0,0,0,0,0,0,1,17,17,24,12,25,1,0,0,0,0,0,0,0
0,0,0,0,0,0,0,0,1,1,23,1,1,0,0,0,0,0,0,0,0
0,0,0,0,0,0,0,0,0,0,0,0,0,0,0,0,0,0,0,0,0
0,0,0,0,0,0,0,0,0,0,0,0,0,0,0,0,0,0,0,0,0
0,0,0,0,0,0,0,0,0,0,0,0,0,0,0,0,0,0,0,0,0
0,0,0,0,0,0,0,0,0,0,2,0,0,0,0,0,0,0,0,0,0
0,0,0,0,0,0,0,0,0,0,0,0,0,0,0,0,0,0,0,0,0
0,0,0,0,0,0,0,0,0,0,0,0,0,0,0,0,0,0,0,0,0
endlayer

layer
0,0,0,0,0,0,0,0,0,2,2,2,0,0,0,0,0,0,0,0,0
0,0,0,0,0,0,0,0,2,2,0,2,2,0,0,0,0,0,0,0,0
0,0,0,0,0,0,0,0,2,0,0,0,2,0,0,0,0,0,0,0,0
0,0,0,0,0,0,0,0,2,2,0,2,2,0,0,0,0,0,0,0,0
0,0,0,0,0,0,0,0,0,2,2,2,0,0,0,0,0,0,0,0,0
0,0,0,0,0,0,0,0,0,0,0,0,0,0,0,0,0,0,0,0,0
0,0,0,0,0,0,0,0,1,1,1,1,1,0,0,0,0,0,0,0,0
0,0,0,0,0,0,0,1,2,2,2,2,2,1,0,0,0,0,0,0,0
0,0,0,0,0,0,1,2,2,2,2,2,2,2,1,0,0,2,2,2,0
0,0,0,0,0,0,1,2,2,2,2,2,2,2,1,2,2,2,2,2,2
0,0,0,0,0,0,1,2,2,2,2,2,2,2,2,2,2,2,2,2,2
0,0,0,0,0,0,1,2,2,2,2,2,2,17,1,2,2,2,2,2,2
0,0,0,0,0,0,1,2,2,2,2,2,0,17,1,0,0,2,2,2,0
0,0,0,0,0,0,0,1,2,2,25,17,17,1,0,0,0,0,0,0,0
0,0,0,0,0,0,0,0,1,1,1,1,1,0,0,0,0,0,0,0,0
0,0,0,0,0,0,0,0,0,0,0,0,0,0,0,0,0,0,0,0,0
0,0,0,0,0,0,0,0,0,0,0,0,0,0,0,0,0,0,0,0,0
0,0,0,0,0,0,0,0,0,0,0,0,0,0,0,0,0,0,0,0,0
0,0,0,0,0,0,0,0,0,0,50,0,0,0,0,0,0,0,0,0,0
0,0,0,0,0,0,0,0,0,0,0,0,0,0,0,0,0,0,0,0,0
0,0,0,0,0,0,0,0,0,0,0,0,0,0,0,0,0,0,0,0,0
endlayer

layer
0,0,0,0,0,0,0,0,0,0,45,0,0,0,0,0,0,0,0,0,0
0,0,0,0,0,0,0,0,0,2,2,2,0,0,0,0,0,0,0,0,0
0,0,0,0,0,0,0,0,38,2,0,2,37,0,0,0,0,0,0,0,0
0,0,0,0,0,0,0,0,0,2,2,2,0,0,0,0,0,0,0,0,0
0,0,0,0,0,0,0,0,0,0,8,0,0,0,0,0,0,0,0,0,0
0,0,0,0,0,0,0,0,0,3,3,3,0,0,0,0,0,0,0,0,0
0,0,0,0,0,0,0,0,1,1,23,1,1,0,0,0,0,0,0,0,0
0,0,0,0,0,0,0,1,17,17,0,17,17,1,0,0,0,0,0,0,0
0,0,0,0,0,0,1,17,17,0,43,0,0,0,1,0,0,1,23,1,0
0,0,0,0,0,3,1,17,0,74,73,72,0,17,1,35,1,78,78,78,1
0,0,2,0,0,3,23,24,21,75,80,75,19,17,17,0,65,0,0,79,23
0,0,0,0,0,3,1,12,0,77,73,76,0,0,1,35,1,0,78,78,1
0,0,0,0,0,0,1,25,0,0,44,0,0,17,1,0,0,1,23,1,0
0,0,0,0,0,0,0,1,17,0,17,0,17,1,0,0,0,0,0,0,0
0,0,0,0,0,0,0,0,1,1,23,1,1,0,0,0,0,0,0,0,0
0,0,0,0,0,0,0,0,0,3,3,3,0,0,0,0,0,0,0,0,0
0,0,0,0,0,0,0,0,0,0,0,0,0,0,0,0,0,0,0,0,0
0,0,0,0,0,0,0,0,0,0,0,0,0,0,0,0,0,0,0,0,0
0,0,0,0,0,0,0,0,0,0,36,0,0,0,0,0,0,0,0,0,0
0,0,0,0,0,0,0,0,0,0,0,0,0,0,0,0,0,0,0,0,0
0,0,0,0,0,0,0,0,0,0,0,0,0,0,0,0,0,0,0,0,0
endlayer

layer
0,0,0,0,0,0,0,0,0,0,0,0,0,0,0,0,0,0,0,0,0
0,0,0,0,0,0,0,0,0,2,2,2,0,0,0,0,0,0,0,0,0
0,0,0,0,0,0,0,0,0,2,0,2,0,0,0,0,0,0,0,0,0
0,0,0,0,0,0,0,0,0,2,2,2,0,0,0,0,0,0,0,0,0
0,0,0,0,0,0,0,0,0,0,0,0,0,0,0,0,0,0,0,0,0
0,0,0,0,0,0,0,0,0,0,0,0,0,0,0,0,0,0,0,0,0
0,0,0,0,0,0,0,0,1,1,35,1,1,0,0,0,0,0,0,0,0
0,0,0,0,0,0,0,1,17,17,0,0,17,1,0,0,0,0,0,0,0
0,0,0,0,0,0,1,24,0,0,0,0,17,17,1,0,0,1,34,1,0
0,0,29,0,0,0,1,12,0,0,35,0,0,17,1,35,1,78,0,78,1
0,31,2,30,0,0,35,25,0,35,35,35,0,0,17,0,0,0,0,0,34
0,0,32,0,0,0,1,0,0,0,35,0,0,17,1,35,1,48,17,78,1
0,0,0,0,0,0,1,17,0,0,0,0,0,17,1,0,0,1,34,1,0
0,0,0,0,0,0,0,1,17,0,0,0,0,1,0,0,0,0,0,0,0
0,0,0,0,0,0,0,0,1,1,35,1,1,0,0,0,0,0,0,0,0
0,0,0,0,0,0,0,0,0,0,0,0,0,0,0,0,0,0,0,0,0
0,0,0,0,0,0,0,0,0,0,0,0,0,0,0,0,0,0,0,0,0
0,0,0,0,0,0,0,0,0,0,0,0,0,0,0,0,0,0,0,0,0
0,0,0,0,0,0,0,0,0,0,0,0,0,0,0,0,0,0,0,0,0
0,0,0,0,0,0,0,0,0,0,0,0,0,0,0,0,0,0,0,0,0
0,0,0,0,0,0,0,0,0,0,0,0,0,0,0,0,0,0,0,0,0
endlayer

layer
0,0,0,0,0,0,0,0,0,0,0,0,0,0,0,0,0,0,0,0,0
0,0,0,0,0,0,0,0,0,0,45,0,0,0,0,0,0,0,0,0,0
0,0,0,0,0,0,0,0,0,38,2,37,0,0,0,0,0,0,0,0,0
0,0,0,0,0,0,0,0,0,0,8,0,0,0,0,0,0,0,0,0,0
0,0,0,0,0,0,0,0,0,0,0,0,0,0,0,0,0,0,0,0,0
0,0,0,0,0,0,0,0,0,0,0,0,0,0,0,0,0,0,0,0,0
0,0,0,0,0,0,0,0,1,1,35,1,1,0,0,0,0,0,0,0,0
0,0,0,0,0,0,0,1,24,0,0,17,17,1,0,0,0,0,0,0,0
0,0,0,0,0,0,1,25,12,0,0,0,0,17,1,0,0,1,34,1,0
0,0,2,0,0,0,1,0,0,0,0,0,0,17,1,35,1,17,0,17,1
0,2,2,2,0,0,35,0,0,0,62,0,0,0,17,17,0,0,0,17,34
0,0,2,0,0,0,1,0,0,0,0,0,0,0,1,35,1,17,0,17,1
0,0,0,0,0,0,1,17,0,0,0,0,0,17,1,0,0,1,34,1,0
0,0,0,0,0,0,0,1,17,0,0,0,17,1,0,0,0,0,0,0,0
0,0,0,0,0,0,0,0,1,1,35,1,1,0,0,0,0,0,0,0,0
0,0,0,0,0,0,0,0,0,0,0,0,0,0,0,0,0,0,0,0,0
0,0,0,0,0,0,0,0,0,0,0,0,0,0,0,0,0,0,0,0,0
0,0,0,0,0,0,0,0,0,0,0,0,0,0,0,0,0,0,0,0,0
0,0,0,0,0,0,0,0,0,0,0,0,0,0,0,0,0,0,0,0,0
0,0,0,0,0,0,0,0,0,0,0,0,0,0,0,0,0,0,0,0,0
0,0,0,0,0,0,0,0,0,0,0,0,0,0,0,0,0,0,0,0,0
endlayer

layer
0,0,0,0,0,0,0,0,0,0,0,0,0,0,0,0,0,0,0,0,0
0,0,0,0,0,0,0,0,0,0,0,0,0,0,0,0,0,0,0,0,0
0,0,0,0,0,0,0,0,0,0,2,0,0,0,0,0,0,0,0,0,0
0,0,0,0,0,0,0,0,0,0,0,0,0,0,0,0,0,0,0,0,0
0,0,0,0,0,0,0,0,0,0,0,0,0,0,0,0,0,0,0,0,0
0,0,0,0,0,0,0,0,0,0,0,0,0,0,0,0,0,0,0,0,0
0,0,0,0,0,0,0,0,1,1,23,1,1,0,0,0,0,0,0,0,0
0,0,0,0,0,0,0,1,25,12,24,17,17,1,0,0,0,0,0,0,0
0,0,29,0,0,0,1,17,17,0,0,17,17,17,1,0,0,1,23,1,0
0,2,2,2,0,0,1,17,0,0,0,0,0,17,1,45,1,17,17,17,1
31,2,2,2,30,0,23,17,0,0,63,0,0,17,23,2,23,17,17,17,23
0,2,2,2,0,0,1,17,0,0,0,0,0,17,1,8,1,17,0,17,1
0,0,32,0,0,0,1,17,0,0,0,0,17,17,1,0,0,1,23,1,0
0,0,0,0,0,0,0,1,17,0,0,17,17,1,0,0,0,0,0,0,0
0,0,0,0,0,0,0,0,1,1,23,1,1,0,0,0,0,0,0,0,0
0,0,0,0,0,0,0,0,0,0,0,0,0,0,0,0,0,0,0,0,0
0,0,0,0,0,0,0,0,0,0,0,0,0,0,0,0,0,0,0,0,0
0,0,0,0,0,0,0,0,0,0,0,0,0,0,0,0,0,0,0,0,0
0,0,0,0,0,0,0,0,0,0,0,0,0,0,0,0,0,0,0,0,0
0,0,0,0,0,0,0,0,0,0,0,0,0,0,0,0,0,0,0,0,0
0,0,0,0,0,0,0,0,0,0,0,0,0,0,0,0,0,0,0,0,0
endlayer

layer
0,0,0,0,0,0,0,0,0,0,0,0,0,0,0,0,0,0,0,0,0
0,0,0,0,0,0,0,0,0,0,0,0,0,0,0,0,0,0,0,0,0
0,0,0,0,0,0,0,0,0,0,50,0,0,0,0,0,0,0,0,0,0
0,0,0,0,0,0,0,0,0,0,0,0,0,0,0,0,0,0,0,0,0
0,0,0,0,0,0,0,0,0,0,0,0,0,0,0,0,0,0,0,0,0
0,0,0,0,0,0,0,0,0,0,0,0,0,0,0,0,0,0,0,0,0
0,0,0,0,0,0,0,0,1,1,1,1,1,0,0,0,0,0,0,0,0
0,0,0,0,0,0,0,1,17,0,25,2,2,1,0,0,0,0,0,0,0
0,2,2,2,0,0,1,17,0,2,2,2,2,2,1,0,0,2,2,2,0
2,2,2,2,2,2,1,17,2,2,2,2,2,2,1,0,2,2,0,2,2
2,2,2,2,2,2,2,2,2,2,2,2,2,2,1,0,2,17,0,17,2
2,2,2,2,2,2,1,2,2,2,2,2,2,2,1,0,2,2,17,2,2
0,2,2,2,0,0,1,2,2,2,2,2,2,2,1,0,0,2,2,2,0
0,0,0,0,0,0,0,1,2,2,2,2,2,1,0,0,0,0,0,0,0
0,0,0,0,0,0,0,0,1,1,1,1,1,0,0,0,0,0,0,0,0
0,0,0,0,0,0,0,0,0,0,0,0,0,0,0,0,0,0,0,0,0
0,0,0,0,0,0,0,0,0,0,0,0,0,0,0,0,0,0,0,0,0
0,0,0,0,0,0,0,0,0,0,0,0,0,0,0,0,0,0,0,0,0
0,0,0,0,0,0,0,0,0,0,0,0,0,0,0,0,0,0,0,0,0
0,0,0,0,0,0,0,0,0,0,0,0,0,0,0,0,0,0,0,0,0
0,0,0,0,0,0,0,0,0,0,0,0,0,0,0,0,0,0,0,0,0
endlayer

layer
0,0,0,0,0,0,0,0,0,0,0,0,0,0,0,0,0,0,0,0,0
0,0,0,0,0,0,0,0,0,0,0,0,0,0,0,0,0,0,0,0,0
0,0,0,0,0,0,0,0,0,0,36,0,0,0,0,0,0,0,0,0,0
0,0,0,0,0,0,0,0,0,0,0,0,0,0,0,0,0,0,0,0,0
0,0,0,0,0,0,0,0,0,0,0,0,0,0,0,0,0,0,0,0,0
0,0,0,0,0,0,0,0,0,3,3,3,0,0,0,0,0,0,0,0,0
0,0,0,0,0,0,0,0,1,1,23,1,1,0,0,0,0,0,0,0,0
0,0,0,0,0,0,0,1,17,0,0,0,17,1,0,0,0,0,0,0,0
0,1,23,1,0,0,1,17,0,0,0,0,0,25,1,0,0,0,45,0,0
1,56,17,17,1,35,1,0,0,0,0,0,0,12,1,3,0,2,2,2,0
23,82,81,17,17,17,17,0,17,0,41,0,17,24,23,3,38,2,0,2,37
1,83,0,46,1,35,1,0,0,0,0,0,0,0,1,3,0,2,2,2,0
0,1,23,1,0,0,1,17,17,0,0,0,17,17,1,0,0,0,8,0,0
0,0,0,0,0,0,0,1,56,56,56,56,56,1,0,0,0,0,0,0,0
0,0,0,0,0,0,0,0,1,1,23,1,1,0,0,0,0,0,0,0,0
0,0,0,0,0,0,0,0,0,3,3,3,0,0,0,0,0,0,0,0,0
0,0,0,0,0,0,0,0,0,0,0,0,0,0,0,0,0,0,0,0,0
0,0,0,0,0,0,0,0,0,0,0,0,0,0,0,0,0,0,0,0,0
0,0,0,0,0,0,0,0,0,0,0,0,0,0,0,0,0,0,0,0,0
0,0,0,0,0,0,0,0,0,0,0,0,0,0,0,0,0,0,0,0,0
0,0,0,0,0,0,0,0,0,0,0,0,0,0,0,0,0,0,0,0,0
endlayer

layer
0,0,0,0,0,0,0,0,0,0,0,0,0,0,0,0,0,0,0,0,0
0,0,0,0,0,0,0,0,0,0,0,0,0,0,0,0,0,0,0,0,0
0,0,0,0,0,0,0,0,0,0,0,0,0,0,0,0,0,0,0,0,0
0,0,0,0,0,0,0,0,0,0,0,0,0,0,0,0,0,0,0,0,0
0,0,0,0,0,0,0,0,0,0,0,0,0,0,0,0,0,0,0,0,0
0,0,0,0,0,0,0,0,0,0,0,0,0,0,0,0,0,0,0,0,0
0,0,0,0,0,0,0,0,1,1,35,1,1,0,0,0,0,0,0,0,0
0,0,0,0,0,0,0,1,17,0,0,0,0,1,0,0,0,0,0,0,0
0,1,34,1,0,0,1,17,0,0,0,0,0,0,1,0,0,0,0,0,0
1,17,17,17,1,35,1,0,0,0,0,0,0,0,1,0,0,2,2,2,0
34,17,17,0,17,17,17,0,0,0,17,0,17,25,35,0,0,2,0,2,0
1,17,17,0,1,35,1,0,0,0,0,0,0,12,1,0,0,2,2,2,0
0,1,34,1,0,0,1,17,0,0,0,0,17,24,1,0,0,0,0,0,0
0,0,0,0,0,0,0,1,84,17,0,0,17,1,0,0,0,0,0,0,0
0,0,0,0,0,0,0,0,1,1,35,1,1,0,0,0,0,0,0,0,0
0,0,0,0,0,0,0,0,0,0,0,0,0,0,0,0,0,0,0,0,0
0,0,0,0,0,0,0,0,0,0,0,0,0,0,0,0,0,0,0,0,0
0,0,0,0,0,0,0,0,0,0,0,0,0,0,0,0,0,0,0,0,0
0,0,0,0,0,0,0,0,0,0,0,0,0,0,0,0,0,0,0,0,0
0,0,0,0,0,0,0,0,0,0,0,0,0,0,0,0,0,0,0,0,0
0,0,0,0,0,0,0,0,0,0,0,0,0,0,0,0,0,0,0,0,0
endlayer

layer
0,0,0,0,0,0,0,0,0,0,0,0,0,0,0,0,0,0,0,0,0
0,0,0,0,0,0,0,0,0,0,0,0,0,0,0,0,0,0,0,0,0
0,0,0,0,0,0,0,0,0,0,0,0,0,0,0,0,0,0,0,0,0
0,0,0,0,0,0,0,0,0,0,0,0,0,0,0,0,0,0,0,0,0
0,0,0,0,0,0,0,0,0,0,0,0,0,0,0,0,0,0,0,0,0
0,0,0,0,0,0,0,0,0,0,0,0,0,0,0,0,0,0,0,0,0
0,0,0,0,0,0,0,0,1,1,35,1,1,0,0,0,0,0,0,0,0
0,0,0,0,0,0,0,1,17,17,0,0,17,1,0,0,0,0,0,0,0
0,1,34,1,0,0,1,17,0,0,0,0,0,0,1,0,0,0,0,0,0
1,17,0,17,1,35,1,0,0,0,0,0,0,0,1,0,0,0,45,0,0
34,17,17,0,17,0,0,0,0,0,62,0,0,0,35,0,0,38,2,37,0
1,17,0,17,1,35,1,17,0,0,0,0,0,0,1,0,0,0,8,0,0
0,1,34,1,0,0,1,17,0,0,0,0,12,25,1,0,0,0,0,0,0
0,0,0,0,0,0,0,1,17,0,0,0,24,1,0,0,0,0,0,0,0
0,0,0,0,0,0,0,0,1,1,35,1,1,0,0,0,0,0,0,0,0
0,0,0,0,0,0,0,0,0,0,0,0,0,0,0,0,0,0,0,0,0
0,0,0,0,0,0,0,0,0,0,0,0,0,0,0,0,0,0,0,0,0
0,0,0,0,0,0,0,0,0,0,0,0,0,0,0,0,0,0,0,0,0
0,0,0,0,0,0,0,0,0,0,0,0,0,0,0,0,0,0,0,0,0
0,0,0,0,0,0,0,0,0,0,0,0,0,0,0,0,0,0,0,0,0
0,0,0,0,0,0,0,0,0,0,0,0,0,0,0,0,0,0,0,0,0
endlayer

layer
0,0,0,0,0,0,0,0,0,0,0,0,0,0,0,0,0,0,0,0,0
0,0,0,0,0,0,0,0,0,0,0,0,0,0,0,0,0,0,0,0,0
0,0,0,0,0,0,0,0,0,0,0,0,0,0,0,0,0,0,0,0,0
0,0,0,0,0,0,0,0,0,0,0,0,0,0,0,0,0,0,0,0,0
0,0,0,0,0,0,0,0,0,0,0,0,0,0,0,0,0,0,0,0,0
0,0,0,0,0,0,0,0,0,0,0,0,0,0,0,0,0,0,0,0,0
0,0,0,0,0,0,0,0,1,1,23,1,1,0,0,0,0,0,0,0,0
0,0,0,0,0,0,0,1,17,17,17,17,17,1,0,0,0,0,0,0,0
0,1,23,1,0,0,1,17,0,0,0,0,0,17,1,0,0,0,0,0,0
1,17,0,17,1,45,1,17,0,0,0,0,0,0,1,0,0,0,0,0,0
23,17,0,0,23,2,23,17,0,0,63,0,0,0,23,0,0,0,2,0,0
1,17,17,17,1,8,1,17,0,0,0,0,0,0,1,0,0,0,0,0,0
0,1,23,1,0,0,1,17,17,0,0,0,0,17,1,0,0,0,0,0,0
0,0,0,0,0,0,0,1,17,17,24,12,25,1,0,0,0,0,0,0,0
0,0,0,0,0,0,0,0,1,1,23,1,1,0,0,0,0,0,0,0,0
0,0,0,0,0,0,0,0,0,0,0,0,0,0,0,0,0,0,0,0,0
0,0,0,0,0,0,0,0,0,0,0,0,0,0,0,0,0,0,0,0,0
0,0,0,0,0,0,0,0,0,0,0,0,0,0,0,0,0,0,0,0,0
0,0,0,0,0,0,0,0,0,0,0,0,0,0,0,0,0,0,0,0,0
0,0,0,0,0,0,0,0,0,0,0,0,0,0,0,0,0,0,0,0,0
0,0,0,0,0,0,0,0,0,0,0,0,0,0,0,0,0,0,0,0,0
endlayer

layer
0,0,0,0,0,0,0,0,0,0,0,0,0,0,0,0,0,0,0,0,0
0,0,0,0,0,0,0,0,0,0,0,0,0,0,0,0,0,0,0,0,0
0,0,0,0,0,0,0,0,0,0,0,0,0,0,0,0,0,0,0,0,0
0,0,0,0,0,0,0,0,0,0,0,0,0,0,0,0,0,0,0,0,0
0,0,0,0,0,0,0,0,0,0,0,0,0,0,0,0,0,0,0,0,0
0,0,0,0,0,0,0,0,0,3,3,3,0,0,0,0,0,0,0,0,0
0,0,0,0,0,0,0,0,1,1,1,1,1,0,0,0,0,0,0,0,0
0,0,0,0,0,0,0,1,2,2,2,2,2,1,0,0,0,0,0,0,0
0,2,2,2,0,0,1,2,2,2,2,2,2,2,1,0,0,0,0,0,0
2,2,17,2,2,3,1,2,2,2,2,2,2,2,1,3,0,0,0,0,0
2,17,0,17,2,3,1,2,2,2,2,2,2,2,1,3,0,0,50,0,0
2,2,17,2,2,3,1,2,2,2,2,2,2,0,1,3,0,0,0,0,0
0,2,2,2,0,0,1,2,2,2,2,2,0,17,1,0,0,0,0,0,0
0,0,0,0,0,0,0,1,2,2,25,0,17,1,0,0,0,0,0,0,0
0,0,0,0,0,0,0,0,1,1,1,1,1,0,0,0,0,0,0,0,0
0,0,0,0,0,0,0,0,0,3,3,3,0,0,0,0,0,0,0,0,0
0,0,0,0,0,0,0,0,0,0,0,0,0,0,0,0,0,0,0,0,0
0,0,0,0,0,0,0,0,0,0,0,0,0,0,0,0,0,0,0,0,0
0,0,0,0,0,0,0,0,0,0,0,0,0,0,0,0,0,0,0,0,0
0,0,0,0,0,0,0,0,0,0,0,0,0,0,0,0,0,0,0,0,0
0,0,0,0,0,0,0,0,0,0,0,0,0,0,0,0,0,0,0,0,0
endlayer

layer
0,0,0,0,0,0,0,0,0,0,0,0,0,0,0,0,0,0,0,0,0
0,0,0,0,0,0,0,0,0,0,0,0,0,0,0,0,0,0,0,0,0
0,0,0,0,0,0,0,0,0,0,0,0,0,0,0,0,0,0,0,0,0
0,0,0,0,0,0,0,0,0,0,0,0,0,0,0,0,0,0,0,0,0
0,0,0,0,0,0,0,0,0,0,0,0,0,0,0,0,0,0,0,0,0
0,0,0,0,0,0,0,0,0,0,0,0,0,0,0,0,0,0,0,0,0
0,0,0,0,0,0,0,0,1,50,50,50,1,0,0,0,0,0,0,0,0
0,0,0,0,0,0,0,1,85,0,0,0,4,1,0,0,0,0,0,0,0
0,0,45,0,0,0,1,0,88,86,87,86,0,0,1,0,0,0,0,0,0
0,2,2,2,0,0,50,0,86,87,89,87,86,0,50,0,0,0,0,0,0
38,2,17,2,37,0,50,90,87,89,36,89,87,0,50,0,0,0,36,0,0
0,2,2,2,0,0,50,0,86,87,89,87,86,0,50,0,0,0,0,0,0
0,0,8,0,0,0,1,0,0,86,87,86,0,0,1,0,0,0,0,0,0
0,0,0,0,0,0,0,1,91,0,0,0,0,1,0,0,0,0,0,0,0
0,0,0,0,0,0,0,0,1,50,50,50,1,0,0,0,0,0,0,0,0
0,0,0,0,0,0,0,0,0,0,0,0,0,0,0,0,0,0,0,0,0
0,0,0,0,0,0,0,0,0,0,0,0,0,0,0,0,0,0,0,0,0
0,0,0,0,0,0,0,0,0,0,0,0,0,0,0,0,0,0,0,0,0
0,0,0,0,0,0,0,0,0,0,0,0,0,0,0,0,0,0,0,0,0
0,0,0,0,0,0,0,0,0,0,0,0,0,0,0,0,0,0,0,0,0
0,0,0,0,0,0,0,0,0,0,0,0,0,0,0,0,0,0,0,0,0
endlayer

layer
0,0,0,0,0,0,0,0,0,0,0,0,0,0,0,0,0,0,0,0,0
0,0,0,0,0,0,0,0,0,0,0,0,0,0,0,0,0,0,0,0,0
0,0,0,0,0,0,0,0,0,0,0,0,0,0,0,0,0,0,0,0,0
0,0,0,0,0,0,0,0,0,0,0,0,0,0,0,0,0,0,0,0,0
0,0,0,0,0,0,0,0,0,0,0,0,0,0,0,0,0,0,0,0,0
0,0,0,0,0,0,0,0,0,0,0,0,0,0,0,0,0,0,0,0,0
0,0,0,0,0,0,0,0,1,0,0,0,1,0,0,0,0,0,0,0,0
0,0,0,0,0,0,0,1,0,0,0,0,0,1,0,0,0,0,0,0,0
0,0,0,0,0,0,1,0,0,0,0,0,0,0,1,0,0,0,0,0,0
0,2,2,2,0,0,0,0,0,0,0,0,0,0,0,0,0,0,0,0,0
0,2,0,2,0,0,0,0,0,0,0,0,0,0,0,0,0,0,0,0,0
0,2,2,2,0,0,0,0,0,0,0,0,0,0,0,0,0,0,0,0,0
0,0,0,0,0,0,1,0,0,0,0,0,0,0,1,0,0,0,0,0,0
0,0,0,0,0,0,0,1,0,0,0,17,0,1,0,0,0,0,0,0,0
0,0,0,0,0,0,0,0,1,0,0,0,1,0,0,0,0,0,0,0,0
0,0,0,0,0,0,0,0,0,0,0,0,0,0,0,0,0,0,0,0,0
0,0,0,0,0,0,0,0,0,0,0,0,0,0,0,0,0,0,0,0,0
0,0,0,0,0,0,0,0,0,0,0,0,0,0,0,0,0,0,0,0,0
0,0,0,0,0,0,0,0,0,0,0,0,0,0,0,0,0,0,0,0,0
0,0,0,0,0,0,0,0,0,0,0,0,0,0,0,0,0,0,0,0,0
0,0,0,0,0,0,0,0,0,0,0,0,0,0,0,0,0,0,0,0,0
endlayer

layer
0,0,0,0,0,0,0,0,0,0,0,0,0,0,0,0,0,0,0,0,0
0,0,0,0,0,0,0,0,0,0,0,0,0,0,0,0,0,0,0,0,0
0,0,0,0,0,0,0,0,0,0,0,0,0,0,0,0,0,0,0,0,0
0,0,0,0,0,0,0,0,0,0,0,0,0,0,0,0,0,0,0,0,0
0,0,0,0,0,0,0,0,0,0,0,0,0,0,0,0,0,0,0,0,0
0,0,0,0,0,0,0,0,0,0,0,0,0,0,0,0,0,0,0,0,0
0,0,0,0,0,0,0,0,1,1,0,1,1,0,0,0,0,0,0,0,0
0,0,0,0,0,0,0,1,0,0,0,0,0,1,0,0,0,0,0,0,0
0,0,0,0,0,0,1,0,0,0,92,0,0,0,1,0,0,0,0,0,0
0,0,45,0,0,0,1,0,0,0,93,0,0,0,1,0,0,0,0,0,0
0,38,2,37,0,0,0,0,98,97,96,95,94,0,0,0,0,0,0,0,0
0,0,8,0,0,0,1,0,0,0,99,0,0,0,1,0,0,0,0,0,0
0,0,0,0,0,0,1,0,0,0,100,0,0,0,1,0,0,0,0,0,0
0,0,0,0,0,0,0,1,0,0,0,17,17,1,0,0,0,0,0,0,0
0,0,0,0,0,0,0,0,1,1,0,1,1,0,0,0,0,0,0,0,0
0,0,0,0,0,0,0,0,0,0,0,0,0,0,0,0,0,0,0,0,0
0,0,0,0,0,0,0,0,0,0,0,0,0,0,0,0,0,0,0,0,0
0,0,0,0,0,0,0,0,0,0,0,0,0,0,0,0,0,0,0,0,0
0,0,0,0,0,0,0,0,0,0,0,0,0,0,0,0,0,0,0,0,0
0,0,0,0,0,0,0,0,0,0,0,0,0,0,0,0,0,0,0,0,0
0,0,0,0,0,0,0,0,0,0,0,0,0,0,0,0,0,0,0,0,0
endlayer

layer
0,0,0,0,0,0,0,0,0,0,0,0,0,0,0,0,0,0,0,0,0
0,0,0,0,0,0,0,0,0,0,0,0,0,0,0,0,0,0,0,0,0
0,0,0,0,0,0,0,0,0,0,0,0,0,0,0,0,0,0,0,0,0
0,0,0,0,0,0,0,0,0,0,0,0,0,0,0,0,0,0,0,0,0
0,0,0,0,0,0,0,0,0,0,0,0,0,0,0,0,0,0,0,0,0
0,0,0,0,0,0,0,0,0,0,0,0,0,0,0,0,0,0,0,0,0
0,0,0,0,0,0,0,0,1,1,23,1,1,0,0,0,0,0,0,0,0
0,0,0,0,0,0,0,1,0,0,0,0,0,1,0,0,0,0,0,0,0
0,0,0,0,0,0,1,0,0,0,35,0,0,0,1,0,0,0,0,0,0
0,0,0,0,0,0,1,0,0,0,35,0,0,0,1,0,0,0,0,0,0
0,0,2,0,0,0,23,0,35,35,35,35,35,0,23,0,0,0,0,0,0
0,0,0,0,0,0,1,0,0,0,35,0,0,0,1,0,0,0,0,0,0
0,0,0,0,0,0,1,0,0,0,35,0,17,17,1,0,0,0,0,0,0
0,0,0,0,0,0,0,1,0,0,0,0,17,1,0,0,0,0,0,0,0
0,0,0,0,0,0,0,0,1,1,23,1,1,0,0,0,0,0,0,0,0
0,0,0,0,0,0,0,0,0,0,0,0,0,0,0,0,0,0,0,0,0
0,0,0,0,0,0,0,0,0,0,0,0,0,0,0,0,0,0,0,0,0
0,0,0,0,0,0,0,0,0,0,0,0,0,0,0,0,0,0,0,0,0
0,0,0,0,0,0,0,0,0,0,0,0,0,0,0,0,0,0,0,0,0
0,0,0,0,0,0,0,0,0,0,0,0,0,0,0,0,0,0,0,0,0
0,0,0,0,0,0,0,0,0,0,0,0,0,0,0,0,0,0,0,0,0
endlayer

layer
0,0,0,0,0,0,0,0,0,0,0,0,0,0,0,0,0,0,0,0,0
0,0,0,0,0,0,0,0,0,0,0,0,0,0,0,0,0,0,0,0,0
0,0,0,0,0,0,0,0,0,0,0,0,0,0,0,0,0,0,0,0,0
0,0,0,0,0,0,0,0,0,0,0,0,0,0,0,0,0,0,0,0,0
0,0,0,0,0,0,0,0,0,0,0,0,0,0,0,0,0,0,0,0,0
0,0,0,0,0,0,0,0,101,101,101,101,101,0,0,0,0,0,0,0,0
0,0,0,0,0,0,0,101,2,2,2,2,2,101,0,0,0,0,0,0,0
0,0,0,0,0,0,101,2,2,102,102,102,2,2,101,0,0,0,0,0,0
0,0,0,0,0,101,2,2,102,0,0,0,102,2,2,101,0,0,0,0,0
0,0,0,0,0,101,2,102,0,0,0,0,0,102,2,101,0,0,0,0,0
0,0,50,0,0,101,2,102,0,0,35,0,0,102,2,101,0,0,0,0,0
0,0,0,0,0,101,2,102,0,0,0,0,0,102,2,101,0,0,0,0,0
0,0,0,0,0,101,2,2,102,0,0,0,102,2,2,101,0,0,0,0,0
0,0,0,0,0,0,101,2,2,102,102,102,2,2,101,0,0,0,0,0,0
0,0,0,0,0,0,0,101,2,2,2,2,2,101,0,0,0,0,0,0,0
0,0,0,0,0,0,0,0,101,101,101,101,101,0,0,0,0,0,0,0,0
0,0,0,0,0,0,0,0,0,0,0,0,0,0,0,0,0,0,0,0,0
0,0,0,0,0,0,0,0,0,0,0,0,0,0,0,0,0,0,0,0,0
0,0,0,0,0,0,0,0,0,0,0,0,0,0,0,0,0,0,0,0,0
0,0,0,0,0,0,0,0,0,0,0,0,0,0,0,0,0,0,0,0,0
0,0,0,0,0,0,0,0,0,0,0,0,0,0,0,0,0,0,0,0,0
endlayer

layer
0,0,0,0,0,0,0,0,0,0,0,0,0,0,0,0,0,0,0,0,0
0,0,0,0,0,0,0,0,0,0,0,0,0,0,0,0,0,0,0,0,0
0,0,0,0,0,0,0,0,0,0,0,0,0,0,0,0,0,0,0,0,0
0,0,0,0,0,0,0,0,0,0,0,0,0,0,0,0,0,0,0,0,0
0,0,0,0,0,0,0,0,0,0,0,0,0,0,0,0,0,0,0,0,0
0,0,0,0,0,0,0,0,0,0,0,0,0,0,0,0,0,0,0,0,0
0,0,0,0,0,0,0,0,0,0,0,0,0,0,0,0,0,0,0,0,0
0,0,0,0,0,0,0,0,101,101,101,101,101,0,0,0,0,0,0,0,0
0,0,0,0,0,0,0,101,101,2,2,2,101,101,0,0,0,0,0,0,0
0,0,0,0,0,0,0,101,2,2,0,2,2,101,0,0,0,0,0,0,0
0,0,36,0,0,0,0,101,2,0,35,0,2,103,0,0,0,0,0,0,0
0,0,0,0,0,0,0,101,2,2,0,2,2,101,0,0,0,0,0,0,0
0,0,0,0,0,0,0,101,101,2,2,2,101,101,0,0,0,0,0,0,0
0,0,0,0,0,0,0,0,101,101,101,101,101,0,0,0,0,0,0,0,0
0,0,0,0,0,0,0,0,0,0,0,0,0,0,0,0,0,0,0,0,0
0,0,0,0,0,0,0,0,0,0,0,0,0,0,0,0,0,0,0,0,0
0,0,0,0,0,0,0,0,0,0,0,0,0,0,0,0,0,0,0,0,0
0,0,0,0,0,0,0,0,0,0,0,0,0,0,0,0,0,0,0,0,0
0,0,0,0,0,0,0,0,0,0,0,0,0,0,0,0,0,0,0,0,0
0,0,0,0,0,0,0,0,0,0,0,0,0,0,0,0,0,0,0,0,0
0,0,0,0,0,0,0,0,0,0,0,0,0,0,0,0,0,0,0,0,0
endlayer

layer
0,0,0,0,0,0,0,0,0,0,0,0,0,0,0,0,0,0,0,0,0
0,0,0,0,0,0,0,0,0,0,0,0,0,0,0,0,0,0,0,0,0
0,0,0,0,0,0,0,0,0,0,0,0,0,0,0,0,0,0,0,0,0
0,0,0,0,0,0,0,0,0,0,0,0,0,0,0,0,0,0,0,0,0
0,0,0,0,0,0,0,0,0,0,0,0,0,0,0,0,0,0,0,0,0
0,0,0,0,0,0,0,0,0,0,0,0,0,0,0,0,0,0,0,0,0
0,0,0,0,0,0,0,0,0,0,0,0,0,0,0,0,0,0,0,0,0
0,0,0,0,0,0,0,0,0,0,0,0,0,0,0,0,0,0,0,0,0
0,0,0,0,0,0,0,0,0,0,101,0,0,0,0,0,0,0,0,0,0
0,0,0,0,0,0,0,0,0,2,2,2,0,0,0,0,0,0,0,0,0
0,0,0,0,0,0,0,0,101,2,35,2,101,0,0,0,0,0,0,0,0
0,0,0,0,0,0,0,0,0,2,2,2,0,0,0,0,0,0,0,0,0
0,0,0,0,0,0,0,0,0,0,101,0,0,0,0,0,0,0,0,0,0
0,0,0,0,0,0,0,0,0,0,0,0,0,0,0,0,0,0,0,0,0
0,0,0,0,0,0,0,0,0,0,0,0,0,0,0,0,0,0,0,0,0
0,0,0,0,0,0,0,0,0,0,0,0,0,0,0,0,0,0,0,0,0
0,0,0,0,0,0,0,0,0,0,0,0,0,0,0,0,0,0,0,0,0
0,0,0,0,0,0,0,0,0,0,0,0,0,0,0,0,0,0,0,0,0
0,0,0,0,0,0,0,0,0,0,0,0,0,0,0,0,0,0,0,0,0
0,0,0,0,0,0,0,0,0,0,0,0,0,0,0,0,0,0,0,0,0
0,0,0,0,0,0,0,0,0,0,0,0,0,0,0,0,0,0,0,0,0
endlayer

layer
0,0,0,0,0,0,0,0,0,0,0,0,0,0,0,0,0,0,0,0,0
0,0,0,0,0,0,0,0,0,0,0,0,0,0,0,0,0,0,0,0,0
0,0,0,0,0,0,0,0,0,0,0,0,0,0,0,0,0,0,0,0,0
0,0,0,0,0,0,0,0,0,0,0,0,0,0,0,0,0,0,0,0,0
0,0,0,0,0,0,0,0,0,0,0,0,0,0,0,0,0,0,0,0,0
0,0,0,0,0,0,0,0,0,0,0,0,0,0,0,0,0,0,0,0,0
0,0,0,0,0,0,0,0,0,0,0,0,0,0,0,0,0,0,0,0,0
0,0,0,0,0,0,0,0,0,0,0,0,0,0,0,0,0,0,0,0,0
0,0,0,0,0,0,0,0,0,0,0,0,0,0,0,0,0,0,0,0,0
0,0,0,0,0,0,0,0,0,101,2,101,0,0,0,0,0,0,0,0,0
0,0,0,0,0,0,0,0,0,2,35,2,0,0,0,0,0,0,0,0,0
0,0,0,0,0,0,0,0,0,101,2,101,0,0,0,0,0,0,0,0,0
0,0,0,0,0,0,0,0,0,0,0,0,0,0,0,0,0,0,0,0,0
0,0,0,0,0,0,0,0,0,0,0,0,0,0,0,0,0,0,0,0,0
0,0,0,0,0,0,0,0,0,0,0,0,0,0,0,0,0,0,0,0,0
0,0,0,0,0,0,0,0,0,0,0,0,0,0,0,0,0,0,0,0,0
0,0,0,0,0,0,0,0,0,0,0,0,0,0,0,0,0,0,0,0,0
0,0,0,0,0,0,0,0,0,0,0,0,0,0,0,0,0,0,0,0,0
0,0,0,0,0,0,0,0,0,0,0,0,0,0,0,0,0,0,0,0,0
0,0,0,0,0,0,0,0,0,0,0,0,0,0,0,0,0,0,0,0,0
0,0,0,0,0,0,0,0,0,0,0,0,0,0,0,0,0,0,0,0,0
endlayer

layer
0,0,0,0,0,0,0,0,0,0,0,0,0,0,0,0,0,0,0,0,0
0,0,0,0,0,0,0,0,0,0,0,0,0,0,0,0,0,0,0,0,0
0,0,0,0,0,0,0,0,0,0,0,0,0,0,0,0,0,0,0,0,0
0,0,0,0,0,0,0,0,0,0,0,0,0,0,0,0,0,0,0,0,0
0,0,0,0,0,0,0,0,0,0,0,0,0,0,0,0,0,0,0,0,0
0,0,0,0,0,0,0,0,0,0,0,0,0,0,0,0,0,0,0,0,0
0,0,0,0,0,0,0,0,0,0,0,0,0,0,0,0,0,0,0,0,0
0,0,0,0,0,0,0,0,0,0,0,0,0,0,0,0,0,0,0,0,0
0,0,0,0,0,0,0,0,0,0,0,0,0,0,0,0,0,0,0,0,0
0,0,0,0,0,0,0,0,0,0,2,0,0,0,0,0,0,0,0,0,0
0,0,0,0,0,0,0,0,0,2,50,2,0,0,0,0,0,0,0,0,0
0,0,0,0,0,0,0,0,0,0,2,0,0,0,0,0,0,0,0,0,0
0,0,0,0,0,0,0,0,0,0,0,0,0,0,0,0,0,0,0,0,0
0,0,0,0,0,0,0,0,0,0,0,0,0,0,0,0,0,0,0,0,0
0,0,0,0,0,0,0,0,0,0,0,0,0,0,0,0,0,0,0,0,0
0,0,0,0,0,0,0,0,0,0,0,0,0,0,0,0,0,0,0,0,0
0,0,0,0,0,0,0,0,0,0,0,0,0,0,0,0,0,0,0,0,0
0,0,0,0,0,0,0,0,0,0,0,0,0,0,0,0,0,0,0,0,0
0,0,0,0,0,0,0,0,0,0,0,0,0,0,0,0,0,0,0,0,0
0,0,0,0,0,0,0,0,0,0,0,0,0,0,0,0,0,0,0,0,0
0,0,0,0,0,0,0,0,0,0,0,0,0,0,0,0,0,0,0,0,0
endlayer

layer
0,0,0,0,0,0,0,0,0,0,0,0,0,0,0,0,0,0,0,0,0
0,0,0,0,0,0,0,0,0,0,0,0,0,0,0,0,0,0,0,0,0
0,0,0,0,0,0,0,0,0,0,0,0,0,0,0,0,0,0,0,0,0
0,0,0,0,0,0,0,0,0,0,0,0,0,0,0,0,0,0,0,0,0
0,0,0,0,0,0,0,0,0,0,0,0,0,0,0,0,0,0,0,0,0
0,0,0,0,0,0,0,0,0,0,0,0,0,0,0,0,0,0,0,0,0
0,0,0,0,0,0,0,0,0,0,0,0,0,0,0,0,0,0,0,0,0
0,0,0,0,0,0,0,0,0,0,0,0,0,0,0,0,0,0,0,0,0
0,0,0,0,0,0,0,0,0,0,0,0,0,0,0,0,0,0,0,0,0
0,0,0,0,0,0,0,0,0,0,101,0,0,0,0,0,0,0,0,0,0
0,0,0,0,0,0,0,0,0,101,2,101,0,0,0,0,0,0,0,0,0
0,0,0,0,0,0,0,0,0,0,101,0,0,0,0,0,0,0,0,0,0
0,0,0,0,0,0,0,0,0,0,0,0,0,0,0,0,0,0,0,0,0
0,0,0,0,0,0,0,0,0,0,0,0,0,0,0,0,0,0,0,0,0
0,0,0,0,0,0,0,0,0,0,0,0,0,0,0,0,0,0,0,0,0
0,0,0,0,0,0,0,0,0,0,0,0,0,0,0,0,0,0,0,0,0
0,0,0,0,0,0,0,0,0,0,0,0,0,0,0,0,0,0,0,0,0
0,0,0,0,0,0,0,0,0,0,0,0,0,0,0,0,0,0,0,0,0
0,0,0,0,0,0,0,0,0,0,0,0,0,0,0,0,0,0,0,0,0
0,0,0,0,0,0,0,0,0,0,0,0,0,0,0,0,0,0,0,0,0
0,0,0,0,0,0,0,0,0,0,0,0,0,0,0,0,0,0,0,0,0
endlayer

layer
0,0,0,0,0,0,0,0,0,0,0,0,0,0,0,0,0,0,0,0,0
0,0,0,0,0,0,0,0,0,0,0,0,0,0,0,0,0,0,0,0,0
0,0,0,0,0,0,0,0,0,0,0,0,0,0,0,0,0,0,0,0,0
0,0,0,0,0,0,0,0,0,0,0,0,0,0,0,0,0,0,0,0,0
0,0,0,0,0,0,0,0,0,0,0,0,0,0,0,0,0,0,0,0,0
0,0,0,0,0,0,0,0,0,0,0,0,0,0,0,0,0,0,0,0,0
0,0,0,0,0,0,0,0,0,0,0,0,0,0,0,0,0,0,0,0,0
0,0,0,0,0,0,0,0,0,0,0,0,0,0,0,0,0,0,0,0,0
0,0,0,0,0,0,0,0,0,0,0,0,0,0,0,0,0,0,0,0,0
0,0,0,0,0,0,0,0,0,0,0,0,0,0,0,0,0,0,0,0,0
0,0,0,0,0,0,0,0,0,0,2,0,0,0,0,0,0,0,0,0,0
0,0,0,0,0,0,0,0,0,0,0,0,0,0,0,0,0,0,0,0,0
0,0,0,0,0,0,0,0,0,0,0,0,0,0,0,0,0,0,0,0,0
0,0,0,0,0,0,0,0,0,0,0,0,0,0,0,0,0,0,0,0,0
0,0,0,0,0,0,0,0,0,0,0,0,0,0,0,0,0,0,0,0,0
0,0,0,0,0,0,0,0,0,0,0,0,0,0,0,0,0,0,0,0,0
0,0,0,0,0,0,0,0,0,0,0,0,0,0,0,0,0,0,0,0,0
0,0,0,0,0,0,0,0,0,0,0,0,0,0,0,0,0,0,0,0,0
0,0,0,0,0,0,0,0,0,0,0,0,0,0,0,0,0,0,0,0,0
0,0,0,0,0,0,0,0,0,0,0,0,0,0,0,0,0,0,0,0,0
0,0,0,0,0,0,0,0,0,0,0,0,0,0,0,0,0,0,0,0,0
endlayer

layer
0,0,0,0,0,0,0,0,0,0,0,0,0,0,0,0,0,0,0,0,0
0,0,0,0,0,0,0,0,0,0,0,0,0,0,0,0,0,0,0,0,0
0,0,0,0,0,0,0,0,0,0,0,0,0,0,0,0,0,0,0,0,0
0,0,0,0,0,0,0,0,0,0,0,0,0,0,0,0,0,0,0,0,0
0,0,0,0,0,0,0,0,0,0,0,0,0,0,0,0,0,0,0,0,0
0,0,0,0,0,0,0,0,0,0,0,0,0,0,0,0,0,0,0,0,0
0,0,0,0,0,0,0,0,0,0,0,0,0,0,0,0,0,0,0,0,0
0,0,0,0,0,0,0,0,0,0,0,0,0,0,0,0,0,0,0,0,0
0,0,0,0,0,0,0,0,0,0,0,0,0,0,0,0,0,0,0,0,0
0,0,0,0,0,0,0,0,0,0,0,0,0,0,0,0,0,0,0,0,0
0,0,0,0,0,0,0,0,0,0,2,0,0,0,0,0,0,0,0,0,0
0,0,0,0,0,0,0,0,0,0,0,0,0,0,0,0,0,0,0,0,0
0,0,0,0,0,0,0,0,0,0,0,0,0,0,0,0,0,0,0,0,0
0,0,0,0,0,0,0,0,0,0,0,0,0,0,0,0,0,0,0,0,0
0,0,0,0,0,0,0,0,0,0,0,0,0,0,0,0,0,0,0,0,0
0,0,0,0,0,0,0,0,0,0,0,0,0,0,0,0,0,0,0,0,0
0,0,0,0,0,0,0,0,0,0,0,0,0,0,0,0,0,0,0,0,0
0,0,0,0,0,0,0,0,0,0,0,0,0,0,0,0,0,0,0,0,0
0,0,0,0,0,0,0,0,0,0,0,0,0,0,0,0,0,0,0,0,0
0,0,0,0,0,0,0,0,0,0,0,0,0,0,0,0,0,0,0,0,0
0,0,0,0,0,0,0,0,0,0,0,0,0,0,0,0,0,0,0,0,0
endlayer

layer
0,0,0,0,0,0,0,0,0,0,0,0,0,0,0,0,0,0,0,0,0
0,0,0,0,0,0,0,0,0,0,0,0,0,0,0,0,0,0,0,0,0
0,0,0,0,0,0,0,0,0,0,0,0,0,0,0,0,0,0,0,0,0
0,0,0,0,0,0,0,0,0,0,0,0,0,0,0,0,0,0,0,0,0
0,0,0,0,0,0,0,0,0,0,0,0,0,0,0,0,0,0,0,0,0
0,0,0,0,0,0,0,0,0,0,0,0,0,0,0,0,0,0,0,0,0
0,0,0,0,0,0,0,0,0,0,0,0,0,0,0,0,0,0,0,0,0
0,0,0,0,0,0,0,0,0,0,0,0,0,0,0,0,0,0,0,0,0
0,0,0,0,0,0,0,0,0,0,0,0,0,0,0,0,0,0,0,0,0
0,0,0,0,0,0,0,0,0,0,0,0,0,0,0,0,0,0,0,0,0
0,0,0,0,0,0,0,0,0,0,2,0,0,0,0,0,0,0,0,0,0
0,0,0,0,0,0,0,0,0,0,0,0,0,0,0,0,0,0,0,0,0
0,0,0,0,0,0,0,0,0,0,0,0,0,0,0,0,0,0,0,0,0
0,0,0,0,0,0,0,0,0,0,0,0,0,0,0,0,0,0,0,0,0
0,0,0,0,0,0,0,0,0,0,0,0,0,0,0,0,0,0,0,0,0
0,0,0,0,0,0,0,0,0,0,0,0,0,0,0,0,0,0,0,0,0
0,0,0,0,0,0,0,0,0,0,0,0,0,0,0,0,0,0,0,0,0
0,0,0,0,0,0,0,0,0,0,0,0,0,0,0,0,0,0,0,0,0
0,0,0,0,0,0,0,0,0,0,0,0,0,0,0,0,0,0,0,0,0
0,0,0,0,0,0,0,0,0,0,0,0,0,0,0,0,0,0,0,0,0
0,0,0,0,0,0,0,0,0,0,0,0,0,0,0,0,0,0,0,0,0
endlayer

layer
0,0,0,0,0,0,0,0,0,0,0,0,0,0,0,0,0,0,0,0,0
0,0,0,0,0,0,0,0,0,0,0,0,0,0,0,0,0,0,0,0,0
0,0,0,0,0,0,0,0,0,0,0,0,0,0,0,0,0,0,0,0,0
0,0,0,0,0,0,0,0,0,0,0,0,0,0,0,0,0,0,0,0,0
0,0,0,0,0,0,0,0,0,0,0,0,0,0,0,0,0,0,0,0,0
0,0,0,0,0,0,0,0,0,0,0,0,0,0,0,0,0,0,0,0,0
0,0,0,0,0,0,0,0,0,0,0,0,0,0,0,0,0,0,0,0,0
0,0,0,0,0,0,0,0,0,0,0,0,0,0,0,0,0,0,0,0,0
0,0,0,0,0,0,0,0,0,0,0,0,0,0,0,0,0,0,0,0,0
0,0,0,0,0,0,0,0,0,0,0,0,0,0,0,0,0,0,0,0,0
0,0,0,0,0,0,0,0,0,0,50,0,0,0,0,0,0,0,0,0,0
0,0,0,0,0,0,0,0,0,0,0,0,0,0,0,0,0,0,0,0,0
0,0,0,0,0,0,0,0,0,0,0,0,0,0,0,0,0,0,0,0,0
0,0,0,0,0,0,0,0,0,0,0,0,0,0,0,0,0,0,0,0,0
0,0,0,0,0,0,0,0,0,0,0,0,0,0,0,0,0,0,0,0,0
0,0,0,0,0,0,0,0,0,0,0,0,0,0,0,0,0,0,0,0,0
0,0,0,0,0,0,0,0,0,0,0,0,0,0,0,0,0,0,0,0,0
0,0,0,0,0,0,0,0,0,0,0,0,0,0,0,0,0,0,0,0,0
0,0,0,0,0,0,0,0,0,0,0,0,0,0,0,0,0,0,0,0,0
0,0,0,0,0,0,0,0,0,0,0,0,0,0,0,0,0,0,0,0,0
0,0,0,0,0,0,0,0,0,0,0,0,0,0,0,0,0,0,0,0,0
endlayer

layer
0,0,0,0,0,0,0,0,0,0,0,0,0,0,0,0,0,0,0,0,0
0,0,0,0,0,0,0,0,0,0,0,0,0,0,0,0,0,0,0,0,0
0,0,0,0,0,0,0,0,0,0,0,0,0,0,0,0,0,0,0,0,0
0,0,0,0,0,0,0,0,0,0,0,0,0,0,0,0,0,0,0,0,0
0,0,0,0,0,0,0,0,0,0,0,0,0,0,0,0,0,0,0,0,0
0,0,0,0,0,0,0,0,0,0,0,0,0,0,0,0,0,0,0,0,0
0,0,0,0,0,0,0,0,0,0,0,0,0,0,0,0,0,0,0,0,0
0,0,0,0,0,0,0,0,0,0,0,0,0,0,0,0,0,0,0,0,0
0,0,0,0,0,0,0,0,0,0,0,0,0,0,0,0,0,0,0,0,0
0,0,0,0,0,0,0,0,0,0,0,0,0,0,0,0,0,0,0,0,0
0,0,0,0,0,0,0,0,0,0,36,0,0,0,0,0,0,0,0,0,0
0,0,0,0,0,0,0,0,0,0,0,0,0,0,0,0,0,0,0,0,0
0,0,0,0,0,0,0,0,0,0,0,0,0,0,0,0,0,0,0,0,0
0,0,0,0,0,0,0,0,0,0,0,0,0,0,0,0,0,0,0,0,0
0,0,0,0,0,0,0,0,0,0,0,0,0,0,0,0,0,0,0,0,0
0,0,0,0,0,0,0,0,0,0,0,0,0,0,0,0,0,0,0,0,0
0,0,0,0,0,0,0,0,0,0,0,0,0,0,0,0,0,0,0,0,0
0,0,0,0,0,0,0,0,0,0,0,0,0,0,0,0,0,0,0,0,0
0,0,0,0,0,0,0,0,0,0,0,0,0,0,0,0,0,0,0,0,0
0,0,0,0,0,0,0,0,0,0,0,0,0,0,0,0,0,0,0,0,0
0,0,0,0,0,0,0,0,0,0,0,0,0,0,0,0,0,0,0,0,0
endlayer

