# Wizard Tower #3
# Created by Ruins mod version 12.3 Ingame Parser
# authoring Player: Jordan_Greywolf
# Updated to MC 1.8: 28 Feb 2016
# Updated to MC 1.9: 30 Apr 2016
# Updated to MC 1.11: 13 Jan 2017
# Updated to MC 1.12: 8 Jul 2017
# Updated to MC 1.12.1: 10 Sep 2017

biomesToSpawnIn=alpine,alps,alps forest,alps_foothills,autumn hills,autumnal_woods,boreal_forest,coniferous_forest,dark forest,deserthills,desert_hills,dead_forest,enchanted forest,extreme hills,extreme_hills,extreme_hills_with_trees,extreme hills edge,extreme hills+,extreme hills m,extreme hills+ m,extreme jungle,forested hills,foresthills,forest_hills,green hills,highland,highlands,ice mountains,ice_mountains,junglehills,jungle_hills,mountain ridge,mountain taiga,mountainous desert,taiga hills,taiga,stone beach,stone_beach,roofed forest,roofed_forest,oak savannah,oak_savannah,mega taiga,mega spruce taiga,birch forest,roofed forest m,wonderous woods,woodland,woodlands,ominous woods,thick ominous woods,sludgepit,mystic woods,mystic_woods,magical forest,eerie,eldritch,tainted land,bayou,swampland,wetland,wetlands,white_beach,witherlands,xeric shrubland,xeric_shrubland

uniqueMinDistance=2000
spawnMinDistance=800


weight=1
embed_into_distance=6

unacceptable_target_blocks=lava,flowing_lava,red_mushroom_block,brown_mushroom_block,water,flowing_water,cloud,Natura:Cloud,slime_congealed,slime_dirt,slime_grass,command_block,planks,planks2,concrete,cobblestone,stonebrick,brick_block,glass,torch,oak_stairs,stone_stairs,brick_stairs,stone_brick_stairs,nether_brick_stairs,sandstone_stairs,spruce_stairs,birch_stairs,jungle_stairs,quartz_stairs,acacia_stairs,dark_oak_stairs,cobblestone_wall,stone_slab,double_stone_slab,stone_slab2,wooden_slab,double_wooden_slab,nether_brick,fence

dimensions=57,12,12
allowable_overhang=50
max_cut_in=0
cut_in_buffer=0
max_leveling=6
leveling_buffer=-1
preserve_water=0
preserve_lava=0
preserve_plants=1

rule1=0,100,preserveBlock
rule2=0,100,minecraft:stone-0
rule3=0,100,minecraft:stonebrick-0
rule4=0,100,minecraft:quartz_block-2
rule5=0,100,minecraft:wooden_slab-1
rule6=0,100,minecraft:wooden_slab-9
rule7=0,100,minecraft:double_wooden_slab-1
rule8=0,100,minecraft:web-0

rule9=0,100,CommandBlock:RUINSTRIGGER /summon zombie_pigman ~0 ~0 ~0 {HandItems:[{Count:1,id:golden_sword,tag:{display:{Name:"Bone Saw"},ench:[{id:20,lvl:2},{id:19,lvl:2},{id:16,lvl:2}]}},{}],ArmorItems:[{Count:1,id:leather_boots,tag:{display:{Name:"Stitched Boots",color:0}}},{Count:1,id:chainmail_leggings,tag:{display:{Name:"Ragged Leggings"}}},{Count:1,id:leather_chestplate,tag:{display:{Name:"Stitched Leather",color:0}}},{Count:1,id:skull,Damage:3,tag:{SkullOwner:MHF_Herobrine}}],CustomName:"Flesh Golem",Attributes:[{Name:generic.knockbackResistance,Base:1}],HandDropChances:[0.5F,0.0F],ArmorDropChances:[0.1F,0.1F,0.1F,0.1F],ActiveEffects:[{Id:21,Amplifier:1,Duration:999999},{Id:11,Amplifier:1,Duration:999999},{Id:5,Amplifier:1,Duration:999999}],Silent:1,PersistenceRequired:1,CanBreakDoors:1,IsVillager:1,Anger:32767}:@

rule10=0,100,minecraft:stonebrick-3
rule11=0,100,minecraft:quartz_block-1

# Randomly missing floor blocks
rule12=0,75,minecraft:planks-1

rule13=0,100,minecraft:planks-1
rule14=0,100,minecraft:wool-14
rule15=0,100,minecraft:wooden_door-0
rule16=0,100,minecraft:fence-0
rule17=0,100,ChestGenHook:chests/simple_dungeon:3
rule18=0,100,minecraft:oak_stairs-3
rule19=0,100,minecraft:oak_stairs-2
rule20=0,100,ChestGenHook:chests/simple_dungeon:3
rule21=0,100,minecraft:wooden_door-8
rule22=0,100,minecraft:wooden_door-9
rule23=0,100,minecraft:redstone_lamp-0
rule24=0,100,minecraft:redstone_torch-5
rule25=0,100,minecraft:oak_stairs-1
rule26=0,100,minecraft:stone_pressure_plate-0
rule27=0,100,minecraft:crafting_table-0
rule28=0,100,minecraft:furnace-3
rule29=0,100,minecraft:bed-9
rule30=0,100,minecraft:bed-1
rule31=0,100,minecraft:bookshelf-0
rule32=0,100,minecraft:oak_stairs-0


# Evil Wizard!
rule33=0,100,CommandBlock:RUINSTRIGGER /summon witch ~0 ~0 ~0 {HandItems:[{},{Count:1,id:writable_book,tag:{display:{Name:"Dark Tome"},ench:[{id:20,lvl:2},{id:19,lvl:2}]}}],ArmorItems:[{Count:1,id:leather_boots,tag:{display:{Name:"Dark Sandals",Color:0}}},{Count:1,id:leather_leggings,tag:{display:{Name:"Dark Leggings",Color:0}}},{Count:1,id:leather_chestplate,tag:{display:{Name:"Dark Robes",Color:0}}},{Count:1,id:skull,Damage:3,tag:{SkullOwner:MHF_Herobrine}}],CustomName:"Evil Wizard",Health:100.0f,Attributes:[{Name:generic.knockbackResistance,Base:1}],HandDropChances:[1.0F,1.0F],ArmorDropChances:[0.5F,0.5F,0.5F,0.0F],ActiveEffects:[{Id:12,Amplifier:1,Duration:999999,Ambient:1},{Id:3,Amplifier:1,Duration:999999,Ambient:1},{Id:21,Amplifier:1,Duration:999999,Ambient:1},{Id:8,Amplifier:1,Duration:999999,Ambient:1},{Id:11,Amplifier:1,Duration:999999,Ambient:1},{Id:5,Amplifier:1,Duration:999999,Ambient:1},{Id:13,Amplifier:1,Duration:999999,Ambient:1}],Silent:1,PersistenceRequired:1}:@

rule34=0,100,MobSpawner:Skeleton,MobSpawner:Spider

layer
1,1,2,2,2,2,2,1,1,1,1,1
1,2,2,2,3,3,3,3,1,1,1,1
1,2,2,4,1,1,1,1,4,1,1,1
1,2,4,1,1,1,1,1,1,4,1,1
1,3,1,1,1,1,1,1,1,1,3,1
1,3,1,1,1,1,1,1,1,1,3,1
1,3,1,1,1,1,1,1,1,1,3,1
1,3,1,1,1,1,1,1,1,1,3,1
1,1,4,1,1,1,1,1,1,4,1,1
1,1,1,4,1,1,1,1,4,1,1,1
1,1,1,1,3,3,3,3,1,1,1,1
1,1,1,1,1,1,1,1,1,1,1,1
endlayer

layer
1,1,2,2,2,2,2,1,1,1,1,1
1,2,2,2,3,3,3,3,1,1,1,1
1,2,2,4,1,1,1,1,4,1,1,1
1,2,4,1,1,1,1,1,1,4,1,1
1,3,1,1,1,1,1,1,1,1,3,1
1,3,1,1,1,1,1,1,1,1,3,1
1,3,1,1,1,1,1,1,1,1,3,1
1,3,1,1,1,1,1,1,1,1,3,1
1,1,4,1,1,1,1,1,1,4,1,1
1,1,1,4,1,1,1,1,4,1,1,1
1,1,1,1,3,3,3,3,1,1,1,1
1,1,1,1,1,1,1,1,1,1,1,1
endlayer

layer
1,1,2,2,2,2,2,1,1,1,1,1
1,2,2,2,3,3,3,3,1,1,1,1
1,2,2,4,1,1,1,1,4,1,1,1
1,2,4,1,1,1,1,1,1,4,1,1
1,3,1,1,1,1,1,1,1,1,3,1
1,3,1,1,1,1,1,1,1,1,3,1
1,3,1,1,1,1,1,1,1,1,3,1
1,3,1,1,1,1,1,1,1,1,3,1
1,1,4,1,1,1,1,1,1,4,1,1
1,1,1,4,1,1,1,1,4,1,1,1
1,1,1,1,3,3,3,3,1,1,1,1
1,1,1,1,1,1,1,1,1,1,1,1
endlayer

layer
1,1,2,2,2,2,2,1,1,1,1,1
1,2,2,2,3,3,3,3,1,1,1,1
1,2,2,4,1,1,1,1,4,1,1,1
1,2,4,1,1,1,1,1,1,4,1,1
1,3,1,1,1,1,1,1,1,1,3,1
1,3,1,1,1,1,1,1,1,1,3,1
1,3,1,1,1,1,1,1,1,1,3,1
1,3,1,1,1,1,1,1,1,1,3,1
1,1,4,1,1,1,1,1,1,4,1,1
1,1,1,4,1,1,1,1,4,1,1,1
1,1,1,1,3,3,3,3,1,1,1,1
1,1,1,1,1,1,1,1,1,1,1,1
endlayer

layer
1,1,2,2,2,2,2,1,1,1,1,1
1,2,2,2,3,3,3,3,1,1,1,1
1,2,2,4,1,1,1,1,4,1,1,1
1,2,4,1,1,1,1,1,1,4,1,1
1,3,1,1,1,1,1,1,1,1,3,1
1,3,1,1,1,17,17,1,1,1,3,1
1,3,1,1,1,1,1,1,1,1,3,1
1,3,1,1,1,1,1,1,1,1,3,1
1,1,4,1,1,1,1,1,1,4,1,1
1,1,1,4,1,1,1,1,4,1,1,1
1,1,1,1,3,3,3,3,1,1,1,1
1,1,1,1,1,1,1,1,1,1,1,1
endlayer

layer
1,1,2,2,2,2,2,1,1,1,1,1
1,2,2,2,3,3,3,3,1,1,1,1
1,2,2,4,1,1,1,1,4,1,1,1
1,2,4,1,1,1,1,1,1,4,1,1
1,3,1,1,1,1,1,1,1,1,3,1
1,3,1,1,1,1,1,1,1,1,3,1
1,3,1,1,1,1,1,1,1,1,3,1
1,3,1,1,1,1,1,1,1,1,3,1
1,1,4,1,1,1,1,1,1,4,1,1
1,1,1,4,1,1,1,1,4,1,1,1
1,1,1,1,3,3,3,3,1,1,1,1
1,1,1,1,1,1,1,1,1,1,1,1
endlayer


layer
1,1,2,2,2,2,2,1,1,1,1,1
1,2,2,2,3,3,3,3,1,1,1,1
1,2,2,4,0,0,0,0,4,1,1,1
1,2,4,0,0,0,0,0,0,4,1,1
1,3,0,0,0,0,0,0,0,0,3,1
1,3,0,0,0,0,0,0,0,0,3,1
1,3,5,0,0,0,9,0,0,0,3,1
1,3,7,6,0,0,0,0,0,0,3,1
1,1,4,34,8,0,0,0,0,4,1,1
1,1,1,4,0,0,0,0,4,1,1,1
1,1,1,1,3,3,3,3,1,1,1,1
1,1,1,1,1,1,1,1,1,1,1,1
endlayer

layer
1,1,1,2,2,2,2,1,1,1,1,1
1,1,2,2,3,3,3,3,1,1,1,1
1,1,2,4,0,0,0,0,4,1,1,1
1,1,4,0,0,0,0,0,0,4,1,1
1,3,0,0,0,0,0,0,0,0,3,1
1,3,0,0,0,0,0,0,0,0,3,1
1,3,0,0,0,0,0,0,0,0,3,1
1,3,0,5,0,0,0,0,0,0,3,1
1,1,4,7,6,0,0,0,0,4,1,1
1,1,1,4,8,0,0,0,4,1,1,1
1,1,1,1,3,3,3,3,1,1,1,1
1,1,1,1,1,1,1,1,1,1,1,1
endlayer

layer
1,1,1,1,2,2,2,1,1,1,1,1
1,1,1,1,3,3,3,3,1,1,1,1
1,1,1,4,0,0,0,0,4,1,1,1
1,1,4,0,0,0,0,0,0,4,1,1
1,3,0,0,0,0,0,0,0,8,3,1
1,3,0,0,0,0,0,0,0,0,3,1
1,3,0,0,0,0,0,0,0,0,3,1
1,3,0,0,0,0,0,0,0,0,3,1
1,1,4,0,5,0,0,0,8,4,1,1
1,1,1,4,7,6,0,8,4,1,1,1
1,1,1,1,3,3,3,3,1,1,1,1
1,1,1,1,1,1,1,1,1,1,1,1
endlayer

layer
1,1,1,1,1,2,2,1,1,1,1,1
1,1,1,1,3,3,3,3,1,1,1,1
1,1,1,4,8,0,8,8,4,1,1,1
1,1,4,0,0,0,0,0,8,4,1,1
1,3,8,0,0,0,0,0,0,8,3,1
1,3,8,0,0,0,0,0,0,0,3,1
1,3,0,0,0,0,0,0,0,0,3,1
1,3,8,0,0,0,0,0,0,8,3,1
1,1,4,0,0,0,0,0,8,4,1,1
1,1,1,4,0,5,7,6,4,1,1,1
1,1,1,1,3,3,3,3,1,1,1,1
1,1,1,1,1,1,1,1,1,1,1,1
endlayer

layer
1,1,1,1,1,1,2,1,1,1,1,1
1,1,1,1,10,11,11,10,1,1,1,1
1,1,1,4,13,12,13,12,4,1,1,1
1,1,4,13,13,13,13,13,12,4,1,1
1,10,13,13,12,13,12,13,13,13,10,1
1,11,12,13,13,14,14,13,12,13,11,1
1,11,12,13,13,14,14,13,13,13,11,1
1,10,13,13,13,13,12,13,12,13,10,1
1,1,4,6,0,13,13,13,13,4,1,1
1,1,1,4,0,0,0,5,4,1,1,1
1,1,1,1,10,11,11,10,1,1,1,1
1,1,1,1,1,1,1,1,1,1,1,1
endlayer

layer
1,1,1,1,0,0,0,0,1,1,1,1
1,1,1,0,3,15,15,3,0,1,1,1
1,1,0,4,0,0,0,0,4,0,1,1
1,0,4,0,0,0,0,0,0,4,0,1
16,3,0,0,0,0,0,0,0,0,3,16
16,3,0,0,19,9,0,18,0,17,3,16
16,3,5,0,19,0,0,18,0,20,3,16
16,3,7,6,0,0,0,0,0,0,3,16
1,0,4,34,0,0,0,0,0,4,0,1
1,1,0,4,0,0,0,0,4,0,1,1
1,1,1,0,3,3,3,3,0,1,1,1
1,1,1,1,16,16,16,16,1,1,1,1
endlayer

layer
1,1,1,0,0,0,0,0,0,1,1,1
1,1,0,0,3,22,21,3,0,0,1,1
1,0,0,4,0,0,0,0,4,0,0,1
0,0,4,0,0,0,0,0,0,4,0,0
0,3,0,0,0,0,0,0,0,0,3,0
0,23,0,0,0,0,0,0,0,0,23,0
0,23,0,0,0,0,0,0,0,0,23,0
0,3,0,5,0,0,0,0,0,0,3,0
0,0,4,7,6,0,0,0,0,4,0,0
1,0,0,4,0,0,0,0,4,0,0,1
1,1,0,0,3,23,23,3,0,0,1,1
1,1,1,0,0,0,0,0,0,1,1,1
endlayer

layer
1,1,0,0,0,0,0,0,0,0,1,1
1,0,0,0,3,23,23,3,0,0,0,1
0,0,0,4,0,0,0,0,4,0,0,0
0,0,4,0,0,0,0,0,0,4,0,0
0,3,8,0,0,16,16,0,0,0,3,0
0,23,0,0,16,16,16,16,0,0,23,0
0,23,0,0,16,16,16,16,0,0,23,0
0,3,0,0,0,16,16,0,0,0,3,0
0,0,4,0,5,0,0,0,0,4,0,0
0,0,0,4,7,6,0,0,4,0,0,0
1,0,0,0,3,23,23,3,0,0,0,1
1,1,0,0,0,0,0,0,0,0,1,1
endlayer

layer
1,0,0,0,0,0,0,0,0,0,0,1
0,0,0,0,3,3,3,3,0,0,0,0
0,0,0,4,8,0,0,8,4,0,0,0
0,0,4,8,0,0,0,0,0,4,0,0
0,3,8,0,8,24,24,0,0,8,3,0
0,3,8,0,24,16,16,24,0,0,3,0
0,3,8,0,24,16,16,24,0,0,3,0
0,3,8,0,0,24,24,0,0,8,3,0
0,0,4,0,0,0,0,0,8,4,0,0
0,0,0,4,0,5,7,6,4,0,0,0
0,0,0,0,3,3,3,3,0,0,0,0
1,0,0,0,0,0,0,0,0,0,0,1
endlayer

layer
0,0,0,0,0,0,0,0,0,0,0,0
0,0,0,0,10,11,11,10,0,0,0,0
0,0,0,4,13,13,13,12,4,0,0,0
0,0,4,13,13,13,13,13,12,4,0,0
0,10,13,13,12,13,12,13,13,13,10,0
0,11,12,13,13,13,13,13,12,13,11,0
0,11,12,13,12,13,13,13,13,13,11,0
0,10,13,13,13,13,12,13,12,13,10,0
0,0,4,6,0,13,13,13,13,4,0,0
0,0,0,4,0,0,0,5,4,0,0,0
0,0,0,0,10,11,11,10,0,0,0,0
0,0,0,0,0,0,0,0,0,0,0,0
endlayer

layer
0,0,0,0,16,16,16,16,0,0,0,0
0,0,0,0,3,3,3,3,0,0,0,0
0,0,0,4,0,25,25,0,4,0,0,0
0,0,4,0,0,0,0,0,0,4,0,0
16,3,0,0,0,0,0,0,0,16,3,16
16,3,0,0,0,0,9,0,0,17,3,16
16,3,5,0,0,0,0,0,0,20,3,16
16,3,7,6,0,0,0,0,0,16,3,16
0,0,4,34,0,0,0,0,0,4,0,0
0,0,0,4,0,0,0,0,4,0,0,0
0,0,0,0,3,3,3,3,0,0,0,0
0,0,0,0,16,16,16,16,0,0,0,0
endlayer

layer
0,0,0,0,0,0,0,0,0,0,0,0
0,0,0,0,3,23,23,3,0,0,0,0
0,0,0,4,0,0,0,0,4,0,0,0
0,0,4,0,0,0,0,0,0,4,0,0
0,3,0,0,0,0,0,0,0,24,3,0
0,23,0,0,0,0,0,0,0,0,23,0
0,23,0,0,0,0,0,0,0,0,23,0
0,3,0,5,0,0,0,0,0,24,3,0
0,0,4,7,6,0,0,0,0,4,0,0
0,0,0,4,0,0,0,0,4,0,0,0
0,0,0,0,3,23,23,3,0,0,0,0
0,0,0,0,0,0,0,0,0,0,0,0
endlayer

layer
0,0,0,0,0,0,0,0,0,0,0,0
0,0,0,0,3,23,23,3,0,0,0,0
0,0,0,4,0,0,0,0,4,0,0,0
0,0,4,0,0,0,0,0,0,4,0,0
0,3,0,0,0,0,0,0,0,0,3,0
0,23,0,0,0,0,0,0,0,0,23,0
0,23,0,0,0,0,0,0,0,0,23,0
0,3,0,0,0,0,0,0,0,0,3,0
0,0,4,0,5,0,0,0,0,4,0,0
0,0,0,4,7,6,0,0,4,0,0,0
0,0,0,0,3,23,23,3,0,0,0,0
0,0,0,0,0,0,0,0,0,0,0,0
endlayer

layer
0,0,0,0,0,0,0,0,0,0,0,0
0,0,0,0,3,3,3,3,0,0,0,0
0,0,0,4,0,0,0,0,4,0,0,0
0,0,4,0,0,0,0,0,0,4,0,0
0,3,8,0,0,0,0,0,0,0,3,0
0,3,0,0,0,0,0,0,0,0,3,0
0,3,0,0,0,0,0,0,0,0,3,0
0,3,8,0,0,0,0,0,0,0,3,0
0,0,4,0,0,0,0,0,0,4,0,0
0,0,0,4,0,5,7,6,4,0,0,0
0,0,0,0,3,3,3,3,0,0,0,0
0,0,0,0,0,0,0,0,0,0,0,0
endlayer

layer
0,0,0,0,0,0,0,0,0,0,0,0
0,0,0,0,10,11,11,10,0,0,0,0
0,0,0,4,13,12,13,12,4,0,0,0
0,0,4,13,13,13,13,13,12,4,0,0
0,10,13,13,12,13,12,13,13,13,10,0
0,11,12,13,13,13,13,13,12,13,11,0
0,11,12,13,12,13,12,13,13,13,11,0
0,10,13,13,13,13,12,13,12,13,10,0
0,0,4,6,0,13,13,13,13,4,0,0
0,0,0,4,0,0,0,5,4,0,0,0
0,0,0,0,10,11,11,10,0,0,0,0
0,0,0,0,0,0,0,0,0,0,0,0
endlayer

layer
0,0,0,0,16,16,16,16,0,0,0,0
0,0,0,0,3,3,3,3,0,0,0,0
0,0,0,4,0,0,0,0,4,0,0,0
0,0,4,0,0,0,0,0,0,4,0,0
16,3,0,0,0,0,0,0,0,8,3,16
16,3,0,0,9,16,16,8,0,17,3,16
16,3,5,0,0,16,16,0,0,20,3,16
16,3,7,6,0,0,0,0,0,8,3,16
0,0,4,34,0,0,0,0,0,4,0,0
0,0,0,4,0,0,0,0,4,0,0,0
0,0,0,0,3,3,3,3,0,0,0,0
0,0,0,0,16,16,16,16,0,0,0,0
endlayer

layer
0,0,0,0,0,0,0,0,0,0,0,0
0,0,0,0,3,23,23,3,0,0,0,0
0,0,0,4,0,0,0,0,4,0,0,0
0,0,4,0,0,0,0,0,0,4,0,0
0,3,0,0,0,0,0,0,0,0,3,0
0,23,0,0,0,26,26,0,0,0,23,0
0,23,0,0,0,26,26,0,0,0,23,0
0,3,0,5,0,0,0,0,0,0,3,0
0,0,4,7,6,0,0,0,0,4,0,0
0,0,0,4,0,0,0,0,4,0,0,0
0,0,0,0,3,23,23,3,0,0,0,0
0,0,0,0,0,0,0,0,0,0,0,0
endlayer

layer
0,0,0,0,0,0,0,0,0,0,0,0
0,0,0,0,3,23,23,3,0,0,0,0
0,0,0,4,0,0,0,0,4,0,0,0
0,0,4,0,0,0,0,0,0,4,0,0
0,3,0,0,0,0,0,0,0,0,3,0
0,23,0,0,0,0,0,0,0,0,23,0
0,23,0,0,0,0,0,0,0,0,23,0
0,3,0,0,0,0,0,0,0,0,3,0
0,0,4,0,5,0,0,0,8,4,0,0
0,0,0,4,7,6,0,8,4,0,0,0
0,0,0,0,3,23,23,3,0,0,0,0
0,0,0,0,0,0,0,0,0,0,0,0
endlayer

layer
0,0,0,0,0,0,0,0,0,0,0,0
0,0,0,0,3,3,3,3,0,0,0,0
0,0,0,4,8,0,0,8,4,0,0,0
0,0,4,8,0,0,0,0,8,4,0,0
0,3,8,0,0,0,0,0,0,8,3,0
0,3,0,0,0,0,0,0,0,0,3,0
0,3,0,0,0,0,0,0,0,0,3,0
0,3,0,0,0,0,0,0,0,8,3,0
0,0,4,0,0,0,0,0,8,4,0,0
0,0,0,4,0,5,7,6,4,0,0,0
0,0,0,0,3,3,3,3,0,0,0,0
0,0,0,0,0,0,0,0,0,0,0,0
endlayer

layer
0,0,0,0,0,0,0,0,0,0,0,0
0,0,0,0,10,11,11,10,0,0,0,0
0,0,0,4,13,13,13,12,4,0,0,0
0,0,4,13,13,13,13,13,12,4,0,0
0,10,13,13,12,13,12,13,13,13,10,0
0,11,12,13,13,13,12,13,12,13,11,0
0,11,12,13,12,12,13,13,13,13,11,0
0,10,13,13,13,13,12,13,12,13,10,0
0,0,4,6,0,13,13,13,13,4,0,0
0,0,0,4,0,0,0,5,4,0,0,0
0,0,0,0,10,11,11,10,0,0,0,0
0,0,0,0,0,0,0,0,0,0,0,0
endlayer

layer
0,0,0,0,16,16,16,16,0,0,0,0
0,0,0,0,3,3,3,3,0,0,0,0
0,0,0,4,0,0,0,0,4,0,0,0
0,0,4,0,0,0,0,0,0,4,0,0
16,3,0,0,0,0,0,16,0,27,3,16
16,3,0,0,0,9,0,16,0,17,3,16
16,3,5,0,0,0,0,16,0,20,3,16
16,3,7,6,0,0,0,16,0,28,3,16
0,0,4,34,0,0,0,0,0,4,0,0
0,0,0,4,0,0,0,0,4,0,0,0
0,0,0,0,3,3,3,3,0,0,0,0
0,0,0,0,16,16,16,16,0,0,0,0
endlayer

layer
0,0,0,0,0,0,0,0,0,0,0,0
0,0,0,0,3,23,23,3,0,0,0,0
0,0,0,4,0,0,0,0,4,0,0,0
0,0,4,0,0,0,0,0,0,4,0,0
0,3,0,0,0,0,0,26,0,0,3,0
0,23,0,0,0,0,0,26,0,0,23,0
0,23,0,0,0,0,0,26,0,0,23,0
0,3,0,5,0,0,0,26,0,0,3,0
0,0,4,7,6,0,0,0,0,4,0,0
0,0,0,4,0,8,0,0,4,0,0,0
0,0,0,0,3,23,23,3,0,0,0,0
0,0,0,0,0,0,0,0,0,0,0,0
endlayer

layer
0,0,0,0,0,0,0,0,0,0,0,0
0,0,0,0,3,23,23,3,0,0,0,0
0,0,0,4,8,0,0,0,4,0,0,0
0,0,4,0,0,0,0,0,0,4,0,0
0,3,0,0,0,0,0,0,0,0,3,0
0,23,0,0,0,0,0,0,0,0,23,0
0,23,0,0,0,0,0,0,0,0,23,0
0,3,0,0,0,0,0,0,0,0,3,0
0,0,4,0,5,0,0,0,0,4,0,0
0,0,0,4,7,6,0,0,4,0,0,0
0,0,0,0,3,23,23,3,0,0,0,0
0,0,0,0,0,0,0,0,0,0,0,0
endlayer

layer
0,0,0,0,0,0,0,0,0,0,0,0
0,0,0,0,3,3,3,3,0,0,0,0
0,0,0,4,8,0,8,8,4,0,0,0
0,0,4,8,0,0,0,0,8,4,0,0
0,3,0,0,0,0,0,0,0,8,3,0
0,3,0,0,0,0,0,0,0,0,3,0
0,3,0,0,0,0,0,0,0,0,3,0
0,3,0,0,0,0,0,0,0,8,3,0
0,0,4,0,0,0,0,0,0,4,0,0
0,0,0,4,0,5,7,6,4,0,0,0
0,0,0,0,3,3,3,3,0,0,0,0
0,0,0,0,0,0,0,0,0,0,0,0
endlayer

layer
0,0,0,0,0,0,0,0,0,0,0,0
0,0,0,0,10,11,11,10,0,0,0,0
0,0,0,4,13,13,13,13,4,0,0,0
0,0,4,13,13,13,13,13,12,4,0,0
0,10,13,13,13,13,13,13,13,13,10,0
0,11,12,13,13,13,13,13,12,13,11,0
0,11,12,13,12,13,13,13,13,13,11,0
0,10,13,13,13,13,12,13,12,13,10,0
0,0,4,6,0,13,13,13,13,4,0,0
0,0,0,4,0,0,0,5,4,0,0,0
0,0,0,0,10,11,11,10,0,0,0,0
0,0,0,0,0,0,0,0,0,0,0,0
endlayer

layer
0,0,0,0,16,16,16,16,0,0,0,0
0,0,0,0,3,3,3,3,0,0,0,0
0,0,0,4,13,13,13,13,4,0,0,0
0,0,4,0,5,29,29,5,8,4,0,0
16,3,0,0,5,30,30,5,0,0,3,16
16,3,0,0,13,5,5,13,0,17,3,16
16,3,5,0,0,0,0,0,0,20,3,16
16,3,7,6,0,0,0,0,0,0,3,16
0,0,4,34,0,0,0,0,0,4,0,0
0,0,0,4,0,0,0,0,4,0,0,0
0,0,0,0,3,3,3,3,0,0,0,0
0,0,0,0,16,16,16,16,0,0,0,0
endlayer

layer
0,0,0,0,0,0,0,0,0,0,0,0
0,0,0,0,3,23,23,3,0,0,0,0
0,0,0,4,16,0,0,16,4,0,0,0
0,0,4,0,0,0,0,0,0,4,0,0
0,3,0,0,0,0,0,0,0,0,3,0
0,23,0,0,16,0,0,16,0,0,23,0
0,23,0,0,0,9,0,0,0,0,23,0
0,3,0,5,0,0,0,0,0,0,3,0
0,0,4,7,6,0,0,0,0,4,0,0
0,0,0,4,0,0,0,0,4,0,0,0
0,0,0,0,3,23,23,3,0,0,0,0
0,0,0,0,0,0,0,0,0,0,0,0
endlayer

layer
0,0,0,0,0,0,0,0,0,0,0,0
0,0,0,0,3,23,23,3,0,0,0,0
0,0,0,4,16,8,0,16,4,0,0,0
0,0,4,0,0,0,0,0,0,4,0,0
0,3,0,0,0,0,0,0,0,0,3,0
0,23,0,0,16,0,0,16,0,0,23,0
0,23,0,0,0,0,0,0,0,0,23,0
0,3,0,0,0,0,0,0,0,8,3,0
0,0,4,0,5,0,0,0,0,4,0,0
0,0,0,4,7,6,0,8,4,0,0,0
0,0,0,0,3,23,23,3,0,0,0,0
0,0,0,0,0,0,0,0,0,0,0,0
endlayer

layer
0,0,0,0,0,0,0,0,0,0,0,0
0,0,0,0,3,3,3,3,0,0,0,0
0,0,0,4,14,14,14,14,4,0,0,0
0,0,4,8,14,14,14,14,8,4,0,0
0,3,8,0,14,14,14,14,0,8,3,0
0,3,0,0,14,14,14,14,0,8,3,0
0,3,0,0,0,0,0,0,0,8,3,0
0,3,0,0,0,0,0,0,0,8,3,0
0,0,4,0,0,0,0,0,8,4,0,0
0,0,0,4,0,5,7,6,4,0,0,0
0,0,0,0,3,3,3,3,0,0,0,0
0,0,0,0,0,0,0,0,0,0,0,0
endlayer

layer
0,0,0,0,0,0,0,0,0,0,0,0
0,0,0,0,10,11,11,10,0,0,0,0
0,0,0,4,13,13,13,13,4,0,0,0
0,0,4,13,13,13,13,13,13,4,0,0
0,10,13,13,13,13,13,13,13,13,10,0
0,11,12,13,13,13,13,13,12,13,11,0
0,11,12,13,12,13,13,13,13,13,11,0
0,10,13,13,13,13,12,13,12,13,10,0
0,0,4,6,0,13,13,13,13,4,0,0
0,0,0,4,0,0,0,5,4,0,0,0
0,0,0,0,10,11,11,10,0,0,0,0
0,0,0,0,0,0,0,0,0,0,0,0
endlayer

layer
0,0,0,0,16,16,16,16,0,0,0,0
0,0,0,0,3,3,3,3,0,0,0,0
0,0,0,4,31,16,16,31,4,0,0,0
0,0,4,0,0,32,32,0,0,4,0,0
16,3,0,0,0,0,0,0,0,31,3,16
16,3,0,0,0,9,0,0,0,17,3,16
16,3,5,0,0,0,0,0,0,20,3,16
16,3,7,6,0,0,0,0,0,31,3,16
0,0,4,34,0,0,0,0,0,4,0,0
0,0,0,4,0,0,0,0,4,0,0,0
0,0,0,0,3,3,3,3,0,0,0,0
0,0,0,0,16,16,16,16,0,0,0,0
endlayer

layer
0,0,0,0,0,0,0,0,0,0,0,0
0,0,0,0,3,23,23,3,0,0,0,0
0,0,0,4,31,26,26,31,4,0,0,0
0,0,4,0,0,0,0,0,0,4,0,0
0,3,0,0,0,0,0,0,0,31,3,0
0,23,0,0,0,0,0,0,0,0,23,0
0,23,0,0,0,0,0,0,0,0,23,0
0,3,0,5,0,0,0,0,0,31,3,0
0,0,4,7,6,0,0,0,0,4,0,0
0,0,0,4,0,0,0,0,4,0,0,0
0,0,0,0,3,23,23,3,0,0,0,0
0,0,0,0,0,0,0,0,0,0,0,0
endlayer

layer
0,0,0,0,0,0,0,0,0,0,0,0
0,0,0,0,3,23,23,3,0,0,0,0
0,0,0,4,31,0,0,31,4,0,0,0
0,0,4,0,0,0,0,0,0,4,0,0
0,3,0,0,0,0,0,0,0,31,3,0
0,23,0,0,0,0,0,0,0,0,23,0
0,23,0,0,0,0,0,0,0,0,23,0
0,3,0,0,0,0,0,0,0,31,3,0
0,0,4,0,5,0,0,0,0,4,0,0
0,0,0,4,7,6,0,0,4,0,0,0
0,0,0,0,3,23,23,3,0,0,0,0
0,0,0,0,0,0,0,0,0,0,0,0
endlayer

layer
0,0,0,0,0,0,0,0,0,0,0,0
0,0,0,0,3,3,3,3,0,0,0,0
0,0,0,4,31,14,14,31,4,0,0,0
0,0,4,0,0,0,0,0,0,4,0,0
0,3,0,0,0,0,0,0,0,31,3,0
0,3,0,0,0,0,0,0,0,14,3,0
0,3,0,0,0,0,0,0,0,14,3,0
0,3,0,0,0,0,0,0,0,31,3,0
0,0,4,0,0,0,0,0,0,4,0,0
0,0,0,4,0,5,7,6,4,0,0,0
0,0,0,0,3,3,3,3,0,0,0,0
0,0,0,0,0,0,0,0,0,0,0,0
endlayer

layer
0,0,0,0,0,0,0,0,0,0,0,0
0,0,0,0,10,11,11,10,0,0,0,0
0,0,0,4,13,13,13,13,4,0,0,0
0,0,4,13,13,13,13,13,12,4,0,0
0,10,13,13,12,13,12,13,13,13,10,0
0,11,12,13,13,13,13,13,12,13,11,0
0,11,12,13,12,13,13,13,13,13,11,0
0,10,13,13,13,13,12,13,12,13,10,0
0,0,4,6,0,13,13,13,13,4,0,0
0,0,0,4,0,0,0,5,4,0,0,0
0,0,0,0,10,11,11,10,0,0,0,0
0,0,0,0,0,0,0,0,0,0,0,0
endlayer

layer
0,0,0,0,16,16,16,16,0,0,0,0
0,0,0,0,3,3,3,3,0,0,0,0
0,0,0,4,0,0,0,0,4,0,0,0
0,0,4,0,0,0,0,0,0,4,0,0
16,3,0,0,0,0,0,0,0,0,3,16
16,3,0,0,0,0,33,0,0,17,3,16
16,3,0,0,9,0,0,0,0,17,3,16
16,3,0,0,0,0,0,0,0,0,3,16
0,0,4,0,0,0,0,0,0,4,0,0
0,0,0,4,0,0,0,0,4,0,0,0
0,0,0,0,3,3,3,3,0,0,0,0
0,0,0,0,16,16,16,16,0,0,0,0
endlayer

layer
0,0,0,0,24,0,0,24,0,0,0,0
0,0,0,0,0,0,0,0,0,0,0,0
0,0,0,4,0,0,0,0,4,0,0,0
0,0,4,0,0,0,0,0,0,4,0,0
24,0,0,0,0,0,0,0,0,0,0,24
0,0,0,0,0,0,0,0,0,0,0,0
0,0,0,0,0,0,0,0,0,0,0,0
24,0,0,0,0,0,0,0,0,0,0,24
0,0,4,0,0,0,0,0,0,4,0,0
0,0,0,4,0,0,0,0,4,0,0,0
0,0,0,0,0,0,0,0,0,0,0,0
0,0,0,0,24,0,0,24,0,0,0,0
endlayer

layer
0,0,0,0,0,0,0,0,0,0,0,0
0,0,0,0,0,0,0,0,0,0,0,0
0,0,0,4,0,0,0,0,4,0,0,0
0,0,4,0,0,0,0,0,0,4,0,0
0,0,0,0,0,0,0,0,0,0,0,0
0,0,0,0,0,0,0,0,0,0,0,0
0,0,0,0,0,0,0,0,0,0,0,0
0,0,0,0,0,0,0,0,0,0,0,0
0,0,4,0,0,0,0,0,0,4,0,0
0,0,0,4,0,0,0,0,4,0,0,0
0,0,0,0,0,0,0,0,0,0,0,0
0,0,0,0,0,0,0,0,0,0,0,0
endlayer

layer
0,0,0,0,5,5,5,5,0,0,0,0
0,0,0,5,13,13,13,13,5,0,0,0
0,0,5,13,13,13,13,13,13,5,0,0
0,5,13,13,13,0,0,13,13,13,5,0
5,13,13,13,0,0,0,0,13,13,13,5
5,13,13,0,0,0,0,0,0,13,13,5
5,13,13,0,0,0,0,0,0,13,13,5
5,13,13,13,0,0,0,0,13,13,13,5
0,5,13,13,13,0,0,13,13,13,5,0
0,0,5,13,13,13,13,13,13,5,0,0
0,0,0,5,13,13,13,13,5,0,0,0
0,0,0,0,5,5,5,5,0,0,0,0
endlayer

layer
0,0,0,0,0,0,0,0,0,0,0,0
0,0,0,0,0,0,0,0,0,0,0,0
0,0,0,0,5,13,13,5,0,0,0,0
0,0,0,5,13,13,13,13,5,0,0,0
0,0,5,13,13,0,0,13,13,5,0,0
0,0,13,13,0,0,0,0,13,13,0,0
0,0,13,13,0,0,0,0,13,13,0,0
0,0,5,13,13,0,0,13,13,5,0,0
0,0,0,5,13,13,13,13,5,0,0,0
0,0,0,0,5,13,13,5,0,0,0,0
0,0,0,0,0,0,0,0,0,0,0,0
0,0,0,0,0,0,0,0,0,0,0,0
endlayer

layer
0,0,0,0,0,0,0,0,0,0,0,0
0,0,0,0,0,0,0,0,0,0,0,0
0,0,0,0,0,0,0,0,0,0,0,0
0,0,0,0,0,13,13,0,0,0,0,0
0,0,0,0,13,0,0,13,0,0,0,0
0,0,0,13,0,0,0,0,13,0,0,0
0,0,0,13,0,0,0,0,13,0,0,0
0,0,0,0,13,0,0,13,0,0,0,0
0,0,0,0,0,13,13,0,0,0,0,0
0,0,0,0,0,0,0,0,0,0,0,0
0,0,0,0,0,0,0,0,0,0,0,0
0,0,0,0,0,0,0,0,0,0,0,0
endlayer

layer
0,0,0,0,0,0,0,0,0,0,0,0
0,0,0,0,0,0,0,0,0,0,0,0
0,0,0,0,0,0,0,0,0,0,0,0
0,0,0,0,0,13,13,0,0,0,0,0
0,0,0,0,13,13,13,13,0,0,0,0
0,0,0,13,13,0,0,13,13,0,0,0
0,0,0,13,13,0,0,13,13,0,0,0
0,0,0,0,13,13,13,13,0,0,0,0
0,0,0,0,0,13,13,0,0,0,0,0
0,0,0,0,0,0,0,0,0,0,0,0
0,0,0,0,0,0,0,0,0,0,0,0
0,0,0,0,0,0,0,0,0,0,0,0
endlayer

layer
0,0,0,0,0,0,0,0,0,0,0,0
0,0,0,0,0,0,0,0,0,0,0,0
0,0,0,0,0,0,0,0,0,0,0,0
0,0,0,0,0,5,5,0,0,0,0,0
0,0,0,0,5,13,13,5,0,0,0,0
0,0,0,5,13,0,0,13,5,0,0,0
0,0,0,5,13,0,0,13,5,0,0,0
0,0,0,0,5,13,13,5,0,0,0,0
0,0,0,0,0,5,5,0,0,0,0,0
0,0,0,0,0,0,0,0,0,0,0,0
0,0,0,0,0,0,0,0,0,0,0,0
0,0,0,0,0,0,0,0,0,0,0,0
endlayer

layer
0,0,0,0,0,0,0,0,0,0,0,0
0,0,0,0,0,0,0,0,0,0,0,0
0,0,0,0,0,0,0,0,0,0,0,0
0,0,0,0,0,0,0,0,0,0,0,0
0,0,0,0,0,13,13,0,0,0,0,0
0,0,0,0,13,13,13,13,0,0,0,0
0,0,0,0,13,13,13,13,0,0,0,0
0,0,0,0,0,13,13,0,0,0,0,0
0,0,0,0,0,0,0,0,0,0,0,0
0,0,0,0,0,0,0,0,0,0,0,0
0,0,0,0,0,0,0,0,0,0,0,0
0,0,0,0,0,0,0,0,0,0,0,0
endlayer

layer
0,0,0,0,0,0,0,0,0,0,0,0
0,0,0,0,0,0,0,0,0,0,0,0
0,0,0,0,0,0,0,0,0,0,0,0
0,0,0,0,0,0,0,0,0,0,0,0
0,0,0,0,0,5,5,0,0,0,0,0
0,0,0,0,5,13,13,5,0,0,0,0
0,0,0,0,5,13,13,5,0,0,0,0
0,0,0,0,0,5,5,0,0,0,0,0
0,0,0,0,0,0,0,0,0,0,0,0
0,0,0,0,0,0,0,0,0,0,0,0
0,0,0,0,0,0,0,0,0,0,0,0
0,0,0,0,0,0,0,0,0,0,0,0
endlayer

layer
0,0,0,0,0,0,0,0,0,0,0,0
0,0,0,0,0,0,0,0,0,0,0,0
0,0,0,0,0,0,0,0,0,0,0,0
0,0,0,0,0,0,0,0,0,0,0,0
0,0,0,0,0,0,0,0,0,0,0,0
0,0,0,0,0,13,13,0,0,0,0,0
0,0,0,0,0,13,13,0,0,0,0,0
0,0,0,0,0,0,0,0,0,0,0,0
0,0,0,0,0,0,0,0,0,0,0,0
0,0,0,0,0,0,0,0,0,0,0,0
0,0,0,0,0,0,0,0,0,0,0,0
0,0,0,0,0,0,0,0,0,0,0,0
endlayer

layer
0,0,0,0,0,0,0,0,0,0,0,0
0,0,0,0,0,0,0,0,0,0,0,0
0,0,0,0,0,0,0,0,0,0,0,0
0,0,0,0,0,0,0,0,0,0,0,0
0,0,0,0,0,0,0,0,0,0,0,0
0,0,0,0,0,13,13,0,0,0,0,0
0,0,0,0,0,13,13,0,0,0,0,0
0,0,0,0,0,0,0,0,0,0,0,0
0,0,0,0,0,0,0,0,0,0,0,0
0,0,0,0,0,0,0,0,0,0,0,0
0,0,0,0,0,0,0,0,0,0,0,0
0,0,0,0,0,0,0,0,0,0,0,0
endlayer

layer
0,0,0,0,0,0,0,0,0,0,0,0
0,0,0,0,0,0,0,0,0,0,0,0
0,0,0,0,0,0,0,0,0,0,0,0
0,0,0,0,0,0,0,0,0,0,0,0
0,0,0,0,0,0,0,0,0,0,0,0
0,0,0,0,0,13,13,0,0,0,0,0
0,0,0,0,0,13,13,0,0,0,0,0
0,0,0,0,0,0,0,0,0,0,0,0
0,0,0,0,0,0,0,0,0,0,0,0
0,0,0,0,0,0,0,0,0,0,0,0
0,0,0,0,0,0,0,0,0,0,0,0
0,0,0,0,0,0,0,0,0,0,0,0
endlayer

layer
0,0,0,0,0,0,0,0,0,0,0,0
0,0,0,0,0,0,0,0,0,0,0,0
0,0,0,0,0,0,0,0,0,0,0,0
0,0,0,0,0,0,0,0,0,0,0,0
0,0,0,0,0,0,0,0,0,0,0,0
0,0,0,0,0,16,16,0,0,0,0,0
0,0,0,0,0,16,16,0,0,0,0,0
0,0,0,0,0,0,0,0,0,0,0,0
0,0,0,0,0,0,0,0,0,0,0,0
0,0,0,0,0,0,0,0,0,0,0,0
0,0,0,0,0,0,0,0,0,0,0,0
0,0,0,0,0,0,0,0,0,0,0,0
endlayer

layer
0,0,0,0,0,0,0,0,0,0,0,0
0,0,0,0,0,0,0,0,0,0,0,0
0,0,0,0,0,0,0,0,0,0,0,0
0,0,0,0,0,0,0,0,0,0,0,0
0,0,0,0,0,0,0,0,0,0,0,0
0,0,0,0,0,16,16,0,0,0,0,0
0,0,0,0,0,16,16,0,0,0,0,0
0,0,0,0,0,0,0,0,0,0,0,0
0,0,0,0,0,0,0,0,0,0,0,0
0,0,0,0,0,0,0,0,0,0,0,0
0,0,0,0,0,0,0,0,0,0,0,0
0,0,0,0,0,0,0,0,0,0,0,0
endlayer

layer
0,0,0,0,0,0,0,0,0,0,0,0
0,0,0,0,0,0,0,0,0,0,0,0
0,0,0,0,0,0,0,0,0,0,0,0
0,0,0,0,0,0,0,0,0,0,0,0
0,0,0,0,0,0,0,0,0,0,0,0
0,0,0,0,0,24,24,0,0,0,0,0
0,0,0,0,0,24,24,0,0,0,0,0
0,0,0,0,0,0,0,0,0,0,0,0
0,0,0,0,0,0,0,0,0,0,0,0
0,0,0,0,0,0,0,0,0,0,0,0
0,0,0,0,0,0,0,0,0,0,0,0
0,0,0,0,0,0,0,0,0,0,0,0
endlayer

