
# WizardTower_1 (20 Apr 2014) -- no Command Blocks
# Updated to MC 1.7.10, 8 Oct 2014
# Created by Ruins mod version 12.3 Ingame Parser
# authoring Player: Jordan_Greywolf

# Updated to MC 1.8: 28 Feb 2016
# Updated to MC 1.9: 30 Apr 2016
# Updated to MC 1.11: 13 Jan 2017
# Updated to MC 1.12: 8 Jul 2017
# Updated to MC 1.12.1: 10 Sep 2017

uniqueMinDistance=2000

biomesToSpawnIn=alps,alps forest,alps_foothills,alpine,birch forest,birch_forest,boreal_forest,cherry blossom grove,cherry_blossom_grove,clearing,dead forest,dead_forest,dead swamp,dead_swamp,deadlands,desert,eerie,eldritch,extreme hills,extreme_hills,extreme_hills_with_trees,extreme hills edge,extreme hills m,extreme hills+,extreme hills+ m,forest,foresthills,forest_hills,green hills,green_hills,land_of_lakes,magical forest,meadow,mega taiga hills,mountain,mountain ridge,mountain_ridge,mystic grove,mystic_grove,oak_savannah,ominous woods,ominous_woods,origin_island,pasture,plains,prairie,savanna,shield,scrubland,shrubland,silkglades,smaller_extreme_hills,taiga,taigahills,taiga_hills,tainted land,thinned mystic grove,thinned timber,twilight clearing,twilight_clearing,wonderous woods,woodland,woodlands

weight=1
embed_into_distance=5

unacceptable_target_blocks=cloud,Natura:Cloud,slime_congealed,slime_dirt,slime_grass,command_block,planks,planks2,concrete,cobblestone,stonebrick,brick_block,glass,torch,oak_stairs,stone_stairs,brick_stairs,stone_brick_stairs,nether_brick_stairs,sandstone_stairs,spruce_stairs,birch_stairs,jungle_stairs,quartz_stairs,acacia_stairs,dark_oak_stairs,cobblestone_wall,stone_slab,double_stone_slab,stone_slab2,wooden_slab,double_wooden_slab,nether_brick,fence


dimensions=60,21,21
allowable_overhang=500
max_cut_in=0
cut_in_buffer=0
max_leveling=5
leveling_buffer=-1
preserve_water=0
preserve_lava=0
preserve_plants=1

# Dirt
rule1=0,100,preserveBlock

# Stone Bricks (randomized)
rule2=0,100,minecraft:stonebrick-0,minecraft:stonebrick-1,minecraft:stonebrick-2

# Nether Bricks
rule3=0,100,minecraft:nether_brick-0

# Wool (red)
rule4=0,100,minecraft:wool-14

# Cobblestone Wall (Mossy)
rule5=0,100,minecraft:cobblestone_wall-1

# Stone Bricks (Chiseled)
rule6=0,100,minecraft:stonebrick-3

# Cobweb
rule7=0,50,minecraft:web-0

# Fence
rule8=0,100,minecraft:dark_oak_fence-0

# Oak Stairs
rule9=0,100,minecraft:oak_stairs-3
rule10=0,100,minecraft:oak_stairs-2

# Monster Spawner
rule11=0,100,MobSpawner:Cave_Spider,MobSpawner:Skeleton

# Stone Slab (Upper)
rule12=0,100,minecraft:stone_slab-8

# Double Stone Slab
rule13=0,100,minecraft:double_stone_slab-0

# Stone Slab (Lower)
rule14=0,100,minecraft:stone_slab-0

# Bonus Chest
rule15=0,100,ChestGenHook:chests/spawn_bonus_chest:3-5
rule16=0,100,ChestGenHook:chests/spawn_bonus_chest:3-4

# Wooden Door
rule17=1,100,minecraft:dark_oak_door-2

# Nether Brick Stairs
rule18=0,100,minecraft:nether_brick_stairs-4
rule19=0,100,minecraft:nether_brick_stairs-6
rule20=0,100,minecraft:nether_brick_stairs-7
rule21=0,100,minecraft:nether_brick_stairs-5

# Iron Bars
rule22=0,100,minecraft:iron_bars-0

# Stone Pressure Plate
rule23=0,100,minecraft:stone_pressure_plate-0

# Wooden Door
rule24=0,100,minecraft:dark_oak_door-8

# Nether Brick Stairs
rule25=0,100,minecraft:nether_brick_stairs-2
rule26=0,100,minecraft:nether_brick_stairs-3

# Furnace
rule27=0,100,IInventory;minecraft:lit_furnace;minecraft:coal#2#1#1-5

# Cauldron (DV 3 = fully filled)
rule28=0,100,minecraft:cauldron-3

# Crafting Table
rule29=0,100,minecraft:crafting_table-0

# Dungeon Chest
rule30=0,100,ChestGenHook:chests/simple_dungeon:3-3

# Oak Stairs
rule31=0,100,minecraft:oak_stairs-0

# Nether Brick Stairs
rule32=0,100,minecraft:nether_brick_stairs-0
rule33=0,100,minecraft:nether_brick_stairs-1

# Cake!
rule34=0,100,minecraft:cake-0

# Hopper
rule35=0,100,minecraft:hopper-0

# Nether Brick Fence
rule36=0,100,minecraft:nether_brick_fence-0

# Oak Stairs
rule37=0,100,minecraft:oak_stairs-7

# Wooden Slab (Upper)
rule38=0,100,minecraft:wooden_slab-8

# Oak Stairs
rule39=0,100,minecraft:oak_stairs-6

# Randomized Stone Bricks
rule40=0,100,minecraft:stonebrick-0,minecraft:stonebrick-1,minecraft:stonebrick-2

# Bookshelf
rule41=0,100,minecraft:bookshelf-0

# Oak Stairs
rule42=0,100,minecraft:oak_stairs-1

# Bed
rule43=0,100,minecraft:bed-10
rule44=0,100,minecraft:bed-2

# Redstone Torch (Upright)
rule45=0,100,minecraft:redstone_torch-5

# Flower Pot
rule46=0,100,teBlock;minecraft:flower_pot;{Item:"minecraft:sapling",x:0,y:0,z:0,Data:5,id:"flower_pot"}-0,teBlock;minecraft:flower_pot;{Item:"minecraft:tallgrass",x:0,y:0,z:0,Data:2,id:"flower_pot"}-0,teBlock;minecraft:flower_pot;{Item:"minecraft:tallgrass",x:0,y:0,z:0,Data:0,id:"flower_pot"}-0,teBlock;minecraft:flower_pot;{Item:"minecraft:red_mushroom",x:0,y:0,z:0,Data:0,id:"flower_pot"}-0,teBlock;minecraft:flower_pot;{Item:"minecraft:brown_mushroom",x:0,y:0,z:0,Data:0,id:"flower_pot"}-0,teBlock;minecraft:flower_pot;{Item:"minecraft:cactus",x:0,y:0,z:0,Data:0,id:"flower_pot"}-0

# Oak Stairs
rule47=0,100,minecraft:oak_stairs-5

# Redstone Lamp
rule48=0,100,minecraft:redstone_lamp-0

# Wooden Pressure Plate
rule49=0,100,minecraft:wooden_pressure_plate-0

# Dungeon Chest
rule50=0,100,ChestGenHook:chests/simple_dungeon:3-5
rule51=0,100,ChestGenHook:chests/simple_dungeon:3-4

# Glass Pane
rule52=0,100,minecraft:glass_pane-0

# Water
rule53=0,100,minecraft:water-8
rule54=0,100,minecraft:water-0

# Rail
rule55=0,100,minecraft:rail-6
rule56=0,100,minecraft:golden_rail-0
rule57=0,100,minecraft:rail-9
rule58=0,100,minecraft:golden_rail-1
rule59=0,100,minecraft:rail-7
rule60=0,100,minecraft:rail-8

# Trap
#rule61=0,100,CommandBlock:/effect @p[r=3] 9 120:@,CommandBlock:/effect @p[r=3] 15 120:@,CommandBlock:/effect @p[r=3] 17 120:@,CommandBlock:/effect @p[r=3] 18 120:@

rule61=0,100,minecraft:tnt-0

# Dispenser
rule62=0,100,minecraft:dispenser-3

# Piston (Upright)
rule63=0,100,minecraft:piston-1

# Bed
rule64=0,100,minecraft:bed-0
rule65=0,100,minecraft:bed-8

# Hard Chest
rule66=0,100,HardChest

# Skull
rule67=0,100,minecraft:skull

# Redstone Wire
rule68=0,100,minecraft:redstone_wire-13
rule69=0,100,minecraft:redstone_wire-14
rule70=0,100,minecraft:redstone_wire-15

# Obsidian
rule71=0,100,minecraft:stained_glass-15

# Redstone Block
rule72=0,100,minecraft:stained_glass-14

# Glowstone
rule73=0,100,minecraft:glowstone-0

# Lapis Block
rule74=0,100,minecraft:stained_glass-11

# Quartz Block
rule75=0,100,minecraft:stained_glass-0

# Stone Slab
rule76=0,100,minecraft:stone_slab-6
rule77=0,100,minecraft:stone_slab-14

# Double Stone Slab
rule78=0,100,minecraft:double_stone_slab-6

# Basement Treasure
rule79=0,100,IInventory;minecraft:trapped_chest;minecraft:golden_rail#4#0#11+minecraft:rail#32#0#23-4

# embed -5
layer
1,1,1,1,1,1,1,1,1,1,1,1,1,1,1,1,1,1,1,1,1
1,1,1,1,1,1,1,1,1,1,1,1,1,1,1,1,1,1,1,1,1
1,1,1,1,1,1,1,1,1,1,1,1,1,1,1,1,1,1,1,1,1
1,1,1,1,1,1,1,1,1,1,1,1,1,1,1,1,1,1,1,1,1
1,1,1,1,1,1,1,1,1,1,1,1,1,1,1,1,1,1,1,1,1
1,1,1,1,1,1,1,1,2,2,2,2,2,1,1,1,1,1,1,1,1
1,1,1,1,1,1,1,2,2,2,2,2,2,2,1,1,1,1,1,1,1
1,1,1,1,1,1,2,2,3,3,3,3,3,2,2,1,1,1,1,1,1
1,1,1,1,1,2,2,3,3,3,3,3,3,3,2,2,1,1,1,1,1
1,1,1,1,1,2,2,3,3,3,3,3,3,3,2,2,1,1,1,1,1
1,1,1,1,1,2,2,3,3,3,3,3,3,3,2,2,1,1,1,1,1
1,1,1,1,1,2,2,3,3,3,3,3,3,3,2,2,1,1,1,1,1
1,1,1,1,1,2,2,3,3,3,3,3,3,3,2,2,1,1,1,1,1
1,1,1,1,1,1,2,2,3,3,61,3,3,2,2,1,1,1,1,1,1
1,1,1,1,1,1,1,2,2,61,61,61,2,1,1,1,1,1,1,1,1
1,1,1,1,1,1,1,1,2,2,2,2,2,1,1,1,1,1,1,1,1
1,1,1,1,1,1,1,1,1,1,1,1,1,1,1,1,1,1,1,1,1
1,1,1,1,1,1,1,1,1,1,1,1,1,1,1,1,1,1,1,1,1
1,1,1,1,1,1,1,1,1,1,3,1,1,1,1,1,1,1,1,1,1
1,1,1,1,1,1,1,1,1,1,1,1,1,1,1,1,1,1,1,1,1
1,1,1,1,1,1,1,1,1,1,1,1,1,1,1,1,1,1,1,1,1
endlayer

# Embed -4
layer
1,1,1,1,1,1,1,1,1,1,1,1,1,1,1,1,1,1,1,1,1
1,1,1,1,1,1,1,1,1,1,1,1,1,1,1,1,1,1,1,1,1
1,1,1,1,1,1,1,1,1,1,1,1,1,1,1,1,1,1,1,1,1
1,1,1,1,1,1,1,1,1,1,1,1,1,1,1,1,1,1,1,1,1
1,1,1,1,1,1,1,1,1,1,1,1,1,1,1,1,1,1,1,1,1
1,1,1,1,1,1,1,1,1,1,1,1,1,1,1,1,1,1,1,1,1
1,1,1,1,1,1,1,1,2,2,2,2,2,1,1,1,1,1,1,1,1
1,1,1,1,1,1,1,2,7,61,30,61,7,2,1,1,1,1,1,1,1
1,1,1,1,1,1,2,7,0,0,0,0,0,7,2,1,1,1,1,1,1
1,1,1,1,1,1,2,61,0,0,0,0,0,61,2,1,1,1,1,1,1
1,1,1,1,1,1,2,0,0,0,0,0,0,0,2,1,1,1,1,1,1
1,1,1,1,1,1,2,61,0,0,0,0,0,61,2,1,1,1,1,1,1
1,1,1,1,1,1,2,7,0,0,0,0,0,7,2,1,1,1,1,1,1
1,1,1,1,1,1,1,2,7,61,79,61,7,2,1,1,1,1,1,1,1
1,1,1,1,1,1,1,1,2,2,2,2,2,1,1,1,1,1,1,1,1
1,1,1,1,1,1,1,1,1,1,1,1,1,1,1,1,1,1,1,1,1
1,1,1,1,1,1,1,1,1,1,1,1,1,1,1,1,1,1,1,1,1
1,1,1,1,1,1,1,1,1,1,18,1,1,1,1,1,1,1,1,1,1
1,1,1,1,1,1,1,1,1,20,3,19,1,1,1,1,1,1,1,1,1
1,1,1,1,1,1,1,1,1,1,21,1,1,1,1,1,1,1,1,1,1
1,1,1,1,1,1,1,1,1,1,1,1,1,1,1,1,1,1,1,1,1
endlayer

# Embed -3
layer
1,1,1,1,1,1,1,1,1,1,1,1,1,1,1,1,1,1,1,1,1
1,1,1,1,1,1,1,1,1,1,1,1,1,1,1,1,1,1,1,1,1
1,1,1,1,1,1,1,1,1,1,1,1,1,1,1,1,1,1,1,1,1
1,1,1,1,1,1,1,1,1,1,1,1,1,1,1,1,1,1,1,1,1
1,1,1,1,1,1,1,1,1,1,1,1,1,1,1,1,1,1,1,1,1
1,1,1,1,1,1,1,1,1,1,1,1,1,1,1,1,1,1,1,1,1
1,1,1,1,1,1,1,1,2,2,2,2,2,1,1,1,1,1,1,1,1
1,1,1,1,1,1,1,2,7,7,0,7,7,2,1,1,1,1,1,1,1
1,1,1,1,1,1,2,7,7,0,0,0,7,7,2,1,1,1,1,1,1
1,1,1,1,1,1,2,7,0,0,0,0,0,7,2,1,1,1,1,1,1
1,1,1,1,1,1,2,0,0,0,0,0,0,0,2,1,1,1,1,1,1
1,1,1,1,1,1,2,7,0,0,0,0,0,7,2,1,1,1,1,1,1
1,1,1,1,1,1,2,7,7,0,0,0,7,7,2,1,1,1,1,1,1
1,1,1,1,1,1,1,2,7,7,0,7,7,2,1,1,1,1,1,1,1
1,1,1,1,1,1,1,1,2,2,2,2,2,1,1,1,1,1,1,1,1
1,1,1,1,1,1,1,1,1,1,1,1,1,1,1,1,1,1,1,1,1
1,1,1,1,1,1,1,1,1,1,1,1,1,1,1,1,1,1,1,1,1
1,1,1,1,1,1,1,1,1,1,3,1,1,1,1,1,1,1,1,1,1
1,1,1,1,1,1,1,1,1,3,3,3,1,1,1,1,1,1,1,1,1
1,1,1,1,1,1,1,1,1,1,3,1,1,1,1,1,1,1,1,1,1
1,1,1,1,1,1,1,1,1,1,1,1,1,1,1,1,1,1,1,1,1
endlayer


# Embed -2
layer
1,1,1,1,1,1,1,1,1,1,1,1,1,1,1,1,1,1,1,1,1
1,1,1,1,1,1,1,1,1,1,1,1,1,1,1,1,1,1,1,1,1
1,1,1,1,1,1,1,1,1,1,1,1,1,1,1,1,1,1,1,1,1
1,1,1,1,1,1,1,1,1,1,1,1,1,1,1,1,1,1,1,1,1
1,1,1,1,1,1,1,1,1,1,1,1,1,1,1,1,1,1,1,1,1
1,1,1,1,1,1,1,1,1,1,1,1,1,1,1,1,1,1,1,1,1
1,1,1,1,1,1,1,1,2,2,2,2,2,1,1,1,1,1,1,1,1
1,1,1,1,1,1,1,2,3,3,3,3,3,2,1,1,1,1,1,1,1
1,1,1,1,1,1,2,3,3,3,3,3,3,3,2,1,1,1,1,1,1
1,1,1,1,1,1,2,3,3,3,3,3,3,3,2,1,1,1,1,1,1
1,1,1,1,1,1,2,3,3,3,3,3,3,3,2,1,1,1,1,1,1
1,1,1,1,1,1,2,3,3,3,3,3,3,3,2,1,1,1,1,1,1
1,1,1,1,1,1,2,3,3,3,3,3,3,3,2,1,1,1,1,1,1
1,1,1,1,1,1,1,2,3,3,3,3,3,2,1,1,1,1,1,1,1
1,1,1,1,1,1,1,1,2,2,2,2,2,1,1,1,1,1,1,1,1
1,1,1,1,1,1,1,1,1,1,1,1,1,1,1,1,1,1,1,1,1
1,1,1,1,1,1,1,1,1,1,18,1,1,1,1,1,1,1,1,1,1
1,1,1,1,1,1,1,1,1,3,3,3,1,1,1,1,1,1,1,1,1
1,1,1,1,1,1,1,1,20,3,3,3,19,1,1,1,1,1,1,1,1
1,1,1,1,1,1,1,1,1,3,3,3,1,1,1,1,1,1,1,1,1
1,1,1,1,1,1,1,1,1,1,21,1,1,1,1,1,1,1,1,1,1
endlayer


# Base Layer (-1)
layer
1,1,1,1,1,1,1,1,1,1,1,1,1,1,1,1,1,1,1,1,1
1,1,1,1,1,1,1,1,1,1,1,1,1,1,1,1,1,1,1,1,1
1,1,1,1,1,1,1,1,1,1,1,1,1,1,1,1,1,1,1,1,1
1,1,1,1,1,1,1,1,1,1,1,1,1,1,1,1,1,1,1,1,1
1,1,1,1,1,1,1,1,1,1,1,1,1,1,1,1,1,1,1,1,1
1,1,1,1,1,1,1,1,1,1,1,1,1,1,1,1,1,1,1,1,1
1,1,1,1,1,1,1,1,2,2,2,2,2,1,1,1,1,1,1,1,1
1,1,1,1,1,1,1,2,3,3,3,3,3,2,1,1,1,1,1,1,1
1,1,1,1,1,1,2,3,3,3,3,3,3,3,2,1,1,1,1,1,1
1,1,1,1,1,1,2,3,3,3,4,3,3,3,2,1,1,1,1,1,1
1,1,1,1,1,1,2,3,3,3,4,3,3,3,2,1,1,1,1,1,1
1,1,1,1,1,1,2,3,3,3,4,3,3,3,2,1,1,1,1,1,1
1,1,1,1,1,1,2,3,3,3,3,3,3,3,2,1,1,1,1,1,1
1,1,1,1,1,1,1,2,3,3,3,3,3,2,1,1,1,1,1,1,1
1,1,1,1,1,1,1,1,2,2,3,2,2,1,1,1,1,1,1,1,1
1,1,1,1,1,1,1,1,1,3,3,3,1,1,1,1,1,1,1,1,1
1,1,1,1,1,1,1,1,1,3,3,3,1,1,1,1,1,1,1,1,1
1,1,1,1,1,1,1,1,3,3,3,3,3,1,1,1,1,1,1,1,1
1,1,1,1,1,1,1,1,3,3,3,3,3,1,1,1,1,1,1,1,1
1,1,1,1,1,1,1,1,3,3,3,3,3,1,1,1,1,1,1,1,1
1,1,1,1,1,1,1,1,1,3,3,3,1,1,1,1,1,1,1,1,1
endlayer

layer
1,1,1,1,1,1,1,1,1,0,0,0,1,1,1,1,1,1,1,1,1
1,1,1,1,1,1,1,0,0,0,0,0,0,1,1,1,1,1,1,1,1
1,1,1,1,1,1,0,0,0,0,3,0,0,0,1,1,1,1,1,1,1
1,1,1,1,1,0,0,0,0,0,0,0,0,0,0,1,1,1,1,1,1
1,1,1,1,0,0,0,0,0,0,0,0,0,0,0,0,1,1,1,1,1
1,1,1,1,0,0,0,0,0,5,5,5,0,0,0,0,0,1,1,1,1
1,1,1,0,0,0,0,0,2,2,6,2,2,0,0,0,0,0,1,1,1
1,1,0,0,0,0,0,2,0,0,0,0,0,2,0,0,0,0,1,1,1
1,0,0,0,0,0,2,7,8,0,0,0,8,7,2,0,0,0,0,1,1
1,0,0,0,0,5,2,11,10,0,0,0,9,7,2,5,0,0,0,1,1
1,0,0,0,0,5,6,12,10,0,0,0,9,0,6,5,0,0,0,0,1
1,0,0,0,0,5,2,13,10,0,0,0,9,0,2,5,0,0,0,1,1
1,1,0,0,0,0,2,14,0,0,0,0,0,0,2,0,0,0,0,1,1
1,1,0,0,0,0,0,2,0,0,0,0,0,2,0,0,0,0,1,1,1
1,1,1,0,0,0,0,0,2,2,0,2,2,0,0,0,0,0,1,1,1
1,1,1,1,0,0,0,0,0,2,0,2,0,0,0,0,0,1,1,1,1
1,1,1,1,1,0,0,0,0,2,0,2,0,0,0,0,1,1,1,1,1
1,1,1,1,1,1,0,0,2,0,0,0,2,0,0,1,1,1,1,1,1
1,1,1,1,1,1,1,0,6,16,0,15,6,0,1,1,1,1,1,1,1
1,1,1,1,1,1,1,1,2,0,17,7,2,1,1,1,1,1,1,1,1
1,1,1,1,1,1,1,1,1,2,0,2,1,1,1,1,1,1,1,1,1
endlayer

layer
1,1,1,1,1,1,1,1,0,0,0,0,0,1,1,1,1,1,1,1,1
1,1,1,1,1,1,0,0,0,0,18,0,0,0,1,1,1,1,1,1,1
1,1,1,1,1,0,0,0,0,20,3,19,0,0,0,1,1,1,1,1,1
1,1,1,1,0,0,0,0,0,0,21,0,0,0,0,0,1,1,1,1,1
1,1,1,0,0,0,0,0,0,0,0,0,0,0,0,0,0,1,1,1,1
1,1,0,0,0,0,0,0,0,0,0,0,0,0,0,0,0,0,1,1,1
1,0,0,0,0,0,0,0,2,2,22,2,2,0,0,0,0,0,0,1,1
1,0,0,0,0,0,0,2,7,7,7,7,7,2,0,0,0,0,0,0,1
1,0,0,0,0,0,2,12,23,0,0,0,23,7,2,0,0,0,0,0,1
0,0,0,0,0,0,2,13,0,0,0,0,0,0,2,0,0,0,0,0,0
0,0,0,0,0,0,22,14,7,0,0,0,0,0,22,0,0,0,0,0,0
1,0,0,0,0,0,2,0,0,0,0,0,0,0,2,0,0,0,0,0,0
1,0,0,0,0,0,2,0,0,0,0,0,0,0,2,0,0,0,0,0,1
1,1,0,0,0,0,0,2,0,0,0,0,0,2,0,0,0,0,0,0,1
1,1,0,0,0,0,0,0,2,2,0,2,2,0,0,0,0,0,0,1,1
1,1,1,0,0,0,0,0,0,22,0,22,0,0,0,0,0,0,1,1,1
1,1,1,1,0,0,0,0,0,2,0,2,0,0,0,0,0,1,1,1,1
1,1,1,1,1,0,0,0,2,0,0,7,2,0,0,0,1,1,1,1,1
1,1,1,1,1,1,0,0,22,0,0,0,22,0,0,1,1,1,1,1,1
1,1,1,1,1,1,1,0,2,0,24,0,2,0,1,1,1,1,1,1,1
1,1,1,1,1,1,1,1,0,2,0,2,0,1,1,1,1,1,1,1,1
endlayer

layer
1,1,1,1,1,1,1,0,0,0,0,0,0,0,1,1,1,1,1,1,1
1,1,1,1,1,0,0,0,0,0,3,0,0,0,0,1,1,1,1,1,1
1,1,1,1,0,0,0,0,0,3,3,3,0,0,0,0,1,1,1,1,1
1,1,1,0,0,0,0,0,0,0,3,0,0,0,0,0,0,1,1,1,1
1,1,0,0,0,0,0,0,0,0,0,0,0,0,0,0,0,0,1,1,1
1,0,0,0,0,0,0,0,0,0,0,0,0,0,0,0,0,0,0,1,1
0,0,0,0,0,0,0,0,2,2,22,2,2,0,0,0,0,0,0,0,1
0,0,0,0,0,0,0,2,12,7,0,7,7,2,0,0,0,0,0,0,0
0,0,0,0,0,0,2,14,13,0,0,0,0,7,2,0,0,0,0,0,0
0,0,0,0,0,0,2,7,0,7,8,0,0,7,2,0,0,0,0,0,0
0,0,0,0,0,0,22,0,0,8,8,8,0,0,22,0,0,0,0,0,0
0,0,0,0,0,0,2,0,0,0,8,0,0,0,2,0,0,0,0,0,0
0,0,0,0,0,0,2,7,0,0,0,0,0,7,2,0,0,0,0,0,0
0,0,0,0,0,0,0,2,7,0,0,0,7,2,0,0,0,0,0,0,0
1,0,0,0,0,0,0,0,2,2,0,2,2,0,0,0,0,0,0,0,1
1,1,0,0,0,0,0,0,0,22,0,22,0,0,0,0,0,0,0,1,1
1,1,1,0,0,0,0,0,0,2,0,2,0,0,0,0,0,0,1,1,1
1,1,1,1,0,0,0,0,2,7,0,7,2,0,0,0,0,1,1,1,1
1,1,1,1,1,0,0,0,22,0,0,0,22,0,0,0,1,1,1,1,1
1,1,1,1,1,1,0,0,2,7,0,7,2,0,0,1,1,1,1,1,1
1,1,1,1,1,1,1,0,0,2,22,2,0,0,1,1,1,1,1,1,1
endlayer

layer
1,1,1,1,1,0,0,0,0,0,18,0,0,0,0,1,1,1,1,1,1
1,1,1,1,0,0,0,0,0,3,3,3,0,0,0,0,1,1,1,1,1
1,1,1,0,0,0,0,0,20,3,3,3,19,0,0,0,0,1,1,1,1
1,1,0,0,0,0,0,0,0,3,3,3,0,0,0,0,0,0,1,1,1
1,0,0,0,0,0,0,0,0,0,21,0,0,0,0,0,0,0,0,1,1
0,0,0,0,0,0,0,0,0,0,0,0,0,0,0,0,0,0,0,0,1
0,0,0,0,0,0,0,0,2,2,6,2,2,0,0,0,0,0,0,0,0
0,0,0,0,0,0,0,2,14,13,12,7,7,2,0,0,0,0,0,0,0
0,0,0,0,0,0,2,0,0,0,0,0,0,7,2,0,0,0,0,0,0
0,0,0,0,0,0,2,7,0,0,7,0,0,7,2,0,0,0,0,0,0
0,0,0,0,0,0,6,7,7,7,8,0,0,7,6,0,0,0,0,0,0
0,0,0,0,0,0,2,7,0,0,0,0,0,7,2,0,0,0,0,0,0
0,0,0,0,0,0,2,7,0,0,0,0,0,7,2,0,0,0,0,0,0
0,0,0,0,0,0,0,2,7,7,0,7,7,2,0,0,0,0,0,0,0
0,0,0,0,0,0,0,0,2,2,6,2,2,0,0,0,0,0,0,0,0
1,0,0,0,0,0,0,0,0,26,3,25,0,0,0,0,0,0,0,0,1
1,1,0,0,0,0,0,0,0,2,6,2,0,0,0,0,0,0,0,1,1
1,1,1,0,0,0,0,0,2,7,0,7,2,0,0,0,0,0,1,1,1
1,1,1,1,0,0,0,0,6,0,0,0,6,0,0,0,0,1,1,1,1
1,1,1,1,1,0,0,0,2,7,7,7,2,0,0,0,1,1,1,1,1
1,1,1,1,1,1,0,0,0,2,6,2,0,0,0,1,1,1,1,1,1
endlayer

layer
1,1,1,1,0,0,0,0,0,3,3,3,0,0,0,0,1,1,1,1,1
1,1,1,0,0,0,0,0,3,3,3,3,3,0,0,0,0,1,1,1,1
1,1,0,0,0,0,0,0,3,3,3,3,3,0,0,0,0,0,1,1,1
1,0,0,0,0,0,0,0,3,3,3,3,3,0,0,0,0,0,0,1,1
0,0,0,0,0,0,0,0,0,3,3,3,0,0,0,0,0,0,0,0,1
0,0,0,0,0,0,0,0,0,3,3,3,0,0,0,0,0,0,0,0,0
0,0,0,0,0,0,0,0,2,2,3,2,2,0,0,0,0,0,0,0,0
0,0,0,0,0,0,0,2,0,0,14,3,3,2,0,0,0,0,0,0,0
0,0,0,0,0,0,2,0,0,3,3,3,3,3,2,0,0,0,0,0,0
0,0,0,0,0,0,2,0,3,3,3,3,3,3,2,0,0,0,0,0,0
0,0,0,0,0,0,2,3,3,3,3,3,3,3,2,0,0,0,0,0,0
0,0,0,0,0,0,2,3,3,3,3,3,3,3,2,0,0,0,0,0,0
0,0,0,0,0,0,2,3,3,3,3,3,3,3,2,0,0,0,0,0,0
0,0,0,0,0,0,0,2,3,3,3,3,3,2,0,0,0,0,0,0,0
0,0,0,0,0,0,0,0,2,2,2,2,2,0,0,0,0,0,0,0,0
0,0,0,0,0,0,0,0,0,0,0,0,0,0,0,0,0,0,0,0,0
1,0,0,0,0,0,0,0,0,3,3,3,0,0,0,0,0,0,0,0,1
1,1,0,0,0,0,0,0,3,3,0,3,3,0,0,0,0,0,0,1,1
1,1,1,0,0,0,0,0,3,0,0,0,3,0,0,0,0,0,1,1,1
1,1,1,1,0,0,0,0,3,3,7,3,3,0,0,0,0,1,1,1,1
1,1,1,1,1,0,0,0,0,3,3,3,0,0,0,0,1,1,1,1,1
endlayer

layer
1,1,1,0,0,0,0,0,0,2,6,2,0,0,0,0,0,1,1,1,1
1,1,0,0,0,0,0,0,2,29,28,27,2,0,0,0,0,0,1,1,1
1,0,0,0,0,0,0,0,6,7,7,7,6,0,0,0,0,0,0,1,1
0,0,0,0,0,0,0,0,2,11,7,30,2,0,0,0,0,0,0,0,1
0,0,0,0,0,0,0,0,0,2,7,2,0,0,0,0,0,0,0,0,0
0,0,0,0,0,0,0,0,0,22,7,22,0,0,0,0,0,0,0,0,0
0,0,0,0,0,0,0,0,2,2,7,2,2,0,0,0,0,0,0,0,0
0,0,0,0,0,0,0,2,0,0,0,0,0,2,0,0,0,0,0,0,0
0,0,0,0,0,0,2,0,0,0,0,0,0,14,2,0,0,0,0,0,0
0,0,0,0,0,5,2,0,0,10,8,9,0,13,2,5,0,0,0,0,0
0,0,0,0,0,5,6,7,0,7,8,0,0,12,6,5,0,0,3,0,0
0,0,0,0,0,5,2,0,0,10,8,9,0,0,2,5,0,0,0,0,0
0,0,0,0,0,0,2,0,0,0,31,0,0,0,2,0,0,0,0,0,0
0,0,0,0,0,0,0,2,0,0,0,0,0,2,0,0,0,0,0,0,0
0,0,0,0,0,0,0,0,2,2,6,2,2,0,0,0,0,0,0,0,0
0,0,0,0,0,0,0,0,0,5,5,5,0,0,0,0,0,0,0,0,0
0,0,0,0,0,0,0,0,0,0,32,0,0,0,0,0,0,0,0,0,0
1,0,0,0,0,0,0,0,0,3,3,3,0,0,0,0,0,0,0,0,1
1,1,0,0,0,0,0,0,26,3,11,3,25,0,0,0,0,0,0,1,1
1,1,1,0,0,0,0,0,0,3,3,3,0,0,0,0,0,0,1,1,1
1,1,1,1,0,0,0,0,0,0,33,0,0,0,0,0,0,1,1,1,1
endlayer

layer
1,1,0,0,0,0,0,0,0,2,22,2,0,0,0,0,0,0,1,1,1
1,0,0,0,0,0,0,0,2,34,0,7,2,0,0,0,0,0,0,1,1
0,0,0,0,0,0,0,0,22,7,0,0,22,0,0,0,0,0,0,0,1
0,0,0,0,0,0,0,0,2,7,7,7,2,0,0,0,0,0,0,0,0
0,0,0,0,0,0,0,0,0,2,7,2,0,0,0,0,0,0,0,0,0
0,0,0,0,0,0,0,0,0,22,7,22,0,0,0,0,0,0,0,0,0
0,0,0,0,0,0,0,0,2,2,7,2,2,0,0,0,0,0,0,0,0
0,0,0,0,0,0,0,2,7,7,0,0,7,2,0,0,0,0,0,0,0
0,0,0,0,0,0,2,7,0,0,7,0,7,7,2,0,0,0,0,0,0
0,0,0,0,0,0,2,0,0,7,23,0,0,7,2,0,0,0,18,0,0
0,0,0,0,0,0,22,0,0,0,23,0,0,14,22,0,0,20,3,19,0
0,0,0,0,0,0,2,0,0,7,23,0,0,13,2,0,0,0,21,0,0
0,0,0,0,0,0,2,7,0,0,0,0,0,12,2,0,0,0,0,0,0
0,0,0,0,0,0,0,2,7,0,0,0,7,2,0,0,0,0,0,0,0
0,0,0,0,0,0,0,0,2,2,22,2,2,0,0,0,0,0,0,0,0
0,0,0,0,0,0,0,0,0,0,0,0,0,0,0,0,0,0,0,0,0
0,0,0,0,0,0,0,0,0,0,0,0,0,0,0,0,0,0,0,0,0
0,0,0,0,0,0,0,0,0,3,3,3,0,0,0,0,0,0,0,0,0
1,0,0,0,0,0,0,0,0,3,0,3,0,0,0,0,0,0,0,0,1
1,1,0,0,0,0,0,0,0,3,3,3,0,0,0,0,0,0,0,1,1
1,1,1,0,0,0,0,0,0,0,0,0,0,0,0,0,0,0,1,1,1
endlayer

layer
1,0,0,0,0,0,0,0,0,2,22,2,0,0,0,0,0,0,0,1,1
0,0,0,0,0,0,0,0,2,0,0,7,2,0,0,0,0,0,0,0,1
0,0,0,0,0,0,0,0,22,0,0,0,22,0,0,0,0,0,0,0,0
0,0,0,0,0,0,0,0,2,7,0,7,2,0,0,0,0,0,0,0,0
0,0,0,0,0,0,0,0,0,2,7,2,0,0,0,0,0,0,0,0,0
0,0,0,0,0,0,0,0,0,22,7,22,0,0,0,0,0,0,0,0,0
0,0,0,0,0,0,0,0,2,2,7,2,2,0,0,0,0,0,0,0,0
0,0,0,0,0,0,0,2,7,7,7,0,7,2,0,0,0,0,0,0,0
0,0,0,0,0,0,2,7,0,0,0,0,0,7,2,0,0,0,0,0,0
0,0,0,0,0,0,2,7,0,0,8,7,0,0,2,0,0,0,3,0,0
0,0,0,0,0,0,22,7,0,8,8,8,0,0,22,0,0,3,3,3,0
0,0,0,0,0,0,2,7,0,0,8,0,0,0,2,0,0,0,3,0,0
0,0,0,0,0,0,2,7,0,0,0,0,13,14,2,0,0,0,0,0,0
0,0,0,0,0,0,0,2,7,7,0,7,12,2,0,0,0,0,0,0,0
0,0,0,0,0,0,0,0,2,2,22,2,2,0,0,0,0,0,0,0,0
0,0,0,0,0,0,0,0,0,0,0,0,0,0,0,0,0,0,0,0,0
0,0,0,0,0,0,0,0,0,0,0,0,0,0,0,0,0,0,0,0,0
0,0,0,0,0,0,0,0,0,0,32,0,0,0,0,0,0,0,0,0,0
0,0,0,0,0,0,0,0,0,26,3,25,0,0,0,0,0,0,0,0,0
1,0,0,0,0,0,0,0,0,0,33,0,0,0,0,0,0,0,0,0,1
1,1,0,0,0,0,0,0,0,0,0,0,0,0,0,0,0,0,0,1,1
endlayer

layer
0,0,0,0,0,0,0,0,0,2,6,2,0,0,0,0,0,0,0,0,1
0,0,0,0,0,0,0,0,2,7,7,0,2,0,0,0,0,0,0,0,0
0,0,0,0,0,0,0,0,6,7,0,7,6,0,0,0,0,0,0,0,0
0,0,0,0,0,0,0,0,2,7,0,7,2,0,0,0,0,0,0,0,0
0,0,0,0,0,0,0,0,0,2,6,2,0,0,0,0,0,0,0,0,0
0,0,0,0,0,0,0,0,0,26,3,25,0,0,0,0,0,0,0,0,0
0,0,0,0,0,0,0,0,2,2,6,2,2,0,0,0,0,0,0,0,0
0,0,0,0,0,0,0,2,7,7,7,7,7,2,0,0,0,0,0,0,0
0,0,0,0,0,0,2,7,0,7,7,7,7,7,2,0,0,0,18,0,0
0,0,0,0,0,0,2,7,0,7,0,0,7,7,2,0,0,3,3,3,0
0,0,0,0,0,0,6,0,0,0,35,0,0,7,6,0,20,3,3,3,19
0,0,0,0,0,0,2,7,0,0,0,0,0,0,2,0,0,3,3,3,0
0,0,0,0,0,0,2,7,0,0,0,0,0,0,2,0,0,0,21,0,0
0,0,0,0,0,0,0,2,7,7,12,13,14,2,0,0,0,0,0,0,0
0,0,0,0,0,0,0,0,2,2,6,2,2,0,0,0,0,0,0,0,0
0,0,0,0,0,0,0,0,0,0,0,0,0,0,0,0,0,0,0,0,0
0,0,0,0,0,0,0,0,0,0,0,0,0,0,0,0,0,0,0,0,0
0,0,0,0,0,0,0,0,0,0,0,0,0,0,0,0,0,0,0,0,0
0,0,0,0,0,0,0,0,0,0,3,0,0,0,0,0,0,0,0,0,0
0,0,0,0,0,0,0,0,0,0,0,0,0,0,0,0,0,0,0,0,0
1,0,0,0,0,0,0,0,0,0,0,0,0,0,0,0,0,0,0,0,1
endlayer

layer
0,0,0,0,0,0,0,0,0,3,3,3,0,0,0,0,0,0,0,0,0
0,0,0,0,0,0,0,0,3,3,7,3,3,0,0,0,0,0,0,0,0
0,0,0,0,0,0,0,0,3,7,0,7,3,0,0,0,0,0,0,0,0
0,0,0,0,0,0,0,0,3,3,7,3,3,0,0,0,0,0,0,0,0
0,0,0,0,0,0,0,0,0,3,3,3,0,0,0,0,0,0,0,0,0
0,0,0,0,0,0,0,0,0,0,0,0,0,0,0,0,0,0,0,0,0
0,0,0,0,0,0,0,0,2,2,2,2,2,0,0,0,0,0,0,0,0
0,0,0,0,0,0,0,2,3,3,3,3,3,2,0,0,0,0,0,0,0
0,0,0,0,0,0,2,3,3,3,3,3,3,3,2,0,0,3,3,3,0
0,0,0,0,0,0,2,3,3,3,3,3,3,3,2,3,3,3,3,3,3
0,0,0,0,0,0,2,3,3,3,3,3,3,3,3,3,3,3,3,3,3
0,0,0,0,0,0,2,3,3,3,3,3,3,0,2,3,3,3,3,3,3
0,0,0,0,0,0,2,3,3,3,3,3,0,7,2,0,0,3,3,3,0
0,0,0,0,0,0,0,2,3,3,14,0,0,2,0,0,0,0,0,0,0
0,0,0,0,0,0,0,0,2,2,2,2,2,0,0,0,0,0,0,0,0
0,0,0,0,0,0,0,0,0,0,0,0,0,0,0,0,0,0,0,0,0
0,0,0,0,0,0,0,0,0,0,0,0,0,0,0,0,0,0,0,0,0
0,0,0,0,0,0,0,0,0,0,0,0,0,0,0,0,0,0,0,0,0
0,0,0,0,0,0,0,0,0,0,36,0,0,0,0,0,0,0,0,0,0
0,0,0,0,0,0,0,0,0,0,0,0,0,0,0,0,0,0,0,0,0
0,0,0,0,0,0,0,0,0,0,0,0,0,0,0,0,0,0,0,0,0
endlayer

layer
0,0,0,0,0,0,0,0,0,0,32,0,0,0,0,0,0,0,0,0,0
0,0,0,0,0,0,0,0,0,3,3,3,0,0,0,0,0,0,0,0,0
0,0,0,0,0,0,0,0,26,3,7,3,25,0,0,0,0,0,0,0,0
0,0,0,0,0,0,0,0,0,3,3,3,0,0,0,0,0,0,0,0,0
0,0,0,0,0,0,0,0,0,0,33,0,0,0,0,0,0,0,0,0,0
0,0,0,0,0,0,0,0,0,5,5,5,0,0,0,0,0,0,0,0,0
0,0,0,0,0,0,0,0,2,2,6,2,2,0,0,0,0,0,0,0,0
0,0,0,0,0,0,0,2,29,39,38,37,7,2,0,0,0,0,0,0,0
0,0,0,0,0,0,2,0,0,0,31,0,0,41,2,0,0,40,6,40,0
0,0,0,0,0,5,2,0,0,0,0,0,0,42,2,22,40,0,0,30,40
0,0,3,0,0,5,6,12,0,0,7,0,0,0,0,7,7,0,44,43,6
0,0,0,0,0,5,2,13,0,0,0,0,0,0,2,22,40,11,0,8,40
0,0,0,0,0,0,2,14,0,0,0,0,0,7,2,0,0,40,6,40,0
0,0,0,0,0,0,0,2,7,0,0,0,7,2,0,0,0,0,0,0,0
0,0,0,0,0,0,0,0,2,2,6,2,2,0,0,0,0,0,0,0,0
0,0,0,0,0,0,0,0,0,5,5,5,0,0,0,0,0,0,0,0,0
0,0,0,0,0,0,0,0,0,0,0,0,0,0,0,0,0,0,0,0,0
0,0,0,0,0,0,0,0,0,0,0,0,0,0,0,0,0,0,0,0,0
0,0,0,0,0,0,0,0,0,0,45,0,0,0,0,0,0,0,0,0,0
0,0,0,0,0,0,0,0,0,0,0,0,0,0,0,0,0,0,0,0,0
0,0,0,0,0,0,0,0,0,0,0,0,0,0,0,0,0,0,0,0,0
endlayer

layer
0,0,0,0,0,0,0,0,0,0,0,0,0,0,0,0,0,0,0,0,0
0,0,0,0,0,0,0,0,0,3,3,3,0,0,0,0,0,0,0,0,0
0,0,0,0,0,0,0,0,0,3,0,3,0,0,0,0,0,0,0,0,0
0,0,0,0,0,0,0,0,0,3,3,3,0,0,0,0,0,0,0,0,0
0,0,0,0,0,0,0,0,0,0,0,0,0,0,0,0,0,0,0,0,0
0,0,0,0,0,0,0,0,0,0,0,0,0,0,0,0,0,0,0,0,0
0,0,0,0,0,0,0,0,2,2,22,2,2,0,0,0,0,0,0,0,0
0,0,0,0,0,0,0,2,7,7,0,46,7,2,0,0,0,0,0,0,0
0,0,0,0,0,0,2,12,0,0,0,0,0,41,2,0,0,40,22,40,0
0,0,18,0,0,0,2,13,0,0,0,0,0,47,40,22,40,0,0,0,40
0,20,3,19,0,0,22,14,0,0,7,0,0,7,0,7,7,0,0,0,22
0,0,21,0,0,0,2,0,0,0,0,0,0,7,2,22,40,7,0,23,40
0,0,0,0,0,0,2,7,0,0,0,0,0,7,2,0,0,40,22,40,0
0,0,0,0,0,0,0,2,7,0,0,7,7,2,0,0,0,0,0,0,0
0,0,0,0,0,0,0,0,2,2,22,2,2,0,0,0,0,0,0,0,0
0,0,0,0,0,0,0,0,0,0,0,0,0,0,0,0,0,0,0,0,0
0,0,0,0,0,0,0,0,0,0,0,0,0,0,0,0,0,0,0,0,0
0,0,0,0,0,0,0,0,0,0,0,0,0,0,0,0,0,0,0,0,0
0,0,0,0,0,0,0,0,0,0,0,0,0,0,0,0,0,0,0,0,0
0,0,0,0,0,0,0,0,0,0,0,0,0,0,0,0,0,0,0,0,0
0,0,0,0,0,0,0,0,0,0,0,0,0,0,0,0,0,0,0,0,0
endlayer

layer
0,0,0,0,0,0,0,0,0,0,0,0,0,0,0,0,0,0,0,0,0
0,0,0,0,0,0,0,0,0,0,32,0,0,0,0,0,0,0,0,0,0
0,0,0,0,0,0,0,0,0,26,3,25,0,0,0,0,0,0,0,0,0
0,0,0,0,0,0,0,0,0,0,33,0,0,0,0,0,0,0,0,0,0
0,0,0,0,0,0,0,0,0,0,0,0,0,0,0,0,0,0,0,0,0
0,0,0,0,0,0,0,0,0,0,0,0,0,0,0,0,0,0,0,0,0
0,0,0,0,0,0,0,0,2,2,22,2,2,0,0,0,0,0,0,0,0
0,0,0,0,0,0,0,2,12,7,0,7,7,2,0,0,0,0,0,0,0
0,0,0,0,0,0,2,14,13,0,0,0,0,7,2,0,0,40,22,40,0
0,0,3,0,0,0,2,0,0,0,0,0,0,7,2,22,40,7,0,7,40
0,3,3,3,0,0,22,0,0,0,48,0,0,0,22,0,7,0,0,0,22
0,0,3,0,0,0,2,7,0,0,0,0,0,7,2,22,40,7,0,7,40
0,0,0,0,0,0,2,0,0,0,0,0,0,7,2,0,0,40,22,40,0
0,0,0,0,0,0,0,2,0,0,0,7,7,2,0,0,0,0,0,0,0
0,0,0,0,0,0,0,0,2,2,22,2,2,0,0,0,0,0,0,0,0
0,0,0,0,0,0,0,0,0,0,0,0,0,0,0,0,0,0,0,0,0
0,0,0,0,0,0,0,0,0,0,0,0,0,0,0,0,0,0,0,0,0
0,0,0,0,0,0,0,0,0,0,0,0,0,0,0,0,0,0,0,0,0
0,0,0,0,0,0,0,0,0,0,0,0,0,0,0,0,0,0,0,0,0
0,0,0,0,0,0,0,0,0,0,0,0,0,0,0,0,0,0,0,0,0
0,0,0,0,0,0,0,0,0,0,0,0,0,0,0,0,0,0,0,0,0
endlayer

layer
0,0,0,0,0,0,0,0,0,0,0,0,0,0,0,0,0,0,0,0,0
0,0,0,0,0,0,0,0,0,0,0,0,0,0,0,0,0,0,0,0,0
0,0,0,0,0,0,0,0,0,0,3,0,0,0,0,0,0,0,0,0,0
0,0,0,0,0,0,0,0,0,0,0,0,0,0,0,0,0,0,0,0,0
0,0,0,0,0,0,0,0,0,0,0,0,0,0,0,0,0,0,0,0,0
0,0,0,0,0,0,0,0,0,0,0,0,0,0,0,0,0,0,0,0,0
0,0,0,0,0,0,0,0,2,2,6,2,2,0,0,0,0,0,0,0,0
0,0,0,0,0,0,0,2,14,13,12,7,7,2,0,0,0,0,0,0,0
0,0,18,0,0,0,2,0,0,0,0,0,0,7,2,0,0,40,6,40,0
0,3,3,3,0,0,2,0,0,0,0,0,0,0,2,32,40,7,7,7,40
20,3,3,3,19,0,6,7,0,0,8,0,0,7,6,3,6,0,0,0,6
0,3,3,3,0,0,2,7,0,0,0,0,0,7,2,33,40,7,7,7,40
0,0,21,0,0,0,2,7,0,0,7,7,0,7,2,0,0,40,6,40,0
0,0,0,0,0,0,0,2,7,7,7,7,7,2,0,0,0,0,0,0,0
0,0,0,0,0,0,0,0,2,2,6,2,2,0,0,0,0,0,0,0,0
0,0,0,0,0,0,0,0,0,0,0,0,0,0,0,0,0,0,0,0,0
0,0,0,0,0,0,0,0,0,0,0,0,0,0,0,0,0,0,0,0,0
0,0,0,0,0,0,0,0,0,0,0,0,0,0,0,0,0,0,0,0,0
0,0,0,0,0,0,0,0,0,0,0,0,0,0,0,0,0,0,0,0,0
0,0,0,0,0,0,0,0,0,0,0,0,0,0,0,0,0,0,0,0,0
0,0,0,0,0,0,0,0,0,0,0,0,0,0,0,0,0,0,0,0,0
endlayer

layer
0,0,0,0,0,0,0,0,0,0,0,0,0,0,0,0,0,0,0,0,0
0,0,0,0,0,0,0,0,0,0,0,0,0,0,0,0,0,0,0,0,0
0,0,0,0,0,0,0,0,0,0,36,0,0,0,0,0,0,0,0,0,0
0,0,0,0,0,0,0,0,0,0,0,0,0,0,0,0,0,0,0,0,0
0,0,0,0,0,0,0,0,0,0,0,0,0,0,0,0,0,0,0,0,0
0,0,0,0,0,0,0,0,0,0,0,0,0,0,0,0,0,0,0,0,0
0,0,0,0,0,0,0,0,2,2,2,2,2,0,0,0,0,0,0,0,0
0,0,0,0,0,0,0,2,0,0,14,3,3,2,0,0,0,0,0,0,0
0,3,3,3,0,0,2,0,0,3,3,3,3,3,2,0,0,3,3,3,0
3,3,3,3,3,3,2,0,3,3,3,3,3,3,2,0,3,3,7,3,3
3,3,3,3,3,3,3,3,3,3,3,3,3,3,2,0,3,7,0,7,3
3,3,3,3,3,3,2,3,3,3,3,3,3,3,2,0,3,3,7,3,3
0,3,3,3,0,0,2,3,3,3,3,3,3,3,2,0,0,3,3,3,0
0,0,0,0,0,0,0,2,3,3,3,3,3,2,0,0,0,0,0,0,0
0,0,0,0,0,0,0,0,2,2,2,2,2,0,0,0,0,0,0,0,0
0,0,0,0,0,0,0,0,0,0,0,0,0,0,0,0,0,0,0,0,0
0,0,0,0,0,0,0,0,0,0,0,0,0,0,0,0,0,0,0,0,0
0,0,0,0,0,0,0,0,0,0,0,0,0,0,0,0,0,0,0,0,0
0,0,0,0,0,0,0,0,0,0,0,0,0,0,0,0,0,0,0,0,0
0,0,0,0,0,0,0,0,0,0,0,0,0,0,0,0,0,0,0,0,0
0,0,0,0,0,0,0,0,0,0,0,0,0,0,0,0,0,0,0,0,0
endlayer

layer
0,0,0,0,0,0,0,0,0,0,0,0,0,0,0,0,0,0,0,0,0
0,0,0,0,0,0,0,0,0,0,0,0,0,0,0,0,0,0,0,0,0
0,0,0,0,0,0,0,0,0,0,45,0,0,0,0,0,0,0,0,0,0
0,0,0,0,0,0,0,0,0,0,0,0,0,0,0,0,0,0,0,0,0
0,0,0,0,0,0,0,0,0,0,0,0,0,0,0,0,0,0,0,0,0
0,0,0,0,0,0,0,0,0,5,5,5,0,0,0,0,0,0,0,0,0
0,0,0,0,0,0,0,0,2,2,6,2,2,0,0,0,0,0,0,0,0
0,0,0,0,0,0,0,2,0,0,0,0,7,2,0,0,0,0,0,0,0
0,40,6,40,0,0,2,0,0,23,49,23,0,14,2,0,0,0,32,0,0
40,7,0,50,40,22,2,0,23,49,23,49,23,13,2,5,0,3,3,3,0
6,11,7,23,7,7,7,0,49,23,49,23,49,12,6,5,26,3,0,3,25
40,0,7,51,40,22,2,0,23,49,23,49,23,0,2,5,0,3,3,3,0
0,40,6,40,0,0,2,0,0,23,49,23,0,0,2,0,0,0,33,0,0
0,0,0,0,0,0,0,2,0,0,0,0,0,2,0,0,0,0,0,0,0
0,0,0,0,0,0,0,0,2,2,6,2,2,0,0,0,0,0,0,0,0
0,0,0,0,0,0,0,0,0,5,5,5,0,0,0,0,0,0,0,0,0
0,0,0,0,0,0,0,0,0,0,0,0,0,0,0,0,0,0,0,0,0
0,0,0,0,0,0,0,0,0,0,0,0,0,0,0,0,0,0,0,0,0
0,0,0,0,0,0,0,0,0,0,3,0,0,0,0,0,0,0,0,0,0
0,0,0,0,0,0,0,0,0,0,0,0,0,0,0,0,0,0,0,0,0
0,0,0,0,0,0,0,0,0,0,0,0,0,0,0,0,0,0,0,0,0
endlayer

layer
0,0,0,0,0,0,0,0,0,0,0,0,0,0,0,0,0,0,0,0,0
0,0,0,0,0,0,0,0,0,0,0,0,0,0,0,0,0,0,0,0,0
0,0,0,0,0,0,0,0,0,0,0,0,0,0,0,0,0,0,0,0,0
0,0,0,0,0,0,0,0,0,0,0,0,0,0,0,0,0,0,0,0,0
0,0,0,0,0,0,0,0,0,0,0,0,0,0,0,0,0,0,0,0,0
0,0,0,0,0,0,0,0,0,0,0,0,0,0,0,0,0,0,0,0,0
0,0,0,0,0,0,0,0,2,2,22,2,2,0,0,0,0,0,0,0,0
0,0,0,0,0,0,0,2,0,0,0,0,7,2,0,0,0,0,0,0,0
0,40,22,40,0,0,2,0,0,0,0,0,0,0,2,0,0,0,0,0,0
40,7,0,0,40,22,2,0,0,0,0,0,0,7,2,0,0,3,3,3,0
22,0,0,0,7,0,7,0,0,0,0,0,0,14,22,0,0,3,0,3,0
40,7,0,0,40,22,2,0,0,0,0,0,0,13,2,0,0,3,3,3,0
0,40,22,40,0,0,2,0,0,0,0,0,0,12,2,0,0,0,0,0,0
0,0,0,0,0,0,0,2,0,0,0,0,0,2,0,0,0,0,0,0,0
0,0,0,0,0,0,0,0,2,2,22,2,2,0,0,0,0,0,0,0,0
0,0,0,0,0,0,0,0,0,0,0,0,0,0,0,0,0,0,0,0,0
0,0,0,0,0,0,0,0,0,0,0,0,0,0,0,0,0,0,0,0,0
0,0,0,0,0,0,0,0,0,0,18,0,0,0,0,0,0,0,0,0,0
0,0,0,0,0,0,0,0,0,20,3,19,0,0,0,0,0,0,0,0,0
0,0,0,0,0,0,0,0,0,0,21,0,0,0,0,0,0,0,0,0,0
0,0,0,0,0,0,0,0,0,0,0,0,0,0,0,0,0,0,0,0,0
endlayer

layer
0,0,0,0,0,0,0,0,0,0,0,0,0,0,0,0,0,0,0,0,0
0,0,0,0,0,0,0,0,0,0,0,0,0,0,0,0,0,0,0,0,0
0,0,0,0,0,0,0,0,0,0,0,0,0,0,0,0,0,0,0,0,0
0,0,0,0,0,0,0,0,0,0,0,0,0,0,0,0,0,0,0,0,0
0,0,0,0,0,0,0,0,0,0,0,0,0,0,0,0,0,0,0,0,0
0,0,0,0,0,0,0,0,0,0,0,0,0,0,0,0,0,0,0,0,0
0,0,0,0,0,0,0,0,2,2,22,2,2,0,0,0,0,0,0,0,0
0,0,0,0,0,0,0,2,7,0,0,0,7,2,0,0,0,0,0,0,0
0,40,22,40,0,0,2,7,0,0,0,0,7,7,2,0,0,0,0,0,0
40,0,0,0,40,22,2,0,0,0,0,0,7,7,2,0,0,0,32,0,0
22,0,0,0,7,0,7,0,0,0,48,0,0,0,22,0,0,26,3,25,0
40,7,0,0,40,22,2,0,0,0,0,0,0,7,2,0,0,0,33,0,0
0,40,22,40,0,0,2,7,0,0,0,0,13,14,2,0,0,0,0,0,0
0,0,0,0,0,0,0,2,7,0,0,0,12,2,0,0,0,0,0,0,0
0,0,0,0,0,0,0,0,2,2,22,2,2,0,0,0,0,0,0,0,0
0,0,0,0,0,0,0,0,0,0,0,0,0,0,0,0,0,0,0,0,0
0,0,0,0,0,0,0,0,0,0,0,0,0,0,0,0,0,0,0,0,0
0,0,0,0,0,0,0,0,0,0,3,0,0,0,0,0,0,0,0,0,0
0,0,0,0,0,0,0,0,0,3,3,3,0,0,0,0,0,0,0,0,0
0,0,0,0,0,0,0,0,0,0,3,0,0,0,0,0,0,0,0,0,0
0,0,0,0,0,0,0,0,0,0,0,0,0,0,0,0,0,0,0,0,0
endlayer

layer
0,0,0,0,0,0,0,0,0,0,0,0,0,0,0,0,0,0,0,0,0
0,0,0,0,0,0,0,0,0,0,0,0,0,0,0,0,0,0,0,0,0
0,0,0,0,0,0,0,0,0,0,0,0,0,0,0,0,0,0,0,0,0
0,0,0,0,0,0,0,0,0,0,0,0,0,0,0,0,0,0,0,0,0
0,0,0,0,0,0,0,0,0,0,0,0,0,0,0,0,0,0,0,0,0
0,0,0,0,0,0,0,0,0,0,0,0,0,0,0,0,0,0,0,0,0
0,0,0,0,0,0,0,0,2,2,6,2,2,0,0,0,0,0,0,0,0
0,0,0,0,0,0,0,2,7,7,7,7,7,2,0,0,0,0,0,0,0
0,40,40,40,0,0,2,7,0,0,0,0,0,0,2,0,0,0,0,0,0
40,7,0,0,40,32,2,7,0,0,7,0,0,0,2,0,0,0,0,0,0
40,7,0,0,6,3,6,0,0,0,8,0,0,7,6,0,0,0,3,0,0
40,7,0,0,40,33,2,7,0,0,0,0,0,0,2,0,0,0,0,0,0
0,40,40,40,0,0,2,7,0,0,0,0,0,7,2,0,0,0,0,0,0
0,0,0,0,0,0,0,2,7,7,12,13,14,2,0,0,0,0,0,0,0
0,0,0,0,0,0,0,0,2,2,6,2,2,0,0,0,0,0,0,0,0
0,0,0,0,0,0,0,0,0,0,0,0,0,0,0,0,0,0,0,0,0
0,0,0,0,0,0,0,0,0,0,18,0,0,0,0,0,0,0,0,0,0
0,0,0,0,0,0,0,0,0,3,3,3,0,0,0,0,0,0,0,0,0
0,0,0,0,0,0,0,0,20,3,3,3,19,0,0,0,0,0,0,0,0
0,0,0,0,0,0,0,0,0,3,3,3,0,0,0,0,0,0,0,0,0
0,0,0,0,0,0,0,0,0,0,21,0,0,0,0,0,0,0,0,0,0
endlayer

layer
0,0,0,0,0,0,0,0,0,0,0,0,0,0,0,0,0,0,0,0,0
0,0,0,0,0,0,0,0,0,0,0,0,0,0,0,0,0,0,0,0,0
0,0,0,0,0,0,0,0,0,0,0,0,0,0,0,0,0,0,0,0,0
0,0,0,0,0,0,0,0,0,0,0,0,0,0,0,0,0,0,0,0,0
0,0,0,0,0,0,0,0,0,0,0,0,0,0,0,0,0,0,0,0,0
0,0,0,0,0,0,0,0,0,0,0,0,0,0,0,0,0,0,0,0,0
0,0,0,0,0,0,0,0,2,2,2,2,2,0,0,0,0,0,0,0,0
0,0,0,0,0,0,0,2,3,3,3,3,3,2,0,0,0,0,0,0,0
0,3,3,3,0,0,2,3,3,3,3,3,3,3,2,0,0,0,0,0,0
3,3,0,3,3,0,2,3,3,3,3,3,3,3,2,0,0,0,0,0,0
3,0,0,0,3,0,2,3,3,3,3,3,3,3,2,0,0,0,36,0,0
3,3,7,3,3,0,2,3,3,3,3,3,3,7,2,0,0,0,0,0,0
0,3,3,3,0,0,2,3,3,3,3,3,7,7,2,0,0,0,0,0,0
0,0,0,0,0,0,0,2,3,3,14,0,0,2,0,0,0,0,0,0,0
0,0,0,0,0,0,0,0,2,2,3,2,2,0,0,0,0,0,0,0,0
0,0,0,0,0,0,0,0,0,3,3,3,0,0,0,0,0,0,0,0,0
0,0,0,0,0,0,0,0,0,3,3,3,0,0,0,0,0,0,0,0,0
0,0,0,0,0,0,0,0,3,3,3,3,3,0,0,0,0,0,0,0,0
0,0,0,0,0,0,0,0,3,3,3,3,3,0,0,0,0,0,0,0,0
0,0,0,0,0,0,0,0,3,3,3,3,3,0,0,0,0,0,0,0,0
0,0,0,0,0,0,0,0,0,3,3,3,0,0,0,0,0,0,0,0,0
endlayer

layer
0,0,0,0,0,0,0,0,0,0,0,0,0,0,0,0,0,0,0,0,0
0,0,0,0,0,0,0,0,0,0,0,0,0,0,0,0,0,0,0,0,0
0,0,0,0,0,0,0,0,0,0,3,0,0,0,0,0,0,0,0,0,0
0,0,0,0,0,0,0,0,0,0,0,0,0,0,0,0,0,0,0,0,0
0,0,0,0,0,0,0,0,0,0,0,0,0,0,0,0,0,0,0,0,0
0,0,0,0,0,0,0,0,0,5,5,5,0,0,0,0,0,0,0,0,0
0,0,0,0,0,0,0,0,2,2,6,2,2,0,0,0,0,0,0,0,0
0,0,0,0,0,0,0,2,7,0,7,0,7,2,0,0,0,0,0,0,0
0,0,32,0,0,0,2,7,7,0,0,0,0,7,2,0,0,0,0,0,0
0,3,3,3,0,5,2,11,7,52,52,52,0,7,2,5,0,0,0,0,0
26,3,0,3,25,5,6,12,7,52,53,52,0,0,6,5,0,0,45,0,0
0,3,3,3,0,5,2,13,0,52,52,52,0,0,2,5,0,0,0,0,0
0,0,33,0,0,0,2,14,0,0,0,0,0,0,2,0,0,0,0,0,0
0,0,0,0,0,0,0,2,7,0,0,0,0,2,0,0,0,0,0,0,0
0,0,0,0,0,0,0,0,2,2,7,2,2,0,0,0,0,0,0,0,0
0,0,0,0,0,0,0,0,0,22,0,22,0,0,0,0,0,0,0,0,0
0,0,0,0,0,0,0,0,0,2,7,2,0,0,0,0,0,0,0,0,0
0,0,0,0,0,0,0,0,2,0,0,7,2,0,0,0,0,0,0,0,0
0,0,0,0,0,0,0,0,6,0,0,0,6,0,0,0,0,0,0,0,0
0,0,0,0,0,0,0,0,2,31,51,31,2,0,0,0,0,0,0,0,0
0,0,0,0,0,0,0,0,0,2,6,2,0,0,0,0,0,0,0,0,0
endlayer

layer
0,0,0,0,0,0,0,0,0,0,0,0,0,0,0,0,0,0,0,0,0
0,0,0,0,0,0,0,0,0,0,18,0,0,0,0,0,0,0,0,0,0
0,0,0,0,0,0,0,0,0,20,3,19,0,0,0,0,0,0,0,0,0
0,0,0,0,0,0,0,0,0,0,21,0,0,0,0,0,0,0,0,0,0
0,0,0,0,0,0,0,0,0,0,0,0,0,0,0,0,0,0,0,0,0
0,0,0,0,0,0,0,0,0,0,0,0,0,0,0,0,0,0,0,0,0
0,0,0,0,0,0,0,0,2,2,22,2,2,0,0,0,0,0,0,0,0
0,0,0,0,0,0,0,2,7,0,0,0,7,2,0,0,0,0,0,0,0
0,0,0,0,0,0,2,12,7,0,0,0,0,7,2,0,0,0,0,0,0
0,3,3,3,0,0,2,13,7,52,52,52,0,0,2,0,0,0,0,0,0
0,3,0,3,0,0,22,14,0,52,53,52,0,0,22,0,0,0,0,0,0
0,3,3,3,0,0,2,7,0,52,52,52,0,0,2,0,0,0,0,0,0
0,0,0,0,0,0,2,7,0,0,0,0,0,0,2,0,0,0,0,0,0
0,0,0,0,0,0,0,2,7,0,0,0,0,2,0,0,0,0,0,0,0
0,0,0,0,0,0,0,0,2,2,7,2,2,0,0,0,0,0,0,0,0
0,0,0,0,0,0,0,0,0,22,0,22,0,0,0,0,0,0,0,0,0
0,0,0,0,0,0,0,0,0,2,0,2,0,0,0,0,0,0,0,0,0
0,0,0,0,0,0,0,0,2,0,0,7,2,0,0,0,0,0,0,0,0
0,0,0,0,0,0,0,0,22,0,0,0,22,0,0,0,0,0,0,0,0
0,0,0,0,0,0,0,0,2,31,0,31,2,0,0,0,0,0,0,0,0
0,0,0,0,0,0,0,0,0,2,22,2,0,0,0,0,0,0,0,0,0
endlayer

layer
0,0,0,0,0,0,0,0,0,0,0,0,0,0,0,0,0,0,0,0,0
0,0,0,0,0,0,0,0,0,0,3,0,0,0,0,0,0,0,0,0,0
0,0,0,0,0,0,0,0,0,3,3,3,0,0,0,0,0,0,0,0,0
0,0,0,0,0,0,0,0,0,0,3,0,0,0,0,0,0,0,0,0,0
0,0,0,0,0,0,0,0,0,0,0,0,0,0,0,0,0,0,0,0,0
0,0,0,0,0,0,0,0,0,0,0,0,0,0,0,0,0,0,0,0,0
0,0,0,0,0,0,0,0,2,2,22,2,2,0,0,0,0,0,0,0,0
0,0,0,0,0,0,0,2,12,0,0,7,7,2,0,0,0,0,0,0,0
0,0,0,0,0,0,2,14,13,0,0,0,0,7,2,0,0,0,0,0,0
0,0,32,0,0,0,2,7,0,52,52,52,0,0,2,0,0,0,0,0,0
0,26,3,25,0,0,22,0,0,52,53,52,0,0,22,0,0,0,0,0,0
0,0,33,0,0,0,2,7,0,52,52,52,0,0,2,0,0,0,0,0,0
0,0,0,0,0,0,2,7,0,0,0,0,0,7,2,0,0,0,0,0,0
0,0,0,0,0,0,0,2,7,0,0,0,7,2,0,0,0,0,0,0,0
0,0,0,0,0,0,0,0,2,2,7,2,2,0,0,0,0,0,0,0,0
0,0,0,0,0,0,0,0,0,22,7,22,0,0,0,0,0,0,0,0,0
0,0,0,0,0,0,0,0,0,2,7,2,0,0,0,0,0,0,0,0,0
0,0,0,0,0,0,0,0,2,7,0,7,2,0,0,0,0,0,0,0,0
0,0,0,0,0,0,0,0,22,0,0,0,22,0,0,0,0,0,0,0,0
0,0,0,0,0,0,0,0,2,31,0,31,2,0,0,0,0,0,0,0,0
0,0,0,0,0,0,0,0,0,2,22,2,0,0,0,0,0,0,0,0,0
endlayer

layer
0,0,0,0,0,0,0,0,0,0,18,0,0,0,0,0,0,0,0,0,0
0,0,0,0,0,0,0,0,0,3,3,3,0,0,0,0,0,0,0,0,0
0,0,0,0,0,0,0,0,20,3,3,3,19,0,0,0,0,0,0,0,0
0,0,0,0,0,0,0,0,0,3,3,3,0,0,0,0,0,0,0,0,0
0,0,0,0,0,0,0,0,0,0,21,0,0,0,0,0,0,0,0,0,0
0,0,0,0,0,0,0,0,0,0,0,0,0,0,0,0,0,0,0,0,0
0,0,0,0,0,0,0,0,2,2,22,2,2,0,0,0,0,0,0,0,0
0,0,0,0,0,0,0,2,14,13,12,7,7,2,0,0,0,0,0,0,0
0,0,0,0,0,0,2,7,0,0,7,0,0,7,2,0,0,0,0,0,0
0,0,0,0,0,0,2,0,0,52,52,52,0,7,2,0,0,0,0,0,0
0,0,3,0,0,0,6,7,0,52,53,52,0,7,6,0,0,0,0,0,0
0,0,0,0,0,0,2,7,0,52,52,52,0,7,2,0,0,0,0,0,0
0,0,0,0,0,0,2,7,7,0,0,0,0,7,2,0,0,0,0,0,0
0,0,0,0,0,0,0,2,7,7,0,7,7,2,0,0,0,0,0,0,0
0,0,0,0,0,0,0,0,2,2,6,2,2,0,0,0,0,0,0,0,0
0,0,0,0,0,0,0,0,0,26,3,25,0,0,0,0,0,0,0,0,0
0,0,0,0,0,0,0,0,0,2,6,2,0,0,0,0,0,0,0,0,0
0,0,0,0,0,0,0,0,2,7,0,7,2,0,0,0,0,0,0,0,0
0,0,0,0,0,0,0,0,6,0,0,0,6,0,0,0,0,0,0,0,0
0,0,0,0,0,0,0,0,2,31,0,31,2,0,0,0,0,0,0,0,0
0,0,0,0,0,0,0,0,0,2,6,2,0,0,0,0,0,0,0,0,0
endlayer

layer
0,0,0,0,0,0,0,0,0,3,3,3,0,0,0,0,0,0,0,0,0
0,0,0,0,0,0,0,0,3,3,3,3,3,0,0,0,0,0,0,0,0
0,0,0,0,0,0,0,0,3,3,3,3,3,0,0,0,0,0,0,0,0
0,0,0,0,0,0,0,0,3,3,3,3,3,0,0,0,0,0,0,0,0
0,0,0,0,0,0,0,0,0,3,3,3,0,0,0,0,0,0,0,0,0
0,0,0,0,0,0,0,0,0,3,3,3,0,0,0,0,0,0,0,0,0
0,0,0,0,0,0,0,0,2,2,3,2,2,0,0,0,0,0,0,0,0
0,0,0,0,0,0,0,2,7,0,14,3,3,2,0,0,0,0,0,0,0
0,0,0,0,0,0,2,7,0,3,3,3,3,3,2,0,0,0,0,0,0
0,0,0,0,0,0,2,0,3,3,3,3,3,3,2,0,0,0,0,0,0
0,0,36,0,0,0,2,3,3,3,54,3,3,3,2,0,0,0,0,0,0
0,0,0,0,0,0,2,3,3,3,3,3,3,3,2,0,0,0,0,0,0
0,0,0,0,0,0,2,3,3,3,3,3,3,3,2,0,0,0,0,0,0
0,0,0,0,0,0,0,2,3,3,3,3,3,2,0,0,0,0,0,0,0
0,0,0,0,0,0,0,0,2,2,2,2,2,0,0,0,0,0,0,0,0
0,0,0,0,0,0,0,0,0,0,0,0,0,0,0,0,0,0,0,0,0
0,0,0,0,0,0,0,0,0,3,3,3,0,0,0,0,0,0,0,0,0
0,0,0,0,0,0,0,0,3,3,0,3,3,0,0,0,0,0,0,0,0
0,0,0,0,0,0,0,0,3,0,0,0,3,0,0,0,0,0,0,0,0
0,0,0,0,0,0,0,0,3,3,0,3,3,0,0,0,0,0,0,0,0
0,0,0,0,0,0,0,0,0,3,3,3,0,0,0,0,0,0,0,0,0
endlayer

layer
0,0,0,0,0,0,0,0,0,2,6,2,0,0,0,0,0,0,0,0,0
0,0,0,0,0,0,0,0,2,7,0,7,2,0,0,0,0,0,0,0,0
0,0,0,0,0,0,0,0,6,7,0,0,6,0,0,0,0,0,0,0,0
0,0,0,0,0,0,0,0,2,11,0,0,2,0,0,0,0,0,0,0,0
0,0,0,0,0,0,0,0,0,2,7,2,0,0,0,0,0,0,0,0,0
0,0,0,0,0,0,0,0,0,22,7,22,0,0,0,0,0,0,0,0,0
0,0,0,0,0,0,0,0,2,2,7,2,2,0,0,0,0,0,0,0,0
0,0,0,0,0,0,0,2,7,0,7,0,0,2,0,0,0,0,0,0,0
0,0,0,0,0,0,2,7,0,7,0,0,0,14,2,0,0,0,0,0,0
0,0,0,0,0,5,2,0,0,57,56,55,0,13,2,5,0,0,0,0,0
0,0,45,0,0,5,6,0,0,58,35,58,0,12,6,5,0,0,3,0,0
0,0,0,0,0,5,2,0,0,60,56,59,0,7,2,5,0,0,0,0,0
0,0,0,0,0,0,2,7,0,0,0,0,0,7,2,0,0,0,0,0,0
0,0,0,0,0,0,0,2,7,0,0,0,7,2,0,0,0,0,0,0,0
0,0,0,0,0,0,0,0,2,2,6,2,2,0,0,0,0,0,0,0,0
0,0,0,0,0,0,0,0,0,5,5,5,0,0,0,0,0,0,0,0,0
0,0,0,0,0,0,0,0,0,0,32,0,0,0,0,0,0,0,0,0,0
0,0,0,0,0,0,0,0,0,3,3,3,0,0,0,0,0,0,0,0,0
0,0,0,0,0,0,0,0,26,3,0,3,25,0,0,0,0,0,0,0,0
0,0,0,0,0,0,0,0,0,3,3,3,0,0,0,0,0,0,0,0,0
0,0,0,0,0,0,0,0,0,0,33,0,0,0,0,0,0,0,0,0,0
endlayer

layer
0,0,0,0,0,0,0,0,0,2,22,2,0,0,0,0,0,0,0,0,0
0,0,0,0,0,0,0,0,2,0,0,7,2,0,0,0,0,0,0,0,0
0,0,0,0,0,0,0,0,22,0,0,0,22,0,0,0,0,0,0,0,0
0,0,0,0,0,0,0,0,2,7,0,0,2,0,0,0,0,0,0,0,0
0,0,0,0,0,0,0,0,0,2,0,2,0,0,0,0,0,0,0,0,0
0,0,0,0,0,0,0,0,0,22,7,22,0,0,0,0,0,0,0,0,0
0,0,0,0,0,0,0,0,2,2,7,2,2,0,0,0,0,0,0,0,0
0,0,0,0,0,0,0,2,0,0,0,0,7,2,0,0,0,0,0,0,0
0,0,0,0,0,0,2,7,0,0,0,0,0,0,2,0,0,0,0,0,0
0,0,0,0,0,0,2,0,0,0,7,0,0,0,2,0,0,0,18,0,0
0,0,0,0,0,0,22,0,0,0,28,0,0,14,22,0,0,20,3,19,0
0,0,0,0,0,0,2,7,0,0,0,0,0,13,2,0,0,0,21,0,0
0,0,0,0,0,0,2,7,0,0,0,0,7,12,2,0,0,0,0,0,0
0,0,0,0,0,0,0,2,7,0,0,0,7,2,0,0,0,0,0,0,0
0,0,0,0,0,0,0,0,2,2,22,2,2,0,0,0,0,0,0,0,0
0,0,0,0,0,0,0,0,0,0,0,0,0,0,0,0,0,0,0,0,0
0,0,0,0,0,0,0,0,0,0,0,0,0,0,0,0,0,0,0,0,0
0,0,0,0,0,0,0,0,0,3,3,3,0,0,0,0,0,0,0,0,0
0,0,0,0,0,0,0,0,0,3,0,3,0,0,0,0,0,0,0,0,0
0,0,0,0,0,0,0,0,0,3,3,3,0,0,0,0,0,0,0,0,0
0,0,0,0,0,0,0,0,0,0,0,0,0,0,0,0,0,0,0,0,0
endlayer

layer
0,0,0,0,0,0,0,0,0,2,22,2,0,0,0,0,0,0,0,0,0
0,0,0,0,0,0,0,0,2,0,0,7,2,0,0,0,0,0,0,0,0
0,0,0,0,0,0,0,0,22,0,0,0,22,0,0,0,0,0,0,0,0
0,0,0,0,0,0,0,0,2,0,0,0,2,0,0,0,0,0,0,0,0
0,0,0,0,0,0,0,0,0,2,7,2,0,0,0,0,0,0,0,0,0
0,0,0,0,0,0,0,0,0,22,7,22,0,0,0,0,0,0,0,0,0
0,0,0,0,0,0,0,0,2,2,7,2,2,0,0,0,0,0,0,0,0
0,0,0,0,0,0,0,2,7,7,0,0,7,2,0,0,0,0,0,0,0
0,0,0,0,0,0,2,7,0,0,0,0,0,7,2,0,0,0,0,0,0
0,0,0,0,0,0,2,0,0,0,0,0,0,0,2,0,0,0,3,0,0
0,0,0,0,0,0,22,0,0,0,28,0,0,0,22,0,0,3,3,3,0
0,0,0,0,0,0,2,7,0,0,0,0,0,0,2,0,0,0,3,0,0
0,0,0,0,0,0,2,7,0,0,0,0,13,14,2,0,0,0,0,0,0
0,0,0,0,0,0,0,2,7,7,0,7,12,2,0,0,0,0,0,0,0
0,0,0,0,0,0,0,0,2,2,22,2,2,0,0,0,0,0,0,0,0
0,0,0,0,0,0,0,0,0,0,0,0,0,0,0,0,0,0,0,0,0
0,0,0,0,0,0,0,0,0,0,0,0,0,0,0,0,0,0,0,0,0
0,0,0,0,0,0,0,0,0,0,32,0,0,0,0,0,0,0,0,0,0
0,0,0,0,0,0,0,0,0,26,3,25,0,0,0,0,0,0,0,0,0
0,0,0,0,0,0,0,0,0,0,33,0,0,0,0,0,0,0,0,0,0
0,0,0,0,0,0,0,0,0,0,0,0,0,0,0,0,0,0,0,0,0
endlayer

layer
0,0,0,0,0,0,0,0,0,2,6,2,0,0,0,0,0,0,0,0,0
0,0,0,0,0,0,0,0,2,7,7,7,2,0,0,0,0,0,0,0,0
0,0,0,0,0,0,0,0,6,0,0,7,6,0,0,0,0,0,0,0,0
0,0,0,0,0,0,0,0,2,0,0,0,2,0,0,0,0,0,0,0,0
0,0,0,0,0,0,0,0,0,2,6,2,0,0,0,0,0,0,0,0,0
0,0,0,0,0,0,0,0,0,26,3,25,0,0,0,0,0,0,0,0,0
0,0,0,0,0,0,0,0,2,2,6,2,2,0,0,0,0,0,0,0,0
0,0,0,0,0,0,0,2,7,7,0,0,7,2,0,0,0,0,0,0,0
0,0,0,0,0,0,2,7,7,0,0,0,0,7,2,0,0,0,18,0,0
0,0,0,0,0,0,2,7,0,0,22,0,0,0,2,0,0,3,3,3,0
0,0,0,0,0,0,6,7,0,22,28,22,0,0,6,0,20,3,3,3,19
0,0,0,0,0,0,2,7,7,0,22,0,0,0,2,0,0,3,3,3,0
0,0,0,0,0,0,2,7,0,0,0,0,0,7,2,0,0,0,21,0,0
0,0,0,0,0,0,0,2,7,7,12,13,14,2,0,0,0,0,0,0,0
0,0,0,0,0,0,0,0,2,2,6,2,2,0,0,0,0,0,0,0,0
0,0,0,0,0,0,0,0,0,0,0,0,0,0,0,0,0,0,0,0,0
0,0,0,0,0,0,0,0,0,0,0,0,0,0,0,0,0,0,0,0,0
0,0,0,0,0,0,0,0,0,0,0,0,0,0,0,0,0,0,0,0,0
0,0,0,0,0,0,0,0,0,0,3,0,0,0,0,0,0,0,0,0,0
0,0,0,0,0,0,0,0,0,0,0,0,0,0,0,0,0,0,0,0,0
0,0,0,0,0,0,0,0,0,0,0,0,0,0,0,0,0,0,0,0,0
endlayer

layer
0,0,0,0,0,0,0,0,0,3,3,3,0,0,0,0,0,0,0,0,0
0,0,0,0,0,0,0,0,3,3,0,3,3,0,0,0,0,0,0,0,0
0,0,0,0,0,0,0,0,3,0,0,0,3,0,0,0,0,0,0,0,0
0,0,0,0,0,0,0,0,3,3,0,3,3,0,0,0,0,0,0,0,0
0,0,0,0,0,0,0,0,0,3,3,3,0,0,0,0,0,0,0,0,0
0,0,0,0,0,0,0,0,0,0,0,0,0,0,0,0,0,0,0,0,0
0,0,0,0,0,0,0,0,2,2,2,2,2,0,0,0,0,0,0,0,0
0,0,0,0,0,0,0,2,3,3,3,3,3,2,0,0,0,0,0,0,0
0,0,0,0,0,0,2,3,3,3,3,3,3,3,2,0,0,3,3,3,0
0,0,0,0,0,0,2,3,3,3,3,3,3,3,2,3,3,3,3,3,3
0,0,0,0,0,0,2,3,3,3,3,3,3,3,3,3,3,3,3,3,3
0,0,0,0,0,0,2,3,3,3,3,3,3,7,2,3,3,3,3,3,3
0,0,0,0,0,0,2,3,3,3,3,3,0,7,2,0,0,3,3,3,0
0,0,0,0,0,0,0,2,3,3,14,7,7,2,0,0,0,0,0,0,0
0,0,0,0,0,0,0,0,2,2,2,2,2,0,0,0,0,0,0,0,0
0,0,0,0,0,0,0,0,0,0,0,0,0,0,0,0,0,0,0,0,0
0,0,0,0,0,0,0,0,0,0,0,0,0,0,0,0,0,0,0,0,0
0,0,0,0,0,0,0,0,0,0,0,0,0,0,0,0,0,0,0,0,0
0,0,0,0,0,0,0,0,0,0,36,0,0,0,0,0,0,0,0,0,0
0,0,0,0,0,0,0,0,0,0,0,0,0,0,0,0,0,0,0,0,0
0,0,0,0,0,0,0,0,0,0,0,0,0,0,0,0,0,0,0,0,0
endlayer

layer
0,0,0,0,0,0,0,0,0,0,32,0,0,0,0,0,0,0,0,0,0
0,0,0,0,0,0,0,0,0,3,3,3,0,0,0,0,0,0,0,0,0
0,0,0,0,0,0,0,0,26,3,0,3,25,0,0,0,0,0,0,0,0
0,0,0,0,0,0,0,0,0,3,3,3,0,0,0,0,0,0,0,0,0
0,0,0,0,0,0,0,0,0,0,33,0,0,0,0,0,0,0,0,0,0
0,0,0,0,0,0,0,0,0,5,5,5,0,0,0,0,0,0,0,0,0
0,0,0,0,0,0,0,0,2,2,6,2,2,0,0,0,0,0,0,0,0
0,0,0,0,0,0,0,2,7,7,0,7,7,2,0,0,0,0,0,0,0
0,0,0,0,0,0,2,7,7,0,42,0,0,0,2,0,0,2,6,2,0
0,0,0,0,0,5,2,7,0,57,56,55,0,7,2,22,2,61,61,61,2
0,0,3,0,0,5,6,12,10,58,63,58,9,7,7,0,23,0,0,62,6
0,0,0,0,0,5,2,13,0,60,56,59,0,0,2,22,2,11,61,61,2
0,0,0,0,0,0,2,14,0,0,31,0,0,7,2,0,0,2,6,2,0
0,0,0,0,0,0,0,2,7,0,7,0,7,2,0,0,0,0,0,0,0
0,0,0,0,0,0,0,0,2,2,6,2,2,0,0,0,0,0,0,0,0
0,0,0,0,0,0,0,0,0,5,5,5,0,0,0,0,0,0,0,0,0
0,0,0,0,0,0,0,0,0,0,0,0,0,0,0,0,0,0,0,0,0
0,0,0,0,0,0,0,0,0,0,0,0,0,0,0,0,0,0,0,0,0
0,0,0,0,0,0,0,0,0,0,45,0,0,0,0,0,0,0,0,0,0
0,0,0,0,0,0,0,0,0,0,0,0,0,0,0,0,0,0,0,0,0
0,0,0,0,0,0,0,0,0,0,0,0,0,0,0,0,0,0,0,0,0
endlayer

layer
0,0,0,0,0,0,0,0,0,0,0,0,0,0,0,0,0,0,0,0,0
0,0,0,0,0,0,0,0,0,3,3,3,0,0,0,0,0,0,0,0,0
0,0,0,0,0,0,0,0,0,3,0,3,0,0,0,0,0,0,0,0,0
0,0,0,0,0,0,0,0,0,3,3,3,0,0,0,0,0,0,0,0,0
0,0,0,0,0,0,0,0,0,0,0,0,0,0,0,0,0,0,0,0,0
0,0,0,0,0,0,0,0,0,0,0,0,0,0,0,0,0,0,0,0,0
0,0,0,0,0,0,0,0,2,2,22,2,2,0,0,0,0,0,0,0,0
0,0,0,0,0,0,0,2,7,7,0,0,7,2,0,0,0,0,0,0,0
0,0,0,0,0,0,2,12,0,0,0,0,7,7,2,0,0,2,22,2,0
0,0,18,0,0,0,2,13,0,0,22,0,0,7,2,22,2,61,0,61,2
0,20,3,19,0,0,22,14,0,22,22,22,0,0,7,0,0,0,0,0,22
0,0,21,0,0,0,2,0,0,0,22,0,0,7,2,22,2,61,7,61,2
0,0,0,0,0,0,2,7,0,0,0,0,0,7,2,0,0,2,22,2,0
0,0,0,0,0,0,0,2,7,0,0,0,0,2,0,0,0,0,0,0,0
0,0,0,0,0,0,0,0,2,2,22,2,2,0,0,0,0,0,0,0,0
0,0,0,0,0,0,0,0,0,0,0,0,0,0,0,0,0,0,0,0,0
0,0,0,0,0,0,0,0,0,0,0,0,0,0,0,0,0,0,0,0,0
0,0,0,0,0,0,0,0,0,0,0,0,0,0,0,0,0,0,0,0,0
0,0,0,0,0,0,0,0,0,0,0,0,0,0,0,0,0,0,0,0,0
0,0,0,0,0,0,0,0,0,0,0,0,0,0,0,0,0,0,0,0,0
0,0,0,0,0,0,0,0,0,0,0,0,0,0,0,0,0,0,0,0,0
endlayer

layer
0,0,0,0,0,0,0,0,0,0,0,0,0,0,0,0,0,0,0,0,0
0,0,0,0,0,0,0,0,0,0,32,0,0,0,0,0,0,0,0,0,0
0,0,0,0,0,0,0,0,0,26,3,25,0,0,0,0,0,0,0,0,0
0,0,0,0,0,0,0,0,0,0,33,0,0,0,0,0,0,0,0,0,0
0,0,0,0,0,0,0,0,0,0,0,0,0,0,0,0,0,0,0,0,0
0,0,0,0,0,0,0,0,0,0,0,0,0,0,0,0,0,0,0,0,0
0,0,0,0,0,0,0,0,2,2,22,2,2,0,0,0,0,0,0,0,0
0,0,0,0,0,0,0,2,12,0,0,7,7,2,0,0,0,0,0,0,0
0,0,0,0,0,0,2,14,13,0,0,0,0,7,2,0,0,2,22,2,0
0,0,3,0,0,0,2,0,0,0,0,0,0,7,2,22,2,7,0,7,2
0,3,3,3,0,0,22,0,0,0,48,0,0,0,7,7,0,0,0,7,22
0,0,3,0,0,0,2,0,0,0,0,0,0,0,2,22,2,7,0,7,2
0,0,0,0,0,0,2,7,0,0,0,0,0,7,2,0,0,2,22,2,0
0,0,0,0,0,0,0,2,7,0,0,0,7,2,0,0,0,0,0,0,0
0,0,0,0,0,0,0,0,2,2,22,2,2,0,0,0,0,0,0,0,0
0,0,0,0,0,0,0,0,0,0,0,0,0,0,0,0,0,0,0,0,0
0,0,0,0,0,0,0,0,0,0,0,0,0,0,0,0,0,0,0,0,0
0,0,0,0,0,0,0,0,0,0,0,0,0,0,0,0,0,0,0,0,0
0,0,0,0,0,0,0,0,0,0,0,0,0,0,0,0,0,0,0,0,0
0,0,0,0,0,0,0,0,0,0,0,0,0,0,0,0,0,0,0,0,0
0,0,0,0,0,0,0,0,0,0,0,0,0,0,0,0,0,0,0,0,0
endlayer

layer
0,0,0,0,0,0,0,0,0,0,0,0,0,0,0,0,0,0,0,0,0
0,0,0,0,0,0,0,0,0,0,0,0,0,0,0,0,0,0,0,0,0
0,0,0,0,0,0,0,0,0,0,3,0,0,0,0,0,0,0,0,0,0
0,0,0,0,0,0,0,0,0,0,0,0,0,0,0,0,0,0,0,0,0
0,0,0,0,0,0,0,0,0,0,0,0,0,0,0,0,0,0,0,0,0
0,0,0,0,0,0,0,0,0,0,0,0,0,0,0,0,0,0,0,0,0
0,0,0,0,0,0,0,0,2,2,6,2,2,0,0,0,0,0,0,0,0
0,0,0,0,0,0,0,2,14,13,12,7,7,2,0,0,0,0,0,0,0
0,0,18,0,0,0,2,7,7,0,0,7,7,7,2,0,0,2,6,2,0
0,3,3,3,0,0,2,7,0,0,0,0,0,7,2,32,2,7,7,7,2
20,3,3,3,19,0,6,7,0,0,8,0,0,7,6,3,6,7,7,7,6
0,3,3,3,0,0,2,7,0,0,0,0,0,7,2,33,2,7,0,7,2
0,0,21,0,0,0,2,7,0,0,0,0,7,7,2,0,0,2,6,2,0
0,0,0,0,0,0,0,2,7,0,0,7,7,2,0,0,0,0,0,0,0
0,0,0,0,0,0,0,0,2,2,6,2,2,0,0,0,0,0,0,0,0
0,0,0,0,0,0,0,0,0,0,0,0,0,0,0,0,0,0,0,0,0
0,0,0,0,0,0,0,0,0,0,0,0,0,0,0,0,0,0,0,0,0
0,0,0,0,0,0,0,0,0,0,0,0,0,0,0,0,0,0,0,0,0
0,0,0,0,0,0,0,0,0,0,0,0,0,0,0,0,0,0,0,0,0
0,0,0,0,0,0,0,0,0,0,0,0,0,0,0,0,0,0,0,0,0
0,0,0,0,0,0,0,0,0,0,0,0,0,0,0,0,0,0,0,0,0
endlayer

layer
0,0,0,0,0,0,0,0,0,0,0,0,0,0,0,0,0,0,0,0,0
0,0,0,0,0,0,0,0,0,0,0,0,0,0,0,0,0,0,0,0,0
0,0,0,0,0,0,0,0,0,0,36,0,0,0,0,0,0,0,0,0,0
0,0,0,0,0,0,0,0,0,0,0,0,0,0,0,0,0,0,0,0,0
0,0,0,0,0,0,0,0,0,0,0,0,0,0,0,0,0,0,0,0,0
0,0,0,0,0,0,0,0,0,0,0,0,0,0,0,0,0,0,0,0,0
0,0,0,0,0,0,0,0,2,2,2,2,2,0,0,0,0,0,0,0,0
0,0,0,0,0,0,0,2,7,0,14,3,3,2,0,0,0,0,0,0,0
0,3,3,3,0,0,2,7,0,3,3,3,3,3,2,0,0,3,3,3,0
3,3,3,3,3,3,2,7,3,3,3,3,3,3,2,0,3,3,0,3,3
3,3,3,3,3,3,3,3,3,3,3,3,3,3,2,0,3,7,0,7,3
3,3,3,3,3,3,2,3,3,3,3,3,3,3,2,0,3,3,7,3,3
0,3,3,3,0,0,2,3,3,3,3,3,3,3,2,0,0,3,3,3,0
0,0,0,0,0,0,0,2,3,3,3,3,3,2,0,0,0,0,0,0,0
0,0,0,0,0,0,0,0,2,2,2,2,2,0,0,0,0,0,0,0,0
0,0,0,0,0,0,0,0,0,0,0,0,0,0,0,0,0,0,0,0,0
0,0,0,0,0,0,0,0,0,0,0,0,0,0,0,0,0,0,0,0,0
0,0,0,0,0,0,0,0,0,0,0,0,0,0,0,0,0,0,0,0,0
0,0,0,0,0,0,0,0,0,0,0,0,0,0,0,0,0,0,0,0,0
0,0,0,0,0,0,0,0,0,0,0,0,0,0,0,0,0,0,0,0,0
0,0,0,0,0,0,0,0,0,0,0,0,0,0,0,0,0,0,0,0,0
endlayer

layer
0,0,0,0,0,0,0,0,0,0,0,0,0,0,0,0,0,0,0,0,0
0,0,0,0,0,0,0,0,0,0,0,0,0,0,0,0,0,0,0,0,0
0,0,0,0,0,0,0,0,0,0,45,0,0,0,0,0,0,0,0,0,0
0,0,0,0,0,0,0,0,0,0,0,0,0,0,0,0,0,0,0,0,0
0,0,0,0,0,0,0,0,0,0,0,0,0,0,0,0,0,0,0,0,0
0,0,0,0,0,0,0,0,0,5,5,5,0,0,0,0,0,0,0,0,0
0,0,0,0,0,0,0,0,2,2,6,2,2,0,0,0,0,0,0,0,0
0,0,0,0,0,0,0,2,7,0,0,0,7,2,0,0,0,0,0,0,0
0,2,6,2,0,0,2,7,0,0,0,0,0,14,2,0,0,0,32,0,0
2,41,7,0,2,22,2,0,0,0,0,0,0,13,2,5,0,3,3,3,0
6,65,64,7,7,7,7,0,7,0,29,0,7,12,6,5,26,3,0,3,25
2,66,0,11,2,22,2,0,0,0,0,7,7,11,2,5,0,3,3,3,0
0,2,6,2,0,0,2,7,7,0,0,0,7,7,2,0,0,0,33,0,0
0,0,0,0,0,0,0,2,41,41,41,41,41,2,0,0,0,0,0,0,0
0,0,0,0,0,0,0,0,2,2,6,2,2,0,0,0,0,0,0,0,0
0,0,0,0,0,0,0,0,0,5,5,5,0,0,0,0,0,0,0,0,0
0,0,0,0,0,0,0,0,0,0,0,0,0,0,0,0,0,0,0,0,0
0,0,0,0,0,0,0,0,0,0,0,0,0,0,0,0,0,0,0,0,0
0,0,0,0,0,0,0,0,0,0,0,0,0,0,0,0,0,0,0,0,0
0,0,0,0,0,0,0,0,0,0,0,0,0,0,0,0,0,0,0,0,0
0,0,0,0,0,0,0,0,0,0,0,0,0,0,0,0,0,0,0,0,0
endlayer

layer
0,0,0,0,0,0,0,0,0,0,0,0,0,0,0,0,0,0,0,0,0
0,0,0,0,0,0,0,0,0,0,0,0,0,0,0,0,0,0,0,0,0
0,0,0,0,0,0,0,0,0,0,0,0,0,0,0,0,0,0,0,0,0
0,0,0,0,0,0,0,0,0,0,0,0,0,0,0,0,0,0,0,0,0
0,0,0,0,0,0,0,0,0,0,0,0,0,0,0,0,0,0,0,0,0
0,0,0,0,0,0,0,0,0,0,0,0,0,0,0,0,0,0,0,0,0
0,0,0,0,0,0,0,0,2,2,22,2,2,0,0,0,0,0,0,0,0
0,0,0,0,0,0,0,2,7,0,0,0,0,2,0,0,0,0,0,0,0
0,2,22,2,0,0,2,7,0,0,0,0,0,0,2,0,0,0,0,0,0
2,7,7,0,2,22,2,0,0,0,0,0,0,0,2,0,0,3,3,3,0
22,7,7,7,7,7,7,0,0,0,7,0,7,14,22,0,0,3,0,3,0
2,7,7,7,2,22,2,0,0,0,0,0,7,13,2,0,0,3,3,3,0
0,2,22,2,0,0,2,7,0,0,0,0,7,12,2,0,0,0,0,0,0
0,0,0,0,0,0,0,2,67,7,0,0,7,2,0,0,0,0,0,0,0
0,0,0,0,0,0,0,0,2,2,22,2,2,0,0,0,0,0,0,0,0
0,0,0,0,0,0,0,0,0,0,0,0,0,0,0,0,0,0,0,0,0
0,0,0,0,0,0,0,0,0,0,0,0,0,0,0,0,0,0,0,0,0
0,0,0,0,0,0,0,0,0,0,0,0,0,0,0,0,0,0,0,0,0
0,0,0,0,0,0,0,0,0,0,0,0,0,0,0,0,0,0,0,0,0
0,0,0,0,0,0,0,0,0,0,0,0,0,0,0,0,0,0,0,0,0
0,0,0,0,0,0,0,0,0,0,0,0,0,0,0,0,0,0,0,0,0
endlayer

layer
0,0,0,0,0,0,0,0,0,0,0,0,0,0,0,0,0,0,0,0,0
0,0,0,0,0,0,0,0,0,0,0,0,0,0,0,0,0,0,0,0,0
0,0,0,0,0,0,0,0,0,0,0,0,0,0,0,0,0,0,0,0,0
0,0,0,0,0,0,0,0,0,0,0,0,0,0,0,0,0,0,0,0,0
0,0,0,0,0,0,0,0,0,0,0,0,0,0,0,0,0,0,0,0,0
0,0,0,0,0,0,0,0,0,0,0,0,0,0,0,0,0,0,0,0,0
0,0,0,0,0,0,0,0,2,2,22,2,2,0,0,0,0,0,0,0,0
0,0,0,0,0,0,0,2,7,7,0,0,7,2,0,0,0,0,0,0,0
0,2,22,2,0,0,2,7,0,0,0,0,0,0,2,0,0,0,0,0,0
2,7,0,7,2,22,2,0,0,0,0,0,0,0,2,0,0,0,32,0,0
22,7,0,0,7,0,0,0,0,0,48,0,0,0,22,0,0,26,3,25,0
2,7,0,7,2,22,2,7,0,0,0,0,0,0,2,0,0,0,33,0,0
0,2,22,2,0,0,2,7,0,0,0,0,13,14,2,0,0,0,0,0,0
0,0,0,0,0,0,0,2,7,0,0,0,12,2,0,0,0,0,0,0,0
0,0,0,0,0,0,0,0,2,2,22,2,2,0,0,0,0,0,0,0,0
0,0,0,0,0,0,0,0,0,0,0,0,0,0,0,0,0,0,0,0,0
0,0,0,0,0,0,0,0,0,0,0,0,0,0,0,0,0,0,0,0,0
0,0,0,0,0,0,0,0,0,0,0,0,0,0,0,0,0,0,0,0,0
0,0,0,0,0,0,0,0,0,0,0,0,0,0,0,0,0,0,0,0,0
0,0,0,0,0,0,0,0,0,0,0,0,0,0,0,0,0,0,0,0,0
0,0,0,0,0,0,0,0,0,0,0,0,0,0,0,0,0,0,0,0,0
endlayer

layer
0,0,0,0,0,0,0,0,0,0,0,0,0,0,0,0,0,0,0,0,0
0,0,0,0,0,0,0,0,0,0,0,0,0,0,0,0,0,0,0,0,0
0,0,0,0,0,0,0,0,0,0,0,0,0,0,0,0,0,0,0,0,0
0,0,0,0,0,0,0,0,0,0,0,0,0,0,0,0,0,0,0,0,0
0,0,0,0,0,0,0,0,0,0,0,0,0,0,0,0,0,0,0,0,0
0,0,0,0,0,0,0,0,0,0,0,0,0,0,0,0,0,0,0,0,0
0,0,0,0,0,0,0,0,2,2,6,2,2,0,0,0,0,0,0,0,0
0,0,0,0,0,0,0,2,7,7,7,7,7,2,0,0,0,0,0,0,0
0,2,6,2,0,0,2,7,0,0,0,0,0,7,2,0,0,0,0,0,0
2,7,0,7,2,32,2,7,0,0,0,0,0,0,2,0,0,0,0,0,0
6,7,0,0,6,3,6,7,0,0,8,0,0,0,6,0,0,0,3,0,0
2,7,7,7,2,33,2,7,0,0,0,0,0,0,2,0,0,0,0,0,0
0,2,6,2,0,0,2,7,7,0,0,0,0,7,2,0,0,0,0,0,0
0,0,0,0,0,0,0,2,7,7,12,13,14,2,0,0,0,0,0,0,0
0,0,0,0,0,0,0,0,2,2,6,2,2,0,0,0,0,0,0,0,0
0,0,0,0,0,0,0,0,0,0,0,0,0,0,0,0,0,0,0,0,0
0,0,0,0,0,0,0,0,0,0,0,0,0,0,0,0,0,0,0,0,0
0,0,0,0,0,0,0,0,0,0,0,0,0,0,0,0,0,0,0,0,0
0,0,0,0,0,0,0,0,0,0,0,0,0,0,0,0,0,0,0,0,0
0,0,0,0,0,0,0,0,0,0,0,0,0,0,0,0,0,0,0,0,0
0,0,0,0,0,0,0,0,0,0,0,0,0,0,0,0,0,0,0,0,0
endlayer

layer
0,0,0,0,0,0,0,0,0,0,0,0,0,0,0,0,0,0,0,0,0
0,0,0,0,0,0,0,0,0,0,0,0,0,0,0,0,0,0,0,0,0
0,0,0,0,0,0,0,0,0,0,0,0,0,0,0,0,0,0,0,0,0
0,0,0,0,0,0,0,0,0,0,0,0,0,0,0,0,0,0,0,0,0
0,0,0,0,0,0,0,0,0,0,0,0,0,0,0,0,0,0,0,0,0
0,0,0,0,0,0,0,0,0,5,5,5,0,0,0,0,0,0,0,0,0
0,0,0,0,0,0,0,0,2,2,2,2,2,0,0,0,0,0,0,0,0
0,0,0,0,0,0,0,2,3,3,3,3,3,2,0,0,0,0,0,0,0
0,3,3,3,0,0,2,3,3,3,3,3,3,3,2,0,0,0,0,0,0
3,3,7,3,3,5,2,3,3,3,3,3,3,3,2,5,0,0,0,0,0
3,7,0,7,3,5,2,3,3,3,3,3,3,3,2,5,0,0,36,0,0
3,3,7,3,3,5,2,3,3,3,3,3,3,0,2,5,0,0,0,0,0
0,3,3,3,0,0,2,3,3,3,3,3,0,7,2,0,0,0,0,0,0
0,0,0,0,0,0,0,2,3,3,14,0,7,2,0,0,0,0,0,0,0
0,0,0,0,0,0,0,0,2,2,2,2,2,0,0,0,0,0,0,0,0
0,0,0,0,0,0,0,0,0,5,5,5,0,0,0,0,0,0,0,0,0
0,0,0,0,0,0,0,0,0,0,0,0,0,0,0,0,0,0,0,0,0
0,0,0,0,0,0,0,0,0,0,0,0,0,0,0,0,0,0,0,0,0
0,0,0,0,0,0,0,0,0,0,0,0,0,0,0,0,0,0,0,0,0
0,0,0,0,0,0,0,0,0,0,0,0,0,0,0,0,0,0,0,0,0
0,0,0,0,0,0,0,0,0,0,0,0,0,0,0,0,0,0,0,0,0
endlayer

layer
0,0,0,0,0,0,0,0,0,0,0,0,0,0,0,0,0,0,0,0,0
0,0,0,0,0,0,0,0,0,0,0,0,0,0,0,0,0,0,0,0,0
0,0,0,0,0,0,0,0,0,0,0,0,0,0,0,0,0,0,0,0,0
0,0,0,0,0,0,0,0,0,0,0,0,0,0,0,0,0,0,0,0,0
0,0,0,0,0,0,0,0,0,0,0,0,0,0,0,0,0,0,0,0,0
0,0,0,0,0,0,0,0,0,0,0,0,0,0,0,0,0,0,0,0,0
0,0,0,0,0,0,0,0,2,36,36,36,2,0,0,0,0,0,0,0,0
0,0,0,0,0,0,0,2,0,0,0,0,0,2,0,0,0,0,0,0,0
0,0,32,0,0,0,2,11,0,68,69,68,0,0,2,0,0,0,0,0,0
0,3,3,3,0,0,36,0,68,69,70,69,68,0,36,0,0,0,0,0,0
26,3,7,3,25,0,36,0,69,70,45,70,69,0,36,0,0,0,45,0,0
0,3,3,3,0,0,36,0,68,69,70,69,68,0,36,0,0,0,0,0,0
0,0,33,0,0,0,2,0,0,68,69,68,0,0,2,0,0,0,0,0,0
0,0,0,0,0,0,0,2,0,0,0,0,0,2,0,0,0,0,0,0,0
0,0,0,0,0,0,0,0,2,36,36,36,2,0,0,0,0,0,0,0,0
0,0,0,0,0,0,0,0,0,0,0,0,0,0,0,0,0,0,0,0,0
0,0,0,0,0,0,0,0,0,0,0,0,0,0,0,0,0,0,0,0,0
0,0,0,0,0,0,0,0,0,0,0,0,0,0,0,0,0,0,0,0,0
0,0,0,0,0,0,0,0,0,0,0,0,0,0,0,0,0,0,0,0,0
0,0,0,0,0,0,0,0,0,0,0,0,0,0,0,0,0,0,0,0,0
0,0,0,0,0,0,0,0,0,0,0,0,0,0,0,0,0,0,0,0,0
endlayer

layer
0,0,0,0,0,0,0,0,0,0,0,0,0,0,0,0,0,0,0,0,0
0,0,0,0,0,0,0,0,0,0,0,0,0,0,0,0,0,0,0,0,0
0,0,0,0,0,0,0,0,0,0,0,0,0,0,0,0,0,0,0,0,0
0,0,0,0,0,0,0,0,0,0,0,0,0,0,0,0,0,0,0,0,0
0,0,0,0,0,0,0,0,0,0,0,0,0,0,0,0,0,0,0,0,0
0,0,0,0,0,0,0,0,0,0,0,0,0,0,0,0,0,0,0,0,0
0,0,0,0,0,0,0,0,2,0,0,0,2,0,0,0,0,0,0,0,0
0,0,0,0,0,0,0,2,0,0,0,0,0,2,0,0,0,0,0,0,0
0,0,0,0,0,0,2,0,0,0,0,0,0,0,2,0,0,0,0,0,0
0,3,3,3,0,0,0,0,0,0,0,0,0,0,0,0,0,0,0,0,0
0,3,0,3,0,0,0,0,0,0,0,0,0,0,0,0,0,0,0,0,0
0,3,3,3,0,0,0,0,0,0,0,0,0,0,0,0,0,0,0,0,0
0,0,0,0,0,0,2,0,0,0,0,0,0,0,2,0,0,0,0,0,0
0,0,0,0,0,0,0,2,0,0,0,7,0,2,0,0,0,0,0,0,0
0,0,0,0,0,0,0,0,2,0,0,0,2,0,0,0,0,0,0,0,0
0,0,0,0,0,0,0,0,0,0,0,0,0,0,0,0,0,0,0,0,0
0,0,0,0,0,0,0,0,0,0,0,0,0,0,0,0,0,0,0,0,0
0,0,0,0,0,0,0,0,0,0,0,0,0,0,0,0,0,0,0,0,0
0,0,0,0,0,0,0,0,0,0,0,0,0,0,0,0,0,0,0,0,0
0,0,0,0,0,0,0,0,0,0,0,0,0,0,0,0,0,0,0,0,0
0,0,0,0,0,0,0,0,0,0,0,0,0,0,0,0,0,0,0,0,0
endlayer

layer
0,0,0,0,0,0,0,0,0,0,0,0,0,0,0,0,0,0,0,0,0
0,0,0,0,0,0,0,0,0,0,0,0,0,0,0,0,0,0,0,0,0
0,0,0,0,0,0,0,0,0,0,0,0,0,0,0,0,0,0,0,0,0
0,0,0,0,0,0,0,0,0,0,0,0,0,0,0,0,0,0,0,0,0
0,0,0,0,0,0,0,0,0,0,0,0,0,0,0,0,0,0,0,0,0
0,0,0,0,0,0,0,0,0,0,0,0,0,0,0,0,0,0,0,0,0
0,0,0,0,0,0,0,0,2,2,0,2,2,0,0,0,0,0,0,0,0
0,0,0,0,0,0,0,2,0,0,0,0,0,2,0,0,0,0,0,0,0
0,0,0,0,0,0,2,0,0,0,71,0,0,0,2,0,0,0,0,0,0
0,0,32,0,0,0,2,0,0,0,0,0,0,0,2,0,0,0,0,0,0
0,26,3,25,0,0,0,0,74,0,73,0,72,0,0,0,0,0,0,0,0
0,0,33,0,0,0,2,0,0,0,0,0,0,0,2,0,0,0,0,0,0
0,0,0,0,0,0,2,0,0,0,75,0,0,0,2,0,0,0,0,0,0
0,0,0,0,0,0,0,2,0,0,0,7,7,2,0,0,0,0,0,0,0
0,0,0,0,0,0,0,0,2,2,0,2,2,0,0,0,0,0,0,0,0
0,0,0,0,0,0,0,0,0,0,0,0,0,0,0,0,0,0,0,0,0
0,0,0,0,0,0,0,0,0,0,0,0,0,0,0,0,0,0,0,0,0
0,0,0,0,0,0,0,0,0,0,0,0,0,0,0,0,0,0,0,0,0
0,0,0,0,0,0,0,0,0,0,0,0,0,0,0,0,0,0,0,0,0
0,0,0,0,0,0,0,0,0,0,0,0,0,0,0,0,0,0,0,0,0
0,0,0,0,0,0,0,0,0,0,0,0,0,0,0,0,0,0,0,0,0
endlayer

layer
0,0,0,0,0,0,0,0,0,0,0,0,0,0,0,0,0,0,0,0,0
0,0,0,0,0,0,0,0,0,0,0,0,0,0,0,0,0,0,0,0,0
0,0,0,0,0,0,0,0,0,0,0,0,0,0,0,0,0,0,0,0,0
0,0,0,0,0,0,0,0,0,0,0,0,0,0,0,0,0,0,0,0,0
0,0,0,0,0,0,0,0,0,0,0,0,0,0,0,0,0,0,0,0,0
0,0,0,0,0,0,0,0,0,0,0,0,0,0,0,0,0,0,0,0,0
0,0,0,0,0,0,0,0,2,2,6,2,2,0,0,0,0,0,0,0,0
0,0,0,0,0,0,0,2,0,0,0,0,0,2,0,0,0,0,0,0,0
0,0,0,0,0,0,2,0,0,0,22,0,0,0,2,0,0,0,0,0,0
0,0,0,0,0,0,2,0,0,0,22,0,0,0,2,0,0,0,0,0,0
0,0,3,0,0,0,6,0,22,22,22,22,22,0,6,0,0,0,0,0,0
0,0,0,0,0,0,2,0,0,0,22,0,0,0,2,0,0,0,0,0,0
0,0,0,0,0,0,2,0,0,0,22,0,7,7,2,0,0,0,0,0,0
0,0,0,0,0,0,0,2,0,0,0,0,7,2,0,0,0,0,0,0,0
0,0,0,0,0,0,0,0,2,2,6,2,2,0,0,0,0,0,0,0,0
0,0,0,0,0,0,0,0,0,0,0,0,0,0,0,0,0,0,0,0,0
0,0,0,0,0,0,0,0,0,0,0,0,0,0,0,0,0,0,0,0,0
0,0,0,0,0,0,0,0,0,0,0,0,0,0,0,0,0,0,0,0,0
0,0,0,0,0,0,0,0,0,0,0,0,0,0,0,0,0,0,0,0,0
0,0,0,0,0,0,0,0,0,0,0,0,0,0,0,0,0,0,0,0,0
0,0,0,0,0,0,0,0,0,0,0,0,0,0,0,0,0,0,0,0,0
endlayer

layer
0,0,0,0,0,0,0,0,0,0,0,0,0,0,0,0,0,0,0,0,0
0,0,0,0,0,0,0,0,0,0,0,0,0,0,0,0,0,0,0,0,0
0,0,0,0,0,0,0,0,0,0,0,0,0,0,0,0,0,0,0,0,0
0,0,0,0,0,0,0,0,0,0,0,0,0,0,0,0,0,0,0,0,0
0,0,0,0,0,0,0,0,0,0,0,0,0,0,0,0,0,0,0,0,0
0,0,0,0,0,0,0,0,76,76,76,76,76,0,0,0,0,0,0,0,0
0,0,0,0,0,0,0,76,3,3,3,3,3,76,0,0,0,0,0,0,0
0,0,0,0,0,0,76,3,3,77,77,77,3,3,76,0,0,0,0,0,0
0,0,0,0,0,76,3,3,77,0,0,0,77,3,3,76,0,0,0,0,0
0,0,0,0,0,76,3,77,0,0,0,0,0,77,3,76,0,0,0,0,0
0,0,36,0,0,76,3,77,0,0,22,0,0,77,3,76,0,0,0,0,0
0,0,0,0,0,76,3,77,0,0,0,0,0,77,3,76,0,0,0,0,0
0,0,0,0,0,76,3,3,77,0,0,0,77,3,3,76,0,0,0,0,0
0,0,0,0,0,0,76,3,3,77,77,77,3,3,76,0,0,0,0,0,0
0,0,0,0,0,0,0,76,3,3,3,3,3,76,0,0,0,0,0,0,0
0,0,0,0,0,0,0,0,76,76,76,76,76,0,0,0,0,0,0,0,0
0,0,0,0,0,0,0,0,0,0,0,0,0,0,0,0,0,0,0,0,0
0,0,0,0,0,0,0,0,0,0,0,0,0,0,0,0,0,0,0,0,0
0,0,0,0,0,0,0,0,0,0,0,0,0,0,0,0,0,0,0,0,0
0,0,0,0,0,0,0,0,0,0,0,0,0,0,0,0,0,0,0,0,0
0,0,0,0,0,0,0,0,0,0,0,0,0,0,0,0,0,0,0,0,0
endlayer

layer
0,0,0,0,0,0,0,0,0,0,0,0,0,0,0,0,0,0,0,0,0
0,0,0,0,0,0,0,0,0,0,0,0,0,0,0,0,0,0,0,0,0
0,0,0,0,0,0,0,0,0,0,0,0,0,0,0,0,0,0,0,0,0
0,0,0,0,0,0,0,0,0,0,0,0,0,0,0,0,0,0,0,0,0
0,0,0,0,0,0,0,0,0,0,0,0,0,0,0,0,0,0,0,0,0
0,0,0,0,0,0,0,0,0,0,0,0,0,0,0,0,0,0,0,0,0
0,0,0,0,0,0,0,0,0,0,0,0,0,0,0,0,0,0,0,0,0
0,0,0,0,0,0,0,0,76,76,76,76,76,0,0,0,0,0,0,0,0
0,0,0,0,0,0,0,76,76,3,3,3,76,76,0,0,0,0,0,0,0
0,0,0,0,0,0,0,76,3,3,0,3,3,76,0,0,0,0,0,0,0
0,0,45,0,0,0,0,76,3,0,22,0,3,78,0,0,0,0,0,0,0
0,0,0,0,0,0,0,76,3,3,0,3,3,76,0,0,0,0,0,0,0
0,0,0,0,0,0,0,76,76,3,3,3,76,76,0,0,0,0,0,0,0
0,0,0,0,0,0,0,0,76,76,76,76,76,0,0,0,0,0,0,0,0
0,0,0,0,0,0,0,0,0,0,0,0,0,0,0,0,0,0,0,0,0
0,0,0,0,0,0,0,0,0,0,0,0,0,0,0,0,0,0,0,0,0
0,0,0,0,0,0,0,0,0,0,0,0,0,0,0,0,0,0,0,0,0
0,0,0,0,0,0,0,0,0,0,0,0,0,0,0,0,0,0,0,0,0
0,0,0,0,0,0,0,0,0,0,0,0,0,0,0,0,0,0,0,0,0
0,0,0,0,0,0,0,0,0,0,0,0,0,0,0,0,0,0,0,0,0
0,0,0,0,0,0,0,0,0,0,0,0,0,0,0,0,0,0,0,0,0
endlayer

layer
0,0,0,0,0,0,0,0,0,0,0,0,0,0,0,0,0,0,0,0,0
0,0,0,0,0,0,0,0,0,0,0,0,0,0,0,0,0,0,0,0,0
0,0,0,0,0,0,0,0,0,0,0,0,0,0,0,0,0,0,0,0,0
0,0,0,0,0,0,0,0,0,0,0,0,0,0,0,0,0,0,0,0,0
0,0,0,0,0,0,0,0,0,0,0,0,0,0,0,0,0,0,0,0,0
0,0,0,0,0,0,0,0,0,0,0,0,0,0,0,0,0,0,0,0,0
0,0,0,0,0,0,0,0,0,0,0,0,0,0,0,0,0,0,0,0,0
0,0,0,0,0,0,0,0,0,0,0,0,0,0,0,0,0,0,0,0,0
0,0,0,0,0,0,0,0,0,0,76,0,0,0,0,0,0,0,0,0,0
0,0,0,0,0,0,0,0,0,3,3,3,0,0,0,0,0,0,0,0,0
0,0,0,0,0,0,0,0,76,3,22,3,76,0,0,0,0,0,0,0,0
0,0,0,0,0,0,0,0,0,3,3,3,0,0,0,0,0,0,0,0,0
0,0,0,0,0,0,0,0,0,0,76,0,0,0,0,0,0,0,0,0,0
0,0,0,0,0,0,0,0,0,0,0,0,0,0,0,0,0,0,0,0,0
0,0,0,0,0,0,0,0,0,0,0,0,0,0,0,0,0,0,0,0,0
0,0,0,0,0,0,0,0,0,0,0,0,0,0,0,0,0,0,0,0,0
0,0,0,0,0,0,0,0,0,0,0,0,0,0,0,0,0,0,0,0,0
0,0,0,0,0,0,0,0,0,0,0,0,0,0,0,0,0,0,0,0,0
0,0,0,0,0,0,0,0,0,0,0,0,0,0,0,0,0,0,0,0,0
0,0,0,0,0,0,0,0,0,0,0,0,0,0,0,0,0,0,0,0,0
0,0,0,0,0,0,0,0,0,0,0,0,0,0,0,0,0,0,0,0,0
endlayer

layer
0,0,0,0,0,0,0,0,0,0,0,0,0,0,0,0,0,0,0,0,0
0,0,0,0,0,0,0,0,0,0,0,0,0,0,0,0,0,0,0,0,0
0,0,0,0,0,0,0,0,0,0,0,0,0,0,0,0,0,0,0,0,0
0,0,0,0,0,0,0,0,0,0,0,0,0,0,0,0,0,0,0,0,0
0,0,0,0,0,0,0,0,0,0,0,0,0,0,0,0,0,0,0,0,0
0,0,0,0,0,0,0,0,0,0,0,0,0,0,0,0,0,0,0,0,0
0,0,0,0,0,0,0,0,0,0,0,0,0,0,0,0,0,0,0,0,0
0,0,0,0,0,0,0,0,0,0,0,0,0,0,0,0,0,0,0,0,0
0,0,0,0,0,0,0,0,0,0,0,0,0,0,0,0,0,0,0,0,0
0,0,0,0,0,0,0,0,0,76,3,76,0,0,0,0,0,0,0,0,0
0,0,0,0,0,0,0,0,0,3,22,3,0,0,0,0,0,0,0,0,0
0,0,0,0,0,0,0,0,0,76,3,76,0,0,0,0,0,0,0,0,0
0,0,0,0,0,0,0,0,0,0,0,0,0,0,0,0,0,0,0,0,0
0,0,0,0,0,0,0,0,0,0,0,0,0,0,0,0,0,0,0,0,0
0,0,0,0,0,0,0,0,0,0,0,0,0,0,0,0,0,0,0,0,0
0,0,0,0,0,0,0,0,0,0,0,0,0,0,0,0,0,0,0,0,0
0,0,0,0,0,0,0,0,0,0,0,0,0,0,0,0,0,0,0,0,0
0,0,0,0,0,0,0,0,0,0,0,0,0,0,0,0,0,0,0,0,0
0,0,0,0,0,0,0,0,0,0,0,0,0,0,0,0,0,0,0,0,0
0,0,0,0,0,0,0,0,0,0,0,0,0,0,0,0,0,0,0,0,0
0,0,0,0,0,0,0,0,0,0,0,0,0,0,0,0,0,0,0,0,0
endlayer

layer
0,0,0,0,0,0,0,0,0,0,0,0,0,0,0,0,0,0,0,0,0
0,0,0,0,0,0,0,0,0,0,0,0,0,0,0,0,0,0,0,0,0
0,0,0,0,0,0,0,0,0,0,0,0,0,0,0,0,0,0,0,0,0
0,0,0,0,0,0,0,0,0,0,0,0,0,0,0,0,0,0,0,0,0
0,0,0,0,0,0,0,0,0,0,0,0,0,0,0,0,0,0,0,0,0
0,0,0,0,0,0,0,0,0,0,0,0,0,0,0,0,0,0,0,0,0
0,0,0,0,0,0,0,0,0,0,0,0,0,0,0,0,0,0,0,0,0
0,0,0,0,0,0,0,0,0,0,0,0,0,0,0,0,0,0,0,0,0
0,0,0,0,0,0,0,0,0,0,0,0,0,0,0,0,0,0,0,0,0
0,0,0,0,0,0,0,0,0,0,3,0,0,0,0,0,0,0,0,0,0
0,0,0,0,0,0,0,0,0,3,36,3,0,0,0,0,0,0,0,0,0
0,0,0,0,0,0,0,0,0,0,3,0,0,0,0,0,0,0,0,0,0
0,0,0,0,0,0,0,0,0,0,0,0,0,0,0,0,0,0,0,0,0
0,0,0,0,0,0,0,0,0,0,0,0,0,0,0,0,0,0,0,0,0
0,0,0,0,0,0,0,0,0,0,0,0,0,0,0,0,0,0,0,0,0
0,0,0,0,0,0,0,0,0,0,0,0,0,0,0,0,0,0,0,0,0
0,0,0,0,0,0,0,0,0,0,0,0,0,0,0,0,0,0,0,0,0
0,0,0,0,0,0,0,0,0,0,0,0,0,0,0,0,0,0,0,0,0
0,0,0,0,0,0,0,0,0,0,0,0,0,0,0,0,0,0,0,0,0
0,0,0,0,0,0,0,0,0,0,0,0,0,0,0,0,0,0,0,0,0
0,0,0,0,0,0,0,0,0,0,0,0,0,0,0,0,0,0,0,0,0
endlayer

layer
0,0,0,0,0,0,0,0,0,0,0,0,0,0,0,0,0,0,0,0,0
0,0,0,0,0,0,0,0,0,0,0,0,0,0,0,0,0,0,0,0,0
0,0,0,0,0,0,0,0,0,0,0,0,0,0,0,0,0,0,0,0,0
0,0,0,0,0,0,0,0,0,0,0,0,0,0,0,0,0,0,0,0,0
0,0,0,0,0,0,0,0,0,0,0,0,0,0,0,0,0,0,0,0,0
0,0,0,0,0,0,0,0,0,0,0,0,0,0,0,0,0,0,0,0,0
0,0,0,0,0,0,0,0,0,0,0,0,0,0,0,0,0,0,0,0,0
0,0,0,0,0,0,0,0,0,0,0,0,0,0,0,0,0,0,0,0,0
0,0,0,0,0,0,0,0,0,0,0,0,0,0,0,0,0,0,0,0,0
0,0,0,0,0,0,0,0,0,0,76,0,0,0,0,0,0,0,0,0,0
0,0,0,0,0,0,0,0,0,76,3,76,0,0,0,0,0,0,0,0,0
0,0,0,0,0,0,0,0,0,0,76,0,0,0,0,0,0,0,0,0,0
0,0,0,0,0,0,0,0,0,0,0,0,0,0,0,0,0,0,0,0,0
0,0,0,0,0,0,0,0,0,0,0,0,0,0,0,0,0,0,0,0,0
0,0,0,0,0,0,0,0,0,0,0,0,0,0,0,0,0,0,0,0,0
0,0,0,0,0,0,0,0,0,0,0,0,0,0,0,0,0,0,0,0,0
0,0,0,0,0,0,0,0,0,0,0,0,0,0,0,0,0,0,0,0,0
0,0,0,0,0,0,0,0,0,0,0,0,0,0,0,0,0,0,0,0,0
0,0,0,0,0,0,0,0,0,0,0,0,0,0,0,0,0,0,0,0,0
0,0,0,0,0,0,0,0,0,0,0,0,0,0,0,0,0,0,0,0,0
0,0,0,0,0,0,0,0,0,0,0,0,0,0,0,0,0,0,0,0,0
endlayer

layer
0,0,0,0,0,0,0,0,0,0,0,0,0,0,0,0,0,0,0,0,0
0,0,0,0,0,0,0,0,0,0,0,0,0,0,0,0,0,0,0,0,0
0,0,0,0,0,0,0,0,0,0,0,0,0,0,0,0,0,0,0,0,0
0,0,0,0,0,0,0,0,0,0,0,0,0,0,0,0,0,0,0,0,0
0,0,0,0,0,0,0,0,0,0,0,0,0,0,0,0,0,0,0,0,0
0,0,0,0,0,0,0,0,0,0,0,0,0,0,0,0,0,0,0,0,0
0,0,0,0,0,0,0,0,0,0,0,0,0,0,0,0,0,0,0,0,0
0,0,0,0,0,0,0,0,0,0,0,0,0,0,0,0,0,0,0,0,0
0,0,0,0,0,0,0,0,0,0,0,0,0,0,0,0,0,0,0,0,0
0,0,0,0,0,0,0,0,0,0,0,0,0,0,0,0,0,0,0,0,0
0,0,0,0,0,0,0,0,0,0,3,0,0,0,0,0,0,0,0,0,0
0,0,0,0,0,0,0,0,0,0,0,0,0,0,0,0,0,0,0,0,0
0,0,0,0,0,0,0,0,0,0,0,0,0,0,0,0,0,0,0,0,0
0,0,0,0,0,0,0,0,0,0,0,0,0,0,0,0,0,0,0,0,0
0,0,0,0,0,0,0,0,0,0,0,0,0,0,0,0,0,0,0,0,0
0,0,0,0,0,0,0,0,0,0,0,0,0,0,0,0,0,0,0,0,0
0,0,0,0,0,0,0,0,0,0,0,0,0,0,0,0,0,0,0,0,0
0,0,0,0,0,0,0,0,0,0,0,0,0,0,0,0,0,0,0,0,0
0,0,0,0,0,0,0,0,0,0,0,0,0,0,0,0,0,0,0,0,0
0,0,0,0,0,0,0,0,0,0,0,0,0,0,0,0,0,0,0,0,0
0,0,0,0,0,0,0,0,0,0,0,0,0,0,0,0,0,0,0,0,0
endlayer

layer
0,0,0,0,0,0,0,0,0,0,0,0,0,0,0,0,0,0,0,0,0
0,0,0,0,0,0,0,0,0,0,0,0,0,0,0,0,0,0,0,0,0
0,0,0,0,0,0,0,0,0,0,0,0,0,0,0,0,0,0,0,0,0
0,0,0,0,0,0,0,0,0,0,0,0,0,0,0,0,0,0,0,0,0
0,0,0,0,0,0,0,0,0,0,0,0,0,0,0,0,0,0,0,0,0
0,0,0,0,0,0,0,0,0,0,0,0,0,0,0,0,0,0,0,0,0
0,0,0,0,0,0,0,0,0,0,0,0,0,0,0,0,0,0,0,0,0
0,0,0,0,0,0,0,0,0,0,0,0,0,0,0,0,0,0,0,0,0
0,0,0,0,0,0,0,0,0,0,0,0,0,0,0,0,0,0,0,0,0
0,0,0,0,0,0,0,0,0,0,0,0,0,0,0,0,0,0,0,0,0
0,0,0,0,0,0,0,0,0,0,3,0,0,0,0,0,0,0,0,0,0
0,0,0,0,0,0,0,0,0,0,0,0,0,0,0,0,0,0,0,0,0
0,0,0,0,0,0,0,0,0,0,0,0,0,0,0,0,0,0,0,0,0
0,0,0,0,0,0,0,0,0,0,0,0,0,0,0,0,0,0,0,0,0
0,0,0,0,0,0,0,0,0,0,0,0,0,0,0,0,0,0,0,0,0
0,0,0,0,0,0,0,0,0,0,0,0,0,0,0,0,0,0,0,0,0
0,0,0,0,0,0,0,0,0,0,0,0,0,0,0,0,0,0,0,0,0
0,0,0,0,0,0,0,0,0,0,0,0,0,0,0,0,0,0,0,0,0
0,0,0,0,0,0,0,0,0,0,0,0,0,0,0,0,0,0,0,0,0
0,0,0,0,0,0,0,0,0,0,0,0,0,0,0,0,0,0,0,0,0
0,0,0,0,0,0,0,0,0,0,0,0,0,0,0,0,0,0,0,0,0
endlayer

layer
0,0,0,0,0,0,0,0,0,0,0,0,0,0,0,0,0,0,0,0,0
0,0,0,0,0,0,0,0,0,0,0,0,0,0,0,0,0,0,0,0,0
0,0,0,0,0,0,0,0,0,0,0,0,0,0,0,0,0,0,0,0,0
0,0,0,0,0,0,0,0,0,0,0,0,0,0,0,0,0,0,0,0,0
0,0,0,0,0,0,0,0,0,0,0,0,0,0,0,0,0,0,0,0,0
0,0,0,0,0,0,0,0,0,0,0,0,0,0,0,0,0,0,0,0,0
0,0,0,0,0,0,0,0,0,0,0,0,0,0,0,0,0,0,0,0,0
0,0,0,0,0,0,0,0,0,0,0,0,0,0,0,0,0,0,0,0,0
0,0,0,0,0,0,0,0,0,0,0,0,0,0,0,0,0,0,0,0,0
0,0,0,0,0,0,0,0,0,0,0,0,0,0,0,0,0,0,0,0,0
0,0,0,0,0,0,0,0,0,0,3,0,0,0,0,0,0,0,0,0,0
0,0,0,0,0,0,0,0,0,0,0,0,0,0,0,0,0,0,0,0,0
0,0,0,0,0,0,0,0,0,0,0,0,0,0,0,0,0,0,0,0,0
0,0,0,0,0,0,0,0,0,0,0,0,0,0,0,0,0,0,0,0,0
0,0,0,0,0,0,0,0,0,0,0,0,0,0,0,0,0,0,0,0,0
0,0,0,0,0,0,0,0,0,0,0,0,0,0,0,0,0,0,0,0,0
0,0,0,0,0,0,0,0,0,0,0,0,0,0,0,0,0,0,0,0,0
0,0,0,0,0,0,0,0,0,0,0,0,0,0,0,0,0,0,0,0,0
0,0,0,0,0,0,0,0,0,0,0,0,0,0,0,0,0,0,0,0,0
0,0,0,0,0,0,0,0,0,0,0,0,0,0,0,0,0,0,0,0,0
0,0,0,0,0,0,0,0,0,0,0,0,0,0,0,0,0,0,0,0,0
endlayer

layer
0,0,0,0,0,0,0,0,0,0,0,0,0,0,0,0,0,0,0,0,0
0,0,0,0,0,0,0,0,0,0,0,0,0,0,0,0,0,0,0,0,0
0,0,0,0,0,0,0,0,0,0,0,0,0,0,0,0,0,0,0,0,0
0,0,0,0,0,0,0,0,0,0,0,0,0,0,0,0,0,0,0,0,0
0,0,0,0,0,0,0,0,0,0,0,0,0,0,0,0,0,0,0,0,0
0,0,0,0,0,0,0,0,0,0,0,0,0,0,0,0,0,0,0,0,0
0,0,0,0,0,0,0,0,0,0,0,0,0,0,0,0,0,0,0,0,0
0,0,0,0,0,0,0,0,0,0,0,0,0,0,0,0,0,0,0,0,0
0,0,0,0,0,0,0,0,0,0,0,0,0,0,0,0,0,0,0,0,0
0,0,0,0,0,0,0,0,0,0,0,0,0,0,0,0,0,0,0,0,0
0,0,0,0,0,0,0,0,0,0,36,0,0,0,0,0,0,0,0,0,0
0,0,0,0,0,0,0,0,0,0,0,0,0,0,0,0,0,0,0,0,0
0,0,0,0,0,0,0,0,0,0,0,0,0,0,0,0,0,0,0,0,0
0,0,0,0,0,0,0,0,0,0,0,0,0,0,0,0,0,0,0,0,0
0,0,0,0,0,0,0,0,0,0,0,0,0,0,0,0,0,0,0,0,0
0,0,0,0,0,0,0,0,0,0,0,0,0,0,0,0,0,0,0,0,0
0,0,0,0,0,0,0,0,0,0,0,0,0,0,0,0,0,0,0,0,0
0,0,0,0,0,0,0,0,0,0,0,0,0,0,0,0,0,0,0,0,0
0,0,0,0,0,0,0,0,0,0,0,0,0,0,0,0,0,0,0,0,0
0,0,0,0,0,0,0,0,0,0,0,0,0,0,0,0,0,0,0,0,0
0,0,0,0,0,0,0,0,0,0,0,0,0,0,0,0,0,0,0,0,0
endlayer

layer
0,0,0,0,0,0,0,0,0,0,0,0,0,0,0,0,0,0,0,0,0
0,0,0,0,0,0,0,0,0,0,0,0,0,0,0,0,0,0,0,0,0
0,0,0,0,0,0,0,0,0,0,0,0,0,0,0,0,0,0,0,0,0
0,0,0,0,0,0,0,0,0,0,0,0,0,0,0,0,0,0,0,0,0
0,0,0,0,0,0,0,0,0,0,0,0,0,0,0,0,0,0,0,0,0
0,0,0,0,0,0,0,0,0,0,0,0,0,0,0,0,0,0,0,0,0
0,0,0,0,0,0,0,0,0,0,0,0,0,0,0,0,0,0,0,0,0
0,0,0,0,0,0,0,0,0,0,0,0,0,0,0,0,0,0,0,0,0
0,0,0,0,0,0,0,0,0,0,0,0,0,0,0,0,0,0,0,0,0
0,0,0,0,0,0,0,0,0,0,0,0,0,0,0,0,0,0,0,0,0
0,0,0,0,0,0,0,0,0,0,45,0,0,0,0,0,0,0,0,0,0
0,0,0,0,0,0,0,0,0,0,0,0,0,0,0,0,0,0,0,0,0
0,0,0,0,0,0,0,0,0,0,0,0,0,0,0,0,0,0,0,0,0
0,0,0,0,0,0,0,0,0,0,0,0,0,0,0,0,0,0,0,0,0
0,0,0,0,0,0,0,0,0,0,0,0,0,0,0,0,0,0,0,0,0
0,0,0,0,0,0,0,0,0,0,0,0,0,0,0,0,0,0,0,0,0
0,0,0,0,0,0,0,0,0,0,0,0,0,0,0,0,0,0,0,0,0
0,0,0,0,0,0,0,0,0,0,0,0,0,0,0,0,0,0,0,0,0
0,0,0,0,0,0,0,0,0,0,0,0,0,0,0,0,0,0,0,0,0
0,0,0,0,0,0,0,0,0,0,0,0,0,0,0,0,0,0,0,0,0
0,0,0,0,0,0,0,0,0,0,0,0,0,0,0,0,0,0,0,0,0
endlayer

