# Wizard_Tower_2 (3 May 2014)
# Updated to 1.7.10, 8 Oct 2014
# Created by Ruins mod version 12.3 Ingame Parser
# authoring Player: Jordan_Greywolf
# Updated to MC 1.8: 28 Feb 2016
# Updated to MC 1.9: 30 Apr 2016
# Updated to MC 1.11: 13 Jan 2017
# Updated to MC 1.12: 8 Jul 2017
# Updated to MC 1.12.1: 10 Sep 2017

# Last Updated: 2 Jul 2018

biomesToSpawnIn=alpine,alps,alps forest,alps_foothills,autumn hills,autumnal_woods,bayou,birch forest,birch_forest,dark forest,dead_forest,deserthills,dreadlands,eerie,eldritch,enchanted forest,extreme hills,extreme_hills,extreme_hills_with_trees,extreme hills edge,extreme hills+,extreme hills m,extreme hills+ m,extreme jungle,forested hills,foresthills,forest_hills,green hills,highland,highlands,ice mountains,junglehills,jungle_hills,magical forest,mega spruce taiga,mega taiga,mountain ridge,mountain taiga,mountainous desert,mystic grove,mystic_grove,mystic woods,mystic_woods,oak savannah,oak_savannah,ominous woods,ominous_woods,origin_island,roofed forest,roofed forest m,roofed_forest,seasonal_forest,sludgepit,smaller_extreme_hills,steppe,stone beach,swampland,taiga,taiga hills,tainted land,thick ominous woods,wetland,wetlands,wonderous woods,woodland,woodlands

uniqueMinDistance=2000

weight=1
embed_into_distance=14

unacceptable_target_blocks=lava,flowing_lava,cloud,Natura:Cloud,red_mushroom_block,brown_mushroom_block,slime_congealed,slime_dirt,slime_grass,command_block,planks,planks2,concrete,cobblestone,stonebrick,brick_block,glass,torch,oak_stairs,stone_stairs,brick_stairs,stone_brick_stairs,nether_brick_stairs,sandstone_stairs,spruce_stairs,birch_stairs,jungle_stairs,quartz_stairs,acacia_stairs,dark_oak_stairs,cobblestone_wall,stone_slab,double_stone_slab,stone_slab2,wooden_slab,double_wooden_slab,nether_brick,fence

dimensions=47,11,11
allowable_overhang=0
max_cut_in=0
cut_in_buffer=0
max_leveling=7
leveling_buffer=-1
preserve_water=0
preserve_lava=0
preserve_plants=1

# Preserve Terrain
rule1=0,100,preserveBlock

# Mossy Stone Brick, etc. (below-ground basement walls)
rule2=0,100,minecraft:stonebrick-1,minecraft:stonebrick-2,minecraft:monster_egg-2

# Planks, Spruce (floor and rooftop)
rule3=0,100,minecraft:planks-1

# Loot Chest
rule4=0,100,ChestGenHook:chests/simple_dungeon:4-5

# Cobwebs
rule5=0,100,minecraft:web-0

# Loot Chest
rule6=0,100,ChestGenHook:chests/simple_dungeon:4-3

# Spruce Stairs (roof and interior stairs)
rule7=0,100,minecraft:spruce_stairs-0

# Loot Chest
rule8=0,100,ChestGenHook:chests/simple_dungeon:4-2

# Spruce Stairs (roof and interior stairs)
rule9=0,100,minecraft:spruce_stairs-5

# Regular Monster Spawner
rule10=0,100,MobSpawner:Cave_Spider,MobSpawner:Zombie

# Loot Chest
rule11=0,100,ChestGenHook:chests/simple_dungeon:4-4

# Spruce Stairs
rule12=0,100,minecraft:spruce_stairs-3
rule13=0,100,minecraft:spruce_stairs-2

# Stone Brick (aboveground wall)
rule14=0,100,minecraft:stonebrick-0,minecraft:stonebrick-2,minecraft:monster_egg-2

# Front Door
rule15=1,100,minecraft:spruce_door-2

# Randomized Skull
rule16=0,50,minecraft:skull,minecraft:skull-1,minecraft:skull-2,minecraft:skull-3

# Furniture
rule17=0,100,minecraft:crafting_table-0
rule18=0,100,IInventory;minecraft:lit_furnace;minecraft:coal#8#1#1-2
rule19=0,100,minecraft:cauldron-0
rule20=0,100,minecraft:oak_stairs-1
rule21=0,100,minecraft:spruce_fence-0

# Front Door
rule22=1,100,minecraft:spruce_door-8

# Stone Brick Stairs (outer sloping)
rule23=0,100,minecraft:stone_brick_stairs-0
rule24=0,100,minecraft:stone_brick_stairs-2
rule25=0,100,minecraft:stone_brick_stairs-3
rule26=0,100,minecraft:stone_pressure_plate-0
rule27=0,100,minecraft:stone_brick_stairs-1

# Stone Brick, Chiseled
rule28=0,100,minecraft:stonebrick-3

# Spruce Stairs
rule29=0,100,minecraft:spruce_stairs-4
rule30=0,100,minecraft:spruce_stairs-1

# Redstone Lamp (used for "darkened windows")
rule31=0,100,minecraft:redstone_lamp

# Stone Slab, Brick
rule32=0,100,minecraft:stone_slab-5

# Stone Brick Stairs
rule33=0,100,minecraft:stone_brick_stairs-4
rule34=0,100,minecraft:stone_brick_stairs-6
rule35=0,100,minecraft:stone_brick_stairs-7
rule36=0,100,minecraft:stone_brick_stairs-5

# Quartz Block, Pillar (stand)
rule37=0,100,minecraft:quartz_block-2

# Wooden Slab, Spruce
rule38=0,100,minecraft:wooden_slab-1

# Iron Bars (for window, rooftop)
rule39=0,100,minecraft:iron_bars-0

# Bookshelf
rule40=0,100,minecraft:bookshelf-0

# Boss Witch
rule41=0,100,CommandBlock:RUINSTRIGGER /summon witch ~0 ~0 ~0 {AbsorptionAmount:10,HandItems:[{},{Count:1,id:diamond_shovel,tag:{display:{Name:"Witch Broom",Lore:["Sweep away your foes!"]},ench:[{id:18,lvl:5},{id:20,lvl:2},{id:19,lvl:2},{id:16,lvl:5},{id:33,lvl:1},{id:34,lvl:5}]}}],CustomName:"Elder Witch",Health:100.0f,Attributes:[{Name:generic.knockbackResistance,Base:1}],HandDropChances:[1.0F,1.0F],ActiveEffects:[{Id:12,Amplifier:1,Duration:999999},{Id:3,Amplifier:1,Duration:999999},{Id:21,Amplifier:1,Duration:999999},{Id:8,Amplifier:1,Duration:999999},{Id:10,Amplifier:1,Duration:999999},{Id:11,Amplifier:1,Duration:999999},{Id:1,Amplifier:1,Duration:999999},{Id:5,Amplifier:1,Duration:999999},{Id:13,Amplifier:1,Duration:999999}],PersistenceRequired:1}:@

layer
1,1,1,1,2,2,2,1,1,1,1
1,1,2,2,3,3,3,2,2,1,1
1,2,3,3,3,3,3,3,3,2,1
1,2,3,3,3,3,3,3,3,2,1
2,3,3,3,3,3,3,3,3,3,2
2,2,2,3,2,3,3,3,2,2,2
2,3,3,3,2,3,3,3,3,3,2
1,2,3,3,3,3,3,3,3,2,1
1,2,3,3,2,3,3,3,3,2,1
1,1,2,2,2,3,3,2,2,1,1
1,1,1,1,2,2,2,1,1,1,1
endlayer

layer
1,1,1,1,2,2,2,1,1,1,1
1,1,2,2,2,4,2,2,2,1,1
1,2,5,5,2,5,2,0,0,2,1
1,2,0,0,5,0,0,0,0,2,1
2,8,5,0,2,7,2,0,0,6,2
2,2,2,5,2,9,2,0,2,2,2
2,10,5,0,2,4,2,0,5,10,2
1,2,5,0,5,5,5,0,0,2,1
1,2,0,0,2,5,2,0,0,2,1
1,1,2,2,2,11,2,2,2,1,1
1,1,1,1,2,2,2,1,1,1,1
endlayer

layer
1,1,1,1,2,2,2,1,1,1,1
1,1,2,2,2,5,2,2,2,1,1
1,2,5,5,2,0,2,5,5,2,1
1,2,0,0,5,0,5,0,0,2,1
2,5,5,0,2,0,2,0,0,5,2
2,2,2,5,2,7,2,5,2,2,2
2,5,5,0,2,9,2,0,0,5,2
1,2,0,0,5,0,5,0,0,2,1
1,2,5,5,2,0,2,5,5,2,1
1,1,2,2,2,5,2,2,2,1,1
1,1,1,1,2,2,2,1,1,1,1
endlayer

layer
1,1,1,1,2,2,2,1,1,1,1
1,1,2,2,3,3,3,2,2,1,1
1,2,3,3,3,3,3,3,3,2,1
1,2,3,3,3,5,3,3,3,2,1
2,3,3,3,2,0,2,3,3,3,2
2,2,2,3,2,0,2,3,2,2,2
2,3,3,3,2,7,2,3,3,3,2
1,2,3,3,2,9,2,3,3,2,1
1,2,3,3,2,5,2,3,3,2,1
1,1,2,2,2,5,2,2,2,1,1
1,1,1,1,2,2,2,1,1,1,1
endlayer

layer
1,1,1,1,2,2,2,1,1,1,1
1,1,2,2,4,0,4,2,2,1,1
1,2,0,0,0,0,0,0,0,2,1
1,2,0,0,0,2,0,0,0,2,1
2,10,0,0,2,0,2,0,0,10,2
2,2,2,0,2,0,2,0,2,2,2
2,8,0,0,0,0,0,0,0,6,2
1,2,0,0,2,7,2,0,0,2,1
1,2,0,0,2,9,2,0,0,2,1
1,1,2,2,2,5,2,2,2,1,1
1,1,1,1,2,2,2,1,1,1,1
endlayer

layer
1,1,1,1,2,2,2,1,1,1,1
1,1,2,2,0,0,0,2,2,1,1
1,2,5,5,0,0,0,5,5,2,1
1,2,5,0,0,2,0,0,5,2,1
2,5,0,0,2,5,2,0,0,5,2
2,2,2,0,2,0,2,0,2,2,2
2,5,0,0,0,0,0,0,0,5,2
1,2,5,0,2,0,2,0,5,2,1
1,2,5,5,2,7,2,5,5,2,1
1,1,2,2,2,9,2,2,2,1,1
1,1,1,1,2,2,2,1,1,1,1
endlayer

layer
1,1,1,1,2,2,2,1,1,1,1
1,1,2,2,3,3,3,2,2,1,1
1,2,3,3,3,3,3,3,3,2,1
1,2,3,3,3,3,3,3,3,2,1
2,3,3,3,3,3,3,3,3,3,2
2,3,3,3,3,9,3,3,3,3,2
2,3,3,3,3,0,3,3,3,3,2
1,2,3,3,3,0,3,3,3,2,1
1,2,3,3,3,0,3,3,3,2,1
1,1,2,2,3,7,3,2,2,1,1
1,1,1,1,2,2,2,1,1,1,1
endlayer

layer
1,1,1,1,2,2,2,1,1,1,1
1,1,2,2,0,0,0,2,2,1,1
1,2,0,0,0,0,0,0,0,2,1
1,2,0,0,0,7,0,0,0,2,1
2,8,0,0,0,9,0,0,0,6,2
2,10,5,0,0,10,0,0,5,10,2
2,8,0,0,0,0,0,0,0,6,2
1,2,0,0,0,0,0,0,0,2,1
1,2,0,0,0,0,0,0,0,2,1
1,1,2,2,0,0,0,2,2,1,1
1,1,1,1,2,2,2,1,1,1,1
endlayer

layer
1,1,1,1,2,2,2,1,1,1,1
1,1,2,2,0,0,0,2,2,1,1
1,2,0,0,0,0,0,0,0,2,1
1,2,0,0,0,0,0,0,0,2,1
2,0,0,0,0,7,0,0,0,0,2
2,5,0,0,0,9,0,0,0,5,2
2,0,0,0,0,5,0,0,0,0,2
1,2,0,0,0,0,0,0,0,2,1
1,2,0,0,0,0,0,0,0,2,1
1,1,2,2,0,0,0,2,2,1,1
1,1,1,1,2,2,2,1,1,1,1
endlayer

layer
1,1,1,1,2,2,2,1,1,1,1
1,1,2,2,0,0,0,2,2,1,1
1,2,0,0,0,0,0,0,0,2,1
1,2,0,0,0,0,0,0,0,2,1
2,0,0,0,0,0,0,0,0,0,2
2,0,0,0,0,7,0,0,0,0,2
2,0,0,0,0,9,0,0,0,0,2
1,2,0,0,0,5,0,0,0,2,1
1,2,0,0,0,0,0,0,0,2,1
1,1,2,2,0,0,0,2,2,1,1
1,1,1,1,2,2,2,1,1,1,1
endlayer

layer
1,1,1,1,2,2,2,1,1,1,1
1,1,2,2,5,0,5,2,2,1,1
1,2,0,0,0,0,0,0,0,2,1
1,2,0,0,0,0,0,0,0,2,1
2,0,0,0,0,0,0,0,0,0,2
2,0,0,0,0,0,0,0,0,0,2
2,0,0,0,0,7,0,0,0,0,2
1,2,0,0,0,9,0,0,0,2,1
1,2,0,0,0,0,0,0,0,2,1
1,1,2,2,0,0,0,2,2,1,1
1,1,1,1,2,2,2,1,1,1,1
endlayer

layer
1,1,1,1,2,2,2,1,1,1,1
1,1,2,2,5,5,5,2,2,1,1
1,2,5,5,0,0,0,5,5,2,1
1,2,5,0,0,0,0,0,5,2,1
2,5,0,0,0,0,0,0,0,5,2
2,5,0,0,0,0,0,0,0,5,2
2,5,0,0,0,0,0,0,0,5,2
1,2,5,0,0,7,0,0,5,2,1
1,2,5,5,0,9,0,5,5,2,1
1,1,2,2,5,5,5,2,2,1,1
1,1,1,1,2,2,2,1,1,1,1
endlayer

layer
1,1,1,1,2,2,2,1,1,1,1
1,1,2,2,3,3,3,2,2,1,1
1,2,3,3,3,3,3,3,3,2,1
1,2,3,3,3,3,3,3,3,2,1
2,3,3,3,3,3,3,3,3,3,2
2,3,3,3,3,0,3,3,3,3,2
2,3,3,3,3,0,3,3,3,3,2
1,2,3,3,3,0,3,3,3,2,1
1,2,3,3,3,7,3,3,3,2,1
1,1,2,2,3,3,3,2,2,1,1
1,1,1,1,2,2,2,1,1,1,1
endlayer

layer
1,1,1,1,2,2,2,1,1,1,1
1,1,2,2,3,3,3,2,2,1,1
1,2,3,3,3,3,3,3,3,2,1
1,2,3,3,3,3,3,3,3,2,1
2,3,3,3,3,3,3,3,3,3,2
2,3,3,3,3,3,3,3,3,3,2
2,3,3,3,3,5,3,3,3,3,2
1,2,3,3,3,0,3,3,3,2,1
1,2,3,3,13,5,12,3,3,2,1
1,1,2,2,3,3,3,2,2,1,1
1,1,1,1,2,2,2,1,1,1,1
endlayer

layer
1,1,1,0,14,15,14,0,1,1,1
1,1,14,14,16,0,16,14,14,1,1
1,14,16,0,0,0,0,0,16,14,1
0,14,0,0,0,0,0,0,0,14,0
14,17,0,0,0,0,0,0,0,0,14
14,18,0,0,0,7,0,0,0,0,14
14,19,0,0,0,9,0,0,0,0,14
0,14,20,0,0,0,0,0,20,14,0
1,14,21,0,0,5,0,0,21,14,1
1,1,14,14,11,10,11,14,14,1,1
1,1,1,0,14,14,14,0,1,1,1
endlayer

layer
1,1,0,0,14,22,14,0,0,1,1
1,0,23,14,0,0,0,14,23,0,1
0,25,5,0,0,0,0,0,5,24,0
0,14,0,0,0,0,0,0,0,14,0
14,0,0,0,0,0,0,0,0,5,14
14,0,0,0,0,0,0,0,0,0,14
14,0,0,0,0,7,0,0,0,5,14
0,14,0,0,0,9,0,0,0,14,0
0,25,26,0,0,0,0,0,26,24,0
1,0,27,14,0,5,0,14,27,0,1
1,1,0,0,14,14,14,0,0,1,1
endlayer

layer
1,0,0,0,25,28,24,0,0,0,1
0,0,0,14,14,5,14,14,0,0,0
0,0,14,5,0,0,0,5,14,0,0
0,14,5,0,0,0,0,0,5,14,0
23,14,0,0,0,0,0,0,0,14,23
14,5,0,0,0,0,0,0,0,5,14
27,14,0,0,0,0,0,0,0,14,27
0,14,5,0,0,7,0,0,5,14,0
0,0,14,5,29,3,29,5,14,0,0
0,0,0,14,14,3,14,14,0,0,0
1,0,0,0,25,14,24,0,0,0,1
endlayer

layer
0,0,0,0,0,23,0,0,0,0,0
0,0,0,14,14,14,14,14,0,0,0
0,0,14,5,5,5,5,5,14,0,0
0,14,5,0,0,0,0,0,5,14,0
0,14,5,0,0,0,0,0,5,14,0
25,14,5,0,0,0,0,0,5,14,24
0,14,5,0,0,0,0,0,5,14,0
0,14,5,0,29,0,29,0,5,14,0
0,0,14,29,13,5,12,29,14,0,0
0,0,0,14,14,14,14,14,0,0,0
0,0,0,0,0,27,0,0,0,0,0
endlayer

layer
0,0,0,0,0,0,0,0,0,0,0
0,0,0,25,14,14,14,24,0,0,0
0,0,14,14,3,3,3,14,14,0,0
0,23,14,3,3,3,3,3,14,23,0
0,14,3,3,3,3,3,3,3,14,0
0,14,3,3,3,3,3,3,3,14,0
0,14,3,3,3,5,3,3,3,14,0
0,27,14,3,30,0,30,3,14,27,0
0,0,14,14,0,0,0,14,14,0,0
0,0,0,25,14,14,14,24,0,0,0
0,0,0,0,0,0,0,0,0,0,0
endlayer

layer
0,0,0,0,0,0,0,0,0,0,0
0,0,0,0,14,31,14,0,0,0,0
0,0,14,14,16,0,16,14,14,0,0
0,0,14,16,0,0,0,16,14,0,0
0,14,0,0,0,7,0,0,0,14,0
0,31,10,0,0,3,0,0,10,31,0
0,14,0,0,0,9,0,0,0,14,0
0,0,14,0,0,0,0,0,14,0,0
0,0,14,14,0,0,0,14,14,0,0
0,0,0,0,14,31,14,0,0,0,0
0,0,0,0,0,0,0,0,0,0,0
endlayer

layer
0,0,0,0,0,0,0,0,0,0,0
0,0,0,0,14,31,14,0,0,0,0
0,0,32,14,0,0,0,14,32,0,0
0,0,14,5,0,0,0,0,14,0,0
0,14,0,0,0,0,0,0,0,14,0
0,31,0,0,0,7,0,0,0,31,0
0,14,0,0,0,3,0,0,0,14,0
0,0,14,5,0,9,0,0,14,0,0
0,0,32,14,0,0,0,14,32,0,0
0,0,0,0,14,31,14,0,0,0,0
0,0,0,0,0,0,0,0,0,0,0
endlayer

layer
0,0,0,0,0,0,0,0,0,0,0
0,0,0,0,23,14,23,0,0,0,0
0,0,0,14,0,0,0,14,0,0,0
0,0,14,14,0,0,0,14,14,0,0
0,25,0,0,0,0,0,0,5,24,0
0,14,0,0,0,0,0,0,0,14,0
0,25,0,0,0,7,0,0,5,24,0
0,0,14,14,0,3,0,14,14,0,0
0,0,0,14,5,9,5,14,0,0,0
0,0,0,0,27,14,27,0,0,0,0
0,0,0,0,0,0,0,0,0,0,0
endlayer

layer
0,0,0,0,0,0,0,0,0,0,0
0,0,0,0,0,14,0,0,0,0,0
0,0,0,25,14,5,14,24,0,0,0
0,0,23,14,5,0,5,14,23,0,0
0,0,14,5,0,0,0,5,14,0,0
0,14,5,0,0,0,0,0,5,14,0
0,0,14,5,0,0,0,5,14,0,0
0,0,27,14,29,7,29,14,27,0,0
0,0,0,25,14,3,14,24,0,0,0
0,0,0,0,0,14,0,0,0,0,0
0,0,0,0,0,0,0,0,0,0,0
endlayer

layer
0,0,0,0,0,0,0,0,0,0,0
0,0,0,0,0,14,0,0,0,0,0
0,0,0,0,14,3,14,0,0,0,0
0,0,0,14,3,3,3,14,0,0,0
0,0,14,3,3,9,3,3,14,0,0
0,14,3,3,3,5,3,3,3,14,0
0,0,14,3,3,5,3,3,14,0,0
0,0,0,14,13,0,12,14,0,0,0
0,0,0,0,14,14,14,0,0,0,0
0,0,0,0,0,14,0,0,0,0,0
0,0,0,0,0,0,0,0,0,0,0
endlayer

layer
0,0,0,0,0,0,0,0,0,0,0
0,0,0,0,0,23,0,0,0,0,0
0,0,0,0,14,14,14,0,0,0,0
0,0,0,14,16,0,16,14,0,0,0
0,0,14,16,0,7,0,16,14,0,0
0,25,14,10,0,9,0,10,14,24,0
0,0,14,0,0,0,0,0,14,0,0
0,0,0,14,0,0,0,14,0,0,0
0,0,0,0,14,14,14,0,0,0,0
0,0,0,0,0,27,0,0,0,0,0
0,0,0,0,0,0,0,0,0,0,0
endlayer

layer
0,0,0,0,0,0,0,0,0,0,0
0,0,0,0,0,0,0,0,0,0,0
0,0,0,0,14,31,14,0,0,0,0
0,0,0,14,0,0,0,14,0,0,0
0,0,14,0,0,0,0,0,14,0,0
0,0,31,0,0,7,0,0,31,0,0
0,0,14,0,0,9,0,0,14,0,0
0,0,0,14,0,0,0,14,0,0,0
0,0,0,0,14,31,14,0,0,0,0
0,0,0,0,0,0,0,0,0,0,0
0,0,0,0,0,0,0,0,0,0,0
endlayer

layer
0,0,0,0,0,0,0,0,0,0,0
0,0,0,0,0,0,0,0,0,0,0
0,0,0,0,14,31,14,0,0,0,0
0,0,0,14,0,0,0,14,0,0,0
0,0,14,5,0,0,0,5,14,0,0
0,0,31,0,0,0,0,0,31,0,0
0,0,14,5,0,7,0,5,14,0,0
0,0,0,14,0,9,0,14,0,0,0
0,0,0,0,14,31,14,0,0,0,0
0,0,0,0,0,0,0,0,0,0,0
0,0,0,0,0,0,0,0,0,0,0
endlayer

layer
0,0,0,0,0,0,0,0,0,0,0
0,0,0,0,0,0,0,0,0,0,0
0,0,0,0,14,14,14,0,0,0,0
0,0,0,14,5,0,5,14,0,0,0
0,0,14,5,0,0,0,5,14,0,0
0,0,14,5,0,0,0,5,14,0,0
0,0,14,5,0,5,0,5,14,0,0
0,0,0,14,5,7,5,14,0,0,0
0,0,0,0,14,14,14,0,0,0,0
0,0,0,0,0,0,0,0,0,0,0
0,0,0,0,0,0,0,0,0,0,0
endlayer

layer
0,0,0,0,0,0,0,0,0,0,0
0,0,0,0,0,33,0,0,0,0,0
0,0,0,0,14,14,14,0,0,0,0
0,0,0,14,3,3,3,14,0,0,0
0,0,14,3,3,3,3,3,14,0,0
0,35,14,3,3,5,3,3,14,34,0
0,0,14,3,3,5,3,3,14,0,0
0,0,0,14,3,5,3,14,0,0,0
0,0,0,0,14,23,14,0,0,0,0
0,0,0,0,0,36,0,0,0,0,0
0,0,0,0,0,0,0,0,0,0,0
endlayer

layer
0,0,0,0,14,14,14,0,0,0,0
0,0,0,14,14,27,14,14,0,0,0
0,0,14,14,4,16,4,14,14,0,0
0,14,14,37,0,0,0,37,14,14,0
14,14,8,0,0,38,0,0,6,14,14
14,24,16,0,38,3,38,0,16,25,14
14,14,8,0,0,0,0,0,6,14,14
0,14,14,37,0,0,0,37,14,14,0
0,0,14,14,0,0,0,14,14,0,0
0,0,0,14,14,23,14,14,0,0,0
0,0,0,0,14,14,14,0,0,0,0
endlayer

layer
0,0,0,0,39,39,39,0,0,0,0
0,0,0,39,14,31,14,39,0,0,0
0,0,39,14,0,0,0,14,39,0,0
0,39,14,40,0,0,0,40,14,39,0
39,14,0,0,0,0,0,0,0,14,39
39,31,0,0,0,41,0,0,0,31,39
39,14,0,0,0,0,0,0,0,14,39
0,39,14,40,0,0,0,40,14,39,0
0,0,39,14,0,0,0,14,39,0,0
0,0,0,39,14,31,14,39,0,0,0
0,0,0,0,39,39,39,0,0,0,0
endlayer

layer
0,0,0,0,0,0,0,0,0,0,0
0,0,0,0,14,31,14,0,0,0,0
0,0,0,14,5,0,5,14,0,0,0
0,0,14,40,0,0,0,40,14,0,0
0,14,5,0,0,0,0,0,5,14,0
0,31,0,0,0,0,0,0,0,31,0
0,14,5,0,0,0,0,0,5,14,0
0,0,14,40,0,0,0,40,14,0,0
0,0,0,14,5,0,5,14,0,0,0
0,0,0,0,14,31,14,0,0,0,0
0,0,0,0,0,0,0,0,0,0,0
endlayer

layer
0,0,0,0,38,38,38,0,0,0,0
0,0,0,38,7,3,7,38,0,0,0
0,0,38,7,3,5,3,7,38,0,0
0,38,12,3,5,0,5,3,13,38,0
38,12,3,5,0,0,0,5,3,13,38
38,3,5,0,0,0,0,0,5,3,38
38,12,3,5,0,0,0,5,3,13,38
0,38,12,3,5,0,5,3,13,38,0
0,0,38,30,3,5,3,30,38,0,0
0,0,0,38,30,3,30,38,0,0,0
0,0,0,0,38,38,38,0,0,0,0
endlayer

layer
0,0,0,0,0,0,0,0,0,0,0
0,0,0,0,0,7,0,0,0,0,0
0,0,0,0,7,3,7,0,0,0,0
0,0,0,3,3,5,3,3,0,0,0
0,0,12,3,5,0,5,3,13,0,0
0,12,3,5,0,0,0,5,3,13,0
0,0,12,3,5,0,5,3,13,0,0
0,0,0,3,3,5,3,3,0,0,0
0,0,0,0,30,3,30,0,0,0,0
0,0,0,0,0,30,0,0,0,0,0
0,0,0,0,0,0,0,0,0,0,0
endlayer

layer
0,0,0,0,0,0,0,0,0,0,0
0,0,0,0,0,0,0,0,0,0,0
0,0,0,0,0,7,0,0,0,0,0
0,0,0,38,3,3,3,38,0,0,0
0,0,0,3,5,5,5,3,0,0,0
0,0,12,3,5,0,5,3,13,0,0
0,0,0,3,5,5,5,3,0,0,0
0,0,0,38,3,3,3,38,0,0,0
0,0,0,0,0,30,0,0,0,0,0
0,0,0,0,0,0,0,0,0,0,0
0,0,0,0,0,0,0,0,0,0,0
endlayer

layer
0,0,0,0,0,0,0,0,0,0,0
0,0,0,0,0,0,0,0,0,0,0
0,0,0,0,0,0,0,0,0,0,0
0,0,0,0,7,3,7,0,0,0,0
0,0,0,12,3,5,3,13,0,0,0
0,0,0,3,5,0,5,3,0,0,0
0,0,0,12,3,5,3,13,0,0,0
0,0,0,0,30,3,30,0,0,0,0
0,0,0,0,0,0,0,0,0,0,0
0,0,0,0,0,0,0,0,0,0,0
0,0,0,0,0,0,0,0,0,0,0
endlayer

layer
0,0,0,0,0,0,0,0,0,0,0
0,0,0,0,0,0,0,0,0,0,0
0,0,0,0,0,0,0,0,0,0,0
0,0,0,0,0,3,0,0,0,0,0
0,0,0,0,3,3,3,0,0,0,0
0,0,0,3,3,5,3,3,0,0,0
0,0,0,0,3,3,3,0,0,0,0
0,0,0,0,0,3,0,0,0,0,0
0,0,0,0,0,0,0,0,0,0,0
0,0,0,0,0,0,0,0,0,0,0
0,0,0,0,0,0,0,0,0,0,0
endlayer

layer
0,0,0,0,0,0,0,0,0,0,0
0,0,0,0,0,0,0,0,0,0,0
0,0,0,0,0,0,0,0,0,0,0
0,0,0,0,0,7,0,0,0,0,0
0,0,0,0,3,3,3,0,0,0,0
0,0,0,12,3,5,3,13,0,0,0
0,0,0,0,3,3,3,0,0,0,0
0,0,0,0,0,30,0,0,0,0,0
0,0,0,0,0,0,0,0,0,0,0
0,0,0,0,0,0,0,0,0,0,0
0,0,0,0,0,0,0,0,0,0,0
endlayer

layer
0,0,0,0,0,0,0,0,0,0,0
0,0,0,0,0,0,0,0,0,0,0
0,0,0,0,0,0,0,0,0,0,0
0,0,0,0,0,0,0,0,0,0,0
0,0,0,0,3,3,3,0,0,0,0
0,0,0,0,3,5,3,0,0,0,0
0,0,0,0,3,3,3,0,0,0,0
0,0,0,0,0,0,0,0,0,0,0
0,0,0,0,0,0,0,0,0,0,0
0,0,0,0,0,0,0,0,0,0,0
0,0,0,0,0,0,0,0,0,0,0
endlayer

layer
0,0,0,0,0,0,0,0,0,0,0
0,0,0,0,0,0,0,0,0,0,0
0,0,0,0,0,0,0,0,0,0,0
0,0,0,0,0,0,0,0,0,0,0
0,0,0,0,3,3,3,0,0,0,0
0,0,0,0,3,0,3,0,0,0,0
0,0,0,0,3,3,3,0,0,0,0
0,0,0,0,0,0,0,0,0,0,0
0,0,0,0,0,0,0,0,0,0,0
0,0,0,0,0,0,0,0,0,0,0
0,0,0,0,0,0,0,0,0,0,0
endlayer

layer
0,0,0,0,0,0,0,0,0,0,0
0,0,0,0,0,0,0,0,0,0,0
0,0,0,0,0,0,0,0,0,0,0
0,0,0,0,0,0,0,0,0,0,0
0,0,0,0,38,3,38,0,0,0,0
0,0,0,0,3,3,3,0,0,0,0
0,0,0,0,38,3,38,0,0,0,0
0,0,0,0,0,0,0,0,0,0,0
0,0,0,0,0,0,0,0,0,0,0
0,0,0,0,0,0,0,0,0,0,0
0,0,0,0,0,0,0,0,0,0,0
endlayer

layer
0,0,0,0,0,0,0,0,0,0,0
0,0,0,0,0,0,0,0,0,0,0
0,0,0,0,0,0,0,0,0,0,0
0,0,0,0,0,0,0,0,0,0,0
0,0,0,0,0,7,0,0,0,0,0
0,0,0,0,12,3,13,0,0,0,0
0,0,0,0,0,30,0,0,0,0,0
0,0,0,0,0,0,0,0,0,0,0
0,0,0,0,0,0,0,0,0,0,0
0,0,0,0,0,0,0,0,0,0,0
0,0,0,0,0,0,0,0,0,0,0
endlayer

layer
0,0,0,0,0,0,0,0,0,0,0
0,0,0,0,0,0,0,0,0,0,0
0,0,0,0,0,0,0,0,0,0,0
0,0,0,0,0,0,0,0,0,0,0
0,0,0,0,0,0,0,0,0,0,0
0,0,0,0,0,3,0,0,0,0,0
0,0,0,0,0,0,0,0,0,0,0
0,0,0,0,0,0,0,0,0,0,0
0,0,0,0,0,0,0,0,0,0,0
0,0,0,0,0,0,0,0,0,0,0
0,0,0,0,0,0,0,0,0,0,0
endlayer

layer
0,0,0,0,0,0,0,0,0,0,0
0,0,0,0,0,0,0,0,0,0,0
0,0,0,0,0,0,0,0,0,0,0
0,0,0,0,0,0,0,0,0,0,0
0,0,0,0,0,0,0,0,0,0,0
0,0,0,0,0,3,0,0,0,0,0
0,0,0,0,0,0,0,0,0,0,0
0,0,0,0,0,0,0,0,0,0,0
0,0,0,0,0,0,0,0,0,0,0
0,0,0,0,0,0,0,0,0,0,0
0,0,0,0,0,0,0,0,0,0,0
endlayer

layer
0,0,0,0,0,0,0,0,0,0,0
0,0,0,0,0,0,0,0,0,0,0
0,0,0,0,0,0,0,0,0,0,0
0,0,0,0,0,0,0,0,0,0,0
0,0,0,0,0,0,0,0,0,0,0
0,0,0,0,0,3,0,0,0,0,0
0,0,0,0,0,0,0,0,0,0,0
0,0,0,0,0,0,0,0,0,0,0
0,0,0,0,0,0,0,0,0,0,0
0,0,0,0,0,0,0,0,0,0,0
0,0,0,0,0,0,0,0,0,0,0
endlayer

layer
0,0,0,0,0,0,0,0,0,0,0
0,0,0,0,0,0,0,0,0,0,0
0,0,0,0,0,0,0,0,0,0,0
0,0,0,0,0,0,0,0,0,0,0
0,0,0,0,0,0,0,0,0,0,0
0,0,0,0,0,39,0,0,0,0,0
0,0,0,0,0,0,0,0,0,0,0
0,0,0,0,0,0,0,0,0,0,0
0,0,0,0,0,0,0,0,0,0,0
0,0,0,0,0,0,0,0,0,0,0
0,0,0,0,0,0,0,0,0,0,0
endlayer

layer
0,0,0,0,0,0,0,0,0,0,0
0,0,0,0,0,0,0,0,0,0,0
0,0,0,0,0,0,0,0,0,0,0
0,0,0,0,0,0,0,0,0,0,0
0,0,0,0,0,0,0,0,0,0,0
0,0,0,0,0,39,0,0,0,0,0
0,0,0,0,0,0,0,0,0,0,0
0,0,0,0,0,0,0,0,0,0,0
0,0,0,0,0,0,0,0,0,0,0
0,0,0,0,0,0,0,0,0,0,0
0,0,0,0,0,0,0,0,0,0,0
endlayer

