
# Created by Ruins mod version 14.0 Ingame Parser
# authoring Player: Kujaku10
# Created 10/31/2004
# Updated to MC 1.11: 15 Jan 2017
# Updated to MC 1.12: 23 Jun 2017
# Updated to MC 1.12.1: 10 Sep 2017

biomesToSpawnIn=alps,alps forest,alps_foothills,alpine,birch forest,birch_forest,boreal_forest,cherry blossom grove,cherry_blossom_grove,clearing,dead forest,dead_forest,dead swamp,dead_swamp,deadlands,desert,eerie,eldritch,extreme hills,extreme_hills,extreme_hills_with_trees,extreme hills edge,extreme hills m,extreme hills+,extreme hills+ m,forest,foresthills,forest_hills,green hills,magical forest,meadow,mega taiga hills,mountain,mountain ridge,mystic grove,mystic_grove,ominous woods,ominous_woods,origin_island,pasture,prairie,shield,scrubland,shrubland,silkglades,smaller_extreme_hills,taiga,taigahills,taiga_hills,tainted land,thinned mystic grove,thinned timber,twilight clearing,twilight_clearing,wonderous woods,woodland,woodlands

uniqueMinDistance=800
spawnMinDistance=800

weight=1
embed_into_distance=4
acceptable_target_blocks=

unacceptable_target_blocks=flowing_water,water,flowing_lava,lava,slime_congealed,slime_dirt,slime_grass,cloud,command_block,planks,planks2,concrete,cobblestone,stonebrick,brick_block,glass,torch,oak_stairs,stone_stairs,brick_stairs,stone_brick_stairs,nether_brick_stairs,sandstone_stairs,spruce_stairs,birch_stairs,jungle_stairs,quartz_stairs,acacia_stairs,dark_oak_stairs,cobblestone_wall,stone_slab,double_stone_slab,stone_slab2,wooden_slab,double_wooden_slab,nether_brick,fence

dimensions=31,11,11
allowable_overhang=0
max_leveling=4
leveling_buffer=-1
preserve_water=0
preserve_lava=0
preserve_plants=1

rule1=0,100,minecraft:stonebrick-0,minecraft:stonebrick-0,minecraft:stonebrick-0,minecraft:stonebrick-1,minecraft:stonebrick-2


rule2=0,100,minecraft:water-9
rule3=0,100,minecraft:stone_slab-8

rule4=0,100,preserveBlock

rule5=0,100,minecraft:stone_brick_stairs-2
rule6=0,100,minecraft:stone_brick_stairs-3
rule7=0,100,minecraft:stone_brick_stairs-0

rule8=0,100,MobSpawner:Spider,MobSpawner:Skeleton

rule9=0,100,IInventory;minecraft:chest;minecraft:log#16#0#2+minecraft:log#16#0#13+minecraft:log#16#0#16+minecraft:log#16#0#21-5
rule10=0,100,IInventory;minecraft:chest;minecraft:stone#8#0#4+minecraft:stone#8#0#11+minecraft:stone#8#0#19+minecraft:stone#8#0#23-5
rule11=0,100,ChestGenHook:chests/simple_dungeon:3-2
rule12=0,100,minecraft:stone_brick_stairs-1
rule13=0,100,IInventory;minecraft:chest;minecraft:mossy_cobblestone#16#0#4+minecraft:mossy_cobblestone#16#0#11+minecraft:mossy_cobblestone#16#0#16+minecraft:mossy_cobblestone#16#0#23-4
rule14=0,100,IInventory;minecraft:chest;minecraft:leaves#16#0#2+minecraft:leaves#16#0#13+minecraft:leaves#16#0#19+minecraft:leaves#16#0#24-4

rule15=0,100,minecraft:water-0
rule16=0,100,minecraft:water-1
rule17=0,100,minecraft:ladder-3

rule18=0,100,minecraft:stonebrick-2,minecraft:cobblestone

rule19=0,100,MobSpawner:Skeleton,MobSpawner:Zombie

rule20=0,100,minecraft:ladder-2
rule21=0,100,minecraft:cobblestone_wall-0
rule22=0,100,minecraft:stonebrick-3
rule23=1,100,minecraft:redstone_torch-5
rule24=0,100,minecraft:birch_stairs-4
rule25=0,100,minecraft:birch_stairs-6
rule26=0,100,minecraft:birch_stairs-7
rule27=0,100,minecraft:birch_stairs-5
rule28=0,100,minecraft:stone_slab-0
rule29=0,100,minecraft:planks-2
rule30=0,100,minecraft:ladder-5
rule31=0,100,minecraft:birch_stairs-2
rule32=0,100,minecraft:birch_stairs-0
rule33=0,100,minecraft:birch_stairs-3
rule34=0,100,minecraft:stone_brick_stairs-5
rule35=0,100,minecraft:stone_brick_stairs-6
rule36=0,100,minecraft:stone_brick_stairs-7
rule37=0,100,minecraft:birch_stairs-1
rule38=0,100,minecraft:stone_brick_stairs-4

rule39=0,100,ChestGenHook:chests/simple_dungeon:5-3

rule40=0,100,minecraft:wooden_slab-2

layer
1,1,1,1,1,1,1,1,1,1,1
1,1,1,1,1,1,1,1,1,1,1
1,1,1,1,1,2,1,1,1,1,1
1,1,1,1,3,1,3,1,1,1,1
1,1,1,3,1,3,1,3,1,1,1
1,1,2,1,3,1,3,1,2,1,1
1,1,1,3,1,3,1,3,1,1,1
1,1,1,1,3,1,3,1,1,1,1
1,1,1,1,1,2,1,1,1,1,1
1,1,1,1,1,1,1,1,1,1,1
1,1,1,1,1,1,1,1,1,1,1
endlayer

layer
4,4,4,6,1,1,1,5,4,4,4
4,7,7,6,1,8,1,7,7,7,4
4,6,1,1,10,2,9,1,1,5,4
7,6,1,0,0,0,0,0,1,5,7
1,1,11,0,0,0,0,0,0,1,1
1,8,2,0,0,0,0,0,2,8,1
1,1,11,0,0,0,0,0,0,1,1
12,6,1,0,0,0,0,0,1,12,12
4,6,1,1,14,2,13,1,1,5,4
4,6,12,6,1,8,1,12,12,12,4
4,4,4,6,1,1,1,5,4,4,4
endlayer

layer
4,4,4,4,6,1,5,4,4,4,4
4,4,4,4,1,15,1,4,4,4,4
4,4,1,1,0,16,0,1,1,4,4
4,4,1,0,0,0,0,0,1,4,4
7,1,0,0,0,0,0,0,17,1,7
1,15,16,0,0,0,0,0,16,15,1
12,1,0,0,0,0,0,0,17,1,12
4,4,1,0,0,0,0,0,1,4,4
4,4,18,1,0,16,0,1,1,4,4
4,4,4,4,1,15,1,4,4,4,4
4,4,4,4,6,1,5,4,4,4,4
endlayer

layer
4,4,4,4,4,7,4,4,4,4,4
4,4,4,4,1,1,1,4,4,4,4
4,4,1,1,1,3,1,18,1,4,4
4,4,1,1,3,1,3,1,1,4,4
4,1,1,3,1,3,1,0,17,1,4
6,1,3,1,3,1,3,1,3,1,5
4,1,1,3,1,3,1,0,17,1,4
4,4,1,1,3,1,3,1,1,4,4
4,4,1,1,1,3,1,1,1,4,4
4,4,4,4,1,1,1,4,4,4,4
4,4,4,4,4,12,4,4,4,4,4
endlayer

layer
4,4,4,4,4,4,4,4,4,4,4
4,4,4,4,1,1,1,4,4,4,4
4,4,1,1,0,0,0,1,1,4,4
4,4,1,0,0,0,0,0,1,4,4
4,1,0,0,0,0,0,0,0,1,4
4,1,19,0,0,0,0,0,0,0,0
4,1,0,0,0,0,0,0,0,1,4
4,4,1,20,0,0,0,0,1,4,4
4,4,1,1,0,0,0,1,1,4,4
4,4,4,4,1,1,1,4,4,4,4
4,4,4,4,4,4,4,4,4,4,4
endlayer

layer
4,4,4,4,4,4,4,4,4,4,4
4,4,4,4,1,1,1,4,4,4,4
4,4,1,1,0,0,0,1,1,4,4
4,4,1,0,0,0,0,0,1,4,4
4,1,0,0,0,0,0,0,0,1,4
4,1,0,0,0,0,0,0,0,0,0
4,1,0,0,0,0,0,0,0,1,4
4,4,1,20,0,0,0,0,1,4,4
4,4,1,1,0,0,0,1,1,4,4
4,4,4,4,1,1,1,4,4,4,4
4,4,4,4,4,4,4,4,4,4,4
endlayer

layer
4,4,4,4,4,4,4,4,4,4,4
4,4,4,4,1,1,1,4,4,4,4
4,4,18,1,0,21,0,1,1,4,4
4,4,1,0,0,0,0,0,1,4,4
4,1,0,0,0,0,0,0,0,1,4
4,18,21,0,0,0,0,0,21,22,4
4,1,0,0,0,0,0,0,0,1,4
4,4,1,20,0,0,0,0,1,4,4
4,4,1,1,0,21,0,1,1,4,4
4,4,4,4,1,1,1,4,4,4,4
4,4,4,4,4,4,4,4,4,4,4
endlayer

layer
4,4,4,4,4,4,4,4,4,4,4
4,4,4,4,1,1,1,4,4,4,4
4,4,1,1,0,23,0,1,1,4,4
4,4,1,0,0,0,0,0,1,4,4
4,1,0,0,0,0,0,0,0,18,4
4,1,23,0,0,0,0,0,23,1,4
4,1,0,0,0,0,0,0,0,1,4
4,4,1,20,0,0,0,0,1,4,4
4,4,1,1,0,23,0,1,1,4,4
4,4,4,4,1,1,1,4,4,4,4
4,4,4,4,4,4,4,4,4,4,4
endlayer

layer
4,4,4,4,4,4,4,4,4,4,4
4,4,4,4,1,1,1,4,4,4,4
4,4,1,1,0,0,0,1,1,4,4
4,4,1,0,0,0,0,0,1,4,4
4,1,0,0,0,0,0,0,0,1,4
4,1,0,0,0,0,0,0,0,1,4
4,1,0,0,0,0,0,0,0,1,4
4,4,1,20,0,0,0,0,1,4,4
4,4,1,1,0,0,0,1,1,4,4
4,4,4,4,18,1,1,4,4,4,4
4,4,4,4,4,4,4,4,4,4,4
endlayer

layer
4,4,4,4,4,4,4,4,4,4,4
4,4,4,4,1,1,1,4,4,4,4
4,4,1,1,0,0,0,1,1,4,4
4,4,1,0,0,0,0,0,1,4,4
4,1,0,0,0,0,0,0,0,1,4
4,1,0,0,0,0,0,0,0,1,4
4,1,0,0,0,0,0,0,0,1,4
4,4,1,20,0,0,0,0,1,4,4
4,4,1,1,0,0,0,1,18,4,4
4,4,4,4,1,1,1,4,4,4,4
4,4,4,4,4,4,4,4,4,4,4
endlayer

layer
4,4,4,4,4,4,4,4,4,4,4
4,4,4,4,1,1,1,4,4,4,4
4,4,1,1,0,0,0,1,1,4,4
4,4,1,0,0,0,0,0,1,4,4
4,1,0,0,0,0,0,0,0,1,4
4,1,0,0,0,0,0,0,0,1,4
4,1,0,0,0,0,0,0,0,1,4
4,4,1,20,0,0,0,0,1,4,4
4,4,1,1,0,0,0,1,1,4,4
4,4,4,4,1,1,1,4,4,4,4
4,4,4,4,4,4,4,4,4,4,4
endlayer

layer
4,4,4,4,4,4,4,4,4,4,4
4,4,4,4,18,1,1,4,4,4,4
4,4,1,1,0,0,0,1,1,4,4
4,4,1,0,0,0,0,0,1,4,4
4,1,0,0,0,0,0,0,0,1,4
4,1,0,0,0,0,0,0,0,1,4
4,1,0,0,0,0,0,0,0,1,4
4,4,1,20,0,0,0,0,1,4,4
4,4,1,1,0,0,0,1,1,4,4
4,4,4,4,1,1,1,4,4,4,4
4,4,4,4,4,4,4,4,4,4,4
endlayer

layer
4,4,4,4,4,4,4,4,4,4,4
4,4,4,4,1,1,1,4,4,4,4
4,4,1,1,0,0,0,1,1,4,4
4,4,1,0,0,0,0,0,1,4,4
4,1,0,0,0,0,0,0,0,1,4
4,1,0,0,0,0,0,0,0,1,4
4,1,0,0,0,0,0,0,0,1,4
4,4,1,20,0,0,0,0,1,4,4
4,4,1,1,0,0,0,1,1,4,4
4,4,4,4,1,1,1,4,4,4,4
4,4,4,4,4,4,4,4,4,4,4
endlayer

layer
4,4,4,4,4,24,4,4,4,4,4
4,4,4,24,1,1,1,24,4,4,4
4,4,1,1,0,0,0,1,1,4,4
4,26,1,0,0,0,0,0,1,25,4
4,1,0,0,0,0,0,0,0,1,4
26,1,0,0,0,0,0,0,0,1,25
4,1,0,0,0,0,0,0,0,1,4
4,26,1,20,0,0,0,0,1,25,4
4,4,1,1,0,0,0,1,1,4,4
4,4,4,27,1,1,1,27,4,4,4
4,4,4,4,4,27,4,4,4,4,4
endlayer

layer
4,4,4,4,1,1,1,4,4,4,4
4,4,1,1,1,3,1,1,18,4,4
4,1,3,1,3,1,3,1,3,1,4
4,1,1,3,1,3,1,3,1,1,4
1,1,3,1,3,1,3,1,3,1,1
1,3,1,3,1,3,1,3,1,3,1
1,1,3,1,3,1,3,1,3,1,1
4,1,1,20,1,3,1,3,1,1,4
4,1,3,1,3,1,3,1,3,1,4
4,4,1,18,1,3,1,1,1,4,4
4,4,4,4,1,1,1,4,4,4,4
endlayer

layer
4,4,4,4,1,28,1,4,4,4,4
4,4,1,1,0,0,0,1,1,4,4
4,1,0,0,29,0,0,0,0,1,4
4,1,0,0,30,0,0,0,0,1,4
1,0,0,0,0,0,0,0,0,0,1
28,0,0,0,0,21,0,0,0,0,28
1,0,0,0,0,0,0,0,0,0,1
4,1,0,0,0,0,0,0,0,1,4
4,1,0,0,0,0,0,0,0,1,4
4,4,1,1,0,0,0,1,1,4,4
4,4,4,4,1,28,1,4,4,4,4
endlayer

layer
4,4,4,4,1,0,1,4,4,4,4
4,4,1,1,0,0,0,1,1,4,4
4,18,0,0,29,0,0,0,0,1,4
4,1,0,0,30,0,0,0,0,1,4
1,0,0,0,0,0,0,0,0,0,1
0,0,0,0,0,23,0,0,0,0,0
1,0,0,0,0,0,0,0,0,0,1
4,1,0,0,0,0,0,0,0,18,4
4,1,0,0,0,0,0,0,0,1,4
4,4,1,1,0,0,0,1,1,4,4
4,4,4,4,1,0,1,4,4,4,4
endlayer

layer
4,4,4,4,1,22,1,4,4,4,4
4,4,1,1,0,0,0,1,1,4,4
4,1,0,0,29,0,0,0,0,1,4
4,1,0,0,30,0,0,0,0,1,4
1,0,0,0,0,0,0,0,0,0,1
22,0,0,0,0,0,0,0,0,0,22
1,0,0,0,0,0,0,0,0,0,1
4,1,0,0,0,0,0,0,0,1,4
4,1,0,0,0,0,0,0,0,1,4
4,4,1,1,0,0,0,1,1,4,4
4,4,4,4,1,22,1,4,4,4,4
endlayer

layer
4,4,4,33,32,32,32,31,4,4,4
4,33,32,33,1,1,1,32,32,32,4
4,33,1,1,29,34,34,1,1,31,4
32,33,1,35,30,0,0,34,1,31,32
33,1,35,0,0,0,0,0,36,1,31
33,1,35,0,0,19,0,0,36,1,31
33,1,35,0,0,0,0,0,36,1,31
37,37,1,35,0,0,0,36,1,31,37
4,33,1,1,38,38,38,1,1,31,4
4,37,37,37,1,1,1,31,37,31,4
4,4,4,33,37,37,37,31,4,4,4
endlayer

layer
0,0,0,0,0,0,0,0,0,0,0
0,0,0,0,32,32,32,0,0,0,0
0,0,33,32,29,29,29,32,31,0,0
0,0,33,29,30,29,29,29,31,0,0
0,33,29,29,29,29,29,29,29,31,0
0,33,29,29,29,29,29,29,29,31,0
0,33,29,29,29,29,29,29,29,31,0
0,0,33,29,29,29,29,29,31,0,0
0,0,33,37,29,29,29,37,37,0,0
0,0,0,0,37,37,37,0,0,0,0
0,0,0,0,0,0,0,0,0,0,0
endlayer

layer
0,0,0,0,0,0,0,0,0,0,0
0,0,0,0,0,0,0,0,0,0,0
0,0,0,0,1,28,1,0,0,0,0
0,0,0,1,0,0,0,1,0,0,0
0,0,1,0,0,0,0,39,1,0,0
0,0,28,0,0,21,0,0,28,0,0
0,0,18,0,0,0,0,39,1,0,0
0,0,0,1,0,0,0,1,0,0,0
0,0,0,0,1,28,1,0,0,0,0
0,0,0,0,0,0,0,0,0,0,0
0,0,0,0,0,0,0,0,0,0,0
endlayer

layer
0,0,0,0,0,0,0,0,0,0,0
0,0,0,0,0,0,0,0,0,0,0
0,0,0,0,1,0,1,0,0,0,0
0,0,0,1,0,0,0,1,0,0,0
0,0,1,0,0,0,0,0,1,0,0
0,0,0,0,0,23,0,0,0,0,0
0,0,1,0,0,0,0,0,1,0,0
0,0,0,1,0,0,0,1,0,0,0
0,0,0,0,1,0,18,0,0,0,0
0,0,0,0,0,0,0,0,0,0,0
0,0,0,0,0,0,0,0,0,0,0
endlayer

layer
0,0,0,0,0,0,0,0,0,0,0
0,0,0,0,0,0,0,0,0,0,0
0,0,0,0,18,22,1,0,0,0,0
0,0,0,1,0,0,0,1,0,0,0
0,0,1,0,0,0,0,0,18,0,0
0,0,22,0,0,0,0,0,22,0,0
0,0,1,0,0,0,0,0,1,0,0
0,0,0,1,0,0,0,1,0,0,0
0,0,0,0,1,22,1,0,0,0,0
0,0,0,0,0,0,0,0,0,0,0
0,0,0,0,0,0,0,0,0,0,0
endlayer

layer
0,0,0,0,0,0,0,0,0,0,0
0,0,0,33,32,32,32,31,0,0,0
0,0,32,33,1,1,1,32,31,0,0
0,32,33,1,3,3,3,1,32,31,0
0,33,1,3,0,0,0,3,1,31,0
0,33,1,3,0,19,0,3,1,31,0
0,33,1,3,0,0,0,3,1,31,0
0,37,33,1,3,3,3,1,31,37,0
0,0,33,37,1,1,1,31,37,0,0
0,0,0,33,37,37,37,31,0,0,0
0,0,0,0,0,0,0,0,0,0,0
endlayer

layer
0,0,0,0,0,0,0,0,0,0,0
0,0,0,0,0,0,0,0,0,0,0
0,0,0,0,32,32,32,0,0,0,0
0,0,0,32,29,29,29,32,0,0,0
0,0,33,29,27,27,26,29,31,0,0
0,0,33,29,25,21,26,29,31,0,0
0,0,33,29,25,24,26,29,31,0,0
0,0,0,37,29,29,29,37,0,0,0
0,0,0,0,37,37,37,0,0,0,0
0,0,0,0,0,0,0,0,0,0,0
0,0,0,0,0,0,0,0,0,0,0
endlayer

layer
0,0,0,0,0,0,0,0,0,0,0
0,0,0,0,0,0,0,0,0,0,0
0,0,0,0,0,0,0,0,0,0,0
0,0,0,0,32,32,32,0,0,0,0
0,0,0,33,29,29,29,31,0,0,0
0,0,0,33,29,29,29,31,0,0,0
0,0,0,33,29,29,29,31,0,0,0
0,0,0,0,37,37,37,0,0,0,0
0,0,0,0,0,0,0,0,0,0,0
0,0,0,0,0,0,0,0,0,0,0
0,0,0,0,0,0,0,0,0,0,0
endlayer

layer
0,0,0,0,0,0,0,0,0,0,0
0,0,0,0,0,0,0,0,0,0,0
0,0,0,0,0,0,0,0,0,0,0
0,0,0,0,0,0,0,0,0,0,0
0,0,0,0,33,32,32,0,0,0,0
0,0,0,0,33,29,31,0,0,0,0
0,0,0,0,33,37,31,0,0,0,0
0,0,0,0,0,0,0,0,0,0,0
0,0,0,0,0,0,0,0,0,0,0
0,0,0,0,0,0,0,0,0,0,0
0,0,0,0,0,0,0,0,0,0,0
endlayer

layer
0,0,0,0,0,0,0,0,0,0,0
0,0,0,0,0,0,0,0,0,0,0
0,0,0,0,0,0,0,0,0,0,0
0,0,0,0,0,0,0,0,0,0,0
0,0,0,0,0,0,0,0,0,0,0
0,0,0,0,0,29,0,0,0,0,0
0,0,0,0,0,0,0,0,0,0,0
0,0,0,0,0,0,0,0,0,0,0
0,0,0,0,0,0,0,0,0,0,0
0,0,0,0,0,0,0,0,0,0,0
0,0,0,0,0,0,0,0,0,0,0
endlayer

layer
0,0,0,0,0,0,0,0,0,0,0
0,0,0,0,0,0,0,0,0,0,0
0,0,0,0,0,0,0,0,0,0,0
0,0,0,0,0,0,0,0,0,0,0
0,0,0,0,0,0,0,0,0,0,0
0,0,0,0,0,29,0,0,0,0,0
0,0,0,0,0,0,0,0,0,0,0
0,0,0,0,0,0,0,0,0,0,0
0,0,0,0,0,0,0,0,0,0,0
0,0,0,0,0,0,0,0,0,0,0
0,0,0,0,0,0,0,0,0,0,0
endlayer

layer
0,0,0,0,0,0,0,0,0,0,0
0,0,0,0,0,0,0,0,0,0,0
0,0,0,0,0,0,0,0,0,0,0
0,0,0,0,0,0,0,0,0,0,0
0,0,0,0,0,0,0,0,0,0,0
0,0,0,0,0,29,0,0,0,0,0
0,0,0,0,0,0,0,0,0,0,0
0,0,0,0,0,0,0,0,0,0,0
0,0,0,0,0,0,0,0,0,0,0
0,0,0,0,0,0,0,0,0,0,0
0,0,0,0,0,0,0,0,0,0,0
endlayer

layer
0,0,0,0,0,0,0,0,0,0,0
0,0,0,0,0,0,0,0,0,0,0
0,0,0,0,0,0,0,0,0,0,0
0,0,0,0,0,0,0,0,0,0,0
0,0,0,0,0,0,0,0,0,0,0
0,0,0,0,0,40,0,0,0,0,0
0,0,0,0,0,0,0,0,0,0,0
0,0,0,0,0,0,0,0,0,0,0
0,0,0,0,0,0,0,0,0,0,0
0,0,0,0,0,0,0,0,0,0,0
0,0,0,0,0,0,0,0,0,0,0
endlayer

