# Kujaku's Castle Cottage #1
# Created by Ruins mod version 16.4 Ingame Parser
# authoring Player: Kujaku10
# Created for MC 1.11: 2017 Apr 16
# Updated to MC 1.12: 23 Jun 2017
# Updated to MC 1.12.1: 10 Sep 2017

# Last Updated: 7 Dec 2018

biomesToSpawnIn=birch forest,birch forest hills,birch_forest,birch_forest_hills,birch forest hills m,birch forest m,boreal forest,boreal_forest,brushland,chaparral,cold taiga,cold taiga hills,cold taiga m,coniferous forest,coniferous_forest,dead forest,dead_forest,extreme hills edge,forest,foresthills,grassland,grove,heathland,highland,ice mountains,maple woods,maple_woods,mega taiga,mega taiga hills,mountain,mountain foothills,mutated_birch_forest,mutated_birch_forest_hills,mutated_forest,mutated_taiga,ominous woods,ominous_woods,origin_island,redwood taiga hills m,redwood_taiga_hills,steppe,taiga,taiga m,taigahills,taiga_hills,xeric shrubland,xeric_shrubland

weight=1
embed_into_distance=5
acceptable_target_blocks=

unacceptable_target_blocks=flowing_water,water,flowing_lava,lava,cloud,slime_congealed,slime_dirt,slime_grass,command_block,planks,planks2,concrete,cobblestone,stonebrick,brick_block,glass,torch,oak_stairs,stone_stairs,brick_stairs,stone_brick_stairs,nether_brick_stairs,sandstone_stairs,spruce_stairs,birch_stairs,jungle_stairs,quartz_stairs,acacia_stairs,dark_oak_stairs,cobblestone_wall,stone_slab,double_stone_slab,stone_slab2,wooden_slab,double_wooden_slab,nether_brick,fence

dimensions=17,11,9
allowable_overhang=0
max_leveling=5
leveling_buffer=-1
preserve_water=0
preserve_lava=0
preserve_plants=1

rule1=0,100,preserveBlock

rule2=0,100,minecraft:stonebrick-0,minecraft:stonebrick-0,minecraft:stonebrick-0,minecraft:stonebrick-1,minecraft:stonebrick-2

rule3=0,100,minecraft:planks-2
rule4=0,100,minecraft:stonebrick-3
rule5=0,100,minecraft:spruce_stairs-4
rule6=0,100,minecraft:wooden_slab-9
rule7=0,100,minecraft:spruce_stairs-5

rule8=0,100,IInventory;minecraft:chest;minecraft:tipped_arrow#{Potion:"minecraft:strong_poison"}#0#0+minecraft:web#1#0#3+minecraft:tipped_arrow#{Potion:"minecraft:strong_poison"}#0#5+minecraft:rotten_flesh#1#0#7+minecraft:rotten_flesh#1#0#10+minecraft:log#8#2#11+minecraft:stone#8#0#17+minecraft:web#1#0#18+minecraft:stone#8#0#19+minecraft:tipped_arrow#{Potion:"minecraft:strong_poison"}#0#21+minecraft:web#1#0#23+minecraft:log#8#1#24+minecraft:tipped_arrow#{Potion:"minecraft:strong_poison"}#0#26-4

rule9=0,100,minecraft:ladder-3
rule10=2,100,minecraft:redstone_torch-1
rule11=0,100,minecraft:ladder-2
rule12=2,100,minecraft:redstone_torch-3
rule13=2,100,minecraft:redstone_torch-4
rule14=2,100,minecraft:redstone_torch-2
rule15=1,100,minecraft:grass-0
rule16=0,100,minecraft:trapdoor-9
rule17=0,100,minecraft:trapdoor-8
rule18=1,100,minecraft:red_flower-8
rule19=1,100,minecraft:leaves-6
rule20=0,100,minecraft:spruce_stairs-3
rule21=0,100,minecraft:spruce_stairs-2
rule22=1,100,minecraft:leaves-14
rule23=0,100,minecraft:wooden_door-2
rule24=0,100,minecraft:glass_pane-0

rule25=0,100,teBlock;minecraft:flower_pot;{Item:"minecraft:red_flower",x:0,y:0,z:0,Data:4,id:"minecraft:flower_pot"}-0

rule26=0,100,minecraft:wooden_door-8
rule27=0,100,minecraft:fence-0
rule28=1,100,minecraft:torch-5
rule29=0,100,minecraft:birch_stairs-2
rule30=0,100,minecraft:stone_brick_stairs-7
rule31=0,100,minecraft:stone_brick_stairs-6
rule32=0,100,minecraft:birch_stairs-3
rule33=0,100,minecraft:trapdoor-14
rule34=0,100,minecraft:trapdoor-15
rule35=0,100,minecraft:stone_brick_stairs-2
rule36=0,100,minecraft:stone_brick_stairs-3
rule37=0,100,minecraft:wooden_slab-2
rule38=0,100,minecraft:stone_slab-5

rule39=0,100,MobSpawner:Skeleton

layer
1,1,1,1,1,1,1,1,1
1,2,2,2,2,2,2,2,1
1,2,3,3,3,3,3,2,1
1,2,3,4,2,4,3,2,1
1,2,3,2,3,2,3,2,1
1,2,3,2,3,2,3,2,1
1,2,3,2,3,2,3,2,1
1,2,3,4,2,4,3,2,1
1,2,3,3,3,3,3,2,1
1,2,2,2,2,2,2,2,1
1,1,1,1,1,1,1,1,1
endlayer

layer
1,1,1,1,1,1,1,1,1
1,2,2,2,2,2,2,2,1
1,2,0,0,0,0,0,2,1
1,2,0,0,0,0,0,2,1
1,2,5,0,0,0,5,2,1
1,2,6,0,0,0,6,2,1
1,2,7,0,0,0,7,2,1
1,2,0,0,0,0,0,2,1
1,2,39,0,8,0,39,2,1
1,2,2,2,2,2,2,2,1
1,1,1,1,1,1,1,1,1
endlayer

layer
1,1,1,1,1,1,1,1,1
1,2,2,2,2,2,2,2,1
1,2,11,0,10,0,9,2,1
1,2,0,0,0,0,0,2,1
1,2,0,0,0,0,0,2,1
1,2,13,0,0,0,12,2,1
1,2,0,0,0,0,0,2,1
1,2,0,0,0,0,0,2,1
1,2,0,0,14,0,0,2,1
1,2,2,2,2,2,2,2,1
1,1,1,1,1,1,1,1,1
endlayer

layer
1,1,1,1,1,1,1,1,1
1,2,2,2,2,2,2,2,1
1,2,11,0,0,0,9,2,1
1,2,0,0,0,0,0,2,1
1,2,0,0,0,0,0,2,1
1,2,0,0,0,0,0,2,1
1,2,0,0,0,0,0,2,1
1,2,0,0,0,0,0,2,1
1,2,0,0,0,0,0,2,1
1,2,2,2,2,2,2,2,1
1,1,1,1,1,1,1,1,1
endlayer

layer
15,15,15,15,15,15,15,15,15
15,2,2,2,2,2,2,2,15
15,2,17,3,3,3,16,2,15
15,2,3,4,2,4,3,2,15
15,2,3,2,3,2,3,2,15
15,2,3,2,3,2,3,2,15
15,2,3,2,3,2,3,2,15
15,2,3,4,2,4,3,2,15
15,2,3,3,3,3,3,2,15
15,2,2,2,15,2,2,2,15
15,15,15,15,15,15,15,15,15
endlayer

layer
18,19,19,19,19,19,19,19,18
19,2,2,2,2,2,2,2,19
19,2,0,0,0,0,0,2,19
19,2,5,0,0,0,5,2,19
19,2,21,0,0,0,20,2,19
22,2,21,0,0,0,20,2,19
22,2,21,0,0,0,20,2,19
19,2,7,0,0,0,7,2,19
19,2,0,0,23,0,0,2,19
22,2,2,2,0,2,2,2,19
18,19,19,18,0,18,19,19,18
endlayer

layer
0,0,0,0,0,0,0,0,0
0,2,2,2,2,2,2,2,0
0,2,0,0,0,0,0,2,0
0,24,25,0,0,0,25,24,0
0,2,0,0,0,0,0,2,0
0,24,0,0,0,0,0,24,0
0,2,0,0,0,0,0,2,0
0,24,25,0,0,0,25,24,0
0,2,0,0,26,0,0,2,0
0,2,2,2,0,2,2,2,0
0,0,0,0,0,0,0,0,0
endlayer

layer
0,0,0,0,0,0,0,0,0
0,2,2,24,2,24,2,2,0
0,2,0,0,27,0,0,2,0
0,24,0,0,0,0,0,24,0
0,2,27,0,0,0,27,2,0
0,24,0,0,0,0,0,24,0
0,2,27,0,0,0,27,2,0
0,24,0,0,0,0,0,24,0
0,2,0,27,0,27,0,2,0
0,2,2,2,3,2,2,2,0
0,0,0,27,0,27,0,0,0
endlayer

layer
0,0,0,0,0,0,0,0,0
0,2,2,24,2,24,2,2,0
0,2,0,0,28,0,0,2,0
0,24,0,0,0,0,0,24,0
0,2,28,0,0,0,28,2,0
0,24,0,0,0,0,0,24,0
0,2,28,0,0,0,28,2,0
0,24,0,0,0,0,0,24,0
0,2,0,28,0,28,0,2,0
0,2,2,2,2,2,2,2,0
0,0,0,28,0,28,0,0,0
endlayer

layer
0,0,0,0,0,0,0,0,0
0,2,2,2,2,2,2,2,0
32,2,31,0,0,0,30,2,29
32,2,0,0,0,0,0,2,29
32,2,31,0,0,0,30,2,29
32,2,0,0,0,0,0,2,29
32,2,31,0,0,0,30,2,29
32,2,0,0,0,0,0,2,29
32,2,31,0,0,0,30,2,29
0,2,2,2,2,2,2,2,0
0,0,0,0,0,0,0,0,0
endlayer

layer
0,0,0,33,0,33,0,0,0
0,2,2,2,24,2,2,2,0
0,32,3,0,0,0,3,29,0
0,32,3,0,0,0,3,29,0
0,32,3,0,0,0,3,29,0
0,32,3,0,0,0,3,29,0
0,32,3,0,0,0,3,29,0
0,32,3,0,0,0,3,29,0
0,32,3,0,0,0,3,29,0
0,2,2,2,24,2,2,2,0
0,0,0,34,0,34,0,0,0
endlayer

layer
0,0,0,0,0,0,0,0,0
0,36,2,2,2,2,2,35,0
0,0,32,3,0,3,29,0,0
0,0,32,3,0,3,29,0,0
0,0,32,3,0,3,29,0,0
0,0,32,3,0,3,29,0,0
0,0,32,3,0,3,29,0,0
0,0,32,3,0,3,29,0,0
0,0,32,3,0,3,29,0,0
0,36,2,2,2,2,2,35,0
0,0,0,0,0,0,0,0,0
endlayer

layer
0,0,0,0,0,0,0,0,0
0,0,36,2,2,2,35,0,0
0,0,0,32,3,29,0,0,0
0,0,0,32,3,29,0,0,0
0,0,0,32,3,29,0,0,0
0,0,0,32,3,29,0,0,0
0,0,0,32,3,29,0,0,0
0,0,0,32,3,29,0,0,0
0,0,0,32,3,29,0,0,0
0,0,36,2,2,2,35,0,0
0,0,0,0,0,0,0,0,0
endlayer

layer
0,0,0,0,0,0,0,0,0
0,0,0,36,2,35,0,0,0
0,0,0,0,37,0,0,0,0
0,0,0,0,37,0,0,0,0
0,0,0,0,37,0,0,0,0
0,0,0,0,37,0,0,0,0
0,0,0,0,37,0,0,0,0
0,0,0,0,37,0,0,0,0
0,0,0,0,37,0,0,0,0
0,0,0,36,2,35,0,0,0
0,0,0,0,0,0,0,0,0
endlayer

layer
0,0,0,0,0,0,0,0,0
0,0,0,0,2,0,0,0,0
0,0,0,0,0,0,0,0,0
0,0,0,0,0,0,0,0,0
0,0,0,0,0,0,0,0,0
0,0,0,0,0,0,0,0,0
0,0,0,0,0,0,0,0,0
0,0,0,0,0,0,0,0,0
0,0,0,0,0,0,0,0,0
0,0,0,0,2,0,0,0,0
0,0,0,0,0,0,0,0,0
endlayer

layer
0,0,0,0,0,0,0,0,0
0,0,0,0,2,0,0,0,0
0,0,0,0,0,0,0,0,0
0,0,0,0,0,0,0,0,0
0,0,0,0,0,0,0,0,0
0,0,0,0,0,0,0,0,0
0,0,0,0,0,0,0,0,0
0,0,0,0,0,0,0,0,0
0,0,0,0,0,0,0,0,0
0,0,0,0,2,0,0,0,0
0,0,0,0,0,0,0,0,0
endlayer

layer
0,0,0,0,0,0,0,0,0
0,0,0,0,38,0,0,0,0
0,0,0,0,0,0,0,0,0
0,0,0,0,0,0,0,0,0
0,0,0,0,0,0,0,0,0
0,0,0,0,0,0,0,0,0
0,0,0,0,0,0,0,0,0
0,0,0,0,0,0,0,0,0
0,0,0,0,0,0,0,0,0
0,0,0,0,38,0,0,0,0
0,0,0,0,0,0,0,0,0
endlayer

