
# Created by Ruins mod version 14.0 Ingame Parser
# authoring Player: Kujaku10
# Created 10/31/2004
# Updated to MC 1.11: 15 Jan 2017
# Updated to MC 1.12: 23 Jun 2017

biomesToSpawnIn=alps,alps forest,alpine,alps_foothills,birch forest,cherry blossom grove,cherry_blossom_grove,clearing,dead forest,dead_forest,dead swamp,dead_swamp,deadlands,desert,eerie,eldritch,extreme hills,extreme hills edge,extreme hills m,extreme hills+,extreme hills+ m,forest,foresthills,green hills,magical forest,meadow,mega taiga hills,mountain,mountain ridge,mystic grove,mystic_grove,ominous woods,ominous_woods,origin_island,pasture,prairie,shield,scrubland,shrubland,silkglades,taiga,taigahills,tainted land,thinned mystic grove,thinned timber,twilight clearing,twilight_clearing,wonderous woods,woodland,woodlands

weight=1
embed_into_distance=6
acceptable_target_blocks=

unacceptable_target_blocks=flowing_water,water,flowing_lava,lava,cloud,Natura:Cloud,slime_congealed,slime_dirt,slime_grass,command_block,planks,planks2,concrete,cobblestone,stonebrick,brick_block,glass,torch,oak_stairs,stone_stairs,brick_stairs,stone_brick_stairs,nether_brick_stairs,sandstone_stairs,spruce_stairs,birch_stairs,jungle_stairs,quartz_stairs,acacia_stairs,dark_oak_stairs,cobblestone_wall,stone_slab,double_stone_slab,stone_slab2,wooden_slab,double_wooden_slab,nether_brick,fence

dimensions=42,12,11
allowable_overhang=0
max_leveling=6
leveling_buffer=-1
preserve_water=0
preserve_lava=0
preserve_plants=1

rule1=0,100,minecraft:stonebrick-0,minecraft:stonebrick-0,minecraft:stonebrick-1,minecraft:stonebrick-2

rule2=0,100,minecraft:water-9

rule3=0,100,IInventory;minecraft:chest;minecraft:gravel#16#0#0+minecraft:gravel#16#0#7+minecraft:gravel#16#0#11+minecraft:gravel#16#0#23-5
rule4=0,100,minecraft:stonebrick-3
rule5=0,100,IInventory;minecraft:chest;minecraft:arrow#16#0#2+minecraft:arrow#16#0#14+minecraft:arrow#16#0#21+minecraft:arrow#16#0#25-5
rule6=0,100,minecraft:stone_brick_stairs-0

rule7=0,100,MobSpawner:Zombie,MobSpawner:Skeleton,MobSpawner:Spider

rule8=0,100,IInventory;minecraft:chest;minecraft:grass#16#0#6+minecraft:grass#16#0#12+minecraft:grass#16#0#19+minecraft:grass#16#0#24-4
rule9=0,100,IInventory;minecraft:chest;minecraft:clay#16#0#7+minecraft:clay#16#0#12+minecraft:clay#16#0#19+minecraft:clay#16#0#24-4

rule10=0,100,minecraft:stone_brick_stairs-1
rule11=0,100,minecraft:water-0
rule12=0,100,minecraft:water-1
rule13=0,100,minecraft:cobblestone_wall-0
rule14=1,100,minecraft:redstone_torch-5
rule15=0,100,minecraft:stone_brick_stairs-3
rule16=0,100,minecraft:stone_slab-8
rule17=0,100,minecraft:stonebrick-2
rule18=2,100,minecraft:redstone_torch-1
rule19=2,100,minecraft:redstone_torch-3
rule20=2,100,minecraft:redstone_torch-4
rule21=2,100,minecraft:redstone_torch-2
rule22=0,100,minecraft:stone_brick_stairs-2

rule23=0,100,preserveBlock

rule24=0,100,minecraft:stone_slab-5
rule25=0,100,minecraft:ladder-5
rule26=0,100,minecraft:planks-0
rule27=0,100,minecraft:stone_brick_stairs-4
rule28=0,100,minecraft:stone_brick_stairs-5
rule29=0,100,minecraft:double_stone_slab-0

rule30=0,100,ChestGenHook:chests/simple_dungeon:3-3

rule31=0,100,minecraft:stone_brick_stairs-6
rule32=0,100,minecraft:stone_brick_stairs-7
rule33=0,100,minecraft:stone_slab-0
rule34=0,100,minecraft:sandstone-2
rule35=0,100,minecraft:sandstone-0
rule36=0,100,minecraft:stone_slab-1
rule37=0,100,minecraft:fence-0

layer
1,1,1,1,1,1,1,1,1,1,1
1,1,1,1,1,1,1,1,1,1,1
1,1,1,1,1,2,1,1,1,1,1
1,1,1,1,1,1,1,1,1,1,1
1,1,1,1,1,1,1,1,1,1,1
1,1,1,1,1,1,1,1,1,1,1
1,1,1,1,1,1,1,1,1,1,1
1,1,1,1,1,1,1,1,1,1,1
1,1,1,1,1,1,1,1,1,1,1
1,1,1,1,1,2,1,1,1,1,1
1,1,1,1,1,1,1,1,1,1,1
1,1,1,1,1,1,1,1,1,1,1
endlayer

layer
1,1,1,1,1,1,1,1,1,1,1
1,5,0,0,0,4,0,0,0,3,1
1,0,0,0,0,2,0,0,0,0,1
1,0,0,0,0,0,0,0,0,0,1
1,0,0,0,6,0,0,0,0,0,1
1,0,0,0,1,1,0,0,0,0,1
1,0,0,0,1,7,1,0,0,0,1
1,0,0,0,0,0,0,0,0,0,1
1,0,0,0,0,0,0,0,0,0,1
1,0,0,0,0,2,0,0,0,0,1
1,9,0,0,0,4,0,0,0,8,1
1,1,1,1,1,1,1,1,1,1,1
endlayer

layer
1,1,1,1,1,1,1,1,1,1,1
1,0,0,0,10,11,10,0,0,0,1
1,0,0,0,0,12,0,0,0,0,1
1,0,0,0,0,0,0,0,0,0,1
1,0,0,0,0,0,0,0,0,0,1
1,0,0,0,6,1,0,0,0,0,1
1,0,0,0,1,1,1,0,0,0,1
1,0,0,0,0,0,0,0,0,0,1
1,0,0,0,0,0,0,0,0,0,1
1,0,0,0,0,12,0,0,0,0,1
1,0,0,0,6,11,6,0,0,0,1
1,1,1,1,1,1,1,1,1,1,1
endlayer

layer
1,1,1,1,1,1,1,1,1,1,1
1,13,0,0,0,10,0,0,0,13,1
1,0,0,0,0,0,0,0,0,0,1
1,0,0,0,0,0,0,0,0,0,1
1,0,0,0,0,0,0,0,0,0,1
1,0,0,0,0,1,0,0,0,0,1
1,0,0,0,6,1,1,0,0,0,1
1,0,0,0,0,0,0,0,0,0,1
1,0,0,0,0,0,0,0,0,0,1
1,0,0,0,0,0,0,0,0,0,1
1,13,0,0,0,6,0,0,0,13,1
1,1,1,1,1,1,1,1,1,1,1
endlayer

layer
1,1,1,1,1,1,1,1,1,1,1
1,14,0,0,0,0,0,0,0,14,1
1,0,0,0,0,0,0,0,0,0,1
1,0,0,0,0,0,0,0,0,0,1
1,0,0,0,0,0,0,0,0,0,1
1,0,0,0,0,1,0,0,0,0,1
1,0,0,0,0,15,1,0,0,0,1
1,0,0,0,0,0,0,0,0,0,1
1,0,0,0,0,0,0,0,0,0,1
1,0,0,0,0,0,0,0,0,0,1
1,14,0,0,0,0,0,0,0,14,1
1,1,1,1,1,1,1,1,1,1,1
endlayer

layer
1,1,1,1,1,1,1,1,1,1,1
1,16,1,16,1,16,1,16,1,16,1
1,1,16,1,16,1,16,1,16,1,1
1,16,1,16,1,16,1,16,1,16,1
1,1,16,1,16,1,16,1,16,1,1
1,16,1,16,0,1,1,16,1,16,1
1,16,1,16,0,0,15,16,1,16,1
1,1,16,1,16,1,16,1,16,1,1
1,16,1,16,1,16,1,16,1,16,1
1,1,16,1,16,1,16,1,16,1,1
1,16,1,16,1,16,1,16,1,16,1
1,1,1,1,1,1,1,1,1,1,1
endlayer

layer
4,1,1,1,1,1,1,1,1,1,4
1,13,0,0,0,0,0,0,0,13,17
1,0,0,0,0,0,0,0,0,0,1
1,0,0,0,7,1,7,0,0,0,1
1,0,0,0,1,1,1,0,0,0,1
17,0,0,0,0,13,10,0,0,0,1
1,0,0,0,0,0,0,0,0,0,1
1,0,0,0,0,0,0,0,0,0,1
1,0,0,0,0,0,0,0,0,0,1
1,0,0,0,0,0,0,0,0,0,17
1,13,0,0,0,0,0,0,0,13,1
4,1,1,1,1,0,1,1,1,1,4
endlayer

layer
13,1,1,1,17,1,1,1,1,1,13
1,13,0,0,18,0,18,0,0,13,1
1,0,0,0,0,0,0,0,0,0,1
1,20,0,0,0,1,0,0,0,19,1
1,0,0,0,1,1,10,0,0,0,1
1,0,0,0,0,14,0,0,0,0,1
1,0,0,0,0,0,0,0,0,0,1
1,0,0,0,0,0,0,0,0,0,1
1,20,0,0,0,0,0,0,0,19,1
1,0,0,0,0,0,0,0,0,0,1
1,13,0,0,21,0,21,0,0,13,1
13,1,1,1,1,0,1,1,1,17,13
endlayer

layer
13,1,1,1,1,1,1,1,1,1,13
1,13,0,0,0,0,0,0,0,13,1
1,0,0,0,0,0,0,0,0,0,1
1,0,0,0,0,1,0,0,0,0,1
1,0,0,0,1,22,0,0,0,0,1
1,0,0,0,0,0,0,0,0,0,1
1,0,0,0,0,0,0,0,0,0,1
1,0,0,0,0,0,0,0,0,0,1
1,0,0,0,0,0,0,0,0,0,1
1,0,0,0,0,0,0,0,0,0,1
1,13,0,0,0,0,0,0,0,13,1
13,1,1,1,1,4,1,1,1,1,13
endlayer

layer
13,1,1,1,1,1,1,1,1,17,13
1,1,1,1,1,1,1,1,1,1,1
1,1,1,1,1,1,1,1,1,1,1
1,1,1,1,1,1,1,1,1,1,1
1,1,1,1,22,0,0,1,1,1,1
1,1,1,1,1,1,0,1,1,1,17
1,1,1,1,1,1,1,1,1,1,1
1,1,1,1,1,1,1,1,1,1,1
1,1,1,1,1,1,1,1,1,1,1
1,1,1,1,1,1,1,1,1,1,1
1,1,1,1,1,1,1,1,1,1,1
13,17,1,1,1,1,1,1,1,1,13
endlayer

layer
4,1,1,1,1,1,1,1,1,1,4
1,23,23,23,23,0,23,23,23,23,1
1,23,1,1,1,0,1,1,1,23,1
1,23,1,13,0,0,0,13,1,23,1
1,23,1,0,0,0,0,0,1,23,1
1,23,1,0,0,0,0,0,1,23,1
1,23,1,0,0,0,0,0,1,23,1
1,23,1,13,6,7,0,13,1,23,1
17,23,1,1,1,1,1,1,1,23,1
1,23,1,1,1,1,1,1,1,23,1
1,23,23,23,23,23,23,23,23,23,1
4,1,1,1,1,1,1,1,1,1,4
endlayer

layer
1,1,24,1,24,1,24,1,24,1,1
1,23,23,23,23,0,23,23,23,23,1
24,23,1,1,1,0,1,1,1,23,24
1,23,1,13,0,0,0,13,1,23,1
24,23,1,20,0,0,0,19,1,23,24
1,23,1,0,0,0,0,0,1,23,1
1,23,1,20,0,0,0,19,1,23,1
24,23,1,13,0,0,0,13,1,23,24
1,23,1,1,6,1,1,1,1,23,1
24,23,1,1,1,1,1,1,1,23,24
1,23,23,23,23,23,23,23,23,23,1
1,1,24,1,24,1,24,1,24,1,1
endlayer

layer
24,24,23,24,23,24,23,24,23,24,24
24,23,23,23,23,23,23,23,23,23,24
23,23,1,1,1,4,1,1,1,23,23
24,23,1,13,0,0,0,13,1,23,24
23,23,1,0,0,0,0,0,1,23,23
24,23,1,0,0,0,0,0,1,23,24
24,23,1,0,0,0,0,0,1,23,24
23,23,1,13,0,0,0,13,1,23,23
24,23,1,1,0,15,1,1,1,23,24
23,23,1,1,1,1,1,1,1,23,23
24,23,23,23,23,23,23,23,23,23,24
24,24,23,24,23,24,23,24,23,24,24
endlayer

layer
23,23,23,23,23,23,23,23,23,23,23
23,23,23,23,23,23,23,23,23,23,23
23,23,1,1,1,1,1,1,1,23,23
23,23,1,13,0,0,0,13,1,23,23
23,23,1,0,0,0,0,0,1,23,23
23,23,1,0,0,0,0,0,1,23,23
23,23,1,0,0,0,0,0,1,23,23
23,23,1,13,0,0,0,13,1,23,23
23,23,1,1,0,0,15,1,1,23,23
23,23,1,17,1,1,1,1,1,23,23
23,23,23,23,23,23,23,23,23,23,23
23,23,23,23,23,23,23,23,23,23,23
endlayer

layer
23,23,23,23,23,23,23,23,23,23,23
23,23,23,23,23,23,23,23,23,23,23
23,23,1,1,1,1,1,1,1,23,23
23,23,1,1,1,1,1,1,1,23,23
23,23,1,1,1,1,1,1,1,23,23
23,23,1,1,1,1,1,1,1,23,23
23,23,1,1,1,1,1,1,1,23,23
23,23,1,1,1,1,1,1,1,23,23
23,23,1,1,0,0,0,15,1,23,23
23,23,1,1,1,1,1,1,1,23,23
23,23,23,23,23,23,23,23,23,23,23
23,23,23,23,23,23,23,23,23,23,23
endlayer

layer
23,23,23,23,23,23,23,23,23,23,23
23,23,23,23,23,23,23,23,23,23,23
23,23,1,1,1,1,1,1,17,23,23
23,23,1,13,25,7,0,13,1,23,23
23,23,1,0,0,0,0,0,1,23,23
23,23,17,0,0,0,0,0,1,23,23
23,23,1,0,0,0,0,0,1,23,23
23,23,1,0,0,0,0,0,1,23,23
23,23,1,13,0,0,0,13,1,23,23
23,23,1,1,1,1,1,1,1,23,23
23,23,23,23,23,23,23,23,23,23,23
23,23,23,23,23,23,23,23,23,23,23
endlayer

layer
23,23,23,23,23,23,23,23,23,23,23
23,23,23,23,23,23,23,23,23,23,23
23,23,1,17,1,26,1,1,1,23,23
23,23,1,13,25,0,0,13,1,23,23
23,23,1,0,0,0,0,0,1,23,23
23,23,26,0,0,0,0,0,26,23,23
23,23,26,0,0,0,0,0,26,23,23
23,23,1,0,0,0,0,0,1,23,23
23,23,1,13,0,0,0,13,1,23,23
23,23,1,1,1,26,1,17,1,23,23
23,23,23,23,23,23,23,23,23,23,23
23,23,23,23,23,23,23,23,23,23,23
endlayer

layer
23,23,23,23,23,23,23,23,23,23,23
23,23,23,23,23,23,23,23,23,23,23
23,23,1,1,1,26,1,1,1,23,23
23,23,1,13,25,0,0,13,1,23,23
23,23,1,20,0,0,0,19,1,23,23
23,23,26,0,0,0,0,0,26,23,23
23,23,26,0,0,0,0,0,26,23,23
23,23,1,20,0,0,0,19,1,23,23
23,23,1,13,0,0,0,13,1,23,23
23,23,1,1,1,26,1,1,1,23,23
23,23,23,23,23,23,23,23,23,23,23
23,23,23,23,23,23,23,23,23,23,23
endlayer

layer
23,23,23,23,23,23,23,23,23,23,23
23,23,23,23,23,23,23,23,23,23,23
23,23,1,1,1,26,1,1,1,23,23
23,23,1,13,25,0,0,13,1,23,23
23,23,1,0,0,0,0,0,1,23,23
23,23,26,0,0,0,0,0,26,23,23
23,23,26,0,0,0,0,0,26,23,23
23,23,1,0,0,0,0,0,1,23,23
23,23,1,13,0,0,0,13,1,23,23
23,23,1,1,1,26,1,1,1,23,23
23,23,23,23,23,23,23,23,23,23,23
23,23,23,23,23,23,23,23,23,23,23
endlayer

layer
23,23,23,23,23,23,23,23,23,23,23
23,23,23,23,23,23,23,23,23,23,23
23,23,1,1,1,27,1,1,1,23,23
23,23,1,13,25,0,0,13,1,23,23
23,23,1,0,0,0,0,0,1,23,23
23,23,28,0,0,0,0,0,28,23,23
23,23,27,0,0,0,0,0,27,23,23
23,23,1,0,0,0,0,0,1,23,23
23,23,1,13,0,0,0,13,1,23,23
23,23,1,1,1,28,1,1,1,23,23
23,23,23,23,23,23,23,23,23,23,23
23,23,23,23,23,23,23,23,23,23,23
endlayer

layer
23,23,23,23,23,23,23,23,23,23,23
23,23,23,23,23,23,23,23,23,23,23
23,23,17,1,1,1,1,1,1,23,23
23,23,1,1,25,1,1,1,1,23,23
23,23,1,1,1,1,1,1,1,23,23
23,23,1,1,1,1,1,1,1,23,23
23,23,1,1,1,1,1,1,1,23,23
23,23,1,1,1,1,1,1,1,23,23
23,23,1,1,1,1,1,1,1,23,23
23,23,1,1,1,1,1,1,1,23,23
23,23,23,23,23,23,23,23,23,23,23
23,23,23,23,23,23,23,23,23,23,23
endlayer

layer
23,23,23,23,23,23,23,23,23,23,23
23,23,23,23,23,23,23,23,23,23,23
23,23,1,1,1,1,1,1,1,23,23
23,23,1,13,0,0,0,13,1,23,23
23,23,1,0,0,0,0,0,1,23,23
23,23,1,6,0,0,0,0,1,23,23
23,23,1,1,0,0,0,0,1,23,23
23,23,1,7,0,0,0,0,1,23,23
23,23,1,13,0,0,0,13,1,23,23
23,23,1,1,1,1,1,1,1,23,23
23,23,23,23,23,23,23,23,23,23,23
23,23,23,23,23,23,23,23,23,23,23
endlayer

layer
23,23,23,23,23,23,23,23,23,23,23
23,23,23,23,23,23,23,23,23,23,23
23,23,1,1,1,26,1,1,1,23,23
23,23,1,13,18,0,18,13,1,23,23
23,23,1,0,0,0,0,0,1,23,23
23,23,26,0,0,0,0,0,26,23,23
23,23,26,6,0,0,0,0,26,23,23
23,23,1,1,0,0,0,0,1,23,23
23,23,1,13,21,0,21,13,17,23,23
23,23,17,1,1,26,1,1,1,23,23
23,23,23,23,23,23,23,23,23,23,23
23,23,23,23,23,23,23,23,23,23,23
endlayer

layer
23,23,23,23,23,23,23,23,23,23,23
23,23,23,23,23,23,23,23,23,23,23
23,23,1,1,1,26,1,1,1,23,23
23,23,1,13,0,0,0,13,1,23,23
23,23,1,0,0,0,0,0,1,23,23
23,23,26,0,0,0,0,0,26,23,23
23,23,26,0,0,0,0,0,26,23,23
23,23,1,6,0,0,0,0,1,23,23
23,23,1,13,0,0,0,13,1,23,23
23,23,1,1,1,26,1,1,1,23,23
23,23,23,23,23,23,23,23,23,23,23
23,23,23,23,23,23,23,23,23,23,23
endlayer

layer
23,23,23,23,23,23,23,23,23,23,23
23,23,23,23,23,23,23,23,23,23,23
23,23,1,1,17,1,1,1,1,23,23
23,23,1,29,1,16,1,29,1,23,23
23,23,1,1,16,1,16,1,1,23,23
23,23,1,0,1,16,1,16,1,23,23
23,23,1,0,16,1,16,1,1,23,23
23,23,1,0,1,16,1,16,1,23,23
23,23,1,6,16,1,16,1,1,23,23
23,23,1,1,1,1,1,1,1,23,23
23,23,23,23,23,23,23,23,23,23,23
23,23,23,23,23,23,23,23,23,23,23
endlayer

layer
23,23,23,23,23,23,23,23,23,23,23
23,23,23,23,23,23,23,23,23,23,23
23,23,1,1,1,1,1,1,1,23,23
23,23,1,0,0,0,0,0,1,23,23
23,23,1,0,0,0,0,0,1,23,23
23,23,1,0,0,0,0,30,1,23,23
23,23,1,0,0,0,0,30,1,23,23
23,23,1,0,0,0,0,0,1,23,23
23,23,1,0,0,0,0,0,1,23,23
23,23,1,1,1,1,1,1,1,23,23
23,23,23,23,23,23,23,23,23,23,23
23,23,23,23,23,23,23,23,23,23,23
endlayer

layer
23,23,23,23,23,23,23,23,23,23,23
23,23,23,23,23,23,23,23,23,23,23
23,23,1,0,1,0,1,0,1,23,23
23,23,0,0,0,0,0,0,0,23,23
23,23,1,0,0,0,0,0,1,23,23
23,23,0,0,0,0,0,0,0,23,23
23,23,0,0,0,0,0,0,0,23,23
23,23,1,0,0,0,0,0,1,23,23
23,23,0,0,0,0,0,0,0,23,23
23,23,1,0,1,0,17,0,1,23,23
23,23,23,23,23,23,23,23,23,23,23
23,23,23,23,23,23,23,23,23,23,23
endlayer

layer
23,23,23,23,23,23,23,23,23,23,23
23,23,23,23,23,23,23,23,23,23,23
23,23,1,0,1,0,1,0,1,23,23
23,23,0,0,0,0,0,0,0,23,23
23,23,1,20,0,0,0,19,1,23,23
23,23,0,0,0,0,0,0,0,23,23
23,23,0,0,0,0,0,0,0,23,23
23,23,1,20,0,0,0,19,1,23,23
23,23,0,0,0,0,0,0,0,23,23
23,23,1,0,1,0,1,0,1,23,23
23,23,23,23,23,23,23,23,23,23,23
23,23,23,23,23,23,23,23,23,23,23
endlayer

layer
23,23,23,23,23,23,23,23,23,23,23
23,23,23,23,23,23,23,23,23,23,23
23,23,1,1,1,27,1,1,1,23,23
23,23,1,0,0,0,0,0,1,23,23
23,23,1,0,0,0,0,0,17,23,23
23,23,28,0,0,0,0,0,28,23,23
23,23,27,0,0,0,0,0,27,23,23
23,23,1,0,0,0,0,0,1,23,23
23,23,1,0,0,0,0,0,1,23,23
23,23,1,1,1,28,1,1,1,23,23
23,23,23,23,23,23,23,23,23,23,23
23,23,23,23,23,23,23,23,23,23,23
endlayer

layer
23,23,23,23,23,23,23,23,23,23,23
23,23,23,27,23,23,23,27,23,23,23
23,23,1,1,1,1,1,1,1,23,23
23,32,1,0,0,0,0,0,1,31,23
23,23,1,0,0,0,0,0,1,23,23
23,23,1,0,0,0,0,0,1,23,23
23,23,1,0,0,0,0,0,1,23,23
23,23,1,0,0,0,0,0,1,23,23
23,32,1,0,0,0,0,0,1,31,23
23,23,1,1,1,1,1,1,1,23,23
23,23,23,28,23,23,23,28,23,23,23
23,23,23,23,23,23,23,23,23,23,23
endlayer

layer
23,23,23,23,23,23,23,23,23,23,23
23,1,1,1,1,1,1,1,1,17,23
23,1,1,1,1,1,1,1,1,1,23
23,17,1,1,1,1,1,1,1,1,23
23,1,1,1,1,1,1,1,1,1,23
23,1,1,1,1,1,1,1,1,1,23
23,1,1,1,1,1,1,1,1,1,23
23,1,1,1,1,1,1,1,1,1,23
23,1,1,1,1,1,1,1,1,1,23
23,1,1,1,1,1,1,1,1,1,23
23,1,1,1,1,1,1,1,17,1,23
23,23,23,23,23,23,23,23,23,23,23
endlayer

layer
23,23,23,23,23,23,23,23,23,23,23
23,1,17,1,1,1,1,1,1,1,23
23,1,33,33,33,33,33,33,33,1,23
23,1,33,33,34,34,34,33,33,1,23
23,1,33,34,34,34,34,34,33,1,23
23,1,33,34,34,34,34,34,33,1,23
23,1,33,34,34,34,34,34,33,1,23
23,1,33,34,34,34,34,34,33,1,23
23,1,33,33,34,34,34,33,33,1,23
23,17,33,33,33,33,33,33,33,1,23
23,1,1,1,1,1,1,1,1,1,23
23,23,23,23,23,23,23,23,23,23,23
endlayer

layer
23,23,23,23,23,23,23,23,23,23,23
23,1,1,24,1,24,1,24,1,1,23
23,1,0,0,0,0,0,0,0,1,23
23,24,0,0,34,34,34,0,0,24,23
23,1,0,34,35,35,35,34,0,1,23
23,24,0,34,35,35,35,34,0,24,23
23,24,0,34,35,35,35,34,0,24,23
23,1,0,34,35,35,35,34,0,17,23
23,24,0,0,34,34,34,0,0,24,23
23,1,0,0,0,0,0,0,0,1,23
23,1,17,24,1,24,1,24,1,1,23
23,23,23,23,23,23,23,23,23,23,23
endlayer

layer
23,23,23,23,23,23,23,23,23,23,23
23,24,24,0,24,0,24,0,24,24,23
23,24,0,0,0,0,0,0,0,24,23
23,0,0,0,34,34,34,0,0,0,23
23,24,0,34,35,35,35,34,0,24,23
23,0,0,34,35,35,35,34,0,0,23
23,0,0,34,35,35,35,34,0,0,23
23,24,0,34,35,35,35,34,0,24,23
23,0,0,0,34,34,34,0,0,0,23
23,24,0,0,0,0,0,0,0,24,23
23,24,24,0,24,0,24,0,24,24,23
23,23,23,23,23,23,23,23,23,23,23
endlayer

layer
0,0,0,0,0,0,0,0,0,0,0
0,0,0,0,0,0,0,0,0,0,0
0,0,0,0,0,0,0,0,0,0,0
0,0,0,0,34,34,34,0,0,0,0
0,0,0,34,35,35,35,34,0,0,0
0,0,0,34,35,35,35,34,0,0,0
0,0,0,34,35,35,35,34,0,0,0
0,0,0,34,35,35,35,34,0,0,0
0,0,0,0,34,34,34,0,0,0,0
0,0,0,0,0,0,0,0,0,0,0
0,0,0,0,0,0,0,0,0,0,0
0,0,0,0,0,0,0,0,0,0,0
endlayer

layer
0,0,0,0,0,0,0,0,0,0,0
0,0,0,0,0,0,0,0,0,0,0
0,0,0,0,0,0,0,0,0,0,0
0,0,0,0,34,34,34,0,0,0,0
0,0,0,34,35,35,35,34,0,0,0
0,0,0,34,35,35,35,34,0,0,0
0,0,0,34,35,35,35,34,0,0,0
0,0,0,34,35,35,35,34,0,0,0
0,0,0,0,34,34,34,0,0,0,0
0,0,0,0,0,0,0,0,0,0,0
0,0,0,0,0,0,0,0,0,0,0
0,0,0,0,0,0,0,0,0,0,0
endlayer

layer
0,0,0,0,0,0,0,0,0,0,0
0,0,0,0,0,0,0,0,0,0,0
0,0,0,0,0,0,0,0,0,0,0
0,0,0,0,36,34,36,0,0,0,0
0,0,0,36,34,34,34,36,0,0,0
0,0,0,34,34,34,34,34,0,0,0
0,0,0,34,34,34,34,34,0,0,0
0,0,0,36,34,34,34,36,0,0,0
0,0,0,0,36,34,36,0,0,0,0
0,0,0,0,0,0,0,0,0,0,0
0,0,0,0,0,0,0,0,0,0,0
0,0,0,0,0,0,0,0,0,0,0
endlayer

layer
0,0,0,0,0,0,0,0,0,0,0
0,0,0,0,0,0,0,0,0,0,0
0,0,0,0,0,0,0,0,0,0,0
0,0,0,0,0,36,0,0,0,0,0
0,0,0,0,34,34,34,0,0,0,0
0,0,0,36,34,34,34,36,0,0,0
0,0,0,36,34,34,34,36,0,0,0
0,0,0,0,34,34,34,0,0,0,0
0,0,0,0,0,36,0,0,0,0,0
0,0,0,0,0,0,0,0,0,0,0
0,0,0,0,0,0,0,0,0,0,0
0,0,0,0,0,0,0,0,0,0,0
endlayer

layer
0,0,0,0,0,0,0,0,0,0,0
0,0,0,0,0,0,0,0,0,0,0
0,0,0,0,0,0,0,0,0,0,0
0,0,0,0,0,0,0,0,0,0,0
0,0,0,0,36,34,36,0,0,0,0
0,0,0,0,34,34,34,0,0,0,0
0,0,0,0,34,34,34,0,0,0,0
0,0,0,0,36,34,36,0,0,0,0
0,0,0,0,0,0,0,0,0,0,0
0,0,0,0,0,0,0,0,0,0,0
0,0,0,0,0,0,0,0,0,0,0
0,0,0,0,0,0,0,0,0,0,0
endlayer

layer
0,0,0,0,0,0,0,0,0,0,0
0,0,0,0,0,0,0,0,0,0,0
0,0,0,0,0,0,0,0,0,0,0
0,0,0,0,0,0,0,0,0,0,0
0,0,0,0,0,36,0,0,0,0,0
0,0,0,0,36,34,36,0,0,0,0
0,0,0,0,36,34,36,0,0,0,0
0,0,0,0,0,36,0,0,0,0,0
0,0,0,0,0,0,0,0,0,0,0
0,0,0,0,0,0,0,0,0,0,0
0,0,0,0,0,0,0,0,0,0,0
0,0,0,0,0,0,0,0,0,0,0
endlayer

layer
0,0,0,0,0,0,0,0,0,0,0
0,0,0,0,0,0,0,0,0,0,0
0,0,0,0,0,0,0,0,0,0,0
0,0,0,0,0,0,0,0,0,0,0
0,0,0,0,0,0,0,0,0,0,0
0,0,0,0,0,37,0,0,0,0,0
0,0,0,0,0,37,0,0,0,0,0
0,0,0,0,0,0,0,0,0,0,0
0,0,0,0,0,0,0,0,0,0,0
0,0,0,0,0,0,0,0,0,0,0
0,0,0,0,0,0,0,0,0,0,0
0,0,0,0,0,0,0,0,0,0,0
endlayer

layer
0,0,0,0,0,0,0,0,0,0,0
0,0,0,0,0,0,0,0,0,0,0
0,0,0,0,0,0,0,0,0,0,0
0,0,0,0,0,0,0,0,0,0,0
0,0,0,0,0,0,0,0,0,0,0
0,0,0,0,0,37,0,0,0,0,0
0,0,0,0,0,37,0,0,0,0,0
0,0,0,0,0,0,0,0,0,0,0
0,0,0,0,0,0,0,0,0,0,0
0,0,0,0,0,0,0,0,0,0,0
0,0,0,0,0,0,0,0,0,0,0
0,0,0,0,0,0,0,0,0,0,0
endlayer

