# Small Tower No. 1 10/26/2014
# Created by Ruins mod version 13.8 Ingame Parser
# authoring Player: Kujaku10

# Updated to MC 1.11: 17 Jan 2017
# Updated to MC 1.12: 23 Jun 2017

weight=1
embed_into_distance=9

biomesToSpawnIn=alps,alps forest,alpine,alps_foothills,birch forest,birch_forest,cherry blossom grove,cherry_blossom_grove,clearing,dead forest,dead_forest,dead swamp,dead_swamp,deadlands,desert,eerie,eldritch,extreme hills,extreme_hills,extreme_hills_with_trees,extreme hills edge,extreme hills m,extreme hills+,extreme hills+ m,forest,foresthills,forest_hills,green hills,magical forest,magical_forest,meadow,mega taiga hills,mountain,mountain ridge,mountain_ridge,mutated_extreme_hills,mutated_extreme_hills_with_trees,mystic grove,mystic_grove,ominous woods,ominous_woods,origin_island,pasture,prairie,redwood_taiga,redwood_taiga_hills,seasonal_forest,shield,scrubland,shrubland,silkglades,taiga,taigahills,taiga_hills,tainted land,thinned mystic grove,thinned timber,twilight clearing,twilight_clearing,wonderous woods,woodland,woodlands

acceptable_target_blocks=

unacceptable_target_blocks=flowing_water,water,flowing_lava,lava,cloud,Natura:Cloud,slime_congealed,slime_dirt,slime_grass,command_block,planks,planks2,concrete,cobblestone,stonebrick,brick_block,glass,torch,oak_stairs,stone_stairs,brick_stairs,stone_brick_stairs,nether_brick_stairs,sandstone_stairs,spruce_stairs,birch_stairs,jungle_stairs,quartz_stairs,acacia_stairs,dark_oak_stairs,cobblestone_wall,stone_slab,double_stone_slab,stone_slab2,wooden_slab,double_wooden_slab,nether_brick,fence

dimensions=29,9,9
allowable_overhang=0
max_leveling=9
leveling_buffer=-1
preserve_water=0
preserve_lava=0
preserve_plants=1

rule1=0,100,preserveBlock

rule2=0,100,minecraft:stonebrick-0,minecraft:stonebrick-0,minecraft:stonebrick-0,minecraft:stonebrick-1,minecraft:stonebrick-2

rule3=0,100,ChestGenHook:chests/simple_dungeon:3-3
rule4=0,100,minecraft:stone_brick_stairs-1
rule5=0,100,ChestGenHook:chests/simple_dungeon:3-2
rule6=0,100,ChestGenHook:chests/simple_dungeon:3-4
rule7=0,100,minecraft:stone_brick_stairs-3

rule8=0,100,MobSpawner:Skeleton,MobSpawner:Zombie,MobSpawner:Spider

rule9=0,100,minecraft:web-0
rule10=2,100,minecraft:redstone_torch-3
rule11=2,100,minecraft:redstone_torch-4
rule12=0,100,minecraft:stone_brick_stairs-0
rule13=0,100,minecraft:stone_brick_stairs-2

rule14=0,100,Skull:0:0-5
rule15=0,100,Skull:0:0-3
rule16=0,100,Skull:0:0-2
rule17=0,100,Skull:0:0-4

rule18=0,100,minecraft:dark_oak_door-3
rule19=0,100,minecraft:stone_brick_stairs-4
rule20=0,100,minecraft:stone_brick_stairs-6
rule21=0,100,minecraft:stone_brick_stairs-7
rule22=0,100,minecraft:dark_oak_door-8
rule23=0,100,minecraft:dark_oak_door-9
rule24=0,100,minecraft:stone_brick_stairs-5
rule25=0,100,minecraft:stone_slab-5
rule26=0,100,minecraft:dark_oak_door-2
rule27=0,100,minecraft:dark_oak_fence-0
rule28=0,100,minecraft:stone_slab-0

layer
1,1,1,2,2,2,2,1,1
1,1,2,2,2,2,2,1,1
1,2,2,2,2,2,2,2,1
2,2,2,2,2,2,2,2,2
2,2,2,2,2,2,2,2,2
2,2,2,2,2,2,2,2,2
1,2,2,2,2,2,2,2,1
1,1,2,2,2,2,2,1,1
1,1,1,2,2,2,1,1,1
endlayer

layer
1,1,1,2,2,2,1,1,1
1,1,2,2,2,2,2,1,1
1,2,2,2,2,2,2,2,1
2,2,2,2,2,2,2,2,2
2,5,4,4,2,0,0,3,2
2,2,0,0,0,0,0,2,2
1,2,2,0,0,0,2,2,1
1,1,2,2,6,2,2,1,1
1,1,1,2,2,2,1,1,1
endlayer

layer
1,1,1,2,2,2,1,1,1
1,1,2,2,2,2,2,1,1
1,2,2,0,7,2,2,2,1
2,2,0,0,7,2,2,2,2
2,8,0,0,2,9,0,8,2
2,2,0,0,0,0,10,2,2
1,2,2,0,0,9,2,2,1
1,1,2,2,8,2,2,1,1
1,1,1,2,2,2,1,1,1
endlayer

layer
1,1,1,2,2,2,1,1,1
1,1,2,2,2,2,2,1,1
1,2,2,0,0,0,2,2,1
2,2,11,0,0,0,0,2,2
2,2,0,0,2,12,12,2,2
2,2,11,0,0,2,2,2,2
1,2,2,9,0,2,2,2,1
1,1,2,2,2,2,2,1,1
1,1,1,2,2,2,1,1,1
endlayer

layer
1,1,1,2,2,2,1,1,1
1,1,2,2,2,2,2,1,1
1,2,2,9,0,0,2,2,1
2,2,0,0,0,0,0,2,2
2,2,9,0,2,0,0,2,2
2,2,2,2,13,0,0,2,2
1,2,2,2,13,0,2,2,1
1,1,2,2,2,2,2,1,1
1,1,1,2,2,2,1,1,1
endlayer

layer
1,1,1,2,2,2,1,1,1
1,1,2,2,14,2,2,1,1
1,2,2,2,0,9,2,2,1
2,2,2,2,0,0,10,2,2
2,16,4,4,2,0,0,15,2
2,2,0,0,0,0,10,2,2
1,2,2,0,0,0,2,2,1
1,1,2,2,17,2,2,1,1
1,1,1,2,2,2,1,1,1
endlayer

layer
1,1,1,2,2,2,1,1,1
1,1,2,2,9,2,2,1,1
1,2,2,0,7,2,2,2,1
2,2,11,0,7,2,2,2,2
2,0,0,0,2,0,0,9,2
2,2,11,0,0,0,0,2,2
1,2,2,0,0,9,2,2,1
1,1,2,2,9,2,2,1,1
1,1,1,2,2,2,1,1,1
endlayer

layer
1,1,1,2,2,2,1,1,1
1,1,2,2,2,2,2,1,1
1,2,2,0,0,18,2,2,1
2,2,0,0,0,18,0,2,2
2,2,0,0,2,12,12,2,2
2,2,0,0,0,2,2,2,2
1,2,2,9,9,2,2,2,1
1,1,2,2,2,2,2,1,1
1,1,1,2,2,2,1,1,1
endlayer

layer
1,1,1,19,19,19,1,1,1
1,1,21,2,2,2,20,1,1
1,19,2,9,0,22,2,19,1
21,2,0,0,0,23,0,2,20
21,2,9,0,2,0,0,2,20
21,2,2,2,13,0,0,2,20
1,24,2,2,13,0,2,24,1
1,1,21,2,2,2,20,1,1
1,1,1,24,24,24,1,1,1
endlayer

layer
1,1,1,2,2,2,1,1,1
1,1,25,2,2,2,25,1,1
1,25,2,2,2,2,2,25,1
2,2,2,2,2,0,9,2,2
2,2,4,4,2,0,0,2,2
2,2,0,0,0,0,0,2,2
1,25,2,0,0,0,2,25,1
1,1,25,2,26,2,25,1,1
1,1,1,2,0,2,1,1,1
endlayer

layer
1,1,1,7,2,13,1,1,1
1,1,1,2,2,2,1,1,1
1,1,2,0,7,2,2,1,1
12,2,0,0,7,2,2,2,12
2,2,0,0,2,0,0,2,2
4,2,0,0,0,0,10,2,4
1,1,2,0,0,9,2,1,1
1,1,1,2,22,2,1,1,1
1,1,1,7,0,13,1,1,1
endlayer

layer
1,1,1,1,12,1,1,1,1
1,1,1,2,2,2,1,1,1
1,1,2,0,0,0,2,1,1
1,2,11,0,0,0,0,2,1
7,2,0,0,2,12,12,2,13
1,2,11,0,0,2,2,2,1
1,1,2,9,0,2,2,1,1
1,1,1,2,2,2,1,1,1
1,1,1,1,4,1,1,1,1
endlayer

layer
1,1,1,1,1,1,1,1,1
1,1,1,2,2,2,1,1,1
1,1,2,9,0,0,2,1,1
1,2,9,0,0,0,0,2,1
1,2,0,0,2,0,0,2,1
1,2,2,2,13,0,0,2,1
1,1,2,2,13,0,2,1,1
1,1,1,2,2,2,1,1,1
1,1,1,1,1,1,1,1,1
endlayer

layer
1,1,1,1,1,1,1,1,1
1,1,1,2,27,2,1,1,1
1,1,2,2,0,9,2,1,1
1,2,2,2,0,0,10,2,1
1,27,4,4,2,0,0,27,1
1,2,0,0,0,0,10,2,1
1,1,2,0,0,0,2,1,1
1,1,1,2,27,2,1,1,1
1,1,1,1,1,1,1,1,1
endlayer

layer
1,1,1,1,1,1,1,1,1
1,1,1,2,27,2,1,1,1
1,1,2,0,7,2,2,1,1
1,2,11,0,7,2,2,2,1
1,27,0,0,2,0,0,27,1
1,2,11,0,0,0,0,2,1
1,1,2,0,0,9,2,1,1
1,1,1,2,27,2,1,1,1
1,1,1,1,1,1,1,1,1
endlayer

layer
1,1,1,1,1,1,1,1,1
1,1,1,2,2,2,1,1,1
1,1,2,0,0,0,2,1,1
1,2,0,0,0,0,0,2,1
1,2,0,0,2,12,12,2,1
1,2,0,0,0,2,2,2,1
1,1,2,0,9,2,2,1,1
1,1,1,2,2,2,1,1,1
1,1,1,1,1,1,1,1,1
endlayer

layer
1,1,1,19,19,19,1,1,1
1,1,21,2,2,2,20,1,1
1,19,2,0,0,0,2,19,1
21,2,0,0,0,0,0,2,20
21,2,9,0,2,0,0,2,20
21,2,2,2,13,0,0,2,20
1,24,2,2,13,0,2,24,1
1,1,21,2,2,2,20,1,1
1,1,1,24,24,24,1,1,1
endlayer

layer
1,1,1,28,28,28,1,1,1
1,1,28,2,2,2,28,1,1
1,28,2,2,2,9,2,28,1
28,2,2,2,2,0,10,2,28
28,2,4,4,2,0,0,2,28
28,2,0,0,0,0,10,2,28
1,28,2,0,0,0,2,28,1
1,1,28,2,2,2,28,1,1
1,1,1,28,28,28,1,1,1
endlayer

layer
1,1,1,1,1,1,1,1,1
1,1,1,2,2,2,1,1,1
1,1,2,0,7,2,2,1,1
1,2,0,0,7,2,2,2,1
1,2,0,0,2,0,0,2,1
1,2,0,0,0,0,0,2,1
1,1,2,0,0,9,2,1,1
1,1,1,2,2,2,1,1,1
1,1,1,1,1,1,1,1,1
endlayer

layer
1,1,1,1,1,1,1,1,1
1,1,1,2,27,2,1,1,1
1,1,2,0,0,0,2,1,1
1,2,11,0,0,0,0,2,1
1,27,0,0,2,12,12,27,1
1,2,11,0,0,2,2,2,1
1,1,2,9,0,2,2,1,1
1,1,1,2,27,2,1,1,1
1,1,1,1,1,1,1,1,1
endlayer

layer
1,1,1,1,1,1,1,1,1
1,1,1,2,27,2,1,1,1
1,1,2,0,0,0,2,1,1
1,2,0,0,0,0,10,2,1
1,27,0,0,2,0,0,27,1
1,2,2,2,13,0,10,2,1
1,1,2,2,13,0,2,1,1
1,1,1,2,27,2,1,1,1
1,1,1,1,1,1,1,1,1
endlayer

layer
1,1,1,1,1,1,1,1,1
1,1,1,2,2,2,1,1,1
1,1,2,2,9,0,2,1,1
1,2,2,2,0,0,0,2,1
1,2,4,4,2,0,0,2,1
1,2,0,0,0,0,0,2,1
1,1,2,0,0,0,2,1,1
1,1,1,2,2,2,1,1,1
1,1,1,1,1,1,1,1,1
endlayer

layer
1,1,1,1,1,1,1,1,1
1,1,1,2,2,2,1,1,1
1,1,2,0,7,2,2,1,1
1,2,11,0,7,2,2,2,1
1,2,0,0,2,0,9,2,1
1,2,11,0,0,0,0,2,1
1,1,2,0,0,0,2,1,1
1,1,1,2,2,2,1,1,1
1,1,1,1,1,1,1,1,1
endlayer

layer
1,1,1,19,19,19,1,1,1
1,1,21,2,2,2,20,1,1
1,19,2,0,0,0,2,19,1
21,2,9,0,0,0,0,2,20
21,2,0,0,2,12,12,2,20
21,2,0,0,0,2,2,2,20
1,24,2,9,0,2,2,24,1
1,1,21,2,2,2,20,1,1
1,1,1,24,24,24,1,1,1
endlayer

layer
1,1,1,28,28,28,1,1,1
1,1,28,2,2,2,28,1,1
1,28,2,9,0,0,2,28,1
28,2,2,0,0,0,10,2,28
28,2,2,2,2,0,0,2,28
28,2,2,2,13,0,10,2,28
1,28,2,2,13,0,2,28,1
1,1,28,2,2,2,28,1,1
1,1,1,28,28,28,1,1,1
endlayer

layer
1,1,2,2,2,2,2,1,1
1,2,2,2,2,2,2,2,1
2,2,2,2,0,9,2,2,2
2,2,2,2,0,0,9,2,2
2,2,4,4,2,0,0,2,2
2,2,0,0,0,0,9,2,2
2,2,2,0,0,0,2,2,2
1,2,2,2,2,2,2,2,1
1,1,2,2,2,2,2,1,1
endlayer

layer
1,1,2,2,2,2,2,1,1
1,2,25,25,25,25,25,2,1
2,25,25,25,25,25,25,25,2
2,25,25,25,25,25,25,25,2
2,25,0,0,25,25,25,25,2
2,25,0,0,0,0,25,25,2
2,25,25,0,0,0,25,25,2
1,2,25,25,25,25,25,2,1
1,1,2,2,2,2,2,1,1
endlayer

layer
1,1,25,2,25,2,25,1,1
1,2,0,0,0,0,0,2,1
25,0,0,0,0,0,0,0,25
2,0,0,0,0,0,0,0,2
25,0,0,0,0,0,0,0,25
2,0,0,0,0,0,0,0,2
25,0,0,0,0,0,0,0,25
1,2,0,0,0,0,0,2,1
1,1,25,2,25,2,25,1,1
endlayer

layer
1,1,0,25,0,25,0,1,1
1,25,0,0,0,0,0,25,1
0,0,0,0,0,0,0,0,0
25,0,0,0,0,0,0,0,25
0,0,0,0,0,0,0,0,0
25,0,0,0,0,0,0,0,25
0,0,0,0,0,0,0,0,0
1,25,0,0,0,0,0,25,1
1,1,0,25,0,25,0,1,1
endlayer

