# Kujaku Tower #4
# Created by Ruins mod version 16.4 Ingame Parser
# authoring Player: Kujaku10
# Created for MC 1.11: 15 Jan 2017
# Last Updated: 16 Apr 2017
# Updated to MC 1.12: 23 Jun 2017
# Updated to MC 1.12.1: 10 Sep 2017

biomesToSpawnIn=birch forest,birch_forest,birch forest hills,birch_forest_hills,birch forest hills m,birch forest m,boreal forest,boreal_forest,brushland,chaparral,cold taiga,cold taiga hills,cold taiga m,coniferous forest,coniferous_forest,dead forest,extreme hills edge,forest,foresthills,grassland,grove,heathland,highland,ice mountains,maple woods,mega taiga,mega taiga hills,mountain,mountain foothills,mutated_birch_forest,mutated_birch_forest_hills,mutated_taiga,mutated_redwood_taiga,mutated_redwood_taiga_hills,mystic_grove,ominous woods,ominous_woods,origin_island,redwood_taiga,redwood_taiga_hills,redwood taiga hills m,smaller_extreme_hills,steppe,taiga,taiga m,taigahills,xeric shrubland,xeric_shrubland

weight=1
embed_into_distance=63
acceptable_target_blocks=

unacceptable_target_blocks=flowing_water,water,flowing_lava,lava,cloud,slime_congealed,slime_dirt,slime_grass,command_block,planks,planks2,concrete,cobblestone,stonebrick,brick_block,glass,torch,oak_stairs,stone_stairs,brick_stairs,stone_brick_stairs,nether_brick_stairs,sandstone_stairs,spruce_stairs,birch_stairs,jungle_stairs,quartz_stairs,acacia_stairs,dark_oak_stairs,cobblestone_wall,stone_slab,double_stone_slab,stone_slab2,wooden_slab,double_wooden_slab,nether_brick,fence

dimensions=95,13,13
allowable_overhang=0
max_leveling=33
leveling_buffer=-1
preserve_water=0
preserve_lava=0
preserve_plants=1

# Bottom layer is "preserveBlock" to make sure if this is too deep,
# there's still a layer of bedrock.
rule1=0,100,preserveBlock

# Below-ground preserve terrain
rule2=0,100,preserveBlock

# Below-ground walls
rule3=0,100,minecraft:stonebrick-1,minecraft:stonebrick-1,minecraft:stonebrick-0,minecraft:stonebrick-2

rule4=0,100,minecraft:water-9
rule5=0,100,minecraft:stone-2

# Chiseled Stone
rule6=0,100,minecraft:stonebrick-3

rule7=0,100,minecraft:stone_stairs-1
rule8=0,100,minecraft:stone_stairs-3

rule9=0,100,minecraft:cobblestone_wall-0,minecraft:cobblestone_wall-0,minecraft:cobblestone_wall-1

rule10=0,100,minecraft:stone_stairs-2
rule11=0,100,minecraft:stone_stairs-0

# Standing Torch
rule12=1,100,minecraft:torch-5

rule13=0,100,minecraft:stone_stairs-6
rule14=0,100,minecraft:stone_stairs-5
rule15=0,100,minecraft:stone_stairs-7
rule16=0,100,minecraft:stone_stairs-4

rule17=0,100,IInventory;minecraft:chest;minecraft:apple#4#0#1+minecraft:apple#4#0#8+minecraft:apple#4#0#14+minecraft:apple#4#0#21-5
rule18=0,100,IInventory;minecraft:chest;minecraft:leather#2#0#0+minecraft:leather#2#0#6+minecraft:leather#2#0#11+minecraft:leather#2#0#24-5
rule19=0,100,IInventory;minecraft:chest;minecraft:mossy_cobblestone#4#0#6+minecraft:mossy_cobblestone#4#0#12+minecraft:mossy_cobblestone#4#0#19+minecraft:mossy_cobblestone#4#0#26-3
rule20=0,100,Skull:0:12-1
rule21=0,100,IInventory;minecraft:chest;minecraft:log#4#0#7+minecraft:log#4#0#11+minecraft:log#4#0#18+minecraft:log#4#0#23-2

rule22=0,100,Skull:0:0-1
rule23=0,100,Skull:0:8-1

rule24=0,100,IInventory;minecraft:chest;minecraft:stonebrick#4#1#0+minecraft:stonebrick#4#1#8+minecraft:stonebrick#4#1#12+minecraft:stonebrick#4#1#23-3

rule25=0,100,Skull:0:4-1

rule26=0,100,IInventory;minecraft:chest;minecraft:stone#4#0#7+minecraft:stone#4#0#11+minecraft:stone#4#0#19+minecraft:stone#4#0#23-2
rule27=0,100,IInventory;minecraft:chest;minecraft:clay#2#0#7+minecraft:clay#2#0#12+minecraft:clay#2#0#19+minecraft:clay#2#0#24-4
rule28=0,100,IInventory;minecraft:chest;minecraft:grass#2#0#7+minecraft:grass#2#0#11+minecraft:grass#2#0#18+minecraft:grass#2#0#23-4

rule29=0,100,minecraft:stone_brick_stairs-6
rule30=0,100,minecraft:stone_brick_stairs-3
rule31=2,100,minecraft:torch-1
rule32=0,100,minecraft:stonebrick-0
rule33=0,100,minecraft:stone_brick_stairs-5
rule34=0,100,minecraft:stone_brick_stairs-0
rule35=2,100,minecraft:torch-2
rule36=0,100,minecraft:stone_brick_stairs-7
rule37=0,100,minecraft:stone_brick_stairs-2
rule38=0,100,minecraft:stone_brick_stairs-4
rule39=0,100,minecraft:stone_brick_stairs-1
rule40=0,100,minecraft:water-0
rule41=0,100,minecraft:water-1
rule42=0,100,minecraft:cobblestone-0

rule43=0,100,preserveBlock

rule44=0,100,minecraft:stonebrick-2
rule45=0,100,minecraft:spruce_door-2
rule46=0,100,minecraft:spruce_door-8
rule47=2,100,minecraft:torch-4
rule48=2,100,minecraft:torch-3
rule49=0,100,minecraft:stone_slab-0
rule50=0,100,minecraft:ladder-3
rule51=0,100,minecraft:ladder-5
rule52=0,100,minecraft:sandstone_stairs-4
rule53=0,100,minecraft:sandstone_stairs-6
rule54=0,100,minecraft:sandstone_stairs-7
rule55=0,100,minecraft:stone_slab-1
rule56=0,100,minecraft:sandstone_stairs-5
rule57=0,100,minecraft:sandstone-2
rule58=0,100,minecraft:sandstone_stairs-2
rule59=0,100,minecraft:sandstone_stairs-0
rule60=0,100,minecraft:sandstone_stairs-3
rule61=0,100,minecraft:sandstone_stairs-1

layer
1,1,1,1,1,1,1,1,1,1,1,1,1
1,1,1,1,1,1,1,1,1,1,1,1,1
1,1,1,1,1,1,1,1,1,1,1,1,1
1,1,1,1,1,1,1,1,1,1,1,1,1
1,1,1,1,1,1,1,1,1,1,1,1,1
1,1,1,1,1,1,1,1,1,1,1,1,1
1,1,1,1,1,1,1,1,1,1,1,1,1
1,1,1,1,1,1,1,1,1,1,1,1,1
1,1,1,1,1,1,1,1,1,1,1,1,1
1,1,1,1,1,1,1,1,1,1,1,1,1
1,1,1,1,1,1,1,1,1,1,1,1,1
1,1,1,1,1,1,1,1,1,1,1,1,1
1,1,1,1,1,1,1,1,1,1,1,1,1
endlayer

layer
2,2,3,3,3,3,2,3,3,3,3,2,2
2,3,3,4,4,3,3,3,4,4,3,3,2
3,3,5,5,5,5,3,5,5,5,5,3,3
3,4,5,6,6,6,5,6,6,6,5,4,3
3,4,5,6,5,5,6,5,5,6,5,4,3
3,3,5,6,5,6,5,6,5,6,5,3,3
2,3,3,5,6,5,6,5,6,5,3,3,2
3,3,5,6,5,6,5,6,5,6,5,3,3
3,4,5,6,5,5,6,5,5,6,5,4,3
3,4,5,6,6,6,5,6,6,6,5,4,3
3,3,5,5,5,5,3,5,5,5,5,3,3
2,3,3,4,4,3,3,3,4,4,3,3,2
2,2,3,3,3,3,2,3,3,3,3,2,2
endlayer

layer
2,2,3,3,3,3,2,3,3,3,3,2,2
2,3,3,4,4,3,3,3,4,4,3,3,2
3,3,0,0,0,0,7,0,0,0,0,3,3
3,4,0,0,0,0,0,0,0,0,0,4,3
3,4,0,0,0,0,0,0,0,0,0,4,3
3,3,0,0,0,0,0,0,0,0,0,3,3
2,3,10,0,0,0,9,0,0,0,8,3,2
3,3,0,0,0,0,0,0,0,0,0,3,3
3,4,0,0,0,0,0,0,0,0,0,4,3
3,4,0,0,0,0,0,0,0,0,0,4,3
3,3,0,0,0,0,11,0,0,0,0,3,3
2,3,3,4,4,3,3,3,4,4,3,3,2
2,2,3,3,3,3,2,3,3,3,3,2,2
endlayer

layer
2,2,3,3,3,3,2,3,3,3,3,2,2
2,3,3,4,4,3,3,3,4,4,3,3,2
3,3,0,0,0,0,9,0,0,0,0,3,3
3,4,0,0,0,0,0,0,0,0,0,4,3
3,4,0,0,0,0,0,0,0,0,0,4,3
3,3,0,0,0,0,0,0,0,0,0,3,3
2,3,9,0,0,0,12,0,0,0,9,3,2
3,3,0,0,0,0,0,0,0,0,0,3,3
3,4,0,0,0,0,0,0,0,0,0,4,3
3,4,0,0,0,0,0,0,0,0,0,4,3
3,3,0,0,0,0,9,0,0,0,0,3,3
2,3,3,4,4,3,3,3,4,4,3,3,2
2,2,3,3,3,3,2,3,3,3,3,2,2
endlayer

layer
2,2,3,3,3,3,2,3,3,3,3,2,2
2,3,3,4,4,3,3,3,4,4,3,3,2
3,3,0,0,0,0,9,0,0,0,0,3,3
3,4,0,0,0,0,0,0,0,0,0,4,3
3,4,0,0,0,0,0,0,0,0,0,4,3
3,3,0,0,0,0,0,0,0,0,0,3,3
2,3,9,0,0,0,0,0,0,0,9,3,2
3,3,0,0,0,0,0,0,0,0,0,3,3
3,4,0,0,0,0,0,0,0,0,0,4,3
3,4,0,0,0,0,0,0,0,0,0,4,3
3,3,0,0,0,0,9,0,0,0,0,3,3
2,3,3,4,4,3,3,3,4,4,3,3,2
2,2,3,3,3,3,2,3,3,3,3,2,2
endlayer

layer
2,2,3,3,3,3,2,3,3,3,3,2,2
2,3,3,4,4,3,3,3,4,4,3,3,2
3,3,0,0,0,0,9,0,0,0,0,3,3
3,4,0,0,0,0,0,0,0,0,0,4,3
3,4,0,0,0,0,0,0,0,0,0,4,3
3,3,0,0,0,0,0,0,0,0,0,3,3
2,3,9,0,0,0,0,0,0,0,9,3,2
3,3,0,0,0,0,0,0,0,0,0,3,3
3,4,0,0,0,0,0,0,0,0,0,4,3
3,4,0,0,0,0,0,0,0,0,0,4,3
3,3,0,0,0,0,9,0,0,0,0,3,3
2,3,3,4,4,3,3,3,4,4,3,3,2
2,2,3,3,3,3,2,3,3,3,3,2,2
endlayer

layer
2,2,3,3,3,3,2,3,3,3,3,2,2
2,3,3,4,4,3,3,3,4,4,3,3,2
3,3,0,0,0,0,9,0,0,0,0,3,3
3,4,0,0,0,0,0,0,0,0,0,4,3
3,4,0,0,0,0,0,0,0,0,0,4,3
3,3,0,0,0,0,0,0,0,0,0,3,3
2,3,9,0,0,0,0,0,0,0,9,3,2
3,3,0,0,0,0,0,0,0,0,0,3,3
3,4,0,0,0,0,0,0,0,0,0,4,3
3,4,0,0,0,0,0,0,0,0,0,4,3
3,3,0,0,0,0,9,0,0,0,0,3,3
2,3,3,4,4,3,3,3,4,4,3,3,2
2,2,3,3,3,3,2,3,3,3,3,2,2
endlayer

layer
2,2,3,3,3,3,2,3,3,3,3,2,2
2,3,3,4,4,3,3,3,4,4,3,3,2
3,3,0,0,0,0,9,0,0,0,0,3,3
3,4,0,0,0,0,0,0,0,0,0,4,3
3,4,0,0,0,0,0,0,0,0,0,4,3
3,3,0,0,0,0,0,0,0,0,0,3,3
2,3,9,0,0,0,0,0,0,0,9,3,2
3,3,0,0,0,0,0,0,0,0,0,3,3
3,4,0,0,0,0,0,0,0,0,0,4,3
3,4,0,0,0,0,0,0,0,0,0,4,3
3,3,0,0,0,0,9,0,0,0,0,3,3
2,3,3,4,4,3,3,3,4,4,3,3,2
2,2,3,3,3,3,2,3,3,3,3,2,2
endlayer

layer
2,2,3,3,3,3,2,3,3,3,3,2,2
2,3,3,4,4,3,3,3,4,4,3,3,2
3,3,0,0,0,0,9,0,0,0,0,3,3
3,4,0,0,0,0,0,0,0,0,0,4,3
3,4,0,0,0,0,0,0,0,0,0,4,3
3,3,0,0,0,0,0,0,0,0,0,3,3
2,3,9,0,0,0,0,0,0,0,9,3,2
3,3,0,0,0,0,0,0,0,0,0,3,3
3,4,0,0,0,0,0,0,0,0,0,4,3
3,4,0,0,0,0,0,0,0,0,0,4,3
3,3,0,0,0,0,9,0,0,0,0,3,3
2,3,3,4,4,3,3,3,4,4,3,3,2
2,2,3,3,3,3,2,3,3,3,3,2,2
endlayer

layer
2,2,3,3,3,3,2,3,3,3,3,2,2
2,3,3,4,4,3,3,3,4,4,3,3,2
3,3,0,0,0,0,9,0,0,0,0,3,3
3,4,0,0,0,0,0,0,0,0,0,4,3
3,4,0,0,0,0,0,0,0,0,0,4,3
3,3,0,0,0,0,0,0,0,0,0,3,3
2,3,9,0,0,0,0,0,0,0,9,3,2
3,3,0,0,0,0,0,0,0,0,0,3,3
3,4,0,0,0,0,0,0,0,0,0,4,3
3,4,0,0,0,0,0,0,0,0,0,4,3
3,3,0,0,0,0,9,0,0,0,0,3,3
2,3,3,4,4,3,3,3,4,4,3,3,2
2,2,3,3,3,3,2,3,3,3,3,2,2
endlayer

layer
2,2,3,3,3,3,2,3,3,3,3,2,2
2,3,3,4,4,3,3,3,4,4,3,3,2
3,3,0,0,0,0,9,0,0,0,0,3,3
3,4,0,0,0,0,0,0,0,0,0,4,3
3,4,0,0,0,0,0,0,0,0,0,4,3
3,3,0,0,0,0,0,0,0,0,0,3,3
2,3,9,0,0,0,0,0,0,0,9,3,2
3,3,0,0,0,0,0,0,0,0,0,3,3
3,4,0,0,0,0,0,0,0,0,0,4,3
3,4,0,0,0,0,0,0,0,0,0,4,3
3,3,0,0,0,0,9,0,0,0,0,3,3
2,3,3,4,4,3,3,3,4,4,3,3,2
2,2,3,3,3,3,2,3,3,3,3,2,2
endlayer

layer
2,2,3,3,3,3,2,3,3,3,3,2,2
2,3,3,4,4,3,3,3,4,4,3,3,2
3,3,0,0,0,0,9,0,0,0,0,3,3
3,4,0,0,0,0,0,0,0,0,0,4,3
3,4,0,0,0,0,0,0,0,0,0,4,3
3,3,0,0,0,0,0,0,0,0,0,3,3
2,3,9,0,0,0,0,0,0,0,9,3,2
3,3,0,0,0,0,0,0,0,0,0,3,3
3,4,0,0,0,0,0,0,0,0,0,4,3
3,4,0,0,0,0,0,0,0,0,0,4,3
3,3,0,0,0,0,9,0,0,0,0,3,3
2,3,3,4,4,3,3,3,4,4,3,3,2
2,2,3,3,3,3,2,3,3,3,3,2,2
endlayer

layer
2,2,3,3,3,3,2,3,3,3,3,2,2
2,3,3,4,4,3,3,3,4,4,3,3,2
3,3,0,0,0,15,14,13,0,0,0,3,3
3,4,0,0,0,0,0,0,0,0,0,4,3
3,4,0,0,0,0,0,0,0,0,0,4,3
3,3,16,0,0,0,0,0,0,0,16,3,3
2,3,13,0,0,0,0,0,0,0,15,3,2
3,3,14,0,0,0,0,0,0,0,14,3,3
3,4,0,0,0,0,0,0,0,0,0,4,3
3,4,0,0,0,0,0,0,0,0,0,4,3
3,3,0,0,0,15,16,13,0,0,0,3,3
2,3,3,4,4,3,3,3,4,4,3,3,2
2,2,3,3,3,3,2,3,3,3,3,2,2
endlayer

layer
2,2,3,3,3,3,2,3,3,3,3,2,2
2,3,3,4,4,3,3,3,4,4,3,3,2
3,3,5,5,5,5,3,5,5,5,5,3,3
3,4,5,6,6,6,5,6,6,6,5,4,3
3,4,5,6,5,5,6,5,5,6,5,4,3
3,3,5,6,5,6,5,6,5,6,5,3,3
2,3,3,5,6,5,6,5,6,5,3,3,2
3,3,5,6,5,6,5,6,5,6,5,3,3
3,4,5,6,5,5,6,5,5,6,5,4,3
3,4,5,6,6,6,5,6,6,6,5,4,3
3,3,5,5,5,5,3,5,5,5,5,3,3
2,3,3,4,4,3,3,3,4,4,3,3,2
2,2,3,3,3,3,2,3,3,3,3,2,2
endlayer

layer
2,2,3,3,3,3,2,3,3,3,3,2,2
2,3,3,4,4,3,3,3,4,4,3,3,2
3,3,0,0,0,0,7,0,0,0,0,3,3
3,4,0,0,0,0,0,0,0,0,0,4,3
3,4,0,0,0,0,0,0,0,0,0,4,3
3,3,0,0,0,0,0,0,0,0,0,3,3
2,3,10,0,0,0,9,0,0,0,8,3,2
3,3,0,0,0,0,0,0,0,0,0,3,3
3,4,0,0,0,0,0,0,0,0,0,4,3
3,4,0,0,0,0,0,0,0,0,0,4,3
3,3,0,0,0,0,11,0,0,0,0,3,3
2,3,3,4,4,3,3,3,4,4,3,3,2
2,2,3,3,3,3,2,3,3,3,3,2,2
endlayer

layer
2,2,3,3,3,3,2,3,3,3,3,2,2
2,3,3,4,4,3,3,3,4,4,3,3,2
3,3,0,0,0,0,9,0,0,0,0,3,3
3,4,0,0,0,0,0,0,0,0,0,4,3
3,4,0,0,0,0,0,0,0,0,0,4,3
3,3,0,0,0,0,0,0,0,0,0,3,3
2,3,9,0,0,0,12,0,0,0,9,3,2
3,3,0,0,0,0,0,0,0,0,0,3,3
3,4,0,0,0,0,0,0,0,0,0,4,3
3,4,0,0,0,0,0,0,0,0,0,4,3
3,3,0,0,0,0,9,0,0,0,0,3,3
2,3,3,4,4,3,3,3,4,4,3,3,2
2,2,3,3,3,3,2,3,3,3,3,2,2
endlayer

layer
2,2,3,3,3,3,2,3,3,3,3,2,2
2,3,3,4,4,3,3,3,4,4,3,3,2
3,3,0,0,0,0,9,0,0,0,0,3,3
3,4,0,0,0,0,0,0,0,0,0,4,3
3,4,0,0,0,0,0,0,0,0,0,4,3
3,3,0,0,0,0,0,0,0,0,0,3,3
2,3,9,0,0,0,0,0,0,0,9,3,2
3,3,0,0,0,0,0,0,0,0,0,3,3
3,4,0,0,0,0,0,0,0,0,0,4,3
3,4,0,0,0,0,0,0,0,0,0,4,3
3,3,0,0,0,0,9,0,0,0,0,3,3
2,3,3,4,4,3,3,3,4,4,3,3,2
2,2,3,3,3,3,2,3,3,3,3,2,2
endlayer

layer
2,2,3,3,3,3,2,3,3,3,3,2,2
2,3,3,4,4,3,3,3,4,4,3,3,2
3,3,0,0,0,0,9,0,0,0,0,3,3
3,4,0,0,0,0,0,0,0,0,0,4,3
3,4,0,0,0,0,0,0,0,0,0,4,3
3,3,0,0,0,0,0,0,0,0,0,3,3
2,3,9,0,0,0,0,0,0,0,9,3,2
3,3,0,0,0,0,0,0,0,0,0,3,3
3,4,0,0,0,0,0,0,0,0,0,4,3
3,4,0,0,0,0,0,0,0,0,0,4,3
3,3,0,0,0,0,9,0,0,0,0,3,3
2,3,3,4,4,3,3,3,4,4,3,3,2
2,2,3,3,3,3,2,3,3,3,3,2,2
endlayer

layer
2,2,3,3,3,3,2,3,3,3,3,2,2
2,3,3,4,4,3,3,3,4,4,3,3,2
3,3,0,0,0,0,9,0,0,0,0,3,3
3,4,0,0,0,0,0,0,0,0,0,4,3
3,4,0,0,0,0,0,0,0,0,0,4,3
3,3,0,0,0,0,0,0,0,0,0,3,3
2,3,9,0,0,0,0,0,0,0,9,3,2
3,3,0,0,0,0,0,0,0,0,0,3,3
3,4,0,0,0,0,0,0,0,0,0,4,3
3,4,0,0,0,0,0,0,0,0,0,4,3
3,3,0,0,0,0,9,0,0,0,0,3,3
2,3,3,4,4,3,3,3,4,4,3,3,2
2,2,3,3,3,3,2,3,3,3,3,2,2
endlayer

layer
2,2,3,3,3,3,2,3,3,3,3,2,2
2,3,3,4,4,3,3,3,4,4,3,3,2
3,3,0,0,0,0,9,0,0,0,0,3,3
3,4,0,0,0,0,0,0,0,0,0,4,3
3,4,0,0,0,0,0,0,0,0,0,4,3
3,3,0,0,0,0,0,0,0,0,0,3,3
2,3,9,0,0,0,0,0,0,0,9,3,2
3,3,0,0,0,0,0,0,0,0,0,3,3
3,4,0,0,0,0,0,0,0,0,0,4,3
3,4,0,0,0,0,0,0,0,0,0,4,3
3,3,0,0,0,0,9,0,0,0,0,3,3
2,3,3,4,4,3,3,3,4,4,3,3,2
2,2,3,3,3,3,2,3,3,3,3,2,2
endlayer

layer
2,2,3,3,3,3,2,3,3,3,3,2,2
2,3,3,4,4,3,3,3,4,4,3,3,2
3,3,0,0,0,0,9,0,0,0,0,3,3
3,4,0,0,0,0,0,0,0,0,0,4,3
3,4,0,0,0,0,0,0,0,0,0,4,3
3,3,0,0,0,0,0,0,0,0,0,3,3
2,3,9,0,0,0,0,0,0,0,9,3,2
3,3,0,0,0,0,0,0,0,0,0,3,3
3,4,0,0,0,0,0,0,0,0,0,4,3
3,4,0,0,0,0,0,0,0,0,0,4,3
3,3,0,0,0,0,9,0,0,0,0,3,3
2,3,3,4,4,3,3,3,4,4,3,3,2
2,2,3,3,3,3,2,3,3,3,3,2,2
endlayer

layer
2,2,3,3,3,3,2,3,3,3,3,2,2
2,3,3,4,4,3,3,3,4,4,3,3,2
3,3,0,0,0,0,9,0,0,0,0,3,3
3,4,0,0,0,0,0,0,0,0,0,4,3
3,4,0,0,0,0,0,0,0,0,0,4,3
3,3,0,0,0,0,0,0,0,0,0,3,3
2,3,9,0,0,0,0,0,0,0,9,3,2
3,3,0,0,0,0,0,0,0,0,0,3,3
3,4,0,0,0,0,0,0,0,0,0,4,3
3,4,0,0,0,0,0,0,0,0,0,4,3
3,3,0,0,0,0,9,0,0,0,0,3,3
2,3,3,4,4,3,3,3,4,4,3,3,2
2,2,3,3,3,3,2,3,3,3,3,2,2
endlayer

layer
2,2,3,3,3,3,2,3,3,3,3,2,2
2,3,3,4,4,3,3,3,4,4,3,3,2
3,3,0,0,0,0,9,0,0,0,0,3,3
3,4,0,0,0,0,0,0,0,0,0,4,3
3,4,0,0,0,0,0,0,0,0,0,4,3
3,3,0,0,0,0,0,0,0,0,0,3,3
2,3,9,0,0,0,0,0,0,0,9,3,2
3,3,0,0,0,0,0,0,0,0,0,3,3
3,4,0,0,0,0,0,0,0,0,0,4,3
3,4,0,0,0,0,0,0,0,0,0,4,3
3,3,0,0,0,0,9,0,0,0,0,3,3
2,3,3,4,4,3,3,3,4,4,3,3,2
2,2,3,3,3,3,2,3,3,3,3,2,2
endlayer

layer
2,2,3,3,3,3,2,3,3,3,3,2,2
2,3,3,4,4,3,3,3,4,4,3,3,2
3,3,0,0,0,0,9,0,0,0,0,3,3
3,4,0,0,0,0,0,0,0,0,0,4,3
3,4,0,0,0,0,0,0,0,0,0,4,3
3,3,0,0,0,0,0,0,0,0,0,3,3
2,3,9,0,0,0,0,0,0,0,9,3,2
3,3,0,0,0,0,0,0,0,0,0,3,3
3,4,0,0,0,0,0,0,0,0,0,4,3
3,4,0,0,0,0,0,0,0,0,0,4,3
3,3,0,0,0,0,9,0,0,0,0,3,3
2,3,3,4,4,3,3,3,4,4,3,3,2
2,2,3,3,3,3,2,3,3,3,3,2,2
endlayer

layer
2,2,3,3,3,3,2,3,3,3,3,2,2
2,3,3,4,4,3,3,3,4,4,3,3,2
3,3,0,0,0,15,14,13,0,0,0,3,3
3,4,0,0,0,0,0,0,0,0,0,4,3
3,4,0,0,0,0,0,0,0,0,0,4,3
3,3,16,0,0,0,0,0,0,0,16,3,3
2,3,13,0,0,0,0,0,0,0,15,3,2
3,3,14,0,0,0,0,0,0,0,14,3,3
3,4,0,0,0,0,0,0,0,0,0,4,3
3,4,0,0,0,0,0,0,0,0,0,4,3
3,3,0,0,0,15,16,13,0,0,0,3,3
2,3,3,4,4,3,3,3,4,4,3,3,2
2,2,3,3,3,3,2,3,3,3,3,2,2
endlayer

layer
2,2,3,3,3,3,2,3,3,3,3,2,2
2,3,3,4,4,3,3,3,4,4,3,3,2
3,3,5,5,5,5,3,5,5,5,5,3,3
3,4,5,6,6,6,5,6,6,6,5,4,3
3,4,5,6,5,5,6,5,5,6,5,4,3
3,3,5,6,5,6,5,6,5,6,5,3,3
2,3,3,5,6,5,6,5,6,5,3,3,2
3,3,5,6,5,6,5,6,5,6,5,3,3
3,4,5,6,5,5,6,5,5,6,5,4,3
3,4,5,6,6,6,5,6,6,6,5,4,3
3,3,5,5,5,5,3,5,5,5,5,3,3
2,3,3,4,4,3,3,3,4,4,3,3,2
2,2,3,3,3,3,2,3,3,3,3,2,2
endlayer

layer
2,2,3,3,3,3,2,3,3,3,3,2,2
2,3,3,4,4,3,3,3,4,4,3,3,2
3,3,0,0,0,0,7,0,0,0,0,3,3
3,4,0,0,0,0,0,0,0,0,0,4,3
3,4,0,0,0,0,0,0,0,0,0,4,3
3,3,0,0,0,0,0,0,0,0,0,3,3
2,3,10,0,0,0,9,0,0,0,8,3,2
3,3,0,0,0,0,0,0,0,0,0,3,3
3,4,0,0,0,0,0,0,0,0,0,4,3
3,4,0,0,0,0,0,0,0,0,0,4,3
3,3,0,0,0,0,11,0,0,0,0,3,3
2,3,3,4,4,3,3,3,4,4,3,3,2
2,2,3,3,3,3,2,3,3,3,3,2,2
endlayer

layer
2,2,3,3,3,3,2,3,3,3,3,2,2
2,3,3,4,4,3,3,3,4,4,3,3,2
3,3,0,0,0,0,9,0,0,0,0,3,3
3,4,0,0,0,0,0,0,0,0,0,4,3
3,4,0,0,0,0,0,0,0,0,0,4,3
3,3,0,0,0,0,0,0,0,0,0,3,3
2,3,9,0,0,0,12,0,0,0,9,3,2
3,3,0,0,0,0,0,0,0,0,0,3,3
3,4,0,0,0,0,0,0,0,0,0,4,3
3,4,0,0,0,0,0,0,0,0,0,4,3
3,3,0,0,0,0,9,0,0,0,0,3,3
2,3,3,4,4,3,3,3,4,4,3,3,2
2,2,3,3,3,3,2,3,3,3,3,2,2
endlayer

layer
2,2,3,3,3,3,2,3,3,3,3,2,2
2,3,3,4,4,3,3,3,4,4,3,3,2
3,3,0,0,0,0,9,0,0,0,0,3,3
3,4,0,0,0,0,0,0,0,0,0,4,3
3,4,0,0,0,0,0,0,0,0,0,4,3
3,3,0,0,0,0,0,0,0,0,0,3,3
2,3,9,0,0,0,0,0,0,0,9,3,2
3,3,0,0,0,0,0,0,0,0,0,3,3
3,4,0,0,0,0,0,0,0,0,0,4,3
3,4,0,0,0,0,0,0,0,0,0,4,3
3,3,0,0,0,0,9,0,0,0,0,3,3
2,3,3,4,4,3,3,3,4,4,3,3,2
2,2,3,3,3,3,2,3,3,3,3,2,2
endlayer

layer
2,2,3,3,3,3,2,3,3,3,3,2,2
2,3,3,4,4,3,3,3,4,4,3,3,2
3,3,0,0,0,0,9,0,0,0,0,3,3
3,4,0,0,0,0,0,0,0,0,0,4,3
3,4,0,0,0,0,0,0,0,0,0,4,3
3,3,0,0,0,0,0,0,0,0,0,3,3
2,3,9,0,0,0,0,0,0,0,9,3,2
3,3,0,0,0,0,0,0,0,0,0,3,3
3,4,0,0,0,0,0,0,0,0,0,4,3
3,4,0,0,0,0,0,0,0,0,0,4,3
3,3,0,0,0,0,9,0,0,0,0,3,3
2,3,3,4,4,3,3,3,4,4,3,3,2
2,2,3,3,3,3,2,3,3,3,3,2,2
endlayer

layer
2,2,3,3,3,3,2,3,3,3,3,2,2
2,3,3,4,4,3,3,3,4,4,3,3,2
3,3,0,0,0,0,9,0,0,0,0,3,3
3,4,0,0,0,0,0,0,0,0,0,4,3
3,4,0,0,0,0,0,0,0,0,0,4,3
3,3,0,0,0,0,0,0,0,0,0,3,3
2,3,9,0,0,0,0,0,0,0,9,3,2
3,3,0,0,0,0,0,0,0,0,0,3,3
3,4,0,0,0,0,0,0,0,0,0,4,3
3,4,0,0,0,0,0,0,0,0,0,4,3
3,3,0,0,0,0,9,0,0,0,0,3,3
2,3,3,4,4,3,3,3,4,4,3,3,2
2,2,3,3,3,3,2,3,3,3,3,2,2
endlayer

layer
2,2,3,3,3,3,2,3,3,3,3,2,2
2,3,3,4,4,3,3,3,4,4,3,3,2
3,3,0,0,0,0,9,0,0,0,0,3,3
3,4,0,0,0,0,0,0,0,0,0,4,3
3,4,0,0,0,0,0,0,0,0,0,4,3
3,3,0,0,0,0,0,0,0,0,0,3,3
2,3,9,0,0,0,0,0,0,0,9,3,2
3,3,0,0,0,0,0,0,0,0,0,3,3
3,4,0,0,0,0,0,0,0,0,0,4,3
3,4,0,0,0,0,0,0,0,0,0,4,3
3,3,0,0,0,0,9,0,0,0,0,3,3
2,3,3,4,4,3,3,3,4,4,3,3,2
2,2,3,3,3,3,2,3,3,3,3,2,2
endlayer

layer
2,2,3,3,3,3,2,3,3,3,3,2,2
2,3,3,4,4,3,3,3,4,4,3,3,2
3,3,0,0,0,0,9,0,0,0,0,3,3
3,4,0,0,0,0,0,0,0,0,0,4,3
3,4,0,0,0,0,0,0,0,0,0,4,3
3,3,0,0,0,0,0,0,0,0,0,3,3
2,3,9,0,0,0,0,0,0,0,9,3,2
3,3,0,0,0,0,0,0,0,0,0,3,3
3,4,0,0,0,0,0,0,0,0,0,4,3
3,4,0,0,0,0,0,0,0,0,0,4,3
3,3,0,0,0,0,9,0,0,0,0,3,3
2,3,3,4,4,3,3,3,4,4,3,3,2
2,2,3,3,3,3,2,3,3,3,3,2,2
endlayer

layer
2,2,3,3,3,3,2,3,3,3,3,2,2
2,3,3,4,4,3,3,3,4,4,3,3,2
3,3,0,0,0,0,9,0,0,0,0,3,3
3,4,0,0,0,0,0,0,0,0,0,4,3
3,4,0,0,0,0,0,0,0,0,0,4,3
3,3,0,0,0,0,0,0,0,0,0,3,3
2,3,9,0,0,0,0,0,0,0,9,3,2
3,3,0,0,0,0,0,0,0,0,0,3,3
3,4,0,0,0,0,0,0,0,0,0,4,3
3,4,0,0,0,0,0,0,0,0,0,4,3
3,3,0,0,0,0,9,0,0,0,0,3,3
2,3,3,4,4,3,3,3,4,4,3,3,2
2,2,3,3,3,3,2,3,3,3,3,2,2
endlayer

layer
2,2,3,3,3,3,2,3,3,3,3,2,2
2,3,3,4,4,3,3,3,4,4,3,3,2
3,3,0,0,0,0,9,0,0,0,0,3,3
3,4,0,0,0,0,0,0,0,0,0,4,3
3,4,0,0,0,0,0,0,0,0,0,4,3
3,3,0,0,0,0,0,0,0,0,0,3,3
2,3,9,0,0,0,0,0,0,0,9,3,2
3,3,0,0,0,0,0,0,0,0,0,3,3
3,4,0,0,0,0,0,0,0,0,0,4,3
3,4,0,0,0,0,0,0,0,0,0,4,3
3,3,0,0,0,0,9,0,0,0,0,3,3
2,3,3,4,4,3,3,3,4,4,3,3,2
2,2,3,3,3,3,2,3,3,3,3,2,2
endlayer

layer
2,2,3,3,3,3,2,3,3,3,3,2,2
2,3,3,4,4,3,3,3,4,4,3,3,2
3,3,0,0,0,0,9,0,0,0,0,3,3
3,4,0,0,0,0,0,0,0,0,0,4,3
3,4,0,0,0,0,0,0,0,0,0,4,3
3,3,0,0,0,0,0,0,0,0,0,3,3
2,3,9,0,0,0,0,0,0,0,9,3,2
3,3,0,0,0,0,0,0,0,0,0,3,3
3,4,0,0,0,0,0,0,0,0,0,4,3
3,4,0,0,0,0,0,0,0,0,0,4,3
3,3,0,0,0,0,9,0,0,0,0,3,3
2,3,3,4,4,3,3,3,4,4,3,3,2
2,2,3,3,3,3,2,3,3,3,3,2,2
endlayer

layer
2,2,3,3,3,3,2,3,3,3,3,2,2
2,3,3,4,4,3,3,3,4,4,3,3,2
3,3,0,0,0,15,14,13,0,0,0,3,3
3,4,0,0,0,0,0,0,0,0,0,4,3
3,4,0,0,0,0,0,0,0,0,0,4,3
3,3,16,0,0,0,0,0,0,0,16,3,3
2,3,13,0,0,0,0,0,0,0,15,3,2
3,3,14,0,0,0,0,0,0,0,14,3,3
3,4,0,0,0,0,0,0,0,0,0,4,3
3,4,0,0,0,0,0,0,0,0,0,4,3
3,3,0,0,0,15,16,13,0,0,0,3,3
2,3,3,4,4,3,3,3,4,4,3,3,2
2,2,3,3,3,3,2,3,3,3,3,2,2
endlayer

layer
2,2,3,3,3,3,2,3,3,3,3,2,2
2,3,3,4,4,3,3,3,4,4,3,3,2
3,3,5,5,5,5,3,5,5,5,5,3,3
3,4,5,6,6,6,5,6,6,6,5,4,3
3,4,5,6,5,5,6,5,5,6,5,4,3
3,3,5,6,5,6,5,6,5,6,5,3,3
2,3,3,5,6,5,6,5,6,5,3,3,2
3,3,5,6,5,6,5,6,5,6,5,3,3
3,4,5,6,5,5,6,5,5,6,5,4,3
3,4,5,6,6,6,5,6,6,6,5,4,3
3,3,5,5,5,5,3,5,5,5,5,3,3
2,3,3,4,4,3,3,3,4,4,3,3,2
2,2,3,3,3,3,2,3,3,3,3,2,2
endlayer

layer
2,2,3,3,3,3,2,3,3,3,3,2,2
2,3,3,4,4,3,3,3,4,4,3,3,2
3,3,6,0,0,18,7,17,0,0,6,3,3
3,4,0,0,0,0,0,0,0,0,0,4,3
3,4,0,0,0,0,0,0,0,0,0,4,3
3,3,21,0,0,0,20,0,0,0,19,3,3
2,3,10,0,0,23,9,22,0,0,8,3,2
3,3,26,0,0,0,25,0,0,0,24,3,3
3,4,0,0,0,0,0,0,0,0,0,4,3
3,4,0,0,0,0,0,0,0,0,0,4,3
3,3,6,0,0,28,11,27,0,0,6,3,3
2,3,3,4,4,3,3,3,4,4,3,3,2
2,2,3,3,3,3,2,3,3,3,3,2,2
endlayer

layer
2,2,3,3,3,3,2,3,3,3,3,2,2
2,3,3,4,4,3,3,3,4,4,3,3,2
3,3,9,0,0,0,9,0,0,0,9,3,3
3,4,0,0,0,0,0,0,0,0,0,4,3
3,4,0,0,0,0,0,0,0,0,0,4,3
3,3,0,0,0,0,0,0,0,0,0,3,3
2,3,9,0,0,0,12,0,0,0,9,3,2
3,3,0,0,0,0,0,0,0,0,0,3,3
3,4,0,0,0,0,0,0,0,0,0,4,3
3,4,0,0,0,0,0,0,0,0,0,4,3
3,3,9,0,0,0,9,0,0,0,9,3,3
2,3,3,4,4,3,3,3,4,4,3,3,2
2,2,3,3,3,3,2,3,3,3,3,2,2
endlayer

layer
2,2,3,3,3,3,2,3,3,3,3,2,2
2,3,3,4,4,3,3,3,4,4,3,3,2
3,3,12,0,0,0,9,0,0,0,12,3,3
3,4,0,0,0,0,0,0,0,0,0,4,3
3,4,0,0,0,0,0,0,0,0,0,4,3
3,3,0,0,0,0,0,0,0,0,0,3,3
2,3,9,0,0,0,0,0,0,0,9,3,2
3,3,0,0,0,0,0,0,0,0,0,3,3
3,4,0,0,0,0,0,0,0,0,0,4,3
3,4,0,0,0,0,0,0,0,0,0,4,3
3,3,12,0,0,0,9,0,0,0,12,3,3
2,3,3,4,4,3,3,3,4,4,3,3,2
2,2,3,3,3,3,2,3,3,3,3,2,2
endlayer

layer
2,2,3,3,3,3,2,3,3,3,3,2,2
2,3,3,4,4,3,3,3,4,4,3,3,2
3,3,0,0,0,0,9,0,0,0,0,3,3
3,4,0,0,0,0,0,0,0,0,0,4,3
3,4,0,0,0,0,0,0,0,0,0,4,3
3,3,0,0,0,0,0,0,0,0,0,3,3
2,3,9,0,0,0,0,0,0,0,9,3,2
3,3,0,0,0,0,0,0,0,0,0,3,3
3,4,0,0,0,0,0,0,0,0,0,4,3
3,4,0,0,0,0,0,0,0,0,0,4,3
3,3,0,0,0,0,9,0,0,0,0,3,3
2,3,3,4,4,3,3,3,4,4,3,3,2
2,2,3,3,3,3,2,3,3,3,3,2,2
endlayer

layer
2,2,3,3,3,3,2,3,3,3,3,2,2
2,3,3,4,4,3,3,3,4,4,3,3,2
3,3,0,0,0,0,9,0,0,0,0,3,3
3,4,0,0,0,0,0,0,0,0,0,4,3
3,4,0,0,0,0,0,0,0,0,0,4,3
3,3,0,0,0,0,0,0,0,0,0,3,3
2,3,9,0,0,0,0,0,0,0,9,3,2
3,3,0,0,0,0,0,0,0,0,0,3,3
3,4,0,0,0,0,0,0,0,0,0,4,3
3,4,0,0,0,0,0,0,0,0,0,4,3
3,3,0,0,0,0,9,0,0,0,0,3,3
2,3,3,4,4,3,3,3,4,4,3,3,2
2,2,3,3,3,3,2,3,3,3,3,2,2
endlayer

layer
2,2,3,3,3,3,2,3,3,3,3,2,2
2,3,3,4,4,3,3,3,4,4,3,3,2
3,3,0,0,0,0,9,0,0,0,0,3,3
3,4,0,0,0,0,0,0,0,0,0,4,3
3,4,0,0,0,0,0,0,0,0,0,4,3
3,3,0,0,0,0,0,0,0,0,0,3,3
2,3,9,0,0,0,0,0,0,0,9,3,2
3,3,0,0,0,0,0,0,0,0,0,3,3
3,4,0,0,0,0,0,0,0,0,0,4,3
3,4,0,0,0,0,0,0,0,0,0,4,3
3,3,0,0,0,0,9,0,0,0,0,3,3
2,3,3,4,4,3,3,3,4,4,3,3,2
2,2,3,3,3,3,2,3,3,3,3,2,2
endlayer

layer
2,2,3,3,3,3,2,3,3,3,3,2,2
2,3,3,4,4,3,3,3,4,4,3,3,2
3,3,0,0,0,0,9,0,0,0,0,3,3
3,4,0,0,0,0,0,0,0,0,0,4,3
3,4,0,0,0,0,0,0,0,0,0,4,3
3,3,0,0,0,0,0,0,0,0,0,3,3
2,3,9,0,0,0,0,0,0,0,9,3,2
3,3,0,0,0,0,0,0,0,0,0,3,3
3,4,0,0,0,0,0,0,0,0,0,4,3
3,4,0,0,0,0,0,0,0,0,0,4,3
3,3,0,0,0,0,9,0,0,0,0,3,3
2,3,3,4,4,3,3,3,4,4,3,3,2
2,2,3,3,3,3,2,3,3,3,3,2,2
endlayer

layer
2,2,3,3,3,3,2,3,3,3,3,2,2
2,3,3,4,4,3,3,3,4,4,3,3,2
3,3,0,0,0,0,9,0,0,0,0,3,3
3,4,0,0,0,0,0,0,0,0,0,4,3
3,4,0,0,0,0,0,0,0,0,0,4,3
3,3,0,0,0,0,0,0,0,0,0,3,3
2,3,9,0,0,0,0,0,0,0,9,3,2
3,3,0,0,0,0,0,0,0,0,0,3,3
3,4,0,0,0,0,0,0,0,0,0,4,3
3,4,0,0,0,0,0,0,0,0,0,4,3
3,3,0,0,0,0,9,0,0,0,0,3,3
2,3,3,4,4,3,3,3,4,4,3,3,2
2,2,3,3,3,3,2,3,3,3,3,2,2
endlayer

layer
2,2,3,3,3,3,2,3,3,3,3,2,2
2,3,3,4,4,3,3,3,4,4,3,3,2
3,3,0,0,0,0,9,0,0,0,0,3,3
3,4,0,0,0,0,0,0,0,0,0,4,3
3,4,0,0,0,0,0,0,0,0,0,4,3
3,3,0,0,0,0,0,0,0,0,0,3,3
2,3,9,0,0,0,0,0,0,0,9,3,2
3,3,0,0,0,0,0,0,0,0,0,3,3
3,4,0,0,0,0,0,0,0,0,0,4,3
3,4,0,0,0,0,0,0,0,0,0,4,3
3,3,0,0,0,0,9,0,0,0,0,3,3
2,3,3,4,4,3,3,3,4,4,3,3,2
2,2,3,3,3,3,2,3,3,3,3,2,2
endlayer

layer
2,2,3,3,3,3,2,3,3,3,3,2,2
2,3,3,4,4,3,3,3,4,4,3,3,2
3,3,0,0,0,0,9,0,0,0,0,3,3
3,4,0,0,0,0,0,0,0,0,0,4,3
3,4,0,0,0,0,0,0,0,0,0,4,3
3,3,0,0,0,0,0,0,0,0,0,3,3
2,3,9,0,0,0,0,0,0,0,9,3,2
3,3,0,0,0,0,0,0,0,0,0,3,3
3,4,0,0,0,0,0,0,0,0,0,4,3
3,4,0,0,0,0,0,0,0,0,0,4,3
3,3,0,0,0,0,9,0,0,0,0,3,3
2,3,3,4,4,3,3,3,4,4,3,3,2
2,2,3,3,3,3,2,3,3,3,3,2,2
endlayer

layer
2,2,3,3,3,3,2,3,3,3,3,2,2
2,3,3,4,4,3,3,3,4,4,3,3,2
3,3,0,0,0,15,14,13,0,0,0,3,3
3,4,0,0,0,0,0,0,0,0,0,4,3
3,4,0,0,0,0,0,0,0,0,0,4,3
3,3,16,0,0,0,0,0,0,0,16,3,3
2,3,13,0,0,0,0,0,0,0,15,3,2
3,3,14,0,0,0,0,0,0,0,14,3,3
3,4,0,0,0,0,0,0,0,0,0,4,3
3,4,0,0,0,0,0,0,0,0,0,4,3
3,3,0,0,0,15,16,13,0,0,0,3,3
2,3,3,4,4,3,3,3,4,4,3,3,2
2,2,3,3,3,3,2,3,3,3,3,2,2
endlayer

layer
2,2,3,3,3,3,2,3,3,3,3,2,2
2,3,3,4,4,3,3,3,4,4,3,3,2
3,3,5,5,5,5,3,5,5,5,5,3,3
3,4,5,6,6,6,5,6,6,6,5,4,3
3,4,5,6,5,5,6,5,5,6,5,4,3
3,3,5,6,5,6,5,6,5,6,5,3,3
2,3,3,5,6,5,6,5,6,5,3,3,2
3,3,5,6,5,6,5,6,5,6,5,3,3
3,4,5,6,5,5,6,5,5,6,5,4,3
3,4,5,6,6,6,5,6,6,6,5,4,3
3,3,5,5,5,5,3,5,5,5,5,3,3
2,3,3,4,4,3,3,3,4,4,3,3,2
2,2,3,3,3,3,2,3,3,3,3,2,2
endlayer

layer
2,2,3,3,3,3,2,3,3,3,3,2,2
2,3,3,4,4,3,3,3,4,4,3,3,2
3,3,6,0,0,0,7,0,0,0,6,3,3
3,4,0,0,0,0,0,0,0,0,0,4,3
3,4,0,0,0,0,30,29,0,0,0,4,3
3,3,0,0,0,0,30,29,0,0,0,3,3
2,3,10,0,0,0,6,0,0,0,8,3,2
3,3,0,0,0,0,31,0,0,0,0,3,3
3,4,0,0,0,0,0,0,0,0,0,4,3
3,4,0,0,0,0,0,0,0,0,0,4,3
3,3,6,0,0,0,11,0,0,0,6,3,3
2,3,3,4,4,3,3,3,4,4,3,3,2
2,2,3,3,3,3,2,3,3,3,3,2,2
endlayer

layer
2,2,3,3,3,3,2,3,3,3,3,2,2
2,3,3,4,4,3,3,3,4,4,3,3,2
3,3,9,0,0,0,9,0,0,0,9,3,3
3,4,0,0,0,0,0,0,0,0,0,4,3
3,4,0,0,0,0,0,30,32,0,0,4,3
3,3,0,0,0,0,0,30,32,0,0,3,3
2,3,9,0,0,0,32,33,33,0,9,3,2
3,3,0,0,0,0,0,0,0,0,0,3,3
3,4,0,0,0,0,0,0,0,0,0,4,3
3,4,0,0,0,0,0,0,0,0,0,4,3
3,3,9,0,0,0,9,0,0,0,9,3,3
2,3,3,4,4,3,3,3,4,4,3,3,2
2,2,3,3,3,3,2,3,3,3,3,2,2
endlayer

layer
2,2,3,3,3,3,2,3,3,3,3,2,2
2,3,3,4,4,3,3,3,4,4,3,3,2
3,3,12,0,0,0,9,0,0,0,12,3,3
3,4,0,0,0,0,0,0,0,0,0,4,3
3,4,0,0,0,0,0,0,0,0,0,4,3
3,3,0,0,0,0,0,0,0,0,0,3,3
2,3,9,0,0,0,32,34,34,0,9,3,2
3,3,0,0,0,0,0,33,33,0,0,3,3
3,4,0,0,0,0,0,0,0,0,0,4,3
3,4,0,0,0,0,0,0,0,0,0,4,3
3,3,12,0,0,0,9,0,0,0,12,3,3
2,3,3,4,4,3,3,3,4,4,3,3,2
2,2,3,3,3,3,2,3,3,3,3,2,2
endlayer

layer
2,2,3,3,3,3,2,3,3,3,3,2,2
2,3,3,4,4,3,3,3,4,4,3,3,2
3,3,0,0,0,0,9,0,0,0,0,3,3
3,4,0,0,0,0,0,0,0,0,0,4,3
3,4,0,0,0,0,0,0,0,0,0,4,3
3,3,0,0,0,0,35,0,0,0,0,3,3
2,3,9,0,0,0,6,0,0,0,9,3,2
3,3,0,0,0,0,36,34,34,0,0,3,3
3,4,0,0,0,0,36,32,32,0,0,4,3
3,4,0,0,0,0,0,0,0,0,0,4,3
3,3,0,0,0,0,9,0,0,0,0,3,3
2,3,3,4,4,3,3,3,4,4,3,3,2
2,2,3,3,3,3,2,3,3,3,3,2,2
endlayer

layer
2,2,3,3,3,3,2,3,3,3,3,2,2
2,3,3,4,4,3,3,3,4,4,3,3,2
3,3,0,0,0,0,9,0,0,0,0,3,3
3,4,0,0,0,0,0,0,0,0,0,4,3
3,4,0,0,0,0,0,0,0,0,0,4,3
3,3,0,0,0,0,0,0,0,0,0,3,3
2,3,9,0,0,0,32,0,0,0,9,3,2
3,3,0,0,0,36,37,0,0,0,0,3,3
3,4,0,0,0,36,37,0,0,0,0,4,3
3,4,0,0,0,0,0,0,0,0,0,4,3
3,3,0,0,0,0,9,0,0,0,0,3,3
2,3,3,4,4,3,3,3,4,4,3,3,2
2,2,3,3,3,3,2,3,3,3,3,2,2
endlayer

layer
2,2,3,3,3,3,2,3,3,3,3,2,2
2,3,3,4,4,3,3,3,4,4,3,3,2
3,3,0,0,0,0,9,0,0,0,0,3,3
3,4,0,0,0,0,0,0,0,0,0,4,3
3,4,0,0,0,0,0,0,0,0,0,4,3
3,3,0,0,0,0,0,0,0,0,0,3,3
2,3,9,0,38,38,32,0,0,0,9,3,2
3,3,0,0,32,37,0,0,0,0,0,3,3
3,4,0,0,32,37,0,0,0,0,0,4,3
3,4,0,0,0,0,0,0,0,0,0,4,3
3,3,0,0,0,0,9,0,0,0,0,3,3
2,3,3,4,4,3,3,3,4,4,3,3,2
2,2,3,3,3,3,2,3,3,3,3,2,2
endlayer

layer
2,2,3,3,3,3,2,3,3,3,3,2,2
2,3,3,4,4,3,3,3,4,4,3,3,2
3,3,0,0,0,0,9,0,0,0,0,3,3
3,4,0,0,0,0,0,0,0,0,0,4,3
3,4,0,0,0,0,0,0,0,0,0,4,3
3,3,0,0,38,38,0,0,0,0,0,3,3
2,3,9,0,39,39,32,0,0,0,9,3,2
3,3,0,0,0,0,0,0,0,0,0,3,3
3,4,0,0,0,0,0,0,0,0,0,4,3
3,4,0,0,0,0,0,0,0,0,0,4,3
3,3,0,0,0,0,9,0,0,0,0,3,3
2,3,3,4,4,3,3,3,4,4,3,3,2
2,2,3,3,3,3,2,3,3,3,3,2,2
endlayer

layer
2,2,3,3,3,3,2,3,3,3,3,2,2
2,3,3,4,4,3,3,3,4,4,3,3,2
3,3,0,0,0,0,9,0,0,0,0,3,3
3,4,0,0,0,0,0,0,0,0,0,4,3
3,4,0,0,32,32,29,0,0,0,0,4,3
3,3,0,0,39,39,29,0,0,0,0,3,3
2,3,9,0,0,0,6,0,0,0,9,3,2
3,3,0,0,0,0,31,0,0,0,0,3,3
3,4,0,0,0,0,0,0,0,0,0,4,3
3,4,0,0,0,0,0,0,0,0,0,4,3
3,3,0,0,0,0,9,0,0,0,0,3,3
2,3,3,4,4,3,3,3,4,4,3,3,2
2,2,3,3,3,3,2,3,3,3,3,2,2
endlayer

layer
2,2,3,3,3,3,2,3,3,3,3,2,2
2,3,3,4,4,3,3,3,4,4,3,3,2
3,3,0,0,0,0,9,0,0,0,0,3,3
3,4,0,0,0,0,0,0,0,0,0,4,3
3,4,0,0,0,0,30,29,0,0,0,4,3
3,3,0,0,0,0,30,29,0,0,0,3,3
2,3,9,0,0,0,32,0,0,0,9,3,2
3,3,0,0,0,0,0,0,0,0,0,3,3
3,4,0,0,0,0,0,0,0,0,0,4,3
3,4,0,0,0,0,0,0,0,0,0,4,3
3,3,0,0,0,0,9,0,0,0,0,3,3
2,3,3,4,4,3,3,3,4,4,3,3,2
2,2,3,3,3,3,2,3,3,3,3,2,2
endlayer

layer
2,2,3,3,3,3,2,3,3,3,3,2,2
2,3,3,4,4,3,3,3,4,4,3,3,2
3,3,0,0,0,0,9,0,0,0,0,3,3
3,4,0,0,0,0,0,0,0,0,0,4,3
3,4,0,0,0,0,0,30,32,0,0,4,3
3,3,0,0,0,0,0,30,32,0,0,3,3
2,3,9,0,0,0,32,33,33,0,9,3,2
3,3,0,0,0,0,0,0,0,0,0,3,3
3,4,0,0,0,0,0,0,0,0,0,4,3
3,4,0,0,0,0,0,0,0,0,0,4,3
3,3,0,0,0,0,9,0,0,0,0,3,3
2,3,3,4,4,3,3,3,4,4,3,3,2
2,2,3,3,3,3,2,3,3,3,3,2,2
endlayer

layer
2,2,3,6,6,3,2,3,6,6,3,2,2
2,3,40,41,41,40,3,40,41,41,40,3,2
3,40,6,0,0,15,14,13,0,0,6,40,3
6,41,0,0,0,0,0,0,0,0,0,41,6
6,41,0,0,0,0,0,0,0,0,0,41,6
3,40,16,0,0,0,0,0,0,0,16,40,3
2,3,13,0,0,0,32,34,34,0,15,3,2
3,40,14,0,0,0,0,33,33,0,14,40,3
6,41,0,0,0,0,0,0,0,0,0,41,6
6,41,0,0,0,0,0,0,0,0,0,41,6
3,40,6,0,0,15,16,13,0,0,6,40,3
2,3,40,41,41,40,3,40,41,41,40,3,2
2,2,3,6,6,3,2,3,6,6,3,2,2
endlayer

layer
2,2,3,3,3,3,2,3,3,3,3,2,2
2,3,3,33,33,3,3,3,33,33,3,3,2
3,3,0,0,0,6,3,6,0,0,0,3,3
3,29,0,6,6,6,42,6,6,6,0,36,3
3,29,0,6,42,42,0,0,0,6,0,36,3
3,3,6,6,42,6,35,0,0,6,6,3,3
2,3,3,42,6,42,6,0,0,42,3,3,2
3,3,6,6,42,6,42,34,34,6,6,3,3
3,29,0,6,42,42,6,42,42,6,0,36,3
3,29,0,6,6,6,42,6,6,6,0,36,3
3,3,0,0,0,6,3,6,0,0,0,3,3
2,3,3,38,38,3,3,3,38,38,3,3,2
2,2,3,3,3,3,2,3,3,3,3,2,2
endlayer

layer
43,43,43,43,43,43,43,43,43,43,43,43,43
43,43,43,43,43,43,43,43,43,43,43,43,43
43,43,32,32,32,32,32,32,32,32,32,43,43
43,43,32,32,32,32,32,32,32,32,32,43,43
43,43,32,32,32,32,32,0,0,32,32,43,43
43,43,32,32,32,32,32,0,0,32,32,43,43
43,43,32,32,32,32,32,0,0,32,32,43,43
43,43,32,32,32,32,37,0,0,32,32,43,43
43,43,32,32,32,32,32,34,34,32,32,43,43
43,43,32,32,32,32,32,32,32,32,32,43,43
43,43,32,32,32,32,32,32,32,32,32,43,43
43,43,43,43,43,43,43,43,43,43,43,43,43
43,43,43,43,43,43,43,43,43,43,43,43,43
endlayer

layer
43,43,43,43,43,43,43,43,43,43,43,43,43
43,43,43,43,43,43,43,43,43,43,43,43,43
43,43,43,43,43,43,43,43,43,43,43,43,43
43,43,43,32,44,32,32,32,32,32,43,43,43
43,43,43,32,32,32,32,0,0,32,43,43,43
43,43,43,32,32,32,32,0,0,32,43,43,43
43,43,43,32,39,39,32,0,0,32,43,43,43
43,43,43,32,0,0,0,0,0,32,43,43,43
43,43,43,32,0,0,0,0,0,44,43,43,43
43,43,43,32,32,32,45,32,32,32,43,43,43
43,43,43,43,43,43,43,43,43,43,43,43,43
43,43,43,43,43,43,43,43,43,43,43,43,43
43,43,43,43,43,43,43,43,43,43,43,43,43
endlayer

layer
43,43,43,43,43,43,43,43,43,43,43,43,43
43,43,43,43,43,43,43,43,43,43,43,43,43
43,43,43,43,43,43,43,43,43,43,43,43,43
43,43,43,32,32,32,32,32,32,32,43,43,43
43,43,43,32,0,0,30,32,32,32,43,43,43
43,43,43,32,0,0,30,32,32,32,43,43,43
43,43,43,32,0,0,32,32,32,32,43,43,43
43,43,43,32,0,0,0,0,0,32,43,43,43
43,43,43,32,0,35,0,35,0,32,43,43,43
43,43,43,32,32,32,46,32,32,32,43,43,43
43,43,43,43,43,43,43,43,43,43,43,43,43
43,43,43,43,43,43,43,43,43,43,43,43,43
43,43,43,43,43,43,43,43,43,43,43,43,43
endlayer

layer
43,43,43,43,43,43,43,43,43,43,43,43,43
43,43,43,43,43,43,43,43,43,43,43,43,43
43,43,43,43,43,43,43,43,43,43,43,43,43
43,43,43,32,32,32,32,32,32,32,43,43,43
43,43,43,32,0,0,0,0,0,32,43,43,43
43,43,43,44,0,0,0,0,0,32,43,43,43
43,43,43,32,47,0,32,34,34,32,43,43,43
43,43,43,32,0,0,32,32,32,32,43,43,43
43,43,43,32,0,0,32,32,32,32,43,43,43
43,43,43,32,32,32,32,32,32,32,43,43,43
43,43,43,43,43,43,43,43,43,43,43,43,43
43,43,43,43,43,43,43,43,43,43,43,43,43
43,43,43,43,43,43,43,43,43,43,43,43,43
endlayer

layer
43,43,43,43,43,43,43,43,43,43,43,43,43
43,43,43,43,43,43,43,43,43,43,43,43,43
43,43,43,43,43,43,43,43,43,43,43,43,43
43,43,43,32,32,32,32,32,32,32,43,43,43
43,43,43,32,0,0,0,0,0,32,43,43,43
43,43,43,32,0,0,0,0,0,32,43,43,43
43,43,43,32,32,32,32,0,0,32,43,43,43
43,43,43,32,32,32,37,0,0,32,43,43,43
43,43,43,32,32,32,37,0,0,32,43,43,43
43,43,43,32,32,32,32,32,32,32,43,43,43
43,43,43,43,43,43,43,43,43,43,43,43,43
43,43,43,43,43,43,43,43,43,43,43,43,43
43,43,43,43,43,43,43,43,43,43,43,43,43
endlayer

layer
43,43,43,43,43,43,43,43,43,43,43,43,43
43,43,43,43,43,43,43,43,43,43,43,43,43
43,43,43,43,43,43,43,43,43,43,43,43,43
43,43,43,32,32,32,32,32,32,32,43,43,43
43,43,43,32,32,32,32,0,0,32,43,43,43
43,43,43,32,32,32,32,0,0,32,43,43,43
43,43,43,32,39,39,32,0,48,32,43,43,43
43,43,43,32,0,0,0,0,0,32,43,43,43
43,43,43,32,0,0,0,0,0,32,43,43,43
43,43,43,32,32,32,32,44,32,32,43,43,43
43,43,43,43,43,43,43,43,43,43,43,43,43
43,43,43,43,43,43,43,43,43,43,43,43,43
43,43,43,43,43,43,43,43,43,43,43,43,43
endlayer

layer
43,43,43,43,43,43,43,43,43,43,43,43,43
43,43,43,43,43,43,43,43,43,43,43,43,43
43,43,43,43,43,43,43,43,43,43,43,43,43
43,43,43,32,32,32,32,32,32,32,43,43,43
43,43,43,32,0,0,30,32,32,32,43,43,43
43,43,43,32,0,0,30,32,32,32,43,43,43
43,43,43,32,0,0,32,32,32,32,43,43,43
43,43,43,32,0,0,0,0,0,32,43,43,43
43,43,43,32,0,0,0,0,0,32,43,43,43
43,43,43,44,32,32,32,32,32,32,43,43,43
43,43,43,43,43,43,43,43,43,43,43,43,43
43,43,43,43,43,43,43,43,43,43,43,43,43
43,43,43,43,43,43,43,43,43,43,43,43,43
endlayer

layer
43,43,43,43,43,43,43,43,43,43,43,43,43
43,43,43,43,43,43,43,43,43,43,43,43,43
43,43,43,43,43,43,43,43,43,43,43,43,43
43,43,43,32,32,32,32,32,32,32,43,43,43
43,43,43,32,0,0,0,0,0,32,43,43,43
43,43,43,32,0,0,0,0,0,32,43,43,43
43,43,43,32,47,0,32,34,34,44,43,43,43
43,43,43,32,0,0,32,32,32,32,43,43,43
43,43,43,32,0,0,32,32,32,32,43,43,43
43,43,43,32,32,32,32,32,32,32,43,43,43
43,43,43,43,43,43,43,43,43,43,43,43,43
43,43,43,43,43,43,43,43,43,43,43,43,43
43,43,43,43,43,43,43,43,43,43,43,43,43
endlayer

layer
43,43,43,43,43,43,43,43,43,43,43,43,43
43,43,43,43,43,43,43,43,43,43,43,43,43
43,43,43,43,43,43,43,43,43,43,43,43,43
43,43,43,32,32,32,44,32,32,32,43,43,43
43,43,43,32,0,0,0,0,0,32,43,43,43
43,43,43,32,0,0,0,0,0,32,43,43,43
43,43,43,32,32,32,32,0,0,32,43,43,43
43,43,43,32,32,32,37,0,0,32,43,43,43
43,43,43,32,32,32,37,0,0,32,43,43,43
43,43,43,32,32,32,32,32,32,32,43,43,43
43,43,43,43,43,43,43,43,43,43,43,43,43
43,43,43,43,43,43,43,43,43,43,43,43,43
43,43,43,43,43,43,43,43,43,43,43,43,43
endlayer

layer
43,43,43,43,43,43,43,43,43,43,43,43,43
43,43,43,43,43,43,43,43,43,43,43,43,43
43,43,43,43,43,43,43,43,43,43,43,43,43
43,43,43,32,32,32,32,32,32,32,43,43,43
43,43,43,32,32,32,32,0,0,32,43,43,43
43,43,43,32,32,32,32,0,0,32,43,43,43
43,43,43,32,39,39,32,0,48,32,43,43,43
43,43,43,32,0,0,0,0,0,32,43,43,43
43,43,43,32,0,0,0,0,0,32,43,43,43
43,43,43,32,32,32,32,32,32,32,43,43,43
43,43,43,43,43,43,43,43,43,43,43,43,43
43,43,43,43,43,43,43,43,43,43,43,43,43
43,43,43,43,43,43,43,43,43,43,43,43,43
endlayer

layer
43,43,43,43,43,43,43,43,43,43,43,43,43
43,43,43,43,43,43,43,43,43,43,43,43,43
43,43,43,38,43,38,38,38,43,38,43,43,43
43,43,36,32,32,32,32,32,32,32,29,43,43
43,43,43,32,0,0,30,32,32,32,43,43,43
43,43,36,32,0,0,30,32,32,32,29,43,43
43,43,36,32,0,0,32,32,32,32,29,43,43
43,43,36,32,0,0,0,0,0,32,29,43,43
43,43,43,32,0,0,0,0,0,32,43,43,43
43,43,36,32,32,32,32,32,32,32,29,43,43
43,43,43,33,43,33,33,33,43,33,43,43,43
43,43,43,43,43,43,43,43,43,43,43,43,43
43,43,43,43,43,43,43,43,43,43,43,43,43
endlayer

layer
43,43,43,43,43,43,43,43,43,43,43,43,43
43,43,43,43,43,43,43,43,43,43,43,43,43
43,43,49,49,49,49,49,49,49,49,49,43,43
43,43,49,32,32,32,32,32,32,32,49,43,43
43,43,49,32,0,0,0,0,0,32,49,43,43
43,43,49,32,0,0,0,0,0,32,49,43,43
43,43,49,32,0,0,32,34,34,32,49,43,43
43,43,49,32,0,0,32,32,32,32,49,43,43
43,43,49,32,32,32,32,32,32,32,49,43,43
43,43,49,32,32,32,32,32,32,32,49,43,43
43,43,49,49,49,49,49,49,49,49,49,43,43
43,43,43,43,43,43,43,43,43,43,43,43,43
43,43,43,43,43,43,43,43,43,43,43,43,43
endlayer

layer
43,43,43,43,43,43,43,43,43,43,43,43,43
43,43,43,43,43,43,43,43,43,43,43,43,43
43,43,43,43,43,43,43,43,43,43,43,43,43
43,43,43,32,32,32,32,32,32,32,43,43,43
43,43,43,32,0,0,0,0,0,32,43,43,43
43,43,43,32,0,0,0,0,0,32,43,43,43
43,43,43,32,0,0,0,0,0,32,43,43,43
43,43,43,32,0,0,0,0,0,32,43,43,43
43,43,43,32,0,0,0,0,50,32,43,43,43
43,43,43,32,32,32,32,32,32,32,43,43,43
43,43,43,43,43,33,33,33,43,43,43,43,43
43,43,43,43,43,43,43,43,43,43,43,43,43
43,43,43,43,43,43,43,43,43,43,43,43,43
endlayer

layer
43,43,43,43,43,43,43,43,43,43,43,43,43
43,43,43,43,43,43,43,43,43,43,43,43,43
43,43,43,43,43,43,43,43,43,43,43,43,43
43,43,43,44,32,32,32,32,32,32,43,43,43
43,43,43,32,0,0,0,0,0,44,43,43,43
43,43,43,32,47,0,0,0,48,32,43,43,43
43,43,43,32,0,0,0,0,0,32,43,43,43
43,43,43,32,47,0,0,0,48,32,43,43,43
43,43,43,32,0,0,0,0,50,32,43,43,43
43,43,43,32,32,0,0,0,32,32,43,43,43
43,43,43,43,43,43,43,43,43,43,43,43,43
43,43,43,43,43,43,43,43,43,43,43,43,43
43,43,43,43,43,43,43,43,43,43,43,43,43
endlayer

layer
43,43,43,43,43,43,43,43,43,43,43,43,43
43,43,43,43,43,43,43,43,43,43,43,43,43
43,43,43,43,43,43,43,43,43,43,43,43,43
43,43,43,32,32,32,32,32,32,32,43,43,43
43,43,43,32,0,0,0,0,0,32,43,43,43
43,43,43,32,0,0,0,0,0,32,43,43,43
43,43,43,32,0,0,0,0,0,32,43,43,43
43,43,43,32,0,0,0,0,0,32,43,43,43
43,43,43,32,0,0,0,0,50,32,43,43,43
43,43,43,32,32,0,0,0,32,32,43,43,43
43,43,43,43,43,43,43,43,43,43,43,43,43
43,43,43,43,43,43,43,43,43,43,43,43,43
43,43,43,43,43,43,43,43,43,43,43,43,43
endlayer

layer
43,43,43,43,43,43,43,43,43,43,43,43,43
43,43,43,43,43,43,43,43,43,43,43,43,43
43,43,43,43,43,43,43,43,43,43,43,43,43
43,43,43,32,32,32,32,32,32,32,43,43,43
43,43,43,32,0,0,0,0,0,32,43,43,43
43,43,43,32,0,0,0,0,0,32,43,43,43
43,43,43,32,0,0,0,0,0,32,43,43,43
43,43,43,32,0,0,0,0,0,32,43,43,43
43,43,43,44,0,0,0,0,50,32,43,43,43
43,43,43,32,32,29,0,36,32,44,43,43,43
43,43,43,43,43,43,0,43,43,43,43,43,43
43,43,43,43,43,43,43,43,43,43,43,43,43
43,43,43,43,43,43,43,43,43,43,43,43,43
endlayer

layer
43,43,43,43,43,43,43,43,43,43,43,43,43
43,43,43,43,43,43,43,43,43,43,43,43,43
43,43,43,43,43,43,43,43,43,43,43,43,43
43,43,43,32,32,32,32,32,32,32,43,43,43
43,43,43,32,0,0,0,0,0,32,43,43,43
43,43,43,32,0,0,0,0,0,32,43,43,43
43,43,43,32,0,0,0,0,0,32,43,43,43
43,43,43,32,0,0,0,0,0,32,43,43,43
43,43,43,32,0,0,0,0,50,32,43,43,43
43,43,43,32,32,32,32,32,32,32,43,43,43
43,43,43,43,43,43,43,43,43,43,43,43,43
43,43,43,43,43,43,43,43,43,43,43,43,43
43,43,43,43,43,43,43,43,43,43,43,43,43
endlayer

layer
43,43,43,43,43,43,43,43,43,43,43,43,43
43,43,43,43,43,43,43,43,43,43,43,43,43
43,43,49,49,49,49,49,49,49,49,49,43,43
43,43,49,32,32,32,32,32,32,32,49,43,43
43,43,49,32,0,0,0,0,0,32,49,43,43
43,43,49,32,0,0,0,0,0,32,49,43,43
43,43,49,32,0,0,0,0,0,32,49,43,43
43,43,49,32,0,0,0,0,0,32,49,43,43
43,43,49,32,0,0,0,0,50,32,49,43,43
43,43,49,32,32,32,32,32,32,32,49,43,43
43,43,49,49,49,49,49,49,49,49,49,43,43
43,43,43,43,43,43,43,43,43,43,43,43,43
43,43,43,43,43,43,43,43,43,43,43,43,43
endlayer

layer
43,43,43,43,43,43,43,43,43,43,43,43,43
43,43,43,43,43,43,43,43,43,43,43,43,43
43,43,43,43,43,43,43,43,43,43,43,43,43
43,43,43,32,44,32,32,32,32,32,43,43,43
43,43,43,32,32,32,32,32,32,32,43,43,43
43,43,43,32,32,32,32,32,32,44,43,43,43
43,43,43,32,32,32,32,32,32,32,43,43,43
43,43,43,44,32,32,32,32,32,32,43,43,43
43,43,43,32,32,32,32,32,50,32,43,43,43
43,43,43,32,44,32,32,32,32,32,43,43,43
43,43,43,43,43,43,43,43,43,43,43,43,43
43,43,43,43,43,43,43,43,43,43,43,43,43
43,43,43,43,43,43,43,43,43,43,43,43,43
endlayer

layer
43,43,43,43,43,43,43,43,43,43,43,43,43
43,43,43,43,43,43,43,43,43,43,43,43,43
43,43,43,43,43,43,43,43,43,43,43,43,43
43,43,43,32,32,32,32,32,32,32,43,43,43
43,43,43,32,0,0,51,0,0,32,43,43,43
43,43,43,32,0,0,0,0,0,32,43,43,43
43,43,43,32,0,0,0,0,0,32,43,43,43
43,43,43,32,0,0,0,0,0,32,43,43,43
43,43,43,32,0,0,0,0,0,32,43,43,43
43,43,43,32,32,32,32,32,32,32,43,43,43
43,43,43,43,43,43,43,43,43,43,43,43,43
43,43,43,43,43,43,43,43,43,43,43,43,43
43,43,43,43,43,43,43,43,43,43,43,43,43
endlayer

layer
43,43,43,43,43,43,43,43,43,43,43,43,43
43,43,43,43,43,43,43,43,43,43,43,43,43
43,43,43,43,43,43,43,43,43,43,43,43,43
43,43,43,32,32,32,32,32,44,32,43,43,43
43,43,43,32,0,0,51,0,0,32,43,43,43
43,43,43,32,0,0,0,0,0,32,43,43,43
43,43,43,32,0,0,0,0,0,32,43,43,43
43,43,43,32,0,0,0,0,0,32,43,43,43
43,43,43,32,0,0,0,0,0,32,43,43,43
43,43,43,32,32,32,0,32,32,32,43,43,43
43,43,43,43,43,43,43,43,43,43,43,43,43
43,43,43,43,43,43,43,43,43,43,43,43,43
43,43,43,43,43,43,43,43,43,43,43,43,43
endlayer

layer
43,43,43,43,43,43,43,43,43,43,43,43,43
43,43,43,43,43,43,43,43,43,43,43,43,43
43,43,43,43,43,43,43,43,43,43,43,43,43
43,43,43,32,32,32,32,32,32,32,43,43,43
43,43,43,32,0,31,51,31,0,32,43,43,43
43,43,43,32,0,0,0,0,0,32,43,43,43
43,43,43,32,0,0,0,0,0,32,43,43,43
43,43,43,32,0,0,0,0,0,44,43,43,43
43,43,43,32,0,35,0,35,0,32,43,43,43
43,43,43,32,32,32,0,32,32,32,43,43,43
43,43,43,43,43,43,43,43,43,43,43,43,43
43,43,43,43,43,43,43,43,43,43,43,43,43
43,43,43,43,43,43,43,43,43,43,43,43,43
endlayer

layer
43,43,43,43,43,43,43,43,43,43,43,43,43
43,43,43,43,43,43,43,43,43,43,43,43,43
43,43,43,43,43,43,43,43,43,43,43,43,43
43,43,43,32,32,32,32,32,32,32,43,43,43
43,43,43,32,0,0,51,0,0,32,43,43,43
43,43,43,32,0,0,0,0,0,32,43,43,43
43,43,43,44,0,0,0,0,0,32,43,43,43
43,43,43,32,0,0,0,0,0,32,43,43,43
43,43,43,32,0,0,0,0,0,32,43,43,43
43,43,43,32,32,32,32,44,32,32,43,43,43
43,43,43,43,43,43,43,43,43,43,43,43,43
43,43,43,43,43,43,43,43,43,43,43,43,43
43,43,43,43,43,43,43,43,43,43,43,43,43
endlayer

layer
43,43,43,43,43,43,43,43,43,43,43,43,43
43,43,43,43,43,43,43,43,43,43,43,43,43
43,43,52,52,52,52,52,52,52,52,52,43,43
43,43,54,32,32,32,32,32,32,32,53,43,43
43,43,54,32,55,55,51,55,55,32,53,43,43
43,43,54,32,55,55,55,55,55,32,53,43,43
43,43,54,32,55,55,55,55,55,32,53,43,43
43,43,54,32,55,55,55,55,55,32,53,43,43
43,43,54,32,55,55,55,55,55,32,53,43,43
43,43,54,32,32,32,32,32,32,32,53,43,43
43,43,56,56,56,56,56,56,56,56,53,43,43
43,43,43,43,43,43,43,43,43,43,43,43,43
43,43,43,43,43,43,43,43,43,43,43,43,43
endlayer

layer
43,43,43,43,43,43,43,43,43,43,43,43,43
43,43,43,43,43,43,43,43,43,43,43,43,43
43,43,55,55,55,55,55,55,55,55,55,43,43
43,43,55,57,55,57,55,57,55,57,55,43,43
43,43,55,55,0,0,0,0,0,55,55,43,43
43,43,55,57,0,0,0,0,0,57,55,43,43
43,43,55,55,0,0,0,0,0,55,55,43,43
43,43,55,57,0,0,0,0,0,57,55,43,43
43,43,55,55,0,0,0,0,0,55,55,43,43
43,43,55,57,55,57,55,57,55,57,55,43,43
43,43,55,55,55,55,55,55,55,55,55,43,43
43,43,43,43,43,43,43,43,43,43,43,43,43
43,43,43,43,43,43,43,43,43,43,43,43,43
endlayer

layer
43,43,43,43,43,43,43,43,43,43,43,43,43
43,43,43,43,43,43,43,43,43,43,43,43,43
43,43,43,43,43,43,43,43,43,43,43,43,43
43,43,43,57,0,57,0,57,0,57,43,43,43
43,43,43,0,0,0,0,0,0,0,43,43,43
43,43,43,57,0,0,0,0,0,57,43,43,43
43,43,43,0,0,0,0,0,0,0,43,43,43
43,43,43,57,0,0,0,0,0,57,43,43,43
43,43,43,0,0,0,0,0,0,0,43,43,43
43,43,43,57,0,57,0,57,0,57,43,43,43
43,43,43,43,43,43,43,43,43,43,43,43,43
43,43,43,43,43,43,43,43,43,43,43,43,43
43,43,43,43,43,43,43,43,43,43,43,43,43
endlayer

layer
43,43,43,43,43,43,43,43,43,43,43,43,43
43,43,43,43,43,43,43,43,43,43,43,43,43
43,43,43,43,43,43,43,43,43,43,43,43,43
43,43,43,57,57,57,57,57,57,57,43,43,43
43,43,43,57,0,0,0,0,0,57,43,43,43
43,43,43,57,0,0,0,0,0,57,43,43,43
43,43,43,57,0,0,0,0,0,57,43,43,43
43,43,43,57,0,0,0,0,0,57,43,43,43
43,43,43,57,0,0,0,0,0,57,43,43,43
43,43,43,57,57,57,57,57,57,57,43,43,43
43,43,43,43,43,43,43,43,43,43,43,43,43
43,43,43,43,43,43,43,43,43,43,43,43,43
43,43,43,43,43,43,43,43,43,43,43,43,43
endlayer

layer
43,43,43,43,43,43,43,43,43,43,43,43,43
43,43,43,43,43,43,43,43,43,43,43,43,43
43,43,43,60,59,59,59,59,59,58,43,43,43
43,43,59,60,57,57,57,57,57,59,58,43,43
43,43,60,57,57,0,0,0,57,57,58,43,43
43,43,60,57,0,0,0,0,0,57,58,43,43
43,43,60,57,0,0,0,0,0,57,58,43,43
43,43,60,57,0,0,0,0,0,57,58,43,43
43,43,60,57,57,0,0,0,57,57,58,43,43
43,43,61,61,57,57,57,57,57,58,61,43,43
43,43,43,60,61,61,61,61,61,58,43,43,43
43,43,43,43,43,43,43,43,43,43,43,43,43
43,43,43,43,43,43,43,43,43,43,43,43,43
endlayer

layer
43,43,43,43,43,43,43,43,43,43,43,43,43
43,43,43,43,43,43,43,43,43,43,43,43,43
43,43,43,43,43,43,43,43,43,43,43,43,43
43,43,43,43,55,55,55,55,55,43,43,43,43
43,43,43,55,55,57,57,57,55,55,43,43,43
43,43,43,55,57,0,0,0,57,55,43,43,43
43,43,43,55,57,0,0,0,57,55,43,43,43
43,43,43,55,57,0,0,0,57,55,43,43,43
43,43,43,55,55,57,57,57,55,55,43,43,43
43,43,43,43,55,55,55,55,55,43,43,43,43
43,43,43,43,43,43,43,43,43,43,43,43,43
43,43,43,43,43,43,43,43,43,43,43,43,43
43,43,43,43,43,43,43,43,43,43,43,43,43
endlayer

layer
43,43,43,43,43,43,43,43,43,43,43,43,43
43,43,43,43,43,43,43,43,43,43,43,43,43
43,43,43,43,43,43,43,43,43,43,43,43,43
43,43,43,43,43,43,43,43,43,43,43,43,43
43,43,43,43,43,55,57,55,43,43,43,43,43
43,43,43,43,55,57,0,57,55,43,43,43,43
43,43,43,43,57,0,0,0,57,43,43,43,43
43,43,43,43,55,57,0,57,55,43,43,43,43
43,43,43,43,43,55,57,55,43,43,43,43,43
43,43,43,43,43,43,43,43,43,43,43,43,43
43,43,43,43,43,43,43,43,43,43,43,43,43
43,43,43,43,43,43,43,43,43,43,43,43,43
43,43,43,43,43,43,43,43,43,43,43,43,43
endlayer

layer
43,43,43,43,43,43,43,43,43,43,43,43,43
43,43,43,43,43,43,43,43,43,43,43,43,43
43,43,43,43,43,43,43,43,43,43,43,43,43
43,43,43,43,43,43,43,43,43,43,43,43,43
43,43,43,43,43,43,55,43,43,43,43,43,43
43,43,43,43,43,55,57,58,43,43,43,43,43
43,43,43,43,55,57,57,57,55,43,43,43,43
43,43,43,43,43,55,57,55,43,43,43,43,43
43,43,43,43,43,43,55,43,43,43,43,43,43
43,43,43,43,43,43,43,43,43,43,43,43,43
43,43,43,43,43,43,43,43,43,43,43,43,43
43,43,43,43,43,43,43,43,43,43,43,43,43
43,43,43,43,43,43,43,43,43,43,43,43,43
endlayer

layer
43,43,43,43,43,43,43,43,43,43,43,43,43
43,43,43,43,43,43,43,43,43,43,43,43,43
43,43,43,43,43,43,43,43,43,43,43,43,43
43,43,43,43,43,43,43,43,43,43,43,43,43
43,43,43,43,43,43,43,43,43,43,43,43,43
43,43,43,43,43,43,55,43,43,43,43,43,43
43,43,43,43,43,55,57,55,43,43,43,43,43
43,43,43,43,43,43,55,43,43,43,43,43,43
43,43,43,43,43,43,43,43,43,43,43,43,43
43,43,43,43,43,43,43,43,43,43,43,43,43
43,43,43,43,43,43,43,43,43,43,43,43,43
43,43,43,43,43,43,43,43,43,43,43,43,43
43,43,43,43,43,43,43,43,43,43,43,43,43
endlayer

layer
43,43,43,43,43,43,43,43,43,43,43,43,43
43,43,43,43,43,43,43,43,43,43,43,43,43
43,43,43,43,43,43,43,43,43,43,43,43,43
43,43,43,43,43,43,43,43,43,43,43,43,43
43,43,43,43,43,43,43,43,43,43,43,43,43
43,43,43,43,43,43,43,43,43,43,43,43,43
43,43,43,43,43,43,55,43,43,43,43,43,43
43,43,43,43,43,43,43,43,43,43,43,43,43
43,43,43,43,43,43,43,43,43,43,43,43,43
43,43,43,43,43,43,43,43,43,43,43,43,43
43,43,43,43,43,43,43,43,43,43,43,43,43
43,43,43,43,43,43,43,43,43,43,43,43,43
43,43,43,43,43,43,43,43,43,43,43,43,43
endlayer

