
# Created by Ruins mod version 14.0 Ingame Parser
# authoring Player: Kujaku10
# Created 10/31/2004
# Updated to MC 1.11: 15 Jan 2017
# Updated to MC 1.12: 23 Jun 2017
# Updated to MC 1.12.1: 10 Sep 2017

biomesToSpawnIn=alps,alps forest,alps_foothills,alpine,birch forest,birch_forest,cherry blossom grove,cherry_blossom_grove,clearing,dead forest,dead_forest,dead swamp,dead_swamp,deadlands,desert,eerie,eldritch,extreme hills,extreme_hills,extreme hills edge,extreme hills m,extreme hills+,extreme_hills_with_trees,extreme hills+ m,forest,foresthills,forest_hills,green hills,magical forest,meadow,mega taiga hills,mountain,mountain ridge,mutated_extreme_hills,mutated_extreme_hills_with_trees,mystic grove,mystic_grove,ominous woods,ominous_woods,origin_island,pasture,prairie,shield,scrubland,shrubland,silkglades,smaller_extreme_hills,taiga,taigahills,taiga_hills,tainted land,thinned mystic grove,thinned timber,twilight clearing,wonderous woods,woodland,woodlands

weight=1
embed_into_distance=5
acceptable_target_blocks=

unacceptable_target_blocks=flowing_water,water,flowing_lava,lava,cloud,Natura:Cloud,slime_congealed,slime_dirt,slime_grass,command_block,planks,planks2,concrete,cobblestone,stonebrick,brick_block,glass,torch,oak_stairs,stone_stairs,brick_stairs,stone_brick_stairs,nether_brick_stairs,sandstone_stairs,spruce_stairs,birch_stairs,jungle_stairs,quartz_stairs,acacia_stairs,dark_oak_stairs,cobblestone_wall,stone_slab,double_stone_slab,stone_slab2,wooden_slab,double_wooden_slab,nether_brick,fence

dimensions=29,11,11
allowable_overhang=0
max_leveling=5
leveling_buffer=-1
preserve_water=0
preserve_lava=0
preserve_plants=1

rule1=0,100,minecraft:stone_brick_stairs-0
rule2=0,100,preserveBlock

rule3=0,100,minecraft:stonebrick-0,minecraft:stonebrick-1,minecraft:stonebrick-2,minecraft:stonebrick-0,minecraft:stonebrick-0

rule4=0,100,minecraft:double_stone_slab-0
rule5=0,100,minecraft:stone_brick_stairs-2
rule6=0,100,minecraft:stone_brick_stairs-1
rule7=0,100,minecraft:stone_brick_stairs-6
rule8=0,100,minecraft:stone_brick_stairs-3

rule9=0,100,ChestGenHook:chests/simple_dungeon:3-5

rule10=0,100,minecraft:web-0
rule11=0,100,minecraft:cobblestone_wall-0

rule12=0,100,IInventory;minecraft:chest;minecraft:rotten_flesh#1#0#0+minecraft:bone#2#0#1+minecraft:web#1#0#4+minecraft:bone#3#0#6+minecraft:web#1#0#8+minecraft:skull#1#0#10+minecraft:bone#2#0#12+minecraft:web#2#0#15+minecraft:web#1#0#18+minecraft:rotten_flesh#1#0#22+minecraft:bone#3#0#23+minecraft:skull#1#0#24+minecraft:web#1#0#26-3

rule13=0,100,IInventory;minecraft:chest;minecraft:web#2#0#2+minecraft:rotten_flesh#3#0#6+minecraft:skull#1#0#9+minecraft:rotten_flesh#1#0#11+minecraft:web#1#0#13+minecraft:stone#22#0#14+minecraft:web#1#0#16+minecraft:web#1#0#19+minecraft:skull#1#0#23-2

rule14=0,100,IInventory;minecraft:chest;minecraft:skull#1#0#1+minecraft:stone#22#0#4+minecraft:web#2#0#6+minecraft:rotten_flesh#2#0#10+minecraft:web#4#0#11+minecraft:rotten_flesh#2#0#21+minecraft:web#1#0#23+minecraft:skull#1#0#25-4

rule15=0,100,Skull:0:6-1
rule16=0,100,Skull:0:2-1
rule17=0,100,Skull:0:10-1
rule18=0,100,Skull:0:14-1

rule19=0,100,minecraft:stone_brick_stairs-7
rule20=0,100,minecraft:stone_brick_stairs-5
rule21=0,100,minecraft:stone_brick_stairs-4
rule22=0,100,minecraft:stone_slab-0
rule23=0,100,minecraft:planks-0
rule24=2,100,minecraft:redstone_torch-1
rule25=2,100,minecraft:redstone_torch-2

rule26=0,100,MobSpawner:Zombie,MobSpawner:Skeleton,MobSpawner:Spider

rule27=0,100,minecraft:stone_slab-5

layer
2,2,2,2,2,2,2,2,2,2,1
2,2,2,2,2,2,2,2,2,2,3
2,2,3,3,3,3,3,3,3,2,4
2,2,3,4,4,4,4,4,3,2,5
2,2,3,4,4,4,4,4,3,3,4
2,2,3,4,4,4,4,4,3,3,5
2,2,3,4,4,4,4,4,3,3,4
2,2,3,4,4,4,4,4,3,2,5
2,2,3,3,3,3,3,3,3,2,4
2,2,2,2,2,2,2,2,2,2,3
2,2,2,2,2,2,2,2,2,2,6
endlayer

layer
2,2,2,2,2,2,2,2,2,2,2
2,2,2,2,2,2,2,2,2,2,1
2,2,3,3,3,3,3,3,3,2,4
2,2,3,3,5,9,8,3,3,2,7
2,2,3,6,0,0,10,6,3,3,4
2,2,3,13,0,0,0,12,3,3,11
2,2,3,1,10,0,0,1,3,3,4
2,2,3,3,5,14,8,3,3,2,7
2,2,3,3,3,3,3,3,3,2,4
2,2,2,2,2,2,2,2,2,2,6
2,2,2,2,2,2,2,2,2,2,2
endlayer

layer
2,2,2,2,2,2,2,2,2,2,2
2,2,2,2,2,2,2,2,2,2,2
2,2,3,3,3,3,3,3,3,2,1
2,2,3,16,10,0,0,15,3,2,4
2,2,3,0,0,0,0,0,3,3,4
2,2,3,0,0,0,0,0,3,3,7
2,2,3,10,0,0,0,10,3,3,4
2,2,3,18,0,0,10,17,3,2,4
2,2,3,3,3,3,3,3,3,2,6
2,2,2,2,2,2,2,2,2,2,2
2,2,2,2,2,2,2,2,2,2,2
endlayer

layer
2,2,2,2,2,2,2,2,2,2,2
2,2,2,2,2,2,2,2,2,2,2
2,2,3,3,3,3,3,3,3,2,2
2,2,3,3,7,10,19,3,3,2,1
2,2,3,20,0,0,0,20,3,3,4
2,2,3,10,0,0,0,10,3,3,4
2,2,3,21,0,0,0,21,3,3,4
2,2,3,3,7,10,19,3,3,2,6
2,2,3,3,3,3,3,3,3,2,2
2,2,2,2,2,2,2,2,2,2,2
2,2,2,2,2,2,2,2,2,2,2
endlayer

layer
2,2,2,2,2,2,2,2,2,2,2
2,2,2,2,2,2,2,2,2,2,2
2,2,3,3,3,3,3,3,3,2,2
2,2,3,4,4,4,4,4,3,2,2
2,2,3,4,4,4,4,4,3,4,2
2,2,3,4,4,4,4,4,3,4,22
2,2,3,4,4,4,4,4,3,4,2
2,2,3,4,4,4,4,4,3,2,2
2,2,3,3,3,3,3,3,3,2,2
2,2,2,2,2,2,2,2,2,2,2
2,2,2,2,2,2,2,2,2,2,2
endlayer

layer
2,2,2,2,2,2,2,2,2,2,2
2,2,2,2,2,2,2,2,2,2,2
2,2,8,1,3,3,3,1,5,2,2
2,2,1,3,0,0,0,3,1,2,2
2,2,3,3,5,0,0,15,3,22,2
2,2,3,16,0,0,0,0,0,0,2
2,2,3,10,0,0,0,0,3,22,2
2,2,6,3,0,0,0,3,6,2,2
2,2,8,6,3,3,3,6,5,2,2
2,2,2,2,2,2,2,2,2,2,2
2,2,2,2,2,2,2,2,2,2,2
endlayer

layer
2,2,2,2,2,2,2,2,2,2,2
2,2,2,2,2,2,2,2,2,2,2
2,2,2,2,3,23,3,2,2,2,2
2,2,2,3,0,0,0,3,2,2,2
2,2,3,5,0,0,0,24,3,2,2
2,2,3,3,0,0,0,0,0,0,2
2,2,3,0,0,0,0,25,3,2,2
2,2,2,3,0,0,0,3,2,2,2
2,2,2,2,3,23,3,2,2,2,2
2,2,2,2,2,2,2,2,2,2,2
2,2,2,2,2,2,2,2,2,2,2
endlayer

layer
2,2,2,2,2,2,2,2,2,2,2
2,2,2,2,2,2,2,2,2,2,2
2,2,2,2,3,23,3,2,2,2,2
2,2,2,3,10,0,10,3,2,2,2
2,2,3,0,0,0,0,10,3,2,2
2,2,3,1,0,0,0,0,3,2,2
2,2,3,3,0,0,0,10,3,2,2
2,2,2,3,10,0,10,3,2,2,2
2,2,2,2,3,23,3,2,2,2,2
2,2,2,2,2,2,2,2,2,2,2
2,2,2,2,2,2,2,2,2,2,2
endlayer

layer
2,2,2,2,2,2,2,2,2,2,2
2,2,2,2,2,2,2,2,2,2,2
2,2,2,2,3,3,3,2,2,2,2
2,2,2,3,3,3,3,3,2,2,2
2,2,3,10,0,3,3,3,3,2,2
2,2,3,0,3,3,3,3,3,2,2
2,2,3,1,3,3,3,3,3,2,2
2,2,2,3,3,3,3,3,2,2,2
2,2,2,2,3,3,3,2,2,2,2
2,2,2,2,2,2,2,2,2,2,2
2,2,2,2,2,2,2,2,2,2,2
endlayer

layer
2,2,2,2,2,2,2,2,2,2,2
2,2,2,2,2,2,2,2,2,2,2
2,2,2,2,3,3,3,2,2,2,2
2,2,2,3,0,9,15,3,2,2,2
2,2,3,0,0,0,0,0,3,2,2
2,2,3,0,0,0,0,0,3,2,2
2,2,3,0,0,0,8,3,3,2,2
2,2,2,3,0,0,0,3,2,2,2
2,2,2,2,3,3,3,2,2,2,2
2,2,2,2,2,2,2,2,2,2,2
2,2,2,2,2,2,2,2,2,2,2
endlayer

layer
2,2,2,2,2,2,2,2,2,2,2
2,2,2,2,2,2,2,2,2,2,2
2,2,2,2,3,23,3,2,2,2,2
2,2,2,3,0,0,0,3,2,2,2
2,2,3,24,0,0,0,0,3,2,2
2,2,3,0,0,0,0,3,3,2,2
2,2,3,25,0,0,0,8,3,2,2
2,2,2,3,0,0,0,3,2,2,2
2,2,2,2,3,23,3,2,2,2,2
2,2,2,2,2,2,2,2,2,2,2
2,2,2,2,2,2,2,2,2,2,2
endlayer

layer
2,2,2,2,2,2,2,2,2,2,2
2,2,2,2,2,2,2,2,2,2,2
2,2,2,2,3,23,3,2,2,2,2
2,2,2,3,0,0,0,3,2,2,2
2,2,3,0,0,0,0,3,3,2,2
2,2,3,0,0,0,0,6,3,2,2
2,2,3,0,0,0,0,0,3,2,2
2,2,2,3,0,0,0,3,2,2,2
2,2,2,2,3,23,3,2,2,2,2
2,2,2,2,2,2,2,2,2,2,2
2,2,2,2,2,2,2,2,2,2,2
endlayer

layer
2,2,2,2,2,2,2,2,2,2,2
2,2,2,2,2,2,2,2,2,2,2
2,2,2,2,3,3,3,2,2,2,2
2,2,2,3,3,3,3,3,2,2,2
2,2,3,3,3,3,3,6,3,2,2
2,2,3,3,3,3,3,0,3,2,2
2,2,3,3,3,3,0,0,3,2,2
2,2,2,3,3,3,3,3,2,2,2
2,2,2,2,3,3,3,2,2,2,2
2,2,2,2,2,2,2,2,2,2,2
2,2,2,2,2,2,2,2,2,2,2
endlayer

layer
2,2,2,2,2,2,2,2,2,2,2
2,2,2,2,2,2,2,2,2,2,2
2,2,2,2,3,3,3,2,2,2,2
2,2,2,3,0,9,0,3,2,2,2
2,2,3,3,5,0,0,0,3,2,2
2,2,3,26,0,0,0,0,3,2,2
2,2,3,0,0,0,0,0,3,2,2
2,2,2,3,0,0,17,3,2,2,2
2,2,2,2,3,3,3,2,2,2,2
2,2,2,2,2,2,2,2,2,2,2
2,2,2,2,2,2,2,2,2,2,2
endlayer

layer
2,2,2,2,2,2,2,2,2,2,2
2,2,2,2,2,2,2,2,2,2,2
2,2,2,2,3,23,3,2,2,2,2
2,2,2,3,0,0,0,3,2,2,2
2,2,3,5,0,0,0,24,3,2,2
2,2,3,3,0,0,0,0,3,2,2
2,2,3,0,0,0,0,25,3,2,2
2,2,2,3,0,0,0,3,2,2,2
2,2,2,2,3,23,3,2,2,2,2
2,2,2,2,2,2,2,2,2,2,2
2,2,2,2,2,2,2,2,2,2,2
endlayer

layer
2,2,2,2,2,2,2,2,2,2,2
2,2,2,2,2,2,2,2,2,2,2
2,2,2,2,3,23,3,2,2,2,2
2,2,2,3,0,0,10,3,2,2,2
2,2,3,0,0,0,0,0,3,2,2
2,2,3,1,0,0,0,0,3,2,2
2,2,3,3,0,0,0,10,3,2,2
2,2,2,3,0,0,0,3,2,2,2
2,2,2,2,3,23,3,2,2,2,2
2,2,2,2,2,2,2,2,2,2,2
2,2,2,2,2,2,2,2,2,2,2
endlayer

layer
2,2,2,2,2,2,2,2,2,2,2
2,2,2,2,2,2,2,2,2,2,2
2,2,2,2,3,3,3,2,2,2,2
2,2,2,3,3,3,3,3,2,2,2
2,2,3,0,0,3,3,3,3,2,2
2,2,3,0,3,3,3,3,3,2,2
2,2,3,1,3,3,3,3,3,2,2
2,2,2,3,3,3,3,3,2,2,2
2,2,2,2,3,3,3,2,2,2,2
2,2,2,2,2,2,2,2,2,2,2
2,2,2,2,2,2,2,2,2,2,2
endlayer

layer
2,2,2,2,2,2,2,2,2,2,2
2,2,2,2,2,2,2,2,2,2,2
2,2,2,2,3,3,3,2,2,2,2
2,2,2,3,0,9,15,3,2,2,2
2,2,3,0,0,0,0,0,3,2,2
2,2,3,0,0,0,0,26,3,2,2
2,2,3,0,0,0,8,3,3,2,2
2,2,2,3,0,0,0,3,2,2,2
2,2,2,2,3,3,3,2,2,2,2
2,2,2,2,2,2,2,2,2,2,2
2,2,2,2,2,2,2,2,2,2,2
endlayer

layer
2,2,2,2,2,2,2,2,2,2,2
2,2,2,2,2,2,2,2,2,2,2
2,2,2,2,3,23,3,2,2,2,2
2,2,2,3,0,0,0,3,2,2,2
2,2,3,24,0,0,0,0,3,2,2
2,2,3,0,0,0,0,3,3,2,2
2,2,3,25,0,0,0,8,3,2,2
2,2,2,3,0,0,0,3,2,2,2
2,2,2,2,3,23,3,2,2,2,2
2,2,2,2,2,2,2,2,2,2,2
2,2,2,2,2,2,2,2,2,2,2
endlayer

layer
2,2,2,2,2,2,2,2,2,2,2
2,2,2,2,2,2,2,2,2,2,2
2,2,2,2,3,23,3,2,2,2,2
2,2,2,3,0,0,10,3,2,2,2
2,2,3,10,0,0,0,3,3,2,2
2,2,3,0,0,0,0,6,3,2,2
2,2,3,0,0,0,0,0,3,2,2
2,2,2,3,10,0,0,3,2,2,2
2,2,2,2,3,23,3,2,2,2,2
2,2,2,2,2,2,2,2,2,2,2
2,2,2,2,2,2,2,2,2,2,2
endlayer

layer
2,2,2,2,2,2,2,2,2,2,2
2,2,2,2,2,2,2,2,2,2,2
2,2,2,2,3,3,3,2,2,2,2
2,2,2,3,3,3,3,3,2,2,2
2,2,3,3,3,3,3,6,3,2,2
2,2,3,3,3,3,3,0,3,2,2
2,2,3,3,3,3,0,0,3,2,2
2,2,2,3,3,3,3,3,2,2,2
2,2,2,2,3,3,3,2,2,2,2
2,2,2,2,2,2,2,2,2,2,2
2,2,2,2,2,2,2,2,2,2,2
endlayer

layer
2,2,2,2,2,2,2,2,2,2,2
2,2,2,2,2,2,2,2,2,2,2
2,2,2,2,3,3,3,2,2,2,2
2,2,2,3,26,9,26,3,2,2,2
2,2,3,0,0,0,0,0,3,2,2
2,2,3,0,0,0,0,0,3,2,2
2,2,3,10,1,0,0,0,3,2,2
2,2,2,3,3,18,0,3,2,2,2
2,2,2,2,3,3,3,2,2,2,2
2,2,2,2,2,2,2,2,2,2,2
2,2,2,2,2,2,2,2,2,2,2
endlayer

layer
2,2,2,2,2,2,2,2,2,2,2
2,2,2,2,2,2,2,2,2,2,2
2,2,2,2,3,3,3,2,2,2,2
2,2,2,3,0,0,0,3,2,2,2
2,2,3,0,0,0,0,24,3,2,2
2,2,23,0,0,0,0,0,23,2,2
2,2,3,0,0,0,0,25,3,2,2
2,2,2,3,1,3,10,3,2,2,2
2,2,2,2,3,3,3,2,2,2,2
2,2,2,2,2,2,2,2,2,2,2
2,2,2,2,2,2,2,2,2,2,2
endlayer

layer
2,2,2,2,2,2,2,2,2,2,2
2,2,2,2,2,2,2,2,2,2,2
2,2,2,2,3,3,3,2,2,2,2
2,2,2,3,0,0,0,3,2,2,2
2,2,3,0,0,0,0,0,3,2,2
2,2,23,0,0,0,0,0,23,2,2
2,2,3,0,0,0,0,0,3,2,2
2,2,2,3,0,8,3,3,2,2,2
2,2,2,2,3,3,3,2,2,2,2
2,2,2,2,2,2,2,2,2,2,2
2,2,2,2,2,2,2,2,2,2,2
endlayer

layer
2,2,2,2,2,2,2,2,2,2,2
2,2,2,2,21,21,21,2,2,2,2
2,2,2,21,3,3,3,21,2,2,2
2,2,19,3,10,0,0,3,7,2,2
2,19,3,0,0,0,0,10,3,7,2
2,19,3,0,0,0,0,0,3,7,2
2,19,3,10,0,0,0,10,3,7,2
2,2,19,3,0,0,8,3,7,2,2
2,2,2,20,3,3,3,20,2,2,2
2,2,2,2,20,20,20,2,2,2,2
2,2,2,2,2,2,2,2,2,2,2
endlayer

layer
2,2,2,2,22,22,22,2,2,2,2
2,2,2,22,3,3,3,22,2,2,2
2,2,22,3,3,3,3,3,22,2,2
2,22,3,3,3,3,3,3,3,22,2
22,3,3,3,3,3,3,3,3,3,22
22,3,3,3,3,3,3,3,3,3,22
22,3,3,3,3,3,3,3,3,3,22
2,22,3,3,10,0,0,8,3,22,2
2,2,22,3,3,3,3,3,22,2,2
2,2,2,22,3,3,3,22,2,2,2
2,2,2,2,22,22,22,2,2,2,2
endlayer

layer
2,2,2,2,2,2,2,2,2,2,2
2,2,2,2,3,3,3,2,2,2,2
2,2,2,3,22,22,22,3,2,2,2
2,2,3,22,22,22,22,22,3,2,2
2,3,22,22,22,22,22,22,22,3,2
2,3,22,22,22,22,22,22,22,3,2
2,3,22,22,22,22,22,22,22,3,2
2,2,3,22,22,0,0,0,3,2,2
2,2,2,3,22,22,22,3,2,2,2
2,2,2,2,3,3,3,2,2,2,2
2,2,2,2,2,2,2,2,2,2,2
endlayer

layer
2,2,2,2,2,2,2,2,2,2,2
2,2,2,2,3,27,3,2,2,2,2
2,2,2,3,0,0,0,3,2,2,2
2,2,27,0,0,0,0,0,27,2,2
2,3,0,0,0,0,0,0,0,3,2
2,27,0,0,0,0,0,0,0,27,2
2,3,0,0,0,0,0,0,0,3,2
2,2,27,0,0,0,0,0,27,2,2
2,2,2,3,0,0,0,3,2,2,2
2,2,2,2,3,27,3,2,2,2,2
2,2,2,2,2,2,2,2,2,2,2
endlayer

layer
2,2,2,2,2,2,2,2,2,2,2
2,2,2,2,27,0,27,2,2,2,2
2,2,2,27,0,0,0,27,2,2,2
2,2,0,0,0,0,0,0,0,2,2
2,27,0,0,0,0,0,0,0,27,2
2,0,0,0,0,0,0,0,0,0,2
2,27,0,0,0,0,0,0,0,27,2
2,2,0,0,0,0,0,0,0,2,2
2,2,2,27,0,0,0,27,2,2,2
2,2,2,2,27,0,27,2,2,2,2
2,2,2,2,2,2,2,2,2,2,2
endlayer

