# Bandit Manor
# Created by Ruins mod version 15.6 Ingame Parser
# authoring Player: Kujaku10
# Originally created for MC 1.8: 27 Jun 2017
# Updated to MC 1.12: 6 Jul 2018

uniqueMinDistance=1000

biomesToSpawnIn=birch_forest,birch_forest_hills,boreal_forest,brushland,chaparral,cherry_blossom_grove,coniferous_forest,dead_forest,eucalyptus_forest,forest,forest_hills,grassland,grove,land_of_lakes,lavender_fields,lush_desert,maple_woods,meadow,mountain_foothills,mutated_birch_forest,mutated_birch_forest_hills,mutated_forest,mystic_grove,oak_savannah,ominous_woods,orchard,origin_valley,overgrown_cliffs,pasture,rainforest,sacred_springs,seasonal_forest,shield,shrubland,smaller_extreme_hills,snowy_coniferous_forest,snowy_forest,taiga_cold,taiga_cold_hills,taiga_hills,temperate_rainforest,tundra,twilight_clearing,woodland,xeric_shrubland

weight=1
embed_into_distance=6
acceptable_target_blocks=

unacceptable_target_blocks=log,planks,flowing_lava,lava,cloud,Natura:Cloud,red_mushroom_block,brown_mushroom_block,slime_congealed,slime_dirt,slime_grass,command_block,planks2,concrete,cobblestone,stonebrick,brick_block,glass,torch,oak_stairs,stone_stairs,brick_stairs,stone_brick_stairs,nether_brick_stairs,sandstone_stairs,spruce_stairs,birch_stairs,jungle_stairs,quartz_stairs,acacia_stairs,dark_oak_stairs,cobblestone_wall,stone_slab,double_stone_slab,stone_slab2,wooden_slab,double_wooden_slab,nether_brick

dimensions=29,23,16
allowable_overhang=9
max_leveling=6
leveling_buffer=-1
preserve_water=0
preserve_lava=0

rule1=0,100,preserveBlock

rule2=0,100,minecraft:mossy_cobblestone-0,minecraft:cobblestone-0

# Brick Slab
rule3=0,100,minecraft:stone_slab-4

rule4=0,100,minecraft:brick_block-0

rule5=0,100,minecraft:stonebrick-0,minecraft:stonebrick-0,minecraft:stonebrick-1,minecraft:stonebrick-2

rule6=0,100,minecraft:brick_stairs-0

# Spruce Planks
rule7=0,100,minecraft:planks-1

rule8=0,100,minecraft:brick_stairs-2
rule9=0,100,minecraft:brick_stairs-3
rule10=0,100,minecraft:spruce_stairs-1
rule11=0,100,minecraft:brick_stairs-1


# Bandit
rule12=0,100,CommandBlock:RUINSTRIGGER /summon Skeleton ~0 ~0 ~0 {HandItems:[{Count:1,id:wooden_sword,tag:{display:{Name:"Bandit Bludgeon"},ench:[{id:19,lvl:2},{id:21,lvl:2},{id:16,lvl:3}]}},{}],ArmorItems:[{Count:1,id:leather_boots},{Count:1,id:leather_leggings},{Count:1,id:leather_chestplate},{Count:1,id:skull,Damage:3,tag:{SkullOwner:MHF_Villager}}],CustomName:Bandit,HandDropChances:[1.0F,0.0F],ArmorDropChances:[0.5F,0.5F,0.5F,0.0F],Silent:1,PersistenceRequired:1,Health:15.0f}:@

rule13=0,100,minecraft:spruce_stairs-4
rule14=0,100,minecraft:spruce_door-3

rule15=0,100,ChestGenHook:chests/simple_dungeon:3-2

rule16=0,100,minecraft:spruce_door-8

# Spruce Slab
rule17=0,100,minecraft:wooden_slab-1

rule18=0,100,minecraft:spruce_fence-0
rule19=0,100,minecraft:stained_hardened_clay-4
rule20=0,100,minecraft:cobblestone-0
rule21=0,100,minecraft:spruce_stairs-6
rule22=0,100,minecraft:spruce_stairs-5
rule23=0,100,minecraft:spruce_stairs-3
rule24=0,100,minecraft:spruce_stairs-0
rule25=0,100,minecraft:spruce_stairs-7
rule26=0,100,minecraft:stained_hardened_clay-2

# White Concrete
rule27=0,100,minecraft:concrete-0

rule28=2,100,minecraft:torch-1

# Dark Oak Planks
rule29=0,100,minecraft:planks-5

rule30=0,100,minecraft:dark_oak_stairs-3
rule31=0,100,minecraft:wooden_slab-5
rule32=2,100,minecraft:torch-2
rule33=0,100,minecraft:dark_oak_stairs-0
rule34=0,100,minecraft:trapdoor-5
rule35=0,100,minecraft:trapdoor-4
rule36=0,100,minecraft:trapdoor-6
rule37=0,100,minecraft:trapdoor-13
rule38=0,100,minecraft:trapdoor-14
rule39=0,100,minecraft:ladder-2
rule40=0,100,minecraft:dark_oak_stairs-1
rule41=0,100,minecraft:dark_oak_stairs-4
rule42=0,100,minecraft:dark_oak_stairs-5
rule43=0,100,minecraft:dark_oak_stairs-2
rule44=0,100,minecraft:wooden_slab-13
rule45=0,100,minecraft:flower_pot-0
rule46=0,100,minecraft:trapdoor-12
rule47=0,100,ChestGenHook:chests/simple_dungeon:3-5

layer
1,1,1,1,1,1,1,1,1,1,1,1,1,1,1,1
1,1,1,1,1,1,1,1,1,1,1,1,1,1,1,1
1,1,1,1,1,1,1,1,1,1,1,1,1,1,1,1
1,1,1,1,1,1,1,1,1,1,1,1,1,1,1,1
1,1,1,1,1,1,1,1,1,1,1,1,1,1,1,1
1,1,1,1,1,1,1,1,1,1,1,1,1,1,1,1
1,1,1,1,2,2,2,2,2,2,2,1,1,1,1,1
1,1,1,1,2,3,3,3,3,3,2,1,1,1,1,1
4,4,1,1,2,3,3,3,3,3,2,1,1,1,1,1
4,4,1,1,2,3,3,3,3,3,2,1,1,1,1,1
4,4,1,1,2,3,3,3,3,3,2,1,1,1,1,1
4,4,1,1,2,3,3,3,3,3,2,1,1,1,1,1
4,4,1,1,2,3,3,3,3,3,2,1,1,1,1,1
5,5,5,5,5,5,3,3,3,3,2,1,1,1,1,1
5,3,3,3,3,5,3,3,3,3,2,1,1,1,1,1
5,3,3,3,6,5,6,3,3,3,2,1,1,1,1,1
5,4,3,3,9,4,8,3,3,7,2,1,1,1,1,1
5,3,3,3,11,5,11,3,3,10,2,1,1,1,1,1
5,3,3,3,3,5,3,3,3,3,2,1,1,1,1,1
5,5,5,5,5,5,3,3,3,3,2,1,1,1,1,1
1,1,1,1,2,2,2,2,2,2,2,1,1,1,1,1
1,1,1,1,1,1,1,1,1,1,1,1,1,1,1,1
1,1,1,1,1,1,1,1,1,1,1,1,1,1,1,1
endlayer

layer
1,1,1,1,1,1,1,1,1,1,1,1,1,1,1,1
1,1,1,1,1,1,1,1,1,1,1,1,1,1,1,1
1,1,1,1,1,1,1,1,1,1,1,1,1,1,1,1
1,1,1,1,1,1,1,1,1,1,1,1,1,1,1,1
1,1,1,1,1,1,1,1,1,1,1,1,1,1,1,1
1,1,1,1,1,1,1,1,1,1,1,1,1,1,1,1
1,1,1,1,2,2,2,2,2,2,2,1,1,1,1,1
1,1,1,1,2,12,0,0,0,12,2,1,1,1,1,1
1,1,1,1,2,0,0,0,0,0,2,1,1,1,1,1
4,4,1,1,2,0,0,0,0,0,2,1,1,1,1,1
4,4,1,1,2,0,0,0,0,0,2,1,1,1,1,1
4,4,1,1,2,0,0,0,0,0,2,1,1,1,1,1
4,4,1,1,2,0,0,0,0,0,2,1,1,1,1,1
5,5,5,5,5,5,0,0,0,0,2,1,1,1,1,1
5,12,0,0,0,5,0,0,0,0,2,1,1,1,1,1
5,0,0,0,0,5,0,0,0,13,2,1,1,1,1,1
5,15,0,0,0,14,0,0,0,10,2,1,1,1,1,1
5,0,0,0,0,5,0,0,0,0,2,1,1,1,1,1
5,12,0,0,0,5,0,0,0,0,2,1,1,1,1,1
5,5,5,5,5,5,0,0,0,0,2,1,1,1,1,1
1,1,1,1,2,2,2,2,2,2,2,1,1,1,1,1
1,1,1,1,1,1,1,1,1,1,1,1,1,1,1,1
1,1,1,1,1,1,1,1,1,1,1,1,1,1,1,1
endlayer

layer
1,1,1,1,1,1,1,1,1,1,1,1,1,1,1,1
1,1,1,1,1,1,1,1,1,1,1,1,1,1,1,1
1,1,1,1,1,1,1,1,1,1,1,1,1,1,1,1
1,1,1,1,1,1,1,1,1,1,1,1,1,1,1,1
1,1,1,1,1,1,1,1,1,1,1,1,1,1,1,1
1,1,1,1,1,1,1,1,1,1,1,1,1,1,1,1
1,1,1,1,2,2,2,2,2,2,2,1,1,1,1,1
1,1,1,1,2,0,0,0,0,0,2,1,1,1,1,1
1,1,1,1,2,0,0,0,0,0,2,1,1,1,1,1
1,1,1,1,2,0,0,0,0,0,2,1,1,1,1,1
4,4,1,1,2,0,0,0,0,0,2,1,1,1,1,1
4,4,1,1,2,0,0,0,0,0,2,1,1,1,1,1
4,4,1,1,2,0,0,0,0,0,2,1,1,1,1,1
5,5,5,5,5,5,0,0,0,0,2,1,1,1,1,1
5,0,0,0,0,5,0,0,0,13,2,1,1,1,1,1
5,0,0,0,0,5,0,0,0,10,2,1,1,1,1,1
5,0,0,0,0,16,0,0,0,0,2,1,1,1,1,1
5,0,0,0,0,5,0,0,0,0,2,1,1,1,1,1
5,0,0,0,0,5,0,0,0,0,2,1,1,1,1,1
5,5,5,5,5,5,0,0,0,0,2,1,1,1,1,1
1,1,1,1,2,2,2,2,2,2,2,1,1,1,1,1
1,1,1,1,1,1,1,1,1,1,1,1,1,1,1,1
1,1,1,1,1,1,1,1,1,1,1,1,1,1,1,1
endlayer

layer
1,1,1,1,1,1,1,1,1,1,1,1,1,1,1,1
1,1,1,1,1,1,1,1,1,1,1,1,1,1,1,1
1,1,1,1,1,1,1,1,1,1,1,1,1,1,1,1
1,1,1,1,1,1,1,1,1,1,1,1,1,1,1,1
1,1,1,1,1,1,1,1,1,1,1,1,1,1,1,1
1,1,1,1,1,1,1,1,1,1,1,1,1,1,1,1
1,1,1,1,2,2,2,2,2,2,2,1,1,1,1,1
1,1,1,1,2,0,0,0,0,0,2,1,1,1,1,1
1,1,1,1,2,0,0,0,0,0,2,1,1,1,1,1
1,1,1,1,2,0,0,0,0,0,2,1,1,1,1,1
1,1,1,1,2,0,0,0,0,0,2,1,1,1,1,1
4,4,1,1,2,0,0,0,0,0,2,1,1,1,1,1
4,4,1,1,2,0,0,0,0,0,2,1,1,1,1,1
5,5,5,5,5,5,0,0,0,13,2,1,1,1,1,1
5,0,0,0,0,5,0,0,0,10,2,1,1,1,1,1
5,0,0,0,0,5,0,0,0,0,2,1,1,1,1,1
5,0,0,0,0,5,0,0,0,0,2,1,1,1,1,1
5,0,0,0,0,5,0,0,0,0,2,1,1,1,1,1
5,0,0,0,0,5,0,0,0,0,2,1,1,1,1,1
5,5,5,5,5,5,0,0,0,0,2,1,1,1,1,1
1,1,1,1,2,2,2,2,2,2,2,1,1,1,1,1
1,1,1,1,1,1,1,1,1,1,1,1,1,1,1,1
1,1,1,1,1,1,1,1,1,1,1,1,1,1,1,1
endlayer

layer
1,1,1,1,1,1,1,1,1,1,1,1,1,1,1,1
1,1,1,1,1,1,1,1,1,1,1,1,1,1,1,1
1,1,1,1,1,1,1,1,1,1,1,1,1,1,1,1
1,1,1,1,1,1,1,1,1,1,1,1,1,1,1,1
1,1,1,1,1,1,1,1,1,1,1,1,1,1,1,1
1,1,1,1,1,1,1,1,1,1,1,1,1,1,1,1
1,1,1,1,2,2,2,2,2,2,2,1,1,1,1,1
1,1,1,1,2,17,17,17,17,17,2,1,1,1,1,1
1,1,1,1,2,17,17,17,17,17,2,1,1,1,1,1
1,1,1,1,2,17,17,17,17,17,2,1,1,1,1,1
1,1,1,1,2,17,17,17,17,17,2,1,1,1,1,1
1,1,1,1,2,17,17,17,17,17,2,1,1,1,1,1
4,4,1,1,2,17,17,17,17,13,2,1,1,1,1,1
5,5,5,5,5,5,17,17,17,10,2,1,1,1,1,1
5,5,5,5,17,17,17,17,17,0,2,1,1,1,1,1
5,5,5,5,7,17,17,17,7,0,2,1,1,1,1,1
5,5,5,5,17,17,17,17,7,0,2,1,1,1,1,1
5,5,5,5,7,17,17,17,7,7,2,1,1,1,1,1
5,5,5,5,17,17,17,17,17,17,2,1,1,1,1,1
5,5,5,5,5,5,17,17,17,17,2,1,1,1,1,1
1,1,1,1,2,2,2,2,2,2,2,1,1,1,1,1
1,1,1,1,1,1,1,1,1,1,1,1,1,1,1,1
1,1,1,1,1,1,1,1,1,1,1,1,1,1,1,1
endlayer

layer
1,1,1,1,1,1,1,1,1,1,1,1,1,1,1,1
1,1,1,1,1,1,1,1,1,1,1,1,1,1,1,1
1,1,1,1,1,1,1,1,1,1,1,1,1,1,1,1
1,1,1,1,1,1,1,1,1,1,1,1,1,1,1,1
1,1,1,1,1,1,1,1,1,1,1,1,1,1,1,1
1,1,1,1,1,1,1,1,1,1,1,1,1,1,1,1
1,1,1,1,2,2,2,2,2,2,2,1,1,1,1,1
1,1,1,1,2,12,0,0,0,12,2,1,1,1,1,1
1,1,1,1,2,0,0,0,0,0,2,1,1,1,1,1
1,1,1,1,2,0,0,0,0,0,2,1,1,1,1,1
1,1,1,1,2,0,0,0,0,0,2,1,1,1,1,1
1,1,1,1,2,0,0,0,0,13,2,1,1,1,1,1
1,1,1,1,2,0,0,0,0,10,2,1,1,1,1,1
4,4,5,5,5,5,0,0,0,0,2,1,1,1,1,1
4,4,5,5,0,0,0,0,0,0,2,1,1,1,1,1
4,4,5,5,15,0,0,0,18,0,2,1,1,1,1,1
4,4,5,5,0,0,0,0,18,0,2,1,1,1,1,1
4,4,5,5,15,0,0,0,18,18,2,1,1,1,1,1
4,4,5,5,0,0,0,0,0,0,2,1,1,1,1,1
4,4,5,5,5,5,12,0,0,12,2,1,1,1,1,1
1,1,1,1,2,2,2,2,2,2,2,1,1,1,1,1
1,1,1,1,1,1,1,1,1,1,1,1,1,1,1,1
1,1,1,1,1,1,1,1,1,1,1,1,1,1,1,1
endlayer

layer
1,1,1,1,1,1,1,1,1,1,1,1,1,1,1,1
1,1,1,1,1,1,1,1,1,1,1,1,1,1,1,1
1,1,1,1,1,1,1,1,1,1,1,1,1,1,1,1
1,1,1,1,1,1,1,1,1,1,1,1,1,1,1,1
1,1,1,1,0,0,7,7,7,1,1,1,1,1,1,1
1,1,1,1,0,0,7,0,7,1,1,1,1,1,1,1
1,1,1,1,2,2,2,2,2,2,2,1,1,1,1,1
1,1,1,1,2,0,0,0,0,0,2,1,1,1,1,1
1,1,1,1,2,0,0,0,0,0,2,1,1,1,1,1
1,1,1,1,2,0,0,0,0,0,2,1,1,1,1,1
1,1,1,1,2,0,0,0,0,13,2,1,1,1,1,1
1,1,1,1,2,0,0,0,0,10,2,1,1,1,1,1
1,1,1,1,2,0,0,0,0,0,2,1,1,1,1,1
1,1,5,5,5,5,0,0,0,0,2,1,1,1,1,1
1,6,5,5,0,0,0,0,0,0,2,1,1,1,1,1
1,9,5,5,0,0,0,0,0,0,2,1,1,1,1,1
1,9,5,5,0,0,0,0,0,0,2,1,1,1,1,1
1,9,5,5,0,0,0,0,0,0,2,1,1,1,1,1
1,11,5,5,0,0,0,0,0,0,2,1,1,1,1,1
1,1,5,5,5,5,0,0,0,0,2,1,1,1,1,1
1,1,1,1,2,2,2,2,2,2,2,1,1,1,1,1
1,1,1,1,1,1,1,1,1,1,1,1,1,1,1,1
1,1,1,1,1,1,1,1,1,1,1,1,1,1,1,1
endlayer

layer
1,1,1,1,1,1,1,1,1,1,1,1,1,1,1,1
1,1,1,1,1,1,1,1,1,1,1,1,1,1,1,1
1,1,1,1,1,1,1,1,1,1,1,1,1,1,1,1
1,1,1,1,1,1,1,1,1,1,1,1,1,1,1,1
1,1,1,1,0,0,7,19,7,1,1,1,1,1,1,1
1,1,1,1,0,0,19,0,19,1,1,1,1,1,1,1
1,1,1,1,20,20,20,20,20,20,20,1,1,1,1,1
1,1,1,1,20,0,0,0,0,0,20,1,1,1,1,1
1,1,1,1,20,0,0,0,0,0,20,1,1,1,1,1
1,1,1,1,20,0,0,0,0,13,20,1,1,1,1,1
1,1,1,1,20,0,0,0,0,10,20,1,1,1,1,1
1,1,1,1,20,0,0,0,0,0,20,1,1,1,1,1
1,1,1,1,20,0,0,0,0,0,20,1,1,1,1,1
1,1,19,19,19,5,0,0,0,0,20,1,1,1,1,1
1,1,7,6,5,0,0,0,0,0,20,1,1,1,1,1
1,0,0,9,5,0,0,0,0,0,20,1,1,1,1,1
1,0,0,9,5,0,0,0,0,0,20,1,1,1,1,1
1,0,0,9,5,0,0,0,0,0,20,1,1,1,1,1
1,1,7,11,5,0,0,0,0,0,20,1,1,1,1,1
1,1,19,19,19,5,0,0,0,0,20,1,1,1,1,1
1,1,1,1,20,20,20,20,20,20,20,1,1,1,1,1
1,1,1,1,1,1,1,1,1,1,1,1,1,1,1,1
1,1,1,1,1,1,1,1,1,1,1,1,1,1,1,1
endlayer

layer
1,1,1,1,1,1,1,1,1,1,1,1,1,1,1,1
1,1,1,1,1,1,1,1,1,1,1,1,1,1,1,1
1,1,1,1,1,1,1,1,1,1,1,1,1,1,1,1
1,1,1,1,1,1,1,1,1,1,1,1,1,1,1,1
1,1,1,1,0,0,7,19,7,1,1,1,1,1,1,1
1,1,1,1,0,0,19,0,19,1,1,1,1,1,1,1
1,1,1,1,20,20,20,20,20,20,20,1,1,1,1,1
1,1,1,1,20,0,0,0,0,0,20,1,1,1,1,1
1,1,1,1,20,0,0,0,0,13,20,1,1,1,1,1
1,1,1,1,20,0,0,0,0,10,20,1,1,1,1,1
1,1,1,1,20,0,0,0,0,0,20,1,1,1,1,1
1,1,1,1,20,0,0,0,0,0,20,1,1,1,1,1
1,1,1,1,20,0,0,0,0,0,20,1,1,1,1,1
1,1,19,19,19,5,0,0,0,0,20,1,1,1,1,1
1,1,7,0,6,5,13,13,13,0,20,1,1,1,1,1
1,0,0,0,9,5,7,7,21,0,20,1,1,1,1,1
0,0,0,0,9,5,7,7,21,0,20,1,1,1,1,1
1,0,0,0,9,5,7,7,21,0,20,1,1,1,1,1
1,1,7,0,11,5,22,22,22,0,20,1,1,1,1,1
1,1,19,19,19,5,0,0,0,0,20,1,1,1,1,1
1,1,1,1,20,20,20,20,20,20,20,1,1,1,1,1
1,1,1,1,1,1,1,1,1,1,1,1,1,1,1,1
1,1,1,1,1,1,1,1,1,1,1,1,1,1,1,1
endlayer

layer
1,1,1,1,1,1,1,1,1,1,1,1,1,1,1,1
1,1,1,1,1,1,1,1,1,1,1,1,1,1,1,1
1,1,1,1,1,1,1,1,1,1,1,1,1,1,1,1
1,1,1,1,1,1,1,1,1,1,1,1,1,1,1,1
1,1,1,1,0,0,7,19,7,1,1,1,1,1,1,1
1,1,1,1,7,7,7,7,7,7,7,1,1,1,1,1
1,1,1,1,7,7,7,7,7,7,7,1,1,1,1,1
1,1,1,1,7,7,7,7,7,7,7,1,1,1,1,1
1,1,1,1,7,7,7,7,7,10,7,1,1,1,1,1
1,1,1,1,7,7,7,7,7,0,7,1,1,1,1,1
1,1,1,1,7,7,7,7,7,0,7,1,1,1,1,1
1,1,1,1,7,7,7,7,7,0,7,1,1,1,1,1
1,1,1,1,7,7,7,7,7,7,7,1,1,1,1,1
1,1,19,19,19,7,7,7,7,7,7,1,1,1,1,1
1,1,7,0,0,19,7,7,7,7,7,1,1,1,1,1
1,0,22,0,0,7,10,10,7,7,7,1,1,1,1,1
0,0,0,0,0,0,14,23,7,7,7,1,1,1,1,1
1,0,13,0,0,7,24,24,7,7,7,1,1,1,1,1
1,1,7,0,0,19,7,7,7,7,7,1,1,1,1,1
1,1,19,19,19,7,7,7,7,7,7,1,1,1,1,1
1,1,1,1,7,7,7,7,7,7,7,1,1,1,1,1
1,1,1,1,7,7,7,7,7,7,7,1,1,1,1,1
1,1,1,1,1,1,1,1,1,1,1,1,1,1,1,1
endlayer

layer
1,1,1,1,1,1,1,1,1,1,1,1,1,1,1,1
1,1,1,1,1,1,1,1,1,1,1,1,1,1,1,1
1,1,1,1,1,1,1,1,1,1,1,1,1,1,1,1
1,1,1,1,1,13,13,13,13,21,1,1,1,1,1,1
1,1,1,1,0,25,7,7,7,21,1,1,1,1,1,1
1,1,1,1,7,7,7,7,7,7,7,1,1,1,1,1
1,1,1,1,26,7,10,7,0,7,26,1,1,1,1,1
1,1,1,1,26,0,0,0,0,0,26,1,1,1,1,1
1,1,1,1,26,0,0,0,18,0,26,1,1,1,1,1
1,1,1,1,26,0,0,0,18,0,26,1,1,1,1,1
1,1,1,1,26,0,0,0,18,0,26,1,1,1,1,1
1,1,1,1,26,0,0,0,18,0,26,1,1,1,1,1
1,1,1,1,26,26,0,0,18,26,26,1,1,1,1,1
1,1,19,19,19,7,0,0,0,0,7,1,1,1,1,1
1,1,7,0,28,19,12,0,0,0,27,1,1,1,1,1
1,1,19,0,0,7,0,0,0,0,27,1,1,1,1,1
1,1,7,0,0,0,16,0,0,0,27,1,1,1,1,1
1,1,19,0,0,7,0,0,0,29,27,1,1,1,1,1
1,1,7,0,32,19,12,31,0,30,27,1,1,1,1,1
1,1,19,19,19,7,0,0,0,30,27,1,1,1,1,1
1,1,1,1,26,0,29,33,33,29,27,1,1,1,1,1
1,1,1,1,7,27,27,27,27,27,7,1,1,1,1,1
1,1,1,1,1,1,1,1,1,1,1,1,1,1,1,1
endlayer

layer
1,1,1,1,1,1,1,1,1,1,1,1,1,1,1,1
1,1,1,1,1,1,1,1,1,1,1,1,1,1,1,1
1,1,1,1,1,1,1,1,1,1,1,1,1,1,1,1
1,1,1,1,1,7,26,26,26,7,1,1,1,1,1,1
1,1,1,1,0,26,7,7,7,26,1,1,1,1,1,1
1,1,1,1,7,26,10,7,7,26,7,1,1,1,1,1
1,1,1,1,26,18,0,18,0,18,26,1,1,1,1,1
1,1,1,1,35,0,0,0,0,0,34,1,1,1,1,1
1,1,1,1,26,0,0,0,0,0,26,1,1,1,1,1
1,1,1,1,35,0,0,0,0,0,34,1,1,1,1,1
1,1,1,1,26,0,0,0,0,0,26,1,1,1,1,1
1,1,1,1,35,0,0,0,0,0,34,1,1,1,1,1
1,1,1,1,26,26,0,0,0,26,26,1,1,1,1,1
1,1,7,7,7,7,0,0,0,0,7,1,1,1,1,1
1,1,7,0,0,7,0,0,0,0,27,1,1,1,1,1
1,1,7,0,0,7,0,0,0,0,34,1,1,1,1,1
1,1,7,0,0,7,0,0,0,0,27,1,1,1,1,1
1,1,7,0,0,7,0,0,0,0,34,1,1,1,1,1
1,1,7,0,0,7,0,0,0,0,27,1,1,1,1,1
1,1,7,7,7,7,0,0,0,0,34,1,1,1,1,1
1,1,1,1,26,0,0,0,0,0,27,1,1,1,1,1
1,1,1,1,7,27,36,27,36,27,7,1,1,1,1,1
1,1,1,1,1,1,1,1,1,1,1,1,1,1,1,1
endlayer

layer
1,1,1,1,1,1,1,1,1,1,1,1,1,1,1,1
1,1,1,1,1,1,1,1,1,1,1,1,1,1,1,1
1,1,1,1,1,1,1,1,1,1,1,1,1,1,1,1
1,1,1,1,1,7,26,26,26,7,1,1,1,1,1,1
1,1,1,1,0,26,10,7,7,26,1,1,1,1,1,1
1,1,1,1,7,26,0,7,7,26,7,1,1,1,1,1
1,1,1,1,26,0,0,18,0,0,26,1,1,1,1,1
1,1,1,1,26,0,0,0,0,0,26,1,1,1,1,1
1,1,1,1,26,0,0,0,0,0,26,1,1,1,1,1
1,1,1,1,26,0,0,0,0,0,26,1,1,1,1,1
1,1,1,1,26,0,0,0,0,0,26,1,1,1,1,1
1,1,1,1,26,0,0,0,0,0,26,1,1,1,1,1
1,1,1,1,26,26,0,0,0,26,26,1,1,1,1,1
1,1,19,19,19,7,0,0,0,0,7,1,1,1,1,1
1,1,7,0,0,7,0,0,0,0,27,1,1,1,1,1
1,1,19,0,0,19,0,0,0,0,37,1,1,1,1,1
1,1,7,0,0,7,0,0,0,0,27,1,1,1,1,1
1,1,19,0,0,19,0,0,0,0,37,1,1,1,1,1
1,1,7,0,0,7,0,0,0,0,27,1,1,1,1,1
1,1,19,19,19,7,0,0,0,0,37,1,1,1,1,1
1,1,1,1,26,0,0,0,0,0,27,1,1,1,1,1
1,1,1,1,7,27,38,27,38,27,7,1,1,1,1,1
1,1,1,1,1,1,1,1,1,1,1,1,1,1,1,1
endlayer

layer
1,1,1,1,1,1,1,1,1,1,1,1,1,1,1,1
1,1,1,1,1,1,1,1,1,1,1,1,1,1,1,1
1,1,1,1,1,13,1,13,1,13,1,1,1,1,1,1
1,1,1,1,1,7,26,26,26,7,1,1,1,1,1,1
1,1,1,1,25,26,0,23,7,26,21,1,1,1,1,1
1,1,1,25,7,26,0,7,7,26,7,21,1,1,1,1
1,1,1,1,7,0,0,18,0,0,7,1,1,1,1,1
1,1,1,25,7,0,0,0,0,0,7,21,1,1,1,1
1,1,1,1,7,0,0,0,0,0,7,1,1,1,1,1
1,1,1,25,7,0,0,0,0,0,7,21,1,1,1,1
1,1,1,1,7,0,0,0,0,0,7,1,1,1,1,1
1,1,1,25,7,0,0,0,0,0,7,21,1,1,1,1
1,1,1,1,7,7,0,0,0,7,7,1,1,1,1,1
1,1,19,19,19,7,0,0,0,0,7,21,1,1,1,1
1,1,7,0,0,7,0,0,0,0,7,1,1,1,1,1
1,1,19,0,0,19,0,0,0,0,7,21,1,1,1,1
1,1,7,0,0,7,0,0,0,0,7,1,1,1,1,1
1,1,19,0,0,19,0,0,0,0,7,21,1,1,1,1
1,1,7,0,0,7,0,0,0,0,7,1,1,1,1,1
1,1,19,19,19,7,0,0,0,0,7,21,1,1,1,1
1,1,1,1,7,0,0,0,0,0,7,1,1,1,1,1
1,1,1,1,7,7,7,7,7,7,7,21,1,1,1,1
1,1,1,1,22,1,1,22,1,1,22,1,1,1,1,1
endlayer

layer
1,1,1,1,1,1,1,1,1,1,1,1,1,1,1,1
1,1,1,1,13,13,13,13,13,13,13,1,1,1,1,1
1,1,1,1,7,7,7,7,7,7,7,1,1,1,1,1
1,1,1,1,7,7,7,7,7,7,7,1,1,1,1,1
1,1,1,7,7,7,0,0,23,7,7,7,1,1,1,1
1,1,1,7,21,7,0,7,7,7,7,7,1,1,1,1
1,1,1,7,21,0,0,18,0,0,25,7,1,1,1,1
1,1,1,7,21,0,0,0,0,0,25,7,1,1,1,1
1,1,1,7,21,0,0,0,0,0,25,7,1,1,1,1
1,1,1,7,21,0,0,0,0,0,25,7,1,1,1,1
1,1,1,7,21,0,0,0,0,0,25,7,1,1,1,1
1,1,1,7,21,0,0,0,0,0,25,7,1,1,1,1
1,30,1,7,7,7,7,7,7,7,7,7,1,1,1,1
1,30,7,7,7,7,0,0,0,0,25,7,1,1,1,1
1,30,7,7,7,7,0,0,0,0,25,7,1,1,1,1
1,30,7,7,7,7,0,0,0,0,25,7,1,1,1,1
1,30,7,7,7,7,0,0,0,0,25,7,1,1,1,1
1,30,7,7,7,7,0,0,0,0,25,7,1,1,1,1
1,30,7,7,7,7,0,0,0,0,25,7,1,1,1,1
1,30,7,7,7,7,0,0,0,0,25,7,1,1,1,1
1,30,1,7,7,0,0,0,0,0,25,7,1,1,1,1
1,1,1,7,7,13,13,13,13,13,7,7,1,1,1,1
1,1,1,7,7,7,7,7,7,7,7,7,1,1,1,1
endlayer

layer
1,1,1,1,1,1,1,1,1,1,1,1,1,1,1,1
1,1,1,1,27,27,27,27,27,27,27,1,1,1,1,1
1,1,1,1,27,0,12,0,0,0,27,1,1,1,1,1
1,1,1,1,27,0,0,0,0,0,27,1,1,1,1,1
1,1,1,7,27,0,0,0,0,0,27,7,1,1,1,1
1,1,1,27,7,7,7,0,0,0,7,27,1,1,1,1
1,1,1,27,7,7,7,17,17,17,7,27,1,1,1,1
1,1,1,27,7,7,7,7,7,7,7,27,1,1,1,1
1,1,1,27,7,7,7,7,7,7,7,27,1,1,1,1
1,1,1,27,7,7,7,7,7,7,7,27,1,1,1,1
1,1,1,27,7,7,7,7,7,7,7,27,1,1,1,1
1,1,1,27,7,7,7,7,7,7,7,27,1,1,1,1
1,1,30,27,7,7,7,7,7,7,7,27,1,1,1,1
1,1,30,27,7,7,7,7,7,7,7,27,1,1,1,1
1,1,30,27,7,7,7,7,7,7,7,27,1,1,1,1
1,1,30,27,7,7,7,7,7,7,7,27,1,1,1,1
1,1,30,27,7,7,7,7,7,7,7,27,1,1,1,1
1,1,30,27,7,7,7,7,7,7,7,27,1,1,1,1
1,1,30,27,7,7,7,7,7,7,7,27,1,1,1,1
1,1,30,27,7,7,7,7,7,7,7,27,1,1,1,1
1,1,30,27,7,7,7,7,7,7,7,27,1,1,1,1
1,1,1,27,7,7,7,7,7,7,7,27,1,1,1,1
1,1,1,7,27,27,27,27,27,27,27,7,1,1,1,1
endlayer

layer
1,1,1,33,33,33,33,33,33,33,33,33,1,1,1,1
1,1,1,1,27,27,27,27,27,27,27,1,1,1,1,1
1,1,1,1,27,0,0,0,0,0,27,1,1,1,1,1
1,1,1,1,27,0,0,0,0,0,27,1,1,1,1,1
1,1,1,7,27,0,0,0,0,0,27,7,1,1,1,1
1,1,1,7,18,18,18,0,0,0,0,7,1,1,1,1
1,1,1,7,0,0,18,0,0,0,0,7,1,1,1,1
1,1,1,7,0,0,18,0,0,0,0,7,1,1,1,1
1,1,1,7,0,7,39,0,0,0,0,7,1,1,1,1
1,1,1,7,0,0,0,0,0,0,0,7,1,1,1,1
1,1,1,7,0,0,0,0,0,0,0,7,1,1,1,1
1,1,1,7,0,0,0,0,0,0,0,7,1,1,1,1
1,1,1,7,0,0,0,0,0,0,0,7,1,1,1,1
1,1,1,7,0,0,0,40,0,0,0,7,1,1,1,1
1,1,1,7,0,0,0,41,0,0,0,7,1,1,1,1
1,1,1,7,0,0,43,42,30,0,0,7,1,1,1,1
1,1,1,7,0,0,0,44,0,0,0,7,1,1,1,1
1,1,1,7,0,0,0,44,0,0,0,7,1,1,1,1
1,1,1,7,0,0,43,41,30,0,0,7,1,1,1,1
1,1,1,7,0,0,0,42,0,0,0,7,1,1,1,1
1,1,1,7,0,0,0,33,0,0,0,7,1,1,1,1
1,1,1,7,0,0,0,0,0,0,0,7,1,1,1,1
1,1,1,7,7,7,7,7,7,7,7,7,1,1,1,1
endlayer

layer
1,1,1,1,1,1,1,1,1,1,1,1,1,1,1,1
1,1,1,33,33,33,33,33,33,33,33,33,1,1,1,1
1,1,1,1,27,27,27,27,27,27,27,1,1,1,1,1
1,1,1,1,27,0,0,0,0,0,27,1,1,1,1,1
1,1,1,7,27,0,0,0,0,0,27,7,1,1,1,1
1,1,1,27,0,0,0,0,0,0,0,27,1,1,1,1
1,1,1,35,0,0,0,0,0,0,0,34,1,1,1,1
1,1,1,27,0,0,0,0,0,0,0,27,1,1,1,1
1,1,1,35,0,7,39,0,0,0,0,34,1,1,1,1
1,1,1,27,0,0,0,0,0,0,0,27,1,1,1,1
1,1,1,7,0,0,0,0,0,0,0,7,1,1,1,1
1,1,1,27,0,0,0,0,0,0,0,27,1,1,1,1
1,1,1,35,0,0,0,0,0,0,0,34,1,1,1,1
1,1,1,27,0,0,0,0,0,0,0,27,1,1,1,1
1,1,1,7,0,0,0,12,0,0,0,7,1,1,1,1
1,1,1,27,0,0,0,45,0,0,0,27,1,1,1,1
1,1,1,35,0,0,0,12,0,0,0,34,1,1,1,1
1,1,1,27,0,0,0,0,0,0,0,27,1,1,1,1
1,1,1,7,0,0,0,45,0,0,0,7,1,1,1,1
1,1,1,27,0,0,0,12,0,0,0,27,1,1,1,1
1,1,1,35,0,0,0,0,0,0,0,34,1,1,1,1
1,1,1,27,0,0,0,0,0,0,0,27,1,1,1,1
1,1,1,7,27,36,27,7,27,36,27,7,1,1,1,1
endlayer

layer
1,1,1,1,1,1,1,1,1,1,1,1,1,1,1,1
1,1,1,1,1,1,1,1,1,1,1,1,1,1,1,1
1,1,1,33,33,33,33,33,33,33,33,33,1,1,1,1
1,1,1,1,27,27,27,27,27,27,27,1,1,1,1,1
1,1,1,7,27,0,0,0,0,0,27,7,1,1,1,1
1,1,1,27,0,0,0,0,0,0,0,27,1,1,1,1
1,1,1,46,0,0,0,0,0,0,0,37,1,1,1,1
1,1,1,27,0,0,0,0,0,0,0,27,1,1,1,1
1,1,1,46,0,7,39,0,0,0,0,37,1,1,1,1
1,1,1,27,0,0,0,0,0,0,0,27,1,1,1,1
1,1,1,7,0,0,0,0,0,0,0,7,1,1,1,1
1,1,1,27,0,0,0,0,0,0,0,27,1,1,1,1
1,1,1,46,0,0,0,0,0,0,0,37,1,1,1,1
1,1,1,27,0,0,0,0,0,0,0,27,1,1,1,1
1,1,1,7,0,0,0,0,0,0,0,7,1,1,1,1
1,1,1,27,0,0,0,0,0,0,0,27,1,1,1,1
1,1,1,46,0,0,0,0,0,0,0,37,1,1,1,1
1,1,1,27,0,0,0,0,0,0,0,27,1,1,1,1
1,1,1,7,0,0,0,0,0,0,0,7,1,1,1,1
1,1,1,27,0,0,0,0,0,0,0,27,1,1,1,1
1,1,1,46,0,0,0,0,0,0,0,37,1,1,1,1
1,1,1,27,0,0,0,0,0,0,0,27,1,1,1,1
1,1,1,7,27,38,27,7,27,38,27,7,1,1,1,1
endlayer

layer
1,1,1,1,1,1,1,1,1,1,1,1,1,1,1,1
1,1,1,1,1,1,1,1,1,1,1,1,1,1,1,1
1,1,1,1,1,1,1,1,1,1,1,1,1,1,1,1
1,1,1,33,33,33,33,33,33,33,33,33,1,1,1,1
1,1,1,7,27,27,27,27,27,27,27,7,1,1,1,1
1,1,1,27,0,0,0,0,0,0,0,27,1,1,1,1
1,1,1,27,0,0,0,0,0,0,0,27,1,1,1,1
1,1,1,27,0,0,0,0,0,0,0,27,1,1,1,1
1,1,1,27,0,7,39,0,0,0,0,27,1,1,1,1
1,1,1,27,0,0,0,0,0,0,0,27,1,1,1,1
1,1,1,7,0,0,0,0,0,0,0,7,1,1,1,1
1,1,1,27,0,0,0,0,0,0,0,27,1,1,1,1
1,1,1,27,0,0,0,0,0,0,0,27,1,1,1,1
1,1,1,27,0,0,0,0,0,0,0,27,1,1,1,1
1,1,1,7,0,0,0,0,0,0,0,7,1,1,1,1
1,1,1,27,0,0,0,0,0,0,0,27,1,1,1,1
1,1,1,27,0,0,0,0,0,0,0,27,1,1,1,1
1,1,1,27,0,0,0,0,0,0,0,27,1,1,1,1
1,1,1,7,0,0,0,0,0,0,0,7,1,1,1,1
1,1,1,27,0,0,0,0,0,0,0,27,1,1,1,1
1,1,1,27,0,0,0,0,0,0,0,27,1,1,1,1
1,1,1,27,0,0,0,0,0,0,0,27,1,1,1,1
1,1,1,7,27,27,27,7,27,27,27,7,1,1,1,1
endlayer

layer
1,1,1,1,1,1,1,1,1,1,1,1,1,1,1,1
1,1,1,1,1,1,1,1,1,1,1,1,1,1,1,1
1,1,1,1,1,1,1,1,1,1,1,1,1,1,1,1
1,1,1,1,1,1,1,1,1,1,1,1,1,1,1,1
1,1,1,7,7,7,7,7,7,7,7,7,1,1,1,1
1,1,1,7,17,7,17,7,17,7,17,7,1,1,1,1
1,1,1,7,17,17,17,17,17,17,17,7,1,1,1,1
1,1,1,7,17,17,17,17,17,17,17,7,1,1,1,1
1,1,1,7,17,7,39,17,17,17,17,7,1,1,1,1
1,1,1,7,17,17,17,17,17,17,17,7,1,1,1,1
1,1,1,7,7,7,7,7,7,7,7,7,1,1,1,1
1,1,1,7,0,0,0,0,0,0,0,7,1,1,1,1
1,1,1,7,0,0,0,0,0,0,0,7,1,1,1,1
1,1,1,7,0,0,0,0,0,0,0,7,1,1,1,1
1,1,1,7,0,0,0,0,0,0,0,7,1,1,1,1
1,1,1,7,0,0,0,0,0,0,0,7,1,1,1,1
1,1,1,7,0,0,0,0,0,0,0,7,1,1,1,1
1,1,1,7,0,0,0,0,0,0,0,7,1,1,1,1
1,1,1,7,0,0,0,0,0,0,0,7,1,1,1,1
1,1,1,7,0,0,0,0,0,0,0,7,1,1,1,1
1,1,1,7,0,0,0,0,0,0,0,7,1,1,1,1
1,1,1,7,0,0,0,0,0,0,0,7,1,1,1,1
1,1,1,7,7,7,7,7,7,7,7,7,1,1,1,1
endlayer

layer
1,1,1,1,1,1,1,1,1,1,1,1,1,1,1,1
1,1,1,1,1,1,1,1,1,1,1,1,1,1,1,1
1,1,1,1,1,1,1,1,1,1,1,1,1,1,1,1
1,1,30,1,1,1,1,1,1,1,1,1,43,1,1,1
1,1,30,7,27,27,27,27,27,27,27,7,43,1,1,1
1,1,30,7,0,47,0,47,0,47,0,7,43,1,1,1
1,1,30,7,0,0,0,0,0,0,0,7,43,1,1,1
1,1,30,7,0,0,0,0,0,0,0,7,43,1,1,1
1,1,30,7,0,7,39,0,0,0,0,7,43,1,1,1
1,1,30,7,0,0,0,0,0,0,0,7,43,1,1,1
1,1,30,7,18,18,18,18,18,18,18,7,43,1,1,1
1,1,30,7,0,0,0,0,0,0,0,7,43,1,1,1
1,1,30,7,0,0,0,0,0,0,0,7,43,1,1,1
1,1,30,7,0,0,0,0,0,0,0,7,43,1,1,1
1,1,30,7,0,0,0,0,0,0,0,7,43,1,1,1
1,1,30,7,0,0,0,0,0,0,0,7,43,1,1,1
1,1,30,7,0,0,0,0,0,0,0,7,43,1,1,1
1,1,30,7,0,0,0,0,0,0,0,7,43,1,1,1
1,1,30,7,0,0,0,0,0,0,0,7,43,1,1,1
1,1,30,7,0,0,0,0,0,0,0,7,43,1,1,1
1,1,30,7,0,0,0,0,0,0,0,7,43,1,1,1
1,1,30,7,0,0,0,0,0,0,0,7,43,1,1,1
1,1,30,7,27,27,27,27,27,27,27,7,43,1,1,1
endlayer

layer
1,1,1,1,1,1,1,1,1,1,1,1,1,1,1,1
1,1,1,1,1,1,1,1,1,1,1,1,1,1,1,1
1,1,1,1,1,1,1,1,1,1,1,1,1,1,1,1
1,1,1,30,1,1,1,1,1,1,1,43,1,1,1,1
1,1,1,30,7,27,27,27,27,27,7,43,1,1,1,1
1,1,1,30,7,0,0,0,0,0,7,43,1,1,1,1
1,1,1,30,7,0,0,0,0,0,7,43,1,1,1,1
1,1,1,30,7,0,0,0,0,0,7,43,1,1,1,1
1,1,1,30,7,7,39,0,0,0,7,43,1,1,1,1
1,1,1,30,7,0,0,0,0,0,7,43,1,1,1,1
1,1,1,30,7,0,0,0,0,0,7,43,1,1,1,1
1,1,1,30,7,0,0,0,0,0,7,43,1,1,1,1
1,1,1,30,7,0,0,0,0,0,7,43,1,1,1,1
1,1,1,30,7,0,0,0,0,0,7,43,1,1,1,1
1,1,1,30,7,0,0,0,0,0,7,43,1,1,1,1
1,1,1,30,7,0,0,0,0,0,7,43,1,1,1,1
1,1,1,30,7,0,0,0,0,0,7,43,1,1,1,1
1,1,1,30,7,0,0,0,0,0,7,43,1,1,1,1
1,1,1,30,7,0,0,0,0,0,7,43,1,1,1,1
1,1,1,30,7,0,0,0,0,0,7,43,1,1,1,1
1,1,1,30,7,0,0,0,0,0,7,43,1,1,1,1
1,1,1,30,7,0,0,0,0,0,7,43,1,1,1,1
1,1,1,30,7,27,27,27,27,27,7,43,1,1,1,1
endlayer

layer
1,1,1,1,1,1,1,1,1,1,1,1,1,1,1,1
1,1,1,1,1,1,1,1,1,1,1,1,1,1,1,1
1,1,1,1,1,1,1,1,1,1,1,1,1,1,1,1
1,1,1,1,30,1,1,1,1,1,43,1,1,1,1,1
1,1,1,1,30,7,27,27,27,7,43,1,1,1,1,1
1,1,1,1,30,7,0,0,0,7,43,1,1,1,1,1
1,1,1,1,30,7,0,0,0,7,43,1,1,1,1,1
1,1,1,1,30,7,0,0,0,7,43,1,1,1,1,1
1,1,1,1,30,7,39,0,0,7,43,1,1,1,1,1
1,1,1,1,30,7,0,0,0,7,43,1,1,1,1,1
1,1,1,1,30,7,0,0,0,7,43,1,1,1,1,1
1,1,1,1,30,7,0,0,0,7,43,1,1,1,1,1
1,1,1,1,30,7,0,0,0,7,43,1,1,1,1,1
1,1,1,1,30,7,0,0,0,7,43,1,1,1,1,1
1,1,1,1,30,7,0,0,0,7,43,1,1,1,1,1
1,1,1,1,30,7,0,0,0,7,43,1,1,1,1,1
1,1,1,1,30,7,0,0,0,7,43,1,1,1,1,1
1,1,1,1,30,7,0,0,0,7,43,1,1,1,1,1
1,1,1,1,30,7,0,0,0,7,43,1,1,1,1,1
1,1,1,1,30,7,0,0,0,7,43,1,1,1,1,1
1,1,1,1,30,7,0,0,0,7,43,1,1,1,1,1
1,1,1,1,30,7,0,0,0,7,43,1,1,1,1,1
1,1,1,1,30,7,27,27,27,7,43,1,1,1,1,1
endlayer

layer
1,1,1,1,1,1,1,1,1,1,1,1,1,1,1,1
1,1,1,1,1,1,1,1,1,1,1,1,1,1,1,1
1,1,1,1,1,1,1,1,1,1,1,1,1,1,1,1
1,1,1,1,1,30,1,1,1,43,1,1,1,1,1,1
1,1,1,1,1,30,7,27,7,43,1,1,1,1,1,1
1,1,1,1,1,30,7,0,7,43,1,1,1,1,1,1
1,1,1,1,1,30,7,0,7,43,1,1,1,1,1,1
1,1,1,1,1,27,7,0,7,43,1,1,1,1,1,1
1,1,1,1,1,27,35,0,7,43,1,1,1,1,1,1
1,1,1,1,1,27,7,0,7,43,1,1,1,1,1,1
1,1,1,1,1,30,7,0,7,43,1,1,1,1,1,1
1,1,1,1,1,30,7,0,7,43,1,1,1,1,1,1
1,1,1,1,1,30,7,0,7,43,1,1,1,1,1,1
1,1,1,1,1,30,7,0,7,43,1,1,1,1,1,1
1,1,1,1,1,30,7,0,7,43,1,1,1,1,1,1
1,1,1,1,1,30,7,0,7,43,1,1,1,1,1,1
1,1,1,1,1,30,7,0,7,43,1,1,1,1,1,1
1,1,1,1,1,30,7,0,7,43,1,1,1,1,1,1
1,1,1,1,1,30,7,0,7,43,1,1,1,1,1,1
1,1,1,1,1,30,7,0,7,43,1,1,1,1,1,1
1,1,1,1,1,30,7,0,7,43,1,1,1,1,1,1
1,1,1,1,1,30,7,0,7,43,1,1,1,1,1,1
1,1,1,1,1,30,7,27,7,43,1,1,1,1,1,1
endlayer

layer
1,1,1,1,1,1,1,1,1,1,1,1,1,1,1,1
1,1,1,1,1,1,1,1,1,1,1,1,1,1,1,1
1,1,1,1,1,1,1,1,1,1,1,1,1,1,1,1
1,1,1,1,1,1,29,1,29,1,1,1,1,1,1,1
1,1,1,1,1,1,30,7,43,1,1,1,1,1,1,1
1,1,1,1,1,1,30,7,43,1,1,1,1,1,1,1
1,1,1,1,1,1,30,7,43,1,1,1,1,1,1,1
1,1,1,1,1,27,27,7,43,1,1,1,1,1,1,1
1,1,1,1,1,35,0,7,43,1,1,1,1,1,1,1
1,1,1,1,1,27,27,7,43,1,1,1,1,1,1,1
1,1,1,1,1,1,30,7,43,1,1,1,1,1,1,1
1,1,1,1,1,1,30,7,43,1,1,1,1,1,1,1
1,1,1,1,1,1,30,7,43,1,1,1,1,1,1,1
1,1,1,1,1,1,30,7,43,1,1,1,1,1,1,1
1,1,1,1,1,1,30,7,43,1,1,1,1,1,1,1
1,1,1,1,1,1,30,7,43,1,1,1,1,1,1,1
1,1,1,1,1,1,30,7,43,1,1,1,1,1,1,1
1,1,1,1,1,1,30,7,43,1,1,1,1,1,1,1
1,1,1,1,1,1,30,7,43,1,1,1,1,1,1,1
1,1,1,1,1,1,30,7,43,1,1,1,1,1,1,1
1,1,1,1,1,1,30,7,43,1,1,1,1,1,1,1
1,1,1,1,1,1,30,7,43,1,1,1,1,1,1,1
1,1,1,1,1,1,30,7,43,1,1,1,1,1,1,1
endlayer

layer
1,1,1,1,1,1,1,1,1,1,1,1,1,1,1,1
1,1,1,1,1,1,1,1,1,1,1,1,1,1,1,1
1,1,1,1,1,1,1,1,1,1,1,1,1,1,1,1
1,1,1,1,1,1,30,29,43,1,1,1,1,1,1,1
1,1,1,1,1,1,1,40,1,1,1,1,1,1,1,1
1,1,1,1,1,1,1,31,1,1,1,1,1,1,1,1
1,1,1,1,1,1,1,31,1,1,1,1,1,1,1,1
1,1,1,1,1,27,27,31,1,1,1,1,1,1,1,1
1,1,1,1,1,27,27,31,1,1,1,1,1,1,1,1
1,1,1,1,1,27,27,31,1,1,1,1,1,1,1,1
1,1,1,1,1,1,1,31,1,1,1,1,1,1,1,1
1,1,1,1,1,1,1,31,1,1,1,1,1,1,1,1
1,1,1,1,1,1,1,31,1,1,1,1,1,1,1,1
1,1,1,1,1,1,1,31,1,1,1,1,1,1,1,1
1,1,1,1,1,1,1,31,1,1,1,1,1,1,1,1
1,1,1,1,1,1,1,31,1,1,1,1,1,1,1,1
1,1,1,1,1,1,1,31,1,1,1,1,1,1,1,1
1,1,1,1,1,1,1,31,1,1,1,1,1,1,1,1
1,1,1,1,1,1,1,31,1,1,1,1,1,1,1,1
1,1,1,1,1,1,1,31,1,1,1,1,1,1,1,1
1,1,1,1,1,1,1,31,1,1,1,1,1,1,1,1
1,1,1,1,1,1,1,31,1,1,1,1,1,1,1,1
1,1,1,1,1,1,1,33,1,1,1,1,1,1,1,1
endlayer

layer
1,1,1,1,1,1,1,1,1,1,1,1,1,1,1,1
1,1,1,1,1,1,1,1,1,1,1,1,1,1,1,1
1,1,1,1,1,1,1,1,1,1,1,1,1,1,1,1
1,1,1,1,1,1,1,40,1,1,1,1,1,1,1,1
1,1,1,1,1,1,1,1,1,1,1,1,1,1,1,1
1,1,1,1,1,1,1,1,1,1,1,1,1,1,1,1
1,1,1,1,33,33,33,43,1,1,1,1,1,1,1,1
1,1,1,1,30,27,27,43,1,1,1,1,1,1,1,1
1,1,1,1,30,27,27,43,1,1,1,1,1,1,1,1
1,1,1,1,30,27,27,43,1,1,1,1,1,1,1,1
1,1,1,1,40,40,40,40,1,1,1,1,1,1,1,1
1,1,1,1,1,1,1,1,1,1,1,1,1,1,1,1
1,1,1,1,1,1,1,1,1,1,1,1,1,1,1,1
1,1,1,1,1,1,1,1,1,1,1,1,1,1,1,1
1,1,1,1,1,1,1,1,1,1,1,1,1,1,1,1
1,1,1,1,1,1,1,1,1,1,1,1,1,1,1,1
1,1,1,1,1,1,1,1,1,1,1,1,1,1,1,1
1,1,1,1,1,1,1,1,1,1,1,1,1,1,1,1
1,1,1,1,1,1,1,1,1,1,1,1,1,1,1,1
1,1,1,1,1,1,1,1,1,1,1,1,1,1,1,1
1,1,1,1,1,1,1,1,1,1,1,1,1,1,1,1
1,1,1,1,1,1,1,1,1,1,1,1,1,1,1,1
1,1,1,1,1,1,1,1,1,1,1,1,1,1,1,1
endlayer

layer
1,1,1,1,1,1,1,1,1,1,1,1,1,1,1,1
1,1,1,1,1,1,1,1,1,1,1,1,1,1,1,1
1,1,1,1,1,1,1,1,1,1,1,1,1,1,1,1
1,1,1,1,1,1,1,1,1,1,1,1,1,1,1,1
1,1,1,1,1,1,1,1,1,1,1,1,1,1,1,1
1,1,1,1,1,1,1,1,1,1,1,1,1,1,1,1
1,1,1,1,1,1,1,1,1,1,1,1,1,1,1,1
1,1,1,1,1,33,33,1,1,1,1,1,1,1,1,1
1,1,1,1,1,30,43,1,1,1,1,1,1,1,1,1
1,1,1,1,1,40,40,1,1,1,1,1,1,1,1,1
1,1,1,1,1,1,1,1,1,1,1,1,1,1,1,1
1,1,1,1,1,1,1,1,1,1,1,1,1,1,1,1
1,1,1,1,1,1,1,1,1,1,1,1,1,1,1,1
1,1,1,1,1,1,1,1,1,1,1,1,1,1,1,1
1,1,1,1,1,1,1,1,1,1,1,1,1,1,1,1
1,1,1,1,1,1,1,1,1,1,1,1,1,1,1,1
1,1,1,1,1,1,1,1,1,1,1,1,1,1,1,1
1,1,1,1,1,1,1,1,1,1,1,1,1,1,1,1
1,1,1,1,1,1,1,1,1,1,1,1,1,1,1,1
1,1,1,1,1,1,1,1,1,1,1,1,1,1,1,1
1,1,1,1,1,1,1,1,1,1,1,1,1,1,1,1
1,1,1,1,1,1,1,1,1,1,1,1,1,1,1,1
1,1,1,1,1,1,1,1,1,1,1,1,1,1,1,1
endlayer

