# Chisel Nether Library
# Created by Ruins mod version 17.1 Ingame Parser
# authoring Player: Jordan_Greywolf
# Created for MC 1.12 with Chisel Mod: 30 Jun 2018

biomesToSpawnIn=boneyard,corrupted sands,corrupted_sands,fungi_forest,hell,phantasmagoric inferno,phantasmagoric_inferno,spectral garden,spectral_garden,undergarden,visceral heap,visceral_heap

weight=1
embed_into_distance=25
acceptable_target_blocks=

unacceptable_target_blocks=command_block

dimensions=15,7,7
allowable_overhang=99
max_leveling=20
leveling_buffer=-1
preserve_water=0
preserve_lava=0

rule1=0,100,preserveBlock
rule2=0,100,minecraft:nether_brick_fence-0
rule3=0,100,minecraft:nether_brick-0
rule4=0,100,chisel:netherbrick-5
rule5=0,100,chisel:netherbrick-7
rule6=0,100,chisel:bookshelf_spruce-1,chisel:bookshelf_spruce-2,chisel:bookshelf_spruce-3,chisel:bookshelf_spruce-4,chisel:bookshelf_spruce-5,chisel:bookshelf_spruce-6,chisel:bookshelf_spruce-7,chisel:bookshelf_spruce-9

rule7=0,100,ChestGenHook:chests/simple_dungeon:3-5

rule8=0,100,MobSpawner:Wither_Skeleton

rule9=0,100,minecraft:dark_oak_door-3

rule10=0,100,ChestGenHook:chests/simple_dungeon:3-4

rule11=0,100,chisel:glass-3
rule12=0,100,minecraft:ladder-3
rule13=0,100,minecraft:dark_oak_door-9
rule14=0,100,chisel:netherrack-3
rule15=0,100,minecraft:fire-15
rule16=0,100,minecraft:nether_brick_stairs-3
rule17=0,100,minecraft:nether_brick_stairs-2
rule18=0,100,minecraft:stone_slab-6
rule19=0,100,minecraft:nether_brick_stairs-1
rule20=0,100,minecraft:nether_brick_stairs-0

layer
1,1,1,1,1,1,1
1,1,1,1,1,1,1
1,1,1,1,1,1,1
1,1,1,2,1,1,1
1,1,1,1,1,1,1
1,1,1,1,1,1,1
1,1,1,1,1,1,1
endlayer

layer
1,1,1,1,1,1,1
1,1,1,1,1,1,1
1,1,1,2,1,1,1
1,1,2,3,2,1,1
1,1,1,2,1,1,1
1,1,1,1,1,1,1
1,1,1,1,1,1,1
endlayer

layer
1,1,1,1,1,1,1
1,1,1,1,1,1,1
1,1,1,2,1,1,1
1,1,2,3,2,1,1
1,1,1,2,1,1,1
1,1,1,1,1,1,1
1,1,1,1,1,1,1
endlayer

layer
1,1,1,1,1,1,1
1,1,1,1,1,1,1
1,1,2,3,2,1,1
1,1,3,3,3,1,1
1,1,2,3,2,1,1
1,1,1,1,1,1,1
1,1,1,1,1,1,1
endlayer

layer
1,1,1,1,1,1,1
1,1,2,3,2,1,1
1,2,3,3,3,2,1
1,3,3,4,3,3,1
1,2,3,3,3,2,1
1,1,2,3,2,1,1
1,1,1,1,1,1,1
endlayer

layer
1,1,2,2,2,1,1
1,2,3,3,3,2,1
2,3,3,4,3,3,2
2,3,4,4,4,3,2
2,3,3,4,3,3,2
1,2,3,3,3,2,1
1,1,2,2,2,1,1
endlayer

layer
1,2,3,3,3,2,1
2,3,3,4,3,3,2
3,3,4,4,4,3,3
3,4,4,4,4,4,3
3,3,4,4,4,3,3
2,3,3,4,3,3,2
1,2,3,3,3,2,1
endlayer

layer
2,3,3,3,3,3,2
3,3,4,4,4,3,3
3,4,4,4,4,4,3
3,4,4,4,4,4,3
3,4,4,4,4,4,3
3,3,4,4,4,3,3
2,3,3,3,3,3,2
endlayer

layer
2,3,5,5,5,3,2
3,3,6,7,6,3,3
5,6,0,0,0,6,5
9,0,0,0,0,8,4
5,6,0,0,0,6,5
3,3,6,10,6,3,3
2,3,5,5,5,3,2
endlayer

layer
2,3,5,11,5,3,2
3,3,6,0,6,3,3
5,6,0,0,0,6,5
13,0,0,0,0,12,5
5,6,0,0,0,6,5
3,3,6,0,6,3,3
2,3,5,11,5,3,2
endlayer

layer
2,3,5,11,5,3,2
3,3,6,0,6,3,3
5,6,0,0,0,6,5
5,0,0,0,0,12,5
5,6,0,0,0,6,5
3,3,6,0,6,3,3
2,3,5,11,5,3,2
endlayer

layer
2,3,5,11,5,3,2
3,3,6,0,6,3,3
5,6,0,0,0,6,5
11,0,0,0,0,12,5
5,6,0,0,0,6,5
3,3,6,0,6,3,3
2,3,5,11,5,3,2
endlayer

layer
2,3,5,5,5,3,2
3,3,6,0,6,3,3
5,6,0,0,0,6,5
5,0,0,0,0,12,5
5,6,0,0,0,6,5
3,3,6,0,6,3,3
2,3,5,5,5,3,2
endlayer

layer
14,3,3,3,3,3,14
3,14,4,4,4,14,3
3,4,4,4,4,4,3
3,4,4,4,4,12,3
3,4,4,4,4,4,3
3,14,4,4,4,14,3
14,3,3,3,3,3,14
endlayer

layer
15,17,16,18,17,16,15
19,15,0,0,0,15,19
20,0,0,0,0,0,20
18,0,0,0,0,0,18
19,0,0,0,0,0,19
20,15,0,0,0,15,20
15,17,16,18,17,16,15
endlayer

