# Chisel Cobble Tower
# Created by Ruins mod version 17.1 Ingame Parser
# authoring Player: Jordan_Greywolf
# Created for MC 1.12 with Chisel Mod: 27 Jun 2018

biomesToSpawnIn=birch_forest,boreal_forest,brushland,chaparral,flower_field,flower_forest,forest,grassland,grove,heathland,lavender_fields,lighted_forest,magical_forest,meadow,mountain_foothills,mutated_forest,mutated_plains,oak_savannah,orchard,origin_valley,pasture,plains,prairie,quagmire,taiga,twilight_clearing,woodland

weight=1
embed_into_distance=7
acceptable_target_blocks=

unacceptable_target_blocks=cloud,Natura:cloud,red_mushroom_block,brown_mushroom_block,oak_stairs,spruce_stairs,dark_oak_stairs,birch_stairs,jungle_stairs,acacia_stairs,cobblestone,lava,flowing_lava,slime_congealed,slime_dirt,slime_grass,command_block,planks,planks2,concrete,cobblestone,stonebrick,brick_block,glass,torch,oak_stairs,stone_stairs,brick_stairs,stone_brick_stairs,nether_brick_stairs,sandstone_stairs,spruce_stairs,birch_stairs,jungle_stairs,quartz_stairs,acacia_stairs,dark_oak_stairs,cobblestone_wall,stone_slab,double_stone_slab,stone_slab2,wooden_slab,double_wooden_slab,nether_brick

dimensions=38,15,15
allowable_overhang=0
max_leveling=7
leveling_buffer=-1
preserve_water=0
preserve_lava=0

rule1=0,100,preserveBlock

rule2=0,100,chisel:cobblestone2-0,chisel:cobblestone-1,chisel:cobblestone-2,chisel:cobblestonemossy-1,chisel:cobblestonemossy1-8,chisel:cobblestonemossy-2

rule3=0,100,chisel:cobblestone-7
rule4=0,100,chisel:cobblestone-4
rule5=0,100,minecraft:stone_brick_stairs-2
rule6=0,100,minecraft:spruce_door-0
rule7=0,100,minecraft:spruce_door-1
rule8=0,100,chisel:cobblestone1-7
rule9=0,100,minecraft:spruce_door-3
rule10=0,100,ChestGenHook:chests/simple_dungeon:3-3

rule11=0,100,MobSpawner:Spider,MobSpawner:Skeleton

rule12=0,100,ChestGenHook:chests/simple_dungeon:3-2

rule13=0,100,minecraft:spruce_door-2
rule14=0,100,minecraft:spruce_door-9
rule15=0,100,minecraft:spruce_door-8
rule16=0,100,minecraft:stonebrick-3
rule17=0,100,minecraft:stone_brick_stairs-0
rule18=0,100,minecraft:stone_brick_stairs-5
rule19=0,100,minecraft:stone_brick_stairs-4
rule20=0,100,minecraft:stone_brick_stairs-1

rule21=0,100,MobSpawner:Zombie,MobSpawner:Skeleton

rule22=0,100,minecraft:stone_brick_stairs-6
rule23=0,100,minecraft:stone_brick_stairs-3
rule24=1,100,minecraft:redstone_torch-5
rule25=0,100,minecraft:stone_brick_stairs-7
rule26=0,100,minecraft:nether_brick_fence-0
rule27=0,100,minecraft:stone_slab-5
rule28=0,100,minecraft:cobblestone_wall-0
rule29=0,100,chisel:planks-spruce-11
rule30=2,100,minecraft:redstone_torch-4
rule31=0,100,ChestGenHook:chests/simple_dungeon:5-2
rule32=0,100,minecraft:nether_brick_stairs-0
rule33=0,100,minecraft:nether_brick_stairs-3
rule34=0,100,minecraft:nether_brick_stairs-2
rule35=0,100,minecraft:nether_brick-0
rule36=0,100,minecraft:nether_brick_stairs-1
rule37=0,100,minecraft:stone_slab-6

layer
1,1,1,1,1,1,2,2,2,1,1,1,1,1,1
1,1,1,1,1,2,3,4,3,2,1,1,1,1,1
1,1,1,2,2,2,3,4,3,2,2,2,1,1,1
1,1,2,3,3,3,2,2,3,3,3,2,2,1,1
1,1,2,2,2,4,2,2,2,4,2,2,2,1,1
1,2,2,3,4,3,3,2,3,3,4,3,2,2,1
2,3,3,3,2,3,3,4,3,3,2,3,3,3,2
2,4,4,4,2,2,4,4,4,2,2,4,4,4,2
2,3,3,3,2,3,3,4,3,3,2,3,3,3,2
1,2,2,3,4,3,3,2,3,3,4,3,2,2,1
1,1,2,2,2,4,2,2,2,4,2,2,2,1,1
1,1,2,2,3,3,2,2,3,3,3,2,2,1,1
1,1,1,2,2,2,3,4,3,2,2,2,1,1,1
1,1,1,1,1,2,3,4,3,2,1,1,1,1,1
1,1,1,1,1,1,2,2,2,1,1,1,1,1,1
endlayer

layer
1,1,1,1,1,1,2,2,2,1,1,1,1,1,1
1,1,1,1,1,2,0,0,0,2,1,1,1,1,1
1,1,1,2,2,2,2,2,0,2,2,2,1,1,1
1,1,2,0,0,0,2,5,0,0,0,2,2,1,1
1,1,2,2,2,6,2,2,2,6,2,2,2,1,1
1,2,2,0,9,0,0,8,0,0,7,0,2,2,1
2,0,0,0,2,0,0,0,0,0,2,0,0,0,2
2,12,0,11,2,8,0,0,0,8,2,11,0,10,2
2,0,0,0,2,0,0,0,0,0,2,0,0,0,2
1,2,2,0,9,0,0,8,0,0,7,0,2,2,1
1,1,2,2,2,13,2,2,2,13,2,2,2,1,1
1,1,2,2,0,0,2,5,0,0,0,2,2,1,1
1,1,1,2,2,2,2,2,0,2,2,2,1,1,1
1,1,1,1,1,2,0,0,0,2,1,1,1,1,1
1,1,1,1,1,1,2,2,2,1,1,1,1,1,1
endlayer

layer
1,1,1,1,1,1,2,2,2,1,1,1,1,1,1
1,1,1,1,1,2,0,0,0,2,1,1,1,1,1
1,1,1,2,2,2,2,2,0,2,2,2,1,1,1
1,1,2,0,0,0,5,0,0,0,0,2,2,1,1
1,1,2,2,2,14,2,2,2,14,2,2,2,1,1
1,2,2,0,15,0,0,8,0,0,14,0,2,2,1
2,0,0,0,2,0,0,0,0,0,2,0,0,0,2
2,0,0,0,2,8,0,0,0,8,2,0,0,0,2
2,0,0,0,2,0,0,0,0,0,2,0,0,0,2
1,2,2,0,14,0,0,8,0,0,14,0,2,2,1
1,1,2,2,2,15,2,2,2,14,2,2,2,1,1
1,1,2,2,0,0,5,0,0,0,0,2,2,1,1
1,1,1,2,2,2,2,2,0,2,2,2,1,1,1
1,1,1,1,1,2,0,0,0,2,1,1,1,1,1
1,1,1,1,1,1,2,2,2,1,1,1,1,1,1
endlayer

layer
1,1,1,1,1,1,2,2,2,1,1,1,1,1,1
1,1,1,1,1,2,0,0,0,2,1,1,1,1,1
1,1,1,2,2,2,2,2,16,2,2,2,1,1,1
1,1,2,2,2,2,0,0,0,0,0,2,2,1,1
1,1,2,2,2,16,17,2,2,16,2,2,2,1,1
1,2,2,0,16,0,18,8,18,0,16,0,2,2,1
2,0,0,0,2,0,0,0,0,0,2,0,0,0,2
2,0,0,0,2,8,0,0,0,8,2,0,0,0,2
2,0,0,0,2,0,0,0,0,0,2,0,0,0,2
1,2,2,0,16,0,19,8,19,0,16,0,2,2,1
1,1,2,2,2,16,20,2,2,16,2,2,2,1,1
1,1,2,2,2,2,0,0,0,0,0,2,2,1,1
1,1,1,2,2,2,2,2,16,2,2,2,1,1,1
1,1,1,1,1,2,0,0,0,2,1,1,1,1,1
1,1,1,1,1,1,2,2,2,1,1,1,1,1,1
endlayer

layer
1,1,1,1,1,1,2,2,2,1,1,1,1,1,1
1,1,1,1,1,2,0,0,0,2,1,1,1,1,1
1,1,1,2,2,2,2,2,2,2,2,2,1,1,1
1,1,2,2,2,2,0,0,0,0,0,2,2,1,1
1,1,2,2,2,2,0,2,2,2,2,2,2,1,1
1,2,2,2,2,18,17,8,2,18,2,2,2,2,1
2,0,0,2,2,0,0,0,0,0,2,2,0,0,2
2,0,0,2,2,8,0,0,0,8,2,2,0,0,2
2,0,0,2,2,0,0,0,0,0,2,2,0,0,2
1,2,2,2,2,19,20,8,2,19,2,2,2,2,1
1,1,2,2,2,2,0,2,2,2,2,2,2,1,1
1,1,2,2,2,2,0,0,0,0,0,2,2,1,1
1,1,1,2,2,2,2,2,2,2,2,2,1,1,1
1,1,1,1,1,2,0,0,0,2,1,1,1,1,1
1,1,1,1,1,1,2,2,2,1,1,1,1,1,1
endlayer

layer
1,1,1,1,1,1,2,2,2,1,1,1,1,1,1
1,1,1,1,1,2,0,0,0,2,1,1,1,1,1
1,1,1,2,2,2,2,2,2,2,2,2,1,1,1
1,1,2,2,2,2,0,0,0,0,0,2,2,1,1
1,1,2,2,2,2,0,2,2,2,2,2,2,1,1
1,2,2,2,2,5,0,2,2,2,2,2,2,2,1
2,0,2,2,2,18,18,18,18,18,2,2,2,0,2
2,0,2,2,2,8,0,0,0,8,2,2,2,0,2
2,0,2,2,2,19,19,19,19,19,2,2,2,0,2
1,2,2,2,2,5,0,2,2,2,2,2,2,2,1
1,1,2,2,2,2,0,2,2,2,2,2,2,1,1
1,1,2,2,2,2,0,0,0,0,0,2,2,1,1
1,1,1,2,2,2,2,2,2,2,2,2,1,1,1
1,1,1,1,1,2,0,0,0,2,1,1,1,1,1
1,1,1,1,1,1,2,2,2,1,1,1,1,1,1
endlayer

layer
1,1,1,1,1,1,2,2,2,1,1,1,1,1,1
1,1,1,1,1,2,4,4,4,2,1,1,1,1,1
1,1,1,2,2,3,3,4,3,3,2,2,1,1,1
1,1,2,2,4,4,4,4,4,4,4,2,2,1,1
1,1,2,4,2,2,0,2,2,2,2,4,2,1,1
1,2,3,4,2,0,0,4,3,3,2,4,3,2,1
2,4,3,4,2,17,3,4,3,3,2,4,3,4,2
2,4,4,4,2,4,4,4,4,4,2,4,4,4,2
2,4,3,4,2,20,3,4,3,3,2,4,3,4,2
1,2,3,4,2,0,0,4,3,3,2,4,3,2,1
1,1,2,4,2,2,0,2,2,2,2,4,2,1,1
1,1,2,2,4,4,4,4,4,4,4,2,2,1,1
1,1,1,2,2,3,3,4,3,3,2,2,1,1,1
1,1,1,1,1,2,4,4,4,2,1,1,1,1,1
1,1,1,1,1,1,2,2,2,1,1,1,1,1,1
endlayer

layer
1,1,1,1,1,1,2,2,2,1,1,1,1,1,1
1,1,1,1,1,2,0,21,0,2,1,1,1,1,1
1,1,1,2,2,0,0,0,0,0,2,2,1,1,1
1,1,2,2,0,0,0,0,0,0,0,2,2,1,1
1,1,2,0,2,2,2,6,2,2,2,0,2,1,1
1,2,0,0,2,0,0,0,0,0,2,0,0,2,1
2,0,0,0,2,0,0,0,23,22,2,0,0,0,2
7,0,0,0,9,0,0,24,0,0,7,0,0,21,2
2,0,0,0,2,0,0,0,23,22,2,0,0,0,2
1,2,0,0,2,0,0,0,0,0,2,0,1,2,1
1,1,2,0,2,2,2,13,2,2,2,0,2,1,1
1,1,2,2,0,0,0,0,0,0,0,2,2,1,1
1,1,1,2,2,0,0,0,0,0,2,2,1,1,1
1,1,1,1,1,2,0,21,0,2,1,1,1,1,1
1,1,1,1,1,1,2,2,2,1,1,1,1,1,1
endlayer

layer
1,1,1,1,1,1,2,2,2,1,1,1,1,1,1
1,1,1,1,1,2,0,0,0,2,1,1,1,1,1
1,1,1,2,2,0,0,0,0,0,2,2,1,1,1
1,1,2,2,0,0,0,0,0,0,0,2,2,1,1
1,1,2,0,2,2,2,15,2,2,2,0,2,1,1
1,2,0,0,2,0,0,0,0,19,2,0,0,2,1
2,0,0,0,2,0,0,0,0,23,2,0,0,0,2
15,0,0,0,14,0,0,0,0,0,14,0,0,0,2
2,0,0,0,2,0,0,0,0,23,2,0,0,0,2
1,2,0,0,2,0,0,0,0,18,2,0,0,2,1
1,1,2,0,2,2,2,15,2,2,2,0,2,1,1
1,1,2,2,0,0,0,0,0,0,0,2,2,1,1
1,1,1,2,2,0,0,0,0,0,2,2,1,1,1
1,1,1,1,1,2,0,0,0,2,1,1,1,1,1
1,1,1,1,1,1,2,2,2,1,1,1,1,1,1
endlayer

layer
1,1,1,1,1,1,2,2,2,1,1,1,1,1,1
1,1,1,1,1,2,0,0,0,2,1,1,1,1,1
1,1,1,2,2,0,0,0,0,0,2,2,1,1,1
1,1,2,2,0,0,0,0,0,0,0,2,2,1,1
1,1,2,0,2,2,2,16,2,2,2,0,2,1,1
1,2,0,0,2,0,0,0,25,20,2,0,0,2,1
2,0,0,0,2,0,0,0,0,0,2,0,0,0,2
16,0,0,0,16,26,0,0,0,26,16,0,0,0,2
2,0,0,0,2,0,0,0,0,0,2,0,0,0,2
1,2,0,0,2,0,0,0,25,17,2,0,0,2,1
1,1,2,0,2,2,2,16,2,2,2,0,2,1,1
1,1,2,2,0,0,0,0,0,0,0,2,2,1,1
1,1,1,2,2,0,0,0,0,0,2,2,1,1,1
1,1,1,1,1,2,0,0,0,2,1,1,1,1,1
1,1,1,1,1,1,2,2,2,1,1,1,1,1,1
endlayer

layer
1,1,1,1,1,1,1,2,1,1,1,1,1,1,1
1,1,1,1,1,2,2,0,2,2,1,1,1,1,1
1,1,1,2,2,2,0,0,0,2,2,2,1,1,1
1,1,2,2,2,0,0,0,0,0,2,2,2,1,1
1,1,2,2,2,2,2,2,2,2,2,2,2,1,1
1,2,2,0,2,0,0,25,5,0,2,0,2,2,1
1,2,0,0,2,0,0,0,0,0,2,0,0,2,1
2,0,0,0,2,24,0,0,0,24,2,0,0,0,2
1,2,0,0,2,0,0,0,0,0,2,0,0,2,1
1,2,2,0,2,0,0,25,5,0,2,0,2,2,1
1,1,2,2,2,2,2,2,2,2,2,2,2,1,1
1,1,2,2,2,0,0,0,0,0,2,2,2,1,1
1,1,1,2,2,2,0,0,0,2,2,2,1,1,1
1,1,1,1,1,2,2,0,2,2,1,1,1,1,1
1,1,1,1,1,1,1,2,1,1,1,1,1,1,1
endlayer

layer
1,1,1,1,1,1,1,2,1,1,1,1,1,1,1
1,1,1,1,1,2,2,2,2,2,1,1,1,1,1
1,1,1,2,2,2,2,0,2,2,2,2,1,1,1
1,1,2,2,2,2,0,0,0,2,2,2,2,1,1
1,1,2,2,2,2,2,2,2,2,2,2,2,1,1
1,2,2,2,2,0,25,5,0,0,2,2,2,2,1
1,2,2,0,2,0,0,0,0,0,2,0,2,2,1
2,0,0,0,2,0,0,0,0,0,2,0,0,0,2
1,2,2,0,2,0,0,0,0,0,2,0,2,2,1
1,2,2,2,2,0,25,5,0,0,2,2,2,2,1
1,1,2,2,2,2,2,2,2,2,2,2,2,1,1
1,1,2,2,2,2,0,0,0,2,2,2,2,1,1
1,1,1,2,2,2,2,0,2,2,2,2,1,1,1
1,1,1,1,1,2,2,2,2,2,1,1,1,1,1
1,1,1,1,1,1,1,2,1,1,1,1,1,1,1
endlayer

layer
1,1,1,1,1,1,1,1,1,1,1,1,1,1,1
1,1,1,1,1,2,2,2,2,2,1,1,1,1,1
1,1,1,1,2,2,2,2,2,2,2,1,1,1,1
1,1,1,2,2,2,2,2,2,2,2,2,1,1,1
1,1,2,2,2,2,2,2,2,2,2,2,2,1,1
1,2,2,2,2,25,5,0,0,0,2,2,2,2,1
1,2,2,2,2,0,0,0,0,0,2,2,2,2,1
1,2,2,2,2,0,0,0,0,0,2,2,2,2,1
1,2,2,2,2,0,0,0,0,0,2,2,2,2,1
1,2,2,2,2,25,5,0,0,0,2,2,2,2,1
1,1,2,2,2,2,2,2,2,2,2,2,2,1,1
1,1,1,2,2,2,2,2,2,2,2,2,1,1,1
1,1,1,1,2,2,2,2,2,2,2,1,1,1,1
1,1,1,1,1,2,2,2,2,2,1,1,1,1,1
1,1,1,1,1,1,1,1,1,1,1,1,1,1,1
endlayer

layer
1,1,1,1,1,0,0,0,0,0,1,1,1,1,1
1,1,1,1,0,0,0,0,0,0,0,1,1,1,1
1,1,1,0,0,0,2,2,2,0,0,0,1,1,1
1,1,0,0,0,2,2,2,2,2,0,0,0,1,1
1,0,0,0,2,2,2,2,2,2,2,0,0,0,1
0,0,0,2,2,5,0,0,0,0,2,2,0,0,0
0,0,2,2,2,18,0,0,0,0,2,2,2,0,0
0,0,2,2,2,0,0,0,0,0,2,2,2,0,0
0,0,2,2,2,19,0,0,0,0,2,2,2,0,0
0,0,0,2,2,5,0,0,0,0,2,2,0,0,0
1,0,0,0,2,2,2,2,2,2,2,0,0,0,1
1,1,0,0,0,2,2,2,2,2,0,0,0,1,1
1,1,1,0,0,0,2,2,2,0,0,0,1,1,1
1,1,1,1,0,0,0,0,0,0,0,1,1,1,1
1,1,1,1,1,0,0,0,0,0,1,1,1,1,1
endlayer

layer
1,1,1,1,0,0,0,0,0,0,0,1,1,1,1
1,1,1,0,0,0,0,0,0,0,0,0,1,1,1
1,1,0,0,0,0,0,2,0,0,0,0,0,1,1
1,0,0,0,0,0,2,2,2,0,0,0,0,0,1
0,0,0,0,0,2,2,2,2,2,0,0,0,0,0
0,0,0,0,2,0,0,0,0,0,2,0,0,0,0
0,0,0,2,2,17,0,0,0,0,2,2,0,0,0
0,0,2,2,2,22,0,0,0,0,2,2,2,0,0
0,0,0,2,2,20,0,0,0,0,2,2,0,0,0
0,0,0,0,2,0,0,0,0,0,2,0,0,0,0
0,0,0,0,0,2,2,2,2,2,0,0,0,0,0
1,0,0,0,0,0,2,2,2,0,0,0,0,0,1
1,1,0,0,0,0,0,2,0,0,0,0,0,1,1
1,1,1,0,0,0,0,0,0,0,0,0,1,1,1
1,1,1,1,0,0,0,0,0,0,0,1,1,1,1
endlayer

layer
1,1,1,0,0,0,0,0,0,0,0,0,1,1,1
1,1,0,0,0,0,0,0,0,0,0,0,0,1,1
1,0,0,0,0,0,0,0,0,0,0,0,0,0,1
0,0,0,0,0,0,2,2,2,0,0,0,0,0,0
0,0,0,0,0,2,2,2,2,2,0,0,0,0,0
0,0,0,0,2,0,0,4,3,3,2,0,0,0,0
0,0,0,2,2,0,3,4,3,3,2,2,0,0,0
0,0,0,2,2,27,4,4,4,4,2,2,0,0,0
0,0,0,2,2,0,3,4,3,3,2,2,0,0,0
0,0,0,0,2,0,0,4,3,3,2,0,0,0,0
0,0,0,0,0,2,2,2,2,2,0,0,0,0,0
0,0,0,0,0,0,2,2,2,0,0,0,0,0,0
1,0,0,0,0,0,0,0,0,0,0,0,0,0,1
1,1,0,0,0,0,0,0,0,0,0,0,0,1,1
1,1,1,0,0,0,0,0,0,0,0,0,1,1,1
endlayer

layer
1,1,0,0,0,0,0,0,0,0,0,0,0,1,1
1,0,0,0,0,0,0,0,0,0,0,0,0,0,1
0,0,0,0,0,0,0,0,0,0,0,0,0,0,0
0,0,0,0,0,0,28,0,28,0,0,0,0,0,0
0,0,0,0,0,2,2,16,2,2,0,0,0,0,0
0,0,0,0,2,0,0,0,0,11,2,0,0,0,0
0,0,0,28,2,0,0,0,23,22,2,28,0,0,0
0,0,0,0,16,0,0,0,0,26,16,0,0,0,0
0,0,0,28,2,0,0,0,23,22,2,28,0,0,0
0,0,0,0,2,0,0,0,0,11,2,0,0,0,0
0,0,0,0,0,2,2,16,2,2,0,0,0,0,0
0,0,0,0,0,0,28,0,28,0,0,0,0,0,0
0,0,0,0,0,0,0,0,0,0,0,0,0,0,0
1,0,0,0,0,0,0,0,0,0,0,0,0,0,1
1,1,0,0,0,0,0,0,0,0,0,0,0,1,1
endlayer

layer
1,0,0,0,0,0,0,0,0,0,0,0,0,0,1
0,0,0,0,0,0,0,0,0,0,0,0,0,0,0
0,0,0,0,0,0,0,0,0,0,0,0,0,0,0
0,0,0,0,0,0,28,0,28,0,0,0,0,0,0
0,0,0,0,0,2,2,29,2,2,0,0,0,0,0
0,0,0,0,2,0,0,0,0,19,2,0,0,0,0
0,0,0,28,2,0,0,0,0,23,2,28,0,0,0
0,0,0,0,29,0,0,0,0,24,29,0,0,0,0
0,0,0,28,2,0,0,0,0,23,2,28,0,0,0
0,0,0,0,2,0,0,0,0,18,2,0,0,0,0
0,0,0,0,0,2,2,29,2,2,0,0,0,0,0
0,0,0,0,0,0,28,0,28,0,0,0,0,0,0
0,0,0,0,0,0,0,0,0,0,0,0,0,0,0
0,0,0,0,0,0,0,0,0,0,0,0,0,0,0
1,0,0,0,0,0,0,0,0,0,0,0,0,0,1
endlayer

layer
0,0,0,0,0,0,0,0,0,0,0,0,0,0,0
0,0,0,0,0,0,0,0,0,0,0,0,0,0,0
0,0,0,0,0,0,0,0,0,0,0,0,0,0,0
0,0,0,0,0,0,28,0,28,0,0,0,0,0,0
0,0,0,0,0,2,2,29,2,2,0,0,0,0,0
0,0,0,0,2,0,0,0,25,20,2,0,0,0,0
0,0,0,28,2,0,0,0,0,0,2,28,0,0,0
0,0,0,0,29,0,0,0,0,0,29,0,0,0,0
0,0,0,28,2,0,0,0,0,0,2,28,0,0,0
0,0,0,0,2,0,0,0,25,17,2,0,0,0,0
0,0,0,0,0,2,2,29,2,2,0,0,0,0,0
0,0,0,0,0,0,28,0,28,0,0,0,0,0,0
0,0,0,0,0,0,0,0,0,0,0,0,0,0,0
0,0,0,0,0,0,0,0,0,0,0,0,0,0,0
0,0,0,0,0,0,0,0,0,0,0,0,0,0,0
endlayer

layer
0,0,0,0,0,0,0,0,0,0,0,0,0,0,0
0,0,0,0,0,0,0,0,0,0,0,0,0,0,0
0,0,0,0,0,0,0,0,0,0,0,0,0,0,0
0,0,0,0,0,0,28,0,28,0,0,0,0,0,0
0,0,0,0,0,2,2,16,2,2,0,0,0,0,0
0,0,0,0,2,0,0,25,5,0,2,0,0,0,0
0,0,0,28,2,0,0,0,0,0,2,28,0,0,0
0,0,0,0,16,30,0,0,0,0,16,0,0,0,0
0,0,0,28,2,0,0,0,0,0,2,28,0,0,0
0,0,0,0,2,0,0,25,5,0,2,0,0,0,0
0,0,0,0,0,2,2,16,2,2,0,0,0,0,0
0,0,0,0,0,0,28,0,28,0,0,0,0,0,0
0,0,0,0,0,0,0,0,0,0,0,0,0,0,0
0,0,0,0,0,0,0,0,0,0,0,0,0,0,0
0,0,0,0,0,0,0,0,0,0,0,0,0,0,0
endlayer

layer
0,0,0,0,0,0,0,0,0,0,0,0,0,0,0
0,0,0,0,0,0,0,0,0,0,0,0,0,0,0
0,0,0,0,0,0,0,0,0,0,0,0,0,0,0
0,0,0,0,0,0,2,2,2,0,0,0,0,0,0
0,0,0,0,0,2,2,2,2,2,0,0,0,0,0
0,0,0,0,2,2,2,5,0,0,2,0,0,0,0
0,0,0,2,2,2,2,2,2,0,2,2,0,0,0
0,0,0,2,2,2,2,2,2,2,2,2,0,0,0
0,0,0,2,2,2,2,2,2,0,2,2,0,0,0
0,0,0,0,2,2,2,5,0,0,2,0,0,0,0
0,0,0,0,0,2,2,2,2,2,0,0,0,0,0
0,0,0,0,0,0,2,2,2,0,0,0,0,0,0
0,0,0,0,0,0,0,0,0,0,0,0,0,0,0
0,0,0,0,0,0,0,0,0,0,0,0,0,0,0
0,0,0,0,0,0,0,0,0,0,0,0,0,0,0
endlayer

layer
0,0,0,0,0,0,0,0,0,0,0,0,0,0,0
0,0,0,0,0,0,0,0,0,0,0,0,0,0,0
0,0,0,0,0,0,0,2,0,0,0,0,0,0,0
0,0,0,0,0,0,2,2,2,0,0,0,0,0,0
0,0,0,0,0,2,0,0,0,2,0,0,0,0,0
0,0,0,0,2,0,0,0,0,0,2,0,0,0,0
0,0,0,2,31,0,0,0,0,0,0,2,0,0,0
0,0,2,2,11,0,0,0,0,0,0,2,2,0,0
0,0,0,2,31,0,0,0,0,0,0,2,0,0,0
0,0,0,0,2,0,0,0,0,0,2,0,0,0,0
0,0,0,0,0,2,0,0,0,2,0,0,0,0,0
0,0,0,0,0,0,2,2,2,0,0,0,0,0,0
0,0,0,0,0,0,0,2,0,0,0,0,0,0,0
0,0,0,0,0,0,0,0,0,0,0,0,0,0,0
0,0,0,0,0,0,0,0,0,0,0,0,0,0,0
endlayer

layer
0,0,0,0,0,0,0,0,0,0,0,0,0,0,0
0,0,0,0,0,0,0,0,0,0,0,0,0,0,0
0,0,0,0,0,0,2,2,2,0,0,0,0,0,0
0,0,0,0,0,2,2,2,2,2,0,0,0,0,0
0,0,0,0,2,2,0,0,0,2,2,0,0,0,0
0,0,0,2,2,0,0,0,0,0,2,2,0,0,0
0,0,2,2,0,0,0,0,0,0,0,2,2,0,0
0,0,2,2,0,0,0,0,0,0,0,2,2,0,0
0,0,2,2,0,0,0,0,0,0,0,2,2,0,0
0,0,0,2,2,0,0,0,0,0,2,2,0,0,0
0,0,0,0,2,2,0,0,0,2,2,0,0,0,0
0,0,0,0,0,2,2,2,2,2,0,0,0,0,0
0,0,0,0,0,0,2,2,2,0,0,0,0,0,0
0,0,0,0,0,0,0,0,0,0,0,0,0,0,0
0,0,0,0,0,0,0,0,0,0,0,0,0,0,0
endlayer

layer
0,0,0,0,0,0,0,0,0,0,0,0,0,0,0
0,0,0,0,0,33,32,32,32,32,0,0,0,0,0
0,0,0,0,33,32,35,35,35,34,32,0,0,0,0
0,0,0,33,32,35,35,35,35,35,34,32,0,0,0
0,0,33,32,35,35,0,0,0,35,35,34,32,0,0
0,33,32,35,35,0,0,0,0,0,35,35,34,32,0
0,33,35,35,0,0,0,0,0,0,0,35,35,34,0
0,33,35,35,0,0,0,0,0,0,0,35,35,34,0
0,33,35,35,0,0,0,0,0,0,0,35,35,34,0
0,36,33,35,35,0,0,0,0,0,35,35,36,34,0
0,0,36,33,35,35,0,0,0,35,35,36,34,0,0
0,0,0,36,33,35,35,35,35,35,36,34,0,0,0
0,0,0,0,36,33,35,35,35,36,34,0,0,0,0
0,0,0,0,0,36,36,36,36,34,0,0,0,0,0
0,0,0,0,0,0,0,0,0,0,0,0,0,0,0
endlayer

layer
0,0,0,0,0,0,0,0,0,0,0,0,0,0,0
0,0,0,0,0,0,0,0,0,0,0,0,0,0,0
0,0,0,0,0,0,37,37,37,0,0,0,0,0,0
0,0,0,0,0,37,32,32,32,37,0,0,0,0,0
0,0,0,0,37,32,35,35,35,32,37,0,0,0,0
0,0,0,37,33,35,0,0,0,35,34,37,0,0,0
0,0,37,33,35,0,0,26,0,0,35,34,37,0,0
0,0,37,33,35,0,26,26,26,0,35,34,37,0,0
0,0,37,33,35,0,0,26,0,0,35,34,37,0,0
0,0,0,37,33,35,0,0,0,35,34,37,0,0,0
0,0,0,0,37,36,35,35,35,36,37,0,0,0,0
0,0,0,0,0,37,36,36,36,37,0,0,0,0,0
0,0,0,0,0,0,37,37,37,0,0,0,0,0,0
0,0,0,0,0,0,0,0,0,0,0,0,0,0,0
0,0,0,0,0,0,0,0,0,0,0,0,0,0,0
endlayer

layer
0,0,0,0,0,0,0,0,0,0,0,0,0,0,0
0,0,0,0,0,0,0,0,0,0,0,0,0,0,0
0,0,0,0,0,0,0,0,0,0,0,0,0,0,0
0,0,0,0,0,0,0,0,0,0,0,0,0,0,0
0,0,0,0,0,0,35,35,35,0,0,0,0,0,0
0,0,0,0,0,35,35,0,35,35,0,0,0,0,0
0,0,0,0,35,35,0,24,0,35,35,0,0,0,0
0,0,0,0,35,0,24,26,24,0,35,0,0,0,0
0,0,0,0,35,35,0,24,0,35,35,0,0,0,0
0,0,0,0,0,35,35,0,35,35,0,0,0,0,0
0,0,0,0,0,0,35,35,35,0,0,0,0,0,0
0,0,0,0,0,0,0,0,0,0,0,0,0,0,0
0,0,0,0,0,0,0,0,0,0,0,0,0,0,0
0,0,0,0,0,0,0,0,0,0,0,0,0,0,0
0,0,0,0,0,0,0,0,0,0,0,0,0,0,0
endlayer

layer
0,0,0,0,0,0,0,0,0,0,0,0,0,0,0
0,0,0,0,0,0,0,0,0,0,0,0,0,0,0
0,0,0,0,0,0,0,0,0,0,0,0,0,0,0
0,0,0,0,0,0,0,0,0,0,0,0,0,0,0
0,0,0,0,0,0,33,32,32,0,0,0,0,0,0
0,0,0,0,0,33,32,35,34,32,0,0,0,0,0
0,0,0,0,33,32,35,0,35,34,32,0,0,0,0
0,0,0,0,33,35,0,26,0,35,34,0,0,0,0
0,0,0,0,36,33,35,0,35,36,34,0,0,0,0
0,0,0,0,0,36,33,35,36,34,0,0,0,0,0
0,0,0,0,0,0,36,36,34,0,0,0,0,0,0
0,0,0,0,0,0,0,0,0,0,0,0,0,0,0
0,0,0,0,0,0,0,0,0,0,0,0,0,0,0
0,0,0,0,0,0,0,0,0,0,0,0,0,0,0
0,0,0,0,0,0,0,0,0,0,0,0,0,0,0
endlayer

layer
0,0,0,0,0,0,0,0,0,0,0,0,0,0,0
0,0,0,0,0,0,0,0,0,0,0,0,0,0,0
0,0,0,0,0,0,0,0,0,0,0,0,0,0,0
0,0,0,0,0,0,0,0,0,0,0,0,0,0,0
0,0,0,0,0,0,0,0,0,0,0,0,0,0,0
0,0,0,0,0,0,0,35,0,0,0,0,0,0,0
0,0,0,0,0,0,35,0,35,0,0,0,0,0,0
0,0,0,0,0,35,0,26,0,35,0,0,0,0,0
0,0,0,0,0,0,35,0,35,0,0,0,0,0,0
0,0,0,0,0,0,0,35,0,0,0,0,0,0,0
0,0,0,0,0,0,0,0,0,0,0,0,0,0,0
0,0,0,0,0,0,0,0,0,0,0,0,0,0,0
0,0,0,0,0,0,0,0,0,0,0,0,0,0,0
0,0,0,0,0,0,0,0,0,0,0,0,0,0,0
0,0,0,0,0,0,0,0,0,0,0,0,0,0,0
endlayer

layer
0,0,0,0,0,0,0,0,0,0,0,0,0,0,0
0,0,0,0,0,0,0,0,0,0,0,0,0,0,0
0,0,0,0,0,0,0,0,0,0,0,0,0,0,0
0,0,0,0,0,0,0,0,0,0,0,0,0,0,0
0,0,0,0,0,0,0,0,0,0,0,0,0,0,0
0,0,0,0,0,0,0,32,0,0,0,0,0,0,0
0,0,0,0,0,0,35,35,35,0,0,0,0,0,0
0,0,0,0,0,33,35,26,35,34,0,0,0,0,0
0,0,0,0,0,0,35,35,35,0,0,0,0,0,0
0,0,0,0,0,0,0,36,0,0,0,0,0,0,0
0,0,0,0,0,0,0,0,0,0,0,0,0,0,0
0,0,0,0,0,0,0,0,0,0,0,0,0,0,0
0,0,0,0,0,0,0,0,0,0,0,0,0,0,0
0,0,0,0,0,0,0,0,0,0,0,0,0,0,0
0,0,0,0,0,0,0,0,0,0,0,0,0,0,0
endlayer

layer
0,0,0,0,0,0,0,0,0,0,0,0,0,0,0
0,0,0,0,0,0,0,0,0,0,0,0,0,0,0
0,0,0,0,0,0,0,0,0,0,0,0,0,0,0
0,0,0,0,0,0,0,0,0,0,0,0,0,0,0
0,0,0,0,0,0,0,0,0,0,0,0,0,0,0
0,0,0,0,0,0,0,0,0,0,0,0,0,0,0
0,0,0,0,0,0,35,35,35,0,0,0,0,0,0
0,0,0,0,0,0,35,28,35,0,0,0,0,0,0
0,0,0,0,0,0,35,35,35,0,0,0,0,0,0
0,0,0,0,0,0,0,0,0,0,0,0,0,0,0
0,0,0,0,0,0,0,0,0,0,0,0,0,0,0
0,0,0,0,0,0,0,0,0,0,0,0,0,0,0
0,0,0,0,0,0,0,0,0,0,0,0,0,0,0
0,0,0,0,0,0,0,0,0,0,0,0,0,0,0
0,0,0,0,0,0,0,0,0,0,0,0,0,0,0
endlayer

layer
0,0,0,0,0,0,0,0,0,0,0,0,0,0,0
0,0,0,0,0,0,0,0,0,0,0,0,0,0,0
0,0,0,0,0,0,0,0,0,0,0,0,0,0,0
0,0,0,0,0,0,0,0,0,0,0,0,0,0,0
0,0,0,0,0,0,0,0,0,0,0,0,0,0,0
0,0,0,0,0,0,0,0,0,0,0,0,0,0,0
0,0,0,0,0,0,33,32,32,0,0,0,0,0,0
0,0,0,0,0,0,33,35,34,0,0,0,0,0,0
0,0,0,0,0,0,36,36,34,0,0,0,0,0,0
0,0,0,0,0,0,0,0,0,0,0,0,0,0,0
0,0,0,0,0,0,0,0,0,0,0,0,0,0,0
0,0,0,0,0,0,0,0,0,0,0,0,0,0,0
0,0,0,0,0,0,0,0,0,0,0,0,0,0,0
0,0,0,0,0,0,0,0,0,0,0,0,0,0,0
0,0,0,0,0,0,0,0,0,0,0,0,0,0,0
endlayer

layer
0,0,0,0,0,0,0,0,0,0,0,0,0,0,0
0,0,0,0,0,0,0,0,0,0,0,0,0,0,0
0,0,0,0,0,0,0,0,0,0,0,0,0,0,0
0,0,0,0,0,0,0,0,0,0,0,0,0,0,0
0,0,0,0,0,0,0,0,0,0,0,0,0,0,0
0,0,0,0,0,0,0,0,0,0,0,0,0,0,0
0,0,0,0,0,0,0,0,0,0,0,0,0,0,0
0,0,0,0,0,0,0,35,0,0,0,0,0,0,0
0,0,0,0,0,0,0,0,0,0,0,0,0,0,0
0,0,0,0,0,0,0,0,0,0,0,0,0,0,0
0,0,0,0,0,0,0,0,0,0,0,0,0,0,0
0,0,0,0,0,0,0,0,0,0,0,0,0,0,0
0,0,0,0,0,0,0,0,0,0,0,0,0,0,0
0,0,0,0,0,0,0,0,0,0,0,0,0,0,0
0,0,0,0,0,0,0,0,0,0,0,0,0,0,0
endlayer

layer
0,0,0,0,0,0,0,0,0,0,0,0,0,0,0
0,0,0,0,0,0,0,0,0,0,0,0,0,0,0
0,0,0,0,0,0,0,0,0,0,0,0,0,0,0
0,0,0,0,0,0,0,0,0,0,0,0,0,0,0
0,0,0,0,0,0,0,0,0,0,0,0,0,0,0
0,0,0,0,0,0,0,0,0,0,0,0,0,0,0
0,0,0,0,0,0,0,0,0,0,0,0,0,0,0
0,0,0,0,0,0,0,35,0,0,0,0,0,0,0
0,0,0,0,0,0,0,0,0,0,0,0,0,0,0
0,0,0,0,0,0,0,0,0,0,0,0,0,0,0
0,0,0,0,0,0,0,0,0,0,0,0,0,0,0
0,0,0,0,0,0,0,0,0,0,0,0,0,0,0
0,0,0,0,0,0,0,0,0,0,0,0,0,0,0
0,0,0,0,0,0,0,0,0,0,0,0,0,0,0
0,0,0,0,0,0,0,0,0,0,0,0,0,0,0
endlayer

layer
0,0,0,0,0,0,0,0,0,0,0,0,0,0,0
0,0,0,0,0,0,0,0,0,0,0,0,0,0,0
0,0,0,0,0,0,0,0,0,0,0,0,0,0,0
0,0,0,0,0,0,0,0,0,0,0,0,0,0,0
0,0,0,0,0,0,0,0,0,0,0,0,0,0,0
0,0,0,0,0,0,0,0,0,0,0,0,0,0,0
0,0,0,0,0,0,0,0,0,0,0,0,0,0,0
0,0,0,0,0,0,0,35,0,0,0,0,0,0,0
0,0,0,0,0,0,0,0,0,0,0,0,0,0,0
0,0,0,0,0,0,0,0,0,0,0,0,0,0,0
0,0,0,0,0,0,0,0,0,0,0,0,0,0,0
0,0,0,0,0,0,0,0,0,0,0,0,0,0,0
0,0,0,0,0,0,0,0,0,0,0,0,0,0,0
0,0,0,0,0,0,0,0,0,0,0,0,0,0,0
0,0,0,0,0,0,0,0,0,0,0,0,0,0,0
endlayer

layer
0,0,0,0,0,0,0,0,0,0,0,0,0,0,0
0,0,0,0,0,0,0,0,0,0,0,0,0,0,0
0,0,0,0,0,0,0,0,0,0,0,0,0,0,0
0,0,0,0,0,0,0,0,0,0,0,0,0,0,0
0,0,0,0,0,0,0,0,0,0,0,0,0,0,0
0,0,0,0,0,0,0,0,0,0,0,0,0,0,0
0,0,0,0,0,0,0,0,0,0,0,0,0,0,0
0,0,0,0,0,0,0,26,0,0,0,0,0,0,0
0,0,0,0,0,0,0,0,0,0,0,0,0,0,0
0,0,0,0,0,0,0,0,0,0,0,0,0,0,0
0,0,0,0,0,0,0,0,0,0,0,0,0,0,0
0,0,0,0,0,0,0,0,0,0,0,0,0,0,0
0,0,0,0,0,0,0,0,0,0,0,0,0,0,0
0,0,0,0,0,0,0,0,0,0,0,0,0,0,0
0,0,0,0,0,0,0,0,0,0,0,0,0,0,0
endlayer

layer
0,0,0,0,0,0,0,0,0,0,0,0,0,0,0
0,0,0,0,0,0,0,0,0,0,0,0,0,0,0
0,0,0,0,0,0,0,0,0,0,0,0,0,0,0
0,0,0,0,0,0,0,0,0,0,0,0,0,0,0
0,0,0,0,0,0,0,0,0,0,0,0,0,0,0
0,0,0,0,0,0,0,0,0,0,0,0,0,0,0
0,0,0,0,0,0,0,0,0,0,0,0,0,0,0
0,0,0,0,0,0,0,26,0,0,0,0,0,0,0
0,0,0,0,0,0,0,0,0,0,0,0,0,0,0
0,0,0,0,0,0,0,0,0,0,0,0,0,0,0
0,0,0,0,0,0,0,0,0,0,0,0,0,0,0
0,0,0,0,0,0,0,0,0,0,0,0,0,0,0
0,0,0,0,0,0,0,0,0,0,0,0,0,0,0
0,0,0,0,0,0,0,0,0,0,0,0,0,0,0
0,0,0,0,0,0,0,0,0,0,0,0,0,0,0
endlayer

layer
0,0,0,0,0,0,0,0,0,0,0,0,0,0,0
0,0,0,0,0,0,0,0,0,0,0,0,0,0,0
0,0,0,0,0,0,0,0,0,0,0,0,0,0,0
0,0,0,0,0,0,0,0,0,0,0,0,0,0,0
0,0,0,0,0,0,0,0,0,0,0,0,0,0,0
0,0,0,0,0,0,0,0,0,0,0,0,0,0,0
0,0,0,0,0,0,0,0,0,0,0,0,0,0,0
0,0,0,0,0,0,0,26,0,0,0,0,0,0,0
0,0,0,0,0,0,0,0,0,0,0,0,0,0,0
0,0,0,0,0,0,0,0,0,0,0,0,0,0,0
0,0,0,0,0,0,0,0,0,0,0,0,0,0,0
0,0,0,0,0,0,0,0,0,0,0,0,0,0,0
0,0,0,0,0,0,0,0,0,0,0,0,0,0,0
0,0,0,0,0,0,0,0,0,0,0,0,0,0,0
0,0,0,0,0,0,0,0,0,0,0,0,0,0,0
endlayer

layer
0,0,0,0,0,0,0,0,0,0,0,0,0,0,0
0,0,0,0,0,0,0,0,0,0,0,0,0,0,0
0,0,0,0,0,0,0,0,0,0,0,0,0,0,0
0,0,0,0,0,0,0,0,0,0,0,0,0,0,0
0,0,0,0,0,0,0,0,0,0,0,0,0,0,0
0,0,0,0,0,0,0,0,0,0,0,0,0,0,0
0,0,0,0,0,0,0,0,0,0,0,0,0,0,0
0,0,0,0,0,0,0,24,0,0,0,0,0,0,0
0,0,0,0,0,0,0,0,0,0,0,0,0,0,0
0,0,0,0,0,0,0,0,0,0,0,0,0,0,0
0,0,0,0,0,0,0,0,0,0,0,0,0,0,0
0,0,0,0,0,0,0,0,0,0,0,0,0,0,0
0,0,0,0,0,0,0,0,0,0,0,0,0,0,0
0,0,0,0,0,0,0,0,0,0,0,0,0,0,0
0,0,0,0,0,0,0,0,0,0,0,0,0,0,0
endlayer

