# Chisel - Hidden Library
# Created by Ruins mod version 17.1 Ingame Parser
# authoring Player: Jordan_Greywolf
# Created for MC 1.12 with Chisel Mod: 1 Jul 2018

biomesToSpawnIn=biome_meneglin,bog,boreal_forest,brushland,chaparral,coniferous_forest,dead_forest,desert,eucalyptus_forest,fen,flower_field,flower_island,grassland,grove,land_of_lakes,lavender_fields,lush_desert,lush_swamp,maple_woods,marsh,meadow,moor,mountain_foothills,mystic_grove,ominous_woods,orchard,origin_island,outback,overgrown_cliffs,pasture,plains,prairie,quagmire,rainforest,river,sacred_springs,seasonal_forest,shield,shrubland,steppe,temperate_rainforest,tropical_rainforest,volcanic_island,wasteland,wetland,woodland,xeric_shrubland

weight=1
embed_into_distance=64
acceptable_target_blocks=

unacceptable_target_blocks=command_block,slime_congealed,slime_grass,slime_dirt

dimensions=12,13,13
allowable_overhang=0
max_leveling=24
leveling_buffer=-1
preserve_water=0
preserve_lava=0

rule1=0,100,chisel:cobblestone2-8

rule2=0,100,chisel:cobblestone-1,chisel:cobblestone-2,chisel:cobblestone2-0,chisel:cobblestonemossy-1,chisel:cobblestonemossy-2,chisel:cobblestonemossy1-8

rule3=0,100,chisel:cobblestone-1,chisel:cobblestone-2,chisel:cobblestone2-0,chisel:cobblestonemossy-1,chisel:cobblestonemossy-2,chisel:cobblestonemossy1-8

rule4=0,100,chisel:wool_purple-0
rule5=0,100,chisel:wool_green-1
rule6=0,100,chisel:wool_purple-1
rule7=0,100,chisel:cobblestone1-7

rule8=0,100,chisel:bookshelf_spruce-1,chisel:bookshelf_spruce-2,chisel:bookshelf_spruce-3,chisel:bookshelf_spruce-4,chisel:bookshelf_spruce-5,chisel:bookshelf_spruce-6,chisel:bookshelf_spruce-7

rule9=0,100,ChestGenHook:chests/stronghold_library:5-3
rule10=0,100,minecraft:wooden_slab-1
rule11=0,100,minecraft:trapdoor-5
rule12=0,100,chisel:carpet_green-0
rule13=0,100,Skull:0:0-1
rule14=0,100,minecraft:nether_brick_fence-0
rule15=1,100,minecraft:redstone_torch-5
rule16=0,100,minecraft:web-0,minecraft:air
rule17=0,100,chisel:cobblestone1-2
rule18=0,100,minecraft:stone_brick_stairs-7
rule19=0,100,minecraft:stone_brick_stairs-5
rule20=0,100,minecraft:stone_brick_stairs-6
rule21=0,100,minecraft:stone_brick_stairs-4
rule22=0,100,chisel:cobblestone2-9

layer
1,3,3,3,3,3,3,3,3,3,3,2,1
3,3,3,3,3,3,3,3,3,3,3,2,2
3,3,3,3,3,3,3,3,3,3,3,3,3
3,3,3,3,3,3,3,3,3,3,3,3,3
3,3,3,3,3,3,3,3,3,3,3,3,3
3,3,3,3,3,3,3,3,3,3,3,3,3
3,3,3,3,3,3,3,3,3,3,3,3,3
3,3,3,3,3,3,3,3,3,3,3,3,3
3,3,3,3,3,3,3,3,3,3,3,3,3
3,3,3,3,3,3,3,3,3,3,3,3,3
3,3,3,3,3,3,3,3,3,3,3,3,3
3,3,3,3,3,3,3,3,3,3,3,3,3
1,3,3,3,3,3,3,3,3,3,3,3,1
endlayer

layer
1,3,3,3,3,3,3,3,3,3,3,3,1
3,3,3,3,3,3,3,3,3,3,3,3,3
3,3,3,3,3,3,3,3,3,3,3,3,3
3,3,3,3,3,3,3,3,3,3,3,3,3
3,3,3,3,3,3,3,3,3,3,3,3,3
3,3,3,3,3,3,3,3,3,3,3,3,3
3,3,3,3,3,3,3,3,3,3,3,3,3
3,3,3,3,3,3,3,3,3,3,3,3,3
3,3,3,3,3,3,3,3,3,3,3,3,3
3,3,3,3,3,3,3,3,3,3,3,3,3
3,3,3,3,3,3,3,3,3,3,3,3,3
3,3,3,3,3,3,3,3,3,3,3,3,3
1,3,3,3,3,3,3,3,3,3,3,3,1
endlayer

layer
1,3,3,3,3,1,1,1,3,3,3,3,1
3,3,3,3,3,4,4,4,3,3,3,3,3
3,3,4,4,5,4,4,4,5,4,4,3,3
3,3,4,4,5,4,4,4,5,4,4,3,3
3,3,5,5,6,5,5,5,6,5,5,3,3
1,4,4,4,5,4,4,3,5,4,4,4,1
1,4,4,4,5,4,4,3,5,4,4,4,1
1,4,4,4,5,4,4,3,5,4,4,4,1
3,3,5,5,6,5,5,5,6,5,5,3,3
3,3,4,4,5,4,4,4,5,4,4,3,3
3,3,4,4,5,4,4,4,5,4,4,3,3
3,3,3,3,3,4,4,4,3,3,3,3,3
1,3,3,3,3,1,1,1,3,3,3,3,1
endlayer

layer
1,3,3,3,3,7,0,7,3,3,3,3,1
3,7,8,8,7,0,0,0,7,8,8,7,3
3,8,0,0,0,0,0,0,0,0,0,8,3
3,8,0,0,0,0,0,0,0,0,0,8,3
3,7,0,0,0,0,0,0,0,0,0,7,3
7,0,0,0,0,0,8,8,0,0,0,0,7
0,0,0,0,11,10,0,9,0,0,0,0,0
7,0,0,0,0,0,8,8,0,0,0,0,7
3,7,0,0,0,0,0,0,0,0,0,7,3
3,8,0,0,0,0,0,0,0,0,0,8,3
3,8,0,0,0,0,0,0,0,0,0,8,3
3,7,8,8,7,0,0,0,7,8,8,7,3
1,3,3,3,3,7,0,7,3,3,3,3,1
endlayer

layer
1,3,3,3,3,7,0,7,3,3,3,3,1
3,7,8,8,7,0,0,0,7,8,8,7,3
3,8,0,0,0,0,0,0,0,0,0,8,3
3,8,0,0,0,0,0,0,0,0,0,8,3
3,7,0,0,0,0,0,0,0,0,0,7,3
7,0,0,0,0,0,12,12,0,0,0,0,7
0,0,0,0,0,13,0,12,0,0,0,0,0
7,0,0,0,0,0,12,12,0,0,0,0,7
3,7,0,0,0,0,0,0,0,0,0,7,3
3,8,0,0,0,0,0,0,0,0,0,8,3
3,8,0,0,0,0,0,0,0,0,0,8,3
3,7,8,8,7,0,0,0,7,8,8,7,3
1,3,3,3,3,7,0,7,3,3,3,3,1
endlayer

layer
1,3,3,3,3,7,0,7,3,3,3,3,1
3,7,8,8,7,0,0,0,7,8,8,7,3
3,8,0,0,0,0,0,0,0,0,0,8,3
3,8,0,0,0,0,0,0,0,0,0,8,3
3,7,0,0,0,0,0,0,0,0,0,7,3
7,0,0,0,0,0,0,0,0,0,0,0,7
0,0,0,0,0,0,0,0,0,0,0,0,0
7,0,0,0,0,0,0,0,0,0,0,0,7
3,7,0,0,0,0,0,0,0,0,0,7,3
3,8,0,0,0,0,0,0,0,0,0,8,3
3,8,0,0,0,0,0,0,0,0,0,8,3
3,7,8,8,7,0,0,0,7,8,8,7,3
1,3,3,3,3,7,0,7,3,3,3,3,1
endlayer

layer
1,3,3,3,3,7,0,7,3,3,3,3,1
3,7,8,8,7,0,0,0,7,8,8,7,2
3,8,0,0,0,0,0,0,0,0,0,8,3
3,8,0,0,0,0,0,0,0,0,0,8,3
3,7,0,0,0,0,0,0,0,0,0,7,3
7,0,0,0,0,0,14,0,0,0,0,0,7
0,0,0,0,0,14,14,14,0,0,0,0,0
7,0,0,0,0,0,14,0,0,0,0,0,7
3,7,0,0,0,0,0,0,0,0,0,7,3
3,8,0,0,0,0,0,0,0,0,0,8,3
3,8,0,0,0,0,0,0,0,0,0,8,3
3,7,8,8,7,0,0,0,7,8,8,7,3
1,3,3,3,3,7,0,7,3,3,3,3,1
endlayer

layer
1,3,3,3,3,1,1,1,3,3,3,3,1
3,7,8,8,7,0,0,0,7,8,8,7,3
3,8,0,0,0,0,0,0,0,0,0,8,3
3,8,0,0,0,0,0,0,0,0,0,8,3
3,7,0,0,0,0,0,0,0,0,0,7,3
1,0,0,0,0,0,15,0,0,0,0,0,1
1,0,0,0,0,15,14,15,0,0,0,0,1
1,0,0,0,0,0,15,0,0,0,0,0,1
3,7,0,0,0,0,0,0,0,0,0,7,3
3,8,0,0,0,0,0,0,0,0,0,8,3
3,8,0,0,0,0,0,0,0,0,0,8,3
3,7,8,8,7,0,0,0,7,8,8,7,3
1,3,3,3,3,1,1,1,3,3,3,3,1
endlayer

layer
1,3,3,3,3,3,3,3,3,3,3,3,1
3,1,16,16,1,16,0,16,1,16,16,1,3
3,16,0,0,16,0,0,0,16,0,0,16,3
3,16,0,0,0,0,0,0,0,0,0,16,3
3,1,16,0,0,0,0,0,0,0,16,1,3
3,16,0,0,0,0,0,0,0,0,0,16,3
3,0,0,0,0,0,14,0,0,0,0,0,3
3,16,0,0,0,0,0,0,0,0,0,16,3
3,1,16,0,0,0,0,0,0,0,16,1,3
3,16,0,0,0,0,0,0,0,0,0,16,3
3,16,0,0,16,0,0,0,16,0,0,16,3
3,1,16,16,1,16,0,16,1,16,16,1,3
1,3,3,3,3,3,3,3,3,3,3,3,1
endlayer

layer
1,3,3,3,3,3,3,3,3,3,3,3,1
3,3,3,3,3,3,3,3,3,3,3,3,3
3,3,3,3,3,3,3,3,3,3,3,3,3
3,3,3,17,17,17,17,17,17,17,3,3,3
3,3,3,17,19,19,19,19,18,17,3,3,3
3,3,3,17,20,0,0,0,18,17,3,3,3
3,3,3,17,20,0,14,0,18,17,3,3,3
3,3,3,17,20,0,0,0,18,17,3,3,3
3,3,3,17,21,21,21,21,21,17,3,3,3
3,3,3,17,17,17,17,17,17,17,3,3,3
3,3,3,3,3,3,3,3,3,3,3,3,3
3,3,3,3,3,3,3,3,3,3,3,3,3
1,3,3,3,3,3,3,3,3,3,3,3,1
endlayer

layer
1,3,3,3,3,3,3,3,3,3,3,3,1
3,3,3,3,3,3,3,3,3,3,3,3,3
3,3,3,3,3,3,3,3,3,3,3,3,3
3,3,3,3,3,3,3,3,3,3,3,3,3
3,3,3,3,22,22,22,22,22,3,3,3,3
3,3,3,3,22,22,22,22,22,3,3,3,3
3,3,3,3,22,22,22,22,22,3,3,3,3
3,3,3,3,22,22,22,22,22,3,3,3,3
3,3,3,3,22,22,22,22,22,3,3,3,3
3,3,3,3,3,3,3,3,3,3,3,3,3
3,3,3,3,3,3,3,3,3,3,3,3,3
3,3,3,3,3,3,3,3,3,3,3,3,3
1,3,3,3,3,3,3,3,3,3,3,3,1
endlayer

layer
1,3,3,3,3,3,3,3,3,3,3,3,1
3,3,3,3,3,3,3,3,3,3,3,3,3
3,3,3,3,3,3,3,3,3,3,3,3,3
3,3,3,3,3,3,3,3,3,3,3,3,3
3,3,3,3,3,3,3,3,3,3,3,3,3
3,3,3,3,3,3,3,3,3,3,3,3,3
3,3,3,3,3,3,3,3,3,3,3,3,3
3,3,3,3,3,3,3,3,3,3,3,3,3
3,3,3,3,3,3,3,3,3,3,3,3,3
3,3,3,3,3,3,3,3,3,3,3,3,3
3,3,3,3,3,3,3,3,3,3,3,3,3
3,3,3,3,3,3,3,3,3,3,3,3,3
1,3,3,3,3,3,3,3,3,3,3,3,1
endlayer

