# Chisel Marble Tomb
# Created by Ruins mod version 17.1 Ingame Parser
# authoring Player: Jordan_Greywolf
# Created for MC 1.12 and Chisel Mod: 30 Jun 2018

biomesToSpawnIn=biome_meneglin,bog,boreal_forest,brushland,chaparral,coniferous_forest,dead_forest,desert,eucalyptus_forest,fen,flower_field,flower_island,grassland,grove,land_of_lakes,lavender_fields,lush_desert,lush_swamp,maple_woods,marsh,meadow,moor,mountain_foothills,mystic_grove,ominous_woods,orchard,origin_island,outback,overgrown_cliffs,pasture,plains,prairie,quagmire,rainforest,river,sacred_springs,seasonal_forest,shield,shrubland,steppe,temperate_rainforest,tropical_rainforest,volcanic_island,wasteland,wetland,woodland,xeric_shrubland

weight=1
embed_into_distance=32
acceptable_target_blocks=

unacceptable_target_blocks=cloud,slime_congealed,slime_grass,slime_dirt

dimensions=12,13,13
allowable_overhang=0
max_leveling=12
leveling_buffer=-1
preserve_water=0
preserve_lava=0

# Randomized Marble Bricks (Bricks, Cracked Bricks, Weathered Bricks)
rule1=0,100,chisel:marble2-0,chisel:marble-1,chisel:marble-2

rule2=0,100,chisel:marble-4
rule3=0,100,chisel:marble1-2
rule4=0,100,minecraft:water-0
rule5=0,100,ChestGenHook:chests/simple_dungeon:5-3
rule6=0,100,chisel:marblepillar-0
rule7=0,100,chisel:marblepillar-1
rule8=0,100,minecraft:dispenser-3
rule9=0,100,minecraft:water-1
rule10=0,100,chisel:marble-7
rule11=0,100,minecraft:dispenser-2
rule12=0,100,chisel:marblepillar-14
rule13=0,100,minecraft:dispenser-4

rule14=0,100,MobSpawner:Skeleton

rule15=0,100,minecraft:dispenser-5
rule16=0,100,preserveBlock

layer
1,1,1,1,1,1,1,1,1,1,1,1,1
1,2,2,2,2,2,2,2,2,2,2,2,1
1,2,2,2,2,2,2,2,2,2,2,2,1
1,2,2,2,2,2,2,2,2,2,2,2,1
1,2,2,2,2,2,2,2,2,2,2,2,1
1,2,2,2,2,2,2,2,2,2,2,2,1
1,2,2,2,2,2,2,2,2,2,2,2,1
1,2,2,2,2,2,2,2,2,2,2,2,1
1,2,2,2,2,2,2,2,2,2,2,2,1
1,2,2,2,2,2,2,2,2,2,2,2,1
1,2,2,2,2,2,2,2,2,2,2,2,1
1,2,2,2,2,2,2,2,2,2,2,2,1
1,1,1,1,1,1,1,1,1,1,1,1,1
endlayer

layer
1,1,1,1,1,1,3,1,1,1,1,1,1
1,2,2,2,2,2,2,2,2,2,2,2,1
1,2,3,3,3,2,3,2,3,3,3,2,1
1,2,3,2,3,2,2,2,3,2,3,2,1
1,2,3,3,3,3,3,3,3,3,3,2,1
1,2,2,2,3,2,2,2,3,2,2,2,1
1,4,4,2,3,2,5,2,3,2,4,4,1
1,2,2,2,3,2,2,2,3,2,2,2,1
1,2,3,3,3,3,3,3,3,3,3,2,1
1,2,3,2,3,2,2,2,3,2,3,2,1
1,2,3,3,3,2,3,2,3,3,3,2,1
1,2,2,2,2,2,2,2,2,2,2,2,1
1,1,1,1,1,1,3,1,1,1,1,1,1
endlayer

layer
1,1,1,1,1,1,0,1,1,1,1,1,1
1,6,0,6,0,6,0,6,0,6,0,6,1
1,0,0,0,0,0,0,0,0,0,0,0,1
1,6,0,0,0,0,0,0,0,0,0,6,1
1,0,0,0,0,0,0,0,0,0,0,0,1
1,6,0,0,0,7,0,7,0,0,0,6,1
11,4,9,0,0,0,10,0,0,0,9,4,8
1,6,0,0,0,7,0,7,0,0,0,6,1
1,0,0,0,0,0,0,0,0,0,0,0,1
1,6,0,0,0,0,0,0,0,0,0,6,1
1,0,0,0,0,0,0,0,0,0,0,0,1
1,6,0,6,0,6,0,6,0,6,0,6,1
1,1,1,1,1,1,0,1,1,1,1,1,1
endlayer

layer
1,1,1,1,1,1,0,1,1,1,1,1,1
1,6,0,6,0,6,0,6,0,6,0,6,1
1,0,0,0,0,0,0,0,0,0,0,0,1
1,6,0,0,0,0,0,0,0,0,0,6,1
1,0,0,0,0,0,0,0,0,0,0,0,1
1,6,0,0,0,12,0,12,0,0,0,6,1
1,0,0,0,0,0,10,0,0,0,0,0,1
1,6,0,0,0,12,0,12,0,0,0,6,1
1,0,0,0,0,0,0,0,0,0,0,0,1
1,6,0,0,0,0,0,0,0,0,0,6,1
1,0,0,0,0,0,0,0,0,0,0,0,1
1,6,0,6,0,6,0,6,0,6,0,6,1
1,1,1,1,1,1,0,1,1,1,1,1,1
endlayer

layer
1,1,1,1,1,1,3,1,1,1,1,1,1
1,6,0,6,0,6,0,6,0,6,0,6,1
1,0,0,0,0,0,0,0,0,0,0,0,1
1,6,0,0,0,0,0,0,0,0,0,6,1
1,0,0,0,0,0,0,0,0,0,0,0,1
1,6,0,0,0,10,13,10,0,0,0,6,1
1,0,0,0,0,8,14,11,0,0,0,0,1
1,6,0,0,0,10,15,10,0,0,0,6,1
1,0,0,0,0,0,0,0,0,0,0,0,1
1,6,0,0,0,0,0,0,0,0,0,6,1
1,0,0,0,0,0,0,0,0,0,0,0,1
1,6,0,6,0,6,0,6,0,6,0,6,1
1,1,1,1,1,1,3,1,1,1,1,1,1
endlayer

layer
1,1,1,1,1,1,1,1,1,1,1,1,1
1,12,0,12,0,12,0,12,0,12,0,12,1
1,0,0,0,0,0,0,0,0,0,0,0,1
1,12,0,0,0,0,0,0,0,0,0,12,1
1,0,0,0,0,0,0,0,0,0,0,0,1
1,12,0,0,0,0,0,0,0,0,0,12,1
1,0,0,0,0,0,0,0,0,0,0,0,1
1,12,0,0,0,0,0,0,0,0,0,12,1
1,0,0,0,0,0,0,0,0,0,0,0,1
1,12,0,0,0,0,0,0,0,0,0,12,1
1,0,0,0,0,0,0,0,0,0,0,0,1
1,12,0,12,0,12,0,12,0,12,0,12,1
1,1,1,1,1,1,1,1,1,1,1,1,1
endlayer

layer
1,1,1,1,1,1,1,1,1,1,1,1,1
1,10,10,10,10,10,10,10,10,10,10,10,1
1,10,10,10,0,0,0,0,0,10,10,10,1
1,10,10,0,0,0,0,0,0,0,10,10,1
1,10,0,0,0,0,0,0,0,0,0,10,1
1,10,0,0,0,0,0,0,0,0,0,10,1
1,10,0,0,0,0,0,0,0,0,0,10,1
1,10,0,0,0,0,0,0,0,0,0,10,1
1,10,0,0,0,0,0,0,0,0,0,10,1
1,10,10,0,0,0,0,0,0,0,10,10,1
1,10,10,10,0,0,0,0,0,10,10,10,1
1,10,10,10,10,10,10,10,10,10,10,10,1
1,1,1,1,1,1,1,1,1,1,1,1,1
endlayer

layer
16,16,16,16,16,16,16,16,16,16,16,16,16
16,16,16,16,16,16,16,16,16,16,16,16,16
16,16,16,10,10,10,10,10,10,10,16,16,16
16,16,10,10,10,0,0,0,10,10,10,16,16
16,16,10,10,0,0,0,0,0,10,10,16,16
16,16,10,0,0,0,0,0,0,0,10,16,16
16,16,10,0,0,0,0,0,0,0,10,16,16
16,16,10,0,0,0,0,0,0,0,10,16,16
16,16,10,10,0,0,0,0,0,10,10,16,16
16,16,10,10,10,0,0,0,10,10,10,16,16
16,16,16,10,10,10,10,10,10,10,16,16,16
16,16,16,16,16,16,16,16,16,16,16,16,16
16,16,16,16,16,16,16,16,16,16,16,16,16
endlayer

layer
16,16,16,16,16,16,16,16,16,16,16,16,16
16,16,16,16,16,16,16,16,16,16,16,16,16
16,16,16,16,16,16,10,16,16,16,16,16,16
16,16,16,10,10,10,10,10,10,10,16,16,16
16,16,16,10,0,0,0,0,0,10,16,16,16
16,16,16,10,0,0,0,0,0,10,16,16,16
16,16,10,10,0,0,0,0,0,10,10,16,16
16,16,16,10,0,0,0,0,0,10,16,16,16
16,16,16,10,0,0,0,0,0,10,16,16,16
16,16,16,10,10,10,10,10,10,10,16,16,16
16,16,16,16,16,16,10,16,16,16,16,16,16
16,16,16,16,16,16,16,16,16,16,16,16,16
16,16,16,16,16,16,16,16,16,16,16,16,16
endlayer

layer
16,16,16,16,16,16,16,16,16,16,16,16,16
16,16,16,16,16,16,16,16,16,16,16,16,16
16,16,16,16,16,16,16,16,16,16,16,16,16
16,16,16,16,10,10,10,10,10,16,16,16,16
16,16,16,10,0,0,0,0,0,10,16,16,16
16,16,16,10,0,0,0,0,0,10,16,16,16
16,16,16,10,0,0,0,0,0,10,16,16,16
16,16,16,10,0,0,0,0,0,10,16,16,16
16,16,16,10,0,0,0,0,0,10,16,16,16
16,16,16,16,10,10,10,10,10,16,16,16,16
16,16,16,16,16,16,16,16,16,16,16,16,16
16,16,16,16,16,16,16,16,16,16,16,16,16
16,16,16,16,16,16,16,16,16,16,16,16,16
endlayer

layer
16,16,16,16,16,16,16,16,16,16,16,16,16
16,16,16,16,16,16,16,16,16,16,16,16,16
16,16,16,16,16,16,16,16,16,16,16,16,16
16,16,16,16,16,10,10,10,16,16,16,16,16
16,16,16,16,10,10,10,10,10,16,16,16,16
16,16,16,10,10,10,0,10,10,10,16,16,16
16,16,16,10,10,0,0,0,10,10,16,16,16
16,16,16,10,10,10,0,10,10,10,16,16,16
16,16,16,16,10,10,10,10,10,16,16,16,16
16,16,16,16,16,10,10,10,16,16,16,16,16
16,16,16,16,16,16,16,16,16,16,16,16,16
16,16,16,16,16,16,16,16,16,16,16,16,16
16,16,16,16,16,16,16,16,16,16,16,16,16
endlayer

layer
16,16,16,16,16,16,16,16,16,16,16,16,16
16,16,16,16,16,16,16,16,16,16,16,16,16
16,16,16,16,16,16,16,16,16,16,16,16,16
16,16,16,16,16,16,16,16,16,16,16,16,16
16,16,16,16,16,16,16,16,16,16,16,16,16
16,16,16,16,16,10,10,10,16,16,16,16,16
16,16,16,16,16,10,10,10,16,16,16,16,16
16,16,16,16,16,10,10,10,16,16,16,16,16
16,16,16,16,16,16,16,16,16,16,16,16,16
16,16,16,16,16,16,16,16,16,16,16,16,16
16,16,16,16,16,16,16,16,16,16,16,16,16
16,16,16,16,16,16,16,16,16,16,16,16,16
16,16,16,16,16,16,16,16,16,16,16,16,16
endlayer

