# Chisel Marble Garden - Intact (NOCB)
# Created by Ruins mod version 17.1 Ingame Parser
# authoring Player: Jordan_Greywolf
# Created for MC 1.12 with Chisel Mod: 1 Jul 2018

biomesToSpawnIn=birch_forest,boreal_forest,brushland,chaparral,firefly_forest,flower_field,flower_forest,forest,grassland,grove,heathland,lavender_fields,lighted_forest,magical_forest,meadow,mountain_foothills,mutated_forest,mutated_plains,oak_savannah,orchard,origin_valley,pasture,plains,prairie,taiga,twilight_clearing,woodland

uniqueMinDistance=500

weight=1
embed_into_distance=8
acceptable_target_blocks=

unacceptable_target_blocks=cloud,Natura:cloud,red_mushroom_block,brown_mushroom_block,oak_stairs,spruce_stairs,dark_oak_stairs,birch_stairs,jungle_stairs,acacia_stairs,cobblestone,lava,flowing_lava,slime_congealed,slime_dirt,slime_grass,command_block,planks,planks2,concrete,cobblestone,stonebrick,brick_block,glass,torch,oak_stairs,stone_stairs,brick_stairs,stone_brick_stairs,nether_brick_stairs,sandstone_stairs,spruce_stairs,birch_stairs,jungle_stairs,quartz_stairs,acacia_stairs,dark_oak_stairs,cobblestone_wall,stone_slab,double_stone_slab,stone_slab2,wooden_slab,double_wooden_slab,nether_brick

dimensions=16,13,13
allowable_overhang=0
max_leveling=8
leveling_buffer=-1
preserve_water=0
preserve_lava=0

rule1=0,100,chisel:marble-7
rule2=0,100,chisel:marble-4

rule3=0,100,MobSpawner:Skeleton

# Randomized Marble Bricks (Bricks, Cracked Bricks, Weathered Bricks)
rule4=0,100,chisel:marble2-0,chisel:marble-1,chisel:marble-2

rule5=0,100,chisel:marblepillar-6
rule6=0,100,minecraft:vine-4
rule7=0,100,minecraft:vine-8
rule8=0,100,minecraft:vine-1
rule9=0,100,minecraft:water-0
rule10=0,100,minecraft:vine-2
rule11=0,100,ChestGenHook:chests/simple_dungeon:3-4
rule12=0,100,ChestGenHook:chests/simple_dungeon:3-2
rule13=0,100,minecraft:water-8
rule14=0,100,ChestGenHook:chests/simple_dungeon:3-3
rule15=0,100,ChestGenHook:chests/simple_dungeon:3-5
rule16=0,100,minecraft:vine-10
rule17=0,100,minecraft:vine-5
rule18=0,100,preserveBlock
rule19=0,100,minecraft:grass-0
rule20=0,100,chisel:marblepillar-1

rule21=0,100,minecraft:tallgrass-1-addbonemeal,minecraft:sapling-0-addbonemeal,minecraft:sapling-1-addbonemeal,minecraft:sapling-2-addbonemeal,minecraft:sapling-3-addbonemeal

rule22=0,100,minecraft:double_plant-4
rule23=0,100,minecraft:water-1
rule24=0,100,minecraft:double_plant-10
rule25=0,100,chisel:marblepillar-14


layer
1,1,1,1,1,1,1,1,1,1,1,1,1
1,2,2,2,2,2,2,2,2,2,2,2,1
1,2,2,2,2,2,2,2,2,2,2,2,1
1,2,2,2,2,2,2,2,2,2,2,2,1
1,2,2,2,2,2,2,2,2,2,2,2,1
1,2,2,2,2,2,2,2,2,2,2,2,1
1,2,2,2,2,2,3,2,2,2,2,2,1
1,2,2,2,2,2,2,2,2,2,2,2,1
1,2,2,2,2,2,2,2,2,2,2,2,1
1,2,2,2,2,2,2,2,2,2,2,2,1
1,2,2,2,2,2,2,2,2,2,2,2,1
1,2,2,2,2,2,2,2,2,2,2,2,1
1,1,1,1,1,1,1,1,1,1,1,1,1
endlayer

layer
4,4,4,4,4,4,4,4,4,4,4,4,4
4,0,0,0,0,0,0,0,0,0,0,0,4
4,0,5,0,5,0,5,0,5,6,5,0,4
4,0,0,0,0,0,0,0,0,0,0,0,4
4,0,5,8,7,1,1,1,0,0,5,0,4
4,0,0,6,1,9,9,9,1,0,0,0,4
4,0,5,6,1,9,9,9,1,0,5,0,4
4,0,0,0,1,9,9,9,1,0,0,0,4
4,0,5,0,6,1,1,1,0,0,5,0,4
4,0,0,0,0,0,0,0,7,0,0,6,4
4,0,5,0,5,0,5,0,5,0,5,0,4
4,0,0,0,0,0,0,0,0,0,0,0,4
4,4,4,4,4,4,4,4,4,4,4,4,4
endlayer

layer
4,4,4,4,4,4,4,4,4,4,4,4,4
4,0,0,0,0,0,0,0,0,0,0,0,4
4,0,5,8,5,8,5,0,5,6,5,0,4
4,0,0,0,0,0,10,0,0,0,0,0,4
4,0,5,8,0,0,11,0,0,6,5,0,4
4,0,7,0,0,0,0,0,0,0,0,0,4
4,0,5,8,14,0,13,0,12,6,5,6,4
4,0,0,0,0,0,0,0,0,0,0,0,4
4,0,5,0,0,0,15,0,0,6,5,0,4
4,0,0,0,0,0,7,0,7,0,0,6,4
4,0,5,0,5,0,5,0,5,0,5,0,4
4,0,0,0,0,7,0,7,0,0,0,7,4
4,4,4,4,4,4,4,4,4,4,4,4,4
endlayer

layer
4,4,4,4,4,4,4,4,4,4,4,4,4
4,0,0,0,0,10,0,0,0,0,16,0,4
4,0,5,8,5,8,5,6,5,6,5,17,4
4,0,0,0,10,0,10,0,0,0,0,0,4
4,0,5,8,0,0,0,0,0,6,5,6,4
4,0,7,0,0,0,0,0,0,0,0,0,4
4,0,5,8,0,0,13,0,0,6,5,6,4
4,0,0,0,0,0,0,0,0,0,7,0,4
4,0,5,0,0,0,0,0,0,6,5,0,4
4,0,0,0,0,0,7,0,7,0,0,6,4
4,0,5,8,5,0,5,0,5,8,5,0,4
4,0,0,7,7,7,0,7,0,7,0,7,4
4,4,4,4,4,4,4,4,4,4,4,4,4
endlayer

layer
4,4,4,4,4,4,4,4,4,4,4,4,4
4,0,0,0,0,10,0,0,0,0,16,0,4
4,0,5,8,5,8,5,6,5,6,5,17,4
4,0,0,0,10,0,10,0,0,0,0,0,4
4,0,5,8,0,0,0,0,0,6,5,6,4
4,0,7,0,0,0,0,0,0,0,0,0,4
4,0,5,8,0,0,13,0,0,6,5,6,4
4,0,0,0,0,0,0,0,0,0,7,0,4
4,0,5,0,0,0,0,0,0,6,5,0,4
4,0,0,0,0,0,7,0,7,0,0,6,4
4,0,5,8,5,0,5,0,5,8,5,0,4
4,0,0,7,7,7,0,7,0,7,0,7,4
4,4,4,4,4,4,4,4,4,4,4,4,4
endlayer

layer
4,4,4,4,4,4,4,4,4,4,4,4,4
4,0,0,0,0,10,0,0,0,0,16,0,4
4,0,5,8,5,8,5,6,5,6,5,17,4
4,0,0,0,10,0,10,0,0,0,0,0,4
4,0,5,8,0,0,0,0,0,6,5,6,4
4,0,7,0,0,0,0,0,0,0,0,0,4
4,0,5,8,0,0,13,0,0,6,5,6,4
4,0,0,0,0,0,0,0,0,0,7,0,4
4,0,5,0,0,0,0,0,0,6,5,0,4
4,0,0,0,0,0,7,0,7,0,0,6,4
4,0,5,8,5,0,5,0,5,8,5,0,4
4,0,0,7,7,7,0,7,0,7,0,7,4
4,4,4,4,4,4,4,4,4,4,4,4,4
endlayer


layer
4,4,4,4,4,4,4,4,4,4,4,4,4
4,0,0,0,0,10,0,0,7,10,7,0,4
4,0,5,8,5,6,5,6,5,6,5,6,4
4,0,0,0,10,0,10,0,10,0,10,0,4
4,0,5,8,0,0,0,0,0,6,5,6,4
4,0,7,0,0,0,0,0,0,0,0,0,4
4,0,5,8,0,0,13,0,0,6,5,6,4
4,0,10,0,0,0,0,0,0,0,7,6,4
4,0,5,0,0,0,0,0,0,6,5,0,4
4,0,7,0,0,0,7,0,7,0,7,6,4
4,0,5,8,5,0,5,0,5,8,5,0,4
4,0,0,7,7,7,10,7,10,7,0,7,4
4,4,4,4,4,4,4,4,4,4,4,4,4
endlayer

layer
1,1,1,1,1,1,1,1,1,1,1,1,1
1,2,2,2,2,2,2,2,2,2,2,2,1
1,2,2,2,2,2,2,2,2,2,2,2,1
1,2,2,2,2,2,2,2,2,2,2,2,1
1,2,2,2,2,2,2,2,2,2,2,2,1
1,2,2,2,2,2,2,2,2,2,2,2,1
1,2,2,2,2,2,13,2,2,2,2,2,1
1,2,2,2,2,2,2,2,2,2,2,2,1
1,2,2,2,2,2,2,2,2,2,2,2,1
1,2,2,2,2,2,2,2,2,2,2,2,1
1,2,2,2,2,2,2,2,2,2,2,2,1
1,2,2,2,2,2,2,2,2,2,2,2,1
1,1,1,1,1,1,1,1,1,1,1,1,1
endlayer

layer
18,18,18,18,18,18,18,18,18,18,18,18,18
18,1,1,1,1,1,1,1,1,1,1,1,18
18,1,2,2,2,2,2,2,2,2,2,1,18
18,1,2,19,19,19,19,19,19,19,2,1,18
18,1,2,19,19,19,19,19,19,19,2,1,18
18,1,2,19,19,9,9,9,19,19,2,1,18
18,1,2,19,19,9,9,9,19,19,2,1,18
18,1,2,19,19,9,9,9,19,19,2,1,18
18,1,2,19,19,19,19,19,19,19,2,1,18
18,1,2,19,19,19,19,19,19,19,2,1,18
18,1,2,2,2,2,2,2,2,2,2,1,18
18,1,1,1,1,1,1,1,1,1,1,1,18
18,18,18,18,18,18,18,18,18,18,18,18,18
endlayer

layer
18,18,18,18,18,18,18,18,0,18,18,18,18
18,18,18,0,0,18,0,0,0,0,0,18,18
18,18,20,0,20,0,20,0,20,0,20,0,18
18,0,0,22,21,21,21,21,21,21,0,18,18
18,0,20,21,21,21,21,21,21,22,20,0,18
18,18,0,21,21,0,23,0,21,21,0,0,0
18,0,20,21,21,23,9,23,21,21,20,0,18
18,18,0,21,21,0,23,0,21,21,0,18,18
18,0,20,21,21,21,21,21,21,21,20,0,18
0,0,0,21,21,21,21,21,22,21,0,0,0
18,0,20,0,20,0,20,0,20,0,20,0,18
18,18,0,0,0,0,18,0,18,0,0,18,18
18,18,18,0,18,18,18,18,18,18,18,18,18
endlayer

layer
18,18,18,0,0,0,0,0,0,0,0,18,18
18,18,0,0,0,0,0,0,0,0,0,0,18
18,0,20,0,20,0,20,0,20,0,20,0,0
0,0,0,24,0,0,0,0,0,0,0,0,0
0,0,20,0,0,0,0,0,0,24,20,0,0
18,0,0,0,0,0,0,0,0,0,0,0,0
0,0,20,0,0,0,0,0,0,0,20,8,0
18,0,0,0,0,0,0,0,0,0,0,0,0
0,0,20,0,0,0,0,0,0,0,20,0,0
0,0,0,0,0,0,0,0,24,0,0,0,0
0,0,20,0,20,0,20,0,20,0,20,0,0
18,0,0,0,0,0,0,0,0,0,0,0,18
18,18,0,0,0,0,0,0,0,0,0,18,18
endlayer

layer
18,18,0,0,0,0,0,0,0,0,0,0,18
18,0,0,0,0,0,0,0,0,0,0,0,0
0,0,20,0,20,0,20,0,20,0,20,8,0
0,0,0,0,0,0,0,0,0,0,0,0,0
0,0,20,0,0,0,0,0,0,0,20,8,0
0,0,0,0,0,0,0,0,0,0,0,0,0
0,0,20,0,0,0,0,0,0,0,20,8,0
0,0,0,0,0,0,0,0,0,0,0,0,0
0,0,20,0,0,0,0,0,0,0,20,0,0
0,0,0,0,0,0,0,0,0,0,0,0,0
0,0,20,0,20,0,20,0,20,0,20,0,0
0,0,0,0,0,0,0,0,0,0,0,0,0
18,0,0,0,0,0,0,0,0,0,0,0,18
endlayer

layer
18,0,0,0,0,0,0,0,0,0,0,0,0
0,0,0,0,0,0,0,0,0,0,0,0,0
0,0,20,0,20,0,20,0,20,0,20,8,0
0,0,0,0,0,0,0,0,0,0,0,0,0
0,0,20,0,0,0,0,0,0,0,20,8,0
0,0,0,0,0,0,0,0,0,0,0,0,0
0,6,20,0,0,0,0,0,0,0,20,8,0
0,0,0,0,0,0,0,0,0,0,0,0,0
0,0,20,0,0,0,0,0,0,0,20,0,0
0,0,0,0,0,0,0,0,0,0,0,0,0
0,6,20,0,20,0,20,0,20,0,20,0,0
0,0,0,0,0,0,0,0,0,0,0,0,0
0,0,0,0,0,0,0,0,0,0,0,0,0
endlayer

layer
0,0,0,0,0,0,0,0,0,0,0,0,0
0,0,7,0,0,0,7,0,7,0,7,0,0
0,0,20,0,20,0,20,0,20,0,20,8,0
0,0,0,0,0,0,0,0,0,0,0,0,0
0,0,20,0,0,0,0,0,0,0,20,8,0
0,0,0,0,0,0,0,0,0,0,0,0,0
0,6,20,0,0,0,0,0,0,0,20,8,0
0,0,0,0,0,0,0,0,0,0,0,0,0
0,0,20,0,0,0,0,0,0,0,20,0,0
0,0,0,0,0,0,0,0,0,0,10,0,0
0,6,20,0,20,0,20,0,20,0,20,8,0
0,0,0,0,10,0,0,0,10,0,0,0,0
0,0,0,0,0,0,0,10,0,0,0,0,0
endlayer

layer
0,0,0,0,0,0,0,7,0,0,0,0,0
0,0,7,0,7,0,7,0,7,0,7,0,0
0,6,25,0,25,0,25,0,25,0,25,8,0
0,0,0,0,0,0,0,0,0,0,0,0,0
0,0,25,0,0,0,0,0,0,0,25,8,0
6,0,7,0,0,0,0,0,0,0,0,0,8
0,6,25,0,0,0,0,0,0,0,25,8,0
0,0,0,0,0,0,0,0,0,0,0,0,0
0,6,25,0,0,0,0,0,0,0,25,0,0
0,0,0,0,0,0,0,0,0,0,10,0,0
0,6,25,0,25,0,25,0,25,0,25,8,0
0,0,0,0,10,0,0,0,10,0,0,0,8
0,0,0,0,0,0,0,10,0,0,0,10,0
endlayer

layer
0,0,0,7,0,0,0,7,0,7,0,0,0
6,1,1,1,1,1,1,1,1,1,1,1,0
0,1,1,1,1,1,1,1,1,1,1,1,0
0,1,1,0,0,0,0,0,0,0,1,1,0
0,1,1,0,0,0,0,0,0,0,1,1,0
6,1,1,0,0,0,0,0,0,0,1,1,8
0,1,1,0,0,0,0,0,0,0,1,1,0
0,1,1,0,0,0,0,0,0,0,1,1,0
0,1,1,0,0,0,0,0,0,0,1,1,0
0,1,1,0,0,0,0,0,0,0,1,1,0
0,1,1,1,1,1,1,1,1,1,1,1,8
6,1,1,1,1,1,1,1,1,1,1,1,8
0,10,0,0,0,0,0,10,0,0,0,10,0
endlayer

