# Snow Keep
# Created by Ruins mod version 17.1 Ingame Parser
# authoring Player: Jordan_Greywolf
# Created for MC 1.12: 5 Jul 2018
# Last Updated: 8 Dec 2018

biomesToSpawnIn=cold_desert,glacier,ice_flats,ice_mountains,mutated_ice_flats,polar_abyss,polar_chasm,snowy_forest,twilight_glacier

biomeTypesToSpawnIn=COLD,SNOWY

uniqueMinDistance=1000

weight=1
embed_into_distance=21
acceptable_target_blocks=

unacceptable_target_blocks=flowing_water,water,flowing_lava,lava,cloud,Natura:Cloud,bedrock,endstone,red_mushroom_block,brown_mushroom_block,slime_congealed,slime_dirt,slime_grass,command_block,planks,planks2,concrete,cobblestone,stonebrick,brick_block,glass,torch,oak_stairs,stone_stairs,brick_stairs,stone_brick_stairs,nether_brick_stairs,sandstone_stairs,spruce_stairs,birch_stairs,jungle_stairs,quartz_stairs,acacia_stairs,dark_oak_stairs,cobblestone_wall,stone_slab,double_stone_slab,stone_slab2,wooden_slab,double_wooden_slab,nether_brick

dimensions=40,14,14
allowable_overhang=0
max_leveling=2
leveling_buffer=0
preserve_water=0
preserve_lava=0

rule1=0,100,preserveBlock
rule2=0,100,minecraft:snow-0
rule3=0,100,minecraft:packed_ice-0
rule4=0,100,minecraft:ice-0
rule5=0,100,ChestGenHook:chests/simple_dungeon:3-5
rule6=0,100,MobSpawner:Skeleton
rule7=0,100,ChestGenHook:chests/simple_dungeon:3-3
rule8=0,100,ChestGenHook:chests/simple_dungeon:3-2
rule9=0,100,minecraft:snow_layer-4

rule10=0,100,CommandBlock:RUINSTRIGGER /summon minecraft:polar_bear ~ ~1 ~ {PersistanceRequired:1b,Health:60,Passengers:[{id:"minecraft:stray",PersistenceRequired:1b,Health:50,HandItems:[{id:"minecraft:bow",tag:{display:{Name:"Frost Bow",Lore:["Strikes foes with the sting of an arctic wind on bare skin."]},ench:[{id:49,lvl:2}]},Count:1},{id:"minecraft:tipped_arrow",tag:{Potion:"minecraft:long_slowness"},Count:1}],HandDropChances:[2F,2F],ArmorItems:[{tag:{display:{Name:"Frost Boots"},ench:[{id:9,lvl:2}]},Count:1,id:"minecraft:diamond_boots"},{},{},{}],ArmorDropChances:[2F,0F,0F,0F]}]}:@

rule11=0,100,ChestGenHook:chests/simple_dungeon:3-4

rule12=0,100,IInventory;minecraft:chest;minecraft:packed_ice#8#0#0+minecraft:ice#8#0#2+minecraft:snow#8#0#5+minecraft:snowball#4#0#6+minecraft:ice#8#0#8+minecraft:packed_ice#8#0#10+minecraft:snow#8#0#12+minecraft:packed_ice#8#0#13+minecraft:ice#8#0#16+minecraft:snow#8#0#18+minecraft:snowball#4#0#20+minecraft:ice#8#0#23+minecraft:snow#8#0#24+minecraft:packed_ice#8#0#26-2

rule13=0,100,CommandBlock:RUINSTRIGGER /summon falling_block ~ ~3 ~ {Block:chest,Time:1,TileEntityData:{Items:[{id:written_book,Slot:1,Count:1,tag:{author:"Selana Frostheart",title:"Book of Winter and Spring",pages:["{text:'Walk upon the water with ease, by winter power to make it freeze.',color:blue,bold:true,clickEvent:{action:run_command,value:'/fill ~-8 ~-4 ~-8 ~8 ~4 ~8 ice 0 replace water'}}","{text:'When the winter chill is felt, call springtime thaw to make it melt.',color:green,bold:true,clickEvent:{action:run_command,value:'/fill ~-8 ~-4 ~-8 ~8 ~4 ~8 water 0 replace ice'}}"]}}]}}:@

layer
1,1,1,1,1,2,2,2,2,1,1,1,1,1
1,1,1,2,2,3,3,3,3,2,2,1,1,1
1,1,2,3,3,3,3,3,3,3,3,2,1,1
1,2,3,3,3,3,3,3,3,3,3,3,2,1
1,2,3,3,3,3,3,3,3,3,3,3,2,1
2,3,3,3,3,3,3,3,3,3,3,3,3,2
2,3,3,3,3,3,3,3,3,3,3,3,3,2
2,3,3,3,3,3,3,3,3,3,3,3,3,2
2,3,3,3,3,3,3,3,3,3,3,3,3,2
1,2,3,3,3,3,3,3,3,3,3,3,2,1
1,2,3,3,3,3,3,3,3,3,3,3,2,1
1,1,2,3,3,3,3,3,3,3,3,2,1,1
1,1,1,2,2,3,3,3,3,2,2,1,1,1
1,1,1,1,1,2,2,2,2,1,1,1,1,1
endlayer

layer
1,1,1,1,1,2,2,2,2,1,1,1,1,1
1,1,1,2,2,4,4,4,4,2,2,1,1,1
1,1,2,4,4,4,4,4,4,4,4,2,1,1
1,2,4,4,4,4,4,4,4,4,4,4,2,1
1,2,4,4,4,4,4,4,4,4,4,4,2,1
2,4,4,4,4,4,4,4,4,4,4,4,4,2
2,4,4,4,4,4,4,4,4,4,4,4,4,2
2,4,4,4,4,4,4,4,4,4,4,4,4,2
2,4,4,4,4,4,4,4,4,4,4,4,4,2
1,2,4,4,4,4,4,4,4,4,4,4,2,1
1,2,4,4,4,4,4,4,4,4,4,4,2,1
1,1,2,4,4,4,4,4,4,4,4,2,1,1
1,1,1,2,2,4,4,4,4,2,2,1,1,1
1,1,1,1,1,2,2,2,2,1,1,1,1,1
endlayer

layer
1,1,1,1,1,2,2,2,2,1,1,1,1,1
1,1,1,2,2,0,5,5,0,2,2,1,1,1
1,1,2,4,0,0,0,0,0,0,0,2,1,1
1,2,6,4,0,0,0,0,0,0,0,0,2,1
1,2,4,0,0,0,0,0,0,0,0,0,2,1
2,0,0,0,0,0,4,0,0,0,0,0,0,2
2,8,0,0,0,4,6,4,0,0,0,0,7,2
2,8,0,0,0,0,4,13,9,0,0,0,7,2
2,0,0,0,0,0,0,10,2,0,0,0,0,2
1,2,0,0,0,0,0,0,0,0,0,0,2,1
1,2,0,0,0,0,0,0,4,0,0,0,2,1
1,1,2,0,0,0,0,0,0,0,0,2,1,1
1,1,1,2,2,0,11,11,0,2,2,1,1,1
1,1,1,1,1,2,2,2,2,1,1,1,1,1
endlayer

layer
1,1,1,1,1,2,2,2,2,1,1,1,1,1
1,1,1,2,2,0,0,0,0,2,2,1,1,1
1,1,2,0,0,0,0,0,0,0,0,2,1,1
1,2,4,0,0,0,0,0,0,0,0,0,2,1
1,2,0,0,0,0,0,0,0,0,0,0,2,1
2,0,0,0,0,0,0,0,0,0,0,0,0,2
2,0,0,0,0,0,4,0,0,0,0,0,0,2
2,0,0,0,0,0,0,0,0,0,0,0,0,2
2,0,0,0,0,2,2,9,0,0,0,0,0,2
1,2,0,0,0,0,0,0,0,0,0,0,2,1
1,2,0,0,0,0,0,0,4,0,0,0,2,1
1,1,2,0,0,0,0,0,0,0,0,2,1,1
1,1,1,2,2,0,0,0,0,2,2,1,1,1
1,1,1,1,1,2,2,2,2,1,1,1,1,1
endlayer

layer
1,1,1,1,1,2,2,2,2,1,1,1,1,1
1,1,1,2,2,0,0,0,0,2,2,1,1,1
1,1,2,0,0,0,0,0,0,0,0,2,1,1
1,2,0,0,0,0,0,0,0,0,0,0,2,1
1,2,0,0,0,0,0,0,0,0,0,0,2,1
2,0,0,0,0,0,0,0,0,0,0,0,0,2
2,0,0,0,0,2,4,0,0,0,0,0,0,2
2,0,0,0,0,2,0,0,0,0,0,0,0,2
2,0,0,0,0,9,0,0,0,0,0,0,0,2
1,2,0,0,0,0,0,0,0,0,0,0,2,1
1,2,0,0,0,0,0,0,0,0,0,0,2,1
1,1,2,0,0,0,0,0,0,0,0,2,1,1
1,1,1,2,2,0,0,0,0,2,2,1,1,1
1,1,1,1,1,2,2,2,2,1,1,1,1,1
endlayer

layer
1,1,1,1,1,2,2,2,2,1,1,1,1,1
1,1,1,2,2,0,0,0,0,2,2,1,1,1
1,1,2,0,0,0,0,0,0,0,0,2,1,1
1,2,0,0,0,0,0,0,0,0,0,0,2,1
1,2,0,0,0,0,0,0,0,0,0,0,2,1
2,0,0,0,0,2,2,0,0,0,0,0,0,2
2,0,0,0,0,9,4,0,0,0,0,0,0,2
2,0,0,0,0,0,0,0,0,0,0,0,0,2
2,0,0,0,0,0,0,0,0,0,0,0,0,2
1,2,0,0,0,0,0,0,0,0,0,0,2,1
1,2,0,0,0,0,0,0,0,0,0,0,2,1
1,1,2,0,0,0,0,0,0,0,0,2,1,1
1,1,1,2,2,0,0,0,0,2,2,1,1,1
1,1,1,1,1,2,2,2,2,1,1,1,1,1
endlayer

layer
1,1,1,1,1,2,2,2,2,1,1,1,1,1
1,1,1,2,2,0,0,0,0,2,2,1,1,1
1,1,2,0,0,0,0,0,0,0,0,2,1,1
1,2,0,0,0,0,0,0,0,0,0,0,2,1
1,2,0,0,0,0,0,0,0,0,0,0,2,1
2,0,0,0,0,0,9,2,2,0,0,0,0,2
2,0,0,0,0,0,0,0,0,0,0,0,0,2
2,0,0,0,0,0,0,0,0,0,0,0,0,2
2,0,0,0,0,0,0,0,0,0,0,0,0,2
1,2,0,0,0,0,0,0,0,0,0,0,2,1
1,2,0,0,0,0,0,0,4,0,0,0,2,1
1,1,2,0,0,0,0,0,0,0,0,2,1,1
1,1,1,2,2,0,0,0,0,2,2,1,1,1
1,1,1,1,1,2,2,2,2,1,1,1,1,1
endlayer

layer
1,1,1,1,1,2,2,2,2,1,1,1,1,1
1,1,1,2,2,0,0,0,0,2,2,1,1,1
1,1,2,0,0,0,0,0,4,0,0,2,1,1
1,2,0,0,4,0,0,0,0,0,0,0,2,1
1,2,0,0,0,0,0,0,0,0,0,0,2,1
2,0,0,0,0,0,0,0,9,0,0,0,0,2
2,0,0,0,0,0,0,0,2,0,0,0,0,2
2,0,0,0,0,0,0,0,2,4,0,0,0,2
2,0,0,0,0,0,0,0,0,0,0,0,0,2
1,2,0,0,0,0,0,0,0,0,0,0,2,1
1,2,0,0,0,0,0,0,4,0,0,0,2,1
1,1,2,0,0,0,0,0,0,0,0,2,1,1
1,1,1,2,2,0,0,0,0,2,2,1,1,1
1,1,1,1,1,2,2,2,2,1,1,1,1,1
endlayer

layer
1,1,1,1,1,2,2,2,2,1,1,1,1,1
1,1,1,2,2,0,0,0,0,2,2,1,1,1
1,1,2,0,0,0,0,0,4,0,0,2,1,1
1,2,0,0,4,0,0,0,0,0,0,0,2,1
1,2,0,0,0,0,0,0,0,0,0,0,2,1
2,0,0,0,0,0,0,0,0,0,0,0,0,2
2,0,0,4,0,0,0,0,0,0,0,0,0,2
2,0,0,0,0,0,0,0,9,4,0,0,0,2
2,0,0,0,0,0,0,2,2,0,0,0,0,2
1,2,0,0,0,0,0,0,0,0,0,0,2,1
1,2,0,0,0,0,0,0,4,0,0,0,2,1
1,1,2,0,0,0,4,0,0,0,0,2,1,1
1,1,1,2,2,0,0,0,0,2,2,1,1,1
1,1,1,1,1,2,2,2,2,1,1,1,1,1
endlayer

layer
1,1,1,1,1,2,2,2,2,1,1,1,1,1
1,1,1,2,2,0,0,0,0,2,2,1,1,1
1,1,2,0,0,0,0,0,4,0,0,2,1,1
1,2,0,0,4,0,0,4,0,0,0,0,2,1
1,2,0,0,0,0,0,0,0,0,4,0,2,1
2,0,0,0,0,0,0,0,0,0,0,0,0,2
2,0,0,4,0,0,0,0,0,4,0,0,0,2
2,0,0,0,0,0,0,0,0,4,4,0,0,2
2,0,4,0,0,2,2,9,0,4,0,0,0,2
1,2,0,0,0,0,0,0,0,0,0,0,2,1
1,2,0,0,0,0,0,0,4,0,0,0,2,1
1,1,2,0,0,0,4,0,0,0,0,2,1,1
1,1,1,2,2,0,0,0,0,2,2,1,1,1
1,1,1,1,1,2,2,2,2,1,1,1,1,1
endlayer

layer
1,1,1,1,1,2,2,2,2,1,1,1,1,1
1,1,1,2,2,0,0,0,0,2,2,1,1,1
1,1,2,0,0,0,0,0,4,0,0,2,1,1
1,2,0,0,4,0,0,4,0,0,0,0,2,1
1,2,0,0,0,0,0,0,0,0,4,0,2,1
2,0,0,0,0,0,0,4,0,0,0,0,0,2
2,0,0,4,0,2,0,0,0,4,0,0,0,2
2,0,0,0,0,2,0,0,0,4,4,0,0,2
2,0,4,0,0,9,0,0,0,4,0,0,0,2
1,2,0,0,0,0,0,0,0,0,0,0,2,1
1,2,0,0,0,0,0,0,4,0,0,0,2,1
1,1,2,0,0,0,4,0,0,0,0,2,1,1
1,1,1,2,2,0,0,0,0,2,2,1,1,1
1,1,1,1,1,2,2,2,2,1,1,1,1,1
endlayer

layer
1,1,1,1,1,2,2,2,2,1,1,1,1,1
1,1,1,2,2,4,4,4,4,2,2,1,1,1
1,1,2,4,4,4,4,4,4,4,4,2,1,1
1,2,4,4,4,4,4,4,4,4,4,4,2,1
1,2,4,4,4,4,4,4,4,4,4,4,2,1
2,4,4,4,4,2,4,4,4,4,4,4,4,2
2,4,4,4,4,9,4,4,4,4,4,4,4,2
2,4,4,4,4,0,4,4,4,4,4,4,4,2
2,4,4,4,4,0,0,0,0,4,4,4,4,2
1,2,4,4,4,4,4,4,4,4,4,4,2,1
1,2,4,4,4,4,4,4,4,4,4,4,2,1
1,1,2,4,4,4,4,4,4,4,4,2,1,1
1,1,1,2,2,4,4,4,4,2,2,1,1,1
1,1,1,1,1,2,2,2,2,1,1,1,1,1
endlayer

layer
1,1,1,1,1,2,2,2,2,1,1,1,1,1
1,1,1,2,2,3,3,3,3,2,2,1,1,1
1,1,2,3,3,3,3,3,3,3,3,2,1,1
1,2,3,3,3,3,3,3,3,3,3,3,2,1
1,2,3,3,3,3,3,3,3,3,3,3,2,1
2,3,3,3,3,0,9,2,3,3,3,3,3,2
2,3,3,3,3,0,3,3,3,3,3,3,3,2
2,3,3,3,3,0,3,3,3,3,3,3,3,2
2,3,3,3,3,0,0,3,3,3,3,3,3,2
1,2,3,3,3,3,3,3,3,3,3,3,2,1
1,2,3,3,3,3,3,3,3,3,3,3,2,1
1,1,2,3,3,3,3,3,3,3,3,2,1,1
1,1,1,2,2,3,3,3,3,2,2,1,1,1
1,1,1,1,1,2,2,2,2,1,1,1,1,1
endlayer

layer
1,1,1,1,1,2,2,2,2,1,1,1,1,1
1,1,1,2,2,4,4,4,4,2,2,1,1,1
1,1,2,4,4,4,4,4,4,4,4,2,1,1
1,2,4,4,4,4,4,4,4,4,4,4,2,1
1,2,4,4,4,4,4,4,4,4,4,4,2,1
2,4,4,4,4,0,0,0,9,4,4,4,4,2
2,4,4,4,4,0,4,4,4,4,4,4,4,2
2,4,4,4,4,0,4,4,4,4,4,4,4,2
2,4,4,4,4,4,4,4,4,4,4,4,4,2
1,2,4,4,4,4,4,4,4,4,4,4,2,1
1,2,4,4,4,4,4,4,4,4,4,4,2,1
1,1,2,4,4,4,4,4,4,4,4,2,1,1
1,1,1,2,2,4,4,4,4,2,2,1,1,1
1,1,1,1,1,2,2,2,2,1,1,1,1,1
endlayer

layer
1,1,1,1,1,2,2,2,2,1,1,1,1,1
1,1,1,2,2,0,0,0,0,2,2,1,1,1
1,1,2,0,0,0,0,0,0,0,0,2,1,1
1,2,0,0,0,0,0,0,0,0,0,0,2,1
1,2,0,0,0,0,0,0,0,0,0,0,2,1
2,0,0,0,0,0,0,0,0,0,0,0,0,2
2,0,0,0,0,0,0,0,0,0,0,0,0,2
2,0,0,0,0,0,0,0,0,0,0,0,0,2
2,0,0,0,0,0,6,2,9,0,0,0,0,2
1,2,0,0,0,0,0,0,0,0,0,0,2,1
1,2,0,0,0,0,0,0,0,0,0,0,2,1
1,1,2,0,0,0,0,0,0,0,0,2,1,1
1,1,1,2,2,0,0,0,0,2,2,1,1,1
1,1,1,1,1,2,2,2,2,1,1,1,1,1
endlayer

layer
1,1,1,1,1,2,2,2,2,1,1,1,1,1
1,1,1,2,2,0,0,0,0,2,2,1,1,1
1,1,2,0,0,0,0,0,0,0,0,2,1,1
1,2,0,0,0,0,0,0,0,0,0,0,2,1
1,2,0,0,0,0,0,0,0,0,0,0,2,1
2,0,0,0,0,0,0,0,0,0,0,0,0,2
2,0,0,0,0,0,0,0,0,0,0,0,0,2
2,0,0,0,0,2,0,0,0,0,0,0,0,2
2,0,0,0,0,2,9,0,0,0,0,0,0,2
1,2,0,0,0,0,0,0,0,0,0,0,2,1
1,2,0,0,0,0,0,0,0,0,0,0,2,1
1,1,2,0,0,0,0,0,0,0,0,2,1,1
1,1,1,2,2,0,0,0,0,2,2,1,1,1
1,1,1,1,1,2,2,2,2,1,1,1,1,1
endlayer

layer
1,1,1,1,1,2,2,2,2,1,1,1,1,1
1,1,1,2,2,0,0,0,0,2,2,1,1,1
1,1,2,0,0,0,0,0,0,0,0,2,1,1
1,2,0,0,0,0,0,0,0,0,0,0,2,1
1,2,0,0,0,0,0,0,0,0,0,0,2,1
2,0,0,0,0,2,0,0,0,0,0,0,0,2
2,0,0,0,0,2,0,0,0,0,0,0,0,2
2,0,0,0,0,9,0,0,0,0,0,0,0,2
2,0,0,0,0,0,0,0,0,0,0,0,0,2
1,2,0,0,0,0,0,0,0,0,0,0,2,1
1,2,0,0,0,0,0,0,0,0,0,0,2,1
1,1,2,0,0,0,0,0,0,0,0,2,1,1
1,1,1,2,2,0,0,0,0,2,2,1,1,1
1,1,1,1,1,2,2,2,2,1,1,1,1,1
endlayer

layer
1,1,1,1,1,2,2,2,2,1,1,1,1,1
1,1,1,2,2,0,0,0,0,2,2,1,1,1
1,1,2,0,0,0,0,0,0,0,0,2,1,1
1,2,0,0,0,0,0,0,0,0,0,0,2,1
1,2,0,0,0,0,0,0,0,0,0,0,2,1
2,0,0,0,0,9,2,2,0,0,0,0,0,2
2,0,0,0,0,0,0,0,0,0,0,0,0,2
2,0,0,0,0,0,0,0,0,0,0,0,0,2
2,0,0,0,0,0,0,0,0,0,0,0,0,2
1,2,0,0,0,0,0,0,0,0,0,0,2,1
1,2,0,0,0,0,0,0,0,0,0,0,2,1
1,1,2,0,0,0,0,0,0,0,0,2,1,1
1,1,1,2,2,0,0,0,0,2,2,1,1,1
1,1,1,1,1,2,2,2,2,1,1,1,1,1
endlayer

layer
1,1,1,1,1,2,2,2,2,1,1,1,1,1
1,1,1,2,2,4,4,4,4,2,2,1,1,1
1,1,2,4,4,4,4,4,4,4,4,2,1,1
1,2,4,4,4,4,4,4,4,4,4,4,2,1
1,2,4,4,4,4,4,4,4,4,4,4,2,1
2,4,4,4,4,0,0,9,2,4,4,4,4,2
2,4,4,4,4,0,4,4,4,4,4,4,4,2
2,4,4,4,4,0,4,4,4,4,4,4,4,2
2,4,4,4,4,0,4,4,4,4,4,4,4,2
1,2,4,4,4,4,4,4,4,4,4,4,2,1
1,2,4,4,4,4,4,4,4,4,4,4,2,1
1,1,2,4,4,4,4,4,4,4,4,2,1,1
1,1,1,2,2,4,4,4,4,2,2,1,1,1
1,1,1,1,1,2,2,2,2,1,1,1,1,1
endlayer

layer
1,1,1,1,1,2,2,2,2,1,1,1,1,1
1,1,1,2,2,3,3,3,3,2,2,1,1,1
1,1,2,3,3,3,3,3,3,3,3,2,1,1
1,2,3,3,3,3,3,3,3,3,3,3,2,1
1,2,3,3,3,3,3,3,3,3,3,3,2,1
2,3,3,3,3,0,0,0,0,3,3,3,3,2
2,3,3,3,3,0,3,3,9,3,3,3,3,2
2,3,3,3,3,3,3,3,2,3,3,3,3,2
2,3,3,3,3,3,3,3,3,3,3,3,3,2
1,2,3,3,3,3,3,3,3,3,3,3,2,1
1,2,3,3,3,3,3,3,3,3,3,3,2,1
1,1,2,3,3,3,3,3,3,3,3,2,1,1
1,1,1,2,2,3,3,3,3,2,2,1,1,1
1,1,1,1,1,2,2,2,2,1,1,1,1,1
endlayer

layer
1,1,1,1,1,2,2,2,2,1,1,1,1,1
1,1,1,2,2,4,4,4,4,2,2,1,1,1
1,1,2,4,4,4,4,4,4,4,4,2,1,1
1,2,4,4,4,4,4,4,4,4,4,4,2,1
1,2,4,4,4,4,4,4,4,4,4,4,2,1
2,4,4,4,4,4,0,0,0,4,4,4,4,2
2,4,4,4,4,4,4,4,0,4,4,4,4,2
2,4,4,4,4,4,4,4,0,4,4,4,4,2
2,4,4,4,4,4,4,4,9,4,4,4,4,2
1,2,4,4,4,4,4,4,4,4,4,4,2,1
1,2,4,4,4,4,4,4,4,4,4,4,2,1
1,1,2,4,4,4,4,4,4,4,4,2,1,1
1,1,1,2,2,4,4,4,4,2,2,1,1,1
1,1,1,1,1,2,2,2,2,1,1,1,1,1
endlayer

layer
1,1,1,1,1,1,1,1,1,1,1,1,1,1
1,1,1,1,1,2,2,2,2,1,1,1,1,1
1,1,1,2,2,0,0,0,0,2,2,1,1,1
1,1,2,0,0,0,0,0,0,0,0,2,1,1
1,1,2,0,0,0,0,0,0,0,0,2,1,1
1,2,0,0,0,0,0,0,0,0,0,0,2,1
1,2,0,0,0,2,0,0,0,0,0,0,0,0
1,2,0,0,0,2,0,0,0,0,0,0,0,0
1,2,0,0,0,9,0,0,0,0,0,0,2,1
1,1,2,0,0,0,0,0,0,0,0,2,1,1
1,1,2,0,0,0,0,0,0,0,0,2,1,1
1,1,1,2,2,0,4,0,4,2,2,1,1,1
1,1,1,1,1,2,2,2,2,1,1,1,1,1
1,1,1,1,1,1,1,1,1,1,1,1,1,1
endlayer

layer
1,1,1,1,1,1,1,1,1,1,1,1,1,1
1,1,1,1,1,2,2,2,2,1,1,1,1,1
1,1,1,2,2,0,0,0,0,2,2,1,1,1
1,1,2,0,0,0,0,0,0,0,0,2,1,1
1,1,2,0,0,0,0,0,0,0,0,2,1,1
1,2,0,0,0,2,2,0,0,0,0,0,2,1
1,2,4,0,0,9,0,0,4,0,0,0,0,0
1,2,0,0,0,0,4,0,0,0,4,0,0,0
1,2,0,0,0,0,0,0,0,0,0,0,2,1
1,1,2,0,0,4,0,0,0,4,0,2,1,1
1,1,2,0,0,0,0,0,0,0,0,2,1,1
1,1,1,2,2,0,4,0,0,2,2,1,1,1
1,1,1,1,1,2,2,2,2,1,1,1,1,1
1,1,1,1,1,1,1,1,1,1,1,1,1,1
endlayer

layer
1,1,1,1,1,1,1,1,1,1,1,1,1,1
1,1,1,1,1,2,2,2,2,1,1,1,1,1
1,1,1,2,2,0,0,0,0,2,2,1,1,1
1,1,2,0,0,0,0,0,0,0,0,2,1,1
1,1,2,0,0,0,0,0,0,0,0,2,1,1
1,2,0,0,0,0,9,2,2,0,4,0,2,1
1,2,4,0,0,0,0,0,4,0,0,0,0,0
1,2,0,0,0,0,4,0,0,0,4,0,0,0
1,2,0,0,0,0,0,0,0,0,0,0,2,1
1,1,2,0,0,4,0,0,0,4,0,2,1,1
1,1,2,0,0,0,0,0,0,0,0,2,1,1
1,1,1,2,2,0,4,0,4,2,2,1,1,1
1,1,1,1,1,2,2,2,2,1,1,1,1,1
1,1,1,1,1,1,1,1,1,1,1,1,1,1
endlayer

layer
1,1,1,1,1,1,1,1,1,1,1,1,1,1
1,1,1,1,1,2,2,2,2,1,1,1,1,1
1,1,1,2,2,3,3,3,3,2,2,1,1,1
1,1,2,3,3,3,3,3,3,3,3,2,1,1
1,1,2,3,3,3,3,3,3,3,3,2,1,1
1,2,3,3,3,0,0,0,9,3,3,3,2,1
1,2,3,3,3,0,3,3,3,3,3,3,2,1
1,2,3,3,3,0,3,3,3,3,3,3,2,1
1,2,3,3,3,3,3,3,3,3,3,3,2,1
1,1,2,3,3,3,3,3,3,3,3,2,1,1
1,1,2,3,3,3,3,3,3,3,3,2,1,1
1,1,1,2,2,3,3,3,3,2,2,1,1,1
1,1,1,1,1,2,2,2,2,1,1,1,1,1
1,1,1,1,1,1,1,1,1,1,1,1,1,1
endlayer

layer
1,1,1,1,1,1,1,1,1,1,1,1,1,1
1,1,1,1,1,1,1,1,1,1,1,1,1,1
1,1,1,1,1,2,2,2,2,1,1,1,1,1
1,1,1,2,2,0,0,0,0,2,2,1,1,1
1,1,1,2,0,0,0,0,0,0,2,1,1,1
1,1,2,0,0,0,0,0,0,0,0,2,1,1
1,1,2,0,0,0,0,0,0,0,0,2,1,1
1,1,2,0,0,0,0,0,0,0,0,2,1,1
1,1,2,0,0,0,2,2,9,0,0,2,1,1
1,1,1,2,0,0,0,0,0,0,2,1,1,1
1,1,1,2,2,0,0,0,0,2,2,1,1,1
1,1,1,1,1,2,2,2,2,1,1,1,1,1
1,1,1,1,1,1,1,1,1,1,1,1,1,1
1,1,1,1,1,1,1,1,1,1,1,1,1,1
endlayer

layer
1,1,1,1,1,1,1,1,1,1,1,1,1,1
1,1,1,1,1,1,1,1,1,1,1,1,1,1
1,1,1,1,1,2,2,2,2,1,1,1,1,1
1,1,1,2,2,0,0,0,0,2,2,1,1,1
1,1,1,2,0,0,0,0,0,0,2,1,1,1
1,1,2,0,0,0,0,0,0,0,0,2,1,1
1,1,2,0,0,0,0,0,0,0,0,2,1,1
1,1,2,0,0,2,0,0,0,0,0,2,1,1
1,1,2,0,0,2,9,0,0,0,0,2,1,1
1,1,1,2,0,0,0,0,0,0,2,1,1,1
1,1,1,2,2,0,0,0,0,2,2,1,1,1
1,1,1,1,1,2,2,2,2,1,1,1,1,1
1,1,1,1,1,1,1,1,1,1,1,1,1,1
1,1,1,1,1,1,1,1,1,1,1,1,1,1
endlayer

layer
1,1,1,1,1,1,1,1,1,1,1,1,1,1
1,1,1,1,1,1,1,1,1,1,1,1,1,1
1,1,1,1,1,2,2,2,2,1,1,1,1,1
1,1,1,2,2,0,0,0,0,2,2,1,1,1
1,1,1,2,0,0,0,0,0,0,2,1,1,1
1,1,2,0,0,2,0,0,0,0,0,2,1,1
1,1,2,0,0,2,0,0,0,0,0,2,1,1
1,1,2,0,0,9,0,0,0,0,0,2,1,1
1,1,2,0,0,0,0,0,0,0,0,2,1,1
1,1,1,2,0,0,0,0,0,0,2,1,1,1
1,1,1,2,2,0,0,0,0,2,2,1,1,1
1,1,1,1,1,2,2,2,2,1,1,1,1,1
1,1,1,1,1,1,1,1,1,1,1,1,1,1
1,1,1,1,1,1,1,1,1,1,1,1,1,1
endlayer

layer
1,1,1,1,1,1,1,1,1,1,1,1,1,1
1,1,1,1,1,1,1,1,1,1,1,1,1,1
1,1,1,1,1,2,2,2,2,1,1,1,1,1
1,1,1,2,2,3,3,3,3,2,2,1,1,1
1,1,1,2,3,3,3,3,3,3,2,1,1,1
1,1,2,3,3,9,3,3,3,3,3,2,1,1
1,1,2,3,3,0,3,3,3,3,3,2,1,1
1,1,2,3,3,0,3,3,3,3,3,2,1,1
1,1,2,3,3,0,0,0,3,3,3,2,1,1
1,1,1,2,3,3,3,3,3,3,2,1,1,1
1,1,1,2,2,3,3,3,3,2,2,1,1,1
1,1,1,1,1,2,2,2,2,1,1,1,1,1
1,1,1,1,1,1,1,1,1,1,1,1,1,1
1,1,1,1,1,1,1,1,1,1,1,1,1,1
endlayer

layer
1,1,1,1,1,1,1,1,1,1,1,1,1,1
1,1,1,1,1,1,1,1,1,1,1,1,1,1
1,1,1,1,1,1,1,1,1,1,1,1,1,1
1,1,1,1,1,2,2,2,2,1,1,1,1,1
1,1,1,1,2,0,0,0,0,2,1,1,1,1
1,1,1,2,0,0,0,0,9,0,2,1,1,1
1,1,1,2,0,0,0,0,2,0,2,1,1,1
1,1,1,2,0,0,0,0,2,0,2,1,1,1
1,1,1,2,0,0,0,0,0,0,2,1,1,1
1,1,1,1,2,0,0,0,0,2,1,1,1,1
1,1,1,1,1,2,2,2,2,1,1,1,1,1
1,1,1,1,1,1,1,1,1,1,1,1,1,1
1,1,1,1,1,1,1,1,1,1,1,1,1,1
1,1,1,1,1,1,1,1,1,1,1,1,1,1
endlayer

layer
1,1,1,1,1,1,1,1,1,1,1,1,1,1
1,1,1,1,1,1,1,1,1,1,1,1,1,1
1,1,1,1,1,1,1,1,1,1,1,1,1,1
1,1,1,1,1,2,2,2,2,1,1,1,1,1
1,1,1,1,2,0,0,0,0,2,1,1,1,1
1,1,1,2,0,0,0,0,0,0,2,1,1,1
1,1,1,2,0,0,0,0,0,0,2,1,1,1
1,1,1,2,0,0,0,0,9,0,2,1,1,1
1,1,1,2,0,0,0,2,2,0,2,1,1,1
1,1,1,1,2,0,0,0,0,2,1,1,1,1
1,1,1,1,1,2,2,2,2,1,1,1,1,1
1,1,1,1,1,1,1,1,1,1,1,1,1,1
1,1,1,1,1,1,1,1,1,1,1,1,1,1
1,1,1,1,1,1,1,1,1,1,1,1,1,1
endlayer

layer
1,1,1,1,1,1,1,1,1,1,1,1,1,1
1,1,1,1,1,1,1,1,1,1,1,1,1,1
1,1,1,1,1,1,1,1,1,1,1,1,1,1
1,1,1,1,1,2,2,2,2,1,1,1,1,1
1,1,1,1,2,0,0,0,0,2,1,1,1,1
1,1,1,2,0,0,0,0,0,0,2,1,1,1
1,1,1,2,0,0,0,0,0,0,2,1,1,1
1,1,1,2,0,0,0,0,0,0,2,1,1,1
1,1,1,2,0,2,2,9,0,0,2,1,1,1
1,1,1,1,2,0,0,0,0,2,1,1,1,1
1,1,1,1,1,2,2,2,2,1,1,1,1,1
1,1,1,1,1,1,1,1,1,1,1,1,1,1
1,1,1,1,1,1,1,1,1,1,1,1,1,1
1,1,1,1,1,1,1,1,1,1,1,1,1,1
endlayer

layer
1,1,1,1,1,1,1,1,1,1,1,1,1,1
1,1,1,1,1,1,1,1,1,1,1,1,1,1
1,1,1,1,1,1,1,1,1,1,1,1,1,1
1,1,1,1,1,2,2,2,2,1,1,1,1,1
1,1,1,1,2,3,3,3,3,2,1,1,1,1
1,1,1,2,3,3,3,3,3,3,2,1,1,1
1,1,1,2,3,3,3,3,0,3,2,1,1,1
1,1,1,2,3,3,3,3,0,3,2,1,1,1
1,1,1,2,3,9,0,0,0,3,2,1,1,1
1,1,1,1,2,3,3,3,3,2,1,1,1,1
1,1,1,1,1,2,2,2,2,1,1,1,1,1
1,1,1,1,1,1,1,1,1,1,1,1,1,1
1,1,1,1,1,1,1,1,1,1,1,1,1,1
1,1,1,1,1,1,1,1,1,1,1,1,1,1
endlayer

layer
1,1,1,1,1,1,1,1,1,1,1,1,1,1
1,1,1,1,1,1,1,1,1,1,1,1,1,1
1,1,1,1,1,1,1,1,1,1,1,1,1,1
1,1,1,1,1,1,1,1,1,1,1,1,1,1
1,1,1,1,1,2,2,2,2,1,1,1,1,1
1,1,1,1,2,9,2,2,0,2,1,1,1,1
1,1,1,1,2,0,0,0,0,2,1,1,1,1
1,1,1,1,2,0,0,0,0,2,1,1,1,1
1,1,1,1,2,0,0,0,0,2,1,1,1,1
1,1,1,1,1,2,2,2,2,1,1,1,1,1
1,1,1,1,1,1,1,1,1,1,1,1,1,1
1,1,1,1,1,1,1,1,1,1,1,1,1,1
1,1,1,1,1,1,1,1,1,1,1,1,1,1
1,1,1,1,1,1,1,1,1,1,1,1,1,1
endlayer

layer
1,1,1,1,1,1,1,1,1,1,1,1,1,1
1,1,1,1,1,1,1,1,1,1,1,1,1,1
1,1,1,1,1,1,1,1,1,1,1,1,1,1
1,1,1,1,1,1,1,1,1,1,1,1,1,1
1,1,1,1,1,2,2,2,2,1,1,1,1,1
1,1,1,1,2,0,0,9,2,2,1,1,1,1
1,1,1,1,2,0,0,0,2,2,1,1,1,1
1,1,1,1,2,0,0,0,0,2,1,1,1,1
1,1,1,1,2,0,0,0,0,2,1,1,1,1
1,1,1,1,1,2,2,2,2,1,1,1,1,1
1,1,1,1,1,1,1,1,1,1,1,1,1,1
1,1,1,1,1,1,1,1,1,1,1,1,1,1
1,1,1,1,1,1,1,1,1,1,1,1,1,1
1,1,1,1,1,1,1,1,1,1,1,1,1,1
endlayer

layer
1,1,1,1,1,1,1,1,1,1,1,1,1,1
1,1,1,1,1,1,1,1,1,1,1,1,1,1
1,1,1,1,1,1,1,1,1,1,1,1,1,1
1,1,1,1,1,1,1,1,1,1,1,1,1,1
1,1,1,1,1,2,2,2,2,1,1,1,1,1
1,1,1,1,2,0,0,0,0,2,1,1,1,1
1,1,1,1,2,0,0,0,9,2,1,1,1,1
1,1,1,1,2,0,0,0,2,2,1,1,1,1
1,1,1,1,2,0,0,0,2,2,1,1,1,1
1,1,1,1,1,2,2,2,2,1,1,1,1,1
1,1,1,1,1,1,1,1,1,1,1,1,1,1
1,1,1,1,1,1,1,1,1,1,1,1,1,1
1,1,1,1,1,1,1,1,1,1,1,1,1,1
1,1,1,1,1,1,1,1,1,1,1,1,1,1
endlayer

layer
1,1,1,1,1,1,1,1,1,1,1,1,1,1
1,1,1,1,1,1,1,1,1,1,1,1,1,1
1,1,1,1,1,1,1,1,1,1,1,1,1,1
1,1,1,1,1,2,1,1,2,1,1,1,1,1
1,1,1,1,1,2,2,2,2,1,1,1,1,1
1,1,1,2,2,3,0,0,0,2,2,1,1,1
1,1,1,1,2,3,3,3,0,2,1,1,1,1
1,1,1,1,2,3,3,3,0,2,1,1,1,1
1,1,1,2,2,3,3,3,9,2,2,1,1,1
1,1,1,1,1,2,2,2,2,1,1,1,1,1
1,1,1,1,1,2,1,1,2,1,1,1,1,1
1,1,1,1,1,1,1,1,1,1,1,1,1,1
1,1,1,1,1,1,1,1,1,1,1,1,1,1
1,1,1,1,1,1,1,1,1,1,1,1,1,1
endlayer

layer
1,1,1,1,1,0,0,0,0,1,1,1,1,1
1,1,1,1,0,0,0,0,0,0,1,1,1,1
1,1,1,0,0,0,0,0,0,0,0,1,1,1
1,1,0,0,0,2,2,2,2,0,0,0,1,1
1,0,0,0,2,0,0,0,0,2,0,0,0,1
0,0,0,2,0,0,0,0,0,0,2,0,0,0
0,0,0,2,12,0,0,0,0,0,2,0,0,0
0,0,0,2,12,0,0,0,0,0,2,0,0,0
0,0,0,2,0,0,0,0,0,0,2,0,0,0
1,0,0,0,2,0,0,0,0,2,0,0,0,1
1,1,0,0,0,2,2,2,2,0,0,0,1,1
1,1,1,0,0,0,0,0,0,0,0,1,1,1
1,1,1,1,0,0,0,0,0,0,1,1,1,1
1,1,1,1,1,0,0,0,0,1,1,1,1,1
endlayer

layer
1,1,1,1,0,0,0,0,0,0,1,1,1,1
1,1,1,0,0,0,0,0,0,0,0,1,1,1
1,1,0,0,0,0,0,0,0,0,0,0,1,1
1,0,0,0,0,2,0,0,2,0,0,0,0,1
0,0,0,0,0,0,0,0,0,0,0,0,0,0
0,0,0,2,0,0,0,0,0,0,2,0,0,0
0,0,0,0,0,0,0,0,0,0,0,0,0,0
0,0,0,0,0,0,0,0,0,0,0,0,0,0
0,0,0,2,0,0,0,0,0,0,2,0,0,0
0,0,0,0,0,0,0,0,0,0,0,0,0,0
1,0,0,0,0,2,0,0,2,0,0,0,0,1
1,1,0,0,0,0,0,0,0,0,0,0,1,1
1,1,1,0,0,0,0,0,0,0,0,1,1,1
1,1,1,1,0,0,0,0,0,0,1,1,1,1
endlayer

layer
1,1,1,1,0,0,0,0,0,0,1,1,1,1
1,1,1,0,0,0,0,0,0,0,0,1,1,1
1,1,0,0,0,0,0,0,0,0,0,0,1,1
1,0,0,0,0,2,0,0,2,0,0,0,0,1
0,0,0,0,0,0,0,0,0,0,0,0,0,0
0,0,0,2,0,0,0,0,0,0,2,0,0,0
0,0,0,0,0,0,0,0,0,0,0,0,0,0
0,0,0,0,0,0,0,0,0,0,0,0,0,0
0,0,0,2,0,0,0,0,0,0,2,0,0,0
0,0,0,0,0,0,0,0,0,0,0,0,0,0
1,0,0,0,0,2,0,0,2,0,0,0,0,1
1,1,0,0,0,0,0,0,0,0,0,0,1,1
1,1,1,0,0,0,0,0,0,0,0,1,1,1
1,1,1,1,0,0,0,0,0,0,1,1,1,1
endlayer

