# Cave_WaterHollow -- underground lava-filled cave room
# 27 Sep 2014 -- Minecraft 1.7.10
# Updated for MC 1.8: 21 Jul 2015
# Created by Ruins mod version 13.8 Ingame Parser
# authoring Player: Jordan_Greywolf
# Last Upated 26 Feb 2016
# Verified for MC 1.12: 23 Jun 2017
# Updated for MC 1.12.1: 9 Sep 2017
# Last Updated: 8 Dec 2018

biomeTypesToSpawnIn=FOREST,MOUNTAIN,HILLS,SAVANNA,JUNGLE,-NETHER


weight=1
embed_into_distance=25

unacceptable_target_blocks=flowing_lava,lava,Natura:Cloud,slime_congealed,slime_dirt,slime_grass,command_block,planks,planks2,concrete,cobblestone,stonebrick,brick_block,glass,torch,oak_stairs,stone_stairs,brick_stairs,stone_brick_stairs,nether_brick_stairs,sandstone_stairs,spruce_stairs,birch_stairs,jungle_stairs,quartz_stairs,acacia_stairs,dark_oak_stairs,cobblestone_wall,stone_slab,double_stone_slab,stone_slab2,wooden_slab,double_wooden_slab,nether_brick

dimensions=17,16,16
allowable_overhang=200
max_leveling=12
leveling_buffer=-1
preserve_water=1
preserve_lava=1
preserve_plants=1

# Terrain preservation
rule1=0,100,preserveBlock

# Shell
rule2=0,100,minecraft:stone-0

# pool rim
rule3=0,100,minecraft:grass-0

# water
rule4=0,100,minecraft:flowing_water

# glowstone
rule5=0,100,minecraft:glowstone

# flowers
rule6=0,100,minecraft:tallgrass-2,minecraft:yellow_flower,minecraft:red_flower-3,minecraft:red_flower-8

layer
1,1,1,1,1,1,1,1,1,1,1,1,1,1,1,1
1,1,1,1,1,1,1,1,1,1,1,1,1,1,1,1
1,1,1,1,1,1,1,1,1,1,1,1,1,1,1,1
1,1,1,1,1,1,1,1,1,1,1,1,1,1,1,1
1,1,1,1,1,1,1,1,1,1,1,1,1,1,1,1
1,1,1,1,1,1,1,1,1,1,1,1,1,1,1,1
1,1,1,1,1,1,1,1,1,1,1,1,1,1,1,1
1,1,1,1,1,1,1,2,2,1,1,1,1,1,1,1
1,1,1,1,1,1,1,2,2,1,1,1,1,1,1,1
1,1,1,1,1,1,1,1,1,1,1,1,1,1,1,1
1,1,1,1,1,1,1,1,1,1,1,1,1,1,1,1
1,1,1,1,1,1,1,1,1,1,1,1,1,1,1,1
1,1,1,1,1,1,1,1,1,1,1,1,1,1,1,1
1,1,1,1,1,1,1,1,1,1,1,1,1,1,1,1
1,1,1,1,1,1,1,1,1,1,1,1,1,1,1,1
1,1,1,1,1,1,1,1,1,1,1,1,1,1,1,1
endlayer

layer
1,1,1,1,1,1,1,1,1,1,1,1,1,1,1,1
1,1,1,1,1,1,1,1,1,1,1,1,1,1,1,1
1,1,1,1,1,1,1,1,1,1,1,1,1,1,1,1
1,1,1,1,1,1,1,1,1,1,1,1,1,1,1,1
1,1,1,1,1,1,1,1,1,1,1,1,1,1,1,1
1,1,1,1,1,1,1,2,2,1,1,1,1,1,1,1
1,1,1,1,1,1,2,2,2,2,1,1,1,1,1,1
1,1,1,1,1,2,2,4,4,2,2,1,1,1,1,1
1,1,1,1,1,2,2,4,4,2,2,1,1,1,1,1
1,1,1,1,1,1,2,2,2,2,1,1,1,1,1,1
1,1,1,1,1,1,1,2,2,1,1,1,1,1,1,1
1,1,1,1,1,1,1,1,1,1,1,1,1,1,1,1
1,1,1,1,1,1,1,1,1,1,1,1,1,1,1,1
1,1,1,1,1,1,1,1,1,1,1,1,1,1,1,1
1,1,1,1,1,1,1,1,1,1,1,1,1,1,1,1
1,1,1,1,1,1,1,1,1,1,1,1,1,1,1,1
endlayer

layer
1,1,1,1,1,1,1,1,1,1,1,1,1,1,1,1
1,1,1,1,1,1,1,1,1,1,1,1,1,1,1,1
1,1,1,1,1,1,1,1,1,1,1,1,1,1,1,1
1,1,1,1,1,1,1,1,1,1,1,1,1,1,1,1
1,1,1,1,1,1,1,2,2,1,1,1,1,1,1,1
1,1,1,1,1,1,2,2,2,2,1,1,1,1,1,1
1,1,1,1,1,2,2,2,2,2,2,1,1,1,1,1
1,1,1,1,2,2,2,4,4,2,2,2,1,1,1,1
1,1,1,1,2,2,2,4,4,2,2,2,1,1,1,1
1,1,1,1,1,2,2,2,2,2,2,1,1,1,1,1
1,1,1,1,1,1,2,2,2,2,1,1,1,1,1,1
1,1,1,1,1,1,1,2,2,1,1,1,1,1,1,1
1,1,1,1,1,1,1,1,1,1,1,1,1,1,1,1
1,1,1,1,1,1,1,1,1,1,1,1,1,1,1,1
1,1,1,1,1,1,1,1,1,1,1,1,1,1,1,1
1,1,1,1,1,1,1,1,1,1,1,1,1,1,1,1
endlayer


layer
1,1,1,1,1,1,1,1,1,1,1,1,1,1,1,1
1,1,1,1,1,1,1,1,1,1,1,1,1,1,1,1
1,1,1,1,1,1,1,1,1,1,1,1,1,1,1,1
1,1,1,1,1,1,1,2,2,1,1,1,1,1,1,1
1,1,1,1,1,1,2,2,2,2,1,1,1,1,1,1
1,1,1,1,1,2,2,2,2,2,2,1,1,1,1,1
1,1,1,1,2,2,2,2,2,2,2,2,1,1,1,1
1,1,1,2,2,2,2,4,4,2,2,2,2,1,1,1
1,1,1,2,2,2,2,4,4,2,2,2,2,1,1,1
1,1,1,1,2,2,2,2,2,2,2,2,1,1,1,1
1,1,1,1,1,2,2,2,2,2,2,1,1,1,1,1
1,1,1,1,1,1,2,2,2,2,1,1,1,1,1,1
1,1,1,1,1,1,1,2,2,1,1,1,1,1,1,1
1,1,1,1,1,1,1,1,1,1,1,1,1,1,1,1
1,1,1,1,1,1,1,1,1,1,1,1,1,1,1,1
1,1,1,1,1,1,1,1,1,1,1,1,1,1,1,1
endlayer

layer
1,1,1,1,1,1,1,1,1,1,1,1,1,1,1,1
1,1,1,1,1,1,1,1,1,1,1,1,1,1,1,1
1,1,1,1,1,1,1,2,2,1,1,1,1,1,1,1
1,1,1,1,1,2,2,2,2,2,2,1,1,1,1,1
1,1,1,1,2,2,2,2,2,2,2,2,1,1,1,1
1,1,1,2,2,2,2,2,2,2,2,2,2,1,1,1
1,1,1,2,2,2,2,2,2,2,2,2,2,1,1,1
1,1,2,2,2,2,2,4,4,2,2,2,2,2,1,1
1,1,2,2,2,2,2,4,4,2,2,2,2,2,1,1
1,1,1,2,2,2,2,2,2,2,2,2,2,1,1,1
1,1,1,2,2,2,2,2,2,2,2,2,2,1,1,1
1,1,1,1,2,2,2,2,2,2,2,2,1,1,1,1
1,1,1,1,1,2,2,2,2,2,2,1,1,1,1,1
1,1,1,1,1,1,1,2,2,1,1,1,1,1,1,1
1,1,1,1,1,1,1,1,1,1,1,1,1,1,1,1
1,1,1,1,1,1,1,1,1,1,1,1,1,1,1,1
endlayer

layer
1,1,1,1,1,1,1,1,1,1,1,1,1,1,1,1
1,1,1,1,1,1,2,2,2,2,1,1,1,1,1,1
1,1,1,1,1,2,2,2,2,2,2,1,1,1,1,1
1,1,1,1,2,2,2,2,2,2,2,2,1,1,1,1
1,1,1,2,2,2,2,2,2,2,2,2,2,1,1,1
1,1,2,2,2,2,2,2,2,2,2,2,2,2,1,1
1,2,2,2,2,2,2,2,2,2,2,2,2,2,2,1
1,2,2,2,2,2,2,4,4,2,2,2,2,2,2,1
1,2,2,2,2,2,2,4,4,2,2,2,2,2,2,1
1,2,2,2,2,2,2,2,2,2,2,2,2,2,2,1
1,1,2,2,2,2,2,2,2,2,2,2,2,2,1,1
1,1,1,2,2,2,2,2,2,2,2,2,2,1,1,1
1,1,1,1,2,2,2,2,2,2,2,2,1,1,1,1
1,1,1,1,1,2,2,2,2,2,2,1,1,1,1,1
1,1,1,1,1,1,2,2,2,2,1,1,1,1,1,1
1,1,1,1,1,1,1,1,1,1,1,1,1,1,1,1
endlayer



layer
1,1,1,1,1,1,2,2,2,2,1,1,1,1,1,1
1,1,1,1,2,2,2,2,2,2,2,2,1,1,1,1
1,1,1,2,2,2,2,2,2,2,2,2,2,1,1,1
1,1,2,2,2,2,2,2,2,2,2,2,2,2,1,1
1,2,2,2,2,2,2,2,2,2,2,2,2,2,2,1
1,2,2,2,2,2,2,2,2,2,2,2,2,2,2,1
2,2,2,2,2,2,2,4,4,2,2,2,2,2,2,2
2,2,2,2,2,2,4,4,4,4,2,2,2,2,2,2
2,2,2,2,2,2,4,4,4,4,2,2,2,2,2,2
2,2,2,2,2,2,2,4,4,2,2,2,2,2,2,2
1,2,2,2,2,2,2,2,2,2,2,2,2,2,2,1
1,2,2,2,2,2,2,2,2,2,2,2,2,2,2,1
1,1,2,2,2,2,2,2,2,2,2,2,2,2,1,1
1,1,1,2,2,2,2,2,2,2,2,2,2,1,1,1
1,1,1,1,2,2,2,2,2,2,2,2,1,1,1,1
1,1,1,1,1,1,2,2,2,2,1,1,1,1,1,1
endlayer

layer
1,1,1,1,1,1,2,2,2,2,1,1,1,1,1,1
1,1,1,1,2,2,3,3,3,3,2,2,1,1,1,1
1,1,1,2,3,3,4,4,4,4,3,3,2,1,1,1
1,1,2,3,4,4,4,4,4,4,4,4,3,2,1,1
1,2,3,4,4,4,4,4,4,4,4,4,4,3,2,1
1,2,3,4,4,4,4,4,4,4,4,4,4,3,2,1
2,3,4,4,4,4,4,4,4,4,4,4,4,4,3,2
2,3,4,4,4,4,4,4,4,4,4,4,4,4,3,2
2,3,4,4,4,4,4,4,4,4,4,4,4,4,3,2
2,3,4,4,4,4,4,4,4,4,4,4,4,4,3,2
1,2,3,4,4,4,4,4,4,4,4,4,4,3,2,1
1,2,3,4,4,4,4,4,4,4,4,4,4,3,2,1
1,1,2,3,4,4,4,4,4,4,4,4,3,2,1,1
1,1,1,2,3,3,4,4,4,4,3,3,2,1,1,1
1,1,1,1,2,2,3,3,3,3,2,2,1,1,1,1
1,1,1,1,1,1,2,2,2,2,1,1,1,1,1,1
endlayer

layer
1,1,1,1,1,1,2,2,2,2,1,1,1,1,1,1
1,1,1,1,2,2,6,5,5,6,2,2,1,1,1,1
1,1,1,2,6,6,0,0,0,0,6,6,2,1,1,1
1,1,2,6,0,0,0,0,0,0,0,0,6,2,1,1
1,2,6,0,0,0,0,0,0,0,0,0,0,6,2,1
1,2,6,0,0,4,0,0,0,0,4,0,0,6,2,1
2,6,0,0,0,0,0,0,0,0,0,0,0,0,6,2
2,5,0,0,0,0,0,4,4,0,0,0,0,0,5,2
2,5,0,0,0,0,0,4,4,0,0,0,0,0,5,2
2,6,0,0,0,0,0,0,0,0,0,0,0,0,6,2
1,2,6,0,0,4,0,0,0,0,4,0,0,6,2,1
1,2,6,0,0,0,0,0,0,0,0,0,0,6,2,1
1,1,2,6,0,0,0,0,0,0,0,0,6,2,1,1
1,1,1,2,6,6,0,0,0,0,6,6,2,1,1,1
1,1,1,1,2,2,6,5,5,6,2,2,1,1,1,1
1,1,1,1,1,1,2,2,2,2,1,1,1,1,1,1
endlayer

layer
1,1,1,1,1,1,2,2,2,2,1,1,1,1,1,1
1,1,1,1,2,2,0,2,2,0,2,2,1,1,1,1
1,1,1,2,0,0,0,2,2,0,0,0,2,1,1,1
1,1,2,0,0,0,0,2,2,0,0,0,0,2,1,1
1,2,0,0,0,0,0,2,2,0,0,0,0,0,2,1
1,2,0,0,0,0,0,2,2,0,0,0,0,0,2,1
2,0,0,0,0,0,2,2,2,2,0,0,0,0,0,2
2,2,2,2,2,2,2,0,0,2,2,2,2,2,2,2
2,2,2,2,2,2,2,0,0,2,2,2,2,2,2,2
2,0,0,0,0,0,2,2,2,2,0,0,0,0,0,2
1,2,0,0,0,0,0,2,2,0,0,0,0,0,2,1
1,2,0,0,0,0,0,2,2,0,0,0,0,0,2,1
1,1,2,0,0,0,0,2,2,0,0,0,0,2,1,1
1,1,1,2,0,0,0,2,2,0,0,0,2,1,1,1
1,1,1,1,2,2,0,2,2,0,2,2,1,1,1,1
1,1,1,1,1,1,2,2,2,2,1,1,1,1,1,1
endlayer

layer
1,1,1,1,1,1,2,0,0,2,1,1,1,1,1,1
1,1,1,1,2,2,2,0,0,2,2,2,1,1,1,1
1,1,1,2,2,2,0,0,0,0,2,2,2,1,1,1
1,1,2,2,0,0,0,0,0,0,0,0,2,2,1,1
1,2,2,0,0,0,0,0,0,0,0,0,0,2,2,1
1,2,2,0,0,0,0,0,0,0,0,0,0,2,2,1
2,2,0,0,0,0,0,0,0,0,0,0,0,0,2,2
0,0,0,0,0,0,0,0,0,0,0,0,0,0,0,0
0,0,0,0,0,0,0,0,0,0,0,0,0,0,0,0
2,2,0,0,0,0,0,0,0,0,0,0,0,0,2,2
1,2,2,0,0,0,0,0,0,0,0,0,0,2,2,1
1,2,2,0,0,0,0,0,0,0,0,0,0,2,2,1
1,1,2,2,0,0,0,0,0,0,0,0,2,2,1,1
1,1,1,2,2,2,0,0,0,0,2,2,2,1,1,1
1,1,1,1,2,2,2,0,0,2,2,2,1,1,1,1
1,1,1,1,1,1,2,0,0,2,1,1,1,1,1,1
endlayer

layer
1,1,1,1,1,1,2,0,0,2,1,1,1,1,1,1
1,1,1,1,1,2,2,0,0,2,2,1,1,1,1,1
1,1,1,1,2,2,0,0,0,0,2,2,1,1,1,1
1,1,1,2,0,0,0,0,0,0,0,0,2,1,1,1
1,1,2,0,0,0,0,0,0,0,0,0,0,2,1,1
1,2,2,0,0,0,0,0,0,0,0,0,0,2,2,1
2,2,0,0,0,0,0,0,0,0,0,0,0,0,2,2
0,0,0,0,0,0,0,0,0,0,0,0,0,0,0,0
0,0,0,0,0,0,0,0,0,0,0,0,0,0,0,0
2,2,0,0,0,0,0,0,0,0,0,0,0,0,2,2
1,2,2,0,0,0,0,0,0,0,0,0,0,2,2,1
1,1,2,0,0,0,0,0,0,0,0,0,0,2,1,1
1,1,1,2,0,0,0,0,0,0,0,0,2,1,1,1
1,1,1,1,2,2,0,0,0,0,2,2,1,1,1,1
1,1,1,1,1,2,2,0,0,2,2,1,1,1,1,1
1,1,1,1,1,1,2,0,0,2,1,1,1,1,1,1
endlayer

layer
1,1,1,1,1,1,1,2,2,1,1,1,1,1,1,1
1,1,1,1,1,1,2,2,2,2,1,1,1,1,1,1
1,1,1,1,2,2,2,0,0,2,2,2,1,1,1,1
1,1,1,1,2,0,0,0,0,0,0,2,1,1,1,1
1,1,2,2,0,0,0,0,0,0,0,0,2,2,1,1
1,1,2,0,0,0,0,0,0,0,0,0,0,2,1,1
1,2,2,0,0,0,0,0,0,0,0,0,0,2,2,1
2,2,0,0,0,0,0,0,0,0,0,0,0,0,2,2
2,2,0,0,0,0,0,0,0,0,0,0,0,0,2,2
1,2,2,0,0,0,0,0,0,0,0,0,0,2,2,1
1,1,2,0,0,0,0,0,0,0,0,0,0,2,1,1
1,1,2,2,0,0,0,0,0,0,0,0,2,2,1,1
1,1,1,1,2,0,0,0,0,0,0,2,1,1,1,1
1,1,1,1,2,2,2,0,0,2,2,2,1,1,1,1
1,1,1,1,1,1,2,2,2,2,1,1,1,1,1,1
1,1,1,1,1,1,1,2,2,1,1,1,1,1,1,1
endlayer

layer
1,1,1,1,1,1,1,1,1,1,1,1,1,1,1,1
1,1,1,1,1,1,1,1,1,1,1,1,1,1,1,1
1,1,1,1,1,2,2,2,2,2,2,1,1,1,1,1
1,1,1,1,2,2,2,0,0,2,2,2,1,1,1,1
1,1,1,2,2,2,0,0,0,0,2,2,2,1,1,1
1,1,2,2,2,0,0,0,0,0,0,2,2,2,1,1
1,1,2,2,0,0,0,0,0,0,0,0,2,2,1,1
1,1,2,0,0,0,0,0,0,0,0,0,0,2,1,1
1,1,2,0,0,0,0,0,0,0,0,0,0,2,1,1
1,1,2,2,0,0,0,0,0,0,0,0,2,2,1,1
1,1,2,2,2,0,0,0,0,0,0,2,2,2,1,1
1,1,1,2,2,2,0,0,0,0,2,2,2,1,1,1
1,1,1,1,2,2,2,0,0,2,2,2,1,1,1,1
1,1,1,1,1,2,2,2,2,2,2,1,1,1,1,1
1,1,1,1,1,1,1,1,1,1,1,1,1,1,1,1
1,1,1,1,1,1,1,1,1,1,1,1,1,1,1,1
endlayer

layer
1,1,1,1,1,1,1,1,1,1,1,1,1,1,1,1
1,1,1,1,1,1,1,1,1,1,1,1,1,1,1,1
1,1,1,1,1,1,1,1,1,1,1,1,1,1,1,1
1,1,1,1,1,1,1,2,2,1,1,1,1,1,1,1
1,1,1,1,1,2,2,2,2,2,2,1,1,1,1,1
1,1,1,1,2,4,2,0,0,2,4,2,1,1,1,1
1,1,1,1,2,2,5,0,0,5,2,2,1,1,1,1
1,1,1,2,2,0,0,0,0,0,0,2,2,1,1,1
1,1,1,2,2,0,0,0,0,0,0,2,2,1,1,1
1,1,1,1,2,2,5,0,0,5,2,2,1,1,1,1
1,1,1,1,2,4,2,0,0,2,4,2,1,1,1,1
1,1,1,1,1,2,2,2,2,2,2,1,1,1,1,1
1,1,1,1,1,1,1,2,2,1,1,1,1,1,1,1
1,1,1,1,1,1,1,1,1,1,1,1,1,1,1,1
1,1,1,1,1,1,1,1,1,1,1,1,1,1,1,1
1,1,1,1,1,1,1,1,1,1,1,1,1,1,1,1
endlayer

layer
1,1,1,1,1,1,1,1,1,1,1,1,1,1,1,1
1,1,1,1,1,1,1,1,1,1,1,1,1,1,1,1
1,1,1,1,1,1,1,1,1,1,1,1,1,1,1,1
1,1,1,1,1,1,1,1,1,1,1,1,1,1,1,1
1,1,1,1,1,1,1,1,1,1,1,1,1,1,1,1
1,1,1,1,1,1,1,2,2,1,1,1,1,1,1,1
1,1,1,1,1,1,2,2,2,2,1,1,1,1,1,1
1,1,1,1,1,2,2,4,4,2,2,1,1,1,1,1
1,1,1,1,1,2,2,4,4,2,2,1,1,1,1,1
1,1,1,1,1,1,2,2,2,2,1,1,1,1,1,1
1,1,1,1,1,1,1,2,2,1,1,1,1,1,1,1
1,1,1,1,1,1,1,1,1,1,1,1,1,1,1,1
1,1,1,1,1,1,1,1,1,1,1,1,1,1,1,1
1,1,1,1,1,1,1,1,1,1,1,1,1,1,1,1
1,1,1,1,1,1,1,1,1,1,1,1,1,1,1,1
1,1,1,1,1,1,1,1,1,1,1,1,1,1,1,1
endlayer

layer
1,1,1,1,1,1,1,1,1,1,1,1,1,1,1,1
1,1,1,1,1,1,1,1,1,1,1,1,1,1,1,1
1,1,1,1,1,1,1,1,1,1,1,1,1,1,1,1
1,1,1,1,1,1,1,1,1,1,1,1,1,1,1,1
1,1,1,1,1,1,1,1,1,1,1,1,1,1,1,1
1,1,1,1,1,1,1,1,1,1,1,1,1,1,1,1
1,1,1,1,1,1,1,1,1,1,1,1,1,1,1,1
1,1,1,1,1,1,1,2,2,1,1,1,1,1,1,1
1,1,1,1,1,1,1,2,2,1,1,1,1,1,1,1
1,1,1,1,1,1,1,1,1,1,1,1,1,1,1,1
1,1,1,1,1,1,1,1,1,1,1,1,1,1,1,1
1,1,1,1,1,1,1,1,1,1,1,1,1,1,1,1
1,1,1,1,1,1,1,1,1,1,1,1,1,1,1,1
1,1,1,1,1,1,1,1,1,1,1,1,1,1,1,1
1,1,1,1,1,1,1,1,1,1,1,1,1,1,1,1
1,1,1,1,1,1,1,1,1,1,1,1,1,1,1,1
endlayer

