# Created by Ruins mod version 17.2 Ingame Parser
# authoring Player: Iron_noob_73

weight=1
unique=1
embed_into_distance=-20
dimensionsToSpawnIn=overworld
unacceptable_target_blocks=flowing_water,water,flowing_lava,lava,bedrock

dimensions=3,10,10
allowable_overhang=0
max_cut_in=2
max_leveling=999
preserve_water=2
preserve_lava=2
preserve_plants=0

random_height_offset=-20,-255
uniqueMinDistance=500

rule1=0,100,soviet:soviet_chair-1
rule2=0,100,soviet:soviettable-0
rule3=0,100,soviet:soviet_chair-3
rule4=0,100,soviet:wood_labshelf_down_break-3
rule5=0,100,soviet:wood_labshelf_down-3
rule6=0,100,soviet:sovietselector-9
rule7=0,100,soviet:sovietlamptrue-15
rule8=0,100,redstonepaste:redstonepaste-0

layer
0,0,0,0,0,0,0,0,0,0
0,0,0,0,0,0,0,0,0,0
0,0,0,0,0,0,0,0,0,0
0,0,0,0,1,0,0,0,0,0
0,0,0,0,2,2,0,0,0,0
0,0,0,0,2,2,0,0,0,0
0,0,0,0,0,3,0,0,0,0
0,0,0,0,0,0,0,0,0,0
0,4,5,5,0,0,4,5,4,0
0,0,0,0,0,0,0,0,0,0
endlayer

layer
0,0,0,0,0,0,0,0,0,0
0,0,0,0,0,0,0,0,0,0
0,0,0,0,0,0,0,0,0,0
0,0,0,0,0,0,0,0,0,0
0,0,0,0,0,0,0,0,0,0
0,0,0,0,0,0,0,0,0,0
0,0,0,0,0,0,0,0,0,0
0,0,0,0,0,0,0,0,0,0
0,0,0,0,0,0,6,0,0,0
0,0,0,0,0,0,0,0,0,0
endlayer

layer
0,0,0,0,0,0,0,0,0,0
0,0,0,0,0,0,0,0,0,0
0,0,7,8,8,8,8,7,0,0
0,0,0,0,0,0,8,0,0,0
0,0,0,0,0,0,8,0,0,0
0,0,0,0,0,0,8,0,0,0
0,0,0,0,0,0,8,0,0,0
0,0,7,8,8,8,8,7,0,0
0,0,0,0,0,0,8,0,0,0
0,0,0,0,0,0,0,0,0,0
endlayer

