# Dock
# Created for MC 1.7.10, 18 Oct 2014
# Created by Ruins mod version 13.8 Ingame Parser
# authoring Player: Jordan_Greywolf
# Last Updated: 29 Oct 2015
# Updated to MC 1.11: 13 Jan 2017
# Verified for MC 1.12: 23 Jun 2017
# Updated to MC 1.12.1: 10 Sep 2017

biomesToSpawnIn=bayou,dead swamp,dead_swamp,dry river,frozenriver,lush swamp,lush_swamp,river,frozen_river

weight=1
embed_into_distance=8

acceptable_target_blocks=water,flowing_water,grass,dirt,gravel,stone,sand,sandstone,lilypad,snow,ice,snow_layer,clay,red_sand,mycelium

dimensions=10,3,11
allowable_overhang=400
max_leveling=0
leveling_buffer=-1
preserve_water=0
preserve_lava=0
preserve_plants=1

rule1=0,100,minecraft:log-0
rule2=0,100,minecraft:wooden_slab-0
rule3=0,100,preserveBlock

layer
3,1,3,3,3,1,3,3,3,1,3
3,3,3,3,3,3,3,3,3,3,3
3,1,3,3,3,1,3,3,3,1,3
endlayer

layer
3,1,3,3,3,1,3,3,3,1,3
3,3,3,3,3,3,3,3,3,3,3
3,1,3,3,3,1,3,3,3,1,3
endlayer

layer
3,1,3,3,3,1,3,3,3,1,3
3,3,3,3,3,3,3,3,3,3,3
3,1,3,3,3,1,3,3,3,1,3
endlayer

layer
3,1,3,3,3,1,3,3,3,1,3
3,3,3,3,3,3,3,3,3,3,3
3,1,3,3,3,1,3,3,3,1,3
endlayer

layer
3,1,3,3,3,1,3,3,3,1,3
3,3,3,3,3,3,3,3,3,3,3
3,1,3,3,3,1,3,3,3,1,3
endlayer

layer
3,1,3,3,3,1,3,3,3,1,3
3,3,3,3,3,3,3,3,3,3,3
3,1,3,3,3,1,3,3,3,1,3
endlayer

layer
3,1,3,3,3,1,3,3,3,1,3
3,3,3,3,3,3,3,3,3,3,3
3,1,3,3,3,1,3,3,3,1,3
endlayer


layer
3,1,3,3,3,1,3,3,3,1,3
3,3,3,3,3,3,3,3,3,3,3
3,1,3,3,3,1,3,3,3,1,3
endlayer

layer
3,1,3,3,3,1,3,3,3,1,3
3,3,3,3,3,3,3,3,3,3,3
3,1,3,3,3,1,3,3,3,1,3
endlayer

layer
2,1,2,2,2,1,2,2,2,1,2
2,2,2,2,2,2,2,2,2,2,2
2,1,2,2,2,1,2,2,2,1,2
endlayer


