# Fisherman's Shack
# MC 1.7.10; 25 Oct 2014
# Created by Ruins mod version 13.8 Ingame Parser
# authoring Player: Jordan_Greywolf
# Updated 10 Jan 2015 (fixing overly generous fish trade)
# Updated 27 Apr 2015 (fine-tuning build criteria)
# Updated 22 Jan 2016
# Updated to MC 1.8: 5 Mar 2016
# Updated to MC 1.11: 13 Jan 2017
# Verified for MC 1.12: 23 Jun 2017
# Updated to MC 1.12.1: 10 Sep 2017

biomesToSpawnIn=river,beach,beaches,stone beach,stone_beach,gravel beach,gravel_beach,forested island,tropical_island,white_beach

uniqueMinDistance=2000

weight=1
embed_into_distance=7

acceptable_target_blocks=water,flowing_water,sand,clay,dirt,sandstone,grass,gravel,stone

dimensions=21,9,11
allowable_overhang=25
max_leveling=5
leveling_buffer=-1
preserve_water=0
preserve_lava=0
preserve_plants=1

rule1=0,100,preserveBlock
rule2=0,100,minecraft:log-0
rule3=0,100,minecraft:wooden_slab-8
rule4=0,100,minecraft:fence-0
rule5=0,100,minecraft:ladder-2
rule6=0,100,IInventory;minecraft:chest;minecraft:string#4#0#0+minecraft:bread#1#0#1+minecraft:log#5#0#2+minecraft:boat#1#0#3-3
# rule6=0,100,minecraft:chest-3
rule7=1,100,minecraft:torch-5
rule8=0,100,minecraft:log-8
rule9=0,100,minecraft:log-4
rule10=0,100,minecraft:planks-0
rule11=1,100,minecraft:wooden_door-1
rule12=1,100,minecraft:wooden_slab-1
rule13=0,100,minecraft:crafting_table-0
rule14=0,100,minecraft:fence_gate-1
rule15=0,100,IInventory;minecraft:lit_furnace;minecraft:coal#2#1#1-5

rule16=0,100,CommandBlock:RUINSTRIGGER /summon Villager ~0 ~0 ~0 {Profession:4,Career:1,CareerLevel:6,CustomName:Fisherman,Offers:{Recipes:[{buy:{id:fish,Count:32},sell:{id:emerald,Count:1}},{buy:{id:emerald,Count:1},sell:{id:fish,Count:6}},{buy:{id:emerald,Count:1},sell:{id:cooked_fish,Count:6}},{buy:{id:dye,Count:64},sell:{id:emerald,Count:1}},{buy:{id:emerald,Count:25},buyB:{id:fishing_rod,Count:1},sell:{id:fishing_rod,Count:1,tag:{ench:[{id:16,lvl:5},{id:19,lvl:5},{id:34,lvl:10},{id:35,lvl:3}],display:{Name:"Rod of the Sea Serpent"}}}},{buy:{id:emerald,Count:64},buyB:{id:fishing_rod,Count:1},sell:{id:fishing_rod,Count:1,tag:{ench:[{id:61,lvl:5},{id:62,lvl:5},{id:34,lvl:10},{id:19,lvl:5}],display:{Name:"Mighty Fishing Rod"}}}},{buy:{id:string,Count:20},sell:{id:emerald,Count:1}}]}}:@

rule17=0,100,minecraft:fence_gate-2
rule18=0,100,minecraft:spruce_stairs-1
rule19=1,100,minecraft:wooden_door-8
rule20=0,100,minecraft:cobblestone_wall-0
rule21=0,100,minecraft:torch-3
rule22=0,100,minecraft:oak_stairs-2
rule23=0,100,minecraft:oak_stairs-7
rule24=0,100,minecraft:oak_stairs-6
rule25=0,100,minecraft:oak_stairs-3
rule26=0,100,minecraft:wooden_slab-0
rule27=0,100,CommandBlock:RUINSTRIGGER /summon boat ~0 ~0 ~0:@
rule28=0,100,minecraft:water-0



layer
1,1,1,1,1,1,1,1,1,1,1
1,2,1,1,1,2,1,1,1,1,2
1,1,1,1,1,1,1,1,1,1,1
1,1,1,1,1,1,1,1,1,1,1
1,2,1,1,1,2,1,1,1,1,2
1,1,1,1,1,1,1,1,1,1,1
1,1,1,1,1,1,1,1,1,1,1
1,2,1,1,1,2,1,1,1,1,1
1,1,1,1,1,1,1,1,1,1,1
endlayer

layer
1,1,1,1,1,1,1,1,1,1,1
1,2,1,1,1,2,1,1,1,1,2
1,1,1,1,1,1,1,1,1,1,1
1,1,1,1,1,1,1,1,1,1,1
1,2,1,1,1,2,1,1,1,1,2
1,1,1,1,1,1,1,1,1,1,1
1,1,1,1,1,1,1,1,1,1,1
1,2,1,1,1,2,1,1,1,1,1
1,1,1,1,1,1,1,1,1,1,1
endlayer


layer
1,1,1,1,1,1,1,1,1,1,1
1,2,1,1,1,2,1,1,1,1,2
1,1,1,1,1,1,1,1,1,1,1
1,1,1,1,1,1,1,1,1,1,1
1,2,1,1,1,2,1,1,1,1,2
1,1,1,1,1,1,1,1,1,1,1
1,1,1,1,1,1,1,1,1,1,1
1,2,1,1,1,2,1,1,1,1,1
1,1,1,1,1,1,1,1,1,1,1
endlayer


layer
1,1,1,1,1,1,1,1,1,1,1
1,2,1,1,1,2,1,1,1,1,2
1,1,1,1,1,1,1,1,1,1,1
1,1,1,1,1,1,1,1,1,1,1
1,2,1,1,1,2,1,1,1,1,2
1,1,1,1,1,1,1,1,1,1,1
1,1,1,1,1,1,1,1,1,1,1
1,2,1,1,1,2,1,1,1,1,1
1,1,1,1,1,1,1,1,1,1,1
endlayer


layer
1,1,1,1,1,1,1,1,1,1,1
1,2,1,1,1,2,1,1,1,1,2
1,1,1,1,1,1,1,1,1,1,1
1,1,1,1,1,1,1,1,1,1,1
1,2,1,1,1,2,1,1,1,1,2
1,1,1,1,1,1,1,1,1,1,1
1,1,1,1,1,1,1,1,1,1,1
1,2,1,1,1,2,1,1,1,1,1
1,1,1,1,1,1,1,1,1,1,1
endlayer


layer
1,1,1,1,1,1,1,1,1,1,1
1,2,1,1,1,2,1,1,1,1,2
1,1,1,1,1,1,1,1,1,1,1
1,1,1,1,1,1,1,1,1,1,1
1,2,1,1,1,2,1,1,1,1,2
1,1,1,1,1,1,1,1,28,1,1
1,1,1,1,1,1,1,1,1,1,1
1,2,1,1,1,2,1,1,1,1,1
1,1,1,1,1,1,1,1,1,1,1
endlayer


layer
1,1,1,1,1,1,1,1,1,1,1
1,2,1,1,1,2,1,1,1,1,2
1,1,1,1,1,1,1,1,1,1,1
1,1,1,1,1,1,1,1,1,1,1
1,2,1,1,1,2,1,1,28,1,2
1,1,1,1,1,1,1,28,28,28,1
1,1,1,1,1,1,1,1,28,1,1
1,2,1,1,1,2,1,1,1,1,1
1,1,1,1,1,1,1,1,1,1,1
endlayer


layer
0,0,0,0,0,0,0,0,0,0,0
0,2,3,3,3,2,3,3,3,3,2
0,3,3,3,3,3,3,3,3,3,3
0,3,3,3,3,3,3,3,3,3,3
0,2,3,3,3,2,3,3,3,3,2
0,3,3,3,3,3,0,0,27,0,0
0,3,3,3,3,3,0,0,0,0,0
0,2,3,3,3,2,0,0,0,0,0
0,0,0,0,0,0,0,0,0,0,0
endlayer

layer
0,0,0,0,0,0,0,0,0,0,0
0,2,4,0,4,2,4,0,0,0,4
0,4,0,0,0,0,0,0,0,0,0
0,4,0,0,0,0,0,0,0,0,0
0,2,0,0,6,2,5,0,0,0,4
0,4,0,0,0,4,0,0,0,0,0
0,4,0,0,0,4,0,0,0,0,0
0,2,4,0,4,2,0,0,0,0,0
0,0,0,0,0,0,0,0,0,0,0
endlayer

layer
0,0,0,0,0,0,0,0,0,0,0
0,2,7,0,7,2,7,0,0,0,7
0,0,0,0,0,0,0,0,0,0,0
0,0,0,0,0,0,0,0,0,0,0
0,2,0,0,0,2,5,0,0,0,7
0,0,0,0,0,0,0,0,0,0,0
0,0,0,0,0,0,0,0,0,0,0
0,2,7,0,7,2,0,0,0,0,0
0,0,0,0,0,0,0,0,0,0,0
endlayer

layer
0,0,0,0,0,0,0,0,0,0,0
0,2,0,0,0,2,0,0,0,0,0
0,0,0,0,0,0,0,0,0,0,0
0,0,0,0,0,0,0,0,0,0,0
0,2,0,0,0,2,5,0,0,0,0
0,0,0,0,0,0,0,0,0,0,0
0,0,0,0,0,0,0,0,0,0,0
0,2,0,0,0,2,0,0,0,0,0
0,0,0,0,0,0,0,0,0,0,0
endlayer

layer
0,0,0,0,0,0,0,0,0,0,0
0,2,8,8,8,2,8,8,0,0,0
0,9,10,10,10,9,3,3,0,0,0
0,9,10,10,10,9,3,3,0,0,0
0,2,10,10,10,2,5,3,0,0,0
0,9,10,10,10,9,3,3,0,0,0
0,9,10,10,10,9,3,3,0,0,0
0,2,8,8,8,2,8,8,0,0,0
0,0,0,0,0,0,0,0,0,0,0
endlayer

layer
0,0,0,0,0,0,0,0,0,0,0
0,2,10,10,10,2,4,4,0,0,0
0,10,12,0,0,11,0,4,0,0,0
0,10,12,0,0,10,0,4,0,0,0
0,2,15,14,13,2,0,4,0,0,0
0,4,0,0,16,10,0,4,0,0,0
0,4,18,0,0,17,0,4,0,0,0
0,2,4,4,4,2,4,4,0,0,0
0,0,0,0,0,0,0,0,0,0,0
endlayer

layer
0,0,0,0,0,0,0,0,0,0,0
0,2,10,4,10,2,0,7,0,0,0
0,4,0,0,0,19,0,0,0,0,0
0,10,5,0,0,10,0,0,0,0,0
0,2,20,0,7,2,0,0,0,0,0
0,0,0,0,21,10,0,0,0,0,0
0,0,0,0,0,0,0,0,0,0,0
0,2,7,0,7,2,0,7,0,0,0
0,0,0,0,0,0,0,0,0,0,0
endlayer

layer
25,24,0,0,0,23,22,0,0,0,0
25,2,8,8,8,2,22,0,0,0,0
25,9,4,0,4,9,22,0,0,0,0
25,9,5,0,4,9,22,0,0,0,0
20,2,10,10,10,2,22,0,0,0,0
25,9,0,0,0,9,22,0,0,0,0
25,9,0,0,0,9,22,0,0,0,0
25,2,8,8,8,2,22,0,0,0,0
25,24,0,0,0,23,22,0,0,0,0
endlayer

layer
0,26,26,26,26,26,0,0,0,0,0
0,26,2,4,2,26,0,0,0,0,0
0,26,4,0,4,26,0,0,0,0,0
0,26,0,0,4,26,0,0,0,0,0
20,26,2,4,2,26,0,0,0,0,0
0,26,26,26,26,26,0,0,0,0,0
0,26,26,26,26,26,0,0,0,0,0
0,26,26,26,26,26,0,0,0,0,0
0,26,26,26,26,26,0,0,0,0,0
endlayer

layer
0,0,0,0,0,0,0,0,0,0,0
0,0,2,4,2,0,0,0,0,0,0
0,0,4,0,4,0,0,0,0,0,0
0,0,0,0,4,0,0,0,0,0,0
20,0,2,4,2,0,0,0,0,0,0
0,0,0,0,0,0,0,0,0,0,0
0,0,0,0,0,0,0,0,0,0,0
0,0,0,0,0,0,0,0,0,0,0
0,0,0,0,0,0,0,0,0,0,0
endlayer

layer
0,0,0,0,0,0,0,0,0,0,0
0,0,2,8,2,0,0,0,0,0,0
0,0,4,0,4,0,0,0,0,0,0
0,0,0,0,4,0,0,0,0,0,0
20,0,2,8,2,0,0,0,0,0,0
0,0,0,0,0,0,0,0,0,0,0
0,0,0,0,0,0,0,0,0,0,0
0,0,0,0,0,0,0,0,0,0,0
0,0,0,0,0,0,0,0,0,0,0
endlayer

layer
0,0,0,0,0,0,0,0,0,0,0
0,0,25,10,22,0,0,0,0,0,0
0,0,25,10,22,0,0,0,0,0,0
0,0,25,10,22,0,0,0,0,0,0
0,0,25,10,22,0,0,0,0,0,0
0,0,0,0,0,0,0,0,0,0,0
0,0,0,0,0,0,0,0,0,0,0
0,0,0,0,0,0,0,0,0,0,0
0,0,0,0,0,0,0,0,0,0,0
endlayer

layer
0,0,0,0,0,0,0,0,0,0,0
0,0,0,26,0,0,0,0,0,0,0
0,0,0,26,0,0,0,0,0,0,0
0,0,0,26,0,0,0,0,0,0,0
0,0,0,26,0,0,0,0,0,0,0
0,0,0,0,0,0,0,0,0,0,0
0,0,0,0,0,0,0,0,0,0,0
0,0,0,0,0,0,0,0,0,0,0
0,0,0,0,0,0,0,0,0,0,0
endlayer

