# Millhouse_Large_1v7v10 (1.7.2 version 25 May 2014)
# Revised for 1.7.10 - 7 Oct 2014; last updated 4 Jan 2015
# Created by Ruins mod version 12.3 Ingame Parser
# authoring Player: Jordan_Greywolf
# Updated to MC 1.8: 23 Mar 2016
# Updated to MC 1.9: 26 Apr 2016
# Updated to MC 1.11: 13 Jan 2017
# Verified for MC 1.12: 23 Jun 2017
# Updated to MC 1.12.1: 10 Sep 2017

biomesToSpawnIn=river,frozen river,frozenriver,bayou,frozen_river

uniqueMinDistance=1000

weight=1
embed_into_distance=5

unacceptable_target_blocks=lava,flowing_lava,cloud,Natura:Cloud,slime_congealed,slime_dirt,slime_grass,command_block,planks,planks2,concrete,cobblestone,stonebrick,brick_block,glass,torch,oak_stairs,stone_stairs,brick_stairs,stone_brick_stairs,nether_brick_stairs,sandstone_stairs,spruce_stairs,birch_stairs,jungle_stairs,quartz_stairs,acacia_stairs,dark_oak_stairs,cobblestone_wall,stone_slab,double_stone_slab,stone_slab2,wooden_slab,double_wooden_slab,nether_brick,fence

dimensions=27,32,26
allowable_overhang=0
max_cut_in=0
cut_in_buffer=0
max_leveling=5
leveling_buffer=-1
preserve_water=0
preserve_lava=0
preserve_plants=1

rule1=0,100,preserveBlock

rule2=0,100,minecraft:grass-0
rule3=0,100,minecraft:stone-0

# Cobblestone (wall)
rule4=0,100,minecraft:cobblestone-0,minecraft:cobblestone-0,minecraft:mossy_cobblestone-0

rule5=0,100,minecraft:log-0
rule6=0,100,minecraft:water-0
rule7=0,100,minecraft:mossy_cobblestone-0
rule8=0,100,minecraft:dirt-0
rule9=0,100,minecraft:web-0

# Spider Spawner
rule10=0,100,MobSpawner:Cave_Spider,MobSpawner:Spider

rule11=0,100,ChestGenHook:chests/simple_dungeon:4-4
rule12=0,100,minecraft:planks-0
rule13=0,100,minecraft:planks-1
rule14=0,100,minecraft:wooden_slab-1
rule15=0,100,minecraft:spruce_stairs-1
rule16=0,100,minecraft:water-9
rule17=0,100,minecraft:water-1
rule18=0,100,minecraft:log-1
rule19=0,100,minecraft:log-8
rule20=0,100,minecraft:log-4
rule21=0,100,minecraft:fence-0
rule22=0,100,minecraft:spruce_stairs-4

# Other Spawner
rule23=0,100,MobSpawner:Skeleton,MobSpawner:Zombie

rule24=0,100,minecraft:crafting_table-0
rule25=0,100,minecraft:wooden_door-0

# Redstone Lamp (used for windows)
rule26=0,100,minecraft:redstone_lamp-0
rule27=0,100,minecraft:wooden_door-8
rule28=0,100,minecraft:log-5
rule29=0,100,minecraft:stone_stairs-7
rule30=0,100,minecraft:stone_stairs-2
rule31=0,100,minecraft:stone_stairs-0
rule32=0,100,minecraft:stone_stairs-3
rule33=0,100,minecraft:spruce_stairs-3
rule34=0,100,minecraft:spruce_stairs-2
rule35=0,100,minecraft:stone_stairs-4
rule36=0,100,IInventory;minecraft:lit_furnace;minecraft:coal#8#1#1-2
rule37=0,100,minecraft:netherrack-0
rule38=0,100,minecraft:stone_stairs-5
rule39=0,100,minecraft:spruce_stairs-0
rule40=0,100,minecraft:stone_stairs-1
rule41=0,100,minecraft:spruce_stairs-5
rule42=0,100,minecraft:stone_pressure_plate-0
rule43=0,100,minecraft:iron_bars-0
rule44=0,100,minecraft:fire-15
rule45=0,100,minecraft:stone_stairs-6
rule46=0,100,minecraft:water-10
rule47=0,100,minecraft:stonebrick-3
rule48=0,100,minecraft:water-15
rule49=0,100,minecraft:water-2
rule50=0,100,minecraft:planks-2
rule51=0,100,minecraft:wooden_door-2
rule52=0,100,minecraft:wool-12
rule53=0,100,minecraft:wooden_slab-5
rule54=0,100,minecraft:bed-10
rule55=0,100,minecraft:bed-2
rule56=0,100,minecraft:bed-0
rule57=0,100,minecraft:bed-8
rule58=0,100,minecraft:wooden_door-9
rule59=0,100,minecraft:stone_slab-14
rule60=0,100,minecraft:water-3
rule61=0,100,minecraft:water-4
rule62=0,100,minecraft:water-5
rule63=0,100,minecraft:water-6
rule64=0,100,minecraft:water-7
rule65=0,100,minecraft:nether_brick_stairs-0
rule66=0,100,minecraft:nether_brick_stairs-5
rule67=0,100,minecraft:nether_brick-0
rule68=0,100,minecraft:ladder-3
rule69=0,100,minecraft:nether_brick_stairs-4
rule70=0,100,minecraft:nether_brick_stairs-1
rule71=0,100,minecraft:nether_brick_stairs-2
rule72=0,100,minecraft:nether_brick_stairs-7
rule73=0,100,minecraft:nether_brick_stairs-6
rule74=0,100,minecraft:nether_brick_stairs-3
rule75=0,100,minecraft:stone_slab-6

layer
1,1,1,1,1,1,1,2,2,3,3,3,3,3,3,3,3,3,3,3,2,2,1,1,1,1
1,1,1,1,1,2,2,2,3,3,3,3,3,3,3,3,3,3,3,3,3,3,2,2,2,1
1,1,1,2,2,2,3,3,3,3,3,3,3,3,3,3,3,3,3,3,3,3,3,3,2,1
1,1,2,2,3,3,3,3,3,3,3,3,3,3,3,3,3,3,3,3,3,3,3,3,3,2
1,2,2,3,3,3,3,3,3,3,3,3,3,3,3,3,3,3,3,3,3,3,3,3,3,2
1,2,3,3,3,3,3,3,3,3,3,3,3,3,3,3,3,3,3,3,3,3,3,3,3,2
1,2,3,3,3,3,3,3,3,3,3,3,3,3,3,3,3,3,3,3,3,3,3,3,3,2
1,2,3,3,3,3,3,3,3,3,3,3,3,3,3,3,3,3,3,3,3,3,3,3,3,3
1,2,3,3,3,3,3,3,3,3,3,3,3,3,3,3,3,3,3,3,3,3,3,3,3,3
1,2,3,3,3,3,3,3,3,3,3,3,3,3,3,3,3,3,3,3,3,3,3,3,3,3
1,2,5,4,4,4,4,4,4,4,4,4,3,3,3,3,3,3,3,3,3,3,3,3,3,3
1,2,4,5,7,7,7,7,7,7,7,7,5,4,6,6,6,6,3,3,3,3,3,3,1,5
1,2,4,7,7,7,7,7,7,7,7,7,7,4,6,6,6,6,6,3,3,3,3,1,1,1
1,1,4,7,7,7,7,7,7,7,7,7,7,4,6,6,6,6,6,1,3,3,3,1,1,1
1,1,4,7,7,7,7,7,7,7,7,7,7,4,6,6,6,6,6,1,1,3,1,1,1,1
1,1,4,7,7,7,7,7,7,7,7,7,7,4,6,6,6,6,6,6,6,1,1,1,1,1
1,1,4,7,7,7,7,7,7,7,7,7,7,4,6,6,6,6,6,6,5,1,1,1,1,5
1,1,4,7,7,7,7,7,7,7,7,7,7,4,6,6,6,6,6,6,6,6,1,1,1,1
1,1,4,7,7,7,7,7,7,7,7,7,7,4,6,6,6,6,6,6,6,6,6,1,1,1
1,1,4,7,7,7,7,7,7,7,7,7,7,4,6,6,6,6,6,6,6,6,6,6,1,1
1,1,4,7,7,7,7,7,7,7,7,7,7,4,6,6,6,6,6,6,6,6,6,6,6,6
1,1,4,7,7,7,7,7,7,7,7,7,7,4,6,6,6,6,6,6,5,6,6,6,1,5
7,7,4,7,7,7,7,7,7,7,7,7,7,4,6,6,6,6,6,6,6,6,6,1,1,1
7,7,4,7,7,7,7,7,7,7,7,7,7,4,6,6,6,6,6,6,6,1,1,1,1,1
7,7,4,7,7,7,7,7,7,7,7,7,7,4,6,6,6,6,6,6,6,1,1,1,1,1
7,7,4,5,7,7,7,7,7,7,7,7,5,4,6,6,6,6,6,1,1,1,1,1,1,1
5,1,5,4,4,4,4,4,4,4,4,4,4,5,6,6,6,6,6,1,5,1,1,1,1,5
1,1,1,1,1,1,1,1,1,1,1,1,1,1,1,6,6,6,1,1,1,1,1,1,1,1
1,1,1,1,1,1,1,1,1,1,1,1,1,1,1,6,6,6,1,1,1,1,1,1,1,1
1,1,1,1,1,1,1,1,1,1,1,1,1,1,1,6,6,6,1,1,1,1,1,1,1,1
1,1,1,1,1,1,1,1,1,1,1,1,1,1,1,6,6,6,1,1,1,1,1,1,1,1
5,1,5,1,1,1,1,5,5,1,1,1,1,5,1,6,6,6,1,1,5,1,1,1,1,5
endlayer

layer
1,1,1,1,1,1,1,2,2,3,3,3,3,3,3,3,3,3,3,3,2,2,1,1,1,1
1,1,1,1,1,2,2,2,3,3,3,3,3,3,3,3,3,3,3,3,3,3,2,2,2,1
1,1,1,2,2,2,3,3,3,3,3,3,3,3,3,3,3,3,3,3,3,3,3,3,2,1
1,1,2,2,3,3,3,3,3,3,3,3,3,3,3,3,3,3,3,3,3,3,3,3,3,2
1,2,2,3,3,3,3,3,3,3,3,3,3,3,3,3,3,3,3,3,3,3,3,3,3,2
1,2,3,3,3,3,3,3,3,3,3,3,3,3,3,3,3,3,3,3,3,3,3,3,3,2
1,2,3,3,3,3,3,3,3,3,3,3,3,3,3,3,3,3,3,3,3,3,3,3,3,2
1,2,3,3,3,3,3,3,3,3,3,3,3,3,3,3,3,3,3,3,3,3,3,3,3,3
1,2,3,3,3,3,3,3,3,3,3,3,3,3,3,3,3,3,3,3,3,3,3,3,3,3
1,2,3,3,3,3,3,3,3,3,3,3,3,3,3,3,3,3,3,3,3,3,3,3,3,3
1,2,5,4,4,4,4,4,4,4,4,4,3,3,3,3,3,3,3,3,3,3,3,3,3,3
1,2,4,5,7,7,7,7,7,7,7,7,5,4,6,6,6,6,3,3,3,3,3,3,1,5
1,2,4,7,7,7,7,7,7,7,7,7,7,4,6,6,6,6,6,3,3,3,3,1,1,1
1,1,4,7,7,7,7,7,7,7,7,7,7,4,6,6,6,6,6,1,3,3,3,1,1,1
1,1,4,7,7,7,7,7,7,7,7,7,7,4,6,6,6,6,6,1,1,3,1,1,1,1
1,1,4,7,7,7,7,7,7,7,7,7,7,4,6,6,6,6,6,6,6,1,1,1,1,1
1,1,4,7,7,7,7,7,7,7,7,7,7,4,6,6,6,6,6,6,5,1,1,1,1,5
1,1,4,7,7,7,7,7,7,7,7,7,7,4,6,6,6,6,6,6,6,6,1,1,1,1
1,1,4,7,7,7,7,7,7,7,7,7,7,4,6,6,6,6,6,6,6,6,6,1,1,1
1,1,4,7,7,7,7,7,7,7,7,7,7,4,6,6,6,6,6,6,6,6,6,6,1,1
1,1,4,7,7,7,7,7,7,7,7,7,7,4,6,6,6,6,6,6,6,6,6,6,6,6
1,1,4,7,7,7,7,7,7,7,7,7,7,4,6,6,6,6,6,6,5,6,6,6,1,5
7,7,4,7,7,7,7,7,7,7,7,7,7,4,6,6,6,6,6,6,6,6,6,1,1,1
7,7,4,7,7,7,7,7,7,7,7,7,7,4,6,6,6,6,6,6,6,1,1,1,1,1
7,7,4,7,7,7,7,7,7,7,7,7,7,4,6,6,6,6,6,6,6,1,1,1,1,1
7,7,4,5,7,7,7,7,7,7,7,7,5,4,6,6,6,6,6,1,1,1,1,1,1,1
5,1,5,4,4,4,4,4,4,4,4,4,4,5,6,6,6,6,6,1,5,1,1,1,1,5
1,1,1,1,1,1,1,1,1,1,1,1,1,1,1,6,6,6,1,1,1,1,1,1,1,1
1,1,1,1,1,1,1,1,1,1,1,1,1,1,1,6,6,6,1,1,1,1,1,1,1,1
1,1,1,1,1,1,1,1,1,1,1,1,1,1,1,6,6,6,1,1,1,1,1,1,1,1
1,1,1,1,1,1,1,1,1,1,1,1,1,1,1,6,6,6,1,1,1,1,1,1,1,1
5,1,5,1,1,1,1,5,5,1,1,1,1,5,1,6,6,6,1,1,5,1,1,1,1,5
endlayer


layer
1,1,1,1,1,1,1,1,1,2,2,2,8,8,3,3,3,3,8,2,1,1,1,1,1,1
1,1,1,1,1,1,1,1,2,2,2,3,3,3,3,3,3,3,3,3,2,2,1,1,1,1
1,1,1,1,1,1,2,2,2,3,3,3,3,3,3,3,3,3,3,3,3,3,3,2,1,1
1,1,1,1,2,2,2,2,3,3,3,3,3,3,3,3,3,3,3,3,3,3,3,3,2,1
1,1,1,2,2,2,2,3,3,3,3,3,3,3,3,3,3,3,3,3,3,3,3,3,2,1
1,1,2,2,2,2,2,3,3,3,3,3,3,3,3,3,3,3,3,3,3,3,3,3,3,1
1,1,2,2,2,2,2,3,3,3,3,3,3,3,3,3,3,3,3,3,3,3,3,3,3,1
1,1,2,2,2,2,2,3,3,3,3,3,3,3,3,3,3,3,3,3,3,3,3,3,3,3
1,1,2,2,2,3,3,3,3,3,3,3,3,3,3,3,3,3,3,3,3,3,3,3,3,3
1,1,2,2,3,3,3,3,3,3,3,3,3,3,3,3,3,3,3,3,3,3,3,3,3,1
1,1,5,4,4,4,4,4,4,4,4,4,3,3,3,3,3,3,3,3,3,3,3,3,3,3
1,1,4,5,9,0,0,0,0,0,0,9,5,4,0,0,0,0,3,3,3,3,3,3,1,5
1,1,4,10,9,0,0,0,0,0,0,0,9,4,0,0,0,0,0,3,3,3,1,1,1,1
1,1,4,9,0,0,0,0,0,0,0,0,0,4,0,0,0,0,0,0,1,3,1,1,1,1
1,1,4,0,0,0,0,0,0,0,0,0,0,4,0,0,0,0,0,0,0,1,1,1,1,1
1,1,4,0,0,0,0,11,0,0,0,0,0,4,0,0,0,0,0,0,0,0,1,1,1,1
1,1,4,0,0,13,13,13,13,13,13,0,0,4,0,12,0,12,0,0,5,0,0,1,1,5
1,1,4,0,0,13,14,14,14,13,13,0,0,4,0,12,12,12,0,0,0,0,0,0,1,1
1,1,4,0,0,13,14,5,14,13,13,0,0,4,0,12,12,12,0,0,0,0,0,0,0,1
1,1,4,0,9,13,14,14,14,13,15,0,0,4,0,12,12,12,0,0,0,0,0,0,0,1
1,1,4,0,0,13,13,13,13,13,0,0,0,4,0,12,0,12,0,0,0,0,0,0,0,1
1,1,4,0,0,0,0,0,9,0,0,0,0,4,0,0,0,0,0,0,5,0,0,0,0,5
1,1,4,0,0,0,0,0,0,0,0,0,0,4,0,0,0,0,0,0,0,0,0,0,1,1
7,7,4,0,0,0,0,0,0,0,0,0,0,4,0,0,0,0,0,0,0,0,0,1,1,1
7,7,4,0,0,0,0,0,0,0,0,9,9,4,0,17,16,0,0,0,0,0,1,1,1,1
7,7,4,5,0,0,0,0,0,0,9,10,5,4,0,0,0,0,0,1,1,1,1,1,1,1
5,1,5,4,4,4,4,4,4,4,4,4,4,5,0,0,0,0,0,1,5,1,1,1,1,5
1,1,1,1,1,1,1,1,1,1,1,1,1,1,1,0,0,0,1,1,1,1,1,1,1,1
1,1,1,1,1,1,1,1,1,1,1,1,1,1,1,0,0,0,1,1,1,1,1,1,1,1
1,1,1,1,1,1,1,1,1,1,1,1,1,1,1,0,0,0,1,1,1,1,1,1,1,1
1,1,1,1,1,1,1,1,1,1,1,1,1,1,1,0,0,0,1,1,1,1,1,1,1,1
5,1,5,1,1,1,1,5,5,1,1,1,1,5,1,0,0,0,1,1,5,1,1,1,1,5
endlayer

layer
1,1,1,1,1,1,1,1,1,1,1,1,2,8,8,8,8,8,2,1,1,1,1,1,1,1
1,1,1,1,1,1,1,1,1,1,1,2,3,3,3,3,3,3,3,2,1,1,1,1,1,1
1,1,1,1,1,1,1,1,1,2,2,3,3,3,3,3,3,3,3,3,3,3,2,1,1,1
1,1,1,1,1,1,1,1,2,3,3,3,3,3,3,3,3,3,3,3,3,3,3,2,1,1
1,1,1,1,1,1,1,2,3,3,3,3,3,3,3,3,3,3,3,3,3,3,3,3,1,1
1,1,1,1,1,1,1,2,3,3,3,3,3,3,3,3,3,3,3,3,3,3,3,3,1,1
1,1,1,1,1,1,1,2,3,3,3,3,3,3,3,3,3,3,3,3,3,3,3,3,3,1
1,1,1,1,1,1,1,2,2,3,3,3,3,3,3,3,3,3,3,3,3,3,3,3,3,3
1,1,1,1,1,2,2,2,2,3,3,3,3,3,3,3,3,3,3,3,3,3,3,3,3,3
1,1,1,1,2,2,2,2,2,2,3,3,3,3,3,3,3,3,3,3,3,3,3,3,3,1
1,1,5,4,4,4,4,4,4,4,4,4,3,3,3,3,3,3,3,3,3,3,3,3,3,1
1,1,4,5,0,0,0,9,0,0,9,9,5,4,0,0,0,0,0,3,3,3,3,3,1,5
1,1,4,9,0,0,0,0,0,0,0,0,0,4,0,0,0,0,0,0,3,1,1,1,1,1
1,1,4,9,0,0,0,0,0,0,0,0,0,4,0,0,0,0,0,0,0,0,1,1,1,1
1,1,4,0,0,0,0,0,0,0,0,0,0,4,0,12,0,12,0,0,0,0,0,1,1,1
1,1,4,0,0,0,0,0,0,0,0,0,9,4,0,12,12,12,0,0,0,0,0,0,1,1
1,1,4,0,0,0,0,0,0,0,13,0,0,4,0,12,12,12,0,0,5,0,0,0,0,5
1,1,4,0,0,0,0,0,0,0,13,0,0,4,0,12,12,12,0,0,0,0,0,0,0,1
1,1,4,9,0,0,0,5,0,0,15,0,0,4,0,0,18,0,0,0,0,0,0,0,0,1
1,1,4,0,0,0,0,0,0,0,0,0,0,4,0,12,12,12,0,0,0,0,0,0,0,1
1,1,4,9,0,0,0,0,0,0,0,0,9,4,0,12,12,12,0,0,0,0,0,0,0,1
1,1,4,0,0,0,0,0,0,0,0,0,0,4,0,12,12,12,0,0,5,0,0,0,0,5
1,1,4,0,0,0,0,0,0,0,0,0,0,4,0,12,0,12,0,0,0,0,0,0,1,1
1,1,4,9,0,0,0,0,0,0,0,0,9,4,0,0,0,0,0,0,0,0,0,0,1,1
7,7,4,9,0,0,0,0,0,0,0,0,9,4,0,0,16,0,0,0,0,0,0,1,1,1
7,7,4,5,9,9,0,0,9,0,9,9,5,4,0,0,0,0,0,1,1,1,1,1,1,1
5,1,5,4,4,4,4,4,4,4,4,4,4,5,0,0,0,0,0,1,5,1,1,1,1,5
1,1,1,1,1,1,1,1,1,1,1,1,1,1,1,0,0,0,1,1,1,1,1,1,1,1
1,1,1,1,1,1,1,1,1,1,1,1,1,1,1,0,0,0,1,1,1,1,1,1,1,1
1,1,1,1,1,1,1,1,1,1,1,1,1,1,1,0,0,0,1,1,1,1,1,1,1,1
1,1,1,1,1,1,1,1,1,1,1,1,1,1,1,0,0,0,1,1,1,1,1,1,1,1
5,1,5,1,1,1,1,5,5,1,1,1,1,5,1,0,0,0,1,1,5,1,1,1,1,5
endlayer

layer
1,1,1,1,1,1,1,1,1,1,1,1,1,2,2,2,2,2,1,1,1,1,1,1,1,1
1,1,1,1,1,1,1,1,1,1,1,1,2,3,3,3,3,3,2,1,1,1,1,1,1,1
1,1,1,1,1,1,1,1,1,1,1,2,3,3,3,3,3,3,3,3,3,1,1,1,1,1
1,1,1,1,1,1,1,1,1,2,2,3,3,3,3,3,3,3,3,3,3,3,1,1,1,1
1,1,1,1,1,1,1,1,2,2,3,3,3,3,3,3,3,3,3,3,3,3,3,3,1,1
1,1,1,1,1,1,1,1,2,3,3,3,3,3,3,3,3,3,3,3,3,3,3,3,1,1
1,1,1,1,1,1,1,1,2,2,3,3,3,3,3,3,3,3,3,3,3,3,3,3,3,1
1,1,1,1,1,1,1,1,1,2,2,3,3,3,3,3,3,3,3,3,3,3,3,3,3,1
1,1,1,1,1,1,1,1,1,2,2,2,3,3,3,3,3,3,3,3,3,3,3,3,3,1
1,1,1,1,1,1,1,1,1,1,2,2,3,3,3,3,3,3,3,3,3,3,3,3,3,1
1,1,5,19,19,19,19,19,19,19,19,19,19,3,3,3,3,3,3,3,3,3,3,3,1,1
1,1,20,5,12,12,12,12,12,12,12,12,5,20,0,0,0,0,0,3,5,19,19,19,19,5
1,1,20,12,12,12,12,12,12,12,12,12,12,20,0,0,0,0,0,0,20,12,12,12,12,20
1,1,20,12,12,12,12,12,12,12,12,12,12,20,0,0,0,0,0,0,20,12,12,12,12,20
1,1,20,12,12,12,12,12,12,12,12,12,12,20,0,12,12,12,0,0,20,12,12,12,12,20
1,1,20,12,12,12,12,12,12,12,12,12,12,20,0,12,12,12,0,0,20,12,12,12,12,20
1,1,20,12,12,21,21,21,21,21,13,12,12,20,0,0,0,0,0,0,5,19,19,19,19,5
1,1,20,12,12,21,0,0,0,21,15,12,12,20,0,0,0,0,0,0,20,12,12,12,12,20
1,1,20,12,12,21,0,5,0,21,0,12,12,20,0,0,18,0,0,0,20,12,12,12,12,20
1,1,20,12,12,21,0,0,0,21,0,12,12,20,0,0,0,0,0,0,20,12,12,12,12,20
1,1,20,12,12,21,21,21,21,21,0,12,12,20,0,0,0,0,0,0,20,12,12,12,12,20
1,1,20,12,12,12,12,12,12,12,12,12,12,20,0,12,12,12,0,0,5,19,19,19,19,5
1,1,20,12,12,12,12,12,12,12,12,12,12,20,0,12,12,12,0,0,20,12,12,12,12,20
1,1,20,12,12,12,12,12,12,12,12,12,12,20,0,0,0,0,0,0,20,12,12,12,12,20
1,1,20,12,12,12,12,12,12,12,12,12,12,20,0,0,16,0,0,0,20,12,12,12,12,20
7,7,20,5,12,12,12,12,12,12,12,12,5,20,0,0,0,0,0,0,20,12,12,12,12,20
5,19,5,19,19,19,19,19,19,19,19,19,19,5,19,19,19,19,19,19,5,19,19,19,19,5
20,12,20,12,12,12,12,12,12,12,12,12,12,20,12,12,12,12,12,12,20,12,12,12,12,20
20,12,20,12,12,12,12,12,12,12,12,12,12,20,12,12,12,12,12,12,20,12,12,12,12,20
20,12,20,12,12,12,12,12,12,12,12,12,12,20,12,12,12,12,12,12,20,12,12,12,12,20
20,12,20,12,12,12,12,12,12,12,12,12,12,20,12,12,12,12,12,12,20,12,12,12,12,20
5,19,5,19,19,19,19,19,19,19,19,19,19,5,19,19,19,19,19,19,5,19,19,19,19,5
endlayer

layer
1,1,1,1,1,1,1,1,1,1,1,1,1,1,1,1,1,1,1,1,1,1,1,1,1,1
1,1,1,1,1,1,1,1,1,1,1,1,1,3,3,3,3,3,1,1,1,1,1,1,1,1
1,1,1,1,1,1,1,1,1,1,1,1,3,3,3,3,3,3,3,3,3,1,1,1,1,1
1,1,1,1,1,1,1,1,1,1,1,3,3,3,3,3,3,3,3,3,3,3,1,1,1,1
1,1,1,1,1,1,1,1,1,1,2,3,3,3,3,3,3,3,3,3,3,3,3,1,1,1
1,1,1,1,1,1,1,1,1,3,3,3,3,3,3,3,3,3,3,3,3,3,3,3,1,1
1,1,1,1,1,1,1,1,1,1,3,3,3,3,3,3,3,3,3,3,3,3,3,3,1,1
1,1,1,1,1,1,1,1,1,1,1,3,3,3,3,3,3,3,3,3,3,3,3,3,1,1
1,1,1,1,1,1,1,1,1,1,1,1,3,3,3,3,3,3,3,3,3,3,3,3,1,1
1,1,1,1,1,1,1,1,1,1,1,1,3,3,3,3,3,3,3,3,3,3,3,3,1,1
1,1,5,4,4,4,4,5,5,4,4,4,4,3,3,3,3,3,3,3,3,3,3,1,1,1
1,1,4,5,0,0,0,0,0,0,0,9,5,4,0,0,0,0,0,3,21,21,21,21,21,21
1,1,4,0,0,0,0,0,0,0,0,9,10,4,0,0,0,0,0,0,21,0,0,0,0,21
1,1,4,0,0,0,0,0,0,0,0,0,9,4,0,12,0,12,0,0,21,0,0,0,0,0
1,1,4,0,0,0,0,0,0,0,0,9,0,4,0,12,12,12,0,0,21,0,0,0,0,0
1,1,4,0,0,0,0,11,0,0,0,22,0,4,0,0,0,0,0,0,21,0,0,0,0,21
1,1,5,0,0,21,21,21,21,21,0,15,0,4,0,0,0,0,0,0,21,0,0,0,0,21
1,1,4,0,0,21,0,0,0,21,0,0,0,4,0,0,0,0,0,0,21,0,0,0,0,21
1,1,4,0,0,21,0,5,0,21,0,0,0,4,0,0,18,0,0,0,21,0,0,0,0,21
1,1,4,0,0,21,0,0,0,21,0,0,0,4,0,0,0,0,0,0,21,0,0,0,0,21
1,1,5,0,0,21,21,21,21,21,0,0,0,4,0,0,0,0,0,0,21,0,0,0,0,21
1,1,4,0,0,0,0,0,0,0,0,0,0,4,0,0,0,0,0,0,21,0,0,0,0,21
1,1,4,0,0,0,0,0,0,0,0,0,0,4,0,12,12,12,0,0,21,0,0,0,0,21
1,1,4,0,0,0,0,0,0,0,0,0,9,4,0,12,0,12,0,0,21,0,0,0,0,21
0,0,4,0,0,0,0,0,0,0,0,9,23,4,0,0,16,0,0,0,21,0,0,0,0,21
0,0,4,5,24,0,0,0,0,0,0,11,5,4,0,0,0,0,0,0,21,0,0,0,0,21
21,0,5,4,4,25,4,5,5,4,4,4,4,5,21,21,21,21,21,21,21,0,0,0,0,21
21,0,0,0,0,0,0,0,0,0,0,0,0,0,0,0,0,0,0,0,0,0,0,0,0,21
0,0,0,0,0,0,0,0,0,0,0,0,0,0,0,0,0,0,0,0,0,0,0,0,0,0
0,0,0,0,0,0,0,0,0,0,0,0,0,0,0,0,0,0,0,0,0,0,0,0,0,0
21,0,0,0,0,0,0,0,0,0,0,0,0,0,0,0,0,0,0,0,0,0,0,0,0,21
21,21,21,21,21,21,21,21,21,21,21,21,21,21,21,21,21,21,21,21,21,21,21,21,21,21
endlayer

layer
1,1,1,1,1,1,1,1,1,1,1,1,1,1,1,1,1,1,1,1,1,1,1,1,1,1
1,1,1,1,1,1,1,1,1,1,1,1,1,2,3,3,3,3,1,1,1,1,1,1,1,1
1,1,1,1,1,1,1,1,1,1,1,1,2,3,3,3,3,3,3,3,3,1,1,1,1,1
1,1,1,1,1,1,1,1,1,1,1,2,3,3,3,3,3,3,3,3,3,3,1,1,1,1
1,1,1,1,1,1,1,1,1,1,1,3,3,3,3,3,3,3,3,3,3,3,1,1,1,1
1,1,1,1,1,1,1,1,1,3,3,3,3,3,3,3,3,3,3,3,3,3,3,1,1,1
1,1,1,1,1,1,1,1,1,1,3,3,3,3,3,3,3,3,3,3,3,3,3,1,1,1
1,1,1,1,1,1,1,1,1,1,1,3,3,3,3,3,3,3,3,3,3,3,3,1,1,1
1,1,1,1,1,1,1,1,1,1,1,1,3,3,3,3,3,3,3,3,3,3,3,1,1,1
1,1,1,1,1,1,1,1,1,1,1,1,3,3,3,3,3,3,3,3,3,3,3,1,1,1
1,1,5,4,4,4,4,5,5,4,4,4,4,3,3,3,3,3,3,3,3,3,0,1,1,1
1,1,4,5,0,0,0,0,0,0,0,0,5,4,0,0,0,0,0,0,0,0,0,0,0,0
1,1,4,0,0,0,0,0,0,0,0,0,9,4,0,0,0,0,0,0,0,0,0,0,0,0
1,1,4,0,0,0,0,0,0,0,0,0,0,4,0,12,12,12,0,0,0,0,0,0,0,0
1,1,4,0,0,0,0,0,0,0,0,22,0,4,0,12,12,12,0,0,0,0,0,0,0,0
1,1,4,0,0,0,0,0,0,0,0,15,0,4,0,0,0,0,0,0,0,0,0,0,0,0
1,1,5,0,0,0,0,0,0,0,0,0,0,4,0,0,0,0,0,0,0,0,0,0,0,0
0,0,20,0,0,0,0,0,0,0,0,0,0,4,0,12,12,12,0,0,0,0,0,0,0,0
0,0,20,0,0,0,0,5,0,0,0,0,0,4,0,12,12,12,0,0,0,0,0,0,0,0
0,0,20,0,0,0,0,0,0,0,0,0,0,4,0,12,12,12,0,0,0,0,0,0,0,0
0,0,5,0,0,0,0,0,0,0,0,0,0,4,0,0,0,0,0,0,0,0,0,0,0,0
0,0,4,0,0,0,0,0,0,0,0,0,0,4,0,0,0,0,0,0,0,0,0,0,0,0
0,0,4,0,0,0,0,0,0,0,0,0,0,4,0,12,12,12,0,0,0,0,0,0,0,0
0,0,4,0,0,0,0,0,0,0,0,0,0,4,0,12,12,12,0,0,0,0,0,0,0,0
0,0,4,9,0,0,0,0,0,0,0,0,9,4,0,0,16,0,0,0,0,0,0,0,0,0
0,0,4,5,0,0,0,0,0,0,0,9,5,4,0,0,0,0,0,0,0,0,0,0,0,0
0,0,5,4,4,27,4,5,5,4,26,4,4,5,0,0,0,0,0,0,0,0,0,0,0,0
0,0,0,0,0,0,0,0,0,0,0,0,0,0,0,0,0,0,0,0,0,0,0,0,0,0
0,0,0,0,0,0,0,0,0,0,0,0,0,0,0,0,0,0,0,0,0,0,0,0,0,0
0,0,0,0,0,0,0,0,0,0,0,0,0,0,0,0,0,0,0,0,0,0,0,0,0,0
0,0,0,0,0,0,0,0,0,0,0,0,0,0,0,0,0,0,0,0,0,0,0,0,0,0
0,0,0,0,0,0,0,0,0,0,0,0,0,0,0,0,0,0,0,0,0,0,0,0,0,0
endlayer

layer
1,1,1,1,1,1,1,1,1,1,1,1,1,1,1,1,1,1,1,1,1,1,1,1,1,1
1,1,1,1,1,1,1,1,1,1,1,1,1,1,2,3,3,2,1,1,1,1,1,1,1,1
1,1,1,1,1,1,1,1,1,1,1,1,1,2,3,3,3,3,3,3,3,1,1,1,1,1
1,1,1,1,1,1,1,1,1,1,1,1,2,3,3,3,3,3,3,3,3,1,1,1,1,1
1,1,1,1,1,1,1,1,1,1,1,3,3,3,3,3,3,3,3,3,3,3,1,1,1,1
1,1,1,1,1,1,1,1,1,2,3,3,3,3,3,3,3,3,3,3,3,3,1,1,1,1
1,1,1,1,1,1,1,1,1,1,3,3,3,3,3,3,3,3,3,3,3,3,1,1,1,1
1,1,1,1,1,1,1,1,1,1,1,3,3,3,3,3,3,3,3,3,3,3,1,1,1,1
1,1,1,1,1,1,1,1,1,1,1,1,3,3,3,3,3,3,3,3,3,3,1,1,1,1
1,1,1,1,1,1,1,1,1,1,1,1,2,3,3,3,3,3,3,3,3,3,0,1,1,1
1,1,5,4,4,4,4,5,5,4,4,4,4,3,3,3,3,3,3,3,3,0,0,0,1,1
1,1,4,5,9,0,0,9,0,0,0,0,5,4,0,0,0,0,0,0,0,0,0,0,0,0
1,1,4,9,0,0,0,0,0,0,0,0,9,4,0,0,0,0,0,0,0,0,0,0,0,0
0,0,4,0,0,0,0,0,0,0,0,22,0,4,0,12,12,12,0,0,0,0,0,0,0,0
0,0,4,0,0,0,0,0,0,0,0,15,0,4,0,0,28,0,0,0,0,0,0,0,0,0
0,0,4,0,0,0,0,0,0,0,0,0,0,4,0,0,28,0,0,0,0,0,0,0,0,0
0,0,5,0,0,0,0,0,0,0,0,0,0,4,0,0,28,0,0,0,0,0,0,0,0,0
0,0,4,0,0,0,0,0,0,0,0,0,0,4,0,12,12,12,0,0,0,0,0,0,0,0
0,19,19,19,19,19,19,19,19,19,19,19,19,19,19,19,19,19,19,0,0,0,0,0,0,0
0,0,4,0,0,0,0,0,0,0,0,0,0,4,0,12,12,12,0,0,0,0,0,0,0,0
0,0,5,9,0,0,0,0,0,0,0,0,0,4,0,0,28,0,0,0,0,0,0,0,0,0
0,0,4,0,0,0,0,0,0,0,0,0,0,4,0,0,28,0,0,0,0,0,0,0,0,0
0,0,4,0,0,0,0,0,0,0,0,0,0,4,0,0,28,0,0,0,0,0,0,0,0,0
0,0,4,9,0,0,0,0,0,0,0,0,0,4,0,12,12,12,0,0,0,0,0,0,0,0
0,0,4,9,0,0,0,0,0,0,0,0,9,4,0,0,16,0,0,0,0,0,0,0,0,0
0,0,4,5,9,0,0,0,9,0,0,9,5,4,0,0,0,0,0,0,0,0,0,0,0,0
0,0,5,4,4,4,4,5,5,4,4,4,4,5,0,0,0,0,0,0,0,0,0,0,0,0
0,0,0,0,0,21,0,0,0,0,21,0,0,0,0,0,0,0,0,0,0,0,0,0,0,0
0,0,0,0,0,21,0,0,0,0,21,0,0,0,0,0,0,0,0,0,0,0,0,0,0,0
0,0,0,0,0,0,0,0,0,0,0,0,0,0,0,0,0,0,0,0,0,0,0,0,0,0
0,0,0,0,0,0,0,0,0,0,0,0,0,0,0,0,0,0,0,0,0,0,0,0,0,0
0,0,0,0,0,0,0,0,0,0,0,0,0,0,0,0,0,0,0,0,0,0,0,0,0,0
endlayer

layer
1,1,1,1,1,1,1,1,1,1,1,1,1,1,1,1,1,1,1,1,1,1,1,1,1,1
1,1,1,1,1,1,1,1,1,1,1,1,1,1,1,2,2,1,1,1,1,1,1,1,1,1
1,1,1,1,1,1,1,1,1,1,1,1,1,1,3,3,3,3,2,2,1,1,1,1,1,1
1,1,1,1,1,1,1,1,1,1,1,1,1,3,3,3,3,3,3,3,1,1,1,1,1,1
1,1,1,1,1,1,1,1,1,1,1,3,3,3,3,3,3,3,3,3,3,1,1,1,1,1
1,1,1,1,1,1,1,1,1,1,3,3,3,3,3,3,3,3,3,3,3,3,1,1,1,1
1,1,1,1,1,1,1,1,1,1,3,3,3,3,3,3,3,3,3,3,3,3,1,1,1,1
1,1,0,1,1,1,1,1,1,1,1,2,3,3,3,3,3,3,3,3,3,3,1,1,1,1
1,1,0,0,1,1,1,1,1,1,1,0,3,3,3,3,3,3,3,3,3,3,0,0,1,0
1,0,0,0,0,1,1,1,1,1,0,0,0,3,3,3,3,3,3,3,3,0,0,0,0,0
1,0,5,19,5,19,19,19,19,19,19,5,19,5,3,3,3,3,3,3,0,0,0,0,0,0
1,0,20,5,19,19,19,19,19,19,19,19,5,20,0,0,0,0,0,0,0,0,0,0,0,0
0,0,5,20,12,12,12,12,12,12,12,13,20,5,0,0,0,0,0,0,0,0,0,0,0,0
0,0,20,20,12,12,12,12,12,12,12,15,20,20,0,12,12,12,0,0,0,0,0,0,0,0
0,0,20,20,12,12,12,12,12,12,12,0,20,20,0,12,12,12,0,0,0,0,0,0,0,0
0,0,20,20,12,12,12,12,12,12,12,0,20,20,0,0,0,0,0,0,0,0,0,0,0,0
0,0,20,20,12,12,12,12,12,12,12,0,20,20,0,0,0,0,0,0,0,0,0,0,0,0
0,0,20,20,12,12,12,12,12,12,12,22,20,20,0,12,12,12,0,0,0,0,0,0,0,0
0,29,20,20,12,12,12,12,12,12,12,12,20,20,0,12,12,12,0,0,0,0,0,0,0,0
0,0,20,20,12,12,12,12,12,12,12,12,20,20,0,12,12,12,0,0,0,0,0,0,0,0
0,0,20,20,12,12,12,12,12,12,12,12,20,20,0,0,0,0,0,0,0,0,0,0,0,0
0,0,20,20,12,12,12,12,12,12,12,12,20,20,0,0,0,0,0,0,0,0,0,0,0,0
0,0,20,20,12,12,12,12,12,12,12,12,20,20,0,12,12,12,0,0,0,0,0,0,0,0
0,0,20,20,12,12,12,12,12,12,12,12,20,20,0,12,12,12,0,0,0,0,0,0,0,0
0,0,5,20,12,12,12,12,12,12,12,12,20,5,0,0,16,0,0,0,0,0,0,0,0,0
0,0,20,5,19,19,19,19,19,19,19,19,5,20,0,0,0,0,0,0,0,0,0,0,0,0
0,0,5,19,5,19,19,19,19,19,19,5,19,5,0,0,0,0,0,0,0,0,0,0,0,0
0,0,0,0,0,0,0,0,0,0,0,0,0,0,0,0,0,0,0,0,0,0,0,0,0,0
0,0,0,0,0,0,0,0,0,0,0,0,0,0,0,0,0,0,0,0,0,0,0,0,0,0
0,0,0,0,0,0,0,0,0,0,0,0,0,0,0,0,0,0,0,0,0,0,0,0,0,0
0,0,0,0,0,0,0,0,0,0,0,0,0,0,0,0,0,0,0,0,0,0,0,0,0,0
0,0,0,0,0,0,0,0,0,0,0,0,0,0,0,0,0,0,0,0,0,0,0,0,0,0
endlayer

layer
1,1,1,1,1,1,1,1,1,1,1,1,1,1,1,1,1,1,1,1,1,1,1,1,1,1
1,1,1,1,1,1,1,1,1,1,1,1,1,1,1,1,1,1,1,1,1,1,1,1,1,1
1,1,1,1,1,1,1,1,1,1,1,1,1,1,2,3,3,2,1,1,1,1,1,1,1,1
1,1,1,1,1,1,1,1,1,1,1,1,1,3,3,3,3,3,3,1,1,1,1,1,1,1
1,1,1,1,1,1,1,1,1,1,1,3,3,3,3,3,3,3,3,3,3,1,1,1,1,1
1,1,1,1,1,1,1,1,1,1,3,3,3,3,3,3,3,3,3,3,3,1,1,1,1,0
1,0,0,0,1,1,1,1,1,1,2,3,3,3,3,3,3,3,3,3,3,3,1,1,0,0
0,0,0,0,0,0,0,1,1,1,1,1,3,3,3,3,3,3,3,3,3,1,1,1,0,0
0,0,0,0,0,0,0,0,1,1,0,0,3,3,3,3,3,3,3,3,3,0,0,0,0,0
0,0,0,0,0,22,0,0,0,0,22,0,0,3,3,3,3,3,3,3,0,0,0,0,0,0
0,0,32,31,5,4,4,4,4,4,4,5,31,30,0,3,3,3,3,0,0,0,0,0,0,0
0,0,32,4,0,0,0,0,0,0,0,0,4,30,0,0,0,0,0,0,0,0,0,0,0,0
0,0,5,0,0,0,0,0,0,0,0,0,0,5,0,0,0,0,0,0,0,0,0,0,0,0
0,0,4,0,0,0,0,0,0,0,0,0,0,4,0,12,0,12,0,0,0,0,0,0,0,0
0,0,4,0,0,0,0,0,0,0,0,0,0,4,0,12,12,12,0,0,0,0,0,0,0,0
0,0,4,0,0,0,0,0,0,0,0,0,0,4,0,0,0,0,0,0,0,0,0,0,0,0
0,0,5,0,0,0,15,0,0,0,0,22,0,5,0,0,0,0,0,0,0,0,0,0,0,0
0,35,4,0,0,34,21,33,0,0,0,15,0,4,0,0,0,0,0,0,0,0,0,0,0,0
4,37,36,0,0,0,21,0,0,0,0,0,0,4,0,0,18,0,0,0,0,0,0,0,0,0
0,38,4,0,0,34,21,33,0,0,0,0,0,4,0,0,0,0,0,0,0,0,0,0,0,0
0,0,5,0,0,0,39,0,0,0,0,0,0,5,0,0,0,0,0,0,0,0,0,0,0,0
0,0,4,0,0,0,0,0,0,0,0,0,0,4,0,0,0,0,0,0,0,0,0,0,0,0
0,0,4,0,0,0,0,0,0,0,0,0,0,4,0,12,12,12,0,0,0,0,0,0,0,0
0,0,4,0,0,0,0,0,0,0,0,0,0,4,0,12,16,12,0,0,0,0,0,0,0,0
0,0,5,0,0,0,0,0,0,0,0,0,0,5,0,0,17,0,0,0,0,0,0,0,0,0
0,0,32,4,23,0,0,11,11,0,0,23,4,30,0,0,0,0,0,0,0,0,0,0,0,0
0,0,40,40,5,4,4,4,4,4,4,5,40,30,0,0,0,0,0,0,0,0,0,0,0,0
0,0,0,0,0,41,0,0,0,0,41,0,0,0,0,0,0,0,0,0,0,0,0,0,0,0
0,0,0,0,0,0,0,0,0,0,0,0,0,0,0,0,0,0,0,0,0,0,0,0,0,0
0,0,0,0,0,0,0,0,0,0,0,0,0,0,0,0,0,0,0,0,0,0,0,0,0,0
0,0,0,0,0,0,0,0,0,0,0,0,0,0,0,0,0,0,0,0,0,0,0,0,0,0
0,0,0,0,0,0,0,0,0,0,0,0,0,0,0,0,0,0,0,0,0,0,0,0,0,0
endlayer

layer
1,1,1,1,1,1,1,1,1,1,1,1,1,1,1,1,1,1,1,1,1,1,1,1,1,1
1,1,1,1,1,1,1,1,1,1,1,1,1,1,1,1,1,1,1,1,1,1,1,1,1,1
1,1,1,1,1,1,1,1,1,1,1,1,1,1,1,2,2,1,1,1,1,1,1,1,1,1
1,1,1,1,1,1,1,1,1,1,1,1,1,3,3,3,3,3,3,1,1,1,1,1,1,0
1,0,0,0,1,1,1,1,1,1,1,2,3,3,3,3,3,3,3,3,1,1,1,1,1,0
0,0,0,0,0,1,1,1,1,1,2,3,3,3,3,3,3,3,3,3,3,1,1,1,0,0
0,0,0,0,0,0,0,0,0,1,1,2,3,3,3,3,3,3,3,3,3,3,1,1,0,0
0,0,0,0,0,0,0,0,0,0,0,0,3,3,3,3,3,3,3,3,3,1,1,0,0,0
0,0,0,0,0,22,0,0,0,0,22,0,3,3,3,3,3,3,3,3,3,0,0,0,0,0
0,0,0,0,0,15,0,0,0,0,15,0,0,0,3,3,3,3,3,3,0,0,0,0,0,0
0,0,0,0,5,4,4,4,4,4,4,5,0,0,0,3,3,3,0,0,0,0,0,0,0,0
0,0,0,4,0,0,0,0,0,0,0,0,4,0,0,0,0,0,0,0,0,0,0,0,0,0
0,0,5,0,0,0,0,0,0,0,0,0,0,5,0,0,0,0,0,0,0,0,0,0,0,0
0,0,4,0,0,0,0,0,0,0,0,0,0,4,0,0,0,0,0,0,0,0,0,0,0,0
0,0,4,0,0,0,0,0,0,0,0,0,0,4,0,12,12,12,0,0,0,0,0,0,0,0
0,0,4,0,0,0,0,0,0,0,0,22,0,4,0,12,12,12,0,0,0,0,0,0,0,0
0,0,5,0,0,0,0,0,0,0,0,15,0,5,0,0,0,0,0,0,0,0,0,0,0,0
29,4,4,0,0,0,42,0,0,0,0,0,0,4,0,0,0,0,0,0,0,0,0,0,0,0
4,44,43,0,0,0,42,0,0,0,0,0,0,4,0,0,18,0,0,0,0,0,0,0,0,0
29,4,4,0,0,0,42,0,0,0,0,0,0,4,0,0,0,0,0,0,0,0,0,0,0,0
0,0,5,0,0,0,0,0,0,0,0,0,0,5,0,0,0,0,0,0,0,0,0,0,0,0
0,0,4,0,0,0,0,0,0,0,0,0,0,4,0,12,12,12,0,0,0,0,0,0,0,0
0,0,4,0,0,0,0,0,0,0,0,0,0,4,0,12,12,12,0,0,0,0,0,0,0,0
0,0,4,0,0,0,0,0,0,0,0,0,0,4,0,0,16,0,0,0,0,0,0,0,0,0
0,0,5,0,0,0,0,0,0,0,0,0,0,5,0,0,0,0,0,0,0,0,0,0,0,0
0,0,0,4,0,0,0,0,0,0,0,0,4,0,0,0,0,0,0,0,0,0,0,0,0,0
0,0,0,0,5,4,4,4,4,4,4,5,0,0,0,0,0,0,0,0,0,0,0,0,0,0
0,0,0,0,0,39,0,0,0,0,39,0,0,0,0,0,0,0,0,0,0,0,0,0,0,0
0,0,0,0,0,41,0,0,0,0,41,0,0,0,0,0,0,0,0,0,0,0,0,0,0,0
0,0,0,0,0,0,0,0,0,0,0,0,0,0,0,0,0,0,0,0,0,0,0,0,0,0
0,0,0,0,0,0,0,0,0,0,0,0,0,0,0,0,0,0,0,0,0,0,0,0,0,0
0,0,0,0,0,0,0,0,0,0,0,0,0,0,0,0,0,0,0,0,0,0,0,0,0,0
endlayer

layer
0,0,0,0,0,0,0,0,0,0,0,1,1,1,1,1,1,1,1,1,1,1,1,1,1,1
0,0,0,0,0,0,0,0,0,0,1,1,1,1,1,1,1,1,1,1,1,1,1,1,1,1
0,0,0,0,0,0,0,0,0,0,1,1,1,1,1,1,1,1,1,1,1,1,1,1,0,0
0,0,0,0,0,0,0,0,0,1,1,1,1,2,2,2,3,3,1,1,1,1,1,0,0,0
0,0,0,0,0,0,0,0,1,1,1,1,8,3,3,3,3,3,3,1,1,1,1,0,0,0
0,0,0,0,0,0,0,0,1,1,1,3,3,3,3,3,3,3,3,3,3,1,1,0,0,0
0,0,0,0,0,0,0,0,0,0,0,0,3,3,3,3,3,3,3,3,3,1,1,0,0,0
0,0,0,0,0,22,0,0,0,0,22,0,3,3,3,3,3,3,3,3,3,1,0,0,0,0
0,0,0,0,0,15,0,0,0,0,15,0,0,3,3,3,3,3,3,3,3,0,0,0,0,0
0,0,0,0,0,0,0,0,0,0,0,0,0,0,3,3,3,3,0,3,0,0,0,0,0,0
0,0,29,35,5,4,4,4,4,4,4,5,35,45,0,0,0,0,0,0,0,0,0,0,0,0
0,0,29,4,0,0,0,0,0,0,0,0,4,45,0,0,0,0,0,0,0,0,0,0,0,0
0,0,5,0,0,0,0,0,0,0,0,0,0,5,0,0,0,0,0,0,0,0,0,0,0,0
0,0,4,0,0,0,0,0,0,0,0,0,0,4,0,0,0,0,0,0,0,0,0,0,0,0
0,0,4,0,0,0,0,0,0,0,0,22,0,4,0,12,0,12,0,0,0,0,0,0,0,0
0,0,4,0,0,0,0,0,0,0,0,15,0,4,0,12,12,12,0,0,0,0,0,0,0,0
0,0,5,0,0,0,0,0,0,0,0,0,0,5,0,12,12,12,0,0,0,0,0,0,0,0
4,4,4,0,0,0,0,0,0,0,0,0,0,4,0,12,12,12,0,0,0,0,0,0,0,0
4,0,43,0,0,0,0,0,0,0,0,0,0,4,0,0,18,0,0,0,0,0,0,0,0,0
4,4,4,0,0,0,0,0,0,0,0,0,0,4,0,12,12,12,0,0,0,0,0,0,0,0
0,0,5,0,0,0,0,0,0,0,0,0,0,5,0,12,12,12,0,0,0,0,0,0,0,0
0,0,4,0,0,0,0,0,0,0,0,0,0,4,0,12,12,12,0,0,0,0,0,0,0,0
0,0,4,0,0,0,0,0,0,0,0,0,0,4,0,12,46,12,0,0,0,0,0,0,0,0
0,0,4,0,0,0,0,0,0,0,0,0,0,4,0,0,17,0,0,0,0,0,0,0,0,0
0,0,5,0,0,0,0,0,0,0,0,0,0,5,0,0,0,0,0,0,0,0,0,0,0,0
0,0,29,4,0,0,0,0,0,0,0,0,4,45,0,0,0,0,0,0,0,0,0,0,0,0
0,0,38,38,5,4,4,4,4,4,4,5,38,45,0,0,0,0,0,0,0,0,0,0,0,0
0,0,0,0,0,0,0,0,0,0,0,0,0,0,0,0,0,0,0,0,0,0,0,0,0,0
0,0,0,0,0,39,0,0,0,0,39,0,0,0,0,0,0,0,0,0,0,0,0,0,0,0
0,0,0,0,0,41,0,0,0,0,41,0,0,0,0,0,0,0,0,0,0,0,0,0,0,0
0,0,0,0,0,0,0,0,0,0,0,0,0,0,0,0,0,0,0,0,0,0,0,0,0,0
0,0,0,0,0,0,0,0,0,0,0,0,0,0,0,0,0,0,0,0,0,0,0,0,0,0
endlayer

layer
0,0,0,0,0,0,0,0,0,0,0,0,1,1,1,1,1,1,1,1,1,1,1,1,1,0
0,0,0,0,0,0,0,0,0,0,0,1,1,1,1,1,1,1,1,1,1,1,1,1,0,0
0,0,0,0,0,0,0,0,0,0,0,1,1,1,1,1,1,1,1,1,1,1,1,0,0,0
0,0,0,0,0,0,0,0,0,0,0,0,1,1,1,1,3,3,1,1,1,1,0,0,0,0
0,0,0,0,0,0,12,12,12,12,12,12,12,2,3,3,3,3,3,1,1,1,0,0,0,0
0,0,0,0,0,0,12,12,12,12,12,12,3,3,3,3,3,3,3,3,3,1,0,0,0,0
0,0,0,0,5,19,19,19,19,19,19,5,3,3,3,3,3,3,3,3,3,1,0,0,0,0
0,0,0,0,20,12,12,12,12,12,12,20,0,3,3,3,3,3,3,3,3,0,0,0,0,0
0,0,0,0,20,12,12,12,12,12,12,20,0,3,3,3,3,3,3,3,0,0,0,0,0,0
0,0,0,0,20,12,12,12,12,12,12,20,0,0,0,3,3,3,0,0,0,0,0,0,0,0
0,0,5,19,19,19,19,19,19,19,19,19,19,5,0,38,0,38,0,0,0,0,0,0,0,0
0,0,20,5,19,19,19,19,19,19,19,19,5,20,0,0,0,0,0,0,0,0,0,0,0,0
0,0,20,20,12,12,12,12,12,12,12,13,20,20,0,0,0,0,0,0,0,0,0,0,0,0
0,0,20,20,12,12,12,12,12,12,12,13,20,20,0,0,0,0,0,0,0,0,0,0,0,0
0,0,20,20,12,12,12,12,12,12,12,15,20,20,0,0,0,0,0,0,0,0,0,0,0,0
0,0,20,20,12,12,12,12,12,12,12,0,20,20,0,0,0,0,0,0,0,0,0,0,0,0
0,0,20,20,12,12,12,12,12,12,12,0,20,20,0,12,0,12,0,0,0,0,0,0,0,0
4,4,4,47,12,12,12,12,12,12,12,0,20,20,0,12,12,12,0,0,0,0,0,0,0,0
4,0,4,47,12,12,12,12,12,12,12,12,20,20,0,12,12,12,0,0,0,0,0,0,0,0
4,4,4,47,12,12,12,12,12,12,12,12,20,20,0,12,12,12,0,0,0,0,0,0,0,0
0,0,20,20,12,12,12,12,12,12,12,12,20,20,0,12,48,12,0,0,0,0,0,0,0,0
0,0,20,20,12,12,12,12,12,12,12,12,20,20,0,0,17,0,0,0,0,0,0,0,0,0
0,0,20,20,12,12,12,12,12,12,12,12,20,20,0,0,49,0,0,0,0,0,0,0,0,0
0,0,20,20,12,12,12,12,12,12,12,12,20,20,0,0,0,0,0,0,0,0,0,0,0,0
0,0,20,20,12,12,12,12,12,12,12,12,20,20,0,0,0,0,0,0,0,0,0,0,0,0
0,0,20,5,19,19,19,19,19,19,19,19,5,20,0,0,0,0,0,0,0,0,0,0,0,0
0,0,5,19,19,19,19,19,19,19,19,19,19,5,0,0,0,0,0,0,0,0,0,0,0,0
0,0,0,0,20,12,12,12,12,12,12,20,0,0,0,0,0,0,0,0,0,0,0,0,0,0
0,0,0,0,20,12,12,12,12,12,12,20,0,0,0,0,0,0,0,0,0,0,0,0,0,0
0,0,0,0,20,12,12,12,12,12,12,20,0,0,0,0,0,0,0,0,0,0,0,0,0,0
0,0,0,0,5,19,19,19,19,19,19,5,0,0,0,0,0,0,0,0,0,0,0,0,0,0
0,0,0,0,0,0,12,12,12,12,0,0,0,0,0,0,0,0,0,0,0,0,0,0,0,0
endlayer

layer
0,0,0,0,0,0,0,0,0,0,0,0,0,1,1,1,1,1,1,1,1,1,1,0,0,0
0,0,0,0,0,0,0,0,0,0,0,0,0,1,1,1,1,1,1,1,1,1,1,0,0,0
0,0,0,0,0,0,0,0,0,0,0,0,0,1,1,1,1,1,1,1,1,1,0,0,0,0
0,0,0,0,0,0,0,0,0,0,0,0,0,1,1,1,3,1,1,1,1,0,0,0,0,0
0,0,0,0,0,0,21,21,21,21,21,21,21,21,3,3,3,3,1,1,1,0,0,0,0,0
0,0,0,0,0,0,21,0,0,0,0,0,0,3,3,3,3,3,3,3,3,1,0,0,0,0
0,0,0,0,5,50,47,51,51,47,50,5,0,3,3,3,3,3,3,3,3,0,0,0,0,0
0,0,0,0,50,0,0,0,0,0,0,50,0,3,3,3,3,3,3,3,0,0,0,0,0,0
0,0,0,0,47,11,0,0,0,0,11,47,0,0,3,3,3,3,3,3,0,0,0,0,0,0
0,0,0,0,50,23,0,0,0,0,23,50,0,0,0,0,3,3,0,0,0,0,0,0,0,0
0,0,5,50,5,12,5,0,0,5,12,5,50,5,0,31,0,31,0,0,0,0,0,0,0,0
0,0,50,0,0,0,0,0,0,0,0,0,0,50,0,38,0,38,0,0,0,0,0,0,0,0
0,0,5,0,0,0,0,0,0,0,0,0,0,5,0,0,0,0,0,0,0,0,0,0,0,0
0,0,50,0,0,0,0,0,0,0,0,0,0,50,0,0,0,0,0,0,0,0,0,0,0,0
0,0,47,0,0,0,0,0,0,0,0,0,0,47,0,0,0,0,0,0,0,0,0,0,0,0
0,0,50,52,52,52,52,0,0,0,22,0,0,50,0,0,0,0,0,0,0,0,0,0,0,0
0,0,5,52,53,53,52,0,0,0,15,0,0,5,0,0,0,0,0,0,0,0,0,0,0,0
4,4,4,0,0,0,0,0,52,52,0,0,0,50,0,0,0,0,0,0,0,0,0,0,0,0
4,0,36,0,0,0,0,0,53,52,0,0,0,47,0,12,0,12,0,0,0,0,0,0,0,0
4,4,4,0,0,0,0,0,52,52,0,0,0,50,0,0,0,0,0,0,0,0,0,0,0,0
0,0,5,52,53,53,52,0,0,0,0,0,0,5,0,0,48,0,0,0,0,0,0,0,0,0
0,0,50,52,52,52,52,0,0,0,0,0,0,50,0,0,0,0,0,0,0,0,0,0,0,0
0,0,47,0,0,0,0,0,0,0,0,0,0,47,0,0,0,0,0,0,0,0,0,0,0,0
0,0,50,0,0,0,0,0,0,0,0,0,0,50,0,0,0,0,0,0,0,0,0,0,0,0
0,0,5,0,0,0,0,0,0,0,0,0,0,5,0,0,0,0,0,0,0,0,0,0,0,0
0,0,50,0,0,0,0,0,0,0,0,0,0,50,0,0,0,0,0,0,0,0,0,0,0,0
0,0,5,50,5,12,5,0,0,5,12,5,50,5,0,0,0,0,0,0,0,0,0,0,0,0
0,0,0,0,50,23,0,0,0,0,23,50,0,0,0,0,0,0,0,0,0,0,0,0,0,0
0,0,0,0,47,57,56,0,0,55,54,47,0,0,0,0,0,0,0,0,0,0,0,0,0,0
0,0,0,0,50,11,0,0,0,0,11,50,0,0,0,0,0,0,0,0,0,0,0,0,0,0
0,0,0,0,5,50,47,25,25,47,50,5,0,0,0,0,0,0,0,0,0,0,0,0,0,0
0,0,0,0,0,0,21,21,21,21,0,0,0,0,0,0,0,0,0,0,0,0,0,0,0,0
endlayer

layer
0,0,0,0,0,0,0,0,0,0,0,0,0,0,1,1,1,1,1,1,0,0,0,0,0,0
0,0,0,0,0,0,0,0,0,0,0,0,0,1,1,1,1,1,1,1,1,0,0,0,0,0
0,0,0,0,0,0,0,0,0,0,0,0,0,1,1,1,1,1,1,1,1,0,0,0,0,0
0,0,0,0,0,0,0,0,0,0,0,0,0,0,1,1,1,1,1,1,0,0,0,0,0,0
0,0,0,0,0,0,0,0,0,0,0,0,0,1,1,3,3,3,1,1,1,0,0,0,0,0
0,0,0,0,0,0,0,0,0,0,0,0,0,1,3,3,3,3,3,3,3,0,0,0,0,0
0,0,0,0,5,50,5,27,58,5,50,5,0,3,3,3,3,3,3,3,0,0,0,0,0,0
0,0,0,0,50,0,0,0,0,0,0,50,0,0,3,3,3,3,3,3,0,0,0,0,0,0
0,0,0,0,26,0,0,0,0,0,0,26,0,0,3,3,3,3,3,3,0,0,0,0,0,0
0,0,0,0,50,0,0,0,0,0,0,50,0,0,0,0,0,0,0,0,0,0,0,0,0,0
0,0,5,50,5,12,5,0,0,5,12,5,50,5,0,0,0,0,0,0,0,0,0,0,0,0
0,0,50,0,0,0,0,0,0,0,0,0,0,50,0,31,0,31,0,0,0,0,0,0,0,0
0,0,5,0,0,0,0,0,0,0,0,0,0,5,0,38,0,38,0,0,0,0,0,0,0,0
0,0,50,0,0,0,0,0,0,0,0,0,0,50,0,0,0,0,0,0,0,0,0,0,0,0
0,0,26,0,0,0,0,0,0,0,22,0,0,26,0,0,0,0,0,0,0,0,0,0,0,0
0,0,50,0,0,0,0,0,0,0,15,0,0,50,0,0,0,0,0,0,0,0,0,0,0,0
0,0,5,0,0,0,0,0,0,0,0,0,0,5,0,0,0,0,0,0,0,0,0,0,0,0
4,4,4,0,0,0,0,0,0,0,0,0,0,50,0,0,0,0,0,0,0,0,0,0,0,0
4,0,43,0,0,0,0,0,0,0,0,0,0,26,0,0,0,0,0,0,0,0,0,0,0,0
4,4,4,0,0,0,0,0,0,0,0,0,0,50,0,0,0,0,0,0,0,0,0,0,0,0
0,0,5,0,0,0,0,0,0,0,0,0,0,5,0,0,48,0,0,0,0,0,0,0,0,0
0,0,50,0,0,0,0,0,0,0,0,0,0,50,0,0,0,0,0,0,0,0,0,0,0,0
0,0,26,0,0,0,0,0,0,0,0,0,0,26,0,0,0,0,0,0,0,0,0,0,0,0
0,0,50,0,0,0,0,0,0,0,0,0,0,50,0,0,0,0,0,0,0,0,0,0,0,0
0,0,5,0,0,0,0,0,0,0,0,0,0,5,0,0,0,0,0,0,0,0,0,0,0,0
0,0,50,0,0,0,0,0,0,0,0,0,0,50,0,0,0,0,0,0,0,0,0,0,0,0
0,0,5,50,5,12,5,0,0,5,12,5,50,5,0,0,0,0,0,0,0,0,0,0,0,0
0,0,0,0,50,0,0,0,0,0,0,50,0,0,0,0,0,0,0,0,0,0,0,0,0,0
0,0,0,0,26,0,0,0,0,0,0,26,0,0,0,0,0,0,0,0,0,0,0,0,0,0
0,0,0,0,50,0,0,0,0,0,0,50,0,0,0,0,0,0,0,0,0,0,0,0,0,0
0,0,0,0,5,50,5,58,27,5,50,5,0,0,0,0,0,0,0,0,0,0,0,0,0,0
0,0,0,0,0,0,0,0,0,0,0,0,0,0,0,0,0,0,0,0,0,0,0,0,0,0
endlayer

layer
0,0,0,0,0,0,0,0,0,0,0,0,0,0,1,1,1,1,1,1,0,0,0,0,0,0
0,0,0,0,0,0,0,0,0,0,0,0,0,1,1,1,1,1,1,0,0,0,0,0,0,0
0,0,0,0,0,0,0,0,0,0,0,0,0,0,1,1,1,1,1,0,0,0,0,0,0,0
0,0,0,0,0,0,0,0,0,0,0,0,0,0,1,1,1,1,1,0,0,0,0,0,0,0
0,0,0,0,0,0,0,0,0,0,0,0,0,0,1,1,3,1,1,1,0,0,0,0,0,0
0,0,0,0,0,0,0,0,0,0,0,0,0,0,3,3,3,3,3,3,0,0,0,0,0,0
0,0,0,0,5,50,47,19,19,47,50,5,0,0,3,3,3,3,3,3,0,0,0,0,0,0
0,0,0,0,50,0,0,0,0,0,0,50,0,0,3,3,3,3,3,3,0,0,0,0,0,0
0,0,0,0,26,0,0,0,0,0,0,26,0,0,3,3,3,3,3,0,0,0,0,0,0,0
0,0,0,0,50,0,0,0,0,0,0,50,0,0,0,13,13,13,0,0,0,0,0,0,0,0
0,0,5,50,5,12,5,0,0,5,12,5,50,5,0,13,13,13,0,0,0,0,0,0,0,0
0,0,50,0,0,0,0,0,0,0,0,0,0,50,0,13,13,13,0,0,0,0,0,0,0,0
0,0,5,0,0,0,0,0,0,0,0,0,0,5,0,13,13,13,0,0,0,0,0,0,0,0
0,0,50,0,0,0,0,0,0,0,22,0,0,50,0,13,13,13,0,0,0,0,0,0,0,0
0,0,26,0,0,0,0,0,0,0,15,0,0,26,0,13,13,13,0,0,0,0,0,0,0,0
0,0,50,0,0,0,0,0,0,0,0,0,0,50,0,13,13,13,0,0,0,0,0,0,0,0
0,0,5,0,0,0,0,0,0,0,0,0,0,5,0,13,13,13,0,0,0,0,0,0,0,0
4,4,4,0,0,0,0,0,0,0,0,0,0,50,0,13,13,13,0,0,0,0,0,0,0,0
4,0,43,0,0,0,0,0,0,0,0,0,0,26,0,13,13,13,0,0,0,0,0,0,0,0
4,4,4,0,0,0,0,0,0,0,0,0,0,50,0,13,13,13,0,0,0,0,0,0,0,0
0,0,5,0,0,0,0,0,0,0,0,0,0,5,0,0,48,0,0,0,0,0,0,0,0,0
0,0,50,0,0,0,0,0,0,0,0,0,0,50,0,0,0,0,0,0,0,0,0,0,0,0
0,0,26,0,0,0,0,0,0,0,0,0,0,26,0,0,0,0,0,0,0,0,0,0,0,0
0,0,50,0,0,0,0,0,0,0,0,0,0,50,0,0,0,0,0,0,0,0,0,0,0,0
0,0,5,0,0,0,0,0,0,0,0,0,0,5,0,0,0,0,0,0,0,0,0,0,0,0
0,0,50,0,0,0,0,0,0,0,0,0,0,50,0,0,0,0,0,0,0,0,0,0,0,0
0,0,5,50,5,12,5,0,0,5,12,5,50,5,0,0,0,0,0,0,0,0,0,0,0,0
0,0,0,0,50,0,0,0,0,0,0,50,0,0,0,0,0,0,0,0,0,0,0,0,0,0
0,0,0,0,26,0,0,0,0,0,0,26,0,0,0,0,0,0,0,0,0,0,0,0,0,0
0,0,0,0,50,0,0,0,0,0,0,50,0,0,0,0,0,0,0,0,0,0,0,0,0,0
0,0,0,0,5,50,47,19,19,47,50,5,0,0,0,0,0,0,0,0,0,0,0,0,0,0
0,0,0,0,0,0,0,0,0,0,0,0,0,0,0,0,0,0,0,0,0,0,0,0,0,0
endlayer

layer
0,0,0,0,0,0,0,0,0,0,0,0,0,0,1,1,1,1,1,0,0,0,0,0,0,0
0,0,0,0,0,0,0,0,0,0,0,0,0,0,1,1,1,1,1,0,0,0,0,0,0,0
0,0,0,0,0,0,0,0,0,0,0,0,0,0,0,1,1,1,1,0,0,0,0,0,0,0
0,0,0,0,0,0,0,0,0,0,0,0,0,0,0,1,1,1,1,0,0,0,0,0,0,0
0,0,0,0,0,0,0,0,0,0,0,0,0,0,1,1,1,1,1,0,0,0,0,0,0,0
0,0,0,59,59,59,59,59,59,59,59,59,59,0,1,3,3,3,3,0,0,0,0,0,0,0
0,0,0,59,5,19,19,19,19,19,19,5,59,0,3,3,3,3,3,0,0,0,0,0,0,0
0,0,0,0,20,0,0,0,0,0,0,20,0,0,3,3,6,3,3,0,0,0,0,0,0,0
0,0,0,0,20,0,0,0,0,0,0,20,0,0,0,13,6,13,0,0,0,0,0,0,0,0
0,0,0,0,20,0,0,0,0,0,0,20,0,0,0,13,6,13,0,0,0,0,0,0,0,0
0,0,5,19,19,19,19,19,19,19,19,19,19,5,0,13,6,13,0,0,0,0,0,0,0,0
0,0,20,12,20,12,12,12,12,12,12,20,12,20,0,13,6,13,0,0,0,0,0,0,0,0
0,0,20,19,20,19,19,19,19,19,19,20,19,20,0,13,6,13,0,0,0,0,0,0,0,0
0,0,20,12,20,0,0,0,0,0,15,20,12,20,0,13,6,13,0,0,0,0,0,0,0,0
0,0,20,12,20,0,0,0,0,0,0,20,12,20,0,13,17,13,0,0,0,0,0,0,0,0
0,0,20,12,20,0,0,0,0,0,0,20,12,20,0,13,49,13,0,0,0,0,0,0,0,0
0,0,20,12,20,0,0,0,0,0,0,20,12,20,0,13,60,13,0,0,0,0,0,0,0,0
4,4,4,47,20,0,0,0,0,0,0,20,12,20,0,13,61,13,0,0,0,0,0,0,0,0
4,0,4,47,20,0,0,0,0,0,0,20,12,20,0,13,62,13,0,0,0,0,0,0,0,0
4,4,4,47,20,0,0,0,0,0,0,20,12,20,0,13,63,13,0,0,0,0,0,0,0,0
0,0,20,12,20,0,0,0,0,0,0,20,12,20,0,0,64,0,0,0,0,0,0,0,0,0
0,0,20,12,20,0,0,0,0,0,0,20,12,20,0,0,0,0,0,0,0,0,0,0,0,0
0,0,20,12,20,0,0,0,0,0,0,20,12,20,0,0,0,0,0,0,0,0,0,0,0,0
0,0,20,12,20,0,0,0,0,0,0,20,12,20,0,0,0,0,0,0,0,0,0,0,0,0
0,0,20,19,20,19,19,19,19,19,19,20,19,20,0,0,0,0,0,0,0,0,0,0,0,0
0,0,20,12,20,12,12,12,12,12,12,20,12,20,0,0,0,0,0,0,0,0,0,0,0,0
0,0,5,19,19,19,19,19,19,19,19,19,19,5,0,0,0,0,0,0,0,0,0,0,0,0
0,0,0,0,20,0,0,0,0,0,0,20,0,0,0,0,0,0,0,0,0,0,0,0,0,0
0,0,0,0,20,0,0,0,0,0,0,20,0,0,0,0,0,0,0,0,0,0,0,0,0,0
0,0,0,0,20,0,0,0,0,0,0,20,0,0,0,0,0,0,0,0,0,0,0,0,0,0
0,0,0,59,5,19,19,19,19,19,19,5,59,0,0,0,0,0,0,0,0,0,0,0,0,0
0,0,0,59,59,59,59,59,59,59,59,59,59,0,0,0,0,0,0,0,0,0,0,0,0,0
endlayer

layer
0,0,0,0,0,0,0,0,0,0,0,0,0,0,1,1,1,1,1,0,0,0,0,0,0,0
0,0,0,0,0,0,0,0,0,0,0,0,0,0,0,1,1,1,0,0,0,0,0,0,0,0
0,0,0,0,0,0,0,0,0,0,0,0,0,0,0,1,1,1,0,0,0,0,0,0,0,0
0,0,0,0,0,0,0,0,0,0,0,0,0,0,0,1,1,1,0,0,0,0,0,0,0,0
0,0,0,0,0,0,0,0,0,0,0,0,0,0,0,1,1,1,0,0,0,0,0,0,0,0
0,0,0,0,0,0,0,0,0,0,0,0,0,0,0,1,1,1,0,0,0,0,0,0,0,0
0,0,0,65,65,65,65,65,65,65,65,65,65,0,0,3,3,3,0,0,0,0,0,0,0,0
0,0,0,66,50,67,67,67,67,67,67,50,66,0,0,3,6,3,0,0,0,0,0,0,0,0
0,0,0,0,50,0,0,0,0,0,0,50,0,0,0,0,17,0,0,0,0,0,0,0,0,0
0,0,0,0,50,0,0,0,0,0,0,50,0,0,0,0,0,0,0,0,0,0,0,0,0,0
0,0,5,50,5,12,12,5,5,12,12,5,50,5,0,0,0,0,0,0,0,0,0,0,0,0
0,0,50,0,0,0,0,0,0,0,0,0,0,50,0,0,0,0,0,0,0,0,0,0,0,0
0,0,5,0,21,21,21,21,21,21,0,21,0,5,0,0,0,0,0,0,0,0,0,0,0,0
0,0,50,0,21,0,0,0,0,0,0,21,0,50,0,0,0,0,0,0,0,0,0,0,0,0
0,0,47,0,21,0,0,0,0,0,0,21,0,47,0,0,0,0,0,0,0,0,0,0,0,0
0,0,50,0,21,0,0,0,0,0,0,21,0,50,0,0,0,0,0,0,0,0,0,0,0,0
0,0,5,0,21,0,0,0,0,0,0,21,0,5,0,0,0,0,0,0,0,0,0,0,0,0
4,4,4,0,21,0,0,0,0,0,0,21,0,50,0,0,0,0,0,0,0,0,0,0,0,0
4,0,43,0,21,0,0,0,0,0,0,21,0,47,0,21,0,21,0,0,0,0,0,0,0,0
4,4,4,0,21,0,0,0,0,0,0,21,68,50,0,0,0,0,0,0,0,0,0,0,0,0
0,0,5,0,21,0,0,0,0,0,0,21,0,5,0,0,0,0,0,0,0,0,0,0,0,0
0,0,50,0,21,0,0,0,0,0,0,21,0,50,0,0,0,0,0,0,0,0,0,0,0,0
0,0,47,0,21,0,0,0,0,0,0,21,0,47,0,0,0,0,0,0,0,0,0,0,0,0
0,0,50,0,21,0,0,0,0,0,0,21,0,50,0,0,0,0,0,0,0,0,0,0,0,0
0,0,5,0,21,21,21,21,21,21,21,21,0,5,0,0,0,0,0,0,0,0,0,0,0,0
0,0,50,0,0,0,0,0,0,0,0,0,0,50,0,0,0,0,0,0,0,0,0,0,0,0
0,0,5,50,5,12,12,5,5,12,12,5,50,5,0,0,0,0,0,0,0,0,0,0,0,0
0,0,0,0,50,0,0,0,0,0,0,50,0,0,0,0,0,0,0,0,0,0,0,0,0,0
0,0,0,0,50,0,0,0,0,0,0,50,0,0,0,0,0,0,0,0,0,0,0,0,0,0
0,0,0,69,50,67,67,67,67,67,67,50,69,0,0,0,0,0,0,0,0,0,0,0,0,0
0,0,0,70,70,70,70,70,70,70,70,70,70,0,0,0,0,0,0,0,0,0,0,0,0,0
0,0,0,0,0,0,0,0,0,0,0,0,0,0,0,0,0,0,0,0,0,0,0,0,0,0
endlayer

layer
0,0,0,0,0,0,0,0,0,0,0,0,0,0,0,1,1,1,0,0,0,0,0,0,0,0
0,0,0,0,0,0,0,0,0,0,0,0,0,0,0,1,1,0,0,0,0,0,0,0,0,0
0,0,0,0,0,0,0,0,0,0,0,0,0,0,0,0,1,0,0,0,0,0,0,0,0,0
0,0,0,0,0,0,0,0,0,0,0,0,0,0,0,0,1,0,0,0,0,0,0,0,0,0
0,0,0,0,0,0,0,0,0,0,0,0,0,0,0,0,0,0,0,0,0,0,0,0,0,0
0,0,0,0,0,0,0,0,0,0,0,0,0,0,0,0,0,0,0,0,0,0,0,0,0,0
0,0,0,0,0,0,0,0,0,0,0,0,0,0,0,0,0,0,0,0,0,0,0,0,0,0
0,0,0,65,65,65,65,65,65,65,65,65,65,0,0,0,0,0,0,0,0,0,0,0,0,0
0,0,0,66,50,67,67,67,67,67,67,50,66,0,0,0,0,0,0,0,0,0,0,0,0,0
0,0,0,0,50,0,0,0,0,0,0,50,0,0,0,0,0,0,0,0,0,0,0,0,0,0
0,0,5,50,5,12,12,5,5,12,12,5,50,5,0,0,0,0,0,0,0,0,0,0,0,0
0,0,50,0,0,0,0,0,0,0,0,0,0,50,0,0,0,0,0,0,0,0,0,0,0,0
0,0,5,0,0,0,0,0,0,0,0,0,0,5,0,0,0,0,0,0,0,0,0,0,0,0
0,0,50,0,0,0,0,0,0,0,0,0,0,50,0,0,0,0,0,0,0,0,0,0,0,0
0,0,26,0,0,0,0,0,0,0,0,0,0,26,0,0,0,0,0,0,0,0,0,0,0,0
0,0,50,0,0,0,0,0,0,0,0,0,0,50,0,0,0,0,0,0,0,0,0,0,0,0
0,0,5,0,0,0,0,0,0,0,0,0,0,5,0,0,0,0,0,0,0,0,0,0,0,0
4,4,4,0,0,0,0,0,0,0,0,0,0,50,0,0,0,0,0,0,0,0,0,0,0,0
4,0,43,0,0,0,0,0,0,0,0,0,0,26,0,21,0,21,0,0,0,0,0,0,0,0
4,4,4,0,0,0,0,0,0,0,0,0,68,50,0,0,0,0,0,0,0,0,0,0,0,0
0,0,5,0,0,0,0,0,0,0,0,0,0,5,0,0,0,0,0,0,0,0,0,0,0,0
0,0,50,0,0,0,0,0,0,0,0,0,0,50,0,0,0,0,0,0,0,0,0,0,0,0
0,0,26,0,0,0,0,0,0,0,0,0,0,26,0,0,0,0,0,0,0,0,0,0,0,0
0,0,50,0,0,0,0,0,0,0,0,0,0,50,0,0,0,0,0,0,0,0,0,0,0,0
0,0,5,0,0,0,0,0,0,0,0,0,0,5,0,0,0,0,0,0,0,0,0,0,0,0
0,0,50,0,0,0,0,0,0,0,0,0,0,50,0,0,0,0,0,0,0,0,0,0,0,0
0,0,5,50,5,12,12,5,5,12,12,5,50,5,0,0,0,0,0,0,0,0,0,0,0,0
0,0,0,0,50,0,0,0,0,0,0,50,0,0,0,0,0,0,0,0,0,0,0,0,0,0
0,0,0,69,50,67,67,67,67,67,67,50,69,0,0,0,0,0,0,0,0,0,0,0,0,0
0,0,0,70,70,70,70,70,70,70,70,70,70,0,0,0,0,0,0,0,0,0,0,0,0,0
0,0,0,0,0,0,0,0,0,0,0,0,0,0,0,0,0,0,0,0,0,0,0,0,0,0
0,0,0,0,0,0,0,0,0,0,0,0,0,0,0,0,0,0,0,0,0,0,0,0,0,0
endlayer

layer
0,0,0,0,0,0,0,0,0,0,0,0,0,0,0,0,0,0,0,0,0,0,0,0,0,0
0,0,0,0,0,0,0,0,0,0,0,0,0,0,0,0,0,0,0,0,0,0,0,0,0,0
0,0,0,0,0,0,0,0,0,0,0,0,0,0,0,0,0,0,0,0,0,0,0,0,0,0
0,0,0,0,0,0,0,0,0,0,0,0,0,0,0,0,0,0,0,0,0,0,0,0,0,0
0,0,0,0,0,0,0,0,0,0,0,0,0,0,0,0,0,0,0,0,0,0,0,0,0,0
0,0,0,0,0,0,0,0,0,0,0,0,0,0,0,0,0,0,0,0,0,0,0,0,0,0
0,0,0,0,0,0,0,0,0,0,0,0,0,0,0,0,0,0,0,0,0,0,0,0,0,0
0,0,0,0,0,0,0,0,0,0,0,0,0,0,0,0,0,0,0,0,0,0,0,0,0,0
0,0,0,65,65,65,65,65,65,65,65,65,65,0,0,0,0,0,0,0,0,0,0,0,0,0
0,0,0,66,50,67,67,67,67,67,67,50,66,0,0,0,0,0,0,0,0,0,0,0,0,0
0,0,5,50,5,12,12,5,5,12,12,5,50,5,0,0,0,0,0,0,0,0,0,0,0,0
0,0,50,0,0,0,0,0,0,0,0,0,0,50,0,0,0,0,0,0,0,0,0,0,0,0
0,0,5,0,0,0,0,0,0,0,0,0,0,5,0,0,0,0,0,0,0,0,0,0,0,0
0,0,50,0,0,0,0,0,0,0,0,0,0,50,0,0,0,0,0,0,0,0,0,0,0,0
0,0,26,0,0,0,0,0,0,0,0,0,0,26,0,0,0,0,0,0,0,0,0,0,0,0
0,0,50,0,0,0,0,0,0,0,0,0,0,50,0,0,0,0,0,0,0,0,0,0,0,0
0,0,5,0,0,0,0,0,0,0,0,0,0,5,0,0,0,0,0,0,0,0,0,0,0,0
4,4,4,0,0,0,0,0,0,0,0,0,0,50,0,0,0,0,0,0,0,0,0,0,0,0
4,0,4,0,0,0,0,0,0,0,0,0,0,26,0,21,0,21,0,0,0,0,0,0,0,0
4,4,4,0,0,0,0,0,0,0,0,0,68,50,0,0,0,0,0,0,0,0,0,0,0,0
0,0,5,0,0,0,0,0,0,0,0,0,0,5,0,0,0,0,0,0,0,0,0,0,0,0
0,0,50,0,0,0,0,0,0,0,0,0,0,50,0,0,0,0,0,0,0,0,0,0,0,0
0,0,26,0,0,0,0,0,0,0,0,0,0,26,0,0,0,0,0,0,0,0,0,0,0,0
0,0,50,0,0,0,0,0,0,0,0,0,0,50,0,0,0,0,0,0,0,0,0,0,0,0
0,0,5,0,0,0,0,0,0,0,0,0,0,5,0,0,0,0,0,0,0,0,0,0,0,0
0,0,50,0,0,0,0,0,0,0,0,0,0,50,0,0,0,0,0,0,0,0,0,0,0,0
0,0,5,50,5,12,12,5,5,12,12,5,50,5,0,0,0,0,0,0,0,0,0,0,0,0
0,0,0,69,50,67,67,67,67,67,67,50,69,0,0,0,0,0,0,0,0,0,0,0,0,0
0,0,0,70,70,70,70,70,70,70,70,70,70,0,0,0,0,0,0,0,0,0,0,0,0,0
0,0,0,0,0,0,0,0,0,0,0,0,0,0,0,0,0,0,0,0,0,0,0,0,0,0
0,0,0,0,0,0,0,0,0,0,0,0,0,0,0,0,0,0,0,0,0,0,0,0,0,0
0,0,0,0,0,0,0,0,0,0,0,0,0,0,0,0,0,0,0,0,0,0,0,0,0,0
endlayer

layer
0,0,0,0,0,0,0,0,0,0,0,0,0,0,0,0,0,0,0,0,0,0,0,0,0,0
0,0,0,0,0,0,0,0,0,0,0,0,0,0,0,0,0,0,0,0,0,0,0,0,0,0
0,0,0,0,0,0,0,0,0,0,0,0,0,0,0,0,0,0,0,0,0,0,0,0,0,0
0,0,0,0,0,0,0,0,0,0,0,0,0,0,0,0,0,0,0,0,0,0,0,0,0,0
0,0,0,0,0,0,0,0,0,0,0,0,0,0,0,0,0,0,0,0,0,0,0,0,0,0
0,0,0,0,0,0,0,0,0,0,0,0,0,0,0,0,0,0,0,0,0,0,0,0,0,0
0,0,0,0,0,0,0,0,0,0,0,0,0,0,0,0,0,0,0,0,0,0,0,0,0,0
0,0,0,0,0,0,0,0,0,0,0,0,0,0,0,0,0,0,0,0,0,0,0,0,0,0
0,0,0,0,0,0,0,0,0,0,0,0,0,0,0,0,0,0,0,0,0,0,0,0,0,0
0,74,73,65,65,65,65,65,65,65,65,65,65,72,71,0,0,0,0,0,0,0,0,0,0,0
0,74,5,19,5,19,19,19,19,19,19,5,19,5,71,0,0,0,0,0,0,0,0,0,0,0
0,74,20,0,0,0,0,0,0,0,0,0,0,20,71,0,0,0,0,0,0,0,0,0,0,0
0,74,5,0,0,0,0,0,0,0,0,0,0,5,71,0,0,0,0,0,0,0,0,0,0,0
0,74,20,0,0,0,0,0,0,0,0,0,0,20,71,0,0,0,0,0,0,0,0,0,0,0
0,74,20,0,0,0,0,0,0,0,0,0,0,20,71,0,0,0,0,0,0,0,0,0,0,0
0,74,20,0,0,0,0,0,0,0,0,0,0,20,71,0,0,0,0,0,0,0,0,0,0,0
0,74,5,12,12,12,12,12,12,12,12,12,12,5,71,0,0,0,0,0,0,0,0,0,0,0
4,4,4,12,12,12,12,12,12,12,12,12,12,20,71,0,0,0,0,0,0,0,0,0,0,0
4,0,4,19,19,19,19,19,19,19,19,19,19,19,19,19,19,19,19,0,0,0,0,0,0,0
4,4,4,12,12,12,12,12,12,12,12,12,68,20,71,0,0,0,0,0,0,0,0,0,0,0
0,74,5,12,12,12,12,12,12,12,12,12,12,5,71,0,0,0,0,0,0,0,0,0,0,0
0,74,20,0,0,0,0,0,0,0,0,0,0,20,71,0,0,0,0,0,0,0,0,0,0,0
0,74,20,0,0,0,0,0,0,0,0,0,0,20,71,0,0,0,0,0,0,0,0,0,0,0
0,74,20,0,0,0,0,0,0,0,0,0,0,20,71,0,0,0,0,0,0,0,0,0,0,0
0,74,5,0,0,0,0,0,0,0,0,0,0,5,71,0,0,0,0,0,0,0,0,0,0,0
0,74,20,0,0,0,0,0,0,0,0,0,0,20,71,0,0,0,0,0,0,0,0,0,0,0
0,74,5,19,5,19,19,19,19,19,19,5,19,5,71,0,0,0,0,0,0,0,0,0,0,0
0,74,73,70,70,70,70,70,70,70,70,70,70,72,71,0,0,0,0,0,0,0,0,0,0,0
0,0,0,0,0,0,0,0,0,0,0,0,0,0,0,0,0,0,0,0,0,0,0,0,0,0
0,0,0,0,0,0,0,0,0,0,0,0,0,0,0,0,0,0,0,0,0,0,0,0,0,0
0,0,0,0,0,0,0,0,0,0,0,0,0,0,0,0,0,0,0,0,0,0,0,0,0,0
0,0,0,0,0,0,0,0,0,0,0,0,0,0,0,0,0,0,0,0,0,0,0,0,0,0
endlayer

layer
0,0,0,0,0,0,0,0,0,0,0,0,0,0,0,0,0,0,0,0,0,0,0,0,0,0
0,0,0,0,0,0,0,0,0,0,0,0,0,0,0,0,0,0,0,0,0,0,0,0,0,0
0,0,0,0,0,0,0,0,0,0,0,0,0,0,0,0,0,0,0,0,0,0,0,0,0,0
0,0,0,0,0,0,0,0,0,0,0,0,0,0,0,0,0,0,0,0,0,0,0,0,0,0
0,0,0,0,0,0,0,0,0,0,0,0,0,0,0,0,0,0,0,0,0,0,0,0,0,0
0,0,0,0,0,0,0,0,0,0,0,0,0,0,0,0,0,0,0,0,0,0,0,0,0,0
0,0,0,0,0,0,0,0,0,0,0,0,0,0,0,0,0,0,0,0,0,0,0,0,0,0
0,0,0,0,0,0,0,0,0,0,0,0,0,0,0,0,0,0,0,0,0,0,0,0,0,0
0,0,0,0,0,0,0,0,0,0,0,0,0,0,0,0,0,0,0,0,0,0,0,0,0,0
0,0,74,73,0,0,0,0,0,0,0,0,72,71,0,0,0,0,0,0,0,0,0,0,0,0
0,0,74,50,5,50,47,50,50,47,50,5,50,71,0,0,0,0,0,0,0,0,0,0,0,0
0,0,74,67,0,0,0,0,0,0,0,0,67,71,0,0,0,0,0,0,0,0,0,0,0,0
0,0,74,67,0,0,0,0,0,0,0,0,67,71,0,0,0,0,0,0,0,0,0,0,0,0
0,0,74,67,0,0,0,0,0,0,0,0,67,71,0,0,0,0,0,0,0,0,0,0,0,0
0,0,74,67,0,0,0,0,0,0,0,0,67,65,65,0,0,0,0,0,0,0,0,0,0,0
0,0,74,67,0,0,0,0,0,0,0,0,67,50,66,0,0,0,0,0,0,0,0,0,0,0
0,0,74,67,21,21,21,21,21,21,21,21,21,5,0,0,0,0,0,0,0,0,0,0,0,0
4,4,4,67,0,0,0,0,0,0,0,0,0,50,0,0,0,0,0,0,0,0,0,0,0,0
4,0,4,67,0,0,0,0,0,0,0,0,0,47,0,0,0,0,0,0,0,0,0,0,0,0
4,4,4,67,0,0,23,11,11,23,0,0,0,50,0,0,0,0,0,0,0,0,0,0,0,0
0,0,74,67,21,21,21,21,21,21,21,21,21,5,0,0,0,0,0,0,0,0,0,0,0,0
0,0,74,67,0,0,0,0,0,0,0,0,67,50,69,0,0,0,0,0,0,0,0,0,0,0
0,0,74,67,0,0,0,0,0,0,0,0,67,70,70,0,0,0,0,0,0,0,0,0,0,0
0,0,74,67,0,0,0,0,0,0,0,0,67,71,0,0,0,0,0,0,0,0,0,0,0,0
0,0,74,67,0,0,0,0,0,0,0,0,67,71,0,0,0,0,0,0,0,0,0,0,0,0
0,0,74,67,0,0,0,0,0,0,0,0,67,71,0,0,0,0,0,0,0,0,0,0,0,0
0,0,74,50,5,50,47,50,50,47,50,5,50,71,0,0,0,0,0,0,0,0,0,0,0,0
0,0,74,73,0,0,0,0,0,0,0,0,72,71,0,0,0,0,0,0,0,0,0,0,0,0
0,0,0,0,0,0,0,0,0,0,0,0,0,0,0,0,0,0,0,0,0,0,0,0,0,0
0,0,0,0,0,0,0,0,0,0,0,0,0,0,0,0,0,0,0,0,0,0,0,0,0,0
0,0,0,0,0,0,0,0,0,0,0,0,0,0,0,0,0,0,0,0,0,0,0,0,0,0
0,0,0,0,0,0,0,0,0,0,0,0,0,0,0,0,0,0,0,0,0,0,0,0,0,0
endlayer

layer
0,0,0,0,0,0,0,0,0,0,0,0,0,0,0,0,0,0,0,0,0,0,0,0,0,0
0,0,0,0,0,0,0,0,0,0,0,0,0,0,0,0,0,0,0,0,0,0,0,0,0,0
0,0,0,0,0,0,0,0,0,0,0,0,0,0,0,0,0,0,0,0,0,0,0,0,0,0
0,0,0,0,0,0,0,0,0,0,0,0,0,0,0,0,0,0,0,0,0,0,0,0,0,0
0,0,0,0,0,0,0,0,0,0,0,0,0,0,0,0,0,0,0,0,0,0,0,0,0,0
0,0,0,0,0,0,0,0,0,0,0,0,0,0,0,0,0,0,0,0,0,0,0,0,0,0
0,0,0,0,0,0,0,0,0,0,0,0,0,0,0,0,0,0,0,0,0,0,0,0,0,0
0,0,0,0,0,0,0,0,0,0,0,0,0,0,0,0,0,0,0,0,0,0,0,0,0,0
0,0,0,0,0,0,0,0,0,0,0,0,0,0,0,0,0,0,0,0,0,0,0,0,0,0
0,0,0,74,73,0,0,0,0,0,0,72,71,0,0,0,0,0,0,0,0,0,0,0,0,0
0,0,0,74,5,50,26,50,50,26,50,5,71,0,0,0,0,0,0,0,0,0,0,0,0,0
0,0,0,74,67,0,0,0,0,0,0,67,71,0,0,0,0,0,0,0,0,0,0,0,0,0
0,0,0,74,67,0,0,0,0,0,0,67,71,0,0,0,0,0,0,0,0,0,0,0,0,0
0,0,0,74,67,0,0,0,0,0,0,67,71,0,0,0,0,0,0,0,0,0,0,0,0,0
0,0,0,74,67,0,0,0,0,0,0,67,71,0,0,0,0,0,0,0,0,0,0,0,0,0
0,0,0,74,67,0,0,0,0,0,0,67,71,65,65,0,0,0,0,0,0,0,0,0,0,0
0,0,0,74,67,0,0,0,0,0,0,67,67,5,66,0,0,0,0,0,0,0,0,0,0,0
4,4,4,74,67,0,0,0,0,0,0,0,0,50,0,0,0,0,0,0,0,0,0,0,0,0
4,0,4,74,67,0,0,0,0,0,0,0,0,26,0,0,0,0,0,0,0,0,0,0,0,0
4,4,4,74,67,0,0,0,0,0,0,0,0,50,0,0,0,0,0,0,0,0,0,0,0,0
0,0,0,74,67,0,0,0,0,0,0,67,67,5,69,0,0,0,0,0,0,0,0,0,0,0
0,0,0,74,67,0,0,0,0,0,0,67,71,70,70,0,0,0,0,0,0,0,0,0,0,0
0,0,0,74,67,0,0,0,0,0,0,67,71,0,0,0,0,0,0,0,0,0,0,0,0,0
0,0,0,74,67,0,0,0,0,0,0,67,71,0,0,0,0,0,0,0,0,0,0,0,0,0
0,0,0,74,67,0,0,0,0,0,0,67,71,0,0,0,0,0,0,0,0,0,0,0,0,0
0,0,0,74,67,0,0,0,0,0,0,67,71,0,0,0,0,0,0,0,0,0,0,0,0,0
0,0,0,74,5,50,26,50,50,26,50,5,71,0,0,0,0,0,0,0,0,0,0,0,0,0
0,0,0,74,73,0,0,0,0,0,0,72,71,0,0,0,0,0,0,0,0,0,0,0,0,0
0,0,0,0,0,0,0,0,0,0,0,0,0,0,0,0,0,0,0,0,0,0,0,0,0,0
0,0,0,0,0,0,0,0,0,0,0,0,0,0,0,0,0,0,0,0,0,0,0,0,0,0
0,0,0,0,0,0,0,0,0,0,0,0,0,0,0,0,0,0,0,0,0,0,0,0,0,0
0,0,0,0,0,0,0,0,0,0,0,0,0,0,0,0,0,0,0,0,0,0,0,0,0,0
endlayer

layer
0,0,0,0,0,0,0,0,0,0,0,0,0,0,0,0,0,0,0,0,0,0,0,0,0,0
0,0,0,0,0,0,0,0,0,0,0,0,0,0,0,0,0,0,0,0,0,0,0,0,0,0
0,0,0,0,0,0,0,0,0,0,0,0,0,0,0,0,0,0,0,0,0,0,0,0,0,0
0,0,0,0,0,0,0,0,0,0,0,0,0,0,0,0,0,0,0,0,0,0,0,0,0,0
0,0,0,0,0,0,0,0,0,0,0,0,0,0,0,0,0,0,0,0,0,0,0,0,0,0
0,0,0,0,0,0,0,0,0,0,0,0,0,0,0,0,0,0,0,0,0,0,0,0,0,0
0,0,0,0,0,0,0,0,0,0,0,0,0,0,0,0,0,0,0,0,0,0,0,0,0,0
0,0,0,0,0,0,0,0,0,0,0,0,0,0,0,0,0,0,0,0,0,0,0,0,0,0
0,0,0,0,0,0,0,0,0,0,0,0,0,0,0,0,0,0,0,0,0,0,0,0,0,0
0,0,0,0,74,73,0,0,0,0,72,71,0,0,0,0,0,0,0,0,0,0,0,0,0,0
0,0,0,0,74,50,26,50,50,26,50,71,0,0,0,0,0,0,0,0,0,0,0,0,0,0
0,0,0,0,74,67,0,0,0,0,67,71,0,0,0,0,0,0,0,0,0,0,0,0,0,0
0,0,0,0,74,67,0,0,0,0,67,71,0,0,0,0,0,0,0,0,0,0,0,0,0,0
0,0,0,0,74,67,0,0,0,0,67,71,0,0,0,0,0,0,0,0,0,0,0,0,0,0
0,0,0,0,74,67,0,0,0,0,67,71,0,0,0,0,0,0,0,0,0,0,0,0,0,0
0,0,0,0,74,67,0,0,0,0,67,71,0,0,0,0,0,0,0,0,0,0,0,0,0,0
0,0,0,0,74,67,0,0,0,0,67,71,65,65,65,0,0,0,0,0,0,0,0,0,0,0
4,4,4,0,74,67,0,0,0,0,67,67,67,50,66,0,0,0,0,0,0,0,0,0,0,0
4,0,4,0,74,67,0,0,0,0,0,0,0,26,0,0,0,0,0,0,0,0,0,0,0,0
4,4,4,0,74,67,0,0,0,0,67,67,67,50,69,0,0,0,0,0,0,0,0,0,0,0
0,0,0,0,74,67,0,0,0,0,67,71,70,70,70,0,0,0,0,0,0,0,0,0,0,0
0,0,0,0,74,67,0,0,0,0,67,71,0,0,0,0,0,0,0,0,0,0,0,0,0,0
0,0,0,0,74,67,0,0,0,0,67,71,0,0,0,0,0,0,0,0,0,0,0,0,0,0
0,0,0,0,74,67,0,0,0,0,67,71,0,0,0,0,0,0,0,0,0,0,0,0,0,0
0,0,0,0,74,67,0,0,0,0,67,71,0,0,0,0,0,0,0,0,0,0,0,0,0,0
0,0,0,0,74,67,0,0,0,0,67,71,0,0,0,0,0,0,0,0,0,0,0,0,0,0
0,0,0,0,74,50,26,50,50,26,50,71,0,0,0,0,0,0,0,0,0,0,0,0,0,0
0,0,0,0,74,73,0,0,0,0,72,71,0,0,0,0,0,0,0,0,0,0,0,0,0,0
0,0,0,0,0,0,0,0,0,0,0,0,0,0,0,0,0,0,0,0,0,0,0,0,0,0
0,0,0,0,0,0,0,0,0,0,0,0,0,0,0,0,0,0,0,0,0,0,0,0,0,0
0,0,0,0,0,0,0,0,0,0,0,0,0,0,0,0,0,0,0,0,0,0,0,0,0,0
0,0,0,0,0,0,0,0,0,0,0,0,0,0,0,0,0,0,0,0,0,0,0,0,0,0
endlayer

layer
0,0,0,0,0,0,0,0,0,0,0,0,0,0,0,0,0,0,0,0,0,0,0,0,0,0
0,0,0,0,0,0,0,0,0,0,0,0,0,0,0,0,0,0,0,0,0,0,0,0,0,0
0,0,0,0,0,0,0,0,0,0,0,0,0,0,0,0,0,0,0,0,0,0,0,0,0,0
0,0,0,0,0,0,0,0,0,0,0,0,0,0,0,0,0,0,0,0,0,0,0,0,0,0
0,0,0,0,0,0,0,0,0,0,0,0,0,0,0,0,0,0,0,0,0,0,0,0,0,0
0,0,0,0,0,0,0,0,0,0,0,0,0,0,0,0,0,0,0,0,0,0,0,0,0,0
0,0,0,0,0,0,0,0,0,0,0,0,0,0,0,0,0,0,0,0,0,0,0,0,0,0
0,0,0,0,0,0,0,0,0,0,0,0,0,0,0,0,0,0,0,0,0,0,0,0,0,0
0,0,0,0,0,0,0,0,0,0,0,0,0,0,0,0,0,0,0,0,0,0,0,0,0,0
0,0,0,0,0,74,73,0,0,72,71,0,0,0,0,0,0,0,0,0,0,0,0,0,0,0
0,0,0,0,0,74,19,19,19,19,71,0,0,0,0,0,0,0,0,0,0,0,0,0,0,0
0,0,0,0,0,74,67,0,0,67,71,0,0,0,0,0,0,0,0,0,0,0,0,0,0,0
0,0,0,0,0,74,67,0,0,67,71,0,0,0,0,0,0,0,0,0,0,0,0,0,0,0
0,0,0,0,0,74,67,0,0,67,71,0,0,0,0,0,0,0,0,0,0,0,0,0,0,0
0,0,0,0,0,74,67,0,0,67,71,0,0,0,0,0,0,0,0,0,0,0,0,0,0,0
0,0,0,0,0,74,67,0,0,67,71,0,0,0,0,0,0,0,0,0,0,0,0,0,0,0
0,0,0,0,0,74,67,0,0,67,71,0,0,0,0,0,0,0,0,0,0,0,0,0,0,0
4,4,4,0,0,74,67,0,0,67,71,65,65,65,65,0,0,0,0,0,0,0,0,0,0,0
4,37,4,0,0,74,67,0,0,67,67,67,67,50,59,0,0,0,0,0,0,0,0,0,0,0
4,4,4,0,0,74,67,0,0,67,71,70,70,70,70,0,0,0,0,0,0,0,0,0,0,0
0,0,0,0,0,74,67,0,0,67,71,0,0,0,0,0,0,0,0,0,0,0,0,0,0,0
0,0,0,0,0,74,67,0,0,67,71,0,0,0,0,0,0,0,0,0,0,0,0,0,0,0
0,0,0,0,0,74,67,0,0,67,71,0,0,0,0,0,0,0,0,0,0,0,0,0,0,0
0,0,0,0,0,74,67,0,0,67,71,0,0,0,0,0,0,0,0,0,0,0,0,0,0,0
0,0,0,0,0,74,67,0,0,67,71,0,0,0,0,0,0,0,0,0,0,0,0,0,0,0
0,0,0,0,0,74,67,0,0,67,71,0,0,0,0,0,0,0,0,0,0,0,0,0,0,0
0,0,0,0,0,74,19,19,19,19,71,0,0,0,0,0,0,0,0,0,0,0,0,0,0,0
0,0,0,0,0,74,73,0,0,72,71,0,0,0,0,0,0,0,0,0,0,0,0,0,0,0
0,0,0,0,0,0,0,0,0,0,0,0,0,0,0,0,0,0,0,0,0,0,0,0,0,0
0,0,0,0,0,0,0,0,0,0,0,0,0,0,0,0,0,0,0,0,0,0,0,0,0,0
0,0,0,0,0,0,0,0,0,0,0,0,0,0,0,0,0,0,0,0,0,0,0,0,0,0
0,0,0,0,0,0,0,0,0,0,0,0,0,0,0,0,0,0,0,0,0,0,0,0,0,0
endlayer

layer
0,0,0,0,0,0,0,0,0,0,0,0,0,0,0,0,0,0,0,0,0,0,0,0,0,0
0,0,0,0,0,0,0,0,0,0,0,0,0,0,0,0,0,0,0,0,0,0,0,0,0,0
0,0,0,0,0,0,0,0,0,0,0,0,0,0,0,0,0,0,0,0,0,0,0,0,0,0
0,0,0,0,0,0,0,0,0,0,0,0,0,0,0,0,0,0,0,0,0,0,0,0,0,0
0,0,0,0,0,0,0,0,0,0,0,0,0,0,0,0,0,0,0,0,0,0,0,0,0,0
0,0,0,0,0,0,0,0,0,0,0,0,0,0,0,0,0,0,0,0,0,0,0,0,0,0
0,0,0,0,0,0,0,0,0,0,0,0,0,0,0,0,0,0,0,0,0,0,0,0,0,0
0,0,0,0,0,0,0,0,0,0,0,0,0,0,0,0,0,0,0,0,0,0,0,0,0,0
0,0,0,0,0,0,0,0,0,0,0,0,0,0,0,0,0,0,0,0,0,0,0,0,0,0
0,0,0,0,0,0,74,73,72,71,0,0,0,0,0,0,0,0,0,0,0,0,0,0,0,0
0,0,0,0,0,0,74,50,50,71,0,0,0,0,0,0,0,0,0,0,0,0,0,0,0,0
0,0,0,0,0,0,74,67,67,71,0,0,0,0,0,0,0,0,0,0,0,0,0,0,0,0
0,0,0,0,0,0,74,67,67,71,0,0,0,0,0,0,0,0,0,0,0,0,0,0,0,0
0,0,0,0,0,0,74,67,67,71,0,0,0,0,0,0,0,0,0,0,0,0,0,0,0,0
0,0,0,0,0,0,74,67,67,71,0,0,0,0,0,0,0,0,0,0,0,0,0,0,0,0
0,0,0,0,0,0,74,67,67,71,0,0,0,0,0,0,0,0,0,0,0,0,0,0,0,0
0,0,0,0,0,0,74,67,67,71,0,0,0,0,0,0,0,0,0,0,0,0,0,0,0,0
4,4,4,0,0,0,74,67,67,71,0,0,0,0,0,0,0,0,0,0,0,0,0,0,0,0
4,44,4,0,0,0,74,67,67,71,75,75,75,75,75,0,0,0,0,0,0,0,0,0,0,0
4,4,4,0,0,0,74,67,67,71,0,0,0,0,0,0,0,0,0,0,0,0,0,0,0,0
0,0,0,0,0,0,74,67,67,71,0,0,0,0,0,0,0,0,0,0,0,0,0,0,0,0
0,0,0,0,0,0,74,67,67,71,0,0,0,0,0,0,0,0,0,0,0,0,0,0,0,0
0,0,0,0,0,0,74,67,67,71,0,0,0,0,0,0,0,0,0,0,0,0,0,0,0,0
0,0,0,0,0,0,74,67,67,71,0,0,0,0,0,0,0,0,0,0,0,0,0,0,0,0
0,0,0,0,0,0,74,67,67,71,0,0,0,0,0,0,0,0,0,0,0,0,0,0,0,0
0,0,0,0,0,0,74,67,67,71,0,0,0,0,0,0,0,0,0,0,0,0,0,0,0,0
0,0,0,0,0,0,74,50,50,71,0,0,0,0,0,0,0,0,0,0,0,0,0,0,0,0
0,0,0,0,0,0,74,73,72,71,0,0,0,0,0,0,0,0,0,0,0,0,0,0,0,0
0,0,0,0,0,0,0,0,0,0,0,0,0,0,0,0,0,0,0,0,0,0,0,0,0,0
0,0,0,0,0,0,0,0,0,0,0,0,0,0,0,0,0,0,0,0,0,0,0,0,0,0
0,0,0,0,0,0,0,0,0,0,0,0,0,0,0,0,0,0,0,0,0,0,0,0,0,0
0,0,0,0,0,0,0,0,0,0,0,0,0,0,0,0,0,0,0,0,0,0,0,0,0,0
endlayer

layer
0,0,0,0,0,0,0,0,0,0,0,0,0,0,0,0,0,0,0,0,0,0,0,0,0,0
0,0,0,0,0,0,0,0,0,0,0,0,0,0,0,0,0,0,0,0,0,0,0,0,0,0
0,0,0,0,0,0,0,0,0,0,0,0,0,0,0,0,0,0,0,0,0,0,0,0,0,0
0,0,0,0,0,0,0,0,0,0,0,0,0,0,0,0,0,0,0,0,0,0,0,0,0,0
0,0,0,0,0,0,0,0,0,0,0,0,0,0,0,0,0,0,0,0,0,0,0,0,0,0
0,0,0,0,0,0,0,0,0,0,0,0,0,0,0,0,0,0,0,0,0,0,0,0,0,0
0,0,0,0,0,0,0,0,0,0,0,0,0,0,0,0,0,0,0,0,0,0,0,0,0,0
0,0,0,0,0,0,0,0,0,0,0,0,0,0,0,0,0,0,0,0,0,0,0,0,0,0
0,0,0,0,0,0,0,0,0,0,0,0,0,0,0,0,0,0,0,0,0,0,0,0,0,0
0,0,0,0,0,0,0,74,71,0,0,0,0,0,0,0,0,0,0,0,0,0,0,0,0,0
0,0,0,0,0,0,0,74,71,0,0,0,0,0,0,0,0,0,0,0,0,0,0,0,0,0
0,0,0,0,0,0,0,74,71,0,0,0,0,0,0,0,0,0,0,0,0,0,0,0,0,0
0,0,0,0,0,0,0,74,71,0,0,0,0,0,0,0,0,0,0,0,0,0,0,0,0,0
0,0,0,0,0,0,0,74,71,0,0,0,0,0,0,0,0,0,0,0,0,0,0,0,0,0
0,0,0,0,0,0,0,74,71,0,0,0,0,0,0,0,0,0,0,0,0,0,0,0,0,0
0,0,0,0,0,0,0,74,71,0,0,0,0,0,0,0,0,0,0,0,0,0,0,0,0,0
0,0,0,0,0,0,0,74,71,0,0,0,0,0,0,0,0,0,0,0,0,0,0,0,0,0
4,4,4,0,0,0,0,74,71,0,0,0,0,0,0,0,0,0,0,0,0,0,0,0,0,0
4,0,4,0,0,0,0,74,71,0,0,0,0,0,0,0,0,0,0,0,0,0,0,0,0,0
4,4,4,0,0,0,0,74,71,0,0,0,0,0,0,0,0,0,0,0,0,0,0,0,0,0
0,0,0,0,0,0,0,74,71,0,0,0,0,0,0,0,0,0,0,0,0,0,0,0,0,0
0,0,0,0,0,0,0,74,71,0,0,0,0,0,0,0,0,0,0,0,0,0,0,0,0,0
0,0,0,0,0,0,0,74,71,0,0,0,0,0,0,0,0,0,0,0,0,0,0,0,0,0
0,0,0,0,0,0,0,74,71,0,0,0,0,0,0,0,0,0,0,0,0,0,0,0,0,0
0,0,0,0,0,0,0,74,71,0,0,0,0,0,0,0,0,0,0,0,0,0,0,0,0,0
0,0,0,0,0,0,0,74,71,0,0,0,0,0,0,0,0,0,0,0,0,0,0,0,0,0
0,0,0,0,0,0,0,74,71,0,0,0,0,0,0,0,0,0,0,0,0,0,0,0,0,0
0,0,0,0,0,0,0,74,71,0,0,0,0,0,0,0,0,0,0,0,0,0,0,0,0,0
0,0,0,0,0,0,0,0,0,0,0,0,0,0,0,0,0,0,0,0,0,0,0,0,0,0
0,0,0,0,0,0,0,0,0,0,0,0,0,0,0,0,0,0,0,0,0,0,0,0,0,0
0,0,0,0,0,0,0,0,0,0,0,0,0,0,0,0,0,0,0,0,0,0,0,0,0,0
0,0,0,0,0,0,0,0,0,0,0,0,0,0,0,0,0,0,0,0,0,0,0,0,0,0
endlayer

