# Bandit Outpost -- MC 1.8 -- 2 Apr 2016
# Created by Ruins mod version 15.5 Ingame Parser
# authoring Player: Jordan_Greywolf

# Updated to MC 1.9: 29 Apr 2016
# Updated to MC 1.10: 13 Sep 2016
# Updated to MC 1.12: 23 Jun 2017
# Updated to MC 1.12.1: 9 Sep 2017

biomesToSpawnIn=extreme hills edge,forest,forest meadow,green hills,meadow,moor,mountain foothills,ominous woods,origin valley,outback,pasture,plains,prairie,rwg_coldplains,rwg_plains,scrubland,seasonal forest,silkglades,shrubland,swampland,wasteland,woodlands,xeric shrubland,mining biome,mining_biome,smaller_extreme_hills

weight=1

uniqueMinDistance=2000

embed_into_distance=6
acceptable_target_blocks=

unacceptable_target_blocks=cloud,Natura:Cloud,red_mushroom_block,brown_mushroom_block,slime_congealed,slime_dirt,slime_grass,command_block

dimensions=28,18,16
allowable_overhang=0
max_leveling=6
leveling_buffer=0
preserve_water=0
preserve_lava=0
preserve_plants=1

rule1=0,100,minecraft:double_stone_slab-0
rule2=0,100,minecraft:stonebrick-1,minecraft:stonebrick-1,minecraft:stonebrick,minecraft:stonebrick-2
rule3=0,100,minecraft:mossy_cobblestone-0
rule4=0,100,MobSpawner:Zombie,MobSpawner:Skeleton
rule5=0,100,minecraft:skull,minecraft:skull-1,minecraft:skull-2,minecraft:skull-3,minecraft:skull-4
rule6=0,100,minecraft:flower_pot-0

# Insane Prisoner
rule7=0,100,CommandBlock:RUINSTRIGGER /summon Zombie ~0 ~0 ~0 {HandItems:[{Count:1,id:bone},{Count:1,id:rotten_flesh}],ArmorItems:[{Count:1,id:leather_boots},{Count:1,id:leather_leggings},{Count:1,id:leather_chestplate},{Count:1,id:skull,Damage:3,tag:{SkullOwner:MHF_Herobrine}}],CustomName:"Insane Prisoner",HandDropChances:[0.1F,0.1F],ArmorDropChances:[0.1F,0.1F,0.1F,0.1F],Silent:1,PersistenceRequired:1}:@

rule8=0,100,minecraft:stone_brick_stairs-2
rule9=0,100,minecraft:iron_door-2
rule10=0,100,minecraft:web-0

# Bandit
rule11=0,100,CommandBlock:RUINSTRIGGER /summon Skeleton ~0 ~0 ~0 {HandItems:[{Count:1,id:bow,tag:{ench:[{id:48,lvl:5},{id:49,lvl:1}]}},{Count:8,id:arrow}],ArmorItems:[{Count:1,id:leather_boots},{Count:1,id:leather_leggings},{Count:1,id:leather_chestplate},{Count:1,id:skull,Damage:3,tag:{SkullOwner:MHF_Villager}}],CustomName:Bandit,HandDropChances:[0.1F,0.1F],ArmorDropChances:[0.1F,0.1F,0.1F,0.1F],Silent:1,PersistenceRequired:1}:@

rule12=0,100,minecraft:spruce_door-3
rule13=0,100,minecraft:redstone_wire-0
rule14=0,100,minecraft:spruce_stairs-5
rule15=0,100,minecraft:piston-1

rule16=0,100,IInventory;minecraft:trapped_chest;minecraft:torch#9#0#1+minecraft:stained_hardened_clay#24#15#5+minecraft:rotten_flesh#1#0#7+minecraft:stained_hardened_clay#32#8#9+minecraft:skull#1#0#11+minecraft:spruce_fence#2#0#12+minecraft:brown_mushroom#2#0#14+minecraft:red_mushroom#2#0#17+minecraft:rotten_flesh#1#0#19+minecraft:stone#32#0#22+minecraft:skull#1#0#23+minecraft:stained_hardened_clay#24#11#25-4

rule17=0,100,minecraft:spruce_stairs-4
rule18=0,100,minecraft:spruce_door-0
rule19=0,100,ChestGenHook:chests/simple_dungeon:3-2
rule20=0,100,minecraft:ladder-4
rule21=0,100,minecraft:stone_brick_stairs-6
rule22=0,100,minecraft:iron_door-8
rule23=0,100,minecraft:lever-1
rule24=0,100,minecraft:lever-4
rule25=0,100,minecraft:iron_bars-0

rule26=0,100,CommandBlock:RUINSTRIGGER /testruin TP_Dungeon_Mineshaft ~0 ~-1 ~0:@

rule27=0,100,minecraft:spruce_door-8
rule28=0,100,minecraft:tripwire_hook-2
rule29=0,100,minecraft:spruce_door-9
rule30=0,100,minecraft:tripwire_hook-3
rule31=0,100,minecraft:stonebrick-3
rule32=0,100,minecraft:stone_slab-8
rule33=0,100,minecraft:water-0
rule34=0,100,minecraft:grass-0
rule35=0,100,minecraft:stained_hardened_clay-15
rule36=0,100,minecraft:stained_hardened_clay-11
rule37=0,100,minecraft:cobblestone-0
rule38=0,100,preserveBlock,minecraft:gravel-0,minecraft:cobblestone-0
rule39=0,100,minecraft:sapling-0-addbonemeal,minecraft:sapling-1-addbonemeal,minecraft:sapling-2-addbonemeal,minecraft:sapling-3-addbonemeal

rule40=0,100,minecraft:tallgrass-1,minecraft:tallgrass-1,minecraft:tallgrass-1,minecraft:tallgrass-2,minecraft:deadbush

rule41=0,100,minecraft:cobblestone_wall-1
rule42=0,100,minecraft:double_plant-2
rule43=0,100,minecraft:log-0
rule44=0,100,minecraft:stained_hardened_clay-8
rule45=0,100,minecraft:spruce_fence-0
rule46=0,100,minecraft:spruce_stairs-2
rule47=0,100,minecraft:crafting_table-0
rule48=0,100,minecraft:spruce_stairs-0
rule49=0,100,minecraft:trapdoor-2
rule50=0,100,ChestGenHook:chests/simple_dungeon:3-4
rule51=0,100,IInventory;minecraft:lit_furnace;minecraft:coal#3#1#1-4
rule52=0,100,minecraft:double_plant-8
rule53=0,100,minecraft:stone_pressure_plate-0
rule54=0,100,minecraft:stone_stairs-3
rule55=0,100,minecraft:stone_stairs-2
rule56=0,100,minecraft:stone_stairs-1
rule57=0,100,minecraft:stone_slab-0
rule58=0,100,minecraft:stone_stairs-0
rule59=0,100,minecraft:spruce_stairs-3
rule60=0,100,minecraft:log-8
rule61=0,100,minecraft:log-4
rule62=0,100,minecraft:spruce_stairs-6
rule63=0,100,minecraft:spruce_stairs-7
rule64=0,100,minecraft:spruce_stairs-1
rule65=0,100,ChestGenHook:chests/simple_dungeon:3-5
rule66=0,100,minecraft:planks-1

layer
1,2,2,2,2,2,2,2,2,2,2,2,2,2,2,1
2,3,3,3,3,3,3,3,3,3,3,3,3,3,3,2
2,3,3,3,3,3,3,3,3,3,3,3,3,3,3,2
2,3,3,3,3,3,3,3,3,3,3,3,3,3,3,2
2,3,3,3,3,3,3,3,3,3,3,3,3,3,3,2
2,3,3,3,3,3,3,3,3,3,3,3,3,3,3,2
2,3,3,3,3,3,3,3,3,3,3,3,3,3,3,2
2,3,3,3,3,3,3,3,3,3,3,3,3,3,3,2
2,3,3,3,3,3,3,3,3,3,3,3,3,3,3,2
2,3,3,3,3,3,3,3,3,3,3,3,3,3,3,2
2,3,3,3,3,3,3,3,1,3,3,3,3,3,3,1
2,3,3,3,3,3,3,3,3,3,3,3,3,3,3,2
2,3,3,3,3,3,3,3,3,3,3,3,3,3,3,2
2,3,3,3,3,3,3,3,3,3,3,3,3,3,3,2
2,3,3,3,3,3,3,3,3,3,3,3,3,3,3,2
2,3,3,3,3,3,3,3,3,3,3,3,3,3,3,2
2,3,3,3,3,3,3,3,3,3,3,3,3,3,3,2
1,2,2,2,2,2,2,2,1,2,2,2,2,2,2,1
endlayer

layer
1,2,2,2,2,2,2,2,2,2,2,2,2,2,2,1
2,5,6,2,6,4,2,7,0,2,6,0,2,5,4,2
2,0,7,2,0,5,2,0,6,2,0,0,2,0,6,2
2,9,8,2,9,8,2,9,8,2,9,8,2,9,8,2
2,0,0,0,0,0,0,0,0,0,0,0,0,0,0,2
2,0,11,0,0,0,0,11,0,0,0,0,0,0,10,2
2,0,0,0,0,0,0,0,0,0,11,0,0,2,2,2
2,14,13,0,0,0,0,0,0,0,0,0,0,12,0,2
2,15,0,0,13,0,0,0,0,0,0,0,0,2,10,2
2,17,0,0,0,0,0,10,2,10,0,0,10,2,16,2
2,2,2,1,18,1,2,2,1,2,2,2,2,2,2,1
2,5,10,0,0,0,10,10,2,10,10,5,0,10,10,2
2,10,0,0,0,0,0,5,1,10,0,0,0,0,10,2
2,19,10,0,0,11,0,0,12,0,0,0,11,0,10,2
2,19,10,5,0,0,0,0,12,0,0,0,0,0,10,2
2,10,0,0,0,0,0,5,1,10,0,0,10,20,2,2
2,10,10,0,4,0,10,10,2,5,0,10,10,2,2,2
1,2,2,2,2,2,2,2,1,2,2,2,2,2,2,1
endlayer

layer
1,2,2,2,2,2,2,2,2,2,2,2,2,2,2,1
2,10,10,2,0,0,2,0,0,2,0,0,2,0,0,2
2,0,10,2,0,0,2,0,0,2,0,0,2,0,0,2
2,22,21,2,22,21,2,22,21,2,22,21,2,22,21,2
2,24,0,23,0,0,23,0,0,23,0,0,23,0,0,2
2,0,0,0,0,0,0,0,0,0,0,0,0,0,0,2
2,0,0,0,0,0,0,0,0,0,26,0,0,2,25,2
2,28,0,0,0,0,0,0,0,0,0,0,0,27,0,2
2,5,0,0,0,0,0,0,0,0,0,0,0,2,0,2
2,28,0,0,0,0,0,0,2,0,0,0,0,25,10,2
2,2,2,1,27,1,2,2,1,2,2,25,25,2,2,1
2,10,0,0,0,0,0,10,2,10,0,0,0,0,10,2
2,0,0,0,0,0,0,0,1,0,0,0,0,0,0,2
2,10,0,0,0,0,0,0,27,0,0,0,0,0,0,2
2,10,0,0,0,0,0,0,29,0,0,0,0,0,10,2
2,0,0,0,0,0,0,10,1,0,0,0,0,20,2,2
2,10,0,0,0,0,0,10,2,0,0,0,10,2,2,2
1,2,2,2,2,2,2,2,1,2,2,2,2,2,2,1
endlayer

layer
1,2,2,2,2,2,2,2,2,2,2,2,2,2,2,1
2,30,30,2,30,30,2,30,30,2,30,30,2,30,30,2
2,0,0,2,0,10,2,0,0,2,0,0,2,0,0,2
2,25,25,2,25,25,2,25,25,2,25,25,2,25,25,2
2,0,0,0,0,0,0,0,0,0,0,0,0,0,0,2
2,0,0,0,0,0,0,0,0,0,0,0,0,0,10,2
2,0,0,0,0,0,0,0,0,0,0,0,0,2,2,2
2,0,0,0,0,0,0,0,0,0,0,0,0,31,0,2
2,0,0,0,0,0,0,0,0,0,0,0,0,2,0,2
2,10,0,0,0,0,0,10,2,10,0,0,10,2,10,2
2,2,2,1,31,1,2,2,1,2,2,2,2,2,2,1
2,10,0,0,0,0,0,10,2,10,0,0,0,0,10,2
2,0,0,0,0,0,0,0,1,0,0,0,0,0,0,2
2,0,0,0,0,0,0,0,31,0,0,0,0,0,0,2
2,0,0,0,0,0,0,0,31,0,0,0,0,0,10,2
2,0,0,0,0,0,0,0,1,0,0,0,0,20,2,2
2,32,0,0,0,0,10,10,2,0,0,0,10,2,2,2
1,2,2,2,2,2,2,2,1,2,2,2,2,2,2,1
endlayer

layer
1,2,2,2,2,2,2,2,2,2,2,2,2,2,2,1
2,0,0,2,0,10,2,10,0,2,10,10,2,10,10,2
2,0,0,2,0,10,2,0,0,2,10,10,2,0,10,2
2,25,25,2,25,25,2,25,25,2,25,25,2,25,25,2
2,0,0,0,0,0,0,0,0,0,0,0,0,0,10,2
2,0,0,0,0,0,0,0,0,0,0,0,0,10,10,2
2,0,0,0,0,0,0,0,0,0,0,0,0,2,2,2
2,0,0,0,0,0,0,0,0,0,0,0,0,2,10,2
2,10,0,0,0,0,0,0,0,0,0,0,0,2,10,2
2,10,10,0,0,0,0,10,2,10,0,0,0,2,10,2
2,2,2,2,2,2,2,2,1,2,2,2,2,2,2,1
2,10,10,0,0,0,10,10,2,10,10,0,0,0,10,2
2,10,0,0,0,0,0,10,2,10,0,0,0,0,0,2
2,0,0,0,0,0,0,0,2,0,0,0,0,0,0,2
2,32,0,0,0,0,0,0,2,0,0,0,0,0,10,2
2,1,32,0,0,0,0,0,2,0,0,0,10,20,2,2
2,1,1,32,0,0,10,10,2,10,0,10,10,2,2,2
1,2,2,2,2,2,2,2,1,2,2,2,2,2,2,1
endlayer

layer
1,2,2,2,2,2,2,2,2,2,2,2,2,2,2,1
2,1,32,1,32,32,1,32,32,1,32,32,1,32,32,2
2,32,32,1,32,32,1,32,32,1,32,32,1,32,32,2
2,1,1,1,1,1,1,1,1,1,1,1,1,1,1,2
2,32,32,32,32,32,32,32,32,32,32,32,32,32,32,2
2,32,32,32,32,32,32,32,32,32,32,32,32,32,32,2
2,32,32,32,32,32,32,32,32,32,32,32,32,1,1,2
2,32,32,32,32,32,32,32,32,32,32,32,32,1,32,2
2,32,32,32,32,32,32,32,32,32,32,32,32,1,32,2
2,32,32,32,32,32,32,32,1,32,32,32,32,1,1,2
2,1,1,1,1,1,1,1,1,2,2,2,2,2,2,1
2,1,32,32,32,32,32,1,2,10,10,0,10,10,10,2
2,32,32,32,32,32,32,32,2,10,10,0,0,0,10,2
2,1,32,32,32,32,32,32,2,10,0,0,0,0,10,2
2,1,1,32,32,32,32,32,2,0,0,0,10,10,10,2
2,1,1,1,32,32,32,32,2,10,0,10,10,20,2,2
2,1,1,1,1,32,32,1,2,10,10,10,10,2,2,2
1,2,2,2,2,2,2,2,1,2,2,2,2,2,2,1
endlayer

layer
1,1,1,1,1,1,1,1,1,1,1,1,1,1,1,1
1,33,33,1,1,1,1,1,1,1,1,1,1,33,33,1
1,33,33,1,34,34,34,34,34,34,34,34,1,33,33,1
1,1,1,1,34,34,34,34,34,34,34,34,1,1,1,1
1,1,34,34,34,34,34,34,34,34,34,34,34,34,1,1
1,1,34,34,34,34,34,34,34,34,34,34,34,34,1,1
1,1,34,34,34,34,34,34,34,34,34,34,34,34,1,1
1,1,34,34,34,34,34,34,34,34,34,34,34,34,1,1
1,1,34,34,34,34,34,34,34,34,34,34,34,34,1,1
1,1,34,34,34,34,34,34,34,34,34,34,34,34,1,1
1,1,34,34,34,34,34,34,1,1,1,1,1,1,1,1
1,1,34,34,34,34,34,34,1,1,32,32,32,32,1,1
1,1,34,34,34,34,34,34,1,32,36,35,36,35,32,1
1,1,34,34,34,34,34,34,1,32,35,36,35,36,32,1
1,1,1,1,34,34,34,34,1,32,36,35,36,35,32,1
1,33,33,1,34,34,34,34,1,32,35,36,35,20,1,1
1,33,33,1,1,1,1,1,1,1,32,32,32,1,1,1
1,1,1,1,1,1,1,1,1,1,1,1,1,1,1,1
endlayer

layer
1,37,38,37,37,38,37,38,37,37,37,37,37,38,37,1
37,0,0,0,0,11,0,0,0,0,0,0,0,0,0,37
38,0,0,0,0,40,0,40,0,39,0,0,0,0,0,38
37,0,0,41,40,0,0,40,0,40,0,42,41,0,0,37
37,0,0,40,40,40,0,39,42,40,0,40,0,0,0,37
37,0,40,40,0,40,0,0,0,40,0,40,40,0,11,38
38,0,40,39,0,42,40,40,0,40,39,0,0,40,0,37
1,0,42,40,40,0,0,40,0,0,0,40,42,0,0,37
0,0,40,0,39,40,0,0,40,42,0,0,0,40,0,37
0,0,0,40,40,40,42,0,0,40,0,0,40,0,0,37
1,0,40,42,0,39,0,40,0,0,0,0,0,11,0,37
37,0,0,39,0,40,0,40,0,43,44,17,17,44,43,37
37,0,0,40,40,42,0,40,0,44,47,0,46,45,44,38
37,11,0,0,40,0,40,0,0,12,0,0,11,48,44,37
37,0,0,41,0,40,0,42,0,12,0,0,0,0,44,37
38,0,0,0,0,42,0,0,0,44,51,50,0,49,44,37
37,0,0,0,0,0,0,0,11,43,44,44,44,44,43,37
1,37,37,37,37,37,38,37,37,37,37,37,38,37,37,1
endlayer

layer
1,38,37,37,38,37,37,37,38,37,37,37,38,37,37,1
37,0,0,0,0,0,0,0,0,0,0,0,0,0,0,38
37,0,0,0,0,0,0,0,0,0,0,0,0,0,0,37
38,0,0,41,0,0,0,0,0,0,0,52,41,0,0,37
37,0,0,0,0,0,0,0,52,0,0,0,0,0,0,38
37,0,0,0,0,0,0,0,0,0,0,0,0,0,0,37
37,0,0,0,0,52,0,0,0,0,0,0,0,0,0,37
1,0,52,0,0,0,0,0,0,0,0,0,52,0,0,37
0,0,0,0,0,0,0,0,0,52,0,0,0,0,0,38
0,0,0,0,0,0,52,0,0,0,0,0,0,0,0,37
1,0,0,52,0,0,0,0,0,0,0,0,0,0,0,37
37,0,0,0,0,0,0,0,0,43,44,45,45,44,43,38
38,0,0,0,0,52,0,0,0,44,0,0,0,53,44,37
37,0,0,0,0,0,0,0,0,27,0,0,0,0,44,37
37,0,0,41,0,0,0,52,0,29,0,0,0,0,44,37
37,0,0,0,0,52,0,0,0,44,0,0,0,20,44,38
37,0,0,0,0,0,0,0,0,43,44,44,44,44,43,37
1,37,37,38,37,37,37,37,37,38,37,37,37,37,38,1
endlayer

layer
1,55,54,55,54,55,54,55,54,55,54,55,54,55,54,1
56,32,32,57,0,0,0,0,0,0,0,0,57,32,32,56
58,32,32,57,0,0,0,0,0,0,0,0,57,32,32,58
56,57,57,57,0,0,0,0,0,0,0,0,57,57,57,56
58,0,0,0,0,0,0,0,0,0,0,0,0,0,0,58
56,0,0,0,0,0,0,0,0,0,0,0,0,0,0,56
58,0,0,0,0,0,0,0,0,0,0,0,0,0,0,58
1,0,0,0,0,0,0,0,0,0,0,0,0,0,0,56
0,0,0,0,0,0,0,0,0,0,0,0,0,0,0,58
0,0,0,0,0,0,0,0,0,0,0,0,0,0,0,56
1,0,0,0,0,0,0,0,0,0,0,0,0,0,0,58
56,0,0,0,0,0,0,0,0,43,44,45,45,44,43,56
58,0,0,0,0,0,0,0,0,44,0,0,0,0,44,58
56,0,0,0,0,0,0,0,0,31,0,0,0,0,44,56
58,57,57,57,0,0,0,0,0,31,0,0,0,0,44,58
56,32,32,57,0,0,0,0,0,44,0,0,0,20,44,56
58,32,32,57,0,0,0,0,0,43,44,44,44,44,43,58
1,55,54,55,54,55,54,55,54,55,54,55,54,55,54,1
endlayer

layer
41,0,0,0,0,0,0,0,0,0,0,0,0,0,0,41
0,0,0,0,0,0,0,0,0,0,0,0,0,0,0,0
0,0,0,0,0,0,0,0,0,0,0,0,0,0,0,0
0,0,0,0,0,0,0,0,0,0,0,0,0,0,0,0
0,0,0,0,0,0,0,0,0,0,0,0,0,0,0,0
0,0,0,0,0,0,0,0,0,0,0,0,0,0,0,0
0,0,0,0,0,0,0,0,0,0,0,0,0,0,0,0
58,0,0,0,0,0,0,0,0,0,0,0,0,0,0,0
31,0,0,0,0,0,0,0,0,0,0,0,0,0,0,0
31,0,0,0,0,0,0,0,0,0,0,0,0,0,0,0
56,0,0,0,0,0,0,0,0,0,0,0,0,0,0,0
0,0,0,0,0,0,0,0,0,43,44,48,48,44,43,0
0,0,0,0,0,0,0,0,0,44,0,0,0,0,44,0
0,0,0,0,0,0,0,0,0,59,0,0,0,0,44,0
0,0,0,0,0,0,0,0,0,59,0,0,0,0,44,0
0,0,0,0,0,0,0,0,0,44,0,0,0,20,44,0
0,0,0,0,0,0,0,0,0,43,44,44,44,44,43,0
41,0,0,0,0,0,0,0,0,0,0,0,0,0,0,41
endlayer

layer
0,0,0,0,0,0,0,0,0,0,0,0,0,0,0,0
0,0,0,0,0,0,0,0,0,0,0,0,0,0,0,0
0,0,0,0,0,0,0,0,0,0,0,0,0,0,0,0
0,0,0,0,0,0,0,0,0,0,0,0,0,0,0,0
0,0,0,0,0,0,0,0,0,0,0,0,0,0,0,0
0,0,0,0,0,0,0,0,0,0,0,0,0,0,0,0
0,0,0,0,0,0,0,0,0,0,0,0,0,0,0,0
0,0,0,0,0,0,0,0,0,0,0,0,0,0,0,0
58,0,0,0,0,0,0,0,0,0,0,0,0,0,0,0
56,0,0,0,0,0,0,0,0,0,0,0,0,0,0,0
0,0,0,0,0,0,0,0,0,0,0,0,0,0,0,0
0,0,0,0,0,0,0,0,0,43,60,60,60,60,43,0
0,0,0,0,0,0,0,0,0,61,36,35,36,35,61,0
0,0,0,0,0,0,0,0,0,61,35,36,35,36,61,0
0,0,0,0,0,0,0,0,0,61,36,35,36,35,61,0
0,0,0,0,0,0,0,0,0,61,35,36,35,20,61,0
0,0,0,0,0,0,0,0,0,43,60,60,60,60,43,0
0,0,0,0,0,0,0,0,0,0,0,0,0,0,0,0
endlayer

layer
0,0,0,0,0,0,0,0,0,0,0,0,0,0,0,0
0,0,0,0,0,0,0,0,0,0,0,0,0,0,0,0
0,0,0,0,0,0,0,0,0,0,0,0,0,0,0,0
0,0,0,0,0,0,0,0,0,0,0,0,0,0,0,0
0,0,0,0,0,0,0,0,0,0,0,0,0,0,0,0
0,0,0,0,0,0,0,0,0,0,0,0,0,0,0,0
0,0,0,0,0,0,0,0,0,0,0,0,0,0,0,0
0,0,0,0,0,0,0,0,0,0,0,0,0,0,0,0
0,0,0,0,0,0,0,0,0,0,0,0,0,0,0,0
0,0,0,0,0,0,0,0,0,0,0,0,0,0,0,0
0,0,0,0,0,0,0,0,0,0,0,0,0,0,0,0
0,0,0,0,0,0,0,0,0,43,44,17,17,44,43,0
0,0,0,0,0,0,0,0,0,44,0,0,0,0,44,0
0,0,0,0,0,0,0,0,0,63,0,11,0,0,62,0
0,0,0,0,0,0,0,0,0,63,0,0,0,0,62,0
0,0,0,0,0,0,0,0,0,44,0,0,0,49,44,0
0,0,0,0,0,0,0,0,0,43,44,14,14,44,43,0
0,0,0,0,0,0,0,0,0,0,0,0,0,0,0,0
endlayer

layer
0,0,0,0,0,0,0,0,0,0,0,0,0,0,0,0
0,0,0,0,0,0,0,0,0,0,0,0,0,0,0,0
0,0,0,0,0,0,0,0,0,0,0,0,0,0,0,0
0,0,0,0,0,0,0,0,0,0,0,0,0,0,0,0
0,0,0,0,0,0,0,0,0,0,0,0,0,0,0,0
0,0,0,0,0,0,0,0,0,0,0,0,0,0,0,0
0,0,0,0,0,0,0,0,0,0,0,0,0,0,0,0
0,0,0,0,0,0,0,0,0,0,0,0,0,0,0,0
0,0,0,0,0,0,0,0,0,0,0,0,0,0,0,0
0,0,0,0,0,0,0,0,0,0,0,0,0,0,0,0
0,0,0,0,0,0,0,0,0,0,0,0,0,0,0,0
0,0,0,0,0,0,0,0,0,43,44,45,45,44,43,0
0,0,0,0,0,0,0,0,0,44,0,0,0,0,44,0
0,0,0,0,0,0,0,0,0,45,0,0,0,0,45,0
0,0,0,0,0,0,0,0,0,45,0,0,0,0,45,0
0,0,0,0,0,0,0,0,0,44,0,0,0,20,44,0
0,0,0,0,0,0,0,0,0,43,44,45,45,44,43,0
0,0,0,0,0,0,0,0,0,0,0,0,0,0,0,0
endlayer

layer
0,0,0,0,0,0,0,0,0,0,0,0,0,0,0,0
0,0,0,0,0,0,0,0,0,0,0,0,0,0,0,0
0,0,0,0,0,0,0,0,0,0,0,0,0,0,0,0
0,0,0,0,0,0,0,0,0,0,0,0,0,0,0,0
0,0,0,0,0,0,0,0,0,0,0,0,0,0,0,0
0,0,0,0,0,0,0,0,0,0,0,0,0,0,0,0
0,0,0,0,0,0,0,0,0,0,0,0,0,0,0,0
0,0,0,0,0,0,0,0,0,0,0,0,0,0,0,0
0,0,0,0,0,0,0,0,0,0,0,0,0,0,0,0
0,0,0,0,0,0,0,0,0,0,0,0,0,0,0,0
0,0,0,0,0,0,0,0,0,0,0,0,0,0,0,0
0,0,0,0,0,0,0,0,0,43,44,45,45,44,43,0
0,0,0,0,0,0,0,0,0,44,0,0,0,0,44,0
0,0,0,0,0,0,0,0,0,45,0,0,0,0,45,0
0,0,0,0,0,0,0,0,0,45,0,0,0,0,45,0
0,0,0,0,0,0,0,0,0,44,0,0,0,20,44,0
0,0,0,0,0,0,0,0,0,43,44,45,45,44,43,0
0,0,0,0,0,0,0,0,0,0,0,0,0,0,0,0
endlayer

layer
0,0,0,0,0,0,0,0,0,0,0,0,0,0,0,0
0,0,0,0,0,0,0,0,0,0,0,0,0,0,0,0
0,0,0,0,0,0,0,0,0,0,0,0,0,0,0,0
0,0,0,0,0,0,0,0,0,0,0,0,0,0,0,0
0,0,0,0,0,0,0,0,0,0,0,0,0,0,0,0
0,0,0,0,0,0,0,0,0,0,0,0,0,0,0,0
0,0,0,0,0,0,0,0,0,0,0,0,0,0,0,0
0,0,0,0,0,0,0,0,0,0,0,0,0,0,0,0
0,0,0,0,0,0,0,0,0,0,0,0,0,0,0,0
0,0,0,0,0,0,0,0,0,0,0,0,0,0,0,0
0,0,0,0,0,0,0,0,0,0,0,0,0,0,0,0
0,0,0,0,0,0,0,0,0,43,44,48,48,44,43,0
0,0,0,0,0,0,0,0,0,44,36,35,36,35,44,0
0,0,0,0,0,0,0,0,0,59,35,36,35,36,46,0
0,0,0,0,0,0,0,0,0,59,36,35,36,35,46,0
0,0,0,0,0,0,0,0,0,44,35,36,35,20,44,0
0,0,0,0,0,0,0,0,0,43,44,64,64,44,43,0
0,0,0,0,0,0,0,0,0,0,0,0,0,0,0,0
endlayer

layer
0,0,0,0,0,0,0,0,0,0,0,0,0,0,0,0
0,0,0,0,0,0,0,0,0,0,0,0,0,0,0,0
0,0,0,0,0,0,0,0,0,0,0,0,0,0,0,0
0,0,0,0,0,0,0,0,0,0,0,0,0,0,0,0
0,0,0,0,0,0,0,0,0,0,0,0,0,0,0,0
0,0,0,0,0,0,0,0,0,0,0,0,0,0,0,0
0,0,0,0,0,0,0,0,0,0,0,0,0,0,0,0
0,0,0,0,0,0,0,0,0,0,0,0,0,0,0,0
0,0,0,0,0,0,0,0,0,0,0,0,0,0,0,0
0,0,0,0,0,0,0,0,0,0,0,0,0,0,0,0
0,0,0,0,0,0,0,0,0,0,0,0,0,0,0,0
0,0,0,0,0,0,0,0,0,43,60,60,60,60,43,0
0,0,0,0,0,0,0,0,0,61,0,65,65,0,61,0
0,0,0,0,0,0,0,0,0,61,11,0,0,0,61,0
0,0,0,0,0,0,0,0,0,61,0,0,0,0,61,0
0,0,0,0,0,0,0,0,0,61,11,50,50,49,61,0
0,0,0,0,0,0,0,0,0,43,60,60,60,60,43,0
0,0,0,0,0,0,0,0,0,0,0,0,0,0,0,0
endlayer

layer
0,0,0,0,0,0,0,0,0,0,0,0,0,0,0,0
0,0,0,0,0,0,0,0,0,0,0,0,0,0,0,0
0,0,0,0,0,0,0,0,0,0,0,0,0,0,0,0
0,0,0,0,0,0,0,0,0,0,0,0,0,0,0,0
0,0,0,0,0,0,0,0,0,0,0,0,0,0,0,0
0,0,0,0,0,0,0,0,0,0,0,0,0,0,0,0
0,0,0,0,0,0,0,0,0,0,0,0,0,0,0,0
0,0,0,0,0,0,0,0,0,0,0,0,0,0,0,0
0,0,0,0,0,0,0,0,0,0,0,0,0,0,0,0
0,0,0,0,0,0,0,0,0,0,0,0,0,0,0,0
0,0,0,0,0,0,0,0,48,48,48,48,48,48,48,48
0,0,0,0,0,0,0,0,14,43,66,64,64,66,43,14
0,0,0,0,0,0,0,0,0,43,0,0,0,0,43,0
0,0,0,0,0,0,0,0,0,45,0,0,0,0,45,0
0,0,0,0,0,0,0,0,0,45,0,0,0,0,45,0
0,0,0,0,0,0,0,0,0,43,0,0,0,0,43,0
0,0,0,0,0,0,0,0,17,43,66,48,48,66,43,17
0,0,0,0,0,0,0,0,64,64,64,64,64,64,64,64
endlayer

layer
0,0,0,0,0,0,0,0,0,0,0,0,0,0,0,0
0,0,0,0,0,0,0,0,0,0,0,0,0,0,0,0
0,0,0,0,0,0,0,0,0,0,0,0,0,0,0,0
0,0,0,0,0,0,0,0,0,0,0,0,0,0,0,0
0,0,0,0,0,0,0,0,0,0,0,0,0,0,0,0
0,0,0,0,0,0,0,0,0,0,0,0,0,0,0,0
0,0,0,0,0,0,0,0,0,0,0,0,0,0,0,0
0,0,0,0,0,0,0,0,0,0,0,0,0,0,0,0
0,0,0,0,0,0,0,0,0,0,0,0,0,0,0,0
0,0,0,0,0,0,0,0,0,0,0,0,0,0,0,0
0,0,0,0,0,0,0,0,0,0,0,0,0,0,0,0
0,0,0,0,0,0,0,0,66,66,66,45,45,66,66,66
0,0,0,0,0,0,0,0,0,43,0,0,0,0,43,0
0,0,0,0,0,0,0,0,0,45,0,0,0,0,45,0
0,0,0,0,0,0,0,0,0,45,0,0,0,0,45,0
0,0,0,0,0,0,0,0,0,43,0,0,0,0,43,0
0,0,0,0,0,0,0,0,66,66,66,45,45,66,66,66
0,0,0,0,0,0,0,0,0,0,0,0,0,0,0,0
endlayer

layer
0,0,0,0,0,0,0,0,0,0,0,0,0,0,0,0
0,0,0,0,0,0,0,0,0,0,0,0,0,0,0,0
0,0,0,0,0,0,0,0,0,0,0,0,0,0,0,0
0,0,0,0,0,0,0,0,0,0,0,0,0,0,0,0
0,0,0,0,0,0,0,0,0,0,0,0,0,0,0,0
0,0,0,0,0,0,0,0,0,0,0,0,0,0,0,0
0,0,0,0,0,0,0,0,0,0,0,0,0,0,0,0
0,0,0,0,0,0,0,0,0,0,0,0,0,0,0,0
0,0,0,0,0,0,0,0,0,0,0,0,0,0,0,0
0,0,0,0,0,0,0,0,0,0,0,0,0,0,0,0
0,0,0,0,0,0,0,0,0,0,0,0,0,0,0,0
0,0,0,0,0,0,0,0,66,66,66,14,14,66,66,66
0,0,0,0,0,0,0,0,0,43,0,0,0,0,43,0
0,0,0,0,0,0,0,0,0,45,0,0,0,0,45,0
0,0,0,0,0,0,0,0,0,45,0,0,0,0,45,0
0,0,0,0,0,0,0,0,0,43,0,0,0,0,43,0
0,0,0,0,0,0,0,0,66,66,66,17,17,66,66,66
0,0,0,0,0,0,0,0,0,0,0,0,0,0,0,0
endlayer

layer
0,0,0,0,0,0,0,0,0,0,0,0,0,0,0,0
0,0,0,0,0,0,0,0,0,0,0,0,0,0,0,0
0,0,0,0,0,0,0,0,0,0,0,0,0,0,0,0
0,0,0,0,0,0,0,0,0,0,0,0,0,0,0,0
0,0,0,0,0,0,0,0,0,0,0,0,0,0,0,0
0,0,0,0,0,0,0,0,0,0,0,0,0,0,0,0
0,0,0,0,0,0,0,0,0,0,0,0,0,0,0,0
0,0,0,0,0,0,0,0,0,0,0,0,0,0,0,0
0,0,0,0,0,0,0,0,0,0,0,0,0,0,0,0
0,0,0,0,0,0,0,0,0,0,0,0,0,0,0,0
0,0,0,0,0,0,0,0,0,0,0,0,0,0,0,0
0,0,0,0,0,0,0,0,48,48,48,48,48,48,48,48
0,0,0,0,0,0,0,0,14,43,14,14,14,14,43,14
0,0,0,0,0,0,0,0,0,61,0,0,0,0,61,0
0,0,0,0,0,0,0,0,0,61,0,0,0,0,61,0
0,0,0,0,0,0,0,0,17,43,17,17,17,17,43,17
0,0,0,0,0,0,0,0,64,64,64,64,64,64,64,64
0,0,0,0,0,0,0,0,0,0,0,0,0,0,0,0
endlayer

layer
0,0,0,0,0,0,0,0,0,0,0,0,0,0,0,0
0,0,0,0,0,0,0,0,0,0,0,0,0,0,0,0
0,0,0,0,0,0,0,0,0,0,0,0,0,0,0,0
0,0,0,0,0,0,0,0,0,0,0,0,0,0,0,0
0,0,0,0,0,0,0,0,0,0,0,0,0,0,0,0
0,0,0,0,0,0,0,0,0,0,0,0,0,0,0,0
0,0,0,0,0,0,0,0,0,0,0,0,0,0,0,0
0,0,0,0,0,0,0,0,0,0,0,0,0,0,0,0
0,0,0,0,0,0,0,0,0,0,0,0,0,0,0,0
0,0,0,0,0,0,0,0,0,0,0,0,0,0,0,0
0,0,0,0,0,0,0,0,0,0,0,0,0,0,0,0
0,0,0,0,0,0,0,0,0,0,0,0,0,0,0,0
0,0,0,0,0,0,0,0,66,66,66,66,66,66,66,66
0,0,0,0,0,0,0,0,0,44,0,0,0,0,44,0
0,0,0,0,0,0,0,0,0,44,0,0,0,0,44,0
0,0,0,0,0,0,0,0,66,66,66,66,66,66,66,66
0,0,0,0,0,0,0,0,0,0,0,0,0,0,0,0
0,0,0,0,0,0,0,0,0,0,0,0,0,0,0,0
endlayer

layer
0,0,0,0,0,0,0,0,0,0,0,0,0,0,0,0
0,0,0,0,0,0,0,0,0,0,0,0,0,0,0,0
0,0,0,0,0,0,0,0,0,0,0,0,0,0,0,0
0,0,0,0,0,0,0,0,0,0,0,0,0,0,0,0
0,0,0,0,0,0,0,0,0,0,0,0,0,0,0,0
0,0,0,0,0,0,0,0,0,0,0,0,0,0,0,0
0,0,0,0,0,0,0,0,0,0,0,0,0,0,0,0
0,0,0,0,0,0,0,0,0,0,0,0,0,0,0,0
0,0,0,0,0,0,0,0,0,0,0,0,0,0,0,0
0,0,0,0,0,0,0,0,0,0,0,0,0,0,0,0
0,0,0,0,0,0,0,0,0,0,0,0,0,0,0,0
0,0,0,0,0,0,0,0,0,0,0,0,0,0,0,0
0,0,0,0,0,0,0,0,66,66,66,66,66,66,66,66
0,0,0,0,0,0,0,0,0,44,0,0,0,0,44,0
0,0,0,0,0,0,0,0,0,44,0,0,0,0,44,0
0,0,0,0,0,0,0,0,66,66,66,66,66,66,66,66
0,0,0,0,0,0,0,0,0,0,0,0,0,0,0,0
0,0,0,0,0,0,0,0,0,0,0,0,0,0,0,0
endlayer

layer
0,0,0,0,0,0,0,0,0,0,0,0,0,0,0,0
0,0,0,0,0,0,0,0,0,0,0,0,0,0,0,0
0,0,0,0,0,0,0,0,0,0,0,0,0,0,0,0
0,0,0,0,0,0,0,0,0,0,0,0,0,0,0,0
0,0,0,0,0,0,0,0,0,0,0,0,0,0,0,0
0,0,0,0,0,0,0,0,0,0,0,0,0,0,0,0
0,0,0,0,0,0,0,0,0,0,0,0,0,0,0,0
0,0,0,0,0,0,0,0,0,0,0,0,0,0,0,0
0,0,0,0,0,0,0,0,0,0,0,0,0,0,0,0
0,0,0,0,0,0,0,0,0,0,0,0,0,0,0,0
0,0,0,0,0,0,0,0,0,0,0,0,0,0,0,0
0,0,0,0,0,0,0,0,0,0,0,0,0,0,0,0
0,0,0,0,0,0,0,0,48,48,48,48,48,48,48,48
0,0,0,0,0,0,0,0,14,44,14,14,14,14,44,14
0,0,0,0,0,0,0,0,17,44,17,17,17,17,44,17
0,0,0,0,0,0,0,0,64,64,64,64,64,64,64,64
0,0,0,0,0,0,0,0,0,0,0,0,0,0,0,0
0,0,0,0,0,0,0,0,0,0,0,0,0,0,0,0
endlayer

layer
0,0,0,0,0,0,0,0,0,0,0,0,0,0,0,0
0,0,0,0,0,0,0,0,0,0,0,0,0,0,0,0
0,0,0,0,0,0,0,0,0,0,0,0,0,0,0,0
0,0,0,0,0,0,0,0,0,0,0,0,0,0,0,0
0,0,0,0,0,0,0,0,0,0,0,0,0,0,0,0
0,0,0,0,0,0,0,0,0,0,0,0,0,0,0,0
0,0,0,0,0,0,0,0,0,0,0,0,0,0,0,0
0,0,0,0,0,0,0,0,0,0,0,0,0,0,0,0
0,0,0,0,0,0,0,0,0,0,0,0,0,0,0,0
0,0,0,0,0,0,0,0,0,0,0,0,0,0,0,0
0,0,0,0,0,0,0,0,0,0,0,0,0,0,0,0
0,0,0,0,0,0,0,0,0,0,0,0,0,0,0,0
0,0,0,0,0,0,0,0,0,0,0,0,0,0,0,0
0,0,0,0,0,0,0,0,66,66,66,66,66,66,66,66
0,0,0,0,0,0,0,0,66,66,66,66,66,66,66,66
0,0,0,0,0,0,0,0,0,0,0,0,0,0,0,0
0,0,0,0,0,0,0,0,0,0,0,0,0,0,0,0
0,0,0,0,0,0,0,0,0,0,0,0,0,0,0,0
endlayer

layer
0,0,0,0,0,0,0,0,0,0,0,0,0,0,0,0
0,0,0,0,0,0,0,0,0,0,0,0,0,0,0,0
0,0,0,0,0,0,0,0,0,0,0,0,0,0,0,0
0,0,0,0,0,0,0,0,0,0,0,0,0,0,0,0
0,0,0,0,0,0,0,0,0,0,0,0,0,0,0,0
0,0,0,0,0,0,0,0,0,0,0,0,0,0,0,0
0,0,0,0,0,0,0,0,0,0,0,0,0,0,0,0
0,0,0,0,0,0,0,0,0,0,0,0,0,0,0,0
0,0,0,0,0,0,0,0,0,0,0,0,0,0,0,0
0,0,0,0,0,0,0,0,0,0,0,0,0,0,0,0
0,0,0,0,0,0,0,0,0,0,0,0,0,0,0,0
0,0,0,0,0,0,0,0,0,0,0,0,0,0,0,0
0,0,0,0,0,0,0,0,0,0,0,0,0,0,0,0
0,0,0,0,0,0,0,0,66,66,66,66,66,66,66,66
0,0,0,0,0,0,0,0,66,66,66,66,66,66,66,66
0,0,0,0,0,0,0,0,0,0,0,0,0,0,0,0
0,0,0,0,0,0,0,0,0,0,0,0,0,0,0,0
0,0,0,0,0,0,0,0,0,0,0,0,0,0,0,0
endlayer

layer
0,0,0,0,0,0,0,0,0,0,0,0,0,0,0,0
0,0,0,0,0,0,0,0,0,0,0,0,0,0,0,0
0,0,0,0,0,0,0,0,0,0,0,0,0,0,0,0
0,0,0,0,0,0,0,0,0,0,0,0,0,0,0,0
0,0,0,0,0,0,0,0,0,0,0,0,0,0,0,0
0,0,0,0,0,0,0,0,0,0,0,0,0,0,0,0
0,0,0,0,0,0,0,0,0,0,0,0,0,0,0,0
0,0,0,0,0,0,0,0,0,0,0,0,0,0,0,0
0,0,0,0,0,0,0,0,0,0,0,0,0,0,0,0
0,0,0,0,0,0,0,0,0,0,0,0,0,0,0,0
0,0,0,0,0,0,0,0,0,0,0,0,0,0,0,0
0,0,0,0,0,0,0,0,0,0,0,0,0,0,0,0
0,0,0,0,0,0,0,0,0,0,0,0,0,0,0,0
0,0,0,0,0,0,0,0,66,48,48,48,48,48,48,66
0,0,0,0,0,0,0,0,66,64,64,64,64,64,64,66
0,0,0,0,0,0,0,0,0,0,0,0,0,0,0,0
0,0,0,0,0,0,0,0,0,0,0,0,0,0,0,0
0,0,0,0,0,0,0,0,0,0,0,0,0,0,0,0
endlayer

layer
0,0,0,0,0,0,0,0,0,0,0,0,0,0,0,0
0,0,0,0,0,0,0,0,0,0,0,0,0,0,0,0
0,0,0,0,0,0,0,0,0,0,0,0,0,0,0,0
0,0,0,0,0,0,0,0,0,0,0,0,0,0,0,0
0,0,0,0,0,0,0,0,0,0,0,0,0,0,0,0
0,0,0,0,0,0,0,0,0,0,0,0,0,0,0,0
0,0,0,0,0,0,0,0,0,0,0,0,0,0,0,0
0,0,0,0,0,0,0,0,0,0,0,0,0,0,0,0
0,0,0,0,0,0,0,0,0,0,0,0,0,0,0,0
0,0,0,0,0,0,0,0,0,0,0,0,0,0,0,0
0,0,0,0,0,0,0,0,0,0,0,0,0,0,0,0
0,0,0,0,0,0,0,0,0,0,0,0,0,0,0,0
0,0,0,0,0,0,0,0,0,0,0,0,0,0,0,0
0,0,0,0,0,0,0,0,46,0,0,0,0,0,0,59
0,0,0,0,0,0,0,0,46,0,0,0,0,0,0,59
0,0,0,0,0,0,0,0,0,0,0,0,0,0,0,0
0,0,0,0,0,0,0,0,0,0,0,0,0,0,0,0
0,0,0,0,0,0,0,0,0,0,0,0,0,0,0,0
endlayer

