# Conjurer Tower
# MC 1.7.10; created 24 Oct 2014
# Created by Ruins mod version 13.8 Ingame Parser
# authoring Player: Jordan_Greywolf
# Updated to MC 1.8: 28 Feb 2016
# Updated to MC 1.9: 29 Apr 2016
# Updated to MC 1.12: 23 Jun 2017
# Updated to MC 1.12.1: 9 Sep 2017

biomesToSpawnIn=dead forest,dead swamp,alps forest,forest,foresthills,plains,savanna plateau,extreme hills edge,magical forest,mystic grove,ominous woods,thick ominous woods,twilight clearing,highland,mountain,dungeon,tainted land,eerie,eldritch,rwg_coldforest,rwg_hotforest,rwg_snowforest,rwg_temperateforest,forest_hills,mutated_savanna_rock,savanna_rock,smaller_extreme_hills,mining_biome,mining biome

weight=1
embed_into_distance=5
acceptable_target_blocks=

unacceptable_target_blocks=flowing_water,water,flowing_lava,lava,cloud,Natura:Cloud,red_mushroom_block,brown_mushroom_block,slime_congealed,slime_dirt,slime_grass,command_block

dimensions=33,13,14
allowable_overhang=0
max_leveling=5
leveling_buffer=-1
preserve_water=0
preserve_lava=0
preserve_plants=1

rule1=0,100,minecraft:grass-0
rule2=0,100,minecraft:dirt-0
rule3=0,100,minecraft:cobblestone-0
rule4=0,100,minecraft:double_stone_slab-0
rule5=0,100,CommandBlock:/testruin TP_CBTrap_SnowBoom ~0 ~0 ~0:@
rule6=0,100,minecraft:sandstone-2
rule7=0,100,CommandBlock:/testruin TP_CBTrap_Phantom ~0 ~0 ~0:@

rule8=0,100,CommandBlock:/testruin TP_CBTrap_BoomCow ~0 ~0 ~0:@

rule9=0,100,CommandBlock:/testruin TP_CBTrap_Heatsqueaker ~0 ~0 ~0:@

rule10=0,100,minecraft:tallgrass-1,minecraft:tallgrass-1,minecraft:tallgrass-2,minecraft:red_flower,minecraft:red_flower-3,minecraft:tallgrass-1
rule11=0,100,minecraft:double_plant-2

rule12=0,100,IInventory;minecraft:trapped_chest;minecraft:water_bucket#8#0#0+minecraft:packed_ice#8#0#1+minecraft:ice#8#0#2-5

rule13=0,100,minecraft:ladder-3
rule14=0,100,IInventory;minecraft:trapped_chest;minecraft:item_frame#8#0#0+minecraft:clock#1#0#1+minecraft:web#8#0#2-3

rule15=1,100,StandingSign:WARNING::Do not tamper!:DANGER!:You are warned!-8

rule16=0,100,IInventory;minecraft:trapped_chest;minecraft:grass#8#0#0+minecraft:mycelium#8#0#1+minecraft:dirt#8#2#2-2

rule17=0,100,IInventory;minecraft:trapped_chest;minecraft:lava_bucket#8#0#0+minecraft:blaze_powder#2#0#1-4

rule18=0,100,minecraft:fence-0
rule19=0,100,minecraft:stone_stairs-2
rule20=0,100,minecraft:double_plant-8
rule21=0,100,minecraft:double_plant-9
rule22=2,100,WallSign:null:Water:Element:null-5
rule23=0,100,minecraft:double_plant-10
rule24=2,100,WallSign:null:Air:Element:null-3
rule25=2,100,WallSign:null:Earth:Element:null-2
rule26=2,100,WallSign:null:Fire:Element:null-4
rule27=0,100,minecraft:oak_stairs-7
rule28=0,100,minecraft:double_plant-11
rule29=0,100,minecraft:web-0
rule30=0,100,minecraft:planks-0
rule31=0,100,minecraft:stone_stairs-0
rule32=0,100,minecraft:oak_stairs-2
rule33=0,100,minecraft:oak_stairs-6
rule34=0,100,minecraft:oak_stairs-4
rule35=0,100,minecraft:oak_stairs-5
rule36=0,100,minecraft:oak_stairs-1
rule37=0,100,minecraft:wooden_slab-8
rule38=0,100,minecraft:cobblestone_wall-0
rule39=0,100,minecraft:stone_stairs-4
rule40=0,100,minecraft:oak_stairs-0
rule41=0,100,minecraft:wooden_door-0
rule42=0,100,minecraft:stone_stairs-1
rule43=2,100,minecraft:redstone_torch-5
rule44=2,100,minecraft:ladder-2
rule45=0,100,minecraft:wooden_door-8
rule46=0,100,minecraft:stone_stairs-5
rule47=0,100,minecraft:stone_stairs-6
rule48=0,100,minecraft:stone_stairs-7
rule49=0,100,minecraft:planks-5
rule50=0,100,minecraft:stone_slab-3
rule51=0,100,minecraft:wooden_slab-4
rule52=0,100,minecraft:wooden_slab-5
rule53=0,100,minecraft:dark_oak_stairs-1
rule54=0,100,minecraft:dark_oak_stairs-0
rule55=2,100,minecraft:trapdoor-2
rule56=0,100,minecraft:quartz_block-0
rule57=0,100,minecraft:stained_glass_pane-0
rule58=2,100,minecraft:ladder-5
rule59=0,100,ChestGenHook:chests/spawn_bonus_chest:2-2
rule60=1,100,minecraft:wooden_door-3
rule61=0,100,IInventory;minecraft:lit_furnace;minecraft:coal#1#1#1-3
rule62=2,100,minecraft:ladder-4
rule63=0,100,minecraft:bookshelf-0
rule64=0,100,minecraft:dark_oak_stairs-4
rule65=0,100,minecraft:dark_oak_stairs-6
rule66=0,100,minecraft:dark_oak_stairs-7
rule67=0,100,minecraft:dark_oak_stairs-5
rule68=0,100,minecraft:oak_stairs-3

# Magic Cat
rule69=0,100,CommandBlock:RUINSTRIGGER /summon Ocelot ~0 ~0 ~0 {AbsorptionAmount:25,CustomName:"Magic Siamese",Health:250.0f,ActiveEffects:[{Id:12,Amplifier:1,Duration:999999},{Id:10,Amplifier:1,Duration:999999},{Id:13,Amplifier:1,Duration:999999}],PersistenceRequired:1,Silent:1,CatType:3,Invulnerable:1}:@

# Cat Familiar
rule70=0,100,CommandBlock:RUINSTRIGGER /summon Ocelot ~0 ~0 ~0 {CustomName:"Cat Familiar",AbsorptionAmount:25,Health:250.0f,ActiveEffects:[{Id:12,Amplifier:1,Duration:999999},{Id:10,Amplifier:1,Duration:999999},{Id:13,Amplifier:1,Duration:999999}],PersistenceRequired:1,Silent:1,CatType:1,Invulnerable:1}:@

# Villager: Conjurer
rule71=0,100,CommandBlock:RUINSTRIGGER /summon Villager ~0 ~0 ~0 {Profession:1,Career:1,CareerLevel:6,CustomName:Conjurer,Silent:1,Offers:{Recipes:[{buy:{id:brewing_stand,Count:1},sell:{id:emerald,Count:1}},{buy:{id:cauldron,Count:1},sell:{id:emerald,Count:1}},{buy:{id:enchanting_table,Count:1},sell:{id:emerald,Count:1}},{buy:{id:spider_eye,Count:32},sell:{id:emerald,Count:1}},{buy:{id:ghast_tear,Count:8},sell:{id:emerald,Count:1}},{buy:{id:speckled_melon,Count:4},sell:{id:emerald,Count:1}},{buy:{id:rotten_flesh,Count:32},sell:{id:emerald,Count:1}},{buy:{id:blaze_rod,Count:32},sell:{id:emerald,Count:1}},{buy:{id:emerald,Count:20},sell:{id:spawn_egg,Damage:96,Count:1}},{buy:{id:emerald,Count:20},sell:{id:spawn_egg,Damage:100,Count:1}},{buy:{id:emerald,Count:20},sell:{id:spawn_egg,Damage:120,Count:1}},{buy:{id:emerald,Count:20},sell:{id:spawn_egg,Damage:98,Count:1}}]}}:@

rule72=0,100,minecraft:redstone_wire-14
rule73=0,100,minecraft:redstone_wire-15
rule74=0,100,minecraft:fence_gate-0

# Villager: Relic Trader
rule75=0,100,CommandBlock:RUINSTRIGGER /summon Villager ~0 ~0 ~0 {Profession:1,Career:1,CareerLevel:6,CustomName:"Relic Trader",Silent:1,Offers:{Recipes:[{buy:{id:emerald,Count:8},sell:{id:skull,Count:1,Damage:3,tag:{display:{Name:"Head of Herobrine"},SkullOwner:"MHF_Herobrine"}}},{buy:{id:emerald,Count:4},sell:{id:skull,Count:1,Damage:3,tag:{display:{Name:"Box of Mysteries"},SkullOwner:"MHF_Question"}}},{buy:{id:emerald,Count:4},sell:{id:skull,Count:1,Damage:3,tag:{display:{Name:"Box of Imperative"},SkullOwner:"MHF_Exclamation"}}},{buy:{id:emerald,Count:4},sell:{id:skull,Count:1,Damage:3,tag:{display:{Name:"Head of Pig Zombie"},SkullOwner:"MHF_PigZombie"}}},{buy:{id:emerald,Count:4},sell:{id:skull,Count:1,Damage:3,tag:{display:{Name:"Head of Blaze"},SkullOwner:"MHF_Blaze"}}},{buy:{id:emerald,Count:4},sell:{id:skull,Count:1,Damage:3,tag:{display:{Name:"Head of Mooshroom"},SkullOwner:"MHF_MushroomCow"}}},{buy:{id:emerald,Count:4},sell:{id:skull,Count:1,Damage:3,tag:{display:{Name:"Head of Sorrows"},SkullOwner:"MHF_Ghast"}}},{buy:{id:emerald,Count:4},sell:{id:skull,Count:1,Damage:3,tag:{display:{Name:"Shrunken Head"},SkullOwner:"MHF_Villager"}}},{buy:{id:emerald,Count:1},sell:{id:slime_ball,Count:1}},{buy:{id:emerald,Count:1},sell:{id:grass,Count:32}},{buy:{id:emerald,Count:1},sell:{id:sand,Count:32}},{buy:{id:clock,Count:1},sell:{id:emerald,Count:1}},{buy:{id:golden_apple,Count:1},sell:{id:emerald,Count:1}}]}}:@

rule76=1,100,minecraft:torch-5
rule77=0,100,minecraft:carpet-14
rule78=0,100,minecraft:stained_glass-11
rule79=0,100,minecraft:iron_bars-0
rule80=0,100,minecraft:stained_glass-4
rule81=0,100,minecraft:glowstone-0
rule82=0,100,minecraft:stained_glass-13
rule83=0,100,minecraft:stained_glass-14
rule84=0,100,minecraft:wooden_slab-0
rule85=2,100,minecraft:trapdoor-02
rule86=0,100,preserveBlock

rule87=0,100,minecraft:lava-0

layer
86,86,86,1,1,1,1,1,1,1,1,86,86,86
86,86,1,1,1,1,1,1,1,1,1,1,86,86
86,1,1,2,2,1,1,1,2,2,1,1,1,86
1,1,2,2,3,3,3,3,3,2,2,1,1,1
1,1,2,3,3,4,4,4,3,3,2,2,1,1
1,1,1,3,4,6,4,6,4,3,2,1,1,1
1,1,1,3,4,4,6,4,4,3,1,1,1,1
1,1,2,3,4,6,4,6,4,3,1,1,1,1
1,2,2,3,3,4,4,4,3,3,1,1,1,1
1,1,2,1,3,3,3,3,3,1,1,1,1,1
86,1,1,1,1,1,3,3,3,1,1,1,1,86
86,86,1,1,1,1,1,1,1,1,1,1,86,86
86,86,86,1,1,1,1,1,1,1,1,86,86,86
endlayer

layer
86,86,86,1,1,1,1,1,1,1,1,86,86,86
86,86,1,1,1,1,1,1,1,1,1,1,86,86
86,1,1,2,2,1,1,1,2,2,1,1,1,86
1,1,2,2,3,3,3,3,3,2,2,1,1,1
1,1,2,3,3,4,4,4,3,3,2,2,1,1
1,1,1,3,4,6,4,6,4,3,2,1,1,1
1,1,1,3,4,4,6,4,4,3,1,1,1,1
1,1,2,3,4,6,4,6,4,3,1,1,1,1
1,2,2,3,3,4,4,4,3,3,1,1,1,1
1,1,2,1,3,3,3,3,3,1,1,1,1,1
86,1,1,1,1,1,3,3,3,1,1,1,1,86
86,86,1,1,1,1,1,1,1,1,1,1,86,86
86,86,86,1,1,1,1,1,1,1,1,86,86,86
endlayer

layer
86,86,86,1,1,1,1,1,1,1,1,86,86,86
86,86,1,1,1,1,1,1,1,1,1,1,86,86
86,1,1,2,2,1,1,1,2,2,1,1,1,86
1,1,2,2,3,3,3,3,3,2,2,1,1,1
1,1,2,3,3,4,4,4,3,3,2,2,1,1
1,1,1,3,4,87,87,87,4,3,2,1,1,1
1,1,1,3,4,87,87,87,4,3,1,1,1,1
1,1,2,3,4,87,87,87,4,3,1,1,1,1
1,2,2,3,3,4,4,4,3,3,1,1,1,1
1,1,2,1,3,3,3,3,3,1,1,1,1,1
86,1,1,1,1,1,3,3,3,1,1,1,1,86
86,86,1,1,1,1,1,1,1,1,1,1,86,86
86,86,86,1,1,1,1,1,1,1,1,86,86,86
endlayer

layer
86,86,86,1,1,1,1,1,1,1,1,86,86,86
86,86,1,1,1,1,1,1,1,1,1,1,86,86
86,1,1,2,2,1,1,1,2,2,1,1,1,86
1,1,2,2,3,3,3,3,3,2,2,1,1,1
1,1,2,3,3,4,4,4,3,3,2,2,1,1
1,1,1,3,4,87,87,87,4,3,2,1,1,1
1,1,1,3,4,87,87,87,4,3,1,1,1,1
1,1,2,3,4,87,87,87,4,3,1,1,1,1
1,2,2,3,3,4,4,4,3,3,1,1,1,1
1,1,2,1,3,3,3,3,3,1,1,1,1,1
86,1,1,1,1,1,3,3,3,1,1,1,1,86
86,86,1,1,1,1,1,1,1,1,1,1,86,86
86,86,86,1,1,1,1,1,1,1,1,86,86,86
endlayer

layer
86,86,86,1,1,1,1,1,1,1,1,86,86,86
86,86,1,1,1,1,1,1,1,1,1,1,86,86
86,1,1,2,2,1,1,1,2,2,1,1,1,86
1,1,2,2,3,3,3,3,3,2,2,1,1,1
1,1,2,3,3,4,4,4,3,3,2,2,1,1
1,1,1,3,4,87,87,87,4,3,2,1,1,1
1,1,1,3,4,87,87,87,4,3,1,1,1,1
1,1,2,3,4,87,87,87,4,3,1,1,1,1
1,2,2,3,3,4,4,4,3,3,1,1,1,1
1,1,2,1,3,3,3,3,3,1,1,1,1,1
86,1,1,1,1,1,3,3,3,1,1,1,1,86
86,86,1,1,1,1,1,1,1,1,1,1,86,86
86,86,86,1,1,1,1,1,1,1,1,86,86,86
endlayer



layer
86,86,86,1,1,1,1,1,1,1,1,86,86,86
86,86,1,1,1,1,1,1,1,1,1,1,86,86
86,1,1,2,2,1,1,1,2,2,1,1,1,86
1,1,2,2,3,3,3,3,3,2,2,1,1,1
1,1,2,3,3,4,5,4,3,3,2,2,1,1
1,1,1,3,4,6,4,6,4,3,2,1,1,1
1,1,1,3,8,4,6,4,7,3,1,1,1,1
1,1,2,3,4,6,4,6,4,3,1,1,1,1
1,2,2,3,3,4,9,4,3,3,1,1,1,1
1,1,2,1,3,3,3,3,3,1,1,1,1,1
86,1,1,1,1,1,3,3,3,1,1,1,1,86
86,86,1,1,1,1,1,1,1,1,1,1,86,86
86,86,86,1,1,1,1,1,1,1,1,86,86,86
endlayer

layer
86,86,0,10,0,10,0,10,0,0,0,0,86,86
86,0,0,10,0,11,10,0,10,0,11,0,0,86
0,0,10,1,1,0,11,10,1,1,10,0,0,0
10,10,1,2,3,3,3,3,3,2,1,0,10,0
11,0,1,3,3,0,12,0,3,3,2,1,11,0
0,10,11,3,0,0,0,0,13,3,2,11,10,10
0,10,0,3,16,0,15,0,14,3,0,0,10,0
0,0,1,3,0,0,0,0,0,3,10,0,0,0
10,1,1,3,3,0,17,0,3,3,0,0,11,0
0,18,1,0,3,3,3,3,3,0,11,0,0,0
0,10,0,11,0,0,3,3,19,0,0,0,10,0
86,0,0,0,0,10,0,11,0,10,0,10,0,86
86,86,0,10,0,0,10,0,0,0,0,0,86,86
endlayer

layer
86,0,0,0,0,0,0,0,0,0,0,0,0,86
0,0,0,0,0,21,0,0,0,0,20,0,0,0
0,0,0,0,10,0,20,0,0,10,0,0,0,0
0,0,0,1,3,3,3,3,3,1,10,0,0,0
20,0,10,3,3,0,22,0,3,3,1,10,21,0
0,0,20,3,0,0,0,0,13,3,1,23,0,0
0,0,0,3,25,0,0,0,24,3,0,0,0,0
0,0,10,3,0,0,0,0,0,3,0,0,0,0
0,0,11,3,3,0,26,0,3,3,0,0,21,0
0,18,0,0,3,3,3,3,3,0,23,0,0,0
0,0,0,28,0,27,3,19,0,0,0,0,0,0
0,0,0,0,0,0,0,23,0,0,0,0,0,0
86,0,0,0,0,0,0,0,0,0,0,0,0,86
endlayer

layer
0,0,0,0,0,0,0,0,0,0,0,0,0,0
0,0,0,0,0,0,0,0,0,0,0,0,0,0
0,0,0,0,0,0,0,0,0,0,0,0,0,0
0,0,0,10,3,3,3,3,3,10,0,0,0,0
0,0,0,3,3,0,0,29,3,3,0,0,0,0
0,0,0,3,29,0,0,0,13,3,10,0,0,0
0,0,0,31,0,0,0,27,30,3,0,0,0,0
0,0,0,3,29,0,0,0,29,3,0,0,0,0
0,0,28,3,3,0,0,0,3,3,0,0,0,0
0,18,0,18,3,3,3,3,3,0,0,0,0,0
0,0,0,0,27,32,0,0,0,0,0,0,0,0
0,0,0,0,0,0,0,0,0,0,0,0,0,0
0,0,0,0,0,0,0,0,0,0,0,0,0,0
endlayer

layer
0,0,0,0,0,0,0,0,0,0,0,0,0,0
0,0,0,0,0,0,0,0,0,0,0,0,0,0
0,0,0,0,0,27,34,33,0,0,0,0,0,0
0,0,0,0,3,3,3,3,3,0,0,0,0,0
0,0,0,3,3,35,35,30,3,3,0,0,0,0
0,0,0,3,37,0,0,36,13,3,0,0,0,0
0,0,0,39,37,0,0,0,0,3,38,0,0,0
0,0,0,3,37,0,0,40,40,31,0,0,0,0
0,0,0,3,3,34,34,34,3,3,0,0,0,0
0,18,0,30,3,3,3,3,3,0,0,0,0,0
0,0,0,27,32,0,0,0,0,0,0,0,0,0
0,0,0,0,0,0,0,0,0,0,0,0,0,0
0,0,0,0,0,0,0,0,0,0,0,0,0,0
endlayer

layer
0,0,0,0,0,0,0,0,0,0,0,0,0,0
0,0,0,0,0,0,0,0,0,0,0,0,0,0
0,0,0,0,0,18,18,18,0,0,0,0,0,0
0,0,0,0,3,3,41,3,3,0,0,0,0,0
0,0,0,3,3,0,0,0,3,3,0,0,0,0
0,0,0,42,0,0,0,0,0,3,0,0,0,0
0,0,0,3,0,0,0,0,0,3,43,0,0,0
0,0,0,3,0,0,0,0,0,39,0,0,0,0
0,37,0,3,3,44,0,0,3,3,0,0,0,0
0,30,27,36,3,19,3,3,3,0,0,0,0,0
0,0,0,0,0,0,0,38,0,0,0,0,0,0
0,0,0,0,0,0,0,0,0,0,0,0,0,0
0,0,0,0,0,0,0,0,0,0,0,0,0,0
endlayer

layer
0,0,0,0,0,0,0,0,0,0,0,0,0,0
0,0,0,0,0,0,0,0,0,0,0,0,0,0
0,0,0,0,0,43,0,43,0,0,0,0,0,0
0,0,0,0,3,3,45,3,3,0,0,0,0,0
0,0,0,3,3,0,0,0,3,3,0,0,0,0
0,0,0,46,0,0,0,0,0,3,0,0,0,0
0,0,0,3,0,0,0,0,0,3,0,0,0,0
0,34,0,3,0,0,0,0,0,3,0,0,0,0
0,36,0,3,3,44,0,0,3,3,0,0,0,0
0,0,0,0,3,47,3,3,3,0,0,0,0,0
0,0,0,0,0,0,0,43,0,0,0,0,0,0
0,0,0,0,0,0,0,0,0,0,0,0,0,0
0,0,0,0,0,0,0,0,0,0,0,0,0,0
endlayer

layer
0,0,0,0,0,0,0,0,0,0,0,0,0,0
0,0,0,0,0,0,0,0,0,0,0,0,0,0
0,0,0,0,0,39,0,39,0,0,0,0,0,0
0,0,0,0,3,3,3,3,3,0,0,0,0,0
0,0,0,3,3,29,0,29,3,3,0,0,0,0
0,0,48,3,29,0,0,0,29,3,47,0,0,0
0,34,0,3,0,0,0,0,0,3,0,0,0,0
0,36,48,3,29,0,0,0,29,3,47,0,0,0
0,0,0,3,3,44,0,29,3,3,0,0,0,0
0,0,0,0,3,3,3,3,3,0,0,0,0,0
0,0,0,0,0,46,0,46,0,0,0,0,0,0
0,0,0,0,0,0,0,0,0,0,0,0,0,0
0,0,0,0,0,0,0,0,0,0,0,0,0,0
endlayer

layer
0,0,0,0,0,0,0,0,0,0,0,0,0,0
0,0,0,0,0,0,0,0,0,0,0,0,0,0
0,0,49,49,49,49,49,49,49,49,49,0,0,0
0,0,49,3,50,50,50,50,50,3,49,0,0,0
0,0,49,50,51,52,51,52,51,50,49,0,0,0
0,34,49,50,52,51,53,51,52,30,49,0,0,0
0,36,49,50,51,52,51,52,51,36,49,0,0,0
0,0,49,50,52,51,54,51,52,50,49,0,0,0
0,0,49,50,51,55,51,52,51,50,49,0,0,0
0,0,49,3,50,50,50,50,50,3,49,0,0,0
0,0,49,49,49,49,49,49,49,49,49,0,0,0
0,0,0,0,0,0,0,0,0,0,0,0,0,0
0,0,0,0,0,0,0,0,0,0,0,0,0,0
endlayer

layer
0,0,0,0,0,0,0,0,0,0,0,0,0,0
0,0,0,0,0,0,0,0,0,0,0,0,0,0
0,0,49,56,56,49,57,49,56,56,49,0,0,0
0,0,56,59,58,0,0,0,0,0,56,0,0,0
0,0,56,44,0,0,0,0,0,34,56,0,0,0
0,0,49,0,0,0,52,0,0,36,49,0,0,0
0,0,60,0,0,0,51,0,0,0,57,0,0,0
0,0,49,0,0,0,52,0,0,0,49,0,0,0
0,0,56,44,0,0,0,0,0,0,56,0,0,0
0,0,56,63,62,0,0,0,0,61,56,0,0,0
0,0,49,56,56,49,57,49,56,56,49,0,0,0
0,0,0,0,0,0,0,0,0,0,0,0,0,0
0,0,0,0,0,0,0,0,0,0,0,0,0,0
endlayer

layer
0,0,0,0,0,0,0,0,0,0,0,0,0,0
0,0,0,0,0,0,0,0,0,0,0,0,0,0
0,0,49,56,56,49,57,49,56,56,49,0,0,0
0,0,56,59,58,0,0,0,0,34,56,0,0,0
0,0,56,44,0,0,0,0,0,36,56,0,0,0
0,38,49,0,0,0,0,0,0,0,49,0,0,0
0,0,45,0,0,0,0,0,0,0,57,0,0,0
0,0,49,0,0,0,0,0,0,0,49,0,0,0
0,0,56,44,0,0,0,0,0,0,56,0,0,0
0,0,56,63,62,0,0,0,0,38,56,38,0,0
0,0,49,56,56,49,57,49,56,56,49,0,0,0
0,0,0,0,0,0,0,0,0,0,0,0,0,0
0,0,0,0,0,0,0,0,0,0,0,0,0,0
endlayer

layer
0,0,0,0,0,0,0,0,0,0,0,0,0,0
0,0,0,0,0,0,0,0,0,0,0,0,0,0
0,0,49,56,56,49,57,49,56,56,49,0,0,0
0,0,56,59,58,0,0,0,27,36,56,0,0,0
0,0,56,44,0,0,0,0,0,0,56,0,0,0
0,43,49,0,0,0,18,0,0,0,49,0,0,0
0,0,49,0,0,18,18,18,0,0,57,0,0,0
0,0,49,0,0,0,18,0,0,0,49,0,0,0
0,0,56,44,0,0,0,0,0,0,56,0,0,0
0,0,56,63,62,0,0,0,0,0,56,38,0,0
0,0,49,56,56,49,57,49,56,56,49,0,0,0
0,0,0,0,0,0,0,0,0,0,0,0,0,0
0,0,0,0,0,0,0,0,0,0,0,0,0,0
endlayer

layer
0,0,0,0,0,0,0,0,0,0,0,0,0,0
0,0,0,0,0,0,0,0,0,0,0,0,0,0
0,0,49,56,56,49,57,49,56,56,49,0,0,0
0,0,56,59,58,0,0,27,32,0,56,0,0,0
0,0,56,44,0,0,0,0,0,0,56,0,0,0
0,0,49,0,0,0,43,0,0,0,49,0,0,0
0,0,57,0,0,43,18,43,0,0,57,0,0,0
0,0,49,0,0,0,43,0,0,0,49,0,0,0
0,0,56,44,0,0,0,0,0,0,56,0,0,0
0,0,56,63,62,0,0,0,0,0,56,38,38,0
0,0,49,56,56,49,57,49,56,56,49,0,0,0
0,0,0,0,0,0,0,0,0,0,0,0,0,0
0,0,0,0,0,0,0,0,0,0,0,0,0,0
endlayer

layer
0,0,0,0,0,0,0,0,0,0,0,0,0,0
0,0,64,0,0,64,0,64,0,0,64,0,0,0
0,66,49,49,49,49,49,49,49,49,49,65,0,0
0,0,49,37,37,37,49,32,0,0,49,0,0,0
0,0,49,37,37,37,49,37,37,0,49,0,0,0
0,66,49,37,37,37,49,37,37,37,49,65,0,0
0,0,49,49,49,49,49,49,49,49,49,0,0,0
0,66,49,37,37,37,49,37,37,37,49,65,0,0
0,0,49,37,37,37,49,37,37,37,49,0,0,0
0,0,49,37,37,37,49,37,37,37,49,0,38,0
0,66,49,49,49,49,49,49,49,49,49,65,0,0
0,0,67,0,0,67,0,67,0,0,67,0,0,0
0,0,0,0,0,0,0,0,0,0,0,0,0,0
endlayer

layer
40,40,40,40,40,40,40,40,40,40,40,40,40,0
68,30,30,30,30,30,30,30,30,30,30,30,32,0
68,30,63,0,18,0,70,0,69,0,63,30,32,0
68,30,63,0,18,0,0,0,0,0,0,30,32,0
68,30,63,71,18,0,0,0,0,0,0,30,32,0
68,30,49,0,18,72,73,72,0,0,18,30,30,30
68,30,49,0,74,73,0,73,0,0,52,30,30,30
68,30,49,0,18,72,73,72,18,0,0,30,30,30
68,30,63,0,18,18,18,18,18,30,0,30,32,0
68,30,63,0,0,0,0,0,0,0,38,38,38,0
68,30,63,0,0,75,52,0,0,0,61,30,32,0
68,30,30,30,30,30,30,30,30,30,30,30,32,0
36,36,36,36,36,30,30,30,36,36,36,36,32,0
endlayer

layer
0,0,0,0,0,0,0,0,0,0,0,0,0,0
0,30,30,30,30,30,57,30,30,30,30,30,0,0
0,30,63,0,18,0,0,0,0,0,63,30,0,0
0,30,63,0,0,0,0,0,0,0,0,30,0,0
0,30,63,0,0,0,0,0,0,0,0,30,0,0
0,30,77,0,0,0,0,0,0,0,76,30,18,18
0,57,77,0,0,0,0,0,0,0,0,60,0,18
0,30,77,0,0,0,0,0,34,0,0,30,18,18
0,30,63,0,0,0,0,0,27,30,0,30,0,0
0,30,63,0,0,0,0,0,0,0,0,30,38,0
0,30,63,0,0,0,0,0,0,0,0,30,0,0
0,30,30,30,30,30,41,30,30,30,30,30,0,0
0,0,0,0,0,18,18,18,0,0,0,0,0,0
endlayer

layer
0,0,0,0,0,0,0,0,0,0,0,0,0,0
0,40,40,40,40,30,57,30,40,40,40,32,0,0
0,68,30,35,30,35,0,35,35,35,30,32,0,0
0,68,30,0,0,0,0,0,0,0,27,32,0,0
0,68,30,0,0,0,0,0,0,0,27,32,0,0
0,30,0,0,0,0,0,0,0,0,35,30,0,76
0,57,0,0,0,0,0,0,0,0,0,45,0,0
0,30,0,0,0,0,0,0,0,0,34,30,0,76
0,68,30,0,0,0,0,0,13,30,30,32,0,0
0,68,30,0,0,0,0,0,0,0,30,32,38,0
0,68,30,34,34,33,0,27,34,34,30,32,0,0
0,36,36,36,36,30,45,30,36,36,36,36,0,0
0,0,0,0,0,76,0,76,0,0,0,0,0,0
endlayer

layer
0,0,0,0,0,0,0,0,0,0,0,0,0,0
0,0,0,0,0,68,34,32,0,0,0,0,0,0
0,0,30,30,30,30,35,30,30,30,30,0,0,0
0,0,30,0,0,0,0,0,0,0,30,0,0,0
0,0,30,0,0,0,78,0,0,0,30,0,0,0
0,30,35,0,0,0,79,0,0,0,30,40,0,0
0,57,0,0,82,79,81,79,80,0,27,30,0,0
0,30,34,0,0,0,79,0,0,0,30,36,0,0
0,0,30,0,0,0,83,0,13,30,30,0,0,0
0,0,30,0,0,0,0,0,0,0,30,0,38,0
0,0,30,30,30,30,30,30,30,30,30,0,0,0
0,0,0,0,0,68,35,32,0,0,0,0,0,0
0,0,0,0,0,0,0,0,0,0,0,0,0,0
endlayer

layer
0,0,0,0,0,0,0,0,0,0,0,0,0,0
0,0,0,0,0,0,84,0,0,0,0,0,0,0
0,0,68,40,40,40,40,40,40,40,40,0,0,0
0,0,68,30,30,30,30,30,30,30,32,0,0,0
0,0,68,30,0,0,0,0,0,30,32,0,0,0
0,40,30,30,0,0,0,0,0,30,32,0,0,0
0,27,30,30,0,0,79,0,0,30,32,84,0,0
0,36,30,30,0,0,0,0,0,30,32,0,0,0
0,0,68,30,0,0,0,0,13,30,32,0,0,0
0,0,68,30,30,30,30,30,30,30,32,0,38,0
0,0,36,36,36,36,36,36,36,36,32,0,0,0
0,0,0,0,0,0,84,0,0,0,0,0,0,0
0,0,0,0,0,0,0,0,0,0,0,0,0,0
endlayer

layer
0,0,0,0,0,0,0,0,0,0,0,0,0,0
0,0,0,0,0,0,0,0,0,0,0,0,0,0
0,0,0,0,0,0,0,0,0,0,0,0,0,0
0,0,0,30,30,30,30,30,30,30,0,0,0,0
0,0,0,30,0,0,0,0,0,30,0,0,0,0
0,0,40,30,0,0,0,0,0,30,0,0,0,0
0,84,68,30,0,0,79,0,0,30,0,0,0,0
0,0,36,30,0,0,0,0,0,30,0,0,0,0
0,0,0,30,0,0,0,0,13,30,0,0,0,0
0,0,0,30,30,30,30,30,30,30,0,0,38,0
0,0,0,0,0,0,0,0,0,0,0,0,0,0
0,0,0,0,0,0,0,0,0,0,0,0,0,0
0,0,0,0,0,0,0,0,0,0,0,0,0,0
endlayer

layer
0,0,0,0,0,0,0,0,0,0,0,0,0,0
0,0,0,0,0,0,0,0,0,0,0,0,0,0
0,0,0,0,0,0,0,0,0,0,0,0,0,0
0,0,0,68,40,40,40,40,40,40,0,0,0,0
0,0,0,68,30,30,30,30,30,32,0,0,0,0
0,0,0,68,30,0,0,0,30,32,0,0,0,0
0,0,0,68,30,0,79,0,30,32,0,0,0,0
0,0,0,68,30,0,0,0,30,32,0,0,0,0
0,0,0,68,30,30,30,30,13,32,0,0,0,0
0,0,0,36,36,36,36,36,36,32,0,0,38,0
0,0,0,0,0,0,0,0,0,0,0,0,0,0
0,0,0,0,0,0,0,0,0,0,0,0,0,0
0,0,0,0,0,0,0,0,0,0,0,0,0,0
endlayer

layer
0,0,0,0,0,0,0,0,0,0,0,0,0,0
0,0,0,0,0,0,0,0,0,0,0,0,0,0
0,0,0,0,0,0,0,0,0,0,0,0,0,0
0,0,0,0,0,0,0,0,0,0,0,0,0,0
0,0,0,0,30,30,30,30,30,0,0,0,0,0
0,0,0,0,30,0,0,0,30,0,0,0,0,0
0,0,0,0,30,0,79,0,30,0,0,0,0,0
0,0,0,0,30,0,0,0,30,0,0,0,0,0
0,0,0,0,30,30,30,30,85,0,0,0,0,0
0,0,0,0,0,0,0,0,0,0,0,0,0,0
0,0,0,0,0,0,0,0,0,0,0,0,0,0
0,0,0,0,0,0,0,0,0,0,0,0,0,0
0,0,0,0,0,0,0,0,0,0,0,0,0,0
endlayer

layer
0,0,0,0,0,0,0,0,0,0,0,0,0,0
0,0,0,0,0,0,0,0,0,0,0,0,0,0
0,0,0,0,0,0,0,0,0,0,0,0,0,0
0,0,0,0,0,0,0,0,0,0,0,0,0,0
0,0,0,0,68,40,40,40,40,0,0,0,0,0
0,0,0,0,68,30,30,30,32,0,0,0,0,0
0,0,0,0,68,30,79,30,32,0,0,0,0,0
0,0,0,0,68,30,30,30,32,0,0,0,0,0
0,0,0,0,36,36,36,36,0,0,0,0,0,0
0,0,0,0,0,0,0,0,0,0,0,0,0,0
0,0,0,0,0,0,0,0,0,0,0,0,0,0
0,0,0,0,0,0,0,0,0,0,0,0,0,0
0,0,0,0,0,0,0,0,0,0,0,0,0,0
endlayer

layer
0,0,0,0,0,0,0,0,0,0,0,0,0,0
0,0,0,0,0,0,0,0,0,0,0,0,0,0
0,0,0,0,0,0,0,0,0,0,0,0,0,0
0,0,0,0,0,0,0,0,0,0,0,0,0,0
0,0,0,0,0,0,0,0,0,0,0,0,0,0
0,0,0,0,0,30,30,30,0,0,0,0,0,0
0,0,0,0,0,30,79,30,0,0,0,0,0,0
0,0,0,0,0,30,30,30,0,0,0,0,0,0
0,0,0,0,0,0,0,0,0,0,0,0,0,0
0,0,0,0,0,0,0,0,0,0,0,0,0,0
0,0,0,0,0,0,0,0,0,0,0,0,0,0
0,0,0,0,0,0,0,0,0,0,0,0,0,0
0,0,0,0,0,0,0,0,0,0,0,0,0,0
endlayer

layer
0,0,0,0,0,0,0,0,0,0,0,0,0,0
0,0,0,0,0,0,0,0,0,0,0,0,0,0
0,0,0,0,0,0,0,0,0,0,0,0,0,0
0,0,0,0,0,0,0,0,0,0,0,0,0,0
0,0,0,0,0,0,0,0,0,0,0,0,0,0
0,0,0,0,0,68,40,40,0,0,0,0,0,0
0,0,0,0,0,68,30,32,0,0,0,0,0,0
0,0,0,0,0,36,36,32,0,0,0,0,0,0
0,0,0,0,0,0,0,0,0,0,0,0,0,0
0,0,0,0,0,0,0,0,0,0,0,0,0,0
0,0,0,0,0,0,0,0,0,0,0,0,0,0
0,0,0,0,0,0,0,0,0,0,0,0,0,0
0,0,0,0,0,0,0,0,0,0,0,0,0,0
endlayer

layer
0,0,0,0,0,0,0,0,0,0,0,0,0,0
0,0,0,0,0,0,0,0,0,0,0,0,0,0
0,0,0,0,0,0,0,0,0,0,0,0,0,0
0,0,0,0,0,0,0,0,0,0,0,0,0,0
0,0,0,0,0,0,0,0,0,0,0,0,0,0
0,0,0,0,0,0,0,0,0,0,0,0,0,0
0,0,0,0,0,0,30,0,0,0,0,0,0,0
0,0,0,0,0,0,0,0,0,0,0,0,0,0
0,0,0,0,0,0,0,0,0,0,0,0,0,0
0,0,0,0,0,0,0,0,0,0,0,0,0,0
0,0,0,0,0,0,0,0,0,0,0,0,0,0
0,0,0,0,0,0,0,0,0,0,0,0,0,0
0,0,0,0,0,0,0,0,0,0,0,0,0,0
endlayer

layer
0,0,0,0,0,0,0,0,0,0,0,0,0,0
0,0,0,0,0,0,0,0,0,0,0,0,0,0
0,0,0,0,0,0,0,0,0,0,0,0,0,0
0,0,0,0,0,0,0,0,0,0,0,0,0,0
0,0,0,0,0,0,0,0,0,0,0,0,0,0
0,0,0,0,0,0,0,0,0,0,0,0,0,0
0,0,0,0,0,0,18,0,0,0,0,0,0,0
0,0,0,0,0,0,0,0,0,0,0,0,0,0
0,0,0,0,0,0,0,0,0,0,0,0,0,0
0,0,0,0,0,0,0,0,0,0,0,0,0,0
0,0,0,0,0,0,0,0,0,0,0,0,0,0
0,0,0,0,0,0,0,0,0,0,0,0,0,0
0,0,0,0,0,0,0,0,0,0,0,0,0,0
endlayer

layer
0,0,0,0,0,0,0,0,0,0,0,0,0,0
0,0,0,0,0,0,0,0,0,0,0,0,0,0
0,0,0,0,0,0,0,0,0,0,0,0,0,0
0,0,0,0,0,0,0,0,0,0,0,0,0,0
0,0,0,0,0,0,0,0,0,0,0,0,0,0
0,0,0,0,0,0,0,0,0,0,0,0,0,0
0,0,0,0,0,0,76,0,0,0,0,0,0,0
0,0,0,0,0,0,0,0,0,0,0,0,0,0
0,0,0,0,0,0,0,0,0,0,0,0,0,0
0,0,0,0,0,0,0,0,0,0,0,0,0,0
0,0,0,0,0,0,0,0,0,0,0,0,0,0
0,0,0,0,0,0,0,0,0,0,0,0,0,0
0,0,0,0,0,0,0,0,0,0,0,0,0,0
endlayer

