
# Windmill (intact) -- (2014 Mar 19 -- for MC v. 1.7.2)
# Updated to MC 1.7.10, 11 Oct 2014
# Updated 3 Apr 2015 (fixed mob spawner)
# Created by Ruins mod version 12.3 Ingame Parser
# authoring Player: Jordan_Greywolf
# Updated to MC 1.8: 29 Oct 2015
# Updated to MC 1.9: 29 Apr 2016
# Updated to MC 1.12: 23 Jun 2017
# Updated to MC 1.12.1: 9 Sep 2017

biomesToSpawnIn=alps,birch forest hills,birch forest hills m,cold taiga hills,crag,extreme hills,extreme hills edge,extreme hills m,extreme hills+,extreme hills+ m,foresthills,highland,highlands,ice mountains,ice plains,ice wasteland,moor,mountain,mountain foothills,rwg_plains,savanna plateau,savanna plateau m,taigahills,moor,moors,silkglades,mining biome,mining_biome,ice_flats,ice_mountains,mutated_ice_flats,mutated_ice_mountains,mutated_savanna_rock,savanna_rock,smaller_extreme_hills,taiga_hills

weight=1
embed_into_distance=5

unacceptable_target_blocks=water,flowing_water,lava,flowing_lava,cloud,Natura:Cloud,slime_congealed,slime_dirt,slime_grass,command_block

dimensions=20,13,11
allowable_overhang=400
max_cut_in=0
cut_in_buffer=0
max_leveling=5
leveling_buffer=-1
preserve_water=0
preserve_lava=0
preserve_plants=1

# PreserveBlock used as beveling to blend to elevations higher
# than target block at edges
rule1=0,100,preserveBlock

# "Ramp" of grass/dirt is only exposed if elevation drops
# compared to target block toward edges
rule2=0,100,minecraft:grass-0
rule3=0,100,minecraft:dirt-0

rule4=0,100,minecraft:cobblestone-0
rule5=0,100,minecraft:mossy_cobblestone-0

# Monster spawner & treasure
rule6=0,100,MobSpawner:Cave_Spider
rule7=0,100,ChestGenHook:chests/simple_dungeon:3-2

rule8=0,100,minecraft:web-0
rule9=0,100,minecraft:fence-0
rule10=0,100,minecraft:spruce_stairs-6
rule11=0,100,minecraft:spruce_stairs-3

rule12=0,100,minecraft:web-0

rule13=0,100,minecraft:spruce_stairs-4
rule14=0,100,minecraft:spruce_stairs-1

rule15=0,100,minecraft:wooden_slab-9

rule16=0,100,minecraft:planks-1
rule17=0,100,minecraft:log-0

# Occasional possible mossy chunks in outer wall
rule18=0,100,minecraft:cobblestone-0,minecraft:mossy_cobblestone-0

rule19=0,100,minecraft:spruce_stairs-2
rule20=0,100,minecraft:spruce_stairs-5

rule21=0,100,minecraft:log-8

rule22=0,100,minecraft:fence-0

rule23=0,100,minecraft:log-4
rule24=0,100,minecraft:spruce_stairs-0
rule25=0,100,minecraft:stone_stairs-2
rule26=0,100,minecraft:stone_stairs-0
rule27=0,100,minecraft:stone_stairs-3
rule28=0,100,minecraft:stone_stairs-1

rule29=0,100,minecraft:planks-0
rule30=0,100,minecraft:wooden_slab-1

layer
1,1,2,3,3,3,3,2,2,1,1
1,2,3,3,3,3,3,3,3,2,1
2,3,3,3,3,3,3,3,3,3,2
3,3,4,4,4,4,4,4,4,3,3
3,3,4,5,5,5,5,5,4,3,3
3,3,4,5,5,5,5,5,4,3,3
3,3,4,5,5,5,5,5,4,3,3
3,3,4,5,5,5,5,5,4,3,3
3,3,4,5,5,5,5,5,4,3,3
3,3,4,4,4,4,4,4,4,3,3
2,3,3,3,3,3,3,3,3,3,2
1,2,3,3,3,3,3,3,3,2,1
1,1,2,3,3,3,3,3,2,1,1
endlayer

layer
1,1,1,2,3,3,3,2,1,1,1
1,1,2,3,3,3,3,3,2,1,1
1,2,3,3,3,3,3,3,3,2,1
2,3,4,4,4,4,4,4,4,3,2
3,3,4,8,8,0,7,6,4,3,3
3,3,4,0,0,0,8,8,4,3,3
3,3,4,0,0,9,0,0,4,3,3
3,3,4,0,0,0,9,8,4,3,3
3,3,4,0,0,0,11,10,4,3,3
2,3,4,4,4,4,4,4,4,3,2
1,2,3,3,3,3,3,3,3,2,1
1,1,2,3,3,3,3,3,2,1,1
1,1,1,2,3,3,3,2,1,1,1
endlayer

layer
1,1,1,1,2,2,2,1,1,1,1
1,1,1,2,3,3,3,2,1,1,1
1,1,2,3,3,3,3,3,2,1,1
1,2,4,4,4,4,4,4,4,2,1
2,3,4,0,0,0,8,8,4,3,2
3,3,4,0,0,0,8,8,4,3,3
3,3,4,12,0,9,0,8,4,3,3
3,3,4,0,0,0,9,13,4,3,3
2,3,4,0,0,0,0,11,4,3,2
1,2,4,4,4,4,4,4,4,2,1
1,1,2,3,3,3,3,3,2,1,1
1,1,1,2,3,3,3,2,1,1,1
1,1,1,1,2,2,2,1,1,1,1
endlayer

layer
1,1,1,1,1,1,1,1,1,1,1
1,1,1,1,2,2,2,1,1,1,1
1,1,1,2,3,3,3,2,1,1,1
1,1,4,4,4,4,4,4,4,1,1
1,2,4,8,0,8,8,8,4,2,1
2,3,4,0,0,0,0,8,4,3,2
2,3,4,8,0,9,0,13,4,3,2
2,3,4,0,0,0,9,14,4,3,2
1,2,4,8,0,8,0,0,4,2,1
1,1,4,4,4,4,4,4,4,1,1
1,1,1,2,3,3,3,2,1,1,1
1,1,1,1,2,2,2,1,1,1,1
1,1,1,1,1,1,1,1,1,1,1
endlayer

layer
1,1,1,1,1,1,1,1,1,1,1
1,1,1,1,1,1,1,1,1,1,1
1,1,1,1,2,2,2,1,1,1,1
1,1,4,4,4,4,4,4,4,1,1
1,1,4,15,15,16,15,15,4,1,1
1,2,4,15,15,16,15,15,4,2,1
1,2,4,16,16,16,16,14,4,2,1
1,2,4,15,15,16,16,0,4,2,1
1,1,4,15,15,16,0,0,4,1,1
1,1,4,4,4,4,4,4,4,1,1
1,1,1,1,2,2,2,1,1,1,1
1,1,1,1,1,1,1,1,1,1,1
1,1,1,1,1,1,1,1,1,1,1
endlayer

layer
1,1,1,1,1,1,1,1,1,1,1
1,1,1,1,1,1,1,1,1,1,1
1,1,1,1,0,0,0,1,1,1,1
1,1,17,4,4,18,4,18,17,1,1
1,1,4,8,0,0,8,8,4,1,1
1,0,4,8,16,19,0,0,4,0,1
1,0,18,0,8,9,0,0,0,0,1
1,0,4,0,0,0,0,0,4,0,1
1,1,4,8,0,8,0,0,4,1,1
1,1,17,18,4,4,4,4,17,1,1
1,1,1,1,0,0,0,1,1,1,1
1,1,1,1,1,1,1,1,1,1,1
1,1,1,1,1,1,1,1,1,1,1
endlayer

layer
1,1,1,1,1,1,1,1,1,1,1
1,1,1,0,0,0,0,0,1,1,1
1,1,0,0,0,0,0,0,0,1,1
1,0,17,18,4,4,18,4,17,0,1
0,0,18,8,0,8,0,8,4,0,0
0,0,4,8,19,0,0,0,4,0,0
0,0,4,8,20,9,0,0,0,0,0
0,0,4,0,0,0,0,0,4,0,0
0,0,18,8,0,0,0,0,18,0,0
1,0,17,4,4,4,18,4,17,0,1
1,1,0,0,0,0,0,0,0,1,1
1,1,1,0,0,0,0,0,1,1,1
1,1,1,1,1,1,1,1,1,1,1
endlayer

layer
1,1,1,0,0,0,0,0,1,1,1
1,1,0,0,0,0,0,0,0,1,1
1,0,0,0,0,0,0,0,0,0,1
0,0,17,18,4,4,4,18,17,0,0
0,0,4,17,21,21,21,17,18,0,0
0,0,18,23,8,0,0,23,4,0,22
0,0,18,23,24,16,16,23,18,0,9
0,0,4,23,15,16,15,23,4,0,22
0,0,4,17,21,21,21,17,18,0,0
0,0,17,4,18,4,4,18,17,0,0
1,0,0,0,0,0,0,0,0,0,1
1,1,0,0,0,0,0,0,0,1,1
1,1,1,0,0,0,0,0,1,1,1
endlayer

layer
1,1,0,0,0,0,0,0,0,1,1
1,0,0,0,0,0,0,0,0,0,1
0,0,0,0,0,0,0,0,0,0,0
0,0,27,26,26,26,26,26,25,0,0
0,0,27,17,4,4,4,17,25,0,0
0,0,27,4,8,0,8,4,25,0,22
0,0,27,4,8,9,8,4,25,0,9
0,0,27,4,6,8,8,4,25,0,22
0,0,27,17,4,4,4,17,25,0,0
0,0,28,28,28,28,28,28,28,0,0
0,0,0,0,0,0,0,0,0,0,0
1,0,0,0,0,0,0,0,0,0,1
1,1,0,0,0,0,0,0,0,1,1
endlayer

layer
1,0,0,0,0,0,0,0,0,0,1
0,0,0,0,0,0,0,0,0,0,0
0,0,0,0,0,0,0,0,0,0,0
0,0,0,0,0,0,0,0,0,0,0
0,0,0,17,18,9,4,17,0,0,0
0,0,0,18,8,0,8,4,0,0,22
0,0,0,9,8,9,0,9,0,0,9
0,0,0,4,8,0,8,4,0,0,22
0,0,0,17,4,9,4,17,0,0,0
0,0,0,0,0,0,0,0,0,0,0
0,0,0,0,0,0,0,0,0,0,0
0,0,0,0,0,0,0,0,0,0,0
1,0,0,0,0,0,0,0,0,0,1
endlayer

layer
0,0,0,0,0,0,0,0,0,0,0
0,0,0,0,0,0,0,0,0,0,0
0,0,0,0,0,0,0,0,0,0,0
0,0,0,0,0,0,0,0,0,0,0
0,0,0,17,4,18,4,17,0,0,0
0,0,0,4,17,21,17,4,0,0,22
0,0,0,4,23,9,23,18,0,0,9
0,0,0,4,17,21,17,4,0,0,22
0,0,0,17,4,18,4,17,0,0,0
0,0,0,0,0,0,0,0,0,0,0
0,0,0,0,0,0,0,0,0,0,0
0,0,0,0,0,0,0,0,0,0,0
0,0,0,0,0,0,0,0,0,0,0
endlayer

layer
0,0,0,0,0,0,0,0,0,0,0
0,0,0,0,0,0,0,0,0,0,0
0,0,0,0,0,0,0,0,0,0,0
0,0,0,0,0,0,0,0,0,0,0
0,0,0,27,26,26,26,26,0,0,0
0,0,0,27,17,4,17,25,0,0,22
0,0,0,27,4,9,4,25,0,0,9
0,0,0,27,17,4,17,25,0,0,22
0,0,0,28,28,28,28,25,0,0,0
0,0,0,0,0,0,0,0,0,0,0
0,0,0,0,0,0,0,0,0,0,0
0,0,0,0,0,0,0,0,0,0,0
0,0,0,0,0,0,0,0,0,0,0
endlayer

layer
0,0,0,0,0,0,0,0,0,0,0
0,0,0,0,0,0,0,0,0,0,0
0,0,0,0,0,0,0,0,0,0,0
0,0,0,0,0,0,0,0,0,0,0
0,0,0,0,0,0,0,0,0,0,0
0,0,0,0,17,4,17,0,0,0,0
0,0,0,0,4,9,4,0,0,0,9
0,0,0,0,17,4,17,0,0,0,0
0,0,0,0,0,0,0,0,0,0,22
0,0,0,0,0,0,0,0,0,0,22
0,0,0,0,0,0,0,0,0,0,22
0,0,0,0,0,0,0,0,0,0,22
0,0,0,0,0,0,0,0,0,0,22
endlayer

layer
0,0,0,0,0,0,0,0,0,0,9
0,0,0,0,0,0,0,0,0,0,9
0,0,0,0,0,0,0,0,0,0,9
0,0,0,0,0,0,0,0,0,0,9
0,0,0,0,0,0,0,0,0,0,9
0,0,0,0,17,18,17,0,0,0,9
0,0,0,0,4,9,29,29,29,29,29
0,0,0,0,17,18,17,0,0,0,9
0,0,0,0,0,0,0,0,0,0,9
0,0,0,0,0,0,0,0,0,0,9
0,0,0,0,0,0,0,0,0,0,9
0,0,0,0,0,0,0,0,0,0,9
0,0,0,0,0,0,0,0,0,0,9
endlayer

layer
0,0,0,0,0,0,0,0,0,0,22
0,0,0,0,0,0,0,0,0,0,22
0,0,0,0,0,0,0,0,0,0,22
0,0,0,0,0,0,0,0,0,0,22
0,0,0,0,0,0,0,0,0,0,22
0,0,0,0,24,24,19,0,0,0,0
0,0,0,0,11,16,19,0,0,0,9
0,0,0,0,11,14,14,0,0,0,0
0,0,0,0,0,0,0,0,0,0,0
0,0,0,0,0,0,0,0,0,0,0
0,0,0,0,0,0,0,0,0,0,0
0,0,0,0,0,0,0,0,0,0,0
0,0,0,0,0,0,0,0,0,0,0
endlayer

layer
0,0,0,0,0,0,0,0,0,0,0
0,0,0,0,0,0,0,0,0,0,0
0,0,0,0,0,0,0,0,0,0,0
0,0,0,0,0,0,0,0,0,0,0
0,0,0,0,0,0,0,0,0,0,0
0,0,0,0,0,0,0,0,0,0,22
0,0,0,0,0,30,0,0,0,0,9
0,0,0,0,0,0,0,0,0,0,22
0,0,0,0,0,0,0,0,0,0,0
0,0,0,0,0,0,0,0,0,0,0
0,0,0,0,0,0,0,0,0,0,0
0,0,0,0,0,0,0,0,0,0,0
0,0,0,0,0,0,0,0,0,0,0
endlayer

layer
0,0,0,0,0,0,0,0,0,0,0
0,0,0,0,0,0,0,0,0,0,0
0,0,0,0,0,0,0,0,0,0,0
0,0,0,0,0,0,0,0,0,0,0
0,0,0,0,0,0,0,0,0,0,0
0,0,0,0,0,0,0,0,0,0,22
0,0,0,0,0,0,0,0,0,0,9
0,0,0,0,0,0,0,0,0,0,22
0,0,0,0,0,0,0,0,0,0,0
0,0,0,0,0,0,0,0,0,0,0
0,0,0,0,0,0,0,0,0,0,0
0,0,0,0,0,0,0,0,0,0,0
0,0,0,0,0,0,0,0,0,0,0
endlayer

layer
0,0,0,0,0,0,0,0,0,0,0
0,0,0,0,0,0,0,0,0,0,0
0,0,0,0,0,0,0,0,0,0,0
0,0,0,0,0,0,0,0,0,0,0
0,0,0,0,0,0,0,0,0,0,0
0,0,0,0,0,0,0,0,0,0,22
0,0,0,0,0,0,0,0,0,0,9
0,0,0,0,0,0,0,0,0,0,22
0,0,0,0,0,0,0,0,0,0,0
0,0,0,0,0,0,0,0,0,0,0
0,0,0,0,0,0,0,0,0,0,0
0,0,0,0,0,0,0,0,0,0,0
0,0,0,0,0,0,0,0,0,0,0
endlayer

layer
0,0,0,0,0,0,0,0,0,0,0
0,0,0,0,0,0,0,0,0,0,0
0,0,0,0,0,0,0,0,0,0,0
0,0,0,0,0,0,0,0,0,0,0
0,0,0,0,0,0,0,0,0,0,0
0,0,0,0,0,0,0,0,0,0,22
0,0,0,0,0,0,0,0,0,0,9
0,0,0,0,0,0,0,0,0,0,22
0,0,0,0,0,0,0,0,0,0,0
0,0,0,0,0,0,0,0,0,0,0
0,0,0,0,0,0,0,0,0,0,0
0,0,0,0,0,0,0,0,0,0,0
0,0,0,0,0,0,0,0,0,0,0
endlayer

layer
0,0,0,0,0,0,0,0,0,0,0
0,0,0,0,0,0,0,0,0,0,0
0,0,0,0,0,0,0,0,0,0,0
0,0,0,0,0,0,0,0,0,0,0
0,0,0,0,0,0,0,0,0,0,0
0,0,0,0,0,0,0,0,0,0,22
0,0,0,0,0,0,0,0,0,0,9
0,0,0,0,0,0,0,0,0,0,22
0,0,0,0,0,0,0,0,0,0,0
0,0,0,0,0,0,0,0,0,0,0
0,0,0,0,0,0,0,0,0,0,0
0,0,0,0,0,0,0,0,0,0,0
0,0,0,0,0,0,0,0,0,0,0
endlayer

